File: data/instron_tests/clean_data/clean_homogenous_foams_test_1_1.csv
Time,Displacement,Compressive displacement,Compressive strain (Displacement),Compressive stress,Force
(s),(mm),(mm),(%),(kPa),(N)
"0.0000","6.4639","-0.0122","-0.0315","-0.0120","-0.0187"
"0.0600","6.4642","-0.0118","-0.0306","-0.0077","-0.0121"
"0.1200","6.4654","-0.0106","-0.0275","0.0044","0.0069"
"0.1800","6.4687","-0.0074","-0.0191","0.0415","0.0647"
"0.2400","6.4765","0.0005","0.0013","0.1293","0.2018"
"0.3000","6.4839","0.0079","0.0204","0.2138","0.3335"
"0.3600","6.4930","0.0169","0.0439","0.3216","0.5018"
"0.4200","6.5040","0.0280","0.0727","0.4590","0.7162"
"0.4800","6.5156","0.0396","0.1028","0.5910","0.9222"
"0.5400","6.5266","0.0505","0.1311","0.7122","1.1112"
"0.6000","6.5367","0.0607","0.1575","0.8204","1.2800"
"0.6600","6.5463","0.0703","0.1824","0.9314","1.4532"
"0.7200","6.5569","0.0808","0.2098","1.0572","1.6495"
"0.7800","6.5669","0.0909","0.2359","1.1745","1.8325"
"0.8400","6.5768","0.1008","0.2616","1.2999","2.0281"
"0.9000","6.5871","0.1110","0.2882","1.4168","2.2105"
"0.9600","6.5956","0.1196","0.3105","1.5192","2.3703"
"1.0200","6.6050","0.1289","0.3347","1.6409","2.5602"
"1.0800","6.6155","0.1395","0.3620","1.7879","2.7896"
"1.1400","6.6256","0.1495","0.3882","1.9307","3.0125"
"1.2000","6.6371","0.1610","0.4180","2.0974","3.2724"
"1.2600","6.6462","0.1702","0.4418","2.2262","3.4735"
"1.3200","6.6569","0.1808","0.4694","2.4034","3.7499"
"1.3800","6.6682","0.1922","0.4988","2.5952","4.0492"
"1.4400","6.6778","0.2017","0.5237","2.7546","4.2978"
"1.5000","6.6884","0.2123","0.5511","2.9439","4.5933"
"1.5600","6.6970","0.2210","0.5737","3.0968","4.8317"
"1.6200","6.7072","0.2312","0.6001","3.2919","5.1362"
"1.6800","6.7177","0.2416","0.6272","3.4816","5.4322"
"1.7400","6.7266","0.2506","0.6504","3.6387","5.6773"
"1.8000","6.7370","0.2609","0.6773","3.8483","6.0044"
"1.8600","6.7468","0.2708","0.7029","4.0462","6.3130"
"1.9200","6.7566","0.2805","0.7282","4.2483","6.6284"
"1.9800","6.7668","0.2907","0.7547","4.4689","6.9726"
"2.0400","6.7768","0.3008","0.7808","4.6847","7.3094"
"2.1000","6.7873","0.3112","0.8079","4.9248","7.6839"
"2.1600","6.7968","0.3208","0.8326","5.1364","8.0140"
"2.2200","6.8059","0.3299","0.8563","5.3455","8.3404"
"2.2800","6.8161","0.3401","0.8828","5.5974","8.7334"
"2.3400","6.8272","0.3511","0.9114","5.8795","9.1734"
"2.4000","6.8374","0.3614","0.9380","6.1432","9.5849"
"2.4600","6.8478","0.3718","0.9651","6.4207","10.0179"
"2.5200","6.8567","0.3807","0.9882","6.6604","10.3919"
"2.5800","6.8674","0.3913","1.0158","6.9657","10.8682"
"2.6400","6.8780","0.4020","1.0435","7.2647","11.3348"
"2.7000","6.8871","0.4111","1.0672","7.5133","11.7227"
"2.7600","6.8973","0.4213","1.0935","7.8095","12.1848"
"2.8200","6.9059","0.4299","1.1159","8.0506","12.5609"
"2.8800","6.9162","0.4401","1.1425","8.3640","13.0500"
"2.9400","6.9269","0.4509","1.1705","8.6939","13.5647"
"3.0000","6.9363","0.4603","1.1948","8.9682","13.9927"
"3.0600","6.9472","0.4712","1.2231","9.3139","14.5320"
"3.1200","6.9563","0.4803","1.2467","9.5652","14.9241"
"3.1800","6.9665","0.4904","1.2730","9.8872","15.4266"
"3.2400","6.9772","0.5012","1.3009","10.2425","15.9808"
"3.3000","6.9873","0.5112","1.3271","10.5694","16.4909"
"3.3600","6.9985","0.5224","1.3561","10.9493","17.0837"
"3.4200","7.0078","0.5318","1.3803","11.2373","17.5329"
"3.4800","7.0171","0.5411","1.4045","11.5389","18.0035"
"3.5400","7.0272","0.5511","1.4306","11.8896","18.5507"
"3.6000","7.0370","0.5610","1.4562","12.2251","19.0742"
"3.6600","7.0469","0.5708","1.4818","12.5686","19.6101"
"3.7200","7.0571","0.5811","1.5084","12.9361","20.1835"
"3.7800","7.0663","0.5903","1.5322","13.2717","20.7072"
"3.8400","7.0769","0.6009","1.5597","13.7002","21.3758"
"3.9000","7.0878","0.6118","1.5881","14.1486","22.0754"
"3.9600","7.0977","0.6216","1.6136","14.5449","22.6937"
"4.0200","7.1072","0.6312","1.6384","14.9413","23.3121"
"4.0800","7.1155","0.6394","1.6599","15.2797","23.8401"
"4.1400","7.1256","0.6496","1.6861","15.7389","24.5567"
"4.2000","7.1364","0.6604","1.7143","16.2410","25.3399"
"4.2600","7.1465","0.6705","1.7405","16.7044","26.0631"
"4.3200","7.1580","0.6820","1.7704","17.2616","26.9325"
"4.3800","7.1672","0.6912","1.7942","17.6706","27.5706"
"4.4400","7.1776","0.7015","1.8210","18.1640","28.3403"
"4.5000","7.1877","0.7116","1.8473","18.6485","29.0963"
"4.5600","7.1971","0.7211","1.8718","19.0953","29.7934"
"4.6200","7.2077","0.7316","1.8992","19.6187","30.6101"
"4.6800","7.2164","0.7403","1.9218","20.0149","31.2282"
"4.7400","7.2252","0.7492","1.9447","20.4275","31.8720"
"4.8000","7.2353","0.7592","1.9708","20.9297","32.6555"
"4.8600","7.2459","0.7698","1.9984","21.4627","33.4872"
"4.9200","7.2567","0.7806","2.0264","22.0263","34.3665"
"4.9800","7.2667","0.7906","2.0523","22.5330","35.1572"
"5.0400","7.2764","0.8004","2.0777","23.0481","35.9608"
"5.1000","7.2876","0.8115","2.1065","23.6470","36.8952"
"5.1600","7.2980","0.8220","2.1337","24.2052","37.7662"
"5.2200","7.3081","0.8320","2.1598","24.7454","38.6090"
"5.2800","7.3176","0.8415","2.1845","25.2476","39.3925"
"5.3400","7.3272","0.8511","2.2094","25.7745","40.2147"
"5.4000","7.3377","0.8617","2.2367","26.3622","41.1317"
"5.4600","7.3476","0.8716","2.2624","26.9094","41.9854"
"5.5200","7.3566","0.8806","2.2858","27.3963","42.7452"
"5.5800","7.3675","0.8915","2.3140","28.0286","43.7317"
"5.6400","7.3766","0.9005","2.3376","28.5184","44.4958"
"5.7000","7.3868","0.9108","2.3642","29.1128","45.4232"
"5.7600","7.3974","0.9214","2.3918","29.7331","46.3911"
"5.8200","7.4069","0.9309","2.4164","30.2921","47.2632"
"5.8800","7.4174","0.9414","2.4436","30.8980","48.2086"
"5.9400","7.4259","0.9499","2.4657","31.3527","48.9181"
"6.0000","7.4356","0.9595","2.4908","31.9150","49.7954"
"6.0600","7.4464","0.9703","2.5187","32.5593","50.8007"
"6.1200","7.4567","0.9807","2.5457","33.1590","51.7363"
"6.1800","7.4682","0.9921","2.5754","33.8541","52.8208"
"6.2400","7.4773","1.0012","2.5990","34.3488","53.5928"
"6.3000","7.4874","1.0113","2.6252","34.9459","54.5244"
"6.3600","7.4981","1.0220","2.6529","35.5821","55.5170"
"6.4200","7.5075","1.0314","2.6773","36.1159","56.3499"
"6.4800","7.5174","1.0413","2.7031","36.7108","57.2781"
"6.5400","7.5265","1.0505","2.7269","37.2287","58.0861"
"6.6000","7.5358","1.0598","2.7510","37.7762","58.9404"
"6.6600","7.5464","1.0704","2.7785","38.4219","59.9478"
"6.7200","7.5570","1.0810","2.8060","39.0628","60.9478"
"6.7800","7.5666","1.0906","2.8310","39.6383","61.8457"
"6.8400","7.5770","1.1010","2.8580","40.2594","62.8147"
"6.9000","7.5864","1.1104","2.8824","40.8179","63.6861"
"6.9600","7.5971","1.1211","2.9101","41.4675","64.6996"
"7.0200","7.6074","1.1314","2.9369","42.0965","65.6811"
"7.0800","7.6173","1.1413","2.9626","42.6961","66.6165"
"7.1400","7.6283","1.1523","2.9910","43.3745","67.6751"
"7.2000","7.6373","1.1613","3.0144","43.8947","68.4866"
"7.2600","7.6469","1.1708","3.0393","44.4689","69.3826"
"7.3200","7.6573","1.1813","3.0664","45.1182","70.3956"
"7.3800","7.6668","1.1908","3.0911","45.6850","71.2801"
"7.4400","7.6781","1.2020","3.1202","46.4036","72.4012"
"7.5000","7.6865","1.2105","3.1422","46.8825","73.1485"
"7.5600","7.6961","1.2200","3.1669","47.4692","74.0638"
"7.6200","7.7065","1.2304","3.1939","48.1175","75.0753"
"7.6800","7.7161","1.2401","3.2190","48.6992","75.9830"
"7.7400","7.7266","1.2505","3.2461","49.3665","77.0240"
"7.8000","7.7356","1.2596","3.2696","49.9034","77.8617"
"7.8600","7.7457","1.2696","3.2957","50.5390","78.8534"
"7.9200","7.7568","1.2808","3.3246","51.2501","79.9629"
"7.9800","7.7671","1.2911","3.3514","51.8851","80.9538"
"8.0400","7.7776","1.3015","3.3785","52.5525","81.9950"
"8.1000","7.7878","1.3118","3.4050","53.1835","82.9796"
"8.1600","7.7973","1.3213","3.4298","53.7708","83.8958"
"8.2200","7.8074","1.3313","3.4558","54.3950","84.8699"
"8.2800","7.8172","1.3411","3.4813","55.0042","85.8203"
"8.3400","7.8264","1.3504","3.5053","55.5592","86.6863"
"8.4000","7.8366","1.3605","3.5316","56.1833","87.6600"
"8.4600","7.8455","1.3695","3.5549","56.7230","88.5021"
"8.5200","7.8559","1.3798","3.5818","57.3848","89.5346"
"8.5800","7.8671","1.3911","3.6109","58.1173","90.6775"
"8.6400","7.8770","1.4010","3.6366","58.7259","91.6271"
"8.7000","7.8875","1.4114","3.6638","59.3903","92.6637"
"8.7600","7.8961","1.4201","3.6862","59.9076","93.4709"
"8.8200","7.9070","1.4309","3.7144","60.6264","94.5924"
"8.8800","7.9178","1.4418","3.7426","61.3258","95.6836"
"8.9400","7.9273","1.4512","3.7671","61.9041","96.5859"
"9.0000","7.9378","1.4618","3.7945","62.5866","97.6508"
"9.0600","7.9466","1.4706","3.8173","63.1174","98.4789"
"9.1200","7.9569","1.4808","3.8440","63.7811","99.5145"
"9.1800","7.9674","1.4914","3.8713","64.4641","100.5801"
"9.2400","7.9767","1.5007","3.8954","65.0295","101.4622"
"9.3000","7.9871","1.5111","3.9225","65.7211","102.5413"
"9.3600","7.9968","1.5208","3.9476","66.3115","103.4625"
"9.4200","8.0068","1.5308","3.9736","66.9486","104.4565"
"9.4800","8.0171","1.5411","4.0003","67.6154","105.4969"
"9.5400","8.0267","1.5507","4.0253","68.2178","106.4369"
"9.6000","8.0367","1.5607","4.0511","68.8655","107.4475"
"9.6600","8.0466","1.5706","4.0769","69.4819","108.4092"
"9.7200","8.0557","1.5796","4.1004","70.0446","109.2871"
"9.7800","8.0660","1.5900","4.1272","70.7239","110.3469"
"9.8400","8.0769","1.6009","4.1556","71.4430","111.4689"
"9.9000","8.0874","1.6113","4.1827","72.1237","112.5310"
"9.9600","8.0981","1.6220","4.2104","72.8091","113.6004"
"10.0200","8.1068","1.6307","4.2331","73.3446","114.4359"
"10.0800","8.1173","1.6412","4.2603","74.0375","115.5171"
"10.1400","8.1276","1.6516","4.2872","74.7023","116.5542"
"10.2000","8.1367","1.6607","4.3107","75.2657","117.4334"
"10.2600","8.1468","1.6707","4.3369","75.9221","118.4574"
"10.3200","8.1556","1.6795","4.3597","76.4684","119.3098"
"10.3800","8.1663","1.6902","4.3875","77.1829","120.4246"
"10.4400","8.1774","1.7014","4.4164","77.9268","121.5852"
"10.5000","8.1866","1.7106","4.4402","78.4944","122.4709"
"10.5600","8.1971","1.7210","4.4674","79.1922","123.5597"
"10.6200","8.2059","1.7299","4.4904","79.7276","124.3949"
"10.6800","8.2161","1.7401","4.5168","80.3904","125.4291"
"10.7400","8.2269","1.7509","4.5450","81.1152","126.5600"
"10.8000","8.2370","1.7610","4.5711","81.7569","127.5612"
"10.8600","8.2484","1.7723","4.6006","82.5299","128.7673"
"10.9200","8.2580","1.7819","4.6255","83.1273","129.6993"
"10.9800","8.2672","1.7912","4.6495","83.7062","130.6027"
"11.0400","8.2770","1.8010","4.6749","84.3449","131.5992"
"11.1000","8.2871","1.8111","4.7012","85.0038","132.6271"
"11.1600","8.2972","1.8212","4.7274","85.6658","133.6601"
"11.2200","8.3070","1.8310","4.7528","86.2890","134.6324"
"11.2800","8.3161","1.8401","4.7764","86.8731","135.5438"
"11.3400","8.3267","1.8506","4.8038","87.5838","136.6526"
"11.4000","8.3370","1.8609","4.8306","88.2526","137.6962"
"11.4600","8.3460","1.8699","4.8540","88.8133","138.5709"
"11.5200","8.3563","1.8803","4.8808","89.4974","139.6383"
"11.5800","8.3655","1.8895","4.9047","90.0771","140.5428"
"11.6400","8.3766","1.9006","4.9334","90.8348","141.7250"
"11.7000","8.3877","1.9117","4.9623","91.5836","142.8933"
"11.7600","8.3972","1.9211","4.9868","92.1801","143.8239"
"11.8200","8.4082","1.9322","5.0156","92.9339","145.0001"
"11.8800","8.4170","1.9409","5.0383","93.4606","145.8218"
"11.9400","8.4271","1.9510","5.0644","94.1261","146.8603"
"12.0000","8.4373","1.9613","5.0911","94.8108","147.9286"
"12.0600","8.4465","1.9705","5.1149","95.3846","148.8237"
"12.1200","8.4563","1.9803","5.1404","96.0182","149.8125"
"12.1800","8.4653","1.9893","5.1637","96.5670","150.6687"
"12.2400","8.4753","1.9993","5.1897","97.2307","151.7042"
"12.3000","8.4865","2.0105","5.2187","97.9924","152.8927"
"12.3600","8.4971","2.0210","5.2462","98.6835","153.9709"
"12.4200","8.5077","2.0316","5.2737","99.3855","155.0663"
"12.4800","8.5165","2.0404","5.2965","99.9185","155.8979"
"12.5400","8.5259","2.0499","5.3211","100.5333","156.8571"
"12.6000","8.5370","2.0609","5.3497","101.2924","158.0415"
"12.6600","8.5474","2.0714","5.3768","101.9753","159.1069"
"12.7200","8.5577","2.0816","5.4034","102.6676","160.1871"
"12.7800","8.5677","2.0916","5.4294","103.3229","161.2096"
"12.8400","8.5773","2.1013","5.4544","103.9558","162.1970"
"12.9000","8.5879","2.1119","5.4819","104.6671","163.3068"
"12.9600","8.5976","2.1216","5.5071","105.2930","164.2833"
"13.0200","8.6066","2.1305","5.5304","105.8665","165.1782"
"13.0800","8.6177","2.1417","5.5593","106.6398","166.3847"
"13.1400","8.6269","2.1508","5.5831","107.2127","167.2786"
"13.2000","8.6366","2.1606","5.6084","107.8571","168.2841"
"13.2600","8.6467","2.1707","5.6347","108.5296","169.3332"
"13.3200","8.6562","2.1802","5.6594","109.1444","170.2925"
"13.3800","8.6673","2.1913","5.6880","109.9063","171.4814"
"13.4400","8.6757","2.1997","5.7099","110.4173","172.2787"
"13.5000","8.6857","2.2096","5.7357","111.0911","173.3298"
"13.5600","8.6967","2.2206","5.7643","111.8580","174.5265"
"13.6200","8.7073","2.2313","5.7919","112.5593","175.6206"
"13.6800","8.7182","2.2422","5.8203","113.3105","176.7926"
"13.7400","8.7268","2.2508","5.8426","113.8332","177.6082"
"13.8000","8.7366","2.2606","5.8679","114.4871","178.6286"
"13.8600","8.7473","2.2713","5.8958","115.2237","179.7777"
"13.9200","8.7573","2.2813","5.9217","115.8833","180.8069"
"13.9800","8.7672","2.2912","5.9474","116.5495","181.8463"
"14.0400","8.7766","2.3006","5.9719","117.1588","182.7970"
"14.1000","8.7864","2.3103","5.9971","117.8160","183.8224"
"14.1600","8.7968","2.3208","6.0243","118.5303","184.9369"
"14.2200","8.8067","2.3307","6.0499","119.1866","185.9608"
"14.2800","8.8161","2.3401","6.0744","119.8121","186.9368"
"14.3400","8.8267","2.3507","6.1019","120.5365","188.0670"
"14.4000","8.8362","2.3601","6.1264","121.1578","189.0365"
"14.4600","8.8467","2.3707","6.1538","121.8856","190.1721"
"14.5200","8.8571","2.3811","6.1808","122.5917","191.2736"
"14.5800","8.8672","2.3911","6.2069","123.2682","192.3292"
"14.6400","8.8783","2.4023","6.2358","124.0404","193.5341"
"14.7000","8.8873","2.4112","6.2591","124.6059","194.4164"
"14.7600","8.8975","2.4214","6.2856","125.3089","195.5132"
"14.8200","8.9081","2.4321","6.3132","126.0490","196.6680"
"14.8800","8.9175","2.4414","6.3375","126.6512","197.6076"
"14.9400","8.9280","2.4519","6.3647","127.3720","198.7321"
"15.0000","8.9360","2.4599","6.3854","127.8448","199.4699"
"15.0600","8.9457","2.4697","6.4108","128.5155","200.5163"
"15.1200","8.9566","2.4806","6.4391","129.2837","201.7148"
"15.1800","8.9666","2.4906","6.4651","129.9502","202.7548"
"15.2400","8.9770","2.5010","6.4920","130.6705","203.8786"
"15.3000","8.9856","2.5096","6.5144","131.1929","204.6937"
"15.3600","8.9959","2.5199","6.5411","131.9197","205.8276"
"15.4200","9.0074","2.5314","6.5709","132.7428","207.1119"
"15.4800","9.0172","2.5411","6.5963","133.3898","208.1214"
"15.5400","9.0272","2.5512","6.6224","134.0816","209.2007"
"15.6000","9.0373","2.5612","6.6485","134.7538","210.2496"
"15.6600","9.0470","2.5710","6.6737","135.4076","211.2696"
"15.7200","9.0569","2.5809","6.6994","136.0774","212.3147"
"15.7800","9.0668","2.5908","6.7252","136.7556","213.3730"
"15.8400","9.0771","2.6010","6.7517","137.4700","214.4875"
"15.9000","9.0876","2.6116","6.7792","138.1913","215.6131"
"15.9600","9.0959","2.6198","6.8005","138.6898","216.3908"
"16.0200","9.1051","2.6291","6.8246","139.2999","217.3426"
"16.0800","9.1157","2.6397","6.8520","140.0356","218.4905"
"16.1400","9.1260","2.6499","6.8787","140.7308","219.5753"
"16.2000","9.1369","2.6608","6.9069","141.4950","220.7675"
"16.2600","9.1455","2.6694","6.9293","142.0275","221.5984"
"16.3200","9.1564","2.6804","6.9577","142.8155","222.8279"
"16.3800","9.1679","2.6918","6.9874","143.6297","224.0982"
"16.4400","9.1776","2.7016","7.0128","144.2668","225.0922"
"16.5000","9.1884","2.7123","7.0406","145.0220","226.2706"
"16.5600","9.1972","2.7212","7.0636","145.5837","227.1470"
"16.6200","9.2076","2.7316","7.0906","146.3108","228.2815"
"16.6800","9.2179","2.7418","7.1172","147.0084","229.3698"
"16.7400","9.2268","2.7507","7.1403","147.5783","230.2590"
"16.8000","9.2367","2.7607","7.1661","148.2745","231.3454"
"16.8600","9.2464","2.7703","7.1912","148.9205","232.3532"
"16.9200","9.2565","2.7804","7.2174","149.6266","233.4550"
"16.9800","9.2671","2.7910","7.2449","150.3744","234.6216"
"17.0400","9.2771","2.8011","7.2711","151.0609","235.6928"
"17.1000","9.2873","2.8113","7.2975","151.7763","236.8090"
"17.1600","9.2968","2.8207","7.3220","152.3833","237.7560"
"17.2200","9.3058","2.8298","7.3455","152.9997","238.7178"
"17.2800","9.3164","2.8404","7.3730","153.7556","239.8972"
"17.3400","9.3272","2.8512","7.4010","154.5199","241.0897"
"17.4000","9.3373","2.8613","7.4273","155.2099","242.1663"
"17.4600","9.3476","2.8716","7.4541","155.9225","243.2781"
"17.5200","9.3566","2.8806","7.4773","156.5160","244.2041"
"17.5800","9.3672","2.8912","7.5048","157.2783","245.3934"
"17.6400","9.3779","2.9019","7.5327","158.0371","246.5774"
"17.7000","9.3873","2.9113","7.5571","158.6660","247.5586"
"17.7600","9.3972","2.9212","7.5828","159.3466","248.6206"
"17.8200","9.4056","2.9296","7.6046","159.8883","249.4657"
"17.8800","9.4164","2.9404","7.6327","160.6792","250.6998"
"17.9400","9.4271","2.9511","7.6604","161.4381","251.8838"
"18.0000","9.4359","2.9599","7.6832","161.9966","252.7552"
"18.0600","9.4465","2.9705","7.7107","162.7721","253.9653"
"18.1200","9.4562","2.9801","7.7357","163.4125","254.9643"
"18.1800","9.4670","2.9909","7.7638","164.1957","256.1863"
"18.2400","9.4776","3.0016","7.7915","164.9559","257.3725"
"18.3000","9.4874","3.0114","7.8169","165.6273","258.4200"
"18.3600","9.4990","3.0230","7.8470","166.4965","259.7761"
"18.4200","9.5079","3.0318","7.8699","167.0410","260.6258"
"18.4800","9.5169","3.0409","7.8935","167.6550","261.5838"
"18.5400","9.5264","3.0503","7.9180","168.3059","262.5993"
"18.6000","9.5364","3.0603","7.9440","169.0096","263.6972"
"18.6600","9.5467","3.0706","7.9707","169.7486","264.8502"
"18.7200","9.5568","3.0808","7.9971","170.4555","265.9532"
"18.7800","9.5662","3.0901","8.0214","171.1027","266.9630"
"18.8400","9.5766","3.1006","8.0485","171.8484","268.1265"
"18.9000","9.5870","3.1110","8.0754","172.5785","269.2656"
"18.9600","9.5964","3.1204","8.0999","173.2286","270.2799"
"19.0200","9.6067","3.1307","8.1266","173.9625","271.4250"
"19.0800","9.6155","3.1394","8.1493","174.5421","272.3293"
"19.1400","9.6263","3.1503","8.1775","175.3498","273.5895"
"19.2000","9.6371","3.1611","8.2055","176.1288","274.8050"
"19.2600","9.6465","3.1704","8.2298","176.7632","275.7947"
"19.3200","9.6578","3.1818","8.2592","177.6187","277.1296"
"19.3800","9.6672","3.1912","8.2836","178.2494","278.1137"
"19.4400","9.6772","3.2012","8.3096","178.9604","279.2230"
"19.5000","9.6874","3.2114","8.3361","179.6938","280.3672"
"19.5600","9.6969","3.2208","8.3606","180.3410","281.3771"
"19.6200","9.7077","3.2317","8.3887","181.1488","282.6375"
"19.6800","9.7165","3.2404","8.4115","181.7136","283.5187"
"19.7400","9.7260","3.2500","8.4362","182.3872","284.5697"
"19.8000","9.7360","3.2600","8.4623","183.1094","285.6965"
"19.8600","9.7462","3.2701","8.4886","183.8226","286.8092"
"19.9200","9.7569","3.2809","8.5164","184.6182","288.0505"
"19.9800","9.7661","3.2900","8.5402","185.2187","288.9875"
"20.0400","9.7751","3.2991","8.5636","185.8407","289.9579"
"20.1000","9.7859","3.3099","8.5918","186.6460","291.2145"
"20.1600","9.7968","3.3207","8.6199","187.4279","292.4344"
"20.2200","9.8074","3.3314","8.6476","188.2096","293.6541"
"20.2800","9.8180","3.3420","8.6751","188.9600","294.8248"
"20.3400","9.8278","3.3517","8.7003","189.6465","295.8960"
"20.4000","9.8382","3.3622","8.7275","190.4032","297.0766"
"20.4600","9.8476","3.3715","8.7518","191.0470","298.0810"
"20.5200","9.8566","3.3806","8.7752","191.6739","299.0592"
"20.5800","9.8673","3.3913","8.8031","192.4686","300.2991"
"20.6400","9.8766","3.4006","8.8272","193.1088","301.2980"
"20.7000","9.8869","3.4109","8.8539","193.8613","302.4721"
"20.7600","9.8968","3.4208","8.8797","194.5922","303.6125"
"20.8200","9.9064","3.4303","8.9044","195.2736","304.6757"
"20.8800","9.9174","3.4414","8.9331","196.1071","305.9760"
"20.9400","9.9261","3.4501","8.9557","196.6776","306.8661"
"21.0000","9.9359","3.4599","8.9812","197.3912","307.9796"
"21.0600","9.9465","3.4704","9.0085","198.1783","309.2076"
"21.1200","9.9571","3.4810","9.0360","198.9604","310.4279"
"21.1800","9.9686","3.4926","9.0661","199.8598","311.8313"
"21.2400","9.9773","3.5012","9.0885","200.4055","312.6826"
"21.3000","9.9868","3.5107","9.1131","201.0840","313.7413"
"21.3600","9.9974","3.5213","9.1406","201.8738","314.9736"
"21.4200","10.0071","3.5311","9.1659","202.5601","316.0443"
"21.4800","10.0168","3.5407","9.1910","203.2644","317.1432"
"21.5400","10.0263","3.5503","9.2157","203.9356","318.1905"
"21.6000","10.0361","3.5601","9.2412","204.6489","319.3034"
"21.6600","10.0471","3.5711","9.2697","205.4861","320.6098"
"21.7200","10.0569","3.5809","9.2952","206.1784","321.6899"
"21.7800","10.0665","3.5905","9.3201","206.8779","322.7812"
"21.8400","10.0771","3.6010","9.3475","207.6614","324.0037"
"21.9000","10.0863","3.6102","9.3714","208.3028","325.0045"
"21.9600","10.0964","3.6204","9.3977","209.0634","326.1911"
"22.0200","10.1071","3.6311","9.4256","209.8793","327.4641"
"22.0800","10.1173","3.6413","9.4521","210.6268","328.6304"
"22.1400","10.1283","3.6522","9.4804","211.4501","329.9151"
"22.2000","10.1368","3.6608","9.5026","212.0228","330.8085"
"22.2600","10.1468","3.6708","9.5286","212.7761","331.9839"
"22.3200","10.1572","3.6811","9.5554","213.5455","333.1843"
"22.3800","10.1668","3.6908","9.5805","214.2327","334.2565"
"22.4400","10.1777","3.7017","9.6087","215.0646","335.5545"
"22.5000","10.1862","3.7102","9.6308","215.6342","336.4433"
"22.5600","10.1964","3.7204","9.6574","216.4185","337.6669"
"22.6200","10.2073","3.7313","9.6855","217.2490","338.9627"
"22.6800","10.2166","3.7406","9.7098","217.8971","339.9740"
"22.7400","10.2266","3.7505","9.7356","218.6467","341.1435"
"22.8000","10.2356","3.7595","9.7590","219.2732","342.1210"
"22.8600","10.2460","3.7700","9.7860","220.0830","343.3844"
"22.9200","10.2568","3.7808","9.8142","220.9156","344.6835"
"22.9800","10.2665","3.7905","9.8393","221.6185","345.7803"
"23.0400","10.2774","3.8014","9.8676","222.4778","347.1210"
"23.1000","10.2881","3.8121","9.8953","223.2749","348.3646"
"23.1600","10.2980","3.8220","9.9211","224.0027","349.5003"
"23.2200","10.3076","3.8315","9.9458","224.6964","350.5826"
"23.2800","10.3170","3.8410","9.9704","225.3788","351.6473"
"23.3400","10.3265","3.8505","9.9949","226.0783","352.7386"
"23.4000","10.3370","3.8610","10.0222","226.8745","353.9810"
"23.4600","10.3458","3.8698","10.0452","227.4972","354.9525"
"23.5200","10.3561","3.8800","10.0717","228.2892","356.1883"
"23.5800","10.3667","3.8907","10.0993","229.1162","357.4786"
"23.6400","10.3766","3.9006","10.1250","229.8503","358.6240"
"23.7000","10.3875","3.9115","10.1534","230.7032","359.9546"
"23.7600","10.3960","3.9200","10.1755","231.2774","360.8505"
"23.8200","10.4067","3.9307","10.2032","232.1163","362.1595"
"23.8800","10.4182","3.9421","10.2329","233.0306","363.5860"
"23.9400","10.4278","3.9517","10.2579","233.7191","364.6603"
"24.0000","10.4379","3.9619","10.2842","234.4829","365.8520"
"24.0600","10.4463","3.9702","10.3059","235.0434","366.7264"
"24.1200","10.4573","3.9812","10.3344","235.9238","368.1001"
"24.1800","10.4678","3.9918","10.3618","236.7345","369.3651"
"24.2400","10.4766","4.0005","10.3845","237.3384","370.3072"
"24.3000","10.4873","4.0113","10.4124","238.2086","371.6649"
"24.3600","10.4969","4.0209","10.4374","238.9001","372.7439"
"24.4200","10.5069","4.0309","10.4633","239.6606","373.9305"
"24.4800","10.5168","4.0407","10.4889","240.4022","375.0875"
"24.5400","10.5263","4.0503","10.5137","241.1163","376.2018"
"24.6000","10.5364","4.0604","10.5399","241.8980","377.4214"
"24.6600","10.5461","4.0701","10.5651","242.5992","378.5155"
"24.7200","10.5546","4.0786","10.5872","243.1875","379.4333"
"24.7800","10.5649","4.0889","10.6139","243.9902","380.6857"
"24.8400","10.5760","4.0999","10.6425","244.8709","382.0598"
"24.9000","10.5873","4.1112","10.6719","245.7688","383.4607"
"24.9600","10.5983","4.1223","10.7005","246.6672","384.8625"
"25.0200","10.6076","4.1316","10.7247","247.3505","385.9287"
"25.0800","10.6177","4.1417","10.7509","248.1110","387.1151"
"25.1400","10.6278","4.1518","10.7771","248.8745","388.3064"
"25.2000","10.6371","4.1610","10.8011","249.5546","389.3675"
"25.2600","10.6475","4.1715","10.8283","250.3832","390.6604"
"25.3200","10.6561","4.1801","10.8506","250.9790","391.5900"
"25.3800","10.6668","4.1908","10.8784","251.8411","392.9351"
"25.4400","10.6775","4.2014","10.9060","252.6836","394.2495"
"25.5000","10.6865","4.2104","10.9294","253.3277","395.2545"
"25.5600","10.6972","4.2211","10.9572","254.2050","396.6233"
"25.6200","10.7065","4.2305","10.9814","254.8731","397.6658"
"25.6800","10.7170","4.2409","11.0086","255.7118","398.9744"
"25.7400","10.7271","4.2511","11.0350","256.4931","400.1934"
"25.8000","10.7366","4.2605","11.0595","257.1938","401.2866"
"25.8600","10.7479","4.2718","11.0887","258.1326","402.7514"
"25.9200","10.7579","4.2818","11.1147","258.8811","403.9193"
"25.9800","10.7678","4.2918","11.1406","259.6694","405.1491"
"26.0400","10.7780","4.3020","11.1671","260.4688","406.3965"
"26.1000","10.7878","4.3117","11.1923","261.1957","407.5307"
"26.1600","10.7976","4.3216","11.2179","261.9647","408.7304"
"26.2200","10.8071","4.3311","11.2425","262.6754","409.8393"
"26.2800","10.8161","4.3401","11.2659","263.3617","410.9101"
"26.3400","10.8265","4.3504","11.2928","264.1943","412.2092"
"26.4000","10.8365","4.3604","11.3188","264.9696","413.4188"
"26.4600","10.8456","4.3696","11.3425","265.6494","414.4796"
"26.5200","10.8561","4.3801","11.3697","266.4916","415.7935"
"26.5800","10.8651","4.3890","11.3930","267.1548","416.8282"
"26.6400","10.8766","4.4005","11.4228","268.1361","418.3593"
"26.7000","10.8878","4.4118","11.4520","269.0582","419.7980"
"26.7600","10.8970","4.4210","11.4759","269.7330","420.8510"
"26.8200","10.9080","4.4319","11.5043","270.6413","422.2681"
"26.8800","10.9174","4.4413","11.5287","271.3414","423.3604"
"26.9400","10.9278","4.4517","11.5558","272.1865","424.6790"
"27.0000","10.9375","4.4615","11.5810","272.9353","425.8473"
"27.0600","10.9463","4.4703","11.6039","273.5724","426.8413"
"27.1200","10.9573","4.4812","11.6323","274.4929","428.2775"
"27.1800","10.9665","4.4905","11.6563","275.1640","429.3247"
"27.2400","10.9761","4.5000","11.6811","275.9180","430.5010"
"27.3000","10.9861","4.5101","11.7072","276.7189","431.7507"
"27.3600","10.9965","4.5205","11.7342","277.5642","433.0695"
"27.4200","11.0073","4.5312","11.7622","278.4546","434.4588"
"27.4800","11.0166","4.5405","11.7863","279.1374","435.5242"
"27.5400","11.0260","4.5500","11.8108","279.8890","436.6968"
"27.6000","11.0370","4.5610","11.8393","280.8114","438.1359"
"27.6600","11.0475","4.5714","11.8665","281.6530","439.4491"
"27.7200","11.0578","4.5817","11.8932","282.4857","440.7483"
"27.7800","11.0676","4.5915","11.9186","283.2331","441.9145"
"27.8400","11.0770","4.6010","11.9432","283.9739","443.0703"
"27.9000","11.0878","4.6118","11.9712","284.8656","444.4616"
"27.9600","11.0977","4.6217","11.9969","285.6379","445.6665"
"28.0200","11.1065","4.6305","12.0198","286.2942","446.6905"
"28.0800","11.1164","4.6403","12.0454","287.0669","447.8962"
"28.1400","11.1251","4.6491","12.0681","287.7017","448.8865"
"28.2000","11.1356","4.6595","12.0952","288.5579","450.2225"
"28.2600","11.1461","4.6701","12.1226","289.4260","451.5769"
"28.3200","11.1560","4.6800","12.1483","290.2040","452.7907"
"28.3800","11.1677","4.6917","12.1786","291.2125","454.3643"
"28.4400","11.1765","4.7004","12.2013","291.8379","455.3400"
"28.5000","11.1866","4.7106","12.2276","292.6693","456.6373"
"28.5600","11.1973","4.7213","12.2555","293.6594","458.1821"
"28.6200","11.2075","4.7315","12.2820","294.4585","459.4289"
"28.6800","11.2184","4.7424","12.3103","295.3800","460.8667"
"28.7400","11.2270","4.7510","12.3326","295.9765","461.7974"
"28.8000","11.2371","4.7610","12.3586","296.8045","463.0891"
"28.8600","11.2474","4.7714","12.3855","297.6434","464.3981"
"28.9200","11.2570","4.7809","12.4103","298.3876","465.5593"
"28.9800","11.2674","4.7913","12.4373","299.2755","466.9446"
"29.0400","11.2767","4.8006","12.4614","299.9780","468.0406"
"29.1000","11.2866","4.8105","12.4871","300.8001","469.3233"
"29.1600","11.2971","4.8211","12.5145","301.6787","470.6941"
"29.2200","11.3068","4.8308","12.5397","302.4433","471.8871"
"29.2800","11.3159","4.8399","12.5634","303.1657","473.0143"
"29.3400","11.3268","4.8508","12.5917","304.1019","474.4750"
"29.4000","11.3364","4.8603","12.6164","304.8585","475.6555"
"29.4600","11.3471","4.8711","12.6443","305.7705","477.0783"
"29.5200","11.3575","4.8815","12.6713","306.6338","478.4254"
"29.5800","11.3678","4.8918","12.6981","307.4946","479.7684"
"29.6400","11.3790","4.9029","12.7269","308.4324","481.2316"
"29.7000","11.3872","4.9112","12.7484","309.0221","482.1517"
"29.7600","11.3967","4.9207","12.7731","309.7848","483.3417"
"29.8200","11.4068","4.9308","12.7993","310.6348","484.6679"
"29.8800","11.4170","4.9410","12.8258","311.4871","485.9978"
"29.9400","11.4279","4.9518","12.8539","312.4084","487.4352"
"30.0000","11.4361","4.9601","12.8753","313.0024","488.3619"
"30.0600","11.4462","4.9702","12.9016","313.8623","489.7037"
"30.1200","11.4567","4.9807","12.9288","314.7532","491.0937"
"30.1800","11.4664","4.9904","12.9540","315.5228","492.2945"
"30.2400","11.4767","5.0006","12.9806","316.4041","493.6695"
"30.3000","11.4859","5.0098","13.0045","317.1199","494.7863"
"30.3600","11.4964","5.0204","13.0319","318.0469","496.2326"
"30.4200","11.5074","5.0314","13.0604","318.9911","497.7058"
"30.4800","11.5169","5.0409","13.0850","319.7374","498.8703"
"30.5400","11.5268","5.0508","13.1108","320.5731","500.1742"
"30.6000","11.5372","5.0611","13.1376","321.4454","501.5352"
"30.6600","11.5471","5.0711","13.1635","322.2702","502.8221"
"30.7200","11.5571","5.0811","13.1894","323.1007","504.1179"
"30.7800","11.5670","5.0909","13.2149","323.9129","505.3851"
"30.8400","11.5772","5.1011","13.2414","324.7776","506.7343"
"30.9000","11.5874","5.1113","13.2679","325.6234","508.0539"
"30.9600","11.5962","5.1202","13.2910","326.3187","509.1388"
"31.0200","11.6062","5.1301","13.3167","327.1539","510.4419"
"31.0800","11.6164","5.1404","13.3433","328.0282","511.8059"
"31.1400","11.6261","5.1501","13.3685","328.8266","513.0517"
"31.2000","11.6370","5.1610","13.3968","329.7804","514.5399"
"31.2600","11.6457","5.1697","13.4194","330.4482","515.5817"
"31.3200","11.6569","5.1809","13.4485","331.4782","517.1888"
"31.3800","11.6679","5.1918","13.4769","332.4352","518.6820"
"31.4400","11.6773","5.2013","13.5014","333.1812","519.8459"
"31.5000","11.6876","5.2115","13.5280","334.0509","521.2029"
"31.5600","11.6957","5.2197","13.5492","334.6249","522.0986"
"31.6200","11.7063","5.2302","13.5765","335.5501","523.5421"
"31.6800","11.7172","5.2412","13.6051","336.5071","525.0352"
"31.7400","11.7269","5.2508","13.6300","337.2799","526.2410"
"31.8000","11.7373","5.2612","13.6571","338.1928","527.6653"
"31.8600","11.7468","5.2708","13.6819","338.9614","528.8645"
"31.9200","11.7570","5.2810","13.7083","339.8326","530.2239"
"31.9800","11.7670","5.2910","13.7343","340.6960","531.5710"
"32.0400","11.7765","5.3005","13.7589","341.4769","532.7893"
"32.1000","11.7868","5.3107","13.7855","342.3919","534.2170"
"32.1600","11.7968","5.3207","13.8115","343.2221","535.5123"
"32.2200","11.8059","5.3298","13.8351","343.9702","536.6796"
"32.2800","11.8165","5.3404","13.8626","344.9248","538.1689"
"32.3400","11.8269","5.3508","13.8896","345.8326","539.5854"
"32.4000","11.8374","5.3613","13.9168","346.7638","541.0381"
"32.4600","11.8480","5.3720","13.9445","347.6929","542.4879"
"32.5200","11.8569","5.3809","13.9677","348.4103","543.6071"
"32.5800","11.8676","5.3915","13.9953","349.3670","545.0998"
"32.6400","11.8778","5.4017","14.0218","350.2490","546.4760"
"32.7000","11.8872","5.4111","14.0461","351.0301","547.6946"
"32.7600","11.8973","5.4213","14.0726","351.9225","549.0872"
"32.8200","11.9063","5.4302","14.0957","352.6443","550.2133"
"32.8800","11.9172","5.4412","14.1242","353.6554","551.7908"
"32.9400","11.9277","5.4517","14.1514","354.5750","553.2257"
"33.0000","11.9367","5.4607","14.1748","355.2974","554.3527"
"33.0600","11.9472","5.4712","14.2021","356.2399","555.8234"
"33.1200","11.9559","5.4799","14.2246","356.9136","556.8745"
"33.1800","11.9659","5.4898","14.2504","357.7914","558.2440"
"33.2400","11.9767","5.5007","14.2786","358.8006","559.8187"
"33.3000","11.9872","5.5112","14.3059","359.7425","561.2882"
"33.3600","11.9986","5.5226","14.3354","360.8071","562.9492"
"33.4200","12.0075","5.5314","14.3584","361.4910","564.0164"
"33.4800","12.0173","5.5412","14.3839","362.3506","565.3575"
"33.5400","12.0270","5.5510","14.4092","363.1878","566.6637"
"33.6000","12.0368","5.5607","14.4345","364.0198","567.9619"
"33.6600","12.0470","5.5710","14.4611","364.9517","569.4160"
"33.7200","12.0567","5.5807","14.4862","365.7764","570.7027"
"33.7800","12.0658","5.5898","14.5099","366.5688","571.9390"
"33.8400","12.0766","5.6006","14.5380","367.5801","573.5168"
"33.9000","12.0873","5.6113","14.5657","368.5491","575.0288"
"33.9600","12.0968","5.6208","14.5904","369.3588","576.2921"
"34.0200","12.1065","5.6305","14.6156","370.1936","577.5946"
"34.0800","12.1153","5.6392","14.6382","370.9080","578.7092"
"34.1400","12.1262","5.6502","14.6667","371.9409","580.3208"
"34.2000","12.1369","5.6609","14.6944","372.9073","581.8287"
"34.2600","12.1463","5.6703","14.7188","373.7037","583.0712"
"34.3200","12.1578","5.6818","14.7488","374.8186","584.8107"
"34.3800","12.1672","5.6912","14.7730","375.5889","586.0126"
"34.4400","12.1778","5.7018","14.8006","376.5667","587.5383"
"34.5000","12.1875","5.7115","14.8257","377.3989","588.8367"
"34.5600","12.1966","5.7206","14.8494","378.1629","590.0286"
"34.6200","12.2078","5.7317","14.8784","379.2431","591.7141"
"34.6800","12.2166","5.7405","14.9012","379.9346","592.7929"
"34.7400","12.2261","5.7501","14.9260","380.7933","594.1328"
"34.8000","12.2360","5.7600","14.9517","381.6896","595.5312"
"34.8600","12.2461","5.7701","14.9778","382.5971","596.9471"
"34.9200","12.2565","5.7805","15.0049","383.5686","598.4629"
"34.9800","12.2662","5.7902","15.0301","384.4146","599.7829"
"35.0400","12.2762","5.8002","15.0560","385.3336","601.2167"
"35.1000","12.2872","5.8112","15.0847","386.4130","602.9009"
"35.1600","12.2976","5.8215","15.1115","387.3401","604.3474"
"35.2200","12.3076","5.8316","15.1375","388.2452","605.7595"
"35.2800","12.3173","5.8412","15.1626","389.0798","607.0617"
"35.3400","12.3267","5.8507","15.1872","389.9241","608.3790"
"35.4000","12.3379","5.8618","15.2161","390.9921","610.0455"
"35.4600","12.3477","5.8717","15.2416","391.8591","611.3981"
"35.5200","12.3565","5.8805","15.2644","392.5853","612.5312"
"35.5800","12.3671","5.8911","15.2919","393.5911","614.1005"
"35.6400","12.3766","5.9006","15.3167","394.4262","615.4035"
"35.7000","12.3872","5.9111","15.3441","395.4161","616.9479"
"35.7600","12.3968","5.9208","15.3691","396.2666","618.2750"
"35.8200","12.4058","5.9298","15.3925","397.0279","619.4628"
"35.8800","12.4173","5.9412","15.4222","398.1730","621.2494"
"35.9400","12.4262","5.9501","15.4453","398.8949","622.3758"
"36.0000","12.4361","5.9601","15.4711","399.8250","623.8269"
"36.0600","12.4465","5.9705","15.4981","400.8011","625.3499"
"36.1200","12.4566","5.9805","15.5242","401.7118","626.7709"
"36.1800","12.4680","5.9920","15.5540","402.8579","628.5590"
"36.2400","12.4767","6.0007","15.5765","403.5330","629.6124"
"36.3000","12.4862","6.0102","15.6012","404.3950","630.9573"
"36.3600","12.4964","6.0203","15.6275","405.3286","632.4139"
"36.4200","12.5066","6.0306","15.6541","406.2722","633.8862"
"36.4800","12.5175","6.0414","15.6822","407.3189","635.5193"
"36.5400","12.5269","6.0508","15.7067","408.1225","636.7731"
"36.6000","12.5366","6.0606","15.7319","409.0261","638.1830"
"36.6600","12.5471","6.0711","15.7592","410.0199","639.7336"
"36.7200","12.5570","6.0809","15.7848","410.9235","641.1434"
"36.7800","12.5663","6.0903","15.8090","411.7535","642.4384"
"36.8400","12.5767","6.1007","15.8360","412.7409","643.9791"
"36.9000","12.5862","6.1101","15.8606","413.6038","645.3253"
"36.9600","12.5975","6.1215","15.8901","414.7500","647.1138"
"37.0200","12.6079","6.1318","15.9170","415.7200","648.6271"
"37.0800","12.6178","6.1418","15.9427","416.6285","650.0447"
"37.1400","12.6285","6.1525","15.9705","417.6427","651.6271"
"37.2000","12.6371","6.1611","15.9929","418.3646","652.7534"
"37.2600","12.6469","6.1709","16.0182","419.2811","654.1833"
"37.3200","12.6571","6.1811","16.0447","420.2705","655.7271"
"37.3800","12.6669","6.1908","16.0701","421.1626","657.1190"
"37.4400","12.6776","6.2016","16.0979","422.2103","658.7537"
"37.5000","12.6862","6.2102","16.1203","422.9197","659.8604"
"37.5600","12.6964","6.2204","16.1468","423.9159","661.4147"
"37.6200","12.7069","6.2309","16.1741","424.9355","663.0056"
"37.6800","12.7165","6.2405","16.1989","425.7969","664.3497"
"37.7400","12.7269","6.2508","16.2258","426.8209","665.9473"
"37.8000","12.7354","6.2594","16.2481","427.5270","667.0490"
"37.8600","12.7459","6.2698","16.2751","428.5807","668.6930"
"37.9200","12.7570","6.2809","16.3039","429.6840","670.4146"
"37.9800","12.7667","6.2906","16.3292","430.5715","671.7992"
"38.0400","12.7772","6.3012","16.3565","431.6252","673.4433"
"38.1000","12.7877","6.3117","16.3838","432.6134","674.9850"
"38.1600","12.7977","6.3217","16.4098","433.5741","676.4839"
"38.2200","12.8078","6.3317","16.4358","434.5236","677.9654"
"38.2800","12.8171","6.3410","16.4600","435.3626","679.2745"
"38.3400","12.8267","6.3507","16.4850","436.2762","680.6999"
"38.4000","12.8370","6.3609","16.5116","437.2457","682.2126"
"38.4600","12.8459","6.3699","16.5349","438.0485","683.4651"
"38.5200","12.8562","6.3802","16.5616","439.0667","685.0539"
"38.5800","12.8667","6.3907","16.5888","440.0972","686.6616"
"38.6400","12.8767","6.4006","16.6146","441.0363","688.1269"
"38.7000","12.8874","6.4114","16.6426","442.0998","689.7862"
"38.7600","12.8958","6.4198","16.6643","442.7953","690.8713"
"38.8200","12.9067","6.4306","16.6925","443.9172","692.6218"
"38.8800","12.9175","6.4415","16.7208","445.0032","694.3163"
"38.9400","12.9269","6.4509","16.7452","445.8488","695.6356"
"39.0000","12.9378","6.4618","16.7734","446.9691","697.3835"
"39.0600","12.9468","6.4708","16.7968","447.7608","698.6188"
"39.1200","12.9576","6.4816","16.8248","448.8589","700.3321"
"39.1800","12.9677","6.4917","16.8510","449.8309","701.8488"
"39.2400","12.9767","6.5007","16.8744","450.6403","703.1115"
"39.3000","12.9871","6.5111","16.9014","451.7027","704.7692"
"39.3600","12.9969","6.5209","16.9268","452.6113","706.1868"
"39.4200","13.0069","6.5309","16.9528","453.5895","707.7130"
"39.4800","13.0167","6.5407","16.9782","454.5304","709.1812"
"39.5400","13.0262","6.5502","17.0029","455.4282","710.5818"
"39.6000","13.0364","6.5604","17.0293","456.4580","712.1887"
"39.6600","13.0459","6.5699","17.0540","457.3186","713.5313"
"39.7200","13.0547","6.5787","17.0769","458.1222","714.7852"
"39.7800","13.0653","6.5893","17.1043","459.1981","716.4639"
"39.8400","13.0764","6.6004","17.1332","460.3654","718.2852"
"39.9000","13.0877","6.6117","17.1626","461.5411","720.1195"
"39.9600","13.0984","6.6224","17.1903","462.5876","721.7523"
"40.0200","13.1071","6.6311","17.2129","463.3789","722.9869"
"40.0800","13.1179","6.6419","17.2409","464.4880","724.7175"
"40.1400","13.1281","6.6521","17.2673","465.4801","726.2653"
"40.2000","13.1371","6.6610","17.2906","466.3060","727.5540"
"40.2600","13.1470","6.6710","17.3165","467.2824","729.0774"
"40.3200","13.1554","6.6793","17.3381","468.0033","730.2021"
"40.3800","13.1662","6.6902","17.3663","469.1637","732.0126"
"40.4400","13.1768","6.7008","17.3939","470.2372","733.6876"
"40.5000","13.1864","6.7103","17.4186","471.1536","735.1174"
"40.5600","13.1976","6.7215","17.4476","472.3616","737.0022"
"40.6200","13.2064","6.7304","17.4706","473.1224","738.1892"
"40.6800","13.2164","6.7403","17.4965","474.1407","739.7780"
"40.7400","13.2266","6.7506","17.5232","475.1903","741.4156"
"40.8000","13.2366","6.7606","17.5490","476.1770","742.9552"
"40.8600","13.2481","6.7720","17.5788","477.4194","744.8936"
"40.9200","13.2574","6.7814","17.6030","478.2638","746.2111"
"40.9800","13.2673","6.7913","17.6287","479.2770","747.7919"
"41.0400","13.2776","6.8016","17.6555","480.3300","749.4349"
"41.1000","13.2872","6.8112","17.6803","481.2392","750.8534"
"41.1600","13.2971","6.8210","17.7060","482.2500","752.4305"
"41.2200","13.3068","6.8308","17.7313","483.2051","753.9207"
"41.2800","13.3161","6.8401","17.7553","484.1143","755.3393"
"41.3400","13.3267","6.8507","17.7828","485.2190","757.0629"
"41.4000","13.3370","6.8610","17.8097","486.2691","758.7013"
"41.4600","13.3462","6.8702","17.8335","487.1535","760.0813"
"41.5200","13.3563","6.8803","17.8598","488.1916","761.7010"
"41.5800","13.3652","6.8892","17.8829","489.0416","763.0272"
"41.6400","13.3768","6.9008","17.9129","490.3275","765.0335"
"41.7000","13.3876","6.9116","17.9410","491.4635","766.8059"
"41.7600","13.3967","6.9206","17.9645","492.3136","768.1323"
"41.8200","13.4078","6.9317","17.9933","493.5301","770.0303"
"41.8800","13.4174","6.9414","18.0184","494.4758","771.5058"
"41.9400","13.4279","6.9519","18.0456","495.5737","773.2189"
"42.0000","13.4373","6.9612","18.0699","496.4850","774.6407"
"42.0600","13.4465","6.9705","18.0939","497.3907","776.0539"
"42.1200","13.4576","6.9815","18.1225","498.6010","777.9423"
"42.1800","13.4663","6.9903","18.1454","499.3993","779.1878"
"42.2400","13.4761","7.0000","18.1706","500.4113","780.7667"
"42.3000","13.4861","7.0101","18.1967","501.4637","782.4086"
"42.3600","13.4964","7.0203","18.2233","502.5338","784.0783"
"42.4200","13.5071","7.0311","18.2511","503.6998","785.8976"
"42.4800","13.5161","7.0401","18.2746","504.5409","787.2098"
"42.5400","13.5256","7.0496","18.2993","505.5246","788.7448"
"42.6000","13.5370","7.0610","18.3289","506.8144","790.7571"
"42.6600","13.5475","7.0715","18.3561","507.9017","792.4536"
"42.7200","13.5578","7.0817","18.3827","509.0004","794.1679"
"42.7800","13.5675","7.0915","18.4080","509.9714","795.6829"
"42.8400","13.5775","7.1015","18.4339","511.0379","797.3470"
"42.9000","13.5888","7.1127","18.4631","512.2867","799.2952"
"42.9600","13.5983","7.1222","18.4878","513.2127","800.7401"
"43.0200","13.6069","7.1308","18.5102","514.0265","802.0098"
"43.0800","13.6169","7.1409","18.5362","515.1041","803.6911"
"43.1400","13.6259","7.1498","18.5595","515.9822","805.0613"
"43.2000","13.6364","7.1603","18.5867","517.1286","806.8500"
"43.2600","13.6460","7.1699","18.6116","518.1048","808.3730"
"43.3200","13.6547","7.1786","18.6342","518.9207","809.6461"
"43.3800","13.6657","7.1897","18.6628","520.1835","811.6163"
"43.4400","13.6754","7.1994","18.6881","521.1632","813.1448"
"43.5000","13.6861","7.2101","18.7159","522.3572","815.0078"
"43.5600","13.6969","7.2209","18.7439","523.5479","816.8657"
"43.6200","13.7070","7.2310","18.7701","524.5901","818.4918"
"43.6800","13.7185","7.2424","18.7998","526.0476","820.7659"
"43.7400","13.7273","7.2513","18.8228","526.8523","822.0212"
"43.8000","13.7376","7.2616","18.8495","527.9716","823.7677"
"43.8600","13.7476","7.2716","18.8754","529.0113","825.3899"
"43.9200","13.7569","7.2809","18.8996","529.9399","826.8387"
"43.9800","13.7667","7.2907","18.9251","530.9988","828.4908"
"44.0400","13.7761","7.3001","18.9495","531.9408","829.9606"
"44.1000","13.7860","7.3100","18.9751","533.0147","831.6361"
"44.1600","13.7971","7.3211","19.0039","534.2835","833.6157"
"44.2200","13.8066","7.3306","19.0287","535.2513","835.1257"
"44.2800","13.8157","7.3396","19.0521","536.1673","836.5551"
"44.3400","13.8264","7.3504","19.0800","537.3828","838.4515"
"44.4000","13.8359","7.3599","19.1047","538.3692","839.9906"
"44.4600","13.8469","7.3708","19.1331","539.6261","841.9515"
"44.5200","13.8570","7.3810","19.1594","540.7124","843.6465"
"44.5800","13.8670","7.3910","19.1855","541.8019","845.3464"
"44.6400","13.8787","7.4027","19.2157","543.1650","847.4731"
"44.7000","13.8878","7.4118","19.2394","544.0698","848.8849"
"44.7600","13.8977","7.4217","19.2651","545.1406","850.5557"
"44.8200","13.9077","7.4317","19.2911","546.2343","852.2620"
"44.8800","13.9170","7.4410","19.3152","547.1727","853.7263"
"44.9400","13.9275","7.4514","19.3423","548.3525","855.5671"
"45.0000","13.9355","7.4595","19.3632","549.0875","856.7138"
"45.0600","13.9457","7.4697","19.3898","550.2658","858.5522"
"45.1200","13.9568","7.4807","19.4183","551.5566","860.5662"
"45.1800","13.9666","7.4906","19.4440","552.6183","862.2227"
"45.2400","13.9770","7.5009","19.4708","553.7916","864.0533"
"45.3000","13.9858","7.5098","19.4938","554.6640","865.4146"
"45.3600","13.9963","7.5202","19.5209","555.9022","867.3464"
"45.4200","14.0072","7.5312","19.5494","557.1693","869.3234"
"45.4800","14.0167","7.5406","19.5739","558.1549","870.8613"
"45.5400","14.0267","7.5507","19.5999","559.2965","872.6425"
"45.6000","14.0375","7.5615","19.6280","560.5282","874.5641"
"45.6600","14.0476","7.5715","19.6541","561.6426","876.3030"
"45.7200","14.0572","7.5812","19.6791","562.6643","877.8969"
"45.7800","14.0666","7.5906","19.7036","563.6753","879.4744"
"45.8400","14.0764","7.6003","19.7288","564.7446","881.1428"
"45.9000","14.0872","7.6112","19.7569","565.9971","883.0969"
"45.9600","14.0966","7.6206","19.7815","567.0192","884.6918"
"46.0200","14.1069","7.6309","19.8081","568.1860","886.5122"
"46.0800","14.1166","7.6406","19.8334","569.2513","888.1743"
"46.1400","14.1259","7.6498","19.8573","570.2139","889.6762"
"46.2000","14.1363","7.6602","19.8843","571.4136","891.5482"
"46.2600","14.1448","7.6688","19.9065","572.2507","892.8541"
"46.3200","14.1561","7.6801","19.9359","573.6738","895.0746"
"46.3800","14.1678","7.6917","19.9661","575.0928","897.2885"
"46.4400","14.1776","7.7016","19.9917","576.1704","898.9698"
"46.4580","14.1809","7.7048","20.0001","576.5576","899.5741"