File: data/instron_tests/clean_data/clean_250106_metamaterial_foams_3_1.csv
Time,Displacement,Compressive displacement,Compressive strain (Displacement),Compressive stress,Force
(s),(mm),(mm),(%),(kPa),(N)
"0.0000","0.0702","-0.0099","-0.0066","-0.0222","-0.0832"
"0.0400","0.0707","-0.0094","-0.0063","-0.0175","-0.0655"
"0.0800","0.0737","-0.0064","-0.0042","0.0067","0.0250"
"0.1200","0.0851","0.0050","0.0034","0.1141","0.4280"
"0.1600","0.1056","0.0255","0.0170","0.3017","1.1314"
"0.2000","0.1259","0.0458","0.0305","0.4803","1.8012"
"0.2400","0.1459","0.0658","0.0439","0.6474","2.4276"
"0.2800","0.1661","0.0861","0.0574","0.8174","3.0653"
"0.3200","0.1856","0.1055","0.0704","0.9734","3.6502"
"0.3600","0.2043","0.1242","0.0828","1.1221","4.2081"
"0.4000","0.2245","0.1444","0.0963","1.2843","4.8161"
"0.4400","0.2446","0.1645","0.1097","1.4445","5.4169"
"0.4800","0.2651","0.1850","0.1234","1.6067","6.0252"
"0.5200","0.2863","0.2062","0.1375","1.7730","6.6489"
"0.5600","0.3058","0.2257","0.1505","1.9189","7.1958"
"0.6000","0.3255","0.2454","0.1637","2.0705","7.7645"
"0.6400","0.3452","0.2651","0.1768","2.2205","8.3269"
"0.6800","0.3649","0.2848","0.1900","2.3711","8.8915"
"0.7200","0.3850","0.3049","0.2034","2.5228","9.4604"
"0.7600","0.4039","0.3238","0.2160","2.6643","9.9913"
"0.8000","0.4239","0.3438","0.2294","2.8198","10.5741"
"0.8400","0.4451","0.3650","0.2435","2.9847","11.1926"
"0.8800","0.4653","0.3852","0.2570","3.1364","11.7615"
"0.9200","0.4855","0.4054","0.2704","3.2892","12.3346"
"0.9600","0.5049","0.4248","0.2834","3.4336","12.8760"
"1.0000","0.5243","0.4442","0.2963","3.5810","13.4289"
"1.0400","0.5446","0.4645","0.3098","3.7352","14.0070"
"1.0800","0.5643","0.4842","0.3230","3.8841","14.5654"
"1.1200","0.5858","0.5057","0.3373","4.0534","15.2004"
"1.1600","0.6064","0.5263","0.3511","4.2112","15.7920"
"1.2000","0.6258","0.5457","0.3640","4.3561","16.3355"
"1.2400","0.6453","0.5652","0.3770","4.5043","16.8913"
"1.2800","0.6646","0.5845","0.3899","4.6520","17.4450"
"1.3200","0.6847","0.6046","0.4033","4.8088","18.0329"
"1.3600","0.7047","0.6246","0.4166","4.9618","18.6067"
"1.4000","0.7238","0.6437","0.4293","5.1056","19.1460"
"1.4400","0.7447","0.6646","0.4433","5.2696","19.7609"
"1.4800","0.7653","0.6852","0.4571","5.4300","20.3624"
"1.5200","0.7854","0.7053","0.4705","5.5847","20.9426"
"1.5600","0.8047","0.7246","0.4833","5.7299","21.4871"
"1.6000","0.8239","0.7438","0.4961","5.8745","22.0293"
"1.6400","0.8440","0.7639","0.5095","6.0313","22.6174"
"1.6800","0.8643","0.7842","0.5231","6.1904","23.2141"
"1.7200","0.8845","0.8044","0.5366","6.3489","23.8085"
"1.7600","0.9057","0.8256","0.5507","6.5238","24.4642"
"1.8000","0.9258","0.8457","0.5641","6.6781","25.0429"
"1.8400","0.9459","0.8658","0.5775","6.8363","25.6361"
"1.8800","0.9659","0.8858","0.5909","6.9918","26.2194"
"1.9200","0.9849","0.9048","0.6035","7.1365","26.7620"
"1.9600","1.0046","0.9245","0.6167","7.2888","27.3331"
"2.0000","1.0235","0.9434","0.6293","7.4340","27.8775"
"2.0400","1.0434","0.9633","0.6426","7.5921","28.4704"
"2.0800","1.0653","0.9852","0.6572","7.7700","29.1374"
"2.1200","1.0859","1.0058","0.6709","7.9304","29.7390"
"2.1600","1.1054","1.0253","0.6839","8.0808","30.3029"
"2.2000","1.1246","1.0445","0.6967","8.2265","30.8494"
"2.2400","1.1439","1.0638","0.7096","8.3789","31.4211"
"2.2800","1.1649","1.0848","0.7236","8.5434","32.0377"
"2.3200","1.1846","1.1045","0.7368","8.6963","32.6113"
"2.3600","1.2051","1.1250","0.7504","8.8603","33.2260"
"2.4000","1.2257","1.1456","0.7641","9.0231","33.8367"
"2.4400","1.2454","1.1653","0.7773","9.1755","34.4081"
"2.4800","1.2655","1.1854","0.7907","9.3333","35.0000"
"2.5200","1.2850","1.2049","0.8037","9.4851","35.5693"
"2.5600","1.3046","1.2245","0.8168","9.6391","36.1468"
"2.6000","1.3248","1.2447","0.8303","9.8015","36.7555"
"2.6400","1.3435","1.2634","0.8427","9.9414","37.2802"
"2.6800","1.3642","1.2841","0.8565","10.1074","37.9027"
"2.7200","1.3853","1.3052","0.8706","10.2776","38.5410"
"2.7600","1.4052","1.3251","0.8839","10.4312","39.1172"
"2.8000","1.4250","1.3449","0.8971","10.5837","39.6887"
"2.8400","1.4443","1.3642","0.9100","10.7340","40.2523"
"2.8800","1.4644","1.3843","0.9234","10.8942","40.8533"
"2.9200","1.4847","1.4046","0.9369","11.0542","41.4534"
"2.9600","1.5041","1.4240","0.9499","11.2039","42.0146"
"3.0000","1.5250","1.4449","0.9638","11.3752","42.6569"
"3.0400","1.5459","1.4658","0.9777","11.5465","43.2993"
"3.0800","1.5657","1.4856","0.9910","11.7016","43.8811"
"3.1200","1.5857","1.5056","1.0043","11.8585","44.4694"
"3.1600","1.6045","1.5244","1.0168","12.0033","45.0124"
"3.2000","1.6244","1.5443","1.0301","12.1630","45.6111"
"3.2400","1.6440","1.5640","1.0432","12.3178","46.1917"
"3.2800","1.6639","1.5838","1.0564","12.4744","46.7788"
"3.3200","1.6848","1.6047","1.0704","12.6420","47.4074"
"3.3600","1.7052","1.6251","1.0840","12.8065","48.0244"
"3.4000","1.7249","1.6448","1.0972","12.9629","48.6108"
"3.4400","1.7449","1.6648","1.1105","13.1210","49.2038"
"3.4800","1.7642","1.6841","1.1233","13.2701","49.7627"
"3.5200","1.7849","1.7048","1.1372","13.4388","50.3954"
"3.5600","1.8045","1.7244","1.1502","13.5919","50.9696"
"3.6000","1.8242","1.7441","1.1634","13.7478","51.5543"
"3.6400","1.8453","1.7652","1.1774","13.9173","52.1900"
"3.6800","1.8653","1.7852","1.1908","14.0767","52.7876"
"3.7200","1.8855","1.8054","1.2043","14.2395","53.3983"
"3.7600","1.9053","1.8252","1.2174","14.3947","53.9800"
"3.8000","1.9242","1.8441","1.2301","14.5400","54.5249"
"3.8400","1.9440","1.8639","1.2433","14.6954","55.1079"
"3.8800","1.9636","1.8835","1.2563","14.8485","55.6820"
"3.9200","1.9839","1.9038","1.2699","15.0145","56.3044"
"3.9600","2.0050","1.9249","1.2840","15.1845","56.9418"
"4.0000","2.0249","1.9448","1.2972","15.3389","57.5208"
"4.0400","2.0452","1.9651","1.3108","15.5009","58.1282"
"4.0800","2.0649","1.9848","1.3239","15.6549","58.7058"
"4.1200","2.0846","2.0045","1.3370","15.8113","59.2925"
"4.1600","2.1047","2.0246","1.3504","15.9712","59.8921"
"4.2000","2.1242","2.0441","1.3635","16.1256","60.4711"
"4.2400","2.1449","2.0648","1.3773","16.2936","61.1010"
"4.2800","2.1663","2.0862","1.3916","16.4673","61.7523"
"4.3200","2.1860","2.1059","1.4047","16.6209","62.3282"
"4.3600","2.2058","2.1257","1.4179","16.7791","62.9216"
"4.4000","2.2246","2.1445","1.4304","16.9235","63.4632"
"4.4400","2.2446","2.1645","1.4437","17.0845","64.0667"
"4.4800","2.2647","2.1846","1.4572","17.2458","64.6716"
"4.5200","2.2841","2.2040","1.4701","17.3954","65.2326"
"4.5600","2.3044","2.2243","1.4837","17.5582","65.8431"
"4.6000","2.3253","2.2452","1.4976","17.7261","66.4730"
"4.6400","2.3451","2.2650","1.5108","17.8800","67.0500"
"4.6800","2.3653","2.2852","1.5243","18.0401","67.6502"
"4.7200","2.3847","2.3046","1.5372","18.1916","68.2184"
"4.7600","2.4046","2.3246","1.5505","18.3540","68.8275"
"4.8000","2.4245","2.3444","1.5638","18.5120","69.4198"
"4.8400","2.4441","2.3640","1.5768","18.6660","69.9977"
"4.8800","2.4656","2.3856","1.5912","18.8430","70.6611"
"4.9200","2.4860","2.4059","1.6048","19.0054","71.2703"
"4.9600","2.5055","2.4254","1.6178","19.1603","71.8510"
"5.0000","2.5252","2.4451","1.6309","19.3154","72.4328"
"5.0400","2.5443","2.4642","1.6437","19.4632","72.9869"
"5.0800","2.5644","2.4843","1.6571","19.6272","73.6020"
"5.1200","2.5847","2.5046","1.6706","19.7901","74.2130"
"5.1600","2.6041","2.5240","1.6836","19.9426","74.7848"
"5.2000","2.6247","2.5446","1.6973","20.1073","75.4023"
"5.2400","2.6444","2.5643","1.7105","20.2625","75.9845"
"5.2800","2.6655","2.5854","1.7245","20.4361","76.6355"
"5.3200","2.6853","2.6053","1.7378","20.5901","77.2129"
"5.3600","2.7044","2.6243","1.7505","20.7382","77.7684"
"5.4000","2.7243","2.6442","1.7637","20.8955","78.3580"
"5.4400","2.7440","2.6639","1.7769","21.0525","78.9470"
"5.4800","2.7642","2.6841","1.7904","21.2141","79.5529"
"5.5200","2.7861","2.7060","1.8050","21.3936","80.2261"
"5.5600","2.8061","2.7260","1.8183","21.5485","80.8068"
"5.6000","2.8257","2.7456","1.8314","21.7008","81.3778"
"5.6400","2.8449","2.7648","1.8442","21.8481","81.9306"
"5.6800","2.8647","2.7846","1.8574","22.0068","82.5256"
"5.7200","2.8852","2.8051","1.8711","22.1690","83.1336"
"5.7600","2.9042","2.8241","1.8837","22.3156","83.6834"
"5.8000","2.9242","2.8441","1.8971","22.4781","84.2927"
"5.8400","2.9446","2.8645","1.9107","22.6413","84.9050"
"5.8800","2.9651","2.8850","1.9244","22.8038","85.5142"
"5.9200","2.9854","2.9053","1.9379","22.9647","86.1176"
"5.9600","3.0047","2.9247","1.9508","23.1141","86.6780"
"6.0000","3.0240","2.9439","1.9637","23.2648","87.2431"
"6.0400","3.0448","2.9647","1.9775","23.4326","87.8723"
"6.0800","3.0643","2.9842","1.9905","23.5823","88.4337"
"6.1200","3.0855","3.0055","2.0047","23.7597","89.0987"
"6.1600","3.1060","3.0259","2.0184","23.9220","89.7075"
"6.2000","3.1256","3.0455","2.0314","24.0731","90.2741"
"6.2400","3.1453","3.0652","2.0446","24.2249","90.8434"
"6.2800","3.1649","3.0849","2.0577","24.3774","91.4154"
"6.3200","3.1849","3.1048","2.0710","24.5360","92.0099"
"6.3600","3.2046","3.1245","2.0841","24.6873","92.5773"
"6.4000","3.2235","3.1434","2.0968","24.8311","93.1165"
"6.4400","3.2443","3.1642","2.1106","24.9978","93.7417"
"6.4800","3.2652","3.1851","2.1245","25.1623","94.3585"
"6.5200","3.2856","3.2055","2.1382","25.3246","94.9672"
"6.5600","3.3054","3.2253","2.1513","25.4744","95.5289"
"6.6000","3.3242","3.2441","2.1639","25.6167","96.0625"
"6.6400","3.3442","3.2641","2.1772","25.7724","96.6467"
"6.6800","3.3643","3.2842","2.1907","25.9313","97.2426"
"6.7200","3.3848","3.3047","2.2043","26.0919","97.8445"
"6.7600","3.4059","3.3258","2.2184","26.2680","98.5049"
"6.8000","3.4259","3.3458","2.2317","26.4205","99.0769"
"6.8400","3.4456","3.3655","2.2449","26.5736","99.6509"
"6.8800","3.4656","3.3855","2.2582","26.7266","100.2247"
"6.9200","3.4852","3.4051","2.2713","26.8749","100.7810"
"6.9600","3.5052","3.4251","2.2846","27.0305","101.3645"
"7.0000","3.5237","3.4436","2.2970","27.1679","101.8798"
"7.0400","3.5436","3.4635","2.3102","27.3228","102.4605"
"7.0800","3.5650","3.4849","2.3245","27.4927","103.0976"
"7.1200","3.5859","3.5058","2.3385","27.6562","103.7106"
"7.1600","3.6050","3.5249","2.3512","27.7987","104.2452"
"7.2000","3.6246","3.5445","2.3643","27.9491","104.8093"
"7.2400","3.6442","3.5641","2.3773","28.1003","105.3761"
"7.2800","3.6648","3.5847","2.3911","28.2596","105.9734"
"7.3200","3.6842","3.6041","2.4040","28.4067","106.5249"
"7.3600","3.7050","3.6249","2.4179","28.5723","107.1460"
"7.4000","3.7256","3.6455","2.4317","28.7311","107.7417"
"7.4400","3.7456","3.6655","2.4450","28.8815","108.3057"
"7.4800","3.7654","3.6853","2.4582","29.0323","108.8713"
"7.5200","3.7848","3.7047","2.4711","29.1777","109.4162"
"7.5600","3.8045","3.7244","2.4843","29.3295","109.9858"
"7.6000","3.8250","3.7449","2.4979","29.4872","110.5770"
"7.6400","3.8440","3.7639","2.5106","29.6277","111.1041"
"7.6800","3.8645","3.7844","2.5243","29.7880","111.7050"
"7.7200","3.8854","3.8053","2.5382","29.9477","112.3037"
"7.7600","3.9052","3.8251","2.5514","30.0959","112.8596"
"7.8000","3.9251","3.8450","2.5647","30.2470","113.4262"
"7.8400","3.9444","3.8643","2.5776","30.3934","113.9751"
"7.8800","3.9651","3.8850","2.5914","30.5573","114.5898"
"7.9200","3.9851","3.9050","2.6047","30.7082","115.1559"
"7.9600","4.0044","3.9243","2.6176","30.8495","115.6855"
"8.0000","4.0253","3.9452","2.6315","31.0108","116.2905"
"8.0400","4.0459","3.9658","2.6453","31.1698","116.8869"
"8.0800","4.0658","3.9857","2.6586","31.3166","117.4372"
"8.1200","4.0859","4.0058","2.6720","31.4673","118.0024"
"8.1600","4.1048","4.0247","2.6846","31.6039","118.5147"
"8.2000","4.1246","4.0445","2.6977","31.7532","119.0744"
"8.2400","4.1440","4.0639","2.7107","31.8989","119.6207"
"8.2800","4.1640","4.0839","2.7240","32.0485","120.1819"
"8.3200","4.1851","4.1050","2.7381","32.2094","120.7854"
"8.3600","4.2055","4.1254","2.7518","32.3623","121.3586"
"8.4000","4.2250","4.1449","2.7648","32.5075","121.9032"
"8.4400","4.2448","4.1647","2.7780","32.6550","122.4561"
"8.4800","4.2643","4.1842","2.7910","32.7975","122.9907"
"8.5200","4.2850","4.2049","2.8048","32.9557","123.5840"
"8.5600","4.3046","4.2245","2.8178","33.0998","124.1241"
"8.6000","4.3244","4.2443","2.8311","33.2492","124.6846"
"8.6400","4.3458","4.2657","2.8453","33.4129","125.2984"
"8.6800","4.3657","4.2856","2.8586","33.5585","125.8445"
"8.7200","4.3855","4.3054","2.8718","33.7068","126.4006"
"8.7600","4.4053","4.3252","2.8850","33.8575","126.9657"
"8.8000","4.4246","4.3445","2.8979","33.9962","127.4857"
"8.8400","4.4441","4.3640","2.9109","34.1362","128.0107"
"8.8800","4.4634","4.3833","2.9237","34.2766","128.5374"
"8.9200","4.4842","4.4041","2.9376","34.4373","129.1398"
"8.9600","4.5054","4.4253","2.9518","34.5967","129.7375"
"9.0000","4.5248","4.4447","2.9647","34.7337","130.2515"
"9.0400","4.5451","4.4650","2.9782","34.8852","130.8197"
"9.0800","4.5647","4.4846","2.9913","35.0274","131.3529"
"9.1200","4.5847","4.5046","3.0047","35.1755","131.9080"
"9.1600","4.6047","4.5246","3.0180","35.3198","132.4491"
"9.2000","4.6240","4.5439","3.0309","35.4588","132.9705"
"9.2400","4.6448","4.5647","3.0448","35.6172","133.5647"
"9.2800","4.6661","4.5860","3.0590","35.7773","134.1650"
"9.3200","4.6858","4.6057","3.0721","35.9169","134.6884"
"9.3600","4.7056","4.6255","3.0853","36.0598","135.2241"
"9.4000","4.7246","4.6445","3.0980","36.1936","135.7259"
"9.4400","4.7444","4.6643","3.1112","36.3390","136.2711"
"9.4800","4.7645","4.6844","3.1246","36.4858","136.8217"
"9.5200","4.7842","4.7042","3.1378","36.6281","137.3555"
"9.5600","4.8047","4.7246","3.1514","36.7783","137.9187"
"9.6000","4.8251","4.7450","3.1650","36.9251","138.4690"
"9.6400","4.8452","4.7651","3.1784","37.0709","139.0157"
"9.6800","4.8656","4.7855","3.1921","37.2251","139.5941"
"9.7200","4.8847","4.8046","3.2048","37.3569","140.0882"
"9.7600","4.9044","4.8243","3.2179","37.4982","140.6182"
"9.8000","4.9244","4.8443","3.2313","37.6422","141.1581"
"9.8400","4.9445","4.8644","3.2447","37.7875","141.7030"
"9.8800","4.9657","4.8856","3.2588","37.9427","142.2850"
"9.9200","4.9858","4.9057","3.2722","38.0856","142.8211"
"9.9600","5.0057","4.9256","3.2855","38.2284","143.3564"
"10.0000","5.0248","4.9447","3.2983","38.3589","143.8461"
"10.0400","5.0436","4.9635","3.3108","38.4871","144.3268"
"10.0800","5.0646","4.9845","3.3248","38.6428","144.9104"
"10.1200","5.0849","5.0048","3.3383","38.7867","145.4501"
"10.1600","5.1043","5.0242","3.3513","38.9215","145.9556"
"10.2000","5.1248","5.0447","3.3649","39.0670","146.5013"
"10.2400","5.1449","5.0648","3.3783","39.2107","147.0400"
"10.2800","5.1656","5.0855","3.3922","39.3592","147.5969"
"10.3200","5.1852","5.1051","3.4052","39.4961","148.1105"
"10.3600","5.2041","5.1240","3.4179","39.6233","148.5875"
"10.4000","5.2241","5.1440","3.4312","39.7629","149.1109"
"10.4400","5.2440","5.1639","3.4444","39.9028","149.6356"
"10.4800","5.2649","5.1848","3.4584","40.0560","150.2099"
"10.5200","5.2863","5.2062","3.4727","40.2091","150.7841"
"10.5600","5.3058","5.2257","3.4857","40.3404","151.2765"
"10.6000","5.3255","5.2455","3.4988","40.4783","151.7935"
"10.6400","5.3448","5.2647","3.5117","40.6092","152.2847"
"10.6800","5.3646","5.2845","3.5249","40.7485","152.8070"
"10.7200","5.3851","5.3050","3.5385","40.8914","153.3427"
"10.7600","5.4042","5.3241","3.5513","41.0200","153.8251"
"10.8000","5.4243","5.3442","3.5647","41.1658","154.3717"
"10.8400","5.4449","5.3648","3.5785","41.3119","154.9197"
"10.8800","5.4652","5.3851","3.5920","41.4521","155.4454"
"10.9200","5.4856","5.4055","3.6056","41.5927","155.9727"
"10.9600","5.5050","5.4249","3.6185","41.7233","156.4622"
"11.0000","5.5243","5.4442","3.6314","41.8570","156.9637"
"11.0400","5.5446","5.4645","3.6450","41.9986","157.4948"
"11.0800","5.5642","5.4841","3.6580","42.1312","157.9918"
"11.1200","5.5854","5.5053","3.6722","42.2837","158.5637"
"11.1600","5.6060","5.5259","3.6859","42.4312","159.1171"
"11.2000","5.6258","5.5457","3.6991","42.5653","159.6200"
"11.2400","5.6453","5.5652","3.7121","42.6944","160.1042"
"11.2800","5.6647","5.5846","3.7250","42.8250","160.5936"
"11.3200","5.6849","5.6048","3.7385","42.9674","161.1277"
"11.3600","5.7050","5.6249","3.7520","43.1029","161.6360"
"11.4000","5.7237","5.6436","3.7644","43.2260","162.0976"
"11.4400","5.7445","5.6644","3.7783","43.3718","162.6443"
"11.4800","5.7651","5.6850","3.7921","43.5153","163.1823"
"11.5200","5.7859","5.7058","3.8059","43.6614","163.7303"
"11.5600","5.8055","5.7254","3.8190","43.7918","164.2194"
"11.6000","5.8237","5.7436","3.8311","43.9048","164.6430"
"11.6400","5.8437","5.7636","3.8445","44.0422","165.1581"
"11.6800","5.8644","5.7843","3.8583","44.1859","165.6970"
"11.7200","5.8846","5.8046","3.8718","44.3222","166.2084"
"11.7600","5.9054","5.8253","3.8856","44.4653","166.7449"
"11.8000","5.9254","5.8453","3.8990","44.5989","167.2458"
"11.8400","5.9456","5.8655","3.9124","44.7397","167.7740"
"11.8800","5.9661","5.8860","3.9261","44.8785","168.2946"
"11.9200","5.9851","5.9050","3.9388","44.9984","168.7442"
"11.9600","6.0048","5.9248","3.9519","45.1273","169.2275"
"12.0000","6.0234","5.9433","3.9643","45.2457","169.6715"
"12.0400","6.0436","5.9635","3.9778","45.3841","170.1905"
"12.0800","6.0650","5.9849","3.9921","45.5328","170.7481"
"12.1200","6.0857","6.0057","4.0059","45.6722","171.2706"
"12.1600","6.1056","6.0255","4.0192","45.8027","171.7600"
"12.2000","6.1247","6.0446","4.0319","45.9246","172.2172"
"12.2400","6.1434","6.0634","4.0444","46.0442","172.6659"
"12.2800","6.1642","6.0841","4.0582","46.1857","173.1963"
"12.3200","6.1846","6.1045","4.0718","46.3223","173.7088"
"12.3600","6.2053","6.1252","4.0857","46.4635","174.2379"
"12.4000","6.2257","6.1457","4.0993","46.5981","174.7427"
"12.4400","6.2456","6.1655","4.1125","46.7268","175.2257"
"12.4800","6.2654","6.1853","4.1258","46.8546","175.7048"
"12.5200","6.2851","6.2050","4.1389","46.9813","176.1800"
"12.5600","6.3048","6.2247","4.1520","47.1094","176.6604"
"12.6000","6.3245","6.2444","4.1652","47.2351","177.1317"
"12.6400","6.3433","6.2632","4.1777","47.3523","177.5713"
"12.6800","6.3642","6.2841","4.1916","47.4952","178.1071"
"12.7200","6.3855","6.3054","4.2059","47.6406","178.6522"
"12.7600","6.4052","6.3251","4.2190","47.7639","179.1145"
"12.8000","6.4249","6.3448","4.2321","47.8884","179.5816"
"12.8400","6.4439","6.3638","4.2448","48.0070","180.0261"
"12.8800","6.4643","6.3842","4.2584","48.1431","180.5368"
"12.9200","6.4847","6.4046","4.2720","48.2758","181.0343"
"12.9600","6.5045","6.4244","4.2852","48.3999","181.4997"
"13.0000","6.5251","6.4450","4.2990","48.5351","182.0067"
"13.0400","6.5456","6.4655","4.3127","48.6676","182.5034"
"13.0800","6.5656","6.4855","4.3259","48.7937","182.9765"
"13.1200","6.5855","6.5054","4.3393","48.9187","183.4451"
"13.1600","6.6044","6.5243","4.3519","49.0333","183.8749"
"13.2000","6.6248","6.5447","4.3654","49.1644","184.3666"
"13.2400","6.6443","6.5642","4.3785","49.2860","184.8227"
"13.2800","6.6639","6.5838","4.3916","49.4083","185.2811"
"13.3200","6.6848","6.6047","4.4055","49.5433","185.7875"
"13.3600","6.7053","6.6252","4.4192","49.6715","186.2681"
"13.4000","6.7252","6.6451","4.4324","49.7965","186.7369"
"13.4400","6.7451","6.6651","4.4457","49.9230","187.2112"
"13.4800","6.7644","6.6843","4.4586","50.0388","187.6455"
"13.5200","6.7848","6.7047","4.4722","50.1687","188.1325"
"13.5600","6.8044","6.7243","4.4853","50.2894","188.5852"
"13.6000","6.8246","6.7445","4.4987","50.4169","189.0633"
"13.6400","6.8456","6.7656","4.5128","50.5513","189.5672"
"13.6800","6.8658","6.7857","4.5262","50.6765","190.0369"
"13.7200","6.8856","6.8055","4.5394","50.7984","190.4940"
"13.7600","6.9051","6.8250","4.5524","50.9170","190.9389"
"13.8000","6.9243","6.8442","4.5652","51.0305","191.3645"
"13.8400","6.9442","6.8641","4.5785","51.1518","191.8193"
"13.8800","6.9639","6.8838","4.5917","51.2731","192.2739"
"13.9200","6.9842","6.9041","4.6052","51.3998","192.7491"
"13.9600","7.0052","6.9251","4.6192","51.5322","193.2459"
"14.0000","7.0251","6.9450","4.6325","51.6518","193.6944"
"14.0400","7.0453","6.9652","4.6459","51.7752","194.1570"
"14.0800","7.0646","6.9845","4.6588","51.8886","194.5824"
"14.1200","7.0844","7.0043","4.6720","52.0078","195.0293"
"14.1600","7.1044","7.0243","4.6854","52.1296","195.4860"
"14.2000","7.1242","7.0441","4.6986","52.2482","195.9306"
"14.2400","7.1448","7.0647","4.7123","52.3778","196.4169"
"14.2800","7.1663","7.0862","4.7266","52.5124","196.9217"
"14.3200","7.1859","7.1058","4.7397","52.6258","197.3467"
"14.3600","7.2059","7.1258","4.7531","52.7435","197.7881"
"14.4000","7.2250","7.1450","4.7658","52.8572","198.2145"
"14.4400","7.2450","7.1649","4.7792","52.9803","198.6761"
"14.4800","7.2648","7.1847","4.7923","53.0960","199.1101"
"14.5200","7.2837","7.2036","4.8050","53.2015","199.5056"
"14.5600","7.3038","7.2237","4.8184","53.3217","199.9563"
"14.6000","7.3251","7.2450","4.8326","53.4529","200.4484"
"14.6400","7.3452","7.2651","4.8460","53.5698","200.8868"
"14.6800","7.3653","7.2852","4.8594","53.6896","201.3361"
"14.7200","7.3847","7.3046","4.8723","53.8001","201.7504"
"14.7600","7.4045","7.3244","4.8855","53.9151","202.1817"
"14.8000","7.4244","7.3443","4.8988","54.0311","202.6168"
"14.8400","7.4442","7.3641","4.9120","54.1444","203.0415"
"14.8800","7.4657","7.3856","4.9263","54.2747","203.5301"
"14.9200","7.4859","7.4058","4.9398","54.3907","203.9650"
"14.9600","7.5058","7.4257","4.9531","54.5074","204.4029"
"15.0000","7.5250","7.4449","4.9659","54.6132","204.7994"
"15.0400","7.5443","7.4642","4.9788","54.7187","205.1950"
"15.0800","7.5647","7.4846","4.9924","54.8385","205.6443"
"15.1200","7.5847","7.5046","5.0057","54.9526","206.0722"
"15.1600","7.6040","7.5239","5.0186","55.0600","206.4750"
"15.2000","7.6247","7.5446","5.0325","55.1792","206.9220"
"15.2400","7.6447","7.5646","5.0457","55.2914","207.3426"
"15.2800","7.6652","7.5851","5.0594","55.4099","207.7870"
"15.3200","7.6848","7.6047","5.0725","55.5183","208.1937"
"15.3600","7.7043","7.6242","5.0855","55.6230","208.5863"
"15.4000","7.7243","7.6442","5.0988","55.7340","209.0024"
"15.4400","7.7447","7.6646","5.1124","55.8490","209.4339"
"15.4800","7.7648","7.6847","5.1259","55.9628","209.8603"
"15.5200","7.7856","7.7055","5.1397","56.0804","210.3016"
"15.5600","7.8057","7.7257","5.1532","56.1887","210.7076"
"15.6000","7.8259","7.7458","5.1666","56.2991","211.1216"
"15.6400","7.8451","7.7650","5.1795","56.4027","211.5103"
"15.6800","7.8648","7.7847","5.1926","56.5088","211.9082"
"15.7200","7.8851","7.8050","5.2061","56.6183","212.3185"
"15.7600","7.9037","7.8236","5.2185","56.7118","212.6694"
"15.8000","7.9240","7.8439","5.2321","56.8257","213.0963"
"15.8400","7.9449","7.8648","5.2460","56.9429","213.5360"
"15.8800","7.9657","7.8856","5.2599","57.0567","213.9625"
"15.9200","7.9859","7.9058","5.2733","57.1626","214.3598"
"15.9600","8.0050","7.9249","5.2861","57.2594","214.7227"
"16.0000","8.0241","7.9440","5.2988","57.3583","215.0937"
"16.0400","8.0443","7.9642","5.3123","57.4655","215.4955"
"16.0800","8.0642","7.9841","5.3256","57.5700","215.8875"
"16.1200","8.0857","8.0056","5.3399","57.6904","216.3390"
"16.1600","8.1059","8.0258","5.3534","57.7941","216.7280"
"16.2000","8.1255","8.0454","5.3665","57.8934","217.1002"
"16.2400","8.1449","8.0648","5.3794","57.9896","217.4611"
"16.2800","8.1647","8.0846","5.3926","58.0940","217.8525"
"16.3200","8.1851","8.1050","5.4062","58.2037","218.2639"
"16.3600","8.2050","8.1249","5.4195","58.3063","218.6486"
"16.4000","8.2235","8.1434","5.4318","58.3922","218.9708"
"16.4400","8.2443","8.1642","5.4457","58.5043","219.3911"
"16.4800","8.2650","8.1849","5.4595","58.6123","219.7961"
"16.5200","8.2857","8.2056","5.4733","58.7217","220.2062"
"16.5600","8.3059","8.2258","5.4868","58.8236","220.5886"
"16.6000","8.3246","8.2445","5.4993","58.9099","220.9120"
"16.6400","8.3443","8.2642","5.5124","59.0074","221.2776"
"16.6800","8.3644","8.2843","5.5258","59.1092","221.6597"
"16.7200","8.3847","8.3046","5.5394","59.2109","222.0411"
"16.7600","8.4055","8.3254","5.5532","59.3173","222.4400"
"16.8000","8.4256","8.3455","5.5666","59.4146","222.8049"
"16.8400","8.4455","8.3654","5.5799","59.5130","223.1738"
"16.8800","8.4653","8.3852","5.5931","59.6063","223.5238"
"16.9200","8.4847","8.4046","5.6061","59.6992","223.8719"
"16.9600","8.5052","8.4251","5.6197","59.7993","224.2474"
"17.0000","8.5239","8.4438","5.6322","59.8840","224.5651"
"17.0400","8.5439","8.4638","5.6455","59.9822","224.9332"
"17.0800","8.5650","8.4849","5.6596","60.0909","225.3410"
"17.1200","8.5862","8.5061","5.6737","60.1972","225.7395"
"17.1600","8.6057","8.5256","5.6868","60.2867","226.0750"
"17.2000","8.6246","8.5445","5.6993","60.3686","226.3822"
"17.2400","8.6438","8.5637","5.7122","60.4584","226.7190"
"17.2800","8.6649","8.5848","5.7263","60.5630","227.1114"
"17.3200","8.6848","8.6047","5.7395","60.6563","227.4611"
"17.3600","8.7053","8.6252","5.7532","60.7547","227.8300"
"17.4000","8.7254","8.6453","5.7666","60.8471","228.1768"
"17.4400","8.7453","8.6652","5.7799","60.9359","228.5095"
"17.4800","8.7654","8.6853","5.7933","61.0274","228.8528"
"17.5200","8.7852","8.7051","5.8065","61.1173","229.1899"
"17.5600","8.8048","8.7247","5.8196","61.2084","229.5315"
"17.6000","8.8251","8.7450","5.8331","61.3019","229.8821"
"17.6400","8.8439","8.7638","5.8456","61.3783","230.1687"
"17.6800","8.8643","8.7842","5.8592","61.4752","230.5318"
"17.7200","8.8855","8.8054","5.8734","61.5744","230.9038"
"17.7600","8.9054","8.8253","5.8867","61.6594","231.2226"
"17.8000","8.9249","8.8448","5.8997","61.7402","231.5259"
"17.8400","8.9441","8.8640","5.9125","61.8188","231.8203"
"17.8800","8.9645","8.8844","5.9261","61.9088","232.1582"
"17.9200","8.9849","8.9048","5.9397","61.9988","232.4957"
"17.9600","9.0047","8.9246","5.9529","62.0808","232.8029"
"18.0000","9.0248","8.9447","5.9663","62.1643","233.1162"
"18.0400","9.0455","8.9654","5.9801","62.2555","233.4581"
"18.0800","9.0658","8.9857","5.9936","62.3412","233.7794"
"18.1200","9.0858","9.0057","6.0070","62.4227","234.0852"
"18.1600","9.1046","9.0245","6.0196","62.4927","234.3478"
"18.2000","9.1248","9.0447","6.0330","62.5781","234.6680"
"18.2400","9.1442","9.0641","6.0459","62.6552","234.9570"
"18.2800","9.1640","9.0839","6.0591","62.7358","235.2593"
"18.3200","9.1850","9.1049","6.0732","62.8281","235.6054"
"18.3600","9.2056","9.1255","6.0869","62.9125","235.9218"
"18.4000","9.2248","9.1447","6.0997","62.9854","236.1952"
"18.4400","9.2446","9.1646","6.1130","63.0643","236.4913"
"18.4800","9.2643","9.1842","6.1261","63.1389","236.7708"
"18.5200","9.2852","9.2051","6.1400","63.2280","237.1052"
"18.5600","9.3048","9.2247","6.1531","63.2997","237.3737"
"18.6000","9.3244","9.2443","6.1661","63.3744","237.6541"
"18.6400","9.3454","9.2653","6.1802","63.4597","237.9738"
"18.6800","9.3654","9.2853","6.1935","63.5344","238.2539"
"18.7200","9.3856","9.3055","6.2070","63.6121","238.5453"
"18.7600","9.4052","9.3251","6.2201","63.6829","238.8108"
"18.8000","9.4250","9.3449","6.2333","63.7562","239.0857"
"18.8400","9.4451","9.3650","6.2467","63.8323","239.3711"
"18.8800","9.4642","9.3841","6.2594","63.8978","239.6168"
"18.9200","9.4836","9.4035","6.2723","63.9667","239.8752"
"18.9600","9.5050","9.4249","6.2866","64.0536","240.2010"
"19.0000","9.5253","9.4452","6.3002","64.1245","240.4668"
"19.0400","9.5456","9.4655","6.3137","64.1971","240.7391"
"19.0800","9.5649","9.4848","6.3266","64.2613","240.9799"
"19.1200","9.5846","9.5045","6.3397","64.3299","241.2370"
"19.1600","9.6041","9.5240","6.3527","64.3919","241.4698"
"19.2000","9.6242","9.5441","6.3661","64.4622","241.7331"
"19.2400","9.6450","9.5649","6.3800","64.5391","242.0218"
"19.2800","9.6661","9.5860","6.3941","64.6161","242.3102"
"19.3200","9.6858","9.6057","6.4072","64.6754","242.5327"
"19.3600","9.7059","9.6258","6.4206","64.7398","242.7744"
"19.4000","9.7247","9.6446","6.4332","64.7949","242.9810"
"19.4400","9.7447","9.6646","6.4465","64.8620","243.2324"
"19.4800","9.7646","9.6845","6.4598","64.9242","243.4656"
"19.5200","9.7838","9.7037","6.4726","64.9783","243.6687"
"19.5600","9.8041","9.7240","6.4862","65.0424","243.9090"
"19.6000","9.8248","9.7447","6.5000","65.1134","244.1753"
"19.6400","9.8452","9.7651","6.5135","65.1787","244.4202"
"19.6800","9.8655","9.7854","6.5271","65.2400","244.6500"
"19.7200","9.8847","9.8046","6.5399","65.2928","244.8481"
"19.7600","9.9047","9.8246","6.5532","65.3580","245.0927"
"19.8000","9.9247","9.8446","6.5665","65.4191","245.3216"
"19.8400","9.9443","9.8642","6.5796","65.4728","245.5230"
"19.8800","9.9658","9.8857","6.5940","65.5447","245.7925"
"19.9200","9.9861","9.9060","6.6075","65.6020","246.0075"
"19.9600","10.0058","9.9257","6.6206","65.6556","246.2085"
"20.0000","10.0251","9.9450","6.6336","65.7063","246.3986"
"20.0400","10.0445","9.9644","6.6465","65.7554","246.5829"
"20.0800","10.0645","9.9844","6.6598","65.8128","246.7982"
"20.1200","10.0843","10.0042","6.6730","65.8641","246.9902"
"20.1600","10.1039","10.0238","6.6861","65.9160","247.1850"
"20.2000","10.1251","10.0450","6.7003","65.9797","247.4240"
"20.2400","10.1451","10.0650","6.7136","66.0293","247.6100"
"20.2800","10.1650","10.0850","6.7269","66.0814","247.8054"
"20.3200","10.1845","10.1044","6.7399","66.1292","247.9845"
"20.3600","10.2037","10.1236","6.7527","66.1716","248.1436"
"20.4000","10.2237","10.1437","6.7660","66.2225","248.3345"
"20.4400","10.2441","10.1640","6.7796","66.2761","248.5355"
"20.4800","10.2653","10.1852","6.7937","66.3359","248.7596"
"20.5200","10.2867","10.2066","6.8080","66.3941","248.9779"
"20.5600","10.3058","10.2257","6.8208","66.4300","249.1125"
"20.6000","10.3253","10.2452","6.8338","66.4711","249.2668"
"20.6400","10.3451","10.2650","6.8470","66.5151","249.4316"
"20.6800","10.3647","10.2846","6.8601","66.5566","249.5873"
"20.7200","10.3851","10.3050","6.8737","66.6015","249.7555"
"20.7600","10.4040","10.3239","6.8863","66.6340","249.8777"
"20.8000","10.4243","10.3442","6.8998","66.6813","250.0550"
"20.8400","10.4449","10.3648","6.9136","66.7309","250.2410"
"20.8800","10.4654","10.3853","6.9272","66.7779","250.4170"
"20.9200","10.4858","10.4057","6.9408","66.8206","250.5771"
"20.9600","10.5050","10.4249","6.9536","66.8542","250.7031"
"21.0000","10.5243","10.4442","6.9665","66.8910","250.8414"
"21.0400","10.5449","10.4648","6.9803","66.9357","251.0087"
"21.0800","10.5646","10.4845","6.9934","66.9689","251.1333"
"21.1200","10.5856","10.5055","7.0074","67.0172","251.3146"
"21.1600","10.6057","10.5256","7.0208","67.0550","251.4563"
"21.2000","10.6258","10.5457","7.0342","67.0904","251.5889"
"21.2400","10.6453","10.5653","7.0473","67.1172","251.6893"
"21.2800","10.6647","10.5846","7.0602","67.1444","251.7917"
"21.3200","10.6846","10.6045","7.0735","67.1795","251.9230"
"21.3600","10.7047","10.6246","7.0869","67.2124","252.0465"
"21.4000","10.7236","10.6435","7.0994","67.2360","252.1350"
"21.4400","10.7445","10.6644","7.1134","67.2787","252.2951"
"21.4800","10.7651","10.6850","7.1271","67.3174","252.4401"
"21.5200","10.7858","10.7057","7.1410","67.3595","252.5980"
"21.5600","10.8054","10.7253","7.1540","67.3836","252.6887"
"21.6000","10.8244","10.7443","7.1667","67.4072","252.7770"
"21.6400","10.8444","10.7643","7.1800","67.4390","252.8962"
"21.6800","10.8646","10.7845","7.1935","67.4736","253.0260"
"21.7200","10.8848","10.8047","7.2070","67.5058","253.1466"
"21.7600","10.9055","10.8254","7.2208","67.5402","253.2757"
"21.8000","10.9253","10.8452","7.2340","67.5672","253.3769"
"21.8400","10.9454","10.8653","7.2474","67.6003","253.5010"
"21.8800","10.9657","10.8856","7.2609","67.6306","253.6146"
"21.9200","10.9849","10.9048","7.2737","67.6508","253.6904"
"21.9600","11.0050","10.9249","7.2871","67.6789","253.7958"
"22.0000","11.0238","10.9437","7.2997","67.6960","253.8601"
"22.0400","11.0436","10.9635","7.3129","67.7241","253.9653"
"22.0800","11.0649","10.9848","7.3271","67.7645","254.1168"
"22.1200","11.0863","11.0062","7.3414","67.8020","254.2574"
"22.1600","11.1057","11.0256","7.3544","67.8196","254.3236"
"22.2000","11.1250","11.0449","7.3672","67.8354","254.3828"
"22.2400","11.1441","11.0640","7.3799","67.8508","254.4406"
"22.2800","11.1648","11.0847","7.3938","67.8798","254.5494"
"22.3200","11.1846","11.1045","7.4070","67.9026","254.6346"
"22.3600","11.2055","11.1254","7.4209","67.9344","254.7540"
"22.4000","11.2260","11.1459","7.4346","67.9594","254.8478"
"22.4400","11.2455","11.1654","7.4476","67.9756","254.9085"
"22.4800","11.2656","11.1855","7.4610","67.9969","254.9883"
"22.5200","11.2854","11.2053","7.4742","68.0164","255.0615"
"22.5600","11.3049","11.2248","7.4872","68.0384","255.1441"
"22.6000","11.3251","11.2450","7.5007","68.0613","255.2297"
"22.6400","11.3439","11.2638","7.5132","68.0697","255.2615"
"22.6800","11.3641","11.2840","7.5267","68.0943","255.3536"
"22.7200","11.3852","11.3051","7.5407","68.1197","255.4488"
"22.7600","11.4053","11.3252","7.5542","68.1370","255.5136"
"22.8000","11.4250","11.3449","7.5673","68.1505","255.5642"
"22.8400","11.4441","11.3640","7.5801","68.1625","255.6093"
"22.8800","11.4645","11.3844","7.5936","68.1856","255.6961"
"22.9200","11.4847","11.4046","7.6072","68.2045","255.7668"
"22.9600","11.5045","11.4244","7.6204","68.2185","255.8195"
"23.0000","11.5252","11.4451","7.6342","68.2401","255.9004"
"23.0400","11.5456","11.4655","7.6477","68.2565","255.9618"
"23.0800","11.5657","11.4856","7.6612","68.2722","256.0206"
"23.1200","11.5860","11.5059","7.6747","68.2879","256.0795"
"23.1600","11.6046","11.5245","7.6871","68.2897","256.0864"
"23.2000","11.6240","11.5439","7.7000","68.3000","256.1250"
"23.2400","11.6440","11.5639","7.7134","68.3144","256.1789"
"23.2800","11.6640","11.5839","7.7267","68.3257","256.2213"
"23.3200","11.6846","11.6045","7.7405","68.3412","256.2795"
"23.3600","11.7053","11.6252","7.7543","68.3581","256.3428"
"23.4000","11.7251","11.6450","7.7675","68.3676","256.3784"
"23.4400","11.7450","11.6649","7.7808","68.3757","256.4087"
"23.4800","11.7646","11.6845","7.7938","68.3836","256.4387"
"23.5200","11.7852","11.7051","7.8076","68.4029","256.5108"
"23.5600","11.8048","11.7247","7.8207","68.4081","256.5305"
"23.6000","11.8246","11.7445","7.8339","68.4164","256.5615"
"23.6400","11.8456","11.7656","7.8479","68.4334","256.6252"
"23.6800","11.8659","11.7858","7.8614","68.4423","256.6585"
"23.7200","11.8859","11.8058","7.8747","68.4518","256.6942"
"23.7600","11.9053","11.8252","7.8877","68.4533","256.6997"
"23.8000","11.9243","11.8442","7.9004","68.4549","256.7058"
"23.8400","11.9443","11.8642","7.9137","68.4629","256.7358"
"23.8800","11.9638","11.8837","7.9267","68.4646","256.7421"
"23.9200","11.9841","11.9040","7.9402","68.4736","256.7760"
"23.9600","12.0051","11.9250","7.9542","68.4882","256.8307"
"24.0000","12.0249","11.9448","7.9675","68.4909","256.8409"
"24.0400","12.0452","11.9652","7.9810","68.4980","256.8676"
"24.0800","12.0648","11.9847","7.9941","68.5006","256.8772"
"24.1200","12.0848","12.0047","8.0074","68.5066","256.8998"
"24.1600","12.1045","12.0244","8.0205","68.5078","256.9041"
"24.2000","12.1238","12.0437","8.0335","68.5084","256.9066"
"24.2400","12.1446","12.0645","8.0473","68.5222","256.9581"
"24.2800","12.1663","12.0862","8.0618","68.5397","257.0240"
"24.3200","12.1864","12.1063","8.0752","68.5426","257.0349"
"24.3600","12.2059","12.1258","8.0882","68.5403","257.0262"
"24.4000","12.2248","12.1447","8.1008","68.5356","257.0085"
"24.4400","12.2447","12.1646","8.1140","68.5406","257.0272"
"24.4800","12.2648","12.1847","8.1275","68.5436","257.0386"
"24.5200","12.2839","12.2038","8.1402","68.5407","257.0276"
"24.5600","12.3047","12.2246","8.1541","68.5499","257.0620"
"24.6000","12.3254","12.2453","8.1679","68.5561","257.0854"
"24.6400","12.3455","12.2654","8.1813","68.5555","257.0829"
"24.6800","12.3654","12.2853","8.1946","68.5552","257.0819"
"24.7200","12.3845","12.3044","8.2073","68.5494","257.0601"
"24.7600","12.4045","12.3244","8.2207","68.5517","257.0687"
"24.8000","12.4247","12.3446","8.2341","68.5510","257.0662"
"24.8400","12.4442","12.3641","8.2471","68.5472","257.0522"
"24.8800","12.4656","12.3855","8.2614","68.5569","257.0883"
"24.9200","12.4861","12.4060","8.2751","68.5558","257.0844"
"24.9600","12.5059","12.4258","8.2883","68.5522","257.0706"
"25.0000","12.5253","12.4452","8.3012","68.5447","257.0427"
"25.0400","12.5446","12.4645","8.3141","68.5367","257.0125"
"25.0800","12.5646","12.4845","8.3275","68.5352","257.0069"
"25.1200","12.5844","12.5044","8.3407","68.5321","256.9955"
"25.1600","12.6041","12.5240","8.3538","68.5261","256.9728"
"25.2000","12.6247","12.5446","8.3675","68.5247","256.9675"
"25.2400","12.6446","12.5645","8.3808","68.5174","256.9402"
"25.2800","12.6651","12.5850","8.3945","68.5164","256.9364"
"25.3200","12.6851","12.6050","8.4078","68.5113","256.9172"
"25.3600","12.7042","12.6241","8.4206","68.4956","256.8586"
"25.4000","12.7240","12.6439","8.4338","68.4847","256.8178"
"25.4400","12.7439","12.6638","8.4470","68.4775","256.7907"
"25.4800","12.7643","12.6842","8.4606","68.4733","256.7748"
"25.5200","12.7856","12.7055","8.4749","68.4722","256.7708"
"25.5600","12.8057","12.7256","8.4883","68.4632","256.7371"
"25.6000","12.8251","12.7450","8.5012","68.4492","256.6844"
"25.6400","12.8443","12.7642","8.5140","68.4338","256.6268"
"25.6800","12.8642","12.7841","8.5273","68.4283","256.6060"
"25.7200","12.8852","12.8051","8.5413","68.4231","256.5867"
"25.7600","12.9042","12.8241","8.5539","68.4050","256.5187"
"25.8000","12.9242","12.8441","8.5673","68.3985","256.4945"
"25.8400","12.9452","12.8651","8.5813","68.3955","256.4829"
"25.8800","12.9658","12.8857","8.5950","68.3841","256.4403"
"25.9200","12.9857","12.9057","8.6084","68.3697","256.3865"
"25.9490","12.9999","12.9198","8.6178","68.3585","256.3442"