File: data/instron_tests/metamaterials/250416/250416_1310_NSC_m1.is_comp_Exports/240416_1310_NSC_m1_5_1.csv
Results Table 1
,Compresson Axis,H*,V*,Height,Thickness,Width,Area,Fixture separation,Specimen label
,,,,(mm),(mm),(mm),(mm^2),(mm),
"5","X","","","150.00","28.00","150.00","4200.00","150.00","1310_NSC_m1"

Results Table 2
,Modulus (Segment 0 % - 2.5 %),Compresson Axis
,(kPa),
"5","1253.30","X"

Time,Displacement,Force,Compressive displacement,Compressive strain (Displacement),Compressive stress
(s),(mm),(N),(mm),(%),(kPa)
"0.0000","0.0000","-16.2293","0.0000","0.0000","-3.8641"
"0.0800","0.0011","-16.1730","0.0011","0.0008","-3.8507"
"0.1600","0.0172","-15.3881","0.0172","0.0114","-3.6638"
"0.2400","0.0376","-14.4539","0.0376","0.0250","-3.4414"
"0.3200","0.0582","-13.5445","0.0582","0.0388","-3.2249"
"0.4000","0.0768","-12.7583","0.0768","0.0512","-3.0377"
"0.4800","0.0977","-11.8822","0.0977","0.0651","-2.8291"
"0.5600","0.1181","-11.0548","0.1181","0.0787","-2.6321"
"0.6400","0.1377","-10.2649","0.1377","0.0918","-2.4440"
"0.7200","0.1572","-9.5003","0.1572","0.1048","-2.2620"
"0.8000","0.1769","-8.7303","0.1769","0.1179","-2.0786"
"0.8800","0.1973","-7.9150","0.1973","0.1316","-1.8845"
"0.9600","0.2175","-7.1547","0.2175","0.1450","-1.7035"
"1.0400","0.2360","-6.4536","0.2360","0.1573","-1.5366"
"1.1200","0.2569","-5.6404","0.2569","0.1713","-1.3430"
"1.2000","0.2776","-4.8713","0.2776","0.1850","-1.1598"
"1.2800","0.2980","-4.1048","0.2980","0.1986","-0.9773"
"1.3600","0.3177","-3.3692","0.3177","0.2118","-0.8022"
"1.4400","0.3364","-2.6945","0.3364","0.2242","-0.6416"
"1.5200","0.3564","-1.9648","0.3564","0.2376","-0.4678"
"1.6000","0.3768","-1.2067","0.3768","0.2512","-0.2873"
"1.6800","0.3973","-0.4432","0.3973","0.2649","-0.1055"
"1.7600","0.4185","0.3384","0.4185","0.2790","0.0806"
"1.8400","0.4376","1.0071","0.4376","0.2917","0.2398"
"1.9200","0.4575","1.7248","0.4575","0.3050","0.4107"
"2.0000","0.4775","2.4322","0.4775","0.3183","0.5791"
"2.0800","0.4969","3.1325","0.4969","0.3313","0.7458"
"2.1600","0.5173","3.8654","0.5173","0.3449","0.9203"
"2.2400","0.5365","4.5226","0.5365","0.3577","1.0768"
"2.3200","0.5557","5.1969","0.5557","0.3705","1.2373"
"2.4000","0.5776","5.9927","0.5776","0.3850","1.4268"
"2.4800","0.5976","6.6955","0.5976","0.3984","1.5942"
"2.5600","0.6180","7.4088","0.6180","0.4120","1.7640"
"2.6400","0.6372","8.0767","0.6372","0.4248","1.9230"
"2.7200","0.6560","8.7369","0.6560","0.4374","2.0802"
"2.8000","0.6766","9.4607","0.6766","0.4511","2.2526"
"2.8800","0.6971","10.1804","0.6971","0.4647","2.4239"
"2.9600","0.7174","10.8992","0.7174","0.4783","2.5951"
"3.0400","0.7381","11.6306","0.7381","0.4921","2.7692"
"3.1200","0.7572","12.2867","0.7572","0.5048","2.9254"
"3.2000","0.7778","13.0192","0.7778","0.5185","3.0998"
"3.2800","0.7972","13.6675","0.7972","0.5315","3.2542"
"3.3600","0.8171","14.3692","0.8171","0.5448","3.4212"
"3.4400","0.8367","15.0388","0.8367","0.5578","3.5807"
"3.5200","0.8558","15.6826","0.8558","0.5705","3.7340"
"3.6000","0.8770","16.3912","0.8770","0.5847","3.9027"
"3.6800","0.8983","17.0985","0.8983","0.5989","4.0711"
"3.7600","0.9179","17.7473","0.9179","0.6119","4.2255"
"3.8400","0.9373","18.3951","0.9373","0.6249","4.3798"
"3.9200","0.9558","18.9740","0.9558","0.6372","4.5176"
"4.0000","0.9762","19.6337","0.9762","0.6508","4.6747"
"4.0800","0.9975","20.3219","0.9975","0.6650","4.8386"
"4.1600","1.0166","20.9554","1.0166","0.6777","4.9894"
"4.2400","1.0378","21.6867","1.0378","0.6919","5.1635"
"4.3200","1.0579","22.3850","1.0579","0.7053","5.3298"
"4.4000","1.0779","23.0712","1.0779","0.7186","5.4931"
"4.4800","1.0974","23.7452","1.0974","0.7316","5.6536"
"4.5600","1.1164","24.3815","1.1164","0.7443","5.8051"
"4.6400","1.1372","25.1116","1.1372","0.7581","5.9789"
"4.7200","1.1571","25.7952","1.1571","0.7714","6.1417"
"4.8000","1.1762","26.4595","1.1762","0.7841","6.2999"
"4.8800","1.1973","27.2129","1.1973","0.7982","6.4793"
"4.9600","1.2178","27.9093","1.2178","0.8119","6.6451"
"5.0400","1.2377","28.5969","1.2377","0.8251","6.8088"
"5.1200","1.2571","29.2742","1.2571","0.8381","6.9701"
"5.2000","1.2762","29.9303","1.2762","0.8508","7.1263"
"5.2800","1.2971","30.6739","1.2971","0.8647","7.3033"
"5.3600","1.3173","31.3930","1.3173","0.8782","7.4745"
"5.4400","1.3370","32.0778","1.3370","0.8913","7.6376"
"5.5200","1.3576","32.8136","1.3576","0.9050","7.8128"
"5.6000","1.3774","33.5038","1.3774","0.9183","7.9771"
"5.6800","1.3980","34.2392","1.3980","0.9320","8.1522"
"5.7600","1.4179","34.9370","1.4179","0.9452","8.3183"
"5.8400","1.4366","35.5865","1.4366","0.9577","8.4730"
"5.9200","1.4570","36.3312","1.4570","0.9714","8.6503"
"6.0000","1.4761","36.9844","1.4761","0.9840","8.8058"
"6.0800","1.4976","37.7755","1.4976","0.9984","8.9942"
"6.1600","1.5182","38.5166","1.5182","1.0121","9.1706"
"6.2400","1.5372","39.1645","1.5372","1.0248","9.3249"
"6.3200","1.5569","39.8683","1.5569","1.0379","9.4924"
"6.4000","1.5768","40.5611","1.5768","1.0512","9.6574"
"6.4800","1.5963","41.2630","1.5963","1.0642","9.8245"
"6.5600","1.6176","42.0293","1.6176","1.0784","10.0070"
"6.6400","1.6363","42.6617","1.6363","1.0909","10.1576"
"6.7200","1.6574","43.4401","1.6574","1.1050","10.3429"
"6.8000","1.6780","44.1614","1.6780","1.1187","10.5146"
"6.8800","1.6976","44.8459","1.6976","1.1317","10.6776"
"6.9600","1.7177","45.5507","1.7177","1.1451","10.8454"
"7.0400","1.7372","46.2166","1.7372","1.1581","11.0040"
"7.1200","1.7566","46.8657","1.7566","1.1711","11.1585"
"7.2000","1.7775","47.6129","1.7775","1.1850","11.3364"
"7.2800","1.7964","48.2651","1.7964","1.1976","11.4917"
"7.3600","1.8172","49.0127","1.8172","1.2114","11.6697"
"7.4400","1.8376","49.7395","1.8376","1.2251","11.8427"
"7.5200","1.8576","50.4570","1.8576","1.2384","12.0136"
"7.6000","1.8775","51.0911","1.8775","1.2517","12.1645"
"7.6800","1.8963","51.7450","1.8963","1.2642","12.3202"
"7.7600","1.9172","52.5109","1.9172","1.2782","12.5026"
"7.8400","1.9371","53.2029","1.9371","1.2914","12.6674"
"7.9200","1.9566","53.8908","1.9566","1.3044","12.8311"
"8.0000","1.9772","54.6402","1.9772","1.3182","13.0096"
"8.0800","1.9981","55.3510","1.9981","1.3321","13.1788"
"8.1600","2.0178","56.0102","2.0178","1.3452","13.3358"
"8.2400","2.0378","56.7187","2.0378","1.3586","13.5045"
"8.3200","2.0560","57.3462","2.0560","1.3707","13.6539"
"8.4000","2.0774","58.1209","2.0774","1.3849","13.8383"
"8.4800","2.0969","58.8164","2.0969","1.3980","14.0039"
"8.5600","2.1168","59.5221","2.1168","1.4112","14.1719"
"8.6400","2.1370","60.2427","2.1370","1.4247","14.3435"
"8.7200","2.1572","60.9112","2.1572","1.4382","14.5027"
"8.8000","2.1776","61.6062","2.1776","1.4517","14.6681"
"8.8800","2.1981","62.3460","2.1981","1.4654","14.8443"
"8.9600","2.2167","62.9991","2.2167","1.4778","14.9998"
"9.0400","2.2368","63.7112","2.2368","1.4912","15.1693"
"9.1200","2.2559","64.3727","2.2559","1.5039","15.3268"
"9.2000","2.2771","65.1517","2.2771","1.5181","15.5123"
"9.2800","2.2987","65.9234","2.2987","1.5324","15.6960"
"9.3600","2.3180","66.5864","2.3180","1.5454","15.8539"
"9.4400","2.3373","67.1833","2.3373","1.5582","15.9960"
"9.5200","2.3575","67.9189","2.3575","1.5717","16.1712"
"9.6000","2.3768","68.6014","2.3768","1.5845","16.3337"
"9.6800","2.3970","69.3386","2.3970","1.5980","16.5092"
"9.7600","2.4164","70.0058","2.4164","1.6109","16.6680"
"9.8400","2.4370","70.7477","2.4370","1.6246","16.8447"
"9.9200","2.4578","71.4895","2.4578","1.6386","17.0213"
"10.0000","2.4771","72.1654","2.4771","1.6514","17.1822"
"10.0800","2.4976","72.8676","2.4976","1.6651","17.3494"
"10.1600","2.5168","73.4951","2.5168","1.6779","17.4988"
"10.2400","2.5370","74.2173","2.5370","1.6913","17.6708"
"10.3200","2.5567","74.9468","2.5567","1.7045","17.8445"
"10.4000","2.5768","75.6582","2.5768","1.7178","18.0138"
"10.4800","2.5974","76.4016","2.5974","1.7316","18.1909"
"10.5600","2.6184","77.1518","2.6184","1.7456","18.3695"
"10.6400","2.6375","77.8136","2.6375","1.7584","18.5270"
"10.7200","2.6574","78.5072","2.6574","1.7716","18.6922"
"10.8000","2.6766","79.1678","2.6766","1.7844","18.8495"
"10.8800","2.6975","79.8749","2.6975","1.7983","19.0178"
"10.9600","2.7175","80.5860","2.7175","1.8116","19.1872"
"11.0400","2.7360","81.2345","2.7360","1.8240","19.3415"
"11.1200","2.7567","81.9780","2.7567","1.8378","19.5186"
"11.2000","2.7777","82.7395","2.7777","1.8518","19.6999"
"11.2800","2.7977","83.4469","2.7977","1.8651","19.8683"
"11.3600","2.8175","84.1446","2.8175","1.8784","20.0344"
"11.4400","2.8361","84.7749","2.8361","1.8907","20.1845"
"11.5200","2.8569","85.5334","2.8569","1.9046","20.3651"
"11.6000","2.8774","86.2025","2.8774","1.9182","20.5244"
"11.6800","2.8965","86.8777","2.8965","1.9310","20.6852"
"11.7600","2.9177","87.6502","2.9177","1.9451","20.8691"
"11.8400","2.9374","88.3298","2.9374","1.9583","21.0309"
"11.9200","2.9581","89.0657","2.9581","1.9720","21.2061"
"12.0000","2.9774","89.7485","2.9774","1.9849","21.3687"
"12.0800","2.9970","90.4513","2.9970","1.9980","21.5360"
"12.1600","3.0173","91.1956","3.0173","2.0116","21.7132"
"12.2400","3.0369","91.8812","3.0369","2.0246","21.8765"
"12.3200","3.0563","92.5617","3.0563","2.0375","22.0385"
"12.4000","3.0778","93.3212","3.0778","2.0519","22.2193"
"12.4800","3.0973","93.9927","3.0973","2.0648","22.3792"
"12.5600","3.1179","94.7382","3.1179","2.0786","22.5567"
"12.6400","3.1373","95.4228","3.1373","2.0915","22.7197"
"12.7200","3.1565","96.1040","3.1565","2.1043","22.8819"
"12.8000","3.1765","96.8229","3.1765","2.1177","23.0531"
"12.8800","3.1968","97.5530","3.1968","2.1312","23.2269"
"12.9600","3.2174","98.2919","3.2174","2.1450","23.4028"
"13.0400","3.2384","99.0388","3.2384","2.1589","23.5807"
"13.1200","3.2570","99.6449","3.2570","2.1714","23.7250"
"13.2000","3.2774","100.3745","3.2774","2.1849","23.8987"
"13.2800","3.2976","101.1019","3.2976","2.1984","24.0719"
"13.3600","3.3173","101.7929","3.3173","2.2115","24.2364"
"13.4400","3.3368","102.4764","3.3368","2.2245","24.3991"
"13.5200","3.3554","103.1254","3.3554","2.2370","24.5537"
"13.6000","3.3770","103.9043","3.3770","2.2514","24.7391"
"13.6800","3.3983","104.6832","3.3983","2.2656","24.9246"
"13.7600","3.4177","105.3477","3.4177","2.2785","25.0828"
"13.8400","3.4371","106.0387","3.4371","2.2914","25.2473"
"13.9200","3.4564","106.6764","3.4564","2.3043","25.3991"
"14.0000","3.4768","107.4001","3.4768","2.3179","25.5714"
"14.0800","3.4974","108.1230","3.4974","2.3316","25.7436"
"14.1600","3.5162","108.7797","3.5162","2.3441","25.8999"
"14.2400","3.5380","109.5755","3.5380","2.3586","26.0894"
"14.3200","3.5578","110.2642","3.5578","2.3719","26.2534"
"14.4000","3.5778","110.9584","3.5778","2.3852","26.4187"
"14.4800","3.5973","111.6511","3.5973","2.3982","26.5836"
"14.5600","3.6170","112.3383","3.6170","2.4114","26.7472"
"14.6400","3.6371","113.0481","3.6371","2.4247","26.9162"
"14.7200","3.6569","113.7399","3.6569","2.4380","27.0809"
"14.8000","3.6759","114.3965","3.6759","2.4506","27.2373"
"14.8800","3.6972","115.1536","3.6972","2.4648","27.4175"
"14.9600","3.7173","115.8569","3.7173","2.4782","27.5850"
"15.0400","3.7376","116.5821","3.7376","2.4917","27.7576"
"15.1200","3.7573","117.2594","3.7573","2.5049","27.9189"
"15.2000","3.7760","117.9064","3.7760","2.5174","28.0730"
"15.2800","3.7971","118.6633","3.7971","2.5314","28.2532"
"15.3600","3.8173","119.3762","3.8173","2.5449","28.4229"
"15.4400","3.8371","120.0699","3.8371","2.5581","28.5881"
"15.5200","3.8578","120.8110","3.8578","2.5719","28.7645"
"15.6000","3.8776","121.4915","3.8776","2.5851","28.9266"
"15.6800","3.8978","122.2060","3.8978","2.5985","29.0967"
"15.7600","3.9179","122.8883","3.9179","2.6119","29.2591"
"15.8400","3.9365","123.5186","3.9365","2.6244","29.4092"
"15.9200","3.9568","124.2316","3.9568","2.6378","29.5790"
"16.0000","3.9763","124.9096","3.9763","2.6508","29.7404"
"16.0800","3.9972","125.6679","3.9972","2.6648","29.9209"
"16.1600","4.0180","126.4042","4.0180","2.6787","30.0962"
"16.2400","4.0373","127.0537","4.0373","2.6916","30.2509"
"16.3200","4.0568","127.7340","4.0568","2.7045","30.4129"
"16.4000","4.0770","128.4466","4.0770","2.7180","30.5825"
"16.4800","4.0964","129.1217","4.0964","2.7310","30.7433"
"16.5600","4.1175","129.8772","4.1175","2.7450","30.9232"
"16.6400","4.1362","130.4991","4.1362","2.7575","31.0712"
"16.7200","4.1576","131.2559","4.1576","2.7717","31.2514"
"16.8000","4.1775","131.9489","4.1775","2.7850","31.4164"
"16.8800","4.1980","132.6377","4.1980","2.7986","31.5804"
"16.9600","4.2175","133.3256","4.2175","2.8117","31.7442"
"17.0400","4.2372","133.9992","4.2372","2.8248","31.9046"
"17.1200","4.2567","134.6705","4.2567","2.8378","32.0644"
"17.2000","4.2770","135.3857","4.2770","2.8513","32.2347"
"17.2800","4.2960","136.0246","4.2960","2.8640","32.3868"
"17.3600","4.3175","136.8079","4.3175","2.8784","32.5733"
"17.4400","4.3378","137.5049","4.3378","2.8919","32.7393"
"17.5200","4.3570","138.1634","4.3570","2.9046","32.8960"
"17.6000","4.3772","138.8643","4.3772","2.9181","33.0629"
"17.6800","4.3967","139.5316","4.3967","2.9311","33.2218"
"17.7600","4.4175","140.2580","4.4175","2.9450","33.3948"
"17.8400","4.4372","140.9396","4.4372","2.9581","33.5570"
"17.9200","4.4564","141.5873","4.4564","2.9710","33.7113"
"18.0000","4.4772","142.3107","4.4772","2.9848","33.8835"
"18.0800","4.4980","143.0322","4.4980","2.9986","34.0553"
"18.1600","4.5179","143.7161","4.5179","3.0119","34.2181"
"18.2400","4.5375","144.3889","4.5375","3.0250","34.3783"
"18.3200","4.5561","145.0067","4.5561","3.0374","34.5254"
"18.4000","4.5773","145.7726","4.5773","3.0516","34.7078"
"18.4800","4.5968","146.4389","4.5968","3.0645","34.8664"
"18.5600","4.6167","147.1419","4.6167","3.0778","35.0338"
"18.6400","4.6370","147.8418","4.6370","3.0913","35.2004"
"18.7200","4.6575","148.5704","4.6575","3.1050","35.3739"
"18.8000","4.6773","149.2241","4.6773","3.1182","35.5296"
"18.8800","4.6978","149.9526","4.6978","3.1319","35.7030"
"18.9600","4.7161","150.5525","4.7161","3.1440","35.8458"
"19.0400","4.7364","151.2578","4.7364","3.1576","36.0138"
"19.1200","4.7565","151.9194","4.7565","3.1710","36.1713"
"19.2000","4.7773","152.6516","4.7773","3.1849","36.3456"
"19.2800","4.7985","153.3983","4.7985","3.1990","36.5234"
"19.3600","4.8180","154.0506","4.8180","3.2120","36.6787"
"19.4400","4.8379","154.7116","4.8379","3.2252","36.8361"
"19.5200","4.8576","155.3773","4.8576","3.2384","36.9946"
"19.6000","4.8768","156.0231","4.8768","3.2512","37.1483"
"19.6800","4.8968","156.7360","4.8968","3.2645","37.3181"
"19.7600","4.9167","157.4103","4.9167","3.2778","37.4786"
"19.8400","4.9371","158.1259","4.9371","3.2914","37.6490"
"19.9200","4.9579","158.8383","4.9579","3.3053","37.8186"
"20.0000","4.9771","159.4959","4.9771","3.3181","37.9752"
"20.0800","4.9976","160.1894","4.9976","3.3317","38.1403"
"20.1600","5.0168","160.8359","5.0168","3.3445","38.2943"
"20.2400","5.0369","161.5314","5.0369","3.3579","38.4599"
"20.3200","5.0566","162.1881","5.0566","3.3710","38.6162"
"20.4000","5.0767","162.8459","5.0767","3.3845","38.7728"
"20.4800","5.0975","163.5818","5.0975","3.3984","38.9480"
"20.5600","5.1183","164.2943","5.1183","3.4122","39.1177"
"20.6400","5.1374","164.9313","5.1374","3.4249","39.2694"
"20.7200","5.1571","165.6090","5.1571","3.4381","39.4307"
"20.8000","5.1764","166.2477","5.1764","3.4510","39.5828"
"20.8800","5.1974","166.9906","5.1974","3.4649","39.7597"
"20.9600","5.2172","167.6596","5.2172","3.4781","39.9189"
"21.0400","5.2362","168.2921","5.2362","3.4908","40.0695"
"21.1200","5.2568","169.0047","5.2568","3.5046","40.2392"
"21.2000","5.2775","169.7195","5.2775","3.5183","40.4094"
"21.2800","5.2978","170.4030","5.2978","3.5319","40.5721"
"21.3600","5.3177","171.0741","5.3177","3.5452","40.7319"
"21.4400","5.3360","171.6517","5.3360","3.5573","40.8694"
"21.5200","5.3565","172.3657","5.3565","3.5710","41.0395"
"21.6000","5.3771","173.0615","5.3771","3.5847","41.2051"
"21.6800","5.3971","173.7424","5.3971","3.5981","41.3672"
"21.7600","5.4182","174.4666","5.4182","3.6121","41.5397"
"21.8400","5.4375","175.0922","5.4375","3.6250","41.6886"
"21.9200","5.4577","175.7673","5.4577","3.6385","41.8493"
"22.0000","5.4775","176.4266","5.4775","3.6516","42.0063"
"22.0800","5.4968","177.0665","5.4968","3.6645","42.1587"
"22.1600","5.5171","177.7713","5.5171","3.6781","42.3265"
"22.2400","5.5368","178.4020","5.5368","3.6912","42.4767"
"22.3200","5.5562","179.0637","5.5562","3.7041","42.6342"
"22.4000","5.5776","179.8051","5.5776","3.7184","42.8107"
"22.4800","5.5971","180.4444","5.5971","3.7314","42.9630"
"22.5600","5.6181","181.1571","5.6181","3.7454","43.1326"
"22.6400","5.6373","181.7913","5.6373","3.7582","43.2836"
"22.7200","5.6564","182.4205","5.6564","3.7710","43.4334"
"22.8000","5.6763","183.0910","5.6763","3.7842","43.5931"
"22.8800","5.6969","183.7829","5.6969","3.7979","43.7578"
"22.9600","5.7175","184.4656","5.7175","3.8117","43.9204"
"23.0400","5.7379","185.1610","5.7379","3.8253","44.0859"
"23.1200","5.7568","185.7545","5.7568","3.8379","44.2273"
"23.2000","5.7780","186.5002","5.7780","3.8520","44.4048"
"23.2800","5.7976","187.1180","5.7976","3.8651","44.5519"
"23.3600","5.8172","187.7721","5.8172","3.8781","44.7077"
"23.4400","5.8370","188.4148","5.8370","3.8913","44.8607"
"23.5200","5.8557","189.0122","5.8557","3.9038","45.0029"
"23.6000","5.8771","189.7608","5.8771","3.9181","45.1811"
"23.6800","5.8984","190.5048","5.8984","3.9323","45.3583"
"23.7600","5.9179","191.1311","5.9179","3.9452","45.5074"
"23.8400","5.9370","191.7358","5.9370","3.9580","45.6514"
"23.9200","5.9563","192.3497","5.9563","3.9709","45.7975"
"24.0000","5.9766","193.0341","5.9766","3.9844","45.9605"
"24.0800","5.9979","193.7421","5.9979","3.9986","46.1291"
"24.1600","6.0164","194.3107","6.0164","4.0109","46.2644"
"24.2400","6.0376","195.0175","6.0376","4.0251","46.4327"
"24.3200","6.0577","195.6544","6.0577","4.0385","46.5844"
"24.4000","6.0781","196.3243","6.0781","4.0521","46.7439"
"24.4800","6.0975","196.9439","6.0975","4.0650","46.8914"
"24.5600","6.1171","197.5584","6.1171","4.0781","47.0377"
"24.6400","6.1371","198.2168","6.1371","4.0914","47.1945"
"24.7200","6.1573","198.8586","6.1573","4.1049","47.3473"
"24.8000","6.1755","199.4354","6.1755","4.1170","47.4846"
"24.8800","6.1977","200.1999","6.1977","4.1318","47.6666"
"24.9600","6.2176","200.8142","6.2176","4.1451","47.8129"
"25.0400","6.2376","201.4559","6.2376","4.1584","47.9657"
"25.1200","6.2570","202.0763","6.2570","4.1713","48.1134"
"25.2000","6.2762","202.6889","6.2762","4.1841","48.2593"
"25.2800","6.2972","203.3806","6.2972","4.1981","48.4239"
"25.3600","6.3171","204.0142","6.3171","4.2114","48.5748"
"25.4400","6.3371","204.6466","6.3371","4.2247","48.7254"
"25.5200","6.3573","205.3040","6.3573","4.2382","48.8819"
"25.6000","6.3778","205.9659","6.3778","4.2518","49.0395"
"25.6800","6.3977","206.5922","6.3977","4.2651","49.1886"
"25.7600","6.4179","207.2394","6.4179","4.2786","49.3427"
"25.8400","6.4366","207.8198","6.4366","4.2911","49.4809"
"25.9200","6.4571","208.4923","6.4571","4.3047","49.6410"
"26.0000","6.4760","209.0659","6.4760","4.3173","49.7776"
"26.0800","6.4973","209.7786","6.4973","4.3315","49.9473"
"26.1600","6.5182","210.4616","6.5182","4.3455","50.1099"
"26.2400","6.5374","211.0507","6.5374","4.3583","50.2502"
"26.3200","6.5572","211.6675","6.5572","4.3715","50.3970"
"26.4000","6.5771","212.2915","6.5771","4.3847","50.5456"
"26.4800","6.5963","212.8987","6.5963","4.3976","50.6902"
"26.5600","6.6174","213.5840","6.6174","4.4116","50.8533"
"26.6400","6.6363","214.1423","6.6363","4.4242","50.9863"
"26.7200","6.6574","214.8364","6.6574","4.4383","51.1515"
"26.8000","6.6782","215.3895","6.6782","4.4521","51.2832"
"26.8800","6.6981","215.9266","6.6981","4.4654","51.4111"
"26.9600","6.7175","216.5168","6.7175","4.4783","51.5516"
"27.0400","6.7371","217.1290","6.7371","4.4914","51.6974"
"27.1200","6.7569","217.7498","6.7569","4.5046","51.8452"
"27.2000","6.7771","218.3744","6.7771","4.5180","51.9939"
"27.2800","6.7958","218.9313","6.7958","4.5305","52.1265"
"27.3600","6.8174","219.6450","6.8174","4.5449","52.2964"
"27.4400","6.8380","220.2877","6.8380","4.5586","52.4495"
"27.5200","6.8576","220.8861","6.8576","4.5717","52.5919"
"27.6000","6.8771","221.4829","6.8771","4.5847","52.7340"
"27.6800","6.8966","222.0744","6.8966","4.5977","52.8749"
"27.7600","6.9176","222.7361","6.9176","4.6118","53.0324"
"27.8400","6.9370","223.3012","6.9370","4.6246","53.1670"
"27.9200","6.9562","223.8871","6.9562","4.6374","53.3065"
"28.0000","6.9773","224.5713","6.9773","4.6515","53.4694"
"28.0800","6.9985","225.2404","6.9985","4.6657","53.6287"
"28.1600","7.0178","225.8145","7.0178","4.6785","53.7653"
"28.2400","7.0371","226.3863","7.0371","4.6914","53.9015"
"28.3200","7.0563","226.9641","7.0563","4.7042","54.0391"
"28.4000","7.0773","227.6358","7.0773","4.7182","54.1990"
"28.4800","7.0969","228.2218","7.0969","4.7312","54.3385"
"28.5600","7.1168","228.8388","7.1168","4.7445","54.4854"
"28.6400","7.1370","229.4499","7.1370","4.7580","54.6309"
"28.7200","7.1572","230.0567","7.1572","4.7715","54.7754"
"28.8000","7.1773","230.6618","7.1773","4.7848","54.9195"
"28.8800","7.1981","231.2991","7.1981","4.7987","55.0712"
"28.9600","7.2167","231.8301","7.2167","4.8111","55.1977"
"29.0400","7.2368","232.4474","7.2368","4.8246","55.3446"
"29.1200","7.2561","233.0007","7.2561","4.8374","55.4764"
"29.2000","7.2772","233.6743","7.2772","4.8515","55.6367"
"29.2800","7.2987","234.3284","7.2987","4.8658","55.7925"
"29.3600","7.3180","234.8954","7.3180","4.8787","55.9275"
"29.4400","7.3378","235.4705","7.3378","4.8918","56.0644"
"29.5200","7.3572","236.0304","7.3572","4.9048","56.1977"
"29.6000","7.3766","236.6056","7.3766","4.9177","56.3347"
"29.6800","7.3971","237.2244","7.3971","4.9314","56.4820"
"29.7600","7.4165","237.7768","7.4165","4.9443","56.6135"
"29.8400","7.4368","238.3864","7.4368","4.9579","56.7587"
"29.9200","7.4580","239.0367","7.4580","4.9720","56.9135"
"30.0000","7.4774","239.5933","7.4774","4.9849","57.0460"
"30.0800","7.4979","240.1972","7.4979","4.9986","57.1898"
"30.1600","7.5165","240.7063","7.5165","5.0110","57.3110"
"30.2400","7.5371","241.3226","7.5371","5.0247","57.4578"
"30.3200","7.5567","241.8871","7.5567","5.0378","57.5922"
"30.4000","7.5763","242.4479","7.5763","5.0509","57.7257"
"30.4800","7.5973","243.0816","7.5973","5.0649","57.8766"
"30.5600","7.6186","243.7228","7.6186","5.0790","58.0292"
"30.6400","7.6381","244.2895","7.6381","5.0921","58.1642"
"30.7200","7.6576","244.8265","7.6576","5.1051","58.2920"
"30.8000","7.6764","245.3374","7.6764","5.1176","58.4137"
"30.8800","7.6974","245.9703","7.6974","5.1316","58.5644"
"30.9600","7.7175","246.5328","7.7175","5.1450","58.6983"
"31.0400","7.7361","247.0492","7.7361","5.1574","58.8212"
"31.1200","7.7570","247.6574","7.7570","5.1713","58.9660"
"31.2000","7.7775","248.2611","7.7775","5.1850","59.1098"
"31.2800","7.7978","248.8424","7.7978","5.1986","59.2482"
"31.3600","7.8180","249.4128","7.8180","5.2120","59.3840"
"31.4400","7.8363","249.8782","7.8363","5.2242","59.4948"
"31.5200","7.8565","250.4563","7.8565","5.2376","59.6325"
"31.6000","7.8769","251.0265","7.8769","5.2513","59.7682"
"31.6800","7.8969","251.6064","7.8969","5.2646","59.9063"
"31.7600","7.9181","252.2137","7.9181","5.2788","60.0509"
"31.8400","7.9378","252.7435","7.9378","5.2918","60.1770"
"31.9200","7.9581","253.3086","7.9581","5.3054","60.3116"
"32.0000","7.9774","253.8409","7.9774","5.3183","60.4383"
"32.0800","7.9969","254.3735","7.9969","5.3313","60.5651"
"32.1600","8.0171","254.9351","8.0171","5.3447","60.6988"
"32.2400","8.0366","255.4452","8.0366","5.3577","60.8203"
"32.3200","8.0557","255.9672","8.0557","5.3704","60.9446"
"32.4000","8.0775","256.6006","8.0775","5.3850","61.0954"
"32.4800","8.0971","257.1185","8.0971","5.3981","61.2187"
"32.5600","8.1182","257.7234","8.1182","5.4122","61.3627"
"32.6400","8.1373","258.1973","8.1373","5.4249","61.4756"
"32.7200","8.1564","258.7065","8.1564","5.4376","61.5968"
"32.8000","8.1764","259.2597","8.1764","5.4509","61.7285"
"32.8800","8.1968","259.8126","8.1968","5.4646","61.8601"
"32.9600","8.2174","260.3775","8.2174","5.4783","61.9946"
"33.0400","8.2380","260.9374","8.2380","5.4920","62.1279"
"33.1200","8.2569","261.4103","8.2569","5.5046","62.2406"
"33.2000","8.2777","261.9958","8.2777","5.5185","62.3799"
"33.2800","8.2975","262.5072","8.2975","5.5317","62.5017"
"33.3600","8.3176","263.0618","8.3176","5.5450","62.6338"
"33.4400","8.3369","263.5562","8.3369","5.5579","62.7515"
"33.5200","8.3558","264.0423","8.3558","5.5705","62.8672"
"33.6000","8.3768","264.6161","8.3768","5.5845","63.0038"
"33.6800","8.3981","265.2060","8.3981","5.5987","63.1443"
"33.7600","8.4178","265.7083","8.4178","5.6118","63.2639"
"33.8400","8.4371","266.1993","8.4371","5.6247","63.3808"
"33.9200","8.4565","266.6771","8.4565","5.6377","63.4945"
"34.0000","8.4766","267.2062","8.4766","5.6511","63.6205"
"34.0800","8.4976","267.7701","8.4976","5.6651","63.7548"
"34.1600","8.5165","268.2410","8.5165","5.6777","63.8669"
"34.2400","8.5377","268.8156","8.5377","5.6918","64.0037"
"34.3200","8.5576","269.3192","8.5576","5.7051","64.1236"
"34.4000","8.5778","269.8228","8.5778","5.7185","64.2435"
"34.4800","8.5974","270.3125","8.5974","5.7316","64.3601"
"34.5600","8.6169","270.7696","8.6169","5.7446","64.4689"
"34.6400","8.6371","271.2637","8.6371","5.7580","64.5866"
"34.7200","8.6573","271.7382","8.6573","5.7715","64.6996"
"34.8000","8.6760","272.1223","8.6760","5.7840","64.7910"
"34.8800","8.6973","272.6456","8.6973","5.7982","64.9156"
"34.9600","8.7175","273.1090","8.7175","5.8116","65.0259"
"35.0400","8.7379","273.6042","8.7379","5.8252","65.1438"
"35.1200","8.7573","274.0574","8.7573","5.8382","65.2518"
"35.2000","8.7762","274.4937","8.7762","5.8508","65.3556"
"35.2800","8.7970","275.0221","8.7970","5.8647","65.4814"
"35.3600","8.8165","275.4789","8.8165","5.8777","65.5902"
"35.4400","8.8367","275.9930","8.8367","5.8911","65.7126"
"35.5200","8.8580","276.5616","8.8580","5.9053","65.8480"
"35.6000","8.8777","277.0268","8.8777","5.9184","65.9588"
"35.6800","8.8980","277.5289","8.8980","5.9320","66.0783"
"35.7600","8.9179","278.0140","8.9179","5.9453","66.1938"
"35.8400","8.9366","278.4422","8.9366","5.9577","66.2958"
"35.9200","8.9568","278.9545","8.9568","5.9712","66.4177"
"36.0000","8.9762","279.4109","8.9762","5.9841","66.5264"
"36.0800","8.9971","279.9428","8.9971","5.9981","66.6530"
"36.1600","9.0179","280.4562","9.0179","6.0120","66.7753"
"36.2400","9.0377","280.9225","9.0377","6.0251","66.8863"
"36.3200","9.0569","281.3672","9.0569","6.0379","66.9922"
"36.4000","9.0770","281.8484","9.0770","6.0513","67.1068"
"36.4800","9.0968","282.3328","9.0968","6.0645","67.2221"
"36.5600","9.1174","282.8333","9.1174","6.0782","67.3413"
"36.6400","9.1360","283.2314","9.1360","6.0906","67.4361"
"36.7200","9.1576","283.7895","9.1576","6.1051","67.5689"
"36.8000","9.1785","284.3051","9.1785","6.1190","67.6917"
"36.8800","9.1980","284.7391","9.1980","6.1320","67.7950"
"36.9600","9.2174","285.1847","9.2174","6.1449","67.9011"
"37.0400","9.2370","285.6250","9.2370","6.1580","68.0059"
"37.1200","9.2569","286.0870","9.2569","6.1713","68.1159"
"37.2000","9.2770","286.5639","9.2770","6.1846","68.2295"
"37.2800","9.2958","286.9640","9.2958","6.1972","68.3248"
"37.3600","9.3171","287.4995","9.3171","6.2114","68.4523"
"37.4400","9.3382","287.9981","9.3382","6.2254","68.5710"
"37.5200","9.3576","288.4231","9.3576","6.2384","68.6722"
"37.6000","9.3770","288.8433","9.3770","6.2513","68.7722"
"37.6800","9.3963","289.2615","9.3963","6.2642","68.8718"
"37.7600","9.4172","289.7672","9.4172","6.2782","68.9922"
"37.8400","9.4371","290.2060","9.4371","6.2914","69.0967"
"37.9200","9.4567","290.6414","9.4567","6.3045","69.2003"
"38.0000","9.4776","291.1305","9.4776","6.3184","69.3168"
"38.0800","9.4983","291.5930","9.4983","6.3322","69.4269"
"38.1600","9.5177","292.0021","9.5177","6.3451","69.5243"
"38.2400","9.5375","292.4248","9.5375","6.3583","69.6249"
"38.3200","9.5562","292.7935","9.5562","6.3708","69.7127"
"38.4000","9.5773","293.2838","9.5773","6.3849","69.8295"
"38.4800","9.5967","293.6852","9.5967","6.3978","69.9250"
"38.5600","9.6171","294.1498","9.6171","6.4114","70.0357"
"38.6400","9.6370","294.5759","9.6370","6.4247","70.1371"
"38.7200","9.6572","294.9989","9.6572","6.4381","70.2378"
"38.8000","9.6774","295.4326","9.6774","6.4516","70.3411"
"38.8800","9.6979","295.8723","9.6979","6.4652","70.4458"
"38.9600","9.7166","296.2462","9.7166","6.4777","70.5348"
"39.0400","9.7371","296.6930","9.7371","6.4914","70.6412"
"39.1200","9.7562","297.0628","9.7562","6.5041","70.7292"
"39.2000","9.7771","297.5679","9.7771","6.5181","70.8495"
"39.2800","9.7983","298.0320","9.7983","6.5322","70.9600"
"39.3600","9.8177","298.4284","9.8177","6.5451","71.0544"
"39.4400","9.8375","298.8304","9.8375","6.5583","71.1501"
"39.5200","9.8573","299.2335","9.8573","6.5715","71.2461"
"39.6000","9.8769","299.6523","9.8769","6.5846","71.3458"
"39.6800","9.8968","300.0663","9.8968","6.5979","71.4444"
"39.7600","9.9163","300.4398","9.9163","6.6109","71.5333"
"39.8400","9.9369","300.8937","9.9369","6.6246","71.6414"
"39.9200","9.9577","301.3306","9.9577","6.6384","71.7454"
"40.0000","9.9770","301.7293","9.9770","6.6513","71.8403"
"40.0800","9.9982","302.1776","9.9982","6.6654","71.9470"
"40.1600","10.0168","302.5129","10.0168","6.6779","72.0269"
"40.2400","10.0369","302.9265","10.0369","6.6913","72.1253"
"40.3200","10.0565","303.3201","10.0565","6.7043","72.2191"
"40.4000","10.0767","303.7241","10.0767","6.7178","72.3153"
"40.4800","10.0978","304.1817","10.0978","6.7319","72.4242"
"40.5600","10.1189","304.6093","10.1189","6.7459","72.5260"
"40.6400","10.1371","304.9219","10.1371","6.7581","72.6005"
"40.7200","10.1572","305.3255","10.1572","6.7714","72.6965"
"40.8000","10.1769","305.6915","10.1769","6.7846","72.7837"
"40.8800","10.1976","306.1193","10.1976","6.7984","72.8856"
"40.9600","10.2172","306.4762","10.2172","6.8115","72.9705"
"41.0400","10.2362","306.8306","10.2362","6.8241","73.0549"
"41.1200","10.2564","307.2149","10.2564","6.8376","73.1464"
"41.2000","10.2775","307.6418","10.2775","6.8517","73.2481"
"41.2800","10.2980","308.0235","10.2980","6.8653","73.3389"
"41.3600","10.3180","308.1839","10.3180","6.8787","73.3771"
"41.4400","10.3364","308.3709","10.3364","6.8909","73.4216"
"41.5200","10.3565","308.7266","10.3565","6.9043","73.5063"
"41.6000","10.3771","309.0842","10.3771","6.9180","73.5915"
"41.6800","10.3968","309.4408","10.3968","6.9312","73.6764"
"41.7600","10.4183","309.8483","10.4183","6.9455","73.7734"
"41.8400","10.4377","310.1749","10.4377","6.9584","73.8512"
"41.9200","10.4581","310.5182","10.4581","6.9721","73.9329"
"42.0000","10.4774","310.8354","10.4774","6.9849","74.0084"
"42.0800","10.4968","311.1753","10.4968","6.9979","74.0894"
"42.1600","10.5167","311.5386","10.5167","7.0111","74.1759"
"42.2400","10.5364","311.8784","10.5364","7.0243","74.2568"
"42.3200","10.5564","312.2426","10.5564","7.0376","74.3435"
"42.4000","10.5774","312.6349","10.5774","7.0516","74.4369"
"42.4800","10.5973","312.9778","10.5973","7.0648","74.5185"
"42.5600","10.6183","313.3591","10.6183","7.0789","74.6093"
"42.6400","10.6374","313.6632","10.6374","7.0916","74.6817"
"42.7200","10.6564","313.9796","10.6564","7.1043","74.7571"
"42.8000","10.6763","314.3273","10.6763","7.1176","74.8398"
"42.8800","10.6970","314.7054","10.6970","7.1314","74.9299"
"42.9600","10.7175","315.0606","10.7175","7.1450","75.0144"
"43.0400","10.7382","315.4244","10.7382","7.1588","75.1010"
"43.1200","10.7568","315.7055","10.7568","7.1712","75.1680"
"43.2000","10.7780","316.0938","10.7780","7.1853","75.2604"
"43.2800","10.7976","316.4043","10.7976","7.1984","75.3344"
"43.3600","10.8174","316.7437","10.8174","7.2116","75.4152"
"43.4400","10.8370","317.0501","10.8370","7.2247","75.4881"
"43.5200","10.8556","317.3163","10.8556","7.2370","75.5515"
"43.6000","10.8771","317.7225","10.8771","7.2514","75.6482"
"43.6800","10.8984","318.1207","10.8984","7.2656","75.7430"
"43.7600","10.9182","318.4276","10.9182","7.2788","75.8161"
"43.8400","10.9372","318.7110","10.9372","7.2915","75.8836"
"43.9200","10.9563","318.9921","10.9563","7.3042","75.9505"
"44.0000","10.9760","319.3163","10.9760","7.3174","76.0277"
"44.0800","10.9977","319.7076","10.9977","7.3318","76.1209"
"44.1600","11.0169","319.9793","11.0169","7.3446","76.1856"
"44.2400","11.0377","320.3167","11.0377","7.3584","76.2659"
"44.3200","11.0575","320.6243","11.0575","7.3717","76.3391"
"44.4000","11.0781","320.9648","11.0781","7.3854","76.4202"
"44.4800","11.0973","321.2468","11.0973","7.3982","76.4873"
"44.5600","11.1170","321.5394","11.1170","7.4113","76.5570"
"44.6400","11.1369","321.8412","11.1369","7.4246","76.6289"
"44.7200","11.1572","322.1487","11.1572","7.4381","76.7021"
"44.8000","11.1760","322.4170","11.1760","7.4507","76.7659"
"44.8800","11.1975","322.7908","11.1975","7.4650","76.8549"
"44.9600","11.2175","323.0818","11.2175","7.4784","76.9242"
"45.0400","11.2372","323.3589","11.2372","7.4915","76.9902"
"45.1200","11.2568","323.6382","11.2568","7.5045","77.0567"
"45.2000","11.2765","323.9298","11.2765","7.5177","77.1262"
"45.2800","11.2968","324.2165","11.2968","7.5312","77.1944"
"45.3600","11.3172","324.5320","11.3172","7.5448","77.2695"
"45.4400","11.3372","324.8353","11.3372","7.5582","77.3417"
"45.5200","11.3580","325.1668","11.3580","7.5720","77.4207"
"45.6000","11.3778","325.4278","11.3778","7.5852","77.4828"
"45.6800","11.3979","325.7079","11.3979","7.5986","77.5495"
"45.7600","11.4180","325.9889","11.4180","7.6120","77.6164"
"45.8400","11.4366","326.2285","11.4366","7.6244","77.6734"
"45.9200","11.4568","326.5213","11.4568","7.6379","77.7432"
"46.0000","11.4760","326.7597","11.4760","7.6506","77.7999"
"46.0800","11.4973","327.0964","11.4973","7.6649","77.8801"
"46.1600","11.5177","327.3783","11.5177","7.6784","77.9472"
"46.2400","11.5378","327.6464","11.5378","7.6918","78.0110"
"46.3200","11.5572","327.8784","11.5572","7.7048","78.0663"
"46.4000","11.5769","328.1321","11.5769","7.7179","78.1267"
"46.4800","11.5963","328.3785","11.5963","7.7308","78.1853"
"46.5600","11.6175","328.6819","11.6175","7.7450","78.2576"
"46.6400","11.6364","328.8962","11.6364","7.7576","78.3086"
"46.7200","11.6576","329.2066","11.6576","7.7718","78.3825"
"46.8000","11.6783","329.4793","11.6783","7.7855","78.4475"
"46.8800","11.6978","329.7140","11.6978","7.7986","78.5033"
"46.9600","11.7172","329.9340","11.7172","7.8114","78.5557"
"47.0400","11.7371","330.1706","11.7371","7.8248","78.6120"
"47.1200","11.7570","330.4099","11.7570","7.8380","78.6690"
"47.2000","11.7771","330.6552","11.7771","7.8514","78.7274"
"47.2800","11.7959","330.8368","11.7959","7.8639","78.7707"
"47.3600","11.8166","331.1096","11.8166","7.8777","78.8356"
"47.4400","11.8378","331.3860","11.8378","7.8919","78.9014"
"47.5200","11.8576","331.6127","11.8576","7.9051","78.9554"
"47.6000","11.8774","331.8339","11.8774","7.9183","79.0081"
"47.6800","11.8964","332.0164","11.8964","7.9309","79.0515"
"47.7600","11.9174","332.2647","11.9174","7.9449","79.1107"
"47.8400","11.9370","332.4742","11.9370","7.9580","79.1605"
"47.9200","11.9565","332.6641","11.9565","7.9710","79.2057"
"48.0000","11.9776","332.9357","11.9776","7.9851","79.2704"
"48.0800","11.9986","333.1729","11.9986","7.9991","79.3269"
"48.1600","12.0179","333.3645","12.0179","8.0120","79.3725"
"48.2400","12.0375","333.5615","12.0375","8.0250","79.4194"
"48.3200","12.0560","333.7191","12.0560","8.0374","79.4569"
"48.4000","12.0773","333.9864","12.0773","8.0516","79.5206"
"48.4800","12.0970","334.1938","12.0970","8.0647","79.5700"
"48.5600","12.1172","334.4242","12.1172","8.0781","79.6248"
"48.6400","12.1370","334.6367","12.1370","8.0914","79.6754"
"48.7200","12.1579","334.8750","12.1579","8.1052","79.7321"
"48.8000","12.1775","335.0560","12.1775","8.1183","79.7752"
"48.8800","12.1975","335.2701","12.1975","8.1317","79.8262"
"48.9600","12.2165","335.4433","12.2165","8.1443","79.8675"
"49.0400","12.2369","335.6693","12.2369","8.1580","79.9213"
"49.1200","12.2564","335.8528","12.2564","8.1709","79.9649"
"49.2000","12.2772","336.0965","12.2772","8.1848","80.0230"
"49.2800","12.2984","336.3286","12.2984","8.1990","80.0782"
"49.3600","12.3181","336.5130","12.3181","8.2121","80.1221"
"49.4400","12.3378","336.6855","12.3378","8.2252","80.1632"
"49.5200","12.3571","336.8593","12.3571","8.2381","80.2046"
"49.6000","12.3764","337.0392","12.3764","8.2509","80.2474"
"49.6800","12.3964","337.2364","12.3964","8.2642","80.2944"
"49.7600","12.4162","337.4049","12.4162","8.2775","80.3345"
"49.8400","12.4369","337.6490","12.4369","8.2913","80.3926"
"49.9200","12.4583","337.8883","12.4583","8.3055","80.4496"
"50.0000","12.4771","338.0301","12.4771","8.3181","80.4833"
"50.0800","12.4980","338.2448","12.4980","8.3320","80.5345"
"50.1600","12.5169","338.3679","12.5169","8.3446","80.5638"
"50.2400","12.5369","338.5619","12.5369","8.3579","80.6100"
"50.3200","12.5564","338.7184","12.5564","8.3710","80.6472"
"50.4000","12.5764","338.8960","12.5764","8.3843","80.6895"
"50.4800","12.5973","339.1130","12.5973","8.3982","80.7412"
"50.5600","12.6189","339.3565","12.6189","8.4126","80.7992"
"50.6400","12.6378","339.4816","12.6378","8.4252","80.8290"
"50.7200","12.6574","339.6262","12.6574","8.4382","80.8634"
"50.8000","12.6764","339.7627","12.6764","8.4510","80.8959"
"50.8800","12.6975","339.9738","12.6975","8.4650","80.9461"
"50.9600","12.7172","340.1180","12.7172","8.4781","80.9805"
"51.0400","12.7359","340.2415","12.7359","8.4906","81.0099"
"51.1200","12.7567","340.4588","12.7567","8.5045","81.0616"
"51.2000","12.7778","340.6555","12.7778","8.5185","81.1085"
"51.2800","12.7981","340.8370","12.7981","8.5320","81.1517"
"51.3600","12.8179","340.9985","12.8179","8.5453","81.1901"
"51.4400","12.8364","341.0880","12.8364","8.5576","81.2114"
"51.5200","12.8566","341.2620","12.8566","8.5711","81.2529"
"51.6000","12.8770","341.4375","12.8770","8.5847","81.2946"
"51.6800","12.8969","341.6003","12.8969","8.5979","81.3334"
"51.7600","12.9183","341.8079","12.9183","8.6122","81.3828"
"51.8400","12.9377","341.9220","12.9377","8.6251","81.4100"
"51.9200","12.9577","342.0746","12.9577","8.6385","81.4463"
"52.0000","12.9774","342.2194","12.9774","8.6516","81.4808"
"52.0800","12.9973","342.3779","12.9973","8.6649","81.5185"
"52.1600","13.0172","342.5074","13.0172","8.6781","81.5494"
"52.2400","13.0365","342.6157","13.0365","8.6910","81.5752"
"52.3200","13.0562","342.7822","13.0562","8.7041","81.6148"
"52.4000","13.0781","342.9929","13.0781","8.7187","81.6650"
"52.4800","13.0975","343.0980","13.0975","8.7317","81.6900"
"52.5600","13.1182","343.2485","13.1182","8.7455","81.7258"
"52.6400","13.1372","343.3378","13.1372","8.7582","81.7471"
"52.7200","13.1565","343.4533","13.1565","8.7710","81.7746"
"52.8000","13.1764","343.5796","13.1764","8.7843","81.8047"
"52.8800","13.1967","343.7179","13.1967","8.7978","81.8376"
"52.9600","13.2176","343.8760","13.2176","8.8117","81.8752"
"53.0400","13.2382","344.0176","13.2382","8.8255","81.9090"
"53.1200","13.2573","344.1013","13.2573","8.8382","81.9289"
"53.2000","13.2777","344.2473","13.2777","8.8518","81.9636"
"53.2800","13.2974","344.3462","13.2974","8.8649","81.9872"
"53.3600","13.3171","344.4585","13.3171","8.8780","82.0139"
"53.4400","13.3370","344.5780","13.3370","8.8913","82.0424"
"53.5200","13.3558","344.6479","13.3558","8.9039","82.0590"
"53.6000","13.3771","344.7948","13.3771","8.9181","82.0940"
"53.6800","13.3975","344.9158","13.3975","8.9317","82.1228"
"53.7600","13.4178","345.0175","13.4178","8.9452","82.1470"
"53.8400","13.4375","345.1090","13.4375","8.9583","82.1688"
"53.9200","13.4565","345.1575","13.4565","8.9710","82.1804"
"54.0000","13.4766","345.2811","13.4766","8.9844","82.2098"
"54.0800","13.4975","345.4066","13.4975","8.9983","82.2397"
"54.1600","13.5167","345.5037","13.5167","9.0112","82.2628"
"54.2400","13.5379","345.6371","13.5379","9.0253","82.2945"
"54.3200","13.5577","345.7134","13.5577","9.0384","82.3127"
"54.4000","13.5778","345.8266","13.5778","9.0519","82.3397"
"54.4800","13.5975","345.9088","13.5975","9.0650","82.3592"
"54.5600","13.6171","345.9585","13.6171","9.0781","82.3711"
"54.6400","13.6370","346.0425","13.6370","9.0914","82.3911"
"54.7200","13.6570","346.1264","13.6570","9.1046","82.4111"
"54.8000","13.6761","346.1842","13.6761","9.1174","82.4248"
"54.8800","13.6973","346.3171","13.6973","9.1316","82.4564"
"54.9600","13.7174","346.3849","13.7174","9.1450","82.4726"
"55.0400","13.7379","346.4774","13.7379","9.1586","82.4946"
"55.1200","13.7571","346.5225","13.7571","9.1714","82.5054"
"55.2000","13.7765","346.5894","13.7765","9.1843","82.5213"
"55.2800","13.7971","346.6792","13.7971","9.1980","82.5427"
"55.3600","13.8172","346.7517","13.8172","9.2114","82.5599"
"55.4400","13.8372","346.8314","13.8372","9.2248","82.5789"
"55.5200","13.8575","346.9131","13.8575","9.2384","82.5984"
"55.6000","13.8774","346.9615","13.8774","9.2516","82.6099"
"55.6800","13.8981","347.0497","13.8981","9.2654","82.6309"
"55.7600","13.9179","347.0936","13.9179","9.2786","82.6413"
"55.8400","13.9366","347.1161","13.9366","9.2911","82.6467"
"55.9200","13.9570","347.1893","13.9570","9.3046","82.6641"
"56.0000","13.9760","347.1936","13.9760","9.3174","82.6652"
"56.0800","13.9971","347.2891","13.9971","9.3314","82.6879"
"56.1600","14.0179","347.3831","14.0179","9.3453","82.7103"
"56.2400","14.0375","347.4027","14.0375","9.3583","82.7149"
"56.3200","14.0567","347.4012","14.0567","9.3712","82.7146"
"56.4000","14.0770","347.4506","14.0770","9.3847","82.7263"
"56.4800","14.0968","347.4816","14.0968","9.3979","82.7337"
"56.5600","14.1172","347.5130","14.1172","9.4115","82.7412"
"56.6400","14.1362","347.4867","14.1362","9.4241","82.7349"
"56.7200","14.1575","347.5517","14.1575","9.4383","82.7504"
"56.8000","14.1781","347.5645","14.1781","9.4521","82.7535"
"56.8800","14.1979","347.5858","14.1979","9.4653","82.7585"
"56.9600","14.2176","347.5585","14.2176","9.4784","82.7520"
"57.0400","14.2372","347.5405","14.2372","9.4914","82.7477"
"57.1200","14.2569","347.5312","14.2569","9.5046","82.7455"
"57.2000","14.2769","347.5183","14.2769","9.5179","82.7425"
"57.2800","14.2960","347.4865","14.2960","9.5306","82.7349"
"57.3600","14.3170","347.5130","14.3170","9.5447","82.7412"
"57.4400","14.3381","347.5287","14.3381","9.5587","82.7449"
"57.5200","14.3574","347.4999","14.3574","9.5716","82.7381"
"57.6000","14.3771","347.4796","14.3771","9.5847","82.7332"
"57.6800","14.3966","347.4525","14.3966","9.5977","82.7268"
"57.7600","14.4173","347.4583","14.4173","9.6115","82.7282"
"57.8400","14.4372","347.4445","14.4372","9.6248","82.7249"
"57.9200","14.4568","347.4129","14.4568","9.6379","82.7174"
"58.0000","14.4773","347.4087","14.4773","9.6515","82.7163"
"58.0800","14.4980","347.3956","14.4980","9.6654","82.7132"
"58.1600","14.5179","347.3665","14.5179","9.6786","82.7063"
"58.2400","14.5377","347.3307","14.5377","9.6918","82.6978"
"58.3200","14.5563","347.2466","14.5563","9.7042","82.6778"
"58.4000","14.5768","347.2253","14.5768","9.7179","82.6727"
"58.4800","14.5968","347.1830","14.5968","9.7312","82.6626"
"58.5600","14.6163","347.1394","14.6163","9.7442","82.6522"
"58.6400","14.6365","347.1165","14.6365","9.7577","82.6468"
"58.7200","14.6576","347.1043","14.6576","9.7718","82.6439"
"58.8000","14.6778","347.0633","14.6778","9.7852","82.6341"
"58.8800","14.6977","347.0085","14.6977","9.7984","82.6211"
"58.9600","14.7166","346.9452","14.7166","9.8111","82.6060"
"59.0400","14.7369","346.9105","14.7369","9.8246","82.5977"
"59.1200","14.7566","346.8591","14.7566","9.8377","82.5855"
"59.2000","14.7773","346.8367","14.7773","9.8516","82.5802"
"59.2800","14.7986","346.8369","14.7986","9.8657","82.5802"
"59.3600","14.8180","346.7570","14.8180","9.8787","82.5612"
"59.4400","14.8376","346.6914","14.8376","9.8917","82.5456"
"59.5200","14.8571","346.6346","14.8571","9.9047","82.5321"
"59.6000","14.8770","346.5710","14.8770","9.9180","82.5169"
"59.6800","14.8968","346.5234","14.8968","9.9312","82.5056"
"59.7600","14.9161","346.4423","14.9161","9.9441","82.4863"
"59.8400","14.9369","346.4184","14.9369","9.9579","82.4806"
"59.9200","14.9577","346.3808","14.9577","9.9718","82.4716"
"60.0000","14.9771","346.2958","14.9771","9.9847","82.4514"
"60.0800","14.9977","346.2374","14.9977","9.9984","82.4375"
"60.0900","15.0001","346.2380","15.0001","10.0001","82.4376"