File: data/instron_tests/metamaterials/250416/250416_1310_NSC_m1.is_comp_Exports/240416_1310_NSC_m1_4_1.csv
Results Table 1
,Compresson Axis,H*,V*,Height,Thickness,Width,Area,Fixture separation,Specimen label
,,,,(mm),(mm),(mm),(mm^2),(mm),
"4","X","","","150.00","28.00","150.00","4200.00","150.00","1310_NSC_m1"

Results Table 2
,Modulus (Segment 0 % - 2.5 %),Compresson Axis
,(kPa),
"4","1328.36","X"

Time,Displacement,Force,Compressive displacement,Compressive strain (Displacement),Compressive stress
(s),(mm),(N),(mm),(%),(kPa)
"0.0000","0.0000","-0.1272","0.0000","0.0000","-0.0303"
"0.0800","0.0011","-0.0673","0.0011","0.0007","-0.0160"
"0.1600","0.0172","0.7708","0.0172","0.0114","0.1835"
"0.2400","0.0376","1.7697","0.0376","0.0251","0.4213"
"0.3200","0.0577","2.7046","0.0577","0.0385","0.6440"
"0.4000","0.0767","3.5577","0.0767","0.0511","0.8471"
"0.4800","0.0976","4.5093","0.0976","0.0650","1.0736"
"0.5600","0.1181","5.4388","0.1181","0.0788","1.2950"
"0.6400","0.1377","6.3085","0.1377","0.0918","1.5020"
"0.7200","0.1572","7.1478","0.1572","0.1048","1.7019"
"0.8000","0.1767","7.9929","0.1767","0.1178","1.9031"
"0.8800","0.1973","8.8827","0.1973","0.1316","2.1149"
"0.9600","0.2175","9.7131","0.2175","0.1450","2.3126"
"1.0400","0.2358","10.4903","0.2358","0.1572","2.4977"
"1.1200","0.2569","11.3669","0.2569","0.1713","2.7064"
"1.2000","0.2776","12.2421","0.2776","0.1851","2.9148"
"1.2800","0.2981","13.0924","0.2981","0.1987","3.1172"
"1.3600","0.3177","13.8866","0.3177","0.2118","3.3063"
"1.4400","0.3366","14.6513","0.3366","0.2244","3.4884"
"1.5200","0.3565","15.4667","0.3565","0.2377","3.6826"
"1.6000","0.3769","16.2958","0.3769","0.2513","3.8799"
"1.6800","0.3969","17.1189","0.3969","0.2646","4.0759"
"1.7600","0.4183","17.9892","0.4183","0.2789","4.2831"
"1.8400","0.4377","18.7555","0.4377","0.2918","4.4656"
"1.9200","0.4575","19.5550","0.4575","0.3050","4.6560"
"2.0000","0.4774","20.3424","0.4774","0.3182","4.8434"
"2.0800","0.4965","21.0956","0.4965","0.3310","5.0228"
"2.1600","0.5172","21.9314","0.5172","0.3448","5.2218"
"2.2400","0.5368","22.7005","0.5368","0.3578","5.4049"
"2.3200","0.5562","23.4842","0.5562","0.3708","5.5915"
"2.4000","0.5779","24.3502","0.5779","0.3853","5.7977"
"2.4800","0.5974","25.1014","0.5974","0.3982","5.9765"
"2.5600","0.6178","25.8990","0.6178","0.4119","6.1664"
"2.6400","0.6373","26.6517","0.6373","0.4248","6.3456"
"2.7200","0.6562","27.3959","0.6562","0.4375","6.5228"
"2.8000","0.6766","28.2046","0.6766","0.4511","6.7154"
"2.8800","0.6970","28.9899","0.6970","0.4647","6.9024"
"2.9600","0.7174","29.7895","0.7174","0.4783","7.0927"
"3.0400","0.7383","30.6015","0.7383","0.4922","7.2861"
"3.1200","0.7572","31.3223","0.7572","0.5048","7.4577"
"3.2000","0.7775","32.1127","0.7775","0.5183","7.6459"
"3.2800","0.7974","32.8776","0.7974","0.5316","7.8280"
"3.3600","0.8170","33.6348","0.8170","0.5446","8.0083"
"3.4400","0.8369","34.3957","0.8369","0.5579","8.1895"
"3.5200","0.8556","35.1090","0.8556","0.5704","8.3593"
"3.6000","0.8770","35.9400","0.8770","0.5847","8.5571"
"3.6800","0.8984","36.7846","0.8984","0.5989","8.7582"
"3.7600","0.9179","37.5266","0.9179","0.6119","8.9349"
"3.8400","0.9372","38.2600","0.9372","0.6248","9.1095"
"3.9200","0.9558","38.9394","0.9558","0.6372","9.2713"
"4.0000","0.9763","39.7451","0.9763","0.6508","9.4631"
"4.0800","0.9978","40.5638","0.9978","0.6652","9.6581"
"4.1600","1.0166","41.2691","1.0166","0.6777","9.8260"
"4.2400","1.0377","42.0756","1.0377","0.6918","10.0180"
"4.3200","1.0577","42.8421","1.0577","0.7051","10.2005"
"4.4000","1.0779","43.5959","1.0779","0.7186","10.3800"
"4.4800","1.0974","44.3268","1.0974","0.7316","10.5540"
"4.5600","1.1164","45.0175","1.1164","0.7442","10.7185"
"4.6400","1.1371","45.7988","1.1371","0.7580","10.9045"
"4.7200","1.1572","46.5642","1.1572","0.7715","11.0867"
"4.8000","1.1761","47.2674","1.1761","0.7841","11.2542"
"4.8800","1.1974","48.0981","1.1974","0.7983","11.4519"
"4.9600","1.2178","48.8568","1.2178","0.8119","11.6326"
"5.0400","1.2376","49.6024","1.2376","0.8251","11.8101"
"5.1200","1.2570","50.3195","1.2570","0.8380","11.9808"
"5.2000","1.2761","51.0259","1.2761","0.8508","12.1490"
"5.2800","1.2972","51.8287","1.2972","0.8648","12.3402"
"5.3600","1.3173","52.5597","1.3173","0.8782","12.5142"
"5.4400","1.3370","53.3048","1.3370","0.8913","12.6916"
"5.5200","1.3575","54.0843","1.3575","0.9050","12.8772"
"5.6000","1.3777","54.8258","1.3777","0.9184","13.0538"
"5.6800","1.3982","55.5951","1.3982","0.9321","13.2369"
"5.7600","1.4180","56.3201","1.4180","0.9453","13.4095"
"5.8400","1.4364","56.9966","1.4364","0.9576","13.5706"
"5.9200","1.4570","57.7516","1.4570","0.9713","13.7504"
"6.0000","1.4761","58.4492","1.4761","0.9841","13.9165"
"6.0800","1.4973","59.2690","1.4973","0.9982","14.1117"
"6.1600","1.5180","60.0470","1.5180","1.0120","14.2969"
"6.2400","1.5375","60.7598","1.5375","1.0250","14.4666"
"6.3200","1.5567","61.4683","1.5567","1.0378","14.6353"
"6.4000","1.5770","62.2207","1.5770","1.0513","14.8144"
"6.4800","1.5965","62.9504","1.5965","1.0643","14.9882"
"6.5600","1.6176","63.6940","1.6176","1.0784","15.1652"
"6.6400","1.6361","64.3695","1.6361","1.0907","15.3261"
"6.7200","1.6575","65.1825","1.6575","1.1050","15.5197"
"6.8000","1.6779","65.9587","1.6779","1.1186","15.7044"
"6.8800","1.6978","66.6943","1.6978","1.1319","15.8796"
"6.9600","1.7171","67.3986","1.7171","1.1447","16.0473"
"7.0400","1.7369","68.1349","1.7369","1.1579","16.2226"
"7.1200","1.7570","68.8384","1.7570","1.1713","16.3901"
"7.2000","1.7777","69.6105","1.7777","1.1851","16.5739"
"7.2800","1.7963","70.2750","1.7963","1.1975","16.7321"
"7.3600","1.8170","71.0576","1.8170","1.2113","16.9185"
"7.4400","1.8378","71.8469","1.8378","1.2252","17.1064"
"7.5200","1.8575","72.5762","1.8575","1.2384","17.2800"
"7.6000","1.8776","73.3158","1.8776","1.2517","17.4561"
"7.6800","1.8965","73.9825","1.8965","1.2643","17.6149"
"7.7600","1.9172","74.7384","1.9172","1.2782","17.7949"
"7.8400","1.9372","75.4509","1.9372","1.2915","17.9645"
"7.9200","1.9565","76.1527","1.9565","1.3043","18.1316"
"8.0000","1.9772","76.9483","1.9772","1.3181","18.3210"
"8.0800","1.9982","77.7234","1.9982","1.3321","18.5056"
"8.1600","2.0179","78.4498","2.0179","1.3453","18.6785"
"8.2400","2.0377","79.1843","2.0377","1.3585","18.8534"
"8.3200","2.0560","79.8341","2.0560","1.3707","19.0081"
"8.4000","2.0773","80.6448","2.0773","1.3849","19.2011"
"8.4800","2.0969","81.3107","2.0969","1.3979","19.3597"
"8.5600","2.1168","82.0397","2.1168","1.4112","19.5333"
"8.6400","2.1372","82.8107","2.1372","1.4248","19.7168"
"8.7200","2.1574","83.5391","2.1574","1.4383","19.8903"
"8.8000","2.1774","84.2888","2.1774","1.4516","20.0688"
"8.8800","2.1979","85.0475","2.1979","1.4653","20.2494"
"8.9600","2.2165","85.7130","2.2165","1.4776","20.4079"
"9.0400","2.2368","86.4698","2.2368","1.4912","20.5881"
"9.1200","2.2564","87.1831","2.2564","1.5043","20.7579"
"9.2000","2.2772","87.9567","2.2772","1.5181","20.9421"
"9.2800","2.2985","88.6942","2.2985","1.5323","21.1177"
"9.3600","2.3177","89.3891","2.3177","1.5451","21.2831"
"9.4400","2.3376","90.1054","2.3376","1.5584","21.4537"
"9.5200","2.3574","90.8458","2.3574","1.5716","21.6299"
"9.6000","2.3768","91.5589","2.3768","1.5845","21.7997"
"9.6800","2.3971","92.3362","2.3971","1.5981","21.9848"
"9.7600","2.4155","92.9652","2.4155","1.6103","22.1346"
"9.8400","2.4367","93.7636","2.4367","1.6245","22.3247"
"9.9200","2.4582","94.5550","2.4582","1.6388","22.5131"
"10.0000","2.4772","95.2347","2.4772","1.6515","22.6749"
"10.0800","2.4978","95.9399","2.4978","1.6652","22.8428"
"10.1600","2.5169","96.6412","2.5169","1.6780","23.0098"
"10.2400","2.5370","97.3825","2.5370","1.6913","23.1863"
"10.3200","2.5568","98.1151","2.5568","1.7045","23.3607"
"10.4000","2.5766","98.8271","2.5766","1.7177","23.5303"
"10.4800","2.5975","99.6177","2.5975","1.7317","23.7185"
"10.5600","2.6189","100.4199","2.6189","1.7459","23.9095"
"10.6400","2.6376","101.0696","2.6376","1.7584","24.0642"
"10.7200","2.6574","101.7879","2.6574","1.7716","24.2352"
"10.8000","2.6765","102.4773","2.6765","1.7843","24.3994"
"10.8800","2.6973","103.2438","2.6973","1.7982","24.5819"
"10.9600","2.7172","103.9251","2.7172","1.8115","24.7441"
"11.0400","2.7360","104.5975","2.7360","1.8240","24.9042"
"11.1200","2.7566","105.3657","2.7566","1.8377","25.0871"
"11.2000","2.7777","106.1564","2.7777","1.8518","25.2753"
"11.2800","2.7979","106.8989","2.7979","1.8653","25.4521"
"11.3600","2.8175","107.6053","2.8175","1.8784","25.6203"
"11.4400","2.8362","108.2593","2.8362","1.8908","25.7760"
"11.5200","2.8568","109.0348","2.8568","1.9046","25.9607"
"11.6000","2.8770","109.7594","2.8770","1.9180","26.1332"
"11.6800","2.8966","110.4883","2.8966","1.9311","26.3067"
"11.7600","2.9179","111.2876","2.9179","1.9452","26.4970"
"11.8400","2.9377","111.9982","2.9377","1.9585","26.6662"
"11.9200","2.9582","112.7189","2.9582","1.9721","26.8378"
"12.0000","2.9772","113.3910","2.9772","1.9848","26.9979"
"12.0800","2.9969","114.1168","2.9969","1.9979","27.1707"
"12.1600","3.0173","114.8698","3.0173","2.0115","27.3499"
"12.2400","3.0367","115.5645","3.0367","2.0245","27.5154"
"12.3200","3.0561","116.2734","3.0561","2.0374","27.6841"
"12.4000","3.0778","117.0977","3.0778","2.0519","27.8804"
"12.4800","3.0970","117.7794","3.0970","2.0647","28.0427"
"12.5600","3.1181","118.5538","3.1181","2.0787","28.2271"
"12.6400","3.1373","119.2326","3.1373","2.0916","28.3887"
"12.7200","3.1566","119.9441","3.1566","2.1044","28.5581"
"12.8000","3.1767","120.6797","3.1767","2.1178","28.7333"
"12.8800","3.1970","121.4191","3.1970","2.1314","28.9093"
"12.9600","3.2172","122.1521","3.2172","2.1448","29.0838"
"13.0400","3.2384","122.9113","3.2384","2.1589","29.2646"
"13.1200","3.2576","123.6011","3.2576","2.1717","29.4288"
"13.2000","3.2773","124.3130","3.2773","2.1849","29.5983"
"13.2800","3.2974","125.0385","3.2974","2.1983","29.7711"
"13.3600","3.3172","125.7698","3.3172","2.2114","29.9452"
"13.4400","3.3369","126.4670","3.3369","2.2246","30.1112"
"13.5200","3.3555","127.1298","3.3555","2.2370","30.2690"
"13.6000","3.3769","127.9334","3.3769","2.2513","30.4603"
"13.6800","3.3982","128.7204","3.3982","2.2655","30.6477"
"13.7600","3.4178","129.4290","3.4178","2.2785","30.8164"
"13.8400","3.4371","130.1228","3.4371","2.2914","30.9816"
"13.9200","3.4564","130.8047","3.4564","2.3042","31.1440"
"14.0000","3.4767","131.5660","3.4767","2.3178","31.3252"
"14.0800","3.4977","132.3350","3.4977","2.3318","31.5083"
"14.1600","3.5164","132.9964","3.5164","2.3443","31.6658"
"14.2400","3.5380","133.7647","3.5380","2.3587","31.8487"
"14.3200","3.5576","134.4630","3.5576","2.3717","32.0150"
"14.4000","3.5778","135.2156","3.5778","2.3852","32.1942"
"14.4800","3.5973","135.9103","3.5973","2.3982","32.3596"
"14.5600","3.6170","136.6265","3.6170","2.4113","32.5301"
"14.6400","3.6370","137.3532","3.6370","2.4247","32.7031"
"14.7200","3.6568","138.0559","3.6568","2.4378","32.8704"
"14.8000","3.6759","138.7503","3.6759","2.4506","33.0358"
"14.8800","3.6973","139.5506","3.6973","2.4648","33.2263"
"14.9600","3.7175","140.2813","3.7175","2.4784","33.4003"
"15.0400","3.7374","140.9966","3.7374","2.4916","33.5706"
"15.1200","3.7571","141.6976","3.7571","2.5047","33.7375"
"15.2000","3.7761","142.3726","3.7761","2.5174","33.8982"
"15.2800","3.7973","143.1479","3.7973","2.5315","34.0828"
"15.3600","3.8173","143.8541","3.8173","2.5448","34.2510"
"15.4400","3.8372","144.5816","3.8372","2.5581","34.4242"
"15.5200","3.8577","145.2930","3.8577","2.5718","34.5936"
"15.6000","3.8775","145.9874","3.8775","2.5850","34.7589"
"15.6800","3.8978","146.7261","3.8978","2.5985","34.9348"
"15.7600","3.9180","147.4598","3.9180","2.6120","35.1095"
"15.8400","3.9364","148.1045","3.9364","2.6243","35.2630"
"15.9200","3.9570","148.8560","3.9570","2.6380","35.4419"
"16.0000","3.9763","149.5420","3.9763","2.6509","35.6052"
"16.0800","3.9972","150.3170","3.9972","2.6648","35.7898"
"16.1600","4.0180","151.0688","4.0180","2.6786","35.9688"
"16.2400","4.0374","151.7441","4.0374","2.6916","36.1295"
"16.3200","4.0567","152.4283","4.0567","2.7044","36.2924"
"16.4000","4.0772","153.1704","4.0772","2.7181","36.4691"
"16.4800","4.0966","153.8759","4.0966","2.7311","36.6371"
"16.5600","4.1174","154.6387","4.1174","2.7450","36.8187"
"16.6400","4.1359","155.2619","4.1359","2.7573","36.9671"
"16.7200","4.1576","156.0766","4.1576","2.7717","37.1611"
"16.8000","4.1780","156.8255","4.1780","2.7853","37.3394"
"16.8800","4.1980","157.5027","4.1980","2.7987","37.5006"
"16.9600","4.2175","158.2073","4.2175","2.8116","37.6684"
"17.0400","4.2370","158.8957","4.2370","2.8246","37.8323"
"17.1200","4.2567","159.6111","4.2567","2.8378","38.0026"
"17.2000","4.2771","160.3424","4.2771","2.8514","38.1768"
"17.2800","4.2961","160.9964","4.2961","2.8640","38.3325"
"17.3600","4.3176","161.8065","4.3176","2.8784","38.5254"
"17.4400","4.3377","162.5177","4.3377","2.8918","38.6947"
"17.5200","4.3571","163.2055","4.3571","2.9047","38.8585"
"17.6000","4.3773","163.9458","4.3773","2.9182","39.0347"
"17.6800","4.3968","164.6243","4.3968","2.9312","39.1963"
"17.7600","4.4173","165.3655","4.4173","2.9448","39.3727"
"17.8400","4.4371","166.0752","4.4371","2.9581","39.5417"
"17.9200","4.4565","166.7578","4.4565","2.9710","39.7042"
"18.0000","4.4772","167.5152","4.4772","2.9848","39.8846"
"18.0800","4.4981","168.2673","4.4981","2.9988","40.0636"
"18.1600","4.5180","168.9629","4.5180","3.0120","40.2293"
"18.2400","4.5379","169.6361","4.5379","3.0252","40.3895"
"18.3200","4.5559","170.2480","4.5559","3.0372","40.5352"
"18.4000","4.5772","171.0455","4.5772","3.0515","40.7251"
"18.4800","4.5968","171.7327","4.5968","3.0646","40.8887"
"18.5600","4.6169","172.4638","4.6169","3.0779","41.0628"
"18.6400","4.6369","173.1857","4.6369","3.0913","41.2347"
"18.7200","4.6574","173.8896","4.6574","3.1049","41.4023"
"18.8000","4.6774","174.6120","4.6774","3.1183","41.5743"
"18.8800","4.6980","175.3515","4.6980","3.1320","41.7504"
"18.9600","4.7163","175.9678","4.7163","3.1442","41.8971"
"19.0400","4.7367","176.7117","4.7367","3.1578","42.0742"
"19.1200","4.7565","177.4059","4.7565","3.1710","42.2395"
"19.2000","4.7772","178.1696","4.7772","3.1848","42.4213"
"19.2800","4.7984","178.9269","4.7984","3.1989","42.6016"
"19.3600","4.8177","179.5877","4.8177","3.2118","42.7590"
"19.4400","4.8376","180.2937","4.8376","3.2251","42.9271"
"19.5200","4.8572","180.9778","4.8572","3.2382","43.0900"
"19.6000","4.8768","181.6642","4.8768","3.2512","43.2534"
"19.6800","4.8972","182.3962","4.8972","3.2648","43.4277"
"19.7600","4.9166","183.0549","4.9166","3.2777","43.5845"
"19.8400","4.9369","183.7900","4.9369","3.2912","43.7595"
"19.9200","4.9577","184.5340","4.9577","3.3052","43.9367"
"20.0000","4.9773","185.2160","4.9773","3.3182","44.0991"
"20.0800","4.9976","185.9393","4.9976","3.3318","44.2713"
"20.1600","5.0167","186.5992","5.0167","3.3445","44.4284"
"20.2400","5.0370","187.3136","5.0370","3.3580","44.5985"
"20.3200","5.0567","188.0020","5.0567","3.3711","44.7624"
"20.4000","5.0768","188.7098","5.0768","3.3845","44.9309"
"20.4800","5.0975","189.4600","5.0975","3.3983","45.1095"
"20.5600","5.1182","190.1834","5.1182","3.4121","45.2818"
"20.6400","5.1373","190.8538","5.1373","3.4249","45.4414"
"20.7200","5.1572","191.5497","5.1572","3.4381","45.6071"
"20.8000","5.1764","192.2088","5.1764","3.4509","45.7640"
"20.8800","5.1974","192.9755","5.1974","3.4649","45.9466"
"20.9600","5.2171","193.6513","5.2171","3.4781","46.1075"
"21.0400","5.2363","194.3167","5.2363","3.4908","46.2659"
"21.1200","5.2568","195.0458","5.2568","3.5046","46.4395"
"21.2000","5.2775","195.7378","5.2775","3.5183","46.6042"
"21.2800","5.2978","196.4620","5.2978","3.5318","46.7767"
"21.3600","5.3176","197.1524","5.3176","3.5451","46.9410"
"21.4400","5.3358","197.7405","5.3358","3.5572","47.0811"
"21.5200","5.3567","198.5156","5.3567","3.5712","47.2656"
"21.6000","5.3772","199.2139","5.3772","3.5848","47.4319"
"21.6800","5.3967","199.8989","5.3967","3.5978","47.5950"
"21.7600","5.4183","200.6933","5.4183","3.6122","47.7841"
"21.8400","5.4376","201.3405","5.4376","3.6251","47.9382"
"21.9200","5.4579","202.0490","5.4579","3.6386","48.1069"
"22.0000","5.4774","202.7218","5.4774","3.6516","48.2671"
"22.0800","5.4966","203.3702","5.4966","3.6644","48.4215"
"22.1600","5.5169","204.0934","5.5169","3.6779","48.5937"
"22.2400","5.5370","204.7808","5.5370","3.6913","48.7573"
"22.3200","5.5563","205.4359","5.5563","3.7042","48.9133"
"22.4000","5.5775","206.2039","5.5775","3.7184","49.0962"
"22.4800","5.5972","206.8754","5.5972","3.7314","49.2560"
"22.5600","5.6183","207.6126","5.6183","3.7456","49.4316"
"22.6400","5.6374","208.2462","5.6374","3.7583","49.5824"
"22.7200","5.6563","208.8846","5.6563","3.7709","49.7344"
"22.8000","5.6762","209.5572","5.6762","3.7841","49.8946"
"22.8800","5.6970","210.2998","5.6970","3.7980","50.0714"
"22.9600","5.7174","211.0139","5.7174","3.8116","50.2414"
"23.0400","5.7385","211.7595","5.7385","3.8256","50.4189"
"23.1200","5.7574","212.4009","5.7574","3.8383","50.5717"
"23.2000","5.7778","213.1025","5.7778","3.8519","50.7387"
"23.2800","5.7971","213.7574","5.7971","3.8648","50.8946"
"23.3600","5.8172","214.4635","5.8172","3.8782","51.0627"
"23.4400","5.8370","215.1467","5.8370","3.8913","51.2254"
"23.5200","5.8557","215.7653","5.8557","3.9038","51.3727"
"23.6000","5.8771","216.5332","5.8771","3.9181","51.5555"
"23.6800","5.8982","217.3130","5.8982","3.9322","51.7412"
"23.7600","5.9181","217.9824","5.9181","3.9454","51.9006"
"23.8400","5.9369","218.6142","5.9369","3.9579","52.0510"
"23.9200","5.9564","219.2534","5.9564","3.9710","52.2032"
"24.0000","5.9766","219.9616","5.9766","3.9844","52.3718"
"24.0800","5.9976","220.7001","5.9976","3.9984","52.5476"
"24.1600","6.0163","221.3162","6.0163","4.0109","52.6943"
"24.2400","6.0377","222.0714","6.0377","4.0252","52.8741"
"24.3200","6.0577","222.7403","6.0577","4.0385","53.0334"
"24.4000","6.0781","223.4477","6.0781","4.0521","53.2018"
"24.4800","6.0971","224.0727","6.0971","4.0648","53.3506"
"24.5600","6.1166","224.7326","6.1166","4.0778","53.5078"
"24.6400","6.1374","225.4421","6.1374","4.0916","53.6767"
"24.7200","6.1573","226.1142","6.1573","4.1049","53.8367"
"24.8000","6.1757","226.7141","6.1757","4.1171","53.9796"
"24.8800","6.1976","227.4991","6.1976","4.1317","54.1664"
"24.9600","6.2177","228.1750","6.2177","4.1451","54.3274"
"25.0400","6.2378","228.8494","6.2378","4.1586","54.4880"
"25.1200","6.2568","229.4704","6.2568","4.1712","54.6358"
"25.2000","6.2761","230.1155","6.2761","4.1841","54.7894"
"25.2800","6.2973","230.8531","6.2973","4.1982","54.9650"
"25.3600","6.3172","231.5035","6.3172","4.2115","55.1199"
"25.4400","6.3369","232.1768","6.3369","4.2246","55.2802"
"25.5200","6.3577","232.8830","6.3577","4.2385","55.4483"
"25.6000","6.3778","233.5433","6.3778","4.2519","55.6056"
"25.6800","6.3977","234.2084","6.3977","4.2652","55.7639"
"25.7600","6.4178","234.8580","6.4178","4.2785","55.9186"
"25.8400","6.4365","235.4609","6.4365","4.2910","56.0621"
"25.9200","6.4570","236.1537","6.4570","4.3047","56.2271"
"26.0000","6.4761","236.7598","6.4761","4.3174","56.3714"
"26.0800","6.4971","237.4880","6.4971","4.3314","56.5448"
"26.1600","6.5183","238.2144","6.5183","4.3456","56.7177"
"26.2400","6.5377","238.8286","6.5377","4.3585","56.8639"
"26.3200","6.5569","239.4382","6.5569","4.3713","57.0091"
"26.4000","6.5770","240.1067","6.5770","4.3847","57.1683"
"26.4800","6.5966","240.7603","6.5966","4.3977","57.3239"
"26.5600","6.6174","241.4714","6.6174","4.4116","57.4932"
"26.6400","6.6364","242.0823","6.6364","4.4243","57.6386"
"26.7200","6.6574","242.7975","6.6574","4.4382","57.8089"
"26.8000","6.6782","243.4822","6.6782","4.4521","57.9720"
"26.8800","6.6981","244.1411","6.6981","4.4654","58.1288"
"26.9600","6.7174","244.7526","6.7174","4.4783","58.2744"
"27.0400","6.7368","245.3644","6.7368","4.4912","58.4201"
"27.1200","6.7568","246.0360","6.7568","4.5046","58.5800"
"27.2000","6.7772","246.7080","6.7772","4.5182","58.7400"
"27.2800","6.7959","247.2860","6.7959","4.5306","58.8776"
"27.3600","6.8173","248.0196","6.8173","4.5449","59.0523"
"27.4400","6.8378","248.6594","6.8378","4.5585","59.2046"
"27.5200","6.8572","249.2971","6.8572","4.5715","59.3565"
"27.6000","6.8773","249.9561","6.8773","4.5849","59.5134"
"27.6800","6.8967","250.5749","6.8967","4.5978","59.6607"
"27.7600","6.9172","251.2673","6.9172","4.6115","59.8255"
"27.8400","6.9368","251.8937","6.9368","4.6245","59.9747"
"27.9200","6.9568","252.5466","6.9568","4.6379","60.1301"
"28.0000","6.9774","253.2349","6.9774","4.6516","60.2940"
"28.0800","6.9984","253.9406","6.9984","4.6656","60.4621"
"28.1600","7.0178","254.5440","7.0178","4.6785","60.6057"
"28.2400","7.0374","255.1655","7.0374","4.6916","60.7537"
"28.3200","7.0563","255.7679","7.0563","4.7042","60.8971"
"28.4000","7.0774","256.4869","7.0774","4.7183","61.0683"
"28.4800","7.0971","257.0996","7.0971","4.7314","61.2142"
"28.5600","7.1169","257.7244","7.1169","4.7446","61.3630"
"28.6400","7.1369","258.3781","7.1369","4.7579","61.5186"
"28.7200","7.1573","259.0206","7.1573","4.7716","61.6716"
"28.8000","7.1773","259.6565","7.1773","4.7849","61.8230"
"28.8800","7.1979","260.3093","7.1979","4.7986","61.9784"
"28.9600","7.2166","260.8708","7.2166","4.8110","62.1121"
"29.0400","7.2367","261.5140","7.2367","4.8245","62.2652"
"29.1200","7.2562","262.1130","7.2562","4.8375","62.4079"
"29.2000","7.2774","262.8242","7.2774","4.8516","62.5772"
"29.2800","7.2982","263.4881","7.2982","4.8655","62.7353"
"29.3600","7.3174","264.0723","7.3174","4.8783","62.8744"
"29.4400","7.3377","264.7119","7.3377","4.8918","63.0267"
"29.5200","7.3573","265.3092","7.3573","4.9049","63.1689"
"29.6000","7.3764","265.8727","7.3764","4.9176","63.3030"
"29.6800","7.3970","266.5431","7.3970","4.9314","63.4626"
"29.7600","7.4166","267.1165","7.4166","4.9444","63.5992"
"29.8400","7.4367","267.7630","7.4367","4.9578","63.7531"
"29.9200","7.4580","268.4431","7.4580","4.9720","63.9150"
"30.0000","7.4773","269.0284","7.4773","4.9849","64.0544"
"30.0800","7.4978","269.6772","7.4978","4.9986","64.2088"
"30.1600","7.5170","270.2761","7.5170","5.0113","64.3514"
"30.2400","7.5372","270.8953","7.5372","5.0248","64.4989"
"30.3200","7.5567","271.4886","7.5567","5.0378","64.6401"
"30.4000","7.5764","272.0963","7.5764","5.0510","64.7848"
"30.4800","7.5978","272.7882","7.5978","5.0652","64.9496"
"30.5600","7.6185","273.4248","7.6185","5.0790","65.1011"
"30.6400","7.6378","273.9999","7.6378","5.0918","65.2381"
"30.7200","7.6577","274.6071","7.6577","5.1052","65.3826"
"30.8000","7.6766","275.1564","7.6766","5.1178","65.5134"
"30.8800","7.6973","275.8045","7.6973","5.1315","65.6677"
"30.9600","7.7173","276.4074","7.7173","5.1449","65.8113"
"31.0400","7.7361","276.9527","7.7361","5.1574","65.9411"
"31.1200","7.7569","277.6046","7.7569","5.1713","66.0963"
"31.2000","7.7776","278.2351","7.7776","5.1851","66.2465"
"31.2800","7.7978","278.8530","7.7978","5.1985","66.3936"
"31.3600","7.8180","279.4625","7.8180","5.2120","66.5387"
"31.4400","7.8362","279.9526","7.8362","5.2242","66.6554"
"31.5200","7.8563","280.5671","7.8563","5.2376","66.8017"
"31.6000","7.8769","281.1852","7.8769","5.2513","66.9489"
"31.6800","7.8970","281.8010","7.8970","5.2647","67.0955"
"31.7600","7.9181","282.4477","7.9181","5.2787","67.2494"
"31.8400","7.9377","283.0007","7.9377","5.2918","67.3811"
"31.9200","7.9580","283.5938","7.9580","5.3054","67.5223"
"32.0000","7.9775","284.1362","7.9775","5.3183","67.6515"
"32.0800","7.9968","284.6930","7.9968","5.3312","67.7841"
"32.1600","8.0170","285.3038","8.0170","5.3447","67.9295"
"32.2400","8.0366","285.8513","8.0366","5.3577","68.0598"
"32.3200","8.0560","286.4134","8.0560","5.3707","68.1937"
"32.4000","8.0773","287.0670","8.0773","5.3849","68.3493"
"32.4800","8.0974","287.6408","8.0974","5.3982","68.4859"
"32.5600","8.1182","288.2736","8.1182","5.4121","68.6366"
"32.6400","8.1372","288.7731","8.1372","5.4248","68.7555"
"32.7200","8.1563","289.3114","8.1563","5.4375","68.8837"
"32.8000","8.1764","289.9004","8.1764","5.4510","69.0239"
"32.8800","8.1968","290.4921","8.1968","5.4645","69.1648"
"32.9600","8.2174","291.0952","8.2174","5.4783","69.3084"
"33.0400","8.2384","291.7166","8.2384","5.4923","69.4563"
"33.1200","8.2573","292.2236","8.2573","5.5049","69.5771"
"33.2000","8.2776","292.8116","8.2776","5.5184","69.7170"
"33.2800","8.2969","293.3385","8.2969","5.5313","69.8425"
"33.3600","8.3172","293.9338","8.3172","5.5448","69.9842"
"33.4400","8.3372","294.4880","8.3372","5.5581","70.1162"
"33.5200","8.3558","294.9837","8.3558","5.5705","70.2342"
"33.6000","8.3769","295.6088","8.3769","5.5846","70.3830"
"33.6800","8.3983","296.2555","8.3983","5.5989","70.5370"
"33.7600","8.4179","296.7956","8.4179","5.6119","70.6656"
"33.8400","8.4370","297.3156","8.4370","5.6247","70.7894"
"33.9200","8.4565","297.8325","8.4565","5.6377","70.9125"
"34.0000","8.4766","298.3979","8.4766","5.6511","71.0471"
"34.0800","8.4976","299.0037","8.4976","5.6651","71.1913"
"34.1600","8.5166","299.5134","8.5166","5.6778","71.3127"
"34.2400","8.5380","300.1286","8.5380","5.6920","71.4592"
"34.3200","8.5576","300.6553","8.5576","5.7051","71.5846"
"34.4000","8.5778","301.2058","8.5778","5.7185","71.7157"
"34.4800","8.5973","301.7307","8.5973","5.7316","71.8407"
"34.5600","8.6169","302.2326","8.6169","5.7446","71.9602"
"34.6400","8.6371","302.7759","8.6371","5.7580","72.0895"
"34.7200","8.6571","303.2975","8.6571","5.7714","72.2137"
"34.8000","8.6757","303.7646","8.6757","5.7838","72.3249"
"34.8800","8.6973","304.3745","8.6973","5.7982","72.4701"
"34.9600","8.7175","304.8795","8.7175","5.8116","72.5904"
"35.0400","8.7380","305.4051","8.7380","5.8254","72.7155"
"35.1200","8.7571","305.8578","8.7571","5.8380","72.8233"
"35.2000","8.7760","306.3198","8.7760","5.8507","72.9333"
"35.2800","8.7970","306.8835","8.7970","5.8647","73.0675"
"35.3600","8.8168","307.3888","8.8168","5.8778","73.1878"
"35.4400","8.8371","307.9163","8.8371","5.8914","73.3134"
"35.5200","8.8578","308.4734","8.8578","5.9052","73.4461"
"35.6000","8.8776","308.9574","8.8776","5.9184","73.5613"
"35.6800","8.8979","309.4695","8.8979","5.9320","73.6832"
"35.7600","8.9175","309.9364","8.9175","5.9450","73.7944"
"35.8400","8.9363","310.3940","8.9363","5.9575","73.9033"
"35.9200","8.9569","310.9298","8.9569","5.9713","74.0309"
"36.0000","8.9762","311.3961","8.9762","5.9842","74.1419"
"36.0800","8.9974","311.9729","8.9974","5.9983","74.2793"
"36.1600","9.0182","312.5160","9.0182","6.0122","74.4086"
"36.2400","9.0377","312.9560","9.0377","6.0251","74.5133"
"36.3200","9.0569","313.4045","9.0569","6.0379","74.6201"
"36.4000","9.0770","313.9007","9.0770","6.0514","74.7383"
"36.4800","9.0966","314.3864","9.0966","6.0644","74.8539"
"36.5600","9.1174","314.9037","9.1174","6.0783","74.9771"
"36.6400","9.1360","315.3143","9.1360","6.0907","75.0748"
"36.7200","9.1577","315.8911","9.1577","6.1051","75.2122"
"36.8000","9.1783","316.4062","9.1783","6.1189","75.3348"
"36.8800","9.1981","316.8781","9.1981","6.1321","75.4472"
"36.9600","9.2174","317.3087","9.2174","6.1449","75.5497"
"37.0400","9.2369","317.7672","9.2369","6.1580","75.6589"
"37.1200","9.2569","318.2448","9.2569","6.1713","75.7726"
"37.2000","9.2771","318.7258","9.2771","6.1847","75.8871"
"37.2800","9.2958","319.1246","9.2958","6.1972","75.9821"
"37.3600","9.3171","319.6732","9.3171","6.2114","76.1127"
"37.4400","9.3379","320.1621","9.3379","6.2253","76.2291"
"37.5200","9.3576","320.6118","9.3576","6.2384","76.3361"
"37.6000","9.3773","321.0549","9.3773","6.2515","76.4417"
"37.6800","9.3964","321.4517","9.3964","6.2643","76.5361"
"37.7600","9.4173","321.9586","9.4173","6.2782","76.6568"
"37.8400","9.4369","322.3793","9.4369","6.2912","76.7570"
"37.9200","9.4565","322.8301","9.4565","6.3044","76.8643"
"38.0000","9.4769","323.2936","9.4769","6.3179","76.9747"
"38.0800","9.4981","323.7992","9.4981","6.3320","77.0951"
"38.1600","9.5180","324.2175","9.5180","6.3453","77.1946"
"38.2400","9.5378","324.6428","9.5378","6.3586","77.2959"
"38.3200","9.5561","324.9832","9.5561","6.3707","77.3770"
"38.4000","9.5776","325.5019","9.5776","6.3851","77.5005"
"38.4800","9.5967","325.8880","9.5967","6.3978","77.5924"
"38.5600","9.6171","326.3406","9.6171","6.4114","77.7001"
"38.6400","9.6369","326.7432","9.6369","6.4246","77.7960"
"38.7200","9.6573","327.1596","9.6573","6.4382","77.8951"
"38.8000","9.6773","327.5683","9.6773","6.4516","77.9925"
"38.8800","9.6978","327.9916","9.6978","6.4652","78.0932"
"38.9600","9.7166","328.3153","9.7166","6.4777","78.1703"
"39.0400","9.7371","328.7230","9.7371","6.4914","78.2674"
"39.1200","9.7563","329.0299","9.7563","6.5042","78.3404"
"39.2000","9.7771","329.3782","9.7771","6.5181","78.4234"
"39.2800","9.7985","329.7780","9.7985","6.5323","78.5186"
"39.3600","9.8175","330.0599","9.8175","6.5450","78.5857"
"39.4400","9.8375","330.4192","9.8375","6.5583","78.6712"
"39.5200","9.8574","330.7946","9.8574","6.5716","78.7606"
"39.6000","9.8768","331.1539","9.8768","6.5846","78.8462"
"39.6800","9.8966","331.5175","9.8966","6.5977","78.9327"
"39.7600","9.9163","331.8706","9.9163","6.6109","79.0168"
"39.8400","9.9368","332.2928","9.9368","6.6246","79.1173"
"39.9200","9.9581","332.7271","9.9581","6.6388","79.2207"
"40.0000","9.9770","333.0504","9.9770","6.6513","79.2977"
"40.0800","9.9978","333.4655","9.9978","6.6652","79.3966"
"40.1600","10.0166","333.7590","10.0166","6.6777","79.4664"
"40.2400","10.0364","334.1126","10.0364","6.6910","79.5506"
"40.3200","10.0562","334.4847","10.0562","6.7042","79.6392"
"40.4000","10.0769","334.8790","10.0769","6.7180","79.7331"
"40.4800","10.0979","335.2729","10.0979","6.7319","79.8269"
"40.5600","10.1186","335.6614","10.1186","6.7457","79.9194"
"40.6400","10.1373","335.9513","10.1373","6.7582","79.9884"
"40.7200","10.1576","336.3167","10.1576","6.7717","80.0754"
"40.8000","10.1767","336.6079","10.1767","6.7845","80.1447"
"40.8800","10.1976","337.0009","10.1976","6.7984","80.2383"
"40.9600","10.2171","337.3152","10.2171","6.8114","80.3132"
"41.0400","10.2362","337.6144","10.2362","6.8241","80.3844"
"41.1200","10.2565","337.9739","10.2565","6.8376","80.4700"
"41.2000","10.2774","338.3719","10.2774","6.8516","80.5647"
"41.2800","10.2982","338.7430","10.2982","6.8655","80.6531"
"41.3600","10.3183","339.0999","10.3183","6.8789","80.7381"
"41.4400","10.3363","339.3117","10.3363","6.8909","80.7885"
"41.5200","10.3565","339.6559","10.3565","6.9043","80.8705"
"41.6000","10.3770","340.0015","10.3770","6.9180","80.9527"
"41.6800","10.3967","340.3147","10.3967","6.9311","81.0273"
"41.7600","10.4183","340.7177","10.4183","6.9455","81.1232"
"41.8400","10.4377","340.9946","10.4377","6.9585","81.1892"
"41.9200","10.4578","341.3056","10.4578","6.9719","81.2632"
"42.0000","10.4775","341.5999","10.4775","6.9850","81.3333"
"42.0800","10.4968","341.8835","10.4968","6.9979","81.4008"
"42.1600","10.5171","342.1998","10.5171","7.0114","81.4761"
"42.2400","10.5367","342.4758","10.5367","7.0245","81.5419"
"42.3200","10.5564","342.7826","10.5564","7.0376","81.6149"
"42.4000","10.5774","343.1217","10.5774","7.0516","81.6957"
"42.4800","10.5971","343.3892","10.5971","7.0647","81.7593"
"42.5600","10.6182","343.7244","10.6182","7.0788","81.8391"
"42.6400","10.6372","343.9646","10.6372","7.0915","81.8963"
"42.7200","10.6566","344.2349","10.6566","7.1044","81.9607"
"42.8000","10.6759","344.4862","10.6759","7.1172","82.0205"
"42.8800","10.6966","344.8363","10.6966","7.1311","82.1039"
"42.9600","10.7180","345.1715","10.7180","7.1453","82.1837"
"43.0400","10.7381","345.4433","10.7381","7.1588","82.2484"
"43.1200","10.7574","345.6747","10.7574","7.1716","82.3035"
"43.2000","10.7779","345.9659","10.7779","7.1853","82.3728"
"43.2800","10.7976","346.2090","10.7976","7.1984","82.4307"
"43.3600","10.8172","346.4638","10.8172","7.2115","82.4914"
"43.4400","10.8370","346.7208","10.8370","7.2247","82.5526"
"43.5200","10.8556","346.9120","10.8556","7.2371","82.5981"
"43.6000","10.8771","347.2368","10.8771","7.2514","82.6754"
"43.6800","10.8983","347.5509","10.8983","7.2655","82.7502"
"43.7600","10.9179","347.7690","10.9179","7.2786","82.8021"
"43.8400","10.9373","347.9986","10.9373","7.2916","82.8568"
"43.9200","10.9564","348.1788","10.9564","7.3043","82.8997"
"44.0000","10.9761","348.4184","10.9761","7.3174","82.9568"
"44.0800","10.9977","348.7228","10.9977","7.3318","83.0292"
"44.1600","11.0170","348.9086","11.0170","7.3446","83.0735"
"44.2400","11.0377","349.1302","11.0377","7.3585","83.1262"
"44.3200","11.0576","349.0325","11.0576","7.3717","83.1030"
"44.4000","11.0783","349.2630","11.0783","7.3855","83.1579"
"44.4800","11.0973","349.4037","11.0973","7.3982","83.1914"
"44.5600","11.1172","349.6058","11.1172","7.4114","83.2395"
"44.6400","11.1370","349.8133","11.1370","7.4246","83.2889"
"44.7200","11.1575","350.0498","11.1575","7.4383","83.3452"
"44.8000","11.1761","350.2026","11.1761","7.4507","83.3816"
"44.8800","11.1973","350.4824","11.1973","7.4649","83.4482"
"44.9600","11.2177","350.6932","11.2177","7.4785","83.4984"
"45.0400","11.2378","350.8985","11.2378","7.4919","83.5473"
"45.1200","11.2569","351.0531","11.2569","7.5046","83.5841"
"45.2000","11.2762","351.2246","11.2762","7.5175","83.6249"
"45.2800","11.2969","351.4391","11.2969","7.5312","83.6760"
"45.3600","11.3168","351.6378","11.3168","7.5445","83.7233"
"45.4400","11.3370","351.8450","11.3370","7.5580","83.7726"
"45.5200","11.3580","352.0764","11.3580","7.5720","83.8277"
"45.6000","11.3776","352.2385","11.3776","7.5851","83.8663"
"45.6800","11.3981","352.4476","11.3981","7.5988","83.9161"
"45.7600","11.4179","352.6175","11.4179","7.6119","83.9565"
"45.8400","11.4365","352.7560","11.4365","7.6244","83.9895"
"45.9200","11.4570","352.9550","11.4570","7.6380","84.0369"
"46.0000","11.4761","353.0925","11.4761","7.6507","84.0696"
"46.0800","11.4972","353.3231","11.4972","7.6648","84.1245"
"46.1600","11.5177","353.5097","11.5177","7.6785","84.1690"
"46.2400","11.5378","353.6708","11.5378","7.6919","84.2073"
"46.3200","11.5571","353.7917","11.5571","7.7048","84.2361"
"46.4000","11.5770","353.9446","11.5770","7.7180","84.2725"
"46.4800","11.5964","354.0822","11.5964","7.7309","84.3053"
"46.5600","11.6175","354.2884","11.6175","7.7450","84.3544"
"46.6400","11.6361","354.3807","11.6361","7.7574","84.3764"
"46.7200","11.6574","354.5847","11.6574","7.7716","84.4249"
"46.8000","11.6781","354.7580","11.6781","7.7854","84.4662"
"46.8800","11.6979","354.8953","11.6979","7.7986","84.4989"
"46.9600","11.7173","355.0125","11.7173","7.8116","84.5268"
"47.0400","11.7372","355.1429","11.7372","7.8248","84.5578"
"47.1200","11.7571","355.2829","11.7571","7.8381","84.5912"
"47.2000","11.7772","355.4324","11.7772","7.8515","84.6268"
"47.2800","11.7960","355.5122","11.7960","7.8640","84.6458"
"47.3600","11.8169","355.6768","11.8169","7.8779","84.6850"
"47.4400","11.8380","355.8468","11.8380","7.8920","84.7254"
"47.5200","11.8575","355.9508","11.8575","7.9050","84.7502"
"47.6000","11.8772","356.0594","11.8772","7.9181","84.7760"
"47.6800","11.8963","356.1368","11.8963","7.9309","84.7945"
"47.7600","11.9174","356.2943","11.9174","7.9449","84.8320"
"47.8400","11.9372","356.4039","11.9372","7.9581","84.8581"
"47.9200","11.9568","356.5015","11.9568","7.9712","84.8813"
"48.0000","11.9774","356.6418","11.9774","7.9849","84.9147"
"48.0800","11.9988","356.7975","11.9988","7.9992","84.9518"
"48.1600","12.0182","356.8685","12.0182","8.0121","84.9687"
"48.2400","12.0375","356.9474","12.0375","8.0250","84.9875"
"48.3200","12.0562","356.9766","12.0562","8.0374","84.9944"
"48.4000","12.0772","357.1258","12.0772","8.0515","85.0300"
"48.4800","12.0972","357.2231","12.0972","8.0648","85.0531"
"48.5600","12.1169","357.3147","12.1169","8.0779","85.0749"
"48.6400","12.1369","357.4169","12.1369","8.0913","85.0993"
"48.7200","12.1577","357.5297","12.1577","8.1051","85.1261"
"48.8000","12.1774","357.6161","12.1774","8.1183","85.1467"
"48.8800","12.1976","357.7036","12.1976","8.1317","85.1675"
"48.9600","12.2165","357.7545","12.2165","8.1444","85.1796"
"49.0400","12.2370","357.8693","12.2370","8.1580","85.2070"
"49.1200","12.2564","357.9179","12.2564","8.1710","85.2185"
"49.2000","12.2773","358.0545","12.2773","8.1849","85.2511"
"49.2800","12.2985","358.1692","12.2985","8.1990","85.2784"
"49.3600","12.3181","358.2160","12.3181","8.2121","85.2895"
"49.4400","12.3377","358.2575","12.3377","8.2251","85.2994"
"49.5200","12.3570","358.2867","12.3570","8.2380","85.3064"
"49.6000","12.3768","358.3389","12.3768","8.2512","85.3188"
"49.6800","12.3967","358.3995","12.3967","8.2645","85.3332"
"49.7600","12.4162","358.4306","12.4162","8.2775","85.3406"
"49.8400","12.4368","358.5266","12.4368","8.2912","85.3635"
"49.9200","12.4583","358.6435","12.4583","8.3055","85.3913"
"50.0000","12.4772","358.6514","12.4772","8.3181","85.3932"
"50.0800","12.4977","358.7296","12.4977","8.3318","85.4118"
"50.1600","12.5169","358.7373","12.5169","8.3446","85.4136"
"50.2400","12.5370","358.7980","12.5370","8.3580","85.4281"
"50.3200","12.5564","358.8252","12.5564","8.3709","85.4346"
"50.4000","12.5762","358.8593","12.5762","8.3841","85.4427"
"50.4800","12.5973","358.9601","12.5973","8.3982","85.4667"
"50.5600","12.6191","359.0742","12.6191","8.4127","85.4938"
"50.6400","12.6379","359.0642","12.6379","8.4253","85.4915"
"50.7200","12.6577","359.0859","12.6577","8.4384","85.4966"
"50.8000","12.6766","359.0756","12.6766","8.4510","85.4942"
"50.8800","12.6975","359.1684","12.6975","8.4650","85.5163"
"50.9600","12.7172","359.1758","12.7172","8.4781","85.5181"
"51.0400","12.7360","359.1838","12.7360","8.4907","85.5199"
"51.1200","12.7567","359.2575","12.7567","8.5045","85.5375"
"51.2000","12.7779","359.3241","12.7779","8.5186","85.5534"
"51.2800","12.7978","359.3501","12.7978","8.5319","85.5596"
"51.3600","12.8178","359.3911","12.8178","8.5452","85.5693"
"51.4400","12.8365","359.3626","12.8365","8.5577","85.5625"
"51.5200","12.8567","359.4158","12.8567","8.5711","85.5752"
"51.6000","12.8770","359.4522","12.8770","8.5846","85.5839"
"51.6800","12.8966","359.4796","12.8966","8.5977","85.5904"
"51.7600","12.9181","359.5660","12.9181","8.6121","85.6109"
"51.8400","12.9376","359.5460","12.9376","8.6250","85.6062"
"51.9200","12.9579","359.5882","12.9579","8.6386","85.6162"
"52.0000","12.9775","359.5968","12.9775","8.6516","85.6183"
"52.0800","12.9975","359.6181","12.9975","8.6650","85.6234"
"52.1600","13.0171","359.6231","13.0171","8.6780","85.6246"
"52.2400","13.0365","359.6276","13.0365","8.6910","85.6256"
"52.3200","13.0563","359.6745","13.0563","8.7042","85.6368"
"52.4000","13.0778","359.7460","13.0778","8.7185","85.6538"
"52.4800","13.0974","359.7367","13.0974","8.7316","85.6516"
"52.5600","13.1182","359.7714","13.1182","8.7454","85.6599"
"52.6400","13.1372","359.7322","13.1372","8.7582","85.6505"
"52.7200","13.1562","359.7133","13.1562","8.7708","85.6460"
"52.8000","13.1759","359.7130","13.1759","8.7839","85.6460"
"52.8800","13.1969","359.7627","13.1969","8.7979","85.6578"
"52.9600","13.2177","359.7878","13.2177","8.8118","85.6638"
"53.0400","13.2384","359.8054","13.2384","8.8256","85.6680"
"53.1200","13.2575","359.7642","13.2575","8.8384","85.6581"
"53.2000","13.2777","359.7620","13.2777","8.8518","85.6576"
"53.2800","13.2976","359.7565","13.2976","8.8651","85.6563"
"53.3600","13.3174","359.7462","13.3174","8.8783","85.6539"
"53.4400","13.3369","359.7096","13.3369","8.8913","85.6451"
"53.5200","13.3557","359.6518","13.3557","8.9038","85.6314"
"53.6000","13.3771","359.6870","13.3771","8.9181","85.6398"
"53.6800","13.3981","359.7169","13.3981","8.9321","85.6469"
"53.7600","13.4179","359.6772","13.4179","8.9453","85.6374"
"53.8400","13.4372","359.6360","13.4372","8.9581","85.6276"
"53.9200","13.4565","359.5701","13.4565","8.9710","85.6119"
"54.0000","13.4765","359.5586","13.4765","8.9843","85.6092"
"54.0800","13.4976","359.5866","13.4976","8.9984","85.6159"
"54.1600","13.5168","359.5324","13.5168","9.0112","85.6029"
"54.2400","13.5376","359.5192","13.5376","9.0251","85.5998"
"54.3200","13.5577","359.4799","13.5577","9.0384","85.5905"
"54.4000","13.5780","359.4523","13.5780","9.0520","85.5839"
"54.4800","13.5976","359.3989","13.5976","9.0650","85.5712"
"54.5600","13.6170","359.3245","13.6170","9.0780","85.5535"
"54.6400","13.6371","359.2726","13.6371","9.0914","85.5411"
"54.7200","13.6570","359.2259","13.6570","9.1047","85.5300"
"54.8000","13.6759","359.1398","13.6759","9.1173","85.5095"
"54.8800","13.6974","359.1494","13.6974","9.1316","85.5118"
"54.9600","13.7174","359.0688","13.7174","9.1450","85.4926"
"55.0400","13.7375","359.0060","13.7375","9.1584","85.4776"
"55.1200","13.7571","358.9196","13.7571","9.1714","85.4570"
"55.2000","13.7765","358.8470","13.7765","9.1844","85.4397"
"55.2800","13.7968","358.7880","13.7968","9.1979","85.4257"
"55.3600","13.8166","358.7272","13.8166","9.2111","85.4112"
"55.4400","13.8371","358.6790","13.8371","9.2248","85.3998"
"55.5200","13.8578","358.6303","13.8578","9.2385","85.3882"
"55.6000","13.8776","358.5362","13.8776","9.2518","85.3658"
"55.6800","13.8982","358.4852","13.8982","9.2654","85.3536"
"55.7600","13.9180","358.3950","13.9180","9.2787","85.3321"
"55.8400","13.9364","358.2618","13.9364","9.2909","85.3004"
"55.9200","13.9572","358.2220","13.9572","9.3048","85.2909"
"56.0000","13.9762","358.1067","13.9762","9.3175","85.2635"
"56.0800","13.9970","358.0584","13.9970","9.3314","85.2520"
"56.1600","14.0179","357.9760","14.0179","9.3452","85.2324"
"56.2400","14.0376","357.8288","14.0376","9.3584","85.1973"
"56.3200","14.0572","357.6941","14.0572","9.3714","85.1653"
"56.4000","14.0773","357.5955","14.0773","9.3849","85.1418"
"56.4800","14.0967","357.4680","14.0967","9.3978","85.1114"
"56.5600","14.1172","357.3693","14.1172","9.4115","85.0879"
"56.6400","14.1363","357.2097","14.1363","9.4242","85.0499"
"56.7200","14.1573","357.1341","14.1573","9.4382","85.0319"
"56.8000","14.1781","357.0292","14.1781","9.4521","85.0070"
"56.8800","14.1979","356.8933","14.1979","9.4653","84.9746"
"56.9600","14.2174","356.7343","14.2174","9.4783","84.9367"
"57.0400","14.2373","356.5907","14.2373","9.4915","84.9026"
"57.1200","14.2570","356.4358","14.2570","9.5047","84.8657"
"57.2000","14.2770","356.2909","14.2770","9.5180","84.8312"
"57.2800","14.2959","356.1254","14.2959","9.5306","84.7918"
"57.3600","14.3171","356.0305","14.3171","9.5447","84.7692"
"57.4400","14.3378","355.9131","14.3378","9.5585","84.7412"
"57.5200","14.3573","355.7627","14.3573","9.5715","84.7054"
"57.6000","14.3770","355.6058","14.3770","9.5847","84.6681"
"57.6800","14.3961","355.4254","14.3961","9.5974","84.6251"
"57.7600","14.4175","355.3172","14.4175","9.6117","84.5993"
"57.8400","14.4373","355.1474","14.4373","9.6249","84.5589"
"57.9200","14.4569","354.9749","14.4569","9.6379","84.5178"
"58.0000","14.4775","354.8214","14.4775","9.6516","84.4813"
"58.0800","14.4979","354.6456","14.4979","9.6653","84.4394"
"58.1600","14.5180","354.4743","14.5180","9.6787","84.3986"
"58.2400","14.5377","354.2830","14.5377","9.6918","84.3531"
"58.3200","14.5565","353.9060","14.5565","9.7043","84.2633"
"58.4000","14.5768","353.3506","14.5768","9.7179","84.1311"
"58.4800","14.5967","353.1044","14.5967","9.7311","84.0725"
"58.5600","14.6167","352.8909","14.6167","9.7444","84.0216"
"58.6400","14.6373","352.7021","14.6373","9.7582","83.9767"
"58.7200","14.6577","352.4719","14.6577","9.7718","83.9219"
"58.8000","14.6778","352.2395","14.6778","9.7852","83.8665"
"58.8800","14.6975","352.0227","14.6975","9.7984","83.8149"
"58.9600","14.7165","351.7691","14.7165","9.8110","83.7545"
"59.0400","14.7369","351.5624","14.7369","9.8246","83.7053"
"59.1200","14.7565","351.3324","14.7565","9.8377","83.6506"
"59.2000","14.7772","351.1516","14.7772","9.8514","83.6075"
"59.2800","14.7984","350.9743","14.7984","9.8656","83.5653"
"59.3600","14.8180","350.7449","14.8180","9.8787","83.5107"
"59.4400","14.8378","350.5062","14.8378","9.8918","83.4538"
"59.5200","14.8572","350.2701","14.8572","9.9048","83.3976"
"59.6000","14.8768","350.0479","14.8768","9.9178","83.3447"
"59.6800","14.8968","349.8192","14.8968","9.9312","83.2903"
"59.7600","14.9162","349.5655","14.9162","9.9442","83.2299"
"59.8400","14.9369","349.3613","14.9369","9.9579","83.1813"
"59.9200","14.9578","349.1496","14.9578","9.9719","83.1309"
"60.0000","14.9772","348.8969","14.9772","9.9848","83.0707"
"60.0800","14.9976","348.6776","14.9976","9.9984","83.0185"
"60.0910","15.0002","348.6447","15.0002","10.0002","83.0106"