File: data/instron_tests/metamaterials/250416/250416_1310_NSC_m1.is_comp_Exports/240416_1310_NSC_m1_6_1.csv
Results Table 1
,Compresson Axis,H*,V*,Height,Thickness,Width,Area,Fixture separation,Specimen label
,,,,(mm),(mm),(mm),(mm^2),(mm),
"6","X","","","150.00","28.00","150.00","4200.00","150.00","1310_NSC_m1"

Results Table 2
,Modulus (Segment 0 % - 2.5 %),Compresson Axis
,(kPa),
"6","1183.02","X"

Time,Displacement,Force,Compressive displacement,Compressive strain (Displacement),Compressive stress
(s),(mm),(N),(mm),(%),(kPa)
"0.0000","0.0000","-12.1590","0.0000","0.0000","-2.8950"
"0.0800","0.0011","-12.1007","0.0011","0.0008","-2.8811"
"0.1600","0.0175","-11.3087","0.0175","0.0117","-2.6925"
"0.2400","0.0374","-10.4257","0.0374","0.0249","-2.4823"
"0.3200","0.0580","-9.5475","0.0580","0.0387","-2.2732"
"0.4000","0.0772","-8.7647","0.0772","0.0515","-2.0868"
"0.4800","0.0978","-7.9567","0.0978","0.0652","-1.8945"
"0.5600","0.1181","-7.1659","0.1181","0.0787","-1.7062"
"0.6400","0.1378","-6.4040","0.1378","0.0919","-1.5248"
"0.7200","0.1573","-5.6676","0.1573","0.1049","-1.3494"
"0.8000","0.1770","-4.9439","0.1770","0.1180","-1.1771"
"0.8800","0.1973","-4.1757","0.1973","0.1315","-0.9942"
"0.9600","0.2175","-3.4606","0.2175","0.1450","-0.8239"
"1.0400","0.2362","-2.7932","0.2362","0.1575","-0.6650"
"1.1200","0.2571","-2.0522","0.2571","0.1714","-0.4886"
"1.2000","0.2775","-1.3440","0.2775","0.1850","-0.3200"
"1.2800","0.2979","-0.6489","0.2979","0.1986","-0.1545"
"1.3600","0.3180","-0.0094","0.3180","0.2120","-0.0022"
"1.4400","0.3364","0.5410","0.3364","0.2243","0.1288"
"1.5200","0.3568","1.1968","0.3568","0.2379","0.2849"
"1.6000","0.3771","1.8348","0.3771","0.2514","0.4369"
"1.6800","0.3973","2.4773","0.3973","0.2649","0.5898"
"1.7600","0.4182","3.1330","0.4182","0.2788","0.7460"
"1.8400","0.4377","3.6896","0.4377","0.2918","0.8785"
"1.9200","0.4576","4.2700","0.4576","0.3050","1.0167"
"2.0000","0.4773","4.8369","0.4773","0.3182","1.1517"
"2.0800","0.4970","5.3953","0.4970","0.3313","1.2846"
"2.1600","0.5173","5.9664","0.5173","0.3449","1.4206"
"2.2400","0.5369","6.4975","0.5369","0.3579","1.5470"
"2.3200","0.5562","7.0394","0.5562","0.3708","1.6761"
"2.4000","0.5777","7.6773","0.5777","0.3851","1.8279"
"2.4800","0.5975","8.2475","0.5975","0.3983","1.9637"
"2.5600","0.6181","8.8312","0.6181","0.4121","2.1027"
"2.6400","0.6371","9.3225","0.6371","0.4247","2.2197"
"2.7200","0.6563","9.8678","0.6563","0.4376","2.3495"
"2.8000","0.6768","10.4748","0.6768","0.4512","2.4940"
"2.8800","0.6973","11.0809","0.6973","0.4649","2.6383"
"2.9600","0.7174","11.6859","0.7174","0.4783","2.7824"
"3.0400","0.7382","12.3313","0.7382","0.4921","2.9360"
"3.1200","0.7572","12.8890","0.7572","0.5048","3.0688"
"3.2000","0.7777","13.5210","0.7777","0.5185","3.2193"
"3.2800","0.7974","14.1197","0.7974","0.5316","3.3618"
"3.3600","0.8172","14.7437","0.8172","0.5448","3.5104"
"3.4400","0.8368","15.3431","0.8368","0.5578","3.6531"
"3.5200","0.8559","15.9251","0.8559","0.5706","3.7917"
"3.6000","0.8772","16.6191","0.8772","0.5848","3.9569"
"3.6800","0.8983","17.3050","0.8983","0.5988","4.1202"
"3.7600","0.9178","17.9141","0.9178","0.6118","4.2653"
"3.8400","0.9375","18.5300","0.9375","0.6250","4.4119"
"3.9200","0.9559","19.1010","0.9559","0.6373","4.5479"
"4.0000","0.9762","19.7582","0.9762","0.6508","4.7043"
"4.0800","0.9979","20.4682","0.9979","0.6653","4.8734"
"4.1600","1.0169","21.0482","1.0169","0.6780","5.0115"
"4.2400","1.0373","21.6767","1.0373","0.6916","5.1611"
"4.3200","1.0580","22.3222","1.0580","0.7053","5.3148"
"4.4000","1.0784","22.9534","1.0784","0.7189","5.4651"
"4.4800","1.0978","23.5490","1.0978","0.7319","5.6069"
"4.5600","1.1171","24.1292","1.1171","0.7447","5.7451"
"4.6400","1.1373","24.7636","1.1373","0.7582","5.8961"
"4.7200","1.1570","25.3733","1.1570","0.7713","6.0413"
"4.8000","1.1758","25.9469","1.1758","0.7839","6.1778"
"4.8800","1.1974","26.6482","1.1974","0.7982","6.3448"
"4.9600","1.2177","27.2345","1.2177","0.8118","6.4844"
"5.0400","1.2377","27.8255","1.2377","0.8252","6.6251"
"5.1200","1.2573","28.4131","1.2573","0.8382","6.7650"
"5.2000","1.2764","29.0157","1.2764","0.8509","6.9085"
"5.2800","1.2972","29.6846","1.2972","0.8648","7.0678"
"5.3600","1.3171","30.3268","1.3171","0.8781","7.2207"
"5.4400","1.3369","30.9724","1.3369","0.8913","7.3744"
"5.5200","1.3579","31.6680","1.3579","0.9052","7.5400"
"5.6000","1.3778","32.3120","1.3778","0.9186","7.6933"
"5.6800","1.3982","32.9794","1.3982","0.9321","7.8522"
"5.7600","1.4181","33.6176","1.4181","0.9454","8.0042"
"5.8400","1.4365","34.1994","1.4365","0.9577","8.1427"
"5.9200","1.4570","34.8691","1.4570","0.9713","8.3022"
"6.0000","1.4760","35.4703","1.4760","0.9840","8.4453"
"6.0800","1.4972","36.1959","1.4972","0.9981","8.6181"
"6.1600","1.5184","36.9077","1.5184","1.0123","8.7876"
"6.2400","1.5377","37.5130","1.5377","1.0251","8.9317"
"6.3200","1.5572","38.1438","1.5572","1.0381","9.0819"
"6.4000","1.5772","38.8003","1.5772","1.0515","9.2382"
"6.4800","1.5963","39.4096","1.5963","1.0642","9.3832"
"6.5600","1.6175","40.0955","1.6175","1.0783","9.5465"
"6.6400","1.6364","40.6666","1.6364","1.0909","9.6825"
"6.7200","1.6576","41.3721","1.6576","1.1050","9.8505"
"6.8000","1.6782","42.0382","1.6782","1.1188","10.0091"
"6.8800","1.6981","42.6731","1.6981","1.1320","10.1603"
"6.9600","1.7174","43.2595","1.7174","1.1449","10.2999"
"7.0400","1.7371","43.9053","1.7371","1.1581","10.4537"
"7.1200","1.7568","44.5565","1.7568","1.1712","10.6087"
"7.2000","1.7775","45.2418","1.7775","1.1850","10.7719"
"7.2800","1.7963","45.8499","1.7963","1.1976","10.9166"
"7.3600","1.8173","46.5313","1.8173","1.2115","11.0789"
"7.4400","1.8377","47.1749","1.8377","1.2251","11.2321"
"7.5200","1.8574","47.8326","1.8574","1.2382","11.3887"
"7.6000","1.8776","48.4949","1.8776","1.2517","11.5464"
"7.6800","1.8962","49.0998","1.8962","1.2641","11.6904"
"7.7600","1.9174","49.8412","1.9174","1.2783","11.8669"
"7.8400","1.9374","50.5126","1.9374","1.2916","12.0268"
"7.9200","1.9567","51.1651","1.9567","1.3045","12.1822"
"8.0000","1.9776","51.9017","1.9776","1.3184","12.3576"
"8.0800","1.9985","52.6081","1.9985","1.3323","12.5257"
"8.1600","2.0178","53.2501","2.0178","1.3452","12.6786"
"8.2400","2.0378","53.9332","2.0378","1.3585","12.8412"
"8.3200","2.0560","54.5388","2.0560","1.3707","12.9854"
"8.4000","2.0771","55.2846","2.0771","1.3848","13.1630"
"8.4800","2.0971","55.9926","2.0971","1.3981","13.3316"
"8.5600","2.1172","56.6929","2.1172","1.4115","13.4983"
"8.6400","2.1373","57.3958","2.1373","1.4249","13.6657"
"8.7200","2.1574","58.0722","2.1574","1.4383","13.8267"
"8.8000","2.1771","58.7370","2.1771","1.4514","13.9850"
"8.8800","2.1982","59.4797","2.1982","1.4655","14.1618"
"8.9600","2.2165","60.1000","2.2165","1.4777","14.3095"
"9.0400","2.2371","60.8388","2.2371","1.4914","14.4854"
"9.1200","2.2567","61.5028","2.2567","1.5044","14.6435"
"9.2000","2.2773","62.2472","2.2773","1.5182","14.8208"
"9.2800","2.2985","62.9998","2.2985","1.5323","15.0000"
"9.3600","2.3180","63.6727","2.3180","1.5454","15.1602"
"9.4400","2.3376","64.3373","2.3376","1.5584","15.3184"
"9.5200","2.3575","65.0199","2.3575","1.5716","15.4809"
"9.6000","2.3768","65.7105","2.3768","1.5845","15.6454"
"9.6800","2.3972","66.4463","2.3972","1.5981","15.8206"
"9.7600","2.4165","67.1016","2.4165","1.6110","15.9766"
"9.8400","2.4370","67.8483","2.4370","1.6247","16.1544"
"9.9200","2.4578","68.5621","2.4578","1.6385","16.3243"
"10.0000","2.4772","69.2406","2.4772","1.6515","16.4858"
"10.0800","2.4977","69.9635","2.4977","1.6651","16.6580"
"10.1600","2.5169","70.6059","2.5169","1.6779","16.8109"
"10.2400","2.5372","71.2814","2.5372","1.6915","16.9718"
"10.3200","2.5570","71.9737","2.5570","1.7047","17.1366"
"10.4000","2.5763","72.6291","2.5763","1.7176","17.2926"
"10.4800","2.5977","73.4114","2.5977","1.7318","17.4789"
"10.5600","2.6187","74.1382","2.6187","1.7458","17.6520"
"10.6400","2.6373","74.7689","2.6373","1.7582","17.8021"
"10.7200","2.6574","75.4655","2.6574","1.7716","17.9680"
"10.8000","2.6768","76.1271","2.6768","1.7845","18.1255"
"10.8800","2.6977","76.8727","2.6977","1.7985","18.3030"
"10.9600","2.7176","77.5135","2.7176","1.8117","18.4556"
"11.0400","2.7360","78.1281","2.7360","1.8240","18.6019"
"11.1200","2.7569","78.8808","2.7569","1.8379","18.7811"
"11.2000","2.7778","79.6339","2.7778","1.8519","18.9604"
"11.2800","2.7977","80.3378","2.7977","1.8652","19.1281"
"11.3600","2.8176","81.0129","2.8176","1.8784","19.2888"
"11.4400","2.8360","81.6180","2.8360","1.8907","19.4329"
"11.5200","2.8570","82.3808","2.8570","1.9047","19.6145"
"11.6000","2.8774","83.0828","2.8774","1.9183","19.7816"
"11.6800","2.8969","83.7601","2.8969","1.9313","19.9429"
"11.7600","2.9178","84.4753","2.9178","1.9452","20.1132"
"11.8400","2.9377","85.1621","2.9377","1.9585","20.2767"
"11.9200","2.9582","85.8969","2.9582","1.9721","20.4516"
"12.0000","2.9778","86.5810","2.9778","1.9852","20.6145"
"12.0800","2.9970","87.2514","2.9970","1.9980","20.7741"
"12.1600","3.0172","87.9613","3.0172","2.0114","20.9432"
"12.2400","3.0368","88.6428","3.0368","2.0246","21.1054"
"12.3200","3.0562","89.3279","3.0562","2.0375","21.2685"
"12.4000","3.0780","90.1105","3.0780","2.0520","21.4549"
"12.4800","3.0973","90.7500","3.0973","2.0648","21.6071"
"12.5600","3.1181","91.4561","3.1181","2.0787","21.7753"
"12.6400","3.1373","92.1291","3.1373","2.0915","21.9355"
"12.7200","3.1566","92.8024","3.1566","2.1044","22.0958"
"12.8000","3.1766","93.5086","3.1766","2.1177","22.2640"
"12.8800","3.1969","94.2231","3.1969","2.1312","22.4341"
"12.9600","3.2176","94.9687","3.2176","2.1451","22.6116"
"13.0400","3.2384","95.7014","3.2384","2.1590","22.7860"
"13.1200","3.2572","96.3487","3.2572","2.1715","22.9402"
"13.2000","3.2776","97.0671","3.2776","2.1851","23.1112"
"13.2800","3.2975","97.7511","3.2975","2.1983","23.2741"
"13.3600","3.3175","98.4587","3.3175","2.2117","23.4425"
"13.4400","3.3369","99.1184","3.3369","2.2246","23.5996"
"13.5200","3.3556","99.7139","3.3556","2.2370","23.7414"
"13.6000","3.3773","100.5134","3.3773","2.2515","23.9318"
"13.6800","3.3984","101.2693","3.3984","2.2656","24.1117"
"13.7600","3.4176","101.9336","3.4176","2.2784","24.2699"
"13.8400","3.4375","102.6310","3.4375","2.2916","24.4360"
"13.9200","3.4565","103.2728","3.4565","2.3043","24.5888"
"14.0000","3.4768","104.0018","3.4768","2.3179","24.7623"
"14.0800","3.4976","104.7354","3.4976","2.3317","24.9370"
"14.1600","3.5166","105.4006","3.5166","2.3444","25.0954"
"14.2400","3.5380","106.1702","3.5380","2.3587","25.2786"
"14.3200","3.5576","106.8537","3.5576","2.3717","25.4414"
"14.4000","3.5778","107.5714","3.5778","2.3852","25.6122"
"14.4800","3.5974","108.2543","3.5974","2.3983","25.7748"
"14.5600","3.6171","108.9206","3.6171","2.4114","25.9335"
"14.6400","3.6372","109.6189","3.6372","2.4248","26.0997"
"14.7200","3.6571","110.3092","3.6571","2.4380","26.2641"
"14.8000","3.6760","110.9681","3.6760","2.4507","26.4210"
"14.8800","3.6974","111.7545","3.6974","2.4649","26.6082"
"14.9600","3.7174","112.4450","3.7174","2.4783","26.7726"
"15.0400","3.7375","113.1546","3.7375","2.4917","26.9416"
"15.1200","3.7570","113.8227","3.7570","2.5046","27.1007"
"15.2000","3.7762","114.4908","3.7762","2.5175","27.2597"
"15.2800","3.7973","115.2341","3.7973","2.5316","27.4367"
"15.3600","3.8173","115.9329","3.8173","2.5448","27.6031"
"15.4400","3.8374","116.6324","3.8374","2.5583","27.7696"
"15.5200","3.8578","117.3628","3.8578","2.5719","27.9435"
"15.6000","3.8776","118.0322","3.8776","2.5850","28.1029"
"15.6800","3.8979","118.7588","3.8979","2.5986","28.2759"
"15.7600","3.9180","119.4658","3.9180","2.6120","28.4442"
"15.8400","3.9366","120.1054","3.9366","2.6244","28.5965"
"15.9200","3.9571","120.7950","3.9571","2.6381","28.7607"
"16.0000","3.9765","121.4688","3.9765","2.6510","28.9211"
"16.0800","3.9975","122.2271","3.9975","2.6650","29.1017"
"16.1600","4.0181","122.9582","4.0181","2.6787","29.2758"
"16.2400","4.0373","123.6056","4.0373","2.6916","29.4299"
"16.3200","4.0570","124.2906","4.0570","2.7047","29.5930"
"16.4000","4.0769","124.9916","4.0769","2.7180","29.7599"
"16.4800","4.0964","125.6824","4.0964","2.7310","29.9244"
"16.5600","4.1175","126.4409","4.1175","2.7450","30.1050"
"16.6400","4.1365","127.0807","4.1365","2.7577","30.2573"
"16.7200","4.1578","127.8540","4.1578","2.7719","30.4414"
"16.8000","4.1781","128.5673","4.1781","2.7854","30.6113"
"16.8800","4.1979","129.2589","4.1979","2.7986","30.7759"
"16.9600","4.2176","129.9509","4.2176","2.8118","30.9407"
"17.0400","4.2374","130.6324","4.2374","2.8249","31.1030"
"17.1200","4.2568","131.3059","4.2568","2.8378","31.2633"
"17.2000","4.2769","132.0093","4.2769","2.8512","31.4308"
"17.2800","4.2959","132.6566","4.2959","2.8639","31.5849"
"17.3600","4.3176","133.4541","4.3176","2.8784","31.7748"
"17.4400","4.3380","134.1460","4.3380","2.8920","31.9395"
"17.5200","4.3572","134.7796","4.3572","2.9048","32.0904"
"17.6000","4.3772","135.4888","4.3772","2.9182","32.2592"
"17.6800","4.3967","136.1603","4.3967","2.9311","32.4191"
"17.7600","4.4174","136.8770","4.4174","2.9449","32.5898"
"17.8400","4.4368","137.5505","4.4368","2.9579","32.7501"
"17.9200","4.4566","138.2398","4.4566","2.9711","32.9142"
"18.0000","4.4775","138.9931","4.4775","2.9850","33.0936"
"18.0800","4.4984","139.7262","4.4984","2.9989","33.2681"
"18.1600","4.5180","140.4066","4.5180","3.0120","33.4301"
"18.2400","4.5377","141.0926","4.5377","3.0252","33.5935"
"18.3200","4.5560","141.6940","4.5560","3.0373","33.7367"
"18.4000","4.5773","142.4688","4.5773","3.0515","33.9211"
"18.4800","4.5969","143.1403","4.5969","3.0646","34.0810"
"18.5600","4.6169","143.8559","4.6169","3.0780","34.2514"
"18.6400","4.6371","144.5651","4.6371","3.0914","34.4203"
"18.7200","4.6573","145.2633","4.6573","3.1049","34.5865"
"18.8000","4.6774","145.9652","4.6774","3.1183","34.7536"
"18.8800","4.6978","146.6776","4.6978","3.1319","34.9232"
"18.9600","4.7162","147.2948","4.7162","3.1441","35.0702"
"19.0400","4.7369","148.0249","4.7369","3.1579","35.2440"
"19.1200","4.7565","148.6822","4.7565","3.1710","35.4005"
"19.2000","4.7775","149.4352","4.7775","3.1850","35.5798"
"19.2800","4.7984","150.1814","4.7984","3.1989","35.7575"
"19.3600","4.8183","150.8648","4.8183","3.2122","35.9202"
"19.4400","4.8379","151.5412","4.8379","3.2253","36.0812"
"19.5200","4.8576","152.2198","4.8576","3.2384","36.2428"
"19.6000","4.8770","152.8957","4.8770","3.2513","36.4037"
"19.6800","4.8973","153.6384","4.8973","3.2649","36.5806"
"19.7600","4.9166","154.2797","4.9166","3.2778","36.7333"
"19.8400","4.9371","155.0039","4.9371","3.2914","36.9057"
"19.9200","4.9579","155.7382","4.9579","3.3053","37.0805"
"20.0000","4.9772","156.3992","4.9772","3.3181","37.2379"
"20.0800","4.9976","157.1114","4.9976","3.3317","37.4075"
"20.1600","5.0169","157.7576","5.0169","3.3446","37.5613"
"20.2400","5.0369","158.4601","5.0369","3.3579","37.7286"
"20.3200","5.0567","159.1324","5.0567","3.3711","37.8887"
"20.4000","5.0766","159.8236","5.0766","3.3844","38.0532"
"20.4800","5.0979","160.5880","5.0979","3.3986","38.2352"
"20.5600","5.1183","161.2840","5.1183","3.4122","38.4010"
"20.6400","5.1373","161.9361","5.1373","3.4249","38.5562"
"20.7200","5.1574","162.6323","5.1574","3.4383","38.7220"
"20.8000","5.1765","163.2691","5.1765","3.4510","38.8736"
"20.8800","5.1966","163.9661","5.1966","3.4644","39.0395"
"20.9600","5.2172","164.6790","5.2172","3.4782","39.2093"
"21.0400","5.2365","165.3310","5.2365","3.4910","39.3645"
"21.1200","5.2570","166.0522","5.2570","3.5046","39.5362"
"21.2000","5.2778","166.7769","5.2778","3.5185","39.7088"
"21.2800","5.2979","167.4735","5.2979","3.5319","39.8746"
"21.3600","5.3179","168.1560","5.3179","3.5453","40.0371"
"21.4400","5.3362","168.7502","5.3362","3.5575","40.1786"
"21.5200","5.3567","169.4720","5.3567","3.5711","40.3505"
"21.6000","5.3770","170.1941","5.3770","3.5847","40.5224"
"21.6800","5.3973","170.9099","5.3973","3.5982","40.6928"
"21.7600","5.4186","171.6559","5.4186","3.6124","40.8705"
"21.8400","5.4377","172.2899","5.4377","3.6251","41.0214"
"21.9200","5.4578","172.9753","5.4578","3.6386","41.1846"
"22.0000","5.4777","173.6627","5.4777","3.6518","41.3483"
"22.0800","5.4972","174.3173","5.4972","3.6648","41.5041"
"22.1600","5.5170","174.9935","5.5170","3.6780","41.6651"
"22.2400","5.5366","175.6550","5.5366","3.6911","41.8226"
"22.3200","5.5563","176.3382","5.5563","3.7042","41.9853"
"22.4000","5.5779","177.1165","5.5779","3.7186","42.1706"
"22.4800","5.5971","177.7459","5.5971","3.7314","42.3205"
"22.5600","5.6181","178.4777","5.6181","3.7454","42.4947"
"22.6400","5.6373","179.1107","5.6373","3.7582","42.6454"
"22.7200","5.6565","179.7599","5.6565","3.7710","42.8000"
"22.8000","5.6765","180.4524","5.6765","3.7843","42.9648"
"22.8800","5.6968","181.1480","5.6968","3.7979","43.1305"
"22.9600","5.7173","181.8561","5.7173","3.8115","43.2991"
"23.0400","5.7382","182.5874","5.7382","3.8255","43.4732"
"23.1200","5.7574","183.2215","5.7574","3.8382","43.6242"
"23.2000","5.7775","183.9043","5.7775","3.8516","43.7867"
"23.2800","5.7972","184.5699","5.7972","3.8648","43.9452"
"23.3600","5.8172","185.2616","5.8172","3.8782","44.1099"
"23.4400","5.8373","185.9387","5.8373","3.8916","44.2711"
"23.5200","5.8562","186.5568","5.8562","3.9041","44.4183"
"23.6000","5.8773","187.3016","5.8773","3.9182","44.5956"
"23.6800","5.8985","188.0541","5.8985","3.9323","44.7748"
"23.7600","5.9181","188.7151","5.9181","3.9454","44.9322"
"23.8400","5.9374","189.3569","5.9374","3.9583","45.0850"
"23.9200","5.9565","189.9633","5.9565","3.9710","45.2294"
"24.0000","5.9769","190.6790","5.9769","3.9846","45.3998"
"24.0800","5.9980","191.4000","5.9980","3.9987","45.5714"
"24.1600","6.0164","191.9842","6.0164","4.0109","45.7105"
"24.2400","6.0377","192.7126","6.0377","4.0251","45.8840"
"24.3200","6.0579","193.4014","6.0579","4.0386","46.0480"
"24.4000","6.0782","194.0794","6.0782","4.0521","46.2094"
"24.4800","6.0975","194.7196","6.0975","4.0650","46.3618"
"24.5600","6.1172","195.3709","6.1172","4.0781","46.5169"
"24.6400","6.1372","196.0340","6.1372","4.0915","46.6748"
"24.7200","6.1573","196.7110","6.1573","4.1049","46.8359"
"24.8000","6.1757","197.3098","6.1757","4.1171","46.9785"
"24.8800","6.1974","198.0740","6.1974","4.1316","47.1605"
"24.9600","6.2178","198.7502","6.2178","4.1452","47.3215"
"25.0400","6.2375","199.3880","6.2375","4.1584","47.4733"
"25.1200","6.2571","200.0377","6.2571","4.1714","47.6280"
"25.2000","6.2763","200.6703","6.2763","4.1842","47.7786"
"25.2800","6.2972","201.3783","6.2972","4.1981","47.9472"
"25.3600","6.3175","202.0857","6.3175","4.2117","48.1156"
"25.4400","6.3369","202.7093","6.3369","4.2246","48.2641"
"25.5200","6.3573","203.4086","6.3573","4.2382","48.4306"
"25.6000","6.3779","204.0918","6.3779","4.2520","48.5933"
"25.6800","6.3978","204.7494","6.3978","4.2652","48.7498"
"25.7600","6.4180","205.4102","6.4180","4.2787","48.9072"
"25.8400","6.4367","206.0184","6.4367","4.2911","49.0520"
"25.9200","6.4571","206.6954","6.4571","4.3047","49.2132"
"26.0000","6.4761","207.3079","6.4761","4.3174","49.3590"
"26.0800","6.4974","208.0454","6.4974","4.3316","49.5346"
"26.1600","6.5183","208.7601","6.5183","4.3455","49.7048"
"26.2400","6.5377","209.3718","6.5377","4.3585","49.8504"
"26.3200","6.5575","210.0150","6.5575","4.3716","50.0036"
"26.4000","6.5771","210.6661","6.5771","4.3847","50.1586"
"26.4800","6.5966","211.3182","6.5966","4.3977","50.3139"
"26.5600","6.6176","212.0206","6.6176","4.4117","50.4811"
"26.6400","6.6364","212.6256","6.6364","4.4243","50.6252"
"26.7200","6.6573","213.3230","6.6573","4.4382","50.7912"
"26.8000","6.6783","214.0335","6.6783","4.4522","50.9604"
"26.8800","6.6982","214.6895","6.6982","4.4654","51.1165"
"26.9600","6.7175","215.3057","6.7175","4.4783","51.2633"
"27.0400","6.7371","215.9572","6.7371","4.4914","51.4184"
"27.1200","6.7571","216.6193","6.7571","4.5047","51.5760"
"27.2000","6.7772","217.2814","6.7772","4.5181","51.7337"
"27.2800","6.7958","217.8578","6.7958","4.5305","51.8709"
"27.3600","6.8173","218.6051","6.8173","4.5448","52.0488"
"27.4400","6.8380","219.2993","6.8380","4.5587","52.2141"
"27.5200","6.8576","219.9426","6.8576","4.5718","52.3673"
"27.6000","6.8774","220.5797","6.8774","4.5849","52.5190"
"27.6800","6.8965","221.1887","6.8965","4.5977","52.6640"
"27.7600","6.9174","221.8911","6.9174","4.6116","52.8312"
"27.8400","6.9368","222.5001","6.9368","4.6246","52.9762"
"27.9200","6.9562","223.1225","6.9562","4.6374","53.1244"
"28.0000","6.9777","223.8588","6.9777","4.6518","53.2997"
"28.0800","6.9987","224.5440","6.9987","4.6658","53.4629"
"28.1600","7.0181","225.1664","7.0181","4.6787","53.6110"
"28.2400","7.0376","225.7801","7.0376","4.6918","53.7572"
"28.3200","7.0562","226.3618","7.0562","4.7042","53.8957"
"28.4000","7.0772","227.0605","7.0772","4.7181","54.0620"
"28.4800","7.0969","227.6939","7.0969","4.7312","54.2128"
"28.5600","7.1170","228.3589","7.1170","4.7447","54.3712"
"28.6400","7.1372","229.0276","7.1372","4.7582","54.5304"
"28.7200","7.1572","229.6472","7.1572","4.7714","54.6779"
"28.8000","7.1773","230.2930","7.1773","4.7849","54.8317"
"28.8800","7.1980","230.9706","7.1980","4.7987","54.9930"
"28.9600","7.2169","231.5474","7.2169","4.8112","55.1303"
"29.0400","7.2370","232.2008","7.2370","4.8247","55.2859"
"29.1200","7.2562","232.8026","7.2562","4.8375","55.4292"
"29.2000","7.2774","233.5095","7.2774","4.8516","55.5975"
"29.2800","7.2987","234.2265","7.2987","4.8658","55.7682"
"29.3600","7.3184","234.8428","7.3184","4.8789","55.9150"
"29.4400","7.3379","235.4417","7.3379","4.8920","56.0575"
"29.5200","7.3572","236.0298","7.3572","4.9048","56.1976"
"29.6000","7.3765","236.6370","7.3765","4.9177","56.3421"
"29.6800","7.3974","237.3120","7.3974","4.9316","56.5029"
"29.7600","7.4166","237.8820","7.4166","4.9444","56.6386"
"29.8400","7.4368","238.5241","7.4368","4.9579","56.7915"
"29.9200","7.4580","239.2020","7.4580","4.9720","56.9529"
"30.0000","7.4774","239.8047","7.4774","4.9850","57.0964"
"30.0800","7.4977","240.4345","7.4977","4.9985","57.2463"
"30.1600","7.5167","240.9878","7.5167","5.0111","57.3780"
"30.2400","7.5369","241.6291","7.5369","5.0246","57.5307"
"30.3200","7.5565","242.2095","7.5565","5.0377","57.6689"
"30.4000","7.5766","242.8183","7.5766","5.0510","57.8139"
"30.4800","7.5978","243.5056","7.5978","5.0652","57.9775"
"30.5600","7.6187","244.1523","7.6187","5.0791","58.1315"
"30.6400","7.6379","244.7357","7.6379","5.0920","58.2704"
"30.7200","7.6577","245.3189","7.6577","5.1051","58.4093"
"30.8000","7.6767","245.8709","7.6767","5.1178","58.5407"
"30.8800","7.6977","246.5376","7.6977","5.1318","58.6994"
"30.9600","7.7174","247.1092","7.7174","5.1449","58.8355"
"31.0400","7.7362","247.6459","7.7362","5.1574","58.9633"
"31.1200","7.7571","248.3044","7.7571","5.1714","59.1201"
"31.2000","7.7779","248.9245","7.7779","5.1853","59.2677"
"31.2800","7.7978","249.5138","7.7978","5.1985","59.4080"
"31.3600","7.8179","250.1098","7.8179","5.2119","59.5500"
"31.4400","7.8364","250.6120","7.8364","5.2243","59.6695"
"31.5200","7.8567","251.2265","7.8567","5.2378","59.8158"
"31.6000","7.8770","251.8258","7.8770","5.2513","59.9585"
"31.6800","7.8971","252.4228","7.8971","5.2647","60.1007"
"31.7600","7.9184","253.0810","7.9184","5.2790","60.2574"
"31.8400","7.9377","253.5997","7.9377","5.2918","60.3809"
"31.9200","7.9580","254.1927","7.9580","5.3053","60.5221"
"32.0000","7.9776","254.7481","7.9776","5.3184","60.6543"
"32.0800","7.9970","255.2915","7.9970","5.3313","60.7837"
"32.1600","8.0172","255.8834","8.0172","5.3448","60.9246"
"32.2400","8.0366","256.4219","8.0366","5.3578","61.0528"
"32.3200","8.0561","256.9867","8.0561","5.3707","61.1873"
"32.4000","8.0776","257.6450","8.0776","5.3851","61.3440"
"32.4800","8.0971","258.1827","8.0971","5.3981","61.4721"
"32.5600","8.1181","258.8193","8.1181","5.4121","61.6236"
"32.6400","8.1374","259.3592","8.1374","5.4249","61.7522"
"32.7200","8.1562","259.8797","8.1562","5.4375","61.8761"
"32.8000","8.1765","260.4864","8.1765","5.4510","62.0206"
"32.8800","8.1972","261.0990","8.1972","5.4648","62.1664"
"32.9600","8.2174","261.6971","8.2174","5.4783","62.3088"
"33.0400","8.2383","262.3340","8.2383","5.4922","62.4605"
"33.1200","8.2575","262.8718","8.2575","5.5050","62.5885"
"33.2000","8.2779","263.4853","8.2779","5.5186","62.7346"
"33.2800","8.2973","264.0267","8.2973","5.5316","62.8635"
"33.3600","8.3174","264.6122","8.3174","5.5449","63.0029"
"33.4400","8.3370","265.1850","8.3370","5.5580","63.1393"
"33.5200","8.3558","265.6952","8.3558","5.5705","63.2607"
"33.6000","8.3770","266.3484","8.3770","5.5847","63.4163"
"33.6800","8.3980","266.9838","8.3980","5.5987","63.5676"
"33.7600","8.4177","267.5518","8.4177","5.6118","63.7028"
"33.8400","8.4372","268.1044","8.4372","5.6248","63.8344"
"33.9200","8.4566","268.6341","8.4566","5.6377","63.9605"
"34.0000","8.4769","269.2445","8.4769","5.6513","64.1058"
"34.0800","8.4976","269.8515","8.4976","5.6651","64.2504"
"34.1600","8.5167","270.3795","8.5167","5.6778","64.3761"
"34.2400","8.5380","271.0173","8.5380","5.6920","64.5279"
"34.3200","8.5579","271.5672","8.5579","5.7053","64.6589"
"34.4000","8.5779","272.1283","8.5779","5.7186","64.7925"
"34.4800","8.5974","272.6665","8.5974","5.7316","64.9206"
"34.5600","8.6167","273.1956","8.6167","5.7445","65.0466"
"34.6400","8.6372","273.7833","8.6372","5.7582","65.1865"
"34.7200","8.6576","274.3560","8.6576","5.7717","65.3229"
"34.8000","8.6761","274.8503","8.6761","5.7841","65.4405"
"34.8800","8.6971","275.4619","8.6971","5.7980","65.5862"
"34.9600","8.7169","275.9910","8.7169","5.8113","65.7121"
"35.0400","8.7381","276.6161","8.7381","5.8254","65.8610"
"35.1200","8.7577","277.1363","8.7577","5.8384","65.9848"
"35.2000","8.7765","277.6502","8.7765","5.8510","66.1072"
"35.2800","8.7970","278.2215","8.7970","5.8647","66.2432"
"35.3600","8.8170","278.7703","8.8170","5.8780","66.3739"
"35.4400","8.8369","279.3264","8.8369","5.8913","66.5063"
"35.5200","8.8579","279.9080","8.8579","5.9052","66.6448"
"35.6000","8.8777","280.4279","8.8777","5.9185","66.7686"
"35.6800","8.8980","280.9833","8.8980","5.9320","66.9008"
"35.7600","8.9179","281.5194","8.9179","5.9453","67.0284"
"35.8400","8.9367","282.0060","8.9367","5.9578","67.1443"
"35.9200","8.9568","282.5470","8.9568","5.9712","67.2731"
"36.0000","8.9761","283.0674","8.9761","5.9841","67.3970"
"36.0800","8.9974","283.6700","8.9974","5.9982","67.5405"
"36.1600","9.0181","284.2415","9.0181","6.0120","67.6765"
"36.2400","9.0377","284.7420","9.0377","6.0251","67.7957"
"36.3200","9.0569","285.2218","9.0569","6.0379","67.9100"
"36.4000","9.0768","285.7432","9.0768","6.0512","68.0341"
"36.4800","9.0969","286.2863","9.0969","6.0646","68.1634"
"36.5600","9.1176","286.8466","9.1176","6.0784","68.2968"
"36.6400","9.1359","287.2785","9.1359","6.0906","68.3996"
"36.7200","9.1577","287.9029","9.1577","6.1051","68.5483"
"36.8000","9.1784","288.4564","9.1784","6.1189","68.6801"
"36.8800","9.1985","288.9758","9.1985","6.1323","68.8038"
"36.9600","9.2175","289.4384","9.2175","6.1450","68.9139"
"37.0400","9.2371","289.8320","9.2371","6.1581","69.0076"
"37.1200","9.2570","290.3524","9.2570","6.1713","69.1315"
"37.2000","9.2767","290.8475","9.2767","6.1845","69.2494"
"37.2800","9.2958","291.3159","9.2958","6.1972","69.3609"
"37.3600","9.3176","291.9039","9.3176","6.2117","69.5009"
"37.4400","9.3381","292.4108","9.3381","6.2254","69.6216"
"37.5200","9.3576","292.9045","9.3576","6.2384","69.7392"
"37.6000","9.3773","293.3896","9.3773","6.2515","69.8547"
"37.6800","9.3965","293.8433","9.3965","6.2644","69.9627"
"37.7600","9.4173","294.3836","9.4173","6.2782","70.0913"
"37.8400","9.4370","294.8545","9.4370","6.2913","70.2035"
"37.9200","9.4566","295.3408","9.4566","6.3044","70.3192"
"38.0000","9.4777","295.8873","9.4777","6.3185","70.4494"
"38.0800","9.4985","296.4042","9.4985","6.3323","70.5724"
"38.1600","9.5177","296.8580","9.5177","6.3451","70.6805"
"38.2400","9.5377","297.3344","9.5377","6.3584","70.7939"
"38.3200","9.5560","297.7352","9.5560","6.3707","70.8893"
"38.4000","9.5773","298.2844","9.5773","6.3849","71.0201"
"38.4800","9.5970","298.7408","9.5970","6.3980","71.1288"
"38.5600","9.6172","299.2440","9.6172","6.4115","71.2486"
"38.6400","9.6370","299.7036","9.6370","6.4247","71.3580"
"38.7200","9.6574","300.1913","9.6574","6.4383","71.4741"
"38.8000","9.6773","300.6600","9.6773","6.4516","71.5857"
"38.8800","9.6979","301.1393","9.6978","6.4652","71.6998"
"38.9600","9.7166","301.5624","9.7166","6.4777","71.8006"
"39.0400","9.7371","302.0589","9.7371","6.4914","71.9188"
"39.1200","9.7564","302.4786","9.7564","6.5043","72.0187"
"39.2000","9.7773","303.0137","9.7773","6.5182","72.1461"
"39.2800","9.7984","303.5050","9.7984","6.5322","72.2631"
"39.3600","9.8180","303.9395","9.8180","6.5453","72.3665"
"39.4400","9.8375","304.3562","9.8375","6.5583","72.4658"
"39.5200","9.8571","304.8015","9.8571","6.5714","72.5718"
"39.6000","9.8766","305.2353","9.8766","6.5844","72.6751"
"39.6800","9.8970","305.7199","9.8970","6.5980","72.7904"
"39.7600","9.9166","306.1182","9.9166","6.6110","72.8853"
"39.8400","9.9374","306.6209","9.9374","6.6249","73.0050"
"39.9200","9.9582","307.1017","9.9582","6.6388","73.1194"
"40.0000","9.9770","307.4752","9.9770","6.6513","73.2084"
"40.0800","9.9978","307.9359","9.9978","6.6652","73.3181"
"40.1600","10.0168","308.3228","10.0168","6.6779","73.4102"
"40.2400","10.0371","308.7707","10.0371","6.6914","73.5168"
"40.3200","10.0566","309.1825","10.0566","6.7044","73.6149"
"40.4000","10.0765","309.6117","10.0765","6.7177","73.7171"
"40.4800","10.0978","310.1112","10.0978","6.7319","73.8360"
"40.5600","10.1189","310.5682","10.1189","6.7459","73.9448"
"40.6400","10.1373","310.9166","10.1373","6.7582","74.0278"
"40.7200","10.1574","311.3394","10.1574","6.7716","74.1284"
"40.8000","10.1769","311.7332","10.1769","6.7846","74.2222"
"40.8800","10.1979","312.1866","10.1979","6.7986","74.3302"
"40.9600","10.2175","312.5740","10.2175","6.8117","74.4224"
"41.0400","10.2361","312.9275","10.2361","6.8241","74.5065"
"41.1200","10.2565","313.3508","10.2565","6.8377","74.6073"
"41.2000","10.2776","313.8181","10.2776","6.8518","74.7186"
"41.2800","10.2981","314.2440","10.2981","6.8654","74.8200"
"41.3600","10.3180","314.6494","10.3180","6.8787","74.9165"
"41.4400","10.3365","314.9624","10.3365","6.8910","74.9910"
"41.5200","10.3566","315.3778","10.3566","6.9044","75.0900"
"41.6000","10.3770","315.8061","10.3770","6.9180","75.1919"
"41.6800","10.3970","316.2110","10.3970","6.9314","75.2883"
"41.7600","10.4182","316.6677","10.4182","6.9454","75.3971"
"41.8400","10.4372","317.0066","10.4372","6.9581","75.4777"
"41.9200","10.4577","317.4388","10.4577","6.9718","75.5807"
"42.0000","10.4777","317.8320","10.4777","6.9851","75.6743"
"42.0800","10.4972","318.2058","10.4972","6.9981","75.7633"
"42.1600","10.5174","318.6391","10.5174","7.0116","75.8665"
"42.2400","10.5368","318.9937","10.5368","7.0246","75.9509"
"42.3200","10.5565","319.3862","10.5565","7.0377","76.0443"
"42.4000","10.5775","319.8170","10.5775","7.0517","76.1469"
"42.4800","10.5971","320.1821","10.5971","7.0648","76.2338"
"42.5600","10.6181","320.5992","10.6181","7.0787","76.3331"
"42.6400","10.6373","320.9385","10.6373","7.0915","76.4139"
"42.7200","10.6569","321.3256","10.6569","7.1046","76.5061"
"42.8000","10.6765","321.6781","10.6765","7.1177","76.5900"
"42.8800","10.6971","322.0905","10.6971","7.1314","76.6882"
"42.9600","10.7177","322.4868","10.7177","7.1451","76.7826"
"43.0400","10.7383","322.8877","10.7383","7.1589","76.8780"
"43.1200","10.7572","323.1992","10.7572","7.1715","76.9522"
"43.2000","10.7778","323.6018","10.7778","7.1852","77.0480"
"43.2800","10.7978","323.9404","10.7978","7.1985","77.1287"
"43.3600","10.8175","324.2831","10.8175","7.2117","77.2103"
"43.4400","10.8372","324.5875","10.8372","7.2248","77.2827"
"43.5200","10.8555","324.8116","10.8555","7.2370","77.3361"
"43.6000","10.8771","325.1798","10.8771","7.2514","77.4238"
"43.6800","10.8984","325.5665","10.8984","7.2656","77.5158"
"43.7600","10.9180","325.8685","10.9180","7.2787","77.5877"
"43.8400","10.9374","326.1759","10.9374","7.2916","77.6609"
"43.9200","10.9565","326.4690","10.9565","7.3043","77.7307"
"44.0000","10.9763","326.8135","10.9763","7.3175","77.8127"
"44.0800","10.9976","327.2061","10.9976","7.3317","77.9062"
"44.1600","11.0168","327.5234","11.0168","7.3445","77.9818"
"44.2400","11.0378","327.9192","11.0378","7.3586","78.0760"
"44.3200","11.0577","328.2604","11.0577","7.3718","78.1572"
"44.4000","11.0781","328.6132","11.0781","7.3854","78.2412"
"44.4800","11.0973","328.9129","11.0973","7.3982","78.3126"
"44.5600","11.1172","329.2448","11.1172","7.4114","78.3916"
"44.6400","11.1371","329.5771","11.1371","7.4247","78.4708"
"44.7200","11.1573","329.9305","11.1573","7.4382","78.5549"
"44.8000","11.1762","330.2372","11.1762","7.4508","78.6279"
"44.8800","11.1975","330.6513","11.1975","7.4650","78.7265"
"44.9600","11.2178","330.9769","11.2178","7.4785","78.8040"
"45.0400","11.2378","331.3066","11.2378","7.4919","78.8825"
"45.1200","11.2574","331.6117","11.2574","7.5049","78.9552"
"45.2000","11.2764","331.9062","11.2764","7.5176","79.0253"
"45.2800","11.2969","332.2426","11.2969","7.5313","79.1054"
"45.3600","11.3172","332.5873","11.3172","7.5448","79.1875"
"45.4400","11.3372","332.9095","11.3372","7.5581","79.2642"
"45.5200","11.3579","333.2760","11.3579","7.5719","79.3514"
"45.6000","11.3777","333.5619","11.3777","7.5852","79.4195"
"45.6800","11.3982","333.9032","11.3982","7.5988","79.5008"
"45.7600","11.4180","334.2223","11.4180","7.6120","79.5767"
"45.8400","11.4363","334.4776","11.4363","7.6242","79.6375"
"45.9200","11.4565","334.7980","11.4565","7.6377","79.7138"
"46.0000","11.4763","335.0996","11.4763","7.6509","79.7856"
"46.0800","11.4975","335.4575","11.4975","7.6650","79.8708"
"46.1600","11.5177","335.7701","11.5177","7.6785","79.9453"
"46.2400","11.5378","336.0641","11.5378","7.6919","80.0153"
"46.3200","11.5575","336.3508","11.5575","7.7050","80.0835"
"46.4000","11.5772","336.6261","11.5772","7.7181","80.1491"
"46.4800","11.5963","336.8828","11.5963","7.7309","80.2102"
"46.5600","11.6174","337.2283","11.6174","7.7450","80.2925"
"46.6400","11.6364","337.4597","11.6364","7.7576","80.3475"
"46.7200","11.6577","337.8079","11.6577","7.7718","80.4304"
"46.8000","11.6782","338.1061","11.6782","7.7855","80.5015"
"46.8800","11.6981","338.3941","11.6981","7.7987","80.5700"
"46.9600","11.7174","338.6304","11.7174","7.8116","80.6263"
"47.0400","11.7373","338.9120","11.7373","7.8249","80.6933"
"47.1200","11.7571","339.1818","11.7571","7.8380","80.7576"
"47.2000","11.7770","339.4707","11.7770","7.8514","80.8263"
"47.2800","11.7962","339.7064","11.7962","7.8641","80.8825"
"47.3600","11.8169","340.0062","11.8169","7.8779","80.9539"
"47.4400","11.8380","340.3025","11.8380","7.8920","81.0244"
"47.5200","11.8576","340.5266","11.8576","7.9050","81.0778"
"47.6000","11.8773","340.5899","11.8773","7.9182","81.0928"
"47.6800","11.8963","340.6326","11.8963","7.9309","81.1030"
"47.7600","11.9175","340.9109","11.9175","7.9450","81.1693"
"47.8400","11.9375","341.1369","11.9375","7.9583","81.2231"
"47.9200","11.9566","341.3513","11.9566","7.9711","81.2741"
"48.0000","11.9777","341.6625","11.9777","7.9851","81.3482"
"48.0800","11.9988","341.9330","11.9988","7.9992","81.4126"
"48.1600","12.0184","342.1472","12.0184","8.0122","81.4636"
"48.2400","12.0377","342.3621","12.0377","8.0251","81.5148"
"48.3200","12.0561","342.5515","12.0561","8.0374","81.5599"
"48.4000","12.0772","342.8265","12.0772","8.0515","81.6254"
"48.4800","12.0966","343.0597","12.0966","8.0644","81.6809"
"48.5600","12.1172","343.3324","12.1172","8.0782","81.7458"
"48.6400","12.1372","343.5714","12.1372","8.0914","81.8027"
"48.7200","12.1580","343.8270","12.1580","8.1053","81.8636"
"48.8000","12.1777","344.0493","12.1777","8.1184","81.9165"
"48.8800","12.1978","344.2810","12.1978","8.1319","81.9717"
"48.9600","12.2166","344.4626","12.2166","8.1444","82.0149"
"49.0400","12.2372","344.7242","12.2372","8.1581","82.0772"
"49.1200","12.2563","344.9013","12.2563","8.1709","82.1194"
"49.2000","12.2771","345.1767","12.2771","8.1847","82.1849"
"49.2800","12.2982","345.4425","12.2982","8.1988","82.2482"
"49.3600","12.3182","345.6565","12.3182","8.2121","82.2992"
"49.4400","12.3379","345.8460","12.3379","8.2252","82.3443"
"49.5200","12.3572","346.0309","12.3572","8.2381","82.3883"
"49.6000","12.3769","346.2480","12.3769","8.2513","82.4400"
"49.6800","12.3972","346.4634","12.3972","8.2648","82.4913"
"49.7600","12.4159","346.6062","12.4159","8.2773","82.5253"
"49.8400","12.4370","346.8699","12.4370","8.2913","82.5881"
"49.9200","12.4581","347.0945","12.4581","8.3054","82.6415"
"50.0000","12.4772","347.2499","12.4772","8.3182","82.6786"
"50.0800","12.4979","347.4784","12.4979","8.3320","82.7330"
"50.1600","12.5169","347.6150","12.5169","8.3446","82.7655"
"50.2400","12.5373","347.8300","12.5373","8.3582","82.8167"
"50.3200","12.5566","347.9894","12.5566","8.3711","82.8546"
"50.4000","12.5767","348.1703","12.5767","8.3845","82.8977"
"50.4800","12.5974","348.3803","12.5974","8.3983","82.9477"
"50.5600","12.6191","348.6475","12.6191","8.4128","83.0113"
"50.6400","12.6379","348.7692","12.6379","8.4253","83.0403"
"50.7200","12.6576","348.9290","12.6576","8.4384","83.0783"
"50.8000","12.6767","349.0604","12.6767","8.4511","83.1096"
"50.8800","12.6977","349.2944","12.6977","8.4651","83.1653"
"50.9600","12.7174","349.4359","12.7174","8.4782","83.1990"
"51.0400","12.7359","349.5724","12.7359","8.4906","83.2315"
"51.1200","12.7566","349.7725","12.7566","8.5044","83.2792"
"51.2000","12.7778","350.0110","12.7778","8.5185","83.3360"
"51.2800","12.7981","350.1800","12.7981","8.5321","83.3762"
"51.3600","12.8178","350.3309","12.8178","8.5452","83.4121"
"51.4400","12.8365","350.4359","12.8365","8.5577","83.4371"
"51.5200","12.8562","350.5974","12.8562","8.5708","83.4756"
"51.6000","12.8769","350.7814","12.8769","8.5846","83.5194"
"51.6800","12.8971","350.9735","12.8971","8.5980","83.5651"
"51.7600","12.9186","351.1832","12.9186","8.6124","83.6150"
"51.8400","12.9376","351.2834","12.9376","8.6251","83.6389"
"51.9200","12.9579","351.4422","12.9579","8.6386","83.6767"
"52.0000","12.9775","351.5826","12.9775","8.6517","83.7102"
"52.0800","12.9974","351.7295","12.9974","8.6649","83.7451"
"52.1600","13.0176","351.8783","13.0176","8.6784","83.7805"
"52.2400","13.0366","351.9695","13.0366","8.6911","83.8023"
"52.3200","13.0563","352.1393","13.0563","8.7042","83.8427"
"52.4000","13.0781","352.3684","13.0781","8.7187","83.8972"
"52.4800","13.0977","352.4693","13.0977","8.7318","83.9213"
"52.5600","13.1182","352.6101","13.1182","8.7455","83.9548"
"52.6400","13.1372","352.6842","13.1372","8.7582","83.9724"
"52.7200","13.1564","352.7918","13.1564","8.7709","83.9981"
"52.8000","13.1765","352.9173","13.1765","8.7843","84.0279"
"52.8800","13.1967","353.0516","13.1967","8.7978","84.0599"
"52.9600","13.2178","353.2039","13.2178","8.8118","84.0962"
"53.0400","13.2383","353.3285","13.2383","8.8255","84.1258"
"53.1200","13.2575","353.4072","13.2575","8.8383","84.1446"
"53.2000","13.2778","353.5401","13.2778","8.8519","84.1762"
"53.2800","13.2974","353.6308","13.2974","8.8649","84.1978"
"53.3600","13.3173","353.7573","13.3173","8.8782","84.2279"
"53.4400","13.3372","353.8632","13.3372","8.8915","84.2531"
"53.5200","13.3557","353.9131","13.3557","8.9038","84.2650"
"53.6000","13.3772","354.0713","13.3772","8.9181","84.3027"
"53.6800","13.3980","354.2078","13.3980","8.9320","84.3352"
"53.7600","13.4176","354.2811","13.4176","8.9450","84.3526"
"53.8400","13.4374","354.3858","13.4374","8.9583","84.3776"
"53.9200","13.4567","354.4448","13.4567","8.9711","84.3916"
"54.0000","13.4766","354.5523","13.4766","8.9844","84.4172"
"54.0800","13.4977","354.6826","13.4977","8.9985","84.4482"
"54.1600","13.5169","354.7580","13.5169","9.0113","84.4662"
"54.2400","13.5380","354.8835","13.5380","9.0253","84.4961"
"54.3200","13.5578","354.9589","13.5578","9.0386","84.5140"
"54.4000","13.5780","355.0574","13.5780","9.0520","84.5375"
"54.4800","13.5976","355.1133","13.5976","9.0651","84.5508"
"54.5600","13.6172","355.1653","13.6172","9.0781","84.5632"
"54.6400","13.6371","355.2351","13.6371","9.0914","84.5798"
"54.7200","13.6572","355.2939","13.6572","9.1048","84.5938"
"54.8000","13.6763","355.3172","13.6763","9.1175","84.5993"
"54.8800","13.6974","355.2731","13.6974","9.1316","84.5888"
"54.9600","13.7175","355.2032","13.7175","9.1450","84.5722"
"55.0400","13.7377","355.1781","13.7377","9.1585","84.5662"
"55.1200","13.7573","355.1263","13.7573","9.1715","84.5539"
"55.2000","13.7766","355.0003","13.7766","9.1844","84.5239"
"55.2800","13.7972","354.9714","13.7972","9.1981","84.5170"
"55.3600","13.8171","354.9795","13.8171","9.2114","84.5189"
"55.4400","13.8370","355.0089","13.8370","9.2247","84.5259"
"55.5200","13.8579","355.0752","13.8579","9.2386","84.5417"
"55.6000","13.8776","355.0742","13.8776","9.2517","84.5415"
"55.6800","13.8982","355.1302","13.8982","9.2655","84.5548"
"55.7600","13.9178","355.1411","13.9178","9.2786","84.5574"
"55.8400","13.9369","355.1633","13.9369","9.2912","84.5627"
"55.9200","13.9570","355.2037","13.9570","9.3047","84.5723"
"56.0000","13.9762","355.2079","13.9762","9.3175","84.5733"
"56.0800","13.9973","355.2879","13.9973","9.3315","84.5923"
"56.1600","14.0177","355.3480","14.0177","9.3451","84.6067"
"56.2400","14.0372","355.3521","14.0372","9.3581","84.6076"
"56.3200","14.0572","355.3811","14.0572","9.3715","84.6145"
"56.4000","14.0773","355.4076","14.0773","9.3849","84.6209"
"56.4800","14.0968","355.4260","14.0968","9.3979","84.6252"
"56.5600","14.1173","355.4725","14.1173","9.4115","84.6363"
"56.6400","14.1364","355.4683","14.1364","9.4243","84.6353"
"56.7200","14.1575","355.5262","14.1575","9.4383","84.6491"
"56.8000","14.1781","355.5648","14.1781","9.4521","84.6583"
"56.8800","14.1979","355.5769","14.1979","9.4653","84.6612"
"56.9600","14.2174","355.5783","14.2174","9.4782","84.6615"
"57.0400","14.2373","355.5880","14.2373","9.4915","84.6638"
"57.1200","14.2574","355.6225","14.2574","9.5050","84.6720"
"57.2000","14.2770","355.6053","14.2770","9.5180","84.6679"
"57.2800","14.2961","355.5901","14.2961","9.5307","84.6643"
"57.3600","14.3171","355.6413","14.3171","9.5447","84.6765"
"57.4400","14.3380","355.6706","14.3380","9.5587","84.6835"
"57.5200","14.3576","355.6628","14.3576","9.5718","84.6816"
"57.6000","14.3773","355.6434","14.3773","9.5848","84.6770"
"57.6800","14.3965","355.6125","14.3965","9.5977","84.6696"
"57.7600","14.4173","355.6289","14.4173","9.6115","84.6735"
"57.8400","14.4373","355.6254","14.4373","9.6248","84.6727"
"57.9200","14.4570","355.6114","14.4570","9.6380","84.6694"
"58.0000","14.4776","355.6149","14.4776","9.6517","84.6702"
"58.0800","14.4980","355.5979","14.4980","9.6653","84.6662"
"58.1600","14.5182","355.5978","14.5182","9.6788","84.6661"
"58.2400","14.5379","355.5633","14.5379","9.6920","84.6579"
"58.3200","14.5565","355.4886","14.5565","9.7043","84.6401"
"58.4000","14.5767","355.4806","14.5767","9.7178","84.6382"
"58.4800","14.5963","355.4532","14.5963","9.7308","84.6317"
"58.5600","14.6167","355.4577","14.6167","9.7444","84.6328"
"58.6400","14.6375","355.4583","14.6375","9.7583","84.6329"
"58.7200","14.6577","355.4231","14.6577","9.7718","84.6245"
"58.8000","14.6777","355.3903","14.6777","9.7852","84.6167"
"58.8800","14.6979","355.3524","14.6979","9.7986","84.6077"
"58.9600","14.7166","355.2801","14.7166","9.8111","84.5905"
"59.0400","14.7369","355.2496","14.7369","9.8246","84.5832"
"59.1200","14.7566","355.1960","14.7566","9.8377","84.5705"
"59.2000","14.7773","355.1798","14.7773","9.8515","84.5666"
"59.2800","14.7985","355.1722","14.7985","9.8656","84.5648"
"59.3600","14.8180","355.1002","14.8180","9.8787","84.5477"
"59.4400","14.8377","355.0245","14.8377","9.8918","84.5297"
"59.5200","14.8572","354.9513","14.8572","9.9048","84.5122"
"59.6000","14.8769","354.9010","14.8769","9.9179","84.5002"
"59.6800","14.8971","354.8484","14.8971","9.9314","84.4877"
"59.7600","14.9161","354.7397","14.9161","9.9441","84.4618"
"59.8400","14.9368","354.7056","14.9368","9.9579","84.4537"
"59.9200","14.9578","354.6737","14.9578","9.9719","84.4461"
"60.0000","14.9775","354.6111","14.9775","9.9850","84.4312"
"60.0800","14.9979","354.5520","14.9979","9.9986","84.4171"
"60.0890","15.0001","354.5421","15.0001","10.0000","84.4148"