File: data/instron_tests/metamaterials/250416/250416_1310_NSC_m1.is_comp_Exports/240416_1310_NSC_m1_1_1.csv
Results Table 1
,Compresson Axis,H*,V*,Height,Thickness,Width,Area,Fixture separation,Specimen label
,,,,(mm),(mm),(mm),(mm^2),(mm),
"1","Y","","","150.00","28.00","150.00","4200.00","150.00","1310_NSC_m1"

Results Table 2
,Modulus (Segment 0 % - 2.5 %),Compresson Axis
,(kPa),
"1","746.03","Y"

Time,Displacement,Force,Compressive displacement,Compressive strain (Displacement),Compressive stress
(s),(mm),(N),(mm),(%),(kPa)
"0.0000","0.0000","0.4442","0.0000","0.0000","0.1058"
"0.0800","0.0012","0.5044","0.0012","0.0008","0.1201"
"0.1600","0.0175","1.0093","0.0175","0.0117","0.2403"
"0.2400","0.0382","1.6136","0.0382","0.0255","0.3842"
"0.3200","0.0585","2.1797","0.0585","0.0390","0.5190"
"0.4000","0.0772","2.6901","0.0772","0.0515","0.6405"
"0.4800","0.0978","3.2571","0.0978","0.0652","0.7755"
"0.5600","0.1189","3.8157","0.1189","0.0793","0.9085"
"0.6400","0.1384","4.3281","0.1384","0.0923","1.0305"
"0.7200","0.1576","4.8353","0.1576","0.1051","1.1513"
"0.8000","0.1773","5.3505","0.1773","0.1182","1.2739"
"0.8800","0.1979","5.8729","0.1979","0.1319","1.3983"
"0.9600","0.2184","6.3903","0.2184","0.1456","1.5215"
"1.0400","0.2365","6.8595","0.2365","0.1577","1.6332"
"1.1200","0.2575","7.3941","0.2575","0.1717","1.7605"
"1.2000","0.2783","7.9199","0.2783","0.1855","1.8857"
"1.2800","0.2987","8.4292","0.2987","0.1991","2.0069"
"1.3600","0.3184","8.9142","0.3184","0.2123","2.1224"
"1.4400","0.3366","9.3464","0.3366","0.2244","2.2253"
"1.5200","0.3568","9.8381","0.3568","0.2379","2.3424"
"1.6000","0.3777","10.3555","0.3777","0.2518","2.4656"
"1.6800","0.3975","10.8353","0.3975","0.2650","2.5798"
"1.7600","0.4187","11.3455","0.4187","0.2791","2.7013"
"1.8400","0.4380","11.8006","0.4380","0.2920","2.8097"
"1.9200","0.4580","12.2681","0.4580","0.3053","2.9210"
"2.0000","0.4782","12.7549","0.4782","0.3188","3.0369"
"2.0800","0.4973","13.2016","0.4973","0.3315","3.1432"
"2.1600","0.5177","13.6726","0.5177","0.3451","3.2554"
"2.2400","0.5370","14.0949","0.5370","0.3580","3.3559"
"2.3200","0.5567","14.5541","0.5567","0.3711","3.4653"
"2.4000","0.5782","15.0733","0.5782","0.3854","3.5889"
"2.4800","0.5979","15.5210","0.5979","0.3986","3.6955"
"2.5600","0.6183","16.0009","0.6183","0.4122","3.8097"
"2.6400","0.6375","16.4361","0.6375","0.4250","3.9134"
"2.7200","0.6567","16.8899","0.6567","0.4378","4.0214"
"2.8000","0.6766","17.3444","0.6766","0.4511","4.1296"
"2.8800","0.6970","17.8156","0.6970","0.4647","4.2418"
"2.9600","0.7182","18.2958","0.7182","0.4788","4.3561"
"3.0400","0.7390","18.7571","0.7390","0.4926","4.4660"
"3.1200","0.7579","19.1852","0.7579","0.5052","4.5679"
"3.2000","0.7781","19.6521","0.7781","0.5187","4.6791"
"3.2800","0.7981","20.0985","0.7981","0.5320","4.7853"
"3.3600","0.8177","20.5470","0.8177","0.5452","4.8921"
"3.4400","0.8374","20.9808","0.8374","0.5583","4.9954"
"3.5200","0.8563","21.4075","0.8563","0.5709","5.0970"
"3.6000","0.8777","21.8934","0.8777","0.5852","5.2127"
"3.6800","0.8990","22.3819","0.8990","0.5994","5.3290"
"3.7600","0.9185","22.8216","0.9185","0.6124","5.4337"
"3.8400","0.9375","23.2449","0.9375","0.6250","5.5345"
"3.9200","0.9564","23.6612","0.9564","0.6376","5.6336"
"4.0000","0.9771","24.1244","0.9771","0.6514","5.7439"
"4.0800","0.9985","24.6179","0.9985","0.6657","5.8614"
"4.1600","1.0171","25.0279","1.0171","0.6781","5.9590"
"4.2400","1.0383","25.5107","1.0383","0.6922","6.0740"
"4.3200","1.0582","25.9377","1.0582","0.7055","6.1756"
"4.4000","1.0780","26.3707","1.0780","0.7187","6.2787"
"4.4800","1.0980","26.8152","1.0980","0.7320","6.3846"
"4.5600","1.1174","27.2304","1.1174","0.7449","6.4834"
"4.6400","1.1376","27.6786","1.1376","0.7584","6.5901"
"4.7200","1.1573","28.0991","1.1573","0.7716","6.6903"
"4.8000","1.1764","28.5270","1.1764","0.7843","6.7921"
"4.8800","1.1977","29.0062","1.1977","0.7985","6.9062"
"4.9600","1.2182","29.4422","1.2182","0.8121","7.0100"
"5.0400","1.2382","29.8696","1.2382","0.8255","7.1118"
"5.1200","1.2571","30.2564","1.2571","0.8381","7.2039"
"5.2000","1.2763","30.6772","1.2763","0.8508","7.3041"
"5.2800","1.2980","31.1632","1.2980","0.8653","7.4198"
"5.3600","1.3182","31.6014","1.3182","0.8788","7.5241"
"5.4400","1.3376","32.0238","1.3376","0.8918","7.6247"
"5.5200","1.3582","32.4710","1.3582","0.9055","7.7312"
"5.6000","1.3782","32.8989","1.3782","0.9188","7.8331"
"5.6800","1.3988","33.3367","1.3988","0.9325","7.9373"
"5.7600","1.4184","33.7425","1.4184","0.9456","8.0339"
"5.8400","1.4370","34.1474","1.4370","0.9580","8.1303"
"5.9200","1.4571","34.5762","1.4571","0.9714","8.2324"
"6.0000","1.4769","34.9896","1.4769","0.9846","8.3309"
"6.0800","1.4982","35.4528","1.4982","0.9988","8.4411"
"6.1600","1.5184","35.8942","1.5184","1.0123","8.5462"
"6.2400","1.5377","36.2996","1.5377","1.0251","8.6428"
"6.3200","1.5574","36.7090","1.5574","1.0383","8.7402"
"6.4000","1.5776","37.1444","1.5776","1.0517","8.8439"
"6.4800","1.5972","37.5596","1.5972","1.0648","8.9428"
"6.5600","1.6180","38.0017","1.6180","1.0787","9.0480"
"6.6400","1.6366","38.3799","1.6366","1.0911","9.1381"
"6.7200","1.6580","38.8336","1.6580","1.1053","9.2461"
"6.8000","1.6786","39.2726","1.6786","1.1191","9.3506"
"6.8800","1.6985","39.6898","1.6985","1.1323","9.4500"
"6.9600","1.7179","40.0911","1.7179","1.1453","9.5455"
"7.0400","1.7374","40.4888","1.7374","1.1583","9.6402"
"7.1200","1.7573","40.9082","1.7573","1.1715","9.7400"
"7.2000","1.7781","41.3514","1.7781","1.1854","9.8456"
"7.2800","1.7966","41.7298","1.7966","1.1977","9.9357"
"7.3600","1.8173","42.1608","1.8173","1.2115","10.0383"
"7.4400","1.8381","42.5961","1.8381","1.2254","10.1419"
"7.5200","1.8577","43.0017","1.8577","1.2385","10.2385"
"7.6000","1.8778","43.4230","1.8778","1.2519","10.3388"
"7.6800","1.8970","43.8146","1.8970","1.2647","10.4320"
"7.7600","1.9179","44.2492","1.9179","1.2786","10.5355"
"7.8400","1.9379","44.6700","1.9379","1.2920","10.6357"
"7.9200","1.9570","45.0603","1.9570","1.3046","10.7286"
"8.0000","1.9778","45.4936","1.9778","1.3185","10.8318"
"8.0800","1.9988","45.9329","1.9988","1.3325","10.9364"
"8.1600","2.0184","46.3194","2.0184","1.3456","11.0284"
"8.2400","2.0381","46.7247","2.0381","1.3587","11.1249"
"8.3200","2.0568","47.1057","2.0568","1.3712","11.2156"
"8.4000","2.0779","47.5377","2.0779","1.3852","11.3185"
"8.4800","2.0975","47.9395","2.0975","1.3983","11.4142"
"8.5600","2.1173","48.3485","2.1173","1.4115","11.5116"
"8.6400","2.1376","48.7700","2.1376","1.4251","11.6119"
"8.7200","2.1581","49.1866","2.1581","1.4388","11.7111"
"8.8000","2.1781","49.5840","2.1781","1.4521","11.8057"
"8.8800","2.1984","49.9992","2.1984","1.4656","11.9046"
"8.9600","2.2168","50.3707","2.2168","1.4779","11.9930"
"9.0400","2.2374","50.7982","2.2374","1.4916","12.0948"
"9.1200","2.2571","51.1905","2.2571","1.5047","12.1882"
"9.2000","2.2779","51.6171","2.2779","1.5186","12.2898"
"9.2800","2.2989","52.0425","2.2989","1.5326","12.3911"
"9.3600","2.3184","52.4338","2.3184","1.5456","12.4842"
"9.4400","2.3383","52.8319","2.3383","1.5588","12.5790"
"9.5200","2.3577","53.2149","2.3577","1.5718","12.6702"
"9.6000","2.3771","53.6147","2.3771","1.5847","12.7654"
"9.6800","2.3974","54.0242","2.3974","1.5983","12.8629"
"9.7600","2.4168","54.3991","2.4168","1.6112","12.9522"
"9.8400","2.4375","54.8183","2.4375","1.6250","13.0520"
"9.9200","2.4588","55.2413","2.4588","1.6392","13.1527"
"10.0000","2.4777","55.6123","2.4777","1.6518","13.2410"
"10.0800","2.4974","55.9858","2.4974","1.6649","13.3300"
"10.1600","2.5168","56.3704","2.5168","1.6779","13.4215"
"10.2400","2.5374","56.7865","2.5374","1.6916","13.5206"
"10.3200","2.5578","57.2031","2.5578","1.7052","13.6198"
"10.4000","2.5771","57.5722","2.5771","1.7181","13.7077"
"10.4800","2.5980","57.9880","2.5980","1.7320","13.8067"
"10.5600","2.6192","58.4146","2.6192","1.7461","13.9082"
"10.6400","2.6379","58.7723","2.6379","1.7586","13.9934"
"10.7200","2.6578","59.1666","2.6578","1.7719","14.0873"
"10.8000","2.6771","59.5418","2.6771","1.7847","14.1766"
"10.8800","2.6980","59.9463","2.6980","1.7987","14.2729"
"10.9600","2.7178","60.3259","2.7178","1.8118","14.3633"
"11.0400","2.7368","60.6920","2.7368","1.8245","14.4505"
"11.1200","2.7575","61.1065","2.7575","1.8383","14.5492"
"11.2000","2.7783","61.5123","2.7783","1.8522","14.6458"
"11.2800","2.7985","61.9089","2.7985","1.8657","14.7402"
"11.3600","2.8181","62.2914","2.8181","1.8787","14.8313"
"11.4400","2.8367","62.6375","2.8367","1.8912","14.9137"
"11.5200","2.8573","63.0484","2.8573","1.9049","15.0115"
"11.6000","2.8777","63.4387","2.8777","1.9184","15.1044"
"11.6800","2.8971","63.8256","2.8971","1.9314","15.1966"
"11.7600","2.9184","64.2431","2.9184","1.9456","15.2960"
"11.8400","2.9383","64.6111","2.9383","1.9588","15.3836"
"11.9200","2.9584","64.9900","2.9584","1.9723","15.4738"
"12.0000","2.9779","65.3703","2.9779","1.9853","15.5644"
"12.0800","2.9974","65.7478","2.9974","1.9983","15.6542"
"12.1600","3.0177","66.1482","3.0177","2.0118","15.7496"
"12.2400","3.0373","66.5173","3.0373","2.0249","15.8375"
"12.3200","3.0568","66.9018","3.0568","2.0379","15.9290"
"12.4000","3.0782","67.3276","3.0782","2.0521","16.0304"
"12.4800","3.0977","67.6835","3.0977","2.0652","16.1151"
"12.5600","3.1185","68.0794","3.1185","2.0790","16.2094"
"12.6400","3.1374","68.4184","3.1374","2.0916","16.2901"
"12.7200","3.1568","68.7762","3.1568","2.1045","16.3753"
"12.8000","3.1773","69.1801","3.1773","2.1182","16.4714"
"12.8800","3.1973","69.5551","3.1973","2.1315","16.5607"
"12.9600","3.2178","69.9501","3.2178","2.1452","16.6548"
"13.0400","3.2392","70.3800","3.2392","2.1594","16.7572"
"13.1200","3.2578","70.7284","3.2578","2.1718","16.8401"
"13.2000","3.2780","71.1124","3.2780","2.1853","16.9315"
"13.2800","3.2979","71.4903","3.2979","2.1986","17.0215"
"13.3600","3.3177","71.8442","3.3177","2.2118","17.1058"
"13.4400","3.3375","72.2073","3.3375","2.2250","17.1922"
"13.5200","3.3563","72.5535","3.3563","2.2375","17.2746"
"13.6000","3.3776","72.9676","3.3776","2.2517","17.3732"
"13.6800","3.3987","73.3834","3.3987","2.2658","17.4722"
"13.7600","3.4184","73.7612","3.4184","2.2789","17.5622"
"13.8400","3.4376","74.1117","3.4376","2.2918","17.6456"
"13.9200","3.4569","74.4673","3.4569","2.3046","17.7303"
"14.0000","3.4772","74.8568","3.4772","2.3181","17.8230"
"14.0800","3.4981","75.2351","3.4981","2.3321","17.9131"
"14.1600","3.5170","75.5480","3.5170","2.3447","17.9876"
"14.2400","3.5382","75.9555","3.5382","2.3588","18.0846"
"14.3200","3.5581","76.3280","3.5581","2.3721","18.1733"
"14.4000","3.5782","76.7008","3.5782","2.3855","18.2621"
"14.4800","3.5980","77.0814","3.5980","2.3987","18.3527"
"14.5600","3.6176","77.4428","3.6176","2.4117","18.4388"
"14.6400","3.6376","77.8037","3.6376","2.4251","18.5247"
"14.7200","3.6570","78.1600","3.6570","2.4380","18.6095"
"14.8000","3.6761","78.5186","3.6761","2.4507","18.6949"
"14.8800","3.6979","78.9427","3.6979","2.4653","18.7959"
"14.9600","3.7180","79.2498","3.7180","2.4787","18.8690"
"15.0400","3.7382","79.6338","3.7382","2.4922","18.9604"
"15.1200","3.7578","79.9826","3.7578","2.5052","19.0435"
"15.2000","3.7767","80.3374","3.7767","2.5178","19.1280"
"15.2800","3.7975","80.7291","3.7975","2.5317","19.2212"
"15.3600","3.8176","81.1027","3.8176","2.5451","19.3102"
"15.4400","3.8377","81.4764","3.8377","2.5584","19.3991"
"15.5200","3.8584","81.8666","3.8584","2.5722","19.4920"
"15.6000","3.8781","82.2133","3.8781","2.5854","19.5746"
"15.6800","3.8985","82.5918","3.8985","2.5990","19.6647"
"15.7600","3.9184","82.9439","3.9184","2.6123","19.7485"
"15.8400","3.9371","83.2415","3.9371","2.6247","19.8194"
"15.9200","3.9573","83.6242","3.9573","2.6382","19.9105"
"16.0000","3.9766","83.9727","3.9766","2.6511","19.9935"
"16.0800","3.9980","84.3916","3.9980","2.6653","20.0932"
"16.1600","4.0188","84.7635","4.0188","2.6792","20.1818"
"16.2400","4.0375","85.0955","4.0375","2.6917","20.2608"
"16.3200","4.0575","85.4502","4.0575","2.7050","20.3453"
"16.4000","4.0777","85.8276","4.0777","2.7185","20.4351"
"16.4800","4.0972","86.1884","4.0972","2.7315","20.5211"
"16.5600","4.1179","86.5652","4.1179","2.7453","20.6108"
"16.6400","4.1366","86.8851","4.1366","2.7577","20.6869"
"16.7200","4.1579","87.2367","4.1579","2.7719","20.7706"
"16.8000","4.1787","87.6220","4.1787","2.7858","20.8624"
"16.8800","4.1986","87.9897","4.1986","2.7991","20.9499"
"16.9600","4.2180","88.3360","4.2180","2.8120","21.0324"
"17.0400","4.2377","88.6809","4.2377","2.8252","21.1145"
"17.1200","4.2571","89.0219","4.2571","2.8381","21.1957"
"17.2000","4.2776","89.3983","4.2776","2.8518","21.2853"
"17.2800","4.2967","89.7414","4.2967","2.8645","21.3670"
"17.3600","4.3180","90.1252","4.3180","2.8787","21.4584"
"17.4400","4.3378","90.4825","4.3378","2.8919","21.5434"
"17.5200","4.3575","90.8329","4.3575","2.9050","21.6269"
"17.6000","4.3779","91.1966","4.3779","2.9186","21.7135"
"17.6800","4.3969","91.4775","4.3969","2.9313","21.7804"
"17.7600","4.4175","91.8485","4.4175","2.9450","21.8687"
"17.8400","4.4378","92.1957","4.4378","2.9585","21.9514"
"17.9200","4.4571","92.5480","4.4571","2.9714","22.0352"
"18.0000","4.4778","92.9219","4.4778","2.9852","22.1243"
"18.0800","4.4986","93.2781","4.4986","2.9991","22.2091"
"18.1600","4.5184","93.6241","4.5184","3.0122","22.2915"
"18.2400","4.5384","93.9733","4.5384","3.0256","22.3746"
"18.3200","4.5567","94.2742","4.5567","3.0378","22.4462"
"18.4000","4.5777","94.6498","4.5777","3.0518","22.5357"
"18.4800","4.5974","94.9950","4.5974","3.0649","22.6179"
"18.5600","4.6175","95.3514","4.6175","3.0784","22.7027"
"18.6400","4.6376","95.7096","4.6376","3.0917","22.7880"
"18.7200","4.6581","96.0581","4.6581","3.1054","22.8710"
"18.8000","4.6780","96.3728","4.6780","3.1187","22.9459"
"18.8800","4.6983","96.7273","4.6983","3.1322","23.0303"
"18.9600","4.7167","97.0473","4.7167","3.1444","23.1065"
"19.0400","4.7374","97.4207","4.7374","3.1582","23.1954"
"19.1200","4.7568","97.7466","4.7568","3.1712","23.2730"
"19.2000","4.7779","98.1286","4.7779","3.1853","23.3640"
"19.2800","4.7993","98.5105","4.7993","3.1995","23.4549"
"19.3600","4.8182","98.8239","4.8182","3.2122","23.5295"
"19.4400","4.8380","99.1646","4.8380","3.2253","23.6106"
"19.5200","4.8577","99.5034","4.8577","3.2384","23.6913"
"19.6000","4.8774","99.8605","4.8774","3.2516","23.7763"
"19.6800","4.8975","100.2135","4.8975","3.2650","23.8604"
"19.7600","4.9171","100.5432","4.9171","3.2781","23.9389"
"19.8400","4.9377","100.8961","4.9377","3.2918","24.0229"
"19.9200","4.9584","101.2461","4.9584","3.3056","24.1062"
"20.0000","4.9777","101.5617","4.9777","3.3184","24.1814"
"20.0800","4.9980","101.8990","4.9980","3.3320","24.2617"
"20.1600","5.0169","102.2199","5.0169","3.3446","24.3381"
"20.2400","5.0373","102.5757","5.0373","3.3582","24.4228"
"20.3200","5.0577","102.9282","5.0577","3.3718","24.5067"
"20.4000","5.0772","103.2494","5.0772","3.3848","24.5832"
"20.4800","5.0979","103.6031","5.0979","3.3986","24.6674"
"20.5600","5.1189","103.9810","5.1189","3.4126","24.7574"
"20.6400","5.1381","104.3082","5.1381","3.4254","24.8353"
"20.7200","5.1577","104.6243","5.1577","3.4385","24.9105"
"20.8000","5.1761","104.9195","5.1761","3.4507","24.9808"
"20.8800","5.1981","105.3051","5.1981","3.4654","25.0726"
"20.9600","5.2183","105.6633","5.2183","3.4789","25.1579"
"21.0400","5.2370","105.9661","5.2370","3.4913","25.2300"
"21.1200","5.2572","106.3205","5.2572","3.5048","25.3144"
"21.2000","5.2783","106.6757","5.2783","3.5189","25.3990"
"21.2800","5.2984","107.0135","5.2984","3.5322","25.4794"
"21.3600","5.3180","107.3142","5.3180","3.5454","25.5510"
"21.4400","5.3365","107.6103","5.3365","3.5576","25.6215"
"21.5200","5.3572","107.9643","5.3572","3.5715","25.7058"
"21.6000","5.3775","108.3018","5.3775","3.5850","25.7861"
"21.6800","5.3974","108.6382","5.3974","3.5983","25.8662"
"21.7600","5.4183","108.9950","5.4183","3.6122","25.9512"
"21.8400","5.4380","109.3128","5.4380","3.6253","26.0268"
"21.9200","5.4585","109.6557","5.4585","3.6390","26.1085"
"22.0000","5.4779","109.9725","5.4779","3.6519","26.1839"
"22.0800","5.4972","110.2900","5.4972","3.6648","26.2595"
"22.1600","5.5180","110.6490","5.5180","3.6787","26.3450"
"22.2400","5.5373","110.9545","5.5373","3.6915","26.4177"
"22.3200","5.5565","111.2770","5.5565","3.7043","26.4945"
"22.4000","5.5780","111.6481","5.5780","3.7186","26.5829"
"22.4800","5.5976","111.9656","5.5976","3.7317","26.6585"
"22.5600","5.6188","112.3282","5.6188","3.7459","26.7448"
"22.6400","5.6378","112.6426","5.6378","3.7585","26.8197"
"22.7200","5.6570","112.9558","5.6570","3.7713","26.8942"
"22.8000","5.6771","113.2741","5.6771","3.7847","26.9700"
"22.8800","5.6976","113.6135","5.6976","3.7984","27.0508"
"22.9600","5.7178","113.9459","5.7178","3.8118","27.1300"
"23.0400","5.7391","114.3111","5.7391","3.8260","27.2169"
"23.1200","5.7578","114.6096","5.7578","3.8385","27.2880"
"23.2000","5.7776","114.9332","5.7776","3.8517","27.3650"
"23.2800","5.7976","115.2579","5.7976","3.8650","27.4424"
"23.3600","5.8176","115.5957","5.8176","3.8784","27.5228"
"23.4400","5.8377","115.9233","5.8377","3.8918","27.6008"
"23.5200","5.8566","116.2284","5.8566","3.9044","27.6734"
"23.6000","5.8778","116.5863","5.8778","3.9185","27.7587"
"23.6800","5.8990","116.9449","5.8990","3.9327","27.8440"
"23.7600","5.9184","117.2511","5.9184","3.9456","27.9169"
"23.8400","5.9373","117.5583","5.9373","3.9582","27.9901"
"23.9200","5.9567","117.8593","5.9567","3.9711","28.0617"
"24.0000","5.9774","118.2038","5.9774","3.9849","28.1438"
"24.0800","5.9983","118.5556","5.9983","3.9989","28.2275"
"24.1600","6.0169","118.8490","6.0169","4.0113","28.2974"
"24.2400","6.0384","119.2104","6.0384","4.0256","28.3834"
"24.3200","6.0584","119.5196","6.0584","4.0389","28.4570"
"24.4000","6.0787","119.8447","6.0787","4.0525","28.5344"
"24.4800","6.0980","120.1610","6.0980","4.0653","28.6098"
"24.5600","6.1180","120.4852","6.1180","4.0786","28.6870"
"24.6400","6.1377","120.7984","6.1377","4.0918","28.7615"
"24.7200","6.1574","121.1149","6.1574","4.1049","28.8369"
"24.8000","6.1762","121.4242","6.1762","4.1174","28.9105"
"24.8800","6.1979","121.7909","6.1979","4.1319","28.9978"
"24.9600","6.2178","122.0964","6.2178","4.1452","29.0706"
"25.0400","6.2382","122.4356","6.2382","4.1588","29.1513"
"25.1200","6.2578","122.7377","6.2578","4.1718","29.2233"
"25.2000","6.2766","123.0255","6.2766","4.1844","29.2918"
"25.2800","6.2976","123.3769","6.2976","4.1984","29.3755"
"25.3600","6.3176","123.6966","6.3176","4.2118","29.4516"
"25.4400","6.3374","124.0112","6.3374","4.2249","29.5265"
"25.5200","6.3577","124.3391","6.3577","4.2385","29.6046"
"25.6000","6.3784","124.6703","6.3784","4.2522","29.6834"
"25.6800","6.3983","124.9789","6.3983","4.2656","29.7569"
"25.7600","6.4183","125.2914","6.4183","4.2788","29.8313"
"25.8400","6.4373","125.5964","6.4373","4.2915","29.9039"
"25.9200","6.4577","125.9163","6.4577","4.3051","29.9801"
"26.0000","6.4765","126.2001","6.4765","4.3177","30.0476"
"26.0800","6.4979","126.5488","6.4979","4.3320","30.1307"
"26.1600","6.5186","126.8610","6.5186","4.3457","30.2050"
"26.2400","6.5379","127.1627","6.5379","4.3586","30.2768"
"26.3200","6.5574","127.4719","6.5574","4.3716","30.3505"
"26.4000","6.5778","127.7946","6.5778","4.3852","30.4273"
"26.4800","6.5974","128.1052","6.5974","4.3983","30.5012"
"26.5600","6.6178","128.4361","6.6178","4.4118","30.5800"
"26.6400","6.6367","128.7048","6.6367","4.4245","30.6440"
"26.7200","6.6582","129.0651","6.6582","4.4388","30.7298"
"26.8000","6.6787","129.3899","6.6787","4.4524","30.8071"
"26.8800","6.6986","129.7148","6.6986","4.4657","30.8845"
"26.9600","6.7181","130.0182","6.7181","4.4787","30.9567"
"27.0400","6.7377","130.3103","6.7377","4.4918","31.0263"
"27.1200","6.7572","130.6124","6.7572","4.5048","31.0982"
"27.2000","6.7776","130.9457","6.7776","4.5184","31.1775"
"27.2800","6.7965","131.2287","6.7965","4.5310","31.2449"
"27.3600","6.8179","131.5859","6.8179","4.5453","31.3300"
"27.4400","6.8382","131.8996","6.8382","4.5588","31.4047"
"27.5200","6.8575","132.1870","6.8575","4.5717","31.4731"
"27.6000","6.8778","132.5253","6.8778","4.5852","31.5536"
"27.6800","6.8974","132.8223","6.8974","4.5983","31.6244"
"27.7600","6.9178","133.1472","6.9178","4.6118","31.7017"
"27.8400","6.9376","133.4505","6.9376","4.6251","31.7739"
"27.9200","6.9570","133.7514","6.9570","4.6380","31.8456"
"28.0000","6.9782","134.0991","6.9782","4.6521","31.9283"
"28.0800","6.9987","134.4088","6.9987","4.6658","32.0021"
"28.1600","7.0182","134.6956","7.0182","4.6788","32.0704"
"28.2400","7.0383","135.0049","7.0383","4.6922","32.1440"
"28.3200","7.0567","135.2672","7.0567","4.7044","32.2065"
"28.4000","7.0773","135.6008","7.0773","4.7182","32.2859"
"28.4800","7.0974","135.9067","7.0974","4.7316","32.3587"
"28.5600","7.1176","136.2298","7.1176","4.7451","32.4357"
"28.6400","7.1375","136.5488","7.1375","4.7583","32.5116"
"28.7200","7.1578","136.8613","7.1578","4.7719","32.5860"
"28.8000","7.1780","137.1746","7.1780","4.7853","32.6606"
"28.8800","7.1987","137.4891","7.1987","4.7991","32.7355"
"28.9600","7.2168","137.7587","7.2168","4.8112","32.7997"
"29.0400","7.2370","138.0732","7.2370","4.8247","32.8746"
"29.1200","7.2569","138.3753","7.2569","4.8379","32.9465"
"29.2000","7.2779","138.7205","7.2779","4.8519","33.0287"
"29.2800","7.2993","139.0574","7.2993","4.8662","33.1089"
"29.3600","7.3185","139.3442","7.3185","4.8790","33.1772"
"29.4400","7.3381","139.6428","7.3381","4.8921","33.2483"
"29.5200","7.3577","139.9307","7.3577","4.9051","33.3168"
"29.6000","7.3771","140.2203","7.3771","4.9180","33.3858"
"29.6800","7.3975","140.5464","7.3975","4.9317","33.4634"
"29.7600","7.4170","140.8281","7.4170","4.9447","33.5305"
"29.8400","7.4375","141.1503","7.4375","4.9584","33.6072"
"29.9200","7.4586","141.4743","7.4586","4.9724","33.6844"
"30.0000","7.4776","141.7546","7.4776","4.9851","33.7511"
"30.0800","7.4985","142.0855","7.4985","4.9990","33.8299"
"30.1600","7.5175","142.3546","7.5175","5.0116","33.8940"
"30.2400","7.5374","142.6538","7.5374","5.0249","33.9652"
"30.3200","7.5573","142.9521","7.5573","5.0382","34.0362"
"30.4000","7.5772","143.2438","7.5772","5.0515","34.1057"
"30.4800","7.5982","143.5797","7.5982","5.0655","34.1856"
"30.5600","7.6188","143.8877","7.6188","5.0792","34.2590"
"30.6400","7.6381","144.1744","7.6381","5.0921","34.3272"
"30.7200","7.6575","144.4483","7.6575","5.1050","34.3925"
"30.8000","7.6769","144.7211","7.6769","5.1179","34.4574"
"30.8800","7.6980","145.0537","7.6980","5.1320","34.5366"
"30.9600","7.7180","145.3383","7.7180","5.1453","34.6044"
"31.0400","7.7368","145.6262","7.7368","5.1579","34.6729"
"31.1200","7.7573","145.9356","7.7573","5.1715","34.7466"
"31.2000","7.7783","146.2631","7.7783","5.1855","34.8246"
"31.2800","7.7987","146.5742","7.7987","5.1991","34.8986"
"31.3600","7.8185","146.8741","7.8185","5.2123","34.9700"
"31.4400","7.8364","147.1149","7.8364","5.2243","35.0274"
"31.5200","7.8569","147.4293","7.8569","5.2379","35.1022"
"31.6000","7.8776","147.7418","7.8776","5.2517","35.1766"
"31.6800","7.8977","148.0487","7.8977","5.2651","35.2497"
"31.7600","7.9188","148.3823","7.9188","5.2792","35.3291"
"31.8400","7.9382","148.6478","7.9382","5.2921","35.3923"
"31.9200","7.9585","148.9549","7.9585","5.3056","35.4655"
"32.0000","7.9780","149.2283","7.9780","5.3187","35.5306"
"32.0800","7.9972","149.5183","7.9972","5.3314","35.5996"
"32.1600","8.0174","149.8194","8.0174","5.3449","35.6713"
"32.2400","8.0374","150.1200","8.0374","5.3582","35.7429"
"32.3200","8.0565","150.3978","8.0565","5.3710","35.8090"
"32.4000","8.0779","150.7289","8.0779","5.3853","35.8878"
"32.4800","8.0979","151.0158","8.0979","5.3986","35.9561"
"32.5600","8.1187","151.3350","8.1187","5.4125","36.0321"
"32.6400","8.1378","151.5888","8.1378","5.4252","36.0926"
"32.7200","8.1571","151.8746","8.1571","5.4381","36.1606"
"32.8000","8.1770","152.1775","8.1770","5.4513","36.2327"
"32.8800","8.1970","152.4611","8.1970","5.4647","36.3003"
"32.9600","8.2177","152.7840","8.2177","5.4784","36.3771"
"33.0400","8.2391","153.1024","8.2391","5.4927","36.4530"
"33.1200","8.2578","153.3659","8.2578","5.5052","36.5157"
"33.2000","8.2781","153.6703","8.2781","5.5187","36.5882"
"33.2800","8.2977","153.9516","8.2977","5.5318","36.6551"
"33.3600","8.3174","154.2266","8.3174","5.5449","36.7206"
"33.4400","8.3374","154.5184","8.3374","5.5582","36.7901"
"33.5200","8.3563","154.7603","8.3563","5.5709","36.8477"
"33.6000","8.3775","155.0869","8.3775","5.5850","36.9254"
"33.6800","8.3987","155.4059","8.3987","5.5991","37.0014"
"33.7600","8.4183","155.6917","8.4183","5.6122","37.0694"
"33.8400","8.4376","155.9700","8.4376","5.6251","37.1357"
"33.9200","8.4568","156.2273","8.4568","5.6379","37.1970"
"34.0000","8.4769","156.5312","8.4769","5.6512","37.2693"
"34.0800","8.4981","156.8533","8.4981","5.6654","37.3460"
"34.1600","8.5175","157.1232","8.5175","5.6783","37.4103"
"34.2400","8.5384","157.4375","8.5384","5.6923","37.4851"
"34.3200","8.5584","157.7221","8.5584","5.7056","37.5529"
"34.4000","8.5785","158.0116","8.5785","5.7190","37.6218"
"34.4800","8.5980","158.2997","8.5980","5.7320","37.6904"
"34.5600","8.6174","158.5594","8.6174","5.7449","37.7522"
"34.6400","8.6378","158.8547","8.6378","5.7585","37.8226"
"34.7200","8.6576","159.1369","8.6576","5.7717","37.8897"
"34.8000","8.6761","159.3929","8.6761","5.7841","37.9507"
"34.8800","8.6976","159.7262","8.6976","5.7984","38.0301"
"34.9600","8.7183","160.0153","8.7183","5.8122","38.0989"
"35.0400","8.7385","160.3095","8.7385","5.8257","38.1689"
"35.1200","8.7578","160.5647","8.7578","5.8385","38.2297"
"35.2000","8.7765","160.8244","8.7765","5.8510","38.2915"
"35.2800","8.7975","161.1360","8.7975","5.8650","38.3657"
"35.3600","8.8176","161.4162","8.8176","5.8784","38.4324"
"35.4400","8.8374","161.6997","8.8374","5.8916","38.4999"
"35.5200","8.8582","161.9960","8.8582","5.9054","38.5705"
"35.6000","8.8782","162.2840","8.8782","5.9188","38.6390"
"35.6800","8.8984","162.5553","8.8984","5.9323","38.7036"
"35.7600","8.9184","162.8412","8.9184","5.9456","38.7717"
"35.8400","8.9369","163.0912","8.9369","5.9579","38.8312"
"35.9200","8.9569","163.3795","8.9569","5.9712","38.8999"
"36.0000","8.9764","163.6426","8.9764","5.9843","38.9625"
"36.0800","8.9980","163.9634","8.9980","5.9987","39.0389"
"36.1600","9.0186","164.2515","9.0186","6.0124","39.1075"
"36.2400","9.0377","164.5063","9.0377","6.0252","39.1682"
"36.3200","9.0574","164.7601","9.0574","6.0383","39.2286"
"36.4000","9.0777","165.0605","9.0777","6.0518","39.3001"
"36.4800","9.0974","165.3327","9.0974","6.0649","39.3649"
"36.5600","9.1178","165.6358","9.1178","6.0785","39.4371"
"36.6400","9.1367","165.8749","9.1367","6.0912","39.4940"
"36.7200","9.1583","166.1996","9.1583","6.1056","39.5713"
"36.8000","9.1789","166.4965","9.1789","6.1193","39.6420"
"36.8800","9.1984","166.7734","9.1984","6.1323","39.7080"
"36.9600","9.2180","167.0370","9.2180","6.1453","39.7707"
"37.0400","9.2375","167.2936","9.2375","6.1583","39.8318"
"37.1200","9.2574","167.5703","9.2574","6.1716","39.8977"
"37.2000","9.2778","167.8587","9.2778","6.1852","39.9664"
"37.2800","9.2966","168.1205","9.2966","6.1978","40.0287"
"37.3600","9.3178","168.4179","9.3178","6.2119","40.0995"
"37.4400","9.3381","168.6998","9.3381","6.2254","40.1666"
"37.5200","9.3578","168.9703","9.3578","6.2385","40.2310"
"37.6000","9.3776","169.2496","9.3776","6.2518","40.2975"
"37.6800","9.3971","169.5058","9.3971","6.2647","40.3585"
"37.7600","9.4178","169.7888","9.4178","6.2785","40.4259"
"37.8400","9.4374","170.0599","9.4374","6.2916","40.4904"
"37.9200","9.4571","170.3276","9.4571","6.3047","40.5542"
"38.0000","9.4781","170.6339","9.4781","6.3188","40.6271"
"38.0800","9.4984","170.9093","9.4984","6.3323","40.6927"
"38.1600","9.5182","171.1787","9.5182","6.3455","40.7568"
"38.2400","9.5383","171.4437","9.5383","6.3589","40.8199"
"38.3200","9.5564","171.6724","9.5564","6.3710","40.8744"
"38.4000","9.5773","171.9618","9.5773","6.3849","40.9433"
"38.4800","9.5975","172.2319","9.5975","6.3983","41.0076"
"38.5600","9.6177","172.5239","9.6177","6.4118","41.0771"
"38.6400","9.6374","172.7888","9.6374","6.4249","41.1402"
"38.7200","9.6579","173.0644","9.6579","6.4386","41.2058"
"38.8000","9.6780","173.3358","9.6780","6.4520","41.2704"
"38.8800","9.6984","173.6112","9.6984","6.4656","41.3360"
"38.9600","9.7170","173.8550","9.7170","6.4780","41.3941"
"39.0400","9.7374","174.1352","9.7374","6.4916","41.4608"
"39.1200","9.7567","174.3787","9.7567","6.5044","41.5187"
"39.2000","9.7779","174.6982","9.7779","6.5186","41.5948"
"39.2800","9.7992","174.9909","9.7992","6.5328","41.6645"
"39.3600","9.8183","175.2416","9.8183","6.5455","41.7242"
"39.4400","9.8382","175.4922","9.8382","6.5588","41.7839"
"39.5200","9.8580","175.7594","9.8580","6.5720","41.8475"
"39.6000","9.8769","176.0087","9.8769","6.5846","41.9068"
"39.6800","9.8970","176.2897","9.8970","6.5980","41.9737"
"39.7600","9.9170","176.5482","9.9170","6.6113","42.0353"
"39.8400","9.9375","176.8351","9.9375","6.6250","42.1036"
"39.9200","9.9588","177.1253","9.9588","6.6392","42.1727"
"40.0000","9.9775","177.3636","9.9775","6.6516","42.2294"
"40.0800","9.9981","177.6471","9.9981","6.6654","42.2969"
"40.1600","10.0173","177.8957","10.0173","6.6782","42.3561"
"40.2400","10.0374","178.1593","10.0374","6.6916","42.4189"
"40.3200","10.0572","178.4217","10.0572","6.7048","42.4814"
"40.4000","10.0775","178.6982","10.0775","6.7183","42.5472"
"40.4800","10.0984","178.9864","10.0984","6.7323","42.6158"
"40.5600","10.1188","179.2446","10.1188","6.7458","42.6773"
"40.6400","10.1378","179.4910","10.1378","6.7585","42.7360"
"40.7200","10.1581","179.7584","10.1581","6.7720","42.7996"
"40.8000","10.1767","179.9761","10.1767","6.7845","42.8514"
"40.8800","10.1974","180.2524","10.1974","6.7982","42.9172"
"40.9600","10.2178","180.5277","10.2178","6.8119","42.9828"
"41.0400","10.2369","180.7652","10.2369","6.8246","43.0393"
"41.1200","10.2573","181.0450","10.2573","6.8382","43.1059"
"41.2000","10.2782","181.3181","10.2782","6.8522","43.1710"
"41.2800","10.2983","181.5845","10.2983","6.8656","43.2344"
"41.3600","10.3186","181.8542","10.3186","6.8791","43.2986"
"41.4400","10.3368","182.0534","10.3368","6.8912","43.3461"
"41.5200","10.3572","182.3319","10.3572","6.9048","43.4124"
"41.6000","10.3776","182.6011","10.3776","6.9184","43.4765"
"41.6800","10.3976","182.8715","10.3976","6.9317","43.5408"
"41.7600","10.4190","183.1583","10.4190","6.9460","43.6091"
"41.8400","10.4381","183.3834","10.4381","6.9588","43.6627"
"41.9200","10.4583","183.6584","10.4583","6.9722","43.7282"
"42.0000","10.4780","183.8933","10.4780","6.9853","43.7841"
"42.0800","10.4976","184.1567","10.4976","6.9984","43.8468"
"42.1600","10.5175","184.4174","10.5175","7.0117","43.9089"
"42.2400","10.5371","184.6547","10.5371","7.0248","43.9654"
"42.3200","10.5566","184.9052","10.5566","7.0377","44.0250"
"42.4000","10.5780","185.1889","10.5780","7.0520","44.0926"
"42.4800","10.5978","185.4382","10.5978","7.0652","44.1520"
"42.5600","10.6189","185.7129","10.6189","7.0793","44.2173"
"42.6400","10.6377","185.9393","10.6377","7.0918","44.2713"
"42.7200","10.6569","186.1804","10.6569","7.1046","44.3287"
"42.8000","10.6770","186.4427","10.6770","7.1180","44.3911"
"42.8800","10.6973","186.6996","10.6973","7.1315","44.4523"
"42.9600","10.7178","186.9690","10.7178","7.1452","44.5164"
"43.0400","10.7387","187.2386","10.7387","7.1591","44.5806"
"43.1200","10.7572","187.4567","10.7572","7.1715","44.6325"
"43.2000","10.7783","187.7331","10.7783","7.1855","44.6984"
"43.2800","10.7980","187.9736","10.7980","7.1987","44.7556"
"43.3600","10.8179","188.2279","10.8179","7.2119","44.8162"
"43.4400","10.8377","188.4775","10.8377","7.2251","44.8756"
"43.5200","10.8561","188.6851","10.8561","7.2374","44.9250"
"43.6000","10.8776","188.9806","10.8776","7.2517","44.9954"
"43.6800","10.8986","189.2597","10.8986","7.2657","45.0618"
"43.7600","10.9186","189.5024","10.9186","7.2790","45.1196"
"43.8400","10.9377","189.7420","10.9377","7.2918","45.1767"
"43.9200","10.9564","189.9582","10.9564","7.3043","45.2281"
"44.0000","10.9771","190.2249","10.9771","7.3180","45.2916"
"44.0800","10.9988","190.5126","10.9988","7.3325","45.3601"
"44.1600","11.0172","190.7361","11.0172","7.3448","45.4134"
"44.2400","11.0382","191.0146","11.0382","7.3588","45.4797"
"44.3200","11.0581","191.2621","11.0581","7.3721","45.5386"
"44.4000","11.0786","191.5179","11.0786","7.3857","45.5995"
"44.4800","11.0979","191.7499","11.0979","7.3986","45.6547"
"44.5600","11.1174","191.9838","11.1174","7.4116","45.7104"
"44.6400","11.1377","192.2488","11.1377","7.4251","45.7735"
"44.7200","11.1579","192.5036","11.1579","7.4386","45.8342"
"44.8000","11.1764","192.7251","11.1764","7.4509","45.8869"
"44.8800","11.1978","193.0158","11.1978","7.4652","45.9561"
"44.9600","11.2180","193.2580","11.2180","7.4786","46.0138"
"45.0400","11.2386","193.5214","11.2386","7.4924","46.0765"
"45.1200","11.2577","193.7264","11.2577","7.5052","46.1253"
"45.2000","11.2763","193.9456","11.2763","7.5175","46.1775"
"45.2800","11.2975","194.2251","11.2975","7.5317","46.2441"
"45.3600","11.3178","194.4794","11.3178","7.5452","46.3046"
"45.4400","11.3374","194.7185","11.3374","7.5583","46.3615"
"45.5200","11.3577","194.9722","11.3577","7.5718","46.4219"
"45.6000","11.3780","195.2157","11.3780","7.5853","46.4799"
"45.6800","11.3986","195.4646","11.3986","7.5990","46.5392"
"45.7600","11.4185","195.7187","11.4185","7.6123","46.5997"
"45.8400","11.4371","195.9308","11.4371","7.6247","46.6502"
"45.9200","11.4576","196.1886","11.4576","7.6384","46.7116"
"46.0000","11.4767","196.4112","11.4767","7.6511","46.7646"
"46.0800","11.4979","196.6752","11.4979","7.6652","46.8274"
"46.1600","11.5186","196.9364","11.5186","7.6791","46.8896"
"46.2400","11.5380","197.1581","11.5380","7.6920","46.9424"
"46.3200","11.5573","197.3911","11.5573","7.7049","46.9979"
"46.4000","11.5774","197.6283","11.5774","7.7183","47.0544"
"46.4800","11.5972","197.8801","11.5972","7.7314","47.1143"
"46.5600","11.6182","198.1383","11.6182","7.7455","47.1758"
"46.6400","11.6366","198.3349","11.6366","7.7577","47.2226"
"46.7200","11.6580","198.6165","11.6580","7.7720","47.2897"
"46.8000","11.6786","198.8677","11.6786","7.7857","47.3495"
"46.8800","11.6985","199.1049","11.6985","7.7990","47.4059"
"46.9600","11.7180","199.3334","11.7180","7.8120","47.4603"
"47.0400","11.7374","199.5607","11.7374","7.8249","47.5145"
"47.1200","11.7577","199.8095","11.7577","7.8385","47.5737"
"47.2000","11.7782","200.0567","11.7782","7.8522","47.6325"
"47.2800","11.7963","200.2542","11.7963","7.8642","47.6796"
"47.3600","11.8176","200.5244","11.8176","7.8784","47.7439"
"47.4400","11.8383","200.7704","11.8383","7.8922","47.8025"
"47.5200","11.8579","201.0005","11.8579","7.9052","47.8573"
"47.6000","11.8780","201.2476","11.8780","7.9187","47.9161"
"47.6800","11.8970","201.4555","11.8970","7.9313","47.9656"
"47.7600","11.9179","201.7076","11.9179","7.9452","48.0256"
"47.8400","11.9377","201.9384","11.9377","7.9584","48.0806"
"47.9200","11.9571","202.1780","11.9571","7.9714","48.1376"
"48.0000","11.9779","202.4399","11.9779","7.9853","48.2000"
"48.0800","11.9986","202.6774","11.9986","7.9991","48.2565"
"48.1600","12.0183","202.9042","12.0183","8.0122","48.3105"
"48.2400","12.0377","203.1189","12.0377","8.0252","48.3617"
"48.3200","12.0568","203.3230","12.0568","8.0379","48.4102"
"48.4000","12.0779","203.5884","12.0779","8.0519","48.4734"
"48.4800","12.0973","203.7969","12.0973","8.0649","48.5231"
"48.5600","12.1173","204.0402","12.1173","8.0782","48.5810"
"48.6400","12.1378","204.2829","12.1378","8.0919","48.6388"
"48.7200","12.1582","204.5241","12.1582","8.1054","48.6962"
"48.8000","12.1778","204.7380","12.1778","8.1185","48.7471"
"48.8800","12.1981","204.9752","12.1981","8.1321","48.8036"
"48.9600","12.2169","205.1820","12.2169","8.1446","48.8528"
"49.0400","12.2375","205.4283","12.2375","8.1583","48.9115"
"49.1200","12.2569","205.6443","12.2569","8.1713","48.9629"
"49.2000","12.2780","205.9084","12.2780","8.1854","49.0258"
"49.2800","12.2994","206.1623","12.2994","8.1996","49.0863"
"49.3600","12.3183","206.3735","12.3183","8.2122","49.1365"
"49.4400","12.3381","206.5836","12.3381","8.2254","49.1866"
"49.5200","12.3577","206.8050","12.3577","8.2385","49.2393"
"49.6000","12.3772","207.0189","12.3772","8.2515","49.2902"
"49.6800","12.3974","207.2585","12.3974","8.2649","49.3473"
"49.7600","12.4169","207.4684","12.4169","8.2779","49.3972"
"49.8400","12.4375","207.7194","12.4375","8.2917","49.4570"
"49.9200","12.4587","207.9608","12.4587","8.3058","49.5145"
"50.0000","12.4778","208.1827","12.4778","8.3185","49.5673"
"50.0800","12.4983","208.4136","12.4983","8.3322","49.6223"
"50.1600","12.5172","208.5998","12.5172","8.3448","49.6666"
"50.2400","12.5375","208.8363","12.5375","8.3583","49.7229"
"50.3200","12.5569","209.0466","12.5569","8.3713","49.7730"
"50.4000","12.5770","209.2721","12.5770","8.3847","49.8267"
"50.4800","12.5982","209.5351","12.5982","8.3988","49.8893"
"50.5600","12.6194","209.7820","12.6194","8.4129","49.9481"
"50.6400","12.6375","209.9644","12.6375","8.4250","49.9915"
"50.7200","12.6579","210.1893","12.6579","8.4386","50.0451"
"50.8000","12.6770","210.3745","12.6770","8.4513","50.0892"
"50.8800","12.6982","210.6230","12.6982","8.4655","50.1483"
"50.9600","12.7178","210.8248","12.7178","8.4785","50.1964"
"51.0400","12.7367","211.0407","12.7367","8.4912","50.2478"
"51.1200","12.7574","211.2802","12.7574","8.5049","50.3048"
"51.2000","12.7782","211.5179","12.7782","8.5188","50.3614"
"51.2800","12.7981","211.7346","12.7981","8.5321","50.4130"
"51.3600","12.8183","211.9674","12.8183","8.5455","50.4684"
"51.4400","12.8366","212.1195","12.8366","8.5577","50.5046"
"51.5200","12.8569","212.3521","12.8569","8.5713","50.5600"
"51.6000","12.8776","212.5842","12.8776","8.5851","50.6153"
"51.6800","12.8976","212.8296","12.8976","8.5984","50.6737"
"51.7600","12.9191","213.0763","12.9191","8.6127","50.7325"
"51.8400","12.9382","213.2618","12.9382","8.6255","50.7766"
"51.9200","12.9584","213.4790","12.9584","8.6390","50.8283"
"52.0000","12.9781","213.6973","12.9781","8.6521","50.8803"
"52.0800","12.9976","213.9008","12.9976","8.6650","50.9288"
"52.1600","13.0175","214.1078","13.0175","8.6783","50.9780"
"52.2400","13.0373","214.3371","13.0373","8.6915","51.0326"
"52.3200","13.0571","214.5548","13.0571","8.7047","51.0845"
"52.4000","13.0783","214.7997","13.0783","8.7189","51.1428"
"52.4800","13.0976","214.9930","13.0976","8.7318","51.1888"
"52.5600","13.1188","215.2273","13.1188","8.7459","51.2446"
"52.6400","13.1378","215.3990","13.1378","8.7585","51.2855"
"52.7200","13.1567","215.6003","13.1567","8.7711","51.3334"
"52.8000","13.1770","215.8258","13.1770","8.7847","51.3871"
"52.8800","13.1972","216.0397","13.1972","8.7982","51.4380"
"52.9600","13.2180","216.2645","13.2180","8.8120","51.4916"
"53.0400","13.2390","216.5008","13.2390","8.8260","51.5478"
"53.1200","13.2579","216.6813","13.2579","8.8386","51.5908"
"53.2000","13.2782","216.8962","13.2782","8.8522","51.6420"
"53.2800","13.2978","217.0896","13.2978","8.8652","51.6880"
"53.3600","13.3180","217.3120","13.3180","8.8787","51.7410"
"53.4400","13.3376","217.5022","13.3376","8.8917","51.7862"
"53.5200","13.3561","217.6711","13.3561","8.9040","51.8265"
"53.6000","13.3775","217.9172","13.3775","8.9183","51.8850"
"53.6800","13.3983","218.1397","13.3983","8.9322","51.9380"
"53.7600","13.4178","218.3283","13.4178","8.9452","51.9829"
"53.8400","13.4379","218.5329","13.4379","8.9586","52.0317"
"53.9200","13.4568","218.7081","13.4568","8.9712","52.0734"
"54.0000","13.4772","218.9226","13.4772","8.9848","52.1244"
"54.0800","13.4983","219.1464","13.4983","8.9989","52.1777"
"54.1600","13.5173","219.3266","13.5173","9.0115","52.2206"
"54.2400","13.5382","219.5482","13.5382","9.0254","52.2734"
"54.3200","13.5582","219.7396","13.5582","9.0388","52.3189"
"54.4000","13.5785","219.9510","13.5785","9.0523","52.3693"
"54.4800","13.5982","220.1458","13.5982","9.0655","52.4157"
"54.5600","13.6175","220.3156","13.6175","9.0783","52.4561"
"54.6400","13.6374","220.5175","13.6374","9.0916","52.5042"
"54.7200","13.6577","220.7153","13.6577","9.1051","52.5513"
"54.8000","13.6762","220.8779","13.6762","9.1175","52.5900"
"54.8800","13.6979","221.1210","13.6979","9.1320","52.6479"
"54.9600","13.7181","221.3116","13.7181","9.1454","52.6932"
"55.0400","13.7385","221.5089","13.7385","9.1590","52.7402"
"55.1200","13.7576","221.6789","13.7576","9.1717","52.7807"
"55.2000","13.7766","221.8443","13.7766","9.1844","52.8201"
"55.2800","13.7976","222.0695","13.7976","9.1984","52.8737"
"55.3600","13.8178","222.2670","13.8178","9.2119","52.9207"
"55.4400","13.8377","222.4529","13.8377","9.2251","52.9650"
"55.5200","13.8582","222.6602","13.8582","9.2388","53.0143"
"55.6000","13.8780","222.8242","13.8780","9.2520","53.0534"
"55.6800","13.8986","223.0301","13.8986","9.2657","53.1024"
"55.7600","13.9183","223.1965","13.9183","9.2788","53.1420"
"55.8400","13.9371","223.3673","13.9371","9.2914","53.1827"
"55.9200","13.9576","223.5667","13.9576","9.3050","53.2302"
"56.0000","13.9765","223.7225","13.9765","9.3177","53.2673"
"56.0800","13.9973","223.9330","13.9973","9.3316","53.3174"
"56.1600","14.0186","224.1476","14.0186","9.3458","53.3685"
"56.2400","14.0379","224.3003","14.0379","9.3586","53.4048"
"56.3200","14.0576","224.4762","14.0576","9.3717","53.4467"
"56.4000","14.0774","224.6466","14.0774","9.3849","53.4873"
"56.4800","14.0970","224.8192","14.0970","9.3980","53.5284"
"56.5600","14.1179","225.0233","14.1179","9.4119","53.5770"
"56.6400","14.1369","225.1642","14.1369","9.4246","53.6105"
"56.7200","14.1578","225.3574","14.1578","9.4386","53.6565"
"56.8000","14.1786","225.5518","14.1786","9.4524","53.7028"
"56.8800","14.1987","225.7367","14.1987","9.4658","53.7468"
"56.9600","14.2181","225.8936","14.2181","9.4787","53.7842"
"57.0400","14.2373","226.0501","14.2373","9.4915","53.8215"
"57.1200","14.2572","226.2195","14.2572","9.5048","53.8618"
"57.2000","14.2777","226.4005","14.2777","9.5185","53.9049"
"57.2800","14.2967","226.5404","14.2967","9.5311","53.9382"
"57.3600","14.3175","226.7482","14.3175","9.5450","53.9877"
"57.4400","14.3382","226.9274","14.3382","9.5588","54.0303"
"57.5200","14.3578","227.0912","14.3578","9.5719","54.0693"
"57.6000","14.3780","227.2695","14.3780","9.5853","54.1118"
"57.6800","14.3972","227.4103","14.3972","9.5981","54.1453"
"57.7600","14.4181","227.6068","14.4181","9.6121","54.1921"
"57.8400","14.4380","227.7699","14.4380","9.6253","54.2309"
"57.9200","14.4572","227.9312","14.4572","9.6381","54.2693"
"58.0000","14.4777","228.1126","14.4777","9.6518","54.3125"
"58.0800","14.4985","228.2909","14.4985","9.6657","54.3550"
"58.1600","14.5183","228.4531","14.5183","9.6788","54.3936"
"58.2400","14.5379","228.6127","14.5379","9.6920","54.4316"
"58.3200","14.5567","228.7446","14.5567","9.7044","54.4630"
"58.4000","14.5772","228.9154","14.5772","9.7181","54.5037"
"58.4800","14.5973","229.0860","14.5973","9.7315","54.5443"
"58.5600","14.6171","229.2428","14.6171","9.7448","54.5816"
"58.6400","14.6379","229.4217","14.6379","9.7586","54.6242"
"58.7200","14.6582","229.5790","14.6582","9.7721","54.6617"
"58.8000","14.6781","229.7310","14.6781","9.7854","54.6978"
"58.8800","14.6982","229.8919","14.6982","9.7988","54.7362"
"58.9600","14.7170","230.0152","14.7170","9.8113","54.7655"
"59.0400","14.7374","230.1879","14.7374","9.8250","54.8066"
"59.1200","14.7569","230.3234","14.7569","9.8380","54.8389"
"59.2000","14.7779","230.5138","14.7779","9.8519","54.8842"
"59.2800","14.7991","230.6869","14.7991","9.8661","54.9255"
"59.3600","14.8184","230.8160","14.8184","9.8789","54.9562"
"59.4400","14.8379","230.9447","14.8379","9.8919","54.9868"
"59.5200","14.8576","231.0757","14.8576","9.9051","55.0180"
"59.6000","14.8772","231.2144","14.8772","9.9181","55.0510"
"59.6800","14.8973","231.3683","14.8973","9.9315","55.0877"
"59.7600","14.9167","231.4858","14.9167","9.9445","55.1157"
"59.8400","14.9374","231.6464","14.9374","9.9583","55.1539"
"59.9200","14.9587","231.7964","14.9587","9.9724","55.1896"
"60.0000","14.9777","231.9186","14.9777","9.9851","55.2187"
"60.0800","14.9982","232.0818","14.9982","9.9988","55.2576"
"60.0880","15.0002","232.0959","15.0002","10.0001","55.2609"