File: data/instron_tests/metamaterials/250416/250416_1310_NSC_m1.is_comp_Exports/240416_1310_NSC_m1_2_1.csv
Results Table 1
,Compresson Axis,H*,V*,Height,Thickness,Width,Area,Fixture separation,Specimen label
,,,,(mm),(mm),(mm),(mm^2),(mm),
"2","Y","","","150.00","28.00","150.00","4200.00","150.00","1310_NSC_m1"

Results Table 2
,Modulus (Segment 0 % - 2.5 %),Compresson Axis
,(kPa),
"2","630.44","Y"

Time,Displacement,Force,Compressive displacement,Compressive strain (Displacement),Compressive stress
(s),(mm),(N),(mm),(%),(kPa)
"0.0000","0.0000","9.3245","0.0000","0.0000","2.2201"
"0.0800","0.0013","9.3576","0.0013","0.0009","2.2280"
"0.1600","0.0177","9.7893","0.0177","0.0118","2.3308"
"0.2400","0.0385","10.3277","0.0385","0.0256","2.4590"
"0.3200","0.0586","10.8223","0.0586","0.0391","2.5767"
"0.4000","0.0775","11.2811","0.0775","0.0517","2.6860"
"0.4800","0.0982","11.7735","0.0982","0.0655","2.8032"
"0.5600","0.1187","12.2489","0.1187","0.0792","2.9164"
"0.6400","0.1386","12.7060","0.1386","0.0924","3.0252"
"0.7200","0.1580","13.1399","0.1580","0.1054","3.1285"
"0.8000","0.1772","13.5623","0.1772","0.1182","3.2291"
"0.8800","0.1980","14.0134","0.1980","0.1320","3.3365"
"0.9600","0.2184","14.4630","0.2184","0.1456","3.4436"
"1.0400","0.2366","14.8649","0.2366","0.1578","3.5393"
"1.1200","0.2578","15.3170","0.2578","0.1719","3.6469"
"1.2000","0.2783","15.7503","0.2783","0.1855","3.7501"
"1.2800","0.2987","16.1787","0.2987","0.1992","3.8521"
"1.3600","0.3186","16.5679","0.3186","0.2124","3.9447"
"1.4400","0.3368","16.9303","0.3368","0.2245","4.0310"
"1.5200","0.3572","17.3434","0.3572","0.2381","4.1294"
"1.6000","0.3778","17.7573","0.3778","0.2518","4.2279"
"1.6800","0.3976","18.1533","0.3976","0.2651","4.3222"
"1.7600","0.4187","18.5751","0.4187","0.2792","4.4226"
"1.8400","0.4383","18.9205","0.4383","0.2922","4.5049"
"1.9200","0.4583","19.3015","0.4583","0.3055","4.5956"
"2.0000","0.4783","19.6812","0.4783","0.3189","4.6860"
"2.0800","0.4973","20.0546","0.4973","0.3315","4.7749"
"2.1600","0.5180","20.4476","0.5180","0.3454","4.8685"
"2.2400","0.5372","20.7980","0.5372","0.3582","4.9519"
"2.3200","0.5569","21.1737","0.5569","0.3713","5.0414"
"2.4000","0.5785","21.5882","0.5785","0.3857","5.1400"
"2.4800","0.5977","21.9355","0.5977","0.3985","5.2227"
"2.5600","0.6179","22.3021","0.6179","0.4120","5.3100"
"2.6400","0.6379","22.6676","0.6379","0.4253","5.3970"
"2.7200","0.6569","23.0096","0.6569","0.4379","5.4785"
"2.8000","0.6776","23.3897","0.6776","0.4517","5.5690"
"2.8800","0.6973","23.7256","0.6973","0.4649","5.6489"
"2.9600","0.7183","24.0950","0.7183","0.4788","5.7369"
"3.0400","0.7393","24.4570","0.7393","0.4929","5.8231"
"3.1200","0.7580","24.7932","0.7580","0.5054","5.9031"
"3.2000","0.7781","25.1615","0.7781","0.5187","5.9908"
"3.2800","0.7982","25.5148","0.7982","0.5321","6.0749"
"3.3600","0.8179","25.8533","0.8179","0.5453","6.1555"
"3.4400","0.8375","26.2049","0.8375","0.5583","6.2393"
"3.5200","0.8565","26.5349","0.8565","0.5710","6.3178"
"3.6000","0.8780","26.9533","0.8780","0.5854","6.4175"
"3.6800","0.8991","27.3433","0.8991","0.5994","6.5103"
"3.7600","0.9185","27.7044","0.9185","0.6123","6.5963"
"3.8400","0.9378","28.0549","0.9378","0.6252","6.6797"
"3.9200","0.9563","28.3720","0.9563","0.6376","6.7552"
"4.0000","0.9773","28.7798","0.9773","0.6515","6.8523"
"4.0800","0.9986","29.1692","0.9986","0.6657","6.9451"
"4.1600","1.0174","29.4964","1.0174","0.6783","7.0230"
"4.2400","1.0383","29.8806","1.0383","0.6922","7.1144"
"4.3200","1.0583","30.2370","1.0583","0.7055","7.1993"
"4.4000","1.0782","30.5921","1.0782","0.7188","7.2838"
"4.4800","1.0981","30.9449","1.0981","0.7321","7.3678"
"4.5600","1.1175","31.2828","1.1175","0.7450","7.4483"
"4.6400","1.1378","31.6295","1.1378","0.7585","7.5308"
"4.7200","1.1576","31.9827","1.1576","0.7717","7.6149"
"4.8000","1.1765","32.3071","1.1765","0.7843","7.6922"
"4.8800","1.1979","32.6958","1.1979","0.7986","7.7847"
"4.9600","1.2180","33.0211","1.2180","0.8120","7.8622"
"5.0400","1.2385","33.3724","1.2385","0.8256","7.9458"
"5.1200","1.2580","33.7048","1.2580","0.8386","8.0249"
"5.2000","1.2766","34.0195","1.2766","0.8511","8.0999"
"5.2800","1.2979","34.3895","1.2979","0.8652","8.1880"
"5.3600","1.3183","34.7461","1.3183","0.8788","8.2729"
"5.4400","1.3379","35.0809","1.3379","0.8919","8.3526"
"5.5200","1.3586","35.4628","1.3586","0.9057","8.4435"
"5.6000","1.3783","35.7958","1.3783","0.9189","8.5228"
"5.6800","1.3990","36.1576","1.3990","0.9326","8.6089"
"5.7600","1.4187","36.4858","1.4187","0.9458","8.6871"
"5.8400","1.4372","36.8031","1.4372","0.9581","8.7626"
"5.9200","1.4575","37.1566","1.4575","0.9717","8.8468"
"6.0000","1.4766","37.4750","1.4766","0.9844","8.9226"
"6.0800","1.4982","37.8649","1.4982","0.9988","9.0154"
"6.1600","1.5188","38.2184","1.5188","1.0125","9.0996"
"6.2400","1.5380","38.5340","1.5380","1.0253","9.1748"
"6.3200","1.5575","38.8780","1.5575","1.0383","9.2567"
"6.4000","1.5777","39.2442","1.5777","1.0518","9.3438"
"6.4800","1.5975","39.5937","1.5975","1.0650","9.4271"
"6.5600","1.6181","39.9665","1.6181","1.0787","9.5158"
"6.6400","1.6367","40.2810","1.6367","1.0911","9.5907"
"6.7200","1.6581","40.6636","1.6581","1.1054","9.6818"
"6.8000","1.6788","41.0361","1.6788","1.1192","9.7705"
"6.8800","1.6988","41.3879","1.6988","1.1325","9.8543"
"6.9600","1.7180","41.7154","1.7180","1.1454","9.9322"
"7.0400","1.7376","42.0471","1.7376","1.1584","10.0112"
"7.1200","1.7575","42.3981","1.7575","1.1717","10.0948"
"7.2000","1.7782","42.7540","1.7782","1.1854","10.1795"
"7.2800","1.7967","43.0595","1.7967","1.1978","10.2523"
"7.3600","1.8178","43.4249","1.8178","1.2119","10.3393"
"7.4400","1.8386","43.7817","1.8386","1.2257","10.4242"
"7.5200","1.8579","44.1049","1.8579","1.2386","10.5012"
"7.6000","1.8779","44.4314","1.8779","1.2519","10.5789"
"7.6800","1.8973","44.7536","1.8973","1.2649","10.6556"
"7.7600","1.9178","45.1004","1.9178","1.2785","10.7382"
"7.8400","1.9378","45.4376","1.9378","1.2919","10.8185"
"7.9200","1.9572","45.7737","1.9572","1.3048","10.8985"
"8.0000","1.9783","46.1613","1.9783","1.3188","10.9908"
"8.0800","1.9989","46.5191","1.9989","1.3326","11.0760"
"8.1600","2.0184","46.8466","2.0184","1.3456","11.1540"
"8.2400","2.0382","47.1892","2.0382","1.3588","11.2355"
"8.3200","2.0568","47.5039","2.0568","1.3712","11.3105"
"8.4000","2.0781","47.8894","2.0781","1.3854","11.4022"
"8.4800","2.0977","48.2429","2.0977","1.3984","11.4864"
"8.5600","2.1172","48.5830","2.1172","1.4115","11.5674"
"8.6400","2.1379","48.9710","2.1379","1.4253","11.6598"
"8.7200","2.1585","49.3445","2.1585","1.4390","11.7487"
"8.8000","2.1786","49.7081","2.1786","1.4524","11.8353"
"8.8800","2.1985","50.0618","2.1985","1.4657","11.9195"
"8.9600","2.2168","50.3865","2.2168","1.4779","11.9968"
"9.0400","2.2375","50.7815","2.2375","1.4917","12.0908"
"9.1200","2.2571","51.1294","2.2571","1.5047","12.1737"
"9.2000","2.2780","51.5267","2.2780","1.5187","12.2683"
"9.2800","2.2992","51.9188","2.2992","1.5328","12.3616"
"9.3600","2.3186","52.2648","2.3186","1.5457","12.4440"
"9.4400","2.3384","52.6226","2.3384","1.5589","12.5292"
"9.5200","2.3579","52.9814","2.3579","1.5720","12.6146"
"9.6000","2.3769","53.3130","2.3769","1.5846","12.6936"
"9.6800","2.3974","53.6914","2.3974","1.5983","12.7837"
"9.7600","2.4171","54.0373","2.4171","1.6114","12.8660"
"9.8400","2.4380","54.4288","2.4380","1.6254","12.9592"
"9.9200","2.4589","54.8083","2.4589","1.6393","13.0496"
"10.0000","2.4779","55.1663","2.4779","1.6519","13.1348"
"10.0800","2.4980","55.5319","2.4980","1.6654","13.2219"
"10.1600","2.5174","55.8748","2.5174","1.6783","13.3035"
"10.2400","2.5374","56.2525","2.5374","1.6916","13.3935"
"10.3200","2.5577","56.6266","2.5577","1.7051","13.4825"
"10.4000","2.5773","56.9816","2.5773","1.7182","13.5670"
"10.4800","2.5983","57.3666","2.5983","1.7322","13.6587"
"10.5600","2.6192","57.7434","2.6192","1.7461","13.7484"
"10.6400","2.6381","58.0780","2.6381","1.7587","13.8281"
"10.7200","2.6581","58.4289","2.6581","1.7720","13.9116"
"10.8000","2.6774","58.7659","2.6774","1.7849","13.9919"
"10.8800","2.6981","59.1409","2.6981","1.7987","14.0812"
"10.9600","2.7178","59.4954","2.7178","1.8119","14.1656"
"11.0400","2.7368","59.8335","2.7368","1.8245","14.2461"
"11.1200","2.7577","60.2198","2.7577","1.8385","14.3381"
"11.2000","2.7786","60.5834","2.7786","1.8524","14.4246"
"11.2800","2.7986","60.9468","2.7986","1.8657","14.5111"
"11.3600","2.8182","61.2850","2.8182","1.8788","14.5917"
"11.4400","2.8369","61.5973","2.8369","1.8912","14.6660"
"11.5200","2.8575","61.9667","2.8575","1.9050","14.7540"
"11.6000","2.8776","62.3239","2.8776","1.9184","14.8390"
"11.6800","2.8975","62.6755","2.8975","1.9317","14.9227"
"11.7600","2.9185","63.0636","2.9185","1.9457","15.0151"
"11.8400","2.9383","63.3935","2.9383","1.9589","15.0937"
"11.9200","2.9586","63.7442","2.9586","1.9724","15.1772"
"12.0000","2.9781","64.0863","2.9781","1.9854","15.2586"
"12.0800","2.9977","64.4282","2.9977","1.9984","15.3401"
"12.1600","3.0178","64.7759","3.0178","2.0119","15.4228"
"12.2400","3.0376","65.1073","3.0376","2.0251","15.5017"
"12.3200","3.0571","65.4439","3.0571","2.0381","15.5819"
"12.4000","3.0783","65.8204","3.0783","2.0522","15.6715"
"12.4800","3.0979","66.1431","3.0979","2.0652","15.7484"
"12.5600","3.1187","66.4889","3.1187","2.0792","15.8307"
"12.6400","3.1381","66.7967","3.1381","2.0921","15.9040"
"12.7200","3.1568","67.0882","3.1568","2.1046","15.9734"
"12.8000","3.1770","67.4001","3.1770","2.1180","16.0476"
"12.8800","3.1979","67.7308","3.1979","2.1319","16.1264"
"12.9600","3.2181","68.0493","3.2181","2.1454","16.2022"
"13.0400","3.2394","68.4019","3.2394","2.1596","16.2862"
"13.1200","3.2579","68.6845","3.2579","2.1719","16.3535"
"13.2000","3.2781","68.9918","3.2781","2.1854","16.4266"
"13.2800","3.2980","69.2927","3.2980","2.1987","16.4983"
"13.3600","3.3178","69.5796","3.3178","2.2118","16.5666"
"13.4400","3.3379","69.8713","3.3379","2.2253","16.6360"
"13.5200","3.3565","70.1240","3.3565","2.2377","16.6962"
"13.6000","3.3777","70.4486","3.3777","2.2518","16.7735"
"13.6800","3.3987","70.7504","3.3987","2.2658","16.8453"
"13.7600","3.4183","71.0476","3.4183","2.2789","16.9161"
"13.8400","3.4377","71.3637","3.4377","2.2918","16.9914"
"13.9200","3.4569","71.6429","3.4569","2.3046","17.0578"
"14.0000","3.4774","71.9821","3.4774","2.3182","17.1386"
"14.0800","3.4982","72.3203","3.4982","2.3322","17.2191"
"14.1600","3.5171","72.6292","3.5171","2.3448","17.2927"
"14.2400","3.5384","72.9812","3.5384","2.3589","17.3765"
"14.3200","3.5583","73.3139","3.5583","2.3722","17.4557"
"14.4000","3.5784","73.6468","3.5784","2.3856","17.5350"
"14.4800","3.5979","73.9436","3.5979","2.3986","17.6056"
"14.5600","3.6178","74.2618","3.6178","2.4118","17.6814"
"14.6400","3.6379","74.5839","3.6379","2.4253","17.7581"
"14.7200","3.6575","74.9026","3.6575","2.4383","17.8340"
"14.8000","3.6763","75.2317","3.6763","2.4509","17.9123"
"14.8800","3.6979","75.6280","3.6979","2.4653","18.0067"
"14.9600","3.7182","75.9632","3.7182","2.4788","18.0865"
"15.0400","3.7383","76.3028","3.7383","2.4922","18.1673"
"15.1200","3.7576","76.6233","3.7576","2.5051","18.2436"
"15.2000","3.7768","76.9654","3.7768","2.5179","18.3251"
"15.2800","3.7981","77.3411","3.7981","2.5321","18.4146"
"15.3600","3.8178","77.6565","3.8178","2.5452","18.4896"
"15.4400","3.8378","77.9893","3.8378","2.5585","18.5689"
"15.5200","3.8586","78.3598","3.8586","2.5724","18.6571"
"15.6000","3.8781","78.7001","3.8781","2.5854","18.7381"
"15.6800","3.8986","79.0597","3.8986","2.5990","18.8237"
"15.7600","3.9186","79.4078","3.9186","2.6124","18.9066"
"15.8400","3.9372","79.7420","3.9372","2.6248","18.9862"
"15.9200","3.9576","80.1036","3.9576","2.6384","19.0723"
"16.0000","3.9769","80.4398","3.9769","2.6512","19.1523"
"16.0800","3.9979","80.8236","3.9979","2.6653","19.2437"
"16.1600","4.0191","81.1974","4.0191","2.6794","19.3327"
"16.2400","4.0379","81.5050","4.0379","2.6920","19.4060"
"16.3200","4.0574","81.8307","4.0574","2.7050","19.4835"
"16.4000","4.0778","82.1945","4.0778","2.7186","19.5701"
"16.4800","4.0974","82.5287","4.0974","2.7316","19.6497"
"16.5600","4.1181","82.9081","4.1181","2.7454","19.7400"
"16.6400","4.1366","83.2207","4.1366","2.7578","19.8145"
"16.7200","4.1582","83.6043","4.1582","2.7721","19.9058"
"16.8000","4.1787","83.9793","4.1787","2.7858","19.9951"
"16.8800","4.1987","84.3289","4.1987","2.7992","20.0783"
"16.9600","4.2184","84.6742","4.2184","2.8123","20.1605"
"17.0400","4.2378","85.0046","4.2378","2.8252","20.2392"
"17.1200","4.2573","85.3474","4.2573","2.8382","20.3208"
"17.2000","4.2777","85.6781","4.2777","2.8518","20.3996"
"17.2800","4.2970","86.0138","4.2970","2.8647","20.4795"
"17.3600","4.3183","86.3934","4.3183","2.8789","20.5699"
"17.4400","4.3381","86.7430","4.3381","2.8921","20.6531"
"17.5200","4.3579","87.0939","4.3579","2.9053","20.7366"
"17.6000","4.3781","87.4530","4.3781","2.9187","20.8221"
"17.6800","4.3971","87.7759","4.3971","2.9314","20.8990"
"17.7600","4.4177","88.1320","4.4177","2.9451","20.9838"
"17.8400","4.4379","88.4825","4.4379","2.9586","21.0673"
"17.9200","4.4572","88.8235","4.4572","2.9715","21.1484"
"18.0000","4.4780","89.1928","4.4780","2.9853","21.2364"
"18.0800","4.4988","89.5552","4.4988","2.9992","21.3227"
"18.1600","4.5186","89.9012","4.5186","3.0124","21.4051"
"18.2400","4.5384","90.2150","4.5384","3.0256","21.4798"
"18.3200","4.5569","90.5275","4.5569","3.0380","21.5542"
"18.4000","4.5778","90.9038","4.5778","3.0519","21.6438"
"18.4800","4.5975","91.2400","4.5975","3.0650","21.7238"
"18.5600","4.6175","91.5962","4.6175","3.0783","21.8086"
"18.6400","4.6379","91.9526","4.6379","3.0919","21.8935"
"18.7200","4.6581","92.3068","4.6581","3.1054","21.9778"
"18.8000","4.6782","92.6460","4.6782","3.1188","22.0586"
"18.8800","4.6985","92.9915","4.6985","3.1324","22.1408"
"18.9600","4.7168","93.3157","4.7168","3.1446","22.2180"
"19.0400","4.7375","93.6712","4.7375","3.1583","22.3027"
"19.1200","4.7569","94.0029","4.7569","3.1713","22.3816"
"19.2000","4.7782","94.3781","4.7782","3.1855","22.4710"
"19.2800","4.7994","94.7363","4.7994","3.1996","22.5563"
"19.3600","4.8183","95.0386","4.8183","3.2122","22.6282"
"19.4400","4.8384","95.3833","4.8384","3.2256","22.7103"
"19.5200","4.8580","95.7167","4.8580","3.2386","22.7897"
"19.6000","4.8773","96.0489","4.8773","3.2515","22.8688"
"19.6800","4.8977","96.4154","4.8977","3.2651","22.9560"
"19.7600","4.9170","96.7288","4.9170","3.2780","23.0307"
"19.8400","4.9378","97.0899","4.9378","3.2919","23.1167"
"19.9200","4.9586","97.4333","4.9586","3.3057","23.1984"
"20.0000","4.9779","97.7558","4.9779","3.3186","23.2752"
"20.0800","4.9982","98.0985","4.9982","3.3321","23.3568"
"20.1600","5.0173","98.4103","5.0173","3.3448","23.4310"
"20.2400","5.0375","98.7555","5.0375","3.3583","23.5132"
"20.3200","5.0577","99.0933","5.0577","3.3718","23.5936"
"20.4000","5.0774","99.4180","5.0774","3.3850","23.6709"
"20.4800","5.0981","99.7668","5.0981","3.3988","23.7540"
"20.5600","5.1191","100.0966","5.1191","3.4127","23.8325"
"20.6400","5.1383","100.4212","5.1383","3.4255","23.9098"
"20.7200","5.1580","100.7295","5.1580","3.4387","23.9832"
"20.8000","5.1762","101.0221","5.1762","3.4508","24.0529"
"20.8800","5.1979","101.3976","5.1979","3.4653","24.1423"
"20.9600","5.2184","101.7357","5.2184","3.4790","24.2228"
"21.0400","5.2372","102.0413","5.2372","3.4914","24.2955"
"21.1200","5.2575","102.3804","5.2575","3.5050","24.3763"
"21.2000","5.2786","102.7377","5.2786","3.5190","24.4614"
"21.2800","5.2986","103.0620","5.2986","3.5324","24.5386"
"21.3600","5.3183","103.3840","5.3183","3.5455","24.6152"
"21.4400","5.3367","103.6672","5.3367","3.5578","24.6827"
"21.5200","5.3572","104.0107","5.3572","3.5715","24.7645"
"21.6000","5.3776","104.3450","5.3776","3.5851","24.8440"
"21.6800","5.3977","104.6841","5.3977","3.5985","24.9248"
"21.7600","5.4187","105.0248","5.4187","3.6125","25.0059"
"21.8400","5.4381","105.3359","5.4381","3.6254","25.0800"
"21.9200","5.4587","105.6780","5.4587","3.6392","25.1614"
"22.0000","5.4782","105.9776","5.4782","3.6521","25.2328"
"22.0800","5.4974","106.3035","5.4974","3.6649","25.3104"
"22.1600","5.5181","106.6491","5.5181","3.6787","25.3927"
"22.2400","5.5373","106.9438","5.5373","3.6915","25.4628"
"22.3200","5.5568","107.2711","5.5568","3.7045","25.5407"
"22.4000","5.5781","107.6197","5.5781","3.7187","25.6237"
"22.4800","5.5976","107.9379","5.5976","3.7317","25.6995"
"22.5600","5.6188","108.2950","5.6188","3.7459","25.7845"
"22.6400","5.6383","108.6173","5.6383","3.7589","25.8613"
"22.7200","5.6573","108.9194","5.6573","3.7716","25.9332"
"22.8000","5.6772","109.2424","5.6772","3.7848","26.0101"
"22.8800","5.6974","109.5682","5.6974","3.7983","26.0877"
"22.9600","5.7180","109.9051","5.7180","3.8120","26.1679"
"23.0400","5.7391","110.2348","5.7391","3.8261","26.2464"
"23.1200","5.7576","110.5185","5.7576","3.8384","26.3139"
"23.2000","5.7783","110.8567","5.7783","3.8522","26.3945"
"23.2800","5.7980","111.1816","5.7980","3.8654","26.4718"
"23.3600","5.8179","111.4943","5.8179","3.8786","26.5463"
"23.4400","5.8379","111.8131","5.8379","3.8919","26.6222"
"23.5200","5.8565","112.1073","5.8565","3.9044","26.6922"
"23.6000","5.8778","112.4696","5.8778","3.9186","26.7785"
"23.6800","5.8990","112.8139","5.8990","3.9326","26.8605"
"23.7600","5.9185","113.1326","5.9185","3.9457","26.9363"
"23.8400","5.9377","113.4310","5.9377","3.9585","27.0074"
"23.9200","5.9567","113.7131","5.9567","3.9712","27.0745"
"24.0000","5.9774","114.0691","5.9774","3.9849","27.1593"
"24.0800","5.9986","114.4153","5.9986","3.9990","27.2417"
"24.1600","6.0174","114.7097","6.0174","4.0116","27.3118"
"24.2400","6.0384","115.0560","6.0384","4.0256","27.3943"
"24.3200","6.0582","115.3709","6.0582","4.0388","27.4693"
"24.4000","6.0790","115.7124","6.0790","4.0527","27.5506"
"24.4800","6.0982","116.0174","6.0982","4.0655","27.6232"
"24.5600","6.1179","116.3159","6.1179","4.0786","27.6943"
"24.6400","6.1380","116.6304","6.1380","4.0920","27.7691"
"24.7200","6.1576","116.9376","6.1576","4.1051","27.8423"
"24.8000","6.1762","117.2375","6.1762","4.1175","27.9137"
"24.8800","6.1981","117.6047","6.1981","4.1321","28.0011"
"24.9600","6.2181","117.9133","6.2181","4.1454","28.0746"
"25.0400","6.2385","118.2357","6.2385","4.1590","28.1514"
"25.1200","6.2578","118.5298","6.2578","4.1718","28.2214"
"25.2000","6.2766","118.8313","6.2766","4.1844","28.2932"
"25.2800","6.2978","119.1759","6.2978","4.1985","28.3752"
"25.3600","6.3174","119.4847","6.3174","4.2116","28.4487"
"25.4400","6.3377","119.8064","6.3377","4.2251","28.5253"
"25.5200","6.3584","120.1400","6.3584","4.2390","28.6048"
"25.6000","6.3782","120.4371","6.3782","4.2521","28.6755"
"25.6800","6.3984","120.7703","6.3984","4.2656","28.7548"
"25.7600","6.4186","121.0856","6.4186","4.2790","28.8299"
"25.8400","6.4373","121.3760","6.4373","4.2916","28.8990"
"25.9200","6.4578","121.6960","6.4578","4.3052","28.9752"
"26.0000","6.4768","121.9833","6.4768","4.3179","29.0436"
"26.0800","6.4979","122.3166","6.4979","4.3319","29.1230"
"26.1600","6.5190","122.6570","6.5190","4.3460","29.2040"
"26.2400","6.5382","122.9431","6.5382","4.3588","29.2722"
"26.3200","6.5578","123.2563","6.5578","4.3718","29.3467"
"26.4000","6.5777","123.5728","6.5777","4.3851","29.4221"
"26.4800","6.5974","123.8798","6.5974","4.3983","29.4952"
"26.5600","6.6184","124.2257","6.6184","4.4123","29.5776"
"26.6400","6.6368","124.4869","6.6368","4.4246","29.6397"
"26.7200","6.6582","124.8390","6.6582","4.4388","29.7236"
"26.8000","6.6788","125.1629","6.6788","4.4525","29.8007"
"26.8800","6.6986","125.4765","6.6986","4.4657","29.8754"
"26.9600","6.7182","125.7883","6.7182","4.4788","29.9496"
"27.0400","6.7377","126.0787","6.7377","4.4918","30.0187"
"27.1200","6.7576","126.3938","6.7576","4.5051","30.0937"
"27.2000","6.7777","126.7066","6.7777","4.5185","30.1682"
"27.2800","6.7968","127.0063","6.7968","4.5312","30.2396"
"27.3600","6.8180","127.3511","6.8180","4.5453","30.3217"
"27.4400","6.8383","127.6539","6.8383","4.5589","30.3938"
"27.5200","6.8578","127.9597","6.8578","4.5719","30.4666"
"27.6000","6.8778","128.2683","6.8778","4.5852","30.5401"
"27.6800","6.8974","128.5674","6.8974","4.5983","30.6113"
"27.7600","6.9181","128.8918","6.9181","4.6121","30.6885"
"27.8400","6.9377","129.1828","6.9377","4.6251","30.7578"
"27.9200","6.9570","129.4906","6.9570","4.6380","30.8311"
"28.0000","6.9784","129.8247","6.9784","4.6522","30.9107"
"28.0800","6.9988","130.1322","6.9988","4.6659","30.9838"
"28.1600","7.0182","130.4159","7.0182","4.6788","31.0514"
"28.2400","7.0379","130.7001","7.0379","4.6919","31.1191"
"28.3200","7.0570","130.9747","7.0570","4.7047","31.1845"
"28.4000","7.0781","131.2913","7.0781","4.7187","31.2598"
"28.4800","7.0977","131.5781","7.0977","4.7318","31.3281"
"28.5600","7.1174","131.8787","7.1174","4.7450","31.3997"
"28.6400","7.1378","132.1827","7.1378","4.7585","31.4721"
"28.7200","7.1580","132.4735","7.1580","4.7720","31.5413"
"28.8000","7.1783","132.7762","7.1783","4.7855","31.6134"
"28.8800","7.1989","133.0892","7.1989","4.7993","31.6879"
"28.9600","7.2169","133.3431","7.2169","4.8113","31.7484"
"29.0400","7.2373","133.6594","7.2373","4.8249","31.8237"
"29.1200","7.2570","133.9453","7.2570","4.8380","31.8917"
"29.2000","7.2782","134.2831","7.2782","4.8521","31.9722"
"29.2800","7.2995","134.6107","7.2995","4.8663","32.0502"
"29.3600","7.3187","134.8912","7.3187","4.8791","32.1170"
"29.4400","7.3382","135.1760","7.3382","4.8921","32.1848"
"29.5200","7.3579","135.4641","7.3579","4.9052","32.2534"
"29.6000","7.3772","135.7489","7.3772","4.9182","32.3212"
"29.6800","7.3977","136.0688","7.3977","4.9318","32.3973"
"29.7600","7.4171","136.3434","7.4171","4.9447","32.4627"
"29.8400","7.4377","136.6631","7.4377","4.9585","32.5388"
"29.9200","7.4588","136.9813","7.4588","4.9725","32.6146"
"30.0000","7.4781","137.2728","7.4781","4.9854","32.6840"
"30.0800","7.4983","137.5794","7.4983","4.9989","32.7570"
"30.1600","7.5175","137.8568","7.5175","5.0117","32.8230"
"30.2400","7.5375","138.1557","7.5375","5.0250","32.8942"
"30.3200","7.5577","138.4514","7.5577","5.0385","32.9646"
"30.4000","7.5772","138.7475","7.5772","5.0515","33.0351"
"30.4800","7.5978","139.0534","7.5978","5.0652","33.1080"
"30.5600","7.6190","139.3792","7.6190","5.0793","33.1855"
"30.6400","7.6387","139.6855","7.6387","5.0925","33.2585"
"30.7200","7.6581","139.9745","7.6581","5.1054","33.3273"
"30.8000","7.6772","140.2482","7.6772","5.1182","33.3924"
"30.8800","7.6980","140.5690","7.6980","5.1320","33.4688"
"30.9600","7.7182","140.8694","7.7182","5.1454","33.5403"
"31.0400","7.7370","141.1431","7.7370","5.1580","33.6055"
"31.1200","7.7574","141.4641","7.7574","5.1716","33.6819"
"31.2000","7.7783","141.7795","7.7783","5.1855","33.7570"
"31.2800","7.7986","142.0903","7.7986","5.1991","33.8310"
"31.3600","7.8189","142.3842","7.8189","5.2126","33.9010"
"31.4400","7.8368","142.6330","7.8368","5.2246","33.9602"
"31.5200","7.8572","142.9438","7.8572","5.2381","34.0342"
"31.6000","7.8776","143.2432","7.8776","5.2517","34.1055"
"31.6800","7.8977","143.5550","7.8977","5.2651","34.1798"
"31.7600","7.9189","143.8725","7.9189","5.2793","34.2554"
"31.8400","7.9385","144.1521","7.9385","5.2923","34.3219"
"31.9200","7.9587","144.4482","7.9587","5.3058","34.3924"
"32.0000","7.9783","144.7433","7.9783","5.3189","34.4627"
"32.0800","7.9976","145.0276","7.9976","5.3317","34.5304"
"32.1600","8.0177","145.3315","8.0177","5.3451","34.6027"
"32.2400","8.0372","145.6143","8.0372","5.3581","34.6701"
"32.3200","8.0565","145.9026","8.0565","5.3710","34.7387"
"32.4000","8.0781","146.2391","8.0781","5.3854","34.8188"
"32.4800","8.0979","146.5357","8.0979","5.3986","34.8895"
"32.5600","8.1188","146.8374","8.1188","5.4126","34.9613"
"32.6400","8.1378","147.1094","8.1378","5.4252","35.0261"
"32.7200","8.1571","147.3936","8.1571","5.4381","35.0937"
"32.8000","8.1773","147.7000","8.1773","5.4515","35.1667"
"32.8800","8.1974","147.9992","8.1974","5.4649","35.2379"
"32.9600","8.2180","148.3011","8.2180","5.4787","35.3098"
"33.0400","8.2390","148.6285","8.2390","5.4927","35.3877"
"33.1200","8.2578","148.8990","8.2578","5.5052","35.4521"
"33.2000","8.2780","149.1949","8.2780","5.5187","35.5226"
"33.2800","8.2981","149.4917","8.2981","5.5321","35.5933"
"33.3600","8.3180","149.7954","8.3180","5.5453","35.6656"
"33.4400","8.3377","150.0775","8.3377","5.5585","35.7327"
"33.5200","8.3565","150.3349","8.3565","5.5710","35.7940"
"33.6000","8.3777","150.6686","8.3777","5.5852","35.8735"
"33.6800","8.3991","150.9981","8.3991","5.5994","35.9519"
"33.7600","8.4184","151.2715","8.4184","5.6123","36.0170"
"33.8400","8.4376","151.5490","8.4376","5.6251","36.0831"
"33.9200","8.4570","151.8215","8.4570","5.6380","36.1480"
"34.0000","8.4775","152.1337","8.4775","5.6516","36.2223"
"34.0800","8.4983","152.4356","8.4983","5.6656","36.2942"
"34.1600","8.5171","152.7080","8.5171","5.6781","36.3590"
"34.2400","8.5387","153.0462","8.5387","5.6925","36.4396"
"34.3200","8.5586","153.3291","8.5586","5.7057","36.5069"
"34.4000","8.5785","153.6286","8.5785","5.7190","36.5782"
"34.4800","8.5982","153.9151","8.5982","5.7322","36.6465"
"34.5600","8.6177","154.1877","8.6177","5.7451","36.7113"
"34.6400","8.6379","154.4924","8.6379","5.7586","36.7839"
"34.7200","8.6576","154.7626","8.6576","5.7718","36.8482"
"34.8000","8.6765","155.0400","8.6765","5.7843","36.9143"
"34.8800","8.6979","155.3751","8.6979","5.7986","36.9941"
"34.9600","8.7183","155.6746","8.7183","5.8122","37.0654"
"35.0400","8.7385","155.9575","8.7385","5.8257","37.1327"
"35.1200","8.7578","156.2303","8.7578","5.8385","37.1977"
"35.2000","8.7763","156.4937","8.7763","5.8509","37.2604"
"35.2800","8.7976","156.8150","8.7976","5.8651","37.3369"
"35.3600","8.8179","157.1156","8.8179","5.8786","37.4085"
"35.4400","8.8376","157.4019","8.8376","5.8917","37.4766"
"35.5200","8.8583","157.7183","8.8583","5.9055","37.5520"
"35.6000","8.8782","157.9905","8.8782","5.9188","37.6168"
"35.6800","8.8984","158.2729","8.8984","5.9323","37.6840"
"35.7600","8.9186","158.5650","8.9186","5.9457","37.7536"
"35.8400","8.9371","158.8203","8.9371","5.9580","37.8144"
"35.9200","8.9578","159.1280","8.9578","5.9718","37.8876"
"36.0000","8.9767","159.3895","8.9767","5.9845","37.9499"
"36.0800","8.9981","159.7112","8.9981","5.9988","38.0265"
"36.1600","9.0189","160.0145","9.0189","6.0126","38.0987"
"36.2400","9.0380","160.2668","9.0380","6.0253","38.1588"
"36.3200","9.0575","160.5420","9.0575","6.0383","38.2243"
"36.4000","9.0776","160.8314","9.0776","6.0518","38.2932"
"36.4800","9.0975","161.1222","9.0975","6.0650","38.3624"
"36.5600","9.1182","161.4261","9.1182","6.0788","38.4348"
"36.6400","9.1369","161.6822","9.1369","6.0913","38.4958"
"36.7200","9.1585","162.0020","9.1585","6.1057","38.5719"
"36.8000","9.1789","162.3006","9.1789","6.1193","38.6430"
"36.8800","9.1986","162.5922","9.1986","6.1324","38.7124"
"36.9600","9.2181","162.8525","9.2181","6.1454","38.7744"
"37.0400","9.2376","163.1263","9.2376","6.1584","38.8396"
"37.1200","9.2574","163.4012","9.2574","6.1716","38.9051"
"37.2000","9.2779","163.7030","9.2779","6.1853","38.9769"
"37.2800","9.2966","163.9512","9.2966","6.1977","39.0360"
"37.3600","9.3180","164.2755","9.3180","6.2120","39.1132"
"37.4400","9.3383","164.5575","9.3383","6.2256","39.1803"
"37.5200","9.3579","164.8399","9.3579","6.2386","39.2476"
"37.6000","9.3781","165.1167","9.3781","6.2520","39.3135"
"37.6800","9.3973","165.3851","9.3973","6.2648","39.3774"
"37.7600","9.4180","165.6715","9.4180","6.2787","39.4456"
"37.8400","9.4376","165.9384","9.4376","6.2917","39.5091"
"37.9200","9.4568","166.2001","9.4568","6.3046","39.5714"
"38.0000","9.4781","166.5182","9.4781","6.3188","39.6472"
"38.0800","9.4987","166.8016","9.4987","6.3325","39.7147"
"38.1600","9.5186","167.0694","9.5186","6.3457","39.7784"
"38.2400","9.5384","167.3396","9.5384","6.3589","39.8428"
"38.3200","9.5569","167.5787","9.5569","6.3713","39.8997"
"38.4000","9.5781","167.8767","9.5781","6.3854","39.9706"
"38.4800","9.5975","168.1356","9.5975","6.3983","40.0323"
"38.5600","9.6176","168.4170","9.6176","6.4117","40.0993"
"38.6400","9.6378","168.7038","9.6378","6.4252","40.1676"
"38.7200","9.6582","168.9718","9.6582","6.4388","40.2314"
"38.8000","9.6780","169.2402","9.6780","6.4520","40.2953"
"38.8800","9.6985","169.5344","9.6985","6.4657","40.3653"
"38.9600","9.7171","169.7820","9.7171","6.4781","40.4243"
"39.0400","9.7377","170.0673","9.7377","6.4918","40.4922"
"39.1200","9.7568","170.3058","9.7568","6.5045","40.5490"
"39.2000","9.7780","170.6136","9.7780","6.5187","40.6223"
"39.2800","9.7996","170.9198","9.7996","6.5331","40.6952"
"39.3600","9.8184","171.1572","9.8184","6.5456","40.7517"
"39.4400","9.8381","171.4252","9.8381","6.5587","40.8155"
"39.5200","9.8580","171.6992","9.8580","6.5720","40.8808"
"39.6000","9.8771","171.9551","9.8771","6.5847","40.9417"
"39.6800","9.8974","172.2467","9.8974","6.5983","41.0111"
"39.7600","9.9171","172.4990","9.9171","6.6114","41.0712"
"39.8400","9.9376","172.7874","9.9376","6.6251","41.1399"
"39.9200","9.9587","173.0811","9.9587","6.6392","41.2098"
"40.0000","9.9776","173.3265","9.9776","6.6517","41.2682"
"40.0800","9.9984","173.6310","9.9984","6.6656","41.3407"
"40.1600","10.0174","173.8643","10.0174","6.6782","41.3963"
"40.2400","10.0374","174.1528","10.0374","6.6916","41.4649"
"40.3200","10.0576","174.4280","10.0576","6.7051","41.5305"
"40.4000","10.0775","174.6949","10.0775","6.7183","41.5940"
"40.4800","10.0986","175.0007","10.0986","6.7324","41.6668"
"40.5600","10.1191","175.2730","10.1191","6.7461","41.7317"
"40.6400","10.1378","175.5150","10.1378","6.7585","41.7893"
"40.7200","10.1583","175.7955","10.1583","6.7722","41.8561"
"40.8000","10.1772","176.0303","10.1772","6.7848","41.9120"
"40.8800","10.1981","176.3265","10.1981","6.7987","41.9825"
"40.9600","10.2174","176.5726","10.2174","6.8116","42.0411"
"41.0400","10.2368","176.8369","10.2368","6.8245","42.1040"
"41.1200","10.2576","177.1365","10.2576","6.8384","42.1754"
"41.2000","10.2786","177.4257","10.2786","6.8524","42.2442"
"41.2800","10.2986","177.6994","10.2986","6.8657","42.3094"
"41.3600","10.3187","177.9650","10.3187","6.8791","42.3726"
"41.4400","10.3369","178.1961","10.3369","6.8913","42.4276"
"41.5200","10.3574","178.4749","10.3574","6.9049","42.4940"
"41.6000","10.3778","178.7514","10.3778","6.9185","42.5599"
"41.6800","10.3976","179.0285","10.3976","6.9317","42.6258"
"41.7600","10.4191","179.3420","10.4191","6.9461","42.7005"
"41.8400","10.4383","179.5844","10.4383","6.9589","42.7582"
"41.9200","10.4583","179.8483","10.4583","6.9722","42.8210"
"42.0000","10.4782","180.1175","10.4782","6.9855","42.8851"
"42.0800","10.4976","180.3815","10.4976","6.9984","42.9480"
"42.1600","10.5176","180.6531","10.5176","7.0117","43.0126"
"42.2400","10.5373","180.9169","10.5373","7.0249","43.0755"
"42.3200","10.5570","181.1827","10.5570","7.0380","43.1387"
"42.4000","10.5782","181.4757","10.5782","7.0521","43.2085"
"42.4800","10.5979","181.7414","10.5979","7.0653","43.2718"
"42.5600","10.6191","182.0290","10.6191","7.0794","43.3402"
"42.6400","10.6377","182.2638","10.6377","7.0918","43.3961"
"42.7200","10.6569","182.5163","10.6569","7.1046","43.4563"
"42.8000","10.6772","182.7963","10.6772","7.1181","43.5229"
"42.8800","10.6975","183.0662","10.6975","7.1317","43.5872"
"42.9600","10.7179","183.3344","10.7179","7.1453","43.6510"
"43.0400","10.7390","183.6187","10.7390","7.1593","43.7187"
"43.1200","10.7580","183.8629","10.7580","7.1720","43.7769"
"43.2000","10.7783","184.1369","10.7783","7.1856","43.8421"
"43.2800","10.7975","184.3785","10.7975","7.1983","43.8996"
"43.3600","10.8180","184.6688","10.8180","7.2120","43.9688"
"43.4400","10.8381","184.9310","10.8381","7.2254","44.0312"
"43.5200","10.8566","185.1539","10.8566","7.2377","44.0843"
"43.6000","10.8778","185.4546","10.8778","7.2519","44.1559"
"43.6800","10.8987","185.7333","10.8987","7.2658","44.2222"
"43.7600","10.9187","186.0001","10.9187","7.2792","44.2857"
"43.8400","10.9379","186.2562","10.9379","7.2920","44.3467"
"43.9200","10.9566","186.4871","10.9566","7.3044","44.4017"
"44.0000","10.9768","186.7592","10.9768","7.3179","44.4665"
"44.0800","10.9987","187.0700","10.9987","7.3325","44.5405"
"44.1600","11.0174","187.2989","11.0174","7.3449","44.5950"
"44.2400","11.0384","187.5868","11.0384","7.3589","44.6635"
"44.3200","11.0583","187.8634","11.0583","7.3722","44.7294"
"44.4000","11.0789","188.1236","11.0789","7.3860","44.7913"
"44.4800","11.0982","188.3669","11.0982","7.3988","44.8493"
"44.5600","11.1177","188.6274","11.1177","7.4118","44.9113"
"44.6400","11.1376","188.8866","11.1376","7.4251","44.9730"
"44.7200","11.1581","189.1665","11.1581","7.4388","45.0396"
"44.8000","11.1767","189.4119","11.1767","7.4511","45.0981"
"44.8800","11.1980","189.7056","11.1980","7.4653","45.1680"
"44.9600","11.2180","189.9658","11.2180","7.4786","45.2299"
"45.0400","11.2385","190.2276","11.2385","7.4924","45.2923"
"45.1200","11.2578","190.4681","11.2578","7.5052","45.3495"
"45.2000","11.2768","190.7172","11.2768","7.5178","45.4088"
"45.2800","11.2977","190.9950","11.2977","7.5318","45.4750"
"45.3600","11.3180","191.2659","11.3180","7.5453","45.5395"
"45.4400","11.3375","191.5234","11.3375","7.5583","45.6008"
"45.5200","11.3584","191.8016","11.3584","7.5723","45.6671"
"45.6000","11.3782","192.0555","11.3782","7.5855","45.7275"
"45.6800","11.3986","192.3201","11.3986","7.5991","45.7905"
"45.7600","11.4184","192.5632","11.4184","7.6123","45.8484"
"45.8400","11.4366","192.7896","11.4366","7.6244","45.9023"
"45.9200","11.4578","193.0891","11.4578","7.6386","45.9736"
"46.0000","11.4767","193.3199","11.4767","7.6512","46.0286"
"46.0800","11.4981","193.6198","11.4981","7.6654","46.0999"
"46.1600","11.5190","193.9013","11.5190","7.6794","46.1670"
"46.2400","11.5381","194.1265","11.5381","7.6921","46.2206"
"46.3200","11.5577","194.3770","11.5577","7.7051","46.2802"
"46.4000","11.5777","194.6436","11.5777","7.7185","46.3437"
"46.4800","11.5972","194.8935","11.5972","7.7315","46.4032"
"46.5600","11.6185","195.1827","11.6185","7.7457","46.4721"
"46.6400","11.6368","195.3873","11.6368","7.7579","46.5208"
"46.7200","11.6580","195.6896","11.6580","7.7720","46.5928"
"46.8000","11.6789","195.9566","11.6789","7.7859","46.6563"
"46.8800","11.6988","196.2229","11.6988","7.7992","46.7197"
"46.9600","11.7181","196.4542","11.7181","7.8121","46.7748"
"47.0400","11.7376","196.7012","11.7376","7.8251","46.8336"
"47.1200","11.7576","196.9664","11.7576","7.8384","46.8968"
"47.2000","11.7783","197.2395","11.7783","7.8522","46.9618"
"47.2800","11.7968","197.4514","11.7968","7.8645","47.0122"
"47.3600","11.8176","197.7433","11.8176","7.8784","47.0817"
"47.4400","11.8385","198.0115","11.8385","7.8923","47.1456"
"47.5200","11.8580","198.2718","11.8580","7.9054","47.2076"
"47.6000","11.8781","198.5184","11.8781","7.9187","47.2663"
"47.6800","11.8970","198.7534","11.8970","7.9314","47.3222"
"47.7600","11.9180","199.0349","11.9180","7.9453","47.3893"
"47.8400","11.9378","199.2786","11.9378","7.9586","47.4473"
"47.9200","11.9572","199.5317","11.9572","7.9715","47.5076"
"48.0000","11.9781","199.8132","11.9781","7.9854","47.5746"
"48.0800","11.9990","200.0822","11.9990","7.9993","47.6386"
"48.1600","12.0181","200.3143","12.0181","8.0120","47.6939"
"48.2400","12.0382","200.5595","12.0382","8.0255","47.7523"
"48.3200","12.0570","200.7910","12.0570","8.0380","47.8074"
"48.4000","12.0780","201.0799","12.0780","8.0520","47.8762"
"48.4800","12.0977","201.3270","12.0977","8.0651","47.9350"
"48.5600","12.1176","201.5817","12.1176","8.0784","47.9956"
"48.6400","12.1379","201.8423","12.1379","8.0919","48.0577"
"48.7200","12.1583","202.0969","12.1583","8.1055","48.1183"
"48.8000","12.1780","202.3329","12.1780","8.1187","48.1745"
"48.8800","12.1984","202.5976","12.1984","8.1322","48.2375"
"48.9600","12.2170","202.8204","12.2170","8.1447","48.2906"
"49.0400","12.2375","203.0829","12.2375","8.1583","48.3531"
"49.1200","12.2569","203.3137","12.2569","8.1713","48.4080"
"49.2000","12.2781","203.6016","12.2781","8.1854","48.4766"
"49.2800","12.2992","203.8718","12.2992","8.1995","48.5409"
"49.3600","12.3186","204.1074","12.3186","8.2124","48.5970"
"49.4400","12.3384","204.3442","12.3384","8.2256","48.6534"
"49.5200","12.3579","204.5862","12.3579","8.2386","48.7110"
"49.6000","12.3774","204.8190","12.3774","8.2516","48.7664"
"49.6800","12.3975","205.0850","12.3975","8.2650","48.8298"
"49.7600","12.4170","205.3058","12.4170","8.2780","48.8823"
"49.8400","12.4376","205.5706","12.4376","8.2917","48.9454"
"49.9200","12.4589","205.8440","12.4589","8.3060","49.0105"
"50.0000","12.4779","206.0760","12.4779","8.3186","49.0657"
"50.0800","12.4981","206.3271","12.4981","8.3321","49.1255"
"50.1600","12.5172","206.5416","12.5172","8.3448","49.1766"
"50.2400","12.5377","206.8043","12.5377","8.3585","49.2391"
"50.3200","12.5574","207.0335","12.5574","8.3716","49.2937"
"50.4000","12.5771","207.2726","12.5771","8.3847","49.3506"
"50.4800","12.5982","207.5595","12.5982","8.3988","49.4189"
"50.5600","12.6196","207.8315","12.6196","8.4130","49.4837"
"50.6400","12.6381","208.0356","12.6381","8.4254","49.5323"
"50.7200","12.6580","208.2865","12.6580","8.4387","49.5920"
"50.8000","12.6771","208.4964","12.6771","8.4514","49.6420"
"50.8800","12.6986","208.7789","12.6986","8.4657","49.7093"
"50.9600","12.7180","209.0056","12.7180","8.4787","49.7632"
"51.0400","12.7369","209.2183","12.7369","8.4912","49.8139"
"51.1200","12.7575","209.4865","12.7575","8.5050","49.8777"
"51.2000","12.7782","209.7348","12.7782","8.5188","49.9369"
"51.2800","12.7988","210.0057","12.7988","8.5325","50.0013"
"51.3600","12.8186","210.2477","12.8186","8.5457","50.0590"
"51.4400","12.8368","210.4311","12.8368","8.5579","50.1026"
"51.5200","12.8568","210.6748","12.8568","8.5712","50.1607"
"51.6000","12.8777","210.9366","12.8777","8.5852","50.2230"
"51.6800","12.8977","211.1814","12.8977","8.5985","50.2813"
"51.7600","12.9191","211.4549","12.9191","8.6127","50.3464"
"51.8400","12.9385","211.6704","12.9385","8.6256","50.3977"
"51.9200","12.9586","211.9081","12.9586","8.6391","50.4543"
"52.0000","12.9782","212.1387","12.9782","8.6521","50.5092"
"52.0800","12.9978","212.3681","12.9978","8.6652","50.5638"
"52.1600","13.0180","212.6234","13.0180","8.6787","50.6246"
"52.2400","13.0373","212.8361","13.0373","8.6915","50.6753"
"52.3200","13.0571","213.0750","13.0571","8.7047","50.7321"
"52.4000","13.0784","213.3442","13.0784","8.7189","50.7962"
"52.4800","13.0979","213.5561","13.0979","8.7319","50.8467"
"52.5600","13.1188","213.8113","13.1188","8.7459","50.9075"
"52.6400","13.1378","214.0162","13.1378","8.7586","50.9562"
"52.7200","13.1570","214.2295","13.1570","8.7714","51.0070"
"52.8000","13.1771","214.4713","13.1771","8.7847","51.0646"
"52.8800","13.1976","214.7129","13.1976","8.7984","51.1221"
"52.9600","13.2179","214.9458","13.2179","8.8120","51.1776"
"53.0400","13.2392","215.2074","13.2392","8.8261","51.2398"
"53.1200","13.2580","215.4050","13.2580","8.8387","51.2869"
"53.2000","13.2784","215.6455","13.2784","8.8523","51.3442"
"53.2800","13.2983","215.8685","13.2983","8.8655","51.3973"
"53.3600","13.3178","216.0818","13.3178","8.8785","51.4481"
"53.4400","13.3376","216.3028","13.3376","8.8917","51.5007"
"53.5200","13.3563","216.5040","13.3563","8.9042","51.5486"
"53.6000","13.3779","216.7654","13.3779","8.9186","51.6108"
"53.6800","13.3986","217.0074","13.3986","8.9324","51.6684"
"53.7600","13.4179","217.2157","13.4179","8.9453","51.7180"
"53.8400","13.4380","217.4337","13.4380","8.9587","51.7699"
"53.9200","13.4573","217.6322","13.4573","8.9715","51.8172"
"54.0000","13.4772","217.8707","13.4772","8.9848","51.8740"
"54.0800","13.4985","218.1115","13.4985","8.9990","51.9313"
"54.1600","13.5174","218.3218","13.5174","9.0116","51.9814"
"54.2400","13.5383","218.5672","13.5383","9.0256","52.0398"
"54.3200","13.5582","218.7747","13.5582","9.0388","52.0892"
"54.4000","13.5785","219.0116","13.5785","9.0524","52.1456"
"54.4800","13.5983","219.2293","13.5983","9.0655","52.1975"
"54.5600","13.6176","219.4233","13.6176","9.0784","52.2436"
"54.6400","13.6376","219.6453","13.6376","9.0917","52.2965"
"54.7200","13.6576","219.8631","13.6576","9.1051","52.3484"
"54.8000","13.6765","220.0571","13.6765","9.1177","52.3945"
"54.8800","13.6980","220.3264","13.6980","9.1320","52.4587"
"54.9600","13.7182","220.5460","13.7182","9.1455","52.5110"
"55.0400","13.7385","220.7731","13.7385","9.1590","52.5650"
"55.1200","13.7579","220.9704","13.7579","9.1719","52.6120"
"55.2000","13.7771","221.1649","13.7771","9.1847","52.6583"
"55.2800","13.7974","221.3933","13.7974","9.1983","52.7127"
"55.3600","13.8180","221.6279","13.8180","9.2120","52.7685"
"55.4400","13.8378","221.8473","13.8378","9.2252","52.8208"
"55.5200","13.8585","222.0847","13.8585","9.2390","52.8773"
"55.6000","13.8782","222.2867","13.8782","9.2521","52.9254"
"55.6800","13.8989","222.5247","13.8989","9.2659","52.9821"
"55.7600","13.9185","222.7321","13.9185","9.2790","53.0315"
"55.8400","13.9372","222.9218","13.9372","9.2915","53.0766"
"55.9200","13.9577","223.1671","13.9577","9.3052","53.1350"
"56.0000","13.9768","223.3516","13.9768","9.3179","53.1790"
"56.0800","13.9976","223.5749","13.9976","9.3318","53.2321"
"56.1600","14.0186","223.8150","14.0186","9.3458","53.2893"
"56.2400","14.0382","224.0164","14.0382","9.3588","53.3372"
"56.3200","14.0579","224.2071","14.0579","9.3719","53.3826"
"56.4000","14.0777","224.4215","14.0777","9.3851","53.4337"
"56.4800","14.0971","224.6283","14.0971","9.3981","53.4829"
"56.5600","14.1179","224.8441","14.1179","9.4119","53.5343"
"56.6400","14.1369","225.0416","14.1369","9.4246","53.5813"
"56.7200","14.1583","225.2796","14.1583","9.4388","53.6380"
"56.8000","14.1787","225.5018","14.1787","9.4524","53.6909"
"56.8800","14.1986","225.7150","14.1986","9.4657","53.7417"
"56.9600","14.2183","225.9247","14.2183","9.4789","53.7916"
"57.0400","14.2377","226.1098","14.2377","9.4918","53.8357"
"57.1200","14.2575","226.3123","14.2575","9.5050","53.8839"
"57.2000","14.2779","226.5208","14.2779","9.5186","53.9335"
"57.2800","14.2966","226.6999","14.2966","9.5311","53.9762"
"57.3600","14.3179","226.9503","14.3179","9.5453","54.0358"
"57.4400","14.3384","227.1631","14.3384","9.5589","54.0864"
"57.5200","14.3578","227.3630","14.3578","9.5719","54.1341"
"57.6000","14.3781","227.5782","14.3781","9.5854","54.1853"
"57.6800","14.3974","227.7605","14.3974","9.5983","54.2287"
"57.7600","14.4181","227.9733","14.4181","9.6121","54.2794"
"57.8400","14.4379","228.1849","14.4379","9.6252","54.3297"
"57.9200","14.4573","228.3716","14.4573","9.6382","54.3742"
"58.0000","14.4780","228.6033","14.4780","9.6520","54.4294"
"58.0800","14.4986","228.8202","14.4986","9.6657","54.4810"
"58.1600","14.5183","229.0155","14.5183","9.6789","54.5275"
"58.2400","14.5383","229.2093","14.5383","9.6922","54.5736"
"58.3200","14.5570","229.3676","14.5570","9.7047","54.6113"
"58.4000","14.5777","229.5920","14.5777","9.7185","54.6648"
"58.4800","14.5976","229.7919","14.5976","9.7317","54.7124"
"58.5600","14.6174","229.9947","14.6174","9.7449","54.7606"
"58.6400","14.6373","230.1952","14.6373","9.7582","54.8084"
"58.7200","14.6583","230.4111","14.6583","9.7722","54.8598"
"58.8000","14.6784","230.6083","14.6784","9.7856","54.9067"
"58.8800","14.6986","230.8021","14.6986","9.7990","54.9529"
"58.9600","14.7170","230.9614","14.7170","9.8114","54.9908"
"59.0400","14.7375","231.1705","14.7375","9.8250","55.0406"
"59.1200","14.7571","231.3524","14.7571","9.8381","55.0839"
"59.2000","14.7780","231.5580","14.7780","9.8520","55.1329"
"59.2800","14.7994","231.7832","14.7994","9.8662","55.1865"
"59.3600","14.8187","231.9498","14.8187","9.8791","55.2262"
"59.4400","14.8380","232.1167","14.8380","9.8920","55.2659"
"59.5200","14.8577","232.3058","14.8577","9.9051","55.3109"
"59.6000","14.8772","232.4844","14.8772","9.9181","55.3534"
"59.6800","14.8976","232.6931","14.8976","9.9317","55.4031"
"59.7600","14.9170","232.8534","14.9170","9.9447","55.4413"
"59.8400","14.9377","233.0575","14.9377","9.9585","55.4899"
"59.9200","14.9588","233.2614","14.9588","9.9726","55.5384"
"60.0000","14.9778","233.4282","14.9778","9.9852","55.5781"
"60.0800","14.9982","233.6173","14.9982","9.9988","55.6232"
"60.0880","15.0001","233.6379","15.0001","10.0001","55.6281"