File: data/instron_tests/metamaterials/250416/250416_1310_NSC_m1.is_comp_Exports/240416_1310_NSC_m1_3_1.csv
Results Table 1
,Compresson Axis,H*,V*,Height,Thickness,Width,Area,Fixture separation,Specimen label
,,,,(mm),(mm),(mm),(mm^2),(mm),
"3","Y","","","150.00","28.00","150.00","4200.00","150.00","1310_NSC_m1"

Results Table 2
,Modulus (Segment 0 % - 2.5 %),Compresson Axis
,(kPa),
"3","752.02","Y"

Time,Displacement,Force,Compressive displacement,Compressive strain (Displacement),Compressive stress
(s),(mm),(N),(mm),(%),(kPa)
"0.0000","0.0000","-11.2404","0.0000","0.0000","-2.6763"
"0.0800","0.0012","-11.1816","0.0012","0.0008","-2.6623"
"0.1600","0.0174","-10.6655","0.0174","0.0116","-2.5394"
"0.2400","0.0382","-10.0554","0.0382","0.0254","-2.3941"
"0.3200","0.0583","-9.4954","0.0583","0.0389","-2.2608"
"0.4000","0.0770","-8.9831","0.0770","0.0514","-2.1388"
"0.4800","0.0979","-8.4212","0.0979","0.0653","-2.0051"
"0.5600","0.1184","-7.8724","0.1184","0.0789","-1.8744"
"0.6400","0.1381","-7.3494","0.1381","0.0920","-1.7499"
"0.7200","0.1576","-6.8579","0.1576","0.1051","-1.6328"
"0.8000","0.1770","-6.3964","0.1770","0.1180","-1.5229"
"0.8800","0.1974","-5.8766","0.1974","0.1316","-1.3992"
"0.9600","0.2179","-5.3556","0.2179","0.1453","-1.2752"
"1.0400","0.2362","-4.9023","0.2362","0.1574","-1.1672"
"1.1200","0.2574","-4.3634","0.2574","0.1716","-1.0389"
"1.2000","0.2779","-3.8530","0.2779","0.1852","-0.9174"
"1.2800","0.2983","-3.3544","0.2983","0.1989","-0.7987"
"1.3600","0.3179","-2.8745","0.3179","0.2120","-0.6844"
"1.4400","0.3365","-2.4292","0.3365","0.2243","-0.5784"
"1.5200","0.3568","-1.9297","0.3568","0.2379","-0.4595"
"1.6000","0.3774","-1.4354","0.3774","0.2516","-0.3418"
"1.6800","0.3973","-0.9439","0.3973","0.2649","-0.2247"
"1.7600","0.4185","-0.4223","0.4185","0.2790","-0.1005"
"1.8400","0.4381","0.0404","0.4381","0.2921","0.0096"
"1.9200","0.4578","0.5000","0.4578","0.3052","0.1190"
"2.0000","0.4780","0.9777","0.4780","0.3187","0.2328"
"2.0800","0.4969","1.4332","0.4969","0.3313","0.3412"
"2.1600","0.5176","1.9230","0.5176","0.3451","0.4578"
"2.2400","0.5368","2.3763","0.5368","0.3579","0.5658"
"2.3200","0.5564","2.8515","0.5564","0.3709","0.6789"
"2.4000","0.5775","3.3455","0.5775","0.3850","0.7966"
"2.4800","0.5976","3.8049","0.5976","0.3984","0.9059"
"2.5600","0.6181","4.2832","0.6181","0.4121","1.0198"
"2.6400","0.6377","4.7305","0.6377","0.4251","1.1263"
"2.7200","0.6566","5.1716","0.6566","0.4377","1.2313"
"2.8000","0.6771","5.6537","0.6771","0.4514","1.3461"
"2.8800","0.6972","6.1157","0.6972","0.4648","1.4561"
"2.9600","0.7179","6.6005","0.7179","0.4786","1.5715"
"3.0400","0.7389","7.0833","0.7389","0.4926","1.6865"
"3.1200","0.7576","7.5048","0.7576","0.5050","1.7869"
"3.2000","0.7779","7.9813","0.7779","0.5186","1.9003"
"3.2800","0.7979","8.4222","0.7979","0.5320","2.0053"
"3.3600","0.8173","8.8759","0.8173","0.5449","2.1133"
"3.4400","0.8370","9.3328","0.8370","0.5580","2.2221"
"3.5200","0.8561","9.7560","0.8561","0.5707","2.3228"
"3.6000","0.8774","10.2459","0.8774","0.5849","2.4395"
"3.6800","0.8985","10.7226","0.8985","0.5990","2.5530"
"3.7600","0.9181","11.1736","0.9181","0.6121","2.6604"
"3.8400","0.9376","11.6084","0.9376","0.6250","2.7639"
"3.9200","0.9560","12.0105","0.9560","0.6374","2.8596"
"4.0000","0.9766","12.4893","0.9766","0.6511","2.9736"
"4.0800","0.9982","12.9703","0.9982","0.6655","3.0882"
"4.1600","1.0171","13.3855","1.0171","0.6780","3.1870"
"4.2400","1.0379","13.8542","1.0379","0.6919","3.2986"
"4.3200","1.0582","14.3094","1.0582","0.7054","3.4070"
"4.4000","1.0780","14.7508","1.0780","0.7187","3.5121"
"4.4800","1.0978","15.1917","1.0978","0.7319","3.6171"
"4.5600","1.1170","15.6040","1.1170","0.7447","3.7152"
"4.6400","1.1374","16.0529","1.1374","0.7583","3.8221"
"4.7200","1.1573","16.4956","1.1573","0.7715","3.9275"
"4.8000","1.1760","16.8943","1.1760","0.7840","4.0225"
"4.8800","1.1976","17.3927","1.1976","0.7984","4.1411"
"4.9600","1.2183","17.8312","1.2183","0.8122","4.2455"
"5.0400","1.2379","18.2543","1.2379","0.8253","4.3463"
"5.1200","1.2575","18.6854","1.2575","0.8383","4.4489"
"5.2000","1.2764","19.0962","1.2764","0.8509","4.5467"
"5.2800","1.2975","19.5519","1.2975","0.8650","4.6552"
"5.3600","1.3177","20.0010","1.3177","0.8784","4.7621"
"5.4400","1.3376","20.4331","1.3376","0.8917","4.8650"
"5.5200","1.3580","20.8826","1.3580","0.9053","4.9720"
"5.6000","1.3779","21.3109","1.3779","0.9186","5.0740"
"5.6800","1.3985","21.7492","1.3985","0.9323","5.1784"
"5.7600","1.4182","22.1712","1.4182","0.9455","5.2789"
"5.8400","1.4368","22.5768","1.4368","0.9578","5.3754"
"5.9200","1.4572","23.0110","1.4572","0.9715","5.4788"
"6.0000","1.4766","23.4236","1.4766","0.9844","5.5770"
"6.0800","1.4975","23.8876","1.4975","0.9984","5.6875"
"6.1600","1.5185","24.3406","1.5185","1.0123","5.7954"
"6.2400","1.5377","24.7360","1.5377","1.0251","5.8895"
"6.3200","1.5571","25.1426","1.5571","1.0380","5.9863"
"6.4000","1.5773","25.5780","1.5773","1.0515","6.0900"
"6.4800","1.5969","26.0020","1.5969","1.0646","6.1909"
"6.5600","1.6179","26.4592","1.6179","1.0786","6.2998"
"6.6400","1.6364","26.8369","1.6364","1.0910","6.3897"
"6.7200","1.6576","27.2921","1.6576","1.1051","6.4981"
"6.8000","1.6784","27.7298","1.6784","1.1189","6.6023"
"6.8800","1.6982","28.1580","1.6982","1.1322","6.7043"
"6.9600","1.7177","28.5648","1.7177","1.1452","6.8011"
"7.0400","1.7371","28.9655","1.7371","1.1581","6.8966"
"7.1200","1.7567","29.3736","1.7567","1.1712","6.9937"
"7.2000","1.7782","29.8285","1.7782","1.1855","7.1020"
"7.2800","1.7968","30.2165","1.7968","1.1979","7.1944"
"7.3600","1.8173","30.6491","1.8173","1.2115","7.2974"
"7.4400","1.8380","31.0916","1.8380","1.2254","7.4028"
"7.5200","1.8577","31.5031","1.8577","1.2385","7.5007"
"7.6000","1.8777","31.9221","1.8777","1.2518","7.6005"
"7.6800","1.8967","32.3149","1.8967","1.2645","7.6940"
"7.7600","1.9175","32.7472","1.9175","1.2784","7.7969"
"7.8400","1.9376","33.1569","1.9376","1.2917","7.8945"
"7.9200","1.9568","33.5681","1.9568","1.3045","7.9924"
"8.0000","1.9778","34.0168","1.9778","1.3185","8.0992"
"8.0800","1.9983","34.4392","1.9983","1.3322","8.1998"
"8.1600","2.0181","34.8441","2.0181","1.3454","8.2962"
"8.2400","2.0378","35.2520","2.0378","1.3586","8.3933"
"8.3200","2.0564","35.6291","2.0564","1.3709","8.4831"
"8.4000","2.0776","36.0840","2.0776","1.3851","8.5914"
"8.4800","2.0973","36.4818","2.0973","1.3982","8.6861"
"8.5600","2.1169","36.8858","2.1169","1.4113","8.7823"
"8.6400","2.1374","37.3111","2.1374","1.4249","8.8836"
"8.7200","2.1578","37.7259","2.1578","1.4385","8.9824"
"8.8000","2.1778","38.1327","2.1778","1.4519","9.0792"
"8.8800","2.1981","38.5571","2.1981","1.4654","9.1803"
"8.9600","2.2167","38.9239","2.2167","1.4778","9.2676"
"9.0400","2.2374","39.3643","2.2374","1.4916","9.3725"
"9.1200","2.2570","39.7583","2.2570","1.5046","9.4663"
"9.2000","2.2774","40.1694","2.2774","1.5183","9.5641"
"9.2800","2.2988","40.6183","2.2988","1.5325","9.6710"
"9.3600","2.3182","41.0058","2.3182","1.5455","9.7633"
"9.4400","2.3381","41.4047","2.3381","1.5587","9.8583"
"9.5200","2.3577","41.8076","2.3577","1.5718","9.9542"
"9.6000","2.3766","42.1798","2.3766","1.5844","10.0428"
"9.6800","2.3967","42.5965","2.3967","1.5978","10.1420"
"9.7600","2.4166","42.9810","2.4166","1.6111","10.2336"
"9.8400","2.4375","43.4190","2.4375","1.6250","10.3378"
"9.9200","2.4586","43.8327","2.4586","1.6391","10.4364"
"10.0000","2.4774","44.2068","2.4774","1.6516","10.5254"
"10.0800","2.4978","44.6246","2.4978","1.6652","10.6249"
"10.1600","2.5171","45.0122","2.5171","1.6781","10.7172"
"10.2400","2.5375","45.4326","2.5375","1.6917","10.8173"
"10.3200","2.5572","45.8358","2.5572","1.7048","10.9133"
"10.4000","2.5766","46.2170","2.5766","1.7178","11.0040"
"10.4800","2.5979","46.6472","2.5979","1.7319","11.1065"
"10.5600","2.6189","47.0681","2.6189","1.7459","11.2067"
"10.6400","2.6377","47.4265","2.6377","1.7585","11.2920"
"10.7200","2.6576","47.8227","2.6576","1.7717","11.3864"
"10.8000","2.6769","48.2004","2.6769","1.7846","11.4763"
"10.8800","2.6979","48.6191","2.6979","1.7986","11.5760"
"10.9600","2.7176","49.0051","2.7176","1.8117","11.6679"
"11.0400","2.7362","49.3749","2.7362","1.8242","11.7559"
"11.1200","2.7571","49.7910","2.7571","1.8381","11.8550"
"11.2000","2.7782","50.2172","2.7782","1.8521","11.9565"
"11.2800","2.7983","50.6100","2.7983","1.8656","12.0500"
"11.3600","2.8179","50.9916","2.8179","1.8786","12.1409"
"11.4400","2.8366","51.3449","2.8366","1.8910","12.2250"
"11.5200","2.8572","51.7500","2.8572","1.9048","12.3214"
"11.6000","2.8775","52.1457","2.8775","1.9183","12.4156"
"11.6800","2.8971","52.5370","2.8971","1.9314","12.5088"
"11.7600","2.9182","52.9620","2.9182","1.9455","12.6100"
"11.8400","2.9380","53.3436","2.9380","1.9587","12.7009"
"11.9200","2.9581","53.7288","2.9581","1.9721","12.7926"
"12.0000","2.9780","54.1295","2.9780","1.9854","12.8880"
"12.0800","2.9973","54.4901","2.9973","1.9982","12.9738"
"12.1600","3.0173","54.8933","3.0173","2.0116","13.0698"
"12.2400","3.0372","55.2700","3.0372","2.0248","13.1595"
"12.3200","3.0567","55.6463","3.0567","2.0378","13.2491"
"12.4000","3.0781","56.0802","3.0781","2.0521","13.3524"
"12.4800","3.0974","56.4302","3.0974","2.0649","13.4358"
"12.5600","3.1183","56.8441","3.1183","2.0788","13.5343"
"12.6400","3.1378","57.2128","3.1378","2.0919","13.6221"
"12.7200","3.1569","57.5792","3.1569","2.1046","13.7093"
"12.8000","3.1766","57.9588","3.1766","2.1177","13.7997"
"12.8800","3.1970","58.3405","3.1970","2.1313","13.8906"
"12.9600","3.2178","58.7363","3.2178","2.1452","13.9848"
"13.0400","3.2389","59.1457","3.2389","2.1593","14.0823"
"13.1200","3.2576","59.4987","3.2576","2.1717","14.1664"
"13.2000","3.2777","59.8796","3.2777","2.1851","14.2570"
"13.2800","3.2977","60.2578","3.2977","2.1985","14.3471"
"13.3600","3.3173","60.6340","3.3173","2.2115","14.4367"
"13.4400","3.3371","61.0076","3.3371","2.2248","14.5256"
"13.5200","3.3561","61.3518","3.3561","2.2374","14.6076"
"13.6000","3.3773","61.7642","3.3773","2.2515","14.7058"
"13.6800","3.3984","62.1686","3.3984","2.2656","14.8020"
"13.7600","3.4182","62.5426","3.4182","2.2788","14.8911"
"13.8400","3.4374","62.9086","3.4374","2.2916","14.9782"
"13.9200","3.4566","63.2441","3.4566","2.3044","15.0581"
"14.0000","3.4771","63.6543","3.4771","2.3181","15.1558"
"14.0800","3.4978","64.0394","3.4978","2.3319","15.2475"
"14.1600","3.5167","64.3916","3.5167","2.3445","15.3313"
"14.2400","3.5380","64.7978","3.5380","2.3587","15.4280"
"14.3200","3.5580","65.1709","3.5580","2.3720","15.5169"
"14.4000","3.5780","65.5489","3.5780","2.3853","15.6069"
"14.4800","3.5977","65.9107","3.5977","2.3984","15.6930"
"14.5600","3.6175","66.2735","3.6175","2.4117","15.7794"
"14.6400","3.6375","66.6484","3.6375","2.4250","15.8687"
"14.7200","3.6572","67.0109","3.6572","2.4381","15.9550"
"14.8000","3.6760","67.3684","3.6760","2.4507","16.0401"
"14.8800","3.6979","67.8045","3.6979","2.4652","16.1439"
"14.9600","3.7180","68.1531","3.7180","2.4786","16.2269"
"15.0400","3.7377","68.5156","3.7377","2.4918","16.3132"
"15.1200","3.7573","68.8698","3.7573","2.5048","16.3976"
"15.2000","3.7762","69.2228","3.7762","2.5175","16.4816"
"15.2800","3.7977","69.6254","3.7977","2.5318","16.5775"
"15.3600","3.8175","69.9870","3.8175","2.5450","16.6636"
"15.4400","3.8374","70.3588","3.8374","2.5582","16.7521"
"15.5200","3.8581","70.7526","3.8581","2.5721","16.8459"
"15.6000","3.8776","71.1012","3.8776","2.5851","16.9289"
"15.6800","3.8982","71.4787","3.8982","2.5988","17.0187"
"15.7600","3.9183","71.8424","3.9183","2.6122","17.1053"
"15.8400","3.9368","72.1854","3.9368","2.6245","17.1870"
"15.9200","3.9572","72.5544","3.9572","2.6382","17.2748"
"16.0000","3.9765","72.9048","3.9765","2.6510","17.3583"
"16.0800","3.9974","73.2949","3.9974","2.6649","17.4512"
"16.1600","4.0183","73.6800","4.0183","2.6788","17.5429"
"16.2400","4.0375","74.0216","4.0375","2.6917","17.6242"
"16.3200","4.0572","74.3710","4.0572","2.7048","17.7074"
"16.4000","4.0775","74.7493","4.0775","2.7183","17.7975"
"16.4800","4.0970","75.1021","4.0970","2.7313","17.8815"
"16.5600","4.1178","75.4862","4.1178","2.7452","17.9729"
"16.6400","4.1364","75.8013","4.1364","2.7576","18.0479"
"16.7200","4.1580","76.2067","4.1580","2.7720","18.1445"
"16.8000","4.1783","76.5820","4.1783","2.7856","18.2338"
"16.8800","4.1983","76.9564","4.1983","2.7988","18.3230"
"16.9600","4.2178","77.3019","4.2178","2.8118","18.4052"
"17.0400","4.2379","77.6526","4.2379","2.8252","18.4887"
"17.1200","4.2571","78.0002","4.2571","2.8381","18.5715"
"17.2000","4.2773","78.3653","4.2773","2.8515","18.6584"
"17.2800","4.2965","78.7124","4.2965","2.8643","18.7410"
"17.3600","4.3179","79.1058","4.3179","2.8786","18.8347"
"17.4400","4.3379","79.4673","4.3379","2.8919","18.9208"
"17.5200","4.3574","79.8119","4.3574","2.9049","19.0028"
"17.6000","4.3779","80.1821","4.3779","2.9186","19.0910"
"17.6800","4.3970","80.5025","4.3970","2.9313","19.1673"
"17.7600","4.4176","80.8812","4.4176","2.9450","19.2574"
"17.8400","4.4376","81.2469","4.4376","2.9584","19.3445"
"17.9200","4.4563","81.5709","4.4563","2.9709","19.4217"
"18.0000","4.4773","81.9633","4.4773","2.9849","19.5151"
"18.0800","4.4985","82.3406","4.4985","2.9990","19.6049"
"18.1600","4.5184","82.6961","4.5184","3.0122","19.6895"
"18.2400","4.5379","83.0466","4.5379","3.0253","19.7730"
"18.3200","4.5563","83.3559","4.5563","3.0375","19.8466"
"18.4000","4.5777","83.7310","4.5777","3.0518","19.9360"
"18.4800","4.5972","84.0860","4.5972","3.0648","20.0205"
"18.5600","4.6172","84.4529","4.6172","3.0781","20.1078"
"18.6400","4.6374","84.8259","4.6374","3.0916","20.1966"
"18.7200","4.6576","85.1704","4.6576","3.1051","20.2787"
"18.8000","4.6777","85.5366","4.6777","3.1185","20.3658"
"18.8800","4.6983","85.9024","4.6983","3.1322","20.4530"
"18.9600","4.7166","86.2222","4.7166","3.1444","20.5291"
"19.0400","4.7371","86.5944","4.7371","3.1581","20.6177"
"19.1200","4.7567","86.9078","4.7567","3.1711","20.6923"
"19.2000","4.7777","87.3029","4.7777","3.1851","20.7864"
"19.2800","4.7990","87.6877","4.7990","3.1994","20.8780"
"19.3600","4.8183","88.0286","4.8183","3.2122","20.9592"
"19.4400","4.8381","88.3725","4.8381","3.2254","21.0411"
"19.5200","4.8577","88.7273","4.8577","3.2385","21.1256"
"19.6000","4.8771","89.0706","4.8771","3.2514","21.2073"
"19.6800","4.8974","89.4437","4.8974","3.2649","21.2961"
"19.7600","4.9167","89.7641","4.9167","3.2778","21.3724"
"19.8400","4.9376","90.1383","4.9376","3.2917","21.4615"
"19.9200","4.9582","90.5018","4.9582","3.3055","21.5480"
"20.0000","4.9775","90.8244","4.9775","3.3183","21.6248"
"20.0800","4.9979","91.1822","4.9979","3.3319","21.7100"
"20.1600","5.0168","91.5085","5.0168","3.3446","21.7877"
"20.2400","5.0370","91.8650","5.0370","3.3580","21.8726"
"20.3200","5.0574","92.2207","5.0574","3.3716","21.9573"
"20.4000","5.0771","92.5683","5.0771","3.3847","22.0401"
"20.4800","5.0972","92.9244","5.0972","3.3981","22.1249"
"20.5600","5.1185","93.2970","5.1185","3.4123","22.2136"
"20.6400","5.1379","93.6394","5.1379","3.4253","22.2951"
"20.7200","5.1579","94.0018","5.1579","3.4386","22.3814"
"20.8000","5.1767","94.3146","5.1767","3.4511","22.4559"
"20.8800","5.1976","94.6768","5.1976","3.4651","22.5421"
"20.9600","5.2177","94.9973","5.2177","3.4785","22.6184"
"21.0400","5.2362","95.3192","5.2362","3.4908","22.6950"
"21.1200","5.2571","95.6848","5.2571","3.5047","22.7821"
"21.2000","5.2779","96.0480","5.2779","3.5186","22.8686"
"21.2800","5.2982","96.4049","5.2982","3.5321","22.9536"
"21.3600","5.3179","96.7477","5.3179","3.5453","23.0352"
"21.4400","5.3364","97.0537","5.3364","3.5576","23.1080"
"21.5200","5.3569","97.4122","5.3569","3.5713","23.1934"
"21.6000","5.3772","97.7590","5.3772","3.5848","23.2760"
"21.6800","5.3972","98.1152","5.3972","3.5982","23.3608"
"21.7600","5.4183","98.4878","5.4183","3.6122","23.4495"
"21.8400","5.4378","98.8003","5.4378","3.6252","23.5239"
"21.9200","5.4582","99.1492","5.4582","3.6388","23.6070"
"22.0000","5.4777","99.4656","5.4777","3.6518","23.6823"
"22.0800","5.4972","99.8136","5.4972","3.6648","23.7651"
"22.1600","5.5177","100.1754","5.5177","3.6785","23.8513"
"22.2400","5.5370","100.5007","5.5370","3.6914","23.9287"
"22.3200","5.5566","100.8297","5.5566","3.7044","24.0071"
"22.4000","5.5779","101.2097","5.5779","3.7186","24.0976"
"22.4800","5.5974","101.5406","5.5974","3.7316","24.1763"
"22.5600","5.6184","101.8878","5.6184","3.7456","24.2590"
"22.6400","5.6375","102.2112","5.6375","3.7584","24.3360"
"22.7200","5.6568","102.5367","5.6568","3.7712","24.4135"
"22.8000","5.6771","102.8954","5.6771","3.7847","24.4989"
"22.8800","5.6975","103.2388","5.6975","3.7984","24.5807"
"22.9600","5.7175","103.5417","5.7175","3.8116","24.6528"
"23.0400","5.7380","103.8985","5.7380","3.8253","24.7377"
"23.1200","5.7579","104.2377","5.7579","3.8386","24.8185"
"23.2000","5.7782","104.5688","5.7782","3.8522","24.8973"
"23.2800","5.7974","104.8771","5.7974","3.8650","24.9707"
"23.3600","5.8176","105.2266","5.8176","3.8784","25.0540"
"23.4400","5.8375","105.5546","5.8375","3.8917","25.1320"
"23.5200","5.8560","105.8583","5.8560","3.9040","25.2044"
"23.6000","5.8774","106.2292","5.8774","3.9183","25.2927"
"23.6800","5.8987","106.5995","5.8987","3.9325","25.3808"
"23.7600","5.9179","106.9156","5.9179","3.9453","25.4561"
"23.8400","5.9372","107.2388","5.9372","3.9582","25.5330"
"23.9200","5.9565","107.5363","5.9565","3.9710","25.6039"
"24.0000","5.9768","107.8684","5.9768","3.9845","25.6829"
"24.0800","5.9981","108.2342","5.9981","3.9988","25.7701"
"24.1600","6.0168","108.5440","6.0168","4.0112","25.8438"
"24.2400","6.0382","108.9133","6.0382","4.0255","25.9317"
"24.3200","6.0579","109.2374","6.0579","4.0386","26.0089"
"24.4000","6.0785","109.5916","6.0785","4.0523","26.0932"
"24.4800","6.0980","109.9256","6.0980","4.0654","26.1728"
"24.5600","6.1174","110.2430","6.1174","4.0783","26.2483"
"24.6400","6.1376","110.5644","6.1376","4.0918","26.3249"
"24.7200","6.1573","110.8905","6.1573","4.1049","26.4025"
"24.8000","6.1759","111.2048","6.1759","4.1172","26.4773"
"24.8800","6.1980","111.5893","6.1980","4.1320","26.5689"
"24.9600","6.2179","111.9049","6.2179","4.1453","26.6440"
"25.0400","6.2382","112.2360","6.2382","4.1588","26.7228"
"25.1200","6.2575","112.5524","6.2575","4.1717","26.7982"
"25.2000","6.2762","112.8570","6.2762","4.1841","26.8707"
"25.2800","6.2976","113.2169","6.2976","4.1984","26.9564"
"25.3600","6.3175","113.5483","6.3175","4.2116","27.0353"
"25.4400","6.3368","113.8499","6.3368","4.2245","27.1071"
"25.5200","6.3582","114.2271","6.3582","4.2388","27.1969"
"25.6000","6.3780","114.5308","6.3780","4.2520","27.2692"
"25.6800","6.3980","114.8632","6.3980","4.2653","27.3484"
"25.7600","6.4183","115.1949","6.4183","4.2788","27.4274"
"25.8400","6.4369","115.4952","6.4369","4.2913","27.4989"
"25.9200","6.4572","115.8384","6.4572","4.3048","27.5806"
"26.0000","6.4767","116.1458","6.4767","4.3178","27.6538"
"26.0800","6.4974","116.5003","6.4974","4.3316","27.7382"
"26.1600","6.5186","116.8454","6.5186","4.3458","27.8203"
"26.2400","6.5379","117.1431","6.5379","4.3586","27.8912"
"26.3200","6.5573","117.4607","6.5573","4.3715","27.9668"
"26.4000","6.5774","117.7848","6.5774","4.3850","28.0440"
"26.4800","6.5970","118.1081","6.5970","4.3980","28.1210"
"26.5600","6.6178","118.4482","6.6178","4.4118","28.2019"
"26.6400","6.6367","118.7568","6.6367","4.4244","28.2754"
"26.7200","6.6580","119.1021","6.6580","4.4387","28.3576"
"26.8000","6.6784","119.4392","6.6784","4.4523","28.4379"
"26.8800","6.6984","119.7734","6.6984","4.4656","28.5175"
"26.9600","6.7178","120.0760","6.7178","4.4785","28.5895"
"27.0400","6.7374","120.3830","6.7374","4.4916","28.6626"
"27.1200","6.7572","120.7185","6.7572","4.5048","28.7425"
"27.2000","6.7773","121.0499","6.7773","4.5182","28.8214"
"27.2800","6.7962","121.3396","6.7962","4.5308","28.8904"
"27.3600","6.8179","121.7156","6.8179","4.5452","28.9799"
"27.4400","6.8380","122.0249","6.8380","4.5586","29.0536"
"27.5200","6.8575","122.3511","6.8575","4.5716","29.1312"
"27.6000","6.8777","122.6735","6.8777","4.5851","29.2080"
"27.6800","6.8967","122.9607","6.8967","4.5978","29.2764"
"27.7600","6.9176","123.2983","6.9176","4.6117","29.3567"
"27.8400","6.9373","123.6104","6.9373","4.6248","29.4310"
"27.9200","6.9569","123.9338","6.9569","4.6379","29.5080"
"28.0000","6.9778","124.2831","6.9778","4.6518","29.5912"
"28.0800","6.9985","124.6124","6.9985","4.6657","29.6696"
"28.1600","7.0177","124.9103","7.0177","4.6785","29.7405"
"28.2400","7.0377","125.2215","7.0377","4.6918","29.8146"
"28.3200","7.0568","125.5170","7.0568","4.7045","29.8850"
"28.4000","7.0774","125.8582","7.0774","4.7183","29.9662"
"28.4800","7.0972","126.1662","7.0972","4.7314","30.0396"
"28.5600","7.1174","126.4981","7.1174","4.7449","30.1186"
"28.6400","7.1376","126.8227","7.1376","4.7584","30.1959"
"28.7200","7.1575","127.1268","7.1575","4.7717","30.2683"
"28.8000","7.1777","127.4505","7.1777","4.7851","30.3454"
"28.8800","7.1986","127.7844","7.1986","4.7991","30.4249"
"28.9600","7.2169","128.0678","7.2169","4.8112","30.4923"
"29.0400","7.2371","128.3879","7.2371","4.8247","30.5685"
"29.1200","7.2567","128.7063","7.2567","4.8378","30.6444"
"29.2000","7.2777","129.0458","7.2777","4.8518","30.7252"
"29.2800","7.2990","129.3846","7.2990","4.8660","30.8058"
"29.3600","7.3182","129.6993","7.3182","4.8788","30.8808"
"29.4400","7.3379","129.9919","7.3379","4.8919","30.9504"
"29.5200","7.3575","130.3012","7.3575","4.9050","31.0241"
"29.6000","7.3769","130.6156","7.3769","4.9179","31.0990"
"29.6800","7.3975","130.9391","7.3975","4.9317","31.1760"
"29.7600","7.4166","131.2183","7.4166","4.9444","31.2425"
"29.8400","7.4372","131.5480","7.4372","4.9581","31.3210"
"29.9200","7.4583","131.8894","7.4583","4.9722","31.4022"
"30.0000","7.4776","132.1985","7.4776","4.9850","31.4758"
"30.0800","7.4981","132.5085","7.4981","4.9987","31.5496"
"30.1600","7.5170","132.8020","7.5170","5.0114","31.6195"
"30.2400","7.5371","133.1183","7.5371","5.0247","31.6948"
"30.3200","7.5572","133.4379","7.5572","5.0382","31.7709"
"30.4000","7.5768","133.7360","7.5768","5.0512","31.8419"
"30.4800","7.5978","134.0734","7.5978","5.0652","31.9222"
"30.5600","7.6187","134.3994","7.6187","5.0791","31.9999"
"30.6400","7.6377","134.6880","7.6377","5.0918","32.0686"
"30.7200","7.6579","135.0077","7.6579","5.1053","32.1447"
"30.8000","7.6770","135.2845","7.6770","5.1180","32.2106"
"30.8800","7.6978","135.6172","7.6978","5.1318","32.2898"
"30.9600","7.7178","135.9323","7.7178","5.1452","32.3648"
"31.0400","7.7366","136.2178","7.7366","5.1577","32.4328"
"31.1200","7.7572","136.5475","7.7572","5.1715","32.5113"
"31.2000","7.7781","136.8786","7.7781","5.1854","32.5901"
"31.2800","7.7980","137.1890","7.7980","5.1987","32.6640"
"31.3600","7.8183","137.5004","7.8183","5.2122","32.7382"
"31.4400","7.8365","137.7529","7.8365","5.2243","32.7983"
"31.5200","7.8566","138.0640","7.8566","5.2378","32.8724"
"31.6000","7.8773","138.3868","7.8773","5.2516","32.9492"
"31.6800","7.8973","138.7148","7.8973","5.2649","33.0273"
"31.7600","7.9186","139.0546","7.9186","5.2791","33.1082"
"31.8400","7.9384","139.3625","7.9384","5.2923","33.1816"
"31.9200","7.9586","139.6611","7.9586","5.3057","33.2526"
"32.0000","7.9776","139.9479","7.9776","5.3184","33.3209"
"32.0800","7.9970","140.2440","7.9970","5.3313","33.3914"
"32.1600","8.0172","140.5569","8.0172","5.3448","33.4659"
"32.2400","8.0369","140.8509","8.0369","5.3580","33.5359"
"32.3200","8.0563","141.1424","8.0563","5.3709","33.6053"
"32.4000","8.0775","141.4859","8.0775","5.3850","33.6871"
"32.4800","8.0975","141.7885","8.0975","5.3983","33.7592"
"32.5600","8.1186","142.1139","8.1186","5.4124","33.8366"
"32.6400","8.1375","142.3862","8.1375","5.4250","33.9015"
"32.7200","8.1566","142.6843","8.1566","5.4377","33.9725"
"32.8000","8.1769","142.9918","8.1769","5.4512","34.0457"
"32.8800","8.1972","143.3063","8.1972","5.4648","34.1205"
"32.9600","8.2174","143.6107","8.2174","5.4783","34.1930"
"33.0400","8.2384","143.9296","8.2384","5.4923","34.2689"
"33.1200","8.2575","144.2165","8.2575","5.5050","34.3373"
"33.2000","8.2781","144.5364","8.2781","5.5187","34.4134"
"33.2800","8.2976","144.8218","8.2976","5.5318","34.4814"
"33.3600","8.3176","145.1390","8.3176","5.5451","34.5569"
"33.4400","8.3374","145.4274","8.3374","5.5582","34.6256"
"33.5200","8.3559","145.6918","8.3559","5.5706","34.6885"
"33.6000","8.3775","146.0377","8.3775","5.5850","34.7709"
"33.6800","8.3987","146.3664","8.3987","5.5991","34.8491"
"33.7600","8.4181","146.6527","8.4181","5.6121","34.9173"
"33.8400","8.4374","146.9372","8.4374","5.6249","34.9850"
"33.9200","8.4566","147.2112","8.4566","5.6377","35.0503"
"34.0000","8.4770","147.5441","8.4770","5.6514","35.1295"
"34.0800","8.4979","147.8483","8.4979","5.6653","35.2020"
"34.1600","8.5169","148.1327","8.5169","5.6780","35.2697"
"34.2400","8.5381","148.4611","8.5381","5.6921","35.3479"
"34.3200","8.5582","148.7537","8.5582","5.7054","35.4175"
"34.4000","8.5782","149.0492","8.5782","5.7188","35.4879"
"34.4800","8.5977","149.3444","8.5977","5.7318","35.5582"
"34.5600","8.6172","149.6263","8.6172","5.7448","35.6253"
"34.6400","8.6374","149.9302","8.6374","5.7582","35.6977"
"34.7200","8.6576","150.2383","8.6576","5.7717","35.7710"
"34.8000","8.6760","150.5075","8.6760","5.7840","35.8351"
"34.8800","8.6977","150.8397","8.6977","5.7985","35.9142"
"34.9600","8.7178","151.1394","8.7178","5.8119","35.9856"
"35.0400","8.7383","151.4369","8.7383","5.8255","36.0564"
"35.1200","8.7574","151.7111","8.7574","5.8382","36.1217"
"35.2000","8.7762","151.9794","8.7762","5.8508","36.1856"
"35.2800","8.7971","152.3064","8.7971","5.8647","36.2634"
"35.3600","8.8174","152.6188","8.8174","5.8783","36.3378"
"35.4400","8.8374","152.9033","8.8374","5.8916","36.4056"
"35.5200","8.8578","153.2156","8.8578","5.9052","36.4799"
"35.6000","8.8773","153.4929","8.8773","5.9182","36.5459"
"35.6800","8.8985","153.8141","8.8985","5.9323","36.6224"
"35.7600","8.9183","154.0990","8.9183","5.9456","36.6902"
"35.8400","8.9368","154.3585","8.9368","5.9579","36.7520"
"35.9200","8.9572","154.6640","8.9572","5.9715","36.8248"
"36.0000","8.9765","154.9387","8.9765","5.9844","36.8902"
"36.0800","8.9976","155.2593","8.9976","5.9984","36.9665"
"36.1600","9.0184","155.5750","9.0184","6.0123","37.0417"
"36.2400","9.0376","155.8478","9.0376","6.0251","37.1066"
"36.3200","9.0572","156.1367","9.0572","6.0382","37.1754"
"36.4000","9.0773","156.4316","9.0773","6.0516","37.2456"
"36.4800","9.0970","156.7253","9.0970","6.0647","37.3156"
"36.5600","9.1178","157.0324","9.1178","6.0785","37.3887"
"36.6400","9.1365","157.2845","9.1365","6.0910","37.4487"
"36.7200","9.1580","157.6136","9.1580","6.1053","37.5271"
"36.8000","9.1785","157.9256","9.1785","6.1190","37.6013"
"36.8800","9.1985","158.2210","9.1985","6.1323","37.6717"
"36.9600","9.2176","158.4913","9.2176","6.1451","37.7360"
"37.0400","9.2374","158.7763","9.2374","6.1582","37.8039"
"37.1200","9.2572","159.0608","9.2572","6.1714","37.8716"
"37.2000","9.2775","159.3659","9.2775","6.1850","37.9443"
"37.2800","9.2962","159.6145","9.2962","6.1975","38.0035"
"37.3600","9.3176","159.9420","9.3176","6.2117","38.0814"
"37.4400","9.3382","160.2582","9.3382","6.2255","38.1567"
"37.5200","9.3576","160.5268","9.3576","6.2384","38.2207"
"37.6000","9.3775","160.8154","9.3775","6.2517","38.2894"
"37.6800","9.3970","161.0881","9.3970","6.2647","38.3543"
"37.7600","9.4176","161.3862","9.4176","6.2784","38.4253"
"37.8400","9.4367","161.6584","9.4367","6.2912","38.4901"
"37.9200","9.4565","161.9465","9.4565","6.3043","38.5587"
"38.0000","9.4780","162.2759","9.4780","6.3187","38.6371"
"38.0800","9.4985","162.5592","9.4985","6.3323","38.7046"
"38.1600","9.5181","162.8387","9.5181","6.3454","38.7711"
"38.2400","9.5381","163.1198","9.5381","6.3587","38.8381"
"38.3200","9.5566","163.3859","9.5566","6.3711","38.9014"
"38.4000","9.5778","163.7000","9.5778","6.3852","38.9762"
"38.4800","9.5971","163.9699","9.5971","6.3981","39.0404"
"38.5600","9.6173","164.2699","9.6173","6.4115","39.1119"
"38.6400","9.6374","164.5615","9.6374","6.4249","39.1813"
"38.7200","9.6578","164.8405","9.6578","6.4385","39.2477"
"38.8000","9.6775","165.1215","9.6775","6.4517","39.3146"
"38.8800","9.6982","165.4222","9.6982","6.4655","39.3862"
"38.9600","9.7168","165.6777","9.7168","6.4778","39.4471"
"39.0400","9.7373","165.9776","9.7373","6.4915","39.5185"
"39.1200","9.7566","166.2457","9.7566","6.5044","39.5823"
"39.2000","9.7775","166.5634","9.7775","6.5183","39.6580"
"39.2800","9.7988","166.8759","9.7988","6.5325","39.7323"
"39.3600","9.8180","167.1354","9.8180","6.5453","39.7941"
"39.4400","9.8380","167.4187","9.8380","6.5587","39.8616"
"39.5200","9.8577","167.6925","9.8577","6.5718","39.9268"
"39.6000","9.8769","167.9558","9.8769","6.5846","39.9895"
"39.6800","9.8969","168.2585","9.8969","6.5980","40.0616"
"39.7600","9.9168","168.5132","9.9168","6.6112","40.1222"
"39.8400","9.9374","168.8174","9.9374","6.6250","40.1946"
"39.9200","9.9586","169.1266","9.9586","6.6391","40.2682"
"40.0000","9.9774","169.3936","9.9774","6.6516","40.3318"
"40.0800","9.9979","169.6869","9.9979","6.6653","40.4016"
"40.1600","10.0170","169.9457","10.0170","6.6780","40.4633"
"40.2400","10.0370","170.2186","10.0370","6.6914","40.5282"
"40.3200","10.0569","170.5169","10.0569","6.7046","40.5993"
"40.4000","10.0771","170.7910","10.0771","6.7181","40.6645"
"40.4800","10.0982","171.1049","10.0982","6.7322","40.7393"
"40.5600","10.1189","171.3977","10.1189","6.7459","40.8090"
"40.6400","10.1374","171.6397","10.1374","6.7583","40.8666"
"40.7200","10.1579","171.9345","10.1579","6.7719","40.9368"
"40.8000","10.1770","172.1914","10.1770","6.7847","40.9979"
"40.8800","10.1980","172.4903","10.1980","6.7987","41.0691"
"40.9600","10.2177","172.7571","10.2177","6.8118","41.1326"
"41.0400","10.2360","172.9914","10.2360","6.8240","41.1884"
"41.1200","10.2566","173.2994","10.2566","6.8377","41.2618"
"41.2000","10.2781","173.6207","10.2781","6.8521","41.3383"
"41.2800","10.2985","173.9026","10.2985","6.8656","41.4054"
"41.3600","10.3184","174.1800","10.3184","6.8789","41.4714"
"41.4400","10.3367","174.4153","10.3367","6.8911","41.5274"
"41.5200","10.3569","174.7033","10.3569","6.9046","41.5960"
"41.6000","10.3775","174.9871","10.3775","6.9183","41.6636"
"41.6800","10.3973","175.2786","10.3973","6.9315","41.7330"
"41.7600","10.4187","175.5909","10.4187","6.9458","41.8074"
"41.8400","10.4380","175.8316","10.4380","6.9587","41.8647"
"41.9200","10.4579","176.1087","10.4579","6.9720","41.9307"
"42.0000","10.4777","176.3777","10.4777","6.9851","41.9947"
"42.0800","10.4972","176.6495","10.4972","6.9981","42.0594"
"42.1600","10.5171","176.9215","10.5171","7.0114","42.1242"
"42.2400","10.5372","177.2030","10.5372","7.0248","42.1912"
"42.3200","10.5564","177.4621","10.5564","7.0376","42.2529"
"42.4000","10.5777","177.7784","10.5777","7.0518","42.3282"
"42.4800","10.5974","178.0402","10.5974","7.0650","42.3905"
"42.5600","10.6187","178.3369","10.6187","7.0792","42.4612"
"42.6400","10.6375","178.5786","10.6375","7.0917","42.5187"
"42.7200","10.6567","178.8538","10.6567","7.1045","42.5842"
"42.8000","10.6770","179.1475","10.6770","7.1180","42.6542"
"42.8800","10.6975","179.4372","10.6975","7.1316","42.7231"
"42.9600","10.7176","179.7113","10.7176","7.1451","42.7884"
"43.0400","10.7384","179.9964","10.7384","7.1590","42.8563"
"43.1200","10.7574","180.2421","10.7574","7.1716","42.9148"
"43.2000","10.7784","180.5371","10.7784","7.1856","42.9850"
"43.2800","10.7973","180.7808","10.7973","7.1982","43.0431"
"43.3600","10.8173","181.0475","10.8173","7.2116","43.1065"
"43.4400","10.8378","181.3249","10.8378","7.2252","43.1726"
"43.5200","10.8562","181.5499","10.8562","7.2375","43.2262"
"43.6000","10.8772","181.8392","10.8772","7.2514","43.2950"
"43.6800","10.8984","182.1435","10.8984","7.2656","43.3675"
"43.7600","10.9183","182.4072","10.9183","7.2789","43.4303"
"43.8400","10.9375","182.6646","10.9375","7.2917","43.4916"
"43.9200","10.9563","182.8945","10.9563","7.3042","43.5463"
"44.0000","10.9765","183.1776","10.9765","7.3177","43.6137"
"44.0800","10.9983","183.4821","10.9983","7.3322","43.6862"
"44.1600","11.0171","183.7349","11.0171","7.3447","43.7464"
"44.2400","11.0380","184.0265","11.0380","7.3587","43.8158"
"44.3200","11.0579","184.2846","11.0579","7.3719","43.8773"
"44.4000","11.0785","184.5771","11.0785","7.3857","43.9469"
"44.4800","11.0978","184.8292","11.0978","7.3985","44.0069"
"44.5600","11.1172","185.0923","11.1172","7.4115","44.0696"
"44.6400","11.1374","185.3602","11.1374","7.4249","44.1334"
"44.7200","11.1576","185.6358","11.1576","7.4384","44.1990"
"44.8000","11.1762","185.8740","11.1762","7.4508","44.2557"
"44.8800","11.1977","186.1938","11.1977","7.4652","44.3318"
"44.9600","11.2177","186.4442","11.2177","7.4785","44.3915"
"45.0400","11.2381","186.7151","11.2381","7.4920","44.4560"
"45.1200","11.2574","186.9684","11.2574","7.5049","44.5163"
"45.2000","11.2766","187.2200","11.2766","7.5177","44.5762"
"45.2800","11.2973","187.5187","11.2973","7.5315","44.6473"
"45.3600","11.3176","187.7887","11.3176","7.5451","44.7116"
"45.4400","11.3372","188.0448","11.3372","7.5581","44.7726"
"45.5200","11.3583","188.3492","11.3583","7.5722","44.8451"
"45.6000","11.3782","188.5941","11.3782","7.5854","44.9034"
"45.6800","11.3982","188.8652","11.3982","7.5988","44.9679"
"45.7600","11.4178","189.1127","11.4178","7.6118","45.0268"
"45.8400","11.4365","189.3608","11.4365","7.6243","45.0859"
"45.9200","11.4574","189.6521","11.4574","7.6383","45.1553"
"46.0000","11.4766","189.8896","11.4766","7.6510","45.2118"
"46.0800","11.4977","190.1834","11.4977","7.6651","45.2818"
"46.1600","11.5184","190.4603","11.5184","7.6790","45.3477"
"46.2400","11.5380","190.7144","11.5380","7.6920","45.4082"
"46.3200","11.5572","190.9553","11.5572","7.7048","45.4655"
"46.4000","11.5773","191.2154","11.5773","7.7182","45.5275"
"46.4800","11.5970","191.4787","11.5970","7.7313","45.5902"
"46.5600","11.6180","191.7800","11.6180","7.7454","45.6619"
"46.6400","11.6365","191.9991","11.6365","7.7576","45.7141"
"46.7200","11.6576","192.2988","11.6576","7.7718","45.7854"
"46.8000","11.6785","192.5778","11.6785","7.7857","45.8519"
"46.8800","11.6980","192.8378","11.6980","7.7987","45.9138"
"46.9600","11.7178","193.0847","11.7178","7.8119","45.9725"
"47.0400","11.7374","193.3329","11.7374","7.8249","46.0316"
"47.1200","11.7572","193.5907","11.7572","7.8381","46.0930"
"47.2000","11.7775","193.8698","11.7775","7.8517","46.1595"
"47.2800","11.7963","194.1027","11.7963","7.8642","46.2149"
"47.3600","11.8174","194.3965","11.8174","7.8782","46.2849"
"47.4400","11.8383","194.6790","11.8383","7.8922","46.3521"
"47.5200","11.8578","194.9361","11.8578","7.9052","46.4134"
"47.6000","11.8776","195.1940","11.8776","7.9184","46.4748"
"47.6800","11.8967","195.4271","11.8967","7.9311","46.5303"
"47.7600","11.9177","195.7070","11.9177","7.9451","46.5969"
"47.8400","11.9377","195.9749","11.9377","7.9584","46.6607"
"47.9200","11.9568","196.2251","11.9568","7.9712","46.7203"
"48.0000","11.9777","196.5108","11.9777","7.9851","46.7883"
"48.0800","11.9987","196.7848","11.9987","7.9991","46.8535"
"48.1600","12.0181","197.0312","12.0181","8.0121","46.9122"
"48.2400","12.0378","197.2802","12.0378","8.0252","46.9715"
"48.3200","12.0566","197.5079","12.0566","8.0378","47.0257"
"48.4000","12.0774","197.7894","12.0774","8.0516","47.0927"
"48.4800","12.0973","198.0430","12.0973","8.0649","47.1531"
"48.5600","12.1173","198.3077","12.1173","8.0782","47.2161"
"48.6400","12.1376","198.5793","12.1376","8.0917","47.2808"
"48.7200","12.1578","198.8323","12.1578","8.1052","47.3410"
"48.8000","12.1778","199.0893","12.1778","8.1185","47.4022"
"48.8800","12.1979","199.3387","12.1979","8.1319","47.4616"
"48.9600","12.2167","199.5877","12.2167","8.1445","47.5209"
"49.0400","12.2373","199.8470","12.2373","8.1582","47.5826"
"49.1200","12.2568","200.1004","12.2568","8.1712","47.6429"
"49.2000","12.2776","200.3796","12.2776","8.1851","47.7094"
"49.2800","12.2990","200.6669","12.2990","8.1993","47.7778"
"49.3600","12.3185","200.9123","12.3185","8.2124","47.8363"
"49.4400","12.3379","201.1492","12.3379","8.2253","47.8927"
"49.5200","12.3576","201.3889","12.3576","8.2384","47.9497"
"49.6000","12.3768","201.6479","12.3768","8.2512","48.0114"
"49.6800","12.3970","201.9015","12.3970","8.2647","48.0718"
"49.7600","12.4167","202.1392","12.4167","8.2778","48.1284"
"49.8400","12.4372","202.4059","12.4372","8.2914","48.1919"
"49.9200","12.4585","202.6886","12.4585","8.3057","48.2592"
"50.0000","12.4774","202.9267","12.4774","8.3183","48.3159"
"50.0800","12.4979","203.1871","12.4979","8.3319","48.3779"
"50.1600","12.5170","203.4119","12.5170","8.3446","48.4314"
"50.2400","12.5374","203.6829","12.5374","8.3582","48.4959"
"50.3200","12.5569","203.9277","12.5569","8.3713","48.5542"
"50.4000","12.5769","204.1683","12.5769","8.3846","48.6115"
"50.4800","12.5981","204.4757","12.5981","8.3988","48.6847"
"50.5600","12.6192","204.7425","12.6192","8.4128","48.7482"
"50.6400","12.6376","204.9483","12.6376","8.4250","48.7972"
"50.7200","12.6576","205.2003","12.6576","8.4384","48.8572"
"50.8000","12.6767","205.4279","12.6767","8.4511","48.9114"
"50.8800","12.6980","205.7163","12.6980","8.4653","48.9801"
"50.9600","12.7177","205.9448","12.7177","8.4785","49.0345"
"51.0400","12.7364","206.1711","12.7364","8.4909","49.0884"
"51.1200","12.7572","206.4500","12.7572","8.5048","49.1548"
"51.2000","12.7781","206.7204","12.7781","8.5188","49.2191"
"51.2800","12.7978","206.9585","12.7978","8.5318","49.2758"
"51.3600","12.8178","207.2135","12.8178","8.5452","49.3365"
"51.4400","12.8367","207.4216","12.8367","8.5578","49.3861"
"51.5200","12.8570","207.6743","12.8570","8.5713","49.4463"
"51.6000","12.8774","207.9319","12.8774","8.5849","49.5076"
"51.6800","12.8973","208.1991","12.8973","8.5982","49.5712"
"51.7600","12.9187","208.4864","12.9187","8.6125","49.6396"
"51.8400","12.9381","208.7187","12.9381","8.6254","49.6949"
"51.9200","12.9581","208.9491","12.9581","8.6387","49.7498"
"52.0000","12.9779","209.1911","12.9779","8.6519","49.8074"
"52.0800","12.9973","209.4283","12.9973","8.6649","49.8639"
"52.1600","13.0176","209.6839","13.0176","8.6784","49.9247"
"52.2400","13.0369","209.9004","13.0369","8.6913","49.9763"
"52.3200","13.0564","210.1410","13.0564","8.7043","50.0336"
"52.4000","13.0781","210.4419","13.0781","8.7187","50.1052"
"52.4800","13.0976","210.6641","13.0976","8.7318","50.1581"
"52.5600","13.1184","210.9246","13.1184","8.7456","50.2201"
"52.6400","13.1375","211.1370","13.1375","8.7583","50.2707"
"52.7200","13.1566","211.3665","13.1566","8.7711","50.3254"
"52.8000","13.1769","211.6308","13.1769","8.7846","50.3883"
"52.8800","13.1972","211.8581","13.1972","8.7981","50.4424"
"52.9600","13.2177","212.1189","13.2177","8.8118","50.5045"
"53.0400","13.2388","212.3809","13.2388","8.8258","50.5669"
"53.1200","13.2577","212.6025","13.2577","8.8385","50.6196"
"53.2000","13.2781","212.8596","13.2781","8.8521","50.6809"
"53.2800","13.2980","213.1001","13.2980","8.8654","50.7381"
"53.3600","13.3175","213.3380","13.3175","8.8784","50.7948"
"53.4400","13.3372","213.5561","13.3372","8.8915","50.8467"
"53.5200","13.3558","213.7488","13.3558","8.9038","50.8926"
"53.6000","13.3773","214.0256","13.3773","8.9182","50.9585"
"53.6800","13.3986","214.2969","13.3986","8.9324","51.0231"
"53.7600","13.4178","214.5135","13.4178","8.9452","51.0746"
"53.8400","13.4377","214.7565","13.4377","8.9585","51.1325"
"53.9200","13.4568","214.9684","13.4568","8.9712","51.1830"
"54.0000","13.4769","215.2023","13.4769","8.9846","51.2386"
"54.0800","13.4981","215.4620","13.4981","8.9987","51.3005"
"54.1600","13.5170","215.6737","13.5170","9.0113","51.3509"
"54.2400","13.5380","215.9363","13.5380","9.0254","51.4134"
"54.3200","13.5579","216.1724","13.5579","9.0386","51.4696"
"54.4000","13.5781","216.4076","13.5781","9.0521","51.5256"
"54.4800","13.5978","216.6416","13.5978","9.0652","51.5813"
"54.5600","13.6172","216.8586","13.6172","9.0782","51.6330"
"54.6400","13.6374","217.0919","13.6374","9.0916","51.6885"
"54.7200","13.6575","217.3280","13.6575","9.1050","51.7448"
"54.8000","13.6762","217.5363","13.6762","9.1175","51.7944"
"54.8800","13.6976","217.8121","13.6976","9.1317","51.8600"
"54.9600","13.7180","218.0411","13.7180","9.1453","51.9146"
"55.0400","13.7379","218.2735","13.7379","9.1586","51.9699"
"55.1200","13.7573","218.4848","13.7573","9.1716","52.0202"
"55.2000","13.7767","218.7217","13.7767","9.1845","52.0766"
"55.2800","13.7975","218.9662","13.7975","9.1983","52.1348"
"55.3600","13.8175","219.1927","13.8175","9.2116","52.1887"
"55.4400","13.8373","219.4345","13.8373","9.2249","52.2463"
"55.5200","13.8578","219.6728","13.8578","9.2386","52.3030"
"55.6000","13.8779","219.8996","13.8779","9.2519","52.3571"
"55.6800","13.8984","220.1426","13.8984","9.2656","52.4149"
"55.7600","13.9181","220.3576","13.9181","9.2787","52.4661"
"55.8400","13.9365","220.5470","13.9365","9.2910","52.5112"
"55.9200","13.9571","220.7974","13.9571","9.3048","52.5708"
"56.0000","13.9766","221.0093","13.9766","9.3177","52.6213"
"56.0800","13.9973","221.2569","13.9973","9.3316","52.6802"
"56.1600","14.0186","221.5309","14.0186","9.3457","52.7455"
"56.2400","14.0376","221.7211","14.0376","9.3584","52.7907"
"56.3200","14.0574","221.9471","14.0574","9.3716","52.8446"
"56.4000","14.0773","222.1619","14.0773","9.3848","52.8957"
"56.4800","14.0971","222.3933","14.0971","9.3980","52.9508"
"56.5600","14.1175","222.6193","14.1175","9.4116","53.0046"
"56.6400","14.1365","222.8132","14.1365","9.4243","53.0508"
"56.7200","14.1579","223.0689","14.1579","9.4386","53.1117"
"56.8000","14.1785","223.3144","14.1785","9.4524","53.1701"
"56.8800","14.1982","223.5169","14.1982","9.4654","53.2183"
"56.9600","14.2179","223.7453","14.2179","9.4786","53.2727"
"57.0400","14.2375","223.9512","14.2375","9.4917","53.3217"
"57.1200","14.2572","224.1687","14.2572","9.5048","53.3735"
"57.2000","14.2774","224.3803","14.2774","9.5183","53.4239"
"57.2800","14.2962","224.5696","14.2962","9.5308","53.4690"
"57.3600","14.3174","224.8193","14.3174","9.5449","53.5284"
"57.4400","14.3381","225.0564","14.3381","9.5587","53.5849"
"57.5200","14.3575","225.2697","14.3575","9.5717","53.6357"
"57.6000","14.3777","225.4901","14.3777","9.5851","53.6881"
"57.6800","14.3968","225.6772","14.3968","9.5979","53.7327"
"57.7600","14.4177","225.9128","14.4177","9.6118","53.7888"
"57.8400","14.4377","226.1322","14.4377","9.6251","53.8410"
"57.9200","14.4569","226.3299","14.4569","9.6380","53.8881"
"58.0000","14.4777","226.5648","14.4777","9.6518","53.9440"
"58.0800","14.4982","226.7868","14.4982","9.6655","53.9968"
"58.1600","14.5182","226.9992","14.5182","9.6788","54.0474"
"58.2400","14.5378","227.1960","14.5378","9.6919","54.0943"
"58.3200","14.5566","227.3767","14.5566","9.7044","54.1373"
"58.4000","14.5772","227.6065","14.5772","9.7181","54.1920"
"58.4800","14.5970","227.8043","14.5970","9.7314","54.2391"
"58.5600","14.6170","228.0347","14.6170","9.7447","54.2940"
"58.6400","14.6375","228.2570","14.6375","9.7583","54.3469"
"58.7200","14.6572","228.4452","14.6572","9.7714","54.3917"
"58.8000","14.6774","228.6593","14.6774","9.7850","54.4427"
"58.8800","14.6983","228.8755","14.6983","9.7988","54.4942"
"58.9600","14.7170","229.0571","14.7170","9.8113","54.5374"
"59.0400","14.7374","229.2713","14.7374","9.8249","54.5884"
"59.1200","14.7568","229.4580","14.7568","9.8378","54.6329"
"59.2000","14.7777","229.6990","14.7777","9.8518","54.6902"
"59.2800","14.7989","229.9215","14.7989","9.8659","54.7432"
"59.3600","14.8183","230.1018","14.8183","9.8789","54.7861"
"59.4400","14.8380","230.2856","14.8380","9.8920","54.8299"
"59.5200","14.8574","230.4799","14.8574","9.9049","54.8762"
"59.6000","14.8769","230.6602","14.8769","9.9179","54.9191"
"59.6800","14.8973","230.8662","14.8973","9.9315","54.9681"
"59.7600","14.9166","231.0462","14.9166","9.9444","55.0110"
"59.8400","14.9373","231.2523","14.9373","9.9582","55.0601"
"59.9200","14.9584","231.4693","14.9584","9.9723","55.1117"
"60.0000","14.9775","231.6539","14.9775","9.9850","55.1557"
"60.0800","14.9980","231.8544","14.9980","9.9986","55.2034"
"60.0890","15.0001","231.8723","15.0001","10.0001","55.2077"