File: data/instron_tests/metamaterial_samples/539_BULK_m2.is_comp_Exports/539_BULK_m2_5_1.csv
Sample text inputs : Sample No.,Sample choice input : Leading Direction,Sample choice input : Mode,Specimen choice input : Direction,Specimen properties : Height,Specimen properties : Thickness,Specimen properties : Width,Test : Rate 1
,,,,(mm),(mm),(mm),(mm/min)
"509","Bulk","Bimode","1","150.00","25.00","150.00","15.00"

Time,Displacement,Compressive displacement,Compressive strain (Displacement),Compressive stress,Force
(s),(mm),(mm),(%),(kPa),(N)
"0.0000","0.0000","0.0000","0.0000","-1.4285","-5.2854"
"0.0800","0.0014","0.0014","0.0009","-1.4245","-5.2706"
"0.1600","0.0189","0.0189","0.0126","-1.3937","-5.1568"
"0.2400","0.0391","0.0391","0.0261","-1.3561","-5.0176"
"0.3200","0.0584","0.0584","0.0389","-1.3248","-4.9019"
"0.4000","0.0780","0.0780","0.0520","-1.2953","-4.7926"
"0.4800","0.0990","0.0990","0.0660","-1.2741","-4.7142"
"0.5600","0.1192","0.1192","0.0795","-1.2428","-4.5983"
"0.6400","0.1390","0.1390","0.0927","-1.2162","-4.5000"
"0.7200","0.1585","0.1585","0.1056","-1.1906","-4.4053"
"0.8000","0.1771","0.1771","0.1181","-1.1630","-4.3031"
"0.8800","0.1979","0.1979","0.1319","-1.1328","-4.1914"
"0.9600","0.2176","0.2176","0.1451","-1.1132","-4.1189"
"1.0400","0.2378","0.2378","0.1586","-1.0876","-4.0240"
"1.1200","0.2585","0.2585","0.1723","-1.0646","-3.9388"
"1.2000","0.2780","0.2780","0.1853","-1.0415","-3.8534"
"1.2800","0.2985","0.2985","0.1990","-1.0213","-3.7788"
"1.3600","0.3182","0.3182","0.2121","-0.9996","-3.6985"
"1.4400","0.3378","0.3378","0.2252","-0.9716","-3.5950"
"1.5200","0.3580","0.3580","0.2387","-0.9427","-3.4881"
"1.6000","0.3775","0.3775","0.2517","-0.9154","-3.3869"
"1.6800","0.3982","0.3982","0.2654","-0.8876","-3.2842"
"1.7600","0.4197","0.4197","0.2798","-0.8565","-3.1690"
"1.8400","0.4386","0.4386","0.2924","-0.8280","-3.0636"
"1.9200","0.4583","0.4583","0.3055","-0.8035","-2.9728"
"2.0000","0.4778","0.4778","0.3185","-0.7722","-2.8573"
"2.0800","0.4978","0.4978","0.3319","-0.7415","-2.7435"
"2.1600","0.5185","0.5185","0.3457","-0.7152","-2.6464"
"2.2400","0.5370","0.5370","0.3580","-0.6897","-2.5518"
"2.3200","0.5579","0.5579","0.3719","-0.6587","-2.4371"
"2.4000","0.5785","0.5785","0.3856","-0.6288","-2.3265"
"2.4800","0.5979","0.5979","0.3986","-0.5943","-2.1991"
"2.5600","0.6190","0.6190","0.4126","-0.5612","-2.0763"
"2.6400","0.6377","0.6377","0.4251","-0.5356","-1.9816"
"2.7200","0.6579","0.6579","0.4386","-0.5059","-1.8719"
"2.8000","0.6782","0.6782","0.4521","-0.4734","-1.7515"
"2.8800","0.6975","0.6975","0.4650","-0.4456","-1.6487"
"2.9600","0.7184","0.7184","0.4789","-0.4121","-1.5246"
"3.0400","0.7391","0.7391","0.4928","-0.3781","-1.3990"
"3.1200","0.7585","0.7585","0.5057","-0.3458","-1.2793"
"3.2000","0.7781","0.7781","0.5187","-0.3133","-1.1592"
"3.2800","0.7974","0.7974","0.5316","-0.2808","-1.0389"
"3.3600","0.8186","0.8186","0.5457","-0.2461","-0.9107"
"3.4400","0.8381","0.8381","0.5588","-0.2160","-0.7992"
"3.5200","0.8569","0.8569","0.5712","-0.1811","-0.6701"
"3.6000","0.8776","0.8776","0.5851","-0.1464","-0.5416"
"3.6800","0.8985","0.8985","0.5990","-0.1120","-0.4143"
"3.7600","0.9191","0.9191","0.6127","-0.0795","-0.2940"
"3.8400","0.9388","0.9388","0.6259","-0.0459","-0.1697"
"3.9200","0.9574","0.9574","0.6383","-0.0134","-0.0496"
"4.0000","0.9779","0.9779","0.6519","0.0239","0.0885"
"4.0800","0.9979","0.9979","0.6653","0.0553","0.2045"
"4.1600","1.0184","1.0184","0.6790","0.0911","0.3371"
"4.2400","1.0392","1.0392","0.6928","0.1295","0.4790"
"4.3200","1.0586","1.0586","0.7057","0.1612","0.5963"
"4.4000","1.0787","1.0787","0.7191","0.1956","0.7238"
"4.4800","1.0983","1.0983","0.7322","0.2296","0.8497"
"4.5600","1.1176","1.1176","0.7450","0.2647","0.9793"
"4.6400","1.1381","1.1381","0.7587","0.3030","1.1209"
"4.7200","1.1570","1.1570","0.7713","0.3369","1.2465"
"4.8000","1.1773","1.1773","0.7848","0.3633","1.3443"
"4.8800","1.1988","1.1988","0.7992","0.4011","1.4840"
"4.9600","1.2187","1.2187","0.8125","0.4391","1.6248"
"5.0400","1.2387","1.2387","0.8258","0.4767","1.7640"
"5.1200","1.2571","1.2571","0.8381","0.5081","1.8798"
"5.2000","1.2775","1.2775","0.8517","0.5458","2.0196"
"5.2800","1.2982","1.2982","0.8654","0.5825","2.1552"
"5.3600","1.3178","1.3178","0.8785","0.6139","2.2714"
"5.4400","1.3386","1.3386","0.8924","0.6516","2.4108"
"5.5200","1.3597","1.3597","0.9065","0.6894","2.5506"
"5.6000","1.3784","1.3784","0.9189","0.7254","2.6840"
"5.6800","1.3983","1.3983","0.9322","0.7619","2.8189"
"5.7600","1.4177","1.4177","0.9451","0.7957","2.9442"
"5.8400","1.4383","1.4383","0.9589","0.8284","3.0650"
"5.9200","1.4579","1.4579","0.9719","0.8622","3.1902"
"6.0000","1.4767","1.4767","0.9845","0.9004","3.3313"
"6.0800","1.4980","1.4980","0.9987","0.9384","3.4723"
"6.1600","1.5192","1.5192","1.0128","0.9768","3.6143"
"6.2400","1.5383","1.5383","1.0255","1.0099","3.7365"
"6.3200","1.5581","1.5581","1.0387","1.0436","3.8613"
"6.4000","1.5772","1.5772","1.0515","1.0760","3.9813"
"6.4800","1.5982","1.5982","1.0655","1.1167","4.1318"
"6.5600","1.6188","1.6188","1.0792","1.1518","4.2616"
"6.6400","1.6379","1.6379","1.0919","1.1896","4.4016"
"6.7200","1.6589","1.6589","1.1059","1.2276","4.5423"
"6.8000","1.6785","1.6785","1.1190","1.2598","4.6614"
"6.8800","1.6990","1.6990","1.1327","1.2954","4.7928"
"6.9600","1.7187","1.7187","1.1458","1.3292","4.9180"
"7.0400","1.7376","1.7376","1.1584","1.3647","5.0495"
"7.1200","1.7577","1.7577","1.1718","1.4036","5.1932"
"7.2000","1.7775","1.7775","1.1850","1.4405","5.3298"
"7.2800","1.7972","1.7972","1.1981","1.4756","5.4596"
"7.3600","1.8188","1.8188","1.2126","1.5145","5.6035"
"7.4400","1.8384","1.8384","1.2256","1.5458","5.7194"
"7.5200","1.8586","1.8586","1.2391","1.5833","5.8582"
"7.6000","1.8781","1.8781","1.2520","1.6181","5.9871"
"7.6800","1.8976","1.8976","1.2651","1.6564","6.1285"
"7.7600","1.9176","1.9176","1.2784","1.6931","6.2644"
"7.8400","1.9380","1.9380","1.2920","1.7312","6.4056"
"7.9200","1.9583","1.9583","1.3055","1.7674","6.5394"
"8.0000","1.9795","1.9795","1.3197","1.8069","6.6854"
"8.0800","1.9981","1.9981","1.3321","1.8380","6.8004"
"8.1600","2.0187","2.0187","1.3458","1.8764","6.9426"
"8.2400","2.0381","2.0381","1.3587","1.9126","7.0767"
"8.3200","2.0578","2.0578","1.3719","1.9494","7.2129"
"8.4000","2.0783","2.0783","1.3856","1.9898","7.3623"
"8.4800","2.0968","2.0968","1.3979","2.0224","7.4829"
"8.5600","2.1179","2.1179","1.4120","2.0609","7.6253"
"8.6400","2.1391","2.1391","1.4261","2.1019","7.7771"
"8.7200","2.1585","2.1585","1.4390","2.1354","7.9010"
"8.8000","2.1781","2.1781","1.4521","2.1721","8.0368"
"8.8800","2.1979","2.1979","1.4653","2.2092","8.1739"
"8.9600","2.2180","2.2180","1.4787","2.2469","8.3136"
"9.0400","2.2386","2.2386","1.4924","2.2861","8.4585"
"9.1200","2.2571","2.2571","1.5047","2.3224","8.5929"
"9.2000","2.2786","2.2786","1.5191","2.3614","8.7374"
"9.2800","2.2989","2.2989","1.5326","2.4009","8.8832"
"9.3600","2.3189","2.3189","1.5459","2.4322","8.9991"
"9.4400","2.3381","2.3381","1.5587","2.4713","9.1440"
"9.5200","2.3579","2.3579","1.5719","2.5067","9.2748"
"9.6000","2.3778","2.3778","1.5852","2.5450","9.4167"
"9.6800","2.3988","2.3988","1.5992","2.5824","9.5548"
"9.7600","2.4172","2.4172","1.6115","2.6192","9.6909"
"9.8400","2.4380","2.4380","1.6254","2.6594","9.8397"
"9.9200","2.4582","2.4582","1.6388","2.6970","9.9789"
"10.0000","2.4783","2.4783","1.6522","2.7346","10.1180"
"10.0800","2.4985","2.4985","1.6656","2.7674","10.2394"
"10.1600","2.5174","2.5174","1.6782","2.8050","10.3784"
"10.2400","2.5382","2.5382","1.6921","2.8430","10.5192"
"10.3200","2.5581","2.5581","1.7054","2.8796","10.6545"
"10.4000","2.5781","2.5781","1.7188","2.9229","10.8149"
"10.4800","2.5990","2.5990","1.7327","2.9612","10.9563"
"10.5600","2.6188","2.6188","1.7459","2.9987","11.0952"
"10.6400","2.6388","2.6388","1.7592","3.0367","11.2356"
"10.7200","2.6586","2.6586","1.7724","3.0719","11.3659"
"10.8000","2.6773","2.6773","1.7849","3.1054","11.4899"
"10.8800","2.6979","2.6979","1.7986","3.1428","11.6285"
"10.9600","2.7174","2.7174","1.8116","3.1803","11.7671"
"11.0400","2.7381","2.7381","1.8254","3.2176","11.9052"
"11.1200","2.7585","2.7585","1.8390","3.2569","12.0505"
"11.2000","2.7784","2.7784","1.8522","3.2975","12.2006"
"11.2800","2.7986","2.7986","1.8657","3.3339","12.3355"
"11.3600","2.8187","2.8187","1.8791","3.3731","12.4805"
"11.4400","2.8375","2.8375","1.8917","3.4093","12.6146"
"11.5200","2.8584","2.8584","1.9056","3.4505","12.7669"
"11.6000","2.8775","2.8775","1.9183","3.4787","12.8713"
"11.6800","2.8987","2.8987","1.9325","3.5199","13.0237"
"11.7600","2.9197","2.9197","1.9464","3.5613","13.1768"
"11.8400","2.9387","2.9387","1.9591","3.5993","13.3174"
"11.9200","2.9584","2.9584","1.9722","3.6365","13.4551"
"12.0000","2.9778","2.9778","1.9852","3.6726","13.5885"
"12.0800","2.9977","2.9977","1.9985","3.7105","13.7288"
"12.1600","3.0185","3.0185","2.0123","3.7497","13.8740"
"12.2400","3.0370","3.0370","2.0247","3.7862","14.0088"
"12.3200","3.0579","3.0579","2.0386","3.8213","14.1388"
"12.4000","3.0782","3.0782","2.0521","3.8591","14.2787"
"12.4800","3.0981","3.0981","2.0654","3.8982","14.4234"
"12.5600","3.1188","3.1188","2.0792","3.9391","14.5748"
"12.6400","3.1379","3.1379","2.0919","3.9714","14.6943"
"12.7200","3.1582","3.1582","2.1055","4.0089","14.8330"
"12.8000","3.1781","3.1781","2.1187","4.0461","14.9705"
"12.8800","3.1973","3.1973","2.1315","4.0862","15.1191"
"12.9600","3.2185","3.2185","2.1457","4.1287","15.2763"
"13.0400","3.2391","3.2391","2.1594","4.1641","15.4071"
"13.1200","3.2584","3.2584","2.1722","4.1994","15.5378"
"13.2000","3.2783","3.2783","2.1855","4.2355","15.6715"
"13.2800","3.2972","3.2972","2.1981","4.2719","15.8062"
"13.3600","3.3183","3.3183","2.2122","4.3121","15.9546"
"13.4400","3.3382","3.3382","2.2255","4.3502","16.0956"
"13.5200","3.3574","3.3574","2.2383","4.3859","16.2277"
"13.6000","3.3777","3.3777","2.2518","4.4277","16.3826"
"13.6800","3.3982","3.3982","2.2655","4.4650","16.5205"
"13.7600","3.4189","3.4189","2.2793","4.5038","16.6641"
"13.8400","3.4389","3.4389","2.2926","4.5397","16.7968"
"13.9200","3.4573","3.4573","2.3048","4.5747","16.9265"
"14.0000","3.4779","3.4779","2.3186","4.6109","17.0603"
"14.0800","3.4978","3.4978","2.3319","4.6489","17.2009"
"14.1600","3.5187","3.5187","2.3458","4.6864","17.3397"
"14.2400","3.5394","3.5394","2.3596","4.7298","17.5004"
"14.3200","3.5583","3.5583","2.3722","4.7654","17.6319"
"14.4000","3.5789","3.5789","2.3859","4.8031","17.7716"
"14.4800","3.5986","3.5986","2.3991","4.8398","17.9073"
"14.5600","3.6177","3.6177","2.4118","4.8821","18.0638"
"14.6400","3.6380","3.6380","2.4253","4.9200","18.2040"
"14.7200","3.6569","3.6569","2.4379","4.9565","18.3389"
"14.8000","3.6775","3.6775","2.4517","4.9948","18.4809"
"14.8800","3.6993","3.6993","2.4662","5.0372","18.6378"
"14.9600","3.7183","3.7183","2.4788","5.0746","18.7760"
"15.0400","3.7385","3.7385","2.4924","5.1072","18.8965"
"15.1200","3.7573","3.7573","2.5049","5.1437","19.0316"
"15.2000","3.7774","3.7774","2.5182","5.1819","19.1732"
"15.2800","3.7981","3.7981","2.5320","5.2223","19.3224"
"15.3600","3.8181","3.8181","2.5454","5.2590","19.4582"
"15.4400","3.8388","3.8388","2.5592","5.2985","19.6045"
"15.5200","3.8596","3.8596","2.5730","5.3395","19.7562"
"15.6000","3.8781","3.8781","2.5854","5.3748","19.8868"
"15.6800","3.8980","3.8980","2.5986","5.4133","20.0291"
"15.7600","3.9176","3.9176","2.6117","5.4497","20.1639"
"15.8400","3.9383","3.9383","2.6255","5.4873","20.3031"
"15.9200","3.9581","3.9581","2.6387","5.5254","20.4439"
"16.0000","3.9768","3.9768","2.6512","5.5620","20.5794"
"16.0800","3.9980","3.9980","2.6653","5.6030","20.7312"
"16.1600","4.0193","4.0193","2.6795","5.6444","20.8842"
"16.2400","4.0386","4.0386","2.6924","5.6806","21.0183"
"16.3200","4.0582","4.0582","2.7054","5.7184","21.1579"
"16.4000","4.0772","4.0772","2.7181","5.7555","21.2952"
"16.4800","4.0979","4.0979","2.7319","5.7924","21.4318"
"16.5600","4.1184","4.1184","2.7456","5.8269","21.5597"
"16.6400","4.1379","4.1379","2.7586","5.8683","21.7128"
"16.7200","4.1587","4.1587","2.7725","5.9086","21.8618"
"16.8000","4.1786","4.1786","2.7857","5.9472","22.0046"
"16.8800","4.1988","4.1988","2.7992","5.9847","22.1435"
"16.9600","4.2188","4.2188","2.8126","6.0203","22.2750"
"17.0400","4.2376","4.2376","2.8251","6.0570","22.4110"
"17.1200","4.2578","4.2578","2.8385","6.0953","22.5528"
"17.2000","4.2775","4.2775","2.8517","6.1314","22.6861"
"17.2800","4.2971","4.2971","2.8647","6.1728","22.8394"
"17.3600","4.3189","4.3189","2.8793","6.2154","22.9971"
"17.4400","4.3385","4.3385","2.8923","6.2490","23.1213"
"17.5200","4.3586","4.3586","2.9057","6.2889","23.2688"
"17.6000","4.3780","4.3780","2.9187","6.3263","23.4071"
"17.6800","4.3974","4.3974","2.9316","6.3657","23.5529"
"17.7600","4.4180","4.4180","2.9453","6.4041","23.6952"
"17.8400","4.4380","4.4380","2.9587","6.4422","23.8363"
"17.9200","4.4583","4.4583","2.9722","6.4783","23.9695"
"18.0000","4.4792","4.4792","2.9861","6.5192","24.1211"
"18.0800","4.4983","4.4983","2.9989","6.5566","24.2593"
"18.1600","4.5186","4.5186","3.0124","6.5950","24.4014"
"18.2400","4.5384","4.5384","3.0256","6.6310","24.5346"
"18.3200","4.5577","4.5577","3.0384","6.6703","24.6802"
"18.4000","4.5776","4.5776","3.0517","6.7035","24.8028"
"18.4800","4.5968","4.5968","3.0645","6.7414","24.9431"
"18.5600","4.6183","4.6183","3.0789","6.7792","25.0830"
"18.6400","4.6391","4.6391","3.0927","6.8185","25.2285"
"18.7200","4.6583","4.6583","3.1055","6.8575","25.3727"
"18.8000","4.6781","4.6781","3.1188","6.8961","25.5155"
"18.8800","4.6977","4.6977","3.1318","6.9335","25.6538"
"18.9600","4.7178","4.7178","3.1452","6.9703","25.7903"
"19.0400","4.7386","4.7386","3.1591","7.0104","25.9385"
"19.1200","4.7571","4.7571","3.1714","7.0468","26.0732"
"19.2000","4.7785","4.7785","3.1857","7.0906","26.2351"
"19.2800","4.7990","4.7990","3.1993","7.1283","26.3748"
"19.3600","4.8190","4.8190","3.2127","7.1656","26.5127"
"19.4400","4.8381","4.8381","3.2254","7.2018","26.6467"
"19.5200","4.8577","4.8577","3.2384","7.2375","26.7788"
"19.6000","4.8780","4.8780","3.2520","7.2787","26.9312"
"19.6800","4.8982","4.8982","3.2655","7.3182","27.0775"
"19.7600","4.9167","4.9167","3.2778","7.3521","27.2029"
"19.8400","4.9382","4.9382","3.2922","7.3939","27.3574"
"19.9200","4.9584","4.9584","3.3056","7.4328","27.5014"
"20.0000","4.9789","4.9789","3.3193","7.4724","27.6478"
"20.0800","4.9987","4.9987","3.3325","7.5075","27.7777"
"20.1600","5.0177","5.0177","3.3451","7.5460","27.9201"
"20.2400","5.0383","5.0383","3.3589","7.5845","28.0625"
"20.3200","5.0577","5.0577","3.3718","7.6197","28.1928"
"20.4000","5.0779","5.0779","3.3852","7.6628","28.3523"
"20.4800","5.0989","5.0989","3.3993","7.7036","28.5033"
"20.5600","5.1189","5.1189","3.4126","7.7359","28.6229"
"20.6400","5.1390","5.1390","3.4260","7.7726","28.7585"
"20.7200","5.1586","5.1586","3.4391","7.8095","28.8950"
"20.8000","5.1772","5.1772","3.4514","7.8451","29.0268"
"20.8800","5.1976","5.1976","3.4651","7.8876","29.1841"
"20.9600","5.2170","5.2170","3.4780","7.9248","29.3218"
"21.0400","5.2381","5.2381","3.4921","7.9630","29.4632"
"21.1200","5.2586","5.2586","3.5057","8.0025","29.6094"
"21.2000","5.2784","5.2784","3.5190","8.0395","29.7461"
"21.2800","5.2985","5.2985","3.5323","8.0783","29.8897"
"21.3600","5.3188","5.3188","3.5459","8.1184","30.0380"
"21.4400","5.3374","5.3374","3.5583","8.1567","30.1797"
"21.5200","5.3581","5.3581","3.5721","8.1960","30.3251"
"21.6000","5.3773","5.3773","3.5849","8.2317","30.4573"
"21.6800","5.3990","5.3990","3.5993","8.2721","30.6067"
"21.7600","5.4193","5.4193","3.6129","8.3101","30.7472"
"21.8400","5.4385","5.4385","3.6257","8.3488","30.8905"
"21.9200","5.4582","5.4582","3.6388","8.3867","31.0309"
"22.0000","5.4779","5.4779","3.6520","8.4249","31.1723"
"22.0800","5.4979","5.4979","3.6653","8.4625","31.3112"
"22.1600","5.5188","5.5188","3.6792","8.5019","31.4569"
"22.2400","5.5371","5.5371","3.6914","8.5362","31.5839"
"22.3200","5.5578","5.5578","3.7052","8.5740","31.7239"
"22.4000","5.5785","5.5785","3.7190","8.6136","31.8702"
"22.4800","5.5985","5.5985","3.7323","8.6543","32.0208"
"22.5600","5.6190","5.6190","3.7460","8.6938","32.1672"
"22.6400","5.6379","5.6379","3.7586","8.7294","32.2987"
"22.7200","5.6578","5.6578","3.7719","8.7658","32.4334"
"22.8000","5.6780","5.6780","3.7853","8.8012","32.5645"
"22.8800","5.6977","5.6977","3.7985","8.8418","32.7147"
"22.9600","5.7186","5.7186","3.8124","8.8844","32.8722"
"23.0400","5.7394","5.7394","3.8263","8.9237","33.0175"
"23.1200","5.7586","5.7586","3.8391","8.9568","33.1402"
"23.2000","5.7783","5.7783","3.8522","8.9952","33.2823"
"23.2800","5.7973","5.7973","3.8648","9.0306","33.4134"
"23.3600","5.8181","5.8181","3.8787","9.0683","33.5526"
"23.4400","5.8380","5.8380","3.8920","9.1103","33.7080"
"23.5200","5.8573","5.8573","3.9048","9.1452","33.8374"
"23.6000","5.8777","5.8777","3.9185","9.1855","33.9864"
"23.6800","5.8983","5.8983","3.9322","9.2235","34.1271"
"23.7600","5.9188","5.9188","3.9459","9.2618","34.2687"
"23.8400","5.9389","5.9389","3.9593","9.2973","34.3999"
"23.9200","5.9571","5.9571","3.9714","9.3354","34.5410"
"24.0000","5.9780","5.9780","3.9853","9.3749","34.6870"
"24.0800","5.9979","5.9979","3.9986","9.4150","34.8356"
"24.1600","6.0185","6.0185","4.0123","9.4553","34.9845"
"24.2400","6.0392","6.0392","4.0261","9.4923","35.1214"
"24.3200","6.0585","6.0585","4.0390","9.5316","35.2670"
"24.4000","6.0784","6.0784","4.0523","9.5666","35.3963"
"24.4800","6.0988","6.0988","4.0659","9.6056","35.5407"
"24.5600","6.1179","6.1179","4.0786","9.6436","35.6814"
"24.6400","6.1379","6.1379","4.0919","9.6840","35.8307"
"24.7200","6.1572","6.1572","4.1048","9.7171","35.9533"
"24.8000","6.1774","6.1774","4.1183","9.7565","36.0992"
"24.8800","6.1990","6.1990","4.1326","9.7947","36.2403"
"24.9600","6.2185","6.2185","4.1457","9.8344","36.3872"
"25.0400","6.2388","6.2388","4.1592","9.8759","36.5410"
"25.1200","6.2574","6.2574","4.1716","9.9093","36.6646"
"25.2000","6.2773","6.2773","4.1849","9.9466","36.8024"
"25.2800","6.2981","6.2981","4.1988","9.9870","36.9521"
"25.3600","6.3182","6.3182","4.2121","10.0222","37.0823"
"25.4400","6.3387","6.3387","4.2258","10.0581","37.2151"
"25.5200","6.3594","6.3594","4.2396","10.1013","37.3749"
"25.6000","6.3780","6.3780","4.2520","10.1366","37.5053"
"25.6800","6.3981","6.3981","4.2654","10.1788","37.6615"
"25.7600","6.4175","6.4175","4.2783","10.2144","37.7934"
"25.8400","6.4386","6.4386","4.2924","10.2520","37.9323"
"25.9200","6.4582","6.4582","4.3054","10.2888","38.0687"
"26.0000","6.4768","6.4768","4.3179","10.3275","38.2117"
"26.0800","6.4979","6.4979","4.3320","10.3655","38.3522"
"26.1600","6.5189","6.5189","4.3459","10.4054","38.5001"
"26.2400","6.5386","6.5386","4.3591","10.4419","38.6350"
"26.3200","6.5583","6.5583","4.3722","10.4818","38.7827"
"26.4000","6.5773","6.5773","4.3849","10.5169","38.9123"
"26.4800","6.5982","6.5982","4.3988","10.5542","39.0504"
"26.5600","6.6184","6.6184","4.4123","10.5921","39.1908"
"26.6400","6.6374","6.6374","4.4249","10.6332","39.3427"
"26.7200","6.6587","6.6587","4.4391","10.6745","39.4955"
"26.8000","6.6785","6.6785","4.4523","10.7091","39.6235"
"26.8800","6.6991","6.6991","4.4661","10.7499","39.7747"
"26.9600","6.7190","6.7190","4.4794","10.7847","39.9035"
"27.0400","6.7378","6.7378","4.4919","10.8221","40.0418"
"27.1200","6.7578","6.7578","4.5052","10.8607","40.1848"
"27.2000","6.7776","6.7776","4.5184","10.8969","40.3185"
"27.2800","6.7966","6.7966","4.5311","10.9356","40.4616"
"27.3600","6.8189","6.8189","4.5459","10.9807","40.6285"
"27.4400","6.8384","6.8384","4.5589","11.0169","40.7627"
"27.5200","6.8589","6.8590","4.5726","11.0535","40.8980"
"27.6000","6.8780","6.8780","4.5854","11.0878","41.0248"
"27.6800","6.8974","6.8974","4.5983","11.1285","41.1754"
"27.7600","6.9180","6.9180","4.6120","11.1672","41.3186"
"27.8400","6.9381","6.9381","4.6254","11.2054","41.4599"
"27.9200","6.9582","6.9582","4.6388","11.2452","41.6074"
"28.0000","6.9791","6.9791","4.6527","11.2814","41.7411"
"28.0800","6.9983","6.9983","4.6656","11.3219","41.8912"
"28.1600","7.0187","7.0187","4.6791","11.3558","42.0165"
"28.2400","7.0383","7.0383","4.6922","11.3941","42.1582"
"28.3200","7.0578","7.0578","4.7052","11.4295","42.2891"
"28.4000","7.0775","7.0775","4.7183","11.4675","42.4298"
"28.4800","7.0962","7.0962","4.7308","11.5018","42.5565"
"28.5600","7.1183","7.1183","4.7455","11.5448","42.7156"
"28.6400","7.1396","7.1396","4.7597","11.5862","42.8689"
"28.7200","7.1585","7.1585","4.7724","11.6249","43.0123"
"28.8000","7.1782","7.1782","4.7854","11.6622","43.1501"
"28.8800","7.1978","7.1978","4.7986","11.6960","43.2751"
"28.9600","7.2183","7.2183","4.8122","11.7366","43.4255"
"29.0400","7.2390","7.2390","4.8260","11.7748","43.5668"
"29.1200","7.2572","7.2572","4.8381","11.8123","43.7056"
"29.2000","7.2786","7.2786","4.8524","11.8508","43.8481"
"29.2800","7.2992","7.2992","4.8661","11.8932","44.0047"
"29.3600","7.3191","7.3191","4.8794","11.9301","44.1415"
"29.4400","7.3380","7.3380","4.8920","11.9674","44.2793"
"29.5200","7.3576","7.3576","4.9051","12.0054","44.4201"
"29.6000","7.3779","7.3779","4.9186","12.0423","44.5567"
"29.6800","7.3982","7.3982","4.9321","12.0809","44.6991"
"29.7600","7.4170","7.4170","4.9447","12.1171","44.8333"
"29.8400","7.4385","7.4385","4.9590","12.1589","44.9878"
"29.9200","7.4581","7.4581","4.9720","12.1973","45.1299"
"30.0000","7.4784","7.4784","4.9856","12.2360","45.2731"
"30.0800","7.4986","7.4986","4.9990","12.2727","45.4091"
"30.1600","7.5178","7.5178","5.0118","12.3105","45.5488"
"30.2400","7.5380","7.5380","5.0254","12.3496","45.6934"
"30.3200","7.5579","7.5579","5.0386","12.3853","45.8254"
"30.4000","7.5778","7.5778","5.0519","12.4230","45.9650"
"30.4800","7.5990","7.5990","5.0660","12.4647","46.1194"
"30.5600","7.6191","7.6191","5.0794","12.5010","46.2537"
"30.6400","7.6390","7.6390","5.0926","12.5411","46.4020"
"30.7200","7.6587","7.6587","5.1058","12.5787","46.5411"
"30.8000","7.6769","7.6769","5.1179","12.6155","46.6773"
"30.8800","7.6975","7.6975","5.1317","12.6537","46.8188"
"30.9600","7.7175","7.7175","5.1450","12.6898","46.9523"
"31.0400","7.7382","7.7382","5.1588","12.7301","47.1013"
"31.1200","7.7583","7.7583","5.1722","12.7688","47.2444"
"31.2000","7.7781","7.7781","5.1854","12.8056","47.3808"
"31.2800","7.7982","7.7982","5.1988","12.8439","47.5224"
"31.3600","7.8185","7.8185","5.2123","12.8816","47.6620"
"31.4400","7.8376","7.8376","5.2251","12.9179","47.7961"
"31.5200","7.8583","7.8583","5.2389","12.9590","47.9481"
"31.6000","7.8774","7.8774","5.2516","12.9942","48.0787"
"31.6800","7.8989","7.8989","5.2659","13.0345","48.2278"
"31.7600","7.9194","7.9194","5.2796","13.0751","48.3777"
"31.8400","7.9386","7.9386","5.2924","13.1138","48.5211"
"31.9200","7.9582","7.9582","5.3054","13.1501","48.6552"
"32.0000","7.9776","7.9776","5.3184","13.1874","48.7935"
"32.0800","7.9977","7.9977","5.3318","13.2240","48.9287"
"32.1600","8.0185","8.0185","5.3457","13.2614","49.0671"
"32.2400","8.0373","8.0373","5.3582","13.2982","49.2032"
"32.3200","8.0579","8.0579","5.3719","13.3382","49.3513"
"32.4000","8.0784","8.0784","5.3856","13.3790","49.5022"
"32.4800","8.0979","8.0979","5.3986","13.4154","49.6370"
"32.5600","8.1185","8.1185","5.4123","13.4557","49.7861"
"32.6400","8.1377","8.1377","5.4251","13.4918","49.9198"
"32.7200","8.1582","8.1582","5.4388","13.5291","50.0576"
"32.8000","8.1783","8.1783","5.4522","13.5661","50.1945"
"32.8800","8.1978","8.1978","5.4652","13.6040","50.3348"
"32.9600","8.2190","8.2190","5.4793","13.6462","50.4911"
"33.0400","8.2390","8.2390","5.4927","13.6866","50.6406"
"33.1200","8.2586","8.2586","5.5057","13.7191","50.7606"
"33.2000","8.2784","8.2784","5.5189","13.7597","50.9107"
"33.2800","8.2974","8.2974","5.5316","13.7968","51.0481"
"33.3600","8.3187","8.3187","5.5458","13.8368","51.1962"
"33.4400","8.3379","8.3379","5.5586","13.8704","51.3206"
"33.5200","8.3572","8.3572","5.5714","13.9095","51.4651"
"33.6000","8.3774","8.3774","5.5849","13.9470","51.6037"
"33.6800","8.3984","8.3984","5.5989","13.9870","51.7517"
"33.7600","8.4190","8.4190","5.6127","14.0243","51.8899"
"33.8400","8.4391","8.4391","5.6260","14.0625","52.0312"
"33.9200","8.4570","8.4570","5.6380","14.0982","52.1635"
"34.0000","8.4778","8.4778","5.6519","14.1395","52.3162"
"34.0800","8.4978","8.4978","5.6652","14.1779","52.4583"
"34.1600","8.5189","8.5189","5.6792","14.2127","52.5871"
"34.2400","8.5391","8.5391","5.6928","14.2539","52.7396"
"34.3200","8.5585","8.5585","5.7057","14.2912","52.8773"
"34.4000","8.5787","8.5787","5.7192","14.3286","53.0158"
"34.4800","8.5985","8.5985","5.7323","14.3674","53.1594"
"34.5600","8.6180","8.6180","5.7454","14.4054","53.3000"
"34.6400","8.6380","8.6380","5.7586","14.4452","53.4473"
"34.7200","8.6570","8.6570","5.7713","14.4782","53.5694"
"34.8000","8.6775","8.6775","5.7850","14.5182","53.7173"
"34.8800","8.6989","8.6989","5.7993","14.5574","53.8625"
"34.9600","8.7183","8.7183","5.8122","14.5972","54.0095"
"35.0400","8.7390","8.7390","5.8260","14.6358","54.1524"
"35.1200","8.7578","8.7578","5.8385","14.6726","54.2887"
"35.2000","8.7775","8.7775","5.8517","14.7088","54.4227"
"35.2800","8.7978","8.7978","5.8652","14.7510","54.5788"
"35.3600","8.8180","8.8180","5.8787","14.7896","54.7217"
"35.4400","8.8389","8.8389","5.8926","14.8282","54.8645"
"35.5200","8.8596","8.8596","5.9064","14.8656","55.0029"
"35.6000","8.8782","8.8782","5.9188","14.9016","55.1360"
"35.6800","8.8983","8.8983","5.9322","14.9414","55.2830"
"35.7600","8.9175","8.9175","5.9450","14.9755","55.4094"
"35.8400","8.9378","8.9378","5.9586","15.0150","55.5555"
"35.9200","8.9579","8.9579","5.9720","15.0508","55.6879"
"36.0000","8.9770","8.9770","5.9846","15.0893","55.8305"
"36.0800","8.9980","8.9980","5.9987","15.1281","55.9738"
"36.1600","9.0189","9.0189","6.0126","15.1693","56.1264"
"36.2400","9.0387","9.0387","6.0258","15.2082","56.2704"
"36.3200","9.0584","9.0584","6.0389","15.2453","56.4075"
"36.4000","9.0771","9.0771","6.0514","15.2805","56.5377"
"36.4800","9.0978","9.0978","6.0652","15.3184","56.6781"
"36.5600","9.1185","9.1185","6.0790","15.3598","56.8311"
"36.6400","9.1379","9.1379","6.0919","15.3952","56.9624"
"36.7200","9.1588","9.1588","6.1059","15.4381","57.1209"
"36.8000","9.1784","9.1784","6.1189","15.4732","57.2507"
"36.8800","9.1991","9.1991","6.1327","15.5106","57.3892"
"36.9600","9.2186","9.2186","6.1457","15.5486","57.5299"
"37.0400","9.2373","9.2373","6.1582","15.5856","57.6668"
"37.1200","9.2576","9.2576","6.1717","15.6247","57.8114"
"37.2000","9.2775","9.2775","6.1850","15.6607","57.9447"
"37.2800","9.2973","9.2973","6.1982","15.7005","58.0917"
"37.3600","9.3192","9.3192","6.2128","15.7421","58.2456"
"37.4400","9.3385","9.3385","6.2257","15.7777","58.3775"
"37.5200","9.3588","9.3588","6.2392","15.8158","58.5186"
"37.6000","9.3783","9.3783","6.2522","15.8535","58.6580"
"37.6800","9.3976","9.3976","6.2650","15.8902","58.7937"
"37.7600","9.4179","9.4179","6.2786","15.9300","58.9411"
"37.8400","9.4379","9.4379","6.2919","15.9658","59.0735"
"37.9200","9.4583","9.4583","6.3055","16.0064","59.2236"
"38.0000","9.4794","9.4794","6.3196","16.0442","59.3635"
"38.0800","9.4984","9.4984","6.3323","16.0840","59.5109"
"38.1600","9.5183","9.5183","6.3455","16.1205","59.6458"
"38.2400","9.5381","9.5381","6.3588","16.1574","59.7825"
"38.3200","9.5574","9.5574","6.3716","16.1928","59.9134"
"38.4000","9.5772","9.5772","6.3848","16.2324","60.0598"
"38.4800","9.5968","9.5968","6.3979","16.2689","60.1951"
"38.5600","9.6186","9.6186","6.4124","16.3079","60.3392"
"38.6400","9.6391","9.6391","6.4261","16.3473","60.4851"
"38.7200","9.6584","9.6584","6.4389","16.3851","60.6248"
"38.8000","9.6780","9.6780","6.4520","16.4234","60.7667"
"38.8800","9.6976","9.6976","6.4651","16.4594","60.8998"
"38.9600","9.7182","9.7182","6.4788","16.4999","61.0498"
"39.0400","9.7387","9.7387","6.4924","16.5390","61.1944"
"39.1200","9.7572","9.7572","6.5048","16.5761","61.3314"
"39.2000","9.7791","9.7791","6.5194","16.6180","61.4868"
"39.2800","9.7988","9.7988","6.5325","16.6569","61.6306"
"39.3600","9.8189","9.8189","6.5460","16.6948","61.7707"
"39.4400","9.8384","9.8384","6.5589","16.7325","61.9102"
"39.5200","9.8577","9.8577","6.5718","16.7666","62.0364"
"39.6000","9.8778","9.8778","6.5852","16.8040","62.1748"
"39.6800","9.8983","9.8983","6.5988","16.8430","62.3190"
"39.7600","9.9171","9.9171","6.6114","16.8819","62.4631"
"39.8400","9.9383","9.9383","6.6255","16.9225","62.6134"
"39.9200","9.9581","9.9581","6.6388","16.9587","62.7470"
"40.0000","9.9786","9.9786","6.6524","16.9975","62.8907"
"40.0800","9.9985","9.9985","6.6656","17.0347","63.0283"
"40.1600","10.0176","10.0176","6.6784","17.0731","63.1703"
"40.2400","10.0382","10.0382","6.6922","17.1125","63.3162"
"40.3200","10.0581","10.0581","6.7054","17.1482","63.4484"
"40.4000","10.0779","10.0779","6.7186","17.1885","63.5973"
"40.4800","10.0988","10.0988","6.7325","17.2331","63.7624"
"40.5600","10.1188","10.1188","6.7459","17.2654","63.8820"
"40.6400","10.1384","10.1384","6.7590","17.3024","64.0189"
"40.7200","10.1582","10.1582","6.7721","17.3399","64.1575"
"40.8000","10.1774","10.1774","6.7849","17.3795","64.3043"
"40.8800","10.1983","10.1983","6.7989","17.4170","64.4429"
"40.9600","10.2173","10.2173","6.8115","17.4529","64.5758"
"41.0400","10.2379","10.2379","6.8253","17.4894","64.7108"
"41.1200","10.2586","10.2586","6.8391","17.5319","64.8679"
"41.2000","10.2782","10.2782","6.8522","17.5702","65.0097"
"41.2800","10.2983","10.2983","6.8655","17.6101","65.1576"
"41.3600","10.3187","10.3187","6.8791","17.6481","65.2980"
"41.4400","10.3376","10.3376","6.8917","17.6855","65.4365"
"41.5200","10.3582","10.3582","6.9055","17.7257","65.5851"
"41.6000","10.3771","10.3771","6.9181","17.7576","65.7032"
"41.6800","10.3990","10.3990","6.9327","17.8002","65.8606"
"41.7600","10.4192","10.4192","6.9461","17.8393","66.0055"
"41.8400","10.4385","10.4385","6.9590","17.8781","66.1491"
"41.9200","10.4582","10.4582","6.9721","17.9160","66.2891"
"42.0000","10.4780","10.4780","6.9853","17.9543","66.4309"
"42.0800","10.4979","10.4979","6.9986","17.9935","66.5760"
"42.1600","10.5185","10.5185","7.0123","18.0315","66.7167"
"42.2400","10.5371","10.5371","7.0248","18.0650","66.8404"
"42.3200","10.5580","10.5580","7.0387","18.1044","66.9863"
"42.4000","10.5784","10.5784","7.0523","18.1433","67.1304"
"42.4800","10.5982","10.5982","7.0655","18.1816","67.2719"
"42.5600","10.6188","10.6188","7.0792","18.2190","67.4104"
"42.6400","10.6375","10.6375","7.0917","18.2540","67.5400"
"42.7200","10.6580","10.6580","7.1053","18.2926","67.6827"
"42.8000","10.6782","10.6782","7.1188","18.3314","67.8261"
"42.8800","10.6977","10.6977","7.1318","18.3688","67.9646"
"42.9600","10.7186","10.7186","7.1458","18.4120","68.1244"
"43.0400","10.7394","10.7394","7.1596","18.4522","68.2731"
"43.1200","10.7587","10.7587","7.1725","18.4861","68.3986"
"43.2000","10.7785","10.7785","7.1856","18.5228","68.5342"
"43.2800","10.7969","10.7969","7.1980","18.5568","68.6601"
"43.3600","10.8181","10.8181","7.2120","18.5944","68.7992"
"43.4400","10.8381","10.8381","7.2254","18.6365","68.9551"
"43.5200","10.8576","10.8576","7.2384","18.6755","69.0993"
"43.6000","10.8778","10.8778","7.2519","18.7149","69.2453"
"43.6800","10.8983","10.8983","7.2655","18.7528","69.3855"
"43.7600","10.9191","10.9191","7.2794","18.7928","69.5334"
"43.8400","10.9391","10.9391","7.2928","18.8302","69.6718"
"43.9200","10.9572","10.9572","7.3048","18.8638","69.7962"
"44.0000","10.9776","10.9776","7.3184","18.9019","69.9369"
"44.0800","10.9979","10.9979","7.3319","18.9429","70.0888"
"44.1600","11.0184","11.0184","7.3456","18.9823","70.2345"
"44.2400","11.0395","11.0395","7.3596","19.0222","70.3823"
"44.3200","11.0584","11.0584","7.3722","19.0582","70.5153"
"44.4000","11.0788","11.0788","7.3859","19.0975","70.6608"
"44.4800","11.0984","11.0984","7.3990","19.1348","70.7987"
"44.5600","11.1178","11.1178","7.4119","19.1724","70.9377"
"44.6400","11.1378","11.1378","7.4252","19.2093","71.0743"
"44.7200","11.1570","11.1570","7.4380","19.2449","71.2061"
"44.8000","11.1773","11.1773","7.4515","19.2840","71.3509"
"44.8800","11.1991","11.1991","7.4660","19.3259","71.5059"
"44.9600","11.2186","11.2186","7.4791","19.3647","71.6494"
"45.0400","11.2389","11.2389","7.4926","19.4054","71.8000"
"45.1200","11.2571","11.2571","7.5048","19.4377","71.9196"
"45.2000","11.2773","11.2773","7.5182","19.4769","72.0647"
"45.2800","11.2979","11.2979","7.5320","19.5179","72.2163"
"45.3600","11.3178","11.3178","7.5452","19.5579","72.3642"
"45.4400","11.3388","11.3388","7.5592","19.5941","72.4981"
"45.5200","11.3592","11.3592","7.5728","19.6344","72.6474"
"45.6000","11.3778","11.3778","7.5852","19.6686","72.7738"
"45.6800","11.3980","11.3980","7.5987","19.7113","72.9319"
"45.7600","11.4181","11.4181","7.6121","19.7496","73.0734"
"45.8400","11.4386","11.4386","7.6257","19.7880","73.2158"
"45.9200","11.4581","11.4581","7.6388","19.8245","73.3507"
"46.0000","11.4768","11.4768","7.6512","19.8600","73.4818"
"46.0800","11.4979","11.4979","7.6653","19.9017","73.6365"
"46.1600","11.5191","11.5191","7.6794","19.9419","73.7851"
"46.2400","11.5386","11.5386","7.6924","19.9758","73.9106"
"46.3200","11.5586","11.5586","7.7057","20.0161","74.0596"
"46.4000","11.5775","11.5775","7.7183","20.0514","74.1902"
"46.4800","11.5979","11.5979","7.7319","20.0911","74.3372"
"46.5600","11.6187","11.6187","7.7458","20.1329","74.4918"
"46.6400","11.6378","11.6378","7.7585","20.1687","74.6241"
"46.7200","11.6588","11.6588","7.7725","20.2097","74.7758"
"46.8000","11.6782","11.6782","7.7855","20.2452","74.9071"
"46.8800","11.6991","11.6991","7.7994","20.2848","75.0536"
"46.9600","11.7187","11.7187","7.8125","20.3208","75.1869"
"47.0400","11.7377","11.7377","7.8251","20.3587","75.3273"
"47.1200","11.7580","11.7580","7.8386","20.3995","75.4781"
"47.2000","11.7778","11.7778","7.8519","20.4382","75.6213"
"47.2800","11.7970","11.7970","7.8647","20.4742","75.7547"
"47.3600","11.8190","11.8190","7.8793","20.5178","75.9160"
"47.4400","11.8384","11.8384","7.8923","20.5538","76.0489"
"47.5200","11.8588","11.8588","7.9058","20.5917","76.1894"
"47.6000","11.8779","11.8779","7.9186","20.6260","76.3163"
"47.6800","11.8975","11.8975","7.9317","20.6644","76.4581"
"47.7600","11.9182","11.9182","7.9454","20.7071","76.6161"
"47.8400","11.9381","11.9381","7.9587","20.7423","76.7466"
"47.9200","11.9583","11.9583","7.9722","20.7826","76.8957"
"48.0000","11.9791","11.9791","7.9861","20.8207","77.0367"
"48.0800","11.9981","11.9981","7.9987","20.8583","77.1758"
"48.1600","12.0183","12.0183","8.0122","20.8972","77.3198"
"48.2400","12.0381","12.0381","8.0254","20.9353","77.4608"
"48.3200","12.0579","12.0579","8.0386","20.9727","77.5989"
"48.4000","12.0783","12.0783","8.0522","21.0131","77.7486"
"48.4800","12.0966","12.0966","8.0644","21.0465","77.8722"
"48.5600","12.1181","12.1181","8.0787","21.0872","78.0225"
"48.6400","12.1393","12.1393","8.0929","21.1295","78.1791"
"48.7200","12.1582","12.1582","8.1055","21.1671","78.3184"
"48.8000","12.1782","12.1782","8.1188","21.2062","78.4629"
"48.8800","12.1982","12.1982","8.1321","21.2435","78.6008"
"48.9600","12.2183","12.2183","8.1455","21.2820","78.7433"
"49.0400","12.2385","12.2385","8.1590","21.3182","78.8772"
"49.1200","12.2570","12.2570","8.1713","21.3560","79.0172"
"49.2000","12.2788","12.2788","8.1858","21.3977","79.1714"
"49.2800","12.2990","12.2990","8.1993","21.4382","79.3214"
"49.3600","12.3190","12.3190","8.2126","21.4755","79.4592"
"49.4400","12.3381","12.3381","8.2254","21.5138","79.6011"
"49.5200","12.3579","12.3579","8.2386","21.5483","79.7288"
"49.6000","12.3780","12.3780","8.2520","21.5862","79.8690"
"49.6800","12.3983","12.3983","8.2656","21.6264","80.0178"
"49.7600","12.4168","12.4168","8.2778","21.6621","80.1497"
"49.8400","12.4377","12.4377","8.2918","21.7026","80.2998"
"49.9200","12.4582","12.4582","8.3055","21.7415","80.4437"
"50.0000","12.4786","12.4786","8.3191","21.7808","80.5888"
"50.0800","12.4985","12.4985","8.3323","21.8196","80.7326"
"50.1600","12.5178","12.5178","8.3452","21.8593","80.8795"
"50.2400","12.5384","12.5384","8.3590","21.8949","81.0113"
"50.3200","12.5580","12.5580","8.3720","21.9336","81.1544"
"50.4000","12.5778","12.5778","8.3852","21.9690","81.2853"
"50.4800","12.5988","12.5988","8.3992","22.0130","81.4482"
"50.5600","12.6190","12.6190","8.4127","22.0499","81.5846"
"50.6400","12.6388","12.6388","8.4259","22.0874","81.7234"
"50.7200","12.6586","12.6586","8.4391","22.1235","81.8568"
"50.8000","12.6772","12.6772","8.4514","22.1630","82.0030"
"50.8800","12.6977","12.6977","8.4651","22.2023","82.1485"
"50.9600","12.7171","12.7171","8.4781","22.2374","82.2785"
"51.0400","12.7384","12.7384","8.4923","22.2780","82.4288"
"51.1200","12.7588","12.7588","8.5059","22.3202","82.5848"
"51.2000","12.7780","12.7780","8.5187","22.3543","82.7108"
"51.2800","12.7983","12.7983","8.5322","22.3945","82.8598"
"51.3600","12.8184","12.8184","8.5456","22.4322","82.9991"
"51.4400","12.8374","12.8374","8.5582","22.4678","83.1309"
"51.5200","12.8584","12.8584","8.5723","22.5074","83.2775"
"51.6000","12.8772","12.8772","8.5848","22.5427","83.4080"
"51.6800","12.8988","12.8988","8.5992","22.5874","83.5733"
"51.7600","12.9197","12.9197","8.6132","22.6261","83.7167"
"51.8400","12.9387","12.9387","8.6258","22.6641","83.8573"
"51.9200","12.9580","12.9580","8.6386","22.7006","83.9923"
"52.0000","12.9780","12.9780","8.6520","22.7374","84.1285"
"52.0800","12.9981","12.9981","8.6654","22.7758","84.2703"
"52.1600","13.0185","13.0185","8.6790","22.8154","84.4170"
"52.2400","13.0371","13.0371","8.6914","22.8503","84.5462"
"52.3200","13.0580","13.0580","8.7053","22.8898","84.6924"
"52.4000","13.0787","13.0787","8.7192","22.9304","84.8426"
"52.4800","13.0982","13.0982","8.7321","22.9694","84.9869"
"52.5600","13.1185","13.1185","8.7456","23.0098","85.1364"
"52.6400","13.1376","13.1376","8.7584","23.0439","85.2625"
"52.7200","13.1581","13.1581","8.7720","23.0788","85.3916"
"52.8000","13.1782","13.1782","8.7854","23.1190","85.5404"
"52.8800","13.1977","13.1977","8.7985","23.1590","85.6884"
"52.9600","13.2190","13.2190","8.8127","23.1985","85.8343"
"53.0400","13.2390","13.2390","8.8260","23.2388","85.9837"
"53.1200","13.2581","13.2581","8.8387","23.2730","86.1100"
"53.2000","13.2781","13.2781","8.8521","23.3127","86.2569"
"53.2800","13.2974","13.2974","8.8649","23.3468","86.3830"
"53.3600","13.3186","13.3186","8.8791","23.3899","86.5425"
"53.4400","13.3379","13.3379","8.8919","23.4234","86.6667"
"53.5200","13.3573","13.3573","8.9049","23.4614","86.8071"
"53.6000","13.3780","13.3780","8.9187","23.5036","86.9635"
"53.6800","13.3986","13.3986","8.9324","23.5430","87.1092"
"53.7600","13.4187","13.4187","8.9458","23.5786","87.2408"
"53.8400","13.4385","13.4385","8.9590","23.6163","87.3801"
"53.9200","13.4574","13.4574","8.9716","23.6534","87.5176"
"54.0000","13.4780","13.4780","8.9854","23.6960","87.6752"
"54.0800","13.4978","13.4978","8.9985","23.7337","87.8149"
"54.1600","13.5184","13.5184","9.0123","23.7718","87.9557"
"54.2400","13.5394","13.5394","9.0263","23.8097","88.0958"
"54.3200","13.5585","13.5585","9.0390","23.8478","88.2370"
"54.4000","13.5787","13.5787","9.0524","23.8867","88.3807"
"54.4800","13.5984","13.5984","9.0656","23.9237","88.5179"
"54.5600","13.6180","13.6180","9.0787","23.9636","88.6655"
"54.6400","13.6383","13.6383","9.0922","24.0048","88.8179"
"54.7200","13.6571","13.6571","9.1048","24.0400","88.9479"
"54.8000","13.6776","13.6776","9.1184","24.0781","89.0888"
"54.8800","13.6987","13.6987","9.1325","24.1183","89.2378"
"54.9600","13.7185","13.7185","9.1456","24.1569","89.3806"
"55.0400","13.7386","13.7386","9.1590","24.1940","89.5179"
"55.1200","13.7576","13.7576","9.1717","24.2285","89.6455"
"55.2000","13.7772","13.7772","9.1848","24.2684","89.7929"
"55.2800","13.7980","13.7980","9.1986","24.3070","89.9359"
"55.3600","13.8183","13.8183","9.2122","24.3469","90.0836"
"55.4400","13.8391","13.8391","9.2261","24.3873","90.2331"
"55.5200","13.8594","13.8594","9.2396","24.4253","90.3735"
"55.6000","13.8781","13.8781","9.2520","24.4629","90.5126"
"55.6800","13.8981","13.8981","9.2654","24.5013","90.6549"
"55.7600","13.9178","13.9178","9.2785","24.5364","90.7847"
"55.8400","13.9381","13.9381","9.2921","24.5742","90.9246"
"55.9200","13.9581","13.9581","9.3054","24.6115","91.0626"
"56.0000","13.9766","13.9766","9.3178","24.6487","91.2001"
"56.0800","13.9979","13.9979","9.3319","24.6881","91.3458"
"56.1600","14.0189","14.0189","9.3459","24.7286","91.4960"
"56.2400","14.0386","14.0386","9.3591","24.7684","91.6431"
"56.3200","14.0584","14.0584","9.3722","24.8060","91.7823"
"56.4000","14.0773","14.0773","9.3849","24.8403","91.9090"
"56.4800","14.0984","14.0984","9.3989","24.8799","92.0556"
"56.5600","14.1185","14.1185","9.4124","24.9183","92.1979"
"56.6400","14.1374","14.1374","9.4249","24.9539","92.3295"
"56.7200","14.1586","14.1586","9.4390","24.9960","92.4852"
"56.8000","14.1787","14.1787","9.4524","25.0346","92.6279"
"56.8800","14.1991","14.1991","9.4661","25.0737","92.7727"
"56.9600","14.2186","14.2186","9.4791","25.1075","92.8979"
"57.0400","14.2376","14.2376","9.4917","25.1448","93.0357"
"57.1200","14.2578","14.2578","9.5052","25.1821","93.1739"
"57.2000","14.2775","14.2775","9.5183","25.2201","93.3145"
"57.2800","14.2973","14.2973","9.5315","25.2579","93.4541"
"57.3600","14.3190","14.3190","9.5460","25.3018","93.6166"
"57.4400","14.3384","14.3384","9.5590","25.3361","93.7435"
"57.5200","14.3588","14.3588","9.5725","25.3749","93.8870"
"57.6000","14.3783","14.3783","9.5855","25.4097","94.0158"
"57.6800","14.3973","14.3973","9.5982","25.4471","94.1543"
"57.7600","14.4180","14.4180","9.6120","25.4909","94.3162"
"57.8400","14.4381","14.4381","9.6254","25.5255","94.4443"
"57.9200","14.4586","14.4586","9.6391","25.5638","94.5860"
"58.0000","14.4791","14.4791","9.6528","25.6020","94.7274"
"58.0800","14.4983","14.4983","9.6655","25.6405","94.8698"
"58.1600","14.5188","14.5188","9.6792","25.6796","95.0147"
"58.2400","14.5380","14.5380","9.6920","25.7131","95.1384"
"58.3200","14.5575","14.5575","9.7050","25.7527","95.2848"
"58.4000","14.5780","14.5780","9.7187","25.7904","95.4246"
"58.4800","14.5969","14.5969","9.7312","25.8265","95.5579"
"58.5600","14.6184","14.6184","9.7456","25.8653","95.7015"
"58.6400","14.6391","14.6391","9.7594","25.9051","95.8488"
"58.7200","14.6584","14.6584","9.7723","25.9419","95.9851"
"58.8000","14.6783","14.6783","9.7855","25.9798","96.1253"
"58.8800","14.6976","14.6976","9.7984","26.0136","96.2503"
"58.9600","14.7178","14.7178","9.8119","26.0548","96.4028"
"59.0400","14.7388","14.7388","9.8259","26.0938","96.5471"
"59.1200","14.7573","14.7573","9.8382","26.1288","96.6765"
"59.2000","14.7786","14.7786","9.8524","26.1725","96.8384"
"59.2800","14.7990","14.7990","9.8660","26.2077","96.9686"
"59.3600","14.8189","14.8189","9.8793","26.2421","97.0959"
"59.4400","14.8385","14.8385","9.8923","26.2815","97.2415"
"59.5200","14.8575","14.8575","9.9050","26.3119","97.3539"
"59.6000","14.8777","14.8777","9.9185","26.3513","97.5000"
"59.6800","14.8982","14.8982","9.9321","26.3893","97.6404"
"59.7600","14.9172","14.9172","9.9448","26.4279","97.7833"
"59.8400","14.9379","14.9379","9.9586","26.4676","97.9302"
"59.9200","14.9580","14.9580","9.9720","26.5054","98.0702"
"60.0000","14.9784","14.9784","9.9856","26.5406","98.2003"
"60.0800","14.9984","14.9984","9.9989","26.5780","98.3386"
"60.0870","15.0001","15.0001","10.0001","26.5803","98.3472"