File: data/instron_tests/metamaterial_samples/539_BULK_m2.is_comp_Exports/539_BULK_m2_2_1.csv
Sample text inputs : Sample No.,Sample choice input : Leading Direction,Sample choice input : Mode,Specimen choice input : Direction,Specimen properties : Height,Specimen properties : Thickness,Specimen properties : Width,Test : Rate 1
,,,,(mm),(mm),(mm),(mm/min)
"509","Bulk","Bimode","1","150.00","25.00","150.00","15.00"

Time,Displacement,Compressive displacement,Compressive strain (Displacement),Compressive stress,Force
(s),(mm),(mm),(%),(kPa),(N)
"0.0000","-0.0002","-0.0002","-0.0001","-0.2962","-1.0959"
"0.0800","0.0011","0.0011","0.0007","-0.2918","-1.0795"
"0.1600","0.0094","0.0094","0.0063","-0.2573","-0.9520"
"0.2400","0.0296","0.0296","0.0197","-0.1848","-0.6838"
"0.3200","0.0498","0.0498","0.0332","-0.1155","-0.4273"
"0.4000","0.0672","0.0672","0.0448","-0.0564","-0.2085"
"0.4800","0.0878","0.0878","0.0585","0.0080","0.0297"
"0.5600","0.1100","0.1100","0.0733","0.0727","0.2688"
"0.6400","0.1296","0.1296","0.0864","0.1255","0.4645"
"0.7200","0.1493","0.1493","0.0995","0.1760","0.6512"
"0.8000","0.1682","0.1682","0.1122","0.2224","0.8227"
"0.8800","0.1890","0.1890","0.1260","0.2725","1.0081"
"0.9600","0.2092","0.2092","0.1395","0.3198","1.1831"
"1.0400","0.2284","0.2284","0.1523","0.3662","1.3550"
"1.1200","0.2490","0.2490","0.1660","0.4156","1.5378"
"1.2000","0.2694","0.2694","0.1796","0.4609","1.7053"
"1.2800","0.2894","0.2894","0.1929","0.5068","1.8751"
"1.3600","0.3097","0.3097","0.2065","0.5494","2.0327"
"1.4400","0.3286","0.3286","0.2191","0.5917","2.1893"
"1.5200","0.3494","0.3494","0.2329","0.6311","2.3352"
"1.6000","0.3693","0.3693","0.2462","0.6768","2.5042"
"1.6800","0.3884","0.3884","0.2589","0.7135","2.6400"
"1.7600","0.4097","0.4097","0.2731","0.7670","2.8377"
"1.8400","0.4302","0.4302","0.2868","0.8129","3.0077"
"1.9200","0.4503","0.4503","0.3002","0.8558","3.1664"
"2.0000","0.4695","0.4695","0.3130","0.9001","3.3305"
"2.0800","0.4883","0.4883","0.3255","0.9423","3.4866"
"2.1600","0.5090","0.5090","0.3394","0.9950","3.6814"
"2.2400","0.5291","0.5291","0.3527","1.0417","3.8544"
"2.3200","0.5484","0.5484","0.3656","1.0839","4.0106"
"2.4000","0.5690","0.5690","0.3793","1.1357","4.2022"
"2.4800","0.5889","0.5889","0.3926","1.1835","4.3788"
"2.5600","0.6102","0.6102","0.4068","1.2300","4.5511"
"2.6400","0.6295","0.6295","0.4196","1.2806","4.7384"
"2.7200","0.6486","0.6486","0.4324","1.3327","4.9310"
"2.8000","0.6686","0.6686","0.4457","1.3843","5.1218"
"2.8800","0.6887","0.6887","0.4592","1.4369","5.3166"
"2.9600","0.7092","0.7092","0.4728","1.4914","5.5182"
"3.0400","0.7311","0.7311","0.4874","1.5434","5.7107"
"3.1200","0.7494","0.7494","0.4996","1.5970","5.9089"
"3.2000","0.7694","0.7694","0.5129","1.6514","6.1101"
"3.2800","0.7888","0.7888","0.5258","1.7053","6.3094"
"3.3600","0.8091","0.8091","0.5394","1.7603","6.5130"
"3.4400","0.8295","0.8295","0.5530","1.8161","6.7196"
"3.5200","0.8481","0.8481","0.5654","1.8577","6.8734"
"3.6000","0.8688","0.8688","0.5792","1.9209","7.1074"
"3.6800","0.8897","0.8897","0.5932","1.9806","7.3281"
"3.7600","0.9096","0.9096","0.6064","2.0384","7.5421"
"3.8400","0.9297","0.9297","0.6198","2.0957","7.7541"
"3.9200","0.9489","0.9489","0.6326","2.1448","7.9357"
"4.0000","0.9687","0.9687","0.6458","2.1978","8.1319"
"4.0800","0.9896","0.9896","0.6597","2.2608","8.3650"
"4.1600","1.0084","1.0084","0.6723","2.3148","8.5646"
"4.2400","1.0299","1.0299","0.6866","2.3777","8.7975"
"4.3200","1.0500","1.0500","0.7000","2.4361","9.0136"
"4.4000","1.0701","1.0701","0.7134","2.4913","9.2179"
"4.4800","1.0889","1.0889","0.7259","2.5482","9.4285"
"4.5600","1.1087","1.1087","0.7391","2.6044","9.6361"
"4.6400","1.1293","1.1293","0.7529","2.6689","9.8750"
"4.7200","1.1493","1.1493","0.7662","2.7266","10.0886"
"4.8000","1.1679","1.1679","0.7786","2.7866","10.3103"
"4.8800","1.1893","1.1893","0.7929","2.8479","10.5374"
"4.9600","1.2094","1.2094","0.8063","2.9106","10.7692"
"5.0400","1.2302","1.2302","0.8201","2.9734","11.0017"
"5.1200","1.2490","1.2490","0.8327","3.0313","11.2158"
"5.2000","1.2681","1.2681","0.8454","3.0889","11.4288"
"5.2800","1.2891","1.2891","0.8594","3.1552","11.6743"
"5.3600","1.3097","1.3097","0.8731","3.2190","11.9103"
"5.4400","1.3294","1.3294","0.8862","3.2735","12.1119"
"5.5200","1.3503","1.3503","0.9002","3.3422","12.3662"
"5.6000","1.3692","1.3692","0.9128","3.3983","12.5736"
"5.6800","1.3897","1.3897","0.9264","3.4653","12.8215"
"5.7600","1.4097","1.4097","0.9398","3.5274","13.0514"
"5.8400","1.4286","1.4286","0.9524","3.5882","13.2763"
"5.9200","1.4493","1.4493","0.9662","3.6540","13.5200"
"6.0000","1.4677","1.4677","0.9785","3.7058","13.7116"
"6.0800","1.4889","1.4889","0.9926","3.7738","13.9631"
"6.1600","1.5101","1.5101","1.0067","3.8432","14.2197"
"6.2400","1.5296","1.5296","1.0197","3.9089","14.4628"
"6.3200","1.5490","1.5490","1.0327","3.9718","14.6955"
"6.4000","1.5691","1.5691","1.0461","4.0385","14.9426"
"6.4800","1.5882","1.5882","1.0588","4.1023","15.1784"
"6.5600","1.6096","1.6096","1.0731","4.1776","15.4570"
"6.6400","1.6287","1.6287","1.0858","4.2397","15.6868"
"6.7200","1.6502","1.6502","1.1001","4.3099","15.9467"
"6.8000","1.6701","1.6701","1.1134","4.3697","16.1681"
"6.8800","1.6895","1.6895","1.1264","4.4342","16.4066"
"6.9600","1.7091","1.7091","1.1394","4.4969","16.6384"
"7.0400","1.7294","1.7294","1.1529","4.5644","16.8885"
"7.1200","1.7490","1.7490","1.1660","4.6309","17.1342"
"7.2000","1.7689","1.7689","1.1793","4.6952","17.3721"
"7.2800","1.7879","1.7879","1.1919","4.7624","17.6210"
"7.3600","1.8094","1.8094","1.2063","4.8361","17.8937"
"7.4400","1.8302","1.8302","1.2202","4.9073","18.1571"
"7.5200","1.8493","1.8493","1.2329","4.9700","18.3889"
"7.6000","1.8692","1.8692","1.2461","5.0351","18.6299"
"7.6800","1.8884","1.8884","1.2589","5.0941","18.8483"
"7.7600","1.9095","1.9095","1.2730","5.1652","19.1111"
"7.8400","1.9296","1.9296","1.2864","5.2354","19.3709"
"7.9200","1.9486","1.9486","1.2990","5.2979","19.6023"
"8.0000","1.9690","1.9690","1.3127","5.3723","19.8775"
"8.0800","1.9899","1.9899","1.3266","5.4403","20.1291"
"8.1600","2.0098","2.0098","1.3399","5.5055","20.3704"
"8.2400","2.0301","2.0301","1.3534","5.5728","20.6195"
"8.3200","2.0484","2.0484","1.3656","5.6354","20.8508"
"8.4000","2.0697","2.0697","1.3798","5.7089","21.1228"
"8.4800","2.0885","2.0885","1.3923","5.7696","21.3475"
"8.5600","2.1082","2.1082","1.4055","5.8357","21.5919"
"8.6400","2.1294","2.1294","1.4196","5.9096","21.8655"
"8.7200","2.1500","2.1500","1.4333","5.9755","22.1094"
"8.8000","2.1693","2.1693","1.4462","6.0343","22.3269"
"8.8800","2.1896","2.1896","1.4598","6.1050","22.5886"
"8.9600","2.2084","2.2084","1.4722","6.1699","22.8285"
"9.0400","2.2294","2.2294","1.4862","6.2426","23.0975"
"9.1200","2.2487","2.2487","1.4991","6.3067","23.3349"
"9.2000","2.2693","2.2693","1.5129","6.3759","23.5908"
"9.2800","2.2901","2.2901","1.5268","6.4498","23.8643"
"9.3600","2.3097","2.3097","1.5398","6.5151","24.1060"
"9.4400","2.3298","2.3298","1.5532","6.5856","24.3667"
"9.5200","2.3497","2.3497","1.5665","6.6533","24.6172"
"9.6000","2.3686","2.3686","1.5791","6.7175","24.8549"
"9.6800","2.3888","2.3888","1.5925","6.7907","25.1256"
"9.7600","2.4086","2.4086","1.6057","6.8553","25.3647"
"9.8400","2.4290","2.4290","1.6193","6.9213","25.6088"
"9.9200","2.4500","2.4500","1.6333","6.9948","25.8808"
"10.0000","2.4686","2.4686","1.6457","7.0621","26.1299"
"10.0800","2.4895","2.4895","1.6597","7.1344","26.3973"
"10.1600","2.5090","2.5090","1.6726","7.2011","26.6440"
"10.2400","2.5293","2.5293","1.6862","7.2731","26.9104"
"10.3200","2.5486","2.5486","1.6991","7.3387","27.1531"
"10.4000","2.5683","2.5683","1.7122","7.4043","27.3959"
"10.4800","2.5900","2.5900","1.7266","7.4847","27.6932"
"10.5600","2.6107","2.6107","1.7405","7.5571","27.9612"
"10.6400","2.6297","2.6297","1.7532","7.6219","28.2010"
"10.7200","2.6495","2.6495","1.7663","7.6922","28.4613"
"10.8000","2.6686","2.6686","1.7791","7.7567","28.6997"
"10.8800","2.6890","2.6890","1.7927","7.8253","28.9536"
"10.9600","2.7094","2.7094","1.8063","7.8961","29.2154"
"11.0400","2.7285","2.7285","1.8190","7.9645","29.4688"
"11.1200","2.7493","2.7493","1.8328","8.0347","29.7284"
"11.2000","2.7695","2.7695","1.8463","8.1065","29.9939"
"11.2800","2.7894","2.7894","1.8596","8.1762","30.2520"
"11.3600","2.8099","2.8099","1.8733","8.2445","30.5046"
"11.4400","2.8287","2.8287","1.8858","8.3093","30.7445"
"11.5200","2.8492","2.8492","1.8995","8.3800","31.0059"
"11.6000","2.8694","2.8694","1.9129","8.4507","31.2674"
"11.6800","2.8887","2.8887","1.9258","8.5191","31.5206"
"11.7600","2.9102","2.9102","1.9402","8.5959","31.8049"
"11.8400","2.9296","2.9296","1.9531","8.6606","32.0443"
"11.9200","2.9499","2.9499","1.9666","8.7309","32.3042"
"12.0000","2.9700","2.9700","1.9800","8.8015","32.5657"
"12.0800","2.9886","2.9886","1.9924","8.8644","32.7981"
"12.1600","3.0090","3.0090","2.0060","8.9339","33.0553"
"12.2400","3.0288","3.0288","2.0192","9.0001","33.3005"
"12.3200","3.0485","3.0485","2.0323","9.0702","33.5597"
"12.4000","3.0692","3.0692","2.0461","9.1416","33.8239"
"12.4800","3.0892","3.0892","2.0595","9.2105","34.0788"
"12.5600","3.1099","3.1099","2.0733","9.2836","34.3493"
"12.6400","3.1297","3.1297","2.0864","9.3512","34.5993"
"12.7200","3.1485","3.1485","2.0990","9.4175","34.8446"
"12.8000","3.1686","3.1686","2.1124","9.4865","35.1000"
"12.8800","3.1883","3.1883","2.1255","9.5538","35.3491"
"12.9600","3.2091","3.2091","2.1394","9.6240","35.6089"
"13.0400","3.2308","3.2308","2.1539","9.6991","35.8866"
"13.1200","3.2493","3.2493","2.1662","9.7645","36.1287"
"13.2000","3.2693","3.2693","2.1795","9.8314","36.3761"
"13.2800","3.2887","3.2887","2.1925","9.8968","36.6183"
"13.3600","3.3089","3.3089","2.2059","9.9676","36.8801"
"13.4400","3.3293","3.3293","2.2195","10.0357","37.1323"
"13.5200","3.3481","3.3481","2.2321","10.1006","37.3722"
"13.6000","3.3690","3.3690","2.2460","10.1717","37.6354"
"13.6800","3.3897","3.3897","2.2598","10.2438","37.9021"
"13.7600","3.4096","3.4096","2.2731","10.3155","38.1673"
"13.8400","3.4297","3.4297","2.2865","10.3837","38.4196"
"13.9200","3.4489","3.4489","2.2993","10.4472","38.6546"
"14.0000","3.4689","3.4689","2.3126","10.5169","38.9127"
"14.0800","3.4899","3.4899","2.3266","10.5866","39.1703"
"14.1600","3.5087","3.5087","2.3391","10.6526","39.4146"
"14.2400","3.5301","3.5301","2.3534","10.7277","39.6926"
"14.3200","3.5498","3.5498","2.3665","10.7929","39.9339"
"14.4000","3.5697","3.5697","2.3798","10.8625","40.1913"
"14.4800","3.5892","3.5892","2.3928","10.9291","40.4375"
"14.5600","3.6091","3.6091","2.4061","10.9972","40.6896"
"14.6400","3.6293","3.6293","2.4195","11.0645","40.9386"
"14.7200","3.6493","3.6493","2.4329","11.1324","41.1898"
"14.8000","3.6676","3.6676","2.4451","11.1947","41.4205"
"14.8800","3.6891","3.6891","2.4594","11.2711","41.7030"
"14.9600","3.7095","3.7095","2.4730","11.3390","41.9541"
"15.0400","3.7301","3.7301","2.4867","11.4068","42.2050"
"15.1200","3.7495","3.7495","2.4996","11.4719","42.4460"
"15.2000","3.7681","3.7681","2.5120","11.5335","42.6738"
"15.2800","3.7887","3.7887","2.5258","11.6043","42.9358"
"15.3600","3.8093","3.8093","2.5395","11.6750","43.1975"
"15.4400","3.8293","3.8293","2.5529","11.7413","43.4429"
"15.5200","3.8505","3.8505","2.5670","11.8145","43.7137"
"15.6000","3.8696","3.8696","2.5797","11.8771","43.9454"
"15.6800","3.8894","3.8894","2.5930","11.9435","44.1909"
"15.7600","3.9094","3.9094","2.6063","12.0075","44.4277"
"15.8400","3.9285","3.9285","2.6190","12.0727","44.6691"
"15.9200","3.9491","3.9491","2.6327","12.1407","44.9207"
"16.0000","3.9681","3.9681","2.6454","12.2049","45.1580"
"16.0800","3.9888","3.9888","2.6592","12.2731","45.4106"
"16.1600","4.0099","4.0099","2.6733","12.3484","45.6890"
"16.2400","4.0299","4.0299","2.6866","12.4128","45.9274"
"16.3200","4.0495","4.0495","2.6997","12.4774","46.1664"
"16.4000","4.0690","4.0690","2.7127","12.5398","46.3974"
"16.4800","4.0883","4.0883","2.7255","12.6047","46.6375"
"16.5600","4.1094","4.1094","2.7396","12.6748","46.8966"
"16.6400","4.1285","4.1285","2.7524","12.7365","47.1249"
"16.7200","4.1499","4.1499","2.7666","12.8064","47.3837"
"16.8000","4.1702","4.1702","2.7802","12.8728","47.6292"
"16.8800","4.1895","4.1895","2.7930","12.9388","47.8737"
"16.9600","4.2092","4.2092","2.8061","13.0042","48.1155"
"17.0400","4.2288","4.2288","2.8192","13.0658","48.3434"
"17.1200","4.2492","4.2492","2.8328","13.1346","48.5979"
"17.2000","4.2690","4.2690","2.8460","13.1986","48.8349"
"17.2800","4.2876","4.2876","2.8584","13.2582","49.0552"
"17.3600","4.3092","4.3092","2.8728","13.3298","49.3203"
"17.4400","4.3301","4.3301","2.8867","13.3994","49.5779"
"17.5200","4.3494","4.3494","2.8996","13.4609","49.8054"
"17.6000","4.3691","4.3691","2.9127","13.5265","50.0481"
"17.6800","4.3883","4.3883","2.9255","13.5895","50.2812"
"17.7600","4.4095","4.4095","2.9397","13.6590","50.5383"
"17.8400","4.4295","4.4295","2.9530","13.7236","50.7773"
"17.9200","4.4485","4.4485","2.9656","13.7836","50.9992"
"18.0000","4.4696","4.4696","2.9797","13.8550","51.2633"
"18.0800","4.4899","4.4899","2.9933","13.9214","51.5093"
"18.1600","4.5098","4.5098","3.0065","13.9827","51.7361"
"18.2400","4.5298","4.5298","3.0199","14.0457","51.9690"
"18.3200","4.5486","4.5486","3.0324","14.1054","52.1901"
"18.4000","4.5689","4.5689","3.0459","14.1699","52.4285"
"18.4800","4.5883","4.5883","3.0589","14.2353","52.6706"
"18.5600","4.6085","4.6085","3.0723","14.3018","52.9168"
"18.6400","4.6296","4.6296","3.0864","14.3718","53.1755"
"18.7200","4.6497","4.6497","3.0998","14.4325","53.4004"
"18.8000","4.6695","4.6695","3.1130","14.4937","53.6267"
"18.8800","4.6895","4.6895","3.1263","14.5554","53.8548"
"18.9600","4.7083","4.7083","3.1389","14.6193","54.0914"
"19.0400","4.7291","4.7291","3.1527","14.6855","54.3365"
"19.1200","4.7488","4.7488","3.1659","14.7483","54.5686"
"19.2000","4.7693","4.7693","3.1795","14.8139","54.8116"
"19.2800","4.7900","4.7900","3.1933","14.8813","55.0608"
"19.3600","4.8097","4.8097","3.2065","14.9446","55.2949"
"19.4400","4.8299","4.8299","3.2199","15.0062","55.5230"
"19.5200","4.8495","4.8495","3.2330","15.0687","55.7540"
"19.6000","4.8687","4.8687","3.2458","15.1298","55.9803"
"19.6800","4.8887","4.8887","3.2591","15.1933","56.2153"
"19.7600","4.9080","4.9080","3.2720","15.2540","56.4399"
"19.8400","4.9291","4.9291","3.2860","15.3205","56.6858"
"19.9200","4.9499","4.9499","3.3000","15.3856","56.9267"
"20.0000","4.9692","4.9692","3.3128","15.4482","57.1585"
"20.0800","4.9895","4.9895","3.3263","15.5103","57.3880"
"20.1600","5.0088","5.0088","3.3392","15.5703","57.6102"
"20.2400","5.0295","5.0295","3.3530","15.6370","57.8569"
"20.3200","5.0491","5.0491","3.3660","15.6962","58.0760"
"20.4000","5.0683","5.0683","3.3789","15.7559","58.2969"
"20.4800","5.0893","5.0893","3.3929","15.8224","58.5427"
"20.5600","5.1106","5.1106","3.4071","15.8882","58.7862"
"20.6400","5.1293","5.1293","3.4195","15.9460","59.0001"
"20.7200","5.1494","5.1494","3.4329","16.0098","59.2364"
"20.8000","5.1685","5.1685","3.4456","16.0636","59.4351"
"20.8800","5.1891","5.1891","3.4594","16.1288","59.6765"
"20.9600","5.2091","5.2091","3.4728","16.1900","59.9030"
"21.0400","5.2282","5.2282","3.4855","16.2495","60.1232"
"21.1200","5.2490","5.2490","3.4993","16.3149","60.3652"
"21.2000","5.2700","5.2700","3.5133","16.3794","60.6036"
"21.2800","5.2896","5.2896","3.5264","16.4407","60.8306"
"21.3600","5.3099","5.3099","3.5399","16.5028","61.0603"
"21.4400","5.3290","5.3290","3.5527","16.5620","61.2793"
"21.5200","5.3494","5.3494","3.5663","16.6253","61.5135"
"21.6000","5.3691","5.3691","3.5794","16.6836","61.7292"
"21.6800","5.3889","5.3889","3.5926","16.7447","61.9554"
"21.7600","5.4099","5.4099","3.6066","16.8105","62.1989"
"21.8400","5.4297","5.4297","3.6198","16.8670","62.4080"
"21.9200","5.4500","5.4500","3.6333","16.9275","62.6318"
"22.0000","5.4697","5.4697","3.6464","16.9859","62.8480"
"22.0800","5.4886","5.4886","3.6591","17.0432","63.0598"
"22.1600","5.5092","5.5092","3.6728","17.1080","63.2998"
"22.2400","5.5290","5.5290","3.6860","17.1659","63.5138"
"22.3200","5.5484","5.5484","3.6990","17.2234","63.7267"
"22.4000","5.5694","5.5694","3.7130","17.2849","63.9542"
"22.4800","5.5890","5.5890","3.7260","17.3421","64.1657"
"22.5600","5.6101","5.6101","3.7401","17.4049","64.3980"
"22.6400","5.6297","5.6297","3.7531","17.4618","64.6088"
"22.7200","5.6486","5.6486","3.7657","17.5195","64.8220"
"22.8000","5.6682","5.6682","3.7788","17.5752","65.0282"
"22.8800","5.6887","5.6887","3.7925","17.6376","65.2592"
"22.9600","5.7097","5.7097","3.8065","17.7016","65.4957"
"23.0400","5.7305","5.7305","3.8204","17.7625","65.7213"
"23.1200","5.7492","5.7492","3.8328","17.8162","65.9198"
"23.2000","5.7692","5.7692","3.8462","17.8714","66.1244"
"23.2800","5.7889","5.7889","3.8593","17.9305","66.3429"
"23.3600","5.8091","5.8091","3.8727","17.9915","66.5685"
"23.4400","5.8294","5.8294","3.8863","18.0483","66.7789"
"23.5200","5.8481","5.8481","3.8988","18.1016","66.9759"
"23.6000","5.8689","5.8689","3.9126","18.1596","67.1904"
"23.6800","5.8896","5.8896","3.9264","18.2235","67.4268"
"23.7600","5.9095","5.9095","3.9397","18.2823","67.6445"
"23.8400","5.9298","5.9298","3.9532","18.3435","67.8710"
"23.9200","5.9489","5.9489","3.9659","18.3947","68.0602"
"24.0000","5.9690","5.9690","3.9793","18.4534","68.2774"
"24.0800","5.9897","5.9897","3.9931","18.5127","68.4970"
"24.1600","6.0086","6.0086","4.0057","18.5672","68.6985"
"24.2400","6.0299","6.0299","4.0199","18.6300","68.9311"
"24.3200","6.0498","6.0498","4.0332","18.6893","69.1503"
"24.4000","6.0696","6.0696","4.0464","18.7434","69.3506"
"24.4800","6.0891","6.0891","4.0594","18.8030","69.5711"
"24.5600","6.1092","6.1092","4.0728","18.8601","69.7824"
"24.6400","6.1294","6.1294","4.0863","18.9172","69.9935"
"24.7200","6.1493","6.1493","4.0995","18.9717","70.1954"
"24.8000","6.1680","6.1680","4.1120","19.0267","70.3987"
"24.8800","6.1894","6.1894","4.1263","19.0908","70.6360"
"24.9600","6.2094","6.2094","4.1396","19.1455","70.8384"
"25.0400","6.2300","6.2300","4.1534","19.2048","71.0576"
"25.1200","6.2491","6.2491","4.1661","19.2581","71.2550"
"25.2000","6.2680","6.2680","4.1786","19.3102","71.4477"
"25.2800","6.2889","6.2889","4.1926","19.3706","71.6713"
"25.3600","6.3096","6.3096","4.2064","19.4302","71.8916"
"25.4400","6.3294","6.3294","4.2196","19.4851","72.0949"
"25.5200","6.3499","6.3499","4.2333","19.5448","72.3157"
"25.6000","6.3695","6.3695","4.2463","19.5964","72.5067"
"25.6800","6.3896","6.3896","4.2597","19.6521","72.7129"
"25.7600","6.4097","6.4097","4.2731","19.7093","72.9243"
"25.8400","6.4287","6.4287","4.2858","19.7622","73.1202"
"25.9200","6.4485","6.4485","4.2990","19.8169","73.3225"
"26.0000","6.4679","6.4679","4.3120","19.8701","73.5195"
"26.0800","6.4891","6.4891","4.3261","19.9308","73.7438"
"26.1600","6.5102","6.5102","4.3401","19.9897","73.9618"
"26.2400","6.5298","6.5298","4.3532","20.0422","74.1561"
"26.3200","6.5494","6.5494","4.3663","20.0983","74.3637"
"26.4000","6.5693","6.5693","4.3795","20.1514","74.5601"
"26.4800","6.5884","6.5884","4.3923","20.2070","74.7658"
"26.5600","6.6094","6.6094","4.4063","20.2640","74.9769"
"26.6400","6.6284","6.6284","4.4189","20.3160","75.1693"
"26.7200","6.6501","6.6501","4.4334","20.3760","75.3910"
"26.8000","6.6701","6.6701","4.4467","20.4304","75.5926"
"26.8800","6.6896","6.6896","4.4598","20.4844","75.7922"
"26.9600","6.7097","6.7097","4.4731","20.5424","76.0069"
"27.0400","6.7294","6.7294","4.4863","20.5946","76.2001"
"27.1200","6.7492","6.7492","4.4995","20.6466","76.3925"
"27.2000","6.7691","6.7691","4.5127","20.6976","76.5810"
"27.2800","6.7876","6.7876","4.5251","20.7480","76.7675"
"27.3600","6.8090","6.8090","4.5394","20.8068","76.9853"
"27.4400","6.8302","6.8302","4.5535","20.8679","77.2111"
"27.5200","6.8495","6.8495","4.5663","20.9192","77.4010"
"27.6000","6.8690","6.8690","4.5793","20.9699","77.5885"
"27.6800","6.8882","6.8882","4.5921","21.0191","77.7707"
"27.7600","6.9095","6.9095","4.6063","21.0743","77.9750"
"27.8400","6.9297","6.9297","4.6198","21.1294","78.1788"
"27.9200","6.9487","6.9487","4.6324","21.1796","78.3646"
"28.0000","6.9692","6.9692","4.6462","21.2353","78.5706"
"28.0800","6.9899","6.9899","4.6599","21.2905","78.7750"
"28.1600","7.0098","7.0098","4.6732","21.3440","78.9729"
"28.2400","7.0300","7.0300","4.6866","21.3955","79.1633"
"28.3200","7.0485","7.0485","4.6990","21.4419","79.3352"
"28.4000","7.0689","7.0689","4.7126","21.4954","79.5329"
"28.4800","7.0883","7.0883","4.7255","21.5448","79.7157"
"28.5600","7.1085","7.1085","4.7390","21.5999","79.9198"
"28.6400","7.1295","7.1295","4.7530","21.6547","80.1224"
"28.7200","7.1503","7.1503","4.7669","21.7114","80.3321"
"28.8000","7.1697","7.1697","4.7798","21.7563","80.4983"
"28.8800","7.1898","7.1898","4.7932","21.8078","80.6888"
"28.9600","7.2085","7.2085","4.8057","21.8581","80.8750"
"29.0400","7.2294","7.2294","4.8196","21.9146","81.0839"
"29.1200","7.2486","7.2486","4.8324","21.9612","81.2563"
"29.2000","7.2692","7.2692","4.8461","22.0136","81.4504"
"29.2800","7.2903","7.2903","4.8602","22.0699","81.6587"
"29.3600","7.3098","7.3098","4.8732","22.1181","81.8368"
"29.4400","7.3299","7.3299","4.8866","22.1701","82.0293"
"29.5200","7.3493","7.3493","4.8995","22.2173","82.2040"
"29.6000","7.3687","7.3687","4.9125","22.2653","82.3817"
"29.6800","7.3889","7.3889","4.9259","22.3212","82.5883"
"29.7600","7.4082","7.4082","4.9388","22.3664","82.7557"
"29.8400","7.4294","7.4294","4.9529","22.4230","82.9652"
"29.9200","7.4501","7.4501","4.9667","22.4738","83.1532"
"30.0000","7.4687","7.4687","4.9791","22.5184","83.3179"
"30.0800","7.4895","7.4895","4.9930","22.5738","83.5232"
"30.1600","7.5088","7.5088","5.0059","22.6212","83.6985"
"30.2400","7.5291","7.5291","5.0194","22.6705","83.8810"
"30.3200","7.5492","7.5492","5.0328","22.7219","84.0711"
"30.4000","7.5684","7.5684","5.0456","22.7673","84.2391"
"30.4800","7.5896","7.5896","5.0597","22.8238","84.4479"
"30.5600","7.6106","7.6106","5.0737","22.8749","84.6370"
"30.6400","7.6294","7.6294","5.0863","22.9207","84.8066"
"30.7200","7.6495","7.6495","5.0996","22.9711","84.9930"
"30.8000","7.6686","7.6686","5.1124","23.0136","85.1503"
"30.8800","7.6885","7.6885","5.1257","23.0624","85.3310"
"30.9600","7.7090","7.7090","5.1394","23.1111","85.5111"
"31.0400","7.7288","7.7288","5.1525","23.1623","85.7006"
"31.1200","7.7492","7.7492","5.1661","23.2112","85.8815"
"31.2000","7.7697","7.7697","5.1798","23.2627","86.0721"
"31.2800","7.7894","7.7894","5.1929","23.3090","86.2431"
"31.3600","7.8094","7.8094","5.2063","23.3580","86.4245"
"31.4400","7.8287","7.8287","5.2192","23.4020","86.5875"
"31.5200","7.8492","7.8492","5.2328","23.4519","86.7719"
"31.6000","7.8693","7.8693","5.2462","23.4978","86.9417"
"31.6800","7.8887","7.8887","5.2592","23.5482","87.1285"
"31.7600","7.9100","7.9100","5.2734","23.5996","87.3186"
"31.8400","7.9300","7.9300","5.2866","23.6448","87.4857"
"31.9200","7.9500","7.9500","5.3000","23.6912","87.6575"
"32.0000","7.9694","7.9694","5.3129","23.7339","87.8155"
"32.0800","7.9885","7.9885","5.3257","23.7788","87.9816"
"32.1600","8.0092","8.0092","5.3395","23.8301","88.1712"
"32.2400","8.0292","8.0292","5.3528","23.8725","88.3282"
"32.3200","8.0481","8.0481","5.3654","23.9156","88.4877"
"32.4000","8.0694","8.0694","5.3796","23.9657","88.6731"
"32.4800","8.0887","8.0887","5.3925","24.0100","88.8371"
"32.5600","8.1100","8.1100","5.4067","24.0587","89.0172"
"32.6400","8.1296","8.1296","5.4197","24.1027","89.1798"
"32.7200","8.1487","8.1487","5.4325","24.1452","89.3371"
"32.8000","8.1686","8.1686","5.4458","24.1927","89.5129"
"32.8800","8.1888","8.1888","5.4592","24.2355","89.6713"
"32.9600","8.2097","8.2097","5.4731","24.2833","89.8481"
"33.0400","8.2308","8.2308","5.4872","24.3327","90.0310"
"33.1200","8.2494","8.2494","5.4996","24.3715","90.1744"
"33.2000","8.2691","8.2691","5.5128","24.4137","90.3306"
"33.2800","8.2889","8.2889","5.5259","24.4574","90.4922"
"33.3600","8.3089","8.3089","5.5393","24.5046","90.6670"
"33.4400","8.3294","8.3294","5.5530","24.5482","90.8284"
"33.5200","8.3481","8.3481","5.5654","24.5877","90.9743"
"33.6000","8.3687","8.3687","5.5791","24.6301","91.1314"
"33.6800","8.3899","8.3899","5.5932","24.6780","91.3086"
"33.7600","8.4099","8.4099","5.6066","24.7207","91.4667"
"33.8400","8.4297","8.4297","5.6198","24.7644","91.6282"
"33.9200","8.4489","8.4489","5.6326","24.8015","91.7655"
"34.0000","8.4688","8.4688","5.6458","24.8438","91.9220"
"34.0800","8.4897","8.4897","5.6598","24.8887","92.0882"
"34.1600","8.5089","8.5089","5.6726","24.9318","92.2476"
"34.2400","8.5303","8.5303","5.6868","24.9774","92.4163"
"34.3200","8.5497","8.5497","5.6998","25.0164","92.5607"
"34.4000","8.5698","8.5698","5.7132","25.0545","92.7017"
"34.4800","8.5893","8.5893","5.7262","25.0940","92.8479"
"34.5600","8.6090","8.6090","5.7393","25.1335","92.9941"
"34.6400","8.6293","8.6293","5.7529","25.1737","93.1427"
"34.7200","8.6491","8.6491","5.7661","25.2124","93.2857"
"34.8000","8.6678","8.6678","5.7786","25.2548","93.4426"
"34.8800","8.6893","8.6893","5.7928","25.2996","93.6086"
"34.9600","8.7093","8.7093","5.8062","25.3364","93.7447"
"35.0400","8.7299","8.7299","5.8200","25.3792","93.9031"
"35.1200","8.7495","8.7495","5.8330","25.4169","94.0424"
"35.2000","8.7682","8.7682","5.8455","25.4506","94.1673"
"35.2800","8.7887","8.7887","5.8591","25.4909","94.3162"
"35.3600","8.8095","8.8095","5.8730","25.5341","94.4761"
"35.4400","8.8294","8.8294","5.8863","25.5727","94.6191"
"35.5200","8.8505","8.8505","5.9004","25.6179","94.7862"
"35.6000","8.8696","8.8696","5.9131","25.6546","94.9220"
"35.6800","8.8896","8.8896","5.9264","25.6896","95.0517"
"35.7600","8.9096","8.9096","5.9397","25.7289","95.1970"
"35.8400","8.9285","8.9285","5.9524","25.7668","95.3372"
"35.9200","8.9488","8.9488","5.9659","25.8039","95.4744"
"36.0000","8.9680","8.9680","5.9786","25.8384","95.6022"
"36.0800","8.9886","8.9886","5.9924","25.8783","95.7497"
"36.1600","9.0099","9.0099","6.0066","25.9213","95.9087"
"36.2400","9.0298","9.0298","6.0199","25.9581","96.0450"
"36.3200","9.0495","9.0495","6.0330","25.9916","96.1687"
"36.4000","9.0690","9.0690","6.0460","26.0270","96.2998"
"36.4800","9.0882","9.0882","6.0588","26.0616","96.4279"
"36.5600","9.1095","9.1095","6.0730","26.1049","96.5880"
"36.6400","9.1288","9.1288","6.0859","26.1350","96.6993"
"36.7200","9.1498","9.1498","6.0998","26.1735","96.8418"
"36.8000","9.1702","9.1702","6.1135","26.2092","96.9740"
"36.8800","9.1897","9.1897","6.1265","26.2462","97.1111"
"36.9600","9.2093","9.2093","6.1395","26.2779","97.2284"
"37.0400","9.2292","9.2292","6.1528","26.3120","97.3544"
"37.1200","9.2489","9.2489","6.1659","26.3479","97.4873"
"37.2000","9.2689","9.2689","6.1793","26.3794","97.6037"
"37.2800","9.2876","9.2876","6.1917","26.4102","97.7177"
"37.3600","9.3093","9.3093","6.2062","26.4492","97.8621"
"37.4400","9.3303","9.3303","6.2202","26.4863","97.9995"
"37.5200","9.3495","9.3495","6.2330","26.5189","98.1198"
"37.6000","9.3690","9.3690","6.2460","26.5502","98.2359"
"37.6800","9.3882","9.3882","6.2588","26.5798","98.3454"
"37.7600","9.4092","9.4092","6.2728","26.6165","98.4811"
"37.8400","9.4296","9.4296","6.2864","26.6492","98.6019"
"37.9200","9.4491","9.4491","6.2994","26.6817","98.7223"
"38.0000","9.4696","9.4696","6.3131","26.7163","98.8503"
"38.0800","9.4897","9.4897","6.3265","26.7467","98.9629"
"38.1600","9.5098","9.5098","6.3399","26.7779","99.0782"
"38.2400","9.5300","9.5300","6.3533","26.8091","99.1935"
"38.3200","9.5483","9.5483","6.3655","26.8364","99.2946"
"38.4000","9.5686","9.5686","6.3791","26.8639","99.3964"
"38.4800","9.5882","9.5882","6.3921","26.8971","99.5193"
"38.5600","9.6087","9.6087","6.4058","26.9283","99.6346"
"38.6400","9.6296","9.6296","6.4197","26.9630","99.7630"
"38.7200","9.6497","9.6497","6.4332","26.9918","99.8696"
"38.8000","9.6695","9.6695","6.4463","27.0196","99.9726"
"38.8800","9.6897","9.6897","6.4598","27.0488","100.0804"
"38.9600","9.7082","9.7082","6.4721","27.0772","100.1855"
"39.0400","9.7290","9.7290","6.4860","27.1103","100.3080"
"39.1200","9.7488","9.7488","6.4992","27.1360","100.4031"
"39.2000","9.7694","9.7694","6.5129","27.1696","100.5274"
"39.2800","9.7902","9.7902","6.5268","27.2024","100.6487"
"39.3600","9.8097","9.8097","6.5398","27.2288","100.7467"
"39.4400","9.8299","9.8299","6.5533","27.2584","100.8561"
"39.5200","9.8495","9.8495","6.5664","27.2815","100.9415"
"39.6000","9.8685","9.8685","6.5790","27.3114","101.0523"
"39.6800","9.8889","9.8889","6.5926","27.3425","101.1674"
"39.7600","9.9082","9.9082","6.6055","27.3657","101.2532"
"39.8400","9.9292","9.9292","6.6195","27.3981","101.3728"
"39.9200","9.9503","9.9503","6.6335","27.4271","101.4802"
"40.0000","9.9691","9.9691","6.6461","27.4526","101.5747"
"40.0800","9.9894","9.9894","6.6596","27.4810","101.6797"
"40.1600","10.0085","10.0085","6.6723","27.5028","101.7604"
"40.2400","10.0293","10.0293","6.6862","27.5333","101.8733"
"40.3200","10.0491","10.0491","6.6994","27.5598","101.9714"
"40.4000","10.0687","10.0687","6.7125","27.5843","102.0618"
"40.4800","10.0893","10.0893","6.7262","27.6141","102.1723"
"40.5600","10.1106","10.1106","6.7404","27.6408","102.2708"
"40.6400","10.1296","10.1296","6.7531","27.6658","102.3636"
"40.7200","10.1497","10.1497","6.7665","27.6916","102.4588"
"40.8000","10.1684","10.1684","6.7789","27.7126","102.5364"
"40.8800","10.1893","10.1893","6.7929","27.7403","102.6390"
"40.9600","10.2092","10.2092","6.8061","27.7638","102.7260"
"41.0400","10.2281","10.2281","6.8187","27.7877","102.8145"
"41.1200","10.2489","10.2489","6.8326","27.8143","102.9131"
"41.2000","10.2691","10.2691","6.8461","27.8384","103.0021"
"41.2800","10.2894","10.2894","6.8596","27.8619","103.0891"
"41.3600","10.3100","10.3100","6.8734","27.8897","103.1921"
"41.4400","10.3289","10.3289","6.8859","27.9075","103.2578"
"41.5200","10.3495","10.3495","6.8996","27.9329","103.3519"
"41.6000","10.3692","10.3692","6.9128","27.9552","103.4341"
"41.6800","10.3887","10.3887","6.9258","27.9753","103.5087"
"41.7600","10.4098","10.4098","6.9399","28.0033","103.6122"
"41.8400","10.4296","10.4296","6.9531","28.0202","103.6749"
"41.9200","10.4500","10.4500","6.9667","28.0410","103.7518"
"42.0000","10.4694","10.4694","6.9796","28.0614","103.8272"
"42.0800","10.4888","10.4888","6.9925","28.0822","103.9040"
"42.1600","10.5088","10.5088","7.0059","28.1053","103.9895"
"42.2400","10.5288","10.5288","7.0192","28.1235","104.0570"
"42.3200","10.5485","10.5485","7.0324","28.1470","104.1438"
"42.4000","10.5695","10.5695","7.0463","28.1701","104.2292"
"42.4800","10.5888","10.5888","7.0592","28.1860","104.2881"
"42.5600","10.6102","10.6102","7.0735","28.2097","104.3757"
"42.6400","10.6296","10.6296","7.0864","28.2260","104.4364"
"42.7200","10.6489","10.6489","7.0993","28.2448","104.5056"
"42.8000","10.6686","10.6686","7.1124","28.2614","104.5671"
"42.8800","10.6887","10.6887","7.1258","28.2833","104.6482"
"42.9600","10.7094","10.7094","7.1396","28.3034","104.7226"
"43.0400","10.7308","10.7308","7.1539","28.3237","104.7978"
"43.1200","10.7495","10.7495","7.1663","28.3403","104.8590"
"43.2000","10.7694","10.7694","7.1796","28.3574","104.9225"
"43.2800","10.7890","10.7890","7.1927","28.3744","104.9852"
"43.3600","10.8090","10.8090","7.2060","28.3928","105.0532"
"43.4400","10.8297","10.8297","7.2198","28.4106","105.1191"
"43.5200","10.8476","10.8476","7.2317","28.4243","105.1698"
"43.6000","10.8685","10.8685","7.2456","28.4443","105.2441"
"43.6800","10.8896","10.8896","7.2597","28.4642","105.3177"
"43.7600","10.9099","10.9099","7.2733","28.4832","105.3878"
"43.8400","10.9298","10.9298","7.2865","28.5014","105.4552"
"43.9200","10.9488","10.9488","7.2992","28.5146","105.5042"
"44.0000","10.9687","10.9687","7.3125","28.5323","105.5694"
"44.0800","10.9896","10.9896","7.3264","28.5485","105.6294"
"44.1600","11.0084","11.0084","7.3390","28.5669","105.6976"
"44.2400","11.0301","11.0301","7.3534","28.5828","105.7565"
"44.3200","11.0499","11.0499","7.3666","28.6006","105.8222"
"44.4000","11.0700","11.0700","7.3800","28.6133","105.8690"
"44.4800","11.0893","11.0893","7.3928","28.6289","105.9269"
"44.5600","11.1088","11.1088","7.4059","28.6426","105.9775"
"44.6400","11.1290","11.1290","7.4194","28.6611","106.0462"
"44.7200","11.1489","11.1489","7.4326","28.6748","106.0966"
"44.8000","11.1678","11.1678","7.4452","28.6869","106.1414"
"44.8800","11.1896","11.1896","7.4598","28.7061","106.2126"
"44.9600","11.2094","11.2094","7.4729","28.7200","106.2638"
"45.0400","11.2306","11.2306","7.4870","28.7348","106.3186"
"45.1200","11.2491","11.2491","7.4994","28.7433","106.3501"
"45.2000","11.2678","11.2678","7.5119","28.7561","106.3977"
"45.2800","11.2891","11.2891","7.5260","28.7729","106.4599"
"45.3600","11.3094","11.3094","7.5396","28.7881","106.5161"
"45.4400","11.3295","11.3295","7.5530","28.8017","106.5661"
"45.5200","11.3501","11.3501","7.5668","28.8148","106.6149"
"45.6000","11.3693","11.3693","7.5795","28.8236","106.6472"
"45.6800","11.3897","11.3897","7.5931","28.8371","106.6974"
"45.7600","11.4100","11.4100","7.6067","28.8470","106.7340"
"45.8400","11.4285","11.4285","7.6190","28.8600","106.7821"
"45.9200","11.4488","11.4488","7.6326","28.8719","106.8260"
"46.0000","11.4674","11.4674","7.6449","28.8816","106.8620"
"46.0800","11.4890","11.4890","7.6593","28.8956","106.9138"
"46.1600","11.5101","11.5101","7.6734","28.9082","106.9604"
"46.2400","11.5298","11.5298","7.6865","28.9177","106.9956"
"46.3200","11.5494","11.5494","7.6996","28.9284","107.0352"
"46.4000","11.5691","11.5691","7.7128","28.9357","107.0622"
"46.4800","11.5882","11.5882","7.7254","28.9443","107.0941"
"46.5600","11.6096","11.6096","7.7397","28.9602","107.1528"
"46.6400","11.6287","11.6287","7.7525","28.9678","107.1808"
"46.7200","11.6501","11.6501","7.7668","28.9793","107.2234"
"46.8000","11.6699","11.6699","7.7799","28.9876","107.2542"
"46.8800","11.6897","11.6897","7.7931","28.9971","107.2891"
"46.9600","11.7094","11.7094","7.8062","29.0059","107.3217"
"47.0400","11.7292","11.7292","7.8195","29.0156","107.3576"
"47.1200","11.7492","11.7492","7.8328","29.0242","107.3896"
"47.2000","11.7695","11.7695","7.8463","29.0329","107.4217"
"47.2800","11.7875","11.7875","7.8583","29.0391","107.4445"
"47.3600","11.8093","11.8093","7.8729","29.0540","107.4996"
"47.4400","11.8302","11.8302","7.8868","29.0647","107.5394"
"47.5200","11.8497","11.8497","7.8998","29.0751","107.5780"
"47.6000","11.8691","11.8691","7.9128","29.0812","107.6005"
"47.6800","11.8883","11.8883","7.9255","29.0889","107.6288"
"47.7600","11.9097","11.9097","7.9398","29.0989","107.6659"
"47.8400","11.9297","11.9297","7.9531","29.1055","107.6903"
"47.9200","11.9490","11.9490","7.9660","29.1167","107.7317"
"48.0000","11.9691","11.9691","7.9794","29.1292","107.7780"
"48.0800","11.9899","11.9899","7.9933","29.1366","107.8055"
"48.1600","12.0102","12.0102","8.0068","29.1484","107.8490"
"48.2400","12.0301","12.0301","8.0200","29.1549","107.8733"
"48.3200","12.0481","12.0481","8.0321","29.1619","107.8990"
"48.4000","12.0689","12.0689","8.0459","29.1700","107.9289"
"48.4800","12.0884","12.0884","8.0589","29.1748","107.9466"
"48.5600","12.1083","12.1083","8.0722","29.1869","107.9915"
"48.6400","12.1294","12.1294","8.0863","29.1978","108.0319"
"48.7200","12.1496","12.1496","8.0998","29.2023","108.0486"
"48.8000","12.1696","12.1696","8.1131","29.2099","108.0768"
"48.8800","12.1898","12.1898","8.1265","29.2163","108.1005"
"48.9600","12.2086","12.2086","8.1391","29.2238","108.1280"
"49.0400","12.2293","12.2293","8.1529","29.2328","108.1615"
"49.1200","12.2485","12.2485","8.1657","29.2370","108.1771"
"49.2000","12.2690","12.2690","8.1793","29.2461","108.2106"
"49.2800","12.2904","12.2904","8.1936","29.2555","108.2453"
"49.3600","12.3097","12.3097","8.2064","29.2617","108.2682"
"49.4400","12.3300","12.3300","8.2200","29.2668","108.2870"
"49.5200","12.3494","12.3494","8.2330","29.2717","108.3054"
"49.6000","12.3686","12.3686","8.2457","29.2774","108.3264"
"49.6800","12.3889","12.3889","8.2592","29.2858","108.3575"
"49.7600","12.4084","12.4084","8.2723","29.2887","108.3682"
"49.8400","12.4287","12.4287","8.2858","29.2926","108.3827"
"49.9200","12.4500","12.4500","8.3000","29.2994","108.4079"
"50.0000","12.4687","12.4687","8.3125","29.3042","108.4255"
"50.0800","12.4895","12.4895","8.3263","29.3100","108.4470"
"50.1600","12.5089","12.5089","8.3393","29.3115","108.4525"
"50.2400","12.5295","12.5295","8.3530","29.3162","108.4699"
"50.3200","12.5492","12.5492","8.3661","29.3204","108.4854"
"50.4000","12.5686","12.5686","8.3791","29.3229","108.4946"
"50.4800","12.5894","12.5894","8.3929","29.3316","108.5270"
"50.5600","12.6106","12.6106","8.4071","29.3372","108.5475"
"50.6400","12.6298","12.6298","8.4198","29.3399","108.5575"
"50.7200","12.6495","12.6495","8.4330","29.3435","108.5709"
"50.8000","12.6685","12.6685","8.4457","29.3397","108.5570"
"50.8800","12.6892","12.6892","8.4594","29.3475","108.5856"
"50.9600","12.7092","12.7092","8.4728","29.3480","108.5876"
"51.0400","12.7284","12.7284","8.4856","29.3509","108.5982"
"51.1200","12.7490","12.7490","8.4994","29.3570","108.6210"
"51.2000","12.7698","12.7698","8.5132","29.3601","108.6324"
"51.2800","12.7890","12.7890","8.5260","29.3589","108.6277"
"51.3600","12.8095","12.8095","8.5397","29.3630","108.6432"
"51.4400","12.8288","12.8288","8.5525","29.3609","108.6352"
"51.5200","12.8496","12.8496","8.5664","29.3615","108.6374"
"51.6000","12.8693","12.8693","8.5796","29.3645","108.6488"
"51.6800","12.8884","12.8884","8.5923","29.3646","108.6489"
"51.7600","12.9101","12.9101","8.6068","29.3707","108.6715"
"51.8400","12.9299","12.9299","8.6199","29.3695","108.6672"
"51.9200","12.9499","12.9499","8.6333","29.3707","108.6715"
"52.0000","12.9694","12.9694","8.6463","29.3701","108.6695"
"52.0800","12.9888","12.9888","8.6592","29.3725","108.6781"
"52.1600","13.0089","13.0089","8.6726","29.3699","108.6687"
"52.2400","13.0291","13.0291","8.6860","29.3700","108.6691"
"52.3200","13.0483","13.0483","8.6989","29.3698","108.6684"
"52.4000","13.0695","13.0695","8.7130","29.3701","108.6695"
"52.4800","13.0890","13.0890","8.7260","29.3708","108.6720"
"52.5600","13.1100","13.1100","8.7400","29.3695","108.6672"
"52.6400","13.1295","13.1295","8.7530","29.3713","108.6740"
"52.7200","13.1492","13.1492","8.7661","29.3720","108.6763"
"52.8000","13.1687","13.1687","8.7791","29.3722","108.6771"
"52.8800","13.1887","13.1887","8.7925","29.3704","108.6705"
"52.9600","13.2097","13.2097","8.8065","29.3706","108.6712"
"53.0400","13.2310","13.2310","8.8207","29.3712","108.6733"
"53.1200","13.2494","13.2494","8.8329","29.3704","108.6705"
"53.2000","13.2691","13.2691","8.8461","29.3658","108.6533"
"53.2800","13.2890","13.2890","8.8593","29.3655","108.6523"
"53.3600","13.3091","13.3091","8.8727","29.3668","108.6573"
"53.4400","13.3293","13.3293","8.8862","29.3624","108.6409"
"53.5200","13.3479","13.3479","8.8986","29.3596","108.6307"
"53.6000","13.3690","13.3690","8.9127","29.3576","108.6230"
"53.6800","13.3897","13.3897","8.9265","29.3585","108.6263"
"53.7600","13.4091","13.4091","8.9394","29.3538","108.6089"
"53.8400","13.4295","13.4295","8.9530","29.3550","108.6136"
"53.9200","13.4494","13.4494","8.9663","29.3528","108.6054"
"54.0000","13.4688","13.4688","8.9792","29.3494","108.5928"
"54.0800","13.4894","13.4894","8.9930","29.3502","108.5957"
"54.1600","13.5084","13.5084","9.0056","29.3479","108.5873"
"54.2400","13.5301","13.5301","9.0201","29.3479","108.5873"
"54.3200","13.5498","13.5498","9.0332","29.3460","108.5802"
"54.4000","13.5697","13.5697","9.0465","29.3457","108.5790"
"54.4800","13.5892","13.5892","9.0594","29.3416","108.5639"
"54.5600","13.6090","13.6090","9.0727","29.3391","108.5548"
"54.6400","13.6293","13.6293","9.0862","29.3398","108.5574"
"54.7200","13.6495","13.6495","9.0997","29.3371","108.5474"
"54.8000","13.6680","13.6680","9.1120","29.3336","108.5341"
"54.8800","13.6891","13.6891","9.1261","29.3356","108.5419"
"54.9600","13.7096","13.7096","9.1398","29.3340","108.5357"
"55.0400","13.7303","13.7303","9.1535","29.3314","108.5264"
"55.1200","13.7496","13.7496","9.1664","29.3262","108.5070"
"55.2000","13.7679","13.7679","9.1786","29.3203","108.4853"
"55.2800","13.7888","13.7888","9.1926","29.3173","108.4741"
"55.3600","13.8094","13.8094","9.2063","29.3155","108.4673"
"55.4400","13.8296","13.8296","9.2198","29.3152","108.4663"
"55.5200","13.8507","13.8507","9.2338","29.3137","108.4605"
"55.6000","13.8694","13.8694","9.2463","29.3061","108.4326"
"55.6800","13.8894","13.8894","9.2596","29.3000","108.4100"
"55.7600","13.9096","13.9096","9.2731","29.2963","108.3964"
"55.8400","13.9289","13.9289","9.2859","29.2960","108.3951"
"55.9200","13.9488","13.9488","9.2992","29.2880","108.3658"
"56.0000","13.9680","13.9680","9.3120","29.2837","108.3495"
"56.0800","13.9885","13.9885","9.3257","29.2786","108.3310"
"56.1600","14.0099","14.0099","9.3399","29.2768","108.3241"
"56.2400","14.0296","14.0296","9.3531","29.2684","108.2931"
"56.3200","14.0493","14.0493","9.3662","29.2616","108.2679"
"56.4000","14.0691","14.0691","9.3794","29.2550","108.2433"
"56.4800","14.0882","14.0882","9.3922","29.2512","108.2295"
"56.5600","14.1093","14.1093","9.4062","29.2496","108.2233"
"56.6400","14.1288","14.1288","9.4192","29.2443","108.2038"
"56.7200","14.1494","14.1494","9.4329","29.2406","108.1901"
"56.8000","14.1701","14.1701","9.4467","29.2373","108.1778"
"56.8800","14.1898","14.1898","9.4599","29.2317","108.1572"
"56.9600","14.2095","14.2095","9.4730","29.2297","108.1498"
"57.0400","14.2292","14.2292","9.4861","29.2227","108.1238"
"57.1200","14.2491","14.2491","9.4994","29.2169","108.1026"
"57.2000","14.2691","14.2691","9.5127","29.2106","108.0793"
"57.2800","14.2877","14.2877","9.5252","29.2073","108.0671"
"57.3600","14.3097","14.3097","9.5398","29.2034","108.0525"
"57.4400","14.3299","14.3299","9.5533","29.1994","108.0380"
"57.5200","14.3494","14.3494","9.5662","29.1936","108.0165"
"57.6000","14.3694","14.3694","9.5796","29.1884","107.9972"
"57.6800","14.3885","14.3885","9.5923","29.1815","107.9715"
"57.7600","14.4093","14.4093","9.6062","29.1776","107.9570"
"57.8400","14.4297","14.4297","9.6198","29.1741","107.9441"
"57.9200","14.4489","14.4489","9.6326","29.1687","107.9242"
"58.0000","14.4694","14.4694","9.6463","29.1670","107.9177"
"58.0800","14.4897","14.4897","9.6598","29.1597","107.8908"
"58.1600","14.5101","14.5101","9.6734","29.1522","107.8632"
"58.2400","14.5300","14.5300","9.6866","29.1469","107.8435"
"58.3200","14.5482","14.5482","9.6988","29.1376","107.8091"
"58.4000","14.5689","14.5689","9.7126","29.1328","107.7914"
"58.4800","14.5886","14.5886","9.7257","29.1262","107.7670"
"58.5600","14.6087","14.6087","9.7392","29.1187","107.7393"
"58.6400","14.6294","14.6294","9.7529","29.1162","107.7300"
"58.7200","14.6498","14.6498","9.7665","29.1044","107.6865"
"58.8000","14.6698","14.6698","9.7799","29.0995","107.6682"
"58.8800","14.6897","14.6897","9.7932","29.0891","107.6296"
"58.9600","14.7082","14.7082","9.8055","29.0783","107.5898"
"59.0400","14.7289","14.7289","9.8193","29.0726","107.5684"
"59.1200","14.7485","14.7485","9.8323","29.0618","107.5287"
"59.2000","14.7691","14.7691","9.8461","29.0552","107.5042"
"59.2800","14.7902","14.7902","9.8601","29.0476","107.4762"
"59.3600","14.8095","14.8095","9.8730","29.0385","107.4426"
"59.4400","14.8300","14.8300","9.8867","29.0289","107.4069"
"59.5200","14.8494","14.8494","9.8996","29.0190","107.3702"
"59.6000","14.8685","14.8685","9.9123","29.0066","107.3245"
"59.6800","14.8889","14.8889","9.9260","28.9987","107.2953"
"59.7600","14.9082","14.9082","9.9388","28.9871","107.2523"
"59.8400","14.9288","14.9288","9.9525","28.9762","107.2119"
"59.9200","14.9501","14.9501","9.9667","28.9679","107.1814"
"60.0000","14.9691","14.9691","9.9794","28.9579","107.1442"
"60.0800","14.9895","14.9895","9.9930","28.9487","107.1102"
"60.1220","15.0000","15.0000","10.0000","28.9423","107.0864"