File: data/instron_tests/metamaterial_samples/539_BULK_m2.is_comp_Exports/539_BULK_m2_1_1.csv
Sample text inputs : Sample No.,Sample choice input : Leading Direction,Sample choice input : Mode,Specimen choice input : Direction,Specimen properties : Height,Specimen properties : Thickness,Specimen properties : Width,Test : Rate 1
,,,,(mm),(mm),(mm),(mm/min)
"509","Bulk","Bimode","1","150.00","25.00","150.00","15.00"

Time,Displacement,Compressive displacement,Compressive strain (Displacement),Compressive stress,Force
(s),(mm),(mm),(%),(kPa),(N)
"0.0000","0.0000","0.0000","0.0000","-0.1006","-0.3722"
"0.0800","0.0013","0.0013","0.0008","-0.0947","-0.3503"
"0.1600","0.0097","0.0097","0.0065","-0.0562","-0.2081"
"0.2400","0.0303","0.0303","0.0202","0.0308","0.1139"
"0.3200","0.0507","0.0507","0.0338","0.1086","0.4020"
"0.4000","0.0685","0.0685","0.0457","0.1804","0.6676"
"0.4800","0.0886","0.0886","0.0591","0.2594","0.9596"
"0.5600","0.1104","0.1104","0.0736","0.3444","1.2743"
"0.6400","0.1297","0.1297","0.0865","0.4164","1.5406"
"0.7200","0.1497","0.1497","0.0998","0.4928","1.8235"
"0.8000","0.1689","0.1689","0.1126","0.5603","2.0731"
"0.8800","0.1893","0.1893","0.1262","0.6326","2.3405"
"0.9600","0.2096","0.2096","0.1397","0.7033","2.6022"
"1.0400","0.2286","0.2286","0.1524","0.7661","2.8344"
"1.1200","0.2493","0.2493","0.1662","0.8387","3.1033"
"1.2000","0.2699","0.2699","0.1799","0.9042","3.3457"
"1.2800","0.2900","0.2900","0.1933","0.9525","3.5242"
"1.3600","0.3099","0.3099","0.2066","1.0165","3.7612"
"1.4400","0.3289","0.3289","0.2193","1.0763","3.9821"
"1.5200","0.3495","0.3495","0.2330","1.1418","4.2248"
"1.6000","0.3697","0.3697","0.2465","1.2059","4.4619"
"1.6800","0.3885","0.3885","0.2590","1.2675","4.6898"
"1.7600","0.4104","0.4104","0.2736","1.3380","4.9505"
"1.8400","0.4305","0.4305","0.2870","1.3903","5.1442"
"1.9200","0.4503","0.4503","0.3002","1.4512","5.3695"
"2.0000","0.4699","0.4699","0.3133","1.5085","5.5814"
"2.0800","0.4887","0.4887","0.3258","1.5704","5.8105"
"2.1600","0.5095","0.5095","0.3397","1.6343","6.0470"
"2.2400","0.5294","0.5294","0.3529","1.6813","6.2207"
"2.3200","0.5488","0.5488","0.3659","1.7430","6.4489"
"2.4000","0.5695","0.5695","0.3797","1.8102","6.6978"
"2.4800","0.5892","0.5892","0.3928","1.8609","6.8854"
"2.5600","0.6106","0.6106","0.4071","1.9296","7.1397"
"2.6400","0.6298","0.6298","0.4198","1.9788","7.3215"
"2.7200","0.6489","0.6489","0.4326","2.0383","7.5417"
"2.8000","0.6691","0.6691","0.4460","2.1015","7.7754"
"2.8800","0.6891","0.6891","0.4594","2.1595","7.9900"
"2.9600","0.7099","0.7099","0.4733","2.2232","8.2260"
"3.0400","0.7308","0.7308","0.4872","2.2864","8.4598"
"3.1200","0.7494","0.7494","0.4996","2.3303","8.6220"
"3.2000","0.7698","0.7698","0.5132","2.3907","8.8456"
"3.2800","0.7892","0.7892","0.5262","2.4503","9.0661"
"3.3600","0.8096","0.8096","0.5398","2.5154","9.3071"
"3.4400","0.8298","0.8298","0.5532","2.5769","9.5346"
"3.5200","0.8484","0.8484","0.5656","2.6350","9.7494"
"3.6000","0.8692","0.8692","0.5795","2.6908","9.9558"
"3.6800","0.8899","0.8899","0.5933","2.7587","10.2073"
"3.7600","0.9101","0.9101","0.6067","2.8230","10.4450"
"3.8400","0.9301","0.9301","0.6201","2.8869","10.6816"
"3.9200","0.9492","0.9492","0.6328","2.9409","10.8814"
"4.0000","0.9693","0.9693","0.6462","3.0093","11.1343"
"4.0800","0.9898","0.9898","0.6599","3.0746","11.3758"
"4.1600","1.0087","1.0087","0.6724","3.1255","11.5643"
"4.2400","1.0302","1.0302","0.6868","3.2006","11.8423"
"4.3200","1.0503","1.0503","0.7002","3.2641","12.0772"
"4.4000","1.0704","1.0704","0.7136","3.3302","12.3217"
"4.4800","1.0895","1.0895","0.7263","3.3936","12.5564"
"4.5600","1.1092","1.1092","0.7395","3.4577","12.7933"
"4.6400","1.1295","1.1295","0.7530","3.5251","13.0427"
"4.7200","1.1496","1.1496","0.7664","3.5810","13.2496"
"4.8000","1.1681","1.1681","0.7788","3.6375","13.4587"
"4.8800","1.1898","1.1898","0.7932","3.7112","13.7313"
"4.9600","1.2100","1.2100","0.8067","3.7775","13.9766"
"5.0400","1.2304","1.2304","0.8203","3.8455","14.2282"
"5.1200","1.2494","1.2494","0.8329","3.9087","14.4623"
"5.2000","1.2687","1.2687","0.8458","3.9748","14.7068"
"5.2800","1.2893","1.2893","0.8596","4.0467","14.9729"
"5.3600","1.3096","1.3096","0.8731","4.1159","15.2289"
"5.4400","1.3297","1.3297","0.8864","4.1825","15.4751"
"5.5200","1.3508","1.3508","0.9005","4.2456","15.7088"
"5.6000","1.3695","1.3695","0.9130","4.3018","15.9167"
"5.6800","1.3897","1.3897","0.9265","4.3705","16.1710"
"5.7600","1.4098","1.4098","0.9399","4.4408","16.4309"
"5.8400","1.4291","1.4291","0.9527","4.5102","16.6878"
"5.9200","1.4497","1.4497","0.9665","4.5808","16.9488"
"6.0000","1.4680","1.4680","0.9787","4.6454","17.1880"
"6.0800","1.4894","1.4894","0.9930","4.7187","17.4594"
"6.1600","1.5104","1.5104","1.0069","4.7914","17.7282"
"6.2400","1.5298","1.5298","1.0199","4.8508","17.9481"
"6.3200","1.5493","1.5493","1.0329","4.9195","18.2020"
"6.4000","1.5694","1.5694","1.0462","4.9910","18.4668"
"6.4800","1.5887","1.5887","1.0591","5.0569","18.7106"
"6.5600","1.6099","1.6099","1.0733","5.1291","18.9776"
"6.6400","1.6291","1.6291","1.0861","5.1931","19.2143"
"6.7200","1.6506","1.6506","1.1004","5.2684","19.4931"
"6.8000","1.6706","1.6706","1.1137","5.3397","19.7570"
"6.8800","1.6897","1.6897","1.1265","5.4060","20.0021"
"6.9600","1.7095","1.7095","1.1397","5.4745","20.2555"
"7.0400","1.7298","1.7298","1.1532","5.5435","20.5110"
"7.1200","1.7494","1.7494","1.1662","5.6039","20.7345"
"7.2000","1.7692","1.7692","1.1795","5.6744","20.9954"
"7.2800","1.7882","1.7882","1.1922","5.7414","21.2432"
"7.3600","1.8099","1.8099","1.2066","5.8238","21.5482"
"7.4400","1.8304","1.8304","1.2202","5.8940","21.8077"
"7.5200","1.8500","1.8500","1.2333","5.9658","22.0736"
"7.6000","1.8697","1.8697","1.2464","6.0314","22.3161"
"7.6800","1.8885","1.8885","1.2590","6.0937","22.5468"
"7.7600","1.9099","1.9099","1.2733","6.1667","22.8166"
"7.8400","1.9298","1.9298","1.2866","6.2375","23.0786"
"7.9200","1.9494","1.9494","1.2996","6.3063","23.3333"
"8.0000","1.9696","1.9696","1.3130","6.3779","23.5982"
"8.0800","1.9900","1.9900","1.3266","6.4452","23.8472"
"8.1600","2.0103","2.0103","1.3402","6.5162","24.1101"
"8.2400","2.0303","2.0303","1.3535","6.5857","24.3671"
"8.3200","2.0483","2.0483","1.3655","6.6490","24.6011"
"8.4000","2.0697","2.0697","1.3798","6.7266","24.8885"
"8.4800","2.0886","2.0886","1.3924","6.7911","25.1270"
"8.5600","2.1089","2.1089","1.4059","6.8630","25.3929"
"8.6400","2.1299","2.1299","1.4199","6.9432","25.6900"
"8.7200","2.1501","2.1501","1.4334","7.0113","25.9418"
"8.8000","2.1698","2.1698","1.4466","7.0748","26.1767"
"8.8800","2.1900","2.1900","1.4600","7.1443","26.4338"
"8.9600","2.2088","2.2088","1.4725","7.2128","26.6873"
"9.0400","2.2297","2.2297","1.4865","7.2872","26.9625"
"9.1200","2.2491","2.2491","1.4994","7.3538","27.2089"
"9.2000","2.2697","2.2697","1.5131","7.4264","27.4777"
"9.2800","2.2905","2.2905","1.5270","7.5025","27.7593"
"9.3600","2.3101","2.3101","1.5401","7.5718","28.0156"
"9.4400","2.3302","2.3302","1.5534","7.6416","28.2738"
"9.5200","2.3496","2.3496","1.5664","7.7096","28.5255"
"9.6000","2.3687","2.3687","1.5791","7.7814","28.7912"
"9.6800","2.3892","2.3892","1.5928","7.8548","29.0626"
"9.7600","2.4090","2.4090","1.6060","7.9216","29.3098"
"9.8400","2.4297","2.4297","1.6198","8.0000","29.5998"
"9.9200","2.4504","2.4504","1.6336","8.0705","29.8610"
"10.0000","2.4690","2.4690","1.6460","8.1377","30.1095"
"10.0800","2.4900","2.4900","1.6600","8.2142","30.3924"
"10.1600","2.5092","2.5092","1.6728","8.2804","30.6375"
"10.2400","2.5297","2.5297","1.6865","8.3523","30.9035"
"10.3200","2.5494","2.5494","1.6996","8.4208","31.1569"
"10.4000","2.5695","2.5695","1.7130","8.4966","31.4373"
"10.4800","2.5897","2.5897","1.7265","8.5671","31.6983"
"10.5600","2.6106","2.6106","1.7404","8.6435","31.9808"
"10.6400","2.6299","2.6299","1.7533","8.7124","32.2360"
"10.7200","2.6496","2.6496","1.7664","8.7801","32.4863"
"10.8000","2.6688","2.6688","1.7792","8.8457","32.7292"
"10.8800","2.6896","2.6896","1.7931","8.9207","33.0066"
"10.9600","2.7096","2.7096","1.8064","8.9916","33.2687"
"11.0400","2.7289","2.7289","1.8192","9.0569","33.5107"
"11.1200","2.7493","2.7493","1.8329","9.1334","33.7935"
"11.2000","2.7699","2.7699","1.8466","9.2060","34.0624"
"11.2800","2.7898","2.7898","1.8599","9.2742","34.3144"
"11.3600","2.8101","2.8101","1.8734","9.3492","34.5921"
"11.4400","2.8291","2.8291","1.8861","9.4144","34.8332"
"11.5200","2.8496","2.8496","1.8997","9.4867","35.1008"
"11.6000","2.8694","2.8694","1.9129","9.5534","35.3474"
"11.6800","2.8893","2.8893","1.9262","9.6270","35.6199"
"11.7600","2.9106","2.9106","1.9404","9.7026","35.8997"
"11.8400","2.9300","2.9300","1.9533","9.7684","36.1431"
"11.9200","2.9503","2.9503","1.9669","9.8422","36.4161"
"12.0000","2.9700","2.9700","1.9800","9.9128","36.6773"
"12.0800","2.9889","2.9889","1.9926","9.9811","36.9300"
"12.1600","3.0093","3.0093","2.0062","10.0522","37.1933"
"12.2400","3.0290","3.0290","2.0194","10.1222","37.4523"
"12.3200","3.0487","3.0487","2.0325","10.1892","37.6999"
"12.4000","3.0699","3.0699","2.0466","10.2681","37.9919"
"12.4800","3.0895","3.0895","2.0597","10.3359","38.2428"
"12.5600","3.1102","3.1102","2.0735","10.4073","38.5070"
"12.6400","3.1299","3.1299","2.0866","10.4773","38.7660"
"12.7200","3.1489","3.1489","2.0992","10.5444","39.0142"
"12.8000","3.1689","3.1689","2.1126","10.6161","39.2796"
"12.8800","3.1891","3.1891","2.1260","10.6850","39.5346"
"12.9600","3.2097","3.2097","2.1398","10.7592","39.8091"
"13.0400","3.2310","3.2310","2.1540","10.8349","40.0893"
"13.1200","3.2494","3.2494","2.1662","10.8959","40.3149"
"13.2000","3.2694","3.2694","2.1796","10.9641","40.5673"
"13.2800","3.2892","3.2892","2.1928","11.0354","40.8310"
"13.3600","3.3097","3.3097","2.2064","11.1086","41.1017"
"13.4400","3.3298","3.3298","2.2199","11.1774","41.3565"
"13.5200","3.3485","3.3485","2.2323","11.2450","41.6065"
"13.6000","3.3694","3.3694","2.2462","11.3168","41.8720"
"13.6800","3.3900","3.3900","2.2600","11.3884","42.1372"
"13.7600","3.4099","3.4099","2.2733","11.4605","42.4040"
"13.8400","3.4299","3.4299","2.2866","11.5295","42.6593"
"13.9200","3.4491","3.4491","2.2994","11.5944","42.8993"
"14.0000","3.4690","3.4690","2.3127","11.6636","43.1554"
"14.0800","3.4901","3.4901","2.3267","11.7347","43.4185"
"14.1600","3.5092","3.5092","2.3395","11.8027","43.6701"
"14.2400","3.5301","3.5301","2.3534","11.8769","43.9447"
"14.3200","3.5501","3.5501","2.3667","11.9473","44.2049"
"14.4000","3.5702","3.5702","2.3801","12.0147","44.4543"
"14.4800","3.5896","3.5896","2.3931","12.0785","44.6904"
"14.5600","3.6091","3.6091","2.4060","12.1404","44.9195"
"14.6400","3.6296","3.6296","2.4197","12.2121","45.1847"
"14.7200","3.6495","3.6495","2.4330","12.2798","45.4352"
"14.8000","3.6682","3.6682","2.4454","12.3423","45.6664"
"14.8800","3.6895","3.6895","2.4597","12.4202","45.9546"
"14.9600","3.7098","3.7098","2.4732","12.4901","46.2132"
"15.0400","3.7304","3.7304","2.4869","12.5602","46.4726"
"15.1200","3.7498","3.7498","2.4999","12.6245","46.7108"
"15.2000","3.7684","3.7684","2.5123","12.6867","46.9407"
"15.2800","3.7889","3.7889","2.5260","12.7588","47.2076"
"15.3600","3.8097","3.8097","2.5398","12.8304","47.4723"
"15.4400","3.8300","3.8300","2.5533","12.9012","47.7346"
"15.5200","3.8506","3.8506","2.5671","12.9723","47.9977"
"15.6000","3.8697","3.8697","2.5798","13.0358","48.2326"
"15.6800","3.8900","3.8900","2.5933","13.1023","48.4787"
"15.7600","3.9099","3.9099","2.6066","13.1703","48.7301"
"15.8400","3.9289","3.9289","2.6193","13.2356","48.9718"
"15.9200","3.9493","3.9493","2.6329","13.3048","49.2279"
"16.0000","3.9683","3.9683","2.6455","13.3678","49.4610"
"16.0800","3.9890","3.9890","2.6594","13.4365","49.7152"
"16.1600","4.0103","4.0103","2.6735","13.5103","49.9882"
"16.2400","4.0301","4.0301","2.6868","13.5762","50.2319"
"16.3200","4.0496","4.0496","2.6998","13.6403","50.4690"
"16.4000","4.0693","4.0693","2.7128","13.7060","50.7123"
"16.4800","4.0886","4.0886","2.7257","13.7700","50.9491"
"16.5600","4.1097","4.1097","2.7398","13.8466","51.2325"
"16.6400","4.1290","4.1290","2.7527","13.9056","51.4507"
"16.7200","4.1503","4.1503","2.7668","13.9786","51.7206"
"16.8000","4.1705","4.1705","2.7803","14.0424","51.9570"
"16.8800","4.1898","4.1898","2.7932","14.1092","52.2039"
"16.9600","4.2095","4.2095","2.8063","14.1735","52.4421"
"17.0400","4.2292","4.2292","2.8194","14.2394","52.6857"
"17.1200","4.2495","4.2495","2.8330","14.3043","52.9259"
"17.2000","4.2693","4.2693","2.8462","14.3712","53.1734"
"17.2800","4.2883","4.2883","2.8588","14.4344","53.4072"
"17.3600","4.3094","4.3094","2.8730","14.5073","53.6769"
"17.4400","4.3303","4.3303","2.8869","14.5768","53.9343"
"17.5200","4.3497","4.3497","2.8998","14.6406","54.1703"
"17.6000","4.3696","4.3696","2.9131","14.7064","54.4138"
"17.6800","4.3886","4.3886","2.9257","14.7667","54.6368"
"17.7600","4.4099","4.4099","2.9399","14.8363","54.8944"
"17.8400","4.4300","4.4300","2.9534","14.8995","55.1280"
"17.9200","4.4490","4.4490","2.9660","14.9637","55.3656"
"18.0000","4.4692","4.4692","2.9795","15.0311","55.6152"
"18.0800","4.4902","4.4902","2.9935","15.1007","55.8724"
"18.1600","4.5105","4.5105","3.0070","15.1667","56.1168"
"18.2400","4.5305","4.5305","3.0204","15.2305","56.3529"
"18.3200","4.5488","4.5488","3.0325","15.2870","56.5619"
"18.4000","4.5692","4.5692","3.0461","15.3525","56.8041"
"18.4800","4.5886","4.5886","3.0591","15.4153","57.0366"
"18.5600","4.6090","4.6090","3.0726","15.4808","57.2789"
"18.6400","4.6301","4.6301","3.0867","15.5527","57.5449"
"18.7200","4.6501","4.6501","3.1001","15.6141","57.7722"
"18.8000","4.6697","4.6697","3.1132","15.6785","58.0103"
"18.8800","4.6900","4.6900","3.1266","15.7417","58.2441"
"18.9600","4.7087","4.7087","3.1391","15.8017","58.4662"
"19.0400","4.7293","4.7293","3.1529","15.8703","58.7200"
"19.1200","4.7491","4.7491","3.1661","15.9352","58.9604"
"19.2000","4.7698","4.7698","3.1798","15.9993","59.1976"
"19.2800","4.7905","4.7905","3.1937","16.0647","59.4394"
"19.3600","4.8100","4.8100","3.2067","16.1272","59.6706"
"19.4400","4.8301","4.8301","3.2201","16.1886","59.8980"
"19.5200","4.8499","4.8499","3.2333","16.2512","60.1293"
"19.6000","4.8689","4.8689","3.2460","16.3124","60.3560"
"19.6800","4.8892","4.8892","3.2595","16.3766","60.5935"
"19.7600","4.9084","4.9084","3.2723","16.4382","60.8213"
"19.8400","4.9295","4.9295","3.2864","16.5035","61.0631"
"19.9200","4.9503","4.9503","3.3002","16.5692","61.3061"
"20.0000","4.9696","4.9696","3.3131","16.6309","61.5345"
"20.0800","4.9896","4.9896","3.3264","16.6921","61.7608"
"20.1600","5.0092","5.0092","3.3395","16.7549","61.9931"
"20.2400","5.0300","5.0300","3.3533","16.8209","62.2371"
"20.3200","5.0495","5.0495","3.3663","16.8827","62.4662"
"20.4000","5.0687","5.0687","3.3791","16.9425","62.6871"
"20.4800","5.0896","5.0896","3.3930","17.0075","62.9278"
"20.5600","5.1107","5.1107","3.4072","17.0741","63.1743"
"20.6400","5.1296","5.1296","3.4197","17.1292","63.3782"
"20.7200","5.1501","5.1501","3.4334","17.1953","63.6225"
"20.8000","5.1688","5.1688","3.4458","17.2505","63.8269"
"20.8800","5.1894","5.1894","3.4596","17.3132","64.0590"
"20.9600","5.2094","5.2094","3.4729","17.3729","64.2796"
"21.0400","5.2286","5.2286","3.4857","17.4337","64.5047"
"21.1200","5.2496","5.2496","3.4997","17.5026","64.7597"
"21.2000","5.2703","5.2703","3.5136","17.5662","64.9949"
"21.2800","5.2897","5.2897","3.5265","17.6234","65.2065"
"21.3600","5.3101","5.3101","3.5401","17.6860","65.4382"
"21.4400","5.3293","5.3293","3.5528","17.7437","65.6516"
"21.5200","5.3496","5.3496","3.5664","17.8073","65.8870"
"21.6000","5.3696","5.3696","3.5797","17.8660","66.1044"
"21.6800","5.3892","5.3892","3.5928","17.9298","66.3402"
"21.7600","5.4103","5.4103","3.6068","17.9955","66.5835"
"21.8400","5.4300","5.4300","3.6200","18.0537","66.7987"
"21.9200","5.4505","5.4505","3.6337","18.1157","67.0280"
"22.0000","5.4701","5.4701","3.6468","18.1715","67.2346"
"22.0800","5.4889","5.4889","3.6592","18.2297","67.4498"
"22.1600","5.5096","5.5096","3.6730","18.2922","67.6812"
"22.2400","5.5291","5.5291","3.6861","18.3493","67.8923"
"22.3200","5.5486","5.5486","3.6991","18.4099","68.1164"
"22.4000","5.5700","5.5700","3.7133","18.4744","68.3552"
"22.4800","5.5895","5.5895","3.7264","18.5323","68.5695"
"22.5600","5.6104","5.6104","3.7403","18.5933","68.7952"
"22.6400","5.6299","5.6299","3.7533","18.6508","69.0081"
"22.7200","5.6489","5.6489","3.7659","18.7097","69.2261"
"22.8000","5.6686","5.6686","3.7791","18.7663","69.4352"
"22.8800","5.6890","5.6890","3.7927","18.8266","69.6583"
"22.9600","5.7101","5.7101","3.8067","18.8897","69.8920"
"23.0400","5.7313","5.7313","3.8208","18.9531","70.1264"
"23.1200","5.7494","5.7494","3.8329","19.0076","70.3281"
"23.2000","5.7696","5.7696","3.8464","19.0642","70.5377"
"23.2800","5.7892","5.7892","3.8595","19.1224","70.7529"
"23.3600","5.8094","5.8094","3.8729","19.1824","70.9749"
"23.4400","5.8296","5.8296","3.8864","19.2452","71.2073"
"23.5200","5.8483","5.8483","3.8989","19.2953","71.3925"
"23.6000","5.8692","5.8692","3.9128","19.3550","71.6135"
"23.6800","5.8899","5.8899","3.9266","19.4175","71.8446"
"23.7600","5.9099","5.9099","3.9400","19.4763","72.0624"
"23.8400","5.9299","5.9299","3.9532","19.5333","72.2732"
"23.9200","5.9492","5.9492","3.9662","19.5880","72.4758"
"24.0000","5.9693","5.9693","3.9795","19.6448","72.6859"
"24.0800","5.9898","5.9898","3.9932","19.7066","72.9146"
"24.1600","6.0090","6.0090","4.0060","19.7631","73.1235"
"24.2400","6.0301","6.0301","4.0201","19.8250","73.3526"
"24.3200","6.0501","6.0501","4.0334","19.8836","73.5694"
"24.4000","6.0702","6.0702","4.0468","19.9361","73.7635"
"24.4800","6.0894","6.0894","4.0596","19.9936","73.9763"
"24.5600","6.1096","6.1096","4.0731","20.0542","74.2006"
"24.6400","6.1300","6.1300","4.0867","20.1119","74.4140"
"24.7200","6.1496","6.1496","4.0998","20.1631","74.6034"
"24.8000","6.1683","6.1683","4.1122","20.2184","74.8081"
"24.8800","6.1897","6.1897","4.1265","20.2864","75.0595"
"24.9600","6.2097","6.2097","4.1398","20.3388","75.2537"
"25.0400","6.2304","6.2304","4.1536","20.3998","75.4793"
"25.1200","6.2494","6.2494","4.1663","20.4481","75.6579"
"25.2000","6.2683","6.2683","4.1789","20.5037","75.8638"
"25.2800","6.2893","6.2893","4.1929","20.5642","76.0874"
"25.3600","6.3098","6.3098","4.2066","20.6249","76.3122"
"25.4400","6.3296","6.3296","4.2197","20.6798","76.5153"
"25.5200","6.3500","6.3500","4.2333","20.7401","76.7383"
"25.6000","6.3695","6.3695","4.2463","20.7915","76.9285"
"25.6800","6.3902","6.3902","4.2601","20.8500","77.1448"
"25.7600","6.4102","6.4102","4.2734","20.9056","77.3507"
"25.8400","6.4290","6.4290","4.2860","20.9566","77.5393"
"25.9200","6.4493","6.4493","4.2995","21.0161","77.7594"
"26.0000","6.4685","6.4685","4.3123","21.0678","77.9510"
"26.0800","6.4891","6.4891","4.3261","21.1250","78.1627"
"26.1600","6.5103","6.5103","4.3402","21.1854","78.3859"
"26.2400","6.5301","6.5301","4.3534","21.2426","78.5976"
"26.3200","6.5495","6.5495","4.3663","21.2934","78.7855"
"26.4000","6.5694","6.5694","4.3796","21.3498","78.9944"
"26.4800","6.5889","6.5889","4.3926","21.4044","79.1965"
"26.5600","6.6099","6.6099","4.4066","21.4643","79.4178"
"26.6400","6.6289","6.6289","4.4193","21.5136","79.6005"
"26.7200","6.6504","6.6504","4.4336","21.5728","79.8192"
"26.8000","6.6705","6.6705","4.4470","21.6270","80.0199"
"26.8800","6.6902","6.6902","4.4601","21.6837","80.2295"
"26.9600","6.7100","6.7100","4.4734","21.7423","80.4464"
"27.0400","6.7297","6.7297","4.4865","21.7953","80.6426"
"27.1200","6.7495","6.7495","4.4997","21.8465","80.8319"
"27.2000","6.7695","6.7695","4.5130","21.9017","81.0365"
"27.2800","6.7880","6.7880","4.5253","21.9513","81.2197"
"27.3600","6.8097","6.8097","4.5398","22.0123","81.4456"
"27.4400","6.8304","6.8304","4.5536","22.0690","81.6551"
"27.5200","6.8497","6.8497","4.5665","22.1220","81.8513"
"27.6000","6.8695","6.8695","4.5797","22.1749","82.0471"
"27.6800","6.8886","6.8886","4.5924","22.2233","82.2260"
"27.7600","6.9099","6.9099","4.6066","22.2798","82.4353"
"27.8400","6.9298","6.9298","4.6199","22.3362","82.6439"
"27.9200","6.9491","6.9491","4.6327","22.3899","82.8427"
"28.0000","6.9697","6.9697","4.6465","22.4481","83.0581"
"28.0800","6.9901","6.9901","4.6601","22.5006","83.2521"
"28.1600","7.0103","7.0103","4.6735","22.5542","83.4505"
"28.2400","7.0304","7.0304","4.6870","22.6080","83.6495"
"28.3200","7.0483","7.0483","4.6989","22.6519","83.8120"
"28.4000","7.0690","7.0690","4.7127","22.7080","84.0195"
"28.4800","7.0890","7.0890","4.7260","22.7605","84.2139"
"28.5600","7.1090","7.1090","4.7394","22.8162","84.4198"
"28.6400","7.1298","7.1298","4.7532","22.8744","84.6354"
"28.7200","7.1502","7.1502","4.7668","22.9246","84.8210"
"28.8000","7.1700","7.1700","4.7800","22.9743","85.0050"
"28.8800","7.1901","7.1901","4.7934","23.0298","85.2102"
"28.9600","7.2087","7.2087","4.8058","23.0786","85.3908"
"29.0400","7.2298","7.2298","4.8199","23.1357","85.6022"
"29.1200","7.2491","7.2491","4.8327","23.1860","85.7883"
"29.2000","7.2698","7.2698","4.8465","23.2391","85.9845"
"29.2800","7.2907","7.2907","4.8605","23.2925","86.1824"
"29.3600","7.3101","7.3101","4.8734","23.3440","86.3727"
"29.4400","7.3300","7.3300","4.8866","23.3947","86.5604"
"29.5200","7.3497","7.3497","4.8998","23.4442","86.7436"
"29.6000","7.3689","7.3689","4.9126","23.4952","86.9322"
"29.6800","7.3892","7.3892","4.9261","23.5509","87.1385"
"29.7600","7.4088","7.4088","4.9392","23.5956","87.3037"
"29.8400","7.4298","7.4298","4.9532","23.6499","87.5047"
"29.9200","7.4503","7.4503","4.9669","23.7066","87.7145"
"30.0000","7.4690","7.4690","4.9793","23.7559","87.8969"
"30.0800","7.4898","7.4898","4.9932","23.8079","88.0891"
"30.1600","7.5091","7.5091","5.0061","23.8585","88.2765"
"30.2400","7.5296","7.5296","5.0197","23.9094","88.4649"
"30.3200","7.5494","7.5494","5.0329","23.9595","88.6503"
"30.4000","7.5687","7.5687","5.0458","24.0082","88.8302"
"30.4800","7.5899","7.5899","5.0599","24.0612","89.0263"
"30.5600","7.6109","7.6109","5.0740","24.1159","89.2287"
"30.6400","7.6298","7.6298","5.0865","24.1600","89.3920"
"30.7200","7.6496","7.6496","5.0997","24.2093","89.5745"
"30.8000","7.6690","7.6690","5.1127","24.2593","89.7593"
"30.8800","7.6895","7.6895","5.1264","24.3072","89.9367"
"30.9600","7.7094","7.7094","5.1396","24.3554","90.1151"
"31.0400","7.7286","7.7286","5.1524","24.4028","90.2903"
"31.1200","7.7494","7.7494","5.1663","24.4591","90.4985"
"31.2000","7.7700","7.7700","5.1800","24.5060","90.6722"
"31.2800","7.7895","7.7895","5.1930","24.5561","90.8575"
"31.3600","7.8100","7.8100","5.2067","24.6045","91.0365"
"31.4400","7.8294","7.8294","5.2196","24.6555","91.2254"
"31.5200","7.8499","7.8499","5.2333","24.7052","91.4092"
"31.6000","7.8695","7.8695","5.2464","24.7509","91.5782"
"31.6800","7.8890","7.8890","5.2593","24.8021","91.7676"
"31.7600","7.9105","7.9105","5.2737","24.8565","91.9689"
"31.8400","7.9303","7.9303","5.2869","24.9004","92.1316"
"31.9200","7.9504","7.9504","5.3003","24.9464","92.3015"
"32.0000","7.9697","7.9697","5.3131","24.9893","92.4602"
"32.0800","7.9888","7.9888","5.3259","25.0377","92.6395"
"32.1600","8.0094","8.0094","5.3396","25.0870","92.8218"
"32.2400","8.0293","8.0293","5.3529","25.1352","93.0002"
"32.3200","8.0488","8.0488","5.3659","25.1813","93.1708"
"32.4000","8.0697","8.0697","5.3798","25.2327","93.3609"
"32.4800","8.0892","8.0892","5.3928","25.2793","93.5335"
"32.5600","8.1103","8.1103","5.4069","25.3285","93.7153"
"32.6400","8.1297","8.1297","5.4198","25.3724","93.8779"
"32.7200","8.1489","8.1489","5.4326","25.4158","94.0385"
"32.8000","8.1691","8.1691","5.4461","25.4671","94.2281"
"32.8800","8.1891","8.1891","5.4594","25.5130","94.3981"
"32.9600","8.2103","8.2103","5.4735","25.5654","94.5919"
"33.0400","8.2311","8.2311","5.4874","25.6146","94.7740"
"33.1200","8.2499","8.2499","5.4999","25.6563","94.9282"
"33.2000","8.2695","8.2695","5.5130","25.7034","95.1026"
"33.2800","8.2892","8.2892","5.5261","25.7472","95.2646"
"33.3600","8.3094","8.3094","5.5396","25.7941","95.4381"
"33.4400","8.3298","8.3298","5.5532","25.8407","95.6107"
"33.5200","8.3485","8.3485","5.5657","25.8797","95.7550"
"33.6000","8.3693","8.3693","5.5795","25.9287","95.9364"
"33.6800","8.3901","8.3901","5.5934","25.9751","96.1080"
"33.7600","8.4096","8.4096","5.6064","26.0221","96.2817"
"33.8400","8.4301","8.4301","5.6200","26.0697","96.4580"
"33.9200","8.4494","8.4494","5.6329","26.1081","96.6001"
"34.0000","8.4692","8.4692","5.6462","26.1539","96.7693"
"34.0800","8.4899","8.4899","5.6600","26.1970","96.9287"
"34.1600","8.5089","8.5089","5.6726","26.2416","97.0938"
"34.2400","8.5303","8.5303","5.6868","26.2911","97.2772"
"34.3200","8.5505","8.5505","5.7003","26.3356","97.4417"
"34.4000","8.5703","8.5703","5.7135","26.3758","97.5903"
"34.4800","8.5897","8.5897","5.7265","26.4214","97.7593"
"34.5600","8.6094","8.6094","5.7396","26.4608","97.9050"
"34.6400","8.6297","8.6297","5.7531","26.5048","98.0678"
"34.7200","8.6494","8.6494","5.7663","26.5443","98.2139"
"34.8000","8.6682","8.6682","5.7788","26.5855","98.3662"
"34.8800","8.6896","8.6896","5.7931","26.6338","98.5452"
"34.9600","8.7097","8.7097","5.8065","26.6749","98.6970"
"35.0400","8.7303","8.7303","5.8202","26.7151","98.8459"
"35.1200","8.7498","8.7498","5.8332","26.7556","98.9957"
"35.2000","8.7686","8.7686","5.8457","26.7930","99.1340"
"35.2800","8.7891","8.7891","5.8594","26.8379","99.3001"
"35.3600","8.8097","8.8097","5.8732","26.8813","99.4608"
"35.4400","8.8298","8.8298","5.8865","26.9201","99.6042"
"35.5200","8.8509","8.8509","5.9006","26.9652","99.7712"
"35.6000","8.8698","8.8698","5.9132","26.9999","99.8997"
"35.6800","8.8898","8.8898","5.9266","27.0398","100.0471"
"35.7600","8.9097","8.9097","5.9398","27.0762","100.1820"
"35.8400","8.9292","8.9292","5.9528","27.1193","100.3415"
"35.9200","8.9496","8.9496","5.9664","27.1609","100.4952"
"36.0000","8.9681","8.9681","5.9788","27.1926","100.6127"
"36.0800","8.9888","8.9888","5.9925","27.2333","100.7633"
"36.1600","9.0099","9.0099","6.0066","27.2768","100.9243"
"36.2400","9.0302","9.0302","6.0202","27.3147","101.0645"
"36.3200","9.0499","9.0499","6.0333","27.3533","101.2073"
"36.4000","9.0693","9.0693","6.0462","27.3891","101.3397"
"36.4800","9.0884","9.0884","6.0589","27.4229","101.4648"
"36.5600","9.1099","9.1099","6.0733","27.4677","101.6304"
"36.6400","9.1290","9.1290","6.0860","27.5029","101.7607"
"36.7200","9.1502","9.1502","6.1001","27.5447","101.9155"
"36.8000","9.1705","9.1705","6.1136","27.5819","102.0530"
"36.8800","9.1899","9.1899","6.1266","27.6189","102.1899"
"36.9600","9.2095","9.2095","6.1397","27.6557","102.3262"
"37.0400","9.2294","9.2294","6.1529","27.6885","102.4476"
"37.1200","9.2493","9.2493","6.1662","27.7251","102.5830"
"37.2000","9.2693","9.2693","6.1796","27.7612","102.7164"
"37.2800","9.2882","9.2882","6.1921","27.7943","102.8390"
"37.3600","9.3097","9.3097","6.2065","27.8353","102.9908"
"37.4400","9.3304","9.3304","6.2203","27.8742","103.1345"
"37.5200","9.3500","9.3500","6.2333","27.9063","103.2533"
"37.6000","9.3698","9.3698","6.2465","27.9418","103.3846"
"37.6800","9.3887","9.3887","6.2592","27.9736","103.5024"
"37.7600","9.4096","9.4096","6.2731","28.0098","103.6361"
"37.8400","9.4298","9.4298","6.2865","28.0463","103.7713"
"37.9200","9.4491","9.4491","6.2994","28.0799","103.8957"
"38.0000","9.4695","9.4695","6.3130","28.1161","104.0294"
"38.0800","9.4901","9.4901","6.3267","28.1516","104.1608"
"38.1600","9.5102","9.5102","6.3401","28.1835","104.2791"
"38.2400","9.5307","9.5307","6.3538","28.2199","104.4138"
"38.3200","9.5484","9.5484","6.3656","28.2466","104.5126"
"38.4000","9.5690","9.5690","6.3794","28.2794","104.6339"
"38.4800","9.5888","9.5888","6.3925","28.3141","104.7622"
"38.5600","9.6090","9.6090","6.4060","28.3493","104.8925"
"38.6400","9.6301","9.6301","6.4201","28.3817","105.0122"
"38.7200","9.6500","9.6500","6.4333","28.4151","105.1358"
"38.8000","9.6699","9.6699","6.4466","28.4456","105.2488"
"38.8800","9.6897","9.6897","6.4598","28.4730","105.3500"
"38.9600","9.7085","9.7085","6.4724","28.5040","105.4647"
"39.0400","9.7293","9.7293","6.4862","28.5383","105.5916"
"39.1200","9.7492","9.7492","6.4994","28.5685","105.7035"
"39.2000","9.7700","9.7700","6.5133","28.6003","105.8213"
"39.2800","9.7907","9.7907","6.5271","28.6339","105.9454"
"39.3600","9.8100","9.8100","6.5400","28.6594","106.0398"
"39.4400","9.8299","9.8299","6.5533","28.6863","106.1393"
"39.5200","9.8498","9.8498","6.5665","28.7154","106.2469"
"39.6000","9.8688","9.8688","6.5792","28.7440","106.3527"
"39.6800","9.8893","9.8893","6.5929","28.7748","106.4667"
"39.7600","9.9087","9.9087","6.6058","28.7988","106.5556"
"39.8400","9.9296","9.9296","6.6197","28.8306","106.6734"
"39.9200","9.9506","9.9506","6.6337","28.8593","106.7795"
"40.0000","9.9691","9.9691","6.6461","28.8849","106.8739"
"40.0800","9.9897","9.9897","6.6598","28.9121","106.9748"
"40.1600","10.0090","10.0090","6.6727","28.9374","107.0683"
"40.2400","10.0296","10.0296","6.6864","28.9622","107.1602"
"40.3200","10.0496","10.0496","6.6997","28.9893","107.2606"
"40.4000","10.0692","10.0692","6.7128","29.0165","107.3609"
"40.4800","10.0896","10.0896","6.7264","29.0436","107.4612"
"40.5600","10.1109","10.1109","6.7406","29.0712","107.5634"
"40.6400","10.1300","10.1300","6.7533","29.0966","107.6574"
"40.7200","10.1499","10.1499","6.7666","29.1206","107.7462"
"40.8000","10.1688","10.1688","6.7792","29.1390","107.8144"
"40.8800","10.1896","10.1896","6.7931","29.1654","107.9121"
"40.9600","10.2095","10.2095","6.8063","29.1869","107.9916"
"41.0400","10.2287","10.2287","6.8191","29.2089","108.0729"
"41.1200","10.2493","10.2493","6.8328","29.2370","108.1769"
"41.2000","10.2699","10.2699","6.8466","29.2594","108.2599"
"41.2800","10.2899","10.2899","6.8600","29.2829","108.3466"
"41.3600","10.3102","10.3102","6.8735","29.3076","108.4380"
"41.4400","10.3290","10.3290","6.8860","29.3260","108.5061"
"41.5200","10.3493","10.3493","6.8995","29.3464","108.5818"
"41.6000","10.3696","10.3696","6.9131","29.3701","108.6694"
"41.6800","10.3893","10.3893","6.9262","29.3899","108.7427"
"41.7600","10.4102","10.4102","6.9402","29.4137","108.8307"
"41.8400","10.4299","10.4299","6.9532","29.4297","108.8899"
"41.9200","10.4503","10.4503","6.9669","29.4510","108.9688"
"42.0000","10.4699","10.4699","6.9799","29.4669","109.0274"
"42.0800","10.4890","10.4890","6.9927","29.4863","109.0993"
"42.1600","10.5090","10.5090","7.0060","29.5036","109.1632"
"42.2400","10.5292","10.5292","7.0195","29.5206","109.2264"
"42.3200","10.5487","10.5487","7.0325","29.5384","109.2919"
"42.4000","10.5701","10.5701","7.0467","29.5602","109.3727"
"42.4800","10.5892","10.5892","7.0595","29.5726","109.4185"
"42.5600","10.6102","10.6102","7.0735","29.5946","109.4999"
"42.6400","10.6298","10.6298","7.0865","29.6088","109.5524"
"42.7200","10.6491","10.6491","7.0994","29.6251","109.6128"
"42.8000","10.6691","10.6691","7.1127","29.6407","109.6704"
"42.8800","10.6891","10.6891","7.1261","29.6575","109.7327"
"42.9600","10.7099","10.7099","7.1400","29.6730","109.7899"
"43.0400","10.7313","10.7313","7.1542","29.6907","109.8555"
"43.1200","10.7499","10.7499","7.1666","29.7018","109.8967"
"43.2000","10.7695","10.7695","7.1797","29.7154","109.9469"
"43.2800","10.7892","10.7892","7.1928","29.7286","109.9959"
"43.3600","10.8096","10.8096","7.2064","29.7423","110.0467"
"43.4400","10.8300","10.8300","7.2200","29.7601","110.1125"
"43.5200","10.8483","10.8483","7.2322","29.7689","110.1449"
"43.6000","10.8691","10.8691","7.2461","29.7837","110.1998"
"43.6800","10.8898","10.8898","7.2599","29.8003","110.2612"
"43.7600","10.9096","10.9096","7.2731","29.8119","110.3039"
"43.8400","10.9300","10.9300","7.2867","29.8263","110.3574"
"43.9200","10.9494","10.9494","7.2996","29.8347","110.3885"
"44.0000","10.9694","10.9694","7.3130","29.8474","110.4353"
"44.0800","10.9900","10.9900","7.3266","29.8563","110.4684"
"44.1600","11.0088","11.0088","7.3392","29.8700","110.5189"
"44.2400","11.0302","11.0302","7.3535","29.8854","110.5761"
"44.3200","11.0503","11.0503","7.3669","29.8962","110.6161"
"44.4000","11.0704","11.0704","7.3802","29.9059","110.6517"
"44.4800","11.0894","11.0894","7.3930","29.9141","110.6821"
"44.5600","11.1092","11.1092","7.4061","29.9227","110.7139"
"44.6400","11.1294","11.1294","7.4196","29.9343","110.7570"
"44.7200","11.1493","11.1493","7.4329","29.9415","110.7834"
"44.8000","11.1680","11.1680","7.4453","29.9523","110.8235"
"44.8800","11.1894","11.1894","7.4596","29.9679","110.8813"
"44.9600","11.2099","11.2099","7.4733","29.9753","110.9087"
"45.0400","11.2309","11.2309","7.4873","29.9893","110.9605"
"45.1200","11.2495","11.2495","7.4997","29.9900","110.9630"
"45.2000","11.2682","11.2682","7.5121","29.9985","110.9944"
"45.2800","11.2894","11.2894","7.5263","30.0100","111.0372"
"45.3600","11.3097","11.3097","7.5398","30.0177","111.0655"
"45.4400","11.3298","11.3298","7.5532","30.0254","111.0941"
"45.5200","11.3505","11.3505","7.5670","30.0354","111.1310"
"45.6000","11.3697","11.3697","7.5798","30.0390","111.1443"
"45.6800","11.3900","11.3900","7.5934","30.0468","111.1731"
"45.7600","11.4103","11.4103","7.6069","30.0545","111.2017"
"45.8400","11.4292","11.4292","7.6195","30.0600","111.2221"
"45.9200","11.4493","11.4493","7.6329","30.0682","111.2524"
"46.0000","11.4680","11.4680","7.6454","30.0722","111.2672"
"46.0800","11.4892","11.4892","7.6595","30.0791","111.2926"
"46.1600","11.5105","11.5105","7.6737","30.0895","111.3313"
"46.2400","11.5299","11.5299","7.6866","30.0926","111.3426"
"46.3200","11.5490","11.5490","7.6993","30.0926","111.3428"
"46.4000","11.5695","11.5695","7.7130","30.1008","111.3729"
"46.4800","11.5886","11.5886","7.7258","30.1047","111.3876"
"46.5600","11.6101","11.6101","7.7401","30.1115","111.4125"
"46.6400","11.6291","11.6291","7.7527","30.1121","111.4148"
"46.7200","11.6504","11.6504","7.7669","30.1198","111.4434"
"46.8000","11.6703","11.6703","7.7802","30.1230","111.4552"
"46.8800","11.6900","11.6900","7.7933","30.1269","111.4694"
"46.9600","11.7096","11.7096","7.8064","30.1290","111.4773"
"47.0400","11.7296","11.7296","7.8197","30.1323","111.4897"
"47.1200","11.7498","11.7498","7.8332","30.1354","111.5010"
"47.2000","11.7697","11.7697","7.8465","30.1390","111.5144"
"47.2800","11.7879","11.7879","7.8586","30.1377","111.5096"
"47.3600","11.8096","11.8096","7.8730","30.1472","111.5445"
"47.4400","11.8305","11.8305","7.8870","30.1505","111.5569"
"47.5200","11.8500","11.8500","7.9000","30.1510","111.5587"
"47.6000","11.8695","11.8695","7.9130","30.1492","111.5520"
"47.6800","11.8886","11.8886","7.9257","30.1493","111.5522"
"47.7600","11.9099","11.9099","7.9399","30.1520","111.5623"
"47.8400","11.9299","11.9299","7.9532","30.1521","111.5628"
"47.9200","11.9494","11.9494","7.9663","30.1535","111.5681"
"48.0000","11.9696","11.9696","7.9797","30.1596","111.5905"
"48.0800","11.9904","11.9904","7.9936","30.1584","111.5860"
"48.1600","12.0104","12.0104","8.0069","30.1615","111.5976"
"48.2400","12.0306","12.0306","8.0204","30.1611","111.5959"
"48.3200","12.0484","12.0484","8.0323","30.1558","111.5766"
"48.4000","12.0697","12.0697","8.0465","30.1603","111.5932"
"48.4800","12.0886","12.0886","8.0591","30.1583","111.5856"
"48.5600","12.1082","12.1082","8.0721","30.1564","111.5788"
"48.6400","12.1294","12.1294","8.0862","30.1626","111.6015"
"48.7200","12.1502","12.1502","8.1001","30.1635","111.6051"
"48.8000","12.1701","12.1701","8.1134","30.1639","111.6065"
"48.8800","12.1901","12.1901","8.1267","30.1625","111.6013"
"48.9600","12.2087","12.2087","8.1392","30.1620","111.5995"
"49.0400","12.2295","12.2295","8.1530","30.1643","111.6078"
"49.1200","12.2489","12.2489","8.1660","30.1636","111.6052"
"49.2000","12.2694","12.2694","8.1796","30.1634","111.6047"
"49.2800","12.2907","12.2907","8.1938","30.1658","111.6135"
"49.3600","12.3100","12.3100","8.2066","30.1670","111.6181"
"49.4400","12.3302","12.3302","8.2202","30.1674","111.6192"
"49.5200","12.3496","12.3496","8.2331","30.1672","111.6186"
"49.6000","12.3689","12.3689","8.2459","30.1677","111.6205"
"49.6800","12.3894","12.3894","8.2596","30.1713","111.6338"
"49.7600","12.4089","12.4089","8.2726","30.1672","111.6187"
"49.8400","12.4293","12.4293","8.2862","30.1670","111.6180"
"49.9200","12.4504","12.4504","8.3002","30.1680","111.6216"
"50.0000","12.4691","12.4691","8.3127","30.1652","111.6112"
"50.0800","12.4898","12.4898","8.3265","30.1660","111.6144"
"50.1600","12.5093","12.5093","8.3395","30.1648","111.6097"
"50.2400","12.5300","12.5300","8.3533","30.1647","111.6095"
"50.3200","12.5496","12.5496","8.3664","30.1618","111.5986"
"50.4000","12.5690","12.5690","8.3793","30.1599","111.5918"
"50.4800","12.5898","12.5898","8.3932","30.1619","111.5989"
"50.5600","12.6108","12.6108","8.4072","30.1607","111.5947"
"50.6400","12.6300","12.6300","8.4200","30.1580","111.5845"
"50.7200","12.6500","12.6500","8.4333","30.1554","111.5748"
"50.8000","12.6688","12.6688","8.4458","30.1475","111.5458"
"50.8800","12.6895","12.6895","8.4596","30.1473","111.5449"
"50.9600","12.7095","12.7095","8.4730","30.1457","111.5393"
"51.0400","12.7287","12.7287","8.4858","30.1444","111.5342"
"51.1200","12.7494","12.7494","8.4996","30.1443","111.5338"
"51.2000","12.7699","12.7699","8.5133","30.1394","111.5159"
"51.2800","12.7895","12.7895","8.5263","30.1347","111.4982"
"51.3600","12.8102","12.8102","8.5401","30.1341","111.4962"
"51.4400","12.8290","12.8290","8.5527","30.1257","111.4649"
"51.5200","12.8496","12.8496","8.5664","30.1214","111.4491"
"51.6000","12.8697","12.8697","8.5798","30.1178","111.4358"
"51.6800","12.8890","12.8890","8.5927","30.1180","111.4367"
"51.7600","12.9104","12.9104","8.6069","30.1177","111.4356"
"51.8400","12.9300","12.9300","8.6200","30.1110","111.4105"
"51.9200","12.9501","12.9501","8.6334","30.1068","111.3950"
"52.0000","12.9699","12.9700","8.6466","30.1014","111.3750"
"52.0800","12.9889","12.9889","8.6593","30.0941","111.3482"
"52.1600","13.0093","13.0093","8.6728","30.0933","111.3452"
"52.2400","13.0292","13.0292","8.6861","30.0848","111.3137"
"52.3200","13.0486","13.0486","8.6990","30.0798","111.2954"
"52.4000","13.0702","13.0702","8.7134","30.0768","111.2840"
"52.4800","13.0893","13.0893","8.7262","30.0690","111.2554"
"52.5600","13.1105","13.1105","8.7403","30.0654","111.2419"
"52.6400","13.1297","13.1297","8.7532","30.0581","111.2151"
"52.7200","13.1493","13.1493","8.7662","30.0519","111.1921"
"52.8000","13.1692","13.1692","8.7795","30.0454","111.1680"
"52.8800","13.1893","13.1893","8.7929","30.0360","111.1334"
"52.9600","13.2101","13.2101","8.8067","30.0318","111.1178"
"53.0400","13.2314","13.2314","8.8209","30.0243","111.0899"
"53.1200","13.2495","13.2495","8.8330","30.0158","111.0586"
"53.2000","13.2697","13.2697","8.8465","30.0116","111.0431"
"53.2800","13.2893","13.2893","8.8596","30.0022","111.0081"
"53.3600","13.3093","13.3093","8.8729","29.9960","110.9854"
"53.4400","13.3295","13.3295","8.8864","29.9883","110.9569"
"53.5200","13.3484","13.3484","8.8989","29.9765","110.9129"
"53.6000","13.3694","13.3694","8.9129","29.9703","110.8900"
"53.6800","13.3901","13.3901","8.9267","29.9658","110.8736"
"53.7600","13.4094","13.4094","8.9396","29.9550","110.8333"
"53.8400","13.4298","13.4298","8.9532","29.9497","110.8138"
"53.9200","13.4493","13.4493","8.9662","29.9397","110.7770"
"54.0000","13.4692","13.4692","8.9795","29.9306","110.7433"
"54.0800","13.4899","13.4899","8.9933","29.9236","110.7175"
"54.1600","13.5088","13.5088","9.0059","29.9140","110.6820"
"54.2400","13.5303","13.5303","9.0202","29.9066","110.6545"
"54.3200","13.5501","13.5501","9.0334","29.8996","110.6284"
"54.4000","13.5702","13.5702","9.0468","29.8891","110.5896"
"54.4800","13.5895","13.5895","9.0597","29.8807","110.5586"
"54.5600","13.6093","13.6093","9.0729","29.8732","110.5309"
"54.6400","13.6300","13.6300","9.0867","29.8674","110.5093"
"54.7200","13.6496","13.6496","9.0997","29.8561","110.4675"
"54.8000","13.6683","13.6683","9.1122","29.8492","110.4419"
"54.8800","13.6896","13.6896","9.1264","29.8437","110.4217"
"54.9600","13.7098","13.7098","9.1399","29.8379","110.4001"
"55.0400","13.7308","13.7308","9.1538","29.8299","110.3706"
"55.1200","13.7498","13.7498","9.1665","29.8192","110.3311"
"55.2000","13.7684","13.7684","9.1789","29.8059","110.2819"
"55.2800","13.7891","13.7891","9.1927","29.8008","110.2629"
"55.3600","13.8098","13.8098","9.2066","29.7957","110.2440"
"55.4400","13.8302","13.8302","9.2201","29.7882","110.2165"
"55.5200","13.8510","13.8510","9.2340","29.7786","110.1808"
"55.6000","13.8697","13.8697","9.2464","29.7681","110.1419"
"55.6800","13.8899","13.8899","9.2599","29.7609","110.1153"
"55.7600","13.9098","13.9098","9.2732","29.7502","110.0756"
"55.8400","13.9290","13.9290","9.2860","29.7423","110.0465"
"55.9200","13.9494","13.9494","9.2996","29.7335","110.0141"
"56.0000","13.9684","13.9684","9.3123","29.7211","109.9681"
"56.0800","13.9890","13.9890","9.3260","29.7096","109.9256"
"56.1600","14.0098","14.0098","9.3399","29.7036","109.9032"
"56.2400","14.0301","14.0301","9.3534","29.6922","109.8613"
"56.3200","14.0498","14.0498","9.3666","29.6814","109.8213"
"56.4000","14.0694","14.0694","9.3796","29.6687","109.7744"
"56.4800","14.0888","14.0888","9.3925","29.6597","109.7410"
"56.5600","14.1101","14.1101","9.4067","29.6491","109.7018"
"56.6400","14.1292","14.1292","9.4195","29.6359","109.6529"
"56.7200","14.1501","14.1501","9.4334","29.6232","109.6057"
"56.8000","14.1703","14.1703","9.4469","29.6115","109.5624"
"56.8800","14.1898","14.1898","9.4599","29.6028","109.5304"
"56.9600","14.2098","14.2098","9.4732","29.5934","109.4954"
"57.0400","14.2295","14.2295","9.4863","29.5796","109.4447"
"57.1200","14.2493","14.2493","9.4995","29.5686","109.4036"
"57.2000","14.2695","14.2695","9.5130","29.5582","109.3652"
"57.2800","14.2881","14.2881","9.5254","29.5462","109.3211"
"57.3600","14.3099","14.3099","9.5399","29.5374","109.2883"
"57.4400","14.3302","14.3302","9.5535","29.5285","109.2554"
"57.5200","14.3497","14.3497","9.5665","29.5204","109.2256"
"57.6000","14.3696","14.3696","9.5797","29.5054","109.1701"
"57.6800","14.3889","14.3889","9.5926","29.4954","109.1330"
"57.7600","14.4100","14.4100","9.6067","29.4860","109.0983"
"57.8400","14.4302","14.4302","9.6201","29.4766","109.0633"
"57.9200","14.4491","14.4491","9.6327","29.4680","109.0318"
"58.0000","14.4696","14.4696","9.6464","29.4586","108.9967"
"58.0800","14.4901","14.4901","9.6600","29.4481","108.9579"
"58.1600","14.5104","14.5104","9.6736","29.4383","108.9218"
"58.2400","14.5303","14.5303","9.6868","29.4275","108.8818"
"58.3200","14.5487","14.5487","9.6991","29.4157","108.8380"
"58.4000","14.5692","14.5692","9.7128","29.4060","108.8022"
"58.4800","14.5887","14.5887","9.7258","29.3955","108.7635"
"58.5600","14.6090","14.6090","9.7393","29.3860","108.7283"
"58.6400","14.6297","14.6297","9.7531","29.3769","108.6945"
"58.7200","14.6501","14.6501","9.7667","29.3641","108.6472"
"58.8000","14.6700","14.6700","9.7800","29.3513","108.5997"
"58.8800","14.6899","14.6899","9.7933","29.3351","108.5398"
"58.9600","14.7086","14.7086","9.8057","29.3232","108.4958"
"59.0400","14.7295","14.7295","9.8197","29.3119","108.4539"
"59.1200","14.7490","14.7490","9.8327","29.2983","108.4037"
"59.2000","14.7692","14.7692","9.8462","29.2845","108.3527"
"59.2800","14.7906","14.7906","9.8604","29.2754","108.3190"
"59.3600","14.8100","14.8100","9.8734","29.2619","108.2689"
"59.4400","14.8301","14.8301","9.8868","29.2475","108.2156"
"59.5200","14.8496","14.8496","9.8997","29.2329","108.1618"
"59.6000","14.8688","14.8688","9.9126","29.2190","108.1102"
"59.6800","14.8890","14.8890","9.9260","29.2068","108.0653"
"59.7600","14.9087","14.9087","9.9391","29.1919","108.0102"
"59.8400","14.9294","14.9294","9.9529","29.1787","107.9611"
"59.9200","14.9503","14.9503","9.9669","29.1662","107.9149"
"60.0000","14.9694","14.9694","9.9796","29.1537","107.8686"
"60.0800","14.9898","14.9898","9.9932","29.1413","107.8227"
"60.1210","15.0001","15.0001","10.0001","29.1319","107.7881"