File: data/instron_tests/metamaterial_samples/510_BULK_m1.is_comp_Exports/510_BULK_m1_4_1.csv
Sample text inputs : Sample No.,Sample choice input : Leading Direction,Sample choice input : Mode,Specimen choice input : Direction,Specimen properties : Height,Specimen properties : Thickness,Specimen properties : Width,Test : Rate 1
,,,,(mm),(mm),(mm),(mm/min)
"510","Bulk","Unimode","1","150.00","25.00","150.00","15.00"

Time,Displacement,Compressive displacement,Compressive strain (Displacement),Compressive stress,Force
(s),(mm),(mm),(%),(kPa),(N)
"0.0000","0.0000","0.0000","0.0000","-0.3653","-1.3426"
"0.0800","0.0009","0.0009","0.0006","-0.3660","-1.3450"
"0.1600","0.0090","0.0090","0.0060","-0.3392","-1.2464"
"0.2400","0.0298","0.0298","0.0199","-0.2892","-1.0629"
"0.3200","0.0500","0.0500","0.0334","-0.2375","-0.8730"
"0.4000","0.0693","0.0693","0.0462","-0.1877","-0.6899"
"0.4800","0.0895","0.0895","0.0597","-0.1393","-0.5118"
"0.5600","0.1088","0.1088","0.0726","-0.0935","-0.3437"
"0.6400","0.1279","0.1279","0.0853","-0.0488","-0.1793"
"0.7200","0.1481","0.1481","0.0988","-0.0016","-0.0060"
"0.8000","0.1679","0.1679","0.1120","0.0419","0.1540"
"0.8800","0.1896","0.1896","0.1264","0.0906","0.3328"
"0.9600","0.2099","0.2099","0.1399","0.1344","0.4940"
"1.0400","0.2290","0.2290","0.1527","0.1790","0.6578"
"1.1200","0.2487","0.2487","0.1658","0.2201","0.8090"
"1.2000","0.2686","0.2686","0.1791","0.2642","0.9709"
"1.2800","0.2886","0.2886","0.1924","0.3082","1.1325"
"1.3600","0.3088","0.3088","0.2059","0.3547","1.3034"
"1.4400","0.3270","0.3270","0.2180","0.3868","1.4214"
"1.5200","0.3492","0.3492","0.2328","0.4403","1.6180"
"1.6000","0.3690","0.3690","0.2460","0.4808","1.7671"
"1.6800","0.3890","0.3890","0.2593","0.5207","1.9134"
"1.7600","0.4094","0.4094","0.2729","0.5677","2.0864"
"1.8400","0.4276","0.4276","0.2851","0.6056","2.2257"
"1.9200","0.4485","0.4485","0.2990","0.6528","2.3989"
"2.0000","0.4692","0.4692","0.3128","0.7001","2.5727"
"2.0800","0.4886","0.4886","0.3257","0.7414","2.7247"
"2.1600","0.5090","0.5090","0.3393","0.7852","2.8855"
"2.2400","0.5290","0.5290","0.3527","0.8305","3.0521"
"2.3200","0.5491","0.5491","0.3660","0.8727","3.2072"
"2.4000","0.5696","0.5696","0.3797","0.9149","3.3624"
"2.4800","0.5878","0.5878","0.3918","0.9580","3.5206"
"2.5600","0.6084","0.6084","0.4056","1.0044","3.6911"
"2.6400","0.6278","0.6278","0.4186","1.0468","3.8468"
"2.7200","0.6481","0.6481","0.4321","1.0940","4.0205"
"2.8000","0.6686","0.6686","0.4457","1.1406","4.1917"
"2.8800","0.6891","0.6891","0.4594","1.1843","4.3522"
"2.9600","0.7088","0.7088","0.4725","1.2308","4.5231"
"3.0400","0.7287","0.7287","0.4858","1.2769","4.6927"
"3.1200","0.7472","0.7472","0.4982","1.3169","4.8395"
"3.2000","0.7683","0.7683","0.5122","1.3645","5.0147"
"3.2800","0.7888","0.7888","0.5259","1.4146","5.1985"
"3.3600","0.8097","0.8097","0.5398","1.4599","5.3650"
"3.4400","0.8296","0.8296","0.5531","1.5067","5.5372"
"3.5200","0.8486","0.8486","0.5657","1.5465","5.6832"
"3.6000","0.8691","0.8691","0.5794","1.5954","5.8632"
"3.6800","0.8889","0.8889","0.5926","1.6449","6.0450"
"3.7600","0.9083","0.9083","0.6055","1.6892","6.2078"
"3.8400","0.9285","0.9285","0.6190","1.7393","6.3920"
"3.9200","0.9477","0.9477","0.6318","1.7761","6.5271"
"4.0000","0.9686","0.9686","0.6457","1.8261","6.7111"
"4.0800","0.9900","0.9900","0.6600","1.8766","6.8966"
"4.1600","1.0086","1.0086","0.6724","1.9236","7.0694"
"4.2400","1.0289","1.0289","0.6859","1.9705","7.2415"
"4.3200","1.0479","1.0479","0.6986","2.0155","7.4070"
"4.4000","1.0687","1.0687","0.7125","2.0614","7.5755"
"4.4800","1.0890","1.0890","0.7260","2.1066","7.7416"
"4.5600","1.1085","1.1085","0.7390","2.1569","7.9264"
"4.6400","1.1288","1.1288","0.7526","2.2068","8.1101"
"4.7200","1.1496","1.1496","0.7664","2.2544","8.2849"
"4.8000","1.1689","1.1689","0.7792","2.3023","8.4608"
"4.8800","1.1898","1.1898","0.7932","2.3488","8.6319"
"4.9600","1.2080","1.2080","0.8053","2.3925","8.7924"
"5.0400","1.2284","1.2284","0.8189","2.4418","8.9735"
"5.1200","1.2483","1.2483","0.8322","2.4895","9.1489"
"5.2000","1.2677","1.2677","0.8451","2.5404","9.3358"
"5.2800","1.2889","1.2889","0.8593","2.5920","9.5257"
"5.3600","1.3093","1.3093","0.8729","2.6358","9.6867"
"5.4400","1.3291","1.3291","0.8861","2.6831","9.8605"
"5.5200","1.3487","1.3487","0.8991","2.7330","10.0436"
"5.6000","1.3675","1.3675","0.9117","2.7782","10.2100"
"5.6800","1.3889","1.3889","0.9260","2.8339","10.4147"
"5.7600","1.4089","1.4089","0.9393","2.8839","10.5982"
"5.8400","1.4281","1.4281","0.9521","2.9266","10.7554"
"5.9200","1.4488","1.4488","0.9659","2.9796","10.9502"
"6.0000","1.4689","1.4689","0.9793","3.0281","11.1281"
"6.0800","1.4895","1.4895","0.9930","3.0789","11.3148"
"6.1600","1.5090","1.5090","1.0060","3.1260","11.4881"
"6.2400","1.5280","1.5280","1.0187","3.1753","11.6693"
"6.3200","1.5481","1.5481","1.0321","3.2274","11.8608"
"6.4000","1.5682","1.5682","1.0455","3.2744","12.0334"
"6.4800","1.5881","1.5881","1.0587","3.3222","12.2091"
"6.5600","1.6097","1.6097","1.0732","3.3804","12.4230"
"6.6400","1.6286","1.6286","1.0858","3.4275","12.5961"
"6.7200","1.6493","1.6493","1.0995","3.4782","12.7822"
"6.8000","1.6684","1.6684","1.1122","3.5262","12.9588"
"6.8800","1.6883","1.6883","1.1255","3.5804","13.1581"
"6.9600","1.7084","1.7084","1.1389","3.6319","13.3471"
"7.0400","1.7283","1.7283","1.1522","3.6739","13.5016"
"7.1200","1.7487","1.7487","1.1658","3.7296","13.7064"
"7.2000","1.7703","1.7703","1.1802","3.7863","13.9147"
"7.2800","1.7892","1.7892","1.1928","3.8354","14.0951"
"7.3600","1.8093","1.8093","1.2062","3.8898","14.2950"
"7.4400","1.8283","1.8283","1.2189","3.9368","14.4677"
"7.5200","1.8486","1.8486","1.2324","3.9884","14.6572"
"7.6000","1.8686","1.8686","1.2457","4.0364","14.8336"
"7.6800","1.8878","1.8878","1.2585","4.0855","15.0142"
"7.7600","1.9088","1.9088","1.2726","4.1391","15.2112"
"7.8400","1.9292","1.9292","1.2861","4.1918","15.4050"
"7.9200","1.9485","1.9485","1.2990","4.2424","15.5906"
"8.0000","1.9688","1.9688","1.3126","4.2990","15.7989"
"8.0800","1.9887","1.9887","1.3258","4.3479","15.9786"
"8.1600","2.0086","2.0086","1.3391","4.3922","16.1413"
"8.2400","2.0292","2.0292","1.3528","4.4452","16.3361"
"8.3200","2.0476","2.0476","1.3651","4.4960","16.5229"
"8.4000","2.0690","2.0690","1.3793","4.5534","16.7336"
"8.4800","2.0892","2.0892","1.3928","4.6028","16.9155"
"8.5600","2.1090","2.1090","1.4060","4.6546","17.1056"
"8.6400","2.1287","2.1287","1.4191","4.7059","17.2943"
"8.7200","2.1485","2.1485","1.4323","4.7530","17.4673"
"8.8000","2.1685","2.1685","1.4457","4.8060","17.6622"
"8.8800","2.1885","2.1885","1.4590","4.8550","17.8420"
"8.9600","2.2077","2.2077","1.4718","4.9087","18.0395"
"9.0400","2.2289","2.2289","1.4859","4.9659","18.2497"
"9.1200","2.2490","2.2490","1.4993","5.0150","18.4301"
"9.2000","2.2694","2.2694","1.5129","5.0695","18.6304"
"9.2800","2.2892","2.2892","1.5262","5.1146","18.7963"
"9.3600","2.3080","2.3080","1.5386","5.1684","18.9938"
"9.4400","2.3282","2.3282","1.5521","5.2209","19.1870"
"9.5200","2.3483","2.3483","1.5655","5.2740","19.3818"
"9.6000","2.3685","2.3685","1.5790","5.3291","19.5843"
"9.6800","2.3900","2.3900","1.5933","5.3861","19.7941"
"9.7600","2.4089","2.4089","1.6060","5.4342","19.9707"
"9.8400","2.4290","2.4290","1.6193","5.4832","20.1509"
"9.9200","2.4489","2.4489","1.6326","5.5355","20.3428"
"10.0000","2.4682","2.4682","1.6455","5.5882","20.5366"
"10.0800","2.4889","2.4889","1.6593","5.6474","20.7541"
"10.1600","2.5075","2.5075","1.6717","5.6939","20.9251"
"10.2400","2.5282","2.5282","1.6855","5.7510","21.1349"
"10.3200","2.5492","2.5492","1.6994","5.8103","21.3529"
"10.4000","2.5690","2.5690","1.7127","5.8627","21.5453"
"10.4800","2.5891","2.5891","1.7260","5.9165","21.7432"
"10.5600","2.6086","2.6086","1.7390","5.9647","21.9204"
"10.6400","2.6279","2.6279","1.7519","6.0166","22.1109"
"10.7200","2.6485","2.6485","1.7657","6.0751","22.3260"
"10.8000","2.6680","2.6680","1.7786","6.1268","22.5161"
"10.8800","2.6893","2.6893","1.7928","6.1840","22.7262"
"10.9600","2.7100","2.7100","1.8067","6.2421","22.9398"
"11.0400","2.7293","2.7293","1.8196","6.2981","23.1456"
"11.1200","2.7479","2.7479","1.8319","6.3467","23.3241"
"11.2000","2.7685","2.7685","1.8456","6.4023","23.5286"
"11.2800","2.7890","2.7890","1.8593","6.4567","23.7282"
"11.3600","2.8088","2.8088","1.8725","6.5053","23.9071"
"11.4400","2.8272","2.8272","1.8848","6.5563","24.0945"
"11.5200","2.8487","2.8487","1.8991","6.6182","24.3219"
"11.6000","2.8697","2.8697","1.9131","6.6740","24.5268"
"11.6800","2.8894","2.8894","1.9262","6.7282","24.7261"
"11.7600","2.9086","2.9086","1.9390","6.7786","24.9113"
"11.8400","2.9274","2.9274","1.9516","6.8305","25.1022"
"11.9200","2.9487","2.9487","1.9658","6.8898","25.3202"
"12.0000","2.9690","2.9690","1.9794","6.9461","25.5269"
"12.0800","2.9886","2.9886","1.9924","7.0004","25.7263"
"12.1600","3.0090","3.0090","2.0060","7.0579","25.9379"
"12.2400","3.0292","3.0292","2.0195","7.1134","26.1418"
"12.3200","3.0490","3.0490","2.0326","7.1675","26.3405"
"12.4000","3.0691","3.0691","2.0461","7.2237","26.5471"
"12.4800","3.0881","3.0881","2.0587","7.2785","26.7486"
"12.5600","3.1088","3.1088","2.0725","7.3312","26.9423"
"12.6400","3.1279","3.1279","2.0853","7.3843","27.1373"
"12.7200","3.1477","3.1477","2.0984","7.4400","27.3422"
"12.8000","3.1689","3.1689","2.1126","7.5012","27.5670"
"12.8800","3.1891","3.1891","2.1261","7.5552","27.7655"
"12.9600","3.2089","3.2089","2.1393","7.6083","27.9606"
"13.0400","3.2289","3.2289","2.1526","7.6636","28.1637"
"13.1200","3.2476","3.2476","2.1651","7.7188","28.3667"
"13.2000","3.2688","3.2688","2.1792","7.7794","28.5895"
"13.2800","3.2882","3.2882","2.1921","7.8336","28.7883"
"13.3600","3.3089","3.3089","2.2059","7.8907","28.9981"
"13.4400","3.3295","3.3295","2.2197","7.9463","29.2025"
"13.5200","3.3486","3.3486","2.2324","7.9994","29.3978"
"13.6000","3.3689","3.3689","2.2459","8.0565","29.6075"
"13.6800","3.3887","3.3887","2.2591","8.1123","29.8128"
"13.7600","3.4084","3.4084","2.2723","8.1669","30.0132"
"13.8400","3.4284","3.4284","2.2856","8.2247","30.2259"
"13.9200","3.4474","3.4474","2.2983","8.2764","30.4158"
"14.0000","3.4684","3.4684","2.3122","8.3329","30.6234"
"14.0800","3.4897","3.4897","2.3265","8.3924","30.8419"
"14.1600","3.5086","3.5086","2.3391","8.4467","31.0417"
"14.2400","3.5288","3.5288","2.3525","8.5020","31.2449"
"14.3200","3.5481","3.5481","2.3654","8.5563","31.4446"
"14.4000","3.5685","3.5685","2.3790","8.6130","31.6526"
"14.4800","3.5889","3.5889","2.3926","8.6718","31.8687"
"14.5600","3.6082","3.6082","2.4055","8.7244","32.0620"
"14.6400","3.6287","3.6287","2.4191","8.7831","32.2780"
"14.7200","3.6496","3.6496","2.4331","8.8421","32.4947"
"14.8000","3.6693","3.6693","2.4462","8.8993","32.7048"
"14.8800","3.6894","3.6894","2.4596","8.9562","32.9140"
"14.9600","3.7080","3.7080","2.4720","9.0070","33.1008"
"15.0400","3.7284","3.7284","2.4856","9.0629","33.3063"
"15.1200","3.7482","3.7482","2.4988","9.1181","33.5089"
"15.2000","3.7676","3.7676","2.5117","9.1744","33.7159"
"15.2800","3.7889","3.7889","2.5259","9.2389","33.9529"
"15.3600","3.8092","3.8092","2.5395","9.2953","34.1601"
"15.4400","3.8288","3.8288","2.5525","9.3498","34.3604"
"15.5200","3.8489","3.8489","2.5659","9.4079","34.5742"
"15.6000","3.8678","3.8678","2.5786","9.4589","34.7613"
"15.6800","3.8889","3.8889","2.5926","9.5214","34.9912"
"15.7600","3.9087","3.9087","2.6058","9.5768","35.1949"
"15.8400","3.9285","3.9285","2.6190","9.6311","35.3941"
"15.9200","3.9490","3.9490","2.6327","9.6916","35.6167"
"16.0000","3.9688","3.9688","2.6459","9.7455","35.8147"
"16.0800","3.9900","3.9900","2.6600","9.8054","36.0350"
"16.1600","4.0093","4.0093","2.6729","9.8609","36.2389"
"16.2400","4.0277","4.0277","2.6851","9.9136","36.4325"
"16.3200","4.0479","4.0479","2.6986","9.9767","36.6644"
"16.4000","4.0681","4.0681","2.7121","10.0316","36.8662"
"16.4800","4.0883","4.0883","2.7255","10.0891","37.0775"
"16.5600","4.1096","4.1096","2.7397","10.1497","37.3002"
"16.6400","4.1286","4.1286","2.7524","10.2058","37.5062"
"16.7200","4.1492","4.1492","2.7662","10.2632","37.7172"
"16.8000","4.1687","4.1687","2.7792","10.3228","37.9364"
"16.8800","4.1880","4.1880","2.7920","10.3776","38.1377"
"16.9600","4.2084","4.2084","2.8056","10.4400","38.3669"
"17.0400","4.2284","4.2284","2.8189","10.4969","38.5760"
"17.1200","4.2487","4.2487","2.8324","10.5535","38.7843"
"17.2000","4.2700","4.2700","2.8467","10.6144","39.0079"
"17.2800","4.2892","4.2892","2.8595","10.6720","39.2197"
"17.3600","4.3093","4.3093","2.8729","10.7295","39.4310"
"17.4400","4.3281","4.3281","2.8854","10.7820","39.6238"
"17.5200","4.3481","4.3481","2.8987","10.8389","39.8331"
"17.6000","4.3686","4.3686","2.9124","10.8999","40.0573"
"17.6800","4.3874","4.3874","2.9250","10.9538","40.2554"
"17.7600","4.4087","4.4087","2.9391","11.0119","40.4687"
"17.8400","4.4291","4.4291","2.9527","11.0715","40.6878"
"17.9200","4.4487","4.4487","2.9658","11.1289","40.8988"
"18.0000","4.4690","4.4690","2.9793","11.1897","41.1222"
"18.0800","4.4887","4.4887","2.9925","11.2453","41.3266"
"18.1600","4.5088","4.5088","3.0059","11.3026","41.5371"
"18.2400","4.5288","4.5288","3.0192","11.3582","41.7414"
"18.3200","4.5475","4.5475","3.0317","11.4149","41.9498"
"18.4000","4.5697","4.5697","3.0465","11.4830","42.2001"
"18.4800","4.5899","4.5899","3.0599","11.5415","42.4148"
"18.5600","4.6092","4.6092","3.0728","11.5956","42.6139"
"18.6400","4.6290","4.6290","3.0860","11.6540","42.8283"
"18.7200","4.6479","4.6479","3.0986","11.7083","43.0278"
"18.8000","4.6683","4.6683","3.1122","11.7656","43.2386"
"18.8800","4.6885","4.6885","3.1257","11.8234","43.4512"
"18.9600","4.7081","4.7081","3.1387","11.8816","43.6649"
"19.0400","4.7289","4.7289","3.1526","11.9445","43.8962"
"19.1200","4.7487","4.7487","3.1658","12.0006","44.1023"
"19.2000","4.7694","4.7694","3.1796","12.0601","44.3209"
"19.2800","4.7891","4.7891","3.1927","12.1168","44.5291"
"19.3600","4.8082","4.8082","3.2054","12.1727","44.7346"
"19.4400","4.8283","4.8283","3.2188","12.2325","44.9544"
"19.5200","4.8482","4.8482","3.2321","12.2886","45.1608"
"19.6000","4.8686","4.8686","3.2457","12.3492","45.3834"
"19.6800","4.8903","4.8903","3.2602","12.4136","45.6200"
"19.7600","4.9092","4.9092","3.2728","12.4706","45.8294"
"19.8400","4.9291","4.9291","3.2860","12.5261","46.0335"
"19.9200","4.9487","4.9487","3.2991","12.5825","46.2409"
"20.0000","4.9680","4.9680","3.3120","12.6423","46.4603"
"20.0800","4.9886","4.9886","3.3258","12.7039","46.6868"
"20.1600","5.0074","5.0074","3.3382","12.7526","46.8657"
"20.2400","5.0279","5.0279","3.3519","12.8155","47.0971"
"20.3200","5.0491","5.0491","3.3661","12.8743","47.3131"
"20.4000","5.0689","5.0689","3.3793","12.9318","47.5243"
"20.4800","5.0888","5.0888","3.3926","12.9940","47.7529"
"20.5600","5.1088","5.1088","3.4059","13.0496","47.9573"
"20.6400","5.1282","5.1282","3.4188","13.1071","48.1686"
"20.7200","5.1485","5.1485","3.4324","13.1656","48.3835"
"20.8000","5.1676","5.1676","3.4451","13.2235","48.5963"
"20.8800","5.1895","5.1895","3.4597","13.2886","48.8354"
"20.9600","5.2097","5.2097","3.4731","13.3463","49.0478"
"21.0400","5.2292","5.2292","3.4861","13.4039","49.2592"
"21.1200","5.2477","5.2477","3.4985","13.4584","49.4597"
"21.2000","5.2687","5.2687","3.5125","13.5197","49.6851"
"21.2800","5.2889","5.2889","3.5259","13.5823","49.9151"
"21.3600","5.3092","5.3092","3.5394","13.6418","50.1336"
"21.4400","5.3274","5.3274","3.5516","13.6939","50.3252"
"21.5200","5.3487","5.3487","3.5658","13.7570","50.5570"
"21.6000","5.3692","5.3692","3.5795","13.8165","50.7755"
"21.6800","5.3890","5.3890","3.5926","13.8755","50.9925"
"21.7600","5.4088","5.4088","3.6059","13.9325","51.2018"
"21.8400","5.4276","5.4276","3.6184","13.9842","51.3918"
"21.9200","5.4485","5.4485","3.6323","14.0466","51.6214"
"22.0000","5.4691","5.4691","3.6461","14.1101","51.8547"
"22.0800","5.4887","5.4887","3.6591","14.1685","52.0691"
"22.1600","5.5090","5.5090","3.6727","14.2302","52.2958"
"22.2400","5.5292","5.5292","3.6861","14.2874","52.5064"
"22.3200","5.5492","5.5492","3.6995","14.3424","52.7082"
"22.4000","5.5693","5.5693","3.7129","14.4038","52.9339"
"22.4800","5.5880","5.5880","3.7253","14.4582","53.1340"
"22.5600","5.6086","5.6086","3.7391","14.5199","53.3606"
"22.6400","5.6280","5.6280","3.7520","14.5756","53.5654"
"22.7200","5.6481","5.6481","3.7654","14.6395","53.8003"
"22.8000","5.6691","5.6691","3.7794","14.7039","54.0369"
"22.8800","5.6892","5.6892","3.7928","14.7583","54.2366"
"22.9600","5.7090","5.7090","3.8060","14.8179","54.4559"
"23.0400","5.7290","5.7290","3.8193","14.8755","54.6674"
"23.1200","5.7474","5.7474","3.8316","14.9315","54.8732"
"23.2000","5.7687","5.7687","3.8458","14.9962","55.1109"
"23.2800","5.7883","5.7883","3.8589","15.0521","55.3163"
"23.3600","5.8093","5.8093","3.8729","15.1145","55.5456"
"23.4400","5.8298","5.8298","3.8865","15.1757","55.7708"
"23.5200","5.8484","5.8484","3.8989","15.2332","55.9820"
"23.6000","5.8683","5.8683","3.9122","15.2920","56.1980"
"23.6800","5.8891","5.8891","3.9260","15.3541","56.4262"
"23.7600","5.9086","5.9086","3.9391","15.4104","56.6331"
"23.8400","5.9282","5.9282","3.9522","15.4714","56.8572"
"23.9200","5.9474","5.9474","3.9649","15.5261","57.0584"
"24.0000","5.9685","5.9685","3.9790","15.5908","57.2963"
"24.0800","5.9897","5.9897","3.9931","15.6517","57.5200"
"24.1600","6.0087","6.0087","4.0058","15.7106","57.7365"
"24.2400","6.0289","6.0289","4.0193","15.7722","57.9628"
"24.3200","6.0479","6.0479","4.0319","15.8269","58.1640"
"24.4000","6.0688","6.0688","4.0459","15.8919","58.4026"
"24.4800","6.0890","6.0890","4.0593","15.9509","58.6195"
"24.5600","6.1080","6.1080","4.0720","16.0078","58.8288"
"24.6400","6.1286","6.1286","4.0857","16.0710","59.0610"
"24.7200","6.1500","6.1500","4.1000","16.1353","59.2972"
"24.8000","6.1693","6.1693","4.1129","16.1941","59.5133"
"24.8800","6.1893","6.1893","4.1262","16.2559","59.7405"
"24.9600","6.2079","6.2079","4.1386","16.3107","59.9420"
"25.0400","6.2283","6.2283","4.1522","16.3716","60.1657"
"25.1200","6.2486","6.2486","4.1657","16.4299","60.3800"
"25.2000","6.2676","6.2676","4.1784","16.4893","60.5982"
"25.2800","6.2888","6.2888","4.1925","16.5531","60.8327"
"25.3600","6.3096","6.3096","4.2064","16.6147","61.0592"
"25.4400","6.3293","6.3293","4.2195","16.6724","61.2709"
"25.5200","6.3491","6.3491","4.2328","16.7314","61.4879"
"25.6000","6.3679","6.3679","4.2452","16.7861","61.6889"
"25.6800","6.3889","6.3889","4.2592","16.8532","61.9355"
"25.7600","6.4088","6.4088","4.2726","16.9108","62.1472"
"25.8400","6.4283","6.4283","4.2855","16.9693","62.3623"
"25.9200","6.4487","6.4487","4.2991","17.0326","62.5949"
"26.0000","6.4688","6.4688","4.3125","17.0948","62.8232"
"26.0800","6.4900","6.4900","4.3266","17.1554","63.0461"
"26.1600","6.5093","6.5093","4.3395","17.2142","63.2623"
"26.2400","6.5277","6.5277","4.3518","17.2675","63.4582"
"26.3200","6.5479","6.5479","4.3652","17.3301","63.6880"
"26.4000","6.5681","6.5681","4.3787","17.3936","63.9213"
"26.4800","6.5883","6.5883","4.3922","17.4581","64.1585"
"26.5600","6.6096","6.6096","4.4064","17.5210","64.3897"
"26.6400","6.6284","6.6284","4.4189","17.5788","64.6020"
"26.7200","6.6491","6.6491","4.4327","17.6397","64.8258"
"26.8000","6.6687","6.6687","4.4458","17.7006","65.0497"
"26.8800","6.6881","6.6881","4.4587","17.7600","65.2678"
"26.9600","6.7079","6.7079","4.4719","17.8216","65.4945"
"27.0400","6.7284","6.7284","4.4856","17.8821","65.7167"
"27.1200","6.7486","6.7486","4.4990","17.9446","65.9464"
"27.2000","6.7702","6.7702","4.5135","18.0103","66.1880"
"27.2800","6.7892","6.7892","4.5262","18.0711","66.4112"
"27.3600","6.8092","6.8092","4.5394","18.1332","66.6395"
"27.4400","6.8282","6.8282","4.5521","18.1883","66.8420"
"27.5200","6.8482","6.8482","4.5654","18.2486","67.0636"
"27.6000","6.8688","6.8688","4.5792","18.3134","67.3017"
"27.6800","6.8878","6.8878","4.5919","18.3699","67.5093"
"27.7600","6.9089","6.9089","4.6059","18.4352","67.7493"
"27.8400","6.9292","6.9292","4.6195","18.4976","67.9785"
"27.9200","6.9488","6.9488","4.6325","18.5584","68.2020"
"28.0000","6.9690","6.9690","4.6460","18.6232","68.4401"
"28.0800","6.9885","6.9885","4.6590","18.6790","68.6454"
"28.1600","7.0086","7.0086","4.6724","18.7417","68.8757"
"28.2400","7.0287","7.0287","4.6858","18.7999","69.0895"
"28.3200","7.0474","7.0474","4.6982","18.8584","69.3046"
"28.4000","7.0690","7.0690","4.7127","18.9289","69.5636"
"28.4800","7.0892","7.0892","4.7262","18.9888","69.7838"
"28.5600","7.1101","7.1101","4.7401","19.0532","70.0205"
"28.6400","7.1288","7.1288","4.7525","19.1110","70.2330"
"28.7200","7.1478","7.1478","4.7652","19.1653","70.4324"
"28.8000","7.1683","7.1683","4.7788","19.2289","70.6664"
"28.8800","7.1888","7.1888","4.7925","19.2941","70.9058"
"28.9600","7.2073","7.2073","4.8049","19.3507","71.1138"
"29.0400","7.2287","7.2287","4.8192","19.4202","71.3694"
"29.1200","7.2485","7.2485","4.8323","19.4780","71.5816"
"29.2000","7.2694","7.2694","4.8463","19.5449","71.8276"
"29.2800","7.2893","7.2893","4.8595","19.6023","72.0386"
"29.3600","7.3080","7.3080","4.8720","19.6625","72.2597"
"29.4400","7.3286","7.3286","4.8857","19.7283","72.5014"
"29.5200","7.3485","7.3485","4.8990","19.7891","72.7249"
"29.6000","7.3686","7.3686","4.9124","19.8528","72.9589"
"29.6800","7.3899","7.3899","4.9266","19.9210","73.2098"
"29.7600","7.4090","7.4090","4.9393","19.9763","73.4131"
"29.8400","7.4290","7.4290","4.9527","20.0385","73.6417"
"29.9200","7.4491","7.4491","4.9661","20.1014","73.8727"
"30.0000","7.4683","7.4683","4.9789","20.1622","74.0961"
"30.0800","7.4887","7.4887","4.9924","20.2273","74.3355"
"30.1600","7.5075","7.5075","5.0050","20.2858","74.5503"
"30.2400","7.5285","7.5285","5.0190","20.3496","74.7848"
"30.3200","7.5490","7.5490","5.0327","20.4138","75.0208"
"30.4000","7.5692","7.5692","5.0461","20.4783","75.2577"
"30.4800","7.5893","7.5893","5.0595","20.5409","75.4877"
"30.5600","7.6087","7.6087","5.0725","20.6007","75.7076"
"30.6400","7.6279","7.6279","5.0853","20.6594","75.9231"
"30.7200","7.6485","7.6485","5.0990","20.7253","76.1656"
"30.8000","7.6679","7.6679","5.1119","20.7842","76.3818"
"30.8800","7.6898","7.6898","5.1266","20.8556","76.6442"
"30.9600","7.7099","7.7099","5.1399","20.9169","76.8696"
"31.0400","7.7290","7.7290","5.1526","20.9784","77.0955"
"31.1200","7.7485","7.7485","5.1656","21.0392","77.3191"
"31.2000","7.7684","7.7684","5.1789","21.0998","77.5419"
"31.2800","7.7886","7.7886","5.1924","21.1621","77.7707"
"31.3600","7.8087","7.8087","5.2058","21.2244","77.9995"
"31.4400","7.8273","7.8273","5.2182","21.2816","78.2099"
"31.5200","7.8484","7.8484","5.2323","21.3507","78.4639"
"31.6000","7.8693","7.8693","5.2462","21.4165","78.7056"
"31.6800","7.8892","7.8892","5.2594","21.4809","78.9423"
"31.7600","7.9088","7.9088","5.2726","21.5432","79.1714"
"31.8400","7.9277","7.9277","5.2852","21.5995","79.3781"
"31.9200","7.9484","7.9484","5.2990","21.6653","79.6198"
"32.0000","7.9687","7.9687","5.3125","21.7298","79.8570"
"32.0800","7.9883","7.9883","5.3255","21.7916","80.0843"
"32.1600","8.0095","8.0095","5.3397","21.8590","80.3320"
"32.2400","8.0292","8.0292","5.3528","21.9220","80.5635"
"32.3200","8.0491","8.0491","5.3661","21.9843","80.7923"
"32.4000","8.0694","8.0694","5.3796","22.0485","81.0284"
"32.4800","8.0880","8.0880","5.3920","22.1071","81.2435"
"32.5600","8.1086","8.1086","5.4057","22.1702","81.4756"
"32.6400","8.1279","8.1279","5.4186","22.2317","81.7014"
"32.7200","8.1479","8.1479","5.4319","22.2978","81.9444"
"32.8000","8.1691","8.1691","5.4461","22.3676","82.2010"
"32.8800","8.1892","8.1892","5.4594","22.4305","82.4322"
"32.9600","8.2090","8.2090","5.4727","22.4928","82.6610"
"33.0400","8.2291","8.2291","5.4861","22.5571","82.8975"
"33.1200","8.2475","8.2475","5.4983","22.6165","83.1157"
"33.2000","8.2686","8.2686","5.5124","22.6879","83.3781"
"33.2800","8.2883","8.2883","5.5255","22.7492","83.6034"
"33.3600","8.3092","8.3092","5.5395","22.8178","83.8553"
"33.4400","8.3296","8.3296","5.5531","22.8819","84.0909"
"33.5200","8.3488","8.3488","5.5659","22.9429","84.3153"
"33.6000","8.3689","8.3689","5.5793","23.0072","84.5514"
"33.6800","8.3887","8.3887","5.5924","23.0686","84.7772"
"33.7600","8.4082","8.4082","5.6055","23.1308","85.0057"
"33.8400","8.4281","8.4281","5.6187","23.1957","85.2443"
"33.9200","8.4475","8.4475","5.6317","23.2577","85.4722"
"34.0000","8.4684","8.4684","5.6456","23.3241","85.7161"
"34.0800","8.4896","8.4896","5.6597","23.3936","85.9715"
"34.1600","8.5087","8.5087","5.6725","23.4541","86.1937"
"34.2400","8.5290","8.5290","5.6860","23.5200","86.4361"
"34.3200","8.5477","8.5477","5.6984","23.5782","86.6497"
"34.4000","8.5685","8.5685","5.7123","23.6471","86.9032"
"34.4800","8.5887","8.5887","5.7258","23.7144","87.1504"
"34.5600","8.6081","8.6081","5.7387","23.7748","87.3725"
"34.6400","8.6291","8.6291","5.7527","23.8446","87.6288"
"34.7200","8.6502","8.6502","5.7668","23.9153","87.8887"
"34.8000","8.6692","8.6692","5.7795","23.9769","88.1150"
"34.8800","8.6892","8.6892","5.7928","24.0420","88.3544"
"34.9600","8.7077","8.7077","5.8052","24.0982","88.5610"
"35.0400","8.7284","8.7284","5.8189","24.1662","88.8109"
"35.1200","8.7484","8.7484","5.8322","24.2327","89.0552"
"35.2000","8.7677","8.7677","5.8451","24.2951","89.2847"
"35.2800","8.7891","8.7891","5.8594","24.3671","89.5493"
"35.3600","8.8095","8.8095","5.8730","24.4310","89.7840"
"35.4400","8.8290","8.8290","5.8860","24.4935","90.0136"
"35.5200","8.8485","8.8485","5.8990","24.5596","90.2567"
"35.6000","8.8676","8.8676","5.9117","24.6180","90.4711"
"35.6800","8.8891","8.8891","5.9260","24.6916","90.7417"
"35.7600","8.9092","8.9092","5.9395","24.7581","90.9862"
"35.8400","8.9283","8.9283","5.9522","24.8205","91.2152"
"35.9200","8.9491","8.9491","5.9660","24.8911","91.4747"
"36.0000","8.9691","8.9691","5.9794","24.9537","91.7048"
"36.0800","8.9895","8.9895","5.9930","25.0213","91.9531"
"36.1600","9.0091","9.0091","6.0061","25.0846","92.1858"
"36.2400","9.0281","9.0281","6.0187","25.1470","92.4151"
"36.3200","9.0478","9.0478","6.0318","25.2128","92.6570"
"36.4000","9.0677","9.0677","6.0451","25.2763","92.8905"
"36.4800","9.0883","9.0883","6.0589","25.3450","93.1428"
"36.5600","9.1096","9.1096","6.0731","25.4164","93.4053"
"36.6400","9.1285","9.1285","6.0857","25.4764","93.6258"
"36.7200","9.1491","9.1491","6.0994","25.5442","93.8750"
"36.8000","9.1683","9.1683","6.1122","25.6084","94.1107"
"36.8800","9.1881","9.1881","6.1254","25.6745","94.3536"
"36.9600","9.2081","9.2081","6.1387","25.7408","94.5974"
"37.0400","9.2282","9.2282","6.1522","25.8074","94.8421"
"37.1200","9.2489","9.2489","6.1659","25.8757","95.0934"
"37.2000","9.2703","9.2703","6.1802","25.9482","95.3596"
"37.2800","9.2891","9.2891","6.1927","26.0090","95.5832"
"37.3600","9.3091","9.3091","6.2061","26.0774","95.8346"
"37.4400","9.3283","9.3283","6.2188","26.1382","96.0580"
"37.5200","9.3481","9.3481","6.2321","26.2073","96.3118"
"37.6000","9.3688","9.3688","6.2458","26.2750","96.5606"
"37.6800","9.3878","9.3878","6.2585","26.3397","96.7984"
"37.7600","9.4087","9.4087","6.2725","26.4092","97.0536"
"37.8400","9.4291","9.4291","6.2860","26.4772","97.3036"
"37.9200","9.4487","9.4487","6.2991","26.5429","97.5452"
"38.0000","9.4691","9.4691","6.3128","26.6127","97.8015"
"38.0800","9.4886","9.4886","6.3258","26.6763","98.0354"
"38.1600","9.5089","9.5089","6.3392","26.7466","98.2936"
"38.2400","9.5290","9.5290","6.3527","26.8108","98.5298"
"38.3200","9.5472","9.5472","6.3648","26.8717","98.7533"
"38.4000","9.5693","9.5693","6.3795","26.9511","99.0455"
"38.4800","9.5895","9.5895","6.3930","27.0187","99.2937"
"38.5600","9.6097","9.6097","6.4065","27.0820","99.5263"
"38.6400","9.6285","9.6285","6.4190","27.1452","99.7587"
"38.7200","9.6480","9.6480","6.4320","27.2089","99.9929"
"38.8000","9.6684","9.6684","6.4456","27.2784","100.2481"
"38.8800","9.6886","9.6886","6.4591","27.3455","100.4948"
"38.9600","9.7074","9.7074","6.4716","27.4107","100.7345"
"39.0400","9.7287","9.7287","6.4858","27.4846","101.0060"
"39.1200","9.7485","9.7485","6.4990","27.5528","101.2566"
"39.2000","9.7690","9.7690","6.5127","27.6183","101.4973"
"39.2800","9.7893","9.7893","6.5262","27.6868","101.7491"
"39.3600","9.8083","9.8083","6.5389","27.7488","101.9767"
"39.4400","9.8284","9.8284","6.5523","27.8176","102.2296"
"39.5200","9.8484","9.8484","6.5656","27.8856","102.4795"
"39.6000","9.8687","9.8687","6.5791","27.9550","102.7346"
"39.6800","9.8900","9.8900","6.5933","28.0304","103.0117"
"39.7600","9.9092","9.9092","6.6061","28.0908","103.2338"
"39.8400","9.9289","9.9289","6.6193","28.1587","103.4834"
"39.9200","9.9489","9.9489","6.6326","28.2235","103.7212"
"40.0000","9.9682","9.9682","6.6455","28.2921","103.9735"
"40.0800","9.9891","9.9891","6.6594","28.3647","104.2402"
"40.1600","10.0072","10.0072","6.6715","28.4218","104.4501"
"40.2400","10.0282","10.0282","6.6855","28.4954","104.7205"
"40.3200","10.0491","10.0491","6.6994","28.5678","104.9868"
"40.4000","10.0693","10.0693","6.7129","28.6411","105.2562"
"40.4800","10.0893","10.0893","6.7262","28.7105","105.5112"
"40.5600","10.1090","10.1090","6.7393","28.7746","105.7467"
"40.6400","10.1278","10.1278","6.7519","28.8374","105.9775"
"40.7200","10.1484","10.1484","6.7656","28.9102","106.2451"
"40.8000","10.1675","10.1675","6.7784","28.9736","106.4779"
"40.8800","10.1896","10.1896","6.7931","29.0491","106.7553"
"40.9600","10.2099","10.2099","6.8066","29.1204","107.0175"
"41.0400","10.2290","10.2290","6.8193","29.1840","107.2513"
"41.1200","10.2485","10.2485","6.8323","29.2524","107.5026"
"41.2000","10.2684","10.2684","6.8456","29.3170","107.7402"
"41.2800","10.2885","10.2885","6.8590","29.3871","107.9976"
"41.3600","10.3086","10.3086","6.8724","29.4565","108.2528"
"41.4400","10.3273","10.3273","6.8849","29.5205","108.4877"
"41.5200","10.3492","10.3492","6.8995","29.5967","108.7680"
"41.6000","10.3690","10.3690","6.9127","29.6659","109.0223"
"41.6800","10.3884","10.3884","6.9256","29.7315","109.2634"
"41.7600","10.4091","10.4091","6.9394","29.8018","109.5215"
"41.8400","10.4279","10.4279","6.9519","29.8658","109.7568"
"41.9200","10.4485","10.4485","6.9657","29.9378","110.0215"
"42.0000","10.4689","10.4689","6.9793","30.0100","110.2866"
"42.0800","10.4886","10.4886","6.9924","30.0798","110.5433"
"42.1600","10.5088","10.5088","7.0059","30.1523","110.8097"
"42.2400","10.5290","10.5290","7.0193","30.2201","111.0589"
"42.3200","10.5491","10.5491","7.0327","30.2898","111.3151"
"42.4000","10.5696","10.5696","7.0464","30.3603","111.5742"
"42.4800","10.5882","10.5882","7.0588","30.4256","111.8142"
"42.5600","10.6086","10.6086","7.0724","30.4949","112.0688"
"42.6400","10.6280","10.6280","7.0853","30.5616","112.3139"
"42.7200","10.6476","10.6476","7.0984","30.6317","112.5717"
"42.8000","10.6691","10.6691","7.1127","30.7097","112.8580"
"42.8800","10.6897","10.6897","7.1264","30.7811","113.1204"
"42.9600","10.7088","10.7088","7.1392","30.8448","113.3546"
"43.0400","10.7287","10.7287","7.1525","30.9133","113.6064"
"43.1200","10.7476","10.7476","7.1650","30.9782","113.8447"
"43.2000","10.7687","10.7687","7.1791","31.0560","114.1309"
"43.2800","10.7882","10.7882","7.1921","31.1203","114.3669"
"43.3600","10.8093","10.8093","7.2062","31.1941","114.6382"
"43.4400","10.8297","10.8297","7.2198","31.2655","114.9006"
"43.5200","10.8486","10.8486","7.2324","31.3337","115.1513"
"43.6000","10.8690","10.8690","7.2460","31.4042","115.4105"
"43.6800","10.8890","10.8890","7.2593","31.4731","115.6635"
"43.7600","10.9085","10.9085","7.2723","31.5451","115.9284"
"43.8400","10.9283","10.9283","7.2855","31.6131","116.1781"
"43.9200","10.9476","10.9476","7.2984","31.6792","116.4212"
"44.0000","10.9681","10.9681","7.3121","31.7511","116.6852"
"44.0800","10.9893","10.9893","7.3262","31.8271","116.9647"
"44.1600","11.0090","11.0090","7.3393","31.8982","117.2259"
"44.2400","11.0290","11.0290","7.3527","31.9654","117.4729"
"44.3200","11.0482","11.0482","7.3655","32.0343","117.7259"
"44.4000","11.0688","11.0688","7.3792","32.1088","117.9998"
"44.4800","11.0889","11.0889","7.3926","32.1785","118.2559"
"44.5600","11.1085","11.1085","7.4057","32.2475","118.5097"
"44.6400","11.1288","11.1288","7.4192","32.3181","118.7692"
"44.7200","11.1495","11.1495","7.4330","32.3923","119.0416"
"44.8000","11.1690","11.1690","7.4460","32.4626","119.2999"
"44.8800","11.1895","11.1895","7.4597","32.5373","119.5746"
"44.9600","11.2079","11.2079","7.4720","32.5993","119.8025"
"45.0400","11.2283","11.2283","7.4855","32.6696","120.0608"
"45.1200","11.2480","11.2480","7.4986","32.7386","120.3145"
"45.2000","11.2676","11.2676","7.5117","32.8081","120.5698"
"45.2800","11.2890","11.2890","7.5260","32.8898","120.8700"
"45.3600","11.3095","11.3095","7.5396","32.9608","121.1309"
"45.4400","11.3289","11.3289","7.5526","33.0281","121.3784"
"45.5200","11.3487","11.3487","7.5658","33.0975","121.6332"
"45.6000","11.3676","11.3676","7.5784","33.1645","121.8796"
"45.6800","11.3890","11.3890","7.5927","33.2439","122.1715"
"45.7600","11.4089","11.4089","7.6060","33.3166","122.4386"
"45.8400","11.4281","11.4281","7.6187","33.3836","122.6847"
"45.9200","11.4494","11.4494","7.6329","33.4642","122.9810"
"46.0000","11.4691","11.4691","7.6461","33.5305","123.2246"
"46.0800","11.4895","11.4895","7.6597","33.6043","123.4957"
"46.1600","11.5091","11.5091","7.6727","33.6733","123.7494"
"46.2400","11.5280","11.5280","7.6853","33.7401","123.9950"
"46.3200","11.5480","11.5480","7.6987","33.8151","124.2707"
"46.4000","11.5682","11.5682","7.7121","33.8895","124.5439"
"46.4800","11.5882","11.5882","7.7255","33.9606","124.8050"
"46.5600","11.6091","11.6091","7.7394","34.0370","125.0860"
"46.6400","11.6285","11.6285","7.7523","34.1056","125.3382"
"46.7200","11.6494","11.6494","7.7663","34.1798","125.6109"
"46.8000","11.6686","11.6686","7.7791","34.2485","125.8634"
"46.8800","11.6884","11.6884","7.7923","34.3204","126.1273"
"46.9600","11.7082","11.7082","7.8055","34.3923","126.3915"
"47.0400","11.7281","11.7281","7.8188","34.4643","126.6564"
"47.1200","11.7486","11.7486","7.8324","34.5391","126.9310"
"47.2000","11.7703","11.7703","7.8468","34.6212","127.2329"
"47.2800","11.7893","11.7893","7.8595","34.6915","127.4912"
"47.3600","11.8094","11.8094","7.8729","34.7615","127.7486"
"47.4400","11.8281","11.8281","7.8854","34.8289","127.9961"
"47.5200","11.8480","11.8480","7.8987","34.9016","128.2632"
"47.6000","11.8688","11.8688","7.9125","34.9779","128.5436"
"47.6800","11.8877","11.8877","7.9251","35.0456","128.7926"
"47.7600","11.9089","11.9089","7.9393","35.1250","129.0844"
"47.8400","11.9294","11.9294","7.9530","35.1997","129.3589"
"47.9200","11.9484","11.9484","7.9656","35.2695","129.6155"
"48.0000","11.9688","11.9688","7.9792","35.3449","129.8926"
"48.0800","11.9885","11.9885","7.9923","35.4133","130.1438"
"48.1600","12.0086","12.0086","8.0057","35.4875","130.4164"
"48.2400","12.0292","12.0292","8.0195","35.5634","130.6956"
"48.3200","12.0476","12.0476","8.0318","35.6303","130.9413"
"48.4000","12.0691","12.0691","8.0460","35.7115","131.2398"
"48.4800","12.0895","12.0895","8.0597","35.7892","131.5253"
"48.5600","12.1099","12.1099","8.0733","35.8636","131.7988"
"48.6400","12.1291","12.1291","8.0860","35.9334","132.0554"
"48.7200","12.1481","12.1481","8.0988","35.9988","132.2954"
"48.8000","12.1680","12.1680","8.1120","36.0736","132.5704"
"48.8800","12.1886","12.1886","8.1257","36.1486","132.8462"
"48.9600","12.2076","12.2076","8.1384","36.2200","133.1084"
"49.0400","12.2287","12.2287","8.1524","36.3018","133.4090"
"49.1200","12.2484","12.2484","8.1656","36.3707","133.6625"
"49.2000","12.2695","12.2695","8.1797","36.4488","133.9494"
"49.2800","12.2892","12.2892","8.1928","36.5208","134.2140"
"49.3600","12.3077","12.3077","8.2052","36.5879","134.4606"
"49.4400","12.3283","12.3283","8.2189","36.6680","134.7548"
"49.5200","12.3488","12.3488","8.2325","36.7447","135.0369"
"49.6000","12.3690","12.3690","8.2460","36.8224","135.3224"
"49.6800","12.3898","12.3898","8.2599","36.8984","135.6015"
"49.7600","12.4088","12.4088","8.2726","36.9657","135.8489"
"49.8400","12.4290","12.4290","8.2860","37.0412","136.1265"
"49.9200","12.4488","12.4488","8.2992","37.1139","136.3936"
"50.0000","12.4681","12.4681","8.3120","37.1880","136.6659"
"50.0800","12.4887","12.4887","8.3258","37.2663","136.9536"
"50.1600","12.5075","12.5075","8.3383","37.3323","137.1961"
"50.2400","12.5282","12.5282","8.3522","37.4120","137.4890"
"50.3200","12.5493","12.5493","8.3662","37.4942","137.7912"
"50.4000","12.5692","12.5692","8.3795","37.5664","138.0566"
"50.4800","12.5889","12.5889","8.3926","37.6420","138.3344"
"50.5600","12.6088","12.6088","8.4059","37.7145","138.6007"
"50.6400","12.6277","12.6277","8.4185","37.7832","138.8532"
"50.7200","12.6487","12.6487","8.4325","37.8633","139.1476"
"50.8000","12.6681","12.6681","8.4454","37.9393","139.4268"
"50.8800","12.6899","12.6899","8.4600","38.0263","139.7468"
"50.9600","12.7097","12.7097","8.4731","38.0970","140.0066"
"51.0400","12.7291","12.7291","8.4861","38.1714","140.2799"
"51.1200","12.7486","12.7486","8.4990","38.2444","140.5481"
"51.2000","12.7683","12.7683","8.5122","38.3173","140.8162"
"51.2800","12.7888","12.7888","8.5259","38.3960","141.1053"
"51.3600","12.8089","12.8089","8.5393","38.4671","141.3667"
"51.4400","12.8273","12.8273","8.5515","38.5385","141.6288"
"51.5200","12.8487","12.8487","8.5658","38.6230","141.9393"
"51.6000","12.8691","12.8691","8.5794","38.6999","142.2221"
"51.6800","12.8892","12.8892","8.5928","38.7759","142.5016"
"51.7600","12.9091","12.9091","8.6061","38.8515","142.7794"
"51.8400","12.9275","12.9275","8.6184","38.9194","143.0287"
"51.9200","12.9486","12.9486","8.6324","38.9987","143.3203"
"52.0000","12.9691","12.9691","8.6460","39.0757","143.6033"
"52.0800","12.9884","12.9884","8.6590","39.1516","143.8820"
"52.1600","13.0094","13.0094","8.6729","39.2363","144.1935"
"52.2400","13.0291","13.0291","8.6861","39.3088","144.4597"
"52.3200","13.0489","13.0489","8.6993","39.3833","144.7335"
"52.4000","13.0690","13.0690","8.7127","39.4620","145.0227"
"52.4800","13.0881","13.0881","8.7254","39.5339","145.2871"
"52.5600","13.1085","13.1085","8.7390","39.6133","145.5790"
"52.6400","13.1280","13.1280","8.7520","39.6872","145.8503"
"52.7200","13.1478","13.1478","8.7652","39.7621","146.1259"
"52.8000","13.1688","13.1688","8.7792","39.8459","146.4337"
"52.8800","13.1892","13.1892","8.7928","39.9223","146.7145"
"52.9600","13.2092","13.2092","8.8061","39.9988","146.9956"
"53.0400","13.2292","13.2292","8.8195","40.0753","147.2767"
"53.1200","13.2478","13.2478","8.8318","40.1477","147.5428"
"53.2000","13.2686","13.2686","8.8458","40.2305","147.8471"
"53.2800","13.2882","13.2882","8.8588","40.3033","148.1145"
"53.3600","13.3093","13.3093","8.8729","40.3878","148.4252"
"53.4400","13.3296","13.3296","8.8864","40.4643","148.7062"
"53.5200","13.3486","13.3486","8.8991","40.5347","148.9650"
"53.6000","13.3690","13.3690","8.9127","40.6174","149.2689"
"53.6800","13.3892","13.3892","8.9261","40.6954","149.5556"
"53.7600","13.4082","13.4082","8.9388","40.7686","149.8246"
"53.8400","13.4283","13.4283","8.9522","40.8489","150.1195"
"53.9200","13.4474","13.4474","8.9650","40.9207","150.3834"
"54.0000","13.4686","13.4686","8.9791","41.0045","150.6916"
"54.0800","13.4895","13.4895","8.9930","41.0841","150.9842"
"54.1600","13.5084","13.5084","9.0056","41.1555","151.2465"
"54.2400","13.5288","13.5288","9.0192","41.2371","151.5463"
"54.3200","13.5482","13.5482","9.0321","41.3116","151.8201"
"54.4000","13.5691","13.5691","9.0461","41.3944","152.1245"
"54.4800","13.5892","13.5892","9.0594","41.4722","152.4103"
"54.5600","13.6079","13.6079","9.0720","41.5430","152.6706"
"54.6400","13.6287","13.6287","9.0858","41.6275","152.9812"
"54.7200","13.6496","13.6496","9.0998","41.7126","153.2937"
"54.8000","13.6691","13.6691","9.1127","41.7870","153.5673"
"54.8800","13.6891","13.6891","9.1261","41.8648","153.8530"
"54.9600","13.7078","13.7078","9.1385","41.9339","154.1070"
"55.0400","13.7284","13.7284","9.1523","42.0123","154.3950"
"55.1200","13.7483","13.7483","9.1655","42.0939","154.6950"
"55.2000","13.7672","13.7672","9.1782","42.1655","154.9583"
"55.2800","13.7889","13.7889","9.1926","42.2570","155.2945"
"55.3600","13.8095","13.8095","9.2063","42.3398","155.5986"
"55.4400","13.8288","13.8288","9.2192","42.4133","155.8690"
"55.5200","13.8486","13.8486","9.2324","42.4922","156.1588"
"55.6000","13.8676","13.8676","9.2451","42.5671","156.4343"
"55.6800","13.8886","13.8886","9.2591","42.6498","156.7380"
"55.7600","13.9089","13.9089","9.2726","42.7272","157.0223"
"55.8400","13.9281","13.9281","9.2854","42.8056","157.3104"
"55.9200","13.9492","13.9492","9.2995","42.8924","157.6297"
"56.0000","13.9692","13.9692","9.3128","42.9702","157.9156"
"56.0800","13.9895","13.9895","9.3264","43.0500","158.2088"
"56.1600","14.0092","14.0092","9.3395","43.1308","158.5058"
"56.2400","14.0280","14.0280","9.3520","43.2026","158.7696"
"56.3200","14.0479","14.0479","9.3652","43.2831","159.0655"
"56.4000","14.0675","14.0675","9.3783","43.3588","159.3436"
"56.4800","14.0880","14.0880","9.3920","43.4404","159.6434"
"56.5600","14.1098","14.1098","9.4065","43.5297","159.9716"
"56.6400","14.1289","14.1289","9.4193","43.6067","160.2547"
"56.7200","14.1493","14.1493","9.4328","43.6889","160.5568"
"56.8000","14.1686","14.1686","9.4457","43.7614","160.8231"
"56.8800","14.1881","14.1881","9.4588","43.8422","161.1200"
"56.9600","14.2084","14.2084","9.4723","43.9286","161.4377"
"57.0400","14.2279","14.2279","9.4853","44.0037","161.7135"
"57.1200","14.2488","14.2488","9.4992","44.0867","162.0186"
"57.2000","14.2699","14.2699","9.5133","44.1759","162.3466"
"57.2800","14.2892","14.2892","9.5261","44.2507","162.6215"
"57.3600","14.3089","14.3089","9.5392","44.3294","162.9106"
"57.4400","14.3280","14.3280","9.5520","44.4040","163.1847"
"57.5200","14.3482","14.3482","9.5655","44.4863","163.4873"
"57.6000","14.3687","14.3687","9.5791","44.5721","163.8026"
"57.6800","14.3875","14.3875","9.5917","44.6470","164.0776"
"57.7600","14.4086","14.4086","9.6057","44.7354","164.4026"
"57.8400","14.4292","14.4292","9.6194","44.8202","164.7144"
"57.9200","14.4488","14.4488","9.6325","44.8979","164.9997"
"58.0000","14.4690","14.4690","9.6460","44.9819","165.3083"
"58.0800","14.4886","14.4886","9.6591","45.0592","165.5927"
"58.1600","14.5085","14.5085","9.6723","45.1387","165.8849"
"58.2400","14.5285","14.5285","9.6856","45.2205","166.1853"
"58.3200","14.5476","14.5476","9.6984","45.3023","166.4858"
"58.4000","14.5697","14.5697","9.7131","45.3975","166.8359"
"58.4800","14.5897","14.5897","9.7265","45.4754","167.1219"
"58.5600","14.6097","14.6097","9.7398","45.5574","167.4236"
"58.6400","14.6286","14.6286","9.7524","45.6317","167.6964"
"58.7200","14.6480","14.6480","9.7653","45.7083","167.9782"
"58.8000","14.6684","14.6684","9.7790","45.7922","168.2863"
"58.8800","14.6885","14.6885","9.7923","45.8722","168.5802"
"58.9600","14.7074","14.7074","9.8049","45.9511","168.8703"
"59.0400","14.7290","14.7290","9.8193","46.0426","169.2065"
"59.1200","14.7486","14.7486","9.8324","46.1234","169.5035"
"59.2000","14.7693","14.7693","9.8462","46.2094","169.8197"
"59.2800","14.7891","14.7891","9.8594","46.2889","170.1118"
"59.3600","14.8079","14.8079","9.8719","46.3643","170.3889"
"59.4400","14.8284","14.8284","9.8856","46.4493","170.7011"
"59.5200","14.8482","14.8482","9.8988","46.5291","170.9945"
"59.6000","14.8686","14.8686","9.9124","46.6154","171.3116"
"59.6800","14.8898","14.8898","9.9265","46.7050","171.6409"
"59.7600","14.9091","14.9091","9.9394","46.7814","171.9218"
"59.8400","14.9290","14.9290","9.9527","46.8644","172.2268"
"59.9200","14.9489","14.9489","9.9659","46.9457","172.5255"
"60.0000","14.9678","14.9678","9.9785","47.0232","172.8102"
"60.0800","14.9885","14.9885","9.9923","47.1139","173.1436"
"60.1250","15.0000","15.0000","10.0000","47.1564","173.2996"