File: data/instron_tests/metamaterial_samples/510_BULK_m1.is_comp_Exports/510_BULK_m1_5_1.csv
Sample text inputs : Sample No.,Sample choice input : Leading Direction,Sample choice input : Mode,Specimen choice input : Direction,Specimen properties : Height,Specimen properties : Thickness,Specimen properties : Width,Test : Rate 1
,,,,(mm),(mm),(mm),(mm/min)
"510","Bulk","Unimode","1","150.00","25.00","150.00","15.00"

Time,Displacement,Compressive displacement,Compressive strain (Displacement),Compressive stress,Force
(s),(mm),(mm),(%),(kPa),(N)
"0.0000","-0.0002","-0.0002","-0.0001","-0.7735","-2.8425"
"0.0800","0.0011","0.0011","0.0007","-0.7692","-2.8269"
"0.1600","0.0091","0.0091","0.0060","-0.7492","-2.7533"
"0.2400","0.0298","0.0298","0.0199","-0.7031","-2.5838"
"0.3200","0.0502","0.0502","0.0334","-0.6552","-2.4080"
"0.4000","0.0683","0.0683","0.0455","-0.6147","-2.2589"
"0.4800","0.0879","0.0879","0.0586","-0.5746","-2.1115"
"0.5600","0.1081","0.1081","0.0721","-0.5333","-1.9600"
"0.6400","0.1273","0.1273","0.0848","-0.4940","-1.8155"
"0.7200","0.1485","0.1485","0.0990","-0.4518","-1.6602"
"0.8000","0.1681","0.1681","0.1121","-0.4160","-1.5286"
"0.8800","0.1897","0.1897","0.1265","-0.3752","-1.3787"
"0.9600","0.2100","0.2100","0.1400","-0.3395","-1.2478"
"1.0400","0.2291","0.2291","0.1527","-0.2970","-1.0915"
"1.1200","0.2488","0.2488","0.1659","-0.2579","-0.9477"
"1.2000","0.2685","0.2685","0.1790","-0.2219","-0.8156"
"1.2800","0.2886","0.2886","0.1924","-0.1797","-0.6603"
"1.3600","0.3090","0.3090","0.2060","-0.1419","-0.5214"
"1.4400","0.3275","0.3275","0.2183","-0.1042","-0.3828"
"1.5200","0.3493","0.3493","0.2329","-0.0585","-0.2149"
"1.6000","0.3693","0.3693","0.2462","-0.0199","-0.0733"
"1.6800","0.3891","0.3891","0.2594","0.0195","0.0717"
"1.7600","0.4089","0.4089","0.2726","0.0599","0.2203"
"1.8400","0.4278","0.4278","0.2852","0.0988","0.3631"
"1.9200","0.4488","0.4488","0.2992","0.1399","0.5141"
"2.0000","0.4693","0.4693","0.3129","0.1797","0.6605"
"2.0800","0.4886","0.4886","0.3258","0.2196","0.8071"
"2.1600","0.5091","0.5091","0.3394","0.2623","0.9638"
"2.2400","0.5293","0.5293","0.3529","0.3035","1.1153"
"2.3200","0.5494","0.5494","0.3663","0.3467","1.2740"
"2.4000","0.5699","0.5699","0.3799","0.3877","1.4247"
"2.4800","0.5880","0.5880","0.3920","0.4288","1.5759"
"2.5600","0.6087","0.6087","0.4058","0.4723","1.7358"
"2.6400","0.6280","0.6280","0.4187","0.5115","1.8799"
"2.7200","0.6481","0.6481","0.4321","0.5574","2.0486"
"2.8000","0.6689","0.6689","0.4459","0.6014","2.2101"
"2.8800","0.6893","0.6893","0.4595","0.6456","2.3727"
"2.9600","0.7092","0.7092","0.4728","0.6857","2.5200"
"3.0400","0.7290","0.7290","0.4860","0.7281","2.6756"
"3.1200","0.7476","0.7476","0.4984","0.7730","2.8406"
"3.2000","0.7686","0.7686","0.5124","0.8183","3.0074"
"3.2800","0.7887","0.7887","0.5258","0.8614","3.1655"
"3.3600","0.8094","0.8094","0.5396","0.9049","3.3256"
"3.4400","0.8296","0.8296","0.5530","0.9513","3.4962"
"3.5200","0.8490","0.8490","0.5660","0.9928","3.6487"
"3.6000","0.8696","0.8696","0.5797","1.0371","3.8113"
"3.6800","0.8893","0.8893","0.5929","1.0812","3.9735"
"3.7600","0.9081","0.9081","0.6054","1.1220","4.1233"
"3.8400","0.9285","0.9285","0.6190","1.1693","4.2972"
"3.9200","0.9479","0.9479","0.6319","1.2094","4.4446"
"4.0000","0.9686","0.9686","0.6457","1.2541","4.6088"
"4.0800","0.9901","0.9901","0.6600","1.3025","4.7867"
"4.1600","1.0088","1.0088","0.6726","1.3487","4.9566"
"4.2400","1.0290","1.0290","0.6860","1.3927","5.1183"
"4.3200","1.0480","1.0480","0.6987","1.4331","5.2668"
"4.4000","1.0689","1.0689","0.7126","1.4794","5.4369"
"4.4800","1.0892","1.0892","0.7261","1.5252","5.6051"
"4.5600","1.1085","1.1085","0.7390","1.5681","5.7628"
"4.6400","1.1291","1.1291","0.7528","1.6183","5.9474"
"4.7200","1.1498","1.1498","0.7666","1.6643","6.1163"
"4.8000","1.1692","1.1692","0.7795","1.7076","6.2753"
"4.8800","1.1899","1.1899","0.7933","1.7542","6.4466"
"4.9600","1.2084","1.2084","0.8056","1.7974","6.6055"
"5.0400","1.2284","1.2284","0.8189","1.8409","6.7652"
"5.1200","1.2484","1.2484","0.8322","1.8880","6.9384"
"5.2000","1.2678","1.2678","0.8452","1.9340","7.1076"
"5.2800","1.2891","1.2891","0.8594","1.9823","7.2849"
"5.3600","1.3096","1.3096","0.8731","2.0282","7.4535"
"5.4400","1.3292","1.3292","0.8861","2.0741","7.6222"
"5.5200","1.3489","1.3489","0.8993","2.1205","7.7930"
"5.6000","1.3677","1.3677","0.9118","2.1673","7.9647"
"5.6800","1.3889","1.3889","0.9259","2.2127","8.1316"
"5.7600","1.4092","1.4092","0.9394","2.2625","8.3145"
"5.8400","1.4283","1.4283","0.9522","2.3094","8.4869"
"5.9200","1.4489","1.4489","0.9659","2.3587","8.6684"
"6.0000","1.4693","1.4693","0.9796","2.4088","8.8524"
"6.0800","1.4898","1.4898","0.9932","2.4564","9.0272"
"6.1600","1.5091","1.5091","1.0061","2.5006","9.1897"
"6.2400","1.5281","1.5281","1.0187","2.5432","9.3463"
"6.3200","1.5482","1.5482","1.0321","2.5949","9.5362"
"6.4000","1.5685","1.5685","1.0456","2.6441","9.7170"
"6.4800","1.5884","1.5884","1.0589","2.6972","9.9121"
"6.5600","1.6099","1.6099","1.0733","2.7490","10.1025"
"6.6400","1.6286","1.6286","1.0857","2.7943","10.2690"
"6.7200","1.6496","1.6496","1.0997","2.8405","10.4389"
"6.8000","1.6685","1.6685","1.1123","2.8878","10.6127"
"6.8800","1.6886","1.6886","1.1257","2.9372","10.7942"
"6.9600","1.7086","1.7086","1.1391","2.9905","10.9902"
"7.0400","1.7285","1.7285","1.1523","3.0374","11.1624"
"7.1200","1.7492","1.7492","1.1661","3.0896","11.3542"
"7.2000","1.7703","1.7703","1.1802","3.1416","11.5455"
"7.2800","1.7893","1.7893","1.1929","3.1873","11.7132"
"7.3600","1.8094","1.8094","1.2063","3.2378","11.8991"
"7.4400","1.8284","1.8284","1.2190","3.2851","12.0728"
"7.5200","1.8483","1.8483","1.2322","3.3324","12.2466"
"7.6000","1.8689","1.8689","1.2460","3.3835","12.4342"
"7.6800","1.8881","1.8881","1.2587","3.4317","12.6115"
"7.7600","1.9089","1.9089","1.2726","3.4812","12.7936"
"7.8400","1.9294","1.9294","1.2863","3.5326","12.9822"
"7.9200","1.9486","1.9486","1.2991","3.5830","13.1674"
"8.0000","1.9693","1.9693","1.3128","3.6349","13.3581"
"8.0800","1.9891","1.9891","1.3261","3.6841","13.5389"
"8.1600","2.0089","2.0089","1.3392","3.7319","13.7147"
"8.2400","2.0291","2.0291","1.3528","3.7839","13.9059"
"8.3200","2.0478","2.0478","1.3652","3.8253","14.0578"
"8.4000","2.0686","2.0686","1.3791","3.8812","14.2635"
"8.4800","2.0899","2.0899","1.3933","3.9351","14.4615"
"8.5600","2.1098","2.1098","1.4065","3.9846","14.6432"
"8.6400","2.1289","2.1289","1.4193","4.0373","14.8372"
"8.7200","2.1486","2.1486","1.4324","4.0836","15.0074"
"8.8000","2.1686","2.1686","1.4457","4.1359","15.1994"
"8.8800","2.1886","2.1886","1.4591","4.1828","15.3719"
"8.9600","2.2077","2.2077","1.4718","4.2320","15.5528"
"9.0400","2.2289","2.2289","1.4859","4.2879","15.7581"
"9.1200","2.2492","2.2492","1.4994","4.3381","15.9425"
"9.2000","2.2695","2.2695","1.5130","4.3891","16.1300"
"9.2800","2.2894","2.2894","1.5263","4.4418","16.3236"
"9.3600","2.3081","2.3081","1.5387","4.4919","16.5077"
"9.4400","2.3284","2.3284","1.5522","4.5395","16.6825"
"9.5200","2.3485","2.3485","1.5657","4.5950","16.8867"
"9.6000","2.3687","2.3687","1.5792","4.6485","17.0833"
"9.6800","2.3899","2.3899","1.5933","4.7036","17.2857"
"9.7600","2.4090","2.4090","1.6060","4.7504","17.4578"
"9.8400","2.4294","2.4294","1.6196","4.8066","17.6644"
"9.9200","2.4491","2.4491","1.6327","4.8567","17.8483"
"10.0000","2.4683","2.4683","1.6455","4.9085","18.0389"
"10.0800","2.4888","2.4888","1.6592","4.9628","18.2382"
"10.1600","2.5077","2.5077","1.6718","5.0125","18.4210"
"10.2400","2.5285","2.5285","1.6857","5.0637","18.6090"
"10.3200","2.5494","2.5494","1.6996","5.1212","18.8203"
"10.4000","2.5691","2.5691","1.7128","5.1722","19.0078"
"10.4800","2.5894","2.5894","1.7262","5.2265","19.2073"
"10.5600","2.6088","2.6088","1.7392","5.2765","19.3913"
"10.6400","2.6281","2.6281","1.7521","5.3240","19.5656"
"10.7200","2.6490","2.6490","1.7660","5.3816","19.7775"
"10.8000","2.6679","2.6679","1.7786","5.4340","19.9698"
"10.8800","2.6895","2.6895","1.7930","5.4920","20.1831"
"10.9600","2.7095","2.7095","1.8064","5.5431","20.3709"
"11.0400","2.7293","2.7293","1.8196","5.5974","20.5704"
"11.1200","2.7487","2.7487","1.8325","5.6488","20.7594"
"11.2000","2.7685","2.7685","1.8457","5.7050","20.9658"
"11.2800","2.7891","2.7891","1.8594","5.7563","21.1544"
"11.3600","2.8093","2.8093","1.8728","5.8107","21.3543"
"11.4400","2.8273","2.8273","1.8849","5.8606","21.5378"
"11.5200","2.8489","2.8489","1.8993","5.9203","21.7573"
"11.6000","2.8698","2.8698","1.9132","5.9801","21.9769"
"11.6800","2.8895","2.8895","1.9263","6.0311","22.1642"
"11.7600","2.9087","2.9087","1.9391","6.0820","22.3514"
"11.8400","2.9278","2.9278","1.9518","6.1342","22.5432"
"11.9200","2.9488","2.9488","1.9659","6.1904","22.7496"
"12.0000","2.9692","2.9692","1.9795","6.2474","22.9593"
"12.0800","2.9887","2.9887","1.9924","6.3011","23.1564"
"12.1600","3.0092","3.0092","2.0062","6.3576","23.3642"
"12.2400","3.0292","3.0292","2.0195","6.4100","23.5567"
"12.3200","3.0492","3.0492","2.0328","6.4659","23.7624"
"12.4000","3.0693","3.0693","2.0462","6.5199","23.9607"
"12.4800","3.0882","3.0882","2.0588","6.5725","24.1538"
"12.5600","3.1089","3.1089","2.0726","6.6293","24.3628"
"12.6400","3.1280","3.1280","2.0853","6.6819","24.5560"
"12.7200","3.1479","3.1479","2.0986","6.7354","24.7525"
"12.8000","3.1690","3.1690","2.1126","6.7956","24.9740"
"12.8800","3.1897","3.1897","2.1265","6.8523","25.1823"
"12.9600","3.2093","3.2093","2.1395","6.9032","25.3691"
"13.0400","3.2291","3.2291","2.1527","6.9599","25.5778"
"13.1200","3.2477","3.2477","2.1651","7.0115","25.7674"
"13.2000","3.2689","3.2689","2.1792","7.0714","25.9874"
"13.2800","3.2881","3.2881","2.1921","7.1242","26.1816"
"13.3600","3.3089","3.3089","2.2059","7.1779","26.3790"
"13.4400","3.3301","3.3301","2.2201","7.2337","26.5840"
"13.5200","3.3490","3.3490","2.2327","7.2887","26.7858"
"13.6000","3.3693","3.3693","2.2462","7.3439","26.9890"
"13.6800","3.3889","3.3889","2.2593","7.3981","27.1879"
"13.7600","3.4083","3.4083","2.2722","7.4540","27.3936"
"13.8400","3.4285","3.4285","2.2856","7.5099","27.5990"
"13.9200","3.4476","3.4476","2.2984","7.5625","27.7921"
"14.0000","3.4686","3.4686","2.3124","7.6214","28.0088"
"14.0800","3.4897","3.4897","2.3265","7.6798","28.2232"
"14.1600","3.5088","3.5088","2.3392","7.7339","28.4222"
"14.2400","3.5289","3.5289","2.3526","7.7886","28.6232"
"14.3200","3.5482","3.5482","2.3655","7.8403","28.8132"
"14.4000","3.5688","3.5688","2.3792","7.8986","29.0274"
"14.4800","3.5891","3.5891","2.3928","7.9578","29.2449"
"14.5600","3.6082","3.6082","2.4055","8.0094","29.4347"
"14.6400","3.6289","3.6289","2.4193","8.0675","29.6482"
"14.7200","3.6497","3.6497","2.4331","8.1248","29.8585"
"14.8000","3.6693","3.6693","2.4462","8.1784","30.0554"
"14.8800","3.6897","3.6897","2.4598","8.2331","30.2566"
"14.9600","3.7082","3.7082","2.4721","8.2835","30.4418"
"15.0400","3.7286","3.7286","2.4857","8.3405","30.6513"
"15.1200","3.7484","3.7484","2.4990","8.3965","30.8570"
"15.2000","3.7678","3.7678","2.5118","8.4512","31.0582"
"15.2800","3.7890","3.7890","2.5260","8.5140","31.2888"
"15.3600","3.8093","3.8093","2.5395","8.5715","31.5001"
"15.4400","3.8291","3.8291","2.5528","8.6265","31.7025"
"15.5200","3.8491","3.8491","2.5661","8.6801","31.8994"
"15.6000","3.8678","3.8678","2.5785","8.7317","32.0889"
"15.6800","3.8890","3.8890","2.5926","8.7910","32.3071"
"15.7600","3.9090","3.9090","2.6060","8.8489","32.5197"
"15.8400","3.9287","3.9287","2.6191","8.9058","32.7287"
"15.9200","3.9493","3.9493","2.6329","8.9641","32.9430"
"16.0000","3.9691","3.9691","2.6461","9.0208","33.1516"
"16.0800","3.9898","3.9898","2.6598","9.0788","33.3647"
"16.1600","4.0094","4.0094","2.6730","9.1319","33.5599"
"16.2400","4.0279","4.0279","2.6852","9.1871","33.7625"
"16.3200","4.0482","4.0482","2.6988","9.2441","33.9720"
"16.4000","4.0685","4.0685","2.7123","9.2993","34.1747"
"16.4800","4.0884","4.0884","2.7256","9.3555","34.3816"
"16.5600","4.1097","4.1097","2.7398","9.4202","34.6193"
"16.6400","4.1289","4.1289","2.7526","9.4708","34.8052"
"16.7200","4.1494","4.1494","2.7663","9.5274","35.0131"
"16.8000","4.1686","4.1686","2.7791","9.5842","35.2219"
"16.8800","4.1884","4.1884","2.7923","9.6427","35.4369"
"16.9600","4.2086","4.2086","2.8057","9.7016","35.6535"
"17.0400","4.2286","4.2286","2.8190","9.7546","35.8480"
"17.1200","4.2488","4.2488","2.8325","9.8124","36.0606"
"17.2000","4.2702","4.2702","2.8468","9.8724","36.2809"
"17.2800","4.2892","4.2892","2.8595","9.9287","36.4878"
"17.3600","4.3094","4.3094","2.8729","9.9889","36.7093"
"17.4400","4.3282","4.3282","2.8855","10.0401","36.8974"
"17.5200","4.3484","4.3484","2.8989","10.0994","37.1154"
"17.6000","4.3689","4.3689","2.9126","10.1583","37.3318"
"17.6800","4.3879","4.3879","2.9253","10.2134","37.5342"
"17.7600","4.4090","4.4090","2.9393","10.2718","37.7490"
"17.8400","4.4294","4.4294","2.9529","10.3288","37.9585"
"17.9200","4.4487","4.4487","2.9658","10.3852","38.1657"
"18.0000","4.4692","4.4692","2.9794","10.4469","38.3924"
"18.0800","4.4884","4.4884","2.9923","10.5001","38.5880"
"18.1600","4.5089","4.5089","3.0060","10.5606","38.8102"
"18.2400","4.5293","4.5293","3.0195","10.6183","39.0221"
"18.3200","4.5478","4.5478","3.0319","10.6724","39.2210"
"18.4000","4.5696","4.5696","3.0464","10.7356","39.4532"
"18.4800","4.5900","4.5900","3.0600","10.7937","39.6669"
"18.5600","4.6095","4.6095","3.0730","10.8507","39.8765"
"18.6400","4.6290","4.6290","3.0860","10.9021","40.0652"
"18.7200","4.6481","4.6481","3.0987","10.9564","40.2648"
"18.8000","4.6686","4.6686","3.1124","11.0167","40.4863"
"18.8800","4.6890","4.6890","3.1260","11.0779","40.7112"
"18.9600","4.7079","4.7079","3.1386","11.1326","40.9123"
"19.0400","4.7289","4.7289","3.1526","11.1950","41.1417"
"19.1200","4.7488","4.7488","3.1658","11.2507","41.3463"
"19.2000","4.7698","4.7698","3.1799","11.3110","41.5679"
"19.2800","4.7894","4.7894","3.1930","11.3667","41.7727"
"19.3600","4.8082","4.8082","3.2055","11.4202","41.9691"
"19.4400","4.8283","4.8283","3.2189","11.4793","42.1865"
"19.5200","4.8485","4.8485","3.2323","11.5368","42.3979"
"19.6000","4.8689","4.8689","3.2459","11.5978","42.6221"
"19.6800","4.8905","4.8905","3.2603","11.6635","42.8634"
"19.7600","4.9094","4.9094","3.2729","11.7184","43.0651"
"19.8400","4.9293","4.9293","3.2862","11.7763","43.2777"
"19.9200","4.9489","4.9489","3.2993","11.8300","43.4752"
"20.0000","4.9681","4.9681","3.3121","11.8889","43.6918"
"20.0800","4.9889","4.9889","3.3260","11.9488","43.9117"
"20.1600","5.0075","5.0075","3.3383","12.0021","44.1079"
"20.2400","5.0283","5.0283","3.3522","12.0613","44.3254"
"20.3200","5.0494","5.0494","3.3663","12.1246","44.5580"
"20.4000","5.0690","5.0690","3.3793","12.1825","44.7705"
"20.4800","5.0889","5.0889","3.3926","12.2422","44.9902"
"20.5600","5.1090","5.1090","3.4060","12.3009","45.2060"
"20.6400","5.1285","5.1285","3.4190","12.3586","45.4179"
"20.7200","5.1490","5.1490","3.4327","12.4165","45.6305"
"20.8000","5.1677","5.1677","3.4451","12.4710","45.8309"
"20.8800","5.1894","5.1894","3.4596","12.5340","46.0626"
"20.9600","5.2097","5.2097","3.4732","12.5923","46.2768"
"21.0400","5.2288","5.2288","3.4859","12.6497","46.4876"
"21.1200","5.2485","5.2485","3.4990","12.7073","46.6992"
"21.2000","5.2690","5.2690","3.5127","12.7689","46.9256"
"21.2800","5.2890","5.2890","3.5260","12.8260","47.1354"
"21.3600","5.3090","5.3090","3.5393","12.8838","47.3481"
"21.4400","5.3276","5.3276","3.5517","12.9396","47.5531"
"21.5200","5.3489","5.3489","3.5660","13.0042","47.7905"
"21.6000","5.3694","5.3694","3.5796","13.0651","48.0143"
"21.6800","5.3890","5.3890","3.5927","13.1205","48.2180"
"21.7600","5.4091","5.4091","3.6061","13.1812","48.4410"
"21.8400","5.4280","5.4280","3.6187","13.2371","48.6465"
"21.9200","5.4486","5.4486","3.6324","13.2973","48.8677"
"22.0000","5.4695","5.4695","3.6463","13.3596","49.0966"
"22.0800","5.4890","5.4890","3.6593","13.4194","49.3163"
"22.1600","5.5093","5.5093","3.6729","13.4813","49.5437"
"22.2400","5.5290","5.5290","3.6860","13.5373","49.7496"
"22.3200","5.5492","5.5492","3.6995","13.5981","49.9730"
"22.4000","5.5696","5.5696","3.7131","13.6556","50.1842"
"22.4800","5.5881","5.5881","3.7254","13.7093","50.3816"
"22.5600","5.6089","5.6089","3.7393","13.7712","50.6093"
"22.6400","5.6280","5.6280","3.7520","13.8300","50.8253"
"22.7200","5.6480","5.6480","3.7653","13.8891","51.0424"
"22.8000","5.6692","5.6692","3.7795","13.9554","51.2860"
"22.8800","5.6895","5.6895","3.7930","14.0135","51.4996"
"22.9600","5.7091","5.7091","3.8061","14.0712","51.7116"
"23.0400","5.7292","5.7292","3.8195","14.1292","51.9246"
"23.1200","5.7477","5.7477","3.8318","14.1854","52.1313"
"23.2000","5.7688","5.7688","3.8458","14.2479","52.3609"
"23.2800","5.7887","5.7887","3.8591","14.3080","52.5818"
"23.3600","5.8096","5.8096","3.8731","14.3688","52.8053"
"23.4400","5.8299","5.8299","3.8866","14.4304","53.0316"
"23.5200","5.8487","5.8487","3.8991","14.4870","53.2396"
"23.6000","5.8691","5.8691","3.9127","14.5471","53.4606"
"23.6800","5.8890","5.8890","3.9260","14.6067","53.6795"
"23.7600","5.9080","5.9080","3.9386","14.6614","53.8807"
"23.8400","5.9284","5.9284","3.9522","14.7234","54.1084"
"23.9200","5.9477","5.9477","3.9651","14.7809","54.3197"
"24.0000","5.9689","5.9689","3.9793","14.8452","54.5561"
"24.0800","5.9900","5.9900","3.9933","14.9086","54.7892"
"24.1600","6.0089","6.0089","4.0059","14.9687","55.0099"
"24.2400","6.0290","6.0290","4.0194","15.0260","55.2207"
"24.3200","6.0480","6.0480","4.0320","15.0836","55.4323"
"24.4000","6.0690","6.0690","4.0460","15.1454","55.6593"
"24.4800","6.0891","6.0891","4.0594","15.2054","55.8799"
"24.5600","6.1081","6.1081","4.0721","15.2620","56.0880"
"24.6400","6.1289","6.1289","4.0860","15.3266","56.3251"
"24.7200","6.1500","6.1500","4.1000","15.3913","56.5632"
"24.8000","6.1695","6.1695","4.1130","15.4503","56.7799"
"24.8800","6.1896","6.1896","4.1264","15.5150","57.0176"
"24.9600","6.2079","6.2079","4.1386","15.5658","57.2044"
"25.0400","6.2285","6.2285","4.1524","15.6265","57.4274"
"25.1200","6.2487","6.2487","4.1658","15.6863","57.6473"
"25.2000","6.2679","6.2679","4.1786","15.7491","57.8778"
"25.2800","6.2890","6.2890","4.1927","15.8120","58.1092"
"25.3600","6.3095","6.3095","4.2063","15.8736","58.3355"
"25.4400","6.3293","6.3293","4.2195","15.9326","58.5521"
"25.5200","6.3491","6.3491","4.2327","15.9898","58.7625"
"25.6000","6.3683","6.3683","4.2455","16.0504","58.9853"
"25.6800","6.3891","6.3891","4.2594","16.1140","59.2190"
"25.7600","6.4088","6.4088","4.2725","16.1722","59.4328"
"25.8400","6.4284","6.4284","4.2856","16.2331","59.6567"
"25.9200","6.4492","6.4492","4.2995","16.2992","59.8994"
"26.0000","6.4690","6.4690","4.3126","16.3558","60.1074"
"26.0800","6.4900","6.4900","4.3267","16.4199","60.3430"
"26.1600","6.5092","6.5092","4.3395","16.4749","60.5451"
"26.2400","6.5277","6.5277","4.3518","16.5310","60.7516"
"26.3200","6.5479","6.5479","4.3653","16.5952","60.9874"
"26.4000","6.5684","6.5684","4.3789","16.6596","61.2239"
"26.4800","6.5883","6.5883","4.3922","16.7198","61.4453"
"26.5600","6.6097","6.6097","4.4064","16.7852","61.6856"
"26.6400","6.6285","6.6285","4.4190","16.8417","61.8933"
"26.7200","6.6493","6.6493","4.4328","16.9059","62.1290"
"26.8000","6.6690","6.6690","4.4460","16.9634","62.3404"
"26.8800","6.6883","6.6883","4.4588","17.0246","62.5654"
"26.9600","6.7082","6.7082","4.4721","17.0878","62.7977"
"27.0400","6.7283","6.7283","4.4855","17.1480","63.0190"
"27.1200","6.7489","6.7489","4.4992","17.2125","63.2560"
"27.2000","6.7706","6.7706","4.5137","17.2790","63.5004"
"27.2800","6.7892","6.7892","4.5261","17.3377","63.7161"
"27.3600","6.8095","6.8095","4.5396","17.3999","63.9446"
"27.4400","6.8283","6.8283","4.5522","17.4557","64.1497"
"27.5200","6.8482","6.8482","4.5655","17.5182","64.3792"
"27.6000","6.8691","6.8691","4.5794","17.5829","64.6171"
"27.6800","6.8880","6.8880","4.5920","17.6412","64.8314"
"27.7600","6.9090","6.9090","4.6060","17.7051","65.0662"
"27.8400","6.9295","6.9295","4.6197","17.7701","65.3052"
"27.9200","6.9492","6.9492","4.6328","17.8312","65.5297"
"28.0000","6.9691","6.9691","4.6461","17.8933","65.7578"
"28.0800","6.9885","6.9885","4.6590","17.9511","65.9702"
"28.1600","7.0087","7.0087","4.6725","18.0115","66.1923"
"28.2400","7.0290","7.0290","4.6860","18.0734","66.4198"
"28.3200","7.0477","7.0477","4.6985","18.1311","66.6320"
"28.4000","7.0696","7.0696","4.7130","18.2000","66.8850"
"28.4800","7.0896","7.0896","4.7264","18.2642","67.1209"
"28.5600","7.1098","7.1098","4.7399","18.3260","67.3480"
"28.6400","7.1291","7.1291","4.7527","18.3881","67.5764"
"28.7200","7.1480","7.1480","4.7653","18.4415","67.7725"
"28.8000","7.1685","7.1685","4.7790","18.5067","68.0123"
"28.8800","7.1889","7.1889","4.7926","18.5681","68.2378"
"28.9600","7.2071","7.2071","4.8047","18.6267","68.4532"
"29.0400","7.2287","7.2287","4.8192","18.6932","68.6973"
"29.1200","7.2489","7.2489","4.8326","18.7577","68.9346"
"29.2000","7.2697","7.2697","4.8464","18.8217","69.1697"
"29.2800","7.2896","7.2896","4.8597","18.8846","69.4010"
"29.3600","7.3080","7.3080","4.8720","18.9435","69.6173"
"29.4400","7.3285","7.3285","4.8857","19.0064","69.8487"
"29.5200","7.3485","7.3485","4.8990","19.0689","70.0782"
"29.6000","7.3689","7.3689","4.9126","19.1346","70.3197"
"29.6800","7.3903","7.3903","4.9269","19.2003","70.5611"
"29.7600","7.4093","7.4093","4.9395","19.2583","70.7743"
"29.8400","7.4293","7.4293","4.9529","19.3208","71.0040"
"29.9200","7.4493","7.4493","4.9662","19.3842","71.2370"
"30.0000","7.4685","7.4685","4.9790","19.4456","71.4625"
"30.0800","7.4889","7.4889","4.9926","19.5121","71.7071"
"30.1600","7.5074","7.5074","5.0050","19.5693","71.9171"
"30.2400","7.5283","7.5283","5.0189","19.6322","72.1484"
"30.3200","7.5494","7.5494","5.0329","19.6996","72.3959"
"30.4000","7.5692","7.5692","5.0461","19.7656","72.6386"
"30.4800","7.5895","7.5895","5.0597","19.8300","72.8751"
"30.5600","7.6089","7.6089","5.0726","19.8884","73.0900"
"30.6400","7.6281","7.6281","5.0854","19.9498","73.3156"
"30.7200","7.6488","7.6488","5.0992","20.0153","73.5564"
"30.8000","7.6681","7.6681","5.1121","20.0763","73.7803"
"30.8800","7.6898","7.6898","5.1265","20.1467","74.0392"
"30.9600","7.7099","7.7099","5.1400","20.2139","74.2860"
"31.0400","7.7293","7.7293","5.1529","20.2722","74.5005"
"31.1200","7.7487","7.7487","5.1658","20.3332","74.7246"
"31.2000","7.7687","7.7687","5.1791","20.3948","74.9510"
"31.2800","7.7892","7.7892","5.1928","20.4620","75.1980"
"31.3600","7.8090","7.8090","5.2060","20.5223","75.4196"
"31.4400","7.8269","7.8269","5.2180","20.5813","75.6365"
"31.5200","7.8486","7.8486","5.2324","20.6509","75.8922"
"31.6000","7.8695","7.8695","5.2463","20.7193","76.1434"
"31.6800","7.8892","7.8892","5.2595","20.7798","76.3657"
"31.7600","7.9090","7.9090","5.2727","20.8438","76.6010"
"31.8400","7.9281","7.9281","5.2854","20.9041","76.8224"
"31.9200","7.9484","7.9484","5.2990","20.9694","77.0625"
"32.0000","7.9689","7.9689","5.3126","21.0331","77.2966"
"32.0800","7.9886","7.9886","5.3258","21.0996","77.5410"
"32.1600","8.0097","8.0097","5.3398","21.1695","77.7978"
"32.2400","8.0294","8.0294","5.3529","21.2283","78.0141"
"32.3200","8.0493","8.0493","5.3662","21.2911","78.2449"
"32.4000","8.0695","8.0695","5.3797","21.3601","78.4982"
"32.4800","8.0881","8.0881","5.3920","21.4187","78.7139"
"32.5600","8.1090","8.1090","5.4060","21.4862","78.9619"
"32.6400","8.1280","8.1280","5.4187","21.5469","79.1850"
"32.7200","8.1479","8.1479","5.4319","21.6118","79.4234"
"32.8000","8.1690","8.1690","5.4460","21.6810","79.6777"
"32.8800","8.1893","8.1893","5.4595","21.7450","79.9130"
"32.9600","8.2093","8.2093","5.4728","21.8084","80.1457"
"33.0400","8.2293","8.2293","5.4862","21.8727","80.3823"
"33.1200","8.2478","8.2478","5.4985","21.9348","80.6105"
"33.2000","8.2688","8.2688","5.5125","22.0046","80.8670"
"33.2800","8.2884","8.2884","5.5256","22.0662","81.0931"
"33.3600","8.3094","8.3094","5.5396","22.1369","81.3531"
"33.4400","8.3297","8.3297","5.5531","22.2018","81.5918"
"33.5200","8.3491","8.3491","5.5660","22.2639","81.8199"
"33.6000","8.3693","8.3693","5.5795","22.3288","82.0585"
"33.6800","8.3890","8.3890","5.5927","22.3972","82.3098"
"33.7600","8.4084","8.4084","5.6056","22.4569","82.5291"
"33.8400","8.4282","8.4282","5.6188","22.5227","82.7711"
"33.9200","8.4474","8.4474","5.6316","22.5862","83.0043"
"34.0000","8.4683","8.4683","5.6455","22.6514","83.2439"
"34.0800","8.4898","8.4898","5.6599","22.7210","83.4996"
"34.1600","8.5089","8.5089","5.6726","22.7839","83.7308"
"34.2400","8.5292","8.5292","5.6861","22.8536","83.9869"
"34.3200","8.5481","8.5481","5.6987","22.9124","84.2029"
"34.4000","8.5690","8.5690","5.7127","22.9808","84.4546"
"34.4800","8.5892","8.5892","5.7261","23.0472","84.6985"
"34.5600","8.6081","8.6081","5.7387","23.1092","84.9264"
"34.6400","8.6289","8.6289","5.7526","23.1798","85.1857"
"34.7200","8.6500","8.6500","5.7667","23.2505","85.4456"
"34.8000","8.6693","8.6693","5.7795","23.3141","85.6794"
"34.8800","8.6895","8.6895","5.7930","23.3803","85.9227"
"34.9600","8.7080","8.7080","5.8053","23.4376","86.1332"
"35.0400","8.7286","8.7286","5.8190","23.5060","86.3844"
"35.1200","8.7487","8.7487","5.8325","23.5744","86.6358"
"35.2000","8.7679","8.7679","5.8453","23.6380","86.8698"
"35.2800","8.7890","8.7890","5.8593","23.7137","87.1479"
"35.3600","8.8098","8.8098","5.8732","23.7809","87.3950"
"35.4400","8.8294","8.8294","5.8863","23.8443","87.6277"
"35.5200","8.8486","8.8486","5.8991","23.9079","87.8615"
"35.6000","8.8676","8.8676","5.9117","23.9672","88.0796"
"35.6800","8.8890","8.8890","5.9260","24.0402","88.3476"
"35.7600","8.9092","8.9092","5.9395","24.1070","88.5931"
"35.8400","8.9286","8.9286","5.9524","24.1726","88.8344"
"35.9200","8.9493","8.9493","5.9662","24.2423","89.0906"
"36.0000","8.9692","8.9692","5.9795","24.3087","89.3345"
"36.0800","8.9896","8.9896","5.9931","24.3740","89.5743"
"36.1600","9.0092","9.0092","6.0061","24.4387","89.8123"
"36.2400","9.0282","9.0282","6.0188","24.5023","90.0460"
"36.3200","9.0481","9.0481","6.0321","24.5688","90.2902"
"36.4000","9.0681","9.0681","6.0454","24.6357","90.5360"
"36.4800","9.0881","9.0881","6.0587","24.7024","90.7812"
"36.5600","9.1103","9.1103","6.0735","24.7805","91.0682"
"36.6400","9.1289","9.1289","6.0860","24.8380","91.2796"
"36.7200","9.1492","9.1492","6.0994","24.9090","91.5407"
"36.8000","9.1683","9.1683","6.1122","24.9738","91.7788"
"36.8800","9.1883","9.1883","6.1255","25.0418","92.0286"
"36.9600","9.2085","9.2085","6.1390","25.1117","92.2857"
"37.0400","9.2284","9.2284","6.1523","25.1749","92.5177"
"37.1200","9.2489","9.2489","6.1659","25.2445","92.7735"
"37.2000","9.2705","9.2705","6.1803","25.3188","93.0467"
"37.2800","9.2892","9.2892","6.1928","25.3832","93.2834"
"37.3600","9.3094","9.3094","6.2063","25.4514","93.5338"
"37.4400","9.3283","9.3283","6.2189","25.5142","93.7647"
"37.5200","9.3482","9.3482","6.2322","25.5832","94.0182"
"37.6000","9.3690","9.3690","6.2460","25.6551","94.2824"
"37.6800","9.3879","9.3879","6.2586","25.7167","94.5089"
"37.7600","9.4089","9.4089","6.2726","25.7889","94.7743"
"37.8400","9.4291","9.4291","6.2861","25.8573","95.0255"
"37.9200","9.4489","9.4489","6.2993","25.9256","95.2766"
"38.0000","9.4694","9.4694","6.3129","25.9965","95.5370"
"38.0800","9.4888","9.4888","6.3258","26.0615","95.7761"
"38.1600","9.5088","9.5088","6.3392","26.1289","96.0238"
"38.2400","9.5290","9.5290","6.3527","26.1983","96.2789"
"38.3200","9.5476","9.5476","6.3650","26.2650","96.5238"
"38.4000","9.5696","9.5696","6.3797","26.3421","96.8072"
"38.4800","9.5895","9.5895","6.3930","26.4087","97.0520"
"38.5600","9.6098","9.6098","6.4065","26.4750","97.2956"
"38.6400","9.6288","9.6288","6.4192","26.5403","97.5357"
"38.7200","9.6482","9.6482","6.4321","26.6057","97.7758"
"38.8000","9.6688","9.6688","6.4459","26.6770","98.0380"
"38.8800","9.6889","9.6889","6.4593","26.7435","98.2825"
"38.9600","9.7075","9.7075","6.4717","26.8122","98.5348"
"39.0400","9.7288","9.7288","6.4858","26.8874","98.8111"
"39.1200","9.7487","9.7487","6.4992","26.9567","99.0659"
"39.2000","9.7692","9.7692","6.5128","27.0253","99.3181"
"39.2800","9.7897","9.7897","6.5265","27.0938","99.5698"
"39.3600","9.8083","9.8083","6.5389","27.1576","99.8041"
"39.4400","9.8285","9.8285","6.5523","27.2256","100.0541"
"39.5200","9.8487","9.8487","6.5658","27.2979","100.3199"
"39.6000","9.8688","9.8688","6.5792","27.3682","100.5783"
"39.6800","9.8899","9.8899","6.5933","27.4419","100.8490"
"39.7600","9.9094","9.9094","6.6063","27.5086","101.0940"
"39.8400","9.9291","9.9291","6.6194","27.5770","101.3454"
"39.9200","9.9491","9.9491","6.6328","27.6441","101.5920"
"40.0000","9.9684","9.9684","6.6456","27.7139","101.8485"
"40.0800","9.9889","9.9889","6.6593","27.7831","102.1027"
"40.1600","10.0074","10.0074","6.6716","27.8474","102.3393"
"40.2400","10.0285","10.0285","6.6857","27.9192","102.6029"
"40.3200","10.0492","10.0492","6.6995","27.9952","102.8825"
"40.4000","10.0693","10.0693","6.7129","28.0677","103.1487"
"40.4800","10.0893","10.0893","6.7262","28.1370","103.4035"
"40.5600","10.1089","10.1089","6.7392","28.2047","103.6522"
"40.6400","10.1281","10.1281","6.7521","28.2720","103.8995"
"40.7200","10.1487","10.1487","6.7658","28.3431","104.1609"
"40.8000","10.1680","10.1680","6.7787","28.4117","104.4128"
"40.8800","10.1897","10.1897","6.7931","28.4902","104.7013"
"40.9600","10.2100","10.2100","6.8067","28.5571","104.9473"
"41.0400","10.2291","10.2291","6.8194","28.6253","105.1981"
"41.1200","10.2487","10.2487","6.8325","28.6936","105.4491"
"41.2000","10.2688","10.2688","6.8458","28.7636","105.7063"
"41.2800","10.2886","10.2886","6.8591","28.8323","105.9587"
"41.3600","10.3090","10.3090","6.8727","28.9043","106.2235"
"41.4400","10.3270","10.3270","6.8847","28.9640","106.4428"
"41.5200","10.3491","10.3491","6.8994","29.0472","106.7485"
"41.6000","10.3700","10.3700","6.9134","29.1209","107.0193"
"41.6800","10.3890","10.3890","6.9260","29.1858","107.2579"
"41.7600","10.4088","10.4088","6.9392","29.2564","107.5173"
"41.8400","10.4277","10.4277","6.9518","29.3203","107.7522"
"41.9200","10.4487","10.4487","6.9658","29.3961","108.0308"
"42.0000","10.4688","10.4688","6.9792","29.4670","108.2914"
"42.0800","10.4887","10.4887","6.9925","29.5394","108.5574"
"42.1600","10.5091","10.5091","7.0061","29.6153","108.8361"
"42.2400","10.5289","10.5289","7.0193","29.6824","109.0827"
"42.3200","10.5492","10.5492","7.0328","29.7554","109.3510"
"42.4000","10.5700","10.5700","7.0467","29.8296","109.6240"
"42.4800","10.5886","10.5886","7.0591","29.8974","109.8728"
"42.5600","10.6090","10.6090","7.0727","29.9708","110.1428"
"42.6400","10.6280","10.6280","7.0854","30.0377","110.3884"
"42.7200","10.6479","10.6479","7.0986","30.1095","110.6522"
"42.8000","10.6694","10.6694","7.1129","30.1891","110.9450"
"42.8800","10.6897","10.6897","7.1265","30.2592","111.2026"
"42.9600","10.7090","10.7090","7.1393","30.3256","111.4464"
"43.0400","10.7288","10.7288","7.1525","30.3965","111.7072"
"43.1200","10.7475","10.7475","7.1650","30.4620","111.9478"
"43.2000","10.7689","10.7689","7.1793","30.5411","112.2387"
"43.2800","10.7884","10.7884","7.1923","30.6081","112.4849"
"43.3600","10.8094","10.8094","7.2062","30.6873","112.7758"
"43.4400","10.8299","10.8299","7.2199","30.7564","113.0297"
"43.5200","10.8488","10.8488","7.2325","30.8259","113.2852"
"43.6000","10.8689","10.8689","7.2459","30.8980","113.5500"
"43.6800","10.8892","10.8892","7.2594","30.9731","113.8260"
"43.7600","10.9087","10.9087","7.2725","31.0415","114.0775"
"43.8400","10.9284","10.9284","7.2856","31.1130","114.3402"
"43.9200","10.9476","10.9476","7.2984","31.1783","114.5803"
"44.0000","10.9685","10.9685","7.3123","31.2562","114.8666"
"44.0800","10.9901","10.9901","7.3267","31.3328","115.1480"
"44.1600","11.0090","11.0090","7.3393","31.4037","115.4087"
"44.2400","11.0288","11.0288","7.3526","31.4766","115.6766"
"44.3200","11.0482","11.0482","7.3655","31.5457","115.9304"
"44.4000","11.0691","11.0691","7.3794","31.6234","116.2158"
"44.4800","11.0890","11.0890","7.3927","31.6917","116.4669"
"44.5600","11.1086","11.1086","7.4057","31.7620","116.7254"
"44.6400","11.1289","11.1289","7.4193","31.8372","117.0016"
"44.7200","11.1498","11.1498","7.4332","31.9154","117.2891"
"44.8000","11.1691","11.1691","7.4460","31.9831","117.5380"
"44.8800","11.1900","11.1900","7.4600","32.0652","117.8396"
"44.9600","11.2082","11.2082","7.4722","32.1275","118.0684"
"45.0400","11.2285","11.2285","7.4856","32.2018","118.3416"
"45.1200","11.2480","11.2480","7.4987","32.2697","118.5912"
"45.2000","11.2680","11.2680","7.5120","32.3442","118.8651"
"45.2800","11.2891","11.2891","7.5261","32.4256","119.1639"
"45.3600","11.3096","11.3096","7.5398","32.4995","119.4356"
"45.4400","11.3289","11.3289","7.5526","32.5678","119.6867"
"45.5200","11.3489","11.3489","7.5659","32.6397","119.9508"
"45.6000","11.3680","11.3680","7.5787","32.7114","120.2145"
"45.6800","11.3889","11.3889","7.5926","32.7907","120.5058"
"45.7600","11.4091","11.4091","7.6060","32.8624","120.7693"
"45.8400","11.4283","11.4283","7.6188","32.9327","121.0276"
"45.9200","11.4495","11.4495","7.6330","33.0145","121.3284"
"46.0000","11.4694","11.4694","7.6463","33.0858","121.5903"
"46.0800","11.4896","11.4896","7.6597","33.1603","121.8640"
"46.1600","11.5091","11.5091","7.6727","33.2268","122.1086"
"46.2400","11.5285","11.5285","7.6857","33.3035","122.3904"
"46.3200","11.5482","11.5482","7.6988","33.3765","122.6586"
"46.4000","11.5682","11.5682","7.7121","33.4498","122.9279"
"46.4800","11.5885","11.5885","7.7256","33.5269","123.2113"
"46.5600","11.6098","11.6098","7.7399","33.6067","123.5046"
"46.6400","11.6287","11.6287","7.7525","33.6752","123.7562"
"46.7200","11.6492","11.6492","7.7661","33.7502","124.0319"
"46.8000","11.6685","11.6685","7.7790","33.8238","124.3025"
"46.8800","11.6884","11.6884","7.7923","33.8949","124.5639"
"46.9600","11.7086","11.7086","7.8058","33.9755","124.8601"
"47.0400","11.7284","11.7284","7.8190","34.0475","125.1246"
"47.1200","11.7488","11.7488","7.8325","34.1244","125.4070"
"47.2000","11.7706","11.7706","7.8471","34.2070","125.7106"
"47.2800","11.7895","11.7895","7.8597","34.2787","125.9742"
"47.3600","11.8094","11.8094","7.8729","34.3507","126.2387"
"47.4400","11.8282","11.8282","7.8855","34.4181","126.4866"
"47.5200","11.8482","11.8482","7.8988","34.4946","126.7676"
"47.6000","11.8690","11.8690","7.9127","34.5719","127.0518"
"47.6800","11.8878","11.8878","7.9252","34.6432","127.3138"
"47.7600","11.9090","11.9090","7.9394","34.7238","127.6101"
"47.8400","11.9296","11.9296","7.9531","34.8031","127.9013"
"47.9200","11.9486","11.9486","7.9658","34.8722","128.1555"
"48.0000","11.9690","11.9690","7.9793","34.9525","128.4503"
"48.0800","11.9888","11.9888","7.9925","35.0261","128.7209"
"48.1600","12.0089","12.0089","8.0059","35.1008","128.9955"
"48.2400","12.0291","12.0291","8.0194","35.1745","129.2662"
"48.3200","12.0479","12.0479","8.0319","35.2477","129.5353"
"48.4000","12.0694","12.0694","8.0462","35.3272","129.8274"
"48.4800","12.0896","12.0896","8.0598","35.4092","130.1287"
"48.5600","12.1099","12.1099","8.0732","35.4819","130.3961"
"48.6400","12.1286","12.1286","8.0857","35.5515","130.6517"
"48.7200","12.1482","12.1482","8.0988","35.6259","130.9254"
"48.8000","12.1688","12.1688","8.1125","35.7032","131.2092"
"48.8800","12.1889","12.1889","8.1260","35.7787","131.4869"
"48.9600","12.2076","12.2076","8.1384","35.8506","131.7508"
"49.0400","12.2289","12.2289","8.1526","35.9305","132.0447"
"49.1200","12.2486","12.2486","8.1657","36.0071","132.3260"
"49.2000","12.2698","12.2698","8.1798","36.0882","132.6242"
"49.2800","12.2894","12.2894","8.1930","36.1621","132.8957"
"49.3600","12.3080","12.3080","8.2053","36.2334","133.1577"
"49.4400","12.3283","12.3283","8.2189","36.3118","133.4459"
"49.5200","12.3488","12.3488","8.2325","36.3910","133.7371"
"49.6000","12.3690","12.3690","8.2460","36.4693","134.0247"
"49.6800","12.3900","12.3900","8.2600","36.5506","134.3236"
"49.7600","12.4090","12.4090","8.2726","36.6202","134.5793"
"49.8400","12.4294","12.4294","8.2863","36.7000","134.8727"
"49.9200","12.4491","12.4491","8.2994","36.7713","135.1347"
"50.0000","12.4680","12.4680","8.3120","36.8453","135.4063"
"50.0800","12.4887","12.4887","8.3258","36.9276","135.7088"
"50.1600","12.5076","12.5076","8.3384","36.9960","135.9603"
"50.2400","12.5283","12.5283","8.3522","37.0769","136.2575"
"50.3200","12.5494","12.5494","8.3662","37.1601","136.5633"
"50.4000","12.5694","12.5694","8.3796","37.2366","136.8447"
"50.4800","12.5891","12.5891","8.3927","37.3125","137.1236"
"50.5600","12.6090","12.6090","8.4060","37.3863","137.3948"
"50.6400","12.6280","12.6280","8.4187","37.4592","137.6624"
"50.7200","12.6489","12.6489","8.4326","37.5439","137.9738"
"50.8000","12.6679","12.6679","8.4453","37.6160","138.2387"
"50.8800","12.6899","12.6899","8.4599","37.7051","138.5661"
"50.9600","12.7102","12.7102","8.4735","37.7845","138.8582"
"51.0400","12.7293","12.7293","8.4862","37.8555","139.1191"
"51.1200","12.7488","12.7488","8.4992","37.9302","139.3933"
"51.2000","12.7685","12.7685","8.5123","38.0052","139.6691"
"51.2800","12.7895","12.7895","8.5263","38.0944","139.9970"
"51.3600","12.8093","12.8093","8.5395","38.1683","140.2683"
"51.4400","12.8275","12.8275","8.5516","38.2377","140.5235"
"51.5200","12.8488","12.8488","8.5659","38.3235","140.8389"
"51.6000","12.8692","12.8692","8.5795","38.4028","141.1303"
"51.6800","12.8893","12.8893","8.5929","38.4827","141.4239"
"51.7600","12.9091","12.9091","8.6061","38.5580","141.7006"
"51.8400","12.9277","12.9277","8.6185","38.6299","141.9647"
"51.9200","12.9486","12.9486","8.6324","38.7096","142.2576"
"52.0000","12.9692","12.9692","8.6462","38.7912","142.5577"
"52.0800","12.9888","12.9888","8.6592","38.8690","142.8436"
"52.1600","13.0095","13.0095","8.6730","38.9542","143.1568"
"52.2400","13.0292","13.0292","8.6861","39.0254","143.4182"
"52.3200","13.0492","13.0492","8.6995","39.1053","143.7121"
"52.4000","13.0695","13.0695","8.7130","39.1852","144.0056"
"52.4800","13.0882","13.0882","8.7255","39.2584","144.2747"
"52.5600","13.1088","13.1088","8.7392","39.3401","144.5748"
"52.6400","13.1281","13.1281","8.7521","39.4139","144.8459"
"52.7200","13.1481","13.1481","8.7654","39.4946","145.1425"
"52.8000","13.1689","13.1689","8.7793","39.5767","145.4445"
"52.8800","13.1893","13.1893","8.7928","39.6565","145.7376"
"52.9600","13.2092","13.2092","8.8062","39.7341","146.0228"
"53.0400","13.2291","13.2291","8.8194","39.8113","146.3065"
"53.1200","13.2481","13.2481","8.8321","39.8892","146.5927"
"53.2000","13.2691","13.2691","8.8460","39.9756","146.9102"
"53.2800","13.2885","13.2885","8.8590","40.0499","147.1834"
"53.3600","13.3092","13.3092","8.8728","40.1346","147.4945"
"53.4400","13.3300","13.3300","8.8867","40.2168","147.7967"
"53.5200","13.3487","13.3487","8.8991","40.2867","148.0538"
"53.6000","13.3692","13.3692","8.9128","40.3701","148.3601"
"53.6800","13.3890","13.3890","8.9260","40.4512","148.6582"
"53.7600","13.4084","13.4084","8.9389","40.5273","148.9379"
"53.8400","13.4285","13.4285","8.9523","40.6088","149.2375"
"53.9200","13.4478","13.4478","8.9652","40.6837","149.5125"
"54.0000","13.4687","13.4687","8.9792","40.7696","149.8281"
"54.0800","13.4899","13.4899","8.9933","40.8528","150.1340"
"54.1600","13.5083","13.5083","9.0055","40.9276","150.4090"
"54.2400","13.5288","13.5288","9.0192","41.0057","150.6960"
"54.3200","13.5483","13.5483","9.0322","41.0845","150.9856"
"54.4000","13.5691","13.5691","9.0461","41.1705","151.3017"
"54.4800","13.5893","13.5893","9.0595","41.2501","151.5942"
"54.5600","13.6083","13.6083","9.0722","41.3253","151.8706"
"54.6400","13.6288","13.6288","9.0859","41.4112","152.1860"
"54.7200","13.6498","13.6498","9.0999","41.4959","152.4974"
"54.8000","13.6691","13.6691","9.1127","41.5710","152.7734"
"54.8800","13.6893","13.6893","9.1262","41.6541","153.0787"
"54.9600","13.7080","13.7080","9.1386","41.7241","153.3362"
"55.0400","13.7286","13.7286","9.1524","41.8065","153.6389"
"55.1200","13.7485","13.7485","9.1657","41.8868","153.9339"
"55.2000","13.7672","13.7672","9.1781","41.9619","154.2099"
"55.2800","13.7891","13.7891","9.1927","42.0595","154.5686"
"55.3600","13.8099","13.8099","9.2066","42.1434","154.8770"
"55.4400","13.8293","13.8293","9.2195","42.2185","155.1528"
"55.5200","13.8488","13.8488","9.2325","42.2964","155.4392"
"55.6000","13.8678","13.8678","9.2452","42.3696","155.7084"
"55.6800","13.8889","13.8889","9.2592","42.4587","156.0358"
"55.7600","13.9090","13.9090","9.2726","42.5392","156.3316"
"55.8400","13.9283","13.9283","9.2856","42.6184","156.6227"
"55.9200","13.9496","13.9496","9.2997","42.7090","156.9557"
"56.0000","13.9693","13.9693","9.3129","42.7862","157.2392"
"56.0800","13.9897","13.9897","9.3264","42.8697","157.5461"
"56.1600","14.0096","14.0096","9.3397","42.9506","157.8433"
"56.2400","14.0282","14.0282","9.3521","43.0249","158.1166"
"56.3200","14.0482","14.0482","9.3654","43.1061","158.4149"
"56.4000","14.0680","14.0680","9.3787","43.1871","158.7126"
"56.4800","14.0883","14.0883","9.3922","43.2700","159.0172"
"56.5600","14.1098","14.1098","9.4065","43.3609","159.3512"
"56.6400","14.1289","14.1289","9.4193","43.4375","159.6330"
"56.7200","14.1491","14.1491","9.4327","43.5209","159.9391"
"56.8000","14.1687","14.1687","9.4458","43.5992","160.2272"
"56.8800","14.1887","14.1887","9.4591","43.6860","160.5460"
"56.9600","14.2084","14.2084","9.4722","43.7678","160.8467"
"57.0400","14.2279","14.2279","9.4853","43.8420","161.1194"
"57.1200","14.2485","14.2485","9.4990","43.9277","161.4343"
"57.2000","14.2701","14.2701","9.5134","44.0164","161.7602"
"57.2800","14.2895","14.2895","9.5263","44.0992","162.0645"
"57.3600","14.3092","14.3092","9.5394","44.1820","162.3687"
"57.4400","14.3282","14.3282","9.5521","44.2555","162.6391"
"57.5200","14.3483","14.3483","9.5655","44.3400","162.9495"
"57.6000","14.3690","14.3690","9.5793","44.4274","163.2706"
"57.6800","14.3878","14.3878","9.5918","44.5026","163.5471"
"57.7600","14.4088","14.4088","9.6059","44.5933","163.8802"
"57.8400","14.4294","14.4294","9.6196","44.6782","164.1926"
"57.9200","14.4489","14.4489","9.6326","44.7588","164.4886"
"58.0000","14.4690","14.4690","9.6460","44.8427","164.7969"
"58.0800","14.4888","14.4888","9.6592","44.9230","165.0919"
"58.1600","14.5089","14.5089","9.6726","45.0070","165.4008"
"58.2400","14.5288","14.5288","9.6859","45.0911","165.7096"
"58.3200","14.5476","14.5476","9.6984","45.1683","165.9935"
"58.4000","14.5698","14.5698","9.7132","45.2673","166.3574"
"58.4800","14.5899","14.5899","9.7266","45.3498","166.6606"
"58.5600","14.6099","14.6099","9.7399","45.4288","166.9509"
"58.6400","14.6289","14.6289","9.7526","45.5078","167.2410"
"58.7200","14.6481","14.6481","9.7654","45.5870","167.5323"
"58.8000","14.6686","14.6686","9.7790","45.6739","167.8514"
"58.8800","14.6890","14.6890","9.7927","45.7590","168.1645"
"58.9600","14.7077","14.7077","9.8051","45.8342","168.4406"
"59.0400","14.7284","14.7284","9.8189","45.9266","168.7801"
"59.1200","14.7487","14.7487","9.8325","46.0107","169.0892"
"59.2000","14.7697","14.7697","9.8464","46.0987","169.4127"
"59.2800","14.7891","14.7891","9.8594","46.1778","169.7033"
"59.3600","14.8081","14.8081","9.8720","46.2577","169.9972"
"59.4400","14.8281","14.8281","9.8854","46.3420","170.3068"
"59.5200","14.8482","14.8482","9.8988","46.4250","170.6119"
"59.6000","14.8690","14.8690","9.9127","46.5144","170.9405"
"59.6800","14.8904","14.8904","9.9269","46.6051","171.2738"
"59.7600","14.9093","14.9093","9.9395","46.6821","171.5568"
"59.8400","14.9291","14.9291","9.9528","46.7632","171.8548"
"59.9200","14.9490","14.9490","9.9660","46.8453","172.1565"
"60.0000","14.9680","14.9680","9.9787","46.9257","172.4518"
"60.0800","14.9889","14.9889","9.9926","47.0170","172.7874"
"60.1250","15.0001","15.0001","10.0001","47.0615","172.9509"