File: data/instron_tests/metamaterial_samples/510_BULK_m1.is_comp_Exports/510_BULK_m1_1_1.csv
Sample text inputs : Sample No.,Sample choice input : Leading Direction,Sample choice input : Mode,Specimen choice input : Direction,Specimen properties : Height,Specimen properties : Thickness,Specimen properties : Width,Test : Rate 1
,,,,(mm),(mm),(mm),(mm/min)
"510","Bulk","Unimode","1","150.00","25.00","150.00","15.00"

Time,Displacement,Compressive displacement,Compressive strain (Displacement),Compressive stress,Force
(s),(mm),(mm),(%),(kPa),(N)
"0.0000","0.0000","0.0000","0.0000","-0.6015","-2.2256"
"0.0800","0.0016","0.0016","0.0011","-0.5890","-2.1793"
"0.1600","0.0210","0.0210","0.0140","-0.4771","-1.7651"
"0.2400","0.0413","0.0413","0.0275","-0.3625","-1.3411"
"0.3200","0.0590","0.0590","0.0393","-0.2708","-1.0020"
"0.4000","0.0787","0.0787","0.0525","-0.1655","-0.6124"
"0.4800","0.0985","0.0985","0.0657","-0.0632","-0.2337"
"0.5600","0.1177","0.1177","0.0784","0.0352","0.1303"
"0.6400","0.1387","0.1387","0.0925","0.1405","0.5199"
"0.7200","0.1595","0.1595","0.1064","0.2453","0.9078"
"0.8000","0.1790","0.1790","0.1193","0.3400","1.2578"
"0.8800","0.1993","0.1993","0.1328","0.4399","1.6278"
"0.9600","0.2181","0.2181","0.1454","0.5274","1.9513"
"1.0400","0.2388","0.2388","0.1592","0.6257","2.3149"
"1.1200","0.2587","0.2587","0.1725","0.7157","2.6480"
"1.2000","0.2784","0.2784","0.1856","0.7919","2.9301"
"1.2800","0.2998","0.2998","0.1999","0.8825","3.2653"
"1.3600","0.3197","0.3197","0.2132","0.9714","3.5941"
"1.4400","0.3399","0.3399","0.2266","1.0529","3.8957"
"1.5200","0.3595","0.3595","0.2396","1.1418","4.2246"
"1.6000","0.3780","0.3780","0.2520","1.2224","4.5230"
"1.6800","0.3989","0.3989","0.2659","1.3143","4.8630"
"1.7600","0.4183","0.4183","0.2789","1.4026","5.1897"
"1.8400","0.4385","0.4385","0.2924","1.4925","5.5221"
"1.9200","0.4591","0.4591","0.3061","1.5870","5.8720"
"2.0000","0.4793","0.4793","0.3195","1.6754","6.1989"
"2.0800","0.4994","0.4994","0.3329","1.7671","6.5383"
"2.1600","0.5197","0.5197","0.3465","1.8634","6.8947"
"2.2400","0.5386","0.5386","0.3590","1.9533","7.2270"
"2.3200","0.5583","0.5583","0.3722","2.0511","7.5890"
"2.4000","0.5778","0.5778","0.3852","2.1392","7.9152"
"2.4800","0.5994","0.5994","0.3996","2.2457","8.3090"
"2.5600","0.6208","0.6208","0.4139","2.3510","8.6988"
"2.6400","0.6396","0.6396","0.4264","2.4405","9.0297"
"2.7200","0.6593","0.6593","0.4395","2.5345","9.3778"
"2.8000","0.6788","0.6788","0.4526","2.6318","9.7376"
"2.8800","0.6987","0.6987","0.4658","2.7297","10.0998"
"2.9600","0.7191","0.7191","0.4794","2.8314","10.4762"
"3.0400","0.7378","0.7378","0.4919","2.9210","10.8077"
"3.1200","0.7591","0.7591","0.5061","3.0339","11.2255"
"3.2000","0.7799","0.7799","0.5199","3.1361","11.6035"
"3.2800","0.7990","0.7990","0.5327","3.2364","11.9747"
"3.3600","0.8194","0.8194","0.5463","3.3420","12.3653"
"3.4400","0.8385","0.8385","0.5590","3.4364","12.7148"
"3.5200","0.8590","0.8590","0.5727","3.5440","13.1128"
"3.6000","0.8792","0.8792","0.5861","3.6481","13.4981"
"3.6800","0.8983","0.8983","0.5989","3.7500","13.8749"
"3.7600","0.9196","0.9196","0.6131","3.8678","14.3110"
"3.8400","0.9402","0.9402","0.6268","3.9741","14.7043"
"3.9200","0.9591","0.9591","0.6394","4.0719","15.0662"
"4.0000","0.9794","0.9794","0.6529","4.1818","15.4728"
"4.0800","0.9986","0.9986","0.6657","4.2810","15.8397"
"4.1600","1.0196","1.0196","0.6797","4.3934","16.2555"
"4.2400","1.0390","1.0390","0.6927","4.4964","16.6367"
"4.3200","1.0578","1.0578","0.7052","4.5993","17.0172"
"4.4000","1.0783","1.0783","0.7189","4.7156","17.4476"
"4.4800","1.0996","1.0996","0.7331","4.8315","17.8767"
"4.5600","1.1200","1.1200","0.7467","4.9418","18.2845"
"4.6400","1.1400","1.1400","0.7600","5.0494","18.6827"
"4.7200","1.1579","1.1579","0.7719","5.1483","19.0488"
"4.8000","1.1788","1.1788","0.7859","5.2642","19.4776"
"4.8800","1.1988","1.1988","0.7992","5.3768","19.8943"
"4.9600","1.2187","1.2187","0.8125","5.4860","20.2982"
"5.0400","1.2400","1.2400","0.8267","5.6069","20.7456"
"5.1200","1.2597","1.2597","0.8398","5.7127","21.1372"
"5.2000","1.2799","1.2799","0.8533","5.8252","21.5531"
"5.2800","1.2993","1.2993","0.8662","5.9333","21.9531"
"5.3600","1.3185","1.3185","0.8790","6.0436","22.3613"
"5.4400","1.3389","1.3389","0.8926","6.1579","22.7843"
"5.5200","1.3583","1.3583","0.9055","6.2676","23.1903"
"5.6000","1.3784","1.3784","0.9190","6.3816","23.6119"
"5.6800","1.3996","1.3996","0.9331","6.5040","24.0647"
"5.7600","1.4187","1.4187","0.9458","6.6111","24.4612"
"5.8400","1.4401","1.4401","0.9601","6.7344","24.9174"
"5.9200","1.4587","1.4587","0.9725","6.8403","25.3089"
"6.0000","1.4786","1.4786","0.9857","6.9550","25.7334"
"6.0800","1.4983","1.4983","0.9989","7.0702","26.1596"
"6.1600","1.5189","1.5189","1.0126","7.1892","26.6001"
"6.2400","1.5392","1.5392","1.0262","7.3071","27.0364"
"6.3200","1.5606","1.5606","1.0404","7.4335","27.5040"
"6.4000","1.5790","1.5790","1.0527","7.5375","27.8886"
"6.4800","1.5995","1.5995","1.0663","7.6576","28.3332"
"6.5600","1.6189","1.6189","1.0793","7.7700","28.7488"
"6.6400","1.6392","1.6392","1.0928","7.8881","29.1858"
"6.7200","1.6588","1.6588","1.1059","8.0032","29.6119"
"6.8000","1.6775","1.6775","1.1183","8.1137","30.0207"
"6.8800","1.6988","1.6988","1.1326","8.2383","30.4818"
"6.9600","1.7199","1.7199","1.1466","8.3653","30.9515"
"7.0400","1.7396","1.7396","1.1598","8.4805","31.3779"
"7.1200","1.7590","1.7590","1.1727","8.5929","31.7937"
"7.2000","1.7783","1.7783","1.1855","8.7053","32.2096"
"7.2800","1.7988","1.7988","1.1992","8.8282","32.6644"
"7.3600","1.8199","1.8199","1.2133","8.9600","33.1519"
"7.4400","1.8386","1.8386","1.2257","9.0692","33.5562"
"7.5200","1.8593","1.8593","1.2395","9.1924","34.0120"
"7.6000","1.8795","1.8795","1.2530","9.3150","34.4654"
"7.6800","1.9001","1.9001","1.2667","9.4342","34.9064"
"7.7600","1.9194","1.9194","1.2796","9.5486","35.3298"
"7.8400","1.9386","1.9386","1.2924","9.6632","35.7539"
"7.9200","1.9588","1.9588","1.3058","9.7842","36.2014"
"8.0000","1.9788","1.9788","1.3192","9.9069","36.6554"
"8.0800","1.9979","1.9979","1.3320","10.0223","37.0823"
"8.1600","2.0197","2.0197","1.3465","10.1586","37.5867"
"8.2400","2.0389","2.0389","1.3593","10.2715","38.0044"
"8.3200","2.0596","2.0596","1.3731","10.3957","38.4641"
"8.4000","2.0792","2.0792","1.3861","10.5122","38.8953"
"8.4800","2.0982","2.0982","1.3988","10.6278","39.3228"
"8.5600","2.1191","2.1191","1.4127","10.7532","39.7868"
"8.6400","2.1392","2.1392","1.4261","10.8725","40.2282"
"8.7200","2.1592","2.1592","1.4395","10.9948","40.6808"
"8.8000","2.1798","2.1798","1.4532","11.1188","41.1395"
"8.8800","2.1992","2.1992","1.4661","11.2332","41.5630"
"8.9600","2.2203","2.2203","1.4802","11.3638","42.0459"
"9.0400","2.2395","2.2395","1.4930","11.4796","42.4745"
"9.1200","2.2580","2.2580","1.5053","11.5901","42.8832"
"9.2000","2.2787","2.2787","1.5191","11.7163","43.3503"
"9.2800","2.2981","2.2981","1.5321","11.8332","43.7829"
"9.3600","2.3195","2.3195","1.5463","11.9638","44.2660"
"9.4400","2.3401","2.3401","1.5600","12.0878","44.7247"
"9.5200","2.3594","2.3594","1.5729","12.2049","45.1581"
"9.6000","2.3787","2.3787","1.5858","12.3220","45.5914"
"9.6800","2.3987","2.3987","1.5991","12.4419","46.0350"
"9.7600","2.4184","2.4184","1.6123","12.5612","46.4764"
"9.8400","2.4398","2.4398","1.6265","12.6933","46.9654"
"9.9200","2.4578","2.4578","1.6386","12.7957","47.3443"
"10.0000","2.4795","2.4795","1.6530","12.9313","47.8457"
"10.0800","2.4999","2.4999","1.6666","13.0535","48.2980"
"10.1600","2.5199","2.5199","1.6799","13.1744","48.7453"
"10.2400","2.5391","2.5391","1.6927","13.2888","49.1686"
"10.3200","2.5586","2.5586","1.7057","13.4052","49.5993"
"10.4000","2.5786","2.5786","1.7191","13.5240","50.0388"
"10.4800","2.5991","2.5991","1.7328","13.6513","50.5100"
"10.5600","2.6180","2.6180","1.7453","13.7648","50.9299"
"10.6400","2.6394","2.6394","1.7596","13.8958","51.4146"
"10.7200","2.6594","2.6594","1.7729","14.0159","51.8588"
"10.8000","2.6795","2.6795","1.7863","14.1381","52.3111"
"10.8800","2.6995","2.6995","1.7997","14.2583","52.7557"
"10.9600","2.7185","2.7185","1.8123","14.3702","53.1698"
"11.0400","2.7392","2.7392","1.8261","14.4950","53.6314"
"11.1200","2.7591","2.7591","1.8394","14.6140","54.0717"
"11.2000","2.7784","2.7784","1.8522","14.7360","54.5232"
"11.2800","2.7997","2.7997","1.8665","14.8720","55.0263"
"11.3600","2.8200","2.8200","1.8800","14.9901","55.4634"
"11.4400","2.8399","2.8399","1.8933","15.1086","55.9020"
"11.5200","2.8598","2.8598","1.9065","15.2269","56.3395"
"11.6000","2.8779","2.8779","1.9186","15.3311","56.7251"
"11.6800","2.8990","2.8990","1.9327","15.4598","57.2011"
"11.7600","2.9186","2.9186","1.9458","15.5788","57.6417"
"11.8400","2.9389","2.9389","1.9593","15.7008","58.0930"
"11.9200","2.9592","2.9592","1.9728","15.8229","58.5449"
"12.0000","2.9788","2.9788","1.9859","15.9408","58.9811"
"12.0800","2.9994","2.9994","1.9996","16.0630","59.4329"
"12.1600","3.0201","3.0201","2.0134","16.1861","59.8885"
"12.2400","3.0385","3.0385","2.0257","16.2968","60.2980"
"12.3200","3.0591","3.0591","2.0394","16.4193","60.7516"
"12.4000","3.0781","3.0781","2.0520","16.5276","61.1522"
"12.4800","3.0986","3.0986","2.0657","16.6488","61.6007"
"12.5600","3.1206","3.1206","2.0804","16.7832","62.0979"
"12.6400","3.1399","3.1399","2.0933","16.8977","62.5216"
"12.7200","3.1593","3.1593","2.1062","17.0092","62.9342"
"12.8000","3.1788","3.1788","2.1192","17.1271","63.3701"
"12.8800","3.1985","3.1985","2.1323","17.2422","63.7960"
"12.9600","3.2189","3.2189","2.1460","17.3632","64.2438"
"13.0400","3.2380","3.2380","2.1586","17.4728","64.6494"
"13.1200","3.2590","3.2590","2.1727","17.5989","65.1160"
"13.2000","3.2798","3.2798","2.1865","17.7214","65.5691"
"13.2800","3.2989","3.2989","2.1993","17.8349","65.9891"
"13.3600","3.3195","3.3195","2.2130","17.9576","66.4430"
"13.4400","3.3385","3.3385","2.2257","18.0655","66.8425"
"13.5200","3.3593","3.3593","2.2395","18.1951","67.3220"
"13.6000","3.3789","3.3789","2.2526","18.3097","67.7459"
"13.6800","3.3985","3.3985","2.2656","18.4246","68.1709"
"13.7600","3.4197","3.4197","2.2798","18.5521","68.6429"
"13.8400","3.4400","3.4400","2.2934","18.6689","69.0748"
"13.9200","3.4596","3.4596","2.3064","18.7822","69.4943"
"14.0000","3.4789","3.4789","2.3193","18.8976","69.9210"
"14.0800","3.4982","3.4982","2.3321","19.0058","70.3213"
"14.1600","3.5194","3.5194","2.3463","19.1314","70.7863"
"14.2400","3.5391","3.5391","2.3594","19.2445","71.2046"
"14.3200","3.5580","3.5580","2.3720","19.3554","71.6151"
"14.4000","3.5786","3.5786","2.3857","19.4757","72.0600"
"14.4800","3.5994","3.5994","2.3996","19.5951","72.5019"
"14.5600","3.6196","3.6196","2.4131","19.7114","72.9321"
"14.6400","3.6397","3.6397","2.4264","19.8254","73.3540"
"14.7200","3.6582","3.6582","2.4388","19.9306","73.7431"
"14.8000","3.6786","3.6786","2.4524","20.0489","74.1810"
"14.8800","3.6989","3.6989","2.4660","20.1674","74.6194"
"14.9600","3.7191","3.7191","2.4794","20.2834","75.0485"
"15.0400","3.7398","3.7398","2.4932","20.4031","75.4915"
"15.1200","3.7595","3.7595","2.5063","20.5121","75.8949"
"15.2000","3.7797","3.7797","2.5198","20.6243","76.3098"
"15.2800","3.7993","3.7993","2.5328","20.7394","76.7356"
"15.3600","3.8185","3.8185","2.5457","20.8463","77.1312"
"15.4400","3.8389","3.8389","2.5593","20.9682","77.5822"
"15.5200","3.8583","3.8583","2.5722","21.0747","77.9763"
"15.6000","3.8782","3.8782","2.5855","21.1895","78.4010"
"15.6800","3.9001","3.9001","2.6001","21.3163","78.8702"
"15.7600","3.9193","3.9193","2.6128","21.4263","79.2775"
"15.8400","3.9399","3.9399","2.6266","21.5412","79.7026"
"15.9200","3.9586","3.9586","2.6391","21.6456","80.0889"
"16.0000","3.9782","3.9782","2.6521","21.7552","80.4941"
"16.0800","3.9987","3.9987","2.6658","21.8723","80.9275"
"16.1600","4.0191","4.0191","2.6794","21.9889","81.3591"
"16.2400","4.0393","4.0393","2.6929","22.1002","81.7708"
"16.3200","4.0601","4.0601","2.7067","22.2213","82.2187"
"16.4000","4.0792","4.0792","2.7195","22.3301","82.6214"
"16.4800","4.0993","4.0993","2.7328","22.4414","83.0331"
"16.5600","4.1188","4.1188","2.7459","22.5499","83.4345"
"16.6400","4.1391","4.1391","2.7594","22.6652","83.8613"
"16.7200","4.1589","4.1589","2.7726","22.7748","84.2669"
"16.8000","4.1776","4.1776","2.7851","22.8766","84.6432"
"16.8800","4.1990","4.1990","2.7993","22.9939","85.0776"
"16.9600","4.2200","4.2200","2.8133","23.1146","85.5242"
"17.0400","4.2394","4.2394","2.8263","23.2239","85.9284"
"17.1200","4.2591","4.2591","2.8394","23.3302","86.3218"
"17.2000","4.2783","4.2783","2.8522","23.4339","86.7054"
"17.2800","4.2990","4.2990","2.8660","23.5500","87.1350"
"17.3600","4.3196","4.3196","2.8797","23.6613","87.5467"
"17.4400","4.3384","4.3384","2.8923","23.7657","87.9330"
"17.5200","4.3594","4.3594","2.9062","23.8800","88.3559"
"17.6000","4.3792","4.3792","2.9195","23.9884","88.7572"
"17.6800","4.3999","4.3999","2.9333","24.1027","89.1800"
"17.7600","4.4193","4.4193","2.9462","24.2078","89.5687"
"17.8400","4.4385","4.4385","2.9590","24.3096","89.9456"
"17.9200","4.4589","4.4589","2.9726","24.4232","90.3659"
"18.0000","4.4785","4.4785","2.9857","24.5288","90.7566"
"18.0800","4.4978","4.4978","2.9985","24.6350","91.1493"
"18.1600","4.5193","4.5193","3.0129","24.7540","91.5897"
"18.2400","4.5391","4.5391","3.0261","24.8583","91.9758"
"18.3200","4.5595","4.5595","3.0397","24.9696","92.3876"
"18.4000","4.5792","4.5792","3.0528","25.0726","92.7685"
"18.4800","4.5980","4.5980","3.0654","25.1756","93.1499"
"18.5600","4.6189","4.6189","3.0793","25.2894","93.5708"
"18.6400","4.6389","4.6389","3.0926","25.3944","93.9594"
"18.7200","4.6592","4.6592","3.1061","25.5073","94.3771"
"18.8000","4.6798","4.6798","3.1199","25.6175","94.7849"
"18.8800","4.6997","4.6997","3.1331","25.7220","95.1713"
"18.9600","4.7200","4.7200","3.1466","25.8314","95.5762"
"19.0400","4.7393","4.7393","3.1595","25.9292","95.9379"
"19.1200","4.7583","4.7583","3.1722","26.0308","96.3138"
"19.2000","4.7788","4.7788","3.1859","26.1411","96.7221"
"19.2800","4.7980","4.7980","3.1987","26.2404","97.0895"
"19.3600","4.8193","4.8193","3.2129","26.3548","97.5127"
"19.4400","4.8402","4.8402","3.2268","26.4667","97.9269"
"19.5200","4.8592","4.8592","3.2395","26.5622","98.2801"
"19.6000","4.8788","4.8788","3.2525","26.6677","98.6703"
"19.6800","4.8988","4.8988","3.2659","26.7726","99.0585"
"19.7600","4.9187","4.9187","3.2792","26.8744","99.4354"
"19.8400","4.9394","4.9394","3.2929","26.9855","99.8463"
"19.9200","4.9580","4.9580","3.3053","27.0806","100.1981"
"20.0000","4.9795","4.9795","3.3197","27.1949","100.6212"
"20.0800","4.9997","4.9997","3.3332","27.3033","101.0221"
"20.1600","5.0197","5.0197","3.3465","27.4062","101.4031"
"20.2400","5.0394","5.0394","3.3596","27.5066","101.7743"
"20.3200","5.0586","5.0586","3.3724","27.6057","102.1412"
"20.4000","5.0783","5.0783","3.3855","27.7039","102.5044"
"20.4800","5.0993","5.0993","3.3995","27.8125","102.9061"
"20.5600","5.1180","5.1180","3.4120","27.9091","103.2637"
"20.6400","5.1393","5.1393","3.4262","28.0208","103.6771"
"20.7200","5.1594","5.1594","3.4396","28.1268","104.0693"
"20.8000","5.1797","5.1797","3.4531","28.2307","104.4536"
"20.8800","5.1995","5.1995","3.4663","28.3304","104.8223"
"20.9600","5.2185","5.2185","3.4790","28.4326","105.2004"
"21.0400","5.2391","5.2391","3.4928","28.5356","105.5819"
"21.1200","5.2591","5.2591","3.5061","28.6354","105.9508"
"21.2000","5.2784","5.2784","3.5189","28.7345","106.3176"
"21.2800","5.2996","5.2996","3.5330","28.8466","106.7326"
"21.3600","5.3201","5.3201","3.5467","28.9504","107.1166"
"21.4400","5.3399","5.3399","3.5599","29.0478","107.4770"
"21.5200","5.3597","5.3597","3.5731","29.1450","107.8366"
"21.6000","5.3779","5.3779","3.5853","29.2391","108.1847"
"21.6800","5.3989","5.3989","3.5993","29.3465","108.5820"
"21.7600","5.4183","5.4183","3.6122","29.4414","108.9333"
"21.8400","5.4388","5.4388","3.6259","29.5486","109.3299"
"21.9200","5.4590","5.4590","3.6393","29.6476","109.6962"
"22.0000","5.4792","5.4792","3.6528","29.7474","110.0655"
"22.0800","5.4993","5.4993","3.6662","29.8480","110.4374"
"22.1600","5.5199","5.5199","3.6799","29.9552","110.8341"
"22.2400","5.5388","5.5388","3.6925","30.0485","111.1795"
"22.3200","5.5587","5.5587","3.7058","30.1478","111.5470"
"22.4000","5.5779","5.5779","3.7186","30.2389","111.8839"
"22.4800","5.5994","5.5994","3.7329","30.3491","112.2916"
"22.5600","5.6206","5.6206","3.7471","30.4549","112.6831"
"22.6400","5.6398","5.6398","3.7599","30.5479","113.0271"
"22.7200","5.6594","5.6594","3.7730","30.6450","113.3865"
"22.8000","5.6786","5.6786","3.7857","30.7351","113.7199"
"22.8800","5.6983","5.6983","3.7989","30.8326","114.0808"
"22.9600","5.7194","5.7194","3.8129","30.9388","114.4734"
"23.0400","5.7382","5.7382","3.8255","31.0238","114.7881"
"23.1200","5.7590","5.7590","3.8393","31.1289","115.1769"
"23.2000","5.7796","5.7796","3.8531","31.2295","115.5490"
"23.2800","5.7989","5.7989","3.8659","31.3229","115.8947"
"23.3600","5.8196","5.8196","3.8797","31.4257","116.2750"
"23.4400","5.8388","5.8388","3.8925","31.5128","116.5972"
"23.5200","5.8589","5.8589","3.9059","31.6100","116.9569"
"23.6000","5.8788","5.8788","3.9192","31.7073","117.3169"
"23.6800","5.8986","5.8986","3.9324","31.8054","117.6800"
"23.7600","5.9197","5.9197","3.9465","31.9114","118.0723"
"23.8400","5.9404","5.9404","3.9603","32.0128","118.4473"
"23.9200","5.9596","5.9596","3.9731","32.0997","118.7690"
"24.0000","5.9792","5.9792","3.9861","32.1939","119.1174"
"24.0800","5.9983","5.9983","3.9989","32.2822","119.4442"
"24.1600","6.0194","6.0194","4.0129","32.3824","119.8149"
"24.2400","6.0388","6.0388","4.0259","32.4730","120.1500"
"24.3200","6.0575","6.0575","4.0383","32.5623","120.4805"
"24.4000","6.0787","6.0787","4.0525","32.6634","120.8547"
"24.4800","6.0996","6.0996","4.0664","32.7639","121.2264"
"24.5600","6.1197","6.1197","4.0798","32.8585","121.5766"
"24.6400","6.1398","6.1398","4.0932","32.9538","121.9290"
"24.7200","6.1583","6.1583","4.1055","33.0360","122.2331"
"24.8000","6.1786","6.1786","4.1190","33.1332","122.5929"
"24.8800","6.1986","6.1986","4.1324","33.2249","122.9319"
"24.9600","6.2190","6.2190","4.1460","33.3240","123.2989"
"25.0400","6.2403","6.2403","4.1602","33.4253","123.6736"
"25.1200","6.2596","6.2596","4.1731","33.5125","123.9964"
"25.2000","6.2795","6.2795","4.1863","33.6037","124.3339"
"25.2800","6.2993","6.2993","4.1995","33.6954","124.6731"
"25.3600","6.3190","6.3190","4.2127","33.7913","125.0278"
"25.4400","6.3386","6.3386","4.2257","33.8799","125.3555"
"25.5200","6.3580","6.3580","4.2387","33.9665","125.6762"
"25.6000","6.3785","6.3785","4.2524","34.0621","126.0297"
"25.6800","6.3999","6.3999","4.2666","34.1610","126.3957"
"25.7600","6.4189","6.4189","4.2793","34.2482","126.7183"
"25.8400","6.4398","6.4398","4.2932","34.3462","127.0811"
"25.9200","6.4590","6.4590","4.3060","34.4295","127.3890"
"26.0000","6.4783","6.4783","4.3188","34.5157","127.7082"
"26.0800","6.4982","6.4982","4.3321","34.6091","128.0536"
"26.1600","6.5185","6.5185","4.3457","34.7035","128.4030"
"26.2400","6.5396","6.5396","4.3597","34.7986","128.7548"
"26.3200","6.5604","6.5604","4.3736","34.8929","129.1037"
"26.4000","6.5790","6.5790","4.3860","34.9728","129.3994"
"26.4800","6.5995","6.5995","4.3997","35.0681","129.7520"
"26.5600","6.6189","6.6189","4.4126","35.1519","130.0622"
"26.6400","6.6390","6.6390","4.4260","35.2427","130.3980"
"26.7200","6.6587","6.6587","4.4392","35.3315","130.7265"
"26.8000","6.6778","6.6778","4.4519","35.4148","131.0349"
"26.8800","6.6992","6.6992","4.4661","35.5165","131.4112"
"26.9600","6.7199","6.7199","4.4799","35.6082","131.7504"
"27.0400","6.7392","6.7392","4.4928","35.6922","132.0611"
"27.1200","6.7594","6.7594","4.5062","35.7803","132.3870"
"27.2000","6.7782","6.7782","4.5188","35.8590","132.6784"
"27.2800","6.7990","6.7990","4.5327","35.9525","133.0244"
"27.3600","6.8197","6.8197","4.5465","36.0470","133.3740"
"27.4400","6.8387","6.8387","4.5591","36.1297","133.6798"
"27.5200","6.8595","6.8595","4.5730","36.2240","134.0289"
"27.6000","6.8791","6.8791","4.5861","36.3094","134.3449"
"27.6800","6.8999","6.8999","4.5999","36.3976","134.6712"
"27.7600","6.9198","6.9198","4.6132","36.4912","135.0174"
"27.8400","6.9386","6.9386","4.6257","36.5630","135.2831"
"27.9200","6.9582","6.9582","4.6388","36.6478","135.5970"
"28.0000","6.9790","6.9790","4.6526","36.7360","135.9233"
"28.0800","6.9978","6.9978","4.6652","36.8170","136.2230"
"28.1600","7.0195","7.0195","4.6797","36.9148","136.5847"
"28.2400","7.0391","7.0391","4.6927","36.9981","136.8929"
"28.3200","7.0600","7.0600","4.7067","37.0869","137.2216"
"28.4000","7.0792","7.0792","4.7195","37.1669","137.5176"
"28.4800","7.0983","7.0983","4.7322","37.2507","137.8276"
"28.5600","7.1190","7.1190","4.7460","37.3411","138.1620"
"28.6400","7.1389","7.1389","4.7592","37.4226","138.4636"
"28.7200","7.1589","7.1589","4.7726","37.5101","138.7873"
"28.8000","7.1801","7.1801","4.7867","37.6008","139.1231"
"28.8800","7.1997","7.1997","4.7998","37.6842","139.4316"
"28.9600","7.2197","7.2197","4.8131","37.7667","139.7368"
"29.0400","7.2390","7.2390","4.8260","37.8473","140.0351"
"29.1200","7.2581","7.2581","4.8388","37.9280","140.3337"
"29.2000","7.2791","7.2791","4.8528","38.0215","140.6796"
"29.2800","7.2980","7.2980","4.8654","38.0938","140.9471"
"29.3600","7.3190","7.3190","4.8793","38.1838","141.2800"
"29.4400","7.3401","7.3401","4.8934","38.2728","141.6095"
"29.5200","7.3597","7.3597","4.9064","38.3545","141.9116"
"29.6000","7.3788","7.3788","4.9192","38.4342","142.2066"
"29.6800","7.3989","7.3989","4.9326","38.5143","142.5029"
"29.7600","7.4191","7.4191","4.9461","38.6009","142.8234"
"29.8400","7.4396","7.4396","4.9597","38.6841","143.1313"
"29.9200","7.4580","7.4580","4.9720","38.7564","143.3986"
"30.0000","7.4793","7.4793","4.9862","38.8458","143.7295"
"30.0800","7.4996","7.4996","4.9998","38.9308","144.0439"
"30.1600","7.5201","7.5201","5.0134","39.0181","144.3671"
"30.2400","7.5392","7.5392","5.0261","39.0907","144.6354"
"30.3200","7.5584","7.5584","5.0389","39.1646","144.9088"
"30.4000","7.5782","7.5782","5.0521","39.2457","145.2092"
"30.4800","7.5994","7.5994","5.0663","39.3347","145.5382"
"30.5600","7.6181","7.6181","5.0787","39.4087","145.8120"
"30.6400","7.6396","7.6396","5.0930","39.5006","146.1522"
"30.7200","7.6593","7.6593","5.1062","39.5783","146.4396"
"30.8000","7.6792","7.6792","5.1195","39.6576","146.7331"
"30.8800","7.6997","7.6997","5.1331","39.7410","147.0417"
"30.9600","7.7185","7.7185","5.1457","39.8115","147.3025"
"31.0400","7.7391","7.7391","5.1594","39.8951","147.6117"
"31.1200","7.7587","7.7587","5.1725","39.9723","147.8974"
"31.2000","7.7784","7.7784","5.1856","40.0523","148.1934"
"31.2800","7.7997","7.7997","5.1998","40.1415","148.5237"
"31.3600","7.8200","7.8200","5.2134","40.2202","148.8146"
"31.4400","7.8397","7.8397","5.2265","40.2944","149.0894"
"31.5200","7.8595","7.8595","5.2397","40.3746","149.3862"
"31.6000","7.8780","7.8780","5.2520","40.4422","149.6361"
"31.6800","7.8988","7.8988","5.2659","40.5247","149.9414"
"31.7600","7.9185","7.9185","5.2790","40.6020","150.2275"
"31.8400","7.9389","7.9389","5.2926","40.6817","150.5222"
"31.9200","7.9589","7.9589","5.3059","40.7620","150.8195"
"32.0000","7.9792","7.9792","5.3194","40.8386","151.1027"
"32.0800","7.9993","7.9993","5.3329","40.9166","151.3915"
"32.1600","8.0198","8.0198","5.3465","40.9960","151.6853"
"32.2400","8.0387","8.0387","5.3591","41.0690","151.9553"
"32.3200","8.0588","8.0588","5.3725","41.1446","152.2352"
"32.4000","8.0778","8.0778","5.3852","41.2115","152.4824"
"32.4800","8.0993","8.0993","5.3996","41.2988","152.8056"
"32.5600","8.1207","8.1207","5.4138","41.3832","153.1177"
"32.6400","8.1399","8.1399","5.4266","41.4529","153.3757"
"32.7200","8.1592","8.1592","5.4395","41.5232","153.6357"
"32.8000","8.1782","8.1782","5.4522","41.5923","153.8916"
"32.8800","8.1986","8.1986","5.4657","41.6704","154.1806"
"32.9600","8.2192","8.2192","5.4795","41.7458","154.4594"
"33.0400","8.2380","8.2380","5.4920","41.8120","154.7043"
"33.1200","8.2591","8.2591","5.5060","41.8942","155.0086"
"33.2000","8.2799","8.2799","5.5199","41.9707","155.2914"
"33.2800","8.2990","8.2990","5.5326","42.0428","155.5582"
"33.3600","8.3200","8.3200","5.5466","42.1238","155.8581"
"33.4400","8.3387","8.3387","5.5591","42.1898","156.1021"
"33.5200","8.3593","8.3593","5.5728","42.2649","156.3803"
"33.6000","8.3791","8.3791","5.5860","42.3350","156.6394"
"33.6800","8.3984","8.3984","5.5989","42.4021","156.8879"
"33.7600","8.4194","8.4194","5.6130","42.4818","157.1827"
"33.8400","8.4403","8.4403","5.6269","42.5569","157.4605"
"33.9200","8.4593","8.4593","5.6395","42.6207","157.6966"
"34.0000","8.4795","8.4795","5.6530","42.6935","157.9659"
"34.0800","8.4983","8.4983","5.6655","42.7542","158.1907"
"34.1600","8.5195","8.5195","5.6797","42.8318","158.4778"
"34.2400","8.5389","8.5389","5.6926","42.8963","158.7163"
"34.3200","8.5579","8.5579","5.7053","42.9618","158.9585"
"34.4000","8.5784","8.5784","5.7189","43.0322","159.2192"
"34.4800","8.5994","8.5994","5.7329","43.1073","159.4970"
"34.5600","8.6198","8.6198","5.7465","43.1785","159.7604"
"34.6400","8.6399","8.6399","5.7599","43.2435","160.0011"
"34.7200","8.6580","8.6580","5.7720","43.2992","160.2070"
"34.8000","8.6786","8.6786","5.7857","43.3701","160.4695"
"34.8800","8.6987","8.6987","5.7991","43.4369","160.7166"
"34.9600","8.7193","8.7193","5.8129","43.5098","160.9864"
"35.0400","8.7404","8.7404","5.8269","43.5805","161.2478"
"35.1200","8.7595","8.7595","5.8397","43.6387","161.4634"
"35.2000","8.7795","8.7795","5.8530","43.7020","161.6975"
"35.2800","8.7993","8.7993","5.8662","43.7657","161.9333"
"35.3600","8.8190","8.8190","5.8793","43.8307","162.1737"
"35.4400","8.8390","8.8390","5.8927","43.8935","162.4061"
"35.5200","8.8584","8.8584","5.9056","43.9496","162.6135"
"35.6000","8.8784","8.8784","5.9189","44.0114","162.8423"
"35.6800","8.8997","8.8997","5.9331","44.0817","163.1023"
"35.7600","8.9189","8.9189","5.9459","44.1381","163.3111"
"35.8400","8.9394","8.9394","5.9596","44.1993","163.5374"
"35.9200","8.9590","8.9590","5.9727","44.2556","163.7457"
"36.0000","8.9790","8.9790","5.9860","44.3168","163.9722"
"36.0800","8.9985","8.9985","5.9990","44.3704","164.1704"
"36.1600","9.0186","9.0186","6.0124","44.4302","164.3916"
"36.2400","9.0395","9.0395","6.0263","44.4909","164.6162"
"36.3200","9.0602","9.0602","6.0402","44.5512","164.8394"
"36.4000","9.0789","9.0789","6.0526","44.6014","165.0252"
"36.4800","9.0996","9.0996","6.0664","44.6605","165.2438"
"36.5600","9.1188","9.1188","6.0792","44.7099","165.4268"
"36.6400","9.1391","9.1391","6.0927","44.7636","165.6254"
"36.7200","9.1589","9.1589","6.1059","44.8145","165.8136"
"36.8000","9.1776","9.1776","6.1184","44.8579","165.9741"
"36.8800","9.1990","9.1990","6.1327","44.9203","166.2050"
"36.9600","9.2202","9.2202","6.1468","44.9764","166.4125"
"37.0400","9.2393","9.2393","6.1596","45.0169","166.5625"
"37.1200","9.2591","9.2591","6.1727","45.0657","166.7432"
"37.2000","9.2781","9.2781","6.1854","45.1065","166.8942"
"37.2800","9.2989","9.2989","6.1993","45.1602","167.0926"
"37.3600","9.3195","9.3195","6.2130","45.2044","167.2565"
"37.4400","9.3387","9.3387","6.2258","45.2478","167.4170"
"37.5200","9.3597","9.3597","6.2398","45.2939","167.5874"
"37.6000","9.3792","9.3792","6.2528","45.3310","167.7248"
"37.6800","9.3995","9.3995","6.2664","45.3734","167.8815"
"37.7600","9.4192","9.4192","6.2795","45.4120","168.0242"
"37.8400","9.4389","9.4389","6.2926","45.4495","168.1632"
"37.9200","9.4588","9.4588","6.3058","45.4874","168.3033"
"38.0000","9.4790","9.4790","6.3194","45.5229","168.4349"
"38.0800","9.4976","9.4976","6.3318","45.5529","168.5456"
"38.1600","9.5194","9.5194","6.3463","45.5968","168.7081"
"38.2400","9.5392","9.5392","6.3595","45.6236","168.8073"
"38.3200","9.5599","9.5599","6.3732","45.6605","168.9438"
"38.4000","9.5793","9.5793","6.3862","45.6866","169.0404"
"38.4800","9.5985","9.5985","6.3990","45.7111","169.1310"
"38.5600","9.6188","9.6188","6.4125","45.7405","169.2398"
"38.6400","9.6389","9.6389","6.4259","45.7657","169.3330"
"38.7200","9.6592","9.6592","6.4394","45.7909","169.4264"
"38.8000","9.6801","9.6801","6.4534","45.8194","169.5318"
"38.8800","9.6994","9.6994","6.4663","45.8363","169.5943"
"38.9600","9.7197","9.7197","6.4798","45.8581","169.6750"
"39.0400","9.7393","9.7393","6.4929","45.8710","169.7229"
"39.1200","9.7581","9.7581","6.5054","45.8819","169.7631"
"39.2000","9.7788","9.7788","6.5192","45.9050","169.8486"
"39.2800","9.7979","9.7979","6.5319","45.9164","169.8906"
"39.3600","9.8192","9.8192","6.5462","45.9338","169.9552"
"39.4400","9.8402","9.8402","6.5601","45.9493","170.0125"
"39.5200","9.8594","9.8594","6.5729","45.9554","170.0349"
"39.6000","9.8787","9.8787","6.5858","45.9583","170.0457"
"39.6800","9.8983","9.8983","6.5989","45.9638","170.0660"
"39.7600","9.9185","9.9185","6.6123","45.9734","170.1016"
"39.8400","9.9400","9.9400","6.6267","45.9836","170.1393"
"39.9200","9.9581","9.9581","6.6387","45.9769","170.1145"
"40.0000","9.9797","9.9797","6.6532","45.9845","170.1428"
"40.0800","10.0000","10.0000","6.6667","45.9880","170.1555"
"40.1600","10.0201","10.0201","6.6800","45.9875","170.1537"
"40.2400","10.0391","10.0391","6.6927","45.9823","170.1346"
"40.3200","10.0585","10.0585","6.7057","45.9739","170.1034"
"40.4000","10.0785","10.0785","6.7190","45.9684","170.0829"
"40.4800","10.0993","10.0993","6.7328","45.9655","170.0722"
"40.5600","10.1176","10.1176","6.7451","45.9502","170.0158"
"40.6400","10.1392","10.1392","6.7594","45.9520","170.0224"
"40.7200","10.1597","10.1597","6.7732","45.9451","169.9971"
"40.8000","10.1800","10.1800","6.7867","45.9372","169.9677"
"40.8800","10.1991","10.1991","6.7994","45.9212","169.9084"
"40.9600","10.2184","10.2184","6.8122","45.9048","169.8477"
"41.0400","10.2392","10.2392","6.8261","45.8940","169.8077"
"41.1200","10.2590","10.2590","6.8394","45.8780","169.7488"
"41.2000","10.2785","10.2785","6.8524","45.8633","169.6944"
"41.2800","10.2996","10.2996","6.8664","45.8521","169.6528"
"41.3600","10.3200","10.3200","6.8800","45.8325","169.5802"
"41.4400","10.3398","10.3398","6.8932","45.8153","169.5165"
"41.5200","10.3597","10.3597","6.9064","45.7937","169.4365"
"41.6000","10.3776","10.3776","6.9184","45.7666","169.3365"
"41.6800","10.3990","10.3990","6.9327","45.7526","169.2845"
"41.7600","10.4184","10.4184","6.9456","45.7294","169.1990"
"41.8400","10.4389","10.4389","6.9593","45.7137","169.1408"
"41.9200","10.4588","10.4588","6.9725","45.6889","169.0488"
"42.0000","10.4794","10.4794","6.9863","45.6681","168.9719"
"42.0800","10.4994","10.4994","6.9996","45.6434","168.8805"
"42.1600","10.5197","10.5197","7.0131","45.6189","168.7899"
"42.2400","10.5389","10.5389","7.0259","45.5935","168.6958"
"42.3200","10.5590","10.5590","7.0394","45.5719","168.6162"
"42.4000","10.5775","10.5775","7.0517","45.5413","168.5029"
"42.4800","10.5995","10.5995","7.0663","45.5268","168.4491"
"42.5600","10.6207","10.6207","7.0805","45.5070","168.3757"
"42.6400","10.6399","10.6399","7.0932","45.4792","168.2730"
"42.7200","10.6592","10.6592","7.1061","45.4502","168.1657"
"42.8000","10.6790","10.6790","7.1193","45.4248","168.0719"
"42.8800","10.6987","10.6987","7.1324","45.3985","167.9746"
"42.9600","10.7187","10.7187","7.1458","45.3743","167.8851"
"43.0400","10.7382","10.7382","7.1588","45.3474","167.7852"
"43.1200","10.7587","10.7587","7.1725","45.3256","167.7045"
"43.2000","10.7797","10.7797","7.1864","45.3040","167.6249"
"43.2800","10.7988","10.7988","7.1992","45.2755","167.5193"
"43.3600","10.8197","10.8197","7.2131","45.2535","167.4381"
"43.4400","10.8384","10.8384","7.2256","45.2231","167.3255"
"43.5200","10.8592","10.8592","7.2395","45.2005","167.2420"
"43.6000","10.8791","10.8791","7.2527","45.1773","167.1559"
"43.6800","10.8987","10.8987","7.2658","45.1508","167.0582"
"43.7600","10.9195","10.9195","7.2797","45.1331","166.9925"
"43.8400","10.9404","10.9404","7.2936","45.1086","166.9020"
"43.9200","10.9591","10.9591","7.3061","45.0766","166.7834"
"44.0000","10.9794","10.9794","7.3196","45.0527","166.6951"
"44.0800","10.9984","10.9984","7.3323","45.0219","166.5811"
"44.1600","11.0196","11.0196","7.3464","45.0000","166.4998"
"44.2400","11.0388","11.0388","7.3592","44.9702","166.3899"
"44.3200","11.0580","11.0580","7.3720","44.9424","166.2870"
"44.4000","11.0783","11.0783","7.3855","44.9184","166.1982"
"44.4800","11.0995","11.0995","7.3997","44.9015","166.1355"
"44.5600","11.1203","11.1203","7.4136","44.8813","166.0610"
"44.6400","11.1400","11.1400","7.4267","44.8526","165.9545"
"44.7200","11.1580","11.1580","7.4387","44.8231","165.8456"
"44.8000","11.1785","11.1785","7.4524","44.8044","165.7764"
"44.8800","11.1988","11.1988","7.4659","44.7818","165.6927"
"44.9600","11.2193","11.2193","7.4795","44.7618","165.6188"
"45.0400","11.2406","11.2406","7.4938","44.7428","165.5483"
"45.1200","11.2596","11.2596","7.5064","44.7139","165.4415"
"45.2000","11.2795","11.2795","7.5197","44.6901","165.3534"
"45.2800","11.2992","11.2992","7.5328","44.6669","165.2675"
"45.3600","11.3189","11.3189","7.5459","44.6442","165.1834"
"45.4400","11.3385","11.3385","7.5590","44.6225","165.1033"
"45.5200","11.3578","11.3578","7.5719","44.5929","164.9938"
"45.6000","11.3783","11.3783","7.5855","44.5750","164.9275"
"45.6800","11.4004","11.4004","7.6003","44.5567","164.8596"
"45.7600","11.4188","11.4188","7.6125","44.5294","164.7587"
"45.8400","11.4400","11.4400","7.6267","44.5131","164.6986"
"45.9200","11.4590","11.4590","7.6394","44.4846","164.5932"
"46.0000","11.4783","11.4783","7.6522","44.4642","164.5174"
"46.0800","11.4982","11.4982","7.6655","44.4461","164.4505"
"46.1600","11.5189","11.5189","7.6793","44.4263","164.3774"
"46.2400","11.5394","11.5394","7.6929","44.4052","164.2991"
"46.3200","11.5601","11.5601","7.7067","44.3860","164.2282"
"46.4000","11.5789","11.5789","7.7193","44.3612","164.1366"
"46.4800","11.5996","11.5996","7.7330","44.3424","164.0669"
"46.5600","11.6190","11.6190","7.7460","44.3179","163.9761"
"46.6400","11.6393","11.6393","7.7596","44.2971","163.8991"
"46.7200","11.6589","11.6589","7.7726","44.2758","163.8205"
"46.8000","11.6777","11.6777","7.7851","44.2498","163.7244"
"46.8800","11.6990","11.6990","7.7993","44.2351","163.6699"
"46.9600","11.7202","11.7202","7.8135","44.2190","163.6101"
"47.0400","11.7398","11.7398","7.8265","44.1897","163.5017"
"47.1200","11.7591","11.7591","7.8394","44.1670","163.4178"
"47.2000","11.7782","11.7782","7.8522","44.1413","163.3226"
"47.2800","11.7987","11.7987","7.8658","44.1192","163.2410"
"47.3600","11.8195","11.8195","7.8796","44.0998","163.1694"
"47.4400","11.8385","11.8385","7.8923","44.0772","163.0858"
"47.5200","11.8597","11.8597","7.9065","44.0604","163.0234"
"47.6000","11.8793","11.8793","7.9195","44.0420","162.9554"
"47.6800","11.9000","11.9000","7.9333","44.0241","162.8893"
"47.7600","11.9194","11.9194","7.9463","44.0035","162.8128"
"47.8400","11.9387","11.9387","7.9591","43.9828","162.7363"
"47.9200","11.9589","11.9589","7.9726","43.9623","162.6605"
"48.0000","11.9786","11.9786","7.9857","43.9411","162.5822"
"48.0800","11.9974","11.9974","7.9983","43.9213","162.5090"
"48.1600","12.0197","12.0197","8.0132","43.9122","162.4750"
"48.2400","12.0395","12.0395","8.0263","43.8882","162.3864"
"48.3200","12.0600","12.0600","8.0400","43.8709","162.3222"
"48.4000","12.0793","12.0793","8.0529","43.8489","162.2410"
"48.4800","12.0987","12.0987","8.0658","43.8295","162.1693"
"48.5600","12.1188","12.1188","8.0792","43.8121","162.1047"
"48.6400","12.1390","12.1390","8.0927","43.7906","162.0251"
"48.7200","12.1591","12.1591","8.1061","43.7712","161.9534"
"48.8000","12.1799","12.1799","8.1199","43.7580","161.9048"
"48.8800","12.1993","12.1993","8.1329","43.7342","161.8167"
"48.9600","12.2199","12.2199","8.1466","43.7179","161.7564"
"49.0400","12.2399","12.2399","8.1599","43.7006","161.6923"
"49.1200","12.2579","12.2579","8.1719","43.6749","161.5973"
"49.2000","12.2784","12.2784","8.1856","43.6602","161.5429"
"49.2800","12.2977","12.2977","8.1985","43.6397","161.4668"
"49.3600","12.3194","12.3194","8.2129","43.6257","161.4149"
"49.4400","12.3402","12.3402","8.2268","43.6117","161.3632"
"49.5200","12.3596","12.3596","8.2397","43.5900","161.2829"
"49.6000","12.3787","12.3787","8.2524","43.5696","161.2075"
"49.6800","12.3985","12.3985","8.2657","43.5514","161.1403"
"49.7600","12.4186","12.4186","8.2790","43.5342","161.0767"
"49.8400","12.4399","12.4399","8.2933","43.5198","161.0233"
"49.9200","12.4582","12.4582","8.3055","43.4938","160.9272"
"50.0000","12.4797","12.4797","8.3198","43.4773","160.8659"
"50.0800","12.5000","12.5000","8.3333","43.4576","160.7932"
"50.1600","12.5196","12.5196","8.3464","43.4374","160.7183"
"50.2400","12.5392","12.5392","8.3595","43.4176","160.6452"
"50.3200","12.5588","12.5588","8.3726","43.3955","160.5635"
"50.4000","12.5787","12.5787","8.3858","43.3716","160.4751"
"50.4800","12.5991","12.5991","8.3994","43.3441","160.3731"
"50.5600","12.6180","12.6180","8.4120","43.3231","160.2956"
"50.6400","12.6391","12.6391","8.4261","43.3071","160.2363"
"50.7200","12.6592","12.6592","8.4395","43.2874","160.1634"
"50.8000","12.6797","12.6797","8.4531","43.2662","160.0849"
"50.8800","12.6998","12.6998","8.4665","43.2459","160.0097"
"50.9600","12.7183","12.7183","8.4789","43.2188","159.9095"
"51.0400","12.7390","12.7390","8.4926","43.1993","159.8374"
"51.1200","12.7592","12.7592","8.5061","43.1807","159.7688"
"51.2000","12.7786","12.7786","8.5191","43.1623","159.7005"
"51.2800","12.7996","12.7996","8.5330","43.1472","159.6446"
"51.3600","12.8200","12.8200","8.5467","43.1256","159.5646"
"51.4400","12.8401","12.8401","8.5601","43.1052","159.4892"
"51.5200","12.8595","12.8595","8.5730","43.0798","159.3952"
"51.6000","12.8778","12.8778","8.5852","43.0559","159.3069"
"51.6800","12.8993","12.8993","8.5995","43.0425","159.2574"
"51.7600","12.9186","12.9186","8.6124","43.0169","159.1626"
"51.8400","12.9389","12.9389","8.6259","42.9966","159.0875"
"51.9200","12.9591","12.9591","8.6394","42.9763","159.0125"
"52.0000","12.9794","12.9794","8.6529","42.9566","158.9396"
"52.0800","12.9991","12.9991","8.6661","42.9347","158.8585"
"52.1600","13.0195","13.0195","8.6796","42.9136","158.7802"
"52.2400","13.0385","13.0385","8.6923","42.8936","158.7063"
"52.3200","13.0592","13.0592","8.7061","42.8722","158.6272"
"52.4000","13.0784","13.0784","8.7189","42.8466","158.5323"
"52.4800","13.0991","13.0991","8.7328","42.8273","158.4611"
"52.5600","13.1204","13.1204","8.7469","42.8097","158.3958"
"52.6400","13.1401","13.1401","8.7601","42.7933","158.3353"
"52.7200","13.1594","13.1594","8.7729","42.7671","158.2383"
"52.8000","13.1790","13.1790","8.7860","42.7469","158.1635"
"52.8800","13.1985","13.1985","8.7990","42.7255","158.0842"
"52.9600","13.2186","13.2186","8.8124","42.7048","158.0079"
"53.0400","13.2380","13.2380","8.8253","42.6805","157.9177"
"53.1200","13.2587","13.2587","8.8391","42.6634","157.8544"
"53.2000","13.2796","13.2796","8.8530","42.6415","157.7737"
"53.2800","13.2991","13.2991","8.8661","42.6206","157.6961"
"53.3600","13.3194","13.3194","8.8796","42.5988","157.6155"
"53.4400","13.3384","13.3384","8.8922","42.5726","157.5185"
"53.5200","13.3594","13.3594","8.9063","42.5558","157.4563"
"53.6000","13.3794","13.3794","8.9196","42.5320","157.3682"
"53.6800","13.3987","13.3987","8.9325","42.5079","157.2793"
"53.7600","13.4195","13.4195","8.9463","42.4888","157.2085"
"53.8400","13.4402","13.4402","8.9601","42.4652","157.1211"
"53.9200","13.4591","13.4591","8.9727","42.4377","157.0194"
"54.0000","13.4794","13.4794","8.9862","42.4178","156.9459"
"54.0800","13.4983","13.4983","8.9989","42.3917","156.8491"
"54.1600","13.5197","13.5197","9.0131","42.3713","156.7740"
"54.2400","13.5391","13.5391","9.0261","42.3490","156.6911"
"54.3200","13.5578","13.5578","9.0386","42.3207","156.5866"
"54.4000","13.5786","13.5786","9.0524","42.3085","156.5414"
"54.4800","13.5997","13.5997","9.0665","42.2897","156.4719"
"54.5600","13.6196","13.6196","9.0797","42.2672","156.3885"
"54.6400","13.6399","13.6399","9.0933","42.2473","156.3151"
"54.7200","13.6582","13.6582","9.1055","42.2182","156.2074"
"54.8000","13.6785","13.6785","9.1190","42.2009","156.1433"
"54.8800","13.6989","13.6989","9.1326","42.1880","156.0957"
"54.9600","13.7195","13.7195","9.1463","42.1727","156.0388"
"55.0400","13.7401","13.7401","9.1601","42.1582","155.9854"
"55.1200","13.7595","13.7595","9.1730","42.1356","155.9016"
"55.2000","13.7796","13.7796","9.1864","42.1190","155.8404"
"55.2800","13.7994","13.7994","9.1996","42.0995","155.7682"
"55.3600","13.8188","13.8188","9.2125","42.0825","155.7053"
"55.4400","13.8389","13.8389","9.2259","42.0666","155.6463"
"55.5200","13.8583","13.8583","9.2389","42.0453","155.5676"
"55.6000","13.8783","13.8783","9.2522","42.0314","155.5162"
"55.6800","13.9000","13.9000","9.2666","42.0200","155.4741"
"55.7600","13.9194","13.9194","9.2796","42.0021","155.4079"
"55.8400","13.9399","13.9399","9.2933","41.9871","155.3522"
"55.9200","13.9585","13.9585","9.3057","41.9630","155.2630"
"56.0000","13.9781","13.9781","9.3187","41.9472","155.2046"
"56.0800","13.9993","13.9993","9.3329","41.9354","155.1608"
"56.1600","14.0188","14.0188","9.3458","41.9167","155.0917"
"56.2400","14.0395","14.0395","9.3596","41.9004","155.0315"
"56.3200","14.0601","14.0601","9.3734","41.8872","154.9827"
"56.4000","14.0790","14.0790","9.3860","41.8709","154.9223"
"56.4800","14.0993","14.0993","9.3995","41.8581","154.8751"
"56.5600","14.1191","14.1191","9.4127","41.8382","154.8014"
"56.6400","14.1392","14.1392","9.4261","41.8212","154.7384"
"56.7200","14.1591","14.1591","9.4394","41.7998","154.6591"
"56.8000","14.1774","14.1774","9.4516","41.7807","154.5887"
"56.8800","14.1991","14.1991","9.4660","41.7676","154.5400"
"56.9600","14.2199","14.2199","9.4799","41.7512","154.4795"
"57.0400","14.2393","14.2393","9.4929","41.7344","154.4171"
"57.1200","14.2592","14.2592","9.5061","41.7171","154.3534"
"57.2000","14.2785","14.2785","9.5190","41.6944","154.2693"
"57.2800","14.2990","14.2990","9.5327","41.6784","154.2102"
"57.3600","14.3196","14.3196","9.5464","41.6601","154.1425"
"57.4400","14.3388","14.3388","9.5592","41.6421","154.0757"
"57.5200","14.3596","14.3596","9.5731","41.6249","154.0121"
"57.6000","14.3791","14.3791","9.5861","41.6023","153.9286"
"57.6800","14.3998","14.3998","9.5998","41.5856","153.8667"
"57.7600","14.4195","14.4195","9.6130","41.5649","153.7903"
"57.8400","14.4387","14.4387","9.6258","41.5420","153.7052"
"57.9200","14.4588","14.4588","9.6392","41.5249","153.6422"
"58.0000","14.4787","14.4787","9.6524","41.4997","153.5490"
"58.0800","14.4982","14.4982","9.6654","41.4792","153.4730"
"58.1600","14.5196","14.5196","9.6798","41.4602","153.4028"
"58.2400","14.5390","14.5390","9.6927","41.4323","153.2997"
"58.3200","14.5597","14.5597","9.7065","41.4051","153.1988"
"58.4000","14.5790","14.5790","9.7193","41.3807","153.1088"
"58.4800","14.5984","14.5984","9.7323","41.3594","153.0300"
"58.5600","14.6191","14.6191","9.7461","41.3407","152.9608"
"58.6400","14.6388","14.6388","9.7592","41.3180","152.8767"
"58.7200","14.6590","14.6590","9.7727","41.2957","152.7942"
"58.8000","14.6801","14.6801","9.7867","41.2772","152.7257"
"58.8800","14.6995","14.6995","9.7997","41.2504","152.6264"
"58.9600","14.7195","14.7195","9.8130","41.2311","152.5552"
"59.0400","14.7391","14.7391","9.8261","41.2089","152.4729"
"59.1200","14.7582","14.7582","9.8388","41.1882","152.3963"
"59.2000","14.7788","14.7788","9.8525","41.1707","152.3317"
"59.2800","14.7978","14.7978","9.8652","41.1449","152.2360"
"59.3600","14.8192","14.8192","9.8794","41.1310","152.1845"
"59.4400","14.8402","14.8402","9.8934","41.1148","152.1248"
"59.5200","14.8594","14.8594","9.9062","41.0908","152.0359"
"59.6000","14.8789","14.8789","9.9193","41.0680","151.9514"
"59.6800","14.8985","14.8985","9.9323","41.0466","151.8724"
"59.7600","14.9187","14.9187","9.9458","41.0271","151.8003"
"59.8400","14.9397","14.9397","9.9598","41.0073","151.7269"
"59.9200","14.9581","14.9581","9.9721","40.9798","151.6254"
"60.0000","14.9796","14.9796","9.9864","40.9664","151.5756"
"60.0800","15.0000","15.0000","10.0000","40.9437","151.4915"
"60.0810","15.0002","15.0002","10.0001","40.9435","151.4909"