File: data/instron_tests/metamaterial_samples/510_BULK_m1.is_comp_Exports/510_BULK_m1_2_1.csv
Sample text inputs : Sample No.,Sample choice input : Leading Direction,Sample choice input : Mode,Specimen choice input : Direction,Specimen properties : Height,Specimen properties : Thickness,Specimen properties : Width,Test : Rate 1
,,,,(mm),(mm),(mm),(mm/min)
"510","Bulk","Unimode","1","150.00","25.00","150.00","15.00"

Time,Displacement,Compressive displacement,Compressive strain (Displacement),Compressive stress,Force
(s),(mm),(mm),(%),(kPa),(N)
"0.0000","0.0000","0.0000","0.0000","-0.8536","-3.1583"
"0.0800","0.0014","0.0014","0.0009","-0.8431","-3.1194"
"0.1600","0.0107","0.0107","0.0071","-0.7942","-2.9385"
"0.2400","0.0320","0.0320","0.0213","-0.7053","-2.6097"
"0.3200","0.0512","0.0512","0.0341","-0.6276","-2.3221"
"0.4000","0.0690","0.0690","0.0460","-0.5575","-2.0629"
"0.4800","0.0888","0.0888","0.0592","-0.4883","-1.8067"
"0.5600","0.1090","0.1090","0.0727","-0.4220","-1.5612"
"0.6400","0.1303","0.1303","0.0869","-0.3526","-1.3047"
"0.7200","0.1514","0.1514","0.1009","-0.2930","-1.0841"
"0.8000","0.1705","0.1705","0.1137","-0.2380","-0.8805"
"0.8800","0.1907","0.1907","0.1272","-0.1763","-0.6524"
"0.9600","0.2102","0.2102","0.1401","-0.1218","-0.4507"
"1.0400","0.2301","0.2301","0.1534","-0.0754","-0.2789"
"1.1200","0.2502","0.2502","0.1668","-0.0099","-0.0365"
"1.2000","0.2697","0.2697","0.1798","0.0432","0.1597"
"1.2800","0.2907","0.2907","0.1938","0.1120","0.4144"
"1.3600","0.3121","0.3121","0.2081","0.1822","0.6740"
"1.4400","0.3312","0.3312","0.2208","0.2420","0.8953"
"1.5200","0.3509","0.3509","0.2340","0.3036","1.1232"
"1.6000","0.3698","0.3698","0.2465","0.3594","1.3298"
"1.6800","0.3905","0.3905","0.2603","0.4349","1.6091"
"1.7600","0.4105","0.4105","0.2737","0.5054","1.8699"
"1.8400","0.4298","0.4298","0.2865","0.5694","2.1066"
"1.9200","0.4506","0.4506","0.3004","0.6470","2.3939"
"2.0000","0.4713","0.4713","0.3142","0.7204","2.6653"
"2.0800","0.4908","0.4908","0.3272","0.7913","2.9279"
"2.1600","0.5110","0.5110","0.3406","0.8680","3.2115"
"2.2400","0.5304","0.5304","0.3536","0.9353","3.4604"
"2.3200","0.5504","0.5504","0.3670","1.0146","3.7541"
"2.4000","0.5704","0.5704","0.3802","1.0924","4.0421"
"2.4800","0.5896","0.5896","0.3931","1.1665","4.3160"
"2.5600","0.6117","0.6117","0.4078","1.2629","4.6727"
"2.6400","0.6316","0.6316","0.4211","1.3367","4.9458"
"2.7200","0.6513","0.6513","0.4342","1.4168","5.2423"
"2.8000","0.6709","0.6709","0.4473","1.5020","5.5574"
"2.8800","0.6897","0.6897","0.4598","1.5771","5.8352"
"2.9600","0.7103","0.7103","0.4735","1.6658","6.1636"
"3.0400","0.7302","0.7302","0.4868","1.7524","6.4838"
"3.1200","0.7497","0.7497","0.4998","1.8421","6.8156"
"3.2000","0.7710","0.7710","0.5140","1.9348","7.1586"
"3.2800","0.7905","0.7905","0.5270","2.0172","7.4636"
"3.3600","0.8113","0.8113","0.5408","2.1140","7.8219"
"3.4400","0.8309","0.8309","0.5539","2.2022","8.1483"
"3.5200","0.8499","0.8499","0.5666","2.2867","8.4609"
"3.6000","0.8703","0.8703","0.5802","2.3851","8.8248"
"3.6800","0.8903","0.8903","0.5935","2.4786","9.1707"
"3.7600","0.9109","0.9109","0.6072","2.5778","9.5378"
"3.8400","0.9322","0.9322","0.6215","2.6781","9.9091"
"3.9200","0.9508","0.9508","0.6338","2.7638","10.2261"
"4.0000","0.9708","0.9708","0.6472","2.8621","10.5898"
"4.0800","0.9906","0.9906","0.6604","2.9600","10.9520"
"4.1600","1.0108","1.0108","0.6738","3.0614","11.3273"
"4.2400","1.0308","1.0308","0.6872","3.1536","11.6684"
"4.3200","1.0492","1.0492","0.6995","3.2434","12.0004"
"4.4000","1.0700","1.0700","0.7134","3.3520","12.4024"
"4.4800","1.0911","1.0911","0.7274","3.4615","12.8076"
"4.5600","1.1111","1.1111","0.7407","3.5611","13.1762"
"4.6400","1.1311","1.1311","0.7541","3.6613","13.5469"
"4.7200","1.1505","1.1505","0.7670","3.7578","13.9037"
"4.8000","1.1698","1.1698","0.7799","3.8564","14.2686"
"4.8800","1.1904","1.1904","0.7936","3.9575","14.6426"
"4.9600","1.2095","1.2095","0.8063","4.0549","15.0032"
"5.0400","1.2317","1.2317","0.8211","4.1716","15.4350"
"5.1200","1.2516","1.2516","0.8344","4.2735","15.8119"
"5.2000","1.2711","1.2711","0.8474","4.3697","16.1678"
"5.2800","1.2905","1.2905","0.8603","4.4688","16.5344"
"5.3600","1.3100","1.3100","0.8734","4.5704","16.9105"
"5.4400","1.3305","1.3305","0.8870","4.6763","17.3024"
"5.5200","1.3509","1.3509","0.9006","4.7801","17.6865"
"5.6000","1.3693","1.3693","0.9129","4.8789","18.0521"
"5.6800","1.3910","1.3910","0.9273","4.9953","18.4826"
"5.7600","1.4102","1.4102","0.9402","5.0964","18.8567"
"5.8400","1.4315","1.4315","0.9543","5.2112","19.2813"
"5.9200","1.4513","1.4513","0.9675","5.3144","19.6635"
"6.0000","1.4698","1.4698","0.9799","5.4162","20.0401"
"6.0800","1.4902","1.4902","0.9935","5.5280","20.4535"
"6.1600","1.5108","1.5108","1.0072","5.6390","20.8645"
"6.2400","1.5304","1.5304","1.0203","5.7450","21.2566"
"6.3200","1.5513","1.5513","1.0342","5.8635","21.6948"
"6.4000","1.5710","1.5710","1.0473","5.9684","22.0832"
"6.4800","1.5912","1.5912","1.0608","6.0812","22.5005"
"6.5600","1.6115","1.6115","1.0743","6.1932","22.9147"
"6.6400","1.6301","1.6301","1.0867","6.2960","23.2954"
"6.7200","1.6505","1.6505","1.1003","6.4099","23.7166"
"6.8000","1.6692","1.6692","1.1128","6.5122","24.0952"
"6.8800","1.6904","1.6904","1.1269","6.6307","24.5334"
"6.9600","1.7109","1.7109","1.1406","6.7444","24.9544"
"7.0400","1.7309","1.7309","1.1539","6.8573","25.3719"
"7.1200","1.7507","1.7507","1.1671","6.9677","25.7805"
"7.2000","1.7707","1.7707","1.1805","7.0773","26.1861"
"7.2800","1.7895","1.7895","1.1930","7.1842","26.5814"
"7.3600","1.8103","1.8103","1.2069","7.3054","27.0299"
"7.4400","1.8304","1.8304","1.2203","7.4139","27.4316"
"7.5200","1.8517","1.8517","1.2345","7.5367","27.8858"
"7.6000","1.8715","1.8715","1.2477","7.6481","28.2979"
"7.6800","1.8908","1.8908","1.2605","7.7584","28.7060"
"7.7600","1.9110","1.9110","1.2740","7.8720","29.1262"
"7.8400","1.9305","1.9305","1.2870","7.9782","29.5195"
"7.9200","1.9504","1.9504","1.3003","8.0945","29.9496"
"8.0000","1.9706","1.9706","1.3137","8.2108","30.3798"
"8.0800","1.9895","1.9895","1.3264","8.3159","30.7690"
"8.1600","2.0106","2.0106","1.3404","8.4402","31.2287"
"8.2400","2.0315","2.0315","1.3544","8.5600","31.6722"
"8.3200","2.0505","2.0505","1.3670","8.6702","32.0797"
"8.4000","2.0708","2.0708","1.3805","8.7845","32.5027"
"8.4800","2.0895","2.0895","1.3930","8.8909","32.8965"
"8.5600","2.1109","2.1109","1.4073","9.0159","33.3589"
"8.6400","2.1311","2.1311","1.4207","9.1324","33.7899"
"8.7200","2.1504","2.1504","1.4336","9.2404","34.1896"
"8.8000","2.1705","2.1705","1.4470","9.3580","34.6248"
"8.8800","2.1914","2.1914","1.4609","9.4795","35.0742"
"8.9600","2.2113","2.2113","1.4742","9.5964","35.5067"
"9.0400","2.2319","2.2319","1.4880","9.7163","35.9504"
"9.1200","2.2497","2.2497","1.4998","9.8180","36.3265"
"9.2000","2.2706","2.2706","1.5137","9.9388","36.7735"
"9.2800","2.2902","2.2902","1.5268","10.0533","37.1972"
"9.3600","2.3100","2.3100","1.5400","10.1732","37.6409"
"9.4400","2.3308","2.3308","1.5539","10.2959","38.0949"
"9.5200","2.3512","2.3512","1.5674","10.4134","38.5297"
"9.6000","2.3711","2.3711","1.5807","10.5299","38.9608"
"9.6800","2.3907","2.3907","1.5938","10.6439","39.3826"
"9.7600","2.4094","2.4094","1.6063","10.7541","39.7903"
"9.8400","2.4305","2.4305","1.6204","10.8787","40.2513"
"9.9200","2.4503","2.4503","1.6335","10.9902","40.6637"
"10.0000","2.4707","2.4707","1.6472","11.1120","41.1144"
"10.0800","2.4914","2.4914","1.6609","11.2358","41.5724"
"10.1600","2.5109","2.5109","1.6739","11.3468","41.9830"
"10.2400","2.5315","2.5315","1.6877","11.4677","42.4306"
"10.3200","2.5509","2.5509","1.7006","11.5799","42.8458"
"10.4000","2.5698","2.5698","1.7132","11.6888","43.2486"
"10.4800","2.5899","2.5899","1.7266","11.8080","43.6894"
"10.5600","2.6098","2.6098","1.7399","11.9224","44.1128"
"10.6400","2.6303","2.6303","1.7535","12.0440","44.5630"
"10.7200","2.6518","2.6518","1.7679","12.1705","45.0307"
"10.8000","2.6704","2.6704","1.7803","12.2779","45.4283"
"10.8800","2.6912","2.6912","1.7941","12.3984","45.8741"
"10.9600","2.7103","2.7103","1.8068","12.5096","46.2856"
"11.0400","2.7305","2.7305","1.8203","12.6287","46.7260"
"11.1200","2.7504","2.7504","1.8336","12.7457","47.1591"
"11.2000","2.7700","2.7700","1.8467","12.8588","47.5775"
"11.2800","2.7904","2.7904","1.8603","12.9821","48.0339"
"11.3600","2.8125","2.8125","1.8750","13.1170","48.5330"
"11.4400","2.8313","2.8313","1.8875","13.2254","48.9338"
"11.5200","2.8511","2.8511","1.9007","13.3411","49.3622"
"11.6000","2.8700","2.8700","1.9133","13.4450","49.7465"
"11.6800","2.8905","2.8905","1.9270","13.5673","50.1992"
"11.7600","2.9108","2.9108","1.9406","13.6841","50.6311"
"11.8400","2.9299","2.9299","1.9532","13.7962","51.0461"
"11.9200","2.9506","2.9506","1.9671","13.9190","51.5003"
"12.0000","2.9708","2.9708","1.9806","14.0342","51.9267"
"12.0800","2.9906","2.9906","1.9937","14.1482","52.3483"
"12.1600","3.0114","3.0114","2.0076","14.2700","52.7990"
"12.2400","3.0304","3.0304","2.0202","14.3758","53.1904"
"12.3200","3.0506","3.0506","2.0338","14.4932","53.6248"
"12.4000","3.0708","3.0708","2.0472","14.6085","54.0513"
"12.4800","3.0890","3.0890","2.0593","14.7104","54.4285"
"12.5600","3.1110","3.1110","2.0740","14.8426","54.9176"
"12.6400","3.1316","3.1316","2.0878","14.9606","55.3543"
"12.7200","3.1517","3.1517","2.1012","15.0741","55.7741"
"12.8000","3.1707","3.1707","2.1138","15.1805","56.1677"
"12.8800","3.1899","3.1899","2.1266","15.2886","56.5680"
"12.9600","3.2103","3.2103","2.1402","15.4135","57.0298"
"13.0400","3.2304","3.2304","2.1536","15.5264","57.4477"
"13.1200","3.2500","3.2500","2.1666","15.6397","57.8669"
"13.2000","3.2710","3.2710","2.1807","15.7609","58.3153"
"13.2800","3.2905","3.2905","2.1937","15.8689","58.7150"
"13.3600","3.3113","3.3113","2.2075","15.9896","59.1615"
"13.4400","3.3310","3.3310","2.2206","16.1029","59.5809"
"13.5200","3.3501","3.3501","2.2334","16.2130","59.9880"
"13.6000","3.3700","3.3700","2.2466","16.3254","60.4041"
"13.6800","3.3900","3.3900","2.2600","16.4394","60.8258"
"13.7600","3.4107","3.4107","2.2738","16.5595","61.2703"
"13.8400","3.4323","3.4323","2.2882","16.6841","61.7312"
"13.9200","3.4509","3.4509","2.3006","16.7872","62.1126"
"14.0000","3.4709","3.4709","2.3139","16.9002","62.5308"
"14.0800","3.4903","3.4903","2.3269","17.0085","62.9315"
"14.1600","3.5103","3.5103","2.3402","17.1239","63.3585"
"14.2400","3.5305","3.5305","2.3537","17.2397","63.7870"
"14.3200","3.5494","3.5494","2.3663","17.3417","64.1642"
"14.4000","3.5703","3.5703","2.3802","17.4628","64.6122"
"14.4800","3.5913","3.5913","2.3942","17.5828","65.0563"
"14.5600","3.6109","3.6109","2.4073","17.6919","65.4599"
"14.6400","3.6310","3.6310","2.4207","17.8051","65.8788"
"14.7200","3.6504","3.6504","2.4336","17.9101","66.2672"
"14.8000","3.6701","3.6701","2.4468","18.0226","66.6838"
"14.8800","3.6907","3.6907","2.4605","18.1370","67.1071"
"14.9600","3.7098","3.7098","2.4732","18.2443","67.5038"
"15.0400","3.7314","3.7314","2.4876","18.3645","67.9485"
"15.1200","3.7512","3.7512","2.5008","18.4736","68.3525"
"15.2000","3.7711","3.7711","2.5141","18.5808","68.7490"
"15.2800","3.7905","3.7905","2.5270","18.6885","69.1474"
"15.3600","3.8104","3.8104","2.5403","18.8015","69.5656"
"15.4400","3.8308","3.8308","2.5539","18.9154","69.9871"
"15.5200","3.8508","3.8508","2.5672","19.0275","70.4018"
"15.6000","3.8691","3.8691","2.5794","19.1274","70.7712"
"15.6800","3.8907","3.8907","2.5938","19.2497","71.2239"
"15.7600","3.9112","3.9112","2.6075","19.3643","71.6478"
"15.8400","3.9315","3.9315","2.6210","19.4763","72.0624"
"15.9200","3.9508","3.9508","2.6338","19.5778","72.4380"
"16.0000","3.9695","3.9695","2.6463","19.6820","72.8233"
"16.0800","3.9905","3.9905","2.6603","19.7970","73.2489"
"16.1600","4.0109","4.0109","2.6739","19.9113","73.6720"
"16.2400","4.0307","4.0307","2.6871","20.0209","74.0773"
"16.3200","4.0511","4.0511","2.7007","20.1353","74.5005"
"16.4000","4.0708","4.0708","2.7138","20.2388","74.8837"
"16.4800","4.0911","4.0911","2.7274","20.3522","75.3031"
"16.5600","4.1111","4.1111","2.7407","20.4571","75.6912"
"16.6400","4.1299","4.1299","2.7533","20.5628","76.0824"
"16.7200","4.1505","4.1505","2.7670","20.6762","76.5020"
"16.8000","4.1696","4.1696","2.7797","20.7764","76.8725"
"16.8800","4.1902","4.1902","2.7934","20.8901","77.2932"
"16.9600","4.2112","4.2112","2.8075","21.0072","77.7266"
"17.0400","4.2311","4.2311","2.8208","21.1150","78.1256"
"17.1200","4.2509","4.2509","2.8340","21.2243","78.5300"
"17.2000","4.2708","4.2708","2.8472","21.3289","78.9171"
"17.2800","4.2896","4.2896","2.8597","21.4274","79.2815"
"17.3600","4.3106","4.3106","2.8737","21.5439","79.7123"
"17.4400","4.3296","4.3296","2.8864","21.6370","80.0570"
"17.5200","4.3514","4.3514","2.9009","21.7583","80.5057"
"17.6000","4.3718","4.3718","2.9145","21.8647","80.8993"
"17.6800","4.3908","4.3908","2.9272","21.9683","81.2827"
"17.7600","4.4106","4.4106","2.9404","22.0718","81.6657"
"17.8400","4.4302","4.4302","2.9535","22.1748","82.0469"
"17.9200","4.4503","4.4503","2.9669","22.2833","82.4481"
"18.0000","4.4703","4.4703","2.9802","22.3907","82.8456"
"18.0800","4.4892","4.4892","2.9928","22.4863","83.1992"
"18.1600","4.5104","4.5104","3.0069","22.6008","83.6228"
"18.2400","4.5315","4.5315","3.0210","22.7130","84.0382"
"18.3200","4.5506","4.5506","3.0337","22.8141","84.4120"
"18.4000","4.5707","4.5707","3.0471","22.9202","84.8049"
"18.4800","4.5897","4.5897","3.0598","23.0185","85.1685"
"18.5600","4.6107","4.6107","3.0738","23.1290","85.5773"
"18.6400","4.6310","4.6310","3.0873","23.2359","85.9729"
"18.7200","4.6502","4.6502","3.1001","23.3375","86.3489"
"18.8000","4.6706","4.6706","3.1137","23.4443","86.7441"
"18.8800","4.6915","4.6915","3.1277","23.5541","87.1501"
"18.9600","4.7115","4.7115","3.1410","23.6556","87.5256"
"19.0400","4.7313","4.7313","3.1542","23.7570","87.9009"
"19.1200","4.7498","4.7498","3.1665","23.8508","88.2479"
"19.2000","4.7705","4.7705","3.1803","23.9594","88.6499"
"19.2800","4.7902","4.7902","3.1935","24.0605","89.0239"
"19.3600","4.8100","4.8100","3.2066","24.1658","89.4135"
"19.4400","4.8308","4.8308","3.2206","24.2756","89.8196"
"19.5200","4.8511","4.8511","3.2341","24.3766","90.1934"
"19.6000","4.8709","4.8709","3.2473","24.4765","90.5630"
"19.6800","4.8910","4.8910","3.2607","24.5789","90.9420"
"19.7600","4.9098","4.9098","3.2732","24.6733","91.2913"
"19.8400","4.9306","4.9306","3.2870","24.7830","91.6972"
"19.9200","4.9502","4.9502","3.3001","24.8801","92.0564"
"20.0000","4.9704","4.9704","3.3136","24.9846","92.4430"
"20.0800","4.9915","4.9915","3.3276","25.0947","92.8504"
"20.1600","5.0111","5.0111","3.3407","25.1943","93.2189"
"20.2400","5.0315","5.0315","3.3544","25.2950","93.5914"
"20.3200","5.0506","5.0506","3.3670","25.3879","93.9351"
"20.4000","5.0693","5.0693","3.3795","25.4823","94.2843"
"20.4800","5.0904","5.0904","3.3936","25.5940","94.6979"
"20.5600","5.1101","5.1101","3.4067","25.6898","95.0523"
"20.6400","5.1303","5.1303","3.4202","25.7931","95.4343"
"20.7200","5.1516","5.1516","3.4344","25.8997","95.8288"
"20.8000","5.1705","5.1705","3.4470","25.9951","96.1817"
"20.8800","5.1911","5.1911","3.4607","26.1001","96.5704"
"20.9600","5.2102","5.2102","3.4735","26.1919","96.9099"
"21.0400","5.2303","5.2303","3.4869","26.2939","97.2875"
"21.1200","5.2505","5.2505","3.5003","26.3950","97.6616"
"21.2000","5.2701","5.2701","3.5134","26.4897","98.0120"
"21.2800","5.2906","5.2906","3.5271","26.5926","98.3927"
"21.3600","5.3120","5.3120","3.5413","26.7006","98.7924"
"21.4400","5.3312","5.3312","3.5541","26.7966","99.1474"
"21.5200","5.3511","5.3511","3.5674","26.8961","99.5155"
"21.6000","5.3698","5.3698","3.5798","26.9837","99.8398"
"21.6800","5.3904","5.3904","3.5936","27.0862","100.2189"
"21.7600","5.4107","5.4107","3.6071","27.1850","100.5846"
"21.8400","5.4296","5.4296","3.6197","27.2768","100.9242"
"21.9200","5.4505","5.4505","3.6337","27.3833","101.3183"
"22.0000","5.4711","5.4711","3.6474","27.4819","101.6832"
"22.0800","5.4908","5.4908","3.6605","27.5773","102.0360"
"22.1600","5.5112","5.5112","3.6741","27.6803","102.4170"
"22.2400","5.5303","5.5303","3.6869","27.7694","102.7470"
"22.3200","5.5507","5.5507","3.7005","27.8682","103.1124"
"22.4000","5.5705","5.5705","3.7136","27.9620","103.4593"
"22.4800","5.5897","5.5897","3.7265","28.0566","103.8095"
"22.5600","5.6117","5.6117","3.7412","28.1661","104.2144"
"22.6400","5.6315","5.6315","3.7543","28.2572","104.5516"
"22.7200","5.6515","5.6515","3.7677","28.3506","104.8973"
"22.8000","5.6712","5.6712","3.7808","28.4500","105.2652"
"22.8800","5.6899","5.6899","3.7933","28.5364","105.5846"
"22.9600","5.7104","5.7104","3.8069","28.6366","105.9556"
"23.0400","5.7305","5.7305","3.8203","28.7301","106.3014"
"23.1200","5.7498","5.7498","3.8332","28.8207","106.6364"
"23.2000","5.7708","5.7708","3.8472","28.9221","107.0118"
"23.2800","5.7899","5.7899","3.8599","29.0071","107.3262"
"23.3600","5.8114","5.8114","3.8743","29.1126","107.7165"
"23.4400","5.8313","5.8313","3.8875","29.2027","108.0498"
"23.5200","5.8502","5.8502","3.9001","29.2914","108.3783"
"23.6000","5.8698","5.8698","3.9132","29.3824","108.7148"
"23.6800","5.8901","5.8901","3.9267","29.4763","109.0623"
"23.7600","5.9109","5.9109","3.9406","29.5766","109.4333"
"23.8400","5.9324","5.9324","3.9549","29.6778","109.8077"
"23.9200","5.9511","5.9511","3.9674","29.7595","110.1103"
"24.0000","5.9710","5.9710","3.9807","29.8529","110.4555"
"24.0800","5.9904","5.9904","3.9936","29.9393","110.7754"
"24.1600","6.0104","6.0104","4.0069","30.0364","111.1348"
"24.2400","6.0306","6.0306","4.0204","30.1280","111.4735"
"24.3200","6.0491","6.0491","4.0328","30.2077","111.7685"
"24.4000","6.0701","6.0701","4.0467","30.3058","112.1315"
"24.4800","6.0913","6.0913","4.0609","30.4060","112.5021"
"24.5600","6.1108","6.1108","4.0739","30.4909","112.8163"
"24.6400","6.1307","6.1307","4.0872","30.5828","113.1565"
"24.7200","6.1507","6.1507","4.1004","30.6710","113.4825"
"24.8000","6.1704","6.1704","4.1136","30.7597","113.8111"
"24.8800","6.1909","6.1909","4.1273","30.8550","114.1635"
"24.9600","6.2096","6.2096","4.1398","30.9367","114.4659"
"25.0400","6.2314","6.2314","4.1543","31.0369","114.8366"
"25.1200","6.2516","6.2516","4.1677","31.1283","115.1745"
"25.2000","6.2714","6.2714","4.1809","31.2148","115.4946"
"25.2800","6.2904","6.2904","4.1936","31.2991","115.8066"
"25.3600","6.3103","6.3103","4.2069","31.3854","116.1261"
"25.4400","6.3310","6.3310","4.2206","31.4784","116.4701"
"25.5200","6.3509","6.3509","4.2340","31.5619","116.7792"
"25.6000","6.3685","6.3685","4.2457","31.6356","117.0518"
"25.6800","6.3900","6.3900","4.2600","31.7361","117.4237"
"25.7600","6.4109","6.4109","4.2739","31.8267","117.7588"
"25.8400","6.4316","6.4316","4.2877","31.9193","118.1012"
"25.9200","6.4514","6.4514","4.3009","32.0035","118.4130"
"26.0000","6.4698","6.4698","4.3132","32.0809","118.6994"
"26.0800","6.4901","6.4901","4.3268","32.1696","119.0275"
"26.1600","6.5107","6.5107","4.3405","32.2591","119.3587"
"26.2400","6.5307","6.5307","4.3538","32.3443","119.6739"
"26.3200","6.5510","6.5510","4.3674","32.4360","120.0132"
"26.4000","6.5709","6.5709","4.3806","32.5176","120.3152"
"26.4800","6.5912","6.5912","4.3941","32.6024","120.6290"
"26.5600","6.6114","6.6114","4.4076","32.6914","120.9582"
"26.6400","6.6300","6.6300","4.4200","32.7669","121.2375"
"26.7200","6.6502","6.6502","4.4335","32.8531","121.5565"
"26.8000","6.6697","6.6697","4.4464","32.9342","121.8566"
"26.8800","6.6903","6.6903","4.4602","33.0225","122.1833"
"26.9600","6.7112","6.7112","4.4742","33.1130","122.5182"
"27.0400","6.7310","6.7310","4.4873","33.1914","122.8082"
"27.1200","6.7508","6.7508","4.5005","33.2728","123.1094"
"27.2000","6.7706","6.7706","4.5138","33.3548","123.4129"
"27.2800","6.7899","6.7899","4.5266","33.4357","123.7122"
"27.3600","6.8110","6.8110","4.5407","33.5249","124.0423"
"27.4400","6.8300","6.8300","4.5533","33.6000","124.3200"
"27.5200","6.8515","6.8515","4.5677","33.6908","124.6558"
"27.6000","6.8717","6.8717","4.5811","33.7733","124.9612"
"27.6800","6.8905","6.8905","4.5937","33.8463","125.2314"
"27.7600","6.9108","6.9108","4.6072","33.9325","125.5501"
"27.8400","6.9306","6.9306","4.6204","34.0081","125.8301"
"27.9200","6.9499","6.9499","4.6333","34.0823","126.1046"
"28.0000","6.9704","6.9704","4.6469","34.1660","126.4143"
"28.0800","6.9895","6.9895","4.6597","34.2379","126.6804"
"28.1600","7.0106","7.0106","4.6738","34.3259","127.0058"
"28.2400","7.0315","7.0315","4.6877","34.4099","127.3165"
"28.3200","7.0509","7.0509","4.7006","34.4828","127.5865"
"28.4000","7.0706","7.0706","4.7137","34.5615","127.8777"
"28.4800","7.0897","7.0897","4.7265","34.6308","128.1341"
"28.5600","7.1109","7.1109","4.7406","34.7152","128.4463"
"28.6400","7.1309","7.1309","4.7539","34.7929","128.7336"
"28.7200","7.1501","7.1501","4.7667","34.8656","129.0027"
"28.8000","7.1709","7.1709","4.7806","34.9492","129.3120"
"28.8800","7.1915","7.1915","4.7943","35.0294","129.6086"
"28.9600","7.2111","7.2111","4.8074","35.1042","129.8857"
"29.0400","7.2310","7.2310","4.8207","35.1786","130.1608"
"29.1200","7.2495","7.2495","4.8330","35.2428","130.3985"
"29.2000","7.2705","7.2705","4.8470","35.3249","130.7021"
"29.2800","7.2904","7.2904","4.8603","35.3987","130.9751"
"29.3600","7.3097","7.3097","4.8732","35.4739","131.2534"
"29.4400","7.3307","7.3307","4.8871","35.5546","131.5518"
"29.5200","7.3513","7.3513","4.9009","35.6289","131.8269"
"29.6000","7.3711","7.3711","4.9141","35.7033","132.1022"
"29.6800","7.3908","7.3908","4.9272","35.7706","132.3511"
"29.7600","7.4101","7.4101","4.9401","35.8413","132.6129"
"29.8400","7.4310","7.4310","4.9540","35.9212","132.9084"
"29.9200","7.4504","7.4504","4.9669","35.9839","133.1405"
"30.0000","7.4702","7.4702","4.9801","36.0579","133.4144"
"30.0800","7.4913","7.4913","4.9942","36.1362","133.7041"
"30.1600","7.5112","7.5112","5.0074","36.2055","133.9605"
"30.2400","7.5314","7.5314","5.0210","36.2759","134.2207"
"30.3200","7.5509","7.5509","5.0339","36.3417","134.4643"
"30.4000","7.5697","7.5697","5.0465","36.4063","134.7032"
"30.4800","7.5902","7.5902","5.0601","36.4796","134.9745"
"30.5600","7.6098","7.6098","5.0732","36.5456","135.2188"
"30.6400","7.6302","7.6302","5.0868","36.6169","135.4825"
"30.7200","7.6519","7.6519","5.1012","36.6913","135.7577"
"30.8000","7.6706","7.6706","5.1137","36.7564","135.9987"
"30.8800","7.6912","7.6912","5.1275","36.8262","136.2568"
"30.9600","7.7102","7.7102","5.1401","36.8874","136.4835"
"31.0400","7.7302","7.7302","5.1535","36.9570","136.7408"
"31.1200","7.7502","7.7502","5.1668","37.0202","136.9749"
"31.2000","7.7700","7.7700","5.1800","37.0845","137.2125"
"31.2800","7.7908","7.7908","5.1938","37.1525","137.4641"
"31.3600","7.8122","7.8122","5.2082","37.2222","137.7221"
"31.4400","7.8310","7.8310","5.2206","37.2815","137.9414"
"31.5200","7.8509","7.8509","5.2339","37.3460","138.1802"
"31.6000","7.8698","7.8698","5.2466","37.4018","138.3868"
"31.6800","7.8904","7.8904","5.2603","37.4668","138.6270"
"31.7600","7.9106","7.9106","5.2737","37.5303","138.8621"
"31.8400","7.9298","7.9298","5.2865","37.5907","139.0857"
"31.9200","7.9504","7.9504","5.3003","37.6513","139.3098"
"32.0000","7.9707","7.9707","5.3138","37.7153","139.5468"
"32.0800","7.9909","7.9909","5.3273","37.7771","139.7752"
"32.1600","8.0113","8.0113","5.3408","37.8362","139.9941"
"32.2400","8.0303","8.0303","5.3536","37.8904","140.1946"
"32.3200","8.0509","8.0509","5.3673","37.9522","140.4233"
"32.4000","8.0706","8.0706","5.3804","38.0061","140.6225"
"32.4800","8.0894","8.0894","5.3929","38.0629","140.8328"
"32.5600","8.1118","8.1118","5.4079","38.1320","141.0885"
"32.6400","8.1316","8.1316","5.4210","38.1848","141.2836"
"32.7200","8.1517","8.1517","5.4345","38.2406","141.4904"
"32.8000","8.1707","8.1707","5.4471","38.2899","141.6725"
"32.8800","8.1899","8.1899","5.4599","38.3387","141.8531"
"32.9600","8.2103","8.2103","5.4736","38.3954","142.0631"
"33.0400","8.2300","8.2300","5.4867","38.4463","142.2513"
"33.1200","8.2495","8.2495","5.4997","38.4981","142.4429"
"33.2000","8.2714","8.2714","5.5143","38.5612","142.6764"
"33.2800","8.2903","8.2903","5.5269","38.6060","142.8422"
"33.3600","8.3114","8.3114","5.5409","38.6662","143.0648"
"33.4400","8.3311","8.3311","5.5541","38.7142","143.2424"
"33.5200","8.3501","8.3501","5.5667","38.7613","143.4168"
"33.6000","8.3703","8.3703","5.5802","38.8124","143.6060"
"33.6800","8.3902","8.3902","5.5935","38.8623","143.7906"
"33.7600","8.4107","8.4107","5.6072","38.9118","143.9738"
"33.8400","8.4318","8.4318","5.6212","38.9670","144.1779"
"33.9200","8.4507","8.4507","5.6338","39.0084","144.3309"
"34.0000","8.4709","8.4709","5.6473","39.0563","144.5083"
"34.0800","8.4907","8.4907","5.6604","39.0994","144.6676"
"34.1600","8.5103","8.5103","5.6736","39.1466","144.8424"
"34.2400","8.5305","8.5305","5.6870","39.1916","145.0090"
"34.3200","8.5492","8.5492","5.6995","39.2284","145.1449"
"34.4000","8.5703","8.5703","5.7135","39.2763","145.3222"
"34.4800","8.5913","8.5913","5.7275","39.3253","145.5037"
"34.5600","8.6112","8.6112","5.7408","39.3683","145.6627"
"34.6400","8.6312","8.6312","5.7541","39.4151","145.8360"
"34.7200","8.6504","8.6504","5.7669","39.4485","145.9596"
"34.8000","8.6701","8.6701","5.7801","39.4907","146.1155"
"34.8800","8.6908","8.6908","5.7938","39.5322","146.2690"
"34.9600","8.7101","8.7101","5.8067","39.5701","146.4095"
"35.0400","8.7318","8.7318","5.8212","39.6167","146.5820"
"35.1200","8.7516","8.7516","5.8344","39.6546","146.7220"
"35.2000","8.7712","8.7712","5.8474","39.6887","146.8481"
"35.2800","8.7904","8.7904","5.8603","39.7260","146.9864"
"35.3600","8.8104","8.8104","5.8736","39.7603","147.1130"
"35.4400","8.8309","8.8309","5.8872","39.7981","147.2530"
"35.5200","8.8510","8.8510","5.9007","39.8353","147.3906"
"35.6000","8.8686","8.8686","5.9124","39.8592","147.4790"
"35.6800","8.8905","8.8905","5.9270","39.9059","147.6517"
"35.7600","8.9110","8.9110","5.9406","39.9424","147.7870"
"35.8400","8.9316","8.9316","5.9544","39.9759","147.9108"
"35.9200","8.9511","8.9511","5.9674","40.0071","148.0264"
"36.0000","8.9696","8.9696","5.9797","40.0326","148.1207"
"36.0800","8.9902","8.9902","5.9934","40.0673","148.2491"
"36.1600","9.0104","9.0104","6.0069","40.1011","148.3742"
"36.2400","9.0305","9.0305","6.0203","40.1336","148.4943"
"36.3200","9.0514","9.0514","6.0343","40.1695","148.6272"
"36.4000","9.0711","9.0711","6.0474","40.1955","148.7232"
"36.4800","9.0912","9.0912","6.0608","40.2261","148.8366"
"36.5600","9.1111","9.1111","6.0741","40.2525","148.9344"
"36.6400","9.1299","9.1299","6.0866","40.2781","149.0288"
"36.7200","9.1505","9.1505","6.1003","40.3074","149.1374"
"36.8000","9.1695","9.1695","6.1130","40.3298","149.2201"
"36.8800","9.1903","9.1903","6.1268","40.3630","149.3432"
"36.9600","9.2114","9.2114","6.1409","40.3950","149.4614"
"37.0400","9.2310","9.2310","6.1540","40.4186","149.5489"
"37.1200","9.2509","9.2509","6.1672","40.4405","149.6299"
"37.2000","9.2706","9.2706","6.1804","40.4637","149.7157"
"37.2800","9.2896","9.2896","6.1931","40.4866","149.8004"
"37.3600","9.3107","9.3107","6.2071","40.5163","149.9104"
"37.4400","9.3303","9.3303","6.2202","40.5365","149.9852"
"37.5200","9.3514","9.3514","6.2343","40.5647","150.0895"
"37.6000","9.3715","9.3715","6.2477","40.5898","150.1822"
"37.6800","9.3909","9.3909","6.2606","40.6072","150.2467"
"37.7600","9.4108","9.4108","6.2738","40.6296","150.3295"
"37.8400","9.4306","9.4306","6.2870","40.6484","150.3992"
"37.9200","9.4498","9.4498","6.2999","40.6661","150.4646"
"38.0000","9.4708","9.4708","6.3139","40.6892","150.5499"
"38.0800","9.4894","9.4894","6.3262","40.7039","150.6044"
"38.1600","9.5102","9.5102","6.3401","40.7275","150.6916"
"38.2400","9.5314","9.5314","6.3543","40.7511","150.7791"
"38.3200","9.5509","9.5509","6.3673","40.7661","150.8345"
"38.4000","9.5710","9.5710","6.3807","40.7870","150.9117"
"38.4800","9.5900","9.5900","6.3933","40.7986","150.9550"
"38.5600","9.6109","9.6109","6.4072","40.8211","151.0381"
"38.6400","9.6306","9.6306","6.4204","40.8324","151.0797"
"38.7200","9.6501","9.6501","6.4334","40.8501","151.1455"
"38.8000","9.6707","9.6707","6.4471","40.8677","151.2106"
"38.8800","9.6917","9.6917","6.4611","40.8872","151.2826"
"38.9600","9.7113","9.7113","6.4742","40.8987","151.3250"
"39.0400","9.7310","9.7310","6.4873","40.9114","151.3722"
"39.1200","9.7495","9.7495","6.4997","40.9212","151.4085"
"39.2000","9.7704","9.7704","6.5136","40.9406","151.4801"
"39.2800","9.7904","9.7904","6.5269","40.9562","151.5379"
"39.3600","9.8099","9.8099","6.5400","40.9680","151.5817"
"39.4400","9.8309","9.8309","6.5539","40.9866","151.6503"
"39.5200","9.8514","9.8514","6.5676","41.0006","151.7024"
"39.6000","9.8708","9.8708","6.5806","41.0081","151.7299"
"39.6800","9.8904","9.8904","6.5936","41.0160","151.7591"
"39.7600","9.9095","9.9095","6.6063","41.0266","151.7984"
"39.8400","9.9309","9.9309","6.6206","41.0462","151.8711"
"39.9200","9.9505","9.9505","6.6337","41.0560","151.9073"
"40.0000","9.9706","9.9706","6.6471","41.0714","151.9641"
"40.0800","9.9914","9.9914","6.6610","41.0839","152.0105"
"40.1600","10.0111","10.0111","6.6741","41.0928","152.0433"
"40.2400","10.0315","10.0315","6.6877","41.1054","152.0901"
"40.3200","10.0511","10.0511","6.7008","41.1124","152.1159"
"40.4000","10.0699","10.0699","6.7133","41.1182","152.1374"
"40.4800","10.0894","10.0894","6.7263","41.1280","152.1736"
"40.5600","10.1098","10.1098","6.7399","41.1386","152.2130"
"40.6400","10.1304","10.1304","6.7536","41.1504","152.2565"
"40.7200","10.1520","10.1520","6.7680","41.1670","152.3179"
"40.8000","10.1709","10.1709","6.7806","41.1718","152.3358"
"40.8800","10.1910","10.1910","6.7940","41.1810","152.3696"
"40.9600","10.2100","10.2100","6.8067","41.1874","152.3935"
"41.0400","10.2305","10.2305","6.8203","41.1998","152.4394"
"41.1200","10.2501","10.2501","6.8334","41.2064","152.4637"
"41.2000","10.2699","10.2699","6.8466","41.2155","152.4975"
"41.2800","10.2909","10.2909","6.8606","41.2276","152.5421"
"41.3600","10.3123","10.3123","6.8748","41.2434","152.6005"
"41.4400","10.3309","10.3309","6.8873","41.2470","152.6138"
"41.5200","10.3508","10.3508","6.9006","41.2534","152.6377"
"41.6000","10.3698","10.3698","6.9132","41.2547","152.6423"
"41.6800","10.3903","10.3903","6.9269","41.2665","152.6859"
"41.7600","10.4106","10.4106","6.9404","41.2741","152.7141"
"41.8400","10.4297","10.4297","6.9531","41.2789","152.7320"
"41.9200","10.4502","10.4502","6.9668","41.2880","152.7657"
"42.0000","10.4709","10.4709","6.9806","41.2988","152.8056"
"42.0800","10.4909","10.4909","6.9939","41.3055","152.8302"
"42.1600","10.5111","10.5111","7.0074","41.3128","152.8572"
"42.2400","10.5306","10.5306","7.0204","41.3169","152.8725"
"42.3200","10.5508","10.5508","7.0339","41.3245","152.9008"
"42.4000","10.5705","10.5705","7.0470","41.3261","152.9065"
"42.4800","10.5895","10.5895","7.0597","41.3339","152.9355"
"42.5600","10.6119","10.6119","7.0746","41.3514","153.0000"
"42.6400","10.6317","10.6317","7.0878","41.3548","153.0127"
"42.7200","10.6517","10.6517","7.1011","41.3560","153.0171"
"42.8000","10.6708","10.6708","7.1138","41.3593","153.0293"
"42.8800","10.6901","10.6901","7.1268","41.3644","153.0483"
"42.9600","10.7102","10.7102","7.1401","41.3713","153.0739"
"43.0400","10.7302","10.7302","7.1534","41.3766","153.0933"
"43.1200","10.7495","10.7495","7.1663","41.3806","153.1082"
"43.2000","10.7710","10.7710","7.1807","41.3934","153.1557"
"43.2800","10.7902","10.7902","7.1934","41.3929","153.1538"
"43.3600","10.8115","10.8115","7.2076","41.4028","153.1902"
"43.4400","10.8310","10.8310","7.2207","41.4055","153.2004"
"43.5200","10.8502","10.8502","7.2334","41.4073","153.2071"
"43.6000","10.8700","10.8700","7.2467","41.4131","153.2284"
"43.6800","10.8902","10.8902","7.2601","41.4197","153.2528"
"43.7600","10.9109","10.9109","7.2740","41.4265","153.2782"
"43.8400","10.9323","10.9323","7.2882","41.4349","153.3091"
"43.9200","10.9508","10.9508","7.3005","41.4339","153.3053"
"44.0000","10.9706","10.9706","7.3137","41.4361","153.3137"
"44.0800","10.9908","10.9908","7.3272","41.4423","153.3365"
"44.1600","11.0103","11.0103","7.3402","41.4498","153.3643"
"44.2400","11.0309","11.0309","7.3539","41.4545","153.3818"
"44.3200","11.0493","11.0493","7.3662","41.4559","153.3867"
"44.4000","11.0702","11.0702","7.3802","41.4628","153.4125"
"44.4800","11.0910","11.0910","7.3940","41.4712","153.4435"
"44.5600","11.1112","11.1112","7.4075","41.4764","153.4626"
"44.6400","11.1313","11.1313","7.4209","41.4830","153.4870"
"44.7200","11.1506","11.1506","7.4338","41.4823","153.4846"
"44.8000","11.1699","11.1699","7.4466","41.4833","153.4882"
"44.8800","11.1907","11.1907","7.4605","41.4885","153.5074"
"44.9600","11.2097","11.2097","7.4731","41.4927","153.5231"
"45.0400","11.2317","11.2317","7.4878","41.5026","153.5597"
"45.1200","11.2518","11.2518","7.5012","41.5050","153.5684"
"45.2000","11.2712","11.2712","7.5141","41.5078","153.5787"
"45.2800","11.2904","11.2904","7.5269","41.5057","153.5713"
"45.3600","11.3103","11.3103","7.5402","41.5071","153.5761"
"45.4400","11.3304","11.3304","7.5536","41.5082","153.5805"
"45.5200","11.3504","11.3504","7.5669","41.5130","153.5982"
"45.6000","11.3687","11.3687","7.5791","41.5112","153.5916"
"45.6800","11.3908","11.3908","7.5939","41.5239","153.6385"
"45.7600","11.4111","11.4111","7.6074","41.5250","153.6427"
"45.8400","11.4315","11.4315","7.6210","41.5315","153.6665"
"45.9200","11.4511","11.4511","7.6341","41.5298","153.6603"
"46.0000","11.4697","11.4697","7.6464","41.5279","153.6533"
"46.0800","11.4901","11.4901","7.6601","41.5323","153.6695"
"46.1600","11.5108","11.5108","7.6739","41.5382","153.6913"
"46.2400","11.5306","11.5306","7.6871","41.5415","153.7036"
"46.3200","11.5508","11.5508","7.7005","41.5479","153.7271"
"46.4000","11.5707","11.5707","7.7138","41.5461","153.7206"
"46.4800","11.5912","11.5912","7.7275","41.5510","153.7386"
"46.5600","11.6117","11.6117","7.7411","41.5524","153.7438"
"46.6400","11.6303","11.6303","7.7536","41.5553","153.7546"
"46.7200","11.6505","11.6505","7.7670","41.5586","153.7668"
"46.8000","11.6694","11.6694","7.7796","41.5560","153.7572"
"46.8800","11.6901","11.6901","7.7934","41.5604","153.7734"
"46.9600","11.7114","11.7114","7.8076","41.5680","153.8015"
"47.0400","11.7313","11.7313","7.8209","41.5669","153.7977"
"47.1200","11.7509","11.7509","7.8339","41.5651","153.7909"
"47.2000","11.7705","11.7705","7.8470","41.5610","153.7756"
"47.2800","11.7896","11.7896","7.8597","41.5623","153.7805"
"47.3600","11.8106","11.8106","7.8737","41.5698","153.8084"
"47.4400","11.8300","11.8300","7.8866","41.5674","153.7993"
"47.5200","11.8513","11.8513","7.9009","41.5719","153.8160"
"47.6000","11.8715","11.8715","7.9143","41.5713","153.8138"
"47.6800","11.8906","11.8906","7.9271","41.5712","153.8134"
"47.7600","11.9106","11.9106","7.9404","41.5680","153.8018"
"47.8400","11.9306","11.9306","7.9537","41.5647","153.7896"
"47.9200","11.9501","11.9501","7.9667","41.5663","153.7953"
"48.0000","11.9710","11.9710","7.9806","41.5689","153.8050"
"48.0800","11.9896","11.9896","7.9931","41.5632","153.7839"
"48.1600","12.0104","12.0104","8.0069","41.5673","153.7991"
"48.2400","12.0317","12.0317","8.0211","41.5708","153.8119"
"48.3200","12.0510","12.0510","8.0340","41.5687","153.8042"
"48.4000","12.0708","12.0708","8.0472","41.5660","153.7942"
"48.4800","12.0901","12.0901","8.0601","41.5622","153.7800"
"48.5600","12.1111","12.1111","8.0741","41.5667","153.7969"
"48.6400","12.1309","12.1309","8.0873","41.5630","153.7831"
"48.7200","12.1504","12.1504","8.1003","41.5631","153.7833"
"48.8000","12.1705","12.1705","8.1137","41.5624","153.7809"
"48.8800","12.1914","12.1914","8.1276","41.5615","153.7777"
"48.9600","12.2111","12.2111","8.1407","41.5593","153.7693"
"49.0400","12.2319","12.2319","8.1546","41.5614","153.7771"
"49.1200","12.2498","12.2498","8.1665","41.5517","153.7412"
"49.2000","12.2702","12.2702","8.1801","41.5515","153.7407"
"49.2800","12.2899","12.2899","8.1933","41.5415","153.7036"
"49.3600","12.3097","12.3097","8.2064","41.5403","153.6992"
"49.4400","12.3309","12.3309","8.2206","41.5460","153.7203"
"49.5200","12.3513","12.3513","8.2342","41.5399","153.6977"
"49.6000","12.3708","12.3708","8.2472","41.5375","153.6888"
"49.6800","12.3907","12.3907","8.2605","41.5325","153.6702"
"49.7600","12.4095","12.4095","8.2730","41.5308","153.6640"
"49.8400","12.4310","12.4310","8.2873","41.5338","153.6751"
"49.9200","12.4504","12.4504","8.3003","41.5280","153.6535"
"50.0000","12.4704","12.4704","8.3136","41.5264","153.6475"
"50.0800","12.4917","12.4917","8.3278","41.5275","153.6518"
"50.1600","12.5109","12.5109","8.3406","41.5224","153.6329"
"50.2400","12.5314","12.5314","8.3543","41.5203","153.6251"
"50.3200","12.5512","12.5512","8.3675","41.5154","153.6068"
"50.4000","12.5702","12.5702","8.3801","41.5120","153.5945"
"50.4800","12.5899","12.5899","8.3933","41.5079","153.5792"
"50.5600","12.6098","12.6098","8.4065","41.5030","153.5612"
"50.6400","12.6302","12.6302","8.4202","41.5010","153.5535"
"50.7200","12.6517","12.6517","8.4344","41.4999","153.5495"
"50.8000","12.6706","12.6706","8.4471","41.4896","153.5116"
"50.8800","12.6908","12.6908","8.4605","41.4851","153.4950"
"50.9600","12.7101","12.7101","8.4734","41.4784","153.4699"
"51.0400","12.7305","12.7305","8.4870","41.4739","153.4535"
"51.1200","12.7505","12.7505","8.5004","41.4723","153.4475"
"51.2000","12.7698","12.7698","8.5132","41.4623","153.4107"
"51.2800","12.7907","12.7907","8.5271","41.4582","153.3954"
"51.3600","12.8123","12.8123","8.5415","41.4587","153.3973"
"51.4400","12.8312","12.8312","8.5541","41.4521","153.3729"
"51.5200","12.8510","12.8510","8.5673","41.4456","153.3486"
"51.6000","12.8699","12.8699","8.5799","41.4373","153.3180"
"51.6800","12.8903","12.8903","8.5935","41.4349","153.3092"
"51.7600","12.9108","12.9108","8.6072","41.4310","153.2949"
"51.8400","12.9299","12.9299","8.6199","41.4233","153.2664"
"51.9200","12.9506","12.9506","8.6338","41.4218","153.2607"
"52.0000","12.9711","12.9711","8.6474","41.4204","153.2556"
"52.0800","12.9906","12.9906","8.6604","41.4114","153.2222"
"52.1600","13.0108","13.0108","8.6738","41.4084","153.2109"
"52.2400","13.0303","13.0303","8.6868","41.3983","153.1736"
"52.3200","13.0508","13.0508","8.7005","41.3965","153.1671"
"52.4000","13.0710","13.0710","8.7140","41.3894","153.1408"
"52.4800","13.0898","13.0898","8.7265","41.3823","153.1146"
"52.5600","13.1110","13.1110","8.7407","41.3832","153.1178"
"52.6400","13.1316","13.1316","8.7544","41.3795","153.1042"
"52.7200","13.1520","13.1520","8.7680","41.3720","153.0765"
"52.8000","13.1710","13.1710","8.7807","41.3639","153.0464"
"52.8800","13.1899","13.1899","8.7933","41.3544","153.0112"
"52.9600","13.2101","13.2101","8.8067","41.3488","152.9907"
"53.0400","13.2304","13.2304","8.8203","41.3428","152.9683"
"53.1200","13.2497","13.2497","8.8331","41.3365","152.9449"
"53.2000","13.2709","13.2709","8.8473","41.3368","152.9460"
"53.2800","13.2901","13.2901","8.8601","41.3256","152.9046"
"53.3600","13.3115","13.3115","8.8744","41.3248","152.9019"
"53.4400","13.3310","13.3310","8.8873","41.3175","152.8748"
"53.5200","13.3498","13.3498","8.8999","41.3108","152.8501"
"53.6000","13.3700","13.3700","8.9133","41.3060","152.8324"
"53.6800","13.3903","13.3903","8.9269","41.3008","152.8128"
"53.7600","13.4112","13.4112","8.9408","41.3006","152.8122"
"53.8400","13.4320","13.4320","8.9547","41.2962","152.7960"
"53.9200","13.4507","13.4507","8.9672","41.2894","152.7707"
"54.0000","13.4708","13.4709","8.9806","41.2815","152.7416"
"54.0800","13.4906","13.4906","8.9937","41.2776","152.7273"
"54.1600","13.5103","13.5103","9.0069","41.2732","152.7110"
"54.2400","13.5310","13.5310","9.0207","41.2700","152.6989"
"54.3200","13.5494","13.5494","9.0329","41.2576","152.6532"
"54.4000","13.5702","13.5702","9.0468","41.2527","152.6348"
"54.4800","13.5913","13.5913","9.0608","41.2503","152.6262"
"54.5600","13.6108","13.6108","9.0739","41.2447","152.6054"
"54.6400","13.6309","13.6309","9.0873","41.2412","152.5925"
"54.7200","13.6504","13.6504","9.1003","41.2372","152.5775"
"54.8000","13.6701","13.6701","9.1134","41.2285","152.5455"
"54.8800","13.6910","13.6910","9.1273","41.2298","152.5501"
"54.9600","13.7101","13.7101","9.1401","41.2246","152.5309"
"55.0400","13.7317","13.7317","9.1545","41.2228","152.5245"
"55.1200","13.7514","13.7514","9.1676","41.2180","152.5068"
"55.2000","13.7712","13.7712","9.1808","41.2114","152.4823"
"55.2800","13.7905","13.7905","9.1937","41.2077","152.4684"
"55.3600","13.8103","13.8103","9.2069","41.2000","152.4401"
"55.4400","13.8307","13.8307","9.2205","41.1960","152.4251"
"55.5200","13.8507","13.8507","9.2338","41.1936","152.4162"
"55.6000","13.8694","13.8694","9.2462","41.1856","152.3869"
"55.6800","13.8908","13.8908","9.2605","41.1894","152.4009"
"55.7600","13.9113","13.9113","9.2742","41.1860","152.3881"
"55.8400","13.9317","13.9317","9.2878","41.1823","152.3747"
"55.9200","13.9509","13.9509","9.3006","41.1751","152.3479"
"56.0000","13.9694","13.9694","9.3129","41.1660","152.3144"
"56.0800","13.9904","13.9904","9.3269","41.1626","152.3015"
"56.1600","14.0107","14.0107","9.3405","41.1579","152.2841"
"56.2400","14.0305","14.0305","9.3537","41.1520","152.2625"
"56.3200","14.0516","14.0516","9.3677","41.1477","152.2466"
"56.4000","14.0708","14.0708","9.3805","41.1368","152.2063"
"56.4800","14.0912","14.0912","9.3941","41.1308","152.1840"
"56.5600","14.1114","14.1114","9.4076","41.1235","152.1571"
"56.6400","14.1302","14.1302","9.4201","41.1167","152.1316"
"56.7200","14.1504","14.1504","9.4336","41.1110","152.1107"
"56.8000","14.1695","14.1695","9.4463","41.0995","152.0683"
"56.8800","14.1900","14.1900","9.4600","41.0953","152.0527"
"56.9600","14.2110","14.2110","9.4740","41.0930","152.0440"
"57.0400","14.2309","14.2309","9.4873","41.0873","152.0229"
"57.1200","14.2507","14.2507","9.5005","41.0791","151.9925"
"57.2000","14.2707","14.2707","9.5138","41.0723","151.9675"
"57.2800","14.2899","14.2899","9.5266","41.0632","151.9337"
"57.3600","14.3108","14.3108","9.5405","41.0600","151.9219"
"57.4400","14.3301","14.3301","9.5534","41.0471","151.8742"
"57.5200","14.3513","14.3513","9.5675","41.0400","151.8480"
"57.6000","14.3717","14.3717","9.5811","41.0310","151.8149"
"57.6800","14.3908","14.3908","9.5939","41.0216","151.7798"
"57.7600","14.4108","14.4108","9.6072","41.0127","151.7471"
"57.8400","14.4305","14.4305","9.6203","41.0018","151.7068"
"57.9200","14.4503","14.4503","9.6335","40.9908","151.6661"
"58.0000","14.4705","14.4705","9.6470","40.9824","151.6350"
"58.0800","14.4894","14.4894","9.6596","40.9709","151.5922"
"58.1600","14.5108","14.5108","9.6739","40.9619","151.5592"
"58.2400","14.5314","14.5314","9.6876","40.9523","151.5237"
"58.3200","14.5507","14.5507","9.7004","40.9432","151.4897"
"58.4000","14.5704","14.5704","9.7136","40.9337","151.4546"
"58.4800","14.5897","14.5897","9.7265","40.9229","151.4148"
"58.5600","14.6111","14.6111","9.7407","40.9163","151.3903"
"58.6400","14.6312","14.6312","9.7541","40.9051","151.3490"
"58.7200","14.6502","14.6502","9.7668","40.8955","151.3134"
"58.8000","14.6705","14.6705","9.7803","40.8851","151.2748"
"58.8800","14.6914","14.6914","9.7943","40.8773","151.2460"
"58.9600","14.7112","14.7112","9.8075","40.8643","151.1980"
"59.0400","14.7309","14.7309","9.8206","40.8535","151.1580"
"59.1200","14.7495","14.7495","9.8330","40.8395","151.1060"
"59.2000","14.7705","14.7705","9.8470","40.8337","151.0846"
"59.2800","14.7901","14.7901","9.8601","40.8242","151.0496"
"59.3600","14.8096","14.8096","9.8731","40.8142","151.0126"
"59.4400","14.8308","14.8308","9.8872","40.8120","151.0045"
"59.5200","14.8513","14.8513","9.9009","40.8017","150.9664"
"59.6000","14.8710","14.8710","9.9140","40.7890","150.9193"
"59.6800","14.8909","14.8909","9.9272","40.7750","150.8675"
"59.7600","14.9096","14.9096","9.9397","40.7636","150.8254"
"59.8400","14.9307","14.9307","9.9538","40.7544","150.7911"
"59.9200","14.9503","14.9503","9.9669","40.7398","150.7374"
"60.0000","14.9705","14.9705","9.9803","40.7299","150.7005"
"60.0800","14.9915","14.9915","9.9943","40.7201","150.6645"
"60.1140","15.0001","15.0001","10.0001","40.7144","150.6432"