File: data/instron_tests/metamaterials/250416/250416_50-50_Composite.is_comp_Exports/250416_50-50_Composite_1_1.csv
Results Table 1
,Compresson Axis,H*,V*,Height,Thickness,Width,Area,Fixture separation,Specimen label
,,,,(mm),(mm),(mm),(mm^2),(mm),
"1","Y","","","150.00","28.00","150.00","4200.00","150.00","50/50 Composite"

Results Table 2
,Modulus (Segment 0 % - 2.5 %),Compresson Axis
,(kPa),
"1","2341.37","Y"

Time,Displacement,Force,Compressive displacement,Compressive strain (Displacement),Compressive stress
(s),(mm),(N),(mm),(%),(kPa)
"0.0000","0.0000","-0.8779","0.0000","0.0000","-0.2090"
"0.0800","0.0014","-0.7860","0.0014","0.0009","-0.1871"
"0.1600","0.0111","0.0779","0.0111","0.0074","0.0186"
"0.2400","0.0305","1.7025","0.0305","0.0203","0.4054"
"0.3200","0.0507","3.3486","0.0507","0.0338","0.7973"
"0.4000","0.0699","4.8540","0.0699","0.0466","1.1557"
"0.4800","0.0902","6.4646","0.0902","0.0601","1.5392"
"0.5600","0.1112","8.0912","0.1112","0.0742","1.9265"
"0.6400","0.1309","9.5812","0.1309","0.0873","2.2812"
"0.7200","0.1512","11.1099","0.1512","0.1008","2.6452"
"0.8000","0.1712","12.5903","0.1712","0.1141","2.9977"
"0.8800","0.1908","14.0500","0.1908","0.1272","3.3452"
"0.9600","0.2110","15.5288","0.2110","0.1407","3.6973"
"1.0400","0.2300","16.8810","0.2300","0.1533","4.0193"
"1.1200","0.2508","18.4010","0.2508","0.1672","4.3812"
"1.2000","0.2717","19.9083","0.2717","0.1811","4.7401"
"1.2800","0.2915","21.3222","0.2915","0.1943","5.0767"
"1.3600","0.3114","22.7176","0.3114","0.2076","5.4089"
"1.4400","0.3305","24.0229","0.3305","0.2204","5.7197"
"1.5200","0.3503","25.3555","0.3503","0.2336","6.0370"
"1.6000","0.3707","26.7869","0.3707","0.2472","6.3778"
"1.6800","0.3905","28.1658","0.3905","0.2604","6.7061"
"1.7600","0.4126","29.7137","0.4126","0.2751","7.0747"
"1.8400","0.4318","30.9788","0.4318","0.2878","7.3759"
"1.9200","0.4512","32.2871","0.4512","0.3008","7.6874"
"2.0000","0.4708","33.6152","0.4708","0.3139","8.0036"
"2.0800","0.4909","34.9655","0.4909","0.3273","8.3251"
"2.1600","0.5111","36.3406","0.5111","0.3407","8.6525"
"2.2400","0.5312","37.6732","0.5312","0.3541","8.9698"
"2.3200","0.5497","38.8956","0.5497","0.3665","9.2609"
"2.4000","0.5703","40.2582","0.5703","0.3802","9.5853"
"2.4800","0.5913","41.6579","0.5913","0.3942","9.9185"
"2.5600","0.6122","43.0481","0.6122","0.4081","10.2496"
"2.6400","0.6313","44.2422","0.6313","0.4208","10.5339"
"2.7200","0.6501","45.4323","0.6501","0.4334","10.8172"
"2.8000","0.6706","46.7836","0.6706","0.4471","11.1389"
"2.8800","0.6911","48.1276","0.6911","0.4608","11.4590"
"2.9600","0.7110","49.3921","0.7110","0.4740","11.7600"
"3.0400","0.7315","50.7103","0.7315","0.4877","12.0739"
"3.1200","0.7514","51.9332","0.7514","0.5009","12.3650"
"3.2000","0.7717","53.2175","0.7717","0.5145","12.6708"
"3.2800","0.7919","54.4538","0.7919","0.5279","12.9652"
"3.3600","0.8105","55.5547","0.8105","0.5403","13.2273"
"3.4400","0.8309","56.7737","0.8309","0.5539","13.5176"
"3.5200","0.8498","57.8591","0.8498","0.5665","13.7760"
"3.6000","0.8708","59.1520","0.8708","0.5805","14.0838"
"3.6800","0.8914","60.3838","0.8914","0.5943","14.3771"
"3.7600","0.9117","61.5263","0.9117","0.6078","14.6491"
"3.8400","0.9315","62.6006","0.9315","0.6210","14.9049"
"3.9200","0.9511","63.6744","0.9511","0.6341","15.1606"
"4.0000","0.9695","64.6678","0.9695","0.6463","15.3971"
"4.0800","0.9909","65.9317","0.9909","0.6606","15.6980"
"4.1600","1.0106","67.0215","1.0106","0.6738","15.9575"
"4.2400","1.0320","68.3077","1.0320","0.6880","16.2637"
"4.3200","1.0520","69.4733","1.0520","0.7013","16.5413"
"4.4000","1.0713","70.5729","1.0713","0.7142","16.8031"
"4.4800","1.0913","71.7563","1.0913","0.7276","17.0848"
"4.5600","1.1112","72.9069","1.1112","0.7408","17.3588"
"4.6400","1.1309","74.0136","1.1309","0.7540","17.6223"
"4.7200","1.1505","75.0981","1.1505","0.7670","17.8805"
"4.8000","1.1698","76.2174","1.1698","0.7799","18.1470"
"4.8800","1.1910","77.5594","1.1910","0.7940","18.4665"
"4.9600","1.2120","78.8515","1.2120","0.8080","18.7742"
"5.0400","1.2311","80.0235","1.2311","0.8207","19.0532"
"5.1200","1.2510","81.2416","1.2510","0.8340","19.3432"
"5.2000","1.2703","82.4121","1.2703","0.8468","19.6219"
"5.2800","1.2914","83.7486","1.2914","0.8609","19.9401"
"5.3600","1.3113","84.9726","1.3113","0.8742","20.2316"
"5.4400","1.3305","86.1440","1.3305","0.8870","20.5105"
"5.5200","1.3511","87.4565","1.3511","0.9007","20.8230"
"5.6000","1.3718","88.7511","1.3718","0.9145","21.1312"
"5.6800","1.3917","89.9867","1.3917","0.9278","21.4254"
"5.7600","1.4119","91.2372","1.4119","0.9413","21.7232"
"5.8400","1.4305","92.3418","1.4305","0.9537","21.9861"
"5.9200","1.4512","93.6492","1.4512","0.9675","22.2974"
"6.0000","1.4706","94.8271","1.4706","0.9804","22.5779"
"6.0800","1.4903","96.0747","1.4903","0.9935","22.8749"
"6.1600","1.5112","97.4241","1.5112","1.0074","23.1962"
"6.2400","1.5319","98.7263","1.5319","1.0212","23.5063"
"6.3200","1.5512","99.9262","1.5512","1.0341","23.7919"
"6.4000","1.5712","101.2073","1.5712","1.0475","24.0970"
"6.4800","1.5900","102.3837","1.5900","1.0600","24.3771"
"6.5600","1.6112","103.7757","1.6112","1.0741","24.7085"
"6.6400","1.6307","104.9717","1.6307","1.0871","24.9933"
"6.7200","1.6505","106.2502","1.6505","1.1004","25.2977"
"6.8000","1.6717","107.6448","1.6717","1.1144","25.6297"
"6.8800","1.6914","108.9059","1.6914","1.1276","25.9300"
"6.9600","1.7119","110.2441","1.7119","1.1413","26.2486"
"7.0400","1.7312","111.4655","1.7312","1.1541","26.5394"
"7.1200","1.7505","112.6791","1.7505","1.1670","26.8284"
"7.2000","1.7704","113.9665","1.7704","1.1803","27.1349"
"7.2800","1.7904","115.2395","1.7904","1.1936","27.4380"
"7.3600","1.8108","116.5898","1.8108","1.2072","27.7595"
"7.4400","1.8319","117.9827","1.8319","1.2213","28.0911"
"7.5200","1.8511","119.2027","1.8511","1.2341","28.3816"
"7.6000","1.8716","120.5477","1.8716","1.2477","28.7018"
"7.6800","1.8906","121.7458","1.8906","1.2604","28.9871"
"7.7600","1.9108","123.0965","1.9108","1.2739","29.3087"
"7.8400","1.9307","124.3930","1.9307","1.2871","29.6174"
"7.9200","1.9506","125.6751","1.9506","1.3004","29.9227"
"8.0000","1.9711","127.0415","1.9711","1.3141","30.2480"
"8.0800","1.9926","128.5037","1.9926","1.3284","30.5961"
"8.1600","2.0117","129.7443","2.0117","1.3412","30.8915"
"8.2400","2.0315","131.0393","2.0315","1.3543","31.1998"
"8.3200","2.0504","132.2582","2.0504","1.3669","31.4901"
"8.4000","2.0706","133.6082","2.0706","1.3804","31.8115"
"8.4800","2.0911","134.9892","2.0911","1.3941","32.1403"
"8.5600","2.1106","136.2577","2.1106","1.4070","32.4423"
"8.6400","2.1312","137.7316","2.1312","1.4208","32.7932"
"8.7200","2.1515","139.0713","2.1515","1.4343","33.1122"
"8.8000","2.1714","140.3953","2.1714","1.4476","33.4274"
"8.8800","2.1915","141.7632","2.1915","1.4610","33.7531"
"8.9600","2.2109","143.0262","2.2109","1.4740","34.0539"
"9.0400","2.2309","144.3819","2.2309","1.4873","34.3767"
"9.1200","2.2510","145.7239","2.2510","1.5007","34.6962"
"9.2000","2.2702","147.0164","2.2702","1.5135","35.0039"
"9.2800","2.2914","148.4438","2.2914","1.5276","35.3438"
"9.3600","2.3112","149.7583","2.3112","1.5408","35.6567"
"9.4400","2.3320","151.1652","2.3320","1.5546","35.9917"
"9.5200","2.3515","152.4795","2.3515","1.5677","36.3046"
"9.6000","2.3709","153.7682","2.3709","1.5806","36.6115"
"9.6800","2.3909","155.1414","2.3909","1.5939","36.9384"
"9.7600","2.4109","156.4974","2.4109","1.6073","37.2613"
"9.8400","2.4301","157.7828","2.4301","1.6201","37.5673"
"9.9200","2.4511","159.2415","2.4511","1.6340","37.9147"
"10.0000","2.4708","160.5322","2.4708","1.6472","38.2220"
"10.0800","2.4921","162.0110","2.4921","1.6614","38.5741"
"10.1600","2.5113","163.2800","2.5113","1.6742","38.8762"
"10.2400","2.5305","164.5969","2.5305","1.6870","39.1897"
"10.3200","2.5501","165.9344","2.5501","1.7001","39.5082"
"10.4000","2.5706","167.4274","2.5706","1.7137","39.8637"
"10.4800","2.5912","168.8704","2.5912","1.7275","40.2072"
"10.5600","2.6126","170.3838","2.6126","1.7417","40.5676"
"10.6400","2.6314","171.6098","2.6314","1.7542","40.8595"
"10.7200","2.6513","172.9527","2.6513","1.7675","41.1792"
"10.8000","2.6709","174.2900","2.6709","1.7806","41.4976"
"10.8800","2.6910","175.7142","2.6910","1.7940","41.8367"
"10.9600","2.7114","177.1175","2.7114","1.8076","42.1708"
"11.0400","2.7298","178.3505","2.7298","1.8199","42.4644"
"11.1200","2.7507","179.8357","2.7507","1.8338","42.8180"
"11.2000","2.7715","181.3106","2.7715","1.8477","43.1692"
"11.2800","2.7917","182.7262","2.7917","1.8611","43.5062"
"11.3600","2.8113","184.0740","2.8113","1.8742","43.8271"
"11.4400","2.8307","185.3460","2.8307","1.8871","44.1300"
"11.5200","2.8503","186.7243","2.8503","1.9002","44.4582"
"11.6000","2.8710","188.1969","2.8710","1.9140","44.8088"
"11.6800","2.8902","189.5186","2.8902","1.9268","45.1235"
"11.7600","2.9119","191.0787","2.9119","1.9413","45.4949"
"11.8400","2.9318","192.4606","2.9318","1.9545","45.8240"
"11.9200","2.9518","193.8651","2.9518","1.9679","46.1584"
"12.0000","2.9710","195.1723","2.9710","1.9806","46.4696"
"12.0800","2.9907","196.5372","2.9907","1.9938","46.7946"
"12.1600","3.0113","197.9925","3.0113","2.0075","47.1411"
"12.2400","3.0311","199.3882","3.0311","2.0207","47.4734"
"12.3200","3.0497","200.6732","3.0497","2.0332","47.7793"
"12.4000","3.0708","202.1762","3.0708","2.0472","48.1372"
"12.4800","3.0914","203.6203","3.0914","2.0609","48.4810"
"12.5600","3.1117","205.0774","3.1117","2.0745","48.8280"
"12.6400","3.1313","206.4282","3.1313","2.0875","49.1496"
"12.7200","3.1500","207.7085","3.1500","2.1000","49.4544"
"12.8000","3.1707","209.1842","3.1707","2.1138","49.8058"
"12.8800","3.1909","210.6286","3.1909","2.1273","50.1497"
"12.9600","3.2111","212.0399","3.2111","2.1407","50.4857"
"13.0400","3.2316","213.5010","3.2316","2.1544","50.8336"
"13.1200","3.2513","214.8573","3.2513","2.1675","51.1565"
"13.2000","3.2716","216.3329","3.2716","2.1811","51.5078"
"13.2800","3.2921","217.7829","3.2921","2.1947","51.8531"
"13.3600","3.3110","219.0983","3.3110","2.2073","52.1663"
"13.4400","3.3309","220.4960","3.3309","2.2206","52.4990"
"13.5200","3.3496","221.7815","3.3496","2.2330","52.8051"
"13.6000","3.3706","223.3224","3.3706","2.2471","53.1720"
"13.6800","3.3918","224.8574","3.3918","2.2612","53.5375"
"13.7600","3.4118","226.2307","3.4118","2.2745","53.8645"
"13.8400","3.4313","227.5958","3.4313","2.2876","54.1895"
"13.9200","3.4512","229.0009","3.4512","2.3008","54.5240"
"14.0000","3.4700","230.3214","3.4700","2.3134","54.8384"
"14.0800","3.4909","231.8381","3.4909","2.3272","55.1996"
"14.1600","3.5102","233.1762","3.5102","2.3401","55.5181"
"14.2400","3.5316","234.7563","3.5316","2.3544","55.8944"
"14.3200","3.5523","236.2286","3.5523","2.3682","56.2449"
"14.4000","3.5714","237.5507","3.5714","2.3809","56.5597"
"14.4800","3.5908","238.9030","3.5908","2.3939","56.8817"
"14.5600","3.6106","240.2919","3.6106","2.4071","57.2124"
"14.6400","3.6309","241.7569","3.6309","2.4206","57.5612"
"14.7200","3.6505","243.1409","3.6505","2.4337","57.8907"
"14.8000","3.6698","244.4797","3.6698","2.4465","58.2094"
"14.8800","3.6905","245.9912","3.6905","2.4603","58.5693"
"14.9600","3.7117","247.5264","3.7117","2.4745","58.9348"
"15.0400","3.7312","248.9009","3.7312","2.4874","59.2621"
"15.1200","3.7510","250.2926","3.7510","2.5007","59.5935"
"15.2000","3.7698","251.5720","3.7698","2.5132","59.8981"
"15.2800","3.7909","253.1193","3.7909","2.5273","60.2665"
"15.3600","3.8112","254.5576","3.8112","2.5408","60.6090"
"15.4400","3.8307","255.9302","3.8307","2.5538","60.9358"
"15.5200","3.8512","257.4107","3.8512","2.5675","61.2883"
"15.6000","3.8719","258.8876","3.8719","2.5812","61.6399"
"15.6800","3.8916","260.2864","3.8916","2.5944","61.9729"
"15.7600","3.9119","261.7356","3.9119","2.6079","62.3180"
"15.8400","3.9304","263.0002","3.9304","2.6203","62.6191"
"15.9200","3.9511","264.5065","3.9511","2.6341","62.9777"
"16.0000","3.9706","265.8710","3.9706","2.6471","63.3026"
"16.0800","3.9905","267.2978","3.9905","2.6603","63.6423"
"16.1600","4.0112","268.7897","4.0112","2.6741","63.9976"
"16.2400","4.0314","270.2150","4.0314","2.6876","64.3369"
"16.3200","4.0513","271.6079","4.0513","2.7009","64.6686"
"16.4000","4.0711","273.0182","4.0711","2.7141","65.0043"
"16.4800","4.0900","274.3275","4.0900","2.7267","65.3161"
"16.5600","4.1109","275.8472","4.1109","2.7406","65.6779"
"16.6400","4.1307","277.2199","4.1307","2.7538","66.0047"
"16.7200","4.1510","278.6887","4.1510","2.7673","66.3545"
"16.8000","4.1717","280.1660","4.1717","2.7811","66.7062"
"16.8800","4.1916","281.5770","4.1916","2.7944","67.0421"
"16.9600","4.2119","283.0093","4.2119","2.8079","67.3832"
"17.0400","4.2315","284.3992","4.2315","2.8210","67.7141"
"17.1200","4.2506","285.7365","4.2506","2.8337","68.0325"
"17.2000","4.2701","287.1269","4.2701","2.8468","68.3636"
"17.2800","4.2896","288.4796","4.2896","2.8597","68.6856"
"17.3600","4.3103","290.0175","4.3103","2.8735","69.0518"
"17.4400","4.3325","291.6651","4.3325","2.8883","69.4441"
"17.5200","4.3512","292.9284","4.3512","2.9008","69.7449"
"17.6000","4.3713","294.3620","4.3713","2.9142","70.0862"
"17.6800","4.3905","295.7090","4.3905","2.9270","70.4069"
"17.7600","4.4113","297.2383","4.4113","2.9409","70.7710"
"17.8400","4.4306","298.5959","4.4306","2.9537","71.0943"
"17.9200","4.4503","299.9891","4.4503","2.9669","71.4260"
"18.0000","4.4709","301.4853","4.4709","2.9806","71.7822"
"18.0800","4.4926","303.0983","4.4926","2.9951","72.1663"
"18.1600","4.5117","304.4248","4.5117","3.0078","72.4821"
"18.2400","4.5315","305.8239","4.5315","3.0210","72.8152"
"18.3200","4.5500","307.0807","4.5500","3.0333","73.1145"
"18.4000","4.5709","308.6335","4.5709","3.0473","73.4842"
"18.4800","4.5909","310.0694","4.5909","3.0606","73.8260"
"18.5600","4.6102","311.4314","4.6102","3.0734","74.1503"
"18.6400","4.6309","312.9415","4.6309","3.0873","74.5099"
"18.7200","4.6515","314.4350","4.6515","3.1010","74.8655"
"18.8000","4.6713","315.8425","4.6713","3.1142","75.2006"
"18.8800","4.6913","317.2943","4.6913","3.1276","75.5463"
"18.9600","4.7106","318.6306","4.7106","3.1404","75.8644"
"19.0400","4.7309","320.1028","4.7309","3.1539","76.2149"
"19.1200","4.7512","321.5529","4.7512","3.1674","76.5602"
"19.2000","4.7705","322.9378","4.7705","3.1803","76.8900"
"19.2800","4.7916","324.4813","4.7916","3.1944","77.2574"
"19.3600","4.8118","325.9233","4.8118","3.2079","77.6008"
"19.4400","4.8322","327.3910","4.8322","3.2215","77.9502"
"19.5200","4.8515","328.7449","4.8515","3.2343","78.2726"
"19.6000","4.8709","330.1139","4.8709","3.2472","78.5985"
"19.6800","4.8907","331.5382","4.8907","3.2605","78.9377"
"19.7600","4.9106","332.9499","4.9106","3.2737","79.2738"
"19.8400","4.9304","334.4319","4.9304","3.2870","79.6266"
"19.9200","4.9514","335.9509","4.9514","3.3009","79.9883"
"20.0000","4.9707","337.2948","4.9707","3.3138","80.3083"
"20.0800","4.9920","338.8428","4.9920","3.3280","80.6769"
"20.1600","5.0116","340.2149","5.0116","3.3410","81.0035"
"20.2400","5.0304","341.5263","5.0304","3.3536","81.3158"
"20.3200","5.0500","342.9180","5.0500","3.3667","81.6471"
"20.4000","5.0704","344.3730","5.0704","3.3803","81.9936"
"20.4800","5.0913","345.8997","5.0913","3.3942","82.3571"
"20.5600","5.1125","347.4449","5.1125","3.4083","82.7250"
"20.6400","5.1312","348.7056","5.1312","3.4208","83.0252"
"20.7200","5.1514","350.1607","5.1514","3.4342","83.3716"
"20.8000","5.1710","351.5388","5.1710","3.4473","83.6997"
"20.8800","5.1907","352.9669","5.1907","3.4605","84.0397"
"20.9600","5.2108","354.4055","5.2108","3.4739","84.3823"
"21.0400","5.2299","355.7372","5.2299","3.4866","84.6993"
"21.1200","5.2510","357.2905","5.2510","3.5007","85.0692"
"21.2000","5.2715","358.7781","5.2715","3.5144","85.4234"
"21.2800","5.2915","360.1930","5.2915","3.5277","85.7602"
"21.3600","5.3116","361.6133","5.3116","3.5411","86.0984"
"21.4400","5.3306","362.9099","5.3306","3.5537","86.4071"
"21.5200","5.3499","364.2895","5.3499","3.5666","86.7356"
"21.6000","5.3707","365.8000","5.3707","3.5805","87.0953"
"21.6800","5.3903","367.1823","5.3903","3.5935","87.4244"
"21.7600","5.4120","368.7815","5.4120","3.6080","87.8051"
"21.8400","5.4320","370.2165","5.4320","3.6213","88.1468"
"21.9200","5.4515","371.5746","5.4515","3.6343","88.4701"
"22.0000","5.4710","372.9369","5.4710","3.6473","88.7945"
"22.0800","5.4909","374.3354","5.4909","3.6606","89.1275"
"22.1600","5.5112","375.8005","5.5112","3.6741","89.4763"
"22.2400","5.5305","377.1523","5.5305","3.6870","89.7982"
"22.3200","5.5496","378.4962","5.5496","3.6997","90.1182"
"22.4000","5.5711","380.0852","5.5711","3.7140","90.4965"
"22.4800","5.5916","381.5417","5.5916","3.7278","90.8433"
"22.5600","5.6120","382.9984","5.6120","3.7414","91.1901"
"22.6400","5.6315","384.3496","5.6315","3.7543","91.5118"
"22.7200","5.6502","385.6406","5.6502","3.7668","91.8192"
"22.8000","5.6703","387.0781","5.6703","3.7802","92.1614"
"22.8800","5.6909","388.5684","5.6909","3.7939","92.5163"
"22.9600","5.7111","390.0286","5.7111","3.8074","92.8640"
"23.0400","5.7315","391.4842","5.7315","3.8210","93.2105"
"23.1200","5.7512","392.8401","5.7512","3.8341","93.5333"
"23.2000","5.7718","394.3413","5.7718","3.8478","93.8908"
"23.2800","5.7920","395.7659","5.7920","3.8613","94.2300"
"23.3600","5.8108","397.0659","5.8108","3.8738","94.5395"
"23.4400","5.8309","398.4828","5.8309","3.8872","94.8769"
"23.5200","5.8497","399.7736","5.8497","3.8998","95.1842"
"23.6000","5.8710","401.3482","5.8710","3.9140","95.5591"
"23.6800","5.8916","402.8298","5.8916","3.9277","95.9119"
"23.7600","5.9118","404.2932","5.9118","3.9412","96.2603"
"23.8400","5.9315","405.6657","5.9315","3.9544","96.5871"
"23.9200","5.9511","407.0266","5.9511","3.9674","96.9111"
"24.0000","5.9700","408.3437","5.9700","3.9800","97.2247"
"24.0800","5.9907","409.8293","5.9907","3.9938","97.5784"
"24.1600","6.0103","411.1853","6.0103","4.0069","97.9013"
"24.2400","6.0314","412.7157","6.0314","4.0210","98.2656"
"24.3200","6.0520","414.1645","6.0520","4.0347","98.6106"
"24.4000","6.0718","415.5489","6.0718","4.0479","98.9402"
"24.4800","6.0908","416.8471","6.0908","4.0605","99.2493"
"24.5600","6.1109","418.2800","6.1109","4.0739","99.5905"
"24.6400","6.1311","419.6985","6.1311","4.0874","99.9282"
"24.7200","6.1509","421.1027","6.1509","4.1006","100.2626"
"24.8000","6.1697","422.3541","6.1697","4.1131","100.5605"
"24.8800","6.1907","423.8755","6.1907","4.1271","100.9227"
"24.9600","6.2121","425.4079","6.2121","4.1414","101.2876"
"25.0400","6.2312","426.7012","6.2312","4.1541","101.5955"
"25.1200","6.2509","428.0702","6.2509","4.1672","101.9215"
"25.2000","6.2701","429.3872","6.2701","4.1801","102.2350"
"25.2800","6.2909","430.8794","6.2909","4.1939","102.5903"
"25.3600","6.3112","432.3110","6.3112","4.2074","102.9312"
"25.4400","6.3309","433.6771","6.3309","4.2206","103.2564"
"25.5200","6.3508","435.0724","6.3508","4.2339","103.5887"
"25.6000","6.3721","436.6031","6.3721","4.2481","103.9531"
"25.6800","6.3917","437.9471","6.3917","4.2611","104.2731"
"25.7600","6.4115","439.3193","6.4115","4.2743","104.5998"
"25.8400","6.4302","440.5753","6.4302","4.2868","104.8989"
"25.9200","6.4512","442.0997","6.4512","4.3008","105.2618"
"26.0000","6.4705","443.4045","6.4705","4.3137","105.5725"
"26.0800","6.4904","444.8214","6.4904","4.3270","105.9099"
"26.1600","6.5113","446.2987","6.5113","4.3408","106.2616"
"26.2400","6.5317","447.7176","6.5317","4.3544","106.5994"
"26.3200","6.5515","449.0784","6.5515","4.3677","106.9234"
"26.4000","6.5714","450.4506","6.5714","4.3809","107.2501"
"26.4800","6.5903","451.7259","6.5903","4.3935","107.5538"
"26.5600","6.6107","453.1670","6.6107","4.4071","107.8969"
"26.6400","6.6306","454.5403","6.6306","4.4204","108.2239"
"26.7200","6.6509","455.9871","6.6509","4.4340","108.5683"
"26.8000","6.6718","457.4529","6.6718","4.4479","108.9174"
"26.8800","6.6920","458.8289","6.6920","4.4613","109.2450"
"26.9600","6.7118","460.1850","6.7118","4.4746","109.5679"
"27.0400","6.7313","461.5154","6.7313","4.4875","109.8846"
"27.1200","6.7509","462.8700","6.7509","4.5006","110.2071"
"27.2000","6.7705","464.2091","6.7705","4.5137","110.5260"
"27.2800","6.7897","465.4977","6.7897","4.5265","110.8328"
"27.3600","6.8105","466.9778","6.8105","4.5404","111.1852"
"27.4400","6.8320","468.5114","6.8320","4.5547","111.5503"
"27.5200","6.8511","469.7846","6.8511","4.5674","111.8535"
"27.6000","6.8711","471.1535","6.8711","4.5808","112.1794"
"27.6800","6.8903","472.4525","6.8903","4.5936","112.4887"
"27.7600","6.9113","473.9388","6.9113","4.6075","112.8426"
"27.8400","6.9305","475.2415","6.9305","4.6203","113.1527"
"27.9200","6.9502","476.5656","6.9502","4.6335","113.4680"
"28.0000","6.9709","478.0268","6.9709","4.6473","113.8159"
"28.0800","6.9927","479.5807","6.9927","4.6618","114.1859"
"28.1600","7.0121","480.8838","7.0121","4.6748","114.4961"
"28.2400","7.0313","482.1403","7.0313","4.6875","114.7953"
"28.3200","7.0503","483.3911","7.0503","4.7002","115.0931"
"28.4000","7.0710","484.8508","7.0710","4.7140","115.4407"
"28.4800","7.0909","486.2036","7.0909","4.7273","115.7628"
"28.5600","7.1100","487.4731","7.1100","4.7400","116.0650"
"28.6400","7.1309","488.9251","7.1309","4.7540","116.4107"
"28.7200","7.1513","490.3188","7.1513","4.7675","116.7426"
"28.8000","7.1712","491.6606","7.1712","4.7808","117.0620"
"28.8800","7.1912","493.0185","7.1912","4.7942","117.3854"
"28.9600","7.2107","494.2975","7.2107","4.8072","117.6899"
"29.0400","7.2311","495.6868","7.2311","4.8207","118.0207"
"29.1200","7.2509","497.0009","7.2509","4.8340","118.3335"
"29.2000","7.2701","498.2772","7.2701","4.8468","118.6374"
"29.2800","7.2917","499.7836","7.2917","4.8611","118.9961"
"29.3600","7.3123","501.2068","7.3123","4.8748","119.3349"
"29.4400","7.3325","502.5500","7.3325","4.8883","119.6548"
"29.5200","7.3513","503.7537","7.3513","4.9009","119.9413"
"29.6000","7.3704","504.9881","7.3704","4.9136","120.2353"
"29.6800","7.3909","506.3714","7.3909","4.9273","120.5646"
"29.7600","7.4108","507.6639","7.4108","4.9405","120.8724"
"29.8400","7.4301","508.9361","7.4301","4.9534","121.1753"
"29.9200","7.4512","510.3909","7.4512","4.9674","121.5217"
"30.0000","7.4709","511.6656","7.4709","4.9806","121.8251"
"30.0800","7.4920","513.0880","7.4920","4.9946","122.1638"
"30.1600","7.5114","514.3483","7.5114","5.0076","122.4639"
"30.2400","7.5308","515.5967","7.5308","5.0205","122.7611"
"30.3200","7.5502","516.8435","7.5502","5.0334","123.0580"
"30.4000","7.5701","518.1414","7.5701","5.0467","123.3670"
"30.4800","7.5912","519.5900","7.5912","5.0608","123.7119"
"30.5600","7.6120","520.9753","7.6120","5.0747","124.0417"
"30.6400","7.6319","522.2454","7.6319","5.0880","124.3441"
"30.7200","7.6517","523.5385","7.6517","5.1011","124.6520"
"30.8000","7.6711","524.7543","7.6711","5.1140","124.9415"
"30.8800","7.6906","526.0209","7.6906","5.1270","125.2431"
"30.9600","7.7111","527.3589","7.7111","5.1407","125.5616"
"31.0400","7.7296","528.4763","7.7296","5.1531","125.8277"
"31.1200","7.7512","529.9491","7.7512","5.1675","126.1784"
"31.2000","7.7717","531.2742","7.7717","5.1811","126.4939"
"31.2800","7.7916","532.5223","7.7916","5.1944","126.7910"
"31.3600","7.8115","533.8005","7.8115","5.2077","127.0954"
"31.4400","7.8307","534.9766","7.8307","5.2205","127.3754"
"31.5200","7.8504","536.2349","7.8504","5.2336","127.6750"
"31.6000","7.8706","537.5224","7.8706","5.2471","127.9815"
"31.6800","7.8902","538.7491","7.8902","5.2601","128.2736"
"31.7600","7.9123","540.2460","7.9123","5.2748","128.6300"
"31.8400","7.9319","541.4463","7.9319","5.2879","128.9158"
"31.9200","7.9520","542.7184","7.9520","5.3013","129.2187"
"32.0000","7.9709","543.8532","7.9709","5.3139","129.4889"
"32.0800","7.9909","545.0880","7.9909","5.3272","129.7828"
"32.1600","8.0111","546.3698","8.0111","5.3408","130.0880"
"32.2400","8.0310","547.5728","8.0310","5.3540","130.3745"
"32.3200","8.0492","548.6435","8.0492","5.3662","130.6294"
"32.4000","8.0707","550.0471","8.0707","5.3805","130.9636"
"32.4800","8.0912","551.3096","8.0912","5.3942","131.2642"
"32.5600","8.1118","552.5754","8.1118","5.4079","131.5656"
"32.6400","8.1317","553.7749","8.1317","5.4211","131.8512"
"32.7200","8.1502","554.8317","8.1502","5.4335","132.1028"
"32.8000","8.1704","556.0673","8.1704","5.4470","132.3970"
"32.8800","8.1909","557.3331","8.1909","5.4606","132.6984"
"32.9600","8.2112","558.5611","8.2112","5.4741","132.9907"
"33.0400","8.2312","559.7566","8.2312","5.4875","133.2754"
"33.1200","8.2513","560.9287","8.2513","5.5009","133.5545"
"33.2000","8.2717","562.1613","8.2717","5.5145","133.8479"
"33.2800","8.2919","563.3423","8.2919","5.5279","134.1291"
"33.3600","8.3107","564.4063","8.3107","5.5405","134.3825"
"33.4400","8.3308","565.5914","8.3308","5.5539","134.6646"
"33.5200","8.3496","566.6228","8.3496","5.5664","134.9102"
"33.6000","8.3706","567.9033","8.3706","5.5804","135.2151"
"33.6800","8.3909","569.1275","8.3909","5.5939","135.5066"
"33.7600","8.4119","570.3698","8.4119","5.6079","135.8023"
"33.8400","8.4315","571.4412","8.4315","5.6210","136.0574"
"33.9200","8.4513","572.5622","8.4513","5.6342","136.3243"
"34.0000","8.4705","573.6181","8.4705","5.6470","136.5757"
"34.0800","8.4910","574.8102","8.4910","5.6607","136.8596"
"34.1600","8.5102","575.8324","8.5102","5.6735","137.1029"
"34.2400","8.5318","577.1165","8.5318","5.6878","137.4087"
"34.3200","8.5520","578.2172","8.5520","5.7013","137.6708"
"34.4000","8.5718","579.3083","8.5718","5.7145","137.9305"
"34.4800","8.5912","580.3320","8.5912","5.7275","138.1743"
"34.5600","8.6109","581.3826","8.6109","5.7406","138.4244"
"34.6400","8.6307","582.4662","8.6307","5.7538","138.6824"
"34.7200","8.6507","583.5359","8.6507","5.7671","138.9371"
"34.8000","8.6699","584.5139","8.6699","5.7799","139.1700"
"34.8800","8.6910","585.7058","8.6910","5.7940","139.4538"
"34.9600","8.7121","586.8556","8.7121","5.8081","139.7275"
"35.0400","8.7315","587.8303","8.7315","5.8210","139.9596"
"35.1200","8.7512","588.8260","8.7512","5.8341","140.1967"
"35.2000","8.7702","589.7574","8.7702","5.8468","140.4184"
"35.2800","8.7911","590.8773","8.7911","5.8607","140.6851"
"35.3600","8.8108","591.8716","8.8108","5.8739","140.9218"
"35.4400","8.8305","592.8440","8.8305","5.8870","141.1533"
"35.5200","8.8510","593.9020","8.8510","5.9006","141.4053"
"35.6000","8.8719","594.9820","8.8719","5.9146","141.6624"
"35.6800","8.8916","595.9354","8.8916","5.9277","141.8894"
"35.7600","8.9117","596.9149","8.9117","5.9411","142.1226"
"35.8400","8.9302","597.7297","8.9302","5.9535","142.3166"
"35.9200","8.9505","598.7335","8.9505","5.9670","142.5556"
"36.0000","8.9704","599.6847","8.9704","5.9803","142.7821"
"36.0800","8.9907","600.6902","8.9907","5.9938","143.0215"
"36.1600","9.0113","601.7126","9.0113","6.0076","143.2649"
"36.2400","9.0316","602.6190","9.0316","6.0210","143.4807"
"36.3200","9.0515","603.5286","9.0515","6.0343","143.6973"
"36.4000","9.0711","604.4107","9.0711","6.0474","143.9073"
"36.4800","9.0904","605.2384","9.0904","6.0603","144.1044"
"36.5600","9.1109","606.1630","9.1109","6.0739","144.3245"
"36.6400","9.1303","606.9693","9.1303","6.0869","144.5165"
"36.7200","9.1510","607.9337","9.1510","6.1007","144.7461"
"36.8000","9.1719","608.8929","9.1719","6.1146","144.9745"
"36.8800","9.1917","609.7018","9.1917","6.1278","145.1671"
"36.9600","9.2122","610.5761","9.2122","6.1415","145.3753"
"37.0400","9.2316","611.3412","9.2316","6.1544","145.5574"
"37.1200","9.2509","612.1029","9.2509","6.1672","145.7388"
"37.2000","9.2702","612.8508","9.2702","6.1801","145.9168"
"37.2800","9.2898","613.6049","9.2898","6.1932","146.0964"
"37.3600","9.3106","614.4940","9.3106","6.2071","146.3081"
"37.4400","9.3323","615.4226","9.3323","6.2215","146.5292"
"37.5200","9.3512","616.0687","9.3512","6.2342","146.6830"
"37.6000","9.3713","616.8233","9.3713","6.2475","146.8627"
"37.6800","9.3906","617.5102","9.3906","6.2604","147.0262"
"37.7600","9.4110","618.2899","9.4110","6.2740","147.2119"
"37.8400","9.4303","618.9629","9.4303","6.2869","147.3721"
"37.9200","9.4502","619.6519","9.4502","6.3001","147.5362"
"38.0000","9.4711","620.4339","9.4711","6.3140","147.7224"
"38.0800","9.4927","621.2735","9.4927","6.3285","147.9223"
"38.1600","9.5116","621.8287","9.5116","6.3411","148.0545"
"38.2400","9.5305","622.3796","9.5305","6.3537","148.1856"
"38.3200","9.5503","622.9992","9.5503","6.3668","148.3331"
"38.4000","9.5709","623.7252","9.5709","6.3806","148.5060"
"38.4800","9.5912","624.3760","9.5912","6.3941","148.6609"
"38.5600","9.6103","624.9210","9.6103","6.4069","148.7907"
"38.6400","9.6312","625.5880","9.6312","6.4208","148.9495"
"38.7200","9.6515","626.2077","9.6515","6.4343","149.0971"
"38.8000","9.6712","626.7479","9.6712","6.4475","149.2257"
"38.8800","9.6912","627.3153","9.6912","6.4608","149.3608"
"38.9600","9.7109","627.8227","9.7109","6.4739","149.4816"
"39.0400","9.7310","628.3847","9.7310","6.4874","149.6154"
"39.1200","9.7508","628.8658","9.7508","6.5006","149.7300"
"39.2000","9.7702","629.3470","9.7702","6.5134","149.8445"
"39.2800","9.7913","629.9490","9.7913","6.5275","149.9879"
"39.3600","9.8118","630.4664","9.8118","6.5412","150.1110"
"39.4400","9.8325","630.9697","9.8325","6.5550","150.2309"
"39.5200","9.8509","631.2935","9.8509","6.5673","150.3080"
"39.6000","9.8708","631.7341","9.8708","6.5805","150.4129"
"39.6800","9.8906","632.1498","9.8906","6.5937","150.5118"
"39.7600","9.9107","632.5828","9.9107","6.6071","150.6149"
"39.8400","9.9301","632.9323","9.9301","6.6201","150.6982"
"39.9200","9.9516","633.4741","9.9516","6.6344","150.8272"
"40.0000","9.9712","633.7978","9.9712","6.6475","150.9042"
"40.0800","9.9920","634.2214","9.9920","6.6613","151.0051"
"40.1600","10.0113","634.5048","10.0113","6.6742","151.0726"
"40.2400","10.0306","634.7950","10.0306","6.6871","151.1417"
"40.3200","10.0501","635.0836","10.0501","6.7001","151.2104"
"40.4000","10.0700","635.3960","10.0700","6.7134","151.2848"
"40.4800","10.0907","635.7885","10.0907","6.7271","151.3782"
"40.5600","10.1128","636.2669","10.1128","6.7419","151.4921"
"40.6400","10.1319","636.4240","10.1319","6.7546","151.5295"
"40.7200","10.1511","636.6072","10.1511","6.7674","151.5731"
"40.8000","10.1712","636.8671","10.1712","6.7808","151.6350"
"40.8800","10.1910","637.1166","10.1910","6.7940","151.6944"
"40.9600","10.2112","637.3585","10.2112","6.8075","151.7520"
"41.0400","10.2300","637.4571","10.2300","6.8200","151.7755"
"41.1200","10.2507","637.7360","10.2507","6.8338","151.8419"
"41.2000","10.2714","637.9828","10.2714","6.8476","151.9007"
"41.2800","10.2919","638.2042","10.2919","6.8613","151.9534"
"41.3600","10.3117","638.3474","10.3117","6.8745","151.9875"
"41.4400","10.3310","638.4030","10.3310","6.8873","152.0007"
"41.5200","10.3502","638.5007","10.3502","6.9001","152.0240"
"41.6000","10.3707","638.6743","10.3707","6.9138","152.0653"
"41.6800","10.3899","638.7234","10.3899","6.9266","152.0770"
"41.7600","10.4119","638.9937","10.4119","6.9413","152.1413"
"41.8400","10.4320","639.0674","10.4320","6.9546","152.1589"
"41.9200","10.4520","639.1400","10.4520","6.9680","152.1762"
"42.0000","10.4707","639.1072","10.4707","6.9805","152.1684"
"42.0800","10.4909","639.1842","10.4909","6.9939","152.1867"
"42.1600","10.5111","639.2438","10.5111","7.0074","152.2009"
"42.2400","10.5313","639.3077","10.5313","7.0208","152.2161"
"42.3200","10.5502","639.2747","10.5502","7.0335","152.2083"
"42.4000","10.5706","639.3266","10.5706","7.0471","152.2206"
"42.4800","10.5914","639.3674","10.5914","7.0609","152.2303"
"42.5600","10.6123","639.4315","10.6123","7.0749","152.2456"
"42.6400","10.6313","639.3137","10.6313","7.0875","152.2176"
"42.7200","10.6503","639.2302","10.6503","7.1002","152.1977"
"42.8000","10.6707","639.2153","10.6707","7.1138","152.1941"
"42.8800","10.6903","639.1537","10.6903","7.1269","152.1795"
"42.9600","10.7108","639.1712","10.7108","7.1405","152.1836"
"43.0400","10.7323","639.2106","10.7323","7.1548","152.1930"
"43.1200","10.7514","639.0209","10.7514","7.1676","152.1478"
"43.2000","10.7717","638.9851","10.7717","7.1811","152.1393"
"43.2800","10.7926","638.9315","10.7926","7.1951","152.1266"
"43.3600","10.8108","638.6944","10.8108","7.2072","152.0701"
"43.4400","10.8308","638.5730","10.8308","7.2205","152.0412"
"43.5200","10.8497","638.3498","10.8497","7.2331","151.9880"
"43.6000","10.8709","638.3265","10.8709","7.2473","151.9825"
"43.6800","10.8911","638.2159","10.8911","7.2607","151.9562"
"43.7600","10.9121","638.1219","10.9121","7.2747","151.9338"
"43.8400","10.9315","637.8972","10.9315","7.2877","151.8803"
"43.9200","10.9512","637.6874","10.9512","7.3008","151.8303"
"44.0000","10.9700","637.4322","10.9700","7.3133","151.7696"
"44.0800","10.9904","637.2890","10.9904","7.3269","151.7355"
"44.1600","11.0103","637.0817","11.0103","7.3402","151.6861"
"44.2400","11.0319","637.0018","11.0319","7.3546","151.6671"
"44.3200","11.0520","636.7709","11.0520","7.3680","151.6121"
"44.4000","11.0719","636.5654","11.0719","7.3813","151.5632"
"44.4800","11.0913","636.2753","11.0913","7.3942","151.4941"
"44.5600","11.1111","636.0302","11.1111","7.4074","151.4357"
"44.6400","11.1310","635.7867","11.1310","7.4207","151.3778"
"44.7200","11.1506","635.5093","11.1506","7.4337","151.3117"
"44.8000","11.1699","635.2339","11.1699","7.4466","151.2462"
"44.8800","11.1913","635.0751","11.1913","7.4609","151.2084"
"44.9600","11.2122","634.8447","11.2122","7.4748","151.1535"
"45.0400","11.2314","634.5219","11.2314","7.4876","151.0766"
"45.1200","11.2512","634.1981","11.2512","7.5008","150.9995"
"45.2000","11.2702","633.8445","11.2702","7.5135","150.9154"
"45.2800","11.2912","633.6242","11.2912","7.5274","150.8629"
"45.3600","11.3109","633.2926","11.3109","7.5406","150.7840"
"45.4400","11.3310","632.9836","11.3310","7.5540","150.7104"
"45.5200","11.3512","632.6747","11.3512","7.5675","150.6368"
"45.6000","11.3712","632.3373","11.3712","7.5808","150.5565"
"45.6800","11.3917","632.0527","11.3917","7.5945","150.4887"
"45.7600","11.4124","631.7659","11.4124","7.6083","150.4205"
"45.8400","11.4305","631.2799","11.4305","7.6204","150.3047"
"45.9200","11.4509","630.9571","11.4509","7.6339","150.2279"
"46.0000","11.4704","630.5925","11.4704","7.6469","150.1411"
"46.0800","11.4908","630.2796","11.4908","7.6605","150.0666"
"46.1600","11.5110","629.9252","11.5110","7.6740","149.9822"
"46.2400","11.5317","629.5790","11.5317","7.6878","149.8998"
"46.3200","11.5516","629.1715","11.5516","7.7011","149.8027"
"46.4000","11.5715","628.7743","11.5715","7.7143","149.7082"
"46.4800","11.5900","628.2841","11.5900","7.7266","149.5915"
"46.5600","11.6107","627.9415","11.6107","7.7404","149.5099"
"46.6400","11.6306","627.5215","11.6306","7.7538","149.4099"
"46.7200","11.6512","627.1664","11.6512","7.7675","149.3253"
"46.8000","11.6721","626.7941","11.6721","7.7814","149.2367"
"46.8800","11.6916","626.3137","11.6916","7.7944","149.1223"
"46.9600","11.7119","625.8824","11.7119","7.8079","149.0196"
"47.0400","11.7316","625.4181","11.7316","7.8211","148.9091"
"47.1200","11.7509","624.9260","11.7509","7.8339","148.7919"
"47.2000","11.7702","624.4359","11.7702","7.8468","148.6752"
"47.2800","11.7903","623.9739","11.7903","7.8602","148.5652"
"47.3600","11.8107","623.5486","11.8107","7.8738","148.4640"
"47.4400","11.8318","623.1165","11.8318","7.8879","148.3611"
"47.5200","11.8514","622.5853","11.8514","7.9010","148.2346"
"47.6000","11.8715","622.0942","11.8715","7.9144","148.1177"
"47.6800","11.8907","621.5009","11.8907","7.9271","147.9764"
"47.7600","11.9111","621.0266","11.9111","7.9408","147.8635"
"47.8400","11.9299","620.4321","11.9299","7.9533","147.7219"
"47.9200","11.9501","619.9412","11.9501","7.9668","147.6050"
"48.0000","11.9715","619.4799","11.9715","7.9810","147.4952"
"48.0800","11.9930","619.0152","11.9930","7.9954","147.3846"
"48.1600","12.0121","618.4109","12.0121","8.0081","147.2407"
"48.2400","12.0312","617.8021","12.0312","8.0208","147.0957"
"48.3200","12.0505","617.2045","12.0505","8.0336","146.9534"
"48.4000","12.0709","616.6857","12.0709","8.0473","146.8299"
"48.4800","12.0912","616.1207","12.0912","8.0608","146.6954"
"48.5600","12.1106","615.5310","12.1106","8.0737","146.5550"
"48.6400","12.1309","614.9503","12.1309","8.0873","146.4167"
"48.7200","12.1516","614.4195","12.1516","8.1011","146.2904"
"48.8000","12.1717","613.8169","12.1717","8.1145","146.1469"
"48.8800","12.1913","613.1933","12.1913","8.1275","145.9984"
"48.9600","12.2105","612.5345","12.2105","8.1403","145.8415"
"49.0400","12.2312","611.9602","12.2312","8.1541","145.7048"
"49.1200","12.2512","611.3168","12.2512","8.1675","145.5516"
"49.2000","12.2704","610.6436","12.2704","8.1802","145.3913"
"49.2800","12.2918","610.0696","12.2918","8.1946","145.2547"
"49.3600","12.3119","609.3876","12.3119","8.2079","145.0923"
"49.4400","12.3325","608.7422","12.3325","8.2217","144.9386"
"49.5200","12.3512","607.9995","12.3512","8.2341","144.7618"
"49.6000","12.3705","607.3014","12.3705","8.2470","144.5956"
"49.6800","12.3908","606.6371","12.3908","8.2606","144.4374"
"49.7600","12.4107","605.9285","12.4107","8.2738","144.2687"
"49.8400","12.4299","605.2133","12.4299","8.2866","144.0984"
"49.9200","12.4516","604.6019","12.4516","8.3011","143.9528"
"50.0000","12.4710","603.8294","12.4710","8.3140","143.7689"
"50.0800","12.4923","603.1693","12.4923","8.3282","143.6117"
"50.1600","12.5113","602.3644","12.5113","8.3409","143.4201"
"50.2400","12.5309","601.6525","12.5309","8.3539","143.2506"
"50.3200","12.5499","600.8617","12.5499","8.3666","143.0623"
"50.4000","12.5702","600.1401","12.5702","8.3801","142.8905"
"50.4800","12.5914","599.4791","12.5914","8.3943","142.7331"
"50.5600","12.6128","598.7817","12.6128","8.4085","142.5671"
"50.6400","12.6319","597.9533","12.6319","8.4213","142.3698"
"50.7200","12.6514","597.1355","12.6514","8.4343","142.1751"
"50.8000","12.6710","596.2970","12.6710","8.4474","141.9755"
"50.8800","12.6911","595.4724","12.6911","8.4608","141.7791"
"50.9600","12.7114","594.6490","12.7114","8.4743","141.5831"
"51.0400","12.7297","593.7256","12.7297","8.4864","141.3632"
"51.1200","12.7507","592.9399","12.7507","8.5004","141.1762"
"51.2000","12.7715","592.1466","12.7715","8.5143","140.9873"
"51.2800","12.7916","591.2938","12.7916","8.5277","140.7842"
"51.3600","12.8112","590.4285","12.8112","8.5408","140.5782"
"51.4400","12.8314","589.5651","12.8314","8.5543","140.3726"
"51.5200","12.8507","588.6787","12.8507","8.5672","140.1616"
"51.6000","12.8709","587.8007","12.8709","8.5806","139.9526"
"51.6800","12.8898","586.8323","12.8898","8.5932","139.7220"
"51.7600","12.9121","586.0306","12.9121","8.6081","139.5311"
"51.8400","12.9321","585.0696","12.9321","8.6214","139.3023"
"51.9200","12.9520","584.0849","12.9520","8.6347","139.0678"
"52.0000","12.9708","583.0695","12.9708","8.6472","138.8261"
"52.0800","12.9908","582.1096","12.9908","8.6606","138.5975"
"52.1600","13.0114","581.1519","13.0114","8.6743","138.3695"
"52.2400","13.0313","580.1494","13.0313","8.6875","138.1308"
"52.3200","13.0496","579.0923","13.0496","8.6997","137.8791"
"52.4000","13.0709","578.1436","13.0709","8.7139","137.6532"
"52.4800","13.0921","577.1400","13.0921","8.7280","137.4143"
"52.5600","13.1126","576.0566","13.1126","8.7417","137.1563"
"52.6400","13.1314","574.9089","13.1314","8.7543","136.8831"
"52.7200","13.1503","573.8113","13.1503","8.7669","136.6217"
"52.8000","13.1708","572.7583","13.1708","8.7805","136.3710"
"52.8800","13.1907","571.6802","13.1907","8.7938","136.1143"
"52.9600","13.2115","570.6317","13.2115","8.8077","135.8647"
"53.0400","13.2316","569.5095","13.2316","8.8210","135.5975"
"53.1200","13.2515","568.3189","13.2515","8.8343","135.3140"
"53.2000","13.2717","567.1896","13.2717","8.8478","135.0451"
"53.2800","13.2921","566.0647","13.2921","8.8614","134.7773"
"53.3600","13.3109","564.9183","13.3109","8.8739","134.5044"
"53.4400","13.3308","563.8082","13.3308","8.8872","134.2401"
"53.5200","13.3496","562.6337","13.3496","8.8997","133.9604"
"53.6000","13.3705","561.5272","13.3705","8.9136","133.6970"
"53.6800","13.3917","560.3320","13.3917","8.9278","133.4124"
"53.7600","13.4123","559.0322","13.4123","8.9415","133.1029"
"53.8400","13.4316","557.6965","13.4316","8.9544","132.7849"
"53.9200","13.4511","556.3709","13.4511","8.9674","132.4693"
"54.0000","13.4701","555.0453","13.4701","8.9801","132.1536"
"54.0800","13.4908","553.8383","13.4908","8.9939","131.8663"
"54.1600","13.5105","552.5780","13.5105","9.0070","131.5662"
"54.2400","13.5318","551.4100","13.5318","9.0212","131.2881"
"54.3200","13.5524","550.1743","13.5524","9.0350","130.9939"
"54.4000","13.5716","548.8941","13.5716","9.0478","130.6891"
"54.4800","13.5910","547.5945","13.5910","9.0607","130.3796"
"54.5600","13.6112","546.3368","13.6112","9.0741","130.0802"
"54.6400","13.6312","545.1132","13.6312","9.0875","129.7888"
"54.7200","13.6508","543.9023","13.6508","9.1005","129.5005"
"54.8000","13.6698","542.6920","13.6698","9.1132","129.2124"
"54.8800","13.6911","541.5636","13.6911","9.1274","128.9437"
"54.9600","13.7117","540.4144","13.7117","9.1411","128.6701"
"55.0400","13.7317","539.2638","13.7317","9.1545","128.3961"
"55.1200","13.7513","538.0441","13.7513","9.1675","128.1057"
"55.2000","13.7701","536.8608","13.7701","9.1800","127.8240"
"55.2800","13.7914","535.7817","13.7914","9.1943","127.5671"
"55.3600","13.8113","534.6369","13.8113","9.2075","127.2945"
"55.4400","13.8308","533.4221","13.8308","9.2205","127.0053"
"55.5200","13.8510","532.2107","13.8510","9.2340","126.7168"
"55.6000","13.8718","531.0363","13.8718","9.2479","126.4372"
"55.6800","13.8921","529.8678","13.8921","9.2614","126.1590"
"55.7600","13.9119","528.7101","13.9119","9.2746","125.8834"
"55.8400","13.9303","527.4921","13.9303","9.2869","125.5933"
"55.9200","13.9510","526.3022","13.9510","9.3006","125.3100"
"56.0000","13.9704","525.0738","13.9704","9.3136","125.0176"
"56.0800","13.9907","523.8697","13.9907","9.3272","124.7309"
"56.1600","14.0111","522.6327","14.0111","9.3408","124.4364"
"56.2400","14.0315","521.4092","14.0315","9.3544","124.1450"
"56.3200","14.0515","520.1893","14.0515","9.3676","123.8546"
"56.4000","14.0715","518.9952","14.0715","9.3810","123.5703"
"56.4800","14.0904","517.7388","14.0904","9.3936","123.2711"
"56.5600","14.1107","516.5010","14.1107","9.4071","122.9764"
"56.6400","14.1306","515.2440","14.1306","9.4204","122.6771"
"56.7200","14.1512","514.0348","14.1512","9.4341","122.3892"
"56.8000","14.1720","512.7409","14.1720","9.4480","122.0812"
"56.8800","14.1913","511.4027","14.1913","9.4609","121.7625"
"56.9600","14.2120","510.0447","14.2120","9.4747","121.4392"
"57.0400","14.2316","508.5865","14.2316","9.4877","121.0920"
"57.1200","14.2508","507.1841","14.2508","9.5005","120.7581"
"57.2000","14.2705","505.8662","14.2705","9.5137","120.4443"
"57.2800","14.2902","504.5320","14.2902","9.5268","120.1267"
"57.3600","14.3111","503.2170","14.3111","9.5407","119.8136"
"57.4400","14.3320","501.9115","14.3320","9.5546","119.5027"
"57.5200","14.3511","500.5283","14.3511","9.5674","119.1734"
"57.6000","14.3716","499.2146","14.3716","9.5811","118.8606"
"57.6800","14.3907","497.8571","14.3907","9.5938","118.5374"
"57.7600","14.4111","496.5740","14.4111","9.6074","118.2319"
"57.8400","14.4305","495.2360","14.4305","9.6203","117.9133"
"57.9200","14.4505","493.8762","14.4505","9.6337","117.5896"
"58.0000","14.4715","492.5175","14.4715","9.6477","117.2661"
"58.0800","14.4926","491.1307","14.4926","9.6617","116.9359"
"58.1600","14.5118","489.7495","14.5118","9.6746","116.6070"
"58.2400","14.5315","488.4062","14.5315","9.6876","116.2872"
"58.3200","14.5506","486.9584","14.5506","9.7004","115.9425"
"58.4000","14.5709","485.5328","14.5709","9.7140","115.6030"
"58.4800","14.5907","484.1662","14.5907","9.7272","115.2777"
"58.5600","14.6104","482.8769","14.6104","9.7402","114.9707"
"58.6400","14.6310","481.6455","14.6310","9.7540","114.6775"
"58.7200","14.6515","480.4641","14.6515","9.7676","114.3962"
"58.8000","14.6715","479.2705","14.6715","9.7810","114.1120"
"58.8800","14.6914","478.0340","14.6914","9.7943","113.8176"
"58.9600","14.7107","476.7017","14.7107","9.8071","113.5004"
"59.0400","14.7309","475.3753","14.7309","9.8206","113.1846"
"59.1200","14.7505","474.1246","14.7505","9.8336","112.8868"
"59.2000","14.7704","473.0199","14.7704","9.8469","112.6238"
"59.2800","14.7919","471.9749","14.7919","9.8613","112.3750"
"59.3600","14.8120","470.8675","14.8120","9.8746","112.1113"
"59.4400","14.8323","469.7530","14.8323","9.8882","111.8459"
"59.5200","14.8517","468.5648","14.8517","9.9011","111.5631"
"59.6000","14.8707","467.3188","14.8707","9.9138","111.2664"
"59.6800","14.8909","466.1743","14.8909","9.9272","110.9939"
"59.7600","14.9107","465.0987","14.9107","9.9405","110.7378"
"59.8400","14.9301","464.0568","14.9301","9.9534","110.4897"
"59.9200","14.9510","463.0790","14.9510","9.9673","110.2569"
"60.0000","14.9710","462.0565","14.9710","9.9807","110.0135"
"60.0800","14.9923","461.0556","14.9923","9.9949","109.7751"
"60.1140","15.0002","460.6009","15.0002","10.0001","109.6669"