File: data/instron_tests/metamaterials/250416/250416_50-50_Composite.is_comp_Exports/250416_50-50_Composite_3_1.csv
Results Table 1
,Compresson Axis,H*,V*,Height,Thickness,Width,Area,Fixture separation,Specimen label
,,,,(mm),(mm),(mm),(mm^2),(mm),
"3","Y","","","150.00","28.00","150.00","4200.00","150.00","50/50 Composite"

Results Table 2
,Modulus (Segment 0 % - 2.5 %),Compresson Axis
,(kPa),
"3","2393.05","Y"

Time,Displacement,Force,Compressive displacement,Compressive strain (Displacement),Compressive stress
(s),(mm),(N),(mm),(%),(kPa)
"0.0000","0.0000","-61.8525","0.0000","0.0000","-14.7268"
"0.0800","0.0013","-61.7299","0.0013","0.0008","-14.6976"
"0.1600","0.0173","-60.3745","0.0173","0.0115","-14.3749"
"0.2400","0.0381","-58.7363","0.0381","0.0254","-13.9848"
"0.3200","0.0584","-57.1926","0.0584","0.0389","-13.6173"
"0.4000","0.0775","-55.7751","0.0775","0.0517","-13.2798"
"0.4800","0.0986","-54.2235","0.0986","0.0658","-12.9104"
"0.5600","0.1185","-52.7853","0.1185","0.0790","-12.5679"
"0.6400","0.1382","-51.3901","0.1382","0.0922","-12.2357"
"0.7200","0.1578","-50.0280","0.1578","0.1052","-11.9114"
"0.8000","0.1774","-48.6567","0.1774","0.1183","-11.5849"
"0.8800","0.1981","-47.2079","0.1981","0.1320","-11.2400"
"0.9600","0.2180","-45.8416","0.2180","0.1453","-10.9147"
"1.0400","0.2364","-44.5941","0.2364","0.1576","-10.6177"
"1.1200","0.2576","-43.1156","0.2576","0.1718","-10.2656"
"1.2000","0.2782","-41.7146","0.2782","0.1855","-9.9320"
"1.2800","0.2986","-40.3370","0.2986","0.1991","-9.6040"
"1.3600","0.3185","-38.9923","0.3185","0.2123","-9.2839"
"1.4400","0.3366","-37.8152","0.3366","0.2244","-9.0036"
"1.5200","0.3571","-36.4240","0.3571","0.2381","-8.6724"
"1.6000","0.3779","-35.0173","0.3779","0.2519","-8.3375"
"1.6800","0.3977","-33.6950","0.3977","0.2651","-8.0226"
"1.7600","0.4188","-32.2832","0.4188","0.2792","-7.6865"
"1.8400","0.4382","-31.0196","0.4382","0.2922","-7.3856"
"1.9200","0.4583","-29.6971","0.4583","0.3055","-7.0707"
"2.0000","0.4781","-28.3950","0.4781","0.3187","-6.7607"
"2.0800","0.4975","-27.1292","0.4975","0.3316","-6.4593"
"2.1600","0.5177","-25.7897","0.5177","0.3451","-6.1404"
"2.2400","0.5374","-24.5039","0.5374","0.3583","-5.8343"
"2.3200","0.5569","-23.2160","0.5569","0.3713","-5.5276"
"2.4000","0.5782","-21.7926","0.5782","0.3855","-5.1887"
"2.4800","0.5980","-20.5116","0.5980","0.3987","-4.8837"
"2.5600","0.6185","-19.1678","0.6185","0.4123","-4.5638"
"2.6400","0.6377","-17.9413","0.6377","0.4251","-4.2717"
"2.7200","0.6568","-16.6839","0.6568","0.4378","-3.9724"
"2.8000","0.6765","-15.4027","0.6765","0.4510","-3.6673"
"2.8800","0.6976","-14.0086","0.6976","0.4651","-3.3354"
"2.9600","0.7183","-12.6543","0.7183","0.4788","-3.0129"
"3.0400","0.7391","-11.2745","0.7391","0.4927","-2.6844"
"3.1200","0.7579","-10.0607","0.7579","0.5053","-2.3954"
"3.2000","0.7784","-8.7245","0.7784","0.5189","-2.0773"
"3.2800","0.7977","-7.4885","0.7977","0.5318","-1.7830"
"3.3600","0.8177","-6.1521","0.8177","0.5451","-1.4648"
"3.4400","0.8377","-4.8441","0.8377","0.5585","-1.1534"
"3.5200","0.8565","-3.6363","0.8565","0.5710","-0.8658"
"3.6000","0.8780","-2.1881","0.8780","0.5853","-0.5210"
"3.6800","0.8985","-0.8410","0.8985","0.5990","-0.2002"
"3.7600","0.9181","0.4407","0.9181","0.6121","0.1049"
"3.8400","0.9381","1.7523","0.9381","0.6254","0.4172"
"3.9200","0.9569","2.9404","0.9569","0.6380","0.7001"
"4.0000","0.9767","4.2444","0.9767","0.6512","1.0106"
"4.0800","0.9980","5.6654","0.9980","0.6654","1.3489"
"4.1600","1.0172","6.8899","1.0172","0.6781","1.6404"
"4.2400","1.0385","8.3072","1.0385","0.6923","1.9779"
"4.3200","1.0586","9.6237","1.0586","0.7057","2.2914"
"4.4000","1.0784","10.9187","1.0784","0.7190","2.5997"
"4.4800","1.0978","12.1876","1.0978","0.7319","2.9018"
"4.5600","1.1175","13.4350","1.1175","0.7450","3.1988"
"4.6400","1.1376","14.7671","1.1376","0.7584","3.5160"
"4.7200","1.1577","16.0879","1.1577","0.7718","3.8305"
"4.8000","1.1768","17.3231","1.1768","0.7845","4.1246"
"4.8800","1.1981","18.7495","1.1981","0.7987","4.4642"
"4.9600","1.2179","20.0145","1.2179","0.8120","4.7654"
"5.0400","1.2381","21.3534","1.2381","0.8254","5.0841"
"5.1200","1.2576","22.6195","1.2576","0.8384","5.3856"
"5.2000","1.2766","23.8355","1.2766","0.8510","5.6751"
"5.2800","1.2980","25.2662","1.2980","0.8653","6.0158"
"5.3600","1.3180","26.5692","1.3180","0.8787","6.3260"
"5.4400","1.3376","27.8450","1.3376","0.8918","6.6298"
"5.5200","1.3585","29.2240","1.3585","0.9056","6.9581"
"5.6000","1.3782","30.4917","1.3782","0.9188","7.2599"
"5.6800","1.3986","31.8411","1.3986","0.9324","7.5812"
"5.7600","1.4185","33.1363","1.4185","0.9457","7.8896"
"5.8400","1.4373","34.3525","1.4373","0.9582","8.1792"
"5.9200","1.4575","35.6629","1.4575","0.9716","8.4912"
"6.0000","1.4765","36.8905","1.4765","0.9843","8.7835"
"6.0800","1.4978","38.3284","1.4978","0.9985","9.1258"
"6.1600","1.5190","39.7527","1.5190","1.0126","9.4649"
"6.2400","1.5384","40.9856","1.5384","1.0256","9.7585"
"6.3200","1.5577","42.2367","1.5577","1.0384","10.0563"
"6.4000","1.5775","43.5275","1.5775","1.0517","10.3637"
"6.4800","1.5970","44.8195","1.5970","1.0647","10.6713"
"6.5600","1.6182","46.2328","1.6182","1.0788","11.0078"
"6.6400","1.6368","47.4072","1.6368","1.0912","11.2874"
"6.7200","1.6580","48.8280","1.6580","1.1053","11.6257"
"6.8000","1.6784","50.1727","1.6784","1.1190","11.9459"
"6.8800","1.6986","51.4972","1.6986","1.1324","12.2612"
"6.9600","1.7178","52.7455","1.7178","1.1452","12.5585"
"7.0400","1.7378","54.0380","1.7378","1.1585","12.8662"
"7.1200","1.7573","55.3256","1.7573","1.1715","13.1728"
"7.2000","1.7778","56.6914","1.7778","1.1852","13.4980"
"7.2800","1.7966","57.9097","1.7966","1.1977","13.7880"
"7.3600","1.8177","59.3335","1.8177","1.2118","14.1270"
"7.4400","1.8382","60.6860","1.8382","1.2255","14.4491"
"7.5200","1.8579","61.9816","1.8579","1.2386","14.7575"
"7.6000","1.8783","63.3153","1.8783","1.2522","15.0751"
"7.6800","1.8970","64.5072","1.8970","1.2647","15.3589"
"7.7600","1.9176","65.8830","1.9176","1.2784","15.6864"
"7.8400","1.9379","67.2301","1.9379","1.2919","16.0072"
"7.9200","1.9571","68.4758","1.9571","1.3047","16.3038"
"8.0000","1.9783","69.9115","1.9783","1.3188","16.6456"
"8.0800","1.9990","71.2851","1.9990","1.3327","16.9726"
"8.1600","2.0187","72.5719","2.0187","1.3458","17.2790"
"8.2400","2.0384","73.8724","2.0384","1.3589","17.5887"
"8.3200","2.0566","75.0356","2.0566","1.3711","17.8656"
"8.4000","2.0775","76.4448","2.0775","1.3850","18.2011"
"8.4800","2.0974","77.7730","2.0974","1.3983","18.5174"
"8.5600","2.1178","79.1534","2.1178","1.4118","18.8460"
"8.6400","2.1376","80.4821","2.1376","1.4251","19.1624"
"8.7200","2.1580","81.8525","2.1580","1.4387","19.4887"
"8.8000","2.1781","83.2027","2.1781","1.4521","19.8102"
"8.8800","2.1985","84.5817","2.1985","1.4657","20.1385"
"8.9600","2.2173","85.8192","2.2173","1.4782","20.4331"
"9.0400","2.2377","87.2211","2.2377","1.4918","20.7669"
"9.1200","2.2569","88.4841","2.2569","1.5046","21.0677"
"9.2000","2.2778","89.9435","2.2778","1.5186","21.4151"
"9.2800","2.2992","91.4124","2.2992","1.5328","21.7649"
"9.3600","2.3187","92.7040","2.3187","1.5458","22.0724"
"9.4400","2.3380","93.9827","2.3380","1.5587","22.3768"
"9.5200","2.3578","95.3225","2.3578","1.5719","22.6958"
"9.6000","2.3772","96.6376","2.3772","1.5848","23.0089"
"9.6800","2.3982","98.1377","2.3982","1.5988","23.3661"
"9.7600","2.4169","99.3575","2.4169","1.6113","23.6565"
"9.8400","2.4370","100.7271","2.4370","1.6247","23.9826"
"9.9200","2.4583","102.1925","2.4583","1.6389","24.3316"
"10.0000","2.4781","103.5485","2.4781","1.6521","24.6544"
"10.0800","2.4983","104.9145","2.4983","1.6656","24.9796"
"10.1600","2.5175","106.2034","2.5175","1.6783","25.2865"
"10.2400","2.5375","107.5729","2.5375","1.6916","25.6126"
"10.3200","2.5567","108.8528","2.5567","1.7044","25.9173"
"10.4000","2.5766","110.1929","2.5766","1.7177","26.2364"
"10.4800","2.5984","111.7356","2.5984","1.7323","26.6037"
"10.5600","2.6195","113.1828","2.6195","1.7463","26.9483"
"10.6400","2.6383","114.4400","2.6383","1.7588","27.2476"
"10.7200","2.6579","115.7717","2.6579","1.7719","27.5647"
"10.8000","2.6770","117.0661","2.6770","1.7847","27.8729"
"10.8800","2.6983","118.5926","2.6983","1.7989","28.2363"
"10.9600","2.7181","119.9526","2.7181","1.8121","28.5601"
"11.0400","2.7370","121.2446","2.7370","1.8246","28.8678"
"11.1200","2.7573","122.6693","2.7573","1.8382","29.2070"
"11.2000","2.7782","124.1330","2.7782","1.8521","29.5555"
"11.2800","2.7984","125.5568","2.7984","1.8656","29.8945"
"11.3600","2.8185","126.9446","2.8185","1.8790","30.2249"
"11.4400","2.8367","128.1583","2.8367","1.8911","30.5139"
"11.5200","2.8572","129.6210","2.8572","1.9048","30.8622"
"11.6000","2.8778","131.0702","2.8778","1.9186","31.2072"
"11.6800","2.8977","132.4604","2.8977","1.9318","31.5382"
"11.7600","2.9182","133.8949","2.9182","1.9454","31.8797"
"11.8400","2.9382","135.2874","2.9382","1.9588","32.2113"
"11.9200","2.9586","136.7089","2.9586","1.9724","32.5497"
"12.0000","2.9780","138.0374","2.9780","1.9853","32.8661"
"12.0800","2.9976","139.4086","2.9976","1.9984","33.1925"
"12.1600","3.0178","140.8557","3.0178","2.0119","33.5371"
"12.2400","3.0373","142.1811","3.0373","2.0249","33.8526"
"12.3200","3.0568","143.5525","3.0568","2.0379","34.1792"
"12.4000","3.0783","145.0999","3.0783","2.0522","34.5476"
"12.4800","3.0979","146.4576","3.0979","2.0653","34.8709"
"12.5600","3.1185","147.9050","3.1185","2.0790","35.2155"
"12.6400","3.1376","149.2062","3.1376","2.0917","35.5253"
"12.7200","3.1571","150.5751","3.1571","2.1047","35.8512"
"12.8000","3.1771","151.9629","3.1771","2.1181","36.1816"
"12.8800","3.1974","153.3840","3.1974","2.1316","36.5200"
"12.9600","3.2182","154.8700","3.2182","2.1455","36.8738"
"13.0400","3.2389","156.3185","3.2389","2.1593","37.2187"
"13.1200","3.2576","157.5998","3.2576","2.1718","37.5238"
"13.2000","3.2784","159.1134","3.2784","2.1856","37.8842"
"13.2800","3.2982","160.4664","3.2982","2.1988","38.2063"
"13.3600","3.3180","161.8758","3.3180","2.2120","38.5418"
"13.4400","3.3376","163.2254","3.3376","2.2251","38.8632"
"13.5200","3.3563","164.5009","3.3563","2.2375","39.1669"
"13.6000","3.3777","166.0347","3.3777","2.2518","39.5321"
"13.6800","3.3988","167.5365","3.3988","2.2659","39.8896"
"13.7600","3.4185","168.9121","3.4185","2.2790","40.2172"
"13.8400","3.4380","170.2646","3.4380","2.2920","40.5392"
"13.9200","3.4574","171.5943","3.4574","2.3049","40.8558"
"14.0000","3.4772","173.0135","3.4772","2.3182","41.1937"
"14.0800","3.4980","174.4834","3.4980","2.3320","41.5437"
"14.1600","3.5169","175.7818","3.5169","2.3446","41.8528"
"14.2400","3.5382","177.3108","3.5382","2.3588","42.2169"
"14.3200","3.5584","178.7151","3.5584","2.3723","42.5512"
"14.4000","3.5784","180.1350","3.5784","2.3856","42.8893"
"14.4800","3.5979","181.4875","3.5979","2.3986","43.2113"
"14.5600","3.6175","182.8496","3.6175","2.4117","43.5356"
"14.6400","3.6375","184.2531","3.6375","2.4250","43.8698"
"14.7200","3.6576","185.6737","3.6576","2.4384","44.2080"
"14.8000","3.6767","187.0000","3.6767","2.4511","44.5238"
"14.8800","3.6974","188.4883","3.6974","2.4649","44.8782"
"14.9600","3.7179","189.9330","3.7179","2.4786","45.2222"
"15.0400","3.7385","191.3877","3.7385","2.4923","45.5685"
"15.1200","3.7578","192.7189","3.7578","2.5052","45.8854"
"15.2000","3.7766","194.0177","3.7766","2.5177","46.1947"
"15.2800","3.7974","195.5033","3.7974","2.5316","46.5484"
"15.3600","3.8177","196.9424","3.8177","2.5451","46.8911"
"15.4400","3.8375","198.3238","3.8375","2.5583","47.2200"
"15.5200","3.8586","199.8499","3.8586","2.5724","47.5833"
"15.6000","3.8783","201.1939","3.8783","2.5855","47.9033"
"15.6800","3.8984","202.6199","3.8984","2.5989","48.2428"
"15.7600","3.9185","204.0111","3.9185","2.6123","48.5741"
"15.8400","3.9373","205.3256","3.9373","2.6249","48.8870"
"15.9200","3.9576","206.7540","3.9576","2.6384","49.2271"
"16.0000","3.9768","208.0793","3.9768","2.6512","49.5427"
"16.0800","3.9980","209.6094","3.9980","2.6653","49.9070"
"16.1600","4.0184","211.0615","4.0184","2.6789","50.2527"
"16.2400","4.0380","212.4240","4.0380","2.6920","50.5772"
"16.3200","4.0579","213.8044","4.0579","2.7053","50.9058"
"16.4000","4.0777","215.1679","4.0777","2.7184","51.2305"
"16.4800","4.0971","216.5455","4.0971","2.7314","51.5584"
"16.5600","4.1180","218.0370","4.1180","2.7454","51.9136"
"16.6400","4.1369","219.3061","4.1369","2.7579","52.2157"
"16.7200","4.1583","220.8399","4.1583","2.7722","52.5809"
"16.8000","4.1787","222.2760","4.1787","2.7858","52.9229"
"16.8800","4.1985","223.6520","4.1985","2.7990","53.2505"
"16.9600","4.2178","224.9837","4.2178","2.8118","53.5675"
"17.0400","4.2377","226.3804","4.2377","2.8252","53.9001"
"17.1200","4.2576","227.7834","4.2576","2.8384","54.2341"
"17.2000","4.2777","229.1954","4.2777","2.8518","54.5703"
"17.2800","4.2961","230.4261","4.2961","2.8640","54.8634"
"17.3600","4.3179","232.0145","4.3179","2.8786","55.2416"
"17.4400","4.3384","233.4548","4.3384","2.8923","55.5845"
"17.5200","4.3578","234.7875","4.3578","2.9052","55.9018"
"17.6000","4.3777","236.1828","4.3777","2.9184","56.2340"
"17.6800","4.3972","237.5343","4.3972","2.9315","56.5558"
"17.7600","4.4180","239.0103","4.4180","2.9454","56.9072"
"17.8400","4.4377","240.3819","4.4377","2.9585","57.2338"
"17.9200","4.4572","241.7369","4.4572","2.9715","57.5564"
"18.0000","4.4779","243.1939","4.4779","2.9853","57.9033"
"18.0800","4.4987","244.6382","4.4987","2.9991","58.2472"
"18.1600","4.5179","245.9604","4.5179","3.0119","58.5620"
"18.2400","4.5385","247.4112","4.5385","3.0257","58.9074"
"18.3200","4.5569","248.6460","4.5569","3.0379","59.2014"
"18.4000","4.5778","250.1361","4.5778","3.0519","59.5562"
"18.4800","4.5971","251.4632","4.5971","3.0647","59.8722"
"18.5600","4.6176","252.9394","4.6176","3.0784","60.2237"
"18.6400","4.6381","254.3868","4.6381","3.0921","60.5683"
"18.7200","4.6581","255.7516","4.6581","3.1054","60.8932"
"18.8000","4.6780","257.1220","4.6780","3.1187","61.2195"
"18.8800","4.6983","258.5475","4.6983","3.1322","61.5589"
"18.9600","4.7172","259.8306","4.7172","3.1448","61.8644"
"19.0400","4.7374","261.2535","4.7374","3.1582","62.2032"
"19.1200","4.7569","262.5898","4.7569","3.1713","62.5214"
"19.2000","4.7780","264.1139","4.7780","3.1853","62.8843"
"19.2800","4.7989","265.5980","4.7989","3.1993","63.2376"
"19.3600","4.8185","266.9387","4.8185","3.2123","63.5568"
"19.4400","4.8382","268.2866","4.8382","3.2255","63.8778"
"19.5200","4.8579","269.6455","4.8579","3.2386","64.2013"
"19.6000","4.8777","271.0370","4.8777","3.2518","64.5326"
"19.6800","4.8976","272.4306","4.8976","3.2650","64.8644"
"19.7600","4.9170","273.7788","4.9170","3.2780","65.1854"
"19.8400","4.9374","275.2183","4.9374","3.2916","65.5282"
"19.9200","4.9582","276.6721","4.9582","3.3055","65.8743"
"20.0000","4.9779","278.0285","4.9779","3.3186","66.1973"
"20.0800","4.9984","279.4500","4.9984","3.3323","66.5357"
"20.1600","5.0174","280.7221","5.0174","3.3449","66.8386"
"20.2400","5.0374","282.1098","5.0374","3.3583","67.1690"
"20.3200","5.0572","283.4750","5.0572","3.3715","67.4940"
"20.4000","5.0772","284.8412","5.0772","3.3848","67.8193"
"20.4800","5.0985","286.3565","5.0985","3.3990","68.1801"
"20.5600","5.1190","287.7480","5.1190","3.4126","68.5114"
"20.6400","5.1380","289.0321","5.1380","3.4253","68.8172"
"20.7200","5.1580","290.4041","5.1580","3.4386","69.1438"
"20.8000","5.1772","291.6921","5.1772","3.4514","69.4505"
"20.8800","5.1981","293.1711","5.1981","3.4654","69.8026"
"20.9600","5.2179","294.5208","5.2179","3.4786","70.1240"
"21.0400","5.2367","295.7875","5.2367","3.4911","70.4256"
"21.1200","5.2574","297.2281","5.2574","3.5049","70.7686"
"21.2000","5.2782","298.6776","5.2782","3.5188","71.1137"
"21.2800","5.2984","300.0563","5.2984","3.5323","71.4420"
"21.3600","5.3181","301.3914","5.3181","3.5454","71.7599"
"21.4400","5.3362","302.5692","5.3362","3.5575","72.0403"
"21.5200","5.3570","304.0186","5.3570","3.5713","72.3854"
"21.6000","5.3778","305.4743","5.3778","3.5852","72.7320"
"21.6800","5.3979","306.8755","5.3979","3.5986","73.0656"
"21.7600","5.4191","308.3718","5.4191","3.6127","73.4219"
"21.8400","5.4381","309.5975","5.4381","3.6254","73.7137"
"21.9200","5.4580","310.9575","5.4580","3.6387","74.0375"
"22.0000","5.4780","312.3333","5.4780","3.6520","74.3651"
"22.0800","5.4979","313.6699","5.4979","3.6653","74.6833"
"22.1600","5.5177","315.0133","5.5177","3.6785","75.0032"
"22.2400","5.5370","316.2903","5.5370","3.6913","75.3072"
"22.3200","5.5569","317.6599","5.5569","3.7046","75.6333"
"22.4000","5.5784","319.1490","5.5784","3.7189","75.9879"
"22.4800","5.5979","320.4406","5.5979","3.7319","76.2954"
"22.5600","5.6186","321.8428","5.6186","3.7457","76.6292"
"22.6400","5.6377","323.1064","5.6377","3.7585","76.9301"
"22.7200","5.6573","324.4175","5.6573","3.7715","77.2423"
"22.8000","5.6768","325.7245","5.6768","3.7845","77.5534"
"22.8800","5.6974","327.1440","5.6974","3.7983","77.8914"
"22.9600","5.7182","328.5624","5.7182","3.8121","78.2291"
"23.0400","5.7389","329.9843","5.7389","3.8260","78.5677"
"23.1200","5.7581","331.2283","5.7581","3.8387","78.8639"
"23.2000","5.7785","332.5910","5.7785","3.8523","79.1883"
"23.2800","5.7978","333.8521","5.7978","3.8652","79.4886"
"23.3600","5.8178","335.2179","5.8178","3.8786","79.8138"
"23.4400","5.8376","336.5267","5.8376","3.8917","80.1254"
"23.5200","5.8566","337.7624","5.8566","3.9044","80.4196"
"23.6000","5.8772","339.1584","5.8772","3.9182","80.7520"
"23.6800","5.8984","340.6299","5.8984","3.9323","81.1024"
"23.7600","5.9187","341.9833","5.9187","3.9458","81.4246"
"23.8400","5.9381","343.2585","5.9381","3.9587","81.7282"
"23.9200","5.9571","344.4764","5.9571","3.9714","82.0182"
"24.0000","5.9772","345.8282","5.9772","3.9848","82.3400"
"24.0800","5.9985","347.2614","5.9985","3.9990","82.6813"
"24.1600","6.0171","348.4568","6.0171","4.0114","82.9659"
"24.2400","6.0381","349.8602","6.0381","4.0254","83.3001"
"24.3200","6.0582","351.1820","6.0582","4.0388","83.6148"
"24.4000","6.0792","352.5945","6.0792","4.0528","83.9511"
"24.4800","6.0978","353.7743","6.0978","4.0652","84.2320"
"24.5600","6.1176","355.0643","6.1176","4.0784","84.5391"
"24.6400","6.1374","356.3593","6.1374","4.0916","84.8475"
"24.7200","6.1576","357.6914","6.1576","4.1051","85.1646"
"24.8000","6.1768","358.9726","6.1768","4.1179","85.4697"
"24.8800","6.1981","360.3853","6.1981","4.1320","85.8060"
"24.9600","6.2178","361.6388","6.2178","4.1452","86.1045"
"25.0400","6.2383","362.9906","6.2383","4.1589","86.4263"
"25.1200","6.2577","364.2274","6.2577","4.1718","86.7208"
"25.2000","6.2771","365.4724","6.2771","4.1847","87.0172"
"25.2800","6.2976","366.8106","6.2976","4.1984","87.3359"
"25.3600","6.3178","368.1276","6.3178","4.2119","87.6494"
"25.4400","6.3380","369.4215","6.3380","4.2253","87.9575"
"25.5200","6.3581","370.7276","6.3581","4.2387","88.2685"
"25.6000","6.3781","371.9926","6.3781","4.2521","88.5697"
"25.6800","6.3986","373.3313","6.3986","4.2657","88.8884"
"25.7600","6.4185","374.5857","6.4185","4.2790","89.1871"
"25.8400","6.4371","375.7498","6.4371","4.2914","89.4642"
"25.9200","6.4575","377.0811","6.4575","4.3050","89.7812"
"26.0000","6.4766","378.2418","6.4766","4.3177","90.0576"
"26.0800","6.4980","379.6689","6.4980","4.3320","90.3974"
"26.1600","6.5185","380.9710","6.5185","4.3457","90.7074"
"26.2400","6.5383","382.2165","6.5383","4.3589","91.0039"
"26.3200","6.5576","383.4140","6.5576","4.3718","91.2891"
"26.4000","6.5776","384.6663","6.5776","4.3851","91.5872"
"26.4800","6.5971","385.8863","6.5971","4.3980","91.8777"
"26.5600","6.6181","387.2515","6.6181","4.4121","92.2027"
"26.6400","6.6368","388.3821","6.6368","4.4245","92.4719"
"26.7200","6.6580","389.7527","6.6580","4.4387","92.7982"
"26.8000","6.6788","391.0737","6.6788","4.4525","93.1128"
"26.8800","6.6986","392.2999","6.6986","4.4657","93.4047"
"26.9600","6.7180","393.5038","6.7180","4.4787","93.6914"
"27.0400","6.7377","394.6981","6.7377","4.4918","93.9757"
"27.1200","6.7579","395.9760","6.7579","4.5052","94.2800"
"27.2000","6.7772","397.1556","6.7772","4.5182","94.5609"
"27.2800","6.7962","398.2905","6.7962","4.5308","94.8311"
"27.3600","6.8178","399.7014","6.8178","4.5452","95.1670"
"27.4400","6.8386","401.0061","6.8386","4.5591","95.4776"
"27.5200","6.8582","402.2079","6.8582","4.5722","95.7638"
"27.6000","6.8779","403.4056","6.8779","4.5853","96.0490"
"27.6800","6.8968","404.5211","6.8968","4.5979","96.3145"
"27.7600","6.9178","405.8385","6.9178","4.6118","96.6282"
"27.8400","6.9377","407.0712","6.9377","4.6252","96.9217"
"27.9200","6.9574","408.2599","6.9574","4.6383","97.2048"
"28.0000","6.9783","409.5715","6.9783","4.6522","97.5170"
"28.0800","6.9991","410.8187","6.9991","4.6660","97.8140"
"28.1600","7.0187","412.0032","7.0187","4.6791","98.0960"
"28.2400","7.0385","413.1648","7.0385","4.6923","98.3726"
"28.3200","7.0566","414.1928","7.0566","4.7044","98.6173"
"28.4000","7.0779","415.5301","7.0779","4.7186","98.9357"
"28.4800","7.0973","416.6797","7.0973","4.7315","99.2095"
"28.5600","7.1170","417.8588","7.1170","4.7447","99.4902"
"28.6400","7.1377","419.1265","7.1377","4.7584","99.7920"
"28.7200","7.1581","420.3301","7.1581","4.7720","100.0786"
"28.8000","7.1780","421.5019","7.1780","4.7853","100.3576"
"28.8800","7.1985","422.7339","7.1985","4.7990","100.6509"
"28.9600","7.2175","423.8108","7.2175","4.8117","100.9073"
"29.0400","7.2375","424.9972","7.2375","4.8250","101.1898"
"29.1200","7.2566","426.0609","7.2566","4.8377","101.4431"
"29.2000","7.2778","427.3759","7.2778","4.8518","101.7562"
"29.2800","7.2992","428.6769","7.2992","4.8661","102.0659"
"29.3600","7.3189","429.7909","7.3189","4.8793","102.3312"
"29.4400","7.3383","430.8947","7.3383","4.8922","102.5940"
"29.5200","7.3577","432.0105","7.3577","4.9051","102.8596"
"29.6000","7.3776","433.1774","7.3776","4.9184","103.1375"
"29.6800","7.3978","434.3374","7.3978","4.9319","103.4137"
"29.7600","7.4168","435.3623","7.4168","4.9445","103.6577"
"29.8400","7.4374","436.5708","7.4374","4.9583","103.9454"
"29.9200","7.4585","437.7814","7.4585","4.9723","104.2337"
"30.0000","7.4778","438.8429","7.4778","4.9852","104.4864"
"30.0800","7.4984","440.0330","7.4984","4.9990","104.7698"
"30.1600","7.5176","441.0585","7.5176","5.0117","105.0139"
"30.2400","7.5378","442.2038","7.5378","5.0252","105.2866"
"30.3200","7.5573","443.2668","7.5573","5.0382","105.5397"
"30.4000","7.5769","444.3222","7.5769","5.0513","105.7910"
"30.4800","7.5981","445.5652","7.5981","5.0654","106.0870"
"30.5600","7.6191","446.7266","7.6191","5.0794","106.3635"
"30.6400","7.6385","447.7699","7.6385","5.0923","106.6119"
"30.7200","7.6582","448.8296","7.6582","5.1055","106.8642"
"30.8000","7.6771","449.8132","7.6771","5.1181","107.0984"
"30.8800","7.6980","451.0069","7.6980","5.1320","107.3826"
"30.9600","7.7176","452.0461","7.7176","5.1451","107.6300"
"31.0400","7.7366","453.0298","7.7366","5.1577","107.8642"
"31.1200","7.7577","454.2191","7.7577","5.1718","108.1474"
"31.2000","7.7786","455.3633","7.7786","5.1857","108.4198"
"31.2800","7.7986","456.4250","7.7986","5.1991","108.6726"
"31.3600","7.8185","457.4826","7.8185","5.2124","108.9244"
"31.4400","7.8368","458.3595","7.8368","5.2246","109.1332"
"31.5200","7.8566","459.4100","7.8566","5.2377","109.3833"
"31.6000","7.8775","460.5492","7.8775","5.2517","109.6546"
"31.6800","7.8979","461.6387","7.8979","5.2652","109.9140"
"31.7600","7.9189","462.7606","7.9189","5.2792","110.1811"
"31.8400","7.9383","463.7228","7.9383","5.2922","110.4102"
"31.9200","7.9585","464.7674","7.9585","5.3057","110.6589"
"32.0000","7.9781","465.7672","7.9781","5.3188","110.8969"
"32.0800","7.9977","466.7475","7.9977","5.3318","111.1304"
"32.1600","8.0174","467.7523","8.0174","5.3449","111.3696"
"32.2400","8.0369","468.7224","8.0369","5.3579","111.6006"
"32.3200","8.0569","469.7466","8.0569","5.3713","111.8444"
"32.4000","8.0783","470.8658","8.0783","5.3855","112.1109"
"32.4800","8.0981","471.8441","8.0981","5.3987","112.3438"
"32.5600","8.1188","472.8900","8.1188","5.4125","112.5928"
"32.6400","8.1376","473.7617","8.1376","5.4250","112.8004"
"32.7200","8.1573","474.7373","8.1573","5.4382","113.0327"
"32.8000","8.1767","475.6754","8.1767","5.4512","113.2561"
"32.8800","8.1975","476.7371","8.1975","5.4650","113.5088"
"32.9600","8.2183","477.7709","8.2183","5.4788","113.7550"
"33.0400","8.2387","478.7646","8.2387","5.4925","113.9916"
"33.1200","8.2580","479.6616","8.2580","5.5053","114.2051"
"33.2000","8.2782","480.6258","8.2782","5.5188","114.4347"
"33.2800","8.2979","481.5452","8.2979","5.5319","114.6536"
"33.3600","8.3180","482.5123","8.3180","5.5453","114.8839"
"33.4400","8.3373","483.3995","8.3373","5.5582","115.0951"
"33.5200","8.3562","484.2300","8.3562","5.5708","115.2929"
"33.6000","8.3778","485.3168","8.3778","5.5852","115.5516"
"33.6800","8.3989","486.3398","8.3989","5.5993","115.7952"
"33.7600","8.4184","487.2045","8.4184","5.6123","116.0011"
"33.8400","8.4378","488.0612","8.4378","5.6252","116.2051"
"33.9200","8.4568","488.8806","8.4568","5.6379","116.4001"
"34.0000","8.4773","489.8463","8.4773","5.6516","116.6301"
"34.0800","8.4982","490.8235","8.4982","5.6655","116.8627"
"34.1600","8.5172","491.6303","8.5172","5.6781","117.0548"
"34.2400","8.5379","492.5734","8.5379","5.6920","117.2794"
"34.3200","8.5584","493.4898","8.5584","5.7056","117.4976"
"34.4000","8.5790","494.4197","8.5790","5.7193","117.7190"
"34.4800","8.5980","495.1921","8.5980","5.7320","117.9029"
"34.5600","8.6173","495.9890","8.6173","5.7449","118.0926"
"34.6400","8.6374","496.8702","8.6374","5.7583","118.3024"
"34.7200","8.6577","497.7560","8.6577","5.7718","118.5133"
"34.8000","8.6769","498.5633","8.6769","5.7846","118.7055"
"34.8800","8.6978","499.4861","8.6978","5.7986","118.9253"
"34.9600","8.7180","500.3186","8.7180","5.8120","119.1235"
"35.0400","8.7385","501.2019","8.7385","5.8257","119.3338"
"35.1200","8.7582","502.0015","8.7582","5.8388","119.5242"
"35.2000","8.7771","502.7432","8.7771","5.8514","119.7008"
"35.2800","8.7974","503.5809","8.7974","5.8649","119.9002"
"35.3600","8.8175","504.4038","8.8175","5.8783","120.0962"
"35.4400","8.8377","505.2524","8.8377","5.8918","120.2982"
"35.5200","8.8583","506.1136","8.8583","5.9056","120.5032"
"35.6000","8.8783","506.8833","8.8783","5.9189","120.6865"
"35.6800","8.8986","507.6869","8.8986","5.9324","120.8778"
"35.7600","8.9183","508.4331","8.9183","5.9455","121.0555"
"35.8400","8.9372","509.1518","8.9372","5.9581","121.2266"
"35.9200","8.9573","509.9260","8.9573","5.9715","121.4110"
"36.0000","8.9763","510.6171","8.9763","5.9842","121.5755"
"36.0800","8.9984","511.5807","8.9984","5.9989","121.8049"
"36.1600","9.0188","512.3772","9.0188","6.0125","121.9946"
"36.2400","9.0383","513.0602","9.0383","6.0256","122.1572"
"36.3200","9.0576","513.7447","9.0576","6.0384","122.3202"
"36.4000","9.0777","514.4807","9.0777","6.0518","122.4954"
"36.4800","9.0969","515.1696","9.0969","6.0646","122.6594"
"36.5600","9.1176","515.9550","9.1176","6.0784","122.8464"
"36.6400","9.1368","516.5966","9.1368","6.0912","122.9992"
"36.7200","9.1584","517.4306","9.1584","6.1056","123.1978"
"36.8000","9.1787","518.1718","9.1787","6.1191","123.3742"
"36.8800","9.1989","518.8895","9.1989","6.1326","123.5451"
"36.9600","9.2184","519.5479","9.2184","6.1456","123.7019"
"37.0400","9.2379","520.1868","9.2379","6.1586","123.8540"
"37.1200","9.2574","520.8517","9.2574","6.1716","124.0123"
"37.2000","9.2773","521.5386","9.2773","6.1849","124.1759"
"37.2800","9.2964","522.1403","9.2964","6.1976","124.3191"
"37.3600","9.3182","522.9597","9.3182","6.2121","124.5142"
"37.4400","9.3384","523.6096","9.3384","6.2256","124.6689"
"37.5200","9.3582","524.2702","9.3582","6.2388","124.8262"
"37.6000","9.3778","524.8738","9.3778","6.2518","124.9699"
"37.6800","9.3969","525.4506","9.3969","6.2646","125.1073"
"37.7600","9.4178","526.1666","9.4178","6.2785","125.2778"
"37.8400","9.4375","526.7717","9.4375","6.2917","125.4218"
"37.9200","9.4571","527.3727","9.4571","6.3047","125.5649"
"38.0000","9.4779","528.0753","9.4779","6.3186","125.7322"
"38.0800","9.4989","528.7433","9.4989","6.3326","125.8913"
"38.1600","9.5186","529.3164","9.5186","6.3457","126.0277"
"38.2400","9.5385","529.9018","9.5385","6.3590","126.1671"
"38.3200","9.5567","530.3600","9.5567","6.3711","126.2762"
"38.4000","9.5777","531.0493","9.5777","6.3852","126.4403"
"38.4800","9.5973","531.6006","9.5973","6.3982","126.5716"
"38.5600","9.6180","532.2468","9.6180","6.4120","126.7254"
"38.6400","9.6378","532.8096","9.6378","6.4252","126.8594"
"38.7200","9.6581","533.3878","9.6581","6.4387","126.9971"
"38.8000","9.6778","533.9095","9.6778","6.4518","127.1213"
"38.8800","9.6980","534.4883","9.6980","6.4653","127.2591"
"38.9600","9.7173","534.9948","9.7173","6.4782","127.3797"
"39.0400","9.7378","535.5719","9.7378","6.4918","127.5171"
"39.1200","9.7570","536.0377","9.7570","6.5047","127.6280"
"39.2000","9.7777","536.6468","9.7777","6.5185","127.7730"
"39.2800","9.7986","537.2319","9.7986","6.5324","127.9124"
"39.3600","9.8187","537.7469","9.8187","6.5458","128.0350"
"39.4400","9.8384","538.2173","9.8384","6.5589","128.1470"
"39.5200","9.8578","538.6801","9.8578","6.5718","128.2572"
"39.6000","9.8777","539.1843","9.8777","6.5851","128.3772"
"39.6800","9.8975","539.6718","9.8975","6.5984","128.4933"
"39.7600","9.9168","540.0920","9.9168","6.6112","128.5933"
"39.8400","9.9373","540.6388","9.9373","6.6248","128.7235"
"39.9200","9.9587","541.2115","9.9587","6.6391","128.8599"
"40.0000","9.9779","541.6391","9.9779","6.6519","128.9617"
"40.0800","9.9984","542.1251","9.9984","6.6656","129.0774"
"40.1600","10.0171","542.4855","10.0171","6.6781","129.1632"
"40.2400","10.0380","543.0137","10.0380","6.6920","129.2890"
"40.3200","10.0570","543.3845","10.0570","6.7047","129.3773"
"40.4000","10.0768","543.8187","10.0768","6.7178","129.4806"
"40.4800","10.0982","544.3731","10.0982","6.7321","129.6126"
"40.5600","10.1195","544.8818","10.1195","6.7463","129.7338"
"40.6400","10.1381","545.2060","10.1381","6.7587","129.8109"
"40.7200","10.1579","545.6130","10.1579","6.7719","129.9078"
"40.8000","10.1771","545.9686","10.1771","6.7847","129.9925"
"40.8800","10.1983","546.4789","10.1983","6.7989","130.1140"
"40.9600","10.2181","546.8514","10.2181","6.8120","130.2027"
"41.0400","10.2369","547.1777","10.2369","6.8246","130.2804"
"41.1200","10.2570","547.5801","10.2570","6.8380","130.3762"
"41.2000","10.2773","547.9943","10.2773","6.8516","130.4748"
"41.2800","10.2986","548.4778","10.2986","6.8657","130.5899"
"41.3600","10.3190","548.8682","10.3190","6.8793","130.6829"
"41.4400","10.3375","549.1329","10.3375","6.8916","130.7459"
"41.5200","10.3573","549.4805","10.3573","6.9048","130.8287"
"41.6000","10.3775","549.8589","10.3775","6.9183","130.9188"
"41.6800","10.3978","550.2541","10.3978","6.9319","131.0129"
"41.7600","10.4189","550.6671","10.4189","6.9459","131.1112"
"41.8400","10.4382","550.9422","10.4382","6.9588","131.1767"
"41.9200","10.4587","551.2927","10.4587","6.9724","131.2602"
"42.0000","10.4780","551.5807","10.4780","6.9853","131.3287"
"42.0800","10.4977","551.8891","10.4977","6.9985","131.4022"
"42.1600","10.5173","552.1929","10.5173","7.0116","131.4745"
"42.2400","10.5371","552.4965","10.5371","7.0247","131.5468"
"42.3200","10.5572","552.8287","10.5572","7.0381","131.6259"
"42.4000","10.5784","553.2126","10.5784","7.0523","131.7173"
"42.4800","10.5978","553.4525","10.5978","7.0652","131.7744"
"42.5600","10.6186","553.7803","10.6186","7.0791","131.8525"
"42.6400","10.6376","553.9991","10.6376","7.0917","131.9046"
"42.7200","10.6578","554.3266","10.6578","7.1052","131.9825"
"42.8000","10.6772","554.5538","10.6772","7.1182","132.0366"
"42.8800","10.6972","554.8273","10.6972","7.1315","132.1017"
"42.9600","10.7181","555.1443","10.7181","7.1454","132.1772"
"43.0400","10.7391","555.4658","10.7391","7.1594","132.2538"
"43.1200","10.7578","555.6158","10.7578","7.1718","132.2895"
"43.2000","10.7782","555.8920","10.7782","7.1855","132.3552"
"43.2800","10.7980","556.0997","10.7980","7.1987","132.4047"
"43.3600","10.8179","556.3346","10.8179","7.2119","132.4606"
"43.4400","10.8376","556.5463","10.8376","7.2251","132.5110"
"43.5200","10.8561","556.6700","10.8561","7.2374","132.5405"
"43.6000","10.8777","557.0039","10.8777","7.2518","132.6200"
"43.6800","10.8989","557.2927","10.8989","7.2659","132.6887"
"43.7600","10.9183","557.4337","10.9183","7.2789","132.7223"
"43.8400","10.9377","557.5905","10.9377","7.2918","132.7596"
"43.9200","10.9575","557.7459","10.9575","7.3050","132.7966"
"44.0000","10.9773","557.9094","10.9773","7.3182","132.8356"
"44.0800","10.9982","558.1226","10.9982","7.3321","132.8863"
"44.1600","11.0173","558.2370","11.0173","7.3449","132.9136"
"44.2400","11.0386","558.4497","11.0386","7.3590","132.9642"
"44.3200","11.0582","558.5610","11.0582","7.3721","132.9907"
"44.4000","11.0790","558.7443","11.0790","7.3860","133.0343"
"44.4800","11.0980","558.8136","11.0980","7.3987","133.0509"
"44.5600","11.1176","558.9047","11.1176","7.4118","133.0726"
"44.6400","11.1373","558.9851","11.1373","7.4248","133.0917"
"44.7200","11.1576","559.1322","11.1576","7.4384","133.1267"
"44.8000","11.1768","559.2292","11.1768","7.4512","133.1498"
"44.8800","11.1984","559.4484","11.1984","7.4656","133.2020"
"44.9600","11.2181","559.4950","11.2181","7.4787","133.2131"
"45.0400","11.2387","559.6065","11.2387","7.4925","133.2396"
"45.1200","11.2578","559.6165","11.2578","7.5052","133.2420"
"45.2000","11.2770","559.6559","11.2770","7.5180","133.2514"
"45.2800","11.2977","559.7492","11.2977","7.5318","133.2736"
"45.3600","11.3172","559.7708","11.3172","7.5448","133.2788"
"45.4400","11.3378","559.8730","11.3378","7.5585","133.3031"
"45.5200","11.3586","559.9651","11.3586","7.5724","133.3250"
"45.6000","11.3784","559.9437","11.3784","7.5856","133.3199"
"45.6800","11.3987","559.9821","11.3987","7.5991","133.3291"
"45.7600","11.4185","559.9793","11.4185","7.6123","133.3284"
"45.8400","11.4372","559.9489","11.4372","7.6248","133.3212"
"45.9200","11.4575","559.9698","11.4575","7.6383","133.3262"
"46.0000","11.4762","559.9025","11.4762","7.6508","133.3101"
"46.0800","11.4982","560.0320","11.4982","7.6654","133.3410"
"46.1600","11.5185","560.0350","11.5185","7.6790","133.3417"
"46.2400","11.5384","560.0052","11.5384","7.6922","133.3346"
"46.3200","11.5579","559.9563","11.5579","7.7053","133.3229"
"46.4000","11.5776","559.9045","11.5776","7.7184","133.3106"
"46.4800","11.5963","559.8336","11.5963","7.7309","133.2937"
"46.5600","11.6181","559.9041","11.6181","7.7454","133.3105"
"46.6400","11.6370","559.7835","11.6370","7.7580","133.2818"
"46.7200","11.6585","559.8099","11.6585","7.7723","133.2881"
"46.8000","11.6789","559.7467","11.6789","7.7859","133.2730"
"46.8800","11.6990","559.6896","11.6990","7.7993","133.2594"
"46.9600","11.7181","559.5344","11.7181","7.8121","133.2225"
"47.0400","11.7377","559.4243","11.7377","7.8251","133.1962"
"47.1200","11.7576","559.3288","11.7576","7.8384","133.1735"
"47.2000","11.7772","559.2097","11.7772","7.8515","133.1452"
"47.2800","11.7969","559.0677","11.7969","7.8646","133.1114"
"47.3600","11.8176","558.9867","11.8176","7.8784","133.0921"
"47.4400","11.8383","558.8596","11.8383","7.8922","133.0618"
"47.5200","11.8584","558.7286","11.8584","7.9056","133.0306"
"47.6000","11.8784","558.5288","11.8784","7.9189","132.9830"
"47.6800","11.8973","558.2897","11.8973","7.9315","132.9261"
"47.7600","11.9178","558.1329","11.9178","7.9452","132.8888"
"47.8400","11.9374","557.9443","11.9374","7.9582","132.8439"
"47.9200","11.9575","557.7808","11.9575","7.9717","132.8049"
"48.0000","11.9781","557.6249","11.9781","7.9854","132.7678"
"48.0800","11.9990","557.4528","11.9990","7.9993","132.7268"
"48.1600","12.0187","557.2263","12.0187","8.0124","132.6729"
"48.2400","12.0384","556.9940","12.0384","8.0256","132.6176"
"48.3200","12.0568","556.6913","12.0568","8.0378","132.5455"
"48.4000","12.0777","556.5364","12.0777","8.0518","132.5087"
"48.4800","12.0974","556.2739","12.0974","8.0649","132.4462"
"48.5600","12.1182","556.0922","12.1182","8.0788","132.4029"
"48.6400","12.1378","555.8212","12.1378","8.0919","132.3384"
"48.7200","12.1582","555.5870","12.1582","8.1055","132.2826"
"48.8000","12.1779","555.3109","12.1779","8.1186","132.2169"
"48.8800","12.1979","555.0640","12.1979","8.1319","132.1581"
"48.9600","12.2174","554.7972","12.2174","8.1450","132.0946"
"49.0400","12.2376","554.5322","12.2376","8.1584","132.0315"
"49.1200","12.2569","554.2091","12.2569","8.1713","131.9546"
"49.2000","12.2781","553.9935","12.2781","8.1854","131.9032"
"49.2800","12.2991","553.7106","12.2991","8.1994","131.8359"
"49.3600","12.3190","553.3478","12.3190","8.2126","131.7495"
"49.4400","12.3385","552.9294","12.3385","8.2257","131.6499"
"49.5200","12.3577","552.4959","12.3577","8.2385","131.5466"
"49.6000","12.3775","552.1047","12.3775","8.2517","131.4535"
"49.6800","12.3977","551.7239","12.3977","8.2651","131.3628"
"49.7600","12.4170","551.2711","12.4170","8.2780","131.2550"
"49.8400","12.4374","550.8975","12.4374","8.2916","131.1661"
"49.9200","12.4589","550.5648","12.4589","8.3059","131.0868"
"50.0000","12.4782","550.1019","12.4782","8.3188","130.9766"
"50.0800","12.4985","549.7076","12.4985","8.3324","130.8828"
"50.1600","12.5171","549.2206","12.5171","8.3448","130.7668"
"50.2400","12.5381","548.8718","12.5381","8.3587","130.6838"
"50.3200","12.5569","548.3776","12.5569","8.3713","130.5661"
"50.4000","12.5769","547.9429","12.5769","8.3846","130.4626"
"50.4800","12.5981","547.5446","12.5981","8.3988","130.3678"
"50.5600","12.6193","547.0999","12.6193","8.4129","130.2619"
"50.6400","12.6384","546.5557","12.6384","8.4256","130.1323"
"50.7200","12.6582","546.0433","12.6582","8.4388","130.0103"
"50.8000","12.6768","545.4587","12.6768","8.4512","129.8711"
"50.8800","12.6981","545.0173","12.6981","8.4654","129.7660"
"50.9600","12.7178","544.4623","12.7178","8.4785","129.6339"
"51.0400","12.7368","543.8997","12.7368","8.4912","129.4999"
"51.1200","12.7573","543.3900","12.7573","8.5049","129.3786"
"51.2000","12.7779","542.8859","12.7779","8.5186","129.2586"
"51.2800","12.7987","542.3716","12.7987","8.5324","129.1361"
"51.3600","12.8189","541.8420","12.8189","8.5459","129.0100"
"51.4400","12.8375","541.2003","12.8375","8.5583","128.8572"
"51.5200","12.8575","540.6386","12.8575","8.5717","128.7235"
"51.6000","12.8777","540.0773","12.8777","8.5851","128.5898"
"51.6800","12.8975","539.5344","12.8975","8.5984","128.4606"
"51.7600","12.9189","539.0231","12.9189","8.6126","128.3388"
"51.8400","12.9382","538.4083","12.9382","8.6255","128.1925"
"51.9200","12.9588","537.8563","12.9588","8.6392","128.0610"
"52.0000","12.9781","537.2209","12.9781","8.6521","127.9097"
"52.0800","12.9977","536.5789","12.9977","8.6651","127.7569"
"52.1600","13.0177","535.9629","13.0177","8.6784","127.6102"
"52.2400","13.0371","535.2813","13.0371","8.6914","127.4479"
"52.3200","13.0568","534.6735","13.0568","8.7045","127.3032"
"52.4000","13.0786","534.1104","13.0786","8.7191","127.1691"
"52.4800","13.0984","533.4389","13.0984","8.7322","127.0093"
"52.5600","13.1185","532.7905","13.1185","8.7457","126.8549"
"52.6400","13.1379","532.0925","13.1379","8.7586","126.6887"
"52.7200","13.1574","531.3961","13.1574","8.7716","126.5229"
"52.8000","13.1771","530.6590","13.1771","8.7848","126.3474"
"52.8800","13.1972","529.9072","13.1972","8.7981","126.1684"
"52.9600","13.2183","529.1724","13.2183","8.8122","125.9934"
"53.0400","13.2391","528.4370","13.2391","8.8261","125.8183"
"53.1200","13.2580","527.6216","13.2580","8.8387","125.6242"
"53.2000","13.2780","526.8923","13.2780","8.8520","125.4505"
"53.2800","13.2978","526.1943","13.2978","8.8652","125.2843"
"53.3600","13.3182","525.5692","13.3182","8.8788","125.1355"
"53.4400","13.3377","524.9020","13.3377","8.8918","124.9767"
"53.5200","13.3561","524.1998","13.3561","8.9041","124.8095"
"53.6000","13.3775","523.6012","13.3775","8.9184","124.6670"
"53.6800","13.3987","522.9531","13.3987","8.9325","124.5126"
"53.7600","13.4187","522.2148","13.4187","8.9458","124.3369"
"53.8400","13.4380","521.4162","13.4380","8.9587","124.1467"
"53.9200","13.4571","520.6125","13.4571","8.9714","123.9554"
"54.0000","13.4775","519.9121","13.4775","8.9850","123.7886"
"54.0800","13.4981","519.2275","13.4981","8.9987","123.6256"
"54.1600","13.5171","518.5161","13.5171","9.0114","123.4562"
"54.2400","13.5385","517.8956","13.5385","9.0257","123.3085"
"54.3200","13.5586","517.2161","13.5586","9.0391","123.1467"
"54.4000","13.5788","516.5235","13.5788","9.0525","122.9818"
"54.4800","13.5981","515.7858","13.5981","9.0654","122.8061"
"54.5600","13.6177","515.0178","13.6177","9.0785","122.6233"
"54.6400","13.6379","514.2930","13.6379","9.0919","122.4507"
"54.7200","13.6577","513.5640","13.6577","9.1051","122.2771"
"54.8000","13.6763","512.8340","13.6763","9.1176","122.1033"
"54.8800","13.6982","512.2281","13.6982","9.1321","121.9591"
"54.9600","13.7179","511.4900","13.7179","9.1452","121.7833"
"55.0400","13.7388","510.8190","13.7388","9.1592","121.6236"
"55.1200","13.7580","510.0443","13.7580","9.1720","121.4391"
"55.2000","13.7771","509.2821","13.7771","9.1847","121.2576"
"55.2800","13.7975","508.5162","13.7975","9.1983","121.0753"
"55.3600","13.8175","507.7391","13.8175","9.2117","120.8903"
"55.4400","13.8378","506.9700","13.8378","9.2252","120.7071"
"55.5200","13.8585","506.2426","13.8585","9.2390","120.5340"
"55.6000","13.8785","505.4782","13.8785","9.2523","120.3520"
"55.6800","13.8988","504.7412","13.8988","9.2658","120.1765"
"55.7600","13.9185","503.9981","13.9185","9.2790","119.9996"
"55.8400","13.9371","503.2394","13.9371","9.2914","119.8189"
"55.9200","13.9573","502.5134","13.9573","9.3049","119.6461"
"56.0000","13.9767","501.7455","13.9767","9.3178","119.4632"
"56.0800","13.9982","501.0508","13.9982","9.3321","119.2978"
"56.1600","14.0185","500.2941","14.0185","9.3456","119.1176"
"56.2400","14.0383","499.4933","14.0383","9.3588","118.9270"
"56.3200","14.0579","498.6740","14.0579","9.3719","118.7319"
"56.4000","14.0779","497.8275","14.0779","9.3853","118.5304"
"56.4800","14.0974","496.9934","14.0974","9.3983","118.3318"
"56.5600","14.1177","496.1860","14.1177","9.4118","118.1395"
"56.6400","14.1366","495.3053","14.1366","9.4244","117.9298"
"56.7200","14.1583","494.5303","14.1583","9.4389","117.7453"
"56.8000","14.1789","493.7312","14.1789","9.4526","117.5550"
"56.8800","14.1989","492.8908","14.1989","9.4659","117.3550"
"56.9600","14.2179","491.9580","14.2179","9.4786","117.1328"
"57.0400","14.2372","491.0245","14.2372","9.4915","116.9106"
"57.1200","14.2576","490.1659","14.2576","9.5051","116.7062"
"57.2000","14.2778","489.2928","14.2778","9.5185","116.4983"
"57.2800","14.2968","488.3450","14.2968","9.5312","116.2726"
"57.3600","14.3179","487.4586","14.3179","9.5453","116.0616"
"57.4400","14.3384","486.5490","14.3384","9.5589","115.8450"
"57.5200","14.3581","485.6938","14.3581","9.5720","115.6414"
"57.6000","14.3783","484.8296","14.3783","9.5855","115.4356"
"57.6800","14.3972","483.8960","14.3972","9.5981","115.2133"
"57.7600","14.4176","483.0380","14.4176","9.6117","115.0090"
"57.8400","14.4377","482.2053","14.4377","9.6252","114.8108"
"57.9200","14.4576","481.3500","14.4576","9.6384","114.6071"
"58.0000","14.4782","480.4767","14.4782","9.6521","114.3992"
"58.0800","14.4988","479.5672","14.4988","9.6659","114.1827"
"58.1600","14.5186","478.6219","14.5186","9.6790","113.9576"
"58.2400","14.5383","477.6609","14.5383","9.6922","113.7288"
"58.3200","14.5570","476.6212","14.5570","9.7047","113.4812"
"58.4000","14.5778","475.6835","14.5778","9.7185","113.2580"
"58.4800","14.5974","474.7433","14.5974","9.7316","113.0341"
"58.5600","14.6176","473.8742","14.6176","9.7451","112.8272"
"58.6400","14.6376","472.9808","14.6376","9.7584","112.6145"
"58.7200","14.6580","472.0859","14.6580","9.7720","112.4014"
"58.8000","14.6783","471.2495","14.6783","9.7855","112.2023"
"58.8800","14.6984","470.4054","14.6984","9.7989","112.0013"
"58.9600","14.7172","469.4769","14.7172","9.8115","111.7802"
"59.0400","14.7373","468.5798","14.7373","9.8249","111.5666"
"59.1200","14.7570","467.6909","14.7570","9.8380","111.3550"
"59.2000","14.7780","466.9238","14.7780","9.8520","111.1723"
"59.2800","14.7993","466.1956","14.7993","9.8662","110.9990"
"59.3600","14.8186","465.4132","14.8186","9.8790","110.8127"
"59.4400","14.8383","464.6075","14.8383","9.8922","110.6208"
"59.5200","14.8580","463.7327","14.8580","9.9053","110.4125"
"59.6000","14.8777","462.8693","14.8777","9.9185","110.2070"
"59.6800","14.8976","462.0028","14.8976","9.9317","110.0007"
"59.7600","14.9168","461.1119","14.9168","9.9445","109.7886"
"59.8400","14.9373","460.3134","14.9373","9.9582","109.5984"
"59.9200","14.9583","459.5782","14.9583","9.9722","109.4234"
"60.0000","14.9775","458.7800","14.9775","9.9850","109.2333"
"60.0800","14.9986","458.0209","14.9986","9.9991","109.0526"
"60.0860","15.0001","457.9618","15.0001","10.0001","109.0385"