File: data/instron_tests/metamaterials/250416/250416_50-50_Composite.is_comp_Exports/250416_50-50_Composite_2_1.csv
Results Table 1
,Compresson Axis,H*,V*,Height,Thickness,Width,Area,Fixture separation,Specimen label
,,,,(mm),(mm),(mm),(mm^2),(mm),
"2","Y","","","150.00","28.00","150.00","4200.00","150.00","50/50 Composite"

Results Table 2
,Modulus (Segment 0 % - 2.5 %),Compresson Axis
,(kPa),
"2","2397.91","Y"

Time,Displacement,Force,Compressive displacement,Compressive strain (Displacement),Compressive stress
(s),(mm),(N),(mm),(%),(kPa)
"0.0000","0.0000","-48.6580","0.0000","0.0000","-11.5852"
"0.0800","0.0011","-48.5715","0.0011","0.0008","-11.5646"
"0.1600","0.0174","-47.1655","0.0174","0.0116","-11.2299"
"0.2400","0.0378","-45.5431","0.0378","0.0252","-10.8436"
"0.3200","0.0579","-44.0098","0.0579","0.0386","-10.4785"
"0.4000","0.0771","-42.5892","0.0771","0.0514","-10.1403"
"0.4800","0.0981","-41.0133","0.0981","0.0654","-9.7651"
"0.5600","0.1182","-39.5783","0.1182","0.0788","-9.4234"
"0.6400","0.1376","-38.1778","0.1376","0.0917","-9.0899"
"0.7200","0.1571","-36.7983","0.1571","0.1047","-8.7615"
"0.8000","0.1771","-35.3925","0.1771","0.1181","-8.4268"
"0.8800","0.1974","-33.9618","0.1974","0.1316","-8.0862"
"0.9600","0.2174","-32.5714","0.2174","0.1449","-7.7551"
"1.0400","0.2358","-31.3183","0.2358","0.1572","-7.4567"
"1.1200","0.2571","-29.8180","0.2571","0.1714","-7.0995"
"1.2000","0.2777","-28.4159","0.2777","0.1851","-6.7657"
"1.2800","0.2980","-27.0218","0.2980","0.1987","-6.4338"
"1.3600","0.3178","-25.6974","0.3178","0.2118","-6.1184"
"1.4400","0.3363","-24.4664","0.3363","0.2242","-5.8253"
"1.5200","0.3566","-23.1011","0.3566","0.2377","-5.5003"
"1.6000","0.3771","-21.7218","0.3771","0.2514","-5.1719"
"1.6800","0.3972","-20.3569","0.3972","0.2648","-4.8469"
"1.7600","0.4184","-18.9233","0.4184","0.2789","-4.5055"
"1.8400","0.4376","-17.6825","0.4376","0.2917","-4.2101"
"1.9200","0.4578","-16.3363","0.4578","0.3052","-3.8896"
"2.0000","0.4775","-15.0399","0.4775","0.3183","-3.5809"
"2.0800","0.4967","-13.7752","0.4967","0.3311","-3.2798"
"2.1600","0.5172","-12.4022","0.5172","0.3448","-2.9529"
"2.2400","0.5363","-11.1900","0.5363","0.3576","-2.6643"
"2.3200","0.5561","-9.8614","0.5561","0.3708","-2.3480"
"2.4000","0.5777","-8.4212","0.5777","0.3851","-2.0050"
"2.4800","0.5974","-7.1590","0.5974","0.3983","-1.7045"
"2.5600","0.6181","-5.8001","0.6181","0.4121","-1.3810"
"2.6400","0.6371","-4.5824","0.6371","0.4247","-1.0911"
"2.7200","0.6564","-3.3182","0.6564","0.4376","-0.7900"
"2.8000","0.6766","-1.9833","0.6766","0.4511","-0.4722"
"2.8800","0.6970","-0.6612","0.6970","0.4647","-0.1574"
"2.9600","0.7177","0.7098","0.7177","0.4785","0.1690"
"3.0400","0.7382","2.0524","0.7382","0.4922","0.4887"
"3.1200","0.7573","3.2707","0.7573","0.5048","0.7787"
"3.2000","0.7777","4.6056","0.7777","0.5185","1.0966"
"3.2800","0.7974","5.8756","0.7974","0.5316","1.3990"
"3.3600","0.8170","7.1678","0.8170","0.5447","1.7066"
"3.4400","0.8371","8.4645","0.8371","0.5581","2.0153"
"3.5200","0.8557","9.6599","0.8557","0.5705","2.3000"
"3.6000","0.8771","11.0836","0.8771","0.5848","2.6389"
"3.6800","0.8984","12.5027","0.8984","0.5989","2.9768"
"3.7600","0.9177","13.7421","0.9177","0.6118","3.2719"
"3.8400","0.9373","15.0120","0.9373","0.6249","3.5743"
"3.9200","0.9562","16.2049","0.9562","0.6375","3.8583"
"4.0000","0.9765","17.5498","0.9765","0.6510","4.1785"
"4.0800","0.9976","18.9407","0.9976","0.6651","4.5097"
"4.1600","1.0166","20.1745","1.0166","0.6777","4.8035"
"4.2400","1.0378","21.5685","1.0378","0.6919","5.1353"
"4.3200","1.0579","22.8829","1.0579","0.7053","5.4483"
"4.4000","1.0778","24.1928","1.0778","0.7185","5.7602"
"4.4800","1.0974","25.4562","1.0974","0.7316","6.0610"
"4.5600","1.1168","26.7099","1.1168","0.7446","6.3595"
"4.6400","1.1370","28.0389","1.1370","0.7580","6.6759"
"4.7200","1.1568","29.3035","1.1568","0.7712","6.9770"
"4.8000","1.1760","30.5534","1.1760","0.7840","7.2746"
"4.8800","1.1975","31.9895","1.1975","0.7983","7.6166"
"4.9600","1.2174","33.2690","1.2174","0.8116","7.9212"
"5.0400","1.2378","34.6153","1.2378","0.8252","8.2417"
"5.1200","1.2573","35.8662","1.2573","0.8382","8.5396"
"5.2000","1.2763","37.1039","1.2763","0.8509","8.8343"
"5.2800","1.2972","38.4797","1.2972","0.8648","9.1618"
"5.3600","1.3172","39.7969","1.3172","0.8781","9.4755"
"5.4400","1.3371","41.1063","1.3371","0.8914","9.7872"
"5.5200","1.3579","42.4865","1.3579","0.9053","10.1158"
"5.6000","1.3776","43.7396","1.3776","0.9184","10.4142"
"5.6800","1.3982","45.1159","1.3982","0.9322","10.7419"
"5.7600","1.4179","46.3916","1.4179","0.9453","11.0456"
"5.8400","1.4367","47.6095","1.4367","0.9578","11.3356"
"5.9200","1.4568","48.9232","1.4568","0.9712","11.6484"
"6.0000","1.4760","50.1640","1.4760","0.9840","11.9438"
"6.0800","1.4974","51.6192","1.4974","0.9982","12.2903"
"6.1600","1.5183","53.0141","1.5183","1.0122","12.6224"
"6.2400","1.5376","54.2406","1.5376","1.0251","12.9144"
"6.3200","1.5570","55.4940","1.5570","1.0380","13.2129"
"6.4000","1.5771","56.8282","1.5771","1.0514","13.5305"
"6.4800","1.5963","58.0725","1.5963","1.0642","13.8268"
"6.5600","1.6177","59.5048","1.6177","1.0785","14.1678"
"6.6400","1.6364","60.6824","1.6364","1.0909","14.4482"
"6.7200","1.6574","62.0893","1.6574","1.1049","14.7832"
"6.8000","1.6780","63.4604","1.6780","1.1187","15.1096"
"6.8800","1.6980","64.7779","1.6980","1.1320","15.4233"
"6.9600","1.7174","66.0242","1.7174","1.1449","15.7200"
"7.0400","1.7371","67.3067","1.7371","1.1581","16.0254"
"7.1200","1.7565","68.5844","1.7565","1.1710","16.3296"
"7.2000","1.7773","69.9701","1.7773","1.1849","16.6596"
"7.2800","1.7961","71.1739","1.7961","1.1974","16.9462"
"7.3600","1.8172","72.5967","1.8172","1.2114","17.2849"
"7.4400","1.8378","73.9549","1.8378","1.2252","17.6083"
"7.5200","1.8577","75.2758","1.8577","1.2385","17.9228"
"7.6000","1.8777","76.5822","1.8777","1.2518","18.2339"
"7.6800","1.8964","77.7883","1.8964","1.2643","18.5210"
"7.7600","1.9171","79.1842","1.9171","1.2781","18.8534"
"7.8400","1.9370","80.4988","1.9370","1.2914","19.1664"
"7.9200","1.9566","81.7967","1.9566","1.3044","19.4754"
"8.0000","1.9777","83.2267","1.9777","1.3184","19.8159"
"8.0800","1.9984","84.6036","1.9984","1.3322","20.1437"
"8.1600","2.0181","85.9103","2.0181","1.3454","20.4548"
"8.2400","2.0376","87.1964","2.0376","1.3584","20.7610"
"8.3200","2.0560","88.3829","2.0560","1.3707","21.0436"
"8.4000","2.0768","89.8115","2.0768","1.3845","21.3837"
"8.4800","2.0971","91.1907","2.0971","1.3981","21.7121"
"8.5600","2.1172","92.5601","2.1172","1.4115","22.0381"
"8.6400","2.1370","93.8976","2.1370","1.4247","22.3566"
"8.7200","2.1576","95.2906","2.1576","1.4384","22.6882"
"8.8000","2.1775","96.6543","2.1775","1.4517","23.0129"
"8.8800","2.1981","98.0432","2.1981","1.4654","23.3436"
"8.9600","2.2165","99.2555","2.2165","1.4777","23.6323"
"9.0400","2.2371","100.6737","2.2371","1.4914","23.9699"
"9.1200","2.2564","101.9455","2.2564","1.5043","24.2727"
"9.2000","2.2771","103.3958","2.2771","1.5181","24.6181"
"9.2800","2.2983","104.8587","2.2983","1.5322","24.9663"
"9.3600","2.3179","106.1544","2.3179","1.5453","25.2749"
"9.4400","2.3374","107.4381","2.3374","1.5583","25.5805"
"9.5200","2.3570","108.7546","2.3570","1.5713","25.8940"
"9.6000","2.3768","110.1134","2.3768","1.5845","26.2175"
"9.6800","2.3975","111.5929","2.3975","1.5983","26.5697"
"9.7600","2.4167","112.8619","2.4167","1.6111","26.8719"
"9.8400","2.4368","114.2404","2.4368","1.6245","27.2001"
"9.9200","2.4579","115.6867","2.4579","1.6386","27.5445"
"10.0000","2.4773","117.0126","2.4773","1.6515","27.8601"
"10.0800","2.4978","118.4077","2.4978","1.6652","28.1923"
"10.1600","2.5170","119.6835","2.5170","1.6780","28.4961"
"10.2400","2.5370","121.0728","2.5370","1.6913","28.8269"
"10.3200","2.5565","122.4154","2.5565","1.7043","29.1465"
"10.4000","2.5764","123.7759","2.5764","1.7176","29.4704"
"10.4800","2.5976","125.2735","2.5976","1.7317","29.8270"
"10.5600","2.6187","126.7397","2.6187","1.7458","30.1761"
"10.6400","2.6374","127.9853","2.6374","1.7583","30.4727"
"10.7200","2.6572","129.3490","2.6572","1.7715","30.7974"
"10.8000","2.6766","130.6692","2.6766","1.7844","31.1117"
"10.8800","2.6978","132.1871","2.6978","1.7985","31.4731"
"10.9600","2.7175","133.5270","2.7175","1.8117","31.7921"
"11.0400","2.7361","134.7893","2.7361","1.8240","32.0927"
"11.1200","2.7567","136.2525","2.7567","1.8378","32.4411"
"11.2000","2.7776","137.7256","2.7776","1.8517","32.7918"
"11.2800","2.7977","139.1356","2.7977","1.8652","33.1275"
"11.3600","2.8178","140.5360","2.8178","1.8785","33.4610"
"11.4400","2.8364","141.7744","2.8364","1.8909","33.7558"
"11.5200","2.8568","143.2332","2.8568","1.9045","34.1032"
"11.6000","2.8773","144.6565","2.8773","1.9182","34.4420"
"11.6800","2.8968","146.0182","2.8968","1.9312","34.7662"
"11.7600","2.9178","147.4945","2.9178","1.9452","35.1177"
"11.8400","2.9378","148.8734","2.9378","1.9585","35.4461"
"11.9200","2.9581","150.2964","2.9581","1.9721","35.7849"
"12.0000","2.9775","151.6411","2.9775","1.9850","36.1050"
"12.0800","2.9971","152.9989","2.9971","1.9981","36.4283"
"12.1600","3.0172","154.4139","3.0172","2.0114","36.7652"
"12.2400","3.0365","155.7372","3.0365","2.0243","37.0803"
"12.3200","3.0562","157.1237","3.0562","2.0374","37.4104"
"12.4000","3.0781","158.7096","3.0781","2.0520","37.7880"
"12.4800","3.0975","160.0276","3.0975","2.0650","38.1018"
"12.5600","3.1179","161.4618","3.1179","2.0786","38.4433"
"12.6400","3.1370","162.7780","3.1370","2.0913","38.7567"
"12.7200","3.1565","164.1345","3.1565","2.1043","39.0797"
"12.8000","3.1766","165.5341","3.1766","2.1177","39.4129"
"12.8800","3.1968","166.9530","3.1968","2.1312","39.7507"
"12.9600","3.2176","168.4268","3.2176","2.1450","40.1016"
"13.0400","3.2382","169.8876","3.2382","2.1588","40.4494"
"13.1200","3.2571","171.1998","3.2571","2.1714","40.7619"
"13.2000","3.2780","172.7134","3.2780","2.1853","41.1222"
"13.2800","3.2977","174.0948","3.2977","2.1985","41.4511"
"13.3600","3.3176","175.4987","3.3176","2.2117","41.7854"
"13.4400","3.3368","176.8206","3.3368","2.2245","42.1001"
"13.5200","3.3556","178.1375","3.3556","2.2371","42.4137"
"13.6000","3.3771","179.6862","3.3771","2.2514","42.7824"
"13.6800","3.3982","181.2006","3.3982","2.2655","43.1430"
"13.7600","3.4180","182.5869","3.4180","2.2787","43.4731"
"13.8400","3.4372","183.9189","3.4372","2.2915","43.7902"
"13.9200","3.4566","185.2513","3.4566","2.3044","44.1075"
"14.0000","3.4767","186.7108","3.4767","2.3178","44.4549"
"14.0800","3.4976","188.1933","3.4976","2.3317","44.8079"
"14.1600","3.5164","189.4794","3.5164","2.3442","45.1141"
"14.2400","3.5378","191.0315","3.5378","2.3585","45.4837"
"14.3200","3.5578","192.4310","3.5578","2.3719","45.8169"
"14.4000","3.5778","193.8375","3.5778","2.3852","46.1518"
"14.4800","3.5972","195.2014","3.5972","2.3981","46.4765"
"14.5600","3.6169","196.5810","3.6169","2.4113","46.8050"
"14.6400","3.6370","197.9991","3.6370","2.4247","47.1426"
"14.7200","3.6570","199.4178","3.6570","2.4380","47.4804"
"14.8000","3.6760","200.7424","3.6760","2.4507","47.7958"
"14.8800","3.6967","202.2304","3.6967","2.4644","48.1501"
"14.9600","3.7173","203.6831","3.7173","2.4782","48.4960"
"15.0400","3.7378","205.1354","3.7378","2.4918","48.8418"
"15.1200","3.7573","206.4918","3.7573","2.5049","49.1647"
"15.2000","3.7760","207.7781","3.7760","2.5173","49.4710"
"15.2800","3.7970","209.2973","3.7970","2.5313","49.8327"
"15.3600","3.8172","210.7192","3.8172","2.5448","50.1712"
"15.4400","3.8372","212.1422","3.8372","2.5582","50.5100"
"15.5200","3.8578","213.6294","3.8578","2.5719","50.8641"
"15.6000","3.8776","215.0036","3.8776","2.5851","51.1913"
"15.6800","3.8978","216.4420","3.8978","2.5985","51.5338"
"15.7600","3.9180","217.8680","3.9180","2.6120","51.8733"
"15.8400","3.9366","219.1657","3.9366","2.6244","52.1823"
"15.9200","3.9570","220.6214","3.9570","2.6380","52.5289"
"16.0000","3.9762","221.9615","3.9762","2.6508","52.8480"
"16.0800","3.9973","223.4963","3.9973","2.6649","53.2134"
"16.1600","4.0180","224.9818","4.0180","2.6786","53.5671"
"16.2400","4.0375","226.3310","4.0375","2.6917","53.8883"
"16.3200","4.0573","227.7128","4.0573","2.7049","54.2173"
"16.4000","4.0771","229.1027","4.0771","2.7181","54.5483"
"16.4800","4.0964","230.4630","4.0964","2.7309","54.8721"
"16.5600","4.1174","231.9782","4.1174","2.7449","55.2329"
"16.6400","4.1364","233.2896","4.1364","2.7576","55.5452"
"16.7200","4.1577","234.8357","4.1577","2.7718","55.9133"
"16.8000","4.1781","236.2889","4.1781","2.7854","56.2593"
"16.8800","4.1980","237.6895","4.1980","2.7986","56.5927"
"16.9600","4.2173","239.0299","4.2173","2.8116","56.9119"
"17.0400","4.2371","240.4298","4.2371","2.8247","57.2452"
"17.1200","4.2568","241.8271","4.2568","2.8378","57.5779"
"17.2000","4.2770","243.2719","4.2770","2.8513","57.9219"
"17.2800","4.2957","244.5670","4.2957","2.8638","58.2302"
"17.3600","4.3173","246.1457","4.3173","2.8782","58.6061"
"17.4400","4.3380","247.6146","4.3380","2.8920","58.9559"
"17.5200","4.3569","248.9178","4.3569","2.9046","59.2662"
"17.6000","4.3769","250.3322","4.3769","2.9180","59.6029"
"17.6800","4.3968","251.7273","4.3968","2.9312","59.9351"
"17.7600","4.4176","253.2153","4.4176","2.9450","60.2894"
"17.8400","4.4372","254.5983","4.4372","2.9581","60.6186"
"17.9200","4.4566","255.9547","4.4566","2.9711","60.9416"
"18.0000","4.4774","257.4647","4.4774","2.9849","61.3011"
"18.0800","4.4983","258.9482","4.4983","2.9988","61.6543"
"18.1600","4.5181","260.3425","4.5181","3.0120","61.9863"
"18.2400","4.5378","261.7193","4.5378","3.0252","62.3141"
"18.3200","4.5558","262.9294","4.5558","3.0372","62.6023"
"18.4000","4.5772","264.4901","4.5772","3.0515","62.9738"
"18.4800","4.5967","265.8540","4.5967","3.0645","63.2986"
"18.5600","4.6169","267.3047","4.6169","3.0780","63.6440"
"18.6400","4.6372","268.7420","4.6372","3.0914","63.9862"
"18.7200","4.6574","270.1636","4.6574","3.1050","64.3247"
"18.8000","4.6774","271.5710","4.6774","3.1183","64.6598"
"18.8800","4.6979","273.0461","4.6979","3.1320","65.0110"
"18.9600","4.7165","274.3087","4.7165","3.1444","65.3116"
"19.0400","4.7370","275.7783","4.7370","3.1580","65.6615"
"19.1200","4.7566","277.1474","4.7566","3.1711","65.9875"
"19.2000","4.7774","278.6622","4.7774","3.1850","66.3481"
"19.2800","4.7983","280.1530","4.7983","3.1989","66.7031"
"19.3600","4.8180","281.5210","4.8180","3.2120","67.0288"
"19.4400","4.8378","282.8990","4.8378","3.2252","67.3569"
"19.5200","4.8575","284.2772","4.8575","3.2383","67.6850"
"19.6000","4.8770","285.6515","4.8770","3.2514","68.0123"
"19.6800","4.8970","287.0551","4.8970","3.2646","68.3465"
"19.7600","4.9165","288.4435","4.9165","3.2777","68.6770"
"19.8400","4.9370","289.9138","4.9370","3.2914","69.0271"
"19.9200","4.9578","291.3722","4.9578","3.3052","69.3743"
"20.0000","4.9772","292.7124","4.9772","3.3181","69.6934"
"20.0800","4.9977","294.1601","4.9977","3.3318","70.0381"
"20.1600","5.0168","295.4656","5.0168","3.3445","70.3489"
"20.2400","5.0367","296.8653","5.0367","3.3578","70.6822"
"20.3200","5.0564","298.2307","5.0564","3.3709","71.0073"
"20.4000","5.0766","299.6514","5.0766","3.3844","71.3456"
"20.4800","5.0977","301.1574","5.0977","3.3985","71.7041"
"20.5600","5.1183","302.5911","5.1183","3.4122","72.0455"
"20.6400","5.1375","303.9102","5.1375","3.4250","72.3596"
"20.7200","5.1575","305.3013","5.1575","3.4384","72.6908"
"20.8000","5.1763","306.5649","5.1763","3.4509","72.9917"
"20.8800","5.1974","308.0904","5.1974","3.4649","73.3549"
"20.9600","5.2172","309.4614","5.2172","3.4781","73.6813"
"21.0400","5.2363","310.7803","5.2363","3.4909","73.9953"
"21.1200","5.2563","312.1724","5.2563","3.5042","74.3268"
"21.2000","5.2774","313.6796","5.2774","3.5183","74.6856"
"21.2800","5.2982","315.1396","5.2982","3.5321","75.0332"
"21.3600","5.3182","316.5215","5.3182","3.5455","75.3623"
"21.4400","5.3362","317.6875","5.3362","3.5575","75.6399"
"21.5200","5.3563","319.1005","5.3563","3.5709","75.9763"
"21.6000","5.3772","320.5895","5.3772","3.5848","76.3308"
"21.6800","5.3971","321.9907","5.3971","3.5981","76.6645"
"21.7600","5.4184","323.5091","5.4184","3.6123","77.0260"
"21.8400","5.4375","324.7726","5.4375","3.6250","77.3268"
"21.9200","5.4578","326.1870","5.4578","3.6385","77.6636"
"22.0000","5.4776","327.5619","5.4776","3.6518","77.9909"
"22.0800","5.4972","328.8975","5.4972","3.6648","78.3089"
"22.1600","5.5171","330.2943","5.5171","3.6781","78.6415"
"22.2400","5.5365","331.5941","5.5365","3.6910","78.9510"
"22.3200","5.5563","332.9760","5.5563","3.7042","79.2800"
"22.4000","5.5776","334.4728","5.5776","3.7184","79.6364"
"22.4800","5.5973","335.8027","5.5973","3.7315","79.9530"
"22.5600","5.6183","337.2693","5.6183","3.7456","80.3022"
"22.6400","5.6370","338.5052","5.6370","3.7580","80.5965"
"22.7200","5.6566","339.8552","5.6566","3.7711","80.9179"
"22.8000","5.6762","341.1858","5.6762","3.7841","81.2347"
"22.8800","5.6967","342.6202","5.6967","3.7978","81.5763"
"22.9600","5.7176","344.0781","5.7176","3.8118","81.9234"
"23.0400","5.7383","345.5040","5.7383","3.8255","82.2629"
"23.1200","5.7572","346.7486","5.7572","3.8381","82.5592"
"23.2000","5.7778","348.1842","5.7778","3.8518","82.9010"
"23.2800","5.7972","349.4795","5.7972","3.8648","83.2094"
"23.3600","5.8174","350.8724","5.8174","3.8782","83.5411"
"23.4400","5.8370","352.1938","5.8370","3.8914","83.8557"
"23.5200","5.8549","353.3463","5.8549","3.9033","84.1301"
"23.6000","5.8773","354.9743","5.8773","3.9182","84.5177"
"23.6800","5.8986","356.4703","5.8986","3.9324","84.8739"
"23.7600","5.9184","357.7993","5.9184","3.9456","85.1903"
"23.8400","5.9373","359.0471","5.9373","3.9582","85.4874"
"23.9200","5.9566","360.3292","5.9566","3.9711","85.7927"
"24.0000","5.9766","361.7016","5.9766","3.9844","86.1194"
"24.0800","5.9977","363.1637","5.9977","3.9985","86.4675"
"24.1600","6.0165","364.3889","6.0165","4.0110","86.7593"
"24.2400","6.0378","365.8810","6.0378","4.0252","87.1145"
"24.3200","6.0578","367.2205","6.0578","4.0385","87.4335"
"24.4000","6.0782","368.6182","6.0782","4.0522","87.7662"
"24.4800","6.0974","369.8832","6.0974","4.0649","88.0674"
"24.5600","6.1172","371.1973","6.1172","4.0782","88.3803"
"24.6400","6.1367","372.4960","6.1367","4.0912","88.6895"
"24.7200","6.1572","373.9236","6.1572","4.1048","89.0294"
"24.8000","6.1762","375.1595","6.1762","4.1175","89.3237"
"24.8800","6.1975","376.6194","6.1975","4.1317","89.6713"
"24.9600","6.2175","377.9304","6.2175","4.1450","89.9834"
"25.0400","6.2375","379.2686","6.2375","4.1584","90.3020"
"25.1200","6.2572","380.5659","6.2572","4.1715","90.6109"
"25.2000","6.2762","381.7958","6.2762","4.1841","90.9038"
"25.2800","6.2970","383.2030","6.2970","4.1980","91.2388"
"25.3600","6.3172","384.5567","6.3172","4.2115","91.5611"
"25.4400","6.3372","385.8814","6.3372","4.2248","91.8765"
"25.5200","6.3575","387.2484","6.3575","4.2384","92.2020"
"25.6000","6.3776","388.5392","6.3776","4.2517","92.5093"
"25.6800","6.3978","389.8797","6.3978","4.2652","92.8285"
"25.7600","6.4178","391.1901","6.4178","4.2786","93.1405"
"25.8400","6.4366","392.4013","6.4366","4.2911","93.4289"
"25.9200","6.4571","393.7518","6.4571","4.3047","93.7504"
"26.0000","6.4759","394.9430","6.4759","4.3173","94.0340"
"26.0800","6.4968","396.3676","6.4968","4.3312","94.3732"
"26.1600","6.5183","397.8240","6.5183","4.3456","94.7200"
"26.2400","6.5379","399.0637","6.5379","4.3586","95.0152"
"26.3200","6.5575","400.3286","6.5575","4.3717","95.3163"
"26.4000","6.5771","401.5738","6.5771","4.3847","95.6128"
"26.4800","6.5969","402.8724","6.5969","4.3979","95.9220"
"26.5600","6.6172","404.1926","6.6172","4.4114","96.2363"
"26.6400","6.6362","405.3838","6.6362","4.4241","96.5200"
"26.7200","6.6574","406.8047","6.6574","4.4383","96.8583"
"26.8000","6.6782","408.1861","6.6782","4.4521","97.1872"
"26.8800","6.6981","409.4569","6.6981","4.4654","97.4897"
"26.9600","6.7175","410.6754","6.7175","4.4783","97.7798"
"27.0400","6.7371","411.9117","6.7371","4.4914","98.0742"
"27.1200","6.7571","413.1959","6.7571","4.5047","98.3800"
"27.2000","6.7769","414.4846","6.7769","4.5180","98.6868"
"27.2800","6.7957","415.6309","6.7957","4.5305","98.9597"
"27.3600","6.8173","417.0726","6.8173","4.5448","99.3030"
"27.4400","6.8381","418.4180","6.8381","4.5587","99.6233"
"27.5200","6.8576","419.6497","6.8576","4.5717","99.9166"
"27.6000","6.8773","420.8731","6.8773","4.5848","100.2079"
"27.6800","6.8960","422.0124","6.8960","4.5973","100.4791"
"27.7600","6.9174","423.4300","6.9174","4.6116","100.8167"
"27.8400","6.9373","424.6845","6.9373","4.6249","101.1154"
"27.9200","6.9567","425.8884","6.9567","4.6378","101.4020"
"28.0000","6.9771","427.1999","6.9771","4.6514","101.7143"
"28.0800","6.9985","428.5780","6.9985","4.6657","102.0424"
"28.1600","7.0182","429.7919","7.0182","4.6788","102.3314"
"28.2400","7.0376","430.9865","7.0376","4.6918","102.6158"
"28.3200","7.0558","432.0473","7.0558","4.7038","102.8684"
"28.4000","7.0773","433.4656","7.0773","4.7182","103.2061"
"28.4800","7.0969","434.6549","7.0969","4.7312","103.4893"
"28.5600","7.1171","435.9279","7.1171","4.7447","103.7924"
"28.6400","7.1370","437.1466","7.1370","4.7580","104.0825"
"28.7200","7.1575","438.4129","7.1575","4.7717","104.3840"
"28.8000","7.1775","439.6495","7.1775","4.7850","104.6784"
"28.8800","7.1981","440.9304","7.1981","4.7988","104.9834"
"28.9600","7.2169","442.0237","7.2169","4.8113","105.2437"
"29.0400","7.2369","443.2456","7.2369","4.8246","105.5347"
"29.1200","7.2560","444.3686","7.2560","4.8373","105.8021"
"29.2000","7.2771","445.7266","7.2771","4.8514","106.1254"
"29.2800","7.2986","447.0844","7.2986","4.8657","106.4487"
"29.3600","7.3185","448.3015","7.3185","4.8790","106.7385"
"29.4400","7.3380","449.4156","7.3380","4.8920","107.0037"
"29.5200","7.3571","450.5490","7.3571","4.9047","107.2736"
"29.6000","7.3769","451.7372","7.3769","4.9179","107.5565"
"29.6800","7.3972","452.9593","7.3972","4.9315","107.8474"
"29.7600","7.4164","454.0453","7.4164","4.9443","108.1060"
"29.8400","7.4367","455.2756","7.4367","4.9578","108.3989"
"29.9200","7.4577","456.5475","7.4577","4.9718","108.7018"
"30.0000","7.4771","457.6705","7.4771","4.9847","108.9692"
"30.0800","7.4977","458.8799","7.4977","4.9984","109.2571"
"30.1600","7.5170","459.9960","7.5170","5.0113","109.5229"
"30.2400","7.5371","461.1825","7.5371","5.0248","109.8053"
"30.3200","7.5565","462.2783","7.5565","5.0377","110.0663"
"30.4000","7.5763","463.4149","7.5763","5.0508","110.3369"
"30.4800","7.5974","464.6818","7.5974","5.0649","110.6385"
"30.5600","7.6186","465.9424","7.6186","5.0791","110.9387"
"30.6400","7.6381","467.0354","7.6381","5.0921","111.1989"
"30.7200","7.6579","468.1802","7.6579","5.1053","111.4715"
"30.8000","7.6766","469.0849","7.6766","5.1178","111.6869"
"30.8800","7.6975","470.3024","7.6975","5.1316","111.9768"
"30.9600","7.7171","471.3686","7.7171","5.1447","112.2306"
"31.0400","7.7358","472.3878","7.7358","5.1572","112.4733"
"31.1200","7.7574","473.6639","7.7574","5.1716","112.7771"
"31.2000","7.7779","474.8055","7.7779","5.1853","113.0489"
"31.2800","7.7979","475.9235","7.7979","5.1986","113.3151"
"31.3600","7.8179","477.0379","7.8179","5.2119","113.5805"
"31.4400","7.8366","477.9947","7.8366","5.2244","113.8083"
"31.5200","7.8565","479.1024","7.8565","5.2377","114.0720"
"31.6000","7.8768","480.2180","7.8768","5.2512","114.3376"
"31.6800","7.8969","481.3509","7.8969","5.2646","114.6073"
"31.7600","7.9184","482.5815","7.9184","5.2790","114.9004"
"31.8400","7.9377","483.5634","7.9377","5.2918","115.1341"
"31.9200","7.9579","484.6677","7.9579","5.3053","115.3971"
"32.0000","7.9775","485.7047","7.9775","5.3184","115.6440"
"32.0800","7.9969","486.7198","7.9969","5.3313","115.8857"
"32.1600","8.0170","487.8007","8.0170","5.3447","116.1430"
"32.2400","8.0365","488.8069","8.0365","5.3577","116.3826"
"32.3200","8.0562","489.8561","8.0562","5.3708","116.6324"
"32.4000","8.0775","491.0374","8.0775","5.3850","116.9137"
"32.4800","8.0973","492.0417","8.0973","5.3982","117.1528"
"32.5600","8.1181","493.1510","8.1181","5.4121","117.4169"
"32.6400","8.1373","494.1045","8.1373","5.4249","117.6439"
"32.7200","8.1567","495.0872","8.1567","5.4378","117.8779"
"32.8000","8.1761","496.0697","8.1761","5.4507","118.1118"
"32.8800","8.1969","497.1728","8.1969","5.4646","118.3745"
"32.9600","8.2175","498.2353","8.2175","5.4783","118.6275"
"33.0400","8.2382","499.2966","8.2382","5.4921","118.8801"
"33.1200","8.2572","500.2030","8.2572","5.5048","119.0960"
"33.2000","8.2778","501.2641","8.2778","5.5185","119.3486"
"33.2800","8.2974","502.1989","8.2974","5.5316","119.5712"
"33.3600","8.3174","503.2082","8.3174","5.5449","119.8115"
"33.4400","8.3368","504.1299","8.3368","5.5579","120.0309"
"33.5200","8.3559","505.0056","8.3559","5.5706","120.2394"
"33.6000","8.3771","506.0955","8.3771","5.5848","120.4989"
"33.6800","8.3983","507.1766","8.3983","5.5988","120.7563"
"33.7600","8.4177","508.0604","8.4177","5.6118","120.9668"
"33.8400","8.4368","508.9388","8.4368","5.6245","121.1759"
"33.9200","8.4565","509.8574","8.4565","5.6377","121.3946"
"34.0000","8.4770","510.8701","8.4770","5.6513","121.6357"
"34.0800","8.4976","511.8502","8.4976","5.6651","121.8691"
"34.1600","8.5168","512.7114","8.5168","5.6778","122.0741"
"34.2400","8.5377","513.7072","8.5377","5.6918","122.3112"
"34.3200","8.5578","514.6301","8.5578","5.7052","122.5310"
"34.4000","8.5784","515.5956","8.5784","5.7189","122.7609"
"34.4800","8.5973","516.4069","8.5973","5.7315","122.9540"
"34.5600","8.6169","517.2661","8.6169","5.7446","123.1586"
"34.6400","8.6370","518.1760","8.6370","5.7580","123.3752"
"34.7200","8.6571","519.0704","8.6571","5.7714","123.5882"
"34.8000","8.6761","519.8672","8.6761","5.7841","123.7779"
"34.8800","8.6972","520.8548","8.6972","5.7982","124.0130"
"34.9600","8.7177","521.7474","8.7177","5.8118","124.2256"
"35.0400","8.7379","522.6158","8.7379","5.8252","124.4323"
"35.1200","8.7574","523.4368","8.7574","5.8383","124.6278"
"35.2000","8.7765","524.2202","8.7765","5.8510","124.8143"
"35.2800","8.7969","525.0836","8.7969","5.8646","125.0199"
"35.3600","8.8170","525.9274","8.8170","5.8780","125.2208"
"35.4400","8.8370","526.7708","8.8370","5.8913","125.4216"
"35.5200","8.8579","527.6868","8.8579","5.9052","125.6397"
"35.6000","8.8778","528.4678","8.8778","5.9186","125.8257"
"35.6800","8.8979","529.2768","8.8979","5.9319","126.0183"
"35.7600","8.9180","530.0787","8.9180","5.9453","126.2092"
"35.8400","8.9365","530.7520","8.9365","5.9576","126.3695"
"35.9200","8.9567","531.5721","8.9567","5.9711","126.5648"
"36.0000","8.9757","532.2800","8.9757","5.9838","126.7333"
"36.0800","8.9974","533.2306","8.9974","5.9982","126.9597"
"36.1600","9.0174","534.0167","9.0174","6.0116","127.1468"
"36.2400","9.0378","534.8090","9.0378","6.0252","127.3355"
"36.3200","9.0573","535.5107","9.0573","6.0382","127.5025"
"36.4000","9.0773","536.2507","9.0773","6.0515","127.6787"
"36.4800","9.0970","537.0063","9.0970","6.0646","127.8586"
"36.5600","9.1173","537.7749","9.1173","6.0782","128.0416"
"36.6400","9.1359","538.3735","9.1359","6.0906","128.1842"
"36.7200","9.1578","539.2858","9.1578","6.1052","128.4014"
"36.8000","9.1783","540.0405","9.1783","6.1189","128.5811"
"36.8800","9.1984","540.7869","9.1984","6.1323","128.7588"
"36.9600","9.2178","541.4420","9.2178","6.1452","128.9148"
"37.0400","9.2372","542.0817","9.2372","6.1581","129.0671"
"37.1200","9.2569","542.7734","9.2569","6.1713","129.2318"
"37.2000","9.2768","543.4516","9.2768","6.1846","129.3932"
"37.2800","9.2959","544.0564","9.2959","6.1973","129.5372"
"37.3600","9.3174","544.8638","9.3174","6.2116","129.7295"
"37.4400","9.3381","545.5654","9.3381","6.2254","129.8965"
"37.5200","9.3577","546.2020","9.3577","6.2385","130.0481"
"37.6000","9.3773","546.8054","9.3773","6.2515","130.1918"
"37.6800","9.3965","547.3904","9.3965","6.2643","130.3311"
"37.7600","9.4173","548.0917","9.4173","6.2782","130.4980"
"37.8400","9.4368","548.6858","9.4368","6.2912","130.6395"
"37.9200","9.4566","549.3063","9.4566","6.3044","130.7872"
"38.0000","9.4772","549.9757","9.4772","6.3181","130.9466"
"38.0800","9.4985","550.6649","9.4985","6.3323","131.1107"
"38.1600","9.5177","551.1905","9.5177","6.3451","131.2358"
"38.2400","9.5376","551.7827","9.5376","6.3584","131.3768"
"38.3200","9.5559","552.2339","9.5559","6.3706","131.4843"
"38.4000","9.5765","552.8847","9.5765","6.3843","131.6392"
"38.4800","9.5969","553.5018","9.5969","6.3980","131.7862"
"38.5600","9.6171","554.1022","9.6171","6.4114","131.9291"
"38.6400","9.6372","554.6715","9.6372","6.4248","132.0646"
"38.7200","9.6576","555.2346","9.6576","6.4384","132.1987"
"38.8000","9.6774","555.7667","9.6774","6.4516","132.3254"
"38.8800","9.6979","556.3459","9.6979","6.4652","132.4633"
"38.9600","9.7169","556.8027","9.7169","6.4779","132.5721"
"39.0400","9.7369","557.3298","9.7369","6.4913","132.6976"
"39.1200","9.7562","557.7984","9.7562","6.5042","132.8091"
"39.2000","9.7771","558.4046","9.7771","6.5181","132.9535"
"39.2800","9.7981","558.9971","9.7981","6.5321","133.0945"
"39.3600","9.8183","559.4865","9.8183","6.5455","133.2111"
"39.4400","9.8381","559.9360","9.8381","6.5587","133.3181"
"39.5200","9.8570","560.3416","9.8570","6.5713","133.4147"
"39.6000","9.8771","560.8536","9.8771","6.5847","133.5366"
"39.6800","9.8970","561.3110","9.8970","6.5980","133.6455"
"39.7600","9.9163","561.7103","9.9163","6.6109","133.7406"
"39.8400","9.9367","562.2228","9.9367","6.6245","133.8626"
"39.9200","9.9582","562.7923","9.9582","6.6388","133.9982"
"40.0000","9.9777","563.2131","9.9777","6.6518","134.0984"
"40.0800","9.9979","563.6290","9.9979","6.6653","134.1974"
"40.1600","10.0167","563.9700","10.0167","6.6778","134.2786"
"40.2400","10.0372","564.4389","10.0372","6.6915","134.3902"
"40.3200","10.0562","564.7966","10.0562","6.7041","134.4754"
"40.4000","10.0765","565.2340","10.0765","6.7177","134.5795"
"40.4800","10.0978","565.7260","10.0978","6.7318","134.6967"
"40.5600","10.1185","566.1685","10.1185","6.7456","134.8020"
"40.6400","10.1368","566.4438","10.1368","6.7579","134.8676"
"40.7200","10.1574","566.8907","10.1574","6.7716","134.9740"
"40.8000","10.1771","567.2318","10.1771","6.7847","135.0552"
"40.8800","10.1980","567.6742","10.1980","6.7986","135.1605"
"40.9600","10.2174","567.9827","10.2174","6.8116","135.2340"
"41.0400","10.2362","568.2711","10.2362","6.8241","135.3026"
"41.1200","10.2565","568.6418","10.2565","6.8377","135.3909"
"41.2000","10.2776","569.0731","10.2776","6.8517","135.4936"
"41.2800","10.2982","569.4567","10.2982","6.8655","135.5849"
"41.3600","10.3179","569.7595","10.3179","6.8786","135.6570"
"41.4400","10.3366","569.9843","10.3366","6.8911","135.7105"
"41.5200","10.3563","570.2991","10.3563","6.9042","135.7855"
"41.6000","10.3767","570.6415","10.3767","6.9178","135.8670"
"41.6800","10.3971","571.0028","10.3971","6.9314","135.9531"
"41.7600","10.4182","571.3717","10.4182","6.9455","136.0409"
"41.8400","10.4378","571.6143","10.4378","6.9585","136.0986"
"41.9200","10.4580","571.9188","10.4580","6.9720","136.1711"
"42.0000","10.4775","572.1766","10.4775","6.9850","136.2325"
"42.0800","10.4973","572.4380","10.4973","6.9982","136.2948"
"42.1600","10.5169","572.6729","10.5169","7.0113","136.3507"
"42.2400","10.5368","572.9427","10.5368","7.0245","136.4149"
"42.3200","10.5567","573.2214","10.5567","7.0378","136.4813"
"42.4000","10.5776","573.5292","10.5776","7.0517","136.5546"
"42.4800","10.5972","573.7265","10.5972","7.0648","136.6016"
"42.5600","10.6182","574.0109","10.6182","7.0788","136.6692"
"42.6400","10.6371","574.1667","10.6371","7.0914","136.7064"
"42.7200","10.6571","574.4135","10.6571","7.1047","136.7651"
"42.8000","10.6762","574.5639","10.6762","7.1174","136.8009"
"42.8800","10.6965","574.8169","10.6965","7.1310","136.8612"
"42.9600","10.7179","575.1202","10.7179","7.1453","136.9334"
"43.0400","10.7387","575.3547","10.7387","7.1591","136.9892"
"43.1200","10.7571","575.4398","10.7571","7.1714","137.0095"
"43.2000","10.7771","575.6286","10.7771","7.1847","137.0544"
"43.2800","10.7976","575.8384","10.7976","7.1984","137.1044"
"43.3600","10.8176","576.0233","10.8176","7.2117","137.1484"
"43.4400","10.8370","576.1415","10.8370","7.2247","137.1766"
"43.5200","10.8558","576.2372","10.8558","7.2372","137.1993"
"43.6000","10.8773","576.4868","10.8773","7.2515","137.2588"
"43.6800","10.8981","576.7065","10.8981","7.2654","137.3111"
"43.7600","10.9182","576.8399","10.9182","7.2788","137.3428"
"43.8400","10.9374","576.9241","10.9374","7.2916","137.3629"
"43.9200","10.9567","576.9872","10.9567","7.3045","137.3779"
"44.0000","10.9761","577.0925","10.9761","7.3174","137.4030"
"44.0800","10.9973","577.2828","10.9973","7.3315","137.4483"
"44.1600","11.0167","577.3560","11.0167","7.3445","137.4657"
"44.2400","11.0380","577.5322","11.0380","7.3587","137.5077"
"44.3200","11.0577","577.5923","11.0577","7.3718","137.5220"
"44.4000","11.0784","577.7256","11.0784","7.3856","137.5537"
"44.4800","11.0975","577.7533","11.0975","7.3984","137.5603"
"44.5600","11.1172","577.8033","11.1172","7.4115","137.5722"
"44.6400","11.1368","577.8435","11.1368","7.4246","137.5818"
"44.7200","11.1571","577.9357","11.1571","7.4381","137.6037"
"44.8000","11.1766","577.9882","11.1766","7.4510","137.6162"
"44.8800","11.1977","578.1063","11.1977","7.4651","137.6444"
"44.9600","11.2174","578.1020","11.2174","7.4783","137.6433"
"45.0400","11.2380","578.1820","11.2380","7.4920","137.6624"
"45.1200","11.2573","578.1641","11.2573","7.5049","137.6581"
"45.2000","11.2767","578.1529","11.2767","7.5178","137.6555"
"45.2800","11.2970","578.1701","11.2970","7.5313","137.6595"
"45.3600","11.3170","578.1796","11.3170","7.5446","137.6618"
"45.4400","11.3373","578.2068","11.3373","7.5582","137.6683"
"45.5200","11.3577","578.2294","11.3577","7.5718","137.6737"
"45.6000","11.3777","578.1885","11.3777","7.5851","137.6639"
"45.6800","11.3983","578.1806","11.3983","7.5989","137.6621"
"45.7600","11.4181","578.1176","11.4181","7.6121","137.6470"
"45.8400","11.4362","577.9771","11.4362","7.6241","137.6136"
"45.9200","11.4564","577.9589","11.4564","7.6376","137.6093"
"46.0000","11.4760","577.8737","11.4759","7.6506","137.5890"
"46.0800","11.4975","577.9132","11.4975","7.6650","137.5984"
"46.1600","11.5180","577.8638","11.5180","7.6787","137.5866"
"46.2400","11.5377","577.7399","11.5377","7.6918","137.5571"
"46.3200","11.5573","577.6268","11.5573","7.7049","137.5302"
"46.4000","11.5772","577.5140","11.5772","7.7181","137.5033"
"46.4800","11.5962","577.3771","11.5962","7.7308","137.4707"
"46.5600","11.6173","577.3471","11.6173","7.7449","137.4636"
"46.6400","11.6362","577.1315","11.6362","7.7574","137.4123"
"46.7200","11.6577","577.1208","11.6577","7.7718","137.4097"
"46.8000","11.6784","577.0174","11.6784","7.7856","137.3851"
"46.8800","11.6983","576.8774","11.6983","7.7989","137.3518"
"46.9600","11.7174","576.6700","11.7174","7.8116","137.3024"
"47.0400","11.7372","576.5146","11.7372","7.8248","137.2654"
"47.1200","11.7572","576.3750","11.7572","7.8382","137.2321"
"47.2000","11.7770","576.2148","11.7770","7.8513","137.1940"
"47.2800","11.7961","576.0033","11.7961","7.8641","137.1436"
"47.3600","11.8170","575.9048","11.8170","7.8780","137.1202"
"47.4400","11.8381","575.7775","11.8381","7.8921","137.0899"
"47.5200","11.8581","575.5945","11.8581","7.9054","137.0463"
"47.6000","11.8778","575.3611","11.8778","7.9185","136.9907"
"47.6800","11.8964","575.0718","11.8964","7.9309","136.9219"
"47.7600","11.9172","574.9026","11.9172","7.9448","136.8816"
"47.8400","11.9368","574.6663","11.9368","7.9579","136.8253"
"47.9200","11.9571","574.4646","11.9571","7.9714","136.7773"
"48.0000","11.9777","574.2542","11.9777","7.9852","136.7272"
"48.0800","11.9983","574.0078","11.9983","7.9989","136.6685"
"48.1600","12.0178","573.7137","12.0178","8.0119","136.5985"
"48.2400","12.0376","573.4231","12.0376","8.0251","136.5293"
"48.3200","12.0563","573.0521","12.0563","8.0375","136.4410"
"48.4000","12.0772","572.8081","12.0772","8.0515","136.3829"
"48.4800","12.0969","572.4760","12.0969","8.0646","136.3038"
"48.5600","12.1174","572.1955","12.1174","8.0782","136.2370"
"48.6400","12.1369","571.8435","12.1369","8.0913","136.1532"
"48.7200","12.1575","571.5411","12.1575","8.1050","136.0812"
"48.8000","12.1776","571.2020","12.1776","8.1184","136.0005"
"48.8800","12.1978","570.8599","12.1978","8.1319","135.9190"
"48.9600","12.2168","570.4713","12.2168","8.1445","135.8265"
"49.0400","12.2370","570.1246","12.2370","8.1580","135.7439"
"49.1200","12.2562","569.7123","12.2562","8.1708","135.6458"
"49.2000","12.2773","569.4390","12.2773","8.1848","135.5807"
"49.2800","12.2988","569.1349","12.2988","8.1992","135.5083"
"49.3600","12.3182","568.7089","12.3182","8.2121","135.4069"
"49.4400","12.3380","568.2907","12.3380","8.2253","135.3073"
"49.5200","12.3571","567.8355","12.3571","8.2381","135.1989"
"49.6000","12.3771","567.4364","12.3771","8.2514","135.1039"
"49.6800","12.3972","567.0270","12.3972","8.2648","135.0064"
"49.7600","12.4162","566.5207","12.4162","8.2774","134.8859"
"49.8400","12.4368","566.1473","12.4368","8.2912","134.7970"
"49.9200","12.4582","565.7459","12.4582","8.3054","134.7014"
"50.0000","12.4774","565.2520","12.4774","8.3183","134.5838"
"50.0800","12.4980","564.7875","12.4980","8.3320","134.4732"
"50.1600","12.5168","564.2265","12.5168","8.3445","134.3396"
"50.2400","12.5377","563.7963","12.5377","8.3585","134.2372"
"50.3200","12.5563","563.2123","12.5563","8.3709","134.0982"
"50.4000","12.5763","562.6953","12.5763","8.3842","133.9751"
"50.4800","12.5976","562.2137","12.5976","8.3984","133.8604"
"50.5600","12.6189","561.7090","12.6189","8.4126","133.7402"
"50.6400","12.6382","561.1029","12.6382","8.4255","133.5959"
"50.7200","12.6574","560.4831","12.6574","8.4383","133.4484"
"50.8000","12.6762","559.8308","12.6762","8.4508","133.2930"
"50.8800","12.6978","559.3155","12.6978","8.4652","133.1704"
"50.9600","12.7175","558.6876","12.7175","8.4783","133.0209"
"51.0400","12.7363","558.0460","12.7363","8.4909","132.8681"
"51.1200","12.7567","557.4664","12.7567","8.5045","132.7301"
"51.2000","12.7777","556.9069","12.7777","8.5184","132.5969"
"51.2800","12.7983","556.3039","12.7983","8.5322","132.4533"
"51.3600","12.8178","555.6351","12.8178","8.5452","132.2941"
"51.4400","12.8367","554.9020","12.8367","8.5578","132.1195"
"51.5200","12.8568","554.2233","12.8568","8.5712","131.9579"
"51.6000","12.8769","553.5437","12.8769","8.5846","131.7961"
"51.6800","12.8969","552.8632","12.8969","8.5979","131.6341"
"51.7600","12.9183","552.1996","12.9183","8.6122","131.4761"
"51.8400","12.9377","551.4140","12.9377","8.6251","131.2890"
"51.9200","12.9580","550.7020","12.9580","8.6387","131.1195"
"52.0000","12.9775","549.9605","12.9775","8.6517","130.9430"
"52.0800","12.9974","549.2412","12.9974","8.6649","130.7717"
"52.1600","13.0167","548.4919","13.0167","8.6778","130.5933"
"52.2400","13.0364","547.7595","13.0364","8.6909","130.4189"
"52.3200","13.0567","547.0834","13.0567","8.7045","130.2579"
"52.4000","13.0783","546.3798","13.0783","8.7189","130.0904"
"52.4800","13.0979","545.5175","13.0979","8.7320","129.8851"
"52.5600","13.1185","544.6824","13.1185","8.7457","129.6863"
"52.6400","13.1372","543.7755","13.1372","8.7582","129.4703"
"52.7200","13.1567","542.9203","13.1567","8.7712","129.2668"
"52.8000","13.1763","542.0610","13.1763","8.7842","129.0621"
"52.8800","13.1967","541.2483","13.1967","8.7978","128.8686"
"52.9600","13.2179","540.4750","13.2179","8.8119","128.6845"
"53.0400","13.2385","539.6732","13.2385","8.8257","128.4936"
"53.1200","13.2573","538.7684","13.2573","8.8382","128.2782"
"53.2000","13.2776","537.9153","13.2776","8.8517","128.0751"
"53.2800","13.2976","537.0118","13.2976","8.8650","127.8600"
"53.3600","13.3175","536.0974","13.3175","8.8783","127.6422"
"53.4400","13.3371","535.1280","13.3371","8.8914","127.4114"
"53.5200","13.3559","534.1249","13.3559","8.9039","127.1726"
"53.6000","13.3771","533.2498","13.3771","8.9181","126.9642"
"53.6800","13.3982","532.4027","13.3982","8.9321","126.7626"
"53.7600","13.4182","531.4929","13.4182","8.9455","126.5459"
"53.8400","13.4375","530.5624","13.4375","8.9584","126.3244"
"53.9200","13.4567","529.6123","13.4567","8.9711","126.0982"
"54.0000","13.4767","528.7277","13.4767","8.9845","125.8876"
"54.0800","13.4974","527.8591","13.4974","8.9983","125.6807"
"54.1600","13.5166","526.9717","13.5166","9.0111","125.4694"
"54.2400","13.5382","526.1918","13.5382","9.0255","125.2837"
"54.3200","13.5583","525.3387","13.5583","9.0388","125.0806"
"54.4000","13.5780","524.5428","13.5780","9.0520","124.8912"
"54.4800","13.5970","523.7052","13.5970","9.0647","124.6917"
"54.5600","13.6174","522.9160","13.6174","9.0782","124.5038"
"54.6400","13.6372","522.0758","13.6372","9.0915","124.3038"
"54.7200","13.6572","521.2322","13.6572","9.1048","124.1029"
"54.8000","13.6763","520.3710","13.6763","9.1175","123.8979"
"54.8800","13.6973","519.5717","13.6973","9.1315","123.7075"
"54.9600","13.7172","518.7124","13.7172","9.1448","123.5030"
"55.0400","13.7382","517.8984","13.7382","9.1588","123.3091"
"55.1200","13.7575","517.0035","13.7575","9.1717","123.0961"
"55.2000","13.7765","516.1242","13.7765","9.1843","122.8867"
"55.2800","13.7971","515.3126","13.7971","9.1981","122.6935"
"55.3600","13.8170","514.4411","13.8170","9.2113","122.4860"
"55.4400","13.8371","513.5741","13.8371","9.2247","122.2795"
"55.5200","13.8578","512.7232","13.8578","9.2385","122.0770"
"55.6000","13.8778","511.8238","13.8778","9.2518","121.8628"
"55.6800","13.8983","510.9664","13.8983","9.2655","121.6587"
"55.7600","13.9179","510.0645","13.9179","9.2786","121.4439"
"55.8400","13.9367","509.1891","13.9367","9.2911","121.2355"
"55.9200","13.9568","508.3347","13.9568","9.3045","121.0321"
"56.0000","13.9762","507.4430","13.9762","9.3174","120.8198"
"56.0800","13.9974","506.6134","13.9974","9.3316","120.6222"
"56.1600","14.0179","505.7392","14.0179","9.3453","120.4141"
"56.2400","14.0379","504.8250","14.0379","9.3586","120.1964"
"56.3200","14.0575","503.8883","14.0575","9.3717","119.9734"
"56.4000","14.0773","502.9411","14.0773","9.3849","119.7479"
"56.4800","14.0968","502.0098","14.0968","9.3979","119.5261"
"56.5600","14.1169","501.1068","14.1169","9.4113","119.3111"
"56.6400","14.1361","500.1474","14.1361","9.4240","119.0827"
"56.7200","14.1574","499.2740","14.1574","9.4383","118.8748"
"56.8000","14.1784","498.3506","14.1784","9.4522","118.6549"
"56.8800","14.1981","497.3601","14.1981","9.4654","118.4191"
"56.9600","14.2175","496.2835","14.2175","9.4783","118.1627"
"57.0400","14.2373","495.1647","14.2373","9.4915","117.8964"
"57.1200","14.2572","494.0199","14.2572","9.5048","117.6238"
"57.2000","14.2769","492.9280","14.2769","9.5180","117.3638"
"57.2800","14.2963","491.8814","14.2963","9.5309","117.1146"
"57.3600","14.3173","490.9226","14.3173","9.5449","116.8863"
"57.4400","14.3378","489.9221","14.3378","9.5585","116.6481"
"57.5200","14.3575","488.9226","14.3575","9.5717","116.4101"
"57.6000","14.3775","487.8937","14.3775","9.5850","116.1652"
"57.6800","14.3966","486.8420","14.3966","9.5977","115.9148"
"57.7600","14.4174","485.8321","14.4174","9.6116","115.6743"
"57.8400","14.4371","484.8143","14.4371","9.6247","115.4320"
"57.9200","14.4569","483.8266","14.4569","9.6379","115.1968"
"58.0000","14.4775","482.8038","14.4775","9.6517","114.9533"
"58.0800","14.4982","481.6850","14.4982","9.6655","114.6869"
"58.1600","14.5180","480.5583","14.5180","9.6787","114.4186"
"58.2400","14.5378","479.4161","14.5378","9.6919","114.1467"
"58.3200","14.5564","478.2523","14.5564","9.7043","113.8696"
"58.4000","14.5773","477.2319","14.5773","9.7182","113.6267"
"58.4800","14.5968","476.2042","14.5968","9.7312","113.3819"
"58.5600","14.6168","475.2264","14.6168","9.7446","113.1491"
"58.6400","14.6369","474.2238","14.6369","9.7580","112.9104"
"58.7200","14.6575","473.1712","14.6575","9.7717","112.6598"
"58.8000","14.6776","472.0899","14.6776","9.7851","112.4023"
"58.8800","14.6978","471.0443","14.6978","9.7985","112.1534"
"58.9600","14.7168","470.0699","14.7168","9.8112","111.9214"
"59.0400","14.7368","469.1914","14.7368","9.8245","111.7122"
"59.1200","14.7566","468.3085","14.7566","9.8377","111.5020"
"59.2000","14.7774","467.4431","14.7774","9.8516","111.2960"
"59.2800","14.7988","466.4935","14.7988","9.8659","111.0699"
"59.3600","14.8180","465.3458","14.8180","9.8787","110.7966"
"59.4400","14.8379","464.2594","14.8379","9.8919","110.5379"
"59.5200","14.8575","463.3154","14.8575","9.9050","110.3132"
"59.6000","14.8769","462.4381","14.8769","9.9179","110.1043"
"59.6800","14.8965","461.6201","14.8965","9.9310","109.9095"
"59.7600","14.9165","460.7802","14.9165","9.9443","109.7096"
"59.8400","14.9368","459.9364","14.9368","9.9579","109.5087"
"59.9200","14.9578","459.0542","14.9578","9.9719","109.2986"
"60.0000","14.9776","458.0855","14.9776","9.9851","109.0680"
"60.0800","14.9981","457.1462","14.9981","9.9987","108.8443"
"60.0890","15.0002","457.0431","15.0002","10.0001","108.8198"