File: data/instron_tests/metamaterials/250416/250416_50-50_Composite.is_comp_Exports/250416_50-50_Composite_4_1.csv
Results Table 1
,Compresson Axis,H*,V*,Height,Thickness,Width,Area,Fixture separation,Specimen label
,,,,(mm),(mm),(mm),(mm^2),(mm),
"4","X","","","150.00","28.00","150.00","4200.00","150.00","50/50 Composite"

Results Table 2
,Modulus (Segment 0 % - 2.5 %),Compresson Axis
,(kPa),
"4","315.11","X"

Time,Displacement,Force,Compressive displacement,Compressive strain (Displacement),Compressive stress
(s),(mm),(N),(mm),(%),(kPa)
"0.0000","0.0000","-1.0719","0.0000","0.0000","-0.2552"
"0.0800","0.0015","-1.0550","0.0015","0.0010","-0.2512"
"0.1600","0.0119","-0.9045","0.0119","0.0079","-0.2153"
"0.2400","0.0312","-0.6390","0.0312","0.0208","-0.1521"
"0.3200","0.0514","-0.3669","0.0514","0.0343","-0.0874"
"0.4000","0.0702","-0.1297","0.0702","0.0468","-0.0309"
"0.4800","0.0916","0.1405","0.0916","0.0611","0.0334"
"0.5600","0.1127","0.3898","0.1127","0.0752","0.0928"
"0.6400","0.1317","0.6262","0.1317","0.0878","0.1491"
"0.7200","0.1522","0.8690","0.1522","0.1015","0.2069"
"0.8000","0.1719","1.0844","0.1719","0.1146","0.2582"
"0.8800","0.1920","1.3243","0.1920","0.1280","0.3153"
"0.9600","0.2122","1.5498","0.2122","0.1414","0.3690"
"1.0400","0.2306","1.7405","0.2306","0.1537","0.4144"
"1.1200","0.2514","1.9651","0.2514","0.1676","0.4679"
"1.2000","0.2726","2.1897","0.2726","0.1818","0.5214"
"1.2800","0.2923","2.4118","0.2923","0.1948","0.5742"
"1.3600","0.3126","2.6312","0.3126","0.2084","0.6265"
"1.4400","0.3313","2.8161","0.3313","0.2209","0.6705"
"1.5200","0.3510","3.0166","0.3510","0.2340","0.7182"
"1.6000","0.3717","3.2313","0.3717","0.2478","0.7694"
"1.6800","0.3913","3.4346","0.3913","0.2608","0.8178"
"1.7600","0.4129","3.6360","0.4129","0.2753","0.8657"
"1.8400","0.4328","3.8294","0.4328","0.2885","0.9118"
"1.9200","0.4522","4.0104","0.4522","0.3015","0.9549"
"2.0000","0.4718","4.2012","0.4718","0.3145","1.0003"
"2.0800","0.4916","4.3854","0.4916","0.3277","1.0441"
"2.1600","0.5119","4.5743","0.5119","0.3413","1.0891"
"2.2400","0.5322","4.7602","0.5322","0.3548","1.1334"
"2.3200","0.5507","4.9340","0.5507","0.3671","1.1748"
"2.4000","0.5718","5.1322","0.5718","0.3812","1.2220"
"2.4800","0.5925","5.3122","0.5925","0.3950","1.2648"
"2.5600","0.6131","5.4806","0.6131","0.4087","1.3049"
"2.6400","0.6319","5.6241","0.6319","0.4213","1.3391"
"2.7200","0.6506","5.7913","0.6506","0.4338","1.3789"
"2.8000","0.6715","5.9815","0.6715","0.4477","1.4242"
"2.8800","0.6920","6.1734","0.6920","0.4613","1.4699"
"2.9600","0.7114","6.3400","0.7114","0.4743","1.5095"
"3.0400","0.7326","6.5482","0.7326","0.4884","1.5591"
"3.1200","0.7521","6.7235","0.7521","0.5014","1.6008"
"3.2000","0.7727","6.9126","0.7727","0.5151","1.6459"
"3.2800","0.7926","7.0966","0.7926","0.5284","1.6897"
"3.3600","0.8113","7.2466","0.8113","0.5409","1.7254"
"3.4400","0.8318","7.4477","0.8318","0.5545","1.7733"
"3.5200","0.8509","7.6173","0.8509","0.5673","1.8137"
"3.6000","0.8715","7.8170","0.8715","0.5810","1.8612"
"3.6800","0.8925","8.0118","0.8925","0.5950","1.9076"
"3.7600","0.9122","8.1911","0.9122","0.6081","1.9503"
"3.8400","0.9322","8.3773","0.9322","0.6215","1.9946"
"3.9200","0.9521","8.5573","0.9521","0.6348","2.0374"
"4.0000","0.9704","8.7168","0.9704","0.6469","2.0754"
"4.0800","0.9917","8.9344","0.9917","0.6611","2.1272"
"4.1600","1.0112","9.1049","1.0112","0.6741","2.1678"
"4.2400","1.0329","9.3016","1.0329","0.6886","2.2147"
"4.3200","1.0531","9.4905","1.0531","0.7020","2.2596"
"4.4000","1.0723","9.6569","1.0723","0.7149","2.2993"
"4.4800","1.0921","9.8323","1.0921","0.7281","2.3410"
"4.5600","1.1119","10.0111","1.1119","0.7413","2.3836"
"4.6400","1.1317","10.1880","1.1317","0.7544","2.4257"
"4.7200","1.1519","10.3752","1.1519","0.7679","2.4703"
"4.8000","1.1710","10.5366","1.1710","0.7807","2.5087"
"4.8800","1.1920","10.7275","1.1920","0.7947","2.5542"
"4.9600","1.2128","10.9157","1.2128","0.8086","2.5990"
"5.0400","1.2320","11.0891","1.2320","0.8213","2.6403"
"5.1200","1.2521","11.2664","1.2521","0.8347","2.6825"
"5.2000","1.2711","11.4387","1.2711","0.8474","2.7235"
"5.2800","1.2920","11.6160","1.2920","0.8613","2.7657"
"5.3600","1.3124","11.7975","1.3124","0.8749","2.8089"
"5.4400","1.3311","11.9624","1.3311","0.8874","2.8482"
"5.5200","1.3515","12.1472","1.3515","0.9010","2.8922"
"5.6000","1.3731","12.3434","1.3731","0.9154","2.9389"
"5.6800","1.3927","12.4920","1.3927","0.9285","2.9743"
"5.7600","1.4127","12.6675","1.4127","0.9418","3.0161"
"5.8400","1.4311","12.8336","1.4311","0.9541","3.0556"
"5.9200","1.4521","13.0204","1.4521","0.9680","3.1001"
"6.0000","1.4715","13.1934","1.4715","0.9810","3.1413"
"6.0800","1.4914","13.3755","1.4914","0.9943","3.1846"
"6.1600","1.5117","13.5609","1.5117","1.0078","3.2288"
"6.2400","1.5326","13.7362","1.5326","1.0217","3.2705"
"6.3200","1.5524","13.8990","1.5524","1.0349","3.3093"
"6.4000","1.5722","14.0803","1.5722","1.0481","3.3525"
"6.4800","1.5908","14.2433","1.5908","1.0605","3.3913"
"6.5600","1.6120","14.4343","1.6120","1.0746","3.4367"
"6.6400","1.6319","14.6133","1.6319","1.0880","3.4794"
"6.7200","1.6518","14.7826","1.6518","1.1012","3.5197"
"6.8000","1.6726","14.9693","1.6726","1.1151","3.5641"
"6.8800","1.6923","15.1435","1.6923","1.1282","3.6056"
"6.9600","1.7128","15.3136","1.7128","1.1418","3.6461"
"7.0400","1.7322","15.4884","1.7322","1.1548","3.6877"
"7.1200","1.7514","15.6578","1.7514","1.1676","3.7280"
"7.2000","1.7713","15.8458","1.7713","1.1809","3.7728"
"7.2800","1.7911","16.0131","1.7911","1.1941","3.8126"
"7.3600","1.8119","16.2039","1.8119","1.2079","3.8581"
"7.4400","1.8328","16.3853","1.8328","1.2219","3.9013"
"7.5200","1.8517","16.5578","1.8517","1.2345","3.9423"
"7.6000","1.8722","16.7330","1.8722","1.2482","3.9841"
"7.6800","1.8915","16.9034","1.8915","1.2610","4.0246"
"7.7600","1.9117","17.0739","1.9117","1.2744","4.0652"
"7.8400","1.9315","17.2500","1.9315","1.2877","4.1071"
"7.9200","1.9513","17.4174","1.9513","1.3009","4.1470"
"8.0000","1.9718","17.5893","1.9718","1.3145","4.1879"
"8.0800","1.9938","17.7806","1.9938","1.3292","4.2335"
"8.1600","2.0127","17.9303","2.0127","1.3418","4.2691"
"8.2400","2.0323","18.0904","2.0323","1.3549","4.3072"
"8.3200","2.0512","18.2380","2.0512","1.3674","4.3424"
"8.4000","2.0717","18.4127","2.0717","1.3811","4.3840"
"8.4800","2.0920","18.5793","2.0920","1.3947","4.4236"
"8.5600","2.1112","18.7468","2.1112","1.4075","4.4635"
"8.6400","2.1321","18.9375","2.1321","1.4214","4.5089"
"8.7200","2.1522","19.1022","2.1522","1.4348","4.5481"
"8.8000","2.1720","19.2793","2.1720","1.4480","4.5903"
"8.8800","2.1922","19.4515","2.1922","1.4615","4.6313"
"8.9600","2.2115","19.6108","2.2115","1.4743","4.6692"
"9.0400","2.2320","19.7901","2.2320","1.4880","4.7119"
"9.1200","2.2520","19.9457","2.2520","1.5013","4.7490"
"9.2000","2.2710","20.1171","2.2710","1.5140","4.7898"
"9.2800","2.2927","20.3184","2.2927","1.5285","4.8377"
"9.3600","2.3127","20.4840","2.3127","1.5418","4.8772"
"9.4400","2.3330","20.6521","2.3330","1.5553","4.9172"
"9.5200","2.3521","20.8171","2.3521","1.5681","4.9565"
"9.6000","2.3711","20.9869","2.3711","1.5808","4.9969"
"9.6800","2.3920","21.1749","2.3920","1.5946","5.0416"
"9.7600","2.4116","21.3320","2.4116","1.6077","5.0790"
"9.8400","2.4306","21.4926","2.4306","1.6204","5.1173"
"9.9200","2.4521","21.6734","2.4521","1.6347","5.1603"
"10.0000","2.4718","21.8355","2.4718","1.6479","5.1989"
"10.0800","2.4928","22.0206","2.4928","1.6619","5.2430"
"10.1600","2.5124","22.1885","2.5124","1.6749","5.2830"
"10.2400","2.5316","22.3603","2.5316","1.6877","5.3239"
"10.3200","2.5508","22.5351","2.5508","1.7005","5.3655"
"10.4000","2.5712","22.7009","2.5712","1.7142","5.4050"
"10.4800","2.5921","22.8891","2.5921","1.7281","5.4498"
"10.5600","2.6136","23.0712","2.6136","1.7424","5.4932"
"10.6400","2.6323","23.2331","2.6323","1.7548","5.5317"
"10.7200","2.6521","23.4054","2.6521","1.7681","5.5727"
"10.8000","2.6719","23.5862","2.6719","1.7813","5.6158"
"10.8800","2.6919","23.7555","2.6919","1.7946","5.6561"
"10.9600","2.7122","23.9277","2.7122","1.8081","5.6971"
"11.0400","2.7310","24.0878","2.7310","1.8207","5.7352"
"11.1200","2.7517","24.2842","2.7517","1.8345","5.7820"
"11.2000","2.7725","24.4616","2.7725","1.8483","5.8242"
"11.2800","2.7922","24.6454","2.7922","1.8615","5.8679"
"11.3600","2.8124","24.8228","2.8124","1.8749","5.9102"
"11.4400","2.8315","24.9741","2.8315","1.8877","5.9462"
"11.5200","2.8511","25.1414","2.8511","1.9008","5.9861"
"11.6000","2.8720","25.3168","2.8720","1.9147","6.0278"
"11.6800","2.8912","25.4925","2.8912","1.9275","6.0697"
"11.7600","2.9126","25.6864","2.9126","1.9417","6.1158"
"11.8400","2.9326","25.8605","2.9326","1.9550","6.1573"
"11.9200","2.9522","26.0285","2.9522","1.9681","6.1973"
"12.0000","2.9717","26.2062","2.9717","1.9812","6.2396"
"12.0800","2.9919","26.3681","2.9919","1.9946","6.2781"
"12.1600","3.0123","26.5331","3.0123","2.0082","6.3174"
"12.2400","3.0321","26.7089","3.0321","2.0214","6.3593"
"12.3200","3.0505","26.8648","3.0505","2.0336","6.3964"
"12.4000","3.0718","27.0611","3.0718","2.0479","6.4431"
"12.4800","3.0921","27.2389","3.0921","2.0614","6.4854"
"12.5600","3.1127","27.4181","3.1127","2.0752","6.5281"
"12.6400","3.1322","27.5778","3.1322","2.0881","6.5661"
"12.7200","3.1507","27.7304","3.1507","2.1005","6.6025"
"12.8000","3.1719","27.9267","3.1719","2.1146","6.6492"
"12.8800","3.1921","28.1085","3.1921","2.1281","6.6925"
"12.9600","3.2119","28.2755","3.2119","2.1412","6.7323"
"13.0400","3.2324","28.4678","3.2324","2.1550","6.7781"
"13.1200","3.2521","28.6290","3.2521","2.1681","6.8164"
"13.2000","3.2725","28.7966","3.2725","2.1817","6.8563"
"13.2800","3.2928","28.9704","3.2928","2.1952","6.8977"
"13.3600","3.3115","29.1360","3.3115","2.2076","6.9371"
"13.4400","3.3320","29.3088","3.3320","2.2213","6.9783"
"13.5200","3.3508","29.4662","3.3508","2.2339","7.0158"
"13.6000","3.3716","29.6483","3.3716","2.2477","7.0591"
"13.6800","3.3925","29.8362","3.3925","2.2617","7.1038"
"13.7600","3.4123","29.9953","3.4123","2.2749","7.1417"
"13.8400","3.4323","30.1731","3.4323","2.2882","7.1841"
"13.9200","3.4519","30.3215","3.4519","2.3013","7.2194"
"14.0000","3.4708","30.4862","3.4708","2.3138","7.2586"
"14.0800","3.4919","30.6720","3.4919","2.3279","7.3029"
"14.1600","3.5112","30.8291","3.5112","2.3408","7.3403"
"14.2400","3.5323","31.0070","3.5323","2.3548","7.3826"
"14.3200","3.5528","31.1727","3.5528","2.3686","7.4221"
"14.4000","3.5720","31.3421","3.5720","2.3813","7.4624"
"14.4800","3.5920","31.5062","3.5920","2.3946","7.5015"
"14.5600","3.6117","31.6730","3.6117","2.4078","7.5412"
"14.6400","3.6316","31.8339","3.6316","2.4211","7.5795"
"14.7200","3.6517","32.0082","3.6517","2.4345","7.6210"
"14.8000","3.6707","32.1705","3.6707","2.4471","7.6596"
"14.8800","3.6915","32.3516","3.6915","2.4610","7.7028"
"14.9600","3.7126","32.5370","3.7126","2.4751","7.7469"
"15.0400","3.7321","32.7087","3.7321","2.4880","7.7878"
"15.1200","3.7517","32.8738","3.7517","2.5011","7.8271"
"15.2000","3.7707","33.0220","3.7707","2.5138","7.8624"
"15.2800","3.7920","33.2045","3.7920","2.5280","7.9058"
"15.3600","3.8123","33.3786","3.8123","2.5415","7.9473"
"15.4400","3.8314","33.5466","3.8314","2.5543","7.9873"
"15.5200","3.8523","33.7386","3.8523","2.5682","8.0330"
"15.6000","3.8726","33.9086","3.8726","2.5817","8.0735"
"15.6800","3.8923","34.0809","3.8923","2.5949","8.1145"
"15.7600","3.9126","34.2551","3.9126","2.6084","8.1560"
"15.8400","3.9313","34.4018","3.9313","2.6209","8.1909"
"15.9200","3.9521","34.5718","3.9521","2.6347","8.2314"
"16.0000","3.9717","34.7426","3.9717","2.6478","8.2720"
"16.0800","3.9916","34.9092","3.9916","2.6610","8.3117"
"16.1600","4.0121","35.0901","4.0121","2.6747","8.3548"
"16.2400","4.0319","35.2483","4.0319","2.6880","8.3925"
"16.3200","4.0520","35.4164","4.0520","2.7014","8.4325"
"16.4000","4.0723","35.5796","4.0723","2.7149","8.4713"
"16.4800","4.0908","35.7251","4.0908","2.7272","8.5060"
"16.5600","4.1119","35.9199","4.1119","2.7412","8.5524"
"16.6400","4.1317","36.0901","4.1317","2.7545","8.5929"
"16.7200","4.1521","36.2679","4.1521","2.7680","8.6352"
"16.8000","4.1726","36.4312","4.1726","2.7818","8.6741"
"16.8800","4.1922","36.5956","4.1922","2.7948","8.7132"
"16.9600","4.2126","36.7708","4.2126","2.8084","8.7549"
"17.0400","4.2322","36.9327","4.2322","2.8215","8.7935"
"17.1200","4.2513","37.0971","4.2513","2.8342","8.8326"
"17.2000","4.2716","37.2793","4.2716","2.8477","8.8760"
"17.2800","4.2907","37.4193","4.2907","2.8605","8.9094"
"17.3600","4.3116","37.6052","4.3116","2.8744","8.9536"
"17.4400","4.3331","37.7866","4.3331","2.8887","8.9968"
"17.5200","4.3519","37.9534","4.3519","2.9013","9.0365"
"17.6000","4.3721","38.1256","4.3721","2.9147","9.0775"
"17.6800","4.3914","38.2841","4.3914","2.9276","9.1153"
"17.7600","4.4119","38.4661","4.4119","2.9413","9.1586"
"17.8400","4.4318","38.6403","4.4318","2.9545","9.2001"
"17.9200","4.4508","38.7892","4.4508","2.9672","9.2355"
"18.0000","4.4720","38.9782","4.4720","2.9814","9.2805"
"18.0800","4.4936","39.1679","4.4936","2.9958","9.3257"
"18.1600","4.5124","39.3198","4.5124","3.0082","9.3619"
"18.2400","4.5325","39.4897","4.5325","3.0217","9.4023"
"18.3200","4.5511","39.6384","4.5511","3.0341","9.4377"
"18.4000","4.5717","39.8099","4.5717","3.0478","9.4786"
"18.4800","4.5919","39.9736","4.5919","3.0612","9.5175"
"18.5600","4.6110","40.1326","4.6110","3.0740","9.5554"
"18.6400","4.6320","40.3255","4.6320","3.0880","9.6013"
"18.7200","4.6525","40.4951","4.6525","3.1017","9.6417"
"18.8000","4.6718","40.6503","4.6718","3.1145","9.6786"
"18.8800","4.6923","40.8203","4.6923","3.1282","9.7191"
"18.9600","4.7114","40.9713","4.7114","3.1409","9.7551"
"19.0400","4.7319","41.1430","4.7319","3.1546","9.7960"
"19.1200","4.7520","41.3083","4.7520","3.1680","9.8353"
"19.2000","4.7713","41.4767","4.7713","3.1808","9.8754"
"19.2800","4.7924","41.6582","4.7924","3.1949","9.9186"
"19.3600","4.8127","41.8172","4.8127","3.2084","9.9565"
"19.4400","4.8328","41.9811","4.8328","3.2219","9.9955"
"19.5200","4.8521","42.1477","4.8521","3.2348","10.0352"
"19.6000","4.8715","42.2962","4.8715","3.2476","10.0705"
"19.6800","4.8920","42.4788","4.8920","3.2613","10.1140"
"19.7600","4.9119","42.6442","4.9119","3.2746","10.1534"
"19.8400","4.9313","42.8015","4.9313","3.2875","10.1908"
"19.9200","4.9520","42.9755","4.9520","3.3013","10.2323"
"20.0000","4.9715","43.1213","4.9715","3.3144","10.2670"
"20.0800","4.9928","43.2887","4.9928","3.3286","10.3068"
"20.1600","5.0123","43.4250","5.0123","3.3416","10.3393"
"20.2400","5.0311","43.5643","5.0311","3.3541","10.3725"
"20.3200","5.0508","43.7304","5.0508","3.3672","10.4120"
"20.4000","5.0710","43.8790","5.0710","3.3807","10.4474"
"20.4800","5.0927","44.0681","5.0927","3.3952","10.4924"
"20.5600","5.1140","44.2477","5.1140","3.4094","10.5352"
"20.6400","5.1319","44.3904","5.1319","3.4213","10.5691"
"20.7200","5.1520","44.5420","5.1520","3.4347","10.6052"
"20.8000","5.1716","44.7138","5.1716","3.4477","10.6461"
"20.8800","5.1918","44.8691","5.1918","3.4612","10.6831"
"20.9600","5.2120","45.0419","5.2120","3.4747","10.7243"
"21.0400","5.2307","45.1898","5.2307","3.4872","10.7595"
"21.1200","5.2517","45.3564","5.2517","3.5011","10.7991"
"21.2000","5.2726","45.5377","5.2726","3.5150","10.8423"
"21.2800","5.2920","45.7024","5.2920","3.5280","10.8815"
"21.3600","5.3125","45.8838","5.3125","3.5416","10.9247"
"21.4400","5.3315","46.0226","5.3315","3.5543","10.9578"
"21.5200","5.3509","46.1883","5.3509","3.5673","10.9972"
"21.6000","5.3717","46.3573","5.3717","3.5811","11.0374"
"21.6800","5.3912","46.5207","5.3912","3.5941","11.0764"
"21.7600","5.4129","46.7039","5.4129","3.6086","11.1200"
"21.8400","5.4327","46.8690","5.4327","3.6218","11.1593"
"21.9200","5.4522","47.0257","5.4522","3.6348","11.1966"
"22.0000","5.4712","47.1875","5.4712","3.6475","11.2351"
"22.0800","5.4917","47.3546","5.4917","3.6611","11.2749"
"22.1600","5.5124","47.5263","5.5124","3.6750","11.3158"
"22.2400","5.5322","47.6884","5.5322","3.6881","11.3544"
"22.3200","5.5505","47.8330","5.5505","3.7003","11.3888"
"22.4000","5.5717","48.0205","5.5717","3.7145","11.4334"
"22.4800","5.5922","48.1892","5.5922","3.7281","11.4736"
"22.5600","5.6127","48.3449","5.6127","3.7418","11.5107"
"22.6400","5.6318","48.4958","5.6318","3.7545","11.5466"
"22.7200","5.6507","48.6450","5.6507","3.7671","11.5821"
"22.8000","5.6715","48.8197","5.6715","3.7810","11.6237"
"22.8800","5.6922","48.9871","5.6922","3.7948","11.6636"
"22.9600","5.7123","49.1493","5.7123","3.8082","11.7022"
"23.0400","5.7325","49.3195","5.7325","3.8217","11.7427"
"23.1200","5.7520","49.4647","5.7520","3.8347","11.7773"
"23.2000","5.7725","49.6213","5.7725","3.8483","11.8146"
"23.2800","5.7930","49.7822","5.7930","3.8620","11.8529"
"23.3600","5.8117","49.9382","5.8117","3.8745","11.8901"
"23.4400","5.8318","50.0959","5.8318","3.8879","11.9276"
"23.5200","5.8506","50.2408","5.8506","3.9004","11.9621"
"23.6000","5.8717","50.4019","5.8717","3.9144","12.0004"
"23.6800","5.8927","50.5822","5.8927","3.9285","12.0434"
"23.7600","5.9124","50.7432","5.9124","3.9416","12.0817"
"23.8400","5.9323","50.8969","5.9323","3.9549","12.1183"
"23.9200","5.9519","51.0464","5.9519","3.9679","12.1539"
"24.0000","5.9706","51.2011","5.9706","3.9804","12.1907"
"24.0800","5.9919","51.3789","5.9919","3.9946","12.2331"
"24.1600","6.0111","51.5227","6.0111","4.0074","12.2673"
"24.2400","6.0324","51.6941","6.0324","4.0216","12.3081"
"24.3200","6.0528","51.8552","6.0528","4.0352","12.3465"
"24.4000","6.0725","52.0294","6.0725","4.0483","12.3879"
"24.4800","6.0925","52.1933","6.0925","4.0617","12.4270"
"24.5600","6.1121","52.3461","6.1121","4.0747","12.4634"
"24.6400","6.1316","52.4999","6.1316","4.0877","12.5000"
"24.7200","6.1516","52.6583","6.1516","4.1011","12.5377"
"24.8000","6.1707","52.8153","6.1707","4.1138","12.5751"
"24.8800","6.1921","52.9946","6.1921","4.1281","12.6178"
"24.9600","6.2124","53.1577","6.2124","4.1416","12.6566"
"25.0400","6.2318","53.3211","6.2318","4.1545","12.6955"
"25.1200","6.2523","53.4823","6.2523","4.1682","12.7339"
"25.2000","6.2710","53.6315","6.2710","4.1807","12.7694"
"25.2800","6.2919","53.7946","6.2919","4.1946","12.8082"
"25.3600","6.3122","53.9597","6.3122","4.2081","12.8475"
"25.4400","6.3315","54.1154","6.3315","4.2210","12.8846"
"25.5200","6.3520","54.2934","6.3520","4.2347","12.9270"
"25.6000","6.3729","54.4549","6.3729","4.2486","12.9654"
"25.6800","6.3928","54.6076","6.3928","4.2619","13.0018"
"25.7600","6.4125","54.7603","6.4125","4.2750","13.0382"
"25.8400","6.4311","54.9075","6.4311","4.2874","13.0732"
"25.9200","6.4516","55.0709","6.4516","4.3011","13.1121"
"26.0000","6.4716","55.2239","6.4716","4.3144","13.1486"
"26.0800","6.4914","55.3794","6.4914","4.3276","13.1856"
"26.1600","6.5124","55.5556","6.5124","4.3416","13.2275"
"26.2400","6.5323","55.7054","6.5323","4.3548","13.2632"
"26.3200","6.5525","55.8627","6.5525","4.3683","13.3006"
"26.4000","6.5723","56.0125","6.5723","4.3815","13.3363"
"26.4800","6.5908","56.1576","6.5908","4.3939","13.3709"
"26.5600","6.6119","56.3341","6.6119","4.4079","13.4129"
"26.6400","6.6316","56.4775","6.6316","4.4211","13.4470"
"26.7200","6.6519","56.6498","6.6519","4.4346","13.4880"
"26.8000","6.6725","56.8199","6.6725","4.4483","13.5285"
"26.8800","6.6924","56.9769","6.6924","4.4616","13.5659"
"26.9600","6.7127","57.1211","6.7127","4.4751","13.6003"
"27.0400","6.7323","57.2782","6.7323","4.4882","13.6377"
"27.1200","6.7515","57.4389","6.7515","4.5010","13.6759"
"27.2000","6.7712","57.5899","6.7712","4.5142","13.7119"
"27.2800","6.7907","57.7444","6.7907","4.5271","13.7487"
"27.3600","6.8116","57.9085","6.8116","4.5410","13.7877"
"27.4400","6.8331","58.0896","6.8331","4.5554","13.8309"
"27.5200","6.8520","58.2368","6.8520","4.5680","13.8659"
"27.6000","6.8722","58.3978","6.8722","4.5814","13.9042"
"27.6800","6.8914","58.5444","6.8914","4.5943","13.9391"
"27.7600","6.9115","58.6954","6.9115","4.6077","13.9751"
"27.8400","6.9317","58.8611","6.9317","4.6211","14.0145"
"27.9200","6.9515","59.0020","6.9515","4.6343","14.0481"
"28.0000","6.9720","59.1701","6.9720","4.6480","14.0881"
"28.0800","6.9936","59.3550","6.9936","4.6624","14.1322"
"28.1600","7.0124","59.4873","7.0124","4.6749","14.1636"
"28.2400","7.0318","59.6406","7.0318","4.6879","14.2001"
"28.3200","7.0512","59.7862","7.0512","4.7008","14.2348"
"28.4000","7.0720","59.9501","7.0720","4.7147","14.2738"
"28.4800","7.0922","60.0968","7.0922","4.7281","14.3088"
"28.5600","7.1110","60.2432","7.1110","4.7407","14.3436"
"28.6400","7.1318","60.4152","7.1318","4.7545","14.3846"
"28.7200","7.1525","60.5681","7.1525","4.7683","14.4210"
"28.8000","7.1718","60.7190","7.1718","4.7812","14.4569"
"28.8800","7.1921","60.8824","7.1921","4.7947","14.4958"
"28.9600","7.2114","61.0224","7.2114","4.8076","14.5291"
"29.0400","7.2321","61.1884","7.2321","4.8214","14.5687"
"29.1200","7.2519","61.3348","7.2519","4.8346","14.6035"
"29.2000","7.2708","61.4838","7.2708","4.8472","14.6390"
"29.2800","7.2926","61.6742","7.2926","4.8617","14.6843"
"29.3600","7.3132","61.8257","7.3132","4.8754","14.7204"
"29.4400","7.3330","61.9760","7.3330","4.8887","14.7562"
"29.5200","7.3519","62.1139","7.3519","4.9012","14.7890"
"29.6000","7.3713","62.2679","7.3713","4.9142","14.8257"
"29.6800","7.3919","62.4326","7.3919","4.9279","14.8649"
"29.7600","7.4119","62.5790","7.4119","4.9413","14.8998"
"29.8400","7.4310","62.7241","7.4310","4.9540","14.9343"
"29.9200","7.4520","62.8899","7.4520","4.9680","14.9738"
"30.0000","7.4716","63.0374","7.4716","4.9810","15.0089"
"30.0800","7.4930","63.2066","7.4930","4.9953","15.0492"
"30.1600","7.5126","63.3410","7.5126","5.0084","15.0812"
"30.2400","7.5314","63.4879","7.5314","5.0209","15.1162"
"30.3200","7.5514","63.6498","7.5514","5.0343","15.1547"
"30.4000","7.5711","63.7922","7.5711","5.0474","15.1886"
"30.4800","7.5919","63.9492","7.5919","5.0613","15.2260"
"30.5600","7.6133","64.1168","7.6133","5.0755","15.2659"
"30.6400","7.6325","64.2611","7.6325","5.0883","15.3003"
"30.7200","7.6520","64.4057","7.6520","5.1013","15.3347"
"30.8000","7.6722","64.5620","7.6722","5.1148","15.3719"
"30.8800","7.6917","64.7065","7.6917","5.1278","15.4063"
"30.9600","7.7121","64.8683","7.7121","5.1414","15.4448"
"31.0400","7.7308","65.0042","7.7308","5.1538","15.4772"
"31.1200","7.7517","65.1693","7.7517","5.1678","15.5165"
"31.2000","7.7730","65.3369","7.7730","5.1820","15.5564"
"31.2800","7.7923","65.4806","7.7923","5.1949","15.5906"
"31.3600","7.8125","65.6504","7.8125","5.2083","15.6310"
"31.4400","7.8317","65.7819","7.8317","5.2211","15.6624"
"31.5200","7.8510","65.9286","7.8510","5.2340","15.6973"
"31.6000","7.8717","66.0859","7.8717","5.2478","15.7347"
"31.6800","7.8911","66.2418","7.8911","5.2608","15.7719"
"31.7600","7.9128","66.4117","7.9128","5.2752","15.8123"
"31.8400","7.9327","66.5687","7.9327","5.2884","15.8497"
"31.9200","7.9523","66.7222","7.9523","5.3016","15.8862"
"32.0000","7.9719","66.8714","7.9719","5.3146","15.9218"
"32.0800","7.9918","67.0106","7.9918","5.3278","15.9549"
"32.1600","8.0118","67.1600","8.0118","5.3412","15.9905"
"32.2400","8.0319","67.3099","8.0319","5.3546","16.0262"
"32.3200","8.0505","67.4558","8.0505","5.3670","16.0609"
"32.4000","8.0719","67.6232","8.0719","5.3813","16.1008"
"32.4800","8.0923","67.7806","8.0923","5.3948","16.1382"
"32.5600","8.1127","67.9345","8.1127","5.4084","16.1749"
"32.6400","8.1321","68.0719","8.1321","5.4214","16.2076"
"32.7200","8.1509","68.2121","8.1509","5.4340","16.2410"
"32.8000","8.1714","68.3515","8.1714","5.4476","16.2742"
"32.8800","8.1921","68.5264","8.1921","5.4614","16.3158"
"32.9600","8.2120","68.6690","8.2120","5.4747","16.3498"
"33.0400","8.2324","68.8308","8.2324","5.4883","16.3883"
"33.1200","8.2519","68.9606","8.2519","5.5012","16.4192"
"33.2000","8.2727","69.1285","8.2727","5.5151","16.4592"
"33.2800","8.2924","69.2687","8.2924","5.5283","16.4926"
"33.3600","8.3115","69.4166","8.3115","5.5410","16.5278"
"33.4400","8.3321","69.5772","8.3321","5.5547","16.5660"
"33.5200","8.3507","69.7000","8.3507","5.5671","16.5952"
"33.6000","8.3713","69.8605","8.3713","5.5809","16.6335"
"33.6800","8.3926","70.0306","8.3926","5.5951","16.6739"
"33.7600","8.4125","70.1846","8.4125","5.6084","16.7106"
"33.8400","8.4322","70.3129","8.4322","5.6215","16.7412"
"33.9200","8.4519","70.4641","8.4519","5.6346","16.7772"
"34.0000","8.4708","70.5995","8.4708","5.6472","16.8094"
"34.0800","8.4918","70.7712","8.4918","5.6612","16.8503"
"34.1600","8.5113","70.9045","8.5113","5.6742","16.8820"
"34.2400","8.5324","71.0625","8.5324","5.6883","16.9196"
"34.3200","8.5531","71.2285","8.5531","5.7020","16.9592"
"34.4000","8.5723","71.3574","8.5723","5.7148","16.9899"
"34.4800","8.5922","71.5010","8.5922","5.7281","17.0240"
"34.5600","8.6118","71.6367","8.6118","5.7412","17.0563"
"34.6400","8.6317","71.7810","8.6317","5.7545","17.0907"
"34.7200","8.6519","71.9234","8.6519","5.7679","17.1246"
"34.8000","8.6707","72.0671","8.6707","5.7805","17.1588"
"34.8800","8.6920","72.2316","8.6920","5.7947","17.1980"
"34.9600","8.7126","72.3949","8.7126","5.8084","17.2369"
"35.0400","8.7319","72.5318","8.7319","5.8213","17.2695"
"35.1200","8.7518","72.6686","8.7518","5.8346","17.3020"
"35.2000","8.7713","72.8014","8.7713","5.8475","17.3337"
"35.2800","8.7920","72.9580","8.7920","5.8613","17.3710"
"35.3600","8.8122","73.1013","8.8122","5.8748","17.4051"
"35.4400","8.8314","73.2419","8.8314","5.8876","17.4385"
"35.5200","8.8521","73.4084","8.8521","5.9014","17.4782"
"35.6000","8.8727","73.5596","8.8727","5.9151","17.5142"
"35.6800","8.8925","73.6912","8.8925","5.9284","17.5455"
"35.7600","8.9126","73.8354","8.9126","5.9417","17.5799"
"35.8400","8.9310","73.9603","8.9310","5.9540","17.6096"
"35.9200","8.9520","74.1092","8.9520","5.9680","17.6451"
"36.0000","8.9710","74.2393","8.9710","5.9806","17.6760"
"36.0800","8.9914","74.3839","8.9914","5.9943","17.7104"
"36.1600","9.0121","74.5453","9.0121","6.0081","17.7489"
"36.2400","9.0322","74.6784","9.0322","6.0215","17.7806"
"36.3200","9.0521","74.8169","9.0521","6.0348","17.8135"
"36.4000","9.0722","74.9546","9.0722","6.0481","17.8463"
"36.4800","9.0910","75.0894","9.0910","6.0607","17.8784"
"36.5600","9.1120","75.2377","9.1120","6.0746","17.9137"
"36.6400","9.1316","75.3649","9.1316","6.0877","17.9440"
"36.7200","9.1519","75.5155","9.1519","6.1013","17.9799"
"36.8000","9.1728","75.6507","9.1728","6.1152","18.0121"
"36.8800","9.1923","75.8034","9.1923","6.1282","18.0484"
"36.9600","9.2128","75.9360","9.2128","6.1419","18.0800"
"37.0400","9.2322","76.0684","9.2322","6.1548","18.1115"
"37.1200","9.2515","76.1970","9.2515","6.1676","18.1421"
"37.2000","9.2715","76.3406","9.2715","6.1810","18.1763"
"37.2800","9.2908","76.4666","9.2908","6.1938","18.2063"
"37.3600","9.3120","76.6117","9.3120","6.2080","18.2409"
"37.4400","9.3332","76.7604","9.3332","6.2221","18.2763"
"37.5200","9.3517","76.8803","9.3517","6.2345","18.3048"
"37.6000","9.3720","77.0190","9.3720","6.2480","18.3379"
"37.6800","9.3915","77.1469","9.3915","6.2610","18.3683"
"37.7600","9.4118","77.2888","9.4118","6.2745","18.4021"
"37.8400","9.4315","77.4279","9.4315","6.2877","18.4352"
"37.9200","9.4512","77.5546","9.4512","6.3008","18.4654"
"38.0000","9.4718","77.6970","9.4718","6.3146","18.4993"
"38.0800","9.4934","77.8414","9.4934","6.3290","18.5337"
"38.1600","9.5124","77.9626","9.5124","6.3416","18.5625"
"38.2400","9.5323","78.1030","9.5323","6.3549","18.5959"
"38.3200","9.5511","78.2115","9.5511","6.3674","18.6218"
"38.4000","9.5715","78.3556","9.5715","6.3810","18.6561"
"38.4800","9.5913","78.4790","9.5913","6.3942","18.6855"
"38.5600","9.6111","78.6220","9.6111","6.4074","18.7195"
"38.6400","9.6321","78.7729","9.6321","6.4214","18.7554"
"38.7200","9.6527","78.9017","9.6527","6.4351","18.7861"
"38.8000","9.6716","79.0263","9.6716","6.4478","18.8158"
"38.8800","9.6922","79.1658","9.6922","6.4615","18.8490"
"38.9600","9.7117","79.2891","9.7117","6.4744","18.8784"
"39.0400","9.7321","79.4225","9.7321","6.4881","18.9101"
"39.1200","9.7521","79.5521","9.7521","6.5014","18.9410"
"39.2000","9.7710","79.6823","9.7710","6.5140","18.9720"
"39.2800","9.7925","79.8398","9.7925","6.5283","19.0095"
"39.3600","9.8124","79.9595","9.8124","6.5416","19.0380"
"39.4400","9.8330","80.0923","9.8330","6.5553","19.0696"
"39.5200","9.8520","80.1963","9.8520","6.5680","19.0944"
"39.6000","9.8712","80.3158","9.8712","6.5808","19.1228"
"39.6800","9.8920","80.4590","9.8920","6.5946","19.1569"
"39.7600","9.9117","80.5872","9.9117","6.6078","19.1874"
"39.8400","9.9309","80.7067","9.9309","6.6206","19.2159"
"39.9200","9.9526","80.8628","9.9526","6.6351","19.2530"
"40.0000","9.9717","80.9733","9.9717","6.6478","19.2794"
"40.0800","9.9927","81.1071","9.9927","6.6618","19.3112"
"40.1600","10.0121","81.2272","10.0121","6.6747","19.3398"
"40.2400","10.0314","81.3490","10.0314","6.6876","19.3688"
"40.3200","10.0513","81.4748","10.0513","6.7009","19.3988"
"40.4000","10.0713","81.5845","10.0713","6.7142","19.4249"
"40.4800","10.0920","81.7148","10.0920","6.7280","19.4559"
"40.5600","10.1134","81.8596","10.1134","6.7422","19.4904"
"40.6400","10.1321","81.9629","10.1321","6.7548","19.5150"
"40.7200","10.1520","82.0779","10.1520","6.7680","19.5424"
"40.8000","10.1717","82.1905","10.1717","6.7811","19.5692"
"40.8800","10.1911","82.3170","10.1911","6.7940","19.5993"
"40.9600","10.2122","82.4435","10.2122","6.8081","19.6294"
"41.0400","10.2310","82.5384","10.2310","6.8207","19.6520"
"41.1200","10.2520","82.6612","10.2520","6.8346","19.6812"
"41.2000","10.2728","82.7889","10.2728","6.8485","19.7117"
"41.2800","10.2924","82.9114","10.2924","6.8616","19.7408"
"41.3600","10.3124","83.0282","10.3124","6.8750","19.7686"
"41.4400","10.3317","83.1293","10.3317","6.8878","19.7927"
"41.5200","10.3512","83.2370","10.3512","6.9008","19.8183"
"41.6000","10.3720","83.3610","10.3720","6.9146","19.8479"
"41.6800","10.3912","83.4691","10.3912","6.9274","19.8736"
"41.7600","10.4130","83.5998","10.4130","6.9420","19.9047"
"41.8400","10.4328","83.7203","10.4328","6.9552","19.9334"
"41.9200","10.4525","83.8151","10.4525","6.9683","19.9560"
"42.0000","10.4716","83.9188","10.4716","6.9811","19.9807"
"42.0800","10.4918","84.0320","10.4918","6.9945","20.0076"
"42.1600","10.5118","84.1435","10.5118","7.0079","20.0342"
"42.2400","10.5319","84.2523","10.5319","7.0213","20.0601"
"42.3200","10.5506","84.3529","10.5506","7.0337","20.0840"
"42.4000","10.5720","84.4742","10.5720","7.0480","20.1129"
"42.4800","10.5920","84.5809","10.5920","7.0614","20.1383"
"42.5600","10.6128","84.6834","10.6128","7.0752","20.1627"
"42.6400","10.6320","84.7774","10.6320","7.0880","20.1851"
"42.7200","10.6509","84.8671","10.6509","7.1006","20.2065"
"42.8000","10.6716","84.9722","10.6716","7.1144","20.2315"
"42.8800","10.6919","85.0761","10.6919","7.1279","20.2562"
"42.9600","10.7122","85.1852","10.7122","7.1414","20.2822"
"43.0400","10.7328","85.3017","10.7328","7.1552","20.3099"
"43.1200","10.7519","85.3703","10.7519","7.1679","20.3263"
"43.2000","10.7721","85.4636","10.7721","7.1814","20.3485"
"43.2800","10.7920","85.5540","10.7920","7.1947","20.3700"
"43.3600","10.8116","85.6509","10.8116","7.2078","20.3931"
"43.4400","10.8322","85.7524","10.8322","7.2215","20.4172"
"43.5200","10.8509","85.8267","10.8509","7.2340","20.4349"
"43.6000","10.8716","85.9212","10.8716","7.2477","20.4574"
"43.6800","10.8924","86.0334","10.8924","7.2616","20.4841"
"43.7600","10.9123","86.1266","10.9123","7.2749","20.5063"
"43.8400","10.9321","86.2054","10.9321","7.2880","20.5251"
"43.9200","10.9521","86.2995","10.9521","7.3014","20.5475"
"44.0000","10.9707","86.3778","10.9707","7.3138","20.5661"
"44.0800","10.9916","86.4773","10.9916","7.3277","20.5898"
"44.1600","11.0111","86.5584","11.0111","7.3407","20.6091"
"44.2400","11.0327","86.6545","11.0327","7.3551","20.6320"
"44.3200","11.0528","86.7408","11.0528","7.3685","20.6526"
"44.4000","11.0725","86.8279","11.0725","7.3817","20.6733"
"44.4800","11.0922","86.8952","11.0922","7.3948","20.6893"
"44.5600","11.1120","86.9774","11.1120","7.4080","20.7089"
"44.6400","11.1319","87.0584","11.1319","7.4212","20.7282"
"44.7200","11.1521","87.1343","11.1521","7.4347","20.7463"
"44.8000","11.1708","87.2020","11.1708","7.4472","20.7624"
"44.8800","11.1922","87.2907","11.1922","7.4615","20.7835"
"44.9600","11.2127","87.3653","11.2127","7.4751","20.8013"
"45.0400","11.2321","87.4373","11.2321","7.4881","20.8184"
"45.1200","11.2516","87.4985","11.2516","7.5011","20.8330"
"45.2000","11.2707","87.5645","11.2707","7.5138","20.8487"
"45.2800","11.2922","87.6441","11.2922","7.5281","20.8676"
"45.3600","11.3124","87.7210","11.3124","7.5416","20.8860"
"45.4400","11.3314","87.7862","11.3314","7.5543","20.9015"
"45.5200","11.3518","87.8713","11.3518","7.5679","20.9217"
"45.6000","11.3726","87.9380","11.3726","7.5817","20.9376"
"45.6800","11.3923","88.0097","11.3923","7.5949","20.9547"
"45.7600","11.4127","88.0771","11.4127","7.6084","20.9707"
"45.8400","11.4314","88.1369","11.4314","7.6210","20.9850"
"45.9200","11.4521","88.2091","11.4521","7.6347","21.0022"
"46.0000","11.4711","88.2619","11.4711","7.6474","21.0147"
"46.0800","11.4913","88.3442","11.4913","7.6609","21.0343"
"46.1600","11.5122","88.4160","11.5122","7.6748","21.0514"
"46.2400","11.5322","88.4718","11.5322","7.6881","21.0647"
"46.3200","11.5522","88.5285","11.5522","7.7014","21.0782"
"46.4000","11.5726","88.5934","11.5726","7.7150","21.0937"
"46.4800","11.5909","88.6350","11.5909","7.7273","21.1036"
"46.5600","11.6118","88.7120","11.6118","7.7412","21.1219"
"46.6400","11.6315","88.7696","11.6315","7.7543","21.1356"
"46.7200","11.6519","88.8353","11.6519","7.7679","21.1513"
"46.8000","11.6731","88.8999","11.6731","7.7821","21.1666"
"46.8800","11.6926","88.9633","11.6926","7.7951","21.1817"
"46.9600","11.7127","89.0108","11.7127","7.8085","21.1930"
"47.0400","11.7323","89.0665","11.7323","7.8215","21.2063"
"47.1200","11.7514","89.1068","11.7514","7.8343","21.2159"
"47.2000","11.7714","89.1624","11.7714","7.8476","21.2291"
"47.2800","11.7909","89.2170","11.7909","7.8606","21.2421"
"47.3600","11.8118","89.2732","11.8118","7.8745","21.2555"
"47.4400","11.8330","89.3473","11.8330","7.8886","21.2732"
"47.5200","11.8517","89.3849","11.8517","7.9011","21.2821"
"47.6000","11.8722","89.4464","11.8722","7.9148","21.2968"
"47.6800","11.8915","89.4956","11.8915","7.9277","21.3085"
"47.7600","11.9117","89.5441","11.9117","7.9411","21.3200"
"47.8400","11.9314","89.5985","11.9314","7.9542","21.3330"
"47.9200","11.9511","89.6439","11.9511","7.9674","21.3438"
"48.0000","11.9721","89.7009","11.9721","7.9814","21.3574"
"48.0800","11.9936","89.7739","11.9936","7.9958","21.3747"
"48.1600","12.0126","89.8114","12.0126","8.0084","21.3837"
"48.2400","12.0321","89.8642","12.0321","8.0214","21.3962"
"48.3200","12.0510","89.8803","12.0510","8.0340","21.4001"
"48.4000","12.0713","89.9292","12.0713","8.0475","21.4117"
"48.4800","12.0922","89.9804","12.0922","8.0615","21.4239"
"48.5600","12.1114","90.0141","12.1114","8.0743","21.4319"
"48.6400","12.1320","90.0762","12.1320","8.0880","21.4467"
"48.7200","12.1526","90.1264","12.1526","8.1017","21.4587"
"48.8000","12.1721","90.1315","12.1721","8.1148","21.4599"
"48.8800","12.1924","90.1826","12.1924","8.1282","21.4721"
"48.9600","12.2114","90.2100","12.2114","8.1410","21.4786"
"49.0400","12.2318","90.2619","12.2318","8.1545","21.4909"
"49.1200","12.2520","90.2864","12.2520","8.1680","21.4968"
"49.2000","12.2713","90.3321","12.2713","8.1809","21.5076"
"49.2800","12.2928","90.3935","12.2928","8.1952","21.5223"
"49.3600","12.3126","90.4273","12.3126","8.2084","21.5303"
"49.4400","12.3331","90.4645","12.3331","8.2220","21.5392"
"49.5200","12.3522","90.4844","12.3522","8.2348","21.5439"
"49.6000","12.3713","90.5310","12.3713","8.2476","21.5550"
"49.6800","12.3918","90.5742","12.3918","8.2612","21.5653"
"49.7600","12.4120","90.5964","12.4120","8.2747","21.5706"
"49.8400","12.4306","90.6160","12.4306","8.2871","21.5752"
"49.9200","12.4519","90.6626","12.4519","8.3013","21.5863"
"50.0000","12.4718","90.6912","12.4718","8.3145","21.5931"
"50.0800","12.4928","90.7253","12.4928","8.3285","21.6013"
"50.1600","12.5120","90.7476","12.5120","8.3413","21.6066"
"50.2400","12.5314","90.7830","12.5314","8.3543","21.6150"
"50.3200","12.5512","90.8138","12.5512","8.3675","21.6223"
"50.4000","12.5712","90.8469","12.5712","8.3808","21.6302"
"50.4800","12.5923","90.8851","12.5923","8.3949","21.6393"
"50.5600","12.6136","90.9364","12.6136","8.4091","21.6515"
"50.6400","12.6325","90.9492","12.6325","8.4216","21.6546"
"50.7200","12.6522","90.9784","12.6522","8.4348","21.6615"
"50.8000","12.6715","90.9945","12.6715","8.4477","21.6654"
"50.8800","12.6913","91.0247","12.6913","8.4609","21.6726"
"50.9600","12.7120","91.0608","12.7120","8.4747","21.6812"
"51.0400","12.7309","91.0726","12.7309","8.4872","21.6839"
"51.1200","12.7518","91.1084","12.7518","8.5012","21.6925"
"51.2000","12.7726","91.1515","12.7726","8.5151","21.7027"
"51.2800","12.7925","91.1797","12.7925","8.5283","21.7095"
"51.3600","12.8125","91.2047","12.8125","8.5416","21.7154"
"51.4400","12.8317","91.2083","12.8317","8.5545","21.7163"
"51.5200","12.8512","91.2187","12.8512","8.5675","21.7187"
"51.6000","12.8720","91.2441","12.8720","8.5813","21.7248"
"51.6800","12.8910","91.2624","12.8910","8.5940","21.7291"
"51.7600","12.9128","91.3134","12.9128","8.6085","21.7413"
"51.8400","12.9327","91.3340","12.9327","8.6218","21.7462"
"51.9200","12.9527","91.3610","12.9527","8.6351","21.7526"
"52.0000","12.9718","91.3642","12.9718","8.6479","21.7534"
"52.0800","12.9914","91.3783","12.9914","8.6610","21.7567"
"52.1600","13.0123","91.4159","13.0123","8.6749","21.7657"
"52.2400","13.0323","91.4294","13.0323","8.6882","21.7689"
"52.3200","13.0504","91.4231","13.0504","8.7003","21.7674"
"52.4000","13.0719","91.4748","13.0719","8.7146","21.7797"
"52.4800","13.0923","91.4953","13.0923","8.7282","21.7846"
"52.5600","13.1128","91.5198","13.1128","8.7419","21.7904"
"52.6400","13.1324","91.5336","13.1324","8.7549","21.7937"
"52.7200","13.1509","91.5394","13.1509","8.7673","21.7951"
"52.8000","13.1716","91.5704","13.1716","8.7811","21.8025"
"52.8800","13.1920","91.6024","13.1920","8.7947","21.8101"
"52.9600","13.2118","91.6236","13.2118","8.8078","21.8151"
"53.0400","13.2328","91.6619","13.2328","8.8219","21.8243"
"53.1200","13.2516","91.6624","13.2516","8.8344","21.8244"
"53.2000","13.2725","91.7056","13.2725","8.8483","21.8347"
"53.2800","13.2928","91.7313","13.2928","8.8618","21.8408"
"53.3600","13.3116","91.7641","13.3116","8.8744","21.8486"
"53.4400","13.3319","91.7813","13.3319","8.8879","21.8527"
"53.5200","13.3507","91.7978","13.3507","8.9004","21.8566"
"53.6000","13.3711","91.8292","13.3711","8.9141","21.8641"
"53.6800","13.3924","91.8749","13.3924","8.9283","21.8750"
"53.7600","13.4124","91.9042","13.4124","8.9416","21.8819"
"53.8400","13.4323","91.9144","13.4323","8.9549","21.8844"
"53.9200","13.4521","91.9360","13.4521","8.9681","21.8895"
"54.0000","13.4709","91.9490","13.4709","8.9806","21.8926"
"54.0800","13.4921","92.0067","13.4921","8.9947","21.9064"
"54.1600","13.5111","92.0173","13.5111","9.0074","21.9089"
"54.2400","13.5325","92.0665","13.5325","9.0217","21.9206"
"54.3200","13.5529","92.0959","13.5529","9.0353","21.9276"
"54.4000","13.5722","92.1159","13.5722","9.0481","21.9324"
"54.4800","13.5923","92.1502","13.5923","9.0615","21.9405"
"54.5600","13.6122","92.1824","13.6122","9.0748","21.9482"
"54.6400","13.6318","92.2062","13.6318","9.0879","21.9539"
"54.7200","13.6521","92.2454","13.6521","9.1014","21.9632"
"54.8000","13.6706","92.2624","13.6706","9.1137","21.9672"
"54.8800","13.6917","92.3017","13.6917","9.1278","21.9766"
"54.9600","13.7126","92.3497","13.7126","9.1417","21.9880"
"55.0400","13.7321","92.3791","13.7321","9.1547","21.9950"
"55.1200","13.7517","92.4092","13.7517","9.1678","22.0022"
"55.2000","13.7710","92.4406","13.7710","9.1806","22.0097"
"55.2800","13.7919","92.4701","13.7919","9.1946","22.0167"
"55.3600","13.8123","92.5175","13.8123","9.2082","22.0280"
"55.4400","13.8313","92.5368","13.8313","9.2209","22.0326"
"55.5200","13.8520","92.5907","13.8520","9.2346","22.0454"
"55.6000","13.8725","92.6293","13.8725","9.2483","22.0546"
"55.6800","13.8925","92.6509","13.8925","9.2617","22.0597"
"55.7600","13.9125","92.6896","13.9125","9.2750","22.0690"
"55.8400","13.9311","92.7120","13.9311","9.2874","22.0743"
"55.9200","13.9517","92.7449","13.9517","9.3011","22.0821"
"56.0000","13.9715","92.7829","13.9715","9.3143","22.0912"
"56.0800","13.9915","92.8261","13.9915","9.3277","22.1015"
"56.1600","14.0123","92.8778","14.0123","9.3415","22.1138"
"56.2400","14.0321","92.9122","14.0321","9.3547","22.1220"
"56.3200","14.0522","92.9465","14.0522","9.3681","22.1301"
"56.4000","14.0724","92.9806","14.0724","9.3816","22.1382"
"56.4800","14.0910","93.0138","14.0910","9.3940","22.1461"
"56.5600","14.1119","93.0651","14.1119","9.4080","22.1584"
"56.6400","14.1315","93.0943","14.1315","9.4210","22.1653"
"56.7200","14.1517","93.1412","14.1517","9.4345","22.1765"
"56.8000","14.1729","93.2030","14.1729","9.4486","22.1912"
"56.8800","14.1925","93.2196","14.1925","9.4617","22.1952"
"56.9600","14.2128","93.2701","14.2128","9.4752","22.2072"
"57.0400","14.2324","93.3075","14.2324","9.4883","22.2161"
"57.1200","14.2513","93.3488","14.2513","9.5009","22.2259"
"57.2000","14.2714","93.3970","14.2714","9.5142","22.2374"
"57.2800","14.2909","93.4288","14.2909","9.5272","22.2449"
"57.3600","14.3119","93.4976","14.3119","9.5413","22.2613"
"57.4400","14.3328","93.5356","14.3328","9.5552","22.2704"
"57.5200","14.3515","93.5694","14.3515","9.5677","22.2784"
"57.6000","14.3722","93.6222","14.3722","9.5814","22.2910"
"57.6800","14.3915","93.6622","14.3915","9.5943","22.3005"
"57.7600","14.4118","93.7079","14.4118","9.6079","22.3114"
"57.8400","14.4316","93.7500","14.4316","9.6211","22.3214"
"57.9200","14.4511","93.7930","14.4511","9.6341","22.3317"
"58.0000","14.4722","93.8495","14.4722","9.6481","22.3451"
"58.0800","14.4932","93.9035","14.4932","9.6622","22.3580"
"58.1600","14.5123","93.9453","14.5123","9.6749","22.3679"
"58.2400","14.5314","93.9785","14.5314","9.6876","22.3758"
"58.3200","14.5509","94.0100","14.5509","9.7006","22.3833"
"58.4000","14.5720","94.0736","14.5720","9.7146","22.3985"
"58.4800","14.5924","94.1288","14.5924","9.7283","22.4116"
"58.5600","14.6112","94.1640","14.6112","9.7408","22.4200"
"58.6400","14.6318","94.2287","14.6318","9.7546","22.4354"
"58.7200","14.6523","94.2757","14.6523","9.7682","22.4466"
"58.8000","14.6721","94.3295","14.6721","9.7814","22.4594"
"58.8800","14.6923","94.3757","14.6923","9.7948","22.4704"
"58.9600","14.7114","94.4014","14.7114","9.8076","22.4765"
"59.0400","14.7318","94.4472","14.7318","9.8212","22.4874"
"59.1200","14.7518","94.4820","14.7518","9.8345","22.4957"
"59.2000","14.7713","94.5416","14.7713","9.8475","22.5099"
"59.2800","14.7927","94.6106","14.7927","9.8618","22.5263"
"59.3600","14.8125","94.6494","14.8125","9.8750","22.5356"
"59.4400","14.8327","94.6935","14.8327","9.8885","22.5461"
"59.5200","14.8522","94.7315","14.8522","9.9015","22.5551"
"59.6000","14.8715","94.7869","14.8715","9.9143","22.5683"
"59.6800","14.8919","94.8287","14.8919","9.9279","22.5783"
"59.7600","14.9114","94.8643","14.9114","9.9409","22.5867"
"59.8400","14.9308","94.9117","14.9308","9.9539","22.5980"
"59.9200","14.9521","94.9787","14.9521","9.9680","22.6140"
"60.0000","14.9717","95.0242","14.9717","9.9811","22.6248"
"60.0800","14.9929","95.0860","14.9929","9.9952","22.6395"
"60.1100","15.0001","95.0998","15.0001","10.0001","22.6428"