File: data/instron_tests/metamaterials/250416/250416_50-50_Composite.is_comp_Exports/250416_50-50_Composite_5_1.csv
Results Table 1
,Compresson Axis,H*,V*,Height,Thickness,Width,Area,Fixture separation,Specimen label
,,,,(mm),(mm),(mm),(mm^2),(mm),
"5","X","","","150.00","28.00","150.00","4200.00","150.00","50/50 Composite"

Results Table 2
,Modulus (Segment 0 % - 2.5 %),Compresson Axis
,(kPa),
"5","365.46","X"

Time,Displacement,Force,Compressive displacement,Compressive strain (Displacement),Compressive stress
(s),(mm),(N),(mm),(%),(kPa)
"0.0000","0.0000","-15.1795","0.0000","0.0000","-3.6142"
"0.0800","0.0011","-15.1482","0.0011","0.0008","-3.6067"
"0.1600","0.0174","-14.9025","0.0174","0.0116","-3.5482"
"0.2400","0.0378","-14.5907","0.0378","0.0252","-3.4740"
"0.3200","0.0576","-14.3258","0.0576","0.0384","-3.4109"
"0.4000","0.0769","-14.0766","0.0769","0.0513","-3.3516"
"0.4800","0.0984","-13.8035","0.0984","0.0656","-3.2866"
"0.5600","0.1180","-13.5521","0.1180","0.0787","-3.2267"
"0.6400","0.1374","-13.3025","0.1374","0.0916","-3.1673"
"0.7200","0.1574","-13.0432","0.1574","0.1049","-3.1055"
"0.8000","0.1772","-12.8027","0.1772","0.1181","-3.0483"
"0.8800","0.1976","-12.5485","0.1976","0.1317","-2.9877"
"0.9600","0.2176","-12.3209","0.2176","0.1450","-2.9335"
"1.0400","0.2358","-12.0898","0.2358","0.1572","-2.8785"
"1.1200","0.2571","-11.8304","0.2571","0.1714","-2.8168"
"1.2000","0.2777","-11.5753","0.2777","0.1851","-2.7560"
"1.2800","0.2983","-11.3290","0.2983","0.1989","-2.6974"
"1.3600","0.3180","-11.0999","0.3180","0.2120","-2.6428"
"1.4400","0.3363","-10.8918","0.3363","0.2242","-2.5933"
"1.5200","0.3566","-10.6613","0.3566","0.2377","-2.5384"
"1.6000","0.3774","-10.4264","0.3774","0.2516","-2.4825"
"1.6800","0.3968","-10.1895","0.3968","0.2646","-2.4261"
"1.7600","0.4183","-9.9324","0.4183","0.2789","-2.3649"
"1.8400","0.4380","-9.7081","0.4380","0.2920","-2.3115"
"1.9200","0.4578","-9.4893","0.4578","0.3052","-2.2594"
"2.0000","0.4777","-9.2609","0.4777","0.3185","-2.2050"
"2.0800","0.4970","-9.0426","0.4970","0.3313","-2.1530"
"2.1600","0.5171","-8.8184","0.5171","0.3448","-2.0996"
"2.2400","0.5367","-8.6113","0.5367","0.3578","-2.0503"
"2.3200","0.5564","-8.3752","0.5564","0.3709","-1.9941"
"2.4000","0.5776","-8.1341","0.5776","0.3851","-1.9367"
"2.4800","0.5978","-7.9106","0.5978","0.3986","-1.8835"
"2.5600","0.6182","-7.6763","0.6182","0.4122","-1.8277"
"2.6400","0.6371","-7.4875","0.6371","0.4247","-1.7827"
"2.7200","0.6559","-7.2731","0.6559","0.4373","-1.7317"
"2.8000","0.6764","-7.0413","0.6764","0.4509","-1.6765"
"2.8800","0.6970","-6.8041","0.6970","0.4647","-1.6200"
"2.9600","0.7180","-6.5811","0.7180","0.4787","-1.5669"
"3.0400","0.7387","-6.3636","0.7387","0.4924","-1.5151"
"3.1200","0.7572","-6.1609","0.7572","0.5048","-1.4669"
"3.2000","0.7776","-5.9306","0.7776","0.5184","-1.4120"
"3.2800","0.7975","-5.7218","0.7975","0.5317","-1.3623"
"3.3600","0.8170","-5.4911","0.8170","0.5447","-1.3074"
"3.4400","0.8372","-5.2774","0.8372","0.5581","-1.2565"
"3.5200","0.8560","-5.0866","0.8560","0.5707","-1.2111"
"3.6000","0.8772","-4.8467","0.8772","0.5848","-1.1540"
"3.6800","0.8984","-4.6255","0.8984","0.5989","-1.1013"
"3.7600","0.9174","-4.4158","0.9174","0.6116","-1.0514"
"3.8400","0.9374","-4.1926","0.9374","0.6249","-0.9982"
"3.9200","0.9567","-3.9905","0.9567","0.6378","-0.9501"
"4.0000","0.9765","-3.7802","0.9765","0.6510","-0.9001"
"4.0800","0.9974","-3.5537","0.9974","0.6649","-0.8461"
"4.1600","1.0169","-3.3340","1.0169","0.6779","-0.7938"
"4.2400","1.0379","-3.1111","1.0379","0.6919","-0.7407"
"4.3200","1.0578","-2.9034","1.0578","0.7052","-0.6913"
"4.4000","1.0778","-2.6870","1.0778","0.7185","-0.6398"
"4.4800","1.0977","-2.4807","1.0977","0.7318","-0.5906"
"4.5600","1.1170","-2.2843","1.1170","0.7447","-0.5439"
"4.6400","1.1372","-2.0695","1.1372","0.7581","-0.4927"
"4.7200","1.1575","-1.8492","1.1575","0.7717","-0.4403"
"4.8000","1.1763","-1.6478","1.1763","0.7842","-0.3923"
"4.8800","1.1973","-1.4191","1.1973","0.7982","-0.3379"
"4.9600","1.2177","-1.2179","1.2177","0.8118","-0.2900"
"5.0400","1.2371","-1.0116","1.2371","0.8248","-0.2409"
"5.1200","1.2574","-0.8209","1.2574","0.8383","-0.1955"
"5.2000","1.2765","-0.6038","1.2765","0.8510","-0.1438"
"5.2800","1.2974","-0.3912","1.2974","0.8649","-0.0931"
"5.3600","1.3174","-0.1775","1.3174","0.8783","-0.0423"
"5.4400","1.3371","0.0281","1.3371","0.8914","0.0067"
"5.5200","1.3580","0.2514","1.3580","0.9053","0.0599"
"5.6000","1.3779","0.4479","1.3779","0.9186","0.1066"
"5.6800","1.3982","0.6566","1.3982","0.9322","0.1563"
"5.7600","1.4179","0.8628","1.4179","0.9452","0.2054"
"5.8400","1.4366","1.0532","1.4366","0.9577","0.2508"
"5.9200","1.4571","1.2728","1.4571","0.9714","0.3031"
"6.0000","1.4764","1.4700","1.4764","0.9843","0.3500"
"6.0800","1.4973","1.6878","1.4973","0.9982","0.4018"
"6.1600","1.5180","1.9049","1.5180","1.0120","0.4536"
"6.2400","1.5375","2.1092","1.5375","1.0250","0.5022"
"6.3200","1.5574","2.3094","1.5574","1.0382","0.5499"
"6.4000","1.5772","2.5130","1.5772","1.0515","0.5983"
"6.4800","1.5965","2.7201","1.5965","1.0643","0.6476"
"6.5600","1.6175","2.9381","1.6175","1.0784","0.6996"
"6.6400","1.6363","3.1190","1.6363","1.0909","0.7426"
"6.7200","1.6575","3.3393","1.6575","1.1050","0.7951"
"6.8000","1.6782","3.5584","1.6782","1.1188","0.8472"
"6.8800","1.6981","3.7617","1.6981","1.1320","0.8956"
"6.9600","1.7175","3.9554","1.7175","1.1450","0.9418"
"7.0400","1.7372","4.1567","1.7372","1.1581","0.9897"
"7.1200","1.7571","4.3691","1.7571","1.1714","1.0403"
"7.2000","1.7773","4.5621","1.7773","1.1849","1.0862"
"7.2800","1.7962","4.7579","1.7962","1.1975","1.1328"
"7.3600","1.8174","4.9698","1.8174","1.2116","1.1833"
"7.4400","1.8375","5.1746","1.8375","1.2250","1.2320"
"7.5200","1.8575","5.3791","1.8575","1.2383","1.2807"
"7.6000","1.8780","5.5922","1.8780","1.2520","1.3315"
"7.6800","1.8970","5.7708","1.8970","1.2646","1.3740"
"7.7600","1.9172","5.9665","1.9172","1.2781","1.4206"
"7.8400","1.9371","6.1765","1.9371","1.2914","1.4706"
"7.9200","1.9565","6.3791","1.9565","1.3044","1.5188"
"8.0000","1.9774","6.5836","1.9774","1.3183","1.5675"
"8.0800","1.9983","6.8014","1.9983","1.3322","1.6194"
"8.1600","2.0182","6.9872","2.0182","1.3455","1.6636"
"8.2400","2.0379","7.1921","2.0379","1.3586","1.7124"
"8.3200","2.0564","7.3763","2.0564","1.3709","1.7563"
"8.4000","2.0772","7.5831","2.0772","1.3848","1.8055"
"8.4800","2.0969","7.7810","2.0969","1.3980","1.8526"
"8.5600","2.1169","7.9772","2.1169","1.4113","1.8993"
"8.6400","2.1374","8.1970","2.1374","1.4249","1.9517"
"8.7200","2.1576","8.3920","2.1576","1.4384","1.9981"
"8.8000","2.1774","8.5845","2.1774","1.4516","2.0439"
"8.8800","2.1979","8.7842","2.1979","1.4653","2.0915"
"8.9600","2.2165","8.9740","2.2165","1.4777","2.1367"
"9.0400","2.2374","9.1868","2.2374","1.4916","2.1873"
"9.1200","2.2565","9.3780","2.2565","1.5043","2.2329"
"9.2000","2.2772","9.5862","2.2772","1.5181","2.2824"
"9.2800","2.2987","9.7965","2.2987","1.5324","2.3325"
"9.3600","2.3178","9.9766","2.3178","1.5452","2.3754"
"9.4400","2.3378","10.1759","2.3378","1.5585","2.4228"
"9.5200","2.3572","10.3638","2.3572","1.5715","2.4676"
"9.6000","2.3768","10.5700","2.3768","1.5845","2.5167"
"9.6800","2.3976","10.7888","2.3976","1.5984","2.5688"
"9.7600","2.4164","10.9595","2.4164","1.6109","2.6094"
"9.8400","2.4360","11.1589","2.4360","1.6240","2.6569"
"9.9200","2.4577","11.3748","2.4577","1.6385","2.7083"
"10.0000","2.4777","11.5744","2.4777","1.6518","2.7558"
"10.0800","2.4981","11.7750","2.4981","1.6654","2.8036"
"10.1600","2.5172","11.9574","2.5172","1.6781","2.8470"
"10.2400","2.5371","12.1549","2.5371","1.6914","2.8940"
"10.3200","2.5570","12.3385","2.5570","1.7047","2.9377"
"10.4000","2.5764","12.5275","2.5764","1.7176","2.9827"
"10.4800","2.5977","12.7321","2.5977","1.7318","3.0315"
"10.5600","2.6189","12.9451","2.6189","1.7459","3.0822"
"10.6400","2.6376","13.1287","2.6376","1.7584","3.1259"
"10.7200","2.6573","13.3219","2.6573","1.7716","3.1719"
"10.8000","2.6770","13.5011","2.6770","1.7847","3.2145"
"10.8800","2.6978","13.7057","2.6978","1.7985","3.2633"
"10.9600","2.7176","13.8940","2.7176","1.8117","3.3081"
"11.0400","2.7361","14.0736","2.7361","1.8241","3.3509"
"11.1200","2.7569","14.2828","2.7569","1.8379","3.4007"
"11.2000","2.7777","14.4877","2.7777","1.8518","3.4495"
"11.2800","2.7978","14.6856","2.7978","1.8652","3.4966"
"11.3600","2.8180","14.8883","2.8180","1.8787","3.5448"
"11.4400","2.8363","15.0546","2.8363","1.8909","3.5844"
"11.5200","2.8569","15.2554","2.8569","1.9046","3.6322"
"11.6000","2.8772","15.4546","2.8772","1.9181","3.6797"
"11.6800","2.8970","15.6541","2.8970","1.9313","3.7272"
"11.7600","2.9179","15.8673","2.9180","1.9453","3.7779"
"11.8400","2.9378","16.0486","2.9378","1.9585","3.8211"
"11.9200","2.9580","16.2428","2.9580","1.9720","3.8673"
"12.0000","2.9779","16.4410","2.9779","1.9852","3.9145"
"12.0800","2.9971","16.6335","2.9971","1.9980","3.9604"
"12.1600","3.0169","16.8124","3.0169","2.0113","4.0030"
"12.2400","3.0368","17.0082","3.0368","2.0245","4.0496"
"12.3200","3.0565","17.2008","3.0565","2.0377","4.0954"
"12.4000","3.0781","17.4210","3.0781","2.0521","4.1478"
"12.4800","3.0974","17.5985","3.0974","2.0649","4.1901"
"12.5600","3.1181","17.7958","3.1181","2.0787","4.2371"
"12.6400","3.1371","17.9711","3.1371","2.0914","4.2788"
"12.7200","3.1563","18.1642","3.1563","2.1042","4.3248"
"12.8000","3.1770","18.3820","3.1770","2.1180","4.3767"
"12.8800","3.1973","18.5693","3.1973","2.1315","4.4213"
"12.9600","3.2177","18.7735","3.2177","2.1452","4.4699"
"13.0400","3.2388","18.9743","3.2388","2.1592","4.5177"
"13.1200","3.2572","19.1510","3.2572","2.1715","4.5598"
"13.2000","3.2774","19.3446","3.2774","2.1849","4.6059"
"13.2800","3.2974","19.5434","3.2974","2.1983","4.6532"
"13.3600","3.3175","19.7335","3.3175","2.2117","4.6984"
"13.4400","3.3373","19.9184","3.3373","2.2248","4.7425"
"13.5200","3.3559","20.0910","3.3559","2.2373","4.7836"
"13.6000","3.3770","20.2986","3.3770","2.2513","4.8330"
"13.6800","3.3984","20.5031","3.3984","2.2656","4.8817"
"13.7600","3.4178","20.6885","3.4178","2.2785","4.9258"
"13.8400","3.4372","20.8800","3.4372","2.2915","4.9714"
"13.9200","3.4566","21.0521","3.4566","2.3044","5.0124"
"14.0000","3.4768","21.2524","3.4768","2.3179","5.0601"
"14.0800","3.4979","21.4508","3.4979","2.3319","5.1073"
"14.1600","3.5167","21.6328","3.5167","2.3445","5.1507"
"14.2400","3.5377","21.8331","3.5377","2.3584","5.1984"
"14.3200","3.5577","22.0195","3.5577","2.3718","5.2427"
"14.4000","3.5780","22.2085","3.5780","2.3853","5.2877"
"14.4800","3.5975","22.3913","3.5975","2.3984","5.3313"
"14.5600","3.6168","22.5677","3.6168","2.4112","5.3733"
"14.6400","3.6371","22.7586","3.6371","2.4248","5.4187"
"14.7200","3.6571","22.9491","3.6571","2.4381","5.4641"
"14.8000","3.6759","23.1234","3.6759","2.4506","5.5056"
"14.8800","3.6970","23.3392","3.6970","2.4646","5.5569"
"14.9600","3.7178","23.5268","3.7178","2.4785","5.6016"
"15.0400","3.7381","23.7225","3.7381","2.4920","5.6482"
"15.1200","3.7572","23.8911","3.7572","2.5048","5.6884"
"15.2000","3.7763","24.0774","3.7763","2.5175","5.7327"
"15.2800","3.7971","24.2781","3.7971","2.5314","5.7805"
"15.3600","3.8171","24.4632","3.8171","2.5448","5.8246"
"15.4400","3.8372","24.6620","3.8372","2.5581","5.8719"
"15.5200","3.8580","24.8615","3.8580","2.5720","5.9194"
"15.6000","3.8778","25.0336","3.8778","2.5852","5.9604"
"15.6800","3.8979","25.2285","3.8979","2.5986","6.0068"
"15.7600","3.9180","25.4189","3.9180","2.6120","6.0521"
"15.8400","3.9367","25.5953","3.9367","2.6244","6.0941"
"15.9200","3.9570","25.7899","3.9570","2.6380","6.1404"
"16.0000","3.9767","25.9762","3.9767","2.6511","6.1848"
"16.0800","3.9975","26.1737","3.9975","2.6650","6.2318"
"16.1600","4.0180","26.3679","4.0180","2.6787","6.2781"
"16.2400","4.0371","26.5418","4.0371","2.6914","6.3195"
"16.3200","4.0574","26.7303","4.0574","2.7049","6.3644"
"16.4000","4.0772","26.9046","4.0772","2.7182","6.4059"
"16.4800","4.0962","27.0883","4.0962","2.7308","6.4496"
"16.5600","4.1177","27.2988","4.1177","2.7451","6.4997"
"16.6400","4.1365","27.4763","4.1365","2.7577","6.5420"
"16.7200","4.1578","27.6752","4.1578","2.7718","6.5893"
"16.8000","4.1783","27.8606","4.1783","2.7855","6.6335"
"16.8800","4.1979","28.0427","4.1979","2.7986","6.6768"
"16.9600","4.2176","28.2185","4.2176","2.8117","6.7187"
"17.0400","4.2371","28.3928","4.2371","2.8247","6.7602"
"17.1200","4.2571","28.5923","4.2571","2.8381","6.8077"
"17.2000","4.2774","28.7574","4.2774","2.8516","6.8470"
"17.2800","4.2956","28.9374","4.2956","2.8637","6.8899"
"17.3600","4.3172","29.1406","4.3172","2.8782","6.9382"
"17.4400","4.3381","29.3363","4.3381","2.8920","6.9848"
"17.5200","4.3576","29.5195","4.3576","2.9051","7.0285"
"17.6000","4.3775","29.7044","4.3775","2.9183","7.0725"
"17.6800","4.3966","29.8746","4.3966","2.9311","7.1130"
"17.7600","4.4174","30.0647","4.4174","2.9450","7.1583"
"17.8400","4.4375","30.2549","4.4375","2.9583","7.2035"
"17.9200","4.4565","30.4306","4.4565","2.9710","7.2454"
"18.0000","4.4776","30.6437","4.4776","2.9851","7.2961"
"18.0800","4.4984","30.8338","4.4984","2.9990","7.3414"
"18.1600","4.5178","31.0086","4.5178","3.0119","7.3830"
"18.2400","4.5378","31.1810","4.5378","3.0252","7.4241"
"18.3200","4.5561","31.3497","4.5561","3.0374","7.4642"
"18.4000","4.5773","31.5425","4.5773","3.0515","7.5101"
"18.4800","4.5969","31.7342","4.5969","3.0646","7.5558"
"18.5600","4.6169","31.9197","4.6169","3.0779","7.5999"
"18.6400","4.6376","32.1164","4.6376","3.0917","7.6468"
"18.7200","4.6575","32.2940","4.6575","3.1050","7.6890"
"18.8000","4.6773","32.4703","4.6773","3.1182","7.7310"
"18.8800","4.6980","32.6561","4.6980","3.1320","7.7753"
"18.9600","4.7165","32.8319","4.7165","3.1443","7.8171"
"19.0400","4.7369","33.0229","4.7369","3.1580","7.8626"
"19.1200","4.7567","33.1988","4.7567","3.1711","7.9045"
"19.2000","4.7773","33.3934","4.7773","3.1849","7.9508"
"19.2800","4.7984","33.5815","4.7984","3.1989","7.9956"
"19.3600","4.8178","33.7539","4.8178","3.2119","8.0366"
"19.4400","4.8378","33.9307","4.8378","3.2252","8.0787"
"19.5200","4.8573","34.1115","4.8573","3.2382","8.1218"
"19.6000","4.8772","34.3006","4.8772","3.2515","8.1668"
"19.6800","4.8972","34.4840","4.8972","3.2648","8.2105"
"19.7600","4.9165","34.6408","4.9165","3.2777","8.2478"
"19.8400","4.9371","34.8343","4.9371","3.2914","8.2939"
"19.9200","4.9582","35.0069","4.9582","3.3055","8.3350"
"20.0000","4.9774","35.1854","4.9774","3.3183","8.3775"
"20.0800","4.9978","35.3635","4.9978","3.3319","8.4199"
"20.1600","5.0169","35.5407","5.0169","3.3446","8.4621"
"20.2400","5.0368","35.7225","5.0368","3.3579","8.5054"
"20.3200","5.0569","35.9058","5.0569","3.3713","8.5490"
"20.4000","5.0766","36.0880","5.0766","3.3844","8.5924"
"20.4800","5.0980","36.2713","5.0980","3.3987","8.6360"
"20.5600","5.1188","36.4577","5.1188","3.4125","8.6804"
"20.6400","5.1373","36.6229","5.1373","3.4248","8.7197"
"20.7200","5.1572","36.8040","5.1572","3.4381","8.7628"
"20.8000","5.1762","36.9655","5.1762","3.4508","8.8013"
"20.8800","5.1975","37.1601","5.1975","3.4650","8.8476"
"20.9600","5.2178","37.3361","5.2178","3.4785","8.8895"
"21.0400","5.2362","37.5048","5.2362","3.4908","8.9297"
"21.1200","5.2569","37.6952","5.2569","3.5046","8.9750"
"21.2000","5.2777","37.8783","5.2777","3.5185","9.0186"
"21.2800","5.2979","38.0601","5.2979","3.5319","9.0619"
"21.3600","5.3181","38.2344","5.3181","3.5454","9.1034"
"21.4400","5.3364","38.3897","5.3364","3.5576","9.1404"
"21.5200","5.3566","38.5690","5.3566","3.5711","9.1831"
"21.6000","5.3773","38.7436","5.3773","3.5849","9.2247"
"21.6800","5.3971","38.9405","5.3971","3.5980","9.2716"
"21.7600","5.4182","39.1252","5.4182","3.6121","9.3155"
"21.8400","5.4378","39.3007","5.4378","3.6252","9.3573"
"21.9200","5.4577","39.4608","5.4577","3.6385","9.3954"
"22.0000","5.4774","39.6388","5.4774","3.6516","9.4378"
"22.0800","5.4972","39.8187","5.4972","3.6648","9.4806"
"22.1600","5.5174","39.9925","5.5174","3.6783","9.5220"
"22.2400","5.5367","40.1519","5.5367","3.6911","9.5600"
"22.3200","5.5564","40.3336","5.5564","3.7043","9.6032"
"22.4000","5.5779","40.5259","5.5779","3.7186","9.6490"
"22.4800","5.5974","40.6922","5.5974","3.7316","9.6886"
"22.5600","5.6180","40.8738","5.6180","3.7453","9.7319"
"22.6400","5.6375","41.0441","5.6375","3.7583","9.7724"
"22.7200","5.6565","41.2077","5.6565","3.7710","9.8114"
"22.8000","5.6766","41.3824","5.6766","3.7844","9.8529"
"22.8800","5.6973","41.5612","5.6973","3.7982","9.8955"
"22.9600","5.7178","41.7351","5.7178","3.8119","9.9369"
"23.0400","5.7382","41.9083","5.7382","3.8255","9.9782"
"23.1200","5.7566","42.0695","5.7566","3.8378","10.0166"
"23.2000","5.7775","42.2487","5.7775","3.8517","10.0592"
"23.2800","5.7977","42.4301","5.7977","3.8651","10.1024"
"23.3600","5.8175","42.6007","5.8175","3.8783","10.1430"
"23.4400","5.8373","42.7677","5.8373","3.8916","10.1828"
"23.5200","5.8557","42.9207","5.8557","3.9038","10.2192"
"23.6000","5.8774","43.1094","5.8774","3.9182","10.2642"
"23.6800","5.8985","43.3055","5.8985","3.9323","10.3108"
"23.7600","5.9177","43.4655","5.9177","3.9451","10.3489"
"23.8400","5.9376","43.6439","5.9376","3.9584","10.3914"
"23.9200","5.9566","43.7978","5.9566","3.9711","10.4281"
"24.0000","5.9765","43.9660","5.9765","3.9843","10.4681"
"24.0800","5.9976","44.1527","5.9976","3.9984","10.5125"
"24.1600","6.0167","44.3174","6.0167","4.0111","10.5518"
"24.2400","6.0377","44.5018","6.0377","4.0251","10.5957"
"24.3200","6.0579","44.6749","6.0579","4.0386","10.6369"
"24.4000","6.0783","44.8531","6.0783","4.0522","10.6793"
"24.4800","6.0979","45.0300","6.0979","4.0652","10.7214"
"24.5600","6.1172","45.1880","6.1172","4.0781","10.7590"
"24.6400","6.1371","45.3456","6.1371","4.0914","10.7966"
"24.7200","6.1574","45.5203","6.1574","4.1049","10.8382"
"24.8000","6.1760","45.6824","6.1760","4.1173","10.8768"
"24.8800","6.1974","45.8830","6.1974","4.1316","10.9245"
"24.9600","6.2176","46.0393","6.2176","4.1451","10.9617"
"25.0400","6.2379","46.2042","6.2379","4.1586","11.0010"
"25.1200","6.2573","46.3663","6.2573","4.1716","11.0396"
"25.2000","6.2760","46.5172","6.2760","4.1840","11.0755"
"25.2800","6.2973","46.7016","6.2973","4.1982","11.1194"
"25.3600","6.3174","46.8712","6.3174","4.2116","11.1598"
"25.4400","6.3373","47.0492","6.3373","4.2249","11.2022"
"25.5200","6.3577","47.2253","6.3577","4.2385","11.2441"
"25.6000","6.3778","47.3875","6.3778","4.2518","11.2827"
"25.6800","6.3977","47.5509","6.3977","4.2651","11.3216"
"25.7600","6.4180","47.7088","6.4180","4.2787","11.3592"
"25.8400","6.4366","47.8776","6.4366","4.2911","11.3994"
"25.9200","6.4573","48.0467","6.4573","4.3048","11.4397"
"26.0000","6.4765","48.1993","6.4765","4.3176","11.4760"
"26.0800","6.4974","48.3756","6.4974","4.3316","11.5180"
"26.1600","6.5182","48.5512","6.5182","4.3455","11.5598"
"26.2400","6.5373","48.7073","6.5373","4.3582","11.5970"
"26.3200","6.5573","48.8717","6.5573","4.3716","11.6361"
"26.4000","6.5773","49.0371","6.5773","4.3849","11.6755"
"26.4800","6.5966","49.1988","6.5966","4.3977","11.7140"
"26.5600","6.6176","49.3824","6.6176","4.4117","11.7577"
"26.6400","6.6366","49.5309","6.6366","4.4244","11.7931"
"26.7200","6.6578","49.7030","6.6578","4.4385","11.8340"
"26.8000","6.6781","49.8762","6.6781","4.4521","11.8753"
"26.8800","6.6977","50.0490","6.6977","4.4651","11.9164"
"26.9600","6.7176","50.2137","6.7176","4.4784","11.9556"
"27.0400","6.7371","50.3730","6.7371","4.4914","11.9936"
"27.1200","6.7570","50.5321","6.7570","4.5047","12.0314"
"27.2000","6.7776","50.6971","6.7776","4.5184","12.0707"
"27.2800","6.7960","50.8503","6.7960","4.5307","12.1072"
"27.3600","6.8174","51.0348","6.8174","4.5450","12.1511"
"27.4400","6.8382","51.2035","6.8382","4.5588","12.1913"
"27.5200","6.8577","51.3646","6.8577","4.5718","12.2297"
"27.6000","6.8775","51.5247","6.8775","4.5850","12.2678"
"27.6800","6.8965","51.6825","6.8965","4.5977","12.3054"
"27.7600","6.9172","51.8570","6.9172","4.6115","12.3469"
"27.8400","6.9374","52.0197","6.9374","4.6249","12.3857"
"27.9200","6.9567","52.1776","6.9567","4.6378","12.4232"
"28.0000","6.9773","52.3606","6.9773","4.6516","12.4668"
"28.0800","6.9986","52.5384","6.9986","4.6657","12.5091"
"28.1600","7.0183","52.6930","7.0183","4.6788","12.5460"
"28.2400","7.0376","52.8452","7.0376","4.6918","12.5822"
"28.3200","7.0558","52.9814","7.0558","4.7038","12.6146"
"28.4000","7.0773","53.1717","7.0773","4.7182","12.6599"
"28.4800","7.0975","53.3356","7.0975","4.7317","12.6990"
"28.5600","7.1172","53.4963","7.1172","4.7448","12.7372"
"28.6400","7.1370","53.6603","7.1370","4.7580","12.7763"
"28.7200","7.1574","53.8127","7.1574","4.7716","12.8125"
"28.8000","7.1774","53.9661","7.1774","4.7849","12.8491"
"28.8800","7.1979","54.1324","7.1979","4.7986","12.8887"
"28.9600","7.2165","54.2764","7.2165","4.8110","12.9230"
"29.0400","7.2371","54.4603","7.2371","4.8247","12.9667"
"29.1200","7.2565","54.5988","7.2565","4.8377","12.9997"
"29.2000","7.2771","54.7746","7.2771","4.8514","13.0416"
"29.2800","7.2988","54.9566","7.2988","4.8659","13.0849"
"29.3600","7.3180","55.1028","7.3180","4.8786","13.1197"
"29.4400","7.3379","55.2575","7.3379","4.8919","13.1566"
"29.5200","7.3572","55.4031","7.3572","4.9048","13.1912"
"29.6000","7.3769","55.5750","7.3769","4.9179","13.2321"
"29.6800","7.3974","55.7400","7.3974","4.9316","13.2714"
"29.7600","7.4166","55.8775","7.4166","4.9444","13.3042"
"29.8400","7.4369","56.0392","7.4369","4.9579","13.3427"
"29.9200","7.4580","56.2109","7.4580","4.9720","13.3836"
"30.0000","7.4772","56.3714","7.4772","4.9848","13.4218"
"30.0800","7.4980","56.5337","7.4980","4.9987","13.4604"
"30.1600","7.5169","56.6888","7.5169","5.0113","13.4973"
"30.2400","7.5371","56.8346","7.5371","5.0247","13.5320"
"30.3200","7.5572","56.9920","7.5572","5.0381","13.5695"
"30.4000","7.5765","57.1427","7.5765","5.0510","13.6054"
"30.4800","7.5977","57.3183","7.5977","5.0651","13.6472"
"30.5600","7.6186","57.4839","7.6186","5.0791","13.6866"
"30.6400","7.6375","57.6393","7.6375","5.0917","13.7237"
"30.7200","7.6579","57.7933","7.6579","5.1053","13.7603"
"30.8000","7.6772","57.9369","7.6772","5.1181","13.7945"
"30.8800","7.6974","58.0928","7.6974","5.1316","13.8316"
"30.9600","7.7175","58.2397","7.7175","5.1450","13.8666"
"31.0400","7.7362","58.4029","7.7362","5.1574","13.9054"
"31.1200","7.7570","58.5540","7.7570","5.1713","13.9414"
"31.2000","7.7779","58.7203","7.7779","5.1852","13.9810"
"31.2800","7.7978","58.8732","7.7978","5.1985","14.0174"
"31.3600","7.8181","59.0362","7.8181","5.2121","14.0562"
"31.4400","7.8367","59.1678","7.8367","5.2244","14.0876"
"31.5200","7.8567","59.3143","7.8567","5.2378","14.1224"
"31.6000","7.8771","59.4788","7.8771","5.2514","14.1616"
"31.6800","7.8970","59.6303","7.8970","5.2647","14.1977"
"31.7600","7.9182","59.8026","7.9182","5.2788","14.2387"
"31.8400","7.9379","59.9445","7.9379","5.2919","14.2725"
"31.9200","7.9578","60.0874","7.9578","5.3052","14.3065"
"32.0000","7.9778","60.2453","7.9778","5.3185","14.3441"
"32.0800","7.9970","60.3866","7.9970","5.3313","14.3778"
"32.1600","8.0169","60.5428","8.0169","5.3446","14.4149"
"32.2400","8.0367","60.6880","8.0367","5.3578","14.4495"
"32.3200","8.0564","60.8377","8.0564","5.3709","14.4852"
"32.4000","8.0780","61.0084","8.0780","5.3854","14.5258"
"32.4800","8.0975","61.1461","8.0975","5.3983","14.5586"
"32.5600","8.1181","61.3027","8.1181","5.4121","14.5959"
"32.6400","8.1372","61.4394","8.1372","5.4248","14.6284"
"32.7200","8.1565","61.5882","8.1565","5.4377","14.6638"
"32.8000","8.1766","61.7379","8.1766","5.4511","14.6995"
"32.8800","8.1971","61.8890","8.1971","5.4647","14.7355"
"32.9600","8.2178","62.0403","8.2178","5.4785","14.7715"
"33.0400","8.2387","62.2009","8.2387","5.4925","14.8097"
"33.1200","8.2571","62.3332","8.2571","5.5047","14.8412"
"33.2000","8.2776","62.4845","8.2776","5.5184","14.8773"
"33.2800","8.2974","62.6308","8.2974","5.5316","14.9121"
"33.3600","8.3171","62.7701","8.3171","5.5447","14.9453"
"33.4400","8.3372","62.9103","8.3372","5.5581","14.9787"
"33.5200","8.3560","63.0350","8.3560","5.5707","15.0083"
"33.6000","8.3771","63.1918","8.3771","5.5847","15.0457"
"33.6800","8.3983","63.3522","8.3983","5.5989","15.0839"
"33.7600","8.4175","63.4860","8.4175","5.6117","15.1157"
"33.8400","8.4374","63.6365","8.4374","5.6249","15.1515"
"33.9200","8.4566","63.7501","8.4566","5.6377","15.1786"
"34.0000","8.4767","63.8973","8.4767","5.6511","15.2136"
"34.0800","8.4976","64.0565","8.4976","5.6651","15.2515"
"34.1600","8.5166","64.1919","8.5166","5.6778","15.2838"
"34.2400","8.5379","64.3451","8.5379","5.6919","15.3203"
"34.3200","8.5579","64.4907","8.5579","5.7053","15.3549"
"34.4000","8.5779","64.6326","8.5779","5.7186","15.3887"
"34.4800","8.5977","64.7771","8.5977","5.7318","15.4231"
"34.5600","8.6171","64.9091","8.6171","5.7447","15.4546"
"34.6400","8.6371","65.0424","8.6371","5.7581","15.4863"
"34.7200","8.6575","65.1855","8.6575","5.7717","15.5204"
"34.8000","8.6763","65.3182","8.6763","5.7842","15.5520"
"34.8800","8.6975","65.4719","8.6975","5.7984","15.5885"
"34.9600","8.7176","65.6081","8.7176","5.8117","15.6210"
"35.0400","8.7377","65.7440","8.7377","5.8252","15.6533"
"35.1200","8.7573","65.8739","8.7573","5.8382","15.6843"
"35.2000","8.7766","66.0141","8.7766","5.8510","15.7176"
"35.2800","8.7974","66.1574","8.7974","5.8649","15.7518"
"35.3600","8.8174","66.2961","8.8174","5.8783","15.7848"
"35.4400","8.8369","66.4228","8.8369","5.8913","15.8150"
"35.5200","8.8577","66.5773","8.8577","5.9051","15.8517"
"35.6000","8.8773","66.6993","8.8773","5.9182","15.8808"
"35.6800","8.8980","66.8409","8.8980","5.9320","15.9145"
"35.7600","8.9180","66.9666","8.9180","5.9453","15.9444"
"35.8400","8.9367","67.0978","8.9367","5.9578","15.9757"
"35.9200","8.9568","67.2382","8.9568","5.9712","16.0091"
"36.0000","8.9763","67.3588","8.9763","5.9842","16.0378"
"36.0800","8.9975","67.5076","8.9975","5.9983","16.0732"
"36.1600","9.0180","67.6310","9.0180","6.0120","16.1026"
"36.2400","9.0372","67.7520","9.0372","6.0248","16.1314"
"36.3200","9.0573","67.8833","9.0573","6.0382","16.1627"
"36.4000","9.0771","67.9996","9.0771","6.0514","16.1904"
"36.4800","9.0965","68.1283","9.0965","6.0643","16.2210"
"36.5600","9.1178","68.2830","9.1178","6.0785","16.2579"
"36.6400","9.1364","68.3860","9.1364","6.0910","16.2824"
"36.7200","9.1578","68.5330","9.1578","6.1052","16.3174"
"36.8000","9.1783","68.6699","9.1783","6.1189","16.3500"
"36.8800","9.1979","68.7909","9.1979","6.1319","16.3788"
"36.9600","9.2176","68.9187","9.2176","6.1451","16.4092"
"37.0400","9.2372","69.0279","9.2372","6.1582","16.4352"
"37.1200","9.2569","69.1645","9.2569","6.1712","16.4677"
"37.2000","9.2774","69.2861","9.2774","6.1850","16.4967"
"37.2800","9.2960","69.4030","9.2960","6.1973","16.5245"
"37.3600","9.3178","69.5486","9.3178","6.2119","16.5592"
"37.4400","9.3381","69.6726","9.3381","6.2254","16.5887"
"37.5200","9.3573","69.7884","9.3573","6.2382","16.6163"
"37.6000","9.3773","69.9143","9.3773","6.2515","16.6463"
"37.6800","9.3968","70.0351","9.3968","6.2645","16.6750"
"37.7600","9.4175","70.1418","9.4175","6.2783","16.7004"
"37.8400","9.4373","70.2684","9.4373","6.2915","16.7306"
"37.9200","9.4565","70.3823","9.4565","6.3043","16.7577"
"38.0000","9.4775","70.5275","9.4775","6.3183","16.7923"
"38.0800","9.4979","70.6446","9.4979","6.3319","16.8201"
"38.1600","9.5181","70.7605","9.5181","6.3454","16.8477"
"38.2400","9.5379","70.8745","9.5379","6.3586","16.8749"
"38.3200","9.5561","70.9711","9.5561","6.3707","16.8979"
"38.4000","9.5772","71.1007","9.5772","6.3848","16.9287"
"38.4800","9.5968","71.2128","9.5968","6.3979","16.9554"
"38.5600","9.6169","71.3442","9.6169","6.4113","16.9867"
"38.6400","9.6374","71.4614","9.6374","6.4250","17.0146"
"38.7200","9.6577","71.5753","9.6577","6.4384","17.0417"
"38.8000","9.6773","71.6758","9.6773","6.4515","17.0657"
"38.8800","9.6980","71.8031","9.6980","6.4654","17.0960"
"38.9600","9.7168","71.9085","9.7168","6.4778","17.1211"
"39.0400","9.7373","72.0321","9.7373","6.4915","17.1505"
"39.1200","9.7567","72.1379","9.7567","6.5045","17.1757"
"39.2000","9.7770","72.2613","9.7770","6.5180","17.2051"
"39.2800","9.7986","72.3844","9.7986","6.5324","17.2344"
"39.3600","9.8179","72.4928","9.8179","6.5453","17.2602"
"39.4400","9.8378","72.6009","9.8378","6.5586","17.2859"
"39.5200","9.8573","72.7042","9.8573","6.5716","17.3105"
"39.6000","9.8767","72.8205","9.8767","6.5845","17.3382"
"39.6800","9.8974","72.9444","9.8974","6.5982","17.3677"
"39.7600","9.9165","73.0376","9.9165","6.6110","17.3899"
"39.8400","9.9368","73.1552","9.9368","6.6245","17.4179"
"39.9200","9.9582","73.2804","9.9582","6.6388","17.4477"
"40.0000","9.9772","73.3812","9.9772","6.6514","17.4717"
"40.0800","9.9977","73.4998","9.9977","6.6651","17.5000"
"40.1600","10.0167","73.5937","10.0167","6.6778","17.5223"
"40.2400","10.0372","73.7106","10.0372","6.6915","17.5501"
"40.3200","10.0565","73.8087","10.0565","6.7043","17.5735"
"40.4000","10.0763","73.9177","10.0763","6.7175","17.5994"
"40.4800","10.0979","74.0445","10.0979","6.7320","17.6296"
"40.5600","10.1189","74.1664","10.1189","6.7460","17.6587"
"40.6400","10.1372","74.2465","10.1372","6.7581","17.6777"
"40.7200","10.1574","74.3615","10.1574","6.7716","17.7051"
"40.8000","10.1768","74.4478","10.1768","6.7845","17.7257"
"40.8800","10.1979","74.5734","10.1979","6.7986","17.7556"
"40.9600","10.2180","74.6680","10.2180","6.8120","17.7781"
"41.0400","10.2362","74.7483","10.2362","6.8241","17.7972"
"41.1200","10.2569","74.8650","10.2569","6.8379","17.8250"
"41.2000","10.2778","74.9820","10.2778","6.8518","17.8529"
"41.2800","10.2979","75.0761","10.2979","6.8653","17.8753"
"41.3600","10.3183","75.2010","10.3183","6.8788","17.9050"
"41.4400","10.3366","75.2806","10.3366","6.8911","17.9239"
"41.5200","10.3567","75.3776","10.3567","6.9045","17.9471"
"41.6000","10.3772","75.4778","10.3772","6.9181","17.9709"
"41.6800","10.3971","75.5816","10.3971","6.9314","17.9956"
"41.7600","10.4184","75.7076","10.4184","6.9456","18.0256"
"41.8400","10.4377","75.8006","10.4377","6.9585","18.0478"
"41.9200","10.4580","75.8960","10.4580","6.9720","18.0705"
"42.0000","10.4775","75.9957","10.4775","6.9850","18.0942"
"42.0800","10.4969","76.0908","10.4969","6.9979","18.1169"
"42.1600","10.5169","76.1895","10.5169","7.0112","18.1404"
"42.2400","10.5369","76.2785","10.5369","7.0246","18.1616"
"42.3200","10.5565","76.3810","10.5565","7.0377","18.1859"
"42.4000","10.5780","76.5014","10.5780","7.0520","18.2146"
"42.4800","10.5972","76.5850","10.5972","7.0648","18.2345"
"42.5600","10.6180","76.6866","10.6180","7.0787","18.2587"
"42.6400","10.6366","76.7598","10.6366","7.0911","18.2761"
"42.7200","10.6564","76.8676","10.6564","7.1043","18.3018"
"42.8000","10.6770","76.9689","10.6770","7.1180","18.3259"
"42.8800","10.6971","77.0624","10.6971","7.1314","18.3482"
"42.9600","10.7177","77.1702","10.7177","7.1451","18.3739"
"43.0400","10.7387","77.2579","10.7387","7.1591","18.3947"
"43.1200","10.7570","77.3414","10.7570","7.1714","18.4146"
"43.2000","10.7776","77.4323","10.7776","7.1851","18.4363"
"43.2800","10.7975","77.5252","10.7975","7.1984","18.4584"
"43.3600","10.8174","77.6144","10.8174","7.2116","18.4796"
"43.4400","10.8373","77.7018","10.8373","7.2249","18.5004"
"43.5200","10.8560","77.7677","10.8560","7.2373","18.5161"
"43.6000","10.8771","77.8761","10.8771","7.2514","18.5419"
"43.6800","10.8981","77.9745","10.8981","7.2654","18.5654"
"43.7600","10.9176","78.0567","10.9176","7.2784","18.5849"
"43.8400","10.9374","78.1441","10.9374","7.2916","18.6057"
"43.9200","10.9571","78.2337","10.9571","7.3047","18.6271"
"44.0000","10.9767","78.3231","10.9767","7.3178","18.6483"
"44.0800","10.9974","78.4155","10.9974","7.3316","18.6704"
"44.1600","11.0165","78.4988","11.0165","7.3444","18.6902"
"44.2400","11.0381","78.6006","11.0381","7.3588","18.7144"
"44.3200","11.0579","78.6953","11.0579","7.3719","18.7370"
"44.4000","11.0781","78.7843","11.0781","7.3854","18.7582"
"44.4800","11.0974","78.8637","11.0974","7.3983","18.7771"
"44.5600","11.1171","78.9481","11.1171","7.4114","18.7972"
"44.6400","11.1372","79.0382","11.1372","7.4248","18.8186"
"44.7200","11.1575","79.1297","11.1575","7.4384","18.8404"
"44.8000","11.1761","79.2122","11.1761","7.4507","18.8601"
"44.8800","11.1976","79.3221","11.1976","7.4651","18.8862"
"44.9600","11.2175","79.4088","11.2175","7.4783","18.9069"
"45.0400","11.2378","79.4972","11.2378","7.4919","18.9279"
"45.1200","11.2573","79.5763","11.2573","7.5048","18.9467"
"45.2000","11.2764","79.6547","11.2764","7.5176","18.9654"
"45.2800","11.2969","79.7497","11.2969","7.5313","18.9880"
"45.3600","11.3176","79.8490","11.3176","7.5451","19.0117"
"45.4400","11.3374","79.9362","11.3374","7.5582","19.0324"
"45.5200","11.3579","80.0392","11.3579","7.5719","19.0570"
"45.6000","11.3775","80.1192","11.3775","7.5850","19.0760"
"45.6800","11.3981","80.2139","11.3981","7.5988","19.0985"
"45.7600","11.4182","80.3002","11.4182","7.6122","19.1191"
"45.8400","11.4366","80.3766","11.4366","7.6244","19.1373"
"45.9200","11.4569","80.4705","11.4569","7.6379","19.1596"
"46.0000","11.4760","80.5434","11.4760","7.6507","19.1770"
"46.0800","11.4976","80.6486","11.4976","7.6651","19.2021"
"46.1600","11.5182","80.7440","11.5182","7.6788","19.2248"
"46.2400","11.5376","80.8283","11.5376","7.6917","19.2448"
"46.3200","11.5574","80.9110","11.5574","7.7049","19.2645"
"46.4000","11.5773","81.0014","11.5773","7.7182","19.2861"
"46.4800","11.5963","81.0781","11.5963","7.7309","19.3043"
"46.5600","11.6176","81.1810","11.6176","7.7451","19.3288"
"46.6400","11.6367","81.2522","11.6367","7.7578","19.3458"
"46.7200","11.6576","81.3579","11.6576","7.7717","19.3709"
"46.8000","11.6784","81.4401","11.6784","7.7856","19.3905"
"46.8800","11.6980","81.5226","11.6980","7.7986","19.4101"
"46.9600","11.7175","81.6100","11.7175","7.8116","19.4310"
"47.0400","11.7372","81.6855","11.7372","7.8248","19.4489"
"47.1200","11.7569","81.7628","11.7569","7.8379","19.4673"
"47.2000","11.7772","81.8529","11.7772","7.8515","19.4888"
"47.2800","11.7963","81.9302","11.7963","7.8642","19.5072"
"47.3600","11.8175","82.0386","11.8175","7.8783","19.5330"
"47.4400","11.8378","82.1237","11.8378","7.8919","19.5533"
"47.5200","11.8572","82.2006","11.8572","7.9048","19.5716"
"47.6000","11.8776","82.2954","11.8776","7.9184","19.5941"
"47.6800","11.8968","82.3538","11.8968","7.9312","19.6080"
"47.7600","11.9171","82.4277","11.9171","7.9447","19.6256"
"47.8400","11.9369","82.5122","11.9369","7.9580","19.6458"
"47.9200","11.9566","82.6009","11.9566","7.9711","19.6669"
"48.0000","11.9779","82.7071","11.9779","7.9852","19.6922"
"48.0800","11.9987","82.7970","11.9987","7.9991","19.7136"
"48.1600","12.0182","82.8680","12.0182","8.0121","19.7305"
"48.2400","12.0379","82.9483","12.0379","8.0253","19.7496"
"48.3200","12.0559","83.0066","12.0559","8.0373","19.7635"
"48.4000","12.0771","83.1036","12.0771","8.0514","19.7866"
"48.4800","12.0971","83.1930","12.0971","8.0647","19.8079"
"48.5600","12.1171","83.2835","12.1171","8.0781","19.8294"
"48.6400","12.1374","83.3731","12.1374","8.0916","19.8507"
"48.7200","12.1575","83.4556","12.1575","8.1050","19.8704"
"48.8000","12.1776","83.5344","12.1776","8.1184","19.8891"
"48.8800","12.1981","83.6111","12.1981","8.1321","19.9074"
"48.9600","12.2165","83.6750","12.2165","8.1443","19.9226"
"49.0400","12.2370","83.7694","12.2370","8.1580","19.9451"
"49.1200","12.2567","83.8374","12.2567","8.1711","19.9613"
"49.2000","12.2776","83.9369","12.2776","8.1850","19.9850"
"49.2800","12.2987","84.0288","12.2987","8.1991","20.0069"
"49.3600","12.3179","84.1066","12.3179","8.2119","20.0254"
"49.4400","12.3379","84.1735","12.3379","8.2253","20.0413"
"49.5200","12.3573","84.2491","12.3573","8.2382","20.0593"
"49.6000","12.3768","84.3346","12.3768","8.2512","20.0797"
"49.6800","12.3973","84.4118","12.3973","8.2649","20.0980"
"49.7600","12.4165","84.4767","12.4165","8.2777","20.1135"
"49.8400","12.4365","84.5525","12.4365","8.2910","20.1316"
"49.9200","12.4580","84.6453","12.4580","8.3053","20.1536"
"50.0000","12.4773","84.7277","12.4773","8.3182","20.1733"
"50.0800","12.4978","84.8137","12.4978","8.3319","20.1937"
"50.1600","12.5168","84.8659","12.5168","8.3445","20.2062"
"50.2400","12.5372","84.9449","12.5372","8.3581","20.2250"
"50.3200","12.5570","85.0206","12.5570","8.3713","20.2430"
"50.4000","12.5767","85.0906","12.5767","8.3844","20.2597"
"50.4800","12.5978","85.1858","12.5978","8.3985","20.2823"
"50.5600","12.6188","85.2679","12.6188","8.4125","20.3019"
"50.6400","12.6376","85.3305","12.6376","8.4250","20.3168"
"50.7200","12.6575","85.4101","12.6575","8.4383","20.3357"
"50.8000","12.6764","85.4737","12.6764","8.4509","20.3509"
"50.8800","12.6977","85.5644","12.6977","8.4652","20.3725"
"50.9600","12.7173","85.6374","12.7173","8.4782","20.3898"
"51.0400","12.7362","85.7016","12.7362","8.4908","20.4051"
"51.1200","12.7571","85.8006","12.7571","8.5048","20.4287"
"51.2000","12.7781","85.8993","12.7781","8.5187","20.4522"
"51.2800","12.7982","85.9682","12.7982","8.5321","20.4686"
"51.3600","12.8176","86.0343","12.8176","8.5451","20.4843"
"51.4400","12.8364","86.1002","12.8364","8.5576","20.5000"
"51.5200","12.8572","86.1931","12.8572","8.5714","20.5222"
"51.6000","12.8774","86.2673","12.8774","8.5849","20.5398"
"51.6800","12.8969","86.3508","12.8969","8.5979","20.5597"
"51.7600","12.9180","86.4469","12.9180","8.6120","20.5826"
"51.8400","12.9379","86.5197","12.9379","8.6253","20.5999"
"51.9200","12.9580","86.5889","12.9580","8.6386","20.6164"
"52.0000","12.9776","86.6693","12.9776","8.6517","20.6355"
"52.0800","12.9971","86.7606","12.9971","8.6647","20.6573"
"52.1600","13.0174","86.8400","13.0174","8.6782","20.6762"
"52.2400","13.0369","86.9123","13.0369","8.6912","20.6934"
"52.3200","13.0562","86.9847","13.0562","8.7041","20.7107"
"52.4000","13.0778","87.0884","13.0778","8.7185","20.7353"
"52.4800","13.0978","87.1613","13.0978","8.7318","20.7527"
"52.5600","13.1181","87.2481","13.1181","8.7454","20.7734"
"52.6400","13.1375","87.3101","13.1375","8.7583","20.7881"
"52.7200","13.1565","87.3893","13.1565","8.7710","20.8070"
"52.8000","13.1768","87.4715","13.1768","8.7846","20.8265"
"52.8800","13.1970","87.5455","13.1970","8.7980","20.8442"
"52.9600","13.2176","87.6346","13.2176","8.8117","20.8654"
"53.0400","13.2386","87.7297","13.2386","8.8257","20.8880"
"53.1200","13.2573","87.7941","13.2573","8.8382","20.9033"
"53.2000","13.2775","87.8720","13.2775","8.8517","20.9219"
"53.2800","13.2974","87.9519","13.2974","8.8649","20.9409"
"53.3600","13.3176","88.0440","13.3176","8.8784","20.9629"
"53.4400","13.3378","88.1265","13.3378","8.8919","20.9825"
"53.5200","13.3557","88.1719","13.3557","8.9038","20.9933"
"53.6000","13.3769","88.2628","13.3769","8.9180","21.0150"
"53.6800","13.3979","88.3518","13.3979","8.9319","21.0361"
"53.7600","13.4175","88.4358","13.4175","8.9450","21.0561"
"53.8400","13.4378","88.5187","13.4378","8.9585","21.0759"
"53.9200","13.4568","88.5796","13.4568","8.9712","21.0904"
"54.0000","13.4768","88.6549","13.4768","8.9845","21.1083"
"54.0800","13.4974","88.7366","13.4974","8.9983","21.1278"
"54.1600","13.5166","88.8136","13.5166","9.0111","21.1461"
"54.2400","13.5378","88.8969","13.5378","9.0252","21.1659"
"54.3200","13.5579","88.9798","13.5579","9.0386","21.1857"
"54.4000","13.5779","89.0499","13.5779","9.0519","21.2024"
"54.4800","13.5976","89.1396","13.5976","9.0651","21.2237"
"54.5600","13.6173","89.2152","13.6173","9.0782","21.2417"
"54.6400","13.6373","89.2937","13.6373","9.0915","21.2604"
"54.7200","13.6573","89.3626","13.6573","9.1049","21.2768"
"54.8000","13.6759","89.4300","13.6759","9.1173","21.2929"
"54.8800","13.6973","89.5258","13.6973","9.1315","21.3157"
"54.9600","13.7174","89.5995","13.7174","9.1449","21.3332"
"55.0400","13.7378","89.6694","13.7378","9.1585","21.3499"
"55.1200","13.7575","89.7432","13.7575","9.1717","21.3674"
"55.2000","13.7763","89.8191","13.7763","9.1842","21.3855"
"55.2800","13.7972","89.9069","13.7972","9.1981","21.4064"
"55.3600","13.8173","89.9856","13.8173","9.2115","21.4251"
"55.4400","13.8367","90.0607","13.8367","9.2245","21.4430"
"55.5200","13.8582","90.1518","13.8582","9.2388","21.4647"
"55.6000","13.8779","90.2182","13.8779","9.2519","21.4805"
"55.6800","13.8978","90.2907","13.8978","9.2652","21.4978"
"55.7600","13.9178","90.3661","13.9178","9.2785","21.5157"
"55.8400","13.9364","90.4267","13.9364","9.2909","21.5302"
"55.9200","13.9569","90.5187","13.9569","9.3046","21.5521"
"56.0000","13.9765","90.5923","13.9765","9.3176","21.5696"
"56.0800","13.9973","90.6813","13.9973","9.3315","21.5908"
"56.1600","14.0181","90.7699","14.0181","9.3454","21.6119"
"56.2400","14.0373","90.8336","14.0373","9.3582","21.6271"
"56.3200","14.0574","90.9130","14.0574","9.3716","21.6459"
"56.4000","14.0774","90.9813","14.0774","9.3849","21.6622"
"56.4800","14.0967","91.0570","14.0967","9.3978","21.6802"
"56.5600","14.1174","91.1420","14.1174","9.4116","21.7005"
"56.6400","14.1364","91.2055","14.1364","9.4243","21.7156"
"56.7200","14.1576","91.2950","14.1576","9.4384","21.7369"
"56.8000","14.1783","91.3858","14.1783","9.4522","21.7585"
"56.8800","14.1980","91.4599","14.1980","9.4653","21.7762"
"56.9600","14.2176","91.5361","14.2176","9.4784","21.7943"
"57.0400","14.2372","91.6095","14.2372","9.4915","21.8118"
"57.1200","14.2570","91.6764","14.2570","9.5047","21.8277"
"57.2000","14.2769","91.7562","14.2769","9.5180","21.8467"
"57.2800","14.2959","91.8209","14.2959","9.5306","21.8621"
"57.3600","14.3175","91.9160","14.3175","9.5450","21.8848"
"57.4400","14.3379","92.0036","14.3379","9.5586","21.9056"
"57.5200","14.3573","92.0734","14.3573","9.5715","21.9222"
"57.6000","14.3775","92.1674","14.3775","9.5850","21.9446"
"57.6800","14.3966","92.2200","14.3966","9.5977","21.9571"
"57.7600","14.4175","92.3105","14.4175","9.6117","21.9787"
"57.8400","14.4376","92.3876","14.4376","9.6251","21.9970"
"57.9200","14.4564","92.4517","14.4564","9.6376","22.0123"
"58.0000","14.4777","92.5607","14.4777","9.6518","22.0383"
"58.0800","14.4982","92.6290","14.4982","9.6655","22.0545"
"58.1600","14.5179","92.6934","14.5179","9.6786","22.0699"
"58.2400","14.5375","92.7691","14.5375","9.6917","22.0879"
"58.3200","14.5564","92.8328","14.5564","9.7042","22.1030"
"58.4000","14.5775","92.9272","14.5775","9.7183","22.1255"
"58.4800","14.5973","92.9951","14.5973","9.7315","22.1417"
"58.5600","14.6166","93.0780","14.6166","9.7444","22.1614"
"58.6400","14.6375","93.1686","14.6375","9.7583","22.1830"
"58.7200","14.6569","93.2211","14.6569","9.7713","22.1955"
"58.8000","14.6774","93.3072","14.6774","9.7849","22.2160"
"58.8800","14.6980","93.3799","14.6980","9.7987","22.2333"
"58.9600","14.7168","93.4510","14.7168","9.8112","22.2502"
"59.0400","14.7371","93.5353","14.7371","9.8247","22.2703"
"59.1200","14.7565","93.6102","14.7565","9.8377","22.2882"
"59.2000","14.7776","93.6952","14.7776","9.8517","22.3084"
"59.2800","14.7986","93.7808","14.7986","9.8658","22.3288"
"59.3600","14.8176","93.8388","14.8176","9.8784","22.3426"
"59.4400","14.8377","93.9073","14.8377","9.8918","22.3589"
"59.5200","14.8574","93.9769","14.8574","9.9049","22.3755"
"59.6000","14.8767","94.0518","14.8767","9.9178","22.3933"
"59.6800","14.8975","94.1455","14.8975","9.9317","22.4156"
"59.7600","14.9162","94.1902","14.9162","9.9441","22.4262"
"59.8400","14.9366","94.2764","14.9366","9.9577","22.4468"
"59.9200","14.9579","94.3544","14.9579","9.9719","22.4653"
"60.0000","14.9774","94.4244","14.9774","9.9849","22.4820"
"60.0800","14.9983","94.5139","14.9983","9.9989","22.5033"
"60.0870","15.0000","94.5194","15.0000","10.0000","22.5046"