File: data/instron_tests/metamaterials/250416/250416_50-50_Composite.is_comp_Exports/250416_50-50_Composite_6_1.csv
Results Table 1
,Compresson Axis,H*,V*,Height,Thickness,Width,Area,Fixture separation,Specimen label
,,,,(mm),(mm),(mm),(mm^2),(mm),
"6","X","","","150.00","28.00","150.00","4200.00","150.00","50/50 Composite"

Results Table 2
,Modulus (Segment 0 % - 2.5 %),Compresson Axis
,(kPa),
"6","345.93","X"

Time,Displacement,Force,Compressive displacement,Compressive strain (Displacement),Compressive stress
(s),(mm),(N),(mm),(%),(kPa)
"0.0000","0.0000","-14.8719","0.0000","0.0000","-3.5409"
"0.0800","0.0011","-14.8258","0.0011","0.0007","-3.5299"
"0.1600","0.0170","-14.5832","0.0170","0.0113","-3.4722"
"0.2400","0.0371","-14.3059","0.0371","0.0247","-3.4062"
"0.3200","0.0570","-14.0426","0.0570","0.0380","-3.3435"
"0.4000","0.0764","-13.7978","0.0764","0.0509","-3.2852"
"0.4800","0.0980","-13.5223","0.0980","0.0653","-3.2196"
"0.5600","0.1177","-13.2787","0.1177","0.0784","-3.1616"
"0.6400","0.1371","-13.0474","0.1371","0.0914","-3.1065"
"0.7200","0.1569","-12.7956","0.1569","0.1046","-3.0466"
"0.8000","0.1767","-12.5638","0.1767","0.1178","-2.9914"
"0.8800","0.1973","-12.3342","0.1973","0.1315","-2.9367"
"0.9600","0.2172","-12.1147","0.2172","0.1448","-2.8845"
"1.0400","0.2355","-11.8939","0.2355","0.1570","-2.8319"
"1.1200","0.2568","-11.6566","0.2568","0.1712","-2.7754"
"1.2000","0.2771","-11.4308","0.2771","0.1847","-2.7216"
"1.2800","0.2976","-11.2045","0.2976","0.1984","-2.6677"
"1.3600","0.3176","-10.9996","0.3176","0.2118","-2.6190"
"1.4400","0.3359","-10.8140","0.3359","0.2240","-2.5748"
"1.5200","0.3562","-10.5989","0.3562","0.2375","-2.5235"
"1.6000","0.3770","-10.3907","0.3770","0.2513","-2.4740"
"1.6800","0.3964","-10.1792","0.3964","0.2643","-2.4236"
"1.7600","0.4176","-9.9649","0.4176","0.2784","-2.3726"
"1.8400","0.4375","-9.7772","0.4375","0.2917","-2.3279"
"1.9200","0.4573","-9.5753","0.4573","0.3049","-2.2798"
"2.0000","0.4771","-9.4002","0.4771","0.3181","-2.2381"
"2.0800","0.4961","-9.1999","0.4961","0.3307","-2.1904"
"2.1600","0.5167","-8.9907","0.5167","0.3444","-2.1406"
"2.2400","0.5365","-8.7958","0.5365","0.3577","-2.0942"
"2.3200","0.5561","-8.6035","0.5561","0.3707","-2.0484"
"2.4000","0.5766","-8.3955","0.5766","0.3844","-1.9989"
"2.4800","0.5971","-8.1889","0.5971","0.3981","-1.9497"
"2.5600","0.6178","-7.9772","0.6178","0.4119","-1.8993"
"2.6400","0.6370","-7.7917","0.6370","0.4247","-1.8552"
"2.7200","0.6558","-7.5969","0.6558","0.4372","-1.8088"
"2.8000","0.6765","-7.3859","0.6765","0.4510","-1.7585"
"2.8800","0.6965","-7.1830","0.6965","0.4643","-1.7102"
"2.9600","0.7174","-6.9728","0.7174","0.4783","-1.6602"
"3.0400","0.7380","-6.7754","0.7380","0.4920","-1.6132"
"3.1200","0.7566","-6.5769","0.7566","0.5044","-1.5659"
"3.2000","0.7771","-6.3685","0.7771","0.5181","-1.5163"
"3.2800","0.7972","-6.1837","0.7972","0.5315","-1.4723"
"3.3600","0.8167","-5.9844","0.8167","0.5445","-1.4249"
"3.4400","0.8367","-5.7900","0.8367","0.5578","-1.3786"
"3.5200","0.8556","-5.6056","0.8556","0.5704","-1.3347"
"3.6000","0.8768","-5.3999","0.8768","0.5846","-1.2857"
"3.6800","0.8977","-5.1913","0.8977","0.5985","-1.2360"
"3.7600","0.9169","-4.9979","0.9169","0.6113","-1.1900"
"3.8400","0.9370","-4.8007","0.9370","0.6246","-1.1430"
"3.9200","0.9562","-4.6269","0.9562","0.6374","-1.1017"
"4.0000","0.9759","-4.4321","0.9759","0.6506","-1.0553"
"4.0800","0.9971","-4.2255","0.9971","0.6648","-1.0061"
"4.1600","1.0165","-4.0321","1.0165","0.6777","-0.9600"
"4.2400","1.0374","-3.8271","1.0374","0.6916","-0.9112"
"4.3200","1.0576","-3.6340","1.0576","0.7050","-0.8652"
"4.4000","1.0772","-3.4407","1.0772","0.7181","-0.8192"
"4.4800","1.0973","-3.2519","1.0973","0.7315","-0.7743"
"4.5600","1.1164","-3.0663","1.1164","0.7443","-0.7301"
"4.6400","1.1363","-2.8925","1.1363","0.7575","-0.6887"
"4.7200","1.1566","-2.6896","1.1566","0.7711","-0.6404"
"4.8000","1.1760","-2.4936","1.1760","0.7840","-0.5937"
"4.8800","1.1970","-2.2904","1.1970","0.7980","-0.5453"
"4.9600","1.2174","-2.0984","1.2174","0.8116","-0.4996"
"5.0400","1.2373","-1.9167","1.2373","0.8249","-0.4563"
"5.1200","1.2570","-1.7243","1.2570","0.8380","-0.4105"
"5.2000","1.2757","-1.5444","1.2757","0.8504","-0.3677"
"5.2800","1.2970","-1.3371","1.2970","0.8647","-0.3183"
"5.3600","1.3169","-1.1387","1.3169","0.8780","-0.2711"
"5.4400","1.3366","-0.9544","1.3366","0.8910","-0.2272"
"5.5200","1.3576","-0.7501","1.3576","0.9050","-0.1786"
"5.6000","1.3774","-0.5752","1.3774","0.9183","-0.1370"
"5.6800","1.3977","-0.3768","1.3977","0.9318","-0.0897"
"5.7600","1.4176","-0.1878","1.4176","0.9450","-0.0447"
"5.8400","1.4364","0.0020","1.4364","0.9576","0.0005"
"5.9200","1.4567","0.2015","1.4567","0.9712","0.0480"
"6.0000","1.4760","0.3823","1.4760","0.9840","0.0910"
"6.0800","1.4968","0.5863","1.4968","0.9979","0.1396"
"6.1600","1.5169","0.7904","1.5169","1.0112","0.1882"
"6.2400","1.5373","0.9838","1.5373","1.0249","0.2342"
"6.3200","1.5572","1.1688","1.5572","1.0381","0.2783"
"6.4000","1.5769","1.3623","1.5769","1.0513","0.3244"
"6.4800","1.5959","1.5397","1.5959","1.0640","0.3666"
"6.5600","1.6170","1.7464","1.6170","1.0780","0.4158"
"6.6400","1.6361","1.9199","1.6361","1.0907","0.4571"
"6.7200","1.6572","2.1256","1.6572","1.1048","0.5061"
"6.8000","1.6777","2.3192","1.6777","1.1185","0.5522"
"6.8800","1.6975","2.5128","1.6975","1.1316","0.5983"
"6.9600","1.7167","2.6847","1.7167","1.1445","0.6392"
"7.0400","1.7368","2.8565","1.7368","1.1579","0.6801"
"7.1200","1.7566","3.0428","1.7566","1.1711","0.7245"
"7.2000","1.7767","3.2338","1.7767","1.1845","0.7699"
"7.2800","1.7960","3.4256","1.7960","1.1973","0.8156"
"7.3600","1.8170","3.6365","1.8170","1.2114","0.8658"
"7.4400","1.8374","3.8189","1.8374","1.2249","0.9093"
"7.5200","1.8566","4.0105","1.8566","1.2377","0.9549"
"7.6000","1.8771","4.2106","1.8771","1.2514","1.0025"
"7.6800","1.8964","4.3839","1.8964","1.2643","1.0438"
"7.7600","1.9169","4.5806","1.9169","1.2779","1.0906"
"7.8400","1.9365","4.7690","1.9365","1.2910","1.1355"
"7.9200","1.9560","4.9754","1.9560","1.3040","1.1846"
"8.0000","1.9772","5.1887","1.9772","1.3181","1.2354"
"8.0800","1.9979","5.3896","1.9979","1.3320","1.2832"
"8.1600","2.0176","5.5772","2.0176","1.3451","1.3279"
"8.2400","2.0373","5.7756","2.0373","1.3582","1.3751"
"8.3200","2.0560","5.9501","2.0560","1.3707","1.4167"
"8.4000","2.0768","6.1566","2.0768","1.3845","1.4659"
"8.4800","2.0966","6.3530","2.0966","1.3977","1.5126"
"8.5600","2.1163","6.5541","2.1163","1.4108","1.5605"
"8.6400","2.1370","6.7631","2.1370","1.4247","1.6103"
"8.7200","2.1572","6.9561","2.1572","1.4382","1.6562"
"8.8000","2.1771","7.1474","2.1771","1.4514","1.7018"
"8.8800","2.1974","7.3477","2.1974","1.4649","1.7494"
"8.9600","2.2162","7.5362","2.2162","1.4775","1.7943"
"9.0400","2.2368","7.7406","2.2368","1.4912","1.8430"
"9.1200","2.2563","7.9274","2.2563","1.5042","1.8875"
"9.2000","2.2768","8.1233","2.2768","1.5178","1.9341"
"9.2800","2.2980","8.3237","2.2980","1.5320","1.9818"
"9.3600","2.3170","8.5045","2.3170","1.5447","2.0249"
"9.4400","2.3374","8.6872","2.3374","1.5582","2.0684"
"9.5200","2.3570","8.8777","2.3570","1.5713","2.1137"
"9.6000","2.3766","9.0851","2.3766","1.5844","2.1631"
"9.6800","2.3972","9.2770","2.3972","1.5981","2.2088"
"9.7600","2.4158","9.4573","2.4158","1.6106","2.2517"
"9.8400","2.4361","9.6523","2.4361","1.6241","2.2982"
"9.9200","2.4576","9.8612","2.4576","1.6384","2.3479"
"10.0000","2.4769","10.0459","2.4769","1.6513","2.3919"
"10.0800","2.4974","10.2336","2.4974","1.6650","2.4366"
"10.1600","2.5166","10.4199","2.5166","1.6778","2.4809"
"10.2400","2.5364","10.6125","2.5364","1.6909","2.5268"
"10.3200","2.5563","10.8017","2.5563","1.7042","2.5718"
"10.4000","2.5762","10.9987","2.5762","1.7175","2.6187"
"10.4800","2.5971","11.1916","2.5971","1.7314","2.6647"
"10.5600","2.6185","11.4140","2.6185","1.7457","2.7176"
"10.6400","2.6372","11.5855","2.6372","1.7582","2.7584"
"10.7200","2.6568","11.7774","2.6568","1.7712","2.8041"
"10.8000","2.6762","11.9561","2.6762","1.7841","2.8467"
"10.8800","2.6974","12.1516","2.6974","1.7983","2.8932"
"10.9600","2.7173","12.3472","2.7173","1.8115","2.9398"
"11.0400","2.7359","12.5230","2.7359","1.8239","2.9817"
"11.1200","2.7564","12.7250","2.7564","1.8376","3.0298"
"11.2000","2.7773","12.9283","2.7773","1.8515","3.0782"
"11.2800","2.7973","13.1122","2.7973","1.8649","3.1220"
"11.3600","2.8176","13.3094","2.8176","1.8784","3.1689"
"11.4400","2.8360","13.4701","2.8360","1.8906","3.2072"
"11.5200","2.8563","13.6623","2.8563","1.9042","3.2529"
"11.6000","2.8770","13.8613","2.8770","1.9180","3.3003"
"11.6800","2.8966","14.0504","2.8966","1.9311","3.3453"
"11.7600","2.9174","14.2605","2.9174","1.9450","3.3954"
"11.8400","2.9372","14.4383","2.9372","1.9581","3.4377"
"11.9200","2.9575","14.6321","2.9575","1.9716","3.4838"
"12.0000","2.9772","14.8140","2.9772","1.9848","3.5272"
"12.0800","2.9968","15.0162","2.9968","1.9979","3.5753"
"12.1600","3.0168","15.2111","3.0168","2.0112","3.6217"
"12.2400","3.0364","15.3926","3.0364","2.0242","3.6649"
"12.3200","3.0559","15.5764","3.0559","2.0373","3.7087"
"12.4000","3.0774","15.7791","3.0774","2.0516","3.7569"
"12.4800","3.0970","15.9633","3.0970","2.0646","3.8008"
"12.5600","3.1176","16.1522","3.1176","2.0784","3.8458"
"12.6400","3.1368","16.3249","3.1368","2.0912","3.8869"
"12.7200","3.1559","16.5045","3.1559","2.1039","3.9297"
"12.8000","3.1760","16.7063","3.1760","2.1174","3.9777"
"12.8800","3.1969","16.9025","3.1969","2.1313","4.0244"
"12.9600","3.2173","17.1001","3.2173","2.1449","4.0714"
"13.0400","3.2382","17.2924","3.2382","2.1588","4.1172"
"13.1200","3.2567","17.4591","3.2567","2.1711","4.1569"
"13.2000","3.2771","17.6572","3.2771","2.1847","4.2041"
"13.2800","3.2969","17.8379","3.2969","2.1980","4.2471"
"13.3600","3.3169","18.0253","3.3169","2.2113","4.2917"
"13.4400","3.3371","18.2219","3.3371","2.2247","4.3386"
"13.5200","3.3555","18.3901","3.3555","2.2370","4.3786"
"13.6000","3.3765","18.5844","3.3765","2.2510","4.4249"
"13.6800","3.3977","18.7878","3.3977","2.2651","4.4733"
"13.7600","3.4175","18.9848","3.4175","2.2783","4.5202"
"13.8400","3.4368","19.1646","3.4368","2.2912","4.5630"
"13.9200","3.4562","19.3321","3.4562","2.3042","4.6029"
"14.0000","3.4762","19.5266","3.4762","2.3175","4.6492"
"14.0800","3.4973","19.7277","3.4973","2.3316","4.6971"
"14.1600","3.5161","19.9111","3.5161","2.3441","4.7407"
"14.2400","3.5374","20.1201","3.5374","2.3583","4.7905"
"14.3200","3.5573","20.3100","3.5573","2.3716","4.8357"
"14.4000","3.5774","20.5044","3.5774","2.3849","4.8820"
"14.4800","3.5972","20.6952","3.5972","2.3981","4.9274"
"14.5600","3.6166","20.8714","3.6166","2.4110","4.9694"
"14.6400","3.6368","21.0592","3.6368","2.4245","5.0141"
"14.7200","3.6566","21.2394","3.6566","2.4377","5.0570"
"14.8000","3.6755","21.4294","3.6755","2.4503","5.1022"
"14.8800","3.6970","21.6455","3.6970","2.4647","5.1537"
"14.9600","3.7172","21.8279","3.7172","2.4782","5.1971"
"15.0400","3.7372","22.0177","3.7372","2.4915","5.2423"
"15.1200","3.7567","22.1972","3.7567","2.5044","5.2851"
"15.2000","3.7754","22.3720","3.7754","2.5169","5.3267"
"15.2800","3.7968","22.5729","3.7968","2.5312","5.3745"
"15.3600","3.8168","22.7604","3.8168","2.5446","5.4192"
"15.4400","3.8365","22.9519","3.8365","2.5576","5.4647"
"15.5200","3.8574","23.1629","3.8574","2.5716","5.5150"
"15.6000","3.8774","23.3431","3.8774","2.5849","5.5579"
"15.6800","3.8974","23.5311","3.8974","2.5983","5.6026"
"15.7600","3.9177","23.7159","3.9177","2.6118","5.6466"
"15.8400","3.9363","23.9031","3.9363","2.6242","5.6912"
"15.9200","3.9566","24.0965","3.9566","2.6378","5.7373"
"16.0000","3.9761","24.2786","3.9761","2.6507","5.7806"
"16.0800","3.9967","24.4725","3.9967","2.6645","5.8268"
"16.1600","4.0176","24.6608","4.0176","2.6784","5.8716"
"16.2400","4.0369","24.8426","4.0369","2.6913","5.9149"
"16.3200","4.0570","25.0289","4.0570","2.7046","5.9593"
"16.4000","4.0770","25.2155","4.0770","2.7180","6.0037"
"16.4800","4.0959","25.3970","4.0959","2.7306","6.0469"
"16.5600","4.1170","25.5940","4.1170","2.7447","6.0938"
"16.6400","4.1362","25.7615","4.1362","2.7574","6.1337"
"16.7200","4.1573","25.9606","4.1573","2.7715","6.1811"
"16.8000","4.1778","26.1405","4.1778","2.7852","6.2239"
"16.8800","4.1972","26.3299","4.1972","2.7982","6.2690"
"16.9600","4.2169","26.5163","4.2169","2.8112","6.3134"
"17.0400","4.2370","26.6921","4.2370","2.8247","6.3553"
"17.1200","4.2567","26.8696","4.2567","2.8378","6.3975"
"17.2000","4.2769","27.0613","4.2769","2.8513","6.4432"
"17.2800","4.2954","27.2290","4.2954","2.8636","6.4831"
"17.3600","4.3170","27.4371","4.3170","2.8780","6.5326"
"17.4400","4.3377","27.6284","4.3377","2.8918","6.5782"
"17.5200","4.3569","27.8105","4.3569","2.9046","6.6215"
"17.6000","4.3768","27.9994","4.3768","2.9179","6.6665"
"17.6800","4.3957","28.1682","4.3957","2.9305","6.7067"
"17.7600","4.4172","28.3698","4.4172","2.9448","6.7547"
"17.8400","4.4371","28.5475","4.4371","2.9580","6.7970"
"17.9200","4.4561","28.7349","4.4561","2.9707","6.8416"
"18.0000","4.4771","28.9418","4.4771","2.9847","6.8909"
"18.0800","4.4979","29.1386","4.4979","2.9986","6.9378"
"18.1600","4.5175","29.3153","4.5175","3.0117","6.9798"
"18.2400","4.5372","29.4959","4.5372","3.0248","7.0228"
"18.3200","4.5556","29.6684","4.5556","3.0371","7.0639"
"18.4000","4.5769","29.8627","4.5769","3.0513","7.1102"
"18.4800","4.5967","30.0556","4.5967","3.0645","7.1561"
"18.5600","4.6163","30.2409","4.6163","3.0775","7.2002"
"18.6400","4.6370","30.4427","4.6370","3.0913","7.2483"
"18.7200","4.6571","30.6228","4.6571","3.1047","7.2911"
"18.8000","4.6770","30.8055","4.6770","3.1180","7.3346"
"18.8800","4.6976","30.9851","4.6976","3.1317","7.3774"
"18.9600","4.7161","31.1630","4.7161","3.1441","7.4198"
"19.0400","4.7363","31.3465","4.7363","3.1575","7.4635"
"19.1200","4.7560","31.5286","4.7560","3.1707","7.5068"
"19.2000","4.7772","31.7249","4.7772","3.1848","7.5536"
"19.2800","4.7983","31.9306","4.7983","3.1989","7.6025"
"19.3600","4.8173","32.1058","4.8173","3.2116","7.6442"
"19.4400","4.8374","32.2800","4.8374","3.2249","7.6857"
"19.5200","4.8570","32.4659","4.8570","3.2380","7.7300"
"19.6000","4.8767","32.6489","4.8767","3.2511","7.7735"
"19.6800","4.8968","32.8329","4.8968","3.2645","7.8173"
"19.7600","4.9162","32.9911","4.9162","3.2774","7.8550"
"19.8400","4.9364","33.1779","4.9364","3.2910","7.8995"
"19.9200","4.9575","33.3690","4.9575","3.3050","7.9450"
"20.0000","4.9769","33.5440","4.9769","3.3179","7.9867"
"20.0800","4.9974","33.7453","4.9974","3.3316","8.0346"
"20.1600","5.0164","33.9103","5.0164","3.3443","8.0739"
"20.2400","5.0362","34.0920","5.0362","3.3575","8.1171"
"20.3200","5.0565","34.2782","5.0565","3.3710","8.1615"
"20.4000","5.0761","34.4550","5.0761","3.3841","8.2036"
"20.4800","5.0974","34.6564","5.0974","3.3983","8.2515"
"20.5600","5.1184","34.8506","5.1184","3.4122","8.2978"
"20.6400","5.1369","35.0109","5.1369","3.4246","8.3359"
"20.7200","5.1561","35.1889","5.1561","3.4374","8.3783"
"20.8000","5.1763","35.3739","5.1763","3.4508","8.4224"
"20.8800","5.1974","35.5630","5.1974","3.4649","8.4674"
"20.9600","5.2171","35.7358","5.2171","3.4781","8.5085"
"21.0400","5.2356","35.9057","5.2356","3.4904","8.5490"
"21.1200","5.2563","36.0986","5.2563","3.5042","8.5949"
"21.2000","5.2772","36.2881","5.2772","3.5181","8.6400"
"21.2800","5.2972","36.4665","5.2972","3.5315","8.6825"
"21.3600","5.3175","36.6584","5.3175","3.5450","8.7282"
"21.4400","5.3360","36.8127","5.3360","3.5573","8.7649"
"21.5200","5.3562","36.9957","5.3562","3.5708","8.8085"
"21.6000","5.3768","37.1916","5.3768","3.5845","8.8552"
"21.6800","5.3967","37.3822","5.3967","3.5978","8.9005"
"21.7600","5.4178","37.5782","5.4178","3.6119","8.9472"
"21.8400","5.4372","37.7357","5.4372","3.6248","8.9847"
"21.9200","5.4572","37.9139","5.4572","3.6382","9.0271"
"22.0000","5.4769","38.0791","5.4769","3.6513","9.0665"
"22.0800","5.4966","38.2659","5.4966","3.6644","9.1109"
"22.1600","5.5172","38.4425","5.5172","3.6781","9.1530"
"22.2400","5.5365","38.6047","5.5365","3.6910","9.1916"
"22.3200","5.5560","38.7873","5.5560","3.7040","9.2351"
"22.4000","5.5777","38.9822","5.5777","3.7185","9.2815"
"22.4800","5.5970","39.1513","5.5970","3.7313","9.3217"
"22.5600","5.6175","39.3272","5.6175","3.7450","9.3636"
"22.6400","5.6368","39.5040","5.6368","3.7579","9.4057"
"22.7200","5.6558","39.6738","5.6558","3.7705","9.4461"
"22.8000","5.6762","39.8545","5.6762","3.7841","9.4892"
"22.8800","5.6968","40.0390","5.6968","3.7979","9.5331"
"22.9600","5.7174","40.2151","5.7174","3.8116","9.5750"
"23.0400","5.7374","40.3943","5.7374","3.8249","9.6177"
"23.1200","5.7564","40.5605","5.7564","3.8376","9.6573"
"23.2000","5.7774","40.7455","5.7774","3.8516","9.7013"
"23.2800","5.7971","40.9255","5.7971","3.8647","9.7442"
"23.3600","5.8170","41.1019","5.8170","3.8780","9.7862"
"23.4400","5.8369","41.2665","5.8369","3.8913","9.8254"
"23.5200","5.8555","41.4341","5.8555","3.9036","9.8653"
"23.6000","5.8768","41.6219","5.8768","3.9179","9.9100"
"23.6800","5.8980","41.8100","5.8980","3.9320","9.9548"
"23.7600","5.9172","41.9838","5.9172","3.9448","9.9962"
"23.8400","5.9372","42.1678","5.9372","3.9581","10.0400"
"23.9200","5.9562","42.3262","5.9562","3.9708","10.0777"
"24.0000","5.9759","42.5048","5.9759","3.9839","10.1202"
"24.0800","5.9973","42.6964","5.9973","3.9982","10.1658"
"24.1600","6.0162","42.8647","6.0162","4.0108","10.2059"
"24.2400","6.0375","43.0501","6.0375","4.0250","10.2500"
"24.3200","6.0573","43.2327","6.0573","4.0382","10.2935"
"24.4000","6.0779","43.4163","6.0779","4.0519","10.3372"
"24.4800","6.0976","43.5924","6.0976","4.0651","10.3791"
"24.5600","6.1168","43.7693","6.1168","4.0779","10.4213"
"24.6400","6.1370","43.9365","6.1370","4.0914","10.4611"
"24.7200","6.1570","44.1055","6.1570","4.1046","10.5013"
"24.8000","6.1757","44.2761","6.1757","4.1171","10.5419"
"24.8800","6.1969","44.4639","6.1969","4.1313","10.5867"
"24.9600","6.2172","44.6515","6.2172","4.1448","10.6313"
"25.0400","6.2375","44.8064","6.2375","4.1583","10.6682"
"25.1200","6.2567","44.9735","6.2567","4.1711","10.7080"
"25.2000","6.2756","45.1381","6.2756","4.1837","10.7472"
"25.2800","6.2969","45.3309","6.2969","4.1980","10.7931"
"25.3600","6.3169","45.5035","6.3169","4.2113","10.8342"
"25.4400","6.3363","45.6705","6.3363","4.2242","10.8739"
"25.5200","6.3571","45.8657","6.3571","4.2380","10.9204"
"25.6000","6.3776","46.0404","6.3776","4.2517","10.9620"
"25.6800","6.3978","46.2147","6.3978","4.2652","11.0035"
"25.7600","6.4177","46.3711","6.4177","4.2785","11.0407"
"25.8400","6.4358","46.5377","6.4358","4.2906","11.0804"
"25.9200","6.4565","46.7209","6.4565","4.3043","11.1240"
"26.0000","6.4761","46.8968","6.4761","4.3174","11.1659"
"26.0800","6.4968","47.0720","6.4968","4.3312","11.2076"
"26.1600","6.5178","47.2669","6.5178","4.3452","11.2540"
"26.2400","6.5374","47.4363","6.5374","4.3583","11.2944"
"26.3200","6.5569","47.6030","6.5569","4.3713","11.3341"
"26.4000","6.5767","47.7738","6.5767","4.3844","11.3747"
"26.4800","6.5962","47.9454","6.5962","4.3974","11.4156"
"26.5600","6.6168","48.1304","6.6168","4.4112","11.4596"
"26.6400","6.6361","48.2871","6.6361","4.4241","11.4969"
"26.7200","6.6573","48.4733","6.6573","4.4382","11.5413"
"26.8000","6.6779","48.6621","6.6779","4.4519","11.5862"
"26.8800","6.6976","48.8344","6.6976","4.4651","11.6272"
"26.9600","6.7174","49.0054","6.7174","4.4783","11.6680"
"27.0400","6.7368","49.1639","6.7368","4.4912","11.7057"
"27.1200","6.7563","49.3388","6.7563","4.5042","11.7473"
"27.2000","6.7767","49.5125","6.7767","4.5178","11.7887"
"27.2800","6.7957","49.6771","6.7957","4.5305","11.8279"
"27.3600","6.8170","49.8648","6.8170","4.5447","11.8726"
"27.4400","6.8377","50.0433","6.8377","4.5585","11.9151"
"27.5200","6.8571","50.2182","6.8571","4.5714","11.9567"
"27.6000","6.8769","50.3877","6.8769","4.5846","11.9971"
"27.6800","6.8960","50.5494","6.8960","4.5973","12.0356"
"27.7600","6.9169","50.7289","6.9169","4.6113","12.0783"
"27.8400","6.9370","50.9035","6.9370","4.6247","12.1199"
"27.9200","6.9562","51.0647","6.9562","4.6375","12.1583"
"28.0000","6.9770","51.2556","6.9770","4.6514","12.2037"
"28.0800","6.9979","51.4419","6.9979","4.6653","12.2481"
"28.1600","7.0175","51.6046","7.0175","4.6783","12.2868"
"28.2400","7.0374","51.7680","7.0374","4.6916","12.3257"
"28.3200","7.0557","51.9226","7.0557","4.7038","12.3625"
"28.4000","7.0767","52.1161","7.0767","4.7178","12.4086"
"28.4800","7.0966","52.2782","7.0966","4.7311","12.4472"
"28.5600","7.1162","52.4435","7.1162","4.7441","12.4865"
"28.6400","7.1369","52.6394","7.1369","4.7579","12.5332"
"28.7200","7.1571","52.7915","7.1571","4.7714","12.5694"
"28.8000","7.1768","52.9691","7.1768","4.7845","12.6117"
"28.8800","7.1975","53.1359","7.1975","4.7983","12.6514"
"28.9600","7.2163","53.2978","7.2163","4.8108","12.6899"
"29.0400","7.2367","53.4804","7.2367","4.8245","12.7334"
"29.1200","7.2562","53.6412","7.2562","4.8374","12.7717"
"29.2000","7.2769","53.8179","7.2769","4.8513","12.8138"
"29.2800","7.2982","54.0049","7.2982","4.8655","12.8583"
"29.3600","7.3177","54.1704","7.3177","4.8785","12.8977"
"29.4400","7.3376","54.3358","7.3376","4.8917","12.9371"
"29.5200","7.3568","54.4890","7.3568","4.9045","12.9736"
"29.6000","7.3763","54.6666","7.3763","4.9176","13.0159"
"29.6800","7.3971","54.8459","7.3971","4.9314","13.0585"
"29.7600","7.4163","55.0029","7.4163","4.9442","13.0959"
"29.8400","7.4365","55.1657","7.4365","4.9577","13.1347"
"29.9200","7.4573","55.3459","7.4573","4.9716","13.1776"
"30.0000","7.4767","55.5156","7.4767","4.9844","13.2180"
"30.0800","7.4976","55.6880","7.4976","4.9984","13.2591"
"30.1600","7.5166","55.8444","7.5166","5.0111","13.2963"
"30.2400","7.5365","56.0128","7.5365","5.0243","13.3364"
"30.3200","7.5565","56.1813","7.5565","5.0377","13.3765"
"30.4000","7.5761","56.3423","7.5761","5.0507","13.4148"
"30.4800","7.5971","56.5233","7.5971","5.0648","13.4579"
"30.5600","7.6179","56.6922","7.6179","5.0786","13.4981"
"30.6400","7.6367","56.8531","7.6367","5.0912","13.5364"
"30.7200","7.6576","57.0395","7.6576","5.1050","13.5808"
"30.8000","7.6767","57.1854","7.6767","5.1178","13.6156"
"30.8800","7.6970","57.3591","7.6970","5.1314","13.6569"
"30.9600","7.7169","57.5248","7.7169","5.1446","13.6964"
"31.0400","7.7355","57.6812","7.7355","5.1570","13.7336"
"31.1200","7.7567","57.8577","7.7567","5.1711","13.7756"
"31.2000","7.7776","58.0313","7.7776","5.1850","13.8170"
"31.2800","7.7975","58.2065","7.7975","5.1983","13.8587"
"31.3600","7.8177","58.3723","7.8177","5.2118","13.8982"
"31.4400","7.8362","58.5146","7.8362","5.2241","13.9321"
"31.5200","7.8564","58.6799","7.8564","5.2376","13.9714"
"31.6000","7.8768","58.8506","7.8768","5.2512","14.0120"
"31.6800","7.8964","59.0137","7.8964","5.2643","14.0509"
"31.7600","7.9176","59.1931","7.9176","5.2784","14.0936"
"31.8400","7.9373","59.3574","7.9373","5.2916","14.1327"
"31.9200","7.9575","59.5181","7.9575","5.3050","14.1710"
"32.0000","7.9777","59.6897","7.9777","5.3184","14.2118"
"32.0800","7.9965","59.8348","7.9965","5.3310","14.2464"
"32.1600","8.0165","60.0065","8.0165","5.3443","14.2873"
"32.2400","8.0362","60.1747","8.0362","5.3575","14.3273"
"32.3200","8.0559","60.3312","8.0559","5.3706","14.3646"
"32.4000","8.0776","60.5196","8.0776","5.3851","14.4094"
"32.4800","8.0970","60.6757","8.0970","5.3980","14.4466"
"32.5600","8.1173","60.8323","8.1173","5.4115","14.4839"
"32.6400","8.1367","60.9870","8.1367","5.4244","14.5207"
"32.7200","8.1561","61.1504","8.1561","5.4374","14.5596"
"32.8000","8.1760","61.3003","8.1760","5.4507","14.5953"
"32.8800","8.1967","61.4762","8.1967","5.4645","14.6372"
"32.9600","8.2170","61.6397","8.2170","5.4780","14.6761"
"33.0400","8.2378","61.8152","8.2378","5.4918","14.7179"
"33.1200","8.2569","61.9589","8.2569","5.5046","14.7521"
"33.2000","8.2772","62.1262","8.2772","5.5182","14.7920"
"33.2800","8.2968","62.2790","8.2968","5.5312","14.8283"
"33.3600","8.3170","62.4491","8.3170","5.5447","14.8688"
"33.4400","8.3371","62.6106","8.3371","5.5580","14.9073"
"33.5200","8.3554","62.7574","8.3554","5.5702","14.9422"
"33.6000","8.3768","62.9321","8.3768","5.5845","14.9838"
"33.6800","8.3980","63.1061","8.3980","5.5986","15.0253"
"33.7600","8.4173","63.2629","8.4173","5.6115","15.0626"
"33.8400","8.4369","63.4215","8.4369","5.6246","15.1004"
"33.9200","8.4561","63.5637","8.4561","5.6374","15.1342"
"34.0000","8.4763","63.7242","8.4763","5.6509","15.1724"
"34.0800","8.4972","63.8918","8.4972","5.6648","15.2123"
"34.1600","8.5160","64.0383","8.5160","5.6773","15.2472"
"34.2400","8.5374","64.2226","8.5374","5.6916","15.2911"
"34.3200","8.5576","64.3736","8.5576","5.7050","15.3270"
"34.4000","8.5775","64.5413","8.5775","5.7183","15.3670"
"34.4800","8.5971","64.6969","8.5971","5.7314","15.4040"
"34.5600","8.6165","64.8343","8.6165","5.7443","15.4367"
"34.6400","8.6368","64.9988","8.6368","5.7579","15.4759"
"34.7200","8.6572","65.1538","8.6572","5.7715","15.5128"
"34.8000","8.6759","65.3045","8.6759","5.7839","15.5487"
"34.8800","8.6969","65.4793","8.6969","5.7979","15.5903"
"34.9600","8.7172","65.6451","8.7172","5.8115","15.6298"
"35.0400","8.7374","65.7913","8.7374","5.8249","15.6646"
"35.1200","8.7569","65.9455","8.7569","5.8379","15.7013"
"35.2000","8.7759","66.0913","8.7759","5.8506","15.7360"
"35.2800","8.7964","66.2458","8.7964","5.8642","15.7728"
"35.3600","8.8167","66.4053","8.8167","5.8778","15.8108"
"35.4400","8.8368","66.5655","8.8368","5.8912","15.8489"
"35.5200","8.8573","66.7276","8.8573","5.9049","15.8875"
"35.6000","8.8773","66.8729","8.8773","5.9182","15.9221"
"35.6800","8.8978","67.0296","8.8978","5.9318","15.9594"
"35.7600","8.9175","67.1777","8.9175","5.9450","15.9947"
"35.8400","8.9361","67.3223","8.9361","5.9574","16.0291"
"35.9200","8.9566","67.4872","8.9566","5.9711","16.0684"
"36.0000","8.9758","67.6227","8.9758","5.9839","16.1006"
"36.0800","8.9969","67.7856","8.9969","5.9980","16.1394"
"36.1600","9.0175","67.9490","9.0175","6.0117","16.1783"
"36.2400","9.0367","68.0883","9.0367","6.0245","16.2115"
"36.3200","9.0569","68.2400","9.0569","6.0379","16.2476"
"36.4000","9.0767","68.3885","9.0767","6.0511","16.2830"
"36.4800","9.0959","68.5400","9.0959","6.0639","16.3190"
"36.5600","9.1173","68.7096","9.1173","6.0782","16.3594"
"36.6400","9.1361","68.8428","9.1361","6.0907","16.3911"
"36.7200","9.1573","69.0174","9.1573","6.1049","16.4327"
"36.8000","9.1779","69.1644","9.1779","6.1186","16.4677"
"36.8800","9.1976","69.3224","9.1976","6.1317","16.5053"
"36.9600","9.2173","69.4642","9.2173","6.1448","16.5391"
"37.0400","9.2368","69.6073","9.2368","6.1578","16.5732"
"37.1200","9.2563","69.7597","9.2563","6.1709","16.6095"
"37.2000","9.2767","69.9088","9.2767","6.1845","16.6449"
"37.2800","9.2958","70.0499","9.2958","6.1972","16.6786"
"37.3600","9.3173","70.2224","9.3173","6.2115","16.7196"
"37.4400","9.3376","70.3677","9.3376","6.2250","16.7542"
"37.5200","9.3568","70.5152","9.3568","6.2379","16.7893"
"37.6000","9.3763","70.6687","9.3763","6.2509","16.8259"
"37.6800","9.3962","70.7955","9.3962","6.2641","16.8561"
"37.7600","9.4173","70.9593","9.4173","6.2782","16.8951"
"37.8400","9.4369","71.0996","9.4369","6.2913","16.9285"
"37.9200","9.4559","71.2451","9.4559","6.3039","16.9631"
"38.0000","9.4769","71.4080","9.4769","6.3179","17.0019"
"38.0800","9.4981","71.5661","9.4981","6.3321","17.0395"
"38.1600","9.5178","71.7102","9.5178","6.3452","17.0739"
"38.2400","9.5372","71.8496","9.5372","6.3582","17.1070"
"38.3200","9.5555","71.9698","9.5555","6.3703","17.1357"
"38.4000","9.5767","72.1187","9.5767","6.3844","17.1711"
"38.4800","9.5965","72.2623","9.5965","6.3977","17.2053"
"38.5600","9.6163","72.4206","9.6163","6.4109","17.2430"
"38.6400","9.6366","72.5649","9.6366","6.4244","17.2774"
"38.7200","9.6571","72.7119","9.6571","6.4381","17.3124"
"38.8000","9.6769","72.8416","9.6769","6.4513","17.3432"
"38.8800","9.6976","72.9993","9.6976","6.4651","17.3808"
"38.9600","9.7162","73.1350","9.7162","6.4775","17.4131"
"39.0400","9.7370","73.2823","9.7370","6.4913","17.4482"
"39.1200","9.7561","73.4104","9.7561","6.5040","17.4787"
"39.2000","9.7768","73.5623","9.7768","6.5178","17.5148"
"39.2800","9.7981","73.7239","9.7981","6.5320","17.5533"
"39.3600","9.8174","73.8524","9.8174","6.5449","17.5839"
"39.4400","9.8373","73.9959","9.8373","6.5582","17.6181"
"39.5200","9.8571","74.1249","9.8571","6.5714","17.6488"
"39.6000","9.8763","74.2610","9.8763","6.5842","17.6812"
"39.6800","9.8969","74.4188","9.8969","6.5979","17.7188"
"39.7600","9.9162","74.5469","9.9162","6.6108","17.7493"
"39.8400","9.9364","74.6707","9.9364","6.6243","17.7787"
"39.9200","9.9575","74.8240","9.9575","6.6383","17.8152"
"40.0000","9.9766","74.9594","9.9766","6.6511","17.8475"
"40.0800","9.9974","75.1080","9.9974","6.6649","17.8829"
"40.1600","10.0165","75.2233","10.0165","6.6777","17.9103"
"40.2400","10.0368","75.3649","10.0368","6.6912","17.9440"
"40.3200","10.0566","75.5004","10.0566","6.7044","17.9763"
"40.4000","10.0761","75.6267","10.0761","6.7174","18.0064"
"40.4800","10.0972","75.7665","10.0972","6.7314","18.0397"
"40.5600","10.1186","75.9145","10.1186","6.7457","18.0749"
"40.6400","10.1371","76.0338","10.1371","6.7581","18.1033"
"40.7200","10.1568","76.1685","10.1568","6.7712","18.1354"
"40.8000","10.1762","76.2813","10.1762","6.7841","18.1622"
"40.8800","10.1969","76.4151","10.1969","6.7980","18.1941"
"40.9600","10.2165","76.5476","10.2165","6.8110","18.2256"
"41.0400","10.2358","76.6745","10.2358","6.8239","18.2558"
"41.1200","10.2566","76.8141","10.2566","6.8377","18.2891"
"41.2000","10.2776","76.9604","10.2776","6.8518","18.3239"
"41.2800","10.2975","77.0928","10.2975","6.8650","18.3554"
"41.3600","10.3175","77.2121","10.3175","6.8784","18.3838"
"41.4400","10.3362","77.3239","10.3362","6.8908","18.4104"
"41.5200","10.3565","77.4523","10.3565","6.9043","18.4410"
"41.6000","10.3769","77.5810","10.3769","6.9179","18.4717"
"41.6800","10.3965","77.7075","10.3965","6.9310","18.5018"
"41.7600","10.4180","77.8545","10.4180","6.9453","18.5368"
"41.8400","10.4372","77.9751","10.4372","6.9582","18.5655"
"41.9200","10.4575","78.0919","10.4575","6.9717","18.5933"
"42.0000","10.4770","78.2145","10.4770","6.9847","18.6225"
"42.0800","10.4964","78.3257","10.4964","6.9976","18.6490"
"42.1600","10.5162","78.4443","10.5162","7.0108","18.6772"
"42.2400","10.5362","78.5745","10.5362","7.0241","18.7082"
"42.3200","10.5563","78.7050","10.5563","7.0375","18.7393"
"42.4000","10.5776","78.8293","10.5776","7.0517","18.7689"
"42.4800","10.5967","78.9451","10.5967","7.0645","18.7964"
"42.5600","10.6175","79.0726","10.6175","7.0783","18.8268"
"42.6400","10.6369","79.1794","10.6369","7.0913","18.8522"
"42.7200","10.6561","79.2857","10.6561","7.1040","18.8775"
"42.8000","10.6766","79.4262","10.6766","7.1177","18.9110"
"42.8800","10.6965","79.5344","10.6965","7.1310","18.9368"
"42.9600","10.7172","79.6497","10.7172","7.1448","18.9642"
"43.0400","10.7385","79.7781","10.7385","7.1590","18.9948"
"43.1200","10.7569","79.8819","10.7569","7.1713","19.0195"
"43.2000","10.7765","79.9923","10.7765","7.1844","19.0458"
"43.2800","10.7969","80.1121","10.7969","7.1979","19.0743"
"43.3600","10.8174","80.2365","10.8174","7.2116","19.1039"
"43.4400","10.8369","80.3402","10.8369","7.2246","19.1286"
"43.5200","10.8556","80.4302","10.8556","7.2371","19.1500"
"43.6000","10.8768","80.5577","10.8768","7.2512","19.1804"
"43.6800","10.8976","80.6776","10.8976","7.2651","19.2090"
"43.7600","10.9170","80.7834","10.9170","7.2780","19.2341"
"43.8400","10.9368","80.9087","10.9368","7.2912","19.2640"
"43.9200","10.9566","81.0154","10.9566","7.3044","19.2894"
"44.0000","10.9763","81.1219","10.9763","7.3175","19.3147"
"44.0800","10.9969","81.2285","10.9969","7.3313","19.3401"
"44.1600","11.0159","81.3468","11.0159","7.3439","19.3683"
"44.2400","11.0376","81.4787","11.0376","7.3584","19.3997"
"44.3200","11.0574","81.5765","11.0574","7.3716","19.4230"
"44.4000","11.0774","81.6806","11.0774","7.3849","19.4478"
"44.4800","11.0972","81.7944","11.0972","7.3982","19.4749"
"44.5600","11.1168","81.8921","11.1168","7.4112","19.4981"
"44.6400","11.1368","81.9953","11.1368","7.4245","19.5227"
"44.7200","11.1570","82.1040","11.1570","7.4380","19.5486"
"44.8000","11.1756","82.1965","11.1756","7.4504","19.5706"
"44.8800","11.1971","82.3352","11.1971","7.4647","19.6036"
"44.9600","11.2171","82.4401","11.2171","7.4781","19.6286"
"45.0400","11.2373","82.5333","11.2373","7.4916","19.6508"
"45.1200","11.2570","82.6303","11.2570","7.5046","19.6739"
"45.2000","11.2759","82.7267","11.2759","7.5172","19.6968"
"45.2800","11.2968","82.8366","11.2968","7.5312","19.7230"
"45.3600","11.3173","82.9509","11.3173","7.5448","19.7502"
"45.4400","11.3365","83.0365","11.3365","7.5576","19.7706"
"45.5200","11.3574","83.1746","11.3574","7.5716","19.8035"
"45.6000","11.3771","83.2588","11.3771","7.5848","19.8235"
"45.6800","11.3973","83.3572","11.3973","7.5982","19.8469"
"45.7600","11.4176","83.4614","11.4176","7.6117","19.8718"
"45.8400","11.4364","83.5552","11.4364","7.6242","19.8941"
"45.9200","11.4566","83.6580","11.4566","7.6377","19.9186"
"46.0000","11.4756","83.7410","11.4756","7.6504","19.9383"
"46.0800","11.4972","83.8624","11.4972","7.6648","19.9672"
"46.1600","11.5176","83.9682","11.5176","7.6784","19.9924"
"46.2400","11.5369","84.0460","11.5369","7.6913","20.0109"
"46.3200","11.5569","84.1558","11.5569","7.7046","20.0371"
"46.4000","11.5770","84.2494","11.5770","7.7180","20.0594"
"46.4800","11.5959","84.3397","11.5959","7.7306","20.0809"
"46.5600","11.6169","84.4492","11.6169","7.7446","20.1070"
"46.6400","11.6360","84.5210","11.6360","7.7573","20.1241"
"46.7200","11.6571","84.6389","11.6571","7.7714","20.1521"
"46.8000","11.6779","84.7359","11.6779","7.7853","20.1752"
"46.8800","11.6976","84.8357","11.6976","7.7984","20.1990"
"46.9600","11.7172","84.9188","11.7172","7.8115","20.2188"
"47.0400","11.7368","85.0164","11.7368","7.8245","20.2420"
"47.1200","11.7563","85.0942","11.7563","7.8375","20.2605"
"47.2000","11.7766","85.1966","11.7766","7.8511","20.2849"
"47.2800","11.7958","85.2852","11.7958","7.8639","20.3060"
"47.3600","11.8171","85.3975","11.8171","7.8781","20.3327"
"47.4400","11.8375","85.4852","11.8375","7.8916","20.3536"
"47.5200","11.8566","85.5753","11.8566","7.9044","20.3751"
"47.6000","11.8774","85.6806","11.8774","7.9182","20.4001"
"47.6800","11.8963","85.7504","11.8963","7.9309","20.4168"
"47.7600","11.9171","85.8507","11.9171","7.9447","20.4406"
"47.8400","11.9368","85.9320","11.9368","7.9579","20.4600"
"47.9200","11.9561","86.0204","11.9561","7.9707","20.4810"
"48.0000","11.9769","86.1269","11.9769","7.9846","20.5064"
"48.0800","11.9979","86.2171","11.9979","7.9986","20.5279"
"48.1600","12.0177","86.3019","12.0177","8.0118","20.5481"
"48.2400","12.0376","86.3810","12.0376","8.0251","20.5669"
"48.3200","12.0555","86.4400","12.0555","8.0370","20.5809"
"48.4000","12.0768","86.5347","12.0768","8.0512","20.6035"
"48.4800","12.0968","86.6316","12.0968","8.0645","20.6266"
"48.5600","12.1166","86.7215","12.1166","8.0778","20.6480"
"48.6400","12.1370","86.8180","12.1370","8.0913","20.6709"
"48.7200","12.1571","86.8975","12.1571","8.1047","20.6899"
"48.8000","12.1770","86.9726","12.1770","8.1180","20.7078"
"48.8800","12.1977","87.0584","12.1977","8.1318","20.7282"
"48.9600","12.2162","87.1216","12.2162","8.1441","20.7432"
"49.0400","12.2363","87.2182","12.2363","8.1575","20.7662"
"49.1200","12.2561","87.2918","12.2561","8.1708","20.7838"
"49.2000","12.2770","87.3856","12.2770","8.1847","20.8061"
"49.2800","12.2981","87.4795","12.2981","8.1987","20.8285"
"49.3600","12.3175","87.5350","12.3175","8.2116","20.8417"
"49.4400","12.3374","87.6129","12.3374","8.2250","20.8602"
"49.5200","12.3570","87.6813","12.3570","8.2380","20.8765"
"49.6000","12.3763","87.7616","12.3763","8.2509","20.8956"
"49.6800","12.3969","87.8557","12.3969","8.2646","20.9180"
"49.7600","12.4163","87.9217","12.4163","8.2775","20.9337"
"49.8400","12.4360","87.9986","12.4360","8.2906","20.9521"
"49.9200","12.4574","88.0999","12.4574","8.3050","20.9762"
"50.0000","12.4769","88.1855","12.4769","8.3179","20.9966"
"50.0800","12.4975","88.2799","12.4975","8.3317","21.0190"
"50.1600","12.5163","88.3395","12.5163","8.3442","21.0332"
"50.2400","12.5365","88.4295","12.5365","8.3577","21.0546"
"50.3200","12.5563","88.5042","12.5563","8.3709","21.0724"
"50.4000","12.5762","88.5853","12.5762","8.3841","21.0917"
"50.4800","12.5974","88.6757","12.5974","8.3982","21.1133"
"50.5600","12.6187","88.7776","12.6187","8.4125","21.1375"
"50.6400","12.6371","88.8337","12.6371","8.4247","21.1509"
"50.7200","12.6571","88.9168","12.6571","8.4380","21.1707"
"50.8000","12.6760","88.9819","12.6760","8.4506","21.1862"
"50.8800","12.6975","89.0750","12.6975","8.4650","21.2083"
"50.9600","12.7170","89.1499","12.7170","8.4780","21.2262"
"51.0400","12.7357","89.2138","12.7357","8.4905","21.2414"
"51.1200","12.7570","89.3166","12.7570","8.5047","21.2659"
"51.2000","12.7772","89.3982","12.7772","8.5181","21.2853"
"51.2800","12.7970","89.4751","12.7970","8.5313","21.3036"
"51.3600","12.8177","89.5586","12.8177","8.5451","21.3235"
"51.4400","12.8361","89.6096","12.8361","8.5574","21.3356"
"51.5200","12.8563","89.6944","12.8563","8.5709","21.3558"
"51.6000","12.8768","89.7758","12.8768","8.5845","21.3752"
"51.6800","12.8964","89.8640","12.8964","8.5976","21.3962"
"51.7600","12.9176","89.9473","12.9176","8.6117","21.4160"
"51.8400","12.9374","90.0201","12.9374","8.6250","21.4334"
"51.9200","12.9575","90.0799","12.9575","8.6383","21.4476"
"52.0000","12.9770","90.1653","12.9770","8.6513","21.4679"
"52.0800","12.9969","90.2579","12.9969","8.6646","21.4900"
"52.1600","13.0169","90.3273","13.0169","8.6779","21.5065"
"52.2400","13.0365","90.4006","13.0365","8.6910","21.5240"
"52.3200","13.0558","90.4685","13.0558","8.7039","21.5401"
"52.4000","13.0773","90.5690","13.0773","8.7182","21.5640"
"52.4800","13.0972","90.6496","13.0972","8.7315","21.5832"
"52.5600","13.1178","90.7213","13.1178","8.7452","21.6003"
"52.6400","13.1369","90.7849","13.1369","8.7580","21.6154"
"52.7200","13.1559","90.8576","13.1559","8.7706","21.6328"
"52.8000","13.1764","90.9491","13.1764","8.7843","21.6545"
"52.8800","13.1965","91.0290","13.1965","8.7977","21.6736"
"52.9600","13.2174","91.1171","13.2174","8.8116","21.6945"
"53.0400","13.2383","91.2008","13.2383","8.8255","21.7145"
"53.1200","13.2570","91.2715","13.2570","8.8380","21.7313"
"53.2000","13.2774","91.3456","13.2774","8.8516","21.7490"
"53.2800","13.2969","91.4132","13.2969","8.8646","21.7651"
"53.3600","13.3168","91.5019","13.3168","8.8779","21.7862"
"53.4400","13.3370","91.5663","13.3370","8.8913","21.8015"
"53.5200","13.3550","91.6160","13.3550","8.9033","21.8133"
"53.6000","13.3767","91.7177","13.3767","8.9178","21.8376"
"53.6800","13.3980","91.8093","13.3980","8.9320","21.8594"
"53.7600","13.4168","91.8727","13.4168","8.9445","21.8745"
"53.8400","13.4368","91.9544","13.4368","8.9579","21.8939"
"53.9200","13.4564","92.0223","13.4564","8.9709","21.9101"
"54.0000","13.4763","92.0942","13.4763","8.9842","21.9272"
"54.0800","13.4970","92.1732","13.4970","8.9980","21.9460"
"54.1600","13.5160","92.2436","13.5160","9.0106","21.9628"
"54.2400","13.5376","92.3421","13.5376","9.0251","21.9862"
"54.3200","13.5574","92.4116","13.5574","9.0383","22.0028"
"54.4000","13.5775","92.4861","13.5775","9.0516","22.0205"
"54.4800","13.5970","92.5668","13.5970","9.0647","22.0397"
"54.5600","13.6170","92.6389","13.6170","9.0780","22.0569"
"54.6400","13.6372","92.7166","13.6372","9.0915","22.0754"
"54.7200","13.6569","92.7831","13.6569","9.1046","22.0912"
"54.8000","13.6755","92.8558","13.6755","9.1170","22.1085"
"54.8800","13.6967","92.9502","13.6967","9.1311","22.1310"
"54.9600","13.7172","93.0379","13.7172","9.1448","22.1519"
"55.0400","13.7375","93.1121","13.7375","9.1583","22.1695"
"55.1200","13.7571","93.1796","13.7571","9.1714","22.1856"
"55.2000","13.7757","93.2327","13.7757","9.1838","22.1983"
"55.2800","13.7966","93.3334","13.7966","9.1977","22.2222"
"55.3600","13.8171","93.4128","13.8171","9.2114","22.2411"
"55.4400","13.8365","93.4919","13.8365","9.2243","22.2600"
"55.5200","13.8575","93.5912","13.8575","9.2383","22.2836"
"55.6000","13.8776","93.6520","13.8776","9.2517","22.2981"
"55.6800","13.8974","93.7213","13.8974","9.2649","22.3146"
"55.7600","13.9174","93.7908","13.9174","9.2783","22.3312"
"55.8400","13.9362","93.8675","13.9362","9.2908","22.3494"
"55.9200","13.9564","93.9424","13.9564","9.3043","22.3672"
"56.0000","13.9756","94.0094","13.9756","9.3171","22.3832"
"56.0800","13.9970","94.1187","13.9970","9.3314","22.4092"
"56.1600","14.0175","94.2027","14.0175","9.3450","22.4292"
"56.2400","14.0369","94.2710","14.0369","9.3579","22.4455"
"56.3200","14.0570","94.3433","14.0570","9.3714","22.4627"
"56.4000","14.0769","94.4209","14.0769","9.3846","22.4812"
"56.4800","14.0961","94.4897","14.0961","9.3974","22.4976"
"56.5600","14.1168","94.5816","14.1168","9.4112","22.5194"
"56.6400","14.1361","94.6468","14.1361","9.4240","22.5349"
"56.7200","14.1571","94.7320","14.1571","9.4381","22.5552"
"56.8000","14.1779","94.8263","14.1779","9.4519","22.5777"
"56.8800","14.1974","94.9024","14.1974","9.4649","22.5958"
"56.9600","14.2171","94.9788","14.2171","9.4781","22.6140"
"57.0400","14.2367","95.0496","14.2367","9.4911","22.6309"
"57.1200","14.2566","95.1290","14.2566","9.5044","22.6498"
"57.2000","14.2767","95.2003","14.2767","9.5178","22.6667"
"57.2800","14.2955","95.2587","14.2955","9.5303","22.6806"
"57.3600","14.3170","95.3575","14.3170","9.5447","22.7042"
"57.4400","14.3374","95.4493","14.3374","9.5583","22.7260"
"57.5200","14.3569","95.5303","14.3569","9.5713","22.7453"
"57.6000","14.3771","95.6115","14.3771","9.5847","22.7646"
"57.6800","14.3963","95.6702","14.3963","9.5975","22.7786"
"57.7600","14.4170","95.7455","14.4170","9.6113","22.7965"
"57.8400","14.4370","95.8251","14.4370","9.6246","22.8155"
"57.9200","14.4562","95.9093","14.4562","9.6374","22.8355"
"58.0000","14.4770","95.9938","14.4770","9.6514","22.8557"
"58.0800","14.4982","96.0924","14.4982","9.6654","22.8791"
"58.1600","14.5176","96.1589","14.5176","9.6784","22.8950"
"58.2400","14.5367","96.2344","14.5367","9.6911","22.9130"
"58.3200","14.5557","96.2984","14.5557","9.7038","22.9282"
"58.4000","14.5768","96.3902","14.5768","9.7178","22.9501"
"58.4800","14.5967","96.4631","14.5967","9.7311","22.9674"
"58.5600","14.6159","96.5319","14.6159","9.7439","22.9838"
"58.6400","14.6373","96.6238","14.6373","9.7582","23.0057"
"58.7200","14.6570","96.6869","14.6570","9.7713","23.0207"
"58.8000","14.6772","96.7622","14.6772","9.7848","23.0386"
"58.8800","14.6974","96.8370","14.6974","9.7983","23.0564"
"58.9600","14.7164","96.9045","14.7164","9.8109","23.0725"
"59.0400","14.7365","96.9910","14.7365","9.8243","23.0931"
"59.1200","14.7560","97.0607","14.7560","9.8374","23.1097"
"59.2000","14.7769","97.1453","14.7769","9.8512","23.1298"
"59.2800","14.7982","97.2349","14.7982","9.8655","23.1512"
"59.3600","14.8174","97.3005","14.8174","9.8783","23.1668"
"59.4400","14.8374","97.3708","14.8374","9.8916","23.1835"
"59.5200","14.8569","97.4399","14.8569","9.9046","23.2000"
"59.6000","14.8763","97.5128","14.8763","9.9175","23.2173"
"59.6800","14.8970","97.6083","14.8970","9.9314","23.2401"
"59.7600","14.9157","97.6568","14.9157","9.9438","23.2516"
"59.8400","14.9361","97.7475","14.9361","9.9574","23.2732"
"59.9200","14.9572","97.8335","14.9572","9.9714","23.2937"
"60.0000","14.9766","97.9065","14.9766","9.9844","23.3111"
"60.0800","14.9978","97.9930","14.9978","9.9985","23.3317"
"60.0900","15.0002","98.0007","15.0002","10.0001","23.3335"