File: data/instron_tests/241217_metamaterial_foam_test_data/241217_metamaterial_foams_2_1.csv
Results Table 1


Results Table 2


Time,Displacement,Compressive displacement,Compressive strain (Displacement),Compressive stress,Force
(s),(mm),(mm),(%),(kPa),(N)
"0.0000","0.1906","-0.0091","-0.0061","-0.0095","-0.0355"
"0.0800","0.1938","-0.0058","-0.0039","-0.0016","-0.0059"
"0.1600","0.2260","0.0263","0.0176","0.0639","0.2395"
"0.2400","0.2661","0.0664","0.0444","0.1381","0.5177"
"0.3200","0.3043","0.1046","0.0699","0.2129","0.7983"
"0.4000","0.3447","0.1450","0.0968","0.2843","1.0661"
"0.4800","0.3854","0.1857","0.1240","0.3567","1.3375"
"0.5600","0.4251","0.2255","0.1505","0.4221","1.5830"
"0.6400","0.4647","0.2650","0.1769","0.4937","1.8513"
"0.7200","0.5032","0.3035","0.2026","0.5606","2.1023"
"0.8000","0.5452","0.3456","0.2307","0.6350","2.3812"
"0.8800","0.5845","0.3848","0.2569","0.6982","2.6184"
"0.9600","0.6243","0.4246","0.2834","0.7664","2.8739"
"1.0400","0.6642","0.4646","0.3101","0.8370","3.1389"
"1.1200","0.7052","0.5055","0.3375","0.9092","3.4094"
"1.2000","0.7450","0.5454","0.3641","0.9755","3.6582"
"1.2800","0.7843","0.5847","0.3903","1.0401","3.9005"
"1.3600","0.8238","0.6242","0.4167","1.1105","4.1645"
"1.4400","0.8650","0.6653","0.4441","1.1797","4.4239"
"1.5200","0.9038","0.7041","0.4701","1.2456","4.6709"
"1.6000","0.9444","0.7448","0.4972","1.3120","4.9202"
"1.6800","0.9848","0.7852","0.5241","1.3842","5.1909"
"1.7600","1.0256","0.8259","0.5514","1.4490","5.4339"
"1.8400","1.0648","0.8651","0.5775","1.5195","5.6981"
"1.9200","1.1041","0.9044","0.6038","1.5793","5.9225"
"2.0000","1.1448","0.9452","0.6310","1.6518","6.1943"
"2.0800","1.1851","0.9854","0.6578","1.7215","6.4555"
"2.1600","1.2236","1.0239","0.6835","1.7854","6.6952"
"2.2400","1.2646","1.0649","0.7109","1.8522","6.9459"
"2.3200","1.3053","1.1056","0.7381","1.9222","7.2082"
"2.4000","1.3453","1.1456","0.7648","1.9926","7.4722"
"2.4800","1.3848","1.1851","0.7911","2.0592","7.7220"
"2.5600","1.4234","1.2237","0.8169","2.1253","7.9698"
"2.6400","1.4642","1.2645","0.8441","2.1909","8.2158"
"2.7200","1.5047","1.3050","0.8712","2.2635","8.4882"
"2.8000","1.5441","1.3444","0.8975","2.3276","8.7287"
"2.8800","1.5839","1.3842","0.9241","2.3986","8.9948"
"2.9600","1.6251","1.4255","0.9516","2.4659","9.2471"
"3.0400","1.6654","1.4657","0.9784","2.5346","9.5048"
"3.1200","1.7038","1.5042","1.0041","2.5997","9.7489"
"3.2000","1.7437","1.5440","1.0307","2.6691","10.0093"
"3.2800","1.7851","1.5854","1.0583","2.7376","10.2658"
"3.3600","1.8249","1.6252","1.0849","2.8075","10.5280"
"3.4400","1.8642","1.6645","1.1111","2.8756","10.7836"
"3.5200","1.9041","1.7045","1.1378","2.9442","11.0408"
"3.6000","1.9456","1.7460","1.1655","3.0158","11.3094"
"3.6800","1.9853","1.7856","1.1920","3.0810","11.5539"
"3.7600","2.0242","1.8246","1.2180","3.1528","11.8231"
"3.8400","2.0642","1.8646","1.2447","3.2179","12.0673"
"3.9200","2.1047","1.9050","1.2717","3.2901","12.3380"
"4.0000","2.1448","1.9451","1.2985","3.3583","12.5937"
"4.0800","2.1841","1.9844","1.3247","3.4247","12.8426"
"4.1600","2.2242","2.0245","1.3515","3.4946","13.1049"
"4.2400","2.2658","2.0662","1.3793","3.5694","13.3852"
"4.3200","2.3044","2.1047","1.4050","3.6327","13.6225"
"4.4000","2.3445","2.1449","1.4318","3.7002","13.8759"
"4.4800","2.3842","2.1845","1.4583","3.7686","14.1321"
"4.5600","2.4246","2.2250","1.4853","3.8409","14.4035"
"4.6400","2.4650","2.2653","1.5122","3.9095","14.6608"
"4.7200","2.5040","2.3043","1.5383","3.9745","14.9043"
"4.8000","2.5448","2.3451","1.5655","4.0480","15.1799"
"4.8800","2.5853","2.3857","1.5926","4.1152","15.4321"
"4.9600","2.6245","2.4248","1.6187","4.1843","15.6911"
"5.0400","2.6643","2.4647","1.6453","4.2475","15.9282"
"5.1200","2.7037","2.5040","1.6716","4.3193","16.1976"
"5.2000","2.7451","2.5454","1.6992","4.3885","16.4569"
"5.2800","2.7839","2.5842","1.7251","4.4579","16.7170"
"5.3600","2.8242","2.6245","1.7520","4.5236","16.9636"
"5.4400","2.8656","2.6660","1.7797","4.5983","17.2437"
"5.5200","2.9044","2.7047","1.8056","4.6638","17.4893"
"5.6000","2.9450","2.7453","1.8327","4.7345","17.7542"
"5.6800","2.9841","2.7845","1.8588","4.8024","18.0089"
"5.7600","3.0251","2.8254","1.8861","4.8704","18.2639"
"5.8400","3.0654","2.8658","1.9131","4.9424","18.5340"
"5.9200","3.1038","2.9041","1.9386","5.0096","18.7861"
"6.0000","3.1437","2.9440","1.9653","5.0787","19.0452"
"6.0800","3.1856","2.9859","1.9933","5.1501","19.3130"
"6.1600","3.2257","3.0260","2.0200","5.2235","19.5880"
"6.2400","3.2650","3.0654","2.0463","5.2874","19.8276"
"6.3200","3.3032","3.1035","2.0718","5.3583","20.0935"
"6.4000","3.3451","3.1455","2.0998","5.4245","20.3418"
"6.4800","3.3848","3.1851","2.1262","5.4958","20.6092"
"6.5600","3.4239","3.2242","2.1523","5.5605","20.8518"
"6.6400","3.4639","3.2642","2.1791","5.6307","21.1152"
"6.7200","3.5052","3.3055","2.2066","5.6998","21.3742"
"6.8000","3.5455","3.3458","2.2335","5.7691","21.6341"
"6.8800","3.5845","3.3849","2.2596","5.8376","21.8909"
"6.9600","3.6238","3.4242","2.2858","5.9062","22.1482"
"7.0400","3.6650","3.4653","2.3133","5.9783","22.4185"
"7.1200","3.7049","3.5052","2.3399","6.0420","22.6575"
"7.2000","3.7444","3.5447","2.3663","6.1153","22.9322"
"7.2800","3.7844","3.5848","2.3930","6.1808","23.1779"
"7.3600","3.8254","3.6257","2.4204","6.2525","23.4468"
"7.4400","3.8653","3.6656","2.4470","6.3156","23.6836"
"7.5200","3.9044","3.7047","2.4731","6.3869","23.9510"
"7.6000","3.9441","3.7444","2.4996","6.4535","24.2005"
"7.6800","3.9844","3.7848","2.5265","6.5253","24.4699"
"7.7600","4.0245","3.8248","2.5533","6.5922","24.7208"
"7.8400","4.0648","3.8651","2.5802","6.6588","24.9704"
"7.9200","4.1046","3.9049","2.6068","6.7309","25.2408"
"8.0000","4.1455","3.9458","2.6341","6.8014","25.5053"
"8.0800","4.1850","3.9853","2.6604","6.8665","25.7492"
"8.1600","4.2242","4.0245","2.6866","6.9333","26.0000"
"8.2400","4.2648","4.0651","2.7137","7.0077","26.2790"
"8.3200","4.3048","4.1051","2.7404","7.0742","26.5283"
"8.4000","4.3436","4.1439","2.7663","7.1440","26.7899"
"8.4800","4.3841","4.1845","2.7934","7.2090","27.0339"
"8.5600","4.4249","4.2252","2.8205","7.2826","27.3098"
"8.6400","4.4656","4.2659","2.8477","7.3503","27.5635"
"8.7200","4.5041","4.3044","2.8734","7.4207","27.8278"
"8.8000","4.5441","4.3444","2.9001","7.4839","28.0648"
"8.8800","4.5848","4.3851","2.9273","7.5550","28.3313"
"8.9600","4.6250","4.4254","2.9542","7.6259","28.5971"
"9.0400","4.6644","4.4648","2.9805","7.6941","28.8530"
"9.1200","4.7040","4.5043","3.0069","7.7601","29.1006"
"9.2000","4.7450","4.5453","3.0343","7.8301","29.3628"
"9.2800","4.7854","4.5858","3.0612","7.8965","29.6117"
"9.3600","4.8237","4.6241","3.0868","7.9621","29.8581"
"9.4400","4.8638","4.6641","3.1136","8.0337","30.1266"
"9.5200","4.9048","4.7051","3.1409","8.0991","30.3718"
"9.6000","4.9452","4.7455","3.1679","8.1713","30.6425"
"9.6800","4.9841","4.7844","3.1939","8.2374","30.8904"
"9.7600","5.0239","4.8242","3.2204","8.3066","31.1497"
"9.8400","5.0656","4.8660","3.2483","8.3741","31.4029"
"9.9200","5.1054","4.9057","3.2748","8.4434","31.6626"
"10.0000","5.1451","4.9454","3.3014","8.5131","31.9241"
"10.0800","5.1834","4.9837","3.3269","8.5793","32.1725"
"10.1600","5.2248","5.0252","3.3546","8.6492","32.4347"
"10.2400","5.2651","5.0654","3.3814","8.7178","32.6919"
"10.3200","5.3040","5.1044","3.4074","8.7861","32.9479"
"10.4000","5.3443","5.1446","3.4343","8.8540","33.2025"
"10.4800","5.3854","5.1857","3.4618","8.9242","33.4659"
"10.5600","5.4250","5.2253","3.4882","8.9902","33.7134"
"10.6400","5.4648","5.2652","3.5148","9.0595","33.9731"
"10.7200","5.5040","5.3044","3.5410","9.1256","34.2209"
"10.8000","5.5453","5.3456","3.5685","9.2007","34.5025"
"10.8800","5.5846","5.3850","3.5948","9.2663","34.7488"
"10.9600","5.6236","5.4239","3.6208","9.3340","35.0026"
"11.0400","5.6642","5.4646","3.6479","9.4014","35.2553"
"11.1200","5.7053","5.5057","3.6753","9.4769","35.5383"
"11.2000","5.7448","5.5452","3.7017","9.5419","35.7821"
"11.2800","5.7842","5.5845","3.7280","9.6059","36.0221"
"11.3600","5.8240","5.6243","3.7545","9.6770","36.2887"
"11.4400","5.8656","5.6659","3.7823","9.7480","36.5551"
"11.5200","5.9041","5.7044","3.8080","9.8148","36.8055"
"11.6000","5.9443","5.7446","3.8349","9.8812","37.0546"
"11.6800","5.9850","5.7854","3.8620","9.9539","37.3270"
"11.7600","6.0251","5.8254","3.8888","10.0209","37.5785"
"11.8400","6.0648","5.8652","3.9153","10.0880","37.8299"
"11.9200","6.1036","5.9040","3.9412","10.1529","38.0734"
"12.0000","6.1452","5.9455","3.9689","10.2240","38.3401"
"12.0800","6.1846","5.9849","3.9953","10.2938","38.6016"
"12.1600","6.2237","6.0240","4.0213","10.3603","38.8512"
"12.2400","6.2642","6.0646","4.0484","10.4288","39.1082"
"12.3200","6.3053","6.1057","4.0759","10.5005","39.3769"
"12.4000","6.3456","6.1459","4.1027","10.5695","39.6357"
"12.4800","6.3845","6.1848","4.1287","10.6364","39.8867"
"12.5600","6.4239","6.2243","4.1550","10.7035","40.1383"
"12.6400","6.4643","6.2646","4.1820","10.7719","40.3947"
"12.7200","6.5043","6.3047","4.2087","10.8407","40.6526"
"12.8000","6.5439","6.3442","4.2351","10.9084","40.9065"
"12.8800","6.5839","6.3842","4.2618","10.9806","41.1773"
"12.9600","6.6252","6.4255","4.2894","11.0496","41.4360"
"13.0400","6.6656","6.4659","4.3164","11.1184","41.6941"
"13.1200","6.7037","6.5040","4.3418","11.1802","41.9259"
"13.2000","6.7437","6.5440","4.3685","11.2517","42.1939"
"13.2800","6.7849","6.5852","4.3960","11.3201","42.4505"
"13.3600","6.8249","6.6252","4.4227","11.3855","42.6955"
"13.4400","6.8642","6.6646","4.4490","11.4556","42.9586"
"13.5200","6.9037","6.7040","4.4753","11.5214","43.2051"
"13.6000","6.9453","6.7456","4.5031","11.5961","43.4855"
"13.6800","6.9857","6.7861","4.5301","11.6636","43.7384"
"13.7600","7.0247","6.8250","4.5561","11.7305","43.9894"
"13.8400","7.0644","6.8647","4.5826","11.7965","44.2367"
"13.9200","7.1049","6.9052","4.6096","11.8686","44.5071"
"14.0000","7.1447","6.9451","4.6362","11.9341","44.7528"
"14.0800","7.1842","6.9845","4.6626","12.0034","45.0126"
"14.1600","7.2240","7.0243","4.6891","12.0713","45.2673"
"14.2400","7.2656","7.0659","4.7169","12.1458","45.5466"
"14.3200","7.3042","7.1045","4.7426","12.2068","45.7754"
"14.4000","7.3446","7.1449","4.7696","12.2772","46.0397"
"14.4800","7.3842","7.1845","4.7961","12.3466","46.2997"
"14.5600","7.4248","7.2251","4.8232","12.4143","46.5538"
"14.6400","7.4641","7.2645","4.8494","12.4824","46.8091"
"14.7200","7.5044","7.3047","4.8763","12.5473","47.0522"
"14.8000","7.5445","7.3448","4.9030","12.6201","47.3252"
"14.8800","7.5856","7.3859","4.9305","12.6898","47.5869"
"14.9600","7.6247","7.4251","4.9566","12.7562","47.8359"
"15.0400","7.6645","7.4648","4.9832","12.8196","48.0735"
"15.1200","7.7038","7.5041","5.0094","12.8926","48.3473"
"15.2000","7.7452","7.5456","5.0371","12.9601","48.6003"
"15.2800","7.7840","7.5844","5.0630","13.0280","48.8550"
"15.3600","7.8239","7.6242","5.0896","13.0939","49.1020"
"15.4400","7.8655","7.6658","5.1174","13.1653","49.3699"
"15.5200","7.9051","7.7054","5.1438","13.2329","49.6233"
"15.6000","7.9445","7.7449","5.1701","13.3018","49.8817"
"15.6800","7.9841","7.7845","5.1966","13.3643","50.1162"
"15.7600","8.0249","7.8252","5.2237","13.4371","50.3891"
"15.8400","8.0654","7.8658","5.2508","13.5076","50.6536"
"15.9200","8.1043","7.9046","5.2768","13.5728","50.8978"
"16.0000","8.1437","7.9440","5.3031","13.6412","51.1547"
"16.0800","8.1850","7.9854","5.3307","13.7105","51.4143"
"16.1600","8.2255","8.0258","5.3577","13.7797","51.6740"
"16.2400","8.2651","8.0654","5.3841","13.8435","51.9133"
"16.3200","8.3036","8.1039","5.4098","13.9129","52.1732"
"16.4000","8.3458","8.1461","5.4380","13.9806","52.4272"
"16.4800","8.3845","8.1848","5.4638","14.0469","52.6757"
"16.5600","8.4240","8.2244","5.4902","14.1128","52.9228"
"16.6400","8.4644","8.2647","5.5171","14.1844","53.1916"
"16.7200","8.5051","8.3055","5.5444","14.2531","53.4492"
"16.8000","8.5454","8.3457","5.5712","14.3226","53.7097"
"16.8800","8.5844","8.3847","5.5972","14.3881","53.9553"
"16.9600","8.6236","8.4239","5.6234","14.4560","54.2099"
"17.0400","8.6650","8.4653","5.6511","14.5262","54.4732"
"17.1200","8.7039","8.5042","5.6770","14.5893","54.7099"
"17.2000","8.7441","8.5444","5.7039","14.6588","54.9704"
"17.2800","8.7843","8.5846","5.7307","14.7245","55.2170"
"17.3600","8.8257","8.6261","5.7584","14.7975","55.4905"
"17.4400","8.8654","8.6657","5.7848","14.8619","55.7320"
"17.5200","8.9045","8.7048","5.8109","14.9290","55.9838"
"17.6000","8.9443","8.7446","5.8375","14.9951","56.2316"
"17.6800","8.9844","8.7847","5.8643","15.0658","56.4967"
"17.7600","9.0244","8.8248","5.8910","15.1303","56.7385"
"17.8400","9.0648","8.8651","5.9179","15.2003","57.0010"
"17.9200","9.1042","8.9046","5.9443","15.2682","57.2557"
"18.0000","9.1457","8.9460","5.9719","15.3393","57.5224"
"18.0800","9.1847","8.9850","5.9980","15.4057","57.7712"
"18.1600","9.2245","9.0248","6.0246","15.4696","58.0111"
"18.2400","9.2643","9.0647","6.0512","15.5406","58.2772"
"18.3200","9.3046","9.1049","6.0781","15.6076","58.5287"
"18.4000","9.3441","9.1444","6.1044","15.6758","58.7843"
"18.4800","9.3841","9.1844","6.1311","15.7410","59.0287"
"18.5600","9.4249","9.2252","6.1583","15.8131","59.2992"
"18.6400","9.4658","9.2661","6.1857","15.8807","59.5526"
"18.7200","9.5042","9.3045","6.2113","15.9477","59.8039"
"18.8000","9.5443","9.3446","6.2381","16.0145","60.0546"
"18.8800","9.5848","9.3852","6.2651","16.0840","60.3151"
"18.9600","9.6252","9.4255","6.2921","16.1523","60.5712"
"19.0400","9.6641","9.4645","6.3180","16.2197","60.8237"
"19.1200","9.7037","9.5040","6.3445","16.2861","61.0728"
"19.2000","9.7458","9.5461","6.3725","16.3542","61.3283"
"19.2800","9.7852","9.5855","6.3989","16.4234","61.5877"
"19.3600","9.8235","9.6239","6.4245","16.4875","61.8282"
"19.4400","9.8639","9.6642","6.4514","16.5559","62.0845"
"19.5200","9.9048","9.7051","6.4787","16.6233","62.3372"
"19.6000","9.9450","9.7454","6.5056","16.6904","62.5890"
"19.6800","9.9838","9.7841","6.5314","16.7549","62.8310"
"19.7600","10.0240","9.8243","6.5583","16.8250","63.0937"
"19.8400","10.0659","9.8662","6.5863","16.8953","63.3573"
"19.9200","10.1052","9.9055","6.6125","16.9629","63.6110"
"20.0000","10.1446","9.9449","6.6388","17.0270","63.8511"
"20.0800","10.1837","9.9840","6.6649","17.0940","64.1026"
"20.1600","10.2252","10.0255","6.6926","17.1610","64.3537"
"20.2400","10.2655","10.0658","6.7195","17.2297","64.6113"
"20.3200","10.3043","10.1046","6.7454","17.2947","64.8550"
"20.4000","10.3443","10.1446","6.7721","17.3636","65.1134"
"20.4800","10.3854","10.1857","6.7995","17.4332","65.3744"
"20.5600","10.4250","10.2254","6.8260","17.4974","65.6154"
"20.6400","10.4648","10.2651","6.8525","17.5635","65.8632"
"20.7200","10.5035","10.3038","6.8784","17.6275","66.1032"
"20.8000","10.5443","10.3446","6.9056","17.7007","66.3776"
"20.8800","10.5848","10.3851","6.9326","17.7626","66.6097"
"20.9600","10.6240","10.4243","6.9588","17.8286","66.8573"
"21.0400","10.6643","10.4647","6.9857","17.8959","67.1095"
"21.1200","10.7050","10.5053","7.0129","17.9674","67.3779"
"21.2000","10.7448","10.5451","7.0394","18.0318","67.6193"
"21.2800","10.7847","10.5850","7.0661","18.0933","67.8498"
"21.3600","10.8237","10.6241","7.0921","18.1636","68.1137"
"21.4400","10.8653","10.6656","7.1199","18.2309","68.3659"
"21.5200","10.9042","10.7045","7.1458","18.2973","68.6149"
"21.6000","10.9446","10.7449","7.1728","18.3614","68.8553"
"21.6800","10.9850","10.7853","7.1998","18.4308","69.1156"
"21.7600","11.0252","10.8255","7.2266","18.4973","69.3649"
"21.8400","11.0654","10.8658","7.2535","18.5662","69.6232"
"21.9200","11.1039","10.9042","7.2792","18.6267","69.8502"
"22.0000","11.1453","10.9457","7.3068","18.6964","70.1114"
"22.0800","11.1849","10.9853","7.3333","18.7604","70.3516"
"22.1600","11.2235","11.0238","7.3590","18.8277","70.6037"
"22.2400","11.2643","11.0646","7.3863","18.8910","70.8414"
"22.3200","11.3052","11.1055","7.4135","18.9581","71.0930"
"22.4000","11.3457","11.1460","7.4406","19.0255","71.3458"
"22.4800","11.3843","11.1846","7.4664","19.0904","71.5891"
"22.5600","11.4234","11.2237","7.4925","19.1560","71.8350"
"22.6400","11.4648","11.2652","7.5201","19.2225","72.0845"
"22.7200","11.5047","11.3050","7.5467","19.2875","72.3281"
"22.8000","11.5439","11.3442","7.5729","19.3531","72.5743"
"22.8800","11.5836","11.3840","7.5994","19.4182","72.8184"
"22.9600","11.6255","11.4258","7.6274","19.4849","73.0683"
"23.0400","11.6652","11.4655","7.6539","19.5492","73.3093"
"23.1200","11.7044","11.5047","7.6800","19.6130","73.5488"
"23.2000","11.7438","11.5441","7.7063","19.6795","73.7981"
"23.2800","11.7846","11.5850","7.7336","19.7446","74.0422"
"23.3600","11.8249","11.6252","7.7605","19.8087","74.2826"
"23.4400","11.8642","11.6645","7.7867","19.8696","74.5111"
"23.5200","11.9038","11.7042","7.8132","19.9337","74.7514"
"23.6000","11.9459","11.7463","7.8413","20.0026","75.0097"
"23.6800","11.9852","11.7855","7.8675","20.0648","75.2429"
"23.7600","12.0246","11.8249","7.8938","20.1275","75.4782"
"23.8400","12.0644","11.8648","7.9204","20.1906","75.7147"
"23.9200","12.1048","11.9051","7.9473","20.2592","75.9721"
"24.0000","12.1449","11.9452","7.9741","20.3190","76.1962"
"24.0800","12.1843","11.9846","8.0004","20.3857","76.4465"
"24.1600","12.2242","12.0246","8.0271","20.4497","76.6864"
"24.2400","12.2658","12.0661","8.0548","20.5175","76.9407"
"24.3200","12.3045","12.1048","8.0806","20.5750","77.1563"
"24.4000","12.3443","12.1446","8.1072","20.6383","77.3936"
"24.4800","12.3842","12.1845","8.1338","20.7051","77.6440"
"24.5600","12.4248","12.2251","8.1609","20.7680","77.8801"
"24.6400","12.4641","12.2644","8.1872","20.8272","78.1021"
"24.7200","12.5043","12.3047","8.2140","20.8873","78.3274"
"24.8000","12.5445","12.3448","8.2409","20.9536","78.5762"
"24.8800","12.5855","12.3858","8.2682","21.0156","78.8083"
"24.9600","12.6244","12.4247","8.2942","21.0788","79.0453"
"25.0400","12.6646","12.4649","8.3210","21.1366","79.2622"
"25.1200","12.7037","12.5041","8.3472","21.2006","79.5023"
"25.2000","12.7456","12.5459","8.3751","21.2631","79.7367"
"25.2800","12.7842","12.5845","8.4009","21.3224","79.9589"
"25.3600","12.8243","12.6246","8.4276","21.3806","80.1771"
"25.4400","12.8657","12.6660","8.4553","21.4437","80.4140"
"25.5200","12.9052","12.7055","8.4816","21.5044","80.6413"
"25.6000","12.9447","12.7450","8.5080","21.5618","80.8568"
"25.6800","12.9839","12.7843","8.5342","21.6176","81.0658"
"25.7600","13.0241","12.8244","8.5610","21.6752","81.2818"
"25.8400","13.0650","12.8654","8.5883","21.7379","81.5173"
"25.9200","13.1040","12.9044","8.6144","21.7933","81.7248"
"26.0000","13.1438","12.9441","8.6409","21.8488","81.9331"
"26.0800","13.1857","12.9860","8.6689","21.9078","82.1542"
"26.1600","13.2252","13.0255","8.6952","21.9646","82.3672"
"26.2400","13.2650","13.0653","8.7218","22.0215","82.5804"
"26.3200","13.3035","13.1038","8.7475","22.0725","82.7719"
"26.4000","13.3455","13.1458","8.7756","22.1296","82.9859"
"26.4800","13.3848","13.1851","8.8018","22.1838","83.1894"
"26.5600","13.4238","13.2242","8.8279","22.2372","83.3894"
"26.6400","13.4642","13.2645","8.8548","22.2966","83.6123"
"26.7200","13.5052","13.3056","8.8822","22.3499","83.8120"
"26.8000","13.5453","13.3457","8.9090","22.4028","84.0106"
"26.8800","13.5843","13.3846","8.9350","22.4536","84.2009"
"26.9600","13.6228","13.4231","8.9607","22.5040","84.3898"
"27.0400","13.6654","13.4658","8.9891","22.5637","84.6138"
"27.1200","13.7048","13.5051","9.0154","22.6112","84.7920"
"27.2000","13.7443","13.5446","9.0418","22.6624","84.9838"
"27.2800","13.7844","13.5847","9.0686","22.7127","85.1726"
"27.3600","13.8254","13.6258","9.0959","22.7666","85.3747"
"27.4400","13.8651","13.6654","9.1224","22.8087","85.5328"
"27.5200","13.9044","13.7047","9.1487","22.8559","85.7096"
"27.6000","13.9441","13.7444","9.1751","22.9042","85.8906"
"27.6800","13.9841","13.7845","9.2019","22.9532","86.0743"
"27.7600","14.0249","13.8253","9.2291","23.0019","86.2572"
"27.8400","14.0653","13.8656","9.2560","23.0507","86.4399"
"27.9200","14.1046","13.9049","9.2823","23.0962","86.6106"
"28.0000","14.1458","13.9461","9.3098","23.1426","86.7847"
"28.0800","14.1844","13.9848","9.3356","23.1868","86.9504"
"28.1600","14.2246","14.0250","9.3624","23.2274","87.1028"
"28.2400","14.2644","14.0648","9.3890","23.2732","87.2745"
"28.3200","14.3048","14.1051","9.4159","23.3119","87.4198"
"28.4000","14.3440","14.1443","9.4421","23.3539","87.5770"
"28.4800","14.3842","14.1846","9.4690","23.3911","87.7165"
"28.5600","14.4249","14.2252","9.4961","23.4326","87.8722"
"28.6400","14.4654","14.2657","9.5232","23.4685","88.0068"
"28.7200","14.5036","14.3039","9.5486","23.5047","88.1425"
"28.8000","14.5445","14.3448","9.5759","23.5368","88.2631"
"28.8800","14.5844","14.3848","9.6026","23.5712","88.3920"
"28.9600","14.6249","14.4252","9.6296","23.6046","88.5174"
"29.0400","14.6638","14.4641","9.6556","23.6352","88.6320"
"29.1200","14.7033","14.5037","9.6820","23.6657","88.7464"
"29.2000","14.7460","14.5463","9.7105","23.6988","88.8704"
"29.2800","14.7855","14.5858","9.7368","23.7301","88.9879"
"29.3600","14.8237","14.6240","9.7623","23.7521","89.0703"
"29.4400","14.8639","14.6642","9.7892","23.7816","89.1809"
"29.5200","14.9051","14.7054","9.8167","23.8062","89.2731"
"29.6000","14.9453","14.7456","9.8435","23.8327","89.3728"
"29.6800","14.9841","14.7844","9.8694","23.8492","89.4346"
"29.7600","15.0239","14.8242","9.8960","23.8738","89.5267"
"29.8400","15.0657","14.8660","9.9239","23.8903","89.5887"
"29.9200","15.1054","14.9057","9.9504","23.9074","89.6526"
"30.0000","15.1447","14.9450","9.9766","23.9225","89.7094"
"30.0800","15.1831","14.9834","10.0023","23.9350","89.7561"
"30.1600","15.2251","15.0254","10.0303","23.9541","89.8280"
"30.2400","15.2656","15.0659","10.0573","23.9656","89.8708"
"30.3200","15.3039","15.1042","10.0829","23.9769","89.9134"
"30.4000","15.3444","15.1448","10.1100","23.9877","89.9540"
"30.4800","15.3856","15.1859","10.1374","24.0018","90.0068"
"30.5600","15.4252","15.2255","10.1639","24.0087","90.0326"
"30.6400","15.4648","15.2652","10.1903","24.0155","90.0582"
"30.7200","15.5037","15.3041","10.2163","24.0205","90.0769"
"30.8000","15.5449","15.3452","10.2438","24.0285","90.1070"
"30.8800","15.5846","15.3849","10.2703","24.0292","90.1094"
"30.9600","15.6239","15.4243","10.2966","24.0359","90.1345"
"31.0400","15.6641","15.4644","10.3234","24.0398","90.1491"
"31.1200","15.7052","15.5055","10.3508","24.0445","90.1668"
"31.2000","15.7445","15.5449","10.3771","24.0444","90.1667"
"31.2800","15.7847","15.5850","10.4039","24.0460","90.1723"
"31.3600","15.8239","15.6243","10.4301","24.0483","90.1811"
"31.4400","15.8651","15.6654","10.4575","24.0474","90.1779"
"31.5200","15.9034","15.7037","10.4831","24.0418","90.1568"
"31.6000","15.9445","15.7448","10.5106","24.0390","90.1462"
"31.6800","15.9854","15.7858","10.5379","24.0402","90.1509"
"31.7600","16.0255","15.8258","10.5646","24.0352","90.1320"
"31.8400","16.0650","15.8654","10.5910","24.0296","90.1110"
"31.9200","16.1039","15.9042","10.6170","24.0209","90.0785"
"32.0000","16.1449","15.9452","10.6443","24.0175","90.0654"
"32.0800","16.1851","15.9854","10.6711","24.0060","90.0225"
"32.1600","16.2235","16.0238","10.6968","24.0017","90.0063"
"32.2400","16.2644","16.0647","10.7241","23.9908","89.9656"
"32.3200","16.3052","16.1055","10.7513","23.9830","89.9361"
"32.4000","16.3449","16.1452","10.7778","23.9743","89.9038"
"32.4800","16.3846","16.1849","10.8043","23.9628","89.8603"
"32.5600","16.4236","16.2239","10.8304","23.9519","89.8198"
"32.6400","16.4651","16.2654","10.8581","23.9383","89.7687"
"32.7200","16.5042","16.3046","10.8842","23.9257","89.7214"
"32.8000","16.5442","16.3445","10.9109","23.9100","89.6623"
"32.8800","16.5841","16.3844","10.9375","23.8913","89.5924"
"32.9600","16.6252","16.4255","10.9649","23.8723","89.5210"
"33.0400","16.6659","16.4663","10.9921","23.8525","89.4468"
"33.1200","16.7039","16.5042","11.0175","23.8243","89.3411"
"33.2000","16.7435","16.5439","11.0440","23.8071","89.2767"
"33.2800","16.7851","16.5855","11.0717","23.7908","89.2155"
"33.3600","16.8248","16.6251","11.0982","23.7723","89.1462"
"33.4400","16.8645","16.6648","11.1247","23.7506","89.0649"
"33.5200","16.9039","16.7042","11.1510","23.7333","89.0000"
"33.6000","16.9460","16.7463","11.1791","23.7159","88.9347"
"33.6800","16.9851","16.7854","11.2052","23.6934","88.8501"
"33.7600","17.0239","16.8243","11.2311","23.6706","88.7649"
"33.8400","17.0643","16.8646","11.2581","23.6464","88.6741"
"33.9200","17.1047","16.9051","11.2851","23.6254","88.5952"
"34.0000","17.1453","16.9457","11.3122","23.5990","88.4964"
"34.0800","17.1842","16.9845","11.3381","23.5727","88.3976"
"34.1600","17.2244","17.0248","11.3650","23.5464","88.2989"
"34.2400","17.2659","17.0662","11.3926","23.5229","88.2108"
"34.3200","17.3045","17.1048","11.4184","23.4873","88.0772"
"34.4000","17.3445","17.1448","11.4451","23.4580","87.9676"
"34.4800","17.3839","17.1842","11.4714","23.4277","87.8538"
"34.5600","17.4248","17.2251","11.4987","23.4021","87.7580"
"34.6400","17.4645","17.2648","11.5252","23.3715","87.6433"
"34.7200","17.5042","17.3045","11.5517","23.3471","87.5517"
"34.8000","17.5447","17.3451","11.5788","23.3234","87.4626"
"34.8800","17.5850","17.3853","11.6057","23.2893","87.3348"
"34.9600","17.6245","17.4248","11.6320","23.2647","87.2427"
"35.0400","17.6642","17.4645","11.6585","23.2290","87.1087"
"35.1200","17.7040","17.5043","11.6851","23.2024","87.0091"
"35.2000","17.7455","17.5459","11.7128","23.1768","86.9130"
"35.2800","17.7837","17.5840","11.7383","23.1494","86.8102"
"35.3600","17.8242","17.6245","11.7654","23.1187","86.6951"
"35.4400","17.8654","17.6657","11.7929","23.0888","86.5831"
"35.5200","17.9054","17.7057","11.8195","23.0576","86.4661"
"35.6000","17.9445","17.7449","11.8457","23.0305","86.3643"
"35.6800","17.9842","17.7846","11.8722","22.9963","86.2360"
"35.7600","18.0247","17.8250","11.8992","22.9650","86.1187"
"35.8400","18.0652","17.8655","11.9262","22.9357","86.0091"
"35.9200","18.1039","17.9042","11.9521","22.8978","85.8668"
"36.0000","18.1438","17.9442","11.9787","22.8695","85.7608"
"36.0800","18.1850","17.9853","12.0062","22.8367","85.6376"
"36.1600","18.2255","18.0258","12.0332","22.8012","85.5043"
"36.2400","18.2646","18.0649","12.0594","22.7616","85.3559"
"36.3200","18.3036","18.1040","12.0854","22.7253","85.2198"
"36.4000","18.3453","18.1457","12.1132","22.6872","85.0771"
"36.4800","18.3850","18.1853","12.1397","22.6474","84.9276"
"36.5600","18.4237","18.2240","12.1655","22.6040","84.7651"
"36.6400","18.4644","18.2648","12.1927","22.5558","84.5842"
"36.7200","18.5053","18.3056","12.2200","22.5089","84.4084"
"36.8000","18.5456","18.3459","12.2469","22.4659","84.2471"
"36.8800","18.5848","18.3851","12.2731","22.4168","84.0631"
"36.9600","18.6234","18.4237","12.2989","22.3728","83.8981"
"37.0400","18.6652","18.4655","12.3268","22.3238","83.7143"
"37.1200","18.7045","18.5048","12.3530","22.2733","83.5247"
"37.2000","18.7440","18.5443","12.3793","22.2266","83.3496"
"37.2800","18.7843","18.5847","12.4063","22.1797","83.1739"
"37.3600","18.8249","18.6253","12.4334","22.1379","83.0172"
"37.4400","18.8652","18.6655","12.4603","22.0913","82.8423"
"37.5200","18.9047","18.7050","12.4866","22.0518","82.6944"
"37.6000","18.9443","18.7446","12.5131","22.0071","82.5266"
"37.6800","18.9844","18.7847","12.5398","21.9607","82.3526"
"37.7600","19.0242","18.8245","12.5664","21.9156","82.1836"
"37.8400","19.0651","18.8654","12.5937","21.8701","82.0129"
"37.9200","19.1044","18.9047","12.6199","21.8206","81.8274"
"38.0000","19.1457","18.9461","12.6475","21.7748","81.6557"
"38.0800","19.1850","18.9853","12.6737","21.7313","81.4922"
"38.1600","19.2245","19.0248","12.7001","21.6809","81.3032"
"38.2400","19.2648","19.0651","12.7270","21.6337","81.1262"
"38.3200","19.3048","19.1051","12.7537","21.5788","80.9204"
"38.4000","19.3443","19.1447","12.7801","21.5315","80.7432"
"38.4800","19.3840","19.1843","12.8066","21.4760","80.5351"
"38.5600","19.4249","19.2252","12.8339","21.4215","80.3306"
"38.6400","19.4659","19.2663","12.8613","21.3625","80.1093"
"38.7200","19.5038","19.3042","12.8866","21.2987","79.8702"
"38.8000","19.5443","19.3446","12.9136","21.2321","79.6204"
"38.8800","19.5848","19.3851","12.9406","21.1566","79.3373"
"38.9600","19.6246","19.4250","12.9672","21.0855","79.0708"
"39.0400","19.6639","19.4642","12.9934","21.0230","78.8361"
"39.1200","19.7040","19.5043","13.0202","20.9553","78.5822"
"39.2000","19.7461","19.5464","13.0483","20.8885","78.3318"
"39.2800","19.7856","19.5859","13.0747","20.8172","78.0646"
"39.3600","19.8239","19.6242","13.1003","20.7235","77.7131"
"39.4400","19.8640","19.6643","13.1270","20.6304","77.3641"
"39.5200","19.9050","19.7053","13.1544","20.5317","76.9939"
"39.6000","19.9449","19.7453","13.1810","20.4348","76.6305"
"39.6800","19.9841","19.7845","13.2072","20.2649","75.9933"
"39.7600","20.0238","19.8242","13.2337","20.1441","75.5404"
"39.8400","20.0661","19.8664","13.2619","20.0179","75.0670"
"39.9200","20.1054","19.9057","13.2882","19.9189","74.6958"
"40.0000","20.1446","19.9450","13.3144","19.8310","74.3662"
"40.0800","20.1834","19.9837","13.3402","19.7382","74.0183"
"40.1600","20.2252","20.0255","13.3681","19.6424","73.6590"
"40.2400","20.2647","20.0651","13.3945","19.5428","73.2855"
"40.3200","20.3042","20.1045","13.4209","19.4566","72.9621"
"40.4000","20.3446","20.1450","13.4479","19.3784","72.6689"
"40.4800","20.3858","20.1861","13.4753","19.3041","72.3903"
"40.5600","20.4251","20.2254","13.5016","19.2163","72.0609"
"40.6400","20.4647","20.2650","13.5280","19.1343","71.7534"
"40.7200","20.5033","20.3036","13.5538","19.0432","71.4120"
"40.8000","20.5449","20.3452","13.5816","18.9430","71.0364"
"40.8800","20.5847","20.3850","13.6081","18.8305","70.6143"
"40.9600","20.6245","20.4248","13.6347","18.7237","70.2139"
"41.0400","20.6641","20.4644","13.6611","18.6305","69.8643"
"41.1200","20.7051","20.5054","13.6885","18.5485","69.5568"
"41.2000","20.7448","20.5452","13.7150","18.4580","69.2174"
"41.2800","20.7847","20.5850","13.7416","18.3656","68.8709"
"41.3600","20.8240","20.6244","13.7679","18.2912","68.5920"
"41.4400","20.8650","20.6653","13.7952","18.2094","68.2852"
"41.5200","20.9039","20.7042","13.8212","18.1305","67.9893"
"41.6000","20.9444","20.7448","13.8483","18.0482","67.6808"
"41.6800","20.9849","20.7852","13.8753","17.9735","67.4006"
"41.7600","21.0255","20.8258","13.9024","17.8957","67.1088"
"41.8400","21.0648","20.8651","13.9286","17.8175","66.8155"
"41.9200","21.1041","20.9045","13.9549","17.7390","66.5211"
"42.0000","21.1445","20.9449","13.9819","17.6724","66.2713"
"42.0800","21.1852","20.9855","14.0090","17.5990","65.9963"
"42.1600","21.2236","21.0239","14.0346","17.5200","65.7000"
"42.2400","21.2646","21.0649","14.0620","17.4525","65.4470"
"42.3200","21.3053","21.1057","14.0892","17.3821","65.1827"
"42.4000","21.3455","21.1458","14.1160","17.2997","64.8740"
"42.4800","21.3843","21.1847","14.1419","17.2042","64.5156"
"42.5600","21.4234","21.2238","14.1680","17.0973","64.1151"
"42.6400","21.4648","21.2651","14.1956","16.9966","63.7374"
"42.7200","21.5045","21.3048","14.2222","16.8799","63.2996"
"42.8000","21.5440","21.3443","14.2485","16.7342","62.7533"
"42.8800","21.5843","21.3846","14.2754","16.6010","62.2537"
"42.9600","21.6250","21.4254","14.3026","16.4699","61.7623"
"43.0400","21.6659","21.4662","14.3299","16.3510","61.3163"
"43.1200","21.7038","21.5041","14.3552","16.2409","60.9035"
"43.2000","21.7438","21.5441","14.3819","16.1512","60.5670"
"43.2800","21.7850","21.5854","14.4094","16.0568","60.2130"
"43.3600","21.8247","21.6250","14.4359","15.9520","59.8200"
"43.4400","21.8646","21.6649","14.4625","15.8494","59.4354"
"43.5200","21.9039","21.7042","14.4888","15.7479","59.0545"
"43.6000","21.9457","21.7460","14.5167","15.6346","58.6299"
"43.6800","21.9853","21.7857","14.5431","15.5081","58.1553"
"43.7600","22.0243","21.8246","14.5691","15.3869","57.7009"
"43.8400","22.0643","21.8646","14.5958","15.2784","57.2940"
"43.9200","22.1047","21.9050","14.6228","15.1674","56.8776"
"44.0000","22.1452","21.9456","14.6499","15.0367","56.3877"
"44.0800","22.1841","21.9844","14.6758","14.9245","55.9670"
"44.1600","22.2244","22.0248","14.7027","14.8270","55.6011"
"44.2400","22.2660","22.0664","14.7305","14.7515","55.3182"
"44.3200","22.3042","22.1045","14.7560","14.6762","55.0357"
"44.4000","22.3447","22.1450","14.7830","14.5877","54.7038"
"44.4800","22.3838","22.1842","14.8092","14.4993","54.3725"
"44.5600","22.4251","22.2254","14.8367","14.4120","54.0449"
"44.6400","22.4642","22.2646","14.8628","14.3313","53.7425"
"44.7200","22.5046","22.3049","14.8898","14.2477","53.4287"
"44.8000","22.5447","22.3450","14.9165","14.1668","53.1256"
"44.8800","22.5855","22.3858","14.9438","14.0733","52.7748"
"44.9600","22.6246","22.4250","14.9699","13.9828","52.4354"
"45.0400","22.6642","22.4646","14.9963","13.9031","52.1365"
"45.1200","22.7036","22.5039","15.0226","13.8329","51.8735"
"45.2000","22.7452","22.5456","15.0504","13.7374","51.5151"
"45.2800","22.7837","22.5841","15.0761","13.6564","51.2114"
"45.3600","22.8238","22.6241","15.1029","13.5578","50.8418"
"45.4400","22.8654","22.6657","15.1306","13.4923","50.5961"
"45.5200","22.9050","22.7054","15.1571","13.4432","50.4121"
"45.6000","22.9446","22.7449","15.1835","13.3998","50.2491"
"45.6800","22.9838","22.7842","15.2097","13.3521","50.0703"
"45.7600","23.0247","22.8251","15.2370","13.3119","49.9195"
"45.8400","23.0649","22.8652","15.2638","13.2682","49.7558"
"45.9200","23.1043","22.9046","15.2901","13.2196","49.5735"
"46.0000","23.1437","22.9440","15.3164","13.1637","49.3640"
"46.0800","23.1857","22.9861","15.3445","13.0907","49.0900"
"46.1600","23.2257","23.0260","15.3712","13.0356","48.8835"
"46.2400","23.2650","23.0653","15.3974","12.9691","48.6340"
"46.3200","23.3038","23.1041","15.4233","12.9243","48.4663"
"46.4000","23.3454","23.1457","15.4510","12.8785","48.2944"
"46.4800","23.3844","23.1848","15.4771","12.8348","48.1307"
"46.5600","23.4235","23.2239","15.5032","12.7977","47.9914"
"46.6400","23.4641","23.2644","15.5303","12.7630","47.8614"
"46.7200","23.5053","23.3057","15.5578","12.7350","47.7562"
"46.8000","23.5453","23.3457","15.5845","12.7084","47.6566"
"46.8800","23.5845","23.3849","15.6107","12.6829","47.5610"
"46.9600","23.6233","23.4236","15.6366","12.6599","47.4747"
"47.0400","23.6652","23.4655","15.6645","12.6410","47.4039"
"47.1200","23.7046","23.5049","15.6908","12.6173","47.3147"
"47.2000","23.7441","23.5444","15.7172","12.6024","47.2589"
"47.2800","23.7846","23.5850","15.7443","12.5855","47.1958"
"47.3600","23.8255","23.6258","15.7715","12.5684","47.1315"
"47.4400","23.8656","23.6659","15.7983","12.5419","47.0321"
"47.5200","23.9047","23.7050","15.8244","12.5038","46.8892"
"47.6000","23.9441","23.7445","15.8508","12.4591","46.7215"
"47.6800","23.9843","23.7846","15.8776","12.4289","46.6085"
"47.7600","24.0243","23.8247","15.9043","12.4024","46.5088"
"47.8400","24.0645","23.8649","15.9311","12.3848","46.4430"
"47.9200","24.1044","23.9047","15.9577","12.3657","46.3712"
"48.0000","24.1459","23.9462","15.9854","12.3413","46.2799"
"48.0800","24.1847","23.9851","16.0114","12.3213","46.2050"
"48.1600","24.2240","24.0243","16.0375","12.2960","46.1099"
"48.2400","24.2650","24.0653","16.0649","12.2829","46.0610"
"48.3200","24.3050","24.1053","16.0916","12.2648","45.9930"
"48.4000","24.3446","24.1449","16.1181","12.2484","45.9314"
"48.4800","24.3843","24.1846","16.1446","12.2237","45.8387"
"48.5600","24.4254","24.2257","16.1720","12.2034","45.7626"
"48.6400","24.4656","24.2659","16.1988","12.1804","45.6766"
"48.7200","24.5035","24.3039","16.2242","12.1608","45.6029"
"48.8000","24.5443","24.3447","16.2514","12.1419","45.5322"
"48.8800","24.5845","24.3848","16.2782","12.1287","45.4827"
"48.9600","24.6246","24.4249","16.3050","12.1190","45.4461"
"49.0400","24.6643","24.4646","16.3315","12.0977","45.3664"
"49.1200","24.7037","24.5040","16.3578","12.0804","45.3013"
"49.2000","24.7460","24.5463","16.3860","12.0584","45.2189"
"49.2800","24.7858","24.5861","16.4126","12.0443","45.1661"
"49.3600","24.8236","24.6239","16.4378","12.0279","45.1045"
"49.4400","24.8640","24.6643","16.4648","12.0146","45.0549"
"49.5200","24.9048","24.7051","16.4920","11.9935","44.9757"
"49.6000","24.9453","24.7456","16.5191","11.9817","44.9312"
"49.6800","24.9843","24.7847","16.5451","11.9660","44.8725"
"49.7600","25.0239","24.8243","16.5716","11.9596","44.8485"
"49.8400","25.0657","24.8661","16.5995","11.9473","44.8023"
"49.9200","25.1056","24.9059","16.6261","11.9406","44.7774"
"50.0000","25.1448","24.9452","16.6523","11.9348","44.7555"
"50.0800","25.1833","24.9836","16.6779","11.9283","44.7313"
"50.1600","25.2246","25.0250","16.7055","11.9217","44.7064"
"50.2400","25.2652","25.0655","16.7326","11.9109","44.6657"
"50.3200","25.3041","25.1044","16.7586","11.8972","44.6147"
"50.4000","25.3444","25.1447","16.7855","11.8781","44.5428"
"50.4800","25.3853","25.1857","16.8128","11.8667","44.5000"
"50.5600","25.4248","25.2251","16.8392","11.8480","44.4299"
"50.6400","25.4649","25.2652","16.8659","11.8354","44.3827"
"50.7200","25.5037","25.3040","16.8918","11.8192","44.3220"
"50.8000","25.5447","25.3451","16.9192","11.8040","44.2651"
"50.8800","25.5846","25.3850","16.9459","11.7754","44.1576"
"50.9600","25.6244","25.4247","16.9724","11.7545","44.0795"
"51.0400","25.6641","25.4645","16.9989","11.7406","44.0273"
"51.1200","25.7052","25.5055","17.0263","11.7297","43.9864"
"51.2000","25.7449","25.5452","17.0529","11.7189","43.9457"
"51.2800","25.7842","25.5845","17.0791","11.7059","43.8970"
"51.3600","25.8244","25.6248","17.1059","11.6991","43.8717"
"51.4400","25.8653","25.6656","17.1332","11.6865","43.8243"
"51.5200","25.9039","25.7042","17.1590","11.6817","43.8065"
"51.6000","25.9445","25.7448","17.1861","11.6725","43.7719"
"51.6800","25.9850","25.7853","17.2131","11.6696","43.7609"
"51.7600","26.0252","25.8255","17.2399","11.6559","43.7095"
"51.8400","26.0642","25.8646","17.2660","11.6474","43.6778"
"51.9200","26.1040","25.9043","17.2926","11.6341","43.6280"
"52.0000","26.1448","25.9451","17.3198","11.6287","43.6076"
"52.0800","26.1849","25.9852","17.3466","11.6222","43.5834"
"52.1600","26.2235","26.0238","17.3723","11.6161","43.5604"
"52.2400","26.2645","26.0649","17.3997","11.6031","43.5115"
"52.3200","26.3055","26.1059","17.4271","11.5926","43.4723"
"52.4000","26.3453","26.1456","17.4536","11.5881","43.4554"
"52.4800","26.3843","26.1847","17.4797","11.5819","43.4320"
"52.5600","26.4235","26.2238","17.5058","11.5791","43.4218"
"52.6400","26.4649","26.2652","17.5335","11.5751","43.4068"
"52.7200","26.5047","26.3050","17.5600","11.5766","43.4121"
"52.8000","26.5442","26.3445","17.5864","11.5721","43.3955"
"52.8800","26.5840","26.3843","17.6130","11.5766","43.4123"
"52.9600","26.6253","26.4256","17.6406","11.5698","43.3867"
"53.0400","26.6655","26.4659","17.6674","11.5669","43.3757"
"53.1200","26.7039","26.5042","17.6930","11.5612","43.3545"
"53.2000","26.7435","26.5439","17.7195","11.5606","43.3521"
"53.2800","26.7849","26.5852","17.7471","11.5554","43.3327"
"53.3600","26.8249","26.6252","17.7738","11.5537","43.3265"
"53.4400","26.8643","26.6647","17.8001","11.5500","43.3124"
"53.5200","26.9038","26.7041","17.8265","11.5515","43.3181"
"53.6000","26.9458","26.7461","17.8545","11.5475","43.3033"
"53.6800","26.9854","26.7857","17.8810","11.5435","43.2880"
"53.7600","27.0242","26.8246","17.9069","11.5435","43.2881"
"53.8400","27.0644","26.8647","17.9337","11.5342","43.2534"
"53.9200","27.1047","26.9050","17.9606","11.5282","43.2308"
"54.0000","27.1453","26.9456","17.9877","11.5061","43.1477"
"54.0800","27.1844","26.9847","18.0138","11.4873","43.0773"
"54.1600","27.2246","27.0249","18.0406","11.4634","42.9878"
"54.2400","27.2663","27.0666","18.0684","11.4624","42.9841"
"54.3200","27.3045","27.1048","18.0939","11.4622","42.9831"
"54.4000","27.3447","27.1450","18.1208","11.4626","42.9849"
"54.4800","27.3841","27.1844","18.1471","11.4630","42.9862"
"54.5600","27.4247","27.2250","18.1742","11.4622","42.9833"
"54.6400","27.4647","27.2650","18.2009","11.4627","42.9853"
"54.7200","27.5037","27.3040","18.2269","11.4615","42.9805"
"54.8000","27.5448","27.3452","18.2544","11.4646","42.9922"
"54.8800","27.5854","27.3858","18.2815","11.4631","42.9867"
"54.9600","27.6244","27.4247","18.3075","11.4623","42.9837"
"55.0400","27.6645","27.4648","18.3343","11.4605","42.9770"
"55.1200","27.7037","27.5041","18.3605","11.4618","42.9817"
"55.2000","27.7452","27.5456","18.3882","11.4606","42.9774"
"55.2800","27.7840","27.5844","18.4141","11.4646","42.9922"
"55.3600","27.8241","27.6244","18.4408","11.4601","42.9754"
"55.4400","27.8656","27.6659","18.4685","11.4584","42.9690"
"55.5200","27.9049","27.7053","18.4948","11.4515","42.9430"
"55.6000","27.9447","27.7450","18.5213","11.4525","42.9468"
"55.6800","27.9840","27.7843","18.5475","11.4443","42.9160"
"55.7600","28.0247","27.8251","18.5748","11.4377","42.8913"
"55.8400","28.0652","27.8655","18.6018","11.4373","42.8898"
"55.9200","28.1042","27.9046","18.6278","11.4389","42.8958"
"56.0000","28.1440","27.9443","18.6544","11.4405","42.9020"
"56.0800","28.1855","27.9858","18.6821","11.4402","42.9009"
"56.1600","28.2251","28.0254","18.7085","11.4446","42.9172"
"56.2400","28.2648","28.0651","18.7350","11.4443","42.9160"
"56.3200","28.3035","28.1039","18.7609","11.4524","42.9466"
"56.4000","28.3452","28.1455","18.7887","11.4487","42.9328"
"56.4800","28.3849","28.1852","18.8152","11.4539","42.9523"
"56.5600","28.4238","28.2242","18.8412","11.4560","42.9599"
"56.6400","28.4646","28.2649","18.8684","11.4600","42.9748"
"56.7200","28.5056","28.3059","18.8957","11.4610","42.9786"
"56.8000","28.5454","28.3458","18.9224","11.4610","42.9786"
"56.8800","28.5846","28.3849","18.9485","11.4649","42.9933"
"56.9600","28.6235","28.4238","18.9745","11.4648","42.9928"
"57.0400","28.6651","28.4654","19.0022","11.4639","42.9896"
"57.1200","28.7046","28.5049","19.0286","11.4641","42.9904"
"57.2000","28.7445","28.5448","19.0553","11.4646","42.9922"
"57.2800","28.7846","28.5849","19.0820","11.4604","42.9766"
"57.3600","28.8251","28.6254","19.1090","11.4611","42.9791"
"57.4400","28.8650","28.6653","19.1357","11.4512","42.9421"
"57.5200","28.9045","28.7049","19.1621","11.4477","42.9288"
"57.6000","28.9438","28.7442","19.1883","11.4404","42.9014"
"57.6800","28.9845","28.7848","19.2155","11.4438","42.9143"
"57.7600","29.0246","28.8249","19.2422","11.4446","42.9172"
"57.8400","29.0650","28.8653","19.2692","11.4468","42.9254"
"57.9200","29.1046","28.9049","19.2956","11.4544","42.9542"
"58.0000","29.1457","28.9460","19.3231","11.4528","42.9478"
"58.0800","29.1851","28.9854","19.3494","11.4568","42.9631"
"58.1600","29.2240","29.0244","19.3754","11.4582","42.9682"
"58.2400","29.2646","29.0649","19.4024","11.4645","42.9918"
"58.3200","29.3051","29.1054","19.4295","11.4650","42.9936"
"58.4000","29.3439","29.1442","19.4554","11.4712","43.0169"
"58.4800","29.3843","29.1846","19.4823","11.4702","43.0131"
"58.5600","29.4249","29.2252","19.5094","11.4728","43.0231"
"58.6400","29.4653","29.2657","19.5364","11.4756","43.0334"
"58.7200","29.5039","29.3042","19.5622","11.4790","43.0462"
"58.8000","29.5442","29.3445","19.5891","11.4772","43.0395"
"58.8800","29.5845","29.3849","19.6160","11.4786","43.0449"
"58.9600","29.6247","29.4251","19.6429","11.4816","43.0558"
"59.0400","29.6640","29.4643","19.6691","11.4823","43.0586"
"59.1200","29.7037","29.5040","19.6956","11.4835","43.0631"
"59.2000","29.7459","29.5463","19.7238","11.4817","43.0563"
"59.2800","29.7856","29.5859","19.7502","11.4861","43.0729"
"59.3600","29.8238","29.6241","19.7758","11.4868","43.0753"
"59.4400","29.8642","29.6645","19.8027","11.4903","43.0885"
"59.5200","29.9050","29.7053","19.8300","11.4865","43.0743"
"59.6000","29.9451","29.7455","19.8567","11.4878","43.0791"
"59.6800","29.9839","29.7842","19.8826","11.4867","43.0750"
"59.7600","30.0245","29.8248","19.9097","11.4887","43.0825"
"59.8400","30.0656","29.8660","19.9372","11.4861","43.0728"
"59.9200","30.1050","29.9053","19.9634","11.4863","43.0735"
"60.0000","30.1447","29.9451","19.9900","11.4859","43.0722"
"60.0300","30.1599","29.9602","20.0001","11.4838","43.0641"