File: data/instron_tests/241217_metamaterial_foam_test_data/241217_metamaterial_foams_3_1.csv
Results Table 1


Results Table 2


Time,Displacement,Compressive displacement,Compressive strain (Displacement),Compressive stress,Force
(s),(mm),(mm),(%),(kPa),(N)
"0.0000","0.1683","-0.0100","-0.0067","-0.0160","-0.0600"
"0.0800","0.1719","-0.0064","-0.0043","-0.0027","-0.0100"
"0.1600","0.2042","0.0259","0.0173","0.0934","0.3503"
"0.2400","0.2453","0.0670","0.0447","0.2159","0.8097"
"0.3200","0.2842","0.1059","0.0707","0.3179","1.1921"
"0.4000","0.3229","0.1446","0.0965","0.4279","1.6045"
"0.4800","0.3626","0.1843","0.1230","0.5335","2.0005"
"0.5600","0.4034","0.2251","0.1503","0.6438","2.4143"
"0.6400","0.4433","0.2650","0.1769","0.7456","2.7961"
"0.7200","0.4830","0.3047","0.2034","0.8506","3.1897"
"0.8000","0.5230","0.3446","0.2300","0.9540","3.5776"
"0.8800","0.5643","0.3860","0.2576","1.0616","3.9810"
"0.9600","0.6032","0.4249","0.2836","1.1586","4.3448"
"1.0400","0.6430","0.4647","0.3102","1.2647","4.7426"
"1.1200","0.6831","0.5048","0.3369","1.3685","5.1317"
"1.2000","0.7236","0.5453","0.3640","1.4730","5.5237"
"1.2800","0.7630","0.5847","0.3903","1.5749","5.9060"
"1.3600","0.8029","0.6246","0.4169","1.6750","6.2813"
"1.4400","0.8439","0.6656","0.4443","1.7856","6.6958"
"1.5200","0.8845","0.7062","0.4713","1.8867","7.0752"
"1.6000","0.9225","0.7442","0.4967","1.9864","7.4490"
"1.6800","0.9633","0.7850","0.5239","2.0894","7.8353"
"1.7600","1.0031","0.8247","0.5505","2.1944","8.2288"
"1.8400","1.0438","0.8655","0.5777","2.2984","8.6191"
"1.9200","1.0830","0.9047","0.6039","2.4009","9.0034"
"2.0000","1.1222","0.9439","0.6300","2.4999","9.3748"
"2.0800","1.1645","0.9861","0.6582","2.6095","9.7856"
"2.1600","1.2039","1.0255","0.6845","2.7125","10.1719"
"2.2400","1.2430","1.0647","0.7106","2.8118","10.5443"
"2.3200","1.2823","1.1040","0.7369","2.9158","10.9342"
"2.4000","1.3230","1.1447","0.7641","3.0212","11.3294"
"2.4800","1.3638","1.1855","0.7912","3.1311","11.7415"
"2.5600","1.4023","1.2240","0.8170","3.2285","12.1068"
"2.6400","1.4430","1.2647","0.8441","3.3359","12.5095"
"2.7200","1.4845","1.3062","0.8718","3.4429","12.9107"
"2.8000","1.5234","1.3450","0.8978","3.5473","13.3024"
"2.8800","1.5631","1.3848","0.9243","3.6459","13.6723"
"2.9600","1.6024","1.4240","0.9505","3.7536","14.0759"
"3.0400","1.6438","1.4654","0.9781","3.8572","14.4643"
"3.1200","1.6841","1.5057","1.0050","3.9606","14.8522"
"3.2000","1.7226","1.5442","1.0307","4.0602","15.2256"
"3.2800","1.7623","1.5840","1.0573","4.1676","15.6285"
"3.3600","1.8039","1.6256","1.0850","4.2754","16.0328"
"3.4400","1.8442","1.6659","1.1119","4.3825","16.4345"
"3.5200","1.8834","1.7050","1.1380","4.4884","16.8315"
"3.6000","1.9222","1.7439","1.1640","4.5883","17.2061"
"3.6800","1.9638","1.7855","1.1917","4.6980","17.6175"
"3.7600","2.0035","1.8252","1.2183","4.8008","18.0029"
"3.8400","2.0430","1.8647","1.2446","4.9071","18.4015"
"3.9200","2.0833","1.9050","1.2715","5.0112","18.7921"
"4.0000","2.1240","1.9457","1.2987","5.1235","19.2129"
"4.0800","2.1636","1.9853","1.3251","5.2227","19.5852"
"4.1600","2.2032","2.0249","1.3515","5.3275","19.9780"
"4.2400","2.2428","2.0645","1.3780","5.4335","20.3758"
"4.3200","2.2837","2.1054","1.4053","5.5436","20.7885"
"4.4000","2.3228","2.1445","1.4314","5.6424","21.1589"
"4.4800","2.3633","2.1850","1.4584","5.7518","21.5692"
"4.5600","2.4035","2.2252","1.4852","5.8595","21.9731"
"4.6400","2.4440","2.2657","1.5123","5.9656","22.3710"
"4.7200","2.4833","2.3050","1.5385","6.0720","22.7698"
"4.8000","2.5227","2.3444","1.5648","6.1730","23.1489"
"4.8800","2.5637","2.3854","1.5921","6.2870","23.5762"
"4.9600","2.6032","2.4249","1.6185","6.3888","23.9578"
"5.0400","2.6428","2.4645","1.6450","6.4969","24.3634"
"5.1200","2.6834","2.5051","1.6720","6.6012","24.7544"
"5.2000","2.7236","2.5453","1.6989","6.7128","25.1730"
"5.2800","2.7643","2.5859","1.7260","6.8187","25.5701"
"5.3600","2.8031","2.6248","1.7520","6.9215","25.9556"
"5.4400","2.8426","2.6643","1.7783","7.0274","26.3527"
"5.5200","2.8839","2.7056","1.8059","7.1386","26.7697"
"5.6000","2.9235","2.7452","1.8323","7.2469","27.1759"
"5.6800","2.9627","2.7843","1.8584","7.3526","27.5722"
"5.7600","3.0026","2.8243","1.8851","7.4590","27.9713"
"5.8400","3.0444","2.8661","1.9130","7.5708","28.3904"
"5.9200","3.0840","2.9057","1.9394","7.6806","28.8023"
"6.0000","3.1227","2.9444","1.9653","7.7848","29.1929"
"6.0800","3.1628","2.9845","1.9920","7.8931","29.5991"
"6.1600","3.2032","3.0249","2.0190","8.0026","30.0097"
"6.2400","3.2438","3.0655","2.0461","8.1117","30.4190"
"6.3200","3.2827","3.1044","2.0721","8.2146","30.8049"
"6.4000","3.3224","3.1441","2.0985","8.3255","31.2207"
"6.4800","3.3641","3.1858","2.1264","8.4355","31.6331"
"6.5600","3.4041","3.2258","2.1531","8.5432","32.0371"
"6.6400","3.4427","3.2644","2.1788","8.6476","32.4286"
"6.7200","3.4824","3.3041","2.2053","8.7579","32.8420"
"6.8000","3.5233","3.3449","2.2326","8.8672","33.2521"
"6.8800","3.5640","3.3857","2.2598","8.9767","33.6626"
"6.9600","3.6029","3.4245","2.2857","9.0837","34.0640"
"7.0400","3.6429","3.4646","2.3125","9.1919","34.4696"
"7.1200","3.6842","3.5058","2.3400","9.3062","34.8982"
"7.2000","3.7238","3.5455","2.3664","9.4131","35.2992"
"7.2800","3.7634","3.5851","2.3929","9.5240","35.7149"
"7.3600","3.8022","3.6239","2.4188","9.6266","36.0997"
"7.4400","3.8436","3.6653","2.4464","9.7447","36.5427"
"7.5200","3.8833","3.7050","2.4730","9.8506","36.9398"
"7.6000","3.9231","3.7448","2.4995","9.9611","37.3541"
"7.6800","3.9637","3.7853","2.5266","10.0739","37.7771"
"7.7600","4.0040","3.8257","2.5535","10.1842","38.1909"
"7.8400","4.0431","3.8648","2.5796","10.2927","38.5978"
"7.9200","4.0838","3.9055","2.6068","10.4030","39.0112"
"8.0000","4.1227","3.9444","2.6327","10.5127","39.4228"
"8.0800","4.1645","3.9862","2.6606","10.6298","39.8616"
"8.1600","4.2030","4.0247","2.6863","10.7364","40.2615"
"8.2400","4.2427","4.0644","2.7128","10.8437","40.6639"
"8.3200","4.2835","4.1052","2.7401","10.9621","41.1079"
"8.4000","4.3240","4.1456","2.7670","11.0719","41.5197"
"8.4800","4.3630","4.1847","2.7931","11.1829","41.9359"
"8.5600","4.4025","4.2242","2.8195","11.2878","42.3293"
"8.6400","4.4429","4.2646","2.8465","11.4036","42.7636"
"8.7200","4.4838","4.3054","2.8737","11.5187","43.1952"
"8.8000","4.5218","4.3435","2.8991","11.6246","43.5923"
"8.8800","4.5636","4.3853","2.9270","11.7415","44.0306"
"8.9600","4.6042","4.4259","2.9541","11.8538","44.4516"
"9.0400","4.6440","4.4657","2.9807","11.9676","44.8787"
"9.1200","4.6832","4.5048","3.0068","12.0742","45.2784"
"9.2000","4.7222","4.5439","3.0329","12.1837","45.6889"
"9.2800","4.7642","4.5859","3.0609","12.2982","46.1184"
"9.3600","4.8033","4.6250","3.0870","12.4129","46.5483"
"9.4400","4.8426","4.6643","3.1132","12.5217","46.9564"
"9.5200","4.8829","4.7046","3.1401","12.6355","47.3832"
"9.6000","4.9241","4.7457","3.1676","12.7506","47.8148"
"9.6800","4.9640","4.7856","3.1942","12.8629","48.2359"
"9.7600","5.0031","4.8248","3.2203","12.9727","48.6474"
"9.8400","5.0419","4.8636","3.2463","13.0834","49.0629"
"9.9200","5.0832","4.9049","3.2738","13.2008","49.5029"
"10.0000","5.1230","4.9447","3.3004","13.3111","49.9167"
"10.0800","5.1631","4.9848","3.3272","13.4268","50.3505"
"10.1600","5.2025","5.0242","3.3534","13.5371","50.7642"
"10.2400","5.2438","5.0655","3.3810","13.6568","51.2131"
"10.3200","5.2839","5.1055","3.4077","13.7656","51.6208"
"10.4000","5.3230","5.1447","3.4339","13.8797","52.0490"
"10.4800","5.3626","5.1843","3.4603","13.9921","52.4703"
"10.5600","5.4035","5.2252","3.4876","14.1101","52.9128"
"10.6400","5.4433","5.2649","3.5141","14.2229","53.3360"
"10.7200","5.4830","5.3047","3.5407","14.3345","53.7544"
"10.8000","5.5231","5.3448","3.5674","14.4509","54.1908"
"10.8800","5.5645","5.3862","3.5951","14.5743","54.6538"
"10.9600","5.6033","5.4250","3.6209","14.6838","55.0641"
"11.0400","5.6431","5.4648","3.6475","14.7998","55.4991"
"11.1200","5.6828","5.5045","3.6740","14.9130","55.9239"
"11.2000","5.7236","5.5453","3.7012","15.0327","56.3726"
"11.2800","5.7629","5.5846","3.7275","15.1443","56.7911"
"11.3600","5.8028","5.6245","3.7541","15.2574","57.2151"
"11.4400","5.8437","5.6654","3.7814","15.3794","57.6728"
"11.5200","5.8844","5.7061","3.8086","15.4940","58.1025"
"11.6000","5.9225","5.7442","3.8340","15.6054","58.5201"
"11.6800","5.9632","5.7849","3.8612","15.7227","58.9603"
"11.7600","6.0034","5.8251","3.8880","15.8420","59.4073"
"11.8400","6.0436","5.8653","3.9148","15.9573","59.8399"
"11.9200","6.0829","5.9046","3.9411","16.0736","60.2759"
"12.0000","6.1225","5.9442","3.9675","16.1868","60.7006"
"12.0800","6.1641","5.9858","3.9953","16.3113","61.1673"
"12.1600","6.2041","6.0258","4.0220","16.4263","61.5987"
"12.2400","6.2431","6.0647","4.0480","16.5401","62.0253"
"12.3200","6.2823","6.1040","4.0742","16.6560","62.4602"
"12.4000","6.3230","6.1447","4.1013","16.7747","62.9051"
"12.4800","6.3640","6.1857","4.1287","16.8965","63.3619"
"12.5600","6.4026","6.2243","4.1545","17.0091","63.7842"
"12.6400","6.4425","6.2642","4.1811","17.1288","64.2330"
"12.7200","6.4843","6.3060","4.2090","17.2498","64.6868"
"12.8000","6.5237","6.3454","4.2353","17.3661","65.1228"
"12.8800","6.5631","6.3848","4.2616","17.4833","65.5624"
"12.9600","6.6025","6.4241","4.2879","17.5991","65.9966"
"13.0400","6.6441","6.4658","4.3157","17.7250","66.4686"
"13.1200","6.6841","6.5057","4.3423","17.8418","66.9068"
"13.2000","6.7230","6.5447","4.3683","17.9581","67.3431"
"13.2800","6.7619","6.5835","4.3942","18.0738","67.7769"
"13.3600","6.8042","6.6259","4.4225","18.2021","68.2580"
"13.4400","6.8441","6.6658","4.4492","18.3190","68.6963"
"13.5200","6.8834","6.7051","4.4754","18.4361","69.1353"
"13.6000","6.9223","6.7440","4.5013","18.5502","69.5634"
"13.6800","6.9642","6.7859","4.5293","18.6766","70.0371"
"13.7600","7.0031","6.8248","4.5553","18.7902","70.4632"
"13.8400","7.0429","6.8646","4.5818","18.9120","70.9201"
"13.9200","7.0835","6.9052","4.6090","19.0328","71.3730"
"14.0000","7.1237","6.9454","4.6358","19.1565","71.8371"
"14.0800","7.1642","6.9859","4.6628","19.2794","72.2977"
"14.1600","7.2029","7.0246","4.6886","19.3946","72.7298"
"14.2400","7.2429","7.0646","4.7153","19.5177","73.1915"
"14.3200","7.2841","7.1058","4.7428","19.6442","73.6657"
"14.4000","7.3221","7.1438","4.7682","19.7540","74.0776"
"14.4800","7.3634","7.1851","4.7958","19.8795","74.5482"
"14.5600","7.4033","7.2250","4.8224","20.0053","75.0198"
"14.6400","7.4441","7.2658","4.8496","20.1281","75.4804"
"14.7200","7.4832","7.3049","4.8757","20.2492","75.9343"
"14.8000","7.5226","7.3442","4.9020","20.3633","76.3624"
"14.8800","7.5634","7.3850","4.9292","20.4919","76.8445"
"14.9600","7.6029","7.4246","4.9556","20.6097","77.2862"
"15.0400","7.6429","7.4646","4.9823","20.7359","77.7596"
"15.1200","7.6831","7.5047","5.0091","20.8557","78.2088"
"15.2000","7.7234","7.5451","5.0361","20.9825","78.6844"
"15.2800","7.7645","7.5862","5.0635","21.1057","79.1462"
"15.3600","7.8030","7.6247","5.0892","21.2268","79.6006"
"15.4400","7.8427","7.6644","5.1157","21.3491","80.0592"
"15.5200","7.8834","7.7050","5.1428","21.4762","80.5357"
"15.6000","7.9236","7.7453","5.1697","21.5985","80.9944"
"15.6800","7.9630","7.7847","5.1960","21.7223","81.4586"
"15.7600","8.0029","7.8246","5.2226","21.8439","81.9145"
"15.8400","8.0443","7.8660","5.2502","21.9734","82.4002"
"15.9200","8.0844","7.9061","5.2770","22.0981","82.8681"
"16.0000","8.1226","7.9443","5.3025","22.2133","83.3000"
"16.0800","8.1625","7.9842","5.3291","22.3393","83.7725"
"16.1600","8.2038","8.0255","5.3567","22.4712","84.2671"
"16.2400","8.2437","8.0654","5.3833","22.5938","84.7266"
"16.3200","8.2829","8.1045","5.4095","22.7131","85.1742"
"16.4000","8.3221","8.1438","5.4356","22.8375","85.6406"
"16.4800","8.3645","8.1862","5.4640","22.9699","86.1372"
"16.5600","8.4038","8.2255","5.4902","23.0930","86.5986"
"16.6400","8.4420","8.2637","5.5157","23.2103","87.0385"
"16.7200","8.4821","8.3037","5.5424","23.3364","87.5116"
"16.8000","8.5234","8.3451","5.5700","23.4676","88.0036"
"16.8800","8.5636","8.3853","5.5968","23.5916","88.4684"
"16.9600","8.6030","8.4247","5.6231","23.7175","88.9407"
"17.0400","8.6431","8.4648","5.6499","23.8439","89.4147"
"17.1200","8.6844","8.5060","5.6774","23.9762","89.9106"
"17.2000","8.7242","8.5458","5.7040","24.0977","90.3662"
"17.2800","8.7633","8.5850","5.7301","24.2238","90.8391"
"17.3600","8.8025","8.6242","5.7563","24.3447","91.2926"
"17.4400","8.8437","8.6653","5.7838","24.4813","91.8050"
"17.5200","8.8836","8.7053","5.8105","24.6024","92.2590"
"17.6000","8.9231","8.7447","5.8368","24.7273","92.7272"
"17.6800","8.9635","8.7852","5.8637","24.8567","93.2126"
"17.7600","9.0041","8.8258","5.8909","24.9906","93.7149"
"17.8400","9.0435","8.8651","5.9171","25.1156","94.1835"
"17.9200","9.0835","8.9051","5.9438","25.2389","94.6458"
"18.0000","9.1225","8.9441","5.9699","25.3671","95.1266"
"18.0800","9.1637","8.9854","5.9974","25.4993","95.6224"
"18.1600","9.2028","9.0245","6.0235","25.6230","96.0862"
"18.2400","9.2432","9.0649","6.0505","25.7503","96.5637"
"18.3200","9.2835","9.1052","6.0774","25.8841","97.0654"
"18.4000","9.3235","9.1452","6.1041","26.0105","97.5392"
"18.4800","9.3630","9.1846","6.1304","26.1382","98.0182"
"18.5600","9.4027","9.2244","6.1569","26.2621","98.4831"
"18.6400","9.4430","9.2647","6.1838","26.3959","98.9846"
"18.7200","9.4838","9.3055","6.2111","26.5276","99.4786"
"18.8000","9.5222","9.3439","6.2367","26.6515","99.9430"
"18.8800","9.5630","9.3847","6.2639","26.7841","100.4403"
"18.9600","9.6042","9.4259","6.2914","26.9171","100.9390"
"19.0400","9.6437","9.4654","6.3178","27.0465","101.4242"
"19.1200","9.6834","9.5051","6.3443","27.1770","101.9137"
"19.2000","9.7224","9.5441","6.3703","27.3044","102.3915"
"19.2800","9.7641","9.5858","6.3982","27.4402","102.9007"
"19.3600","9.8036","9.6253","6.4245","27.5674","103.3779"
"19.4400","9.8427","9.6644","6.4506","27.6965","103.8617"
"19.5200","9.8830","9.7047","6.4775","27.8277","104.3538"
"19.6000","9.9241","9.7458","6.5049","27.9616","104.8561"
"19.6800","9.9645","9.7862","6.5319","28.0955","105.3582"
"19.7600","10.0032","9.8249","6.5577","28.2197","105.8239"
"19.8400","10.0418","9.8635","6.5835","28.3465","106.2992"
"19.9200","10.0836","9.9052","6.6113","28.4842","106.8157"
"20.0000","10.1233","9.9450","6.6379","28.6143","107.3035"
"20.0800","10.1631","9.9848","6.6644","28.7481","107.8054"
"20.1600","10.2019","10.0236","6.6903","28.8716","108.2686"
"20.2400","10.2439","10.0656","6.7184","29.0122","108.7956"
"20.3200","10.2837","10.1054","6.7450","29.1397","109.2739"
"20.4000","10.3225","10.1442","6.7708","29.2694","109.7601"
"20.4800","10.3627","10.1844","6.7977","29.4018","110.2568"
"20.5600","10.4032","10.2249","6.8247","29.5378","110.7669"
"20.6400","10.4431","10.2648","6.8514","29.6709","111.2659"
"20.7200","10.4834","10.3050","6.8782","29.8074","111.7777"
"20.8000","10.5232","10.3449","6.9048","29.9393","112.2723"
"20.8800","10.5645","10.3862","6.9324","30.0799","112.7995"
"20.9600","10.6033","10.4250","6.9582","30.2042","113.2659"
"21.0400","10.6435","10.4652","6.9851","30.3406","113.7771"
"21.1200","10.6829","10.5046","7.0114","30.4708","114.2654"
"21.2000","10.7237","10.5454","7.0386","30.6090","114.7837"
"21.2800","10.7629","10.5846","7.0648","30.7395","115.2733"
"21.3600","10.8028","10.6245","7.0914","30.8698","115.7616"
"21.4400","10.8438","10.6655","7.1188","31.0141","116.3029"
"21.5200","10.8843","10.7060","7.1458","31.1484","116.8065"
"21.6000","10.9227","10.7444","7.1715","31.2770","117.2887"
"21.6800","10.9631","10.7848","7.1984","31.4091","117.7842"
"21.7600","11.0031","10.8248","7.2251","31.5470","118.3013"
"21.8400","11.0437","10.8654","7.2522","31.6847","118.8177"
"21.9200","11.0826","10.9043","7.2782","31.8140","119.3023"
"22.0000","11.1228","10.9445","7.3050","31.9470","119.8011"
"22.0800","11.1640","10.9857","7.3325","32.0913","120.3425"
"22.1600","11.2038","11.0255","7.3591","32.2252","120.8445"
"22.2400","11.2430","11.0647","7.3852","32.3571","121.3391"
"22.3200","11.2826","11.1043","7.4116","32.4920","121.8450"
"22.4000","11.3232","11.1449","7.4388","32.6302","122.3633"
"22.4800","11.3641","11.1858","7.4661","32.7713","122.8923"
"22.5600","11.4026","11.2243","7.4917","32.8990","123.3712"
"22.6400","11.4425","11.2642","7.5184","33.0388","123.8957"
"22.7200","11.4844","11.3061","7.5464","33.1807","124.4276"
"22.8000","11.5235","11.3452","7.5725","33.3166","124.9373"
"22.8800","11.5635","11.3851","7.5991","33.4514","125.4429"
"22.9600","11.6022","11.4239","7.6250","33.5862","125.9482"
"23.0400","11.6431","11.4648","7.6523","33.7258","126.4716"
"23.1200","11.6837","11.5054","7.6794","33.8678","127.0043"
"23.2000","11.7229","11.5446","7.7056","33.9986","127.4949"
"23.2800","11.7626","11.5843","7.7321","34.1361","128.0105"
"23.3600","11.8044","11.6261","7.7599","34.2776","128.5411"
"23.4400","11.8441","11.6657","7.7864","34.4135","129.0507"
"23.5200","11.8834","11.7051","7.8127","34.5475","129.5532"
"23.6000","11.9222","11.7438","7.8386","34.6820","130.0575"
"23.6800","11.9642","11.7858","7.8666","34.8337","130.6264"
"23.7600","12.0033","11.8250","7.8927","34.9639","131.1148"
"23.8400","12.0428","11.8645","7.9191","35.1029","131.6358"
"23.9200","12.0835","11.9052","7.9462","35.2459","132.1722"
"24.0000","12.1241","11.9457","7.9733","35.3917","132.7190"
"24.0800","12.1638","11.9855","7.9998","35.5264","133.2242"
"24.1600","12.2030","12.0247","8.0260","35.6615","133.7308"
"24.2400","12.2417","12.0633","8.0518","35.7956","134.2333"
"24.3200","12.2840","12.1057","8.0800","35.9479","134.8046"
"24.4000","12.3228","12.1445","8.1060","36.0796","135.2986"
"24.4800","12.3632","12.1849","8.1329","36.2202","135.8257"
"24.5600","12.4034","12.2251","8.1598","36.3644","136.3667"
"24.6400","12.4443","12.2660","8.1871","36.5067","136.9002"
"24.7200","12.4839","12.3055","8.2135","36.6479","137.4295"
"24.8000","12.5227","12.3444","8.2394","36.7784","137.9191"
"24.8800","12.5635","12.3852","8.2666","36.9277","138.4789"
"24.9600","12.6032","12.4249","8.2931","37.0640","138.9901"
"25.0400","12.6428","12.4645","8.3195","37.2033","139.5123"
"25.1200","12.6832","12.5049","8.3465","37.3440","140.0401"
"25.2000","12.7238","12.5455","8.3736","37.4894","140.5853"
"25.2800","12.7643","12.5860","8.4007","37.6323","141.1211"
"25.3600","12.8031","12.6247","8.4265","37.7658","141.6218"
"25.4400","12.8424","12.6641","8.4528","37.9009","142.1284"
"25.5200","12.8834","12.7051","8.4801","38.0473","142.6772"
"25.6000","12.9238","12.7455","8.5071","38.1931","143.2242"
"25.6800","12.9629","12.7845","8.5332","38.3288","143.7330"
"25.7600","13.0027","12.8244","8.5598","38.4671","144.2518"
"25.8400","13.0444","12.8661","8.5876","38.6147","144.8050"
"25.9200","13.0839","12.9056","8.6140","38.7541","145.3279"
"26.0000","13.1228","12.9445","8.6399","38.8850","145.8188"
"26.0800","13.1626","12.9843","8.6665","39.0269","146.3508"
"26.1600","13.2033","13.0250","8.6937","39.1695","146.8857"
"26.2400","13.2437","13.0654","8.7206","39.3124","147.4217"
"26.3200","13.2825","13.1042","8.7465","39.4445","147.9169"
"26.4000","13.3219","13.1435","8.7728","39.5854","148.4451"
"26.4800","13.3646","13.1862","8.8013","39.7370","149.0138"
"26.5600","13.4037","13.2253","8.8274","39.8692","149.5093"
"26.6400","13.4421","13.2638","8.8530","39.9993","149.9974"
"26.7200","13.4818","13.3035","8.8796","40.1370","150.5136"
"26.8000","13.5235","13.3452","8.9074","40.2864","151.0739"
"26.8800","13.5640","13.3857","8.9344","40.4251","151.5942"
"26.9600","13.6030","13.4247","8.9604","40.5609","152.1034"
"27.0400","13.6432","13.4648","8.9872","40.7003","152.6263"
"27.1200","13.6844","13.5061","9.0148","40.8450","153.1689"
"27.2000","13.7239","13.5456","9.0411","40.9779","153.6671"
"27.2800","13.7634","13.5851","9.0675","41.1138","154.1768"
"27.3600","13.8023","13.6240","9.0935","41.2467","154.6753"
"27.4400","13.8441","13.6658","9.1214","41.3955","155.2332"
"27.5200","13.8835","13.7052","9.1477","41.5259","155.7220"
"27.6000","13.9233","13.7449","9.1742","41.6618","156.2318"
"27.6800","13.9633","13.7850","9.2009","41.8002","156.7509"
"27.7600","14.0041","13.8258","9.2282","41.9390","157.2714"
"27.8400","14.0434","13.8650","9.2544","42.0682","157.7559"
"27.9200","14.0833","13.9049","9.2810","42.1990","158.2462"
"28.0000","14.1226","13.9442","9.3072","42.3322","158.7459"
"28.0800","14.1637","13.9854","9.3347","42.4700","159.2624"
"28.1600","14.2029","14.0246","9.3608","42.6003","159.7511"
"28.2400","14.2428","14.0645","9.3875","42.7307","160.2399"
"28.3200","14.2833","14.1050","9.4145","42.8706","160.7646"
"28.4000","14.3239","14.1455","9.4416","43.0018","161.2566"
"28.4800","14.3627","14.1844","9.4675","43.1320","161.7449"
"28.5600","14.4030","14.2246","9.4944","43.2591","162.2216"
"28.6400","14.4436","14.2652","9.5215","43.3960","162.7351"
"28.7200","14.4841","14.3058","9.5485","43.5263","163.2236"
"28.8000","14.5218","14.3435","9.5737","43.6421","163.6578"
"28.8800","14.5627","14.3843","9.6010","43.7765","164.1618"
"28.9600","14.6043","14.4260","9.6288","43.9104","164.6640"
"29.0400","14.6436","14.4653","9.6550","44.0351","165.1316"
"29.1200","14.6833","14.5050","9.6815","44.1599","165.5995"
"29.2000","14.7221","14.5437","9.7074","44.2791","166.0466"
"29.2800","14.7639","14.5856","9.7353","44.4151","166.5566"
"29.3600","14.8035","14.6252","9.7617","44.5383","167.0187"
"29.4400","14.8426","14.6643","9.7878","44.6544","167.4540"
"29.5200","14.8826","14.7043","9.8145","44.7796","167.9235"
"29.6000","14.9241","14.7457","9.8422","44.9072","168.4018"
"29.6800","14.9648","14.7864","9.8694","45.0334","168.8752"
"29.7600","15.0034","14.8251","9.8952","45.1452","169.2946"
"29.8400","15.0422","14.8639","9.9211","45.2589","169.7210"
"29.9200","15.0836","14.9053","9.9487","45.3771","170.1641"
"30.0000","15.1231","14.9448","9.9750","45.4897","170.5864"
"30.0800","15.1633","14.9850","10.0019","45.6077","171.0287"
"30.1600","15.2026","15.0243","10.0281","45.7121","171.4204"
"30.2400","15.2440","15.0656","10.0557","45.8327","171.8725"
"30.3200","15.2843","15.1059","10.0826","45.9407","172.2775"
"30.4000","15.3223","15.1439","10.1080","46.0402","172.6506"
"30.4800","15.3624","15.1841","10.1348","46.1478","173.0544"
"30.5600","15.4032","15.2249","10.1620","46.2590","173.4712"
"30.6400","15.4431","15.2648","10.1887","46.3625","173.8592"
"30.7200","15.4833","15.3050","10.2155","46.4701","174.2630"
"30.8000","15.5227","15.3444","10.2418","46.5721","174.6453"
"30.8800","15.5645","15.3862","10.2697","46.6829","175.0608"
"30.9600","15.6036","15.4253","10.2958","46.7771","175.4141"
"31.0400","15.6435","15.4652","10.3224","46.8747","175.7801"
"31.1200","15.6828","15.5044","10.3486","46.9708","176.1404"
"31.2000","15.7234","15.5451","10.3757","47.0693","176.5101"
"31.2800","15.7635","15.5852","10.4025","47.1624","176.8589"
"31.3600","15.8030","15.6247","10.4289","47.2521","177.1954"
"31.4400","15.8438","15.6655","10.4561","47.3513","177.5674"
"31.5200","15.8847","15.7063","10.4834","47.4435","177.9132"
"31.6000","15.9227","15.7444","10.5088","47.5216","178.2059"
"31.6800","15.9629","15.7846","10.5356","47.6074","178.5279"
"31.7600","16.0025","15.8242","10.5620","47.6930","178.8489"
"31.8400","16.0437","15.8654","10.5895","47.7792","179.1718"
"31.9200","16.0829","15.9046","10.6157","47.8585","179.4694"
"32.0000","16.1228","15.9445","10.6423","47.9339","179.7522"
"32.0800","16.1639","15.9856","10.6697","48.0207","180.0775"
"32.1600","16.2039","16.0256","10.6965","48.0926","180.3471"
"32.2400","16.2430","16.0647","10.7225","48.1558","180.5843"
"32.3200","16.2820","16.1037","10.7486","48.2183","180.8188"
"32.4000","16.3232","16.1449","10.7761","48.2917","181.0938"
"32.4800","16.3642","16.1859","10.8034","48.3638","181.3643"
"32.5600","16.4025","16.2242","10.8290","48.4093","181.5347"
"32.6400","16.4428","16.2645","10.8559","48.4707","181.7651"
"32.7200","16.4843","16.3060","10.8836","48.5354","182.0078"
"32.8000","16.5236","16.3453","10.9098","48.5831","182.1866"
"32.8800","16.5632","16.3849","10.9362","48.6307","182.3653"
"32.9600","16.6021","16.4238","10.9622","48.6766","182.5374"
"33.0400","16.6434","16.4651","10.9898","48.7253","182.7199"
"33.1200","16.6835","16.5052","11.0166","48.7693","182.8848"
"33.2000","16.7226","16.5442","11.0426","48.8006","183.0021"
"33.2800","16.7629","16.5846","11.0695","48.8364","183.1364"
"33.3600","16.8044","16.6261","11.0972","48.8713","183.2676"
"33.4400","16.8437","16.6654","11.1235","48.8906","183.3398"
"33.5200","16.8836","16.7052","11.1501","48.9151","183.4316"
"33.6000","16.9226","16.7443","11.1762","48.9332","183.4997"
"33.6800","16.9645","16.7862","11.2041","48.9595","183.5980"
"33.7600","17.0033","16.8250","11.2300","48.9636","183.6136"
"33.8400","17.0430","16.8646","11.2565","48.9760","183.6601"
"33.9200","17.0836","16.9053","11.2836","48.9809","183.6783"
"34.0000","17.1242","16.9458","11.3107","48.9857","183.6964"
"34.0800","17.1641","16.9858","11.3373","48.9809","183.6783"
"34.1600","17.2031","17.0248","11.3634","48.9684","183.6315"
"34.2400","17.2423","17.0640","11.3895","48.9549","183.5807"
"34.3200","17.2838","17.1054","11.4172","48.9387","183.5202"
"34.4000","17.3225","17.1442","11.4431","48.9069","183.4007"
"34.4800","17.3631","17.1848","11.4702","48.8765","183.2870"
"34.5600","17.4033","17.2250","11.4970","48.8329","183.1235"
"34.6400","17.4435","17.2652","11.5238","48.7849","182.9434"
"34.7200","17.4835","17.3052","11.5505","48.7374","182.7651"
"34.8000","17.5226","17.3443","11.5766","48.6777","182.5412"
"34.8800","17.5637","17.3853","11.6040","48.6254","182.3452"
"34.9600","17.6031","17.4248","11.6304","48.5520","182.0700"
"35.0400","17.6429","17.4646","11.6569","48.4742","181.7783"
"35.1200","17.6831","17.5048","11.6838","48.3888","181.4581"
"35.2000","17.7237","17.5454","11.7109","48.3125","181.1719"
"35.2800","17.7648","17.5864","11.7383","48.2236","180.8386"
"35.3600","17.8028","17.6245","11.7636","48.1186","180.4449"
"35.4400","17.8430","17.6647","11.7905","48.0182","180.0681"
"35.5200","17.8840","17.7057","11.8178","47.9101","179.6628"
"35.6000","17.9239","17.7455","11.8444","47.7897","179.2112"
"35.6800","17.9629","17.7845","11.8705","47.6545","178.7042"
"35.7600","18.0023","17.8239","11.8968","47.5210","178.2037"
"35.8400","18.0443","17.8660","11.9249","47.3876","177.7034"
"35.9200","18.0843","17.9060","11.9515","47.2341","177.1279"
"36.0000","18.1228","17.9445","11.9772","47.0678","176.5042"
"36.0800","18.1628","17.9845","12.0039","46.9016","175.8809"
"36.1600","18.2035","18.0252","12.0311","46.7143","175.1786"
"36.2400","18.2438","18.0655","12.0580","46.5116","174.4184"
"36.3200","18.2827","18.1044","12.0839","46.2963","173.6111"
"36.4000","18.3227","18.1444","12.1106","46.0805","172.8020"
"36.4800","18.3647","18.1864","12.1387","45.8451","171.9191"
"36.5600","18.4040","18.2257","12.1649","45.5708","170.8904"
"36.6400","18.4426","18.2643","12.1907","45.2884","169.8315"
"36.7200","18.4825","18.3042","12.2173","44.9774","168.6653"
"36.8000","18.5236","18.3453","12.2448","44.6028","167.2606"
"36.8800","18.5638","18.3855","12.2716","44.1869","165.7010"
"36.9600","18.6024","18.4240","12.2973","43.8070","164.2764"
"37.0400","18.6431","18.4648","12.3245","43.4346","162.8798"
"37.1200","18.6840","18.5057","12.3518","43.0554","161.4579"
"37.2000","18.7239","18.5456","12.3785","42.6444","159.9167"
"37.2800","18.7634","18.5851","12.4048","42.2405","158.4021"
"37.3600","18.8024","18.6241","12.4308","41.8171","156.8139"
"37.4400","18.8444","18.6661","12.4589","41.4377","155.3912"
"37.5200","18.8832","18.7049","12.4848","41.0443","153.9162"
"37.6000","18.9236","18.7453","12.5118","40.6162","152.3106"
"37.6800","18.9636","18.7853","12.5384","40.2061","150.7727"
"37.7600","19.0044","18.8261","12.5657","39.7822","149.1832"
"37.8400","19.0434","18.8651","12.5917","39.3823","147.6835"
"37.9200","19.0835","18.9052","12.6184","38.9869","146.2008"
"38.0000","19.1224","18.9441","12.6444","38.6120","144.7949"
"38.0800","19.1637","18.9854","12.6720","38.2092","143.2845"
"38.1600","19.2031","19.0248","12.6983","37.7925","141.7218"
"38.2400","19.2431","19.0647","12.7250","37.3897","140.2115"
"38.3200","19.2830","19.1047","12.7516","36.9860","138.6975"
"38.4000","19.3238","19.1455","12.7788","36.5762","137.1607"
"38.4800","19.3633","19.1850","12.8052","36.1962","135.7359"
"38.5600","19.4027","19.2244","12.8315","35.8032","134.2619"
"38.6400","19.4434","19.2651","12.8587","35.4108","132.7905"
"38.7200","19.4840","19.3057","12.8858","35.0416","131.4059"
"38.8000","19.5224","19.3441","12.9114","34.6783","130.0437"
"38.8800","19.5631","19.3847","12.9385","34.3343","128.7535"
"38.9600","19.6044","19.4261","12.9662","33.9828","127.4356"
"39.0400","19.6440","19.4656","12.9925","33.6535","126.2006"
"39.1200","19.6834","19.5051","13.0189","33.3200","124.9501"
"39.2000","19.7220","19.5437","13.0446","32.9817","123.6812"
"39.2800","19.7636","19.5853","13.0724","32.6578","122.4669"
"39.3600","19.8036","19.6252","13.0991","32.3488","121.3082"
"39.4400","19.8426","19.6643","13.1251","32.0304","120.1140"
"39.5200","19.8831","19.7048","13.1521","31.6673","118.7525"
"39.6000","19.9241","19.7458","13.1795","31.3303","117.4885"
"39.6800","19.9645","19.7861","13.2065","31.0018","116.2569"
"39.7600","20.0030","19.8246","13.2322","30.6591","114.9716"
"39.8400","20.0419","19.8635","13.2581","30.2768","113.5380"
"39.9200","20.0840","19.9056","13.2862","29.8648","111.9929"
"40.0000","20.1232","19.9449","13.3124","29.4410","110.4038"
"40.0800","20.1632","19.9849","13.3391","29.0669","109.0009"
"40.1600","20.2028","20.0245","13.3656","28.7076","107.6536"
"40.2400","20.2441","20.0658","13.3931","28.3855","106.4457"
"40.3200","20.2842","20.1059","13.4199","28.0425","105.1592"
"40.4000","20.3224","20.1440","13.4453","27.6521","103.6955"
"40.4800","20.3628","20.1844","13.4723","27.2241","102.0903"
"40.5600","20.4036","20.2252","13.4995","26.7651","100.3692"
"40.6400","20.4436","20.2653","13.5263","26.2940","98.6025"
"40.7200","20.4828","20.3044","13.5524","25.8655","96.9956"
"40.8000","20.5230","20.3447","13.5792","25.4761","95.5352"
"40.8800","20.5642","20.3859","13.6068","25.1022","94.1332"
"40.9600","20.6033","20.4249","13.6328","24.7751","92.9065"
"41.0400","20.6432","20.4649","13.6595","24.5091","91.9090"
"41.1200","20.6831","20.5048","13.6861","24.2459","90.9221"
"41.2000","20.7235","20.5452","13.7131","23.9834","89.9376"
"41.2800","20.7637","20.5853","13.7399","23.7714","89.1426"
"41.3600","20.8030","20.6247","13.7662","23.5727","88.3977"
"41.4400","20.8441","20.6658","13.7936","23.3946","87.7296"
"41.5200","20.8847","20.7063","13.8207","23.1979","86.9920"
"41.6000","20.9227","20.7444","13.8461","23.0046","86.2672"
"41.6800","20.9633","20.7850","13.8732","22.8211","85.5790"
"41.7600","21.0031","20.8248","13.8997","22.6502","84.9382"
"41.8400","21.0437","20.8654","13.9268","22.4745","84.2795"
"41.9200","21.0826","20.9043","13.9528","22.3013","83.6298"
"42.0000","21.1227","20.9444","13.9795","22.1071","82.9014"
"42.0800","21.1642","20.9859","14.0073","21.9397","82.2738"
"42.1600","21.2040","21.0256","14.0338","21.8047","81.7676"
"42.2400","21.2434","21.0651","14.0601","21.6995","81.3733"
"42.3200","21.2821","21.1038","14.0860","21.6089","81.0332"
"42.4000","21.3229","21.1446","14.1132","21.4840","80.5650"
"42.4800","21.3638","21.1855","14.1405","21.3870","80.2013"
"42.5600","21.4026","21.2243","14.1664","21.2811","79.8042"
"42.6400","21.4426","21.2643","14.1931","21.1773","79.4148"
"42.7200","21.4845","21.3062","14.2210","21.0649","78.9933"
"42.8000","21.5237","21.3454","14.2472","20.9672","78.6272"
"42.8800","21.5632","21.3849","14.2736","20.8821","78.3077"
"42.9600","21.6021","21.4237","14.2995","20.8202","78.0756"
"43.0400","21.6435","21.4652","14.3272","20.7568","77.8381"
"43.1200","21.6835","21.5051","14.3538","20.7008","77.6280"
"43.2000","21.7227","21.5444","14.3800","20.6527","77.4476"
"43.2800","21.7624","21.5840","14.4065","20.6010","77.2536"
"43.3600","21.8043","21.6260","14.4345","20.5435","77.0381"
"43.4400","21.8440","21.6657","14.4610","20.4808","76.8030"
"43.5200","21.8835","21.7052","14.4873","20.4033","76.5123"
"43.6000","21.9225","21.7442","14.5134","20.3040","76.1401"
"43.6800","21.9644","21.7861","14.5413","20.2322","75.8708"
"43.7600","22.0027","21.8244","14.5669","20.1593","75.5973"
"43.8400","22.0430","21.8647","14.5938","20.0852","75.3197"
"43.9200","22.0836","21.9053","14.6209","20.0243","75.0912"
"44.0000","22.1241","21.9458","14.6480","19.9763","74.9112"
"44.0800","22.1637","21.9854","14.6744","19.9194","74.6979"
"44.1600","22.2034","22.0251","14.7009","19.8736","74.5258"
"44.2400","22.2424","22.0641","14.7269","19.8247","74.3428"
"44.3200","22.2837","22.1054","14.7545","19.7853","74.1949"
"44.4000","22.3227","22.1444","14.7805","19.7367","74.0127"
"44.4800","22.3631","22.1848","14.8074","19.6881","73.8303"
"44.5600","22.4035","22.2252","14.8345","19.6504","73.6890"
"44.6400","22.4437","22.2654","14.8613","19.6097","73.5363"
"44.7200","22.4834","22.3051","14.8877","19.5756","73.4085"
"44.8000","22.5228","22.3445","14.9141","19.5373","73.2648"
"44.8800","22.5630","22.3847","14.9409","19.5112","73.1669"
"44.9600","22.6030","22.4247","14.9676","19.4826","73.0596"
"45.0400","22.6423","22.4639","14.9938","19.4574","72.9653"
"45.1200","22.6837","22.5054","15.0214","19.4211","72.8291"
"45.2000","22.7240","22.5457","15.0484","19.3848","72.6929"
"45.2800","22.7647","22.5864","15.0755","19.3545","72.5794"
"45.3600","22.8030","22.6247","15.1011","19.3247","72.4676"
"45.4400","22.8427","22.6644","15.1276","19.2913","72.3422"
"45.5200","22.8837","22.7054","15.1550","19.2678","72.2542"
"45.6000","22.9239","22.7455","15.1817","19.2423","72.1586"
"45.6800","22.9627","22.7844","15.2077","19.2162","72.0608"
"45.7600","23.0026","22.8243","15.2343","19.1850","71.9437"
"45.8400","23.0441","22.8658","15.2620","19.1519","71.8197"
"45.9200","23.0843","22.9059","15.2888","19.1219","71.7072"
"46.0000","23.1228","22.9445","15.3145","19.0886","71.5824"
"46.0800","23.1626","22.9842","15.3411","19.0613","71.4798"
"46.1600","23.2033","23.0250","15.3683","19.0301","71.3631"
"46.2400","23.2436","23.0653","15.3952","19.0051","71.2691"
"46.3200","23.2830","23.1047","15.4215","18.9771","71.1641"
"46.4000","23.3224","23.1441","15.4478","18.9587","71.0952"
"46.4800","23.3647","23.1863","15.4760","18.9303","70.9885"
"46.5600","23.4041","23.2257","15.5023","18.9112","70.9170"
"46.6400","23.4422","23.2638","15.5277","18.8911","70.8418"
"46.7200","23.4826","23.3043","15.5547","18.8732","70.7745"
"46.8000","23.5233","23.3450","15.5819","18.8537","70.7013"
"46.8800","23.5639","23.3856","15.6089","18.8196","70.5735"
"46.9600","23.6030","23.4247","15.6350","18.7873","70.4525"
"47.0400","23.6427","23.4644","15.6615","18.7420","70.2825"
"47.1200","23.6841","23.5058","15.6892","18.7119","70.1696"
"47.2000","23.7238","23.5454","15.7156","18.6814","70.0552"
"47.2800","23.7635","23.5851","15.7421","18.6641","69.9904"
"47.3600","23.8021","23.6238","15.7679","18.6421","69.9079"
"47.4400","23.8439","23.6656","15.7958","18.6303","69.8637"
"47.5200","23.8834","23.7051","15.8222","18.6096","69.7859"
"47.6000","23.9231","23.7447","15.8487","18.5922","69.7208"
"47.6800","23.9636","23.7853","15.8758","18.5786","69.6699"
"47.7600","24.0043","23.8260","15.9029","18.5642","69.6158"
"47.8400","24.0434","23.8651","15.9290","18.5450","69.5436"
"47.9200","24.0834","23.9051","15.9557","18.5093","69.4098"
"48.0000","24.1226","23.9443","15.9818","18.4806","69.3021"
"48.0800","24.1640","23.9856","16.0095","18.4421","69.1577"
"48.1600","24.2025","24.0242","16.0352","18.0317","67.6187"
"48.2400","24.2430","24.0647","16.0622","17.9910","67.4661"
"48.3200","24.2834","24.1051","16.0892","17.9434","67.2877"
"48.4000","24.3239","24.1456","16.1162","17.8895","67.0855"
"48.4800","24.3631","24.1847","16.1424","17.8480","66.9301"
"48.5600","24.4028","24.2245","16.1689","17.8176","66.8160"
"48.6400","24.4433","24.2649","16.1959","17.7975","66.7406"
"48.7200","24.4841","24.3058","16.2231","17.7748","66.6556"
"48.8000","24.5223","24.3440","16.2486","17.7436","66.5384"
"48.8800","24.5630","24.3847","16.2758","17.7234","66.4626"
"48.9600","24.6042","24.4259","16.3033","17.7019","66.3823"
"49.0400","24.6438","24.4655","16.3297","17.6842","66.3158"
"49.1200","24.6825","24.5042","16.3556","17.6672","66.2520"
"49.2000","24.7222","24.5438","16.3820","17.6474","66.1777"
"49.2800","24.7639","24.5856","16.4099","17.6350","66.1314"
"49.3600","24.8036","24.6252","16.4364","17.6217","66.0814"
"49.4400","24.8425","24.6642","16.4624","17.6039","66.0146"
"49.5200","24.8829","24.7045","16.4893","17.5906","65.9647"
"49.6000","24.9243","24.7459","16.5169","17.5671","65.8765"
"49.6800","24.9642","24.7859","16.5436","17.5485","65.8067"
"49.7600","25.0032","24.8249","16.5696","17.5241","65.7153"
"49.8400","25.0417","24.8634","16.5953","17.5115","65.6682"
"49.9200","25.0838","24.9055","16.6234","17.4952","65.6069"
"50.0000","25.1235","24.9452","16.6499","17.4793","65.5475"
"50.0800","25.1634","24.9851","16.6765","17.4729","65.5235"
"50.1600","25.2025","25.0242","16.7027","17.4644","65.4915"
"50.2400","25.2440","25.0657","16.7303","17.4480","65.4299"
"50.3200","25.2840","25.1057","16.7571","17.4341","65.3780"
"50.4000","25.3227","25.1444","16.7829","17.4266","65.3496"
"50.4800","25.3624","25.1840","16.8093","17.4157","65.3088"
"50.5600","25.4038","25.2255","16.8370","17.4093","65.2848"
"50.6400","25.4434","25.2651","16.8634","17.3939","65.2273"
"50.7200","25.4835","25.3052","16.8902","17.3834","65.1877"
"50.8000","25.5227","25.3444","16.9164","17.3699","65.1371"
"50.8800","25.5643","25.3860","16.9441","17.3597","65.0989"
"50.9600","25.6033","25.4250","16.9702","17.3320","64.9948"
"51.0400","25.6432","25.4649","16.9968","17.3053","64.8948"
"51.1200","25.6827","25.5044","17.0232","17.2938","64.8517"
"51.2000","25.7237","25.5453","17.0505","17.2815","64.8056"
"51.2800","25.7634","25.5851","17.0770","17.2663","64.7487"
"51.3600","25.8030","25.6247","17.1034","17.2537","64.7013"
"51.4400","25.8442","25.6659","17.1309","17.2492","64.6847"
"51.5200","25.8844","25.7061","17.1578","17.2345","64.6292"
"51.6000","25.9229","25.7446","17.1835","17.2287","64.6074"
"51.6800","25.9633","25.7850","17.2104","17.2148","64.5556"
"51.7600","26.0032","25.8249","17.2371","17.2054","64.5203"
"51.8400","26.0440","25.8657","17.2643","17.1966","64.4871"
"51.9200","26.0830","25.9047","17.2903","17.1851","64.4441"
"52.0000","26.1221","25.9438","17.3165","17.1650","64.3686"
"52.0800","26.1646","25.9862","17.3448","17.1612","64.3546"
"52.1600","26.2042","26.0259","17.3712","17.1479","64.3047"
"52.2400","26.2429","26.0646","17.3971","17.1428","64.2853"
"52.3200","26.2823","26.1040","17.4234","17.1356","64.2586"
"52.4000","26.3229","26.1446","17.4505","17.1252","64.2195"
"52.4800","26.3640","26.1857","17.4779","17.1109","64.1658"
"52.5600","26.4023","26.2240","17.5035","17.0975","64.1155"
"52.6400","26.4425","26.2642","17.5303","17.0854","64.0701"
"52.7200","26.4843","26.3060","17.5582","17.0691","64.0090"
"52.8000","26.5235","26.3452","17.5843","17.0573","63.9648"
"52.8800","26.5635","26.3852","17.6110","17.0353","63.8824"
"52.9600","26.6020","26.4237","17.6368","17.0174","63.8154"
"53.0400","26.6437","26.4654","17.6646","17.0072","63.7769"
"53.1200","26.6842","26.5059","17.6916","17.0013","63.7550"
"53.2000","26.7230","26.5446","17.7175","16.9934","63.7251"
"53.2800","26.7626","26.5843","17.7440","16.9861","63.6979"
"53.3600","26.8040","26.6257","17.7716","16.9733","63.6499"
"53.4400","26.8441","26.6658","17.7984","16.9572","63.5896"
"53.5200","26.8833","26.7049","17.8245","16.9512","63.5671"
"53.6000","26.9222","26.7439","17.8505","16.9359","63.5097"
"53.6800","26.9639","26.7856","17.8783","16.9322","63.4957"
"53.7600","27.0033","26.8250","17.9046","16.9157","63.4339"
"53.8400","27.0432","26.8649","17.9312","16.8990","63.3711"
"53.9200","27.0835","26.9052","17.9581","16.8873","63.3274"
"54.0000","27.1240","26.9457","17.9852","16.8734","63.2751"
"54.0800","27.1640","26.9857","18.0119","16.8606","63.2272"
"54.1600","27.2035","27.0252","18.0382","16.8493","63.1850"
"54.2400","27.2426","27.0643","18.0644","16.8398","63.1494"
"54.3200","27.2839","27.1055","18.0919","16.8224","63.0839"
"54.4000","27.3230","27.1446","18.1180","16.8041","63.0154"
"54.4800","27.3631","27.1848","18.1447","16.7838","62.9391"
"54.5600","27.4033","27.2250","18.1716","16.7771","62.9142"
"54.6400","27.4439","27.2656","18.1987","16.7571","62.8390"
"54.7200","27.4833","27.3050","18.2250","16.7475","62.8032"
"54.8000","27.5224","27.3441","18.2511","16.7303","62.7386"
"54.8800","27.5630","27.3847","18.2782","16.7181","62.6928"
"54.9600","27.6032","27.4249","18.3050","16.6983","62.6188"
"55.0400","27.6429","27.4646","18.3315","16.6855","62.5706"
"55.1200","27.6836","27.5052","18.3587","16.5446","62.0421"
"55.2000","27.7237","27.5454","18.3855","16.1406","60.5271"
"55.2800","27.7646","27.5863","18.4127","15.8347","59.3801"
"55.3600","27.8029","27.6246","18.4383","15.8156","59.3085"
"55.4400","27.8424","27.6641","18.4647","15.7886","59.2072"
"55.5200","27.8838","27.7054","18.4923","15.7701","59.1379"
"55.6000","27.9237","27.7454","18.5189","15.7557","59.0840"
"55.6800","27.9629","27.7846","18.5451","15.7409","59.0285"
"55.7600","28.0029","27.8246","18.5718","15.7276","58.9784"
"55.8400","28.0444","27.8660","18.5995","15.6987","58.8700"
"55.9200","28.0843","27.9060","18.6261","15.6762","58.7859"
"56.0000","28.1226","27.9443","18.6517","15.6548","58.7056"
"56.0800","28.1625","27.9842","18.6783","15.6426","58.6597"
"56.1600","28.2031","28.0248","18.7054","15.6254","58.5954"
"56.2400","28.2438","28.0655","18.7326","15.6099","58.5372"
"56.3200","28.2826","28.1043","18.7585","15.5897","58.4615"
"56.4000","28.3222","28.1439","18.7849","15.5740","58.4025"
"56.4800","28.3643","28.1860","18.8130","15.5570","58.3389"
"56.5600","28.4039","28.2256","18.8395","15.5361","58.2604"
"56.6400","28.4423","28.2640","18.8651","15.4953","58.1073"
"56.7200","28.4825","28.3042","18.8919","15.4874","58.0776"
"56.8000","28.5237","28.3453","18.9194","15.4739","58.0272"
"56.8800","28.5641","28.3858","18.9464","15.4584","57.9690"
"56.9600","28.6028","28.4245","18.9722","15.4437","57.9140"
"57.0400","28.6433","28.4650","18.9992","15.4198","57.8241"
"57.1200","28.6843","28.5060","19.0266","15.4035","57.7633"
"57.2000","28.7239","28.5456","19.0530","15.3855","57.6957"
"57.2800","28.7630","28.5847","19.0791","15.3770","57.6636"
"57.3600","28.8023","28.6240","19.1054","15.3159","57.4346"
"57.4400","28.8437","28.6654","19.1330","15.2961","57.3603"
"57.5200","28.8837","28.7054","19.1597","15.2711","57.2668"
"57.6000","28.9234","28.7451","19.1862","15.2488","57.1831"
"57.6800","28.9637","28.7854","19.2131","15.2293","57.1099"
"57.7600","29.0038","28.8254","19.2398","15.2146","57.0549"
"57.8400","29.0429","28.8645","19.2659","15.2051","57.0190"
"57.9200","29.0835","28.9052","19.2931","15.1686","56.8821"
"58.0000","29.1227","28.9444","19.3192","15.1492","56.8094"
"58.0800","29.1637","28.9854","19.3466","15.1233","56.7126"
"58.1600","29.2022","29.0238","19.3723","15.0943","56.6035"
"58.2400","29.2427","29.0643","19.3993","15.0743","56.5288"
"58.3200","29.2843","29.1060","19.4271","14.0139","52.5521"
"58.3460","29.2979","29.1196","19.4362","8.9037","33.3890"