File: data/instron_tests/241217_metamaterial_foam_test_data/clean_241217_metamaterial_foams_1_1.csv
Time,Displacement,Compressive displacement,Compressive strain (Displacement),Compressive stress,Force
(s),(mm),(mm),(%),(kPa),(N)
"0.0000","0.7286","-0.0095","-0.0063","-0.0093","-0.0349"
"0.0800","0.7320","-0.0061","-0.0041","0.0020","0.0075"
"0.1600","0.7645","0.0264","0.0177","0.0714","0.2678"
"0.2400","0.8040","0.0660","0.0442","0.1555","0.5831"
"0.3200","0.8430","0.1049","0.0703","0.2371","0.8891"
"0.4000","0.8828","0.1448","0.0970","0.3168","1.1881"
"0.4800","0.9240","0.1860","0.1246","0.3996","1.4985"
"0.5600","0.9641","0.2261","0.1515","0.4730","1.7738"
"0.6400","1.0030","0.2650","0.1775","0.5480","2.0549"
"0.7200","1.0415","0.3035","0.2033","0.6229","2.3360"
"0.8000","1.0827","0.3446","0.2309","0.6991","2.6218"
"0.8800","1.1229","0.3848","0.2578","0.7756","2.9085"
"0.9600","1.1630","0.4249","0.2847","0.8505","3.1892"
"1.0400","1.2025","0.4644","0.3112","0.9231","3.4617"
"1.1200","1.2439","0.5058","0.3389","1.0010","3.7537"
"1.2000","1.2831","0.5450","0.3652","1.0702","4.0133"
"1.2800","1.3222","0.5842","0.3914","1.1432","4.2872"
"1.3600","1.3628","0.6248","0.4186","1.2200","4.5751"
"1.4400","1.4031","0.6651","0.4456","1.2945","4.8542"
"1.5200","1.4427","0.7046","0.4721","1.3666","5.1247"
"1.6000","1.4828","0.7448","0.4990","1.4399","5.3995"
"1.6800","1.5232","0.7852","0.5260","1.5165","5.6869"
"1.7600","1.5642","0.8262","0.5535","1.5910","5.9662"
"1.8400","1.6027","0.8647","0.5793","1.6636","6.2385"
"1.9200","1.6427","0.9046","0.6060","1.7337","6.5014"
"2.0000","1.6834","0.9453","0.6333","1.8120","6.7950"
"2.0800","1.7231","0.9850","0.6599","1.8833","7.0625"
"2.1600","1.7626","1.0246","0.6864","1.9555","7.3331"
"2.2400","1.8021","1.0640","0.7129","2.0255","7.5958"
"2.3200","1.8442","1.1061","0.7410","2.1033","7.8875"
"2.4000","1.8837","1.1456","0.7675","2.1759","8.1598"
"2.4800","1.9222","1.1841","0.7933","2.2470","8.4263"
"2.5600","1.9626","1.2245","0.8204","2.3201","8.7002"
"2.6400","2.0035","1.2654","0.8478","2.3908","8.9656"
"2.7200","2.0436","1.3055","0.8746","2.4656","9.2459"
"2.8000","2.0829","1.3448","0.9010","2.5364","9.5116"
"2.8800","2.1222","1.3841","0.9273","2.6093","9.7849"
"2.9600","2.1645","1.4264","0.9556","2.6819","10.0572"
"3.0400","2.2038","1.4657","0.9820","2.7563","10.3362"
"3.1200","2.2434","1.5053","1.0085","2.8255","10.5955"
"3.2000","2.2818","1.5438","1.0343","2.8994","10.8728"
"3.2800","2.3233","1.5852","1.0621","2.9731","11.1492"
"3.3600","2.3638","1.6258","1.0892","3.0456","11.4209"
"3.4400","2.4023","1.6642","1.1149","3.1165","11.6867"
"3.5200","2.4427","1.7046","1.1420","3.1916","11.9685"
"3.6000","2.4835","1.7454","1.1694","3.2629","12.2361"
"3.6800","2.5232","1.7851","1.1960","3.3351","12.5067"
"3.7600","2.5632","1.8251","1.2228","3.4086","12.7824"
"3.8400","2.6018","1.8637","1.2486","3.4754","13.0328"
"3.9200","2.6433","1.9052","1.2764","3.5546","13.3297"
"4.0000","2.6833","1.9453","1.3033","3.6240","13.5900"
"4.0800","2.7221","1.9840","1.3292","3.6951","13.8567"
"4.1600","2.7629","2.0248","1.3566","3.7676","14.1286"
"4.2400","2.8042","2.0662","1.3843","3.8459","14.4221"
"4.3200","2.8439","2.1058","1.4108","3.9149","14.6810"
"4.4000","2.8834","2.1453","1.4373","3.9841","14.9403"
"4.4800","2.9228","2.1847","1.4637","4.0564","15.2116"
"4.5600","2.9630","2.2249","1.4906","4.1318","15.4943"
"4.6400","3.0029","2.2649","1.5174","4.2008","15.7529"
"4.7200","3.0431","2.3050","1.5443","4.2737","16.0263"
"4.8000","3.0830","2.3449","1.5710","4.3477","16.3039"
"4.8800","3.1237","2.3857","1.5983","4.4219","16.5822"
"4.9600","3.1634","2.4254","1.6249","4.4920","16.8449"
"5.0400","3.2027","2.4647","1.6512","4.5601","17.1003"
"5.1200","3.2429","2.5049","1.6782","4.6361","17.3854"
"5.2000","3.2838","2.5457","1.7055","4.7069","17.6508"
"5.2800","3.3220","2.5839","1.7311","4.7776","17.9162"
"5.3600","3.3630","2.6250","1.7586","4.8507","18.1903"
"5.4400","3.4036","2.6655","1.7858","4.9262","18.4732"
"5.5200","3.4443","2.7063","1.8131","4.9985","18.7445"
"5.6000","3.4828","2.7447","1.8389","5.0695","19.0107"
"5.6800","3.5224","2.7843","1.8654","5.1401","19.2755"
"5.7600","3.5633","2.8252","1.8928","5.2144","19.5541"
"5.8400","3.6029","2.8649","1.9194","5.2854","19.8201"
"5.9200","3.6424","2.9044","1.9458","5.3563","20.0860"
"6.0000","3.6826","2.9445","1.9727","5.4317","20.3690"
"6.0800","3.7238","2.9858","2.0004","5.5019","20.6320"
"6.1600","3.7643","3.0262","2.0274","5.5779","20.9171"
"6.2400","3.8021","3.0640","2.0528","5.6439","21.1646"
"6.3200","3.8423","3.1042","2.0797","5.7184","21.4439"
"6.4000","3.8837","3.1456","2.1075","5.7907","21.7150"
"6.4800","3.9231","3.1851","2.1339","5.8595","21.9732"
"6.5600","3.9620","3.2240","2.1599","5.9304","22.2389"
"6.6400","4.0024","3.2644","2.1870","6.0055","22.5206"
"6.7200","4.0441","3.3060","2.2149","6.0806","22.8021"
"6.8000","4.0836","3.3455","2.2414","6.1492","23.0595"
"6.8800","4.1228","3.3848","2.2677","6.2201","23.3253"
"6.9600","4.1624","3.4243","2.2942","6.2937","23.6015"
"7.0400","4.2034","3.4654","2.3217","6.3662","23.8734"
"7.1200","4.2437","3.5057","2.3487","6.4374","24.1402"
"7.2000","4.2827","3.5447","2.3748","6.5070","24.4012"
"7.2800","4.3226","3.5845","2.4015","6.5797","24.6739"
"7.3600","4.3642","3.6262","2.4294","6.6582","24.9682"
"7.4400","4.4030","3.6649","2.4553","6.7225","25.2095"
"7.5200","4.4429","3.7048","2.4821","6.7931","25.4742"
"7.6000","4.4818","3.7438","2.5082","6.8641","25.7404"
"7.6800","4.5232","3.7852","2.5359","6.9417","26.0314"
"7.7600","4.5633","3.8253","2.5628","7.0108","26.2907"
"7.8400","4.6028","3.8647","2.5892","7.0830","26.5611"
"7.9200","4.6428","3.9047","2.6160","7.1540","26.8273"
"8.0000","4.6839","3.9458","2.6436","7.2293","27.1099"
"8.0800","4.7230","3.9849","2.6698","7.2967","27.3624"
"8.1600","4.7633","4.0253","2.6968","7.3685","27.6318"
"8.2400","4.8022","4.0641","2.7228","7.4422","27.9082"
"8.3200","4.8437","4.1057","2.7507","7.5138","28.1766"
"8.4000","4.8827","4.1446","2.7768","7.5882","28.4558"
"8.4800","4.9228","4.1848","2.8037","7.6569","28.7135"
"8.5600","4.9640","4.2260","2.8312","7.7324","28.9965"
"8.6400","5.0036","4.2656","2.8578","7.8026","29.2596"
"8.7200","5.0428","4.3047","2.8840","7.8744","29.5291"
"8.8000","5.0832","4.3452","2.9111","7.9453","29.7950"
"8.8800","5.1230","4.3849","2.9377","8.0214","30.0801"
"8.9600","5.1637","4.4257","2.9650","8.0924","30.3465"
"9.0400","5.2023","4.4643","2.9909","8.1644","30.6163"
"9.1200","5.2423","4.5042","3.0177","8.2343","30.8786"
"9.2000","5.2839","4.5458","3.0455","8.3073","31.1523"
"9.2800","5.3238","4.5858","3.0723","8.3819","31.4321"
"9.3600","5.3628","4.6247","3.0984","8.4490","31.6839"
"9.4400","5.4013","4.6632","3.1242","8.5203","31.9511"
"9.5200","5.4437","4.7056","3.1526","8.5947","32.2301"
"9.6000","5.4836","4.7455","3.1793","8.6692","32.5096"
"9.6800","5.5224","4.7843","3.2053","8.7376","32.7661"
"9.7600","5.5629","4.8248","3.2325","8.8128","33.0480"
"9.8400","5.6038","4.8658","3.2599","8.8842","33.3156"
"9.9200","5.6439","4.9058","3.2867","8.9561","33.5855"
"10.0000","5.6829","4.9448","3.3129","9.0254","33.8453"
"10.0800","5.7220","4.9839","3.3390","9.0990","34.1214"
"10.1600","5.7634","5.0253","3.3668","9.1708","34.3903"
"10.2400","5.8029","5.0648","3.3933","9.2407","34.6528"
"10.3200","5.8424","5.1044","3.4197","9.3135","34.9255"
"10.4000","5.8828","5.1447","3.4468","9.3897","35.2113"
"10.4800","5.9236","5.1856","3.4741","9.4619","35.4821"
"10.5600","5.9634","5.2253","3.5008","9.5308","35.7406"
"10.6400","6.0029","5.2649","3.5273","9.6051","36.0191"
"10.7200","6.0422","5.3041","3.5535","9.6723","36.2713"
"10.8000","6.0826","5.3445","3.5806","9.7487","36.5577"
"10.8800","6.1230","5.3849","3.6077","9.8183","36.8186"
"10.9600","6.1631","5.4251","3.6346","9.8928","37.0979"
"11.0400","6.2027","5.4646","3.6611","9.9626","37.3599"
"11.1200","6.2441","5.5060","3.6888","10.0381","37.6429"
"11.2000","6.2833","5.5452","3.7151","10.1092","37.9095"
"11.2800","6.3226","5.5845","3.7414","10.1788","38.1706"
"11.3600","6.3629","5.6249","3.7685","10.2539","38.4520"
"11.4400","6.4033","5.6652","3.7955","10.3263","38.7235"
"11.5200","6.4425","5.7044","3.8217","10.3981","38.9930"
"11.6000","6.4828","5.7447","3.8487","10.4687","39.2577"
"11.6800","6.5229","5.7849","3.8756","10.5466","39.5496"
"11.7600","6.5640","5.8260","3.9032","10.6170","39.8139"
"11.8400","6.6024","5.8643","3.9289","10.6873","40.0773"
"11.9200","6.6430","5.9049","3.9561","10.7598","40.3494"
"12.0000","6.6835","5.9454","3.9832","10.8356","40.6334"
"12.0800","6.7232","5.9851","4.0098","10.9069","40.9010"
"12.1600","6.7626","6.0245","4.0362","10.9777","41.1664"
"12.2400","6.8019","6.0638","4.0626","11.0452","41.4193"
"12.3200","6.8433","6.1052","4.0903","11.1248","41.7178"
"12.4000","6.8841","6.1461","4.1176","11.1958","41.9842"
"12.4800","6.9225","6.1844","4.1433","11.2640","42.2399"
"12.5600","6.9626","6.2246","4.1702","11.3402","42.5257"
"12.6400","7.0034","6.2653","4.1975","11.4127","42.7977"
"12.7200","7.0435","6.3054","4.2244","11.4871","43.0765"
"12.8000","7.0824","6.3443","4.2504","11.5564","43.3367"
"12.8800","7.1221","6.3841","4.2771","11.6304","43.6141"
"12.9600","7.1640","6.4259","4.3051","11.7039","43.8895"
"13.0400","7.2038","6.4657","4.3318","11.7779","44.1670"
"13.1200","7.2432","6.5051","4.3582","11.8469","44.4259"
"13.2000","7.2820","6.5439","4.3842","11.9174","44.6903"
"13.2800","7.3231","6.5850","4.4117","11.9939","44.9770"
"13.3600","7.3641","6.6261","4.4392","12.0652","45.2443"
"13.4400","7.4025","6.6644","4.4649","12.1356","45.5084"
"13.5200","7.4426","6.7046","4.4918","12.2099","45.7872"
"13.6000","7.4840","6.7460","4.5195","12.2847","46.0678"
"13.6800","7.5235","6.7854","4.5460","12.3579","46.3420"
"13.7600","7.5631","6.8251","4.5725","12.4299","46.6123"
"13.8400","7.6019","6.8639","4.5985","12.5016","46.8808"
"13.9200","7.6439","6.9058","4.6266","12.5801","47.1752"
"14.0000","7.6834","6.9453","4.6531","12.6486","47.4323"
"14.0800","7.7223","6.9843","4.6792","12.7197","47.6987"
"14.1600","7.7623","7.0242","4.7060","12.7919","47.9696"
"14.2400","7.8034","7.0653","4.7335","12.8681","48.2552"
"14.3200","7.8435","7.1054","4.7604","12.9389","48.5207"
"14.4000","7.8832","7.1452","4.7870","13.0098","48.7868"
"14.4800","7.9225","7.1844","4.8133","13.0837","49.0638"
"14.5600","7.9638","7.2258","4.8410","13.1595","49.3479"
"14.6400","8.0027","7.2646","4.8670","13.2294","49.6102"
"14.7200","8.0434","7.3053","4.8943","13.3014","49.8801"
"14.8000","8.0836","7.3455","4.9212","13.3778","50.1669"
"14.8800","8.1239","7.3858","4.9482","13.4510","50.4411"
"14.9600","8.1636","7.4255","4.9748","13.5266","50.7247"
"15.0400","8.2028","7.4648","5.0011","13.5925","50.9720"
"15.1200","8.2431","7.5051","5.0281","13.6693","51.2597"
"15.2000","8.2831","7.5450","5.0549","13.7411","51.5290"
"15.2800","8.3218","7.5838","5.0809","13.8139","51.8022"
"15.3600","8.3628","7.6247","5.1083","13.8859","52.0720"
"15.4400","8.4034","7.6654","5.1355","13.9641","52.3652"
"15.5200","8.4439","7.7059","5.1626","14.0350","52.6314"
"15.6000","8.4830","7.7450","5.1888","14.1072","52.9020"
"15.6800","8.5222","7.7841","5.2151","14.1781","53.1680"
"15.7600","8.5633","7.8252","5.2426","14.2513","53.4424"
"15.8400","8.6029","7.8648","5.2691","14.3291","53.7342"
"15.9200","8.6427","7.9047","5.2958","14.4001","54.0004"
"16.0000","8.6824","7.9444","5.3224","14.4743","54.2786"
"16.0800","8.7237","7.9856","5.3501","14.5480","54.5549"
"16.1600","8.7641","8.0261","5.3772","14.6254","54.8454"
"16.2400","8.8033","8.0652","5.4034","14.6974","55.1152"
"16.3200","8.8418","8.1037","5.4292","14.7687","55.3827"
"16.4000","8.8835","8.1454","5.4571","14.8436","55.6633"
"16.4800","8.9234","8.1854","5.4839","14.9155","55.9333"
"16.5600","8.9626","8.2245","5.5101","14.9864","56.1990"
"16.6400","9.0022","8.2642","5.5367","15.0638","56.4894"
"16.7200","9.0440","8.3060","5.5647","15.1401","56.7755"
"16.8000","9.0840","8.3460","5.5915","15.2107","57.0400"
"16.8800","9.1227","8.3846","5.6174","15.2823","57.3086"
"16.9600","9.1622","8.4242","5.6439","15.3571","57.5893"
"17.0400","9.2035","8.4654","5.6715","15.4353","57.8823"
"17.1200","9.2441","8.5060","5.6987","15.5126","58.1723"
"17.2000","9.2825","8.5445","5.7245","15.5825","58.4345"
"17.2800","9.3227","8.5847","5.7514","15.6550","58.7064"
"17.3600","9.3643","8.6263","5.7793","15.7351","59.0065"
"17.4400","9.4027","8.6647","5.8050","15.8014","59.2551"
"17.5200","9.4429","8.7048","5.8319","15.8804","59.5514"
"17.6000","9.4824","8.7443","5.8584","15.9518","59.8194"
"17.6800","9.5228","8.7847","5.8855","16.0273","60.1025"
"17.7600","9.5626","8.8245","5.9121","16.0980","60.3676"
"17.8400","9.6027","8.8646","5.9390","16.1734","60.6501"
"17.9200","9.6433","8.9053","5.9662","16.2500","60.9375"
"18.0000","9.6837","8.9456","5.9932","16.3256","61.2210"
"18.0800","9.7227","8.9846","6.0194","16.3971","61.4892"
"18.1600","9.7633","9.0252","6.0466","16.4687","61.7576"
"18.2400","9.8023","9.0643","6.0727","16.5460","62.0477"
"18.3200","9.8439","9.1058","6.1006","16.6244","62.3416"
"18.4000","9.8829","9.1448","6.1267","16.6956","62.6086"
"18.4800","9.9229","9.1848","6.1535","16.7665","62.8744"
"18.5600","9.9639","9.2258","6.1810","16.8492","63.1844"
"18.6400","10.0040","9.2659","6.2078","16.9217","63.4563"
"18.7200","10.0432","9.3051","6.2341","16.9983","63.7438"
"18.8000","10.0831","9.3450","6.2608","17.0698","64.0117"
"18.8800","10.1229","9.3848","6.2875","17.1457","64.2963"
"18.9600","10.1639","9.4258","6.3150","17.2205","64.5768"
"19.0400","10.2023","9.4642","6.3407","17.2961","64.8605"
"19.1200","10.2421","9.5041","6.3674","17.3686","65.1323"
"19.2000","10.2837","9.5456","6.3952","17.4464","65.4239"
"19.2800","10.3238","9.5857","6.4221","17.5248","65.7182"
"19.3600","10.3629","9.6248","6.4483","17.5961","65.9855"
"19.4400","10.4020","9.6639","6.4745","17.6711","66.2665"
"19.5200","10.4434","9.7053","6.5022","17.7446","66.5423"
"19.6000","10.4834","9.7454","6.5290","17.8241","66.8405"
"19.6800","10.5224","9.7844","6.5552","17.8965","67.1119"
"19.7600","10.5624","9.8244","6.5820","17.9765","67.4118"
"19.8400","10.6038","9.8658","6.6097","18.0543","67.7035"
"19.9200","10.6436","9.9055","6.6363","18.1300","67.9874"
"20.0000","10.6832","9.9452","6.6629","18.2020","68.2576"
"20.0800","10.7220","9.9840","6.6889","18.2769","68.5382"
"20.1600","10.7637","10.0257","6.7168","18.3544","68.8291"
"20.2400","10.8030","10.0650","6.7432","18.4279","69.1045"
"20.3200","10.8421","10.1040","6.7693","18.5032","69.3871"
"20.4000","10.8829","10.1448","6.7967","18.5806","69.6774"
"20.4800","10.9241","10.1860","6.8243","18.6619","69.9821"
"20.5600","10.9638","10.2257","6.8508","18.7347","70.2551"
"20.6400","11.0032","10.2652","6.8773","18.8119","70.5446"
"20.7200","11.0420","10.3040","6.9033","18.8832","70.8121"
"20.8000","11.0830","10.3450","6.9307","18.9633","71.1125"
"20.8800","11.1228","10.3847","6.9574","19.0371","71.3892"
"20.9600","11.1629","10.4249","6.9843","19.1151","71.6817"
"21.0400","11.2021","10.4640","7.0105","19.1877","71.9539"
"21.1200","11.2443","10.5062","7.0388","19.2699","72.2622"
"21.2000","11.2829","10.5448","7.0646","19.3408","72.5281"
"21.2800","11.3230","10.5849","7.0915","19.4175","72.8157"
"21.3600","11.3630","10.6249","7.1183","19.4958","73.1091"
"21.4400","11.4027","10.6646","7.1449","19.5705","73.3895"
"21.5200","11.4427","10.7047","7.1717","19.6489","73.6833"
"21.6000","11.4830","10.7450","7.1987","19.7225","73.9595"
"21.6800","11.5232","10.7851","7.2256","19.8012","74.2543"
"21.7600","11.5642","10.8261","7.2531","19.8807","74.5527"
"21.8400","11.6024","10.8643","7.2787","19.9542","74.8281"
"21.9200","11.6429","10.9048","7.3058","20.0282","75.1057"
"22.0000","11.6833","10.9452","7.3329","20.1067","75.4002"
"22.0800","11.7233","10.9852","7.3597","20.1839","75.6897"
"22.1600","11.7625","11.0244","7.3859","20.2610","75.9787"
"22.2400","11.8023","11.0642","7.4126","20.3331","76.2493"
"22.3200","11.8443","11.1062","7.4408","20.4175","76.5655"
"22.4000","11.8839","11.1458","7.4673","20.4923","76.8460"
"22.4800","11.9224","11.1843","7.4931","20.5681","77.1303"
"22.5600","11.9627","11.2246","7.5201","20.6421","77.4080"
"22.6400","12.0034","11.2653","7.5474","20.7217","77.7065"
"22.7200","12.0438","11.3057","7.5744","20.8001","78.0002"
"22.8000","12.0824","11.3443","7.6003","20.8745","78.2794"
"22.8800","12.1220","11.3840","7.6268","20.9523","78.5712"
"22.9600","12.1641","11.4260","7.6550","21.0306","78.8647"
"23.0400","12.2034","11.4654","7.6814","21.1076","79.1537"
"23.1200","12.2430","11.5050","7.7079","21.1847","79.4425"
"23.2000","12.2818","11.5437","7.7338","21.2574","79.7153"
"23.2800","12.3230","11.5850","7.7615","21.3371","80.0141"
"23.3600","12.3639","11.6259","7.7889","21.4151","80.3064"
"23.4400","12.4024","11.6643","7.8147","21.4913","80.5925"
"23.5200","12.4425","11.7045","7.8416","21.5723","80.8963"
"23.6000","12.4840","11.7459","7.8693","21.6484","81.1813"
"23.6800","12.5237","11.7856","7.8959","21.7260","81.4725"
"23.7600","12.5631","11.8251","7.9224","21.8045","81.7667"
"23.8400","12.6019","11.8638","7.9483","21.8795","82.0481"
"23.9200","12.6425","11.9045","7.9755","21.9582","82.3434"
"24.0000","12.6836","11.9456","8.0031","22.0339","82.6272"
"24.0800","12.7225","11.9844","8.0291","22.1126","82.9223"
"24.1600","12.7627","12.0247","8.0561","22.1894","83.2103"
"24.2400","12.8037","12.0657","8.0835","22.2722","83.5208"
"24.3200","12.8435","12.1055","8.1102","22.3486","83.8071"
"24.4000","12.8833","12.1452","8.1368","22.4240","84.0899"
"24.4800","12.9223","12.1843","8.1630","22.5033","84.3873"
"24.5600","12.9636","12.2255","8.1906","22.5839","84.6897"
"24.6400","13.0026","12.2645","8.2168","22.6584","84.9689"
"24.7200","13.0428","12.3048","8.2437","22.7386","85.2697"
"24.8000","13.0835","12.3454","8.2710","22.8226","85.5846"
"24.8800","13.1239","12.3858","8.2981","22.9013","85.8798"
"24.9600","13.1635","12.4254","8.3246","22.9793","86.1722"
"25.0400","13.2024","12.4644","8.3507","23.0520","86.4451"
"25.1200","13.2428","12.5047","8.3777","23.1347","86.7552"
"25.2000","13.2838","12.5458","8.4052","23.2136","87.0511"
"25.2800","13.3223","12.5842","8.4310","23.2901","87.3379"
"25.3600","13.3631","12.6250","8.4583","23.3702","87.6383"
"25.4400","13.4037","12.6656","8.4855","23.4533","87.9497"
"25.5200","13.4438","12.7058","8.5124","23.5318","88.2441"
"25.6000","13.4829","12.7448","8.5386","23.6106","88.5397"
"25.6800","13.5221","12.7841","8.5649","23.6863","88.8236"
"25.7600","13.5630","12.8249","8.5922","23.7659","89.1221"
"25.8400","13.6030","12.8649","8.6190","23.8487","89.4328"
"25.9200","13.6427","12.9047","8.6456","23.9292","89.7344"
"26.0000","13.6825","12.9445","8.6723","24.0072","90.0271"
"26.0800","13.7237","12.9856","8.6999","24.0894","90.3354"
"26.1600","13.7637","13.0257","8.7267","24.1709","90.6410"
"26.2400","13.8028","13.0647","8.7529","24.2461","90.9230"
"26.3200","13.8420","13.1040","8.7792","24.3291","91.2340"
"26.4000","13.8838","13.1458","8.8072","24.4086","91.5321"
"26.4800","13.9238","13.1858","8.8340","24.4911","91.8417"
"26.5600","13.9630","13.2249","8.8602","24.5665","92.1245"
"26.6400","14.0022","13.2641","8.8865","24.6475","92.4282"
"26.7200","14.0440","13.3059","8.9145","24.7337","92.7512"
"26.8000","14.0834","13.3454","8.9409","24.8103","93.0387"
"26.8800","14.1228","13.3847","8.9673","24.8899","93.3370"
"26.9600","14.1620","13.4240","8.9936","24.9700","93.6376"
"27.0400","14.2031","13.4650","9.0211","25.0524","93.9464"
"27.1200","14.2433","13.5053","9.0480","25.1332","94.2497"
"27.2000","14.2821","13.5441","9.0740","25.2111","94.5417"
"27.2800","14.3223","13.5842","9.1009","25.2919","94.8447"
"27.3600","14.3643","13.6262","9.1291","25.3787","95.1700"
"27.4400","14.4028","13.6647","9.1549","25.4495","95.4357"
"27.5200","14.4427","13.7047","9.1816","25.5336","95.7510"
"27.6000","14.4823","13.7442","9.2081","25.6132","96.0493"
"27.6800","14.5232","13.7851","9.2355","25.6978","96.3667"
"27.7600","14.5634","13.8253","9.2625","25.7755","96.6581"
"27.8400","14.6026","13.8645","9.2887","25.8569","96.9635"
"27.9200","14.6432","13.9051","9.3159","25.9407","97.2775"
"28.0000","14.6839","13.9459","9.3432","26.0205","97.5768"
"28.0800","14.7231","13.9850","9.3694","26.1011","97.8791"
"28.1600","14.7633","14.0252","9.3964","26.1794","98.1727"
"28.2400","14.8024","14.0643","9.4226","26.2621","98.4829"
"28.3200","14.8436","14.1056","9.4502","26.3495","98.8107"
"28.4000","14.8828","14.1447","9.4765","26.4289","99.1084"
"28.4800","14.9227","14.1846","9.5032","26.5044","99.3913"
"28.5600","14.9640","14.2259","9.5308","26.5937","99.7266"
"28.6400","15.0036","14.2655","9.5574","26.6728","100.0229"
"28.7200","15.0430","14.3050","9.5838","26.7538","100.3267"
"28.8000","15.0823","14.3443","9.6101","26.8315","100.6183"
"28.8800","15.1232","14.3851","9.6375","26.9163","100.9360"
"28.9600","15.1638","14.4257","9.6647","26.9987","101.2450"
"29.0400","15.2024","14.4643","9.6906","27.0751","101.5317"
"29.1200","15.2423","14.5042","9.7173","27.1588","101.8456"
"29.2000","15.2837","14.5456","9.7450","27.2408","102.1530"
"29.2800","15.3239","14.5858","9.7720","27.3251","102.4691"
"29.3600","15.3630","14.6250","9.7982","27.4018","102.7569"
"29.4400","15.4021","14.6640","9.8243","27.4837","103.0639"
"29.5200","15.4435","14.7054","9.8521","27.5678","103.3791"
"29.6000","15.4835","14.7454","9.8789","27.6510","103.6912"
"29.6800","15.5216","14.7836","9.9044","27.7242","103.9658"
"29.7600","15.5623","14.8242","9.9317","27.8132","104.2996"
"29.8400","15.6034","14.8654","9.9592","27.8926","104.5972"
"29.9200","15.6437","14.9057","9.9863","27.9772","104.9145"
"30.0000","15.6830","14.9449","10.0125","28.0549","105.2059"
"30.0800","15.7219","14.9838","10.0386","28.1341","105.5028"
"30.1600","15.7638","15.0258","10.0667","28.2224","105.8342"
"30.2400","15.8031","15.0651","10.0930","28.2986","106.1198"
"30.3200","15.8428","15.1047","10.1196","28.3822","106.4331"
"30.4000","15.8830","15.1449","10.1465","28.4608","106.7280"
"30.4800","15.9236","15.1855","10.1738","28.5466","107.0497"
"30.5600","15.9638","15.2258","10.2007","28.6279","107.3547"
"30.6400","16.0031","15.2650","10.2270","28.7083","107.6562"
"30.7200","16.0423","15.3042","10.2533","28.7858","107.9468"
"30.8000","16.0828","15.3448","10.2804","28.8709","108.2658"
"30.8800","16.1229","15.3848","10.3073","28.9484","108.5565"
"30.9600","16.1633","15.4253","10.3344","29.0322","108.8709"
"31.0400","16.2026","15.4645","10.3607","29.1097","109.1614"
"31.1200","16.2438","15.5057","10.3883","29.1956","109.4836"
"31.2000","16.2832","15.5451","10.4147","29.2755","109.7831"
"31.2800","16.3224","15.5843","10.4409","29.3545","110.0795"
"31.3600","16.3628","15.6248","10.4680","29.4381","110.3929"
"31.4400","16.4035","15.6654","10.4953","29.5204","110.7015"
"31.5200","16.4429","15.7048","10.5216","29.6000","111.0000"
"31.6000","16.4830","15.7450","10.5485","29.6815","111.3058"
"31.6800","16.5230","15.7850","10.5754","29.7676","111.6287"
"31.7600","16.5641","15.8260","10.6029","29.8513","111.9425"
"31.8400","16.6029","15.8648","10.6288","29.9320","112.2449"
"31.9200","16.6427","15.9047","10.6555","30.0082","112.5306"
"32.0000","16.6831","15.9451","10.6826","30.0946","112.8547"
"32.0800","16.7232","15.9852","10.7095","30.1742","113.1534"
"32.1600","16.7621","16.0241","10.7355","30.2545","113.4543"
"32.2400","16.8025","16.0645","10.7626","30.3330","113.7488"
"32.3200","16.8439","16.1059","10.7903","30.4226","114.0848"
"32.4000","16.8840","16.1459","10.8172","30.4987","114.3699"
"32.4800","16.9223","16.1842","10.8428","30.5786","114.6699"
"32.5600","16.9624","16.2243","10.8697","30.6579","114.9671"
"32.6400","17.0033","16.2652","10.8971","30.7418","115.2817"
"32.7200","17.0438","16.3058","10.9243","30.8247","115.5925"
"32.8000","17.0827","16.3446","10.9503","30.9017","115.8814"
"32.8800","17.1225","16.3845","10.9770","30.9886","116.2073"
"32.9600","17.1642","16.4262","11.0049","31.0722","116.5206"
"33.0400","17.2035","16.4654","11.0312","31.1529","116.8234"
"33.1200","17.2429","16.5049","11.0577","31.2293","117.1099"
"33.2000","17.2819","16.5438","11.0837","31.3079","117.4045"
"33.2800","17.3227","16.5847","11.1111","31.3905","117.7143"
"33.3600","17.3638","16.6257","11.1386","31.4744","118.0289"
"33.4400","17.4024","16.6643","11.1645","31.5533","118.3249"
"33.5200","17.4424","16.7043","11.1913","31.6376","118.6411"
"33.6000","17.4838","16.7458","11.2191","31.7209","118.9533"
"33.6800","17.5234","16.7853","11.2455","31.7990","119.2464"
"33.7600","17.5631","16.8251","11.2722","31.8805","119.5519"
"33.8400","17.6021","16.8640","11.2983","31.9609","119.8534"
"33.9200","17.6436","16.9055","11.3261","32.0486","120.1823"
"34.0000","17.6830","16.9450","11.3525","32.1229","120.4609"
"34.0800","17.7225","16.9844","11.3789","32.2064","120.7739"
"34.1600","17.7627","17.0247","11.4059","32.2861","121.0728"
"34.2400","17.8037","17.0657","11.4334","32.3719","121.3947"
"34.3200","17.8435","17.1055","11.4600","32.4496","121.6862"
"34.4000","17.8833","17.1452","11.4867","32.5297","121.9865"
"34.4800","17.9223","17.1842","11.5128","32.6064","122.2739"
"34.5600","17.9639","17.2259","11.5407","32.6943","122.6038"
"34.6400","18.0025","17.2644","11.5665","32.7694","122.8852"
"34.7200","18.0431","17.3050","11.5937","32.8531","123.1990"
"34.8000","18.0835","17.3455","11.6208","32.9367","123.5128"
"34.8800","18.1239","17.3859","11.6479","33.0165","123.8120"
"34.9600","18.1635","17.4255","11.6744","33.0963","124.1112"
"35.0400","18.2030","17.4650","11.7009","33.1731","124.3991"
"35.1200","18.2429","17.5048","11.7276","33.2568","124.7129"
"35.2000","18.2838","17.5457","11.7550","33.3380","125.0176"
"35.2800","18.3222","17.5841","11.7807","33.4122","125.2957"
"35.3600","18.3629","17.6248","11.8080","33.4928","125.5980"
"35.4400","18.4032","17.6651","11.8350","33.5738","125.9016"
"35.5200","18.4436","17.7055","11.8621","33.6538","126.2018"
"35.6000","18.4828","17.7448","11.8884","33.7307","126.4902"
"35.6800","18.5223","17.7842","11.9148","33.8073","126.7774"
"35.7600","18.5632","17.8252","11.9422","33.8895","127.0855"
"35.8400","18.6029","17.8648","11.9688","33.9686","127.3821"
"35.9200","18.6422","17.9042","11.9951","34.0492","127.6847"
"36.0000","18.6828","17.9448","12.0223","34.1298","127.9869"
"36.0800","18.7237","17.9856","12.0497","34.2108","128.2905"
"36.1600","18.7643","18.0263","12.0769","34.2913","128.5923"
"36.2400","18.8025","18.0644","12.1025","34.3612","128.8546"
"36.3200","18.8420","18.1040","12.1290","34.4414","129.1552"
"36.4000","18.8836","18.1455","12.1568","34.5198","129.4493"
"36.4800","18.9235","18.1854","12.1836","34.5987","129.7450"
"36.5600","18.9628","18.2247","12.2099","34.6740","130.0275"
"36.6400","19.0021","18.2641","12.2363","34.7516","130.3184"
"36.7200","19.0438","18.3058","12.2642","34.8364","130.6364"
"36.8000","19.0843","18.3463","12.2913","34.9134","130.9252"
"36.8800","19.1225","18.3845","12.3169","34.9836","131.1885"
"36.9600","19.1624","18.4243","12.3436","35.0605","131.4770"
"37.0400","19.2034","18.4653","12.3711","35.1401","131.7755"
"37.1200","19.2434","18.5054","12.3979","35.2147","132.0551"
"37.2000","19.2826","18.5445","12.4241","35.2898","132.3367"
"37.2800","19.3224","18.5844","12.4508","35.3672","132.6269"
"37.3600","19.3642","18.6262","12.4788","35.4490","132.9336"
"37.4400","19.4029","18.6648","12.5047","35.5147","133.1801"
"37.5200","19.4431","18.7050","12.5317","35.5939","133.4771"
"37.6000","19.4823","18.7443","12.5580","35.6646","133.7423"
"37.6800","19.5231","18.7850","12.5853","35.7433","134.0373"
"37.7600","19.5637","18.8256","12.6125","35.8199","134.3245"
"37.8400","19.6026","18.8646","12.6386","35.8875","134.5782"
"37.9200","19.6429","18.9048","12.6656","35.9629","134.8610"
"38.0000","19.6841","18.9460","12.6931","36.0380","135.1425"
"38.0800","19.7230","18.9849","12.7192","36.1071","135.4015"
"38.1600","19.7632","19.0252","12.7462","36.1772","135.6646"
"38.2400","19.8021","19.0641","12.7722","36.2490","135.9336"
"38.3200","19.8436","19.1056","12.8000","36.3238","136.2141"
"38.4000","19.8823","19.1442","12.8259","36.3922","136.4709"
"38.4800","19.9231","19.1851","12.8533","36.4643","136.7411"
"38.5600","19.9639","19.2258","12.8806","36.5432","137.0371"
"38.6400","20.0037","19.2657","12.9073","36.6106","137.2896"
"38.7200","20.0431","19.3050","12.9337","36.6861","137.5727"
"38.8000","20.0827","19.3446","12.9602","36.7533","137.8250"
"38.8800","20.1229","19.3849","12.9871","36.8216","138.0809"
"38.9600","20.1636","19.4256","13.0144","36.8960","138.3600"
"39.0400","20.2028","19.4647","13.0406","36.9673","138.6274"
"39.1200","20.2424","19.5044","13.0672","37.0343","138.8785"
"39.2000","20.2833","19.5453","13.0946","37.1090","139.1589"
"39.2800","20.3237","19.5857","13.1217","37.1821","139.4330"
"39.3600","20.3628","19.6248","13.1479","37.2452","139.6695"
"39.4400","20.4019","19.6638","13.1740","37.3132","139.9247"
"39.5200","20.4436","19.7055","13.2020","37.3842","140.1906"
"39.6000","20.4835","19.7454","13.2287","37.4554","140.4577"
"39.6800","20.5224","19.7844","13.2548","37.5157","140.6838"
"39.7600","20.5624","19.8244","13.2816","37.5851","140.9440"
"39.8400","20.6035","19.8655","13.3091","37.6518","141.1943"
"39.9200","20.6440","19.9059","13.3362","37.7203","141.4512"
"40.0000","20.6831","19.9450","13.3624","37.7839","141.6897"
"40.0800","20.7217","19.9836","13.3883","37.8461","141.9227"
"40.1600","20.7635","20.0255","13.4163","37.9149","142.1810"
"40.2400","20.8033","20.0652","13.4430","37.9758","142.4093"
"40.3200","20.8422","20.1041","13.4690","38.0387","142.6452"
"40.4000","20.8827","20.1446","13.4962","38.0997","142.8738"
"40.4800","20.9238","20.1857","13.5237","38.1654","143.1204"
"40.5600","20.9635","20.2255","13.5503","38.2256","143.3459"
"40.6400","21.0030","20.2650","13.5768","38.2836","143.5635"
"40.7200","21.0421","20.3041","13.6030","38.3409","143.7783"
"40.8000","21.0830","20.3450","13.6304","38.4058","144.0219"
"40.8800","21.1231","20.3851","13.6572","38.4636","144.2385"
"40.9600","21.1633","20.4253","13.6842","38.5251","144.4690"
"41.0400","21.2030","20.4649","13.7107","38.5848","144.6931"
"41.1200","21.2440","20.5059","13.7382","38.6458","144.9219"
"41.2000","21.2833","20.5452","13.7645","38.7003","145.1261"
"41.2800","21.3221","20.5840","13.7906","38.7526","145.3223"
"41.3600","21.3629","20.6249","13.8179","38.8126","145.5473"
"41.4400","21.4032","20.6651","13.8449","38.8643","145.7410"
"41.5200","21.4424","20.7044","13.8712","38.9167","145.9378"
"41.6000","21.4826","20.7445","13.8980","38.9682","146.1307"
"41.6800","21.5231","20.7850","13.9252","39.0294","146.3604"
"41.7600","21.5641","20.8260","13.9527","39.0831","146.5617"
"41.8400","21.6026","20.8645","13.9785","39.1274","146.7277"
"41.9200","21.6427","20.9046","14.0053","39.1750","146.9062"
"42.0000","21.6833","20.9452","14.0325","39.2295","147.1105"
"42.0800","21.7235","20.9855","14.0595","39.2792","147.2968"
"42.1600","21.7625","21.0244","14.0856","39.3260","147.4727"
"42.2400","21.8027","21.0646","14.1125","39.3720","147.6451"
"42.3200","21.8444","21.1063","14.1405","39.4245","147.8418"
"42.4000","21.8837","21.1456","14.1668","39.4673","148.0022"
"42.4800","21.9220","21.1839","14.1925","39.5036","148.1385"
"42.5600","21.9629","21.2248","14.2198","39.5469","148.3008"
"42.6400","22.0032","21.2652","14.2469","39.5827","148.4353"
"42.7200","22.0431","21.3051","14.2736","39.6242","148.5907"
"42.8000","22.0828","21.3447","14.3002","39.6598","148.7243"
"42.8800","22.1220","21.3839","14.3264","39.6988","148.8706"
"42.9600","22.1643","21.4262","14.3548","39.7417","149.0315"
"43.0400","22.2038","21.4658","14.3813","39.7765","149.1619"
"43.1200","22.2436","21.5055","14.4079","39.8108","149.2904"
"43.2000","22.2815","21.5434","14.4333","39.8394","149.3978"
"43.2800","22.3230","21.5849","14.4611","39.8742","149.5281"
"43.3600","22.3635","21.6255","14.4883","39.9066","149.6499"
"43.4400","22.4023","21.6642","14.5142","39.9325","149.7469"
"43.5200","22.4428","21.7047","14.5414","39.9639","149.8645"
"43.6000","22.4836","21.7455","14.5687","39.9936","149.9760"
"43.6800","22.5234","21.7853","14.5954","40.0181","150.0679"
"43.7600","22.5631","21.8250","14.6220","40.0394","150.1477"
"43.8400","22.6016","21.8635","14.6477","40.0582","150.2182"
"43.9200","22.6435","21.9054","14.6758","40.0865","150.3244"
"44.0000","22.6831","21.9450","14.7023","40.1025","150.3842"
"44.0800","22.7225","21.9844","14.7287","40.1214","150.4552"
"44.1600","22.7619","22.0238","14.7551","40.1376","150.5160"
"44.2400","22.8040","22.0659","14.7834","40.1607","150.6028"
"44.3200","22.8436","22.1056","14.8099","40.1680","150.6299"
"44.4000","22.8832","22.1452","14.8365","40.1782","150.6682"
"44.4800","22.9230","22.1850","14.8631","40.1792","150.6721"
"44.5600","22.9638","22.2258","14.8904","40.1868","150.7003"
"44.6400","23.0023","22.2642","14.9162","40.1884","150.7064"
"44.7200","23.0432","22.3051","14.9436","40.1928","150.7232"
"44.8000","23.0834","22.3453","14.9705","40.1990","150.7461"
"44.8800","23.1238","22.3858","14.9976","40.2032","150.7621"
"44.9600","23.1633","22.4253","15.0241","40.1993","150.7473"
"45.0400","23.2023","22.4642","15.0502","40.1903","150.7137"
"45.1200","23.2423","22.5042","15.0770","40.1856","150.6959"
"45.2000","23.2833","22.5452","15.1045","40.1774","150.6653"
"45.2800","23.3226","22.5845","15.1308","40.1654","150.6203"
"45.3600","23.3634","22.6254","15.1582","40.1535","150.5755"
"45.4400","23.4035","22.6655","15.1850","40.1397","150.5240"
"45.5200","23.4441","22.7061","15.2122","40.1257","150.4713"
"45.6000","23.4832","22.7452","15.2384","40.1056","150.3961"
"45.6800","23.5224","22.7844","15.2647","40.0808","150.3032"
"45.7600","23.5630","22.8249","15.2919","40.0583","150.2185"
"45.8400","23.6030","22.8649","15.3187","40.0329","150.1233"
"45.9200","23.6426","22.9046","15.3452","40.0053","150.0200"
"46.0000","23.6825","22.9445","15.3719","39.9733","149.8999"
"46.0800","23.7237","22.9856","15.3995","39.9376","149.7662"
"46.1600","23.7639","23.0259","15.4265","39.9066","149.6496"
"46.2400","23.8027","23.0646","15.4525","39.8622","149.4834"
"46.3200","23.8420","23.1039","15.4788","39.8242","149.3407"
"46.4000","23.8837","23.1456","15.5067","39.7912","149.2169"
"46.4800","23.9235","23.1855","15.5334","39.7539","149.0772"
"46.5600","23.9629","23.2249","15.5598","39.7090","148.9086"
"46.6400","24.0021","23.2640","15.5860","39.6680","148.7549"
"46.7200","24.0442","23.3061","15.6143","39.6269","148.6009"
"46.8000","24.0840","23.3460","15.6410","39.5781","148.4177"
"46.8800","24.1228","23.3847","15.6669","39.5292","148.2345"
"46.9600","24.1628","23.4248","15.6937","39.4776","148.0410"
"47.0400","24.2030","23.4650","15.7207","39.4198","147.8241"
"47.1200","24.2435","23.5055","15.7478","39.3671","147.6267"
"47.2000","24.2827","23.5447","15.7741","39.3125","147.4220"
"47.2800","24.3224","23.5843","15.8006","39.2573","147.2149"
"47.3600","24.3643","23.6262","15.8287","39.2054","147.0202"
"47.4400","24.4032","23.6652","15.8548","39.1482","146.8059"
"47.5200","24.4427","23.7047","15.8813","39.0942","146.6033"
"47.6000","24.4827","23.7446","15.9080","39.0328","146.3730"
"47.6800","24.5230","23.7849","15.9350","38.9736","146.1510"
"47.7600","24.5632","23.8252","15.9620","38.9062","145.8982"
"47.8400","24.6020","23.8639","15.9880","38.8340","145.6276"
"47.9200","24.6432","23.9051","16.0155","38.7709","145.3908"
"48.0000","24.6838","23.9458","16.0428","38.7057","145.1464"
"48.0800","24.7231","23.9851","16.0691","38.6303","144.8635"
"48.1600","24.7632","24.0251","16.0959","38.5543","144.5785"
"48.2400","24.8020","24.0640","16.1220","38.4747","144.2801"
"48.3200","24.8440","24.1059","16.1501","38.4074","144.0276"
"48.4000","24.8827","24.1446","16.1760","38.3332","143.7494"
"48.4800","24.9227","24.1846","16.2028","38.2557","143.4590"
"48.5600","24.9640","24.2259","16.2305","38.1839","143.1897"
"48.6400","25.0039","24.2658","16.2572","38.1024","142.8841"
"48.7200","25.0431","24.3051","16.2835","38.0212","142.5794"
"48.8000","25.0829","24.3449","16.3102","37.9265","142.2245"
"48.8800","25.1230","24.3849","16.3370","37.8340","141.8777"
"48.9600","25.1638","24.4258","16.3644","37.7412","141.5295"
"49.0400","25.2016","24.4636","16.3897","37.6313","141.1173"
"49.1200","25.2423","24.5043","16.4170","37.5172","140.6896"
"49.2000","25.2839","24.5459","16.4448","37.4146","140.3046"
"49.2800","25.3238","24.5858","16.4715","37.3310","139.9911"
"49.3600","25.3629","24.6248","16.4977","37.2354","139.6329"
"49.4400","25.4020","24.6640","16.5240","37.1392","139.2719"
"49.5200","25.4437","24.7056","16.5518","37.0554","138.9576"
"49.6000","25.4834","24.7453","16.5784","36.9758","138.6593"
"49.6800","25.5223","24.7842","16.6045","36.8889","138.3334"
"49.7600","25.5624","24.8243","16.6314","36.8097","138.0362"
"49.8400","25.6040","24.8660","16.6593","36.7228","137.7103"
"49.9200","25.6432","24.9052","16.6855","36.6289","137.3584"
"50.0000","25.6829","24.9448","16.7121","36.5329","136.9983"
"50.0800","25.7220","24.9839","16.7383","36.4383","136.6435"
"50.1600","25.7636","25.0256","16.7662","36.3518","136.3193"
"50.2400","25.8030","25.0649","16.7926","36.2644","135.9915"
"50.3200","25.8424","25.1043","16.8190","36.1684","135.6313"
"50.4000","25.8828","25.1447","16.8460","36.0705","135.2645"
"50.4800","25.9239","25.1859","16.8736","35.9607","134.8526"
"50.5600","25.9638","25.2258","16.9003","35.8519","134.4445"
"50.6400","26.0032","25.2652","16.9267","35.7434","134.0376"
"50.7200","26.0423","25.3043","16.9529","35.6345","133.6295"
"50.8000","26.0825","25.3444","16.9798","35.5097","133.1615"
"50.8800","26.1229","25.3849","17.0069","35.3919","132.7195"
"50.9600","26.1634","25.4253","17.0340","35.2896","132.3360"
"51.0400","26.2028","25.4648","17.0605","35.1940","131.9776"
"51.1200","26.2443","25.5063","17.0883","35.1029","131.6357"
"51.2000","26.2836","25.5455","17.1145","34.9760","131.1599"
"51.2800","26.3227","25.5846","17.1407","34.8392","130.6471"
"51.3600","26.3627","25.6247","17.1676","34.7227","130.2099"
"51.4400","26.4035","25.6655","17.1949","34.5616","129.6058"
"51.5200","26.4426","25.7045","17.2211","34.4354","129.1328"
"51.6000","26.4828","25.7448","17.2481","34.2949","128.6059"
"51.6800","26.5230","25.7849","17.2749","34.1729","128.1482"
"51.7600","26.5640","25.8260","17.3025","34.0639","127.7395"
"51.8400","26.6027","25.8647","17.3284","33.9553","127.3323"
"51.9200","26.6421","25.9041","17.3548","33.8546","126.9546"
"52.0000","26.6830","25.9450","17.3822","33.7585","126.5942"
"52.0800","26.7230","25.9850","17.4090","33.6398","126.1491"
"52.1600","26.7631","26.0250","17.4358","33.5445","125.7918"
"52.2400","26.8023","26.0643","17.4621","33.4436","125.4135"
"52.3200","26.8445","26.1064","17.4904","33.3138","124.9269"
"52.4000","26.8841","26.1460","17.5169","33.1603","124.3509"
"52.4800","26.9226","26.1845","17.5427","32.9395","123.5232"
"52.5600","26.9629","26.2248","17.5697","32.7764","122.9116"
"52.6400","27.0034","26.2653","17.5968","32.6301","122.3627"
"52.7200","27.0438","26.3058","17.6239","32.4726","121.7722"
"52.8000","27.0826","26.3446","17.6499","32.3028","121.1354"
"52.8800","27.1215","26.3834","17.6759","32.0852","120.3197"
"52.9600","27.1647","26.4266","17.7049","31.8489","119.4335"
"53.0400","27.2034","26.4654","17.7308","31.6716","118.7686"
"53.1200","27.2430","26.5050","17.7574","31.4713","118.0174"
"53.2000","27.2819","26.5438","17.7834","31.2623","117.2336"
"53.2800","27.3231","26.5850","17.8110","31.0472","116.4271"
"53.3600","27.3636","26.6255","17.8381","30.8365","115.6368"
"53.4400","27.4023","26.6642","17.8640","30.5757","114.6590"
"53.5200","27.4431","26.7051","17.8914","30.3418","113.7818"
"53.6000","27.4839","26.7459","17.9188","30.0673","112.7522"
"53.6800","27.5235","26.7855","17.9453","29.7918","111.7193"
"53.7600","27.5632","26.8251","17.9718","29.4962","110.6108"
"53.8400","27.6019","26.8639","17.9978","29.0901","109.0879"
"53.9200","27.6432","26.9052","18.0255","28.6433","107.4123"
"54.0000","27.6833","26.9452","18.0523","28.2321","105.8703"
"54.0800","27.7226","26.9845","18.0786","27.8913","104.5923"
"54.1600","27.7627","27.0246","18.1055","27.5624","103.3589"
"54.2400","27.8036","27.0656","18.1329","27.0744","101.5290"
"54.3200","27.8436","27.1055","18.1597","26.4388","99.1454"
"54.4000","27.8831","27.1450","18.1862","25.7427","96.5351"
"54.4800","27.9230","27.1849","18.2129","24.9851","93.6942"
"54.5600","27.9633","27.2252","18.2399","24.2441","90.9153"
"54.6400","28.0029","27.2648","18.2664","23.3891","87.7090"
"54.7200","28.0433","27.3053","18.2935","22.2535","83.4507"
"54.8000","28.0834","27.3454","18.3204","21.5562","80.8356"
"54.8800","28.1240","27.3860","18.3476","21.1083","79.1561"
"54.9600","28.1635","27.4254","18.3740","20.6292","77.3594"
"55.0400","28.2030","27.4650","18.4005","20.2371","75.8893"
"55.1200","28.2435","27.5055","18.4276","19.9415","74.7806"
"55.2000","28.2837","27.5456","18.4546","19.6617","73.7312"
"55.2800","28.3221","27.5841","18.4803","19.4115","72.7932"
"55.3600","28.3629","27.6249","18.5076","19.1493","71.8099"
"55.4400","28.4038","27.6657","18.5350","18.9766","71.1623"
"55.5200","28.4435","27.7054","18.5616","18.8731","70.7742"
"55.6000","28.4829","27.7448","18.5880","18.7449","70.2935"
"55.6800","28.5223","27.7842","18.6144","18.6012","69.7544"
"55.7600","28.5629","27.8249","18.6416","18.4777","69.2912"
"55.8400","28.6032","27.8651","18.6686","18.3439","68.7897"
"55.9200","28.6427","27.9047","18.6951","18.2421","68.4079"
"56.0000","28.6826","27.9445","18.7218","18.1414","68.0303"
"56.0800","28.7237","27.9856","18.7493","18.0438","67.6641"
"56.1600","28.7641","28.0260","18.7764","17.9533","67.3250"
"56.2400","28.8025","28.0645","18.8022","17.8473","66.9275"
"56.3200","28.8421","28.1041","18.8287","17.7707","66.6403"
"56.4000","28.8836","28.1456","18.8565","17.6862","66.3234"
"56.4800","28.9237","28.1857","18.8834","17.6240","66.0902"
"56.5600","28.9627","28.2246","18.9094","17.5745","65.9044"
"56.6400","29.0021","28.2640","18.9359","17.5149","65.6809"
"56.7200","29.0444","28.3063","18.9642","17.4732","65.5247"
"56.8000","29.0839","28.3458","18.9907","17.4334","65.3753"
"56.8800","29.1225","28.3845","19.0166","17.4118","65.2942"
"56.9600","29.1626","28.4245","19.0434","17.3859","65.1970"
"57.0400","29.2030","28.4649","19.0705","17.3638","65.1143"
"57.1200","29.2435","28.5054","19.0976","17.3296","64.9859"
"57.2000","29.2825","28.5444","19.1237","17.3089","64.9084"
"57.2800","29.3225","28.5844","19.1505","17.2862","64.8231"
"57.3600","29.3643","28.6262","19.1785","17.2625","64.7342"
"57.4400","29.4030","28.6649","19.2045","17.2292","64.6096"
"57.5200","29.4430","28.7049","19.2312","17.2036","64.5134"
"57.6000","29.4826","28.7446","19.2578","17.1785","64.4192"
"57.6800","29.5237","28.7856","19.2853","17.1582","64.3433"
"57.7600","29.5633","28.8252","19.3118","17.1412","64.2794"
"57.8400","29.6026","28.8646","19.3382","17.1103","64.1636"
"57.9200","29.6431","28.9050","19.3653","17.0782","64.0434"
"58.0000","29.6837","28.9456","19.3925","17.0538","63.9516"
"58.0800","29.7231","28.9851","19.4189","17.0270","63.8511"
"58.1600","29.7633","29.0252","19.4458","17.0014","63.7552"
"58.2400","29.8022","29.0641","19.4719","16.9856","63.6962"
"58.3200","29.8439","29.1058","19.4998","16.9693","63.6348"
"58.4000","29.8825","29.1444","19.5257","16.9664","63.6240"
"58.4800","29.9228","29.1848","19.5527","16.9620","63.6075"
"58.5600","29.9637","29.2256","19.5801","16.9591","63.5964"
"58.6400","30.0032","29.2652","19.6066","16.9576","63.5909"
"58.7200","30.0433","29.3052","19.6334","16.9573","63.5899"
"58.8000","30.0826","29.3446","19.6598","16.9501","63.5630"
"58.8800","30.1224","29.3844","19.6864","16.9423","63.5337"
"58.9600","30.1636","29.4256","19.7140","16.9393","63.5223"
"59.0400","30.2026","29.4646","19.7402","16.9383","63.5188"
"59.1200","30.2422","29.5041","19.7667","16.9363","63.5110"
"59.2000","30.2842","29.5461","19.7948","16.9293","63.4851"
"59.2800","30.3237","29.5856","19.8213","16.9239","63.4647"
"59.3600","30.3634","29.6253","19.8479","16.9121","63.4204"
"59.4400","30.4019","29.6639","19.8737","16.9030","63.3864"
"59.5200","30.4431","29.7050","19.9013","16.8928","63.3480"
"59.6000","30.4833","29.7452","19.9282","16.8830","63.3112"
"59.6800","30.5217","29.7836","19.9539","16.8365","63.1368"
"59.7600","30.5616","29.8235","19.9807","16.7888","62.9579"
"59.8140","30.5909","29.8529","20.0003","16.7794","62.9227"