File: data/instron_tests/metamaterials/250327/250327_1467_BULK_m2_2mmTransition.is_comp_Exports/250327_1467_BULK_m2_2mmTransition_3_1.csv
Results Table 1
,Compression Axis,H*,V*,Height,Thickness,Width,Area,Fixture separation,Specimen label
,,,,(mm),(mm),(mm),(mm^2),(mm),
"3","Y","","","148.00","28.00","148.00","4144.00","150.00","1467_BULK_m2_2mmTransition"

Results Table 2
,Modulus (Segment 0 % - 5 %),Compression Axis
,(kPa),
"3","494.32","Y"

Time,Displacement,Force,Compressive displacement,Compressive strain (Displacement),Compressive stress
(s),(mm),(N),(mm),(%),(kPa)
"0.0000","0.0000","-9.1397","0.0000","0.0000","-2.2055"
"0.0800","0.0011","-9.1429","0.0011","0.0008","-2.2063"
"0.1600","0.0172","-8.8300","0.0172","0.0114","-2.1308"
"0.2400","0.0382","-8.4173","0.0382","0.0255","-2.0312"
"0.3200","0.0576","-8.0646","0.0576","0.0384","-1.9461"
"0.4000","0.0768","-7.7263","0.0768","0.0512","-1.8644"
"0.4800","0.0981","-7.3367","0.0981","0.0654","-1.7704"
"0.5600","0.1178","-7.0095","0.1178","0.0786","-1.6915"
"0.6400","0.1371","-6.6813","0.1371","0.0914","-1.6123"
"0.7200","0.1568","-6.3431","0.1568","0.1045","-1.5307"
"0.8000","0.1764","-6.0105","0.1764","0.1176","-1.4504"
"0.8800","0.1971","-5.6625","0.1971","0.1314","-1.3664"
"0.9600","0.2169","-5.3465","0.2169","0.1446","-1.2902"
"1.0400","0.2359","-5.0816","0.2359","0.1572","-1.2263"
"1.1200","0.2572","-4.7328","0.2572","0.1714","-1.1421"
"1.2000","0.2772","-4.4111","0.2772","0.1848","-1.0644"
"1.2800","0.2977","-4.0812","0.2977","0.1985","-0.9848"
"1.3600","0.3173","-3.7702","0.3173","0.2115","-0.9098"
"1.4400","0.3358","-3.4753","0.3358","0.2239","-0.8386"
"1.5200","0.3563","-3.1428","0.3563","0.2376","-0.7584"
"1.6000","0.3765","-2.8276","0.3765","0.2510","-0.6823"
"1.6800","0.3975","-2.4926","0.3975","0.2650","-0.6015"
"1.7600","0.4182","-2.1637","0.4182","0.2788","-0.5221"
"1.8400","0.4370","-1.8803","0.4370","0.2914","-0.4537"
"1.9200","0.4573","-1.5652","0.4573","0.3048","-0.3777"
"2.0000","0.4773","-1.2548","0.4773","0.3182","-0.3028"
"2.0800","0.4966","-0.9579","0.4966","0.3311","-0.2311"
"2.1600","0.5167","-0.6497","0.5167","0.3444","-0.1568"
"2.2400","0.5359","-0.3633","0.5359","0.3573","-0.0877"
"2.3200","0.5567","-0.0457","0.5567","0.3711","-0.0110"
"2.4000","0.5777","0.2885","0.5777","0.3851","0.0696"
"2.4800","0.5967","0.5750","0.5967","0.3978","0.1387"
"2.5600","0.6173","0.8875","0.6173","0.4116","0.2142"
"2.6400","0.6366","1.1856","0.6366","0.4244","0.2861"
"2.7200","0.6564","1.4896","0.6564","0.4376","0.3595"
"2.8000","0.6770","1.7917","0.6770","0.4513","0.4324"
"2.8800","0.6966","2.0953","0.6966","0.4644","0.5056"
"2.9600","0.7175","2.4009","0.7175","0.4783","0.5794"
"3.0400","0.7381","2.7110","0.7381","0.4920","0.6542"
"3.1200","0.7568","3.0008","0.7568","0.5045","0.7241"
"3.2000","0.7768","3.3004","0.7768","0.5178","0.7964"
"3.2800","0.7970","3.6116","0.7970","0.5314","0.8715"
"3.3600","0.8171","3.9117","0.8171","0.5447","0.9439"
"3.4400","0.8363","4.1951","0.8363","0.5575","1.0123"
"3.5200","0.8555","4.4903","0.8555","0.5703","1.0836"
"3.6000","0.8771","4.8168","0.8771","0.5847","1.1623"
"3.6800","0.8978","5.1391","0.8978","0.5985","1.2401"
"3.7600","0.9172","5.4191","0.9172","0.6115","1.3077"
"3.8400","0.9369","5.7089","0.9369","0.6246","1.3776"
"3.9200","0.9559","5.9884","0.9559","0.6373","1.4451"
"4.0000","0.9765","6.3016","0.9765","0.6510","1.5207"
"4.0800","0.9973","6.6154","0.9973","0.6648","1.5964"
"4.1600","1.0169","6.9210","1.0169","0.6779","1.6701"
"4.2400","1.0376","7.2253","1.0376","0.6918","1.7436"
"4.3200","1.0573","7.5170","1.0573","0.7049","1.8139"
"4.4000","1.0778","7.8188","1.0778","0.7185","1.8868"
"4.4800","1.0974","8.1119","1.0974","0.7316","1.9575"
"4.5600","1.1163","8.3877","1.1163","0.7442","2.0241"
"4.6400","1.1364","8.6906","1.1364","0.7576","2.0971"
"4.7200","1.1562","8.9853","1.1562","0.7708","2.1683"
"4.8000","1.1758","9.2630","1.1758","0.7839","2.2353"
"4.8800","1.1975","9.6013","1.1975","0.7983","2.3169"
"4.9600","1.2171","9.8840","1.2171","0.8114","2.3851"
"5.0400","1.2377","10.1901","1.2377","0.8251","2.4590"
"5.1200","1.2570","10.4658","1.2570","0.8380","2.5255"
"5.2000","1.2759","10.7572","1.2759","0.8506","2.5959"
"5.2800","1.2969","11.0663","1.2969","0.8646","2.6704"
"5.3600","1.3169","11.3564","1.3169","0.8779","2.7404"
"5.4400","1.3374","11.6569","1.3374","0.8916","2.8129"
"5.5200","1.3579","11.9516","1.3579","0.9052","2.8841"
"5.6000","1.3771","12.2439","1.3771","0.9181","2.9546"
"5.6800","1.3976","12.5470","1.3976","0.9318","3.0277"
"5.7600","1.4172","12.8248","1.4172","0.9448","3.0948"
"5.8400","1.4366","13.1079","1.4366","0.9577","3.1631"
"5.9200","1.4566","13.4033","1.4566","0.9711","3.2344"
"6.0000","1.4757","13.6777","1.4757","0.9838","3.3006"
"6.0800","1.4970","13.9900","1.4970","0.9980","3.3760"
"6.1600","1.5181","14.3017","1.5181","1.0120","3.4512"
"6.2400","1.5371","14.5854","1.5371","1.0247","3.5196"
"6.3200","1.5565","14.8676","1.5565","1.0377","3.5877"
"6.4000","1.5765","15.1537","1.5765","1.0510","3.6568"
"6.4800","1.5966","15.4480","1.5966","1.0644","3.7278"
"6.5600","1.6174","15.7395","1.6174","1.0782","3.7981"
"6.6400","1.6364","16.0223","1.6364","1.0909","3.8664"
"6.7200","1.6575","16.3196","1.6575","1.1050","3.9381"
"6.8000","1.6774","16.6149","1.6774","1.1182","4.0094"
"6.8800","1.6977","16.9144","1.6977","1.1318","4.0817"
"6.9600","1.7171","17.1920","1.7171","1.1447","4.1487"
"7.0400","1.7363","17.4655","1.7363","1.1576","4.2146"
"7.1200","1.7565","17.7589","1.7565","1.1710","4.2855"
"7.2000","1.7773","18.0543","1.7773","1.1849","4.3567"
"7.2800","1.7960","18.3399","1.7960","1.1973","4.4257"
"7.3600","1.8169","18.6351","1.8169","1.2112","4.4969"
"7.4400","1.8371","18.9280","1.8371","1.2247","4.5676"
"7.5200","1.8575","19.2101","1.8575","1.2383","4.6356"
"7.6000","1.8770","19.4919","1.8770","1.2513","4.7036"
"7.6800","1.8965","19.7719","1.8965","1.2643","4.7712"
"7.7600","1.9172","20.0717","1.9172","1.2782","4.8435"
"7.8400","1.9369","20.3535","1.9369","1.2913","4.9116"
"7.9200","1.9565","20.6386","1.9565","1.3044","4.9804"
"8.0000","1.9775","20.9547","1.9775","1.3183","5.0566"
"8.0800","1.9975","21.2198","1.9975","1.3316","5.1206"
"8.1600","2.0176","21.5098","2.0176","1.3451","5.1906"
"8.2400","2.0371","21.7842","2.0371","1.3581","5.2568"
"8.3200","2.0559","22.0571","2.0559","1.3706","5.3227"
"8.4000","2.0770","22.3693","2.0770","1.3846","5.3980"
"8.4800","2.0964","22.6407","2.0964","1.3976","5.4635"
"8.5600","2.1170","22.9342","2.1170","1.4114","5.5343"
"8.6400","2.1375","23.2328","2.1375","1.4250","5.6064"
"8.7200","2.1570","23.5155","2.1570","1.4380","5.6746"
"8.8000","2.1771","23.7942","2.1771","1.4514","5.7418"
"8.8800","2.1974","24.0850","2.1974","1.4649","5.8120"
"8.9600","2.2163","24.3541","2.2163","1.4775","5.8770"
"9.0400","2.2369","24.6485","2.2369","1.4913","5.9480"
"9.1200","2.2560","24.9138","2.2560","1.5040","6.0120"
"9.2000","2.2774","25.2167","2.2774","1.5183","6.0851"
"9.2800","2.2980","25.5151","2.2980","1.5320","6.1571"
"9.3600","2.3175","25.7964","2.3175","1.5450","6.2250"
"9.4400","2.3371","26.0762","2.3371","1.5581","6.2925"
"9.5200","2.3566","26.3576","2.3566","1.5711","6.3604"
"9.6000","2.3762","26.6278","2.3762","1.5841","6.4256"
"9.6800","2.3971","26.9266","2.3971","1.5981","6.4977"
"9.7600","2.4159","27.1996","2.4159","1.6106","6.5636"
"9.8400","2.4368","27.4940","2.4368","1.6246","6.6347"
"9.9200","2.4574","27.7845","2.4574","1.6383","6.7048"
"10.0000","2.4774","28.0748","2.4774","1.6516","6.7748"
"10.0800","2.4977","28.3669","2.4977","1.6651","6.8453"
"10.1600","2.5165","28.6277","2.5165","1.6776","6.9082"
"10.2400","2.5364","28.9021","2.5364","1.6909","6.9744"
"10.3200","2.5565","29.1887","2.5565","1.7043","7.0436"
"10.4000","2.5766","29.4803","2.5766","1.7177","7.1140"
"10.4800","2.5978","29.7834","2.5978","1.7318","7.1871"
"10.5600","2.6179","30.0596","2.6179","1.7452","7.2538"
"10.6400","2.6373","30.3277","2.6373","1.7582","7.3185"
"10.7200","2.6572","30.6007","2.6572","1.7714","7.3843"
"10.8000","2.6762","30.8715","2.6762","1.7841","7.4497"
"10.8800","2.6974","31.1715","2.6974","1.7982","7.5221"
"10.9600","2.7167","31.4456","2.7167","1.8111","7.5882"
"11.0400","2.7363","31.7139","2.7363","1.8242","7.6530"
"11.1200","2.7565","32.0201","2.7565","1.8377","7.7269"
"11.2000","2.7773","32.2974","2.7773","1.8515","7.7938"
"11.2800","2.7976","32.5808","2.7976","1.8651","7.8622"
"11.3600","2.8176","32.8584","2.8176","1.8784","7.9292"
"11.4400","2.8357","33.1137","2.8357","1.8905","7.9908"
"11.5200","2.8566","33.4082","2.8566","1.9044","8.0618"
"11.6000","2.8767","33.6976","2.8767","1.9178","8.1317"
"11.6800","2.8974","33.9792","2.8974","1.9316","8.1996"
"11.7600","2.9177","34.2839","2.9177","1.9452","8.2731"
"11.8400","2.9371","34.5333","2.9371","1.9581","8.3333"
"11.9200","2.9573","34.8129","2.9573","1.9715","8.4008"
"12.0000","2.9772","35.0918","2.9772","1.9848","8.4681"
"12.0800","2.9965","35.3655","2.9965","1.9977","8.5341"
"12.1600","3.0168","35.6563","3.0168","2.0112","8.6043"
"12.2400","3.0359","35.9148","3.0359","2.0239","8.6667"
"12.3200","3.0561","36.2083","3.0561","2.0374","8.7375"
"12.4000","3.0781","36.5063","3.0781","2.0520","8.8094"
"12.4800","3.0973","36.7770","3.0973","2.0649","8.8748"
"12.5600","3.1174","37.0606","3.1174","2.0783","8.9432"
"12.6400","3.1365","37.3260","3.1365","2.0910","9.0072"
"12.7200","3.1564","37.5962","3.1564","2.1043","9.0725"
"12.8000","3.1769","37.8829","3.1769","2.1179","9.1416"
"12.8800","3.1966","38.1502","3.1966","2.1310","9.2061"
"12.9600","3.2175","38.4501","3.2175","2.1450","9.2785"
"13.0400","3.2378","38.7242","3.2378","2.1586","9.3446"
"13.1200","3.2568","38.9925","3.2568","2.1712","9.4094"
"13.2000","3.2775","39.2821","3.2775","2.1850","9.4793"
"13.2800","3.2966","39.5336","3.2966","2.1978","9.5400"
"13.3600","3.3170","39.8173","3.3170","2.2114","9.6084"
"13.4400","3.3368","40.0879","3.3368","2.2245","9.6737"
"13.5200","3.3556","40.3375","3.3556","2.2371","9.7340"
"13.6000","3.3767","40.6395","3.3767","2.2511","9.8068"
"13.6800","3.3979","40.9412","3.3979","2.2652","9.8796"
"13.7600","3.4175","41.2029","3.4175","2.2783","9.9428"
"13.8400","3.4373","41.4829","3.4373","2.2915","10.0103"
"13.9200","3.4562","41.7293","3.4562","2.3041","10.0698"
"14.0000","3.4765","42.0081","3.4765","2.3177","10.1371"
"14.0800","3.4971","42.3071","3.4971","2.3314","10.2092"
"14.1600","3.5166","42.5682","3.5166","2.3444","10.2723"
"14.2400","3.5373","42.8530","3.5373","2.3582","10.3410"
"14.3200","3.5570","43.1197","3.5570","2.3714","10.4053"
"14.4000","3.5776","43.3961","3.5776","2.3850","10.4720"
"14.4800","3.5974","43.6651","3.5974","2.3982","10.5369"
"14.5600","3.6167","43.9368","3.6167","2.4111","10.6025"
"14.6400","3.6363","44.2040","3.6363","2.4242","10.6670"
"14.7200","3.6558","44.4717","3.6558","2.4372","10.7316"
"14.8000","3.6757","44.7400","3.6757","2.4505","10.7963"
"14.8800","3.6979","45.0481","3.6979","2.4652","10.8707"
"14.9600","3.7175","45.3167","3.7175","2.4783","10.9355"
"15.0400","3.7374","45.5803","3.7374","2.4916","10.9991"
"15.1200","3.7569","45.8359","3.7569","2.5046","11.0608"
"15.2000","3.7765","46.1155","3.7765","2.5176","11.1283"
"15.2800","3.7968","46.3937","3.7968","2.5312","11.1954"
"15.3600","3.8162","46.6470","3.8162","2.5441","11.2565"
"15.4400","3.8370","46.9325","3.8370","2.5580","11.3254"
"15.5200","3.8583","47.2273","3.8583","2.5722","11.3965"
"15.6000","3.8772","47.4837","3.8772","2.5848","11.4584"
"15.6800","3.8974","47.7497","3.8974","2.5983","11.5226"
"15.7600","3.9171","48.0137","3.9171","2.6114","11.5863"
"15.8400","3.9366","48.2812","3.9366","2.6244","11.6509"
"15.9200","3.9568","48.5493","3.9568","2.6378","11.7156"
"16.0000","3.9760","48.8091","3.9760","2.6507","11.7783"
"16.0800","3.9971","49.0999","3.9971","2.6648","11.8484"
"16.1600","4.0179","49.3892","4.0179","2.6786","11.9182"
"16.2400","4.0368","49.6465","4.0368","2.6912","11.9803"
"16.3200","4.0566","49.9075","4.0566","2.7044","12.0433"
"16.4000","4.0766","50.1736","4.0766","2.7178","12.1075"
"16.4800","4.0967","50.4425","4.0967","2.7311","12.1724"
"16.5600","4.1176","50.7176","4.1176","2.7451","12.2388"
"16.6400","4.1362","50.9619","4.1362","2.7575","12.2978"
"16.7200","4.1569","51.2472","4.1569","2.7713","12.3666"
"16.8000","4.1774","51.5243","4.1774","2.7849","12.4335"
"16.8800","4.1977","51.7937","4.1977","2.7985","12.4985"
"16.9600","4.2171","52.0537","4.2171","2.8114","12.5612"
"17.0400","4.2364","52.3008","4.2364","2.8242","12.6208"
"17.1200","4.2565","52.5812","4.2565","2.8377","12.6885"
"17.2000","4.2770","52.8428","4.2770","2.8513","12.7517"
"17.2800","4.2957","53.0975","4.2957","2.8638","12.8131"
"17.3600","4.3173","53.4023","4.3173","2.8782","12.8867"
"17.4400","4.3371","53.6622","4.3371","2.8914","12.9494"
"17.5200","4.3574","53.9309","4.3574","2.9050","13.0142"
"17.6000","4.3772","54.1932","4.3772","2.9181","13.0775"
"17.6800","4.3964","54.4594","4.3964","2.9309","13.1418"
"17.7600","4.4169","54.7314","4.4169","2.9446","13.2074"
"17.8400","4.4370","55.0124","4.4370","2.9580","13.2752"
"17.9200","4.4563","55.2573","4.4563","2.9709","13.3343"
"18.0000","4.4774","55.5486","4.4774","2.9849","13.4046"
"18.0800","4.4973","55.8078","4.4973","2.9982","13.4671"
"18.1600","4.5177","56.0761","4.5177","3.0118","13.5319"
"18.2400","4.5375","56.3412","4.5375","3.0250","13.5959"
"18.3200","4.5558","56.5910","4.5558","3.0372","13.6561"
"18.4000","4.5770","56.8822","4.5770","3.0513","13.7264"
"18.4800","4.5963","57.1392","4.5963","3.0642","13.7884"
"18.5600","4.6169","57.4044","4.6169","3.0779","13.8524"
"18.6400","4.6372","57.6729","4.6372","3.0915","13.9172"
"18.7200","4.6569","57.9350","4.6569","3.1046","13.9805"
"18.8000","4.6771","58.2033","4.6771","3.1180","14.0452"
"18.8800","4.6976","58.4805","4.6976","3.1318","14.1121"
"18.9600","4.7163","58.7199","4.7163","3.1442","14.1699"
"19.0400","4.7366","59.0004","4.7366","3.1577","14.2375"
"19.1200","4.7555","59.2387","4.7555","3.1704","14.2951"
"19.2000","4.7772","59.5326","4.7772","3.1848","14.3660"
"19.2800","4.7984","59.8104","4.7984","3.1989","14.4330"
"19.3600","4.8178","60.0709","4.8178","3.2119","14.4959"
"19.4400","4.8371","60.3233","4.8371","3.2247","14.5568"
"19.5200","4.8567","60.5739","4.8567","3.2378","14.6173"
"19.6000","4.8765","60.8376","4.8765","3.2510","14.6809"
"19.6800","4.8971","61.1151","4.8971","3.2647","14.7479"
"19.7600","4.9159","61.3562","4.9159","3.2773","14.8060"
"19.8400","4.9368","61.6453","4.9368","3.2912","14.8758"
"19.9200","4.9576","61.9162","4.9576","3.3051","14.9412"
"20.0000","4.9770","62.1759","4.9770","3.3180","15.0038"
"20.0800","4.9971","62.4329","4.9971","3.3314","15.0659"
"20.1600","5.0162","62.6774","5.0162","3.3441","15.1249"
"20.2400","5.0369","62.9475","5.0369","3.3579","15.1900"
"20.3200","5.0570","63.2102","5.0570","3.3713","15.2534"
"20.4000","5.0765","63.4682","5.0765","3.3843","15.3157"
"20.4800","5.0976","63.7548","5.0976","3.3984","15.3848"
"20.5600","5.1176","64.0188","5.1176","3.4117","15.4485"
"20.6400","5.1373","64.2701","5.1373","3.4249","15.5092"
"20.7200","5.1572","64.5363","5.1572","3.4382","15.5734"
"20.8000","5.1761","64.7774","5.1761","3.4507","15.6316"
"20.8800","5.1966","65.0472","5.1966","3.4644","15.6967"
"20.9600","5.2168","65.2974","5.2168","3.4779","15.7571"
"21.0400","5.2362","65.5574","5.2362","3.4908","15.8198"
"21.1200","5.2566","65.8300","5.2566","3.5044","15.8856"
"21.2000","5.2774","66.0952","5.2774","3.5183","15.9496"
"21.2800","5.2974","66.3521","5.2974","3.5316","16.0116"
"21.3600","5.3176","66.6180","5.3176","3.5451","16.0758"
"21.4400","5.3359","66.8577","5.3359","3.5572","16.1336"
"21.5200","5.3566","67.1285","5.3566","3.5711","16.1990"
"21.6000","5.3765","67.3875","5.3765","3.5844","16.2615"
"21.6800","5.3974","67.6550","5.3974","3.5982","16.3260"
"21.7600","5.4182","67.9357","5.4182","3.6121","16.3937"
"21.8400","5.4371","68.1703","5.4371","3.6247","16.4504"
"21.9200","5.4572","68.4293","5.4572","3.6381","16.5129"
"22.0000","5.4771","68.6859","5.4771","3.6514","16.5748"
"22.0800","5.4968","68.9464","5.4968","3.6645","16.6376"
"22.1600","5.5168","69.2084","5.5168","3.6778","16.7009"
"22.2400","5.5356","69.4398","5.5356","3.6904","16.7567"
"22.3200","5.5564","69.7115","5.5564","3.7042","16.8223"
"22.4000","5.5782","69.9889","5.5782","3.7188","16.8892"
"22.4800","5.5969","70.2418","5.5969","3.7313","16.9502"
"22.5600","5.6174","70.4985","5.6174","3.7450","17.0122"
"22.6400","5.6363","70.7322","5.6363","3.7575","17.0686"
"22.7200","5.6565","71.0007","5.6565","3.7710","17.1334"
"22.8000","5.6772","71.2631","5.6772","3.7848","17.1967"
"22.8800","5.6968","71.5120","5.6968","3.7979","17.2568"
"22.9600","5.7172","71.7752","5.7172","3.8115","17.3203"
"23.0400","5.7381","72.0422","5.7381","3.8254","17.3847"
"23.1200","5.7565","72.2698","5.7565","3.8377","17.4396"
"23.2000","5.7773","72.5436","5.7773","3.8516","17.5057"
"23.2800","5.7968","72.7792","5.7968","3.8645","17.5625"
"23.3600","5.8172","73.0321","5.8172","3.8781","17.6236"
"23.4400","5.8364","73.2722","5.8364","3.8910","17.6815"
"23.5200","5.8557","73.5293","5.8557","3.9038","17.7436"
"23.6000","5.8770","73.8204","5.8770","3.9180","17.8138"
"23.6800","5.8979","74.0887","5.8979","3.9320","17.8785"
"23.7600","5.9174","74.3308","5.9174","3.9449","17.9370"
"23.8400","5.9371","74.5772","5.9371","3.9581","17.9964"
"23.9200","5.9560","74.8082","5.9560","3.9707","18.0522"
"24.0000","5.9766","75.0733","5.9766","3.9844","18.1161"
"24.0800","5.9974","75.3415","5.9974","3.9983","18.1809"
"24.1600","6.0164","75.5937","6.0165","4.0110","18.2417"
"24.2400","6.0376","75.8725","6.0376","4.0250","18.3090"
"24.3200","6.0572","76.1078","6.0572","4.0381","18.3658"
"24.4000","6.0777","76.3751","6.0777","4.0518","18.4303"
"24.4800","6.0976","76.6186","6.0976","4.0651","18.4890"
"24.5600","6.1166","76.8652","6.1166","4.0778","18.5486"
"24.6400","6.1366","77.1079","6.1366","4.0910","18.6071"
"24.7200","6.1563","77.3540","6.1563","4.1042","18.6665"
"24.8000","6.1759","77.6152","6.1759","4.1172","18.7295"
"24.8800","6.1978","77.8914","6.1978","4.1319","18.7962"
"24.9600","6.2169","78.1254","6.2169","4.1446","18.8527"
"25.0400","6.2374","78.3789","6.2374","4.1583","18.9138"
"25.1200","6.2566","78.6314","6.2566","4.1711","18.9748"
"25.2000","6.2763","78.8806","6.2763","4.1842","19.0349"
"25.2800","6.2968","79.1404","6.2969","4.1979","19.0976"
"25.3600","6.3169","79.3990","6.3169","4.2113","19.1600"
"25.4400","6.3370","79.6524","6.3370","4.2246","19.2211"
"25.5200","6.3574","79.8934","6.3574","4.2382","19.2793"
"25.6000","6.3770","80.1431","6.3770","4.2513","19.3396"
"25.6800","6.3978","80.4106","6.3978","4.2652","19.4041"
"25.7600","6.4173","80.6439","6.4173","4.2782","19.4604"
"25.8400","6.4362","80.8964","6.4362","4.2908","19.5213"
"25.9200","6.4569","81.1544","6.4569","4.3046","19.5836"
"26.0000","6.4757","81.3824","6.4757","4.3171","19.6386"
"26.0800","6.4974","81.6594","6.4974","4.3316","19.7055"
"26.1600","6.5182","81.9263","6.5182","4.3455","19.7699"
"26.2400","6.5369","82.1516","6.5369","4.3580","19.8242"
"26.3200","6.5565","82.3927","6.5565","4.3710","19.8824"
"26.4000","6.5767","82.6516","6.5767","4.3845","19.9449"
"26.4800","6.5972","82.9174","6.5972","4.3981","20.0090"
"26.5600","6.6179","83.1781","6.6179","4.4119","20.0719"
"26.6400","6.6359","83.3884","6.6359","4.4239","20.1227"
"26.7200","6.6570","83.6640","6.6570","4.4380","20.1892"
"26.8000","6.6777","83.9251","6.6777","4.4518","20.2522"
"26.8800","6.6979","84.1730","6.6979","4.4652","20.3120"
"26.9600","6.7168","84.4070","6.7168","4.4779","20.3685"
"27.0400","6.7363","84.6436","6.7363","4.4909","20.4256"
"27.1200","6.7566","84.8918","6.7566","4.5044","20.4855"
"27.2000","6.7770","85.1486","6.7770","4.5180","20.5474"
"27.2800","6.7960","85.3895","6.7960","4.5307","20.6056"
"27.3600","6.8171","85.6618","6.8171","4.5447","20.6713"
"27.4400","6.8371","85.9182","6.8371","4.5581","20.7331"
"27.5200","6.8576","86.1698","6.8576","4.5718","20.7939"
"27.6000","6.8773","86.4038","6.8773","4.5848","20.8503"
"27.6800","6.8961","86.6340","6.8961","4.5974","20.9059"
"27.7600","6.9168","86.8839","6.9168","4.6112","20.9662"
"27.8400","6.9369","87.1350","6.9369","4.6246","21.0268"
"27.9200","6.9565","87.3723","6.9565","4.6377","21.0840"
"28.0000","6.9773","87.6471","6.9773","4.6516","21.1504"
"28.0800","6.9977","87.8929","6.9977","4.6651","21.2097"
"28.1600","7.0176","88.1350","7.0176","4.6784","21.2681"
"28.2400","7.0368","88.3699","7.0368","4.6912","21.3248"
"28.3200","7.0560","88.6018","7.0560","4.7040","21.3807"
"28.4000","7.0770","88.8574","7.0770","4.7180","21.4424"
"28.4800","7.0962","89.0892","7.0962","4.7308","21.4984"
"28.5600","7.1170","89.3413","7.1170","4.7447","21.5592"
"28.6400","7.1373","89.5877","7.1373","4.7582","21.6187"
"28.7200","7.1568","89.8283","7.1568","4.7712","21.6767"
"28.8000","7.1772","90.0786","7.1772","4.7848","21.7371"
"28.8800","7.1975","90.3329","7.1975","4.7984","21.7985"
"28.9600","7.2166","90.5629","7.2166","4.8111","21.8540"
"29.0400","7.2369","90.8203","7.2369","4.8246","21.9161"
"29.1200","7.2556","91.0382","7.2556","4.8371","21.9687"
"29.2000","7.2774","91.3151","7.2774","4.8516","22.0355"
"29.2800","7.2984","91.5767","7.2984","4.8656","22.0986"
"29.3600","7.3176","91.8143","7.3176","4.8784","22.1560"
"29.4400","7.3370","92.0395","7.3370","4.8913","22.2103"
"29.5200","7.3565","92.2751","7.3565","4.9044","22.2672"
"29.6000","7.3761","92.5072","7.3761","4.9174","22.3232"
"29.6800","7.3970","92.7622","7.3970","4.9314","22.3847"
"29.7600","7.4162","92.9976","7.4162","4.9442","22.4415"
"29.8400","7.4372","93.2594","7.4372","4.9581","22.5047"
"29.9200","7.4574","93.5007","7.4574","4.9716","22.5629"
"30.0000","7.4771","93.7506","7.4771","4.9847","22.6232"
"30.0800","7.4975","93.9956","7.4975","4.9983","22.6823"
"30.1600","7.5162","94.2113","7.5162","5.0108","22.7344"
"30.2400","7.5367","94.4608","7.5367","5.0245","22.7946"
"30.3200","7.5569","94.6967","7.5569","5.0379","22.8515"
"30.4000","7.5766","94.9537","7.5766","5.0511","22.9135"
"30.4800","7.5976","95.2158","7.5976","5.0651","22.9768"
"30.5600","7.6180","95.4520","7.6180","5.0787","23.0338"
"30.6400","7.6373","95.6814","7.6373","5.0916","23.0891"
"30.7200","7.6570","95.9148","7.6570","5.1046","23.1455"
"30.8000","7.6757","96.1373","7.6757","5.1171","23.1992"
"30.8800","7.6976","96.4062","7.6976","5.1317","23.2640"
"30.9600","7.7167","96.6268","7.7167","5.1445","23.3173"
"31.0400","7.7361","96.8636","7.7361","5.1574","23.3744"
"31.1200","7.7570","97.1274","7.7570","5.1713","23.4381"
"31.2000","7.7775","97.3687","7.7775","5.1850","23.4963"
"31.2800","7.7978","97.6206","7.7978","5.1985","23.5571"
"31.3600","7.8173","97.8447","7.8173","5.2115","23.6112"
"31.4400","7.8356","98.0737","7.8356","5.2238","23.6664"
"31.5200","7.8567","98.3305","7.8567","5.2378","23.7284"
"31.6000","7.8764","98.5666","7.8764","5.2509","23.7854"
"31.6800","7.8974","98.8280","7.8974","5.2650","23.8485"
"31.7600","7.9184","99.0727","7.9184","5.2789","23.9075"
"31.8400","7.9375","99.3025","7.9375","5.2917","23.9630"
"31.9200","7.9573","99.5437","7.9573","5.3048","24.0212"
"32.0000","7.9771","99.7775","7.9771","5.3181","24.0776"
"32.0800","7.9964","100.0096","7.9964","5.3309","24.1336"
"32.1600","8.0167","100.2645","8.0167","5.3444","24.1951"
"32.2400","8.0359","100.4813","8.0359","5.3572","24.2474"
"32.3200","8.0565","100.7288","8.0565","5.3710","24.3072"
"32.4000","8.0780","100.9886","8.0780","5.3854","24.3698"
"32.4800","8.0971","101.2150","8.0971","5.3981","24.4245"
"32.5600","8.1175","101.4701","8.1175","5.4117","24.4860"
"32.6400","8.1363","101.6814","8.1363","5.4242","24.5370"
"32.7200","8.1563","101.9287","8.1563","5.4375","24.5967"
"32.8000","8.1768","102.1827","8.1768","5.4512","24.6580"
"32.8800","8.1966","102.4130","8.1966","5.4644","24.7136"
"32.9600","8.2169","102.6475","8.2169","5.4780","24.7702"
"33.0400","8.2379","102.9027","8.2379","5.4919","24.8317"
"33.1200","8.2566","103.1303","8.2566","5.5044","24.8867"
"33.2000","8.2773","103.3685","8.2773","5.5182","24.9441"
"33.2800","8.2968","103.6033","8.2968","5.5312","25.0008"
"33.3600","8.3173","103.8421","8.3173","5.5448","25.0584"
"33.4400","8.3366","104.0626","8.3366","5.5577","25.1116"
"33.5200","8.3555","104.2942","8.3555","5.5703","25.1675"
"33.6000","8.3766","104.5469","8.3766","5.5844","25.2285"
"33.6800","8.3977","104.8028","8.3977","5.5985","25.2903"
"33.7600","8.4175","105.0529","8.4175","5.6117","25.3506"
"33.8400","8.4374","105.2719","8.4374","5.6250","25.4034"
"33.9200","8.4558","105.4735","8.4558","5.6372","25.4521"
"34.0000","8.4765","105.7202","8.4765","5.6510","25.5116"
"34.0800","8.4971","105.9604","8.4971","5.6647","25.5696"
"34.1600","8.5167","106.2085","8.5167","5.6778","25.6295"
"34.2400","8.5376","106.4585","8.5376","5.6918","25.6898"
"34.3200","8.5576","106.6866","8.5576","5.7051","25.7448"
"34.4000","8.5778","106.9238","8.5778","5.7186","25.8021"
"34.4800","8.5972","107.1462","8.5972","5.7314","25.8558"
"34.5600","8.6166","107.3630","8.6166","5.7444","25.9081"
"34.6400","8.6364","107.6023","8.6364","5.7576","25.9658"
"34.7200","8.6564","107.8413","8.6564","5.7709","26.0235"
"34.8000","8.6762","108.0629","8.6762","5.7841","26.0770"
"34.8800","8.6975","108.3243","8.6975","5.7983","26.1400"
"34.9600","8.7169","108.5496","8.7169","5.8113","26.1944"
"35.0400","8.7377","108.7870","8.7377","5.8252","26.2517"
"35.1200","8.7568","109.0014","8.7568","5.8379","26.3034"
"35.2000","8.7763","109.2361","8.7763","5.8509","26.3601"
"35.2800","8.7968","109.4808","8.7968","5.8645","26.4191"
"35.3600","8.8165","109.6980","8.8165","5.8777","26.4715"
"35.4400","8.8364","109.9218","8.8364","5.8909","26.5255"
"35.5200","8.8579","110.1737","8.8579","5.9053","26.5863"
"35.6000","8.8775","110.4063","8.8775","5.9183","26.6424"
"35.6800","8.8978","110.6381","8.8978","5.9318","26.6984"
"35.7600","8.9170","110.8591","8.9170","5.9447","26.7517"
"35.8400","8.9362","111.0772","8.9362","5.9574","26.8043"
"35.9200","8.9566","111.3292","8.9566","5.9711","26.8652"
"36.0000","8.9754","111.5287","8.9754","5.9836","26.9133"
"36.0800","8.9972","111.7848","8.9972","5.9981","26.9751"
"36.1600","9.0183","112.0382","9.0183","6.0122","27.0362"
"36.2400","9.0371","112.2495","9.0371","6.0248","27.0872"
"36.3200","9.0566","112.4704","9.0566","6.0377","27.1405"
"36.4000","9.0766","112.7014","9.0766","6.0510","27.1963"
"36.4800","9.0968","112.9423","9.0968","6.0645","27.2544"
"36.5600","9.1174","113.1794","9.1174","6.0783","27.3116"
"36.6400","9.1363","113.3876","9.1363","6.0909","27.3619"
"36.7200","9.1574","113.6372","9.1574","6.1049","27.4221"
"36.8000","9.1776","113.8762","9.1776","6.1184","27.4798"
"36.8800","9.1978","114.1097","9.1978","6.1319","27.5361"
"36.9600","9.2171","114.3292","9.2171","6.1447","27.5891"
"37.0400","9.2363","114.5387","9.2363","6.1575","27.6396"
"37.1200","9.2566","114.7731","9.2566","6.1711","27.6962"
"37.2000","9.2772","115.0118","9.2772","6.1848","27.7538"
"37.2800","9.2957","115.2278","9.2957","6.1971","27.8059"
"37.3600","9.3172","115.4767","9.3172","6.2114","27.8660"
"37.4400","9.3370","115.6994","9.3370","6.2247","27.9197"
"37.5200","9.3575","115.9309","9.3575","6.2383","27.9756"
"37.6000","9.3772","116.1478","9.3772","6.2514","28.0279"
"37.6800","9.3963","116.3699","9.3963","6.2642","28.0816"
"37.7600","9.4169","116.6067","9.4169","6.2779","28.1387"
"37.8400","9.4367","116.8283","9.4367","6.2911","28.1922"
"37.9200","9.4559","117.0425","9.4559","6.3039","28.2439"
"38.0000","9.4774","117.3048","9.4774","6.3183","28.3071"
"38.0800","9.4977","117.5308","9.4977","6.3318","28.3617"
"38.1600","9.5178","117.7547","9.5178","6.3452","28.4157"
"38.2400","9.5373","117.9523","9.5373","6.3582","28.4634"
"38.3200","9.5560","118.1780","9.5560","6.3707","28.5179"
"38.4000","9.5769","118.4232","9.5769","6.3846","28.5770"
"38.4800","9.5962","118.6307","9.5962","6.3974","28.6271"
"38.5600","9.6168","118.8612","9.6168","6.4112","28.6827"
"38.6400","9.6374","119.0991","9.6374","6.4249","28.7401"
"38.7200","9.6573","119.3269","9.6573","6.4382","28.7951"
"38.8000","9.6769","119.5430","9.6769","6.4513","28.8473"
"38.8800","9.6974","119.7707","9.6974","6.4650","28.9022"
"38.9600","9.7165","119.9885","9.7165","6.4777","28.9548"
"39.0400","9.7372","120.2222","9.7372","6.4915","29.0111"
"39.1200","9.7557","120.4188","9.7557","6.5038","29.0586"
"39.2000","9.7772","120.6596","9.7772","6.5181","29.1167"
"39.2800","9.7982","120.9006","9.7982","6.5321","29.1748"
"39.3600","9.8177","121.1157","9.8177","6.5451","29.2268"
"39.4400","9.8369","121.3224","9.8369","6.5579","29.2766"
"39.5200","9.8568","121.5526","9.8568","6.5712","29.3322"
"39.6000","9.8765","121.7620","9.8765","6.5843","29.3827"
"39.6800","9.8972","121.9861","9.8972","6.5981","29.4368"
"39.7600","9.9159","122.1960","9.9159","6.6106","29.4875"
"39.8400","9.9366","122.4298","9.9366","6.6244","29.5439"
"39.9200","9.9575","122.6557","9.9575","6.6383","29.5984"
"40.0000","9.9770","122.8757","9.9770","6.6513","29.6515"
"40.0800","9.9974","123.0990","9.9974","6.6649","29.7053"
"40.1600","10.0163","123.3003","10.0163","6.6775","29.7539"
"40.2400","10.0369","123.5230","10.0369","6.6913","29.8077"
"40.3200","10.0568","123.7368","10.0568","6.7045","29.8593"
"40.4000","10.0766","123.9538","10.0766","6.7177","29.9116"
"40.4800","10.0975","124.1952","10.0975","6.7317","29.9699"
"40.5600","10.1182","124.4208","10.1182","6.7455","30.0243"
"40.6400","10.1369","124.6107","10.1369","6.7580","30.0702"
"40.7200","10.1570","124.8293","10.1570","6.7713","30.1229"
"40.8000","10.1762","125.0269","10.1762","6.7841","30.1706"
"40.8800","10.1973","125.2673","10.1973","6.7982","30.2286"
"40.9600","10.2166","125.4718","10.2166","6.8111","30.2779"
"41.0400","10.2362","125.6922","10.2362","6.8241","30.3311"
"41.1200","10.2561","125.9010","10.2561","6.8374","30.3815"
"41.2000","10.2768","126.1258","10.2768","6.8512","30.4358"
"41.2800","10.2980","126.3636","10.2980","6.8653","30.4932"
"41.3600","10.3179","126.5665","10.3179","6.8786","30.5421"
"41.4400","10.3361","126.7547","10.3361","6.8907","30.5875"
"41.5200","10.3567","126.9770","10.3567","6.9045","30.6412"
"41.6000","10.3768","127.1883","10.3768","6.9179","30.6922"
"41.6800","10.3973","127.4170","10.3973","6.9315","30.7474"
"41.7600","10.4183","127.6404","10.4183","6.9455","30.8013"
"41.8400","10.4371","127.8368","10.4371","6.9581","30.8486"
"41.9200","10.4573","128.0384","10.4573","6.9715","30.8973"
"42.0000","10.4772","128.2458","10.4772","6.9848","30.9474"
"42.0800","10.4967","128.4527","10.4967","6.9978","30.9973"
"42.1600","10.5166","128.6757","10.5166","7.0111","31.0511"
"42.2400","10.5359","128.8580","10.5359","7.0239","31.0951"
"42.3200","10.5565","129.0883","10.5565","7.0376","31.1507"
"42.4000","10.5781","129.3148","10.5781","7.0521","31.2053"
"42.4800","10.5972","129.5256","10.5972","7.0648","31.2562"
"42.5600","10.6173","129.7370","10.6173","7.0782","31.3072"
"42.6400","10.6364","129.9223","10.6364","7.0909","31.3519"
"42.7200","10.6566","130.1354","10.6566","7.1044","31.4033"
"42.8000","10.6767","130.3455","10.6767","7.1178","31.4540"
"42.8800","10.6967","130.5477","10.6967","7.1311","31.5028"
"42.9600","10.7170","130.7699","10.7170","7.1446","31.5564"
"43.0400","10.7379","130.9821","10.7379","7.1586","31.6077"
"43.1200","10.7569","131.1770","10.7569","7.1713","31.6547"
"43.2000","10.7773","131.3966","10.7773","7.1848","31.7077"
"43.2800","10.7969","131.5996","10.7969","7.1979","31.7567"
"43.3600","10.8176","131.8204","10.8175","7.2117","31.8100"
"43.4400","10.8363","132.0018","10.8363","7.2242","31.8537"
"43.5200","10.8554","132.1999","10.8554","7.2369","31.9015"
"43.6000","10.8764","132.4243","10.8764","7.2509","31.9557"
"43.6800","10.8973","132.6461","10.8973","7.2648","32.0092"
"43.7600","10.9177","132.8566","10.9177","7.2785","32.0600"
"43.8400","10.9377","133.0620","10.9377","7.2918","32.1096"
"43.9200","10.9562","133.2390","10.9562","7.3041","32.1523"
"44.0000","10.9766","133.4589","10.9766","7.3178","32.2053"
"44.0800","10.9974","133.6662","10.9974","7.3316","32.2554"
"44.1600","11.0169","133.8757","11.0169","7.3446","32.3059"
"44.2400","11.0374","134.0786","11.0374","7.3583","32.3549"
"44.3200","11.0571","134.2780","11.0571","7.3714","32.4030"
"44.4000","11.0778","134.4774","11.0778","7.3852","32.4511"
"44.4800","11.0975","134.6760","11.0975","7.3983","32.4990"
"44.5600","11.1166","134.8602","11.1166","7.4110","32.5435"
"44.6400","11.1365","135.0655","11.1365","7.4243","32.5930"
"44.7200","11.1564","135.2587","11.1564","7.4376","32.6397"
"44.8000","11.1760","135.4603","11.1760","7.4507","32.6883"
"44.8800","11.1978","135.6941","11.1978","7.4652","32.7447"
"44.9600","11.2169","135.8665","11.2169","7.4780","32.7863"
"45.0400","11.2374","136.0730","11.2374","7.4916","32.8361"
"45.1200","11.2568","136.2574","11.2568","7.5045","32.8806"
"45.2000","11.2765","136.4478","11.2765","7.5176","32.9266"
"45.2800","11.2965","136.6511","11.2965","7.5310","32.9757"
"45.3600","11.3168","136.8508","11.3168","7.5445","33.0238"
"45.4400","11.3368","137.0307","11.3368","7.5579","33.0673"
"45.5200","11.3581","137.2472","11.3581","7.5720","33.1195"
"45.6000","11.3771","137.4217","11.3771","7.5847","33.1616"
"45.6800","11.3976","137.6222","11.3976","7.5984","33.2100"
"45.7600","11.4170","137.8037","11.4170","7.6113","33.2538"
"45.8400","11.4364","137.9875","11.4364","7.6243","33.2981"
"45.9200","11.4565","138.1700","11.4565","7.6377","33.3422"
"46.0000","11.4753","138.3360","11.4753","7.6502","33.3822"
"46.0800","11.4975","138.5555","11.4975","7.6650","33.4352"
"46.1600","11.5180","138.7501","11.5180","7.6787","33.4822"
"46.2400","11.5373","138.9276","11.5373","7.6915","33.5250"
"46.3200","11.5567","139.1195","11.5567","7.7045","33.5713"
"46.4000","11.5768","139.2974","11.5768","7.7178","33.6142"
"46.4800","11.5968","139.4775","11.5968","7.7312","33.6577"
"46.5600","11.6176","139.6612","11.6176","7.7451","33.7020"
"46.6400","11.6361","139.8254","11.6361","7.7574","33.7417"
"46.7200","11.6577","140.0230","11.6577","7.7718","33.7893"
"46.8000","11.6774","140.1913","11.6774","7.7849","33.8299"
"46.8800","11.6978","140.3760","11.6978","7.7985","33.8745"
"46.9600","11.7168","140.5437","11.7168","7.8112","33.9150"
"47.0400","11.7364","140.6970","11.7364","7.8242","33.9520"
"47.1200","11.7568","140.8853","11.7568","7.8379","33.9974"
"47.2000","11.7771","141.0515","11.7771","7.8514","34.0375"
"47.2800","11.7960","141.2032","11.7960","7.8640","34.0741"
"47.3600","11.8172","141.4016","11.8172","7.8781","34.1220"
"47.4400","11.8370","141.5604","11.8370","7.8914","34.1603"
"47.5200","11.8573","141.7276","11.8573","7.9049","34.2007"
"47.6000","11.8769","141.8970","11.8769","7.9179","34.2416"
"47.6800","11.8962","142.0617","11.8962","7.9308","34.2813"
"47.7600","11.9170","142.2351","11.9170","7.9446","34.3231"
"47.8400","11.9368","142.3999","11.9368","7.9578","34.3629"
"47.9200","11.9566","142.5771","11.9566","7.9710","34.4057"
"48.0000","11.9776","142.7647","11.9776","7.9850","34.4509"
"48.0800","11.9975","142.9107","11.9975","7.9983","34.4862"
"48.1600","12.0175","143.0777","12.0175","8.0117","34.5265"
"48.2400","12.0374","143.2319","12.0374","8.0250","34.5637"
"48.3200","12.0561","143.3893","12.0561","8.0374","34.6017"
"48.4000","12.0769","143.5616","12.0769","8.0513","34.6433"
"48.4800","12.0960","143.7045","12.0960","8.0640","34.6777"
"48.5600","12.1167","143.8738","12.1167","8.0778","34.7186"
"48.6400","12.1376","144.0526","12.1376","8.0917","34.7617"
"48.7200","12.1573","144.1961","12.1573","8.1048","34.7963"
"48.8000","12.1771","144.3547","12.1771","8.1181","34.8346"
"48.8800","12.1973","144.5005","12.1973","8.1315","34.8698"
"48.9600","12.2162","144.6446","12.2162","8.1441","34.9046"
"49.0400","12.2371","144.8138","12.2371","8.1581","34.9454"
"49.1200","12.2559","144.9484","12.2559","8.1706","34.9779"
"49.2000","12.2778","145.1303","12.2778","8.1852","35.0218"
"49.2800","12.2982","145.2837","12.2982","8.1988","35.0588"
"49.3600","12.3177","145.4476","12.3177","8.2118","35.0984"
"49.4400","12.3368","145.5718","12.3368","8.2245","35.1283"
"49.5200","12.3565","145.7140","12.3565","8.2377","35.1626"
"49.6000","12.3764","145.8595","12.3764","8.2509","35.1978"
"49.6800","12.3972","146.0153","12.3972","8.2648","35.2353"
"49.7600","12.4160","146.1412","12.4160","8.2773","35.2657"
"49.8400","12.4367","146.3047","12.4367","8.2912","35.3052"
"49.9200","12.4576","146.4493","12.4576","8.3051","35.3401"
"50.0000","12.4772","146.5908","12.4772","8.3181","35.3742"
"50.0800","12.4974","146.7342","12.4974","8.3316","35.4088"
"50.1600","12.5161","146.8466","12.5161","8.3441","35.4360"
"50.2400","12.5368","146.9926","12.5368","8.3579","35.4712"
"50.3200","12.5567","147.1256","12.5567","8.3711","35.5033"
"50.4000","12.5766","147.2757","12.5766","8.3844","35.5395"
"50.4800","12.5975","147.4181","12.5975","8.3983","35.5739"
"50.5600","12.6181","147.5529","12.6181","8.4120","35.6064"
"50.6400","12.6372","147.6742","12.6372","8.4248","35.6357"
"50.7200","12.6571","147.7979","12.6571","8.4381","35.6655"
"50.8000","12.6758","147.9116","12.6758","8.4505","35.6930"
"50.8800","12.6972","148.0594","12.6972","8.4648","35.7286"
"50.9600","12.7165","148.1698","12.7165","8.4777","35.7553"
"51.0400","12.7363","148.2956","12.7363","8.4908","35.7856"
"51.1200","12.7565","148.4275","12.7565","8.5043","35.8174"
"51.2000","12.7774","148.5530","12.7774","8.5183","35.8477"
"51.2800","12.7978","148.6736","12.7978","8.5318","35.8768"
"51.3600","12.8176","148.7822","12.8176","8.5450","35.9030"
"51.4400","12.8358","148.8847","12.8358","8.5572","35.9278"
"51.5200","12.8562","149.0038","12.8562","8.5708","35.9565"
"51.6000","12.8768","149.1265","12.8768","8.5845","35.9861"
"51.6800","12.8976","149.2511","12.8976","8.5984","36.0162"
"51.7600","12.9183","149.3576","12.9183","8.6122","36.0419"
"51.8400","12.9374","149.4299","12.9374","8.6250","36.0593"
"51.9200","12.9573","149.5340","12.9573","8.6382","36.0845"
"52.0000","12.9771","149.6401","12.9771","8.6514","36.1101"
"52.0800","12.9968","149.7315","12.9968","8.6645","36.1321"
"52.1600","13.0172","149.8477","13.0172","8.6781","36.1602"
"52.2400","13.0360","149.9178","13.0360","8.6907","36.1771"
"52.3200","13.0562","150.0182","13.0562","8.7041","36.2013"
"52.4000","13.0780","150.1371","13.0780","8.7186","36.2300"
"52.4800","13.0973","150.2283","13.0973","8.7316","36.2520"
"52.5600","13.1174","150.3172","13.1174","8.7450","36.2735"
"52.6400","13.1363","150.3955","13.1363","8.7575","36.2923"
"52.7200","13.1563","150.4895","13.1563","8.7709","36.3150"
"52.8000","13.1765","150.5914","13.1765","8.7844","36.3396"
"52.8800","13.1969","150.6706","13.1969","8.7979","36.3587"
"52.9600","13.2173","150.7773","13.2173","8.8115","36.3845"
"53.0400","13.2381","150.8704","13.2381","8.8254","36.4070"
"53.1200","13.2571","150.9399","13.2571","8.8380","36.4237"
"53.2000","13.2771","151.0282","13.2771","8.8514","36.4450"
"53.2800","13.2966","151.1039","13.2966","8.8644","36.4633"
"53.3600","13.3170","151.1890","13.3170","8.8780","36.4838"
"53.4400","13.3367","151.2618","13.3367","8.8912","36.5014"
"53.5200","13.3555","151.3251","13.3555","8.9037","36.5167"
"53.6000","13.3766","151.4222","13.3766","8.9178","36.5401"
"53.6800","13.3975","151.5202","13.3975","8.9317","36.5637"
"53.7600","13.4173","151.5891","13.4173","8.9449","36.5804"
"53.8400","13.4369","151.6633","13.4369","8.9579","36.5983"
"53.9200","13.4563","151.7228","13.4563","8.9709","36.6126"
"54.0000","13.4768","151.8114","13.4768","8.9846","36.6340"
"54.0800","13.4973","151.8904","13.4973","8.9982","36.6531"
"54.1600","13.5169","151.9588","13.5169","9.0113","36.6696"
"54.2400","13.5375","152.0554","13.5375","9.0250","36.6929"
"54.3200","13.5571","152.1043","13.5571","9.0381","36.7047"
"54.4000","13.5778","152.1779","13.5778","9.0518","36.7225"
"54.4800","13.5974","152.2482","13.5974","9.0650","36.7394"
"54.5600","13.6165","152.3082","13.6165","9.0777","36.7539"
"54.6400","13.6366","152.3831","13.6366","9.0911","36.7720"
"54.7200","13.6563","152.4326","13.6563","9.1042","36.7839"
"54.8000","13.6760","152.5140","13.6760","9.1173","36.8036"
"54.8800","13.6977","152.5916","13.6977","9.1318","36.8223"
"54.9600","13.7171","152.6555","13.7171","9.1447","36.8377"
"55.0400","13.7376","152.7205","13.7376","9.1584","36.8534"
"55.1200","13.7568","152.7757","13.7568","9.1712","36.8667"
"55.2000","13.7764","152.8407","13.7764","9.1842","36.8824"
"55.2800","13.7964","152.9122","13.7964","9.1976","36.8997"
"55.3600","13.8166","152.9742","13.8166","9.2111","36.9146"
"55.4400","13.8371","153.0341","13.8371","9.2247","36.9291"
"55.5200","13.8579","153.1009","13.8579","9.2386","36.9452"
"55.6000","13.8768","153.1496","13.8768","9.2512","36.9569"
"55.6800","13.8978","153.2190","13.8978","9.2652","36.9737"
"55.7600","13.9172","153.2638","13.9172","9.2781","36.9845"
"55.8400","13.9362","153.3161","13.9362","9.2908","36.9971"
"55.9200","13.9566","153.3805","13.9566","9.3044","37.0127"
"56.0000","13.9758","153.4264","13.9758","9.3172","37.0237"
"56.0800","13.9969","153.4888","13.9969","9.3313","37.0388"
"56.1600","14.0180","153.5644","14.0180","9.3453","37.0570"
"56.2400","14.0371","153.5980","14.0371","9.3580","37.0651"
"56.3200","14.0568","153.6608","14.0568","9.3712","37.0803"
"56.4000","14.0769","153.7086","14.0769","9.3846","37.0918"
"56.4800","14.0972","153.7491","14.0972","9.3981","37.1016"
"56.5600","14.1173","153.8038","14.1173","9.4116","37.1148"
"56.6400","14.1362","153.8419","14.1362","9.4241","37.1240"
"56.7200","14.1572","153.9091","14.1572","9.4381","37.1402"
"56.8000","14.1778","153.9593","14.1778","9.4519","37.1523"
"56.8800","14.1980","154.0162","14.1980","9.4653","37.1661"
"56.9600","14.2171","154.0535","14.2171","9.4781","37.1751"
"57.0400","14.2362","154.0767","14.2362","9.4908","37.1807"
"57.1200","14.2566","154.1242","14.2566","9.5044","37.1921"
"57.2000","14.2769","154.1510","14.2769","9.5180","37.1986"
"57.2800","14.2957","154.1967","14.2957","9.5304","37.2096"
"57.3600","14.3170","154.2659","14.3170","9.5446","37.2263"
"57.4400","14.3370","154.2978","14.3370","9.5580","37.2340"
"57.5200","14.3575","154.3488","14.3575","9.5717","37.2463"
"57.6000","14.3774","154.3813","14.3774","9.5849","37.2542"
"57.6800","14.3961","154.4085","14.3961","9.5974","37.2607"
"57.7600","14.4169","154.4524","14.4169","9.6113","37.2713"
"57.8400","14.4368","154.4884","14.4368","9.6245","37.2800"
"57.9200","14.4568","154.5184","14.4568","9.6379","37.2873"
"58.0000","14.4774","154.5611","14.4774","9.6516","37.2976"
"58.0800","14.4973","154.5983","14.4973","9.6649","37.3065"
"58.1600","14.5172","154.6156","14.5172","9.6782","37.3107"
"58.2400","14.5374","154.6538","14.5374","9.6916","37.3199"
"58.3200","14.5561","154.6786","14.5561","9.7041","37.3259"
"58.4000","14.5767","154.7218","14.5767","9.7178","37.3363"
"58.4800","14.5961","154.7458","14.5961","9.7308","37.3421"
"58.5600","14.6163","154.7737","14.6163","9.7442","37.3489"
"58.6400","14.6368","154.8117","14.6368","9.7579","37.3580"
"58.7200","14.6574","154.8446","14.6574","9.7716","37.3660"
"58.8000","14.6773","154.8729","14.6773","9.7849","37.3728"
"58.8800","14.6976","154.9041","14.6976","9.7984","37.3803"
"58.9600","14.7169","154.9290","14.7169","9.8113","37.3863"
"59.0400","14.7368","154.9578","14.7368","9.8245","37.3933"
"59.1200","14.7558","154.9645","14.7558","9.8372","37.3949"
"59.2000","14.7774","155.0140","14.7774","9.8516","37.4069"
"59.2800","14.7982","155.0353","14.7982","9.8655","37.4120"
"59.3600","14.8177","155.0658","14.8177","9.8785","37.4193"
"59.4400","14.8370","155.0701","14.8370","9.8913","37.4204"
"59.5200","14.8564","155.0847","14.8564","9.9043","37.4239"
"59.6000","14.8764","155.1169","14.8764","9.9176","37.4317"
"59.6800","14.8968","155.1406","14.8968","9.9312","37.4374"
"59.7600","14.9160","155.1545","14.9160","9.9440","37.4408"
"59.8400","14.9372","155.1948","14.9372","9.9581","37.4505"
"59.9200","14.9572","155.2074","14.9572","9.9714","37.4535"
"60.0000","14.9768","155.2334","14.9768","9.9845","37.4598"
"60.0800","14.9973","155.2490","14.9973","9.9982","37.4636"
"60.0910","15.0002","155.2478","15.0002","10.0001","37.4633"