File: data/instron_tests/metamaterials/250327/250327_1467_BULK_m2_2mmTransition.is_comp_Exports/250327_1467_BULK_m2_2mmTransition_1_1.csv
Results Table 1
,Compression Axis,H*,V*,Height,Thickness,Width,Area,Fixture separation,Specimen label
,,,,(mm),(mm),(mm),(mm^2),(mm),
"1","Y","","","148.00","28.00","148.00","4144.00","150.00","1467_BULK_m2_2mmTransition"

Results Table 2
,Modulus (Segment 0 % - 5 %),Compression Axis
,(kPa),
"1","490.94","Y"

Time,Displacement,Force,Compressive displacement,Compressive strain (Displacement),Compressive stress
(s),(mm),(N),(mm),(%),(kPa)
"0.0000","0.0000","-7.6567","0.0000","0.0000","-1.8477"
"0.0800","0.0012","-7.6144","0.0012","0.0008","-1.8374"
"0.1600","0.0174","-7.2985","0.0174","0.0116","-1.7612"
"0.2400","0.0381","-6.9181","0.0381","0.0254","-1.6694"
"0.3200","0.0573","-6.5751","0.0573","0.0382","-1.5866"
"0.4000","0.0768","-6.2156","0.0768","0.0512","-1.4999"
"0.4800","0.0982","-5.8369","0.0982","0.0654","-1.4085"
"0.5600","0.1180","-5.5097","0.1180","0.0786","-1.3296"
"0.6400","0.1371","-5.1887","0.1371","0.0914","-1.2521"
"0.7200","0.1570","-4.8487","0.1570","0.1046","-1.1701"
"0.8000","0.1764","-4.5245","0.1764","0.1176","-1.0918"
"0.8800","0.1972","-4.1830","0.1972","0.1314","-1.0094"
"0.9600","0.2170","-3.8501","0.2170","0.1446","-0.9291"
"1.0400","0.2359","-3.5376","0.2359","0.1573","-0.8537"
"1.1200","0.2570","-3.1847","0.2570","0.1713","-0.7685"
"1.2000","0.2775","-2.8639","0.2775","0.1850","-0.6911"
"1.2800","0.2980","-2.5330","0.2980","0.1987","-0.6112"
"1.3600","0.3172","-2.2419","0.3172","0.2115","-0.5410"
"1.4400","0.3357","-1.9393","0.3357","0.2238","-0.4680"
"1.5200","0.3563","-1.6461","0.3563","0.2375","-0.3972"
"1.6000","0.3767","-1.3301","0.3767","0.2511","-0.3210"
"1.6800","0.3976","-1.0012","0.3976","0.2651","-0.2416"
"1.7600","0.4182","-0.6890","0.4182","0.2788","-0.1663"
"1.8400","0.4371","-0.3994","0.4371","0.2914","-0.0964"
"1.9200","0.4574","-0.0838","0.4574","0.3049","-0.0202"
"2.0000","0.4772","0.2060","0.4772","0.3182","0.0497"
"2.0800","0.4964","0.5047","0.4964","0.3309","0.1218"
"2.1600","0.5168","0.8213","0.5168","0.3446","0.1982"
"2.2400","0.5362","1.1118","0.5362","0.3575","0.2683"
"2.3200","0.5568","1.4129","0.5568","0.3712","0.3410"
"2.4000","0.5775","1.7355","0.5775","0.3850","0.4188"
"2.4800","0.5973","2.0300","0.5973","0.3982","0.4899"
"2.5600","0.6175","2.3407","0.6175","0.4117","0.5648"
"2.6400","0.6365","2.6228","0.6365","0.4243","0.6329"
"2.7200","0.6563","2.9302","0.6563","0.4375","0.7071"
"2.8000","0.6767","3.2387","0.6767","0.4511","0.7815"
"2.8800","0.6962","3.5236","0.6962","0.4641","0.8503"
"2.9600","0.7177","3.8618","0.7177","0.4785","0.9319"
"3.0400","0.7381","4.1545","0.7381","0.4921","1.0025"
"3.1200","0.7569","4.4410","0.7569","0.5046","1.0717"
"3.2000","0.7773","4.7494","0.7773","0.5182","1.1461"
"3.2800","0.7970","5.0416","0.7970","0.5313","1.2166"
"3.3600","0.8170","5.3368","0.8170","0.5447","1.2878"
"3.4400","0.8364","5.6255","0.8364","0.5576","1.3575"
"3.5200","0.8556","5.9131","0.8556","0.5704","1.4269"
"3.6000","0.8769","6.2353","0.8769","0.5846","1.5046"
"3.6800","0.8978","6.5490","0.8978","0.5985","1.5803"
"3.7600","0.9175","6.8402","0.9175","0.6117","1.6506"
"3.8400","0.9373","7.1420","0.9373","0.6248","1.7235"
"3.9200","0.9559","7.4112","0.9559","0.6372","1.7884"
"4.0000","0.9764","7.7222","0.9764","0.6509","1.8635"
"4.0800","0.9973","8.0367","0.9973","0.6649","1.9394"
"4.1600","1.0170","8.3329","1.0170","0.6780","2.0108"
"4.2400","1.0376","8.6418","1.0376","0.6917","2.0854"
"4.3200","1.0574","8.9281","1.0574","0.7049","2.1545"
"4.4000","1.0778","9.2221","1.0778","0.7186","2.2254"
"4.4800","1.0974","9.5103","1.0974","0.7316","2.2950"
"4.5600","1.1163","9.7913","1.1163","0.7442","2.3628"
"4.6400","1.1364","10.0920","1.1364","0.7576","2.4353"
"4.7200","1.1563","10.3798","1.1563","0.7709","2.5048"
"4.8000","1.1763","10.6763","1.1763","0.7842","2.5763"
"4.8800","1.1978","10.9968","1.1978","0.7985","2.6537"
"4.9600","1.2171","11.2780","1.2171","0.8114","2.7215"
"5.0400","1.2375","11.5705","1.2375","0.8250","2.7921"
"5.1200","1.2565","11.8375","1.2565","0.8377","2.8565"
"5.2000","1.2761","12.1362","1.2761","0.8508","2.9286"
"5.2800","1.2972","12.4446","1.2972","0.8648","3.0030"
"5.3600","1.3171","12.7394","1.3171","0.8781","3.0742"
"5.4400","1.3372","13.0302","1.3372","0.8915","3.1444"
"5.5200","1.3578","13.3272","1.3578","0.9052","3.2160"
"5.6000","1.3773","13.6225","1.3773","0.9182","3.2873"
"5.6800","1.3977","13.9167","1.3977","0.9318","3.3583"
"5.7600","1.4171","14.1957","1.4171","0.9448","3.4256"
"5.8400","1.4367","14.4778","1.4367","0.9578","3.4937"
"5.9200","1.4565","14.7636","1.4565","0.9710","3.5627"
"6.0000","1.4758","15.0447","1.4758","0.9838","3.6305"
"6.0800","1.4972","15.3605","1.4972","0.9981","3.7067"
"6.1600","1.5179","15.6608","1.5179","1.0119","3.7791"
"6.2400","1.5372","15.9421","1.5372","1.0248","3.8470"
"6.3200","1.5567","16.2270","1.5567","1.0378","3.9158"
"6.4000","1.5765","16.5143","1.5765","1.0510","3.9851"
"6.4800","1.5967","16.7994","1.5967","1.0644","4.0539"
"6.5600","1.6174","17.1032","1.6174","1.0783","4.1272"
"6.6400","1.6363","17.3726","1.6363","1.0909","4.1922"
"6.7200","1.6576","17.6863","1.6576","1.1050","4.2679"
"6.8000","1.6774","17.9719","1.6774","1.1183","4.3368"
"6.8800","1.6978","18.2694","1.6978","1.1318","4.4086"
"6.9600","1.7171","18.5494","1.7171","1.1447","4.4762"
"7.0400","1.7365","18.8257","1.7365","1.1577","4.5429"
"7.1200","1.7566","19.1056","1.7566","1.1711","4.6104"
"7.2000","1.7773","19.4035","1.7773","1.1848","4.6823"
"7.2800","1.7960","19.6731","1.7960","1.1973","4.7474"
"7.3600","1.8170","19.9840","1.8170","1.2113","4.8224"
"7.4400","1.8371","20.2680","1.8371","1.2247","4.8909"
"7.5200","1.8573","20.5491","1.8573","1.2382","4.9588"
"7.6000","1.8771","20.8319","1.8771","1.2514","5.0270"
"7.6800","1.8967","21.1135","1.8967","1.2645","5.0950"
"7.7600","1.9170","21.3946","1.9170","1.2780","5.1628"
"7.8400","1.9368","21.6855","1.9368","1.2912","5.2330"
"7.9200","1.9568","21.9641","1.9568","1.3045","5.3002"
"8.0000","1.9779","22.2730","1.9779","1.3186","5.3747"
"8.0800","1.9975","22.5390","1.9975","1.3317","5.4389"
"8.1600","2.0176","22.8189","2.0176","1.3451","5.5065"
"8.2400","2.0370","23.0868","2.0370","1.3580","5.5711"
"8.3200","2.0562","23.3728","2.0562","1.3708","5.6402"
"8.4000","2.0770","23.6734","2.0770","1.3846","5.7127"
"8.4800","2.0965","23.9544","2.0965","1.3976","5.7805"
"8.5600","2.1170","24.2492","2.1170","1.4113","5.8516"
"8.6400","2.1373","24.5251","2.1373","1.4249","5.9182"
"8.7200","2.1571","24.8123","2.1571","1.4381","5.9875"
"8.8000","2.1771","25.0950","2.1771","1.4514","6.0557"
"8.8800","2.1974","25.3913","2.1974","1.4649","6.1272"
"8.9600","2.2164","25.6511","2.2164","1.4776","6.1899"
"9.0400","2.2370","25.9531","2.2370","1.4913","6.2628"
"9.1200","2.2561","26.2222","2.2561","1.5041","6.3277"
"9.2000","2.2775","26.5295","2.2775","1.5184","6.4019"
"9.2800","2.2983","26.8180","2.2983","1.5322","6.4715"
"9.3600","2.3175","27.1002","2.3175","1.5450","6.5396"
"9.4400","2.3371","27.3734","2.3371","1.5581","6.6055"
"9.5200","2.3565","27.6456","2.3565","1.5710","6.6712"
"9.6000","2.3767","27.9342","2.3767","1.5845","6.7409"
"9.6800","2.3973","28.2267","2.3973","1.5982","6.8115"
"9.7600","2.4158","28.4847","2.4158","1.6105","6.8737"
"9.8400","2.4367","28.7804","2.4367","1.6245","6.9451"
"9.9200","2.4574","29.0765","2.4574","1.6382","7.0165"
"10.0000","2.4772","29.3621","2.4772","1.6515","7.0854"
"10.0800","2.4976","29.6419","2.4976","1.6650","7.1530"
"10.1600","2.5165","29.8951","2.5165","1.6777","7.2141"
"10.2400","2.5367","30.1751","2.5367","1.6911","7.2816"
"10.3200","2.5568","30.4645","2.5568","1.7045","7.3515"
"10.4000","2.5765","30.7486","2.5765","1.7177","7.4200"
"10.4800","2.5977","31.0487","2.5977","1.7318","7.4924"
"10.5600","2.6181","31.3366","2.6181","1.7454","7.5619"
"10.6400","2.6372","31.5985","2.6372","1.7581","7.6251"
"10.7200","2.6571","31.8735","2.6571","1.7714","7.6915"
"10.8000","2.6760","32.1380","2.6760","1.7840","7.7553"
"10.8800","2.6974","32.4468","2.6974","1.7983","7.8298"
"10.9600","2.7169","32.7112","2.7169","1.8112","7.8936"
"11.0400","2.7364","32.9915","2.7364","1.8242","7.9613"
"11.1200","2.7570","33.2829","2.7570","1.8380","8.0316"
"11.2000","2.7772","33.5576","2.7772","1.8515","8.0979"
"11.2800","2.7976","33.8412","2.7976","1.8651","8.1663"
"11.3600","2.8175","34.1124","2.8175","1.8783","8.2318"
"11.4400","2.8360","34.3817","2.8360","1.8907","8.2967"
"11.5200","2.8566","34.6673","2.8566","1.9044","8.3656"
"11.6000","2.8767","34.9444","2.8767","1.9178","8.4325"
"11.6800","2.8973","35.2356","2.8973","1.9316","8.5028"
"11.7600","2.9181","35.5198","2.9181","1.9454","8.5714"
"11.8400","2.9373","35.7888","2.9373","1.9582","8.6363"
"11.9200","2.9575","36.0692","2.9575","1.9717","8.7040"
"12.0000","2.9773","36.3447","2.9773","1.9848","8.7704"
"12.0800","2.9965","36.6084","2.9965","1.9977","8.8341"
"12.1600","3.0165","36.8936","3.0165","2.0110","8.9029"
"12.2400","3.0359","37.1516","3.0359","2.0239","8.9652"
"12.3200","3.0562","37.4261","3.0562","2.0375","9.0314"
"12.4000","3.0779","37.7362","3.0779","2.0520","9.1062"
"12.4800","3.0973","38.0064","3.0973","2.0648","9.1714"
"12.5600","3.1172","38.2791","3.1172","2.0781","9.2372"
"12.6400","3.1364","38.5364","3.1364","2.0910","9.2993"
"12.7200","3.1566","38.8230","3.1566","2.1044","9.3685"
"12.8000","3.1767","39.0943","3.1767","2.1178","9.4340"
"12.8800","3.1967","39.3712","3.1967","2.1311","9.5008"
"12.9600","3.2175","39.6727","3.2175","2.1450","9.5735"
"13.0400","3.2383","39.9605","3.2383","2.1588","9.6430"
"13.1200","3.2569","40.2087","3.2569","2.1713","9.7029"
"13.2000","3.2773","40.4962","3.2773","2.1849","9.7722"
"13.2800","3.2967","40.7595","3.2967","2.1978","9.8358"
"13.3600","3.3172","41.0349","3.3172","2.2115","9.9022"
"13.4400","3.3369","41.2944","3.3369","2.2246","9.9649"
"13.5200","3.3555","41.5576","3.3555","2.2370","10.0284"
"13.6000","3.3767","41.8617","3.3767","2.2511","10.1018"
"13.6800","3.3980","42.1593","3.3980","2.2654","10.1736"
"13.7600","3.4175","42.4227","3.4175","2.2783","10.2371"
"13.8400","3.4377","42.7052","3.4377","2.2918","10.3053"
"13.9200","3.4561","42.9496","3.4561","2.3041","10.3643"
"14.0000","3.4766","43.2060","3.4766","2.3177","10.4261"
"14.0800","3.4971","43.4910","3.4971","2.3314","10.4949"
"14.1600","3.5167","43.7591","3.5167","2.3444","10.5596"
"14.2400","3.5373","44.0450","3.5373","2.3582","10.6286"
"14.3200","3.5572","44.3162","3.5572","2.3715","10.6941"
"14.4000","3.5776","44.5830","3.5776","2.3851","10.7584"
"14.4800","3.5975","44.8541","3.5975","2.3983","10.8239"
"14.5600","3.6165","45.1087","3.6165","2.4110","10.8853"
"14.6400","3.6363","45.3759","3.6363","2.4242","10.9498"
"14.7200","3.6561","45.6332","3.6561","2.4374","11.0119"
"14.8000","3.6760","45.9078","3.6760","2.4506","11.0781"
"14.8800","3.6976","46.2161","3.6976","2.4651","11.1525"
"14.9600","3.7173","46.4795","3.7173","2.4782","11.2161"
"15.0400","3.7371","46.7382","3.7371","2.4914","11.2785"
"15.1200","3.7570","47.0040","3.7570","2.5047","11.3427"
"15.2000","3.7765","47.2774","3.7765","2.5177","11.4086"
"15.2800","3.7967","47.5503","3.7967","2.5312","11.4745"
"15.3600","3.8165","47.8053","3.8165","2.5443","11.5360"
"15.4400","3.8373","48.0841","3.8373","2.5582","11.6033"
"15.5200","3.8581","48.3637","3.8581","2.5721","11.6708"
"15.6000","3.8771","48.6190","3.8771","2.5847","11.7324"
"15.6800","3.8976","48.8931","3.8976","2.5984","11.7985"
"15.7600","3.9173","49.1488","3.9173","2.6115","11.8602"
"15.8400","3.9366","49.4072","3.9366","2.6244","11.9226"
"15.9200","3.9569","49.6549","3.9569","2.6379","11.9824"
"16.0000","3.9760","49.8819","3.9760","2.6506","12.0371"
"16.0800","3.9973","50.1648","3.9973","2.6648","12.1054"
"16.1600","4.0180","50.4421","4.0180","2.6787","12.1723"
"16.2400","4.0368","50.6984","4.0368","2.6912","12.2342"
"16.3200","4.0569","50.9724","4.0569","2.7046","12.3003"
"16.4000","4.0767","51.2373","4.0767","2.7178","12.3642"
"16.4800","4.0970","51.5116","4.0970","2.7313","12.4304"
"16.5600","4.1175","51.7858","4.1175","2.7450","12.4966"
"16.6400","4.1359","52.0423","4.1359","2.7573","12.5585"
"16.7200","4.1571","52.3208","4.1571","2.7714","12.6257"
"16.8000","4.1775","52.6005","4.1775","2.7850","12.6932"
"16.8800","4.1979","52.8719","4.1979","2.7986","12.7587"
"16.9600","4.2173","53.1350","4.2173","2.8116","12.8222"
"17.0400","4.2365","53.3865","4.2365","2.8243","12.8828"
"17.1200","4.2564","53.6442","4.2564","2.8376","12.9450"
"17.2000","4.2769","53.9265","4.2769","2.8513","13.0131"
"17.2800","4.2958","54.1921","4.2958","2.8639","13.0772"
"17.3600","4.3172","54.4892","4.3172","2.8781","13.1489"
"17.4400","4.3372","54.7476","4.3372","2.8915","13.2113"
"17.5200","4.3573","55.0128","4.3573","2.9049","13.2753"
"17.6000","4.3768","55.2692","4.3768","2.9178","13.3372"
"17.6800","4.3965","55.5297","4.3965","2.9310","13.4000"
"17.7600","4.4169","55.8043","4.4169","2.9446","13.4663"
"17.8400","4.4370","56.0785","4.4370","2.9580","13.5325"
"17.9200","4.4565","56.3360","4.4565","2.9710","13.5946"
"18.0000","4.4776","56.6292","4.4776","2.9850","13.6654"
"18.0800","4.4973","56.8921","4.4973","2.9982","13.7288"
"18.1600","4.5175","57.1561","4.5175","3.0117","13.7925"
"18.2400","4.5376","57.4103","4.5376","3.0251","13.8538"
"18.3200","4.5561","57.6651","4.5561","3.0374","13.9153"
"18.4000","4.5771","57.9538","4.5771","3.0514","13.9850"
"18.4800","4.5962","58.1979","4.5962","3.0641","14.0439"
"18.5600","4.6171","58.4763","4.6171","3.0781","14.1111"
"18.6400","4.6373","58.7455","4.6373","3.0915","14.1760"
"18.7200","4.6570","59.0047","4.6570","3.1046","14.2386"
"18.8000","4.6771","59.2698","4.6771","3.1181","14.3026"
"18.8800","4.6975","59.5423","4.6975","3.1317","14.3683"
"18.9600","4.7164","59.7918","4.7164","3.1443","14.4285"
"19.0400","4.7370","60.0554","4.7370","3.1580","14.4921"
"19.1200","4.7556","60.3011","4.7556","3.1704","14.5514"
"19.2000","4.7774","60.5923","4.7774","3.1849","14.6217"
"19.2800","4.7983","60.8631","4.7983","3.1989","14.6870"
"19.3600","4.8175","61.1242","4.8175","3.2117","14.7501"
"19.4400","4.8369","61.3678","4.8369","3.2246","14.8088"
"19.5200","4.8568","61.6363","4.8568","3.2378","14.8736"
"19.6000","4.8767","61.9059","4.8767","3.2512","14.9387"
"19.6800","4.8974","62.1756","4.8974","3.2649","15.0038"
"19.7600","4.9159","62.4096","4.9159","3.2772","15.0602"
"19.8400","4.9369","62.6878","4.9369","3.2913","15.1274"
"19.9200","4.9576","62.9734","4.9576","3.3051","15.1963"
"20.0000","4.9771","63.2198","4.9771","3.3181","15.2557"
"20.0800","4.9972","63.4770","4.9972","3.3315","15.3178"
"20.1600","5.0164","63.7289","5.0164","3.3443","15.3786"
"20.2400","5.0368","63.9900","5.0368","3.3579","15.4416"
"20.3200","5.0567","64.2474","5.0567","3.3711","15.5037"
"20.4000","5.0768","64.5227","5.0768","3.3845","15.5702"
"20.4800","5.0977","64.7909","5.0977","3.3985","15.6349"
"20.5600","5.1180","65.0544","5.1180","3.4120","15.6985"
"20.6400","5.1372","65.3094","5.1372","3.4248","15.7600"
"20.7200","5.1568","65.5480","5.1568","3.4379","15.8176"
"20.8000","5.1760","65.7961","5.1760","3.4506","15.8774"
"20.8800","5.1974","66.0825","5.1974","3.4649","15.9466"
"20.9600","5.2169","66.3370","5.2169","3.4779","16.0080"
"21.0400","5.2361","66.5843","5.2361","3.4907","16.0676"
"21.1200","5.2565","66.8597","5.2565","3.5044","16.1341"
"21.2000","5.2777","67.1254","5.2777","3.5185","16.1982"
"21.2800","5.2974","67.3754","5.2974","3.5316","16.2585"
"21.3600","5.3174","67.6350","5.3174","3.5449","16.3212"
"21.4400","5.3358","67.8642","5.3358","3.5572","16.3765"
"21.5200","5.3567","68.1331","5.3567","3.5711","16.4414"
"21.6000","5.3765","68.4010","5.3765","3.5844","16.5060"
"21.6800","5.3973","68.6639","5.3973","3.5982","16.5695"
"21.7600","5.4182","68.9408","5.4182","3.6121","16.6363"
"21.8400","5.4372","69.1825","5.4372","3.6248","16.6946"
"21.9200","5.4571","69.4282","5.4571","3.6380","16.7539"
"22.0000","5.4771","69.6830","5.4771","3.6514","16.8154"
"22.0800","5.4968","69.9479","5.4968","3.6646","16.8793"
"22.1600","5.5171","70.2154","5.5171","3.6781","16.9439"
"22.2400","5.5359","70.4386","5.5359","3.6906","16.9977"
"22.3200","5.5564","70.7077","5.5564","3.7042","17.0627"
"22.4000","5.5781","70.9878","5.5781","3.7187","17.1303"
"22.4800","5.5969","71.2329","5.5969","3.7313","17.1894"
"22.5600","5.6175","71.4952","5.6175","3.7450","17.2527"
"22.6400","5.6365","71.7383","5.6365","3.7577","17.3114"
"22.7200","5.6565","71.9905","5.6565","3.7710","17.3722"
"22.8000","5.6768","72.2478","5.6768","3.7845","17.4343"
"22.8800","5.6969","72.5059","5.6969","3.7979","17.4966"
"22.9600","5.7174","72.7710","5.7174","3.8116","17.5606"
"23.0400","5.7383","73.0399","5.7383","3.8255","17.6255"
"23.1200","5.7570","73.2723","5.7570","3.8380","17.6815"
"23.2000","5.7775","73.5377","5.7775","3.8516","17.7456"
"23.2800","5.7964","73.7766","5.7964","3.8643","17.8032"
"23.3600","5.8163","74.0202","5.8163","3.8776","17.8620"
"23.4400","5.8363","74.2698","5.8363","3.8908","17.9223"
"23.5200","5.8559","74.5238","5.8559","3.9039","17.9836"
"23.6000","5.8771","74.7971","5.8771","3.9180","18.0495"
"23.6800","5.8980","75.0673","5.8980","3.9320","18.1147"
"23.7600","5.9175","75.3019","5.9175","3.9450","18.1713"
"23.8400","5.9373","75.5549","5.9373","3.9582","18.2324"
"23.9200","5.9559","75.7882","5.9559","3.9706","18.2887"
"24.0000","5.9767","76.0492","5.9767","3.9845","18.3516"
"24.0800","5.9973","76.3154","5.9973","3.9982","18.4159"
"24.1600","6.0167","76.5626","6.0167","4.0111","18.4755"
"24.2400","6.0377","76.8344","6.0377","4.0252","18.5411"
"24.3200","6.0571","77.0686","6.0571","4.0381","18.5976"
"24.4000","6.0781","77.3260","6.0781","4.0520","18.6598"
"24.4800","6.0978","77.5754","6.0978","4.0652","18.7199"
"24.5600","6.1169","77.8258","6.1169","4.0779","18.7803"
"24.6400","6.1363","78.0692","6.1363","4.0909","18.8391"
"24.7200","6.1562","78.3158","6.1562","4.1041","18.8986"
"24.8000","6.1760","78.5717","6.1760","4.1173","18.9603"
"24.8800","6.1978","78.8617","6.1978","4.1319","19.0303"
"24.9600","6.2170","79.0885","6.2170","4.1446","19.0851"
"25.0400","6.2376","79.3369","6.2376","4.1584","19.1450"
"25.1200","6.2567","79.5683","6.2567","4.1711","19.2009"
"25.2000","6.2762","79.8233","6.2762","4.1841","19.2624"
"25.2800","6.2969","80.0943","6.2969","4.1979","19.3278"
"25.3600","6.3168","80.3333","6.3168","4.2112","19.3854"
"25.4400","6.3374","80.5895","6.3374","4.2249","19.4473"
"25.5200","6.3582","80.8550","6.3582","4.2388","19.5113"
"25.6000","6.3772","81.0903","6.3772","4.2514","19.5681"
"25.6800","6.3975","81.3431","6.3975","4.2650","19.6291"
"25.7600","6.4173","81.5796","6.4173","4.2782","19.6862"
"25.8400","6.4365","81.8142","6.4365","4.2910","19.7428"
"25.9200","6.4564","82.0687","6.4564","4.3043","19.8042"
"26.0000","6.4758","82.3017","6.4758","4.3172","19.8604"
"26.0800","6.4975","82.5783","6.4975","4.3317","19.9272"
"26.1600","6.5182","82.8302","6.5182","4.3454","19.9880"
"26.2400","6.5373","83.0516","6.5373","4.3582","20.0414"
"26.3200","6.5568","83.3062","6.5568","4.3712","20.1028"
"26.4000","6.5766","83.5334","6.5766","4.3844","20.1577"
"26.4800","6.5972","83.7942","6.5972","4.3981","20.2206"
"26.5600","6.6177","84.0473","6.6177","4.4118","20.2817"
"26.6400","6.6360","84.2667","6.6360","4.4240","20.3346"
"26.7200","6.6570","84.5326","6.6570","4.4380","20.3988"
"26.8000","6.6774","84.7904","6.6774","4.4516","20.4610"
"26.8800","6.6980","85.0533","6.6980","4.4653","20.5244"
"26.9600","6.7175","85.2828","6.7175","4.4783","20.5798"
"27.0400","6.7363","85.5062","6.7363","4.4909","20.6337"
"27.1200","6.7565","85.7607","6.7565","4.5044","20.6951"
"27.2000","6.7771","86.0070","6.7771","4.5180","20.7546"
"27.2800","6.7958","86.2463","6.7958","4.5305","20.8123"
"27.3600","6.8172","86.5230","6.8172","4.5448","20.8791"
"27.4400","6.8370","86.7601","6.8370","4.5580","20.9363"
"27.5200","6.8574","87.0057","6.8574","4.5716","20.9956"
"27.6000","6.8770","87.2622","6.8770","4.5847","21.0575"
"27.6800","6.8962","87.4967","6.8962","4.5975","21.1141"
"27.7600","6.9168","87.7444","6.9168","4.6112","21.1738"
"27.8400","6.9372","87.9936","6.9372","4.6248","21.2340"
"27.9200","6.9567","88.2422","6.9567","4.6378","21.2940"
"28.0000","6.9775","88.5004","6.9775","4.6516","21.3563"
"28.0800","6.9977","88.7441","6.9977","4.6651","21.4151"
"28.1600","7.0176","88.9829","7.0176","4.6784","21.4727"
"28.2400","7.0373","89.2204","7.0372","4.6915","21.5300"
"28.3200","7.0560","89.4529","7.0560","4.7040","21.5861"
"28.4000","7.0769","89.7159","7.0769","4.7180","21.6496"
"28.4800","7.0964","89.9478","7.0964","4.7309","21.7056"
"28.5600","7.1171","90.2066","7.1171","4.7448","21.7680"
"28.6400","7.1369","90.4400","7.1369","4.7579","21.8243"
"28.7200","7.1571","90.6814","7.1571","4.7714","21.8826"
"28.8000","7.1774","90.9297","7.1774","4.7849","21.9425"
"28.8800","7.1975","91.1751","7.1975","4.7983","22.0017"
"28.9600","7.2166","91.4030","7.2166","4.8111","22.0567"
"29.0400","7.2369","91.6540","7.2369","4.8246","22.1173"
"29.1200","7.2557","91.8784","7.2557","4.8371","22.1714"
"29.2000","7.2777","92.1480","7.2777","4.8518","22.2365"
"29.2800","7.2983","92.4003","7.2983","4.8655","22.2974"
"29.3600","7.3175","92.6427","7.3175","4.8784","22.3559"
"29.4400","7.3371","92.8648","7.3371","4.8914","22.4095"
"29.5200","7.3565","93.0959","7.3565","4.9043","22.4652"
"29.6000","7.3762","93.3286","7.3762","4.9175","22.5214"
"29.6800","7.3971","93.5886","7.3971","4.9314","22.5841"
"29.7600","7.4160","93.8122","7.4160","4.9440","22.6381"
"29.8400","7.4371","94.0661","7.4371","4.9580","22.6993"
"29.9200","7.4576","94.3227","7.4576","4.9718","22.7613"
"30.0000","7.4771","94.5534","7.4771","4.9847","22.8169"
"30.0800","7.4976","94.8074","7.4976","4.9984","22.8782"
"30.1600","7.5165","95.0288","7.5165","5.0110","22.9317"
"30.2400","7.5368","95.2619","7.5368","5.0245","22.9879"
"30.3200","7.5568","95.5010","7.5568","5.0379","23.0456"
"30.4000","7.5766","95.7415","7.5766","5.0510","23.1036"
"30.4800","7.5977","96.0120","7.5977","5.0651","23.1689"
"30.5600","7.6180","96.2478","7.6180","5.0787","23.2258"
"30.6400","7.6376","96.4857","7.6376","5.0918","23.2832"
"30.7200","7.6572","96.7104","7.6572","5.1048","23.3375"
"30.8000","7.6764","96.9436","7.6764","5.1176","23.3937"
"30.8800","7.6969","97.1887","7.6969","5.1313","23.4529"
"30.9600","7.7168","97.4154","7.7168","5.1445","23.5076"
"31.0400","7.7363","97.6612","7.7363","5.1575","23.5669"
"31.1200","7.7571","97.9140","7.7571","5.1714","23.6279"
"31.2000","7.7776","98.1489","7.7776","5.1851","23.6846"
"31.2800","7.7976","98.3964","7.7976","5.1984","23.7443"
"31.3600","7.8173","98.6251","7.8173","5.2116","23.7995"
"31.4400","7.8356","98.8433","7.8356","5.2238","23.8522"
"31.5200","7.8567","99.0953","7.8567","5.2378","23.9130"
"31.6000","7.8766","99.3299","7.8766","5.2511","23.9696"
"31.6800","7.8975","99.5755","7.8975","5.2650","24.0288"
"31.7600","7.9183","99.8171","7.9183","5.2789","24.0871"
"31.8400","7.9372","100.0403","7.9372","5.2915","24.1410"
"31.9200","7.9573","100.2655","7.9573","5.3049","24.1953"
"32.0000","7.9772","100.5058","7.9772","5.3181","24.2533"
"32.0800","7.9965","100.7375","7.9965","5.3310","24.3092"
"32.1600","8.0167","100.9815","8.0167","5.3444","24.3681"
"32.2400","8.0361","101.1952","8.0361","5.3574","24.4197"
"32.3200","8.0565","101.4421","8.0565","5.3710","24.4793"
"32.4000","8.0781","101.7033","8.0781","5.3854","24.5423"
"32.4800","8.0971","101.9394","8.0971","5.3981","24.5993"
"32.5600","8.1176","102.1822","8.1176","5.4117","24.6579"
"32.6400","8.1362","102.3956","8.1362","5.4242","24.7094"
"32.7200","8.1564","102.6354","8.1564","5.4376","24.7672"
"32.8000","8.1771","102.8855","8.1771","5.4514","24.8276"
"32.8800","8.1963","103.1012","8.1963","5.4642","24.8796"
"32.9600","8.2172","103.3530","8.2172","5.4781","24.9404"
"33.0400","8.2383","103.6138","8.2383","5.4922","25.0033"
"33.1200","8.2572","103.8350","8.2572","5.5048","25.0567"
"33.2000","8.2772","104.0752","8.2772","5.5182","25.1147"
"33.2800","8.2966","104.2947","8.2966","5.5310","25.1676"
"33.3600","8.3172","104.5463","8.3172","5.5448","25.2284"
"33.4400","8.3365","104.7473","8.3365","5.5577","25.2769"
"33.5200","8.3553","104.9750","8.3553","5.5702","25.3318"
"33.6000","8.3767","105.2282","8.3767","5.5845","25.3929"
"33.6800","8.3980","105.4907","8.3980","5.5987","25.4563"
"33.7600","8.4177","105.7142","8.4177","5.6118","25.5102"
"33.8400","8.4372","105.9315","8.4372","5.6248","25.5626"
"33.9200","8.4559","106.1482","8.4559","5.6373","25.6149"
"34.0000","8.4765","106.3902","8.4765","5.6510","25.6733"
"34.0800","8.4972","106.6270","8.4972","5.6648","25.7304"
"34.1600","8.5168","106.8726","8.5168","5.6779","25.7897"
"34.2400","8.5377","107.1166","8.5377","5.6918","25.8486"
"34.3200","8.5574","107.3500","8.5574","5.7049","25.9049"
"34.4000","8.5777","107.5881","8.5777","5.7185","25.9624"
"34.4800","8.5975","107.8179","8.5975","5.7317","26.0178"
"34.5600","8.6167","108.0394","8.6167","5.7444","26.0713"
"34.6400","8.6366","108.2634","8.6366","5.7578","26.1253"
"34.7200","8.6561","108.4811","8.6561","5.7707","26.1779"
"34.8000","8.6760","108.7282","8.6760","5.7840","26.2375"
"34.8800","8.6978","108.9771","8.6978","5.7985","26.2976"
"34.9600","8.7169","109.2058","8.7169","5.8112","26.3528"
"35.0400","8.7377","109.4458","8.7377","5.8252","26.4107"
"35.1200","8.7569","109.6640","8.7569","5.8379","26.4633"
"35.2000","8.7761","109.8852","8.7761","5.8507","26.5167"
"35.2800","8.7969","110.1367","8.7969","5.8646","26.5774"
"35.3600","8.8166","110.3533","8.8166","5.8777","26.6297"
"35.4400","8.8369","110.5843","8.8369","5.8913","26.6854"
"35.5200","8.8579","110.8318","8.8579","5.9053","26.7451"
"35.6000","8.8777","111.0653","8.8777","5.9185","26.8015"
"35.6800","8.8974","111.2810","8.8974","5.9316","26.8535"
"35.7600","8.9167","111.4953","8.9167","5.9445","26.9052"
"35.8400","8.9363","111.7268","8.9363","5.9575","26.9611"
"35.9200","8.9568","111.9652","8.9568","5.9712","27.0186"
"36.0000","8.9759","112.1717","8.9759","5.9840","27.0685"
"36.0800","8.9972","112.4308","8.9972","5.9982","27.1310"
"36.1600","9.0181","112.6723","9.0181","6.0121","27.1893"
"36.2400","9.0371","112.8881","9.0371","6.0247","27.2413"
"36.3200","9.0568","113.1147","9.0568","6.0379","27.2960"
"36.4000","9.0765","113.3395","9.0765","6.0510","27.3503"
"36.4800","9.0968","113.5761","9.0968","6.0646","27.4074"
"36.5600","9.1176","113.8135","9.1176","6.0784","27.4646"
"36.6400","9.1362","114.0244","9.1362","6.0908","27.5155"
"36.7200","9.1573","114.2735","9.1573","6.1049","27.5757"
"36.8000","9.1777","114.5133","9.1777","6.1185","27.6335"
"36.8800","9.1981","114.7460","9.1981","6.1320","27.6897"
"36.9600","9.2171","114.9486","9.2171","6.1447","27.7386"
"37.0400","9.2364","115.1569","9.2364","6.1576","27.7888"
"37.1200","9.2566","115.3921","9.2566","6.1710","27.8456"
"37.2000","9.2771","115.6196","9.2771","6.1847","27.9005"
"37.2800","9.2957","115.8518","9.2957","6.1972","27.9565"
"37.3600","9.3172","116.0970","9.3172","6.2115","28.0157"
"37.4400","9.3371","116.3240","9.3371","6.2247","28.0705"
"37.5200","9.3575","116.5545","9.3575","6.2383","28.1261"
"37.6000","9.3771","116.7798","9.3771","6.2514","28.1805"
"37.6800","9.3964","116.9933","9.3964","6.2642","28.2320"
"37.7600","9.4169","117.2208","9.4169","6.2779","28.2869"
"37.8400","9.4367","117.4543","9.4367","6.2912","28.3432"
"37.9200","9.4566","117.6894","9.4566","6.3044","28.4000"
"38.0000","9.4774","117.9296","9.4774","6.3183","28.4579"
"38.0800","9.4976","118.1519","9.4976","6.3317","28.5116"
"38.1600","9.5176","118.3725","9.5176","6.3451","28.5648"
"38.2400","9.5373","118.5892","9.5373","6.3582","28.6171"
"38.3200","9.5555","118.7898","9.5555","6.3703","28.6655"
"38.4000","9.5770","119.0436","9.5770","6.3846","28.7267"
"38.4800","9.5966","119.2532","9.5966","6.3977","28.7773"
"38.5600","9.6172","119.4892","9.6172","6.4115","28.8343"
"38.6400","9.6373","119.7163","9.6373","6.4249","28.8891"
"38.7200","9.6572","119.9288","9.6572","6.4381","28.9404"
"38.8000","9.6771","120.1551","9.6771","6.4514","28.9950"
"38.8800","9.6977","120.3832","9.6977","6.4651","29.0500"
"38.9600","9.7165","120.6045","9.7165","6.4777","29.1034"
"39.0400","9.7371","120.8353","9.7371","6.4914","29.1591"
"39.1200","9.7558","121.0318","9.7558","6.5039","29.2065"
"39.2000","9.7772","121.2776","9.7772","6.5182","29.2658"
"39.2800","9.7982","121.5203","9.7982","6.5321","29.3244"
"39.3600","9.8176","121.7366","9.8176","6.5451","29.3766"
"39.4400","9.8370","121.9597","9.8370","6.5580","29.4304"
"39.5200","9.8566","122.1689","9.8566","6.5711","29.4809"
"39.6000","9.8766","122.3970","9.8766","6.5844","29.5360"
"39.6800","9.8972","122.6282","9.8972","6.5981","29.5918"
"39.7600","9.9159","122.8297","9.9159","6.6106","29.6404"
"39.8400","9.9368","123.0638","9.9368","6.6245","29.6969"
"39.9200","9.9577","123.3015","9.9577","6.6385","29.7542"
"40.0000","9.9772","123.5145","9.9772","6.6515","29.8056"
"40.0800","9.9973","123.7512","9.9973","6.6649","29.8628"
"40.1600","10.0164","123.9374","10.0164","6.6776","29.9077"
"40.2400","10.0371","124.1625","10.0371","6.6914","29.9620"
"40.3200","10.0569","124.3762","10.0569","6.7046","30.0136"
"40.4000","10.0766","124.6108","10.0766","6.7177","30.0702"
"40.4800","10.0976","124.8556","10.0976","6.7317","30.1292"
"40.5600","10.1181","125.0726","10.1181","6.7454","30.1816"
"40.6400","10.1370","125.2684","10.1370","6.7580","30.2289"
"40.7200","10.1570","125.4829","10.1570","6.7713","30.2806"
"40.8000","10.1756","125.6794","10.1756","6.7837","30.3280"
"40.8800","10.1975","125.9219","10.1975","6.7983","30.3865"
"40.9600","10.2166","126.1277","10.2166","6.8111","30.4362"
"41.0400","10.2365","126.3503","10.2365","6.8243","30.4899"
"41.1200","10.2566","126.5817","10.2566","6.8377","30.5458"
"41.2000","10.2776","126.8163","10.2776","6.8517","30.6024"
"41.2800","10.2977","127.0327","10.2977","6.8651","30.6546"
"41.3600","10.3175","127.2374","10.3175","6.8784","30.7040"
"41.4400","10.3360","127.4328","10.3360","6.8907","30.7512"
"41.5200","10.3565","127.6628","10.3565","6.9043","30.8066"
"41.6000","10.3766","127.8808","10.3766","6.9177","30.8593"
"41.6800","10.3975","128.1026","10.3975","6.9317","30.9128"
"41.7600","10.4185","128.3404","10.4185","6.9456","30.9702"
"41.8400","10.4374","128.5267","10.4374","6.9583","31.0151"
"41.9200","10.4572","128.7328","10.4572","6.9715","31.0649"
"42.0000","10.4773","128.9443","10.4773","6.9849","31.1159"
"42.0800","10.4967","129.1588","10.4967","6.9978","31.1677"
"42.1600","10.5167","129.3734","10.5167","7.0111","31.2194"
"42.2400","10.5357","129.5595","10.5357","7.0238","31.2644"
"42.3200","10.5565","129.7823","10.5565","7.0376","31.3181"
"42.4000","10.5780","130.0194","10.5780","7.0520","31.3753"
"42.4800","10.5971","130.2015","10.5971","7.0647","31.4193"
"42.5600","10.6174","130.4048","10.6174","7.0783","31.4684"
"42.6400","10.6365","130.5955","10.6365","7.0910","31.5144"
"42.7200","10.6568","130.8053","10.6568","7.1045","31.5650"
"42.8000","10.6768","131.0049","10.6768","7.1179","31.6131"
"42.8800","10.6968","131.2101","10.6968","7.1312","31.6627"
"42.9600","10.7170","131.4092","10.7170","7.1447","31.7107"
"43.0400","10.7381","131.6265","10.7381","7.1588","31.7631"
"43.1200","10.7566","131.8208","10.7566","7.1710","31.8100"
"43.2000","10.7773","132.0403","10.7773","7.1849","31.8630"
"43.2800","10.7972","132.2446","10.7972","7.1982","31.9123"
"43.3600","10.8172","132.4345","10.8172","7.2115","31.9581"
"43.4400","10.8364","132.5806","10.8364","7.2243","31.9934"
"43.5200","10.8554","132.7772","10.8554","7.2369","32.0408"
"43.6000","10.8769","133.0205","10.8769","7.2513","32.0995"
"43.6800","10.8978","133.2363","10.8978","7.2652","32.1516"
"43.7600","10.9173","133.4420","10.9173","7.2782","32.2012"
"43.8400","10.9375","133.6415","10.9375","7.2917","32.2494"
"43.9200","10.9563","133.8348","10.9563","7.3042","32.2960"
"44.0000","10.9766","134.0433","10.9766","7.3177","32.3463"
"44.0800","10.9973","134.2589","10.9973","7.3316","32.3984"
"44.1600","11.0168","134.4584","11.0168","7.3445","32.4465"
"44.2400","11.0375","134.6717","11.0375","7.3584","32.4980"
"44.3200","11.0573","134.8650","11.0573","7.3715","32.5446"
"44.4000","11.0778","135.0775","11.0778","7.3852","32.5959"
"44.4800","11.0974","135.2670","11.0974","7.3983","32.6416"
"44.5600","11.1168","135.4714","11.1168","7.4112","32.6910"
"44.6400","11.1365","135.6748","11.1365","7.4244","32.7401"
"44.7200","11.1563","135.8697","11.1563","7.4375","32.7871"
"44.8000","11.1759","136.0672","11.1759","7.4506","32.8347"
"44.8800","11.1980","136.3055","11.1980","7.4653","32.8922"
"44.9600","11.2170","136.4819","11.2170","7.4780","32.9348"
"45.0400","11.2374","136.6809","11.2374","7.4916","32.9828"
"45.1200","11.2568","136.8619","11.2568","7.5046","33.0265"
"45.2000","11.2764","137.0632","11.2764","7.5176","33.0751"
"45.2800","11.2966","137.2567","11.2966","7.5311","33.1218"
"45.3600","11.3170","137.4514","11.3170","7.5446","33.1688"
"45.4400","11.3369","137.6023","11.3369","7.5579","33.2052"
"45.5200","11.3579","137.8088","11.3579","7.5719","33.2550"
"45.6000","11.3767","137.9809","11.3767","7.5844","33.2966"
"45.6800","11.3976","138.1854","11.3976","7.5984","33.3459"
"45.7600","11.4172","138.3779","11.4172","7.6115","33.3924"
"45.8400","11.4367","138.5699","11.4367","7.6244","33.4387"
"45.9200","11.4568","138.7612","11.4568","7.6379","33.4848"
"46.0000","11.4758","138.9370","11.4758","7.6505","33.5273"
"46.0800","11.4973","139.1504","11.4973","7.6648","33.5788"
"46.1600","11.5180","139.3471","11.5180","7.6787","33.6262"
"46.2400","11.5372","139.5267","11.5372","7.6915","33.6696"
"46.3200","11.5567","139.7036","11.5567","7.7045","33.7123"
"46.4000","11.5764","139.8773","11.5764","7.7176","33.7542"
"46.4800","11.5968","140.0728","11.5968","7.7312","33.8013"
"46.5600","11.6179","140.2745","11.6179","7.7453","33.8500"
"46.6400","11.6363","140.4410","11.6363","7.7575","33.8902"
"46.7200","11.6574","140.6480","11.6574","7.7716","33.9402"
"46.8000","11.6775","140.8260","11.6775","7.7850","33.9831"
"46.8800","11.6978","141.0153","11.6978","7.7985","34.0288"
"46.9600","11.7170","141.1882","11.7170","7.8113","34.0705"
"47.0400","11.7366","141.3524","11.7366","7.8244","34.1101"
"47.1200","11.7567","141.5372","11.7567","7.8378","34.1547"
"47.2000","11.7773","141.7229","11.7773","7.8516","34.1995"
"47.2800","11.7960","141.8992","11.7960","7.8640","34.2421"
"47.3600","11.8169","142.0938","11.8169","7.8779","34.2890"
"47.4400","11.8370","142.2583","11.8370","7.8914","34.3288"
"47.5200","11.8573","142.4326","11.8573","7.9048","34.3708"
"47.6000","11.8774","142.5852","11.8774","7.9183","34.4076"
"47.6800","11.8964","142.7537","11.8964","7.9309","34.4483"
"47.7600","11.9169","142.9311","11.9169","7.9446","34.4911"
"47.8400","11.9367","143.0965","11.9367","7.9578","34.5310"
"47.9200","11.9567","143.2735","11.9567","7.9711","34.5737"
"48.0000","11.9777","143.4651","11.9777","7.9851","34.6199"
"48.0800","11.9974","143.6296","11.9974","7.9983","34.6597"
"48.1600","12.0171","143.7807","12.0171","8.0114","34.6961"
"48.2400","12.0373","143.9431","12.0373","8.0249","34.7353"
"48.3200","12.0561","144.1075","12.0561","8.0374","34.7750"
"48.4000","12.0771","144.2789","12.0771","8.0514","34.8163"
"48.4800","12.0964","144.4355","12.0964","8.0643","34.8541"
"48.5600","12.1173","144.6040","12.1173","8.0782","34.8948"
"48.6400","12.1375","144.7612","12.1375","8.0917","34.9327"
"48.7200","12.1569","144.8997","12.1569","8.1046","34.9661"
"48.8000","12.1771","145.0590","12.1771","8.1180","35.0046"
"48.8800","12.1974","145.2147","12.1974","8.1316","35.0422"
"48.9600","12.2165","145.3660","12.2165","8.1443","35.0787"
"49.0400","12.2373","145.5319","12.2373","8.1582","35.1187"
"49.1200","12.2561","145.6547","12.2561","8.1707","35.1483"
"49.2000","12.2775","145.8212","12.2775","8.1850","35.1885"
"49.2800","12.2981","145.9815","12.2981","8.1987","35.2272"
"49.3600","12.3179","146.1151","12.3179","8.2119","35.2594"
"49.4400","12.3369","146.2412","12.3369","8.2246","35.2899"
"49.5200","12.3566","146.3688","12.3566","8.2377","35.3207"
"49.6000","12.3762","146.5017","12.3762","8.2508","35.3527"
"49.6800","12.3973","146.6511","12.3973","8.2649","35.3888"
"49.7600","12.4159","146.7582","12.4159","8.2773","35.4146"
"49.8400","12.4368","146.9106","12.4368","8.2912","35.4514"
"49.9200","12.4576","147.0518","12.4576","8.3051","35.4855"
"50.0000","12.4773","147.1912","12.4773","8.3182","35.5191"
"50.0800","12.4976","147.3169","12.4976","8.3317","35.5494"
"50.1600","12.5161","147.4286","12.5161","8.3441","35.5764"
"50.2400","12.5367","147.5764","12.5367","8.3578","35.6121"
"50.3200","12.5567","147.7074","12.5567","8.3712","35.6437"
"50.4000","12.5768","147.8438","12.5768","8.3846","35.6766"
"50.4800","12.5979","148.0046","12.5979","8.3986","35.7154"
"50.5600","12.6179","148.1143","12.6179","8.4119","35.7419"
"50.6400","12.6369","148.2316","12.6369","8.4246","35.7702"
"50.7200","12.6574","148.3643","12.6574","8.4383","35.8022"
"50.8000","12.6759","148.4672","12.6759","8.4506","35.8270"
"50.8800","12.6972","148.6064","12.6972","8.4648","35.8606"
"50.9600","12.7165","148.7277","12.7165","8.4776","35.8899"
"51.0400","12.7365","148.8609","12.7365","8.4910","35.9220"
"51.1200","12.7567","148.9899","12.7567","8.5044","35.9532"
"51.2000","12.7778","149.1185","12.7778","8.5185","35.9842"
"51.2800","12.7976","149.2328","12.7976","8.5317","36.0118"
"51.3600","12.8176","149.3376","12.8176","8.5451","36.0371"
"51.4400","12.8357","149.4332","12.8357","8.5571","36.0601"
"51.5200","12.8566","149.5676","12.8566","8.5711","36.0926"
"51.6000","12.8766","149.6840","12.8766","8.5844","36.1206"
"51.6800","12.8974","149.8028","12.8974","8.5982","36.1493"
"51.7600","12.9186","149.9403","12.9186","8.6124","36.1825"
"51.8400","12.9376","150.0304","12.9376","8.6251","36.2042"
"51.9200","12.9574","150.1440","12.9574","8.6383","36.2317"
"52.0000","12.9772","150.2417","12.9772","8.6514","36.2552"
"52.0800","12.9970","150.3442","12.9970","8.6647","36.2800"
"52.1600","13.0166","150.4534","13.0166","8.6778","36.3063"
"52.2400","13.0362","150.5535","13.0362","8.6908","36.3305"
"52.3200","13.0567","150.6489","13.0567","8.7045","36.3535"
"52.4000","13.0779","150.7554","13.0779","8.7186","36.3792"
"52.4800","13.0973","150.8565","13.0973","8.7315","36.4036"
"52.5600","13.1176","150.9594","13.1176","8.7451","36.4284"
"52.6400","13.1366","151.0291","13.1366","8.7577","36.4453"
"52.7200","13.1564","151.1300","13.1564","8.7709","36.4696"
"52.8000","13.1766","151.2255","13.1766","8.7844","36.4926"
"52.8800","13.1966","151.3089","13.1966","8.7978","36.5128"
"52.9600","13.2175","151.4030","13.2175","8.8116","36.5355"
"53.0400","13.2383","151.4971","13.2383","8.8255","36.5582"
"53.1200","13.2571","151.5723","13.2571","8.8380","36.5763"
"53.2000","13.2771","151.6607","13.2771","8.8514","36.5977"
"53.2800","13.2967","151.7347","13.2967","8.8645","36.6155"
"53.3600","13.3174","151.8216","13.3174","8.8783","36.6365"
"53.4400","13.3370","151.8899","13.3370","8.8913","36.6530"
"53.5200","13.3555","151.9599","13.3555","8.9037","36.6699"
"53.6000","13.3767","152.0580","13.3767","8.9178","36.6935"
"53.6800","13.3976","152.1391","13.3976","8.9318","36.7131"
"53.7600","13.4176","152.2183","13.4176","8.9451","36.7322"
"53.8400","13.4374","152.2778","13.4374","8.9582","36.7466"
"53.9200","13.4560","152.3325","13.4560","8.9707","36.7598"
"54.0000","13.4768","152.4070","13.4768","8.9845","36.7777"
"54.0800","13.4970","152.4768","13.4970","8.9980","36.7946"
"54.1600","13.5167","152.5468","13.5167","9.0111","36.8115"
"54.2400","13.5376","152.6271","13.5376","9.0251","36.8309"
"54.3200","13.5574","152.6799","13.5574","9.0383","36.8436"
"54.4000","13.5779","152.7456","13.5779","9.0519","36.8595"
"54.4800","13.5975","152.7907","13.5975","9.0650","36.8703"
"54.5600","13.6166","152.8448","13.6166","9.0778","36.8834"
"54.6400","13.6368","152.9033","13.6368","9.0912","36.8975"
"54.7200","13.6563","152.9451","13.6563","9.1042","36.9076"
"54.8000","13.6762","152.9990","13.6762","9.1175","36.9206"
"54.8800","13.6980","153.0743","13.6980","9.1320","36.9388"
"54.9600","13.7169","153.0959","13.7169","9.1446","36.9440"
"55.0400","13.7374","153.1385","13.7374","9.1582","36.9543"
"55.1200","13.7568","153.1790","13.7568","9.1712","36.9641"
"55.2000","13.7762","153.2268","13.7762","9.1842","36.9756"
"55.2800","13.7965","153.2681","13.7965","9.1977","36.9855"
"55.3600","13.8167","153.3079","13.8167","9.2111","36.9951"
"55.4400","13.8373","153.3480","13.8373","9.2248","37.0048"
"55.5200","13.8580","153.4059","13.8580","9.2386","37.0188"
"55.6000","13.8771","153.4473","13.8771","9.2514","37.0288"
"55.6800","13.8977","153.4915","13.8977","9.2651","37.0395"
"55.7600","13.9170","153.5198","13.9170","9.2780","37.0463"
"55.8400","13.9362","153.5592","13.9362","9.2908","37.0558"
"55.9200","13.9568","153.6018","13.9568","9.3045","37.0661"
"56.0000","13.9758","153.6401","13.9758","9.3172","37.0753"
"56.0800","13.9972","153.6985","13.9972","9.3314","37.0894"
"56.1600","14.0180","153.7555","14.0180","9.3454","37.1032"
"56.2400","14.0372","153.7838","14.0372","9.3581","37.1100"
"56.3200","14.0567","153.8078","14.0567","9.3712","37.1158"
"56.4000","14.0768","153.8302","14.0768","9.3845","37.1212"
"56.4800","14.0968","153.8694","14.0968","9.3979","37.1307"
"56.5600","14.1172","153.8925","14.1172","9.4115","37.1362"
"56.6400","14.1359","153.9149","14.1359","9.4239","37.1416"
"56.7200","14.1574","153.9601","14.1574","9.4383","37.1525"
"56.8000","14.1780","153.9982","14.1780","9.4520","37.1617"
"56.8800","14.1981","154.0341","14.1981","9.4654","37.1704"
"56.9600","14.2173","154.0567","14.2173","9.4782","37.1758"
"57.0400","14.2364","154.0798","14.2364","9.4909","37.1814"
"57.1200","14.2568","154.1262","14.2568","9.5046","37.1926"
"57.2000","14.2770","154.1494","14.2770","9.5180","37.1982"
"57.2800","14.2956","154.1801","14.2956","9.5304","37.2056"
"57.3600","14.3170","154.2301","14.3170","9.5446","37.2177"
"57.4400","14.3371","154.2581","14.3371","9.5581","37.2244"
"57.5200","14.3574","154.2900","14.3574","9.5716","37.2321"
"57.6000","14.3776","154.3190","14.3776","9.5851","37.2391"
"57.6800","14.3962","154.3283","14.3962","9.5975","37.2414"
"57.7600","14.4169","154.3636","14.4169","9.6112","37.2499"
"57.8400","14.4370","154.3959","14.4370","9.6247","37.2577"
"57.9200","14.4569","154.4357","14.4569","9.6379","37.2673"
"58.0000","14.4777","154.4629","14.4777","9.6518","37.2739"
"58.0800","14.4973","154.4909","14.4973","9.6648","37.2806"
"58.1600","14.5174","154.5165","14.5174","9.6782","37.2868"
"58.2400","14.5372","154.5233","14.5372","9.6915","37.2884"
"58.3200","14.5560","154.5490","14.5560","9.7040","37.2946"
"58.4000","14.5768","154.5787","14.5768","9.7179","37.3018"
"58.4800","14.5963","154.6042","14.5963","9.7308","37.3080"
"58.5600","14.6165","154.6269","14.6165","9.7443","37.3134"
"58.6400","14.6373","154.6684","14.6373","9.7582","37.3234"
"58.7200","14.6573","154.6839","14.6573","9.7716","37.3272"
"58.8000","14.6774","154.7057","14.6774","9.7849","37.3325"
"58.8800","14.6972","154.7242","14.6972","9.7982","37.3369"
"58.9600","14.7166","154.7372","14.7166","9.8110","37.3401"
"59.0400","14.7369","154.7638","14.7369","9.8246","37.3465"
"59.1200","14.7554","154.7634","14.7554","9.8369","37.3464"
"59.2000","14.7774","154.8095","14.7774","9.8516","37.3575"
"59.2800","14.7986","154.8357","14.7986","9.8658","37.3638"
"59.3600","14.8179","154.8557","14.8179","9.8786","37.3687"
"59.4400","14.8371","154.8603","14.8371","9.8914","37.3698"
"59.5200","14.8565","154.8811","14.8565","9.9044","37.3748"
"59.6000","14.8767","154.8916","14.8767","9.9178","37.3773"
"59.6800","14.8970","154.8998","14.8970","9.9314","37.3793"
"59.7600","14.9160","154.9050","14.9160","9.9440","37.3806"
"59.8400","14.9369","154.9369","14.9369","9.9580","37.3882"
"59.9200","14.9571","154.9465","14.9571","9.9714","37.3906"
"60.0000","14.9768","154.9634","14.9768","9.9845","37.3946"
"60.0800","14.9974","154.9882","14.9974","9.9983","37.4006"
"60.0900","15.0001","154.9912","15.0001","10.0000","37.4014"