File: data/instron_tests/metamaterials/250327/250327_1467_BULK_m2_2mmTransition.is_comp_Exports/250327_1467_BULK_m2_2mmTransition_2_1.csv
Results Table 1
,Compression Axis,H*,V*,Height,Thickness,Width,Area,Fixture separation,Specimen label
,,,,(mm),(mm),(mm),(mm^2),(mm),
"2","Y","","","148.00","28.00","148.00","4144.00","150.00","1467_BULK_m2_2mmTransition"

Results Table 2
,Modulus (Segment 0 % - 5 %),Compression Axis
,(kPa),
"2","493.28","Y"

Time,Displacement,Force,Compressive displacement,Compressive strain (Displacement),Compressive stress
(s),(mm),(N),(mm),(%),(kPa)
"0.0000","0.0000","-8.4096","0.0000","0.0000","-2.0294"
"0.0800","0.0012","-8.3763","0.0012","0.0008","-2.0213"
"0.1600","0.0176","-8.0833","0.0176","0.0117","-1.9506"
"0.2400","0.0386","-7.6857","0.0386","0.0257","-1.8547"
"0.3200","0.0579","-7.3522","0.0579","0.0386","-1.7742"
"0.4000","0.0768","-6.9964","0.0768","0.0512","-1.6883"
"0.4800","0.0981","-6.6136","0.0981","0.0654","-1.5960"
"0.5600","0.1180","-6.2696","0.1180","0.0786","-1.5129"
"0.6400","0.1372","-5.9487","0.1372","0.0915","-1.4355"
"0.7200","0.1570","-5.6184","0.1570","0.1047","-1.3558"
"0.8000","0.1765","-5.2869","0.1765","0.1176","-1.2758"
"0.8800","0.1973","-4.9395","0.1973","0.1315","-1.1920"
"0.9600","0.2171","-4.6204","0.2171","0.1447","-1.1150"
"1.0400","0.2361","-4.2989","0.2361","0.1574","-1.0374"
"1.1200","0.2571","-3.9515","0.2571","0.1714","-0.9535"
"1.2000","0.2772","-3.6958","0.2772","0.1848","-0.8918"
"1.2800","0.2978","-3.3633","0.2978","0.1985","-0.8116"
"1.3600","0.3174","-3.0442","0.3174","0.2116","-0.7346"
"1.4400","0.3360","-2.7482","0.3360","0.2240","-0.6632"
"1.5200","0.3565","-2.4222","0.3565","0.2376","-0.5845"
"1.6000","0.3767","-2.1023","0.3767","0.2511","-0.5073"
"1.6800","0.3975","-1.7733","0.3975","0.2650","-0.4279"
"1.7600","0.4183","-1.4485","0.4183","0.2788","-0.3495"
"1.8400","0.4372","-1.1663","0.4372","0.2915","-0.2814"
"1.9200","0.4575","-0.8522","0.4575","0.3050","-0.2056"
"2.0000","0.4774","-0.5489","0.4774","0.3182","-0.1325"
"2.0800","0.4965","-0.2589","0.4965","0.3310","-0.0625"
"2.1600","0.5166","0.0618","0.5166","0.3444","0.0149"
"2.2400","0.5361","0.3394","0.5361","0.3574","0.0819"
"2.3200","0.5569","0.6576","0.5569","0.3713","0.1587"
"2.4000","0.5778","0.9699","0.5778","0.3852","0.2340"
"2.4800","0.5974","1.2748","0.5974","0.3983","0.3076"
"2.5600","0.6175","1.5736","0.6175","0.4117","0.3797"
"2.6400","0.6365","1.8709","0.6365","0.4244","0.4515"
"2.7200","0.6563","2.1665","0.6563","0.4375","0.5228"
"2.8000","0.6764","2.4724","0.6764","0.4509","0.5966"
"2.8800","0.6966","2.7710","0.6966","0.4644","0.6687"
"2.9600","0.7177","3.0975","0.7177","0.4785","0.7475"
"3.0400","0.7383","3.4037","0.7383","0.4922","0.8214"
"3.1200","0.7567","3.6794","0.7567","0.5044","0.8879"
"3.2000","0.7772","3.9918","0.7772","0.5181","0.9633"
"3.2800","0.7970","4.2818","0.7970","0.5313","1.0332"
"3.3600","0.8172","4.5846","0.8172","0.5448","1.1063"
"3.4400","0.8364","4.8698","0.8364","0.5576","1.1751"
"3.5200","0.8555","5.1687","0.8555","0.5704","1.2473"
"3.6000","0.8772","5.4912","0.8772","0.5848","1.3251"
"3.6800","0.8978","5.8084","0.8978","0.5985","1.4016"
"3.7600","0.9172","6.1061","0.9172","0.6115","1.4735"
"3.8400","0.9372","6.4041","0.9372","0.6248","1.5454"
"3.9200","0.9562","6.6795","0.9562","0.6375","1.6119"
"4.0000","0.9768","6.9911","0.9768","0.6512","1.6870"
"4.0800","0.9972","7.2920","0.9972","0.6648","1.7597"
"4.1600","1.0168","7.5978","1.0168","0.6779","1.8334"
"4.2400","1.0378","7.9109","1.0378","0.6919","1.9090"
"4.3200","1.0573","8.1970","1.0573","0.7049","1.9780"
"4.4000","1.0779","8.5041","1.0779","0.7186","2.0522"
"4.4800","1.0974","8.7932","1.0974","0.7316","2.1219"
"4.5600","1.1165","9.0656","1.1165","0.7444","2.1876"
"4.6400","1.1365","9.3563","1.1365","0.7577","2.2578"
"4.7200","1.1564","9.6587","1.1564","0.7710","2.3308"
"4.8000","1.1763","9.9512","1.1763","0.7842","2.4014"
"4.8800","1.1981","10.2781","1.1981","0.7987","2.4802"
"4.9600","1.2172","10.5543","1.2172","0.8114","2.5469"
"5.0400","1.2373","10.8532","1.2373","0.8249","2.6190"
"5.1200","1.2566","11.1245","1.2566","0.8378","2.6845"
"5.2000","1.2762","11.4257","1.2762","0.8508","2.7572"
"5.2800","1.2973","11.7392","1.2973","0.8649","2.8328"
"5.3600","1.3170","12.0279","1.3170","0.8780","2.9025"
"5.4400","1.3373","12.3189","1.3373","0.8915","2.9727"
"5.5200","1.3580","12.6214","1.3580","0.9054","3.0457"
"5.6000","1.3774","12.9027","1.3774","0.9183","3.1136"
"5.6800","1.3978","13.2152","1.3978","0.9319","3.1890"
"5.7600","1.4170","13.4873","1.4170","0.9447","3.2546"
"5.8400","1.4365","13.7713","1.4365","0.9577","3.3232"
"5.9200","1.4567","14.0705","1.4567","0.9711","3.3954"
"6.0000","1.4758","14.3494","1.4758","0.9839","3.4627"
"6.0800","1.4972","14.6645","1.4972","0.9982","3.5387"
"6.1600","1.5181","14.9652","1.5181","1.0121","3.6113"
"6.2400","1.5370","15.2448","1.5370","1.0247","3.6788"
"6.3200","1.5567","15.5386","1.5567","1.0378","3.7497"
"6.4000","1.5765","15.8158","1.5765","1.0510","3.8166"
"6.4800","1.5968","16.1025","1.5968","1.0645","3.8857"
"6.5600","1.6174","16.4046","1.6174","1.0783","3.9586"
"6.6400","1.6364","16.6852","1.6364","1.0909","4.0264"
"6.7200","1.6575","16.9959","1.6575","1.1050","4.1013"
"6.8000","1.6775","17.2912","1.6775","1.1183","4.1726"
"6.8800","1.6978","17.5802","1.6978","1.1319","4.2423"
"6.9600","1.7172","17.8567","1.7172","1.1448","4.3091"
"7.0400","1.7364","18.1274","1.7364","1.1576","4.3744"
"7.1200","1.7567","18.4207","1.7567","1.1711","4.4452"
"7.2000","1.7775","18.7208","1.7775","1.1850","4.5176"
"7.2800","1.7960","18.9951","1.7960","1.1973","4.5838"
"7.3600","1.8171","19.3096","1.8171","1.2114","4.6597"
"7.4400","1.8371","19.5895","1.8371","1.2247","4.7272"
"7.5200","1.8576","19.8813","1.8576","1.2384","4.7976"
"7.6000","1.8774","20.1554","1.8774","1.2516","4.8638"
"7.6800","1.8965","20.4362","1.8965","1.2643","4.9315"
"7.7600","1.9170","20.7272","1.9170","1.2780","5.0017"
"7.8400","1.9370","21.0129","1.9370","1.2913","5.0707"
"7.9200","1.9568","21.3076","1.9568","1.3045","5.1418"
"8.0000","1.9778","21.6136","1.9778","1.3185","5.2156"
"8.0800","1.9975","21.8829","1.9975","1.3317","5.2806"
"8.1600","2.0177","22.1681","2.0177","1.3451","5.3494"
"8.2400","2.0373","22.4471","2.0373","1.3582","5.4168"
"8.3200","2.0561","22.7104","2.0561","1.3708","5.4803"
"8.4000","2.0770","23.0234","2.0770","1.3846","5.5558"
"8.4800","2.0965","23.2856","2.0965","1.3977","5.6191"
"8.5600","2.1170","23.5929","2.1170","1.4114","5.6933"
"8.6400","2.1376","23.8749","2.1376","1.4250","5.7613"
"8.7200","2.1573","24.1525","2.1573","1.4382","5.8283"
"8.8000","2.1773","24.4498","2.1773","1.4515","5.9001"
"8.8800","2.1974","24.7307","2.1974","1.4649","5.9678"
"8.9600","2.2161","24.9935","2.2161","1.4774","6.0313"
"9.0400","2.2367","25.2903","2.2367","1.4912","6.1029"
"9.1200","2.2563","25.5773","2.2563","1.5042","6.1721"
"9.2000","2.2778","25.8771","2.2778","1.5185","6.2445"
"9.2800","2.2981","26.1707","2.2981","1.5321","6.3153"
"9.3600","2.3177","26.4568","2.3177","1.5451","6.3844"
"9.4400","2.3374","26.7387","2.3374","1.5583","6.4524"
"9.5200","2.3566","27.0150","2.3566","1.5711","6.5191"
"9.6000","2.3764","27.2877","2.3764","1.5842","6.5849"
"9.6800","2.3972","27.5873","2.3972","1.5981","6.6572"
"9.7600","2.4156","27.8470","2.4156","1.6104","6.7198"
"9.8400","2.4365","28.1403","2.4365","1.6244","6.7906"
"9.9200","2.4578","28.4484","2.4578","1.6385","6.8650"
"10.0000","2.4779","28.7331","2.4779","1.6519","6.9337"
"10.0800","2.4979","29.0199","2.4979","1.6653","7.0029"
"10.1600","2.5165","29.2673","2.5165","1.6777","7.0626"
"10.2400","2.5369","29.5556","2.5369","1.6913","7.1322"
"10.3200","2.5569","29.8441","2.5569","1.7046","7.2018"
"10.4000","2.5765","30.1306","2.5765","1.7176","7.2709"
"10.4800","2.5976","30.4264","2.5976","1.7317","7.3423"
"10.5600","2.6179","30.7076","2.6179","1.7453","7.4101"
"10.6400","2.6374","30.9794","2.6374","1.7582","7.4757"
"10.7200","2.6574","31.2558","2.6574","1.7716","7.5424"
"10.8000","2.6762","31.5146","2.6762","1.7841","7.6049"
"10.8800","2.6975","31.8171","2.6975","1.7983","7.6779"
"10.9600","2.7168","32.0949","2.7168","1.8112","7.7449"
"11.0400","2.7363","32.3699","2.7363","1.8242","7.8113"
"11.1200","2.7570","32.6757","2.7570","1.8380","7.8851"
"11.2000","2.7774","32.9509","2.7774","1.8516","7.9515"
"11.2800","2.7977","33.2281","2.7977","1.8651","8.0184"
"11.3600","2.8175","33.5020","2.8175","1.8783","8.0845"
"11.4400","2.8360","33.7606","2.8360","1.8907","8.1469"
"11.5200","2.8566","34.0556","2.8566","1.9044","8.2180"
"11.6000","2.8767","34.3322","2.8767","1.9178","8.2848"
"11.6800","2.8973","34.6223","2.8973","1.9315","8.3548"
"11.7600","2.9180","34.9196","2.9180","1.9453","8.4265"
"11.8400","2.9374","35.1831","2.9374","1.9583","8.4901"
"11.9200","2.9576","35.4610","2.9576","1.9717","8.5572"
"12.0000","2.9772","35.7404","2.9772","1.9848","8.6246"
"12.0800","2.9963","35.9962","2.9963","1.9975","8.6863"
"12.1600","3.0169","36.2901","3.0169","2.0113","8.7573"
"12.2400","3.0360","36.5469","3.0360","2.0240","8.8192"
"12.3200","3.0564","36.8345","3.0564","2.0376","8.8886"
"12.4000","3.0779","37.1367","3.0779","2.0520","8.9616"
"12.4800","3.0974","37.4150","3.0974","2.0649","9.0287"
"12.5600","3.1175","37.6915","3.1175","2.0784","9.0954"
"12.6400","3.1366","37.9489","3.1366","2.0911","9.1575"
"12.7200","3.1566","38.2289","3.1566","2.1044","9.2251"
"12.8000","3.1772","38.5150","3.1772","2.1181","9.2941"
"12.8800","3.1967","38.7816","3.1967","2.1311","9.3585"
"12.9600","3.2175","39.0858","3.2175","2.1450","9.4319"
"13.0400","3.2383","39.3630","3.2383","2.1589","9.4988"
"13.1200","3.2569","39.6247","3.2569","2.1713","9.5619"
"13.2000","3.2773","39.8974","3.2773","2.1849","9.6278"
"13.2800","3.2967","40.1525","3.2967","2.1978","9.6893"
"13.3600","3.3173","40.4394","3.3173","2.2115","9.7585"
"13.4400","3.3369","40.7035","3.3369","2.2246","9.8223"
"13.5200","3.3557","40.9725","3.3557","2.2372","9.8872"
"13.6000","3.3768","41.2609","3.3768","2.2512","9.9568"
"13.6800","3.3980","41.5631","3.3980","2.2653","10.0297"
"13.7600","3.4175","41.8257","3.4175","2.2784","10.0931"
"13.8400","3.4375","42.1034","3.4375","2.2917","10.1601"
"13.9200","3.4562","42.3448","3.4562","2.3041","10.2183"
"14.0000","3.4767","42.6361","3.4767","2.3178","10.2886"
"14.0800","3.4973","42.9161","3.4973","2.3315","10.3562"
"14.1600","3.5167","43.1960","3.5167","2.3445","10.4238"
"14.2400","3.5374","43.4794","3.5374","2.3583","10.4921"
"14.3200","3.5572","43.7424","3.5572","2.3714","10.5556"
"14.4000","3.5778","44.0208","3.5778","2.3852","10.6228"
"14.4800","3.5976","44.2931","3.5976","2.3984","10.6885"
"14.5600","3.6167","44.5502","3.6167","2.4111","10.7505"
"14.6400","3.6365","44.8269","3.6365","2.4243","10.8173"
"14.7200","3.6558","45.0829","3.6558","2.4372","10.8791"
"14.8000","3.6759","45.3667","3.6759","2.4506","10.9476"
"14.8800","3.6980","45.6757","3.6980","2.4653","11.0221"
"14.9600","3.7173","45.9289","3.7173","2.4782","11.0832"
"15.0400","3.7374","46.1988","3.7374","2.4916","11.1484"
"15.1200","3.7570","46.4598","3.7570","2.5047","11.2113"
"15.2000","3.7766","46.7238","3.7766","2.5177","11.2750"
"15.2800","3.7967","47.0026","3.7967","2.5312","11.3423"
"15.3600","3.8166","47.2610","3.8166","2.5444","11.4047"
"15.4400","3.8374","47.5518","3.8374","2.5583","11.4749"
"15.5200","3.8580","47.8288","3.8580","2.5720","11.5417"
"15.6000","3.8772","48.0864","3.8772","2.5848","11.6039"
"15.6800","3.8977","48.3685","3.8977","2.5985","11.6719"
"15.7600","3.9173","48.6339","3.9173","2.6115","11.7360"
"15.8400","3.9367","48.8906","3.9367","2.6244","11.7979"
"15.9200","3.9570","49.1701","3.9570","2.6380","11.8654"
"16.0000","3.9761","49.4229","3.9761","2.6507","11.9264"
"16.0800","3.9973","49.7106","3.9973","2.6649","11.9958"
"16.1600","4.0179","49.9868","4.0179","2.6786","12.0624"
"16.2400","4.0368","50.2516","4.0368","2.6912","12.1263"
"16.3200","4.0568","50.5172","4.0568","2.7045","12.1905"
"16.4000","4.0767","50.7824","4.0767","2.7178","12.2544"
"16.4800","4.0972","51.0628","4.0972","2.7315","12.3221"
"16.5600","4.1177","51.3246","4.1177","2.7452","12.3853"
"16.6400","4.1359","51.5740","4.1359","2.7573","12.4455"
"16.7200","4.1572","51.8636","4.1572","2.7714","12.5153"
"16.8000","4.1775","52.1402","4.1775","2.7850","12.5821"
"16.8800","4.1979","52.4172","4.1979","2.7986","12.6489"
"16.9600","4.2175","52.6850","4.2175","2.8117","12.7136"
"17.0400","4.2364","52.9248","4.2364","2.8243","12.7714"
"17.1200","4.2565","53.1890","4.2565","2.8377","12.8352"
"17.2000","4.2770","53.4697","4.2770","2.8513","12.9029"
"17.2800","4.2960","53.7230","4.2960","2.8640","12.9641"
"17.3600","4.3171","54.0175","4.3171","2.8781","13.0351"
"17.4400","4.3369","54.2737","4.3369","2.8913","13.0969"
"17.5200","4.3575","54.5509","4.3575","2.9050","13.1638"
"17.6000","4.3774","54.8099","4.3774","2.9182","13.2263"
"17.6800","4.3966","55.0670","4.3966","2.9310","13.2884"
"17.7600","4.4169","55.3435","4.4169","2.9446","13.3551"
"17.8400","4.4372","55.6196","4.4372","2.9581","13.4217"
"17.9200","4.4568","55.8808","4.4568","2.9712","13.4847"
"18.0000","4.4775","56.1659","4.4775","2.9850","13.5535"
"18.0800","4.4973","56.4150","4.4973","2.9982","13.6137"
"18.1600","4.5175","56.6837","4.5175","3.0117","13.6785"
"18.2400","4.5373","56.9455","4.5373","3.0249","13.7417"
"18.3200","4.5563","57.2021","4.5563","3.0375","13.8036"
"18.4000","4.5772","57.4855","4.5772","3.0514","13.8720"
"18.4800","4.5964","57.7425","4.5964","3.0643","13.9340"
"18.5600","4.6170","58.0129","4.6170","3.0780","13.9992"
"18.6400","4.6374","58.2847","4.6374","3.0916","14.0648"
"18.7200","4.6571","58.5433","4.6571","3.1047","14.1272"
"18.8000","4.6771","58.8079","4.6771","3.1181","14.1911"
"18.8800","4.6974","59.0682","4.6974","3.1316","14.2539"
"18.9600","4.7162","59.3179","4.7162","3.1441","14.3142"
"19.0400","4.7369","59.5896","4.7369","3.1579","14.3797"
"19.1200","4.7557","59.8315","4.7557","3.1705","14.4381"
"19.2000","4.7773","60.1292","4.7773","3.1849","14.5100"
"19.2800","4.7986","60.4148","4.7986","3.1990","14.5789"
"19.3600","4.8177","60.6669","4.8177","3.2118","14.6397"
"19.4400","4.8375","60.9312","4.8375","3.2250","14.7035"
"19.5200","4.8567","61.1739","4.8567","3.2378","14.7621"
"19.6000","4.8768","61.4406","4.8768","3.2512","14.8264"
"19.6800","4.8974","61.7111","4.8974","3.2650","14.8917"
"19.7600","4.9159","61.9509","4.9159","3.2773","14.9495"
"19.8400","4.9369","62.2293","4.9369","3.2913","15.0167"
"19.9200","4.9576","62.5094","4.9576","3.3051","15.0843"
"20.0000","4.9772","62.7644","4.9772","3.3181","15.1458"
"20.0800","4.9972","63.0322","4.9972","3.3315","15.2105"
"20.1600","5.0165","63.2792","5.0165","3.3443","15.2701"
"20.2400","5.0369","63.5367","5.0369","3.3579","15.3322"
"20.3200","5.0568","63.7940","5.0568","3.3712","15.3943"
"20.4000","5.0766","64.0649","5.0766","3.3844","15.4597"
"20.4800","5.0977","64.3494","5.0977","3.3985","15.5283"
"20.5600","5.1178","64.6060","5.1178","3.4119","15.5902"
"20.6400","5.1374","64.8656","5.1374","3.4249","15.6529"
"20.7200","5.1572","65.1220","5.1572","3.4382","15.7148"
"20.8000","5.1763","65.3712","5.1763","3.4509","15.7749"
"20.8800","5.1973","65.6462","5.1973","3.4648","15.8413"
"20.9600","5.2165","65.8798","5.2165","3.4777","15.8976"
"21.0400","5.2356","66.1335","5.2356","3.4904","15.9589"
"21.1200","5.2568","66.4127","5.2568","3.5045","16.0262"
"21.2000","5.2775","66.6865","5.2775","3.5184","16.0923"
"21.2800","5.2975","66.9360","5.2975","3.5317","16.1525"
"21.3600","5.3176","67.1943","5.3176","3.5450","16.2148"
"21.4400","5.3359","67.4390","5.3359","3.5573","16.2739"
"21.5200","5.3568","67.7099","5.3568","3.5712","16.3393"
"21.6000","5.3769","67.9784","5.3769","3.5846","16.4041"
"21.6800","5.3976","68.2513","5.3976","3.5984","16.4699"
"21.7600","5.4182","68.5102","5.4182","3.6121","16.5324"
"21.8400","5.4370","68.7493","5.4370","3.6247","16.5901"
"21.9200","5.4573","69.0041","5.4573","3.6382","16.6516"
"22.0000","5.4775","69.2680","5.4775","3.6516","16.7152"
"22.0800","5.4967","69.5234","5.4967","3.6645","16.7769"
"22.1600","5.5168","69.7864","5.5168","3.6779","16.8403"
"22.2400","5.5359","70.0209","5.5359","3.6906","16.8969"
"22.3200","5.5564","70.2870","5.5564","3.7043","16.9611"
"22.4000","5.5779","70.5680","5.5779","3.7186","17.0290"
"22.4800","5.5971","70.8191","5.5971","3.7314","17.0896"
"22.5600","5.6174","71.0706","5.6174","3.7449","17.1502"
"22.6400","5.6364","71.3149","5.6364","3.7576","17.2092"
"22.7200","5.6568","71.5742","5.6568","3.7712","17.2718"
"22.8000","5.6771","71.8291","5.6771","3.7847","17.3333"
"22.8800","5.6968","72.0864","5.6968","3.7979","17.3954"
"22.9600","5.7174","72.3605","5.7174","3.8116","17.4615"
"23.0400","5.7383","72.6195","5.7383","3.8255","17.5240"
"23.1200","5.7571","72.8559","5.7571","3.8381","17.5811"
"23.2000","5.7773","73.1142","5.7773","3.8515","17.6434"
"23.2800","5.7965","73.3498","5.7965","3.8643","17.7002"
"23.3600","5.8171","73.6140","5.8171","3.8780","17.7640"
"23.4400","5.8367","73.8562","5.8367","3.8912","17.8225"
"23.5200","5.8560","74.1092","5.8560","3.9040","17.8835"
"23.6000","5.8769","74.3721","5.8769","3.9179","17.9469"
"23.6800","5.8980","74.6570","5.8980","3.9320","18.0157"
"23.7600","5.9175","74.8989","5.9175","3.9450","18.0741"
"23.8400","5.9374","75.1501","5.9374","3.9583","18.1347"
"23.9200","5.9562","75.3763","5.9562","3.9708","18.1893"
"24.0000","5.9767","75.6341","5.9767","3.9845","18.2515"
"24.0800","5.9974","75.8941","5.9974","3.9983","18.3142"
"24.1600","6.0168","76.1501","6.0168","4.0112","18.3760"
"24.2400","6.0379","76.4224","6.0379","4.0253","18.4417"
"24.3200","6.0572","76.6602","6.0572","4.0382","18.4991"
"24.4000","6.0779","76.9299","6.0779","4.0519","18.5642"
"24.4800","6.0980","77.1930","6.0980","4.0653","18.6277"
"24.5600","6.1170","77.4221","6.1170","4.0780","18.6829"
"24.6400","6.1365","77.6690","6.1365","4.0910","18.7425"
"24.7200","6.1564","77.9150","6.1564","4.1042","18.8019"
"24.8000","6.1759","78.1573","6.1759","4.1173","18.8603"
"24.8800","6.1976","78.4399","6.1976","4.1318","18.9285"
"24.9600","6.2171","78.6827","6.2171","4.1447","18.9871"
"25.0400","6.2376","78.9345","6.2376","4.1584","19.0479"
"25.1200","6.2568","79.1733","6.2568","4.1712","19.1055"
"25.2000","6.2763","79.4210","6.2763","4.1842","19.1653"
"25.2800","6.2968","79.6875","6.2968","4.1979","19.2296"
"25.3600","6.3168","79.9344","6.3168","4.2112","19.2892"
"25.4400","6.3373","80.1901","6.3373","4.2249","19.3509"
"25.5200","6.3582","80.4633","6.3582","4.2388","19.4168"
"25.6000","6.3771","80.6928","6.3771","4.2514","19.4722"
"25.6800","6.3972","80.9336","6.3972","4.2648","19.5303"
"25.7600","6.4175","81.1903","6.4175","4.2783","19.5923"
"25.8400","6.4367","81.4296","6.4367","4.2911","19.6500"
"25.9200","6.4569","81.6982","6.4569","4.3046","19.7148"
"26.0000","6.4758","81.9236","6.4758","4.3172","19.7692"
"26.0800","6.4976","82.1987","6.4976","4.3317","19.8356"
"26.1600","6.5183","82.4517","6.5183","4.3455","19.8967"
"26.2400","6.5370","82.6855","6.5370","4.3580","19.9531"
"26.3200","6.5568","82.9315","6.5568","4.3712","20.0124"
"26.4000","6.5767","83.1867","6.5767","4.3845","20.0740"
"26.4800","6.5974","83.4439","6.5974","4.3983","20.1361"
"26.5600","6.6180","83.7067","6.6180","4.4120","20.1995"
"26.6400","6.6359","83.9188","6.6359","4.4239","20.2507"
"26.7200","6.6572","84.1973","6.6572","4.4381","20.3179"
"26.8000","6.6777","84.4471","6.6777","4.4518","20.3782"
"26.8800","6.6979","84.7018","6.6979","4.4653","20.4396"
"26.9600","6.7170","84.9395","6.7170","4.4780","20.4970"
"27.0400","6.7365","85.1633","6.7365","4.4910","20.5510"
"27.1200","6.7569","85.4250","6.7569","4.5046","20.6141"
"27.2000","6.7770","85.6580","6.7770","4.5180","20.6704"
"27.2800","6.7958","85.9065","6.7958","4.5306","20.7303"
"27.3600","6.8172","86.1816","6.8172","4.5448","20.7967"
"27.4400","6.8371","86.4216","6.8371","4.5581","20.8546"
"27.5200","6.8577","86.6806","6.8577","4.5718","20.9171"
"27.6000","6.8773","86.9136","6.8773","4.5849","20.9734"
"27.6800","6.8962","87.1464","6.8962","4.5975","21.0295"
"27.7600","6.9168","87.3886","6.9168","4.6112","21.0880"
"27.8400","6.9370","87.6335","6.9370","4.6246","21.1471"
"27.9200","6.9566","87.8789","6.9566","4.6377","21.2063"
"28.0000","6.9777","88.1430","6.9777","4.6518","21.2700"
"28.0800","6.9980","88.3938","6.9980","4.6653","21.3305"
"28.1600","7.0177","88.6340","7.0177","4.6784","21.3885"
"28.2400","7.0372","88.8666","7.0372","4.6915","21.4447"
"28.3200","7.0559","89.0914","7.0559","4.7039","21.4989"
"28.4000","7.0767","89.3567","7.0767","4.7178","21.5629"
"28.4800","7.0966","89.5870","7.0966","4.7311","21.6185"
"28.5600","7.1176","89.8407","7.1176","4.7450","21.6797"
"28.6400","7.1372","90.0855","7.1372","4.7582","21.7388"
"28.7200","7.1569","90.3394","7.1569","4.7713","21.8001"
"28.8000","7.1775","90.5869","7.1775","4.7850","21.8598"
"28.8800","7.1976","90.8206","7.1976","4.7984","21.9162"
"28.9600","7.2165","91.0586","7.2165","4.8110","21.9736"
"29.0400","7.2369","91.3127","7.2369","4.8246","22.0349"
"29.1200","7.2559","91.5295","7.2559","4.8373","22.0872"
"29.2000","7.2776","91.7976","7.2776","4.8517","22.1519"
"29.2800","7.2986","92.0631","7.2986","4.8657","22.2160"
"29.3600","7.3178","92.2838","7.3178","4.8785","22.2692"
"29.4400","7.3369","92.5095","7.3369","4.8913","22.3237"
"29.5200","7.3566","92.7362","7.3566","4.9044","22.3784"
"29.6000","7.3763","92.9745","7.3763","4.9175","22.4359"
"29.6800","7.3972","93.2267","7.3972","4.9315","22.4968"
"29.7600","7.4162","93.4579","7.4162","4.9441","22.5526"
"29.8400","7.4370","93.7059","7.4370","4.9580","22.6124"
"29.9200","7.4577","93.9618","7.4577","4.9718","22.6742"
"30.0000","7.4772","94.2066","7.4772","4.9848","22.7333"
"30.0800","7.4977","94.4549","7.4977","4.9984","22.7932"
"30.1600","7.5164","94.6712","7.5164","5.0109","22.8454"
"30.2400","7.5368","94.9131","7.5368","5.0245","22.9037"
"30.3200","7.5571","95.1560","7.5571","5.0381","22.9623"
"30.4000","7.5768","95.3974","7.5768","5.0512","23.0206"
"30.4800","7.5979","95.6690","7.5979","5.0652","23.0862"
"30.5600","7.6178","95.9006","7.6178","5.0786","23.1420"
"30.6400","7.6376","96.1311","7.6376","5.0918","23.1977"
"30.7200","7.6571","96.3657","7.6571","5.1047","23.2543"
"30.8000","7.6760","96.5735","7.6760","5.1174","23.3044"
"30.8800","7.6973","96.8425","7.6973","5.1315","23.3693"
"30.9600","7.7170","97.0719","7.7170","5.1447","23.4247"
"31.0400","7.7365","97.3209","7.7365","5.1577","23.4848"
"31.1200","7.7570","97.5765","7.7570","5.1714","23.5465"
"31.2000","7.7777","97.8303","7.7777","5.1851","23.6077"
"31.2800","7.7977","98.0617","7.7977","5.1985","23.6635"
"31.3600","7.8174","98.2964","7.8174","5.2116","23.7202"
"31.4400","7.8356","98.5000","7.8356","5.2237","23.7693"
"31.5200","7.8568","98.7745","7.8568","5.2379","23.8355"
"31.6000","7.8767","99.0102","7.8767","5.2511","23.8924"
"31.6800","7.8976","99.2725","7.8976","5.2651","23.9557"
"31.7600","7.9183","99.5129","7.9183","5.2789","24.0137"
"31.8400","7.9373","99.7481","7.9373","5.2915","24.0705"
"31.9200","7.9574","99.9770","7.9574","5.3049","24.1257"
"32.0000","7.9771","100.2103","7.9771","5.3181","24.1820"
"32.0800","7.9967","100.4447","7.9967","5.3311","24.2386"
"32.1600","8.0169","100.7000","8.0169","5.3446","24.3002"
"32.2400","8.0359","100.9109","8.0359","5.3573","24.3511"
"32.3200","8.0565","101.1595","8.0565","5.3710","24.4111"
"32.4000","8.0782","101.4228","8.0782","5.3854","24.4746"
"32.4800","8.0972","101.6571","8.0972","5.3982","24.5312"
"32.5600","8.1176","101.9035","8.1176","5.4117","24.5906"
"32.6400","8.1363","102.1130","8.1363","5.4242","24.6412"
"32.7200","8.1564","102.3589","8.1564","5.4376","24.7005"
"32.8000","8.1772","102.6204","8.1772","5.4514","24.7636"
"32.8800","8.1966","102.8266","8.1966","5.4644","24.8134"
"32.9600","8.2171","103.0940","8.2171","5.4781","24.8779"
"33.0400","8.2381","103.3334","8.2381","5.4921","24.9357"
"33.1200","8.2571","103.5590","8.2571","5.5048","24.9901"
"33.2000","8.2775","103.8132","8.2775","5.5184","25.0515"
"33.2800","8.2968","104.0314","8.2968","5.5312","25.1041"
"33.3600","8.3173","104.2764","8.3173","5.5449","25.1632"
"33.4400","8.3364","104.4889","8.3364","5.5576","25.2145"
"33.5200","8.3554","104.7159","8.3554","5.5702","25.2693"
"33.6000","8.3768","104.9696","8.3768","5.5846","25.3305"
"33.6800","8.3977","105.2279","8.3977","5.5985","25.3928"
"33.7600","8.4174","105.4504","8.4174","5.6116","25.4465"
"33.8400","8.4376","105.6870","8.4376","5.6251","25.5036"
"33.9200","8.4561","105.8982","8.4561","5.6374","25.5546"
"34.0000","8.4765","106.1391","8.4765","5.6510","25.6127"
"34.0800","8.4973","106.3870","8.4973","5.6648","25.6725"
"34.1600","8.5168","106.6238","8.5168","5.6779","25.7297"
"34.2400","8.5378","106.8749","8.5378","5.6919","25.7903"
"34.3200","8.5574","107.0977","8.5574","5.7050","25.8440"
"34.4000","8.5779","107.3384","8.5779","5.7186","25.9021"
"34.4800","8.5973","107.5598","8.5973","5.7315","25.9556"
"34.5600","8.6166","107.7854","8.6166","5.7444","26.0100"
"34.6400","8.6367","108.0243","8.6367","5.7578","26.0676"
"34.7200","8.6562","108.2497","8.6562","5.7708","26.1220"
"34.8000","8.6760","108.4850","8.6760","5.7840","26.1788"
"34.8800","8.6978","108.7462","8.6978","5.7985","26.2419"
"34.9600","8.7173","108.9777","8.7173","5.8115","26.2977"
"35.0400","8.7379","109.2034","8.7379","5.8253","26.3522"
"35.1200","8.7569","109.4206","8.7569","5.8379","26.4046"
"35.2000","8.7763","109.6449","8.7763","5.8508","26.4587"
"35.2800","8.7968","109.8870","8.7968","5.8645","26.5171"
"35.3600","8.8166","110.1073","8.8166","5.8777","26.5703"
"35.4400","8.8370","110.3394","8.8370","5.8913","26.6263"
"35.5200","8.8580","110.5885","8.8580","5.9053","26.6864"
"35.6000","8.8778","110.8261","8.8778","5.9185","26.7437"
"35.6800","8.8978","111.0365","8.8978","5.9318","26.7945"
"35.7600","8.9170","111.2541","8.9170","5.9447","26.8470"
"35.8400","8.9362","111.4801","8.9362","5.9575","26.9016"
"35.9200","8.9567","111.7183","8.9567","5.9711","26.9591"
"36.0000","8.9760","111.9358","8.9760","5.9840","27.0115"
"36.0800","8.9976","112.1890","8.9976","5.9984","27.0726"
"36.1600","9.0183","112.4278","9.0183","6.0122","27.1302"
"36.2400","9.0372","112.6353","9.0372","6.0248","27.1803"
"36.3200","9.0565","112.8594","9.0565","6.0377","27.2344"
"36.4000","9.0765","113.0992","9.0765","6.0510","27.2923"
"36.4800","9.0969","113.3265","9.0969","6.0646","27.3471"
"36.5600","9.1176","113.5648","9.1176","6.0784","27.4046"
"36.6400","9.1361","113.7721","9.1361","6.0908","27.4547"
"36.7200","9.1575","114.0272","9.1575","6.1050","27.5162"
"36.8000","9.1778","114.2626","9.1778","6.1186","27.5730"
"36.8800","9.1979","114.4903","9.1979","6.1319","27.6280"
"36.9600","9.2170","114.7054","9.2170","6.1446","27.6799"
"37.0400","9.2366","114.9256","9.2366","6.1578","27.7330"
"37.1200","9.2567","115.1507","9.2567","6.1711","27.7873"
"37.2000","9.2772","115.3890","9.2772","6.1848","27.8448"
"37.2800","9.2959","115.6009","9.2959","6.1972","27.8960"
"37.3600","9.3172","115.8526","9.3172","6.2115","27.9567"
"37.4400","9.3372","116.0789","9.3372","6.2248","28.0113"
"37.5200","9.3577","116.3069","9.3577","6.2385","28.0663"
"37.6000","9.3773","116.5279","9.3773","6.2515","28.1197"
"37.6800","9.3965","116.7512","9.3965","6.2643","28.1736"
"37.7600","9.4168","116.9784","9.4168","6.2779","28.2284"
"37.8400","9.4367","117.2116","9.4367","6.2911","28.2846"
"37.9200","9.4567","117.4294","9.4567","6.3045","28.3372"
"38.0000","9.4776","117.6831","9.4776","6.3184","28.3984"
"38.0800","9.4972","117.8864","9.4972","6.3315","28.4475"
"38.1600","9.5174","118.1055","9.5174","6.3450","28.5004"
"38.2400","9.5375","118.3336","9.5375","6.3584","28.5554"
"38.3200","9.5563","118.5470","9.5563","6.3708","28.6069"
"38.4000","9.5772","118.7820","9.5772","6.3848","28.6636"
"38.4800","9.5964","118.9965","9.5964","6.3976","28.7154"
"38.5600","9.6171","119.2234","9.6171","6.4114","28.7701"
"38.6400","9.6374","119.4502","9.6374","6.4249","28.8248"
"38.7200","9.6572","119.6791","9.6572","6.4382","28.8801"
"38.8000","9.6770","119.8938","9.6770","6.4513","28.9319"
"38.8800","9.6975","120.1185","9.6975","6.4650","28.9861"
"38.9600","9.7168","120.3440","9.7168","6.4779","29.0405"
"39.0400","9.7373","120.5663","9.7373","6.4916","29.0942"
"39.1200","9.7559","120.7666","9.7559","6.5040","29.1425"
"39.2000","9.7773","121.0177","9.7773","6.5182","29.2031"
"39.2800","9.7979","121.2407","9.7979","6.5319","29.2569"
"39.3600","9.8179","121.4670","9.8179","6.5452","29.3115"
"39.4400","9.8371","121.6695","9.8371","6.5581","29.3604"
"39.5200","9.8567","121.8709","9.8567","6.5711","29.4090"
"39.6000","9.8768","122.0884","9.8768","6.5845","29.4615"
"39.6800","9.8973","122.3134","9.8973","6.5982","29.5158"
"39.7600","9.9159","122.4927","9.9159","6.6106","29.5591"
"39.8400","9.9367","122.7393","9.9367","6.6244","29.6186"
"39.9200","9.9577","122.9687","9.9577","6.6385","29.6739"
"40.0000","9.9771","123.1904","9.9771","6.6514","29.7274"
"40.0800","9.9975","123.4173","9.9975","6.6650","29.7822"
"40.1600","10.0164","123.6123","10.0164","6.6776","29.8292"
"40.2400","10.0371","123.8386","10.0371","6.6914","29.8838"
"40.3200","10.0568","124.0482","10.0568","6.7045","29.9344"
"40.4000","10.0763","124.2572","10.0763","6.7175","29.9849"
"40.4800","10.0976","124.5035","10.0976","6.7318","30.0443"
"40.5600","10.1183","124.7111","10.1183","6.7455","30.0944"
"40.6400","10.1373","124.9163","10.1373","6.7582","30.1439"
"40.7200","10.1576","125.1463","10.1576","6.7717","30.1994"
"40.8000","10.1763","125.3379","10.1763","6.7842","30.2456"
"40.8800","10.1974","125.5686","10.1974","6.7982","30.3013"
"40.9600","10.2166","125.7784","10.2166","6.8111","30.3519"
"41.0400","10.2363","125.9897","10.2363","6.8242","30.4029"
"41.1200","10.2566","126.2157","10.2566","6.8377","30.4575"
"41.2000","10.2774","126.4411","10.2774","6.8516","30.5118"
"41.2800","10.2978","126.6616","10.2978","6.8652","30.5651"
"41.3600","10.3176","126.8702","10.3176","6.8784","30.6154"
"41.4400","10.3361","127.0581","10.3361","6.8908","30.6607"
"41.5200","10.3567","127.2929","10.3567","6.9045","30.7174"
"41.6000","10.3766","127.5025","10.3766","6.9177","30.7680"
"41.6800","10.3974","127.7346","10.3974","6.9316","30.8240"
"41.7600","10.4184","127.9571","10.4184","6.9456","30.8777"
"41.8400","10.4374","128.1516","10.4374","6.9583","30.9246"
"41.9200","10.4571","128.3579","10.4571","6.9714","30.9744"
"42.0000","10.4776","128.5862","10.4776","6.9850","31.0295"
"42.0800","10.4970","128.7896","10.4970","6.9980","31.0786"
"42.1600","10.5168","129.0024","10.5168","7.0112","31.1299"
"42.2400","10.5359","129.1914","10.5359","7.0239","31.1755"
"42.3200","10.5565","129.4123","10.5565","7.0377","31.2288"
"42.4000","10.5781","129.6464","10.5781","7.0520","31.2853"
"42.4800","10.5974","129.8531","10.5974","7.0650","31.3352"
"42.5600","10.6173","130.0611","10.6173","7.0782","31.3854"
"42.6400","10.6359","130.2430","10.6359","7.0906","31.4293"
"42.7200","10.6566","130.4687","10.6566","7.1044","31.4838"
"42.8000","10.6772","130.6838","10.6772","7.1181","31.5357"
"42.8800","10.6968","130.8862","10.6968","7.1312","31.5845"
"42.9600","10.7171","131.1026","10.7171","7.1448","31.6367"
"43.0400","10.7380","131.3173","10.7380","7.1587","31.6885"
"43.1200","10.7572","131.5199","10.7572","7.1714","31.7374"
"43.2000","10.7775","131.7380","10.7775","7.1850","31.7901"
"43.2800","10.7972","131.9371","10.7972","7.1981","31.8381"
"43.3600","10.8174","132.1368","10.8174","7.2116","31.8863"
"43.4400","10.8367","132.3201","10.8367","7.2244","31.9305"
"43.5200","10.8556","132.5063","10.8556","7.2371","31.9755"
"43.6000","10.8764","132.7301","10.8764","7.2509","32.0295"
"43.6800","10.8980","132.9575","10.8980","7.2653","32.0843"
"43.7600","10.9177","133.1591","10.9177","7.2785","32.1330"
"43.8400","10.9375","133.3530","10.9375","7.2917","32.1798"
"43.9200","10.9562","133.5446","10.9562","7.3041","32.2260"
"44.0000","10.9768","133.7556","10.9768","7.3179","32.2769"
"44.0800","10.9975","133.9622","10.9975","7.3316","32.3268"
"44.1600","11.0167","134.1659","11.0167","7.3445","32.3760"
"44.2400","11.0375","134.3842","11.0375","7.3584","32.4286"
"44.3200","11.0574","134.5730","11.0574","7.3716","32.4742"
"44.4000","11.0782","134.7931","11.0781","7.3854","32.5273"
"44.4800","11.0974","134.9824","11.0974","7.3983","32.5730"
"44.5600","11.1166","135.1710","11.1166","7.4111","32.6185"
"44.6400","11.1366","135.3705","11.1366","7.4244","32.6666"
"44.7200","11.1565","135.5712","11.1565","7.4377","32.7151"
"44.8000","11.1761","135.7612","11.1761","7.4507","32.7609"
"44.8800","11.1979","135.9908","11.1979","7.4653","32.8163"
"44.9600","11.2169","136.1745","11.2169","7.4780","32.8606"
"45.0400","11.2376","136.3679","11.2376","7.4917","32.9073"
"45.1200","11.2569","136.5491","11.2569","7.5046","32.9510"
"45.2000","11.2766","136.7415","11.2766","7.5177","32.9975"
"45.2800","11.2966","136.9472","11.2966","7.5311","33.0471"
"45.3600","11.3170","137.1391","11.3170","7.5447","33.0934"
"45.4400","11.3369","137.3324","11.3369","7.5580","33.1401"
"45.5200","11.3579","137.5353","11.3579","7.5719","33.1890"
"45.6000","11.3772","137.7208","11.3772","7.5848","33.2338"
"45.6800","11.3977","137.9117","11.3977","7.5985","33.2798"
"45.7600","11.4171","138.1023","11.4171","7.6114","33.3258"
"45.8400","11.4366","138.2894","11.4366","7.6244","33.3710"
"45.9200","11.4564","138.4673","11.4564","7.6376","33.4139"
"46.0000","11.4753","138.6470","11.4753","7.6502","33.4573"
"46.0800","11.4975","138.8641","11.4975","7.6650","33.5097"
"46.1600","11.5183","139.0620","11.5183","7.6789","33.5574"
"46.2400","11.5374","139.2267","11.5374","7.6916","33.5972"
"46.3200","11.5567","139.4152","11.5567","7.7044","33.6427"
"46.4000","11.5768","139.5862","11.5768","7.7178","33.6839"
"46.4800","11.5969","139.7701","11.5969","7.7313","33.7283"
"46.5600","11.6179","139.9690","11.6179","7.7452","33.7763"
"46.6400","11.6364","140.1194","11.6364","7.7576","33.8126"
"46.7200","11.6577","140.3297","11.6577","7.7718","33.8633"
"46.8000","11.6775","140.5001","11.6775","7.7850","33.9045"
"46.8800","11.6978","140.6786","11.6978","7.7985","33.9475"
"46.9600","11.7170","140.8370","11.7170","7.8114","33.9858"
"47.0400","11.7366","140.9911","11.7366","7.8244","34.0229"
"47.1200","11.7567","141.1668","11.7567","7.8378","34.0653"
"47.2000","11.7773","141.3447","11.7773","7.8515","34.1083"
"47.2800","11.7963","141.5126","11.7963","7.8642","34.1488"
"47.3600","11.8172","141.7138","11.8172","7.8781","34.1973"
"47.4400","11.8368","141.8664","11.8368","7.8912","34.2342"
"47.5200","11.8574","142.0349","11.8574","7.9049","34.2748"
"47.6000","11.8773","142.1929","11.8773","7.9182","34.3130"
"47.6800","11.8964","142.3537","11.8964","7.9310","34.3518"
"47.7600","11.9170","142.5224","11.9170","7.9446","34.3925"
"47.8400","11.9368","142.6848","11.9368","7.9579","34.4317"
"47.9200","11.9566","142.8525","11.9566","7.9711","34.4721"
"48.0000","11.9778","143.0458","11.9778","7.9852","34.5188"
"48.0800","11.9976","143.1932","11.9976","7.9984","34.5544"
"48.1600","12.0175","143.3531","12.0175","8.0117","34.5929"
"48.2400","12.0376","143.5013","12.0376","8.0251","34.6287"
"48.3200","12.0563","143.6644","12.0563","8.0375","34.6680"
"48.4000","12.0771","143.8257","12.0771","8.0514","34.7070"
"48.4800","12.0961","143.9731","12.0961","8.0641","34.7426"
"48.5600","12.1172","144.1433","12.1172","8.0781","34.7836"
"48.6400","12.1374","144.3027","12.1374","8.0916","34.8221"
"48.7200","12.1572","144.4615","12.1572","8.1048","34.8604"
"48.8000","12.1771","144.6092","12.1771","8.1181","34.8961"
"48.8800","12.1970","144.7539","12.1970","8.1314","34.9310"
"48.9600","12.2165","144.9237","12.2165","8.1444","34.9719"
"49.0400","12.2373","145.0812","12.2373","8.1582","35.0099"
"49.1200","12.2562","145.2177","12.2562","8.1708","35.0429"
"49.2000","12.2776","145.3846","12.2776","8.1851","35.0832"
"49.2800","12.2984","145.5371","12.2984","8.1989","35.1200"
"49.3600","12.3178","145.6908","12.3178","8.2119","35.1570"
"49.4400","12.3369","145.8133","12.3369","8.2246","35.1866"
"49.5200","12.3567","145.9619","12.3567","8.2378","35.2225"
"49.6000","12.3763","146.0999","12.3763","8.2509","35.2558"
"49.6800","12.3973","146.2627","12.3973","8.2649","35.2951"
"49.7600","12.4162","146.3942","12.4162","8.2775","35.3268"
"49.8400","12.4369","146.5401","12.4369","8.2912","35.3620"
"49.9200","12.4577","146.6931","12.4577","8.3051","35.3989"
"50.0000","12.4773","146.8304","12.4773","8.3182","35.4320"
"50.0800","12.4975","146.9666","12.4975","8.3317","35.4649"
"50.1600","12.5163","147.0745","12.5163","8.3442","35.4910"
"50.2400","12.5369","147.2204","12.5369","8.3579","35.5262"
"50.3200","12.5568","147.3538","12.5568","8.3712","35.5584"
"50.4000","12.5767","147.4887","12.5767","8.3845","35.5909"
"50.4800","12.5977","147.6510","12.5977","8.3985","35.6301"
"50.5600","12.6184","147.7746","12.6184","8.4123","35.6599"
"50.6400","12.6375","147.8910","12.6375","8.4250","35.6880"
"50.7200","12.6572","148.0161","12.6572","8.4381","35.7182"
"50.8000","12.6758","148.1148","12.6758","8.4505","35.7420"
"50.8800","12.6973","148.2648","12.6973","8.4648","35.7782"
"50.9600","12.7166","148.3733","12.7166","8.4778","35.8044"
"51.0400","12.7363","148.4891","12.7363","8.4909","35.8323"
"51.1200","12.7567","148.6250","12.7567","8.5045","35.8651"
"51.2000","12.7775","148.7499","12.7775","8.5183","35.8952"
"51.2800","12.7977","148.8699","12.7977","8.5318","35.9242"
"51.3600","12.8178","148.9701","12.8178","8.5452","35.9484"
"51.4400","12.8359","149.0662","12.8359","8.5573","35.9716"
"51.5200","12.8565","149.1880","12.8565","8.5710","36.0010"
"51.6000","12.8763","149.2941","12.8763","8.5842","36.0266"
"51.6800","12.8975","149.4134","12.8975","8.5984","36.0554"
"51.7600","12.9187","149.5314","12.9187","8.6125","36.0838"
"51.8400","12.9376","149.6271","12.9376","8.6250","36.1069"
"51.9200","12.9573","149.7199","12.9573","8.6382","36.1293"
"52.0000","12.9773","149.8242","12.9773","8.6515","36.1545"
"52.0800","12.9969","149.9294","12.9969","8.6646","36.1799"
"52.1600","13.0168","150.0340","13.0168","8.6779","36.2051"
"52.2400","13.0362","150.1194","13.0362","8.6908","36.2257"
"52.3200","13.0565","150.2131","13.0565","8.7043","36.2483"
"52.4000","13.0783","150.3282","13.0783","8.7189","36.2761"
"52.4800","13.0974","150.4110","13.0974","8.7316","36.2961"
"52.5600","13.1176","150.5061","13.1176","8.7450","36.3191"
"52.6400","13.1365","150.5735","13.1365","8.7577","36.3353"
"52.7200","13.1564","150.6634","13.1564","8.7709","36.3570"
"52.8000","13.1767","150.7620","13.1767","8.7844","36.3808"
"52.8800","13.1971","150.8347","13.1971","8.7980","36.3983"
"52.9600","13.2174","150.9316","13.2174","8.8116","36.4217"
"53.0400","13.2381","151.0307","13.2381","8.8254","36.4456"
"53.1200","13.2571","151.0968","13.2571","8.8380","36.4616"
"53.2000","13.2772","151.1848","13.2772","8.8514","36.4828"
"53.2800","13.2969","151.2650","13.2969","8.8646","36.5022"
"53.3600","13.3175","151.3514","13.3175","8.8783","36.5230"
"53.4400","13.3368","151.4218","13.3368","8.8912","36.5400"
"53.5200","13.3556","151.4806","13.3556","8.9037","36.5542"
"53.6000","13.3768","151.5928","13.3768","8.9178","36.5813"
"53.6800","13.3978","151.6758","13.3978","8.9319","36.6013"
"53.7600","13.4177","151.7425","13.4177","8.9451","36.6174"
"53.8400","13.4374","151.8147","13.4374","8.9583","36.6348"
"53.9200","13.4560","151.8605","13.4560","8.9707","36.6459"
"54.0000","13.4766","151.9339","13.4766","8.9844","36.6636"
"54.0800","13.4975","152.0193","13.4975","8.9983","36.6842"
"54.1600","13.5170","152.0873","13.5170","9.0114","36.7006"
"54.2400","13.5376","152.1654","13.5376","9.0251","36.7195"
"54.3200","13.5572","152.2215","13.5572","9.0381","36.7330"
"54.4000","13.5778","152.2937","13.5778","9.0519","36.7504"
"54.4800","13.5978","152.3543","13.5978","9.0652","36.7650"
"54.5600","13.6164","152.4044","13.6164","9.0776","36.7771"
"54.6400","13.6366","152.4620","13.6366","9.0910","36.7910"
"54.7200","13.6563","152.5303","13.6563","9.1042","36.8075"
"54.8000","13.6761","152.5956","13.6761","9.1174","36.8233"
"54.8800","13.6980","152.6811","13.6980","9.1320","36.8439"
"54.9600","13.7172","152.7271","13.7172","9.1448","36.8550"
"55.0400","13.7375","152.7849","13.7375","9.1584","36.8689"
"55.1200","13.7571","152.8399","13.7571","9.1714","36.8822"
"55.2000","13.7763","152.8864","13.7763","9.1842","36.8934"
"55.2800","13.7964","152.9516","13.7964","9.1976","36.9092"
"55.3600","13.8169","153.0059","13.8169","9.2112","36.9223"
"55.4400","13.8372","153.0694","13.8372","9.2248","36.9376"
"55.5200","13.8583","153.1302","13.8583","9.2389","36.9523"
"55.6000","13.8772","153.1897","13.8772","9.2514","36.9666"
"55.6800","13.8978","153.2411","13.8978","9.2652","36.9790"
"55.7600","13.9169","153.2855","13.9169","9.2779","36.9898"
"55.8400","13.9363","153.3260","13.9363","9.2909","36.9995"
"55.9200","13.9566","153.3782","13.9566","9.3044","37.0121"
"56.0000","13.9759","153.4229","13.9759","9.3173","37.0229"
"56.0800","13.9973","153.4879","13.9973","9.3316","37.0386"
"56.1600","14.0180","153.5439","14.0180","9.3453","37.0521"
"56.2400","14.0368","153.5675","14.0368","9.3579","37.0578"
"56.3200","14.0569","153.6316","14.0569","9.3713","37.0733"
"56.4000","14.0770","153.6716","14.0770","9.3847","37.0829"
"56.4800","14.0973","153.7170","14.0973","9.3982","37.0939"
"56.5600","14.1173","153.7620","14.1173","9.4116","37.1047"
"56.6400","14.1361","153.7991","14.1361","9.4240","37.1137"
"56.7200","14.1573","153.8551","14.1573","9.4382","37.1272"
"56.8000","14.1778","153.8961","14.1778","9.4519","37.1371"
"56.8800","14.1981","153.9459","14.1981","9.4654","37.1491"
"56.9600","14.2174","153.9753","14.2174","9.4783","37.1562"
"57.0400","14.2362","154.0062","14.2362","9.4908","37.1637"
"57.1200","14.2568","154.0488","14.2568","9.5045","37.1739"
"57.2000","14.2771","154.0812","14.2771","9.5180","37.1818"
"57.2800","14.2956","154.1107","14.2956","9.5304","37.1889"
"57.3600","14.3171","154.1801","14.3171","9.5448","37.2056"
"57.4400","14.3373","154.2098","14.3373","9.5582","37.2128"
"57.5200","14.3577","154.2464","14.3577","9.5718","37.2216"
"57.6000","14.3773","154.2779","14.3773","9.5848","37.2292"
"57.6800","14.3964","154.2908","14.3964","9.5976","37.2323"
"57.7600","14.4170","154.3410","14.4170","9.6114","37.2444"
"57.8400","14.4371","154.3753","14.4371","9.6247","37.2527"
"57.9200","14.4571","154.4103","14.4571","9.6381","37.2612"
"58.0000","14.4776","154.4688","14.4776","9.6517","37.2753"
"58.0800","14.4973","154.4826","14.4973","9.6649","37.2786"
"58.1600","14.5175","154.5119","14.5175","9.6784","37.2857"
"58.2400","14.5373","154.5232","14.5373","9.6915","37.2884"
"58.3200","14.5560","154.5478","14.5560","9.7040","37.2943"
"58.4000","14.5767","154.5882","14.5767","9.7178","37.3041"
"58.4800","14.5963","154.6116","14.5963","9.7309","37.3097"
"58.5600","14.6166","154.6420","14.6166","9.7444","37.3171"
"58.6400","14.6376","154.6886","14.6376","9.7584","37.3283"
"58.7200","14.6573","154.7075","14.6573","9.7716","37.3329"
"58.8000","14.6771","154.7313","14.6771","9.7848","37.3386"
"58.8800","14.6972","154.7601","14.6972","9.7981","37.3456"
"58.9600","14.7168","154.7726","14.7168","9.8112","37.3486"
"59.0400","14.7369","154.8010","14.7369","9.8246","37.3554"
"59.1200","14.7560","154.8102","14.7560","9.8373","37.3577"
"59.2000","14.7775","154.8492","14.7775","9.8517","37.3671"
"59.2800","14.7984","154.8797","14.7984","9.8656","37.3744"
"59.3600","14.8179","154.8975","14.8179","9.8786","37.3787"
"59.4400","14.8370","154.9087","14.8370","9.8913","37.3815"
"59.5200","14.8565","154.9233","14.8565","9.9043","37.3850"
"59.6000","14.8766","154.9445","14.8766","9.9177","37.3901"
"59.6800","14.8972","154.9660","14.8972","9.9315","37.3953"
"59.7600","14.9161","154.9800","14.9161","9.9441","37.3986"
"59.8400","14.9372","155.0152","14.9372","9.9582","37.4071"
"59.9200","14.9572","155.0285","14.9572","9.9715","37.4103"
"60.0000","14.9768","155.0440","14.9768","9.9845","37.4141"
"60.0800","14.9977","155.0774","14.9977","9.9985","37.4222"
"60.0890","15.0000","155.0762","15.0000","10.0000","37.4219"