File: data/instron_tests/metamaterials/250327/250327_1467_BULK_m2_2mmTransition.is_comp_Exports/250327_1467_BULK_m2_2mmTransition_5_1.csv
Results Table 1
,Compression Axis,H*,V*,Height,Thickness,Width,Area,Fixture separation,Specimen label
,,,,(mm),(mm),(mm),(mm^2),(mm),
"5","X","","","148.00","28.00","148.00","4144.00","150.00","1467_BULK_m2_2mmTransition"

Results Table 2
,Modulus (Segment 0 % - 5 %),Compression Axis
,(kPa),
"5","506.96","X"

Time,Displacement,Force,Compressive displacement,Compressive strain (Displacement),Compressive stress
(s),(mm),(N),(mm),(%),(kPa)
"0.0000","0.0000","-6.0608","0.0000","0.0000","-1.4626"
"0.0800","0.0012","-6.0318","0.0012","0.0008","-1.4556"
"0.1600","0.0175","-5.6850","0.0175","0.0117","-1.3719"
"0.2400","0.0385","-5.2686","0.0385","0.0257","-1.2714"
"0.3200","0.0581","-4.9246","0.0581","0.0387","-1.1884"
"0.4000","0.0770","-4.5652","0.0770","0.0514","-1.1016"
"0.4800","0.0976","-4.1815","0.0976","0.0651","-1.0090"
"0.5600","0.1181","-3.8142","0.1181","0.0788","-0.9204"
"0.6400","0.1376","-3.4561","0.1376","0.0918","-0.8340"
"0.7200","0.1574","-3.1071","0.1574","0.1049","-0.7498"
"0.8000","0.1767","-2.7554","0.1767","0.1178","-0.6649"
"0.8800","0.1973","-2.3920","0.1973","0.1316","-0.5772"
"0.9600","0.2172","-2.0584","0.2172","0.1448","-0.4967"
"1.0400","0.2363","-1.7178","0.2363","0.1575","-0.4145"
"1.1200","0.2572","-1.3515","0.2572","0.1714","-0.3261"
"1.2000","0.2775","-1.0061","0.2775","0.1850","-0.2428"
"1.2800","0.2980","-0.6509","0.2980","0.1987","-0.1571"
"1.3600","0.3177","-0.3179","0.3177","0.2118","-0.0767"
"1.4400","0.3362","-0.0100","0.3362","0.2241","-0.0024"
"1.5200","0.3567","0.3396","0.3567","0.2378","0.0820"
"1.6000","0.3768","0.6782","0.3768","0.2512","0.1637"
"1.6800","0.3975","1.0282","0.3975","0.2650","0.2481"
"1.7600","0.4189","1.3776","0.4189","0.2793","0.3324"
"1.8400","0.4373","1.6849","0.4373","0.2915","0.4066"
"1.9200","0.4573","2.0171","0.4573","0.3049","0.4868"
"2.0000","0.4773","2.3359","0.4773","0.3182","0.5637"
"2.0800","0.4968","2.6668","0.4968","0.3312","0.6435"
"2.1600","0.5169","2.9977","0.5169","0.3446","0.7234"
"2.2400","0.5362","3.2967","0.5362","0.3575","0.7955"
"2.3200","0.5569","3.6405","0.5569","0.3713","0.8785"
"2.4000","0.5782","3.9892","0.5782","0.3854","0.9626"
"2.4800","0.5975","4.3018","0.5975","0.3983","1.0381"
"2.5600","0.6176","4.6243","0.6176","0.4117","1.1159"
"2.6400","0.6365","4.9298","0.6365","0.4243","1.1896"
"2.7200","0.6565","5.2526","0.6565","0.4376","1.2675"
"2.8000","0.6774","5.5965","0.6774","0.4516","1.3505"
"2.8800","0.6972","5.9113","0.6972","0.4648","1.4265"
"2.9600","0.7176","6.2388","0.7176","0.4784","1.5055"
"3.0400","0.7385","6.5653","0.7385","0.4923","1.5843"
"3.1200","0.7570","6.8580","0.7570","0.5047","1.6549"
"3.2000","0.7767","7.1754","0.7767","0.5178","1.7315"
"3.2800","0.7972","7.5026","0.7972","0.5315","1.8105"
"3.3600","0.8179","7.8287","0.8179","0.5453","1.8892"
"3.4400","0.8366","8.1143","0.8366","0.5577","1.9581"
"3.5200","0.8558","8.4154","0.8558","0.5705","2.0308"
"3.6000","0.8774","8.7678","0.8774","0.5849","2.1158"
"3.6800","0.8983","9.0880","0.8983","0.5989","2.1931"
"3.7600","0.9175","9.3772","0.9175","0.6117","2.2628"
"3.8400","0.9372","9.6816","0.9372","0.6248","2.3363"
"3.9200","0.9563","9.9828","0.9563","0.6375","2.4090"
"4.0000","0.9770","10.3154","0.9770","0.6513","2.4892"
"4.0800","0.9973","10.6364","0.9973","0.6648","2.5667"
"4.1600","1.0172","10.9537","1.0172","0.6781","2.6433"
"4.2400","1.0381","11.2853","1.0381","0.6920","2.7233"
"4.3200","1.0574","11.5715","1.0574","0.7049","2.7923"
"4.4000","1.0781","11.8974","1.0781","0.7187","2.8710"
"4.4800","1.0977","12.2013","1.0977","0.7318","2.9443"
"4.5600","1.1165","12.5021","1.1165","0.7443","3.0169"
"4.6400","1.1366","12.8097","1.1366","0.7577","3.0911"
"4.7200","1.1566","13.1265","1.1566","0.7711","3.1676"
"4.8000","1.1764","13.4359","1.1764","0.7843","3.2422"
"4.8800","1.1979","13.7758","1.1979","0.7986","3.3243"
"4.9600","1.2174","14.0673","1.2174","0.8116","3.3946"
"5.0400","1.2377","14.3768","1.2377","0.8251","3.4693"
"5.1200","1.2572","14.6760","1.2572","0.8381","3.5415"
"5.2000","1.2764","14.9837","1.2764","0.8509","3.6158"
"5.2800","1.2973","15.3131","1.2973","0.8649","3.6952"
"5.3600","1.3170","15.6164","1.3170","0.8780","3.7684"
"5.4400","1.3370","15.9258","1.3370","0.8913","3.8431"
"5.5200","1.3577","16.2353","1.3577","0.9052","3.9178"
"5.6000","1.3777","16.5467","1.3777","0.9184","3.9929"
"5.6800","1.3981","16.8667","1.3981","0.9321","4.0702"
"5.7600","1.4177","17.1658","1.4177","0.9451","4.1423"
"5.8400","1.4370","17.4687","1.4370","0.9580","4.2154"
"5.9200","1.4569","17.7592","1.4569","0.9712","4.2855"
"6.0000","1.4759","18.0520","1.4759","0.9839","4.3562"
"6.0800","1.4976","18.3896","1.4976","0.9984","4.4377"
"6.1600","1.5183","18.7044","1.5183","1.0122","4.5136"
"6.2400","1.5372","18.9951","1.5372","1.0248","4.5838"
"6.3200","1.5568","19.2926","1.5568","1.0379","4.6555"
"6.4000","1.5768","19.6020","1.5768","1.0512","4.7302"
"6.4800","1.5970","19.9050","1.5970","1.0647","4.8033"
"6.5600","1.6178","20.2205","1.6178","1.0785","4.8795"
"6.6400","1.6364","20.4998","1.6364","1.0909","4.9469"
"6.7200","1.6578","20.8216","1.6578","1.1052","5.0245"
"6.8000","1.6777","21.1286","1.6777","1.1185","5.0986"
"6.8800","1.6980","21.4257","1.6980","1.1320","5.1703"
"6.9600","1.7174","21.7229","1.7174","1.1449","5.2420"
"7.0400","1.7366","21.9996","1.7366","1.1577","5.3088"
"7.1200","1.7568","22.3053","1.7568","1.1712","5.3825"
"7.2000","1.7774","22.6098","1.7774","1.1849","5.4560"
"7.2800","1.7963","22.8934","1.7963","1.1975","5.5245"
"7.3600","1.8174","23.2118","1.8174","1.2116","5.6013"
"7.4400","1.8371","23.4848","1.8371","1.2247","5.6672"
"7.5200","1.8577","23.7882","1.8577","1.2384","5.7404"
"7.6000","1.8776","24.0809","1.8776","1.2518","5.8110"
"7.6800","1.8966","24.3644","1.8966","1.2644","5.8794"
"7.7600","1.9171","24.6799","1.9171","1.2781","5.9556"
"7.8400","1.9371","24.9734","1.9371","1.2914","6.0264"
"7.9200","1.9564","25.2756","1.9564","1.3043","6.0993"
"8.0000","1.9782","25.6085","1.9782","1.3188","6.1797"
"8.0800","1.9980","25.8820","1.9980","1.3320","6.2456"
"8.1600","2.0179","26.1767","2.0179","1.3453","6.3168"
"8.2400","2.0375","26.4640","2.0375","1.3583","6.3861"
"8.3200","2.0563","26.7351","2.0563","1.3709","6.4515"
"8.4000","2.0770","27.0612","2.0770","1.3847","6.5302"
"8.4800","2.0966","27.3433","2.0966","1.3977","6.5983"
"8.5600","2.1174","27.6553","2.1174","1.4116","6.6736"
"8.6400","2.1377","27.9543","2.1377","1.4251","6.7457"
"8.7200","2.1574","28.2454","2.1574","1.4382","6.8160"
"8.8000","2.1774","28.5409","2.1774","1.4516","6.8873"
"8.8800","2.1976","28.8421","2.1976","1.4651","6.9600"
"8.9600","2.2165","29.1095","2.2165","1.4777","7.0245"
"9.0400","2.2373","29.4274","2.2373","1.4915","7.1012"
"9.1200","2.2564","29.7023","2.2564","1.5043","7.1675"
"9.2000","2.2778","30.0230","2.2778","1.5186","7.2449"
"9.2800","2.2984","30.3293","2.2984","1.5323","7.3188"
"9.3600","2.3179","30.6224","2.3179","1.5453","7.3896"
"9.4400","2.3374","30.9032","2.3374","1.5582","7.4573"
"9.5200","2.3570","31.1997","2.3570","1.5713","7.5289"
"9.6000","2.3766","31.4827","2.3766","1.5844","7.5972"
"9.6800","2.3974","31.7878","2.3974","1.5983","7.6708"
"9.7600","2.4161","32.0528","2.4161","1.6108","7.7347"
"9.8400","2.4371","32.3676","2.4371","1.6247","7.8107"
"9.9200","2.4577","32.6655","2.4577","1.6384","7.8826"
"10.0000","2.4776","32.9633","2.4776","1.6517","7.9545"
"10.0800","2.4981","33.2736","2.4981","1.6654","8.0293"
"10.1600","2.5166","33.5245","2.5166","1.6777","8.0899"
"10.2400","2.5365","33.8091","2.5365","1.6910","8.1586"
"10.3200","2.5568","34.1059","2.5568","1.7045","8.2302"
"10.4000","2.5766","34.3933","2.5766","1.7177","8.2995"
"10.4800","2.5981","34.7233","2.5981","1.7320","8.3792"
"10.5600","2.6183","35.0118","2.6183","1.7455","8.4488"
"10.6400","2.6378","35.2793","2.6378","1.7585","8.5134"
"10.7200","2.6575","35.5696","2.6575","1.7717","8.5834"
"10.8000","2.6764","35.8373","2.6764","1.7842","8.6480"
"10.8800","2.6974","36.1414","2.6974","1.7983","8.7214"
"10.9600","2.7169","36.4288","2.7169","1.8113","8.7907"
"11.0400","2.7366","36.7138","2.7366","1.8244","8.8595"
"11.1200","2.7568","37.0182","2.7568","1.8379","8.9330"
"11.2000","2.7777","37.3120","2.7777","1.8518","9.0039"
"11.2800","2.7981","37.5959","2.7981","1.8654","9.0724"
"11.3600","2.8178","37.8797","2.8178","1.8786","9.1409"
"11.4400","2.8361","38.1448","2.8361","1.8908","9.2048"
"11.5200","2.8568","38.4540","2.8568","1.9046","9.2794"
"11.6000","2.8770","38.7432","2.8770","1.9180","9.3492"
"11.6800","2.8977","39.0373","2.8977","1.9318","9.4202"
"11.7600","2.9182","39.3346","2.9182","1.9455","9.4919"
"11.8400","2.9374","39.6110","2.9374","1.9582","9.5586"
"11.9200","2.9577","39.8967","2.9577","1.9718","9.6276"
"12.0000","2.9773","40.1705","2.9773","1.9849","9.6936"
"12.0800","2.9969","40.4654","2.9969","1.9979","9.7648"
"12.1600","3.0174","40.7666","3.0174","2.0116","9.8375"
"12.2400","3.0361","41.0191","3.0361","2.0240","9.8984"
"12.3200","3.0565","41.3104","3.0565","2.0376","9.9687"
"12.4000","3.0784","41.6220","3.0784","2.0522","10.0439"
"12.4800","3.0973","41.9016","3.0973","2.0649","10.1114"
"12.5600","3.1177","42.1800","3.1177","2.0784","10.1786"
"12.6400","3.1365","42.4441","3.1365","2.0910","10.2423"
"12.7200","3.1566","42.7405","3.1566","2.1044","10.3138"
"12.8000","3.1773","43.0296","3.1773","2.1182","10.3836"
"12.8800","3.1970","43.2990","3.1970","2.1314","10.4486"
"12.9600","3.2176","43.6003","3.2176","2.1451","10.5213"
"13.0400","3.2382","43.8937","3.2382","2.1588","10.5921"
"13.1200","3.2572","44.1608","3.2572","2.1715","10.6566"
"13.2000","3.2776","44.4524","3.2776","2.1851","10.7269"
"13.2800","3.2969","44.7173","3.2969","2.1979","10.7909"
"13.3600","3.3177","45.0119","3.3177","2.2118","10.8620"
"13.4400","3.3372","45.2748","3.3372","2.2248","10.9254"
"13.5200","3.3557","45.5447","3.3557","2.2371","10.9905"
"13.6000","3.3769","45.8549","3.3769","2.2512","11.0654"
"13.6800","3.3981","46.1590","3.3981","2.2654","11.1387"
"13.7600","3.4178","46.4390","3.4178","2.2785","11.2063"
"13.8400","3.4377","46.7222","3.4377","2.2918","11.2747"
"13.9200","3.4564","46.9813","3.4564","2.3043","11.3372"
"14.0000","3.4769","47.2656","3.4769","2.3179","11.4058"
"14.0800","3.4975","47.5606","3.4975","2.3316","11.4770"
"14.1600","3.5169","47.8355","3.5169","2.3446","11.5433"
"14.2400","3.5377","48.1314","3.5377","2.3585","11.6147"
"14.3200","3.5575","48.4008","3.5575","2.3717","11.6797"
"14.4000","3.5781","48.6892","3.5781","2.3854","11.7493"
"14.4800","3.5977","48.9605","3.5977","2.3985","11.8148"
"14.5600","3.6169","49.2290","3.6169","2.4113","11.8796"
"14.6400","3.6365","49.5091","3.6365","2.4244","11.9472"
"14.7200","3.6561","49.7813","3.6561","2.4374","12.0129"
"14.8000","3.6761","50.0602","3.6761","2.4507","12.0802"
"14.8800","3.6983","50.3763","3.6983","2.4655","12.1564"
"14.9600","3.7173","50.6309","3.7173","2.4782","12.2179"
"15.0400","3.7376","50.9128","3.7376","2.4917","12.2859"
"15.1200","3.7571","51.1851","3.7571","2.5047","12.3516"
"15.2000","3.7766","51.4587","3.7766","2.5178","12.4176"
"15.2800","3.7970","51.7495","3.7970","2.5314","12.4878"
"15.3600","3.8166","52.0149","3.8166","2.5444","12.5518"
"15.4400","3.8372","52.3028","3.8372","2.5581","12.6213"
"15.5200","3.8585","52.5933","3.8585","2.5723","12.6914"
"15.6000","3.8776","52.8596","3.8776","2.5850","12.7557"
"15.6800","3.8977","53.1364","3.8977","2.5984","12.8225"
"15.7600","3.9174","53.4088","3.9174","2.6116","12.8882"
"15.8400","3.9368","53.6784","3.9368","2.6245","12.9533"
"15.9200","3.9569","53.9547","3.9569","2.6379","13.0200"
"16.0000","3.9763","54.2234","3.9763","2.6509","13.0848"
"16.0800","3.9975","54.5127","3.9975","2.6650","13.1546"
"16.1600","4.0179","54.7976","4.0179","2.6786","13.2233"
"16.2400","4.0374","55.0771","4.0374","2.6916","13.2908"
"16.3200","4.0572","55.3483","4.0572","2.7048","13.3563"
"16.4000","4.0769","55.6047","4.0769","2.7180","13.4181"
"16.4800","4.0971","55.8822","4.0971","2.7314","13.4851"
"16.5600","4.1176","56.1676","4.1176","2.7451","13.5540"
"16.6400","4.1364","56.4213","4.1364","2.7576","13.6152"
"16.7200","4.1574","56.7142","4.1574","2.7716","13.6859"
"16.8000","4.1779","57.0061","4.1779","2.7853","13.7563"
"16.8800","4.1980","57.2806","4.1980","2.7987","13.8225"
"16.9600","4.2175","57.5532","4.2175","2.8116","13.8883"
"17.0400","4.2370","57.8094","4.2370","2.8247","13.9501"
"17.1200","4.2568","58.0736","4.2568","2.8378","14.0139"
"17.2000","4.2772","58.3489","4.2772","2.8515","14.0803"
"17.2800","4.2959","58.5983","4.2959","2.8639","14.1405"
"17.3600","4.3178","58.9101","4.3178","2.8785","14.2158"
"17.4400","4.3371","59.1641","4.3371","2.8914","14.2770"
"17.5200","4.3576","59.4317","4.3576","2.9050","14.3416"
"17.6000","4.3775","59.7053","4.3775","2.9183","14.4077"
"17.6800","4.3966","59.9672","4.3966","2.9311","14.4708"
"17.7600","4.4172","60.2474","4.4172","2.9448","14.5385"
"17.8400","4.4372","60.5218","4.4372","2.9582","14.6047"
"17.9200","4.4568","60.7768","4.4568","2.9712","14.6662"
"18.0000","4.4777","61.0738","4.4777","2.9851","14.7379"
"18.0800","4.4975","61.3443","4.4975","2.9983","14.8032"
"18.1600","4.5178","61.6075","4.5178","3.0118","14.8667"
"18.2400","4.5375","61.8711","4.5375","3.0250","14.9303"
"18.3200","4.5562","62.1197","4.5562","3.0375","14.9903"
"18.4000","4.5771","62.4152","4.5771","3.0514","15.0616"
"18.4800","4.5965","62.6786","4.5965","3.0644","15.1251"
"18.5600","4.6174","62.9605","4.6174","3.0783","15.1932"
"18.6400","4.6378","63.2346","4.6378","3.0918","15.2593"
"18.7200","4.6570","63.4934","4.6570","3.1047","15.3218"
"18.8000","4.6774","63.7756","4.6774","3.1183","15.3899"
"18.8800","4.6978","64.0432","4.6978","3.1319","15.4544"
"18.9600","4.7165","64.3029","4.7165","3.1443","15.5171"
"19.0400","4.7372","64.5823","4.7372","3.1581","15.5845"
"19.1200","4.7561","64.8367","4.7561","3.1707","15.6459"
"19.2000","4.7778","65.1305","4.7778","3.1852","15.7168"
"19.2800","4.7986","65.4182","4.7986","3.1991","15.7862"
"19.3600","4.8179","65.6834","4.8179","3.2120","15.8503"
"19.4400","4.8370","65.9302","4.8370","3.2247","15.9098"
"19.5200","4.8569","66.1948","4.8569","3.2379","15.9736"
"19.6000","4.8768","66.4639","4.8768","3.2512","16.0386"
"19.6800","4.8976","66.7399","4.8976","3.2651","16.1052"
"19.7600","4.9160","66.9849","4.9160","3.2773","16.1643"
"19.8400","4.9372","67.2734","4.9372","3.2915","16.2339"
"19.9200","4.9578","67.5582","4.9578","3.3052","16.3026"
"20.0000","4.9774","67.8170","4.9774","3.3183","16.3651"
"20.0800","4.9974","68.0898","4.9974","3.3316","16.4309"
"20.1600","5.0166","68.3351","5.0166","3.3444","16.4901"
"20.2400","5.0371","68.6111","5.0371","3.3581","16.5567"
"20.3200","5.0571","68.8765","5.0571","3.3714","16.6208"
"20.4000","5.0767","69.1424","5.0767","3.3845","16.6850"
"20.4800","5.0980","69.4414","5.0980","3.3986","16.7571"
"20.5600","5.1180","69.6981","5.1180","3.4120","16.8191"
"20.6400","5.1378","69.9613","5.1378","3.4252","16.8826"
"20.7200","5.1574","70.2196","5.1574","3.4383","16.9449"
"20.8000","5.1764","70.4687","5.1764","3.4509","17.0050"
"20.8800","5.1976","70.7481","5.1976","3.4650","17.0724"
"20.9600","5.2167","70.9895","5.2167","3.4778","17.1307"
"21.0400","5.2361","71.2353","5.2361","3.4908","17.1900"
"21.1200","5.2568","71.5226","5.2568","3.5045","17.2593"
"21.2000","5.2775","71.7963","5.2775","3.5183","17.3254"
"21.2800","5.2978","72.0615","5.2978","3.5319","17.3894"
"21.3600","5.3179","72.3294","5.3179","3.5452","17.4540"
"21.4400","5.3360","72.5603","5.3360","3.5574","17.5097"
"21.5200","5.3569","72.8459","5.3569","3.5713","17.5786"
"21.6000","5.3770","73.1163","5.3770","3.5847","17.6439"
"21.6800","5.3977","73.3922","5.3977","3.5985","17.7105"
"21.7600","5.4183","73.6622","5.4183","3.6122","17.7756"
"21.8400","5.4374","73.9058","5.4374","3.6250","17.8344"
"21.9200","5.4573","74.1693","5.4573","3.6382","17.8980"
"22.0000","5.4775","74.4285","5.4775","3.6517","17.9606"
"22.0800","5.4971","74.6988","5.4971","3.6647","18.0258"
"22.1600","5.5172","74.9540","5.5172","3.6781","18.0874"
"22.2400","5.5360","75.1993","5.5360","3.6907","18.1465"
"22.3200","5.5567","75.4678","5.5567","3.7045","18.2113"
"22.4000","5.5782","75.7534","5.5782","3.7188","18.2803"
"22.4800","5.5974","76.0083","5.5974","3.7316","18.3418"
"22.5600","5.6175","76.2718","5.6175","3.7450","18.4053"
"22.6400","5.6366","76.5087","5.6366","3.7577","18.4625"
"22.7200","5.6569","76.7855","5.6569","3.7713","18.5293"
"22.8000","5.6775","77.0509","5.6775","3.7850","18.5934"
"22.8800","5.6969","77.3082","5.6969","3.7979","18.6555"
"22.9600","5.7174","77.5767","5.7174","3.8116","18.7203"
"23.0400","5.7383","77.8518","5.7383","3.8255","18.7866"
"23.1200","5.7574","78.1034","5.7574","3.8383","18.8474"
"23.2000","5.7780","78.3801","5.7780","3.8520","18.9141"
"23.2800","5.7970","78.6095","5.7970","3.8647","18.9695"
"23.3600","5.8173","78.8699","5.8173","3.8782","19.0323"
"23.4400","5.8367","79.1138","5.8367","3.8911","19.0912"
"23.5200","5.8557","79.3583","5.8557","3.9038","19.1502"
"23.6000","5.8767","79.6359","5.8767","3.9178","19.2172"
"23.6800","5.8982","79.9300","5.8982","3.9321","19.2881"
"23.7600","5.9177","80.1755","5.9177","3.9452","19.3474"
"23.8400","5.9376","80.4242","5.9376","3.9584","19.4074"
"23.9200","5.9564","80.6633","5.9564","3.9709","19.4651"
"24.0000","5.9771","80.9144","5.9771","3.9848","19.5257"
"24.0800","5.9974","81.1837","5.9974","3.9983","19.5907"
"24.1600","6.0170","81.4391","6.0170","4.0114","19.6523"
"24.2400","6.0380","81.7160","6.0380","4.0253","19.7191"
"24.3200","6.0575","81.9642","6.0575","4.0383","19.7790"
"24.4000","6.0781","82.2296","6.0781","4.0521","19.8430"
"24.4800","6.0979","82.4886","6.0979","4.0652","19.9055"
"24.5600","6.1168","82.7343","6.1168","4.0779","19.9648"
"24.6400","6.1368","82.9882","6.1368","4.0912","20.0261"
"24.7200","6.1566","83.2388","6.1566","4.1044","20.0866"
"24.8000","6.1761","83.4869","6.1761","4.1174","20.1465"
"24.8800","6.1979","83.7738","6.1979","4.1319","20.2157"
"24.9600","6.2173","84.0210","6.2173","4.1449","20.2753"
"25.0400","6.2377","84.2705","6.2377","4.1585","20.3355"
"25.1200","6.2572","84.5201","6.2572","4.1715","20.3958"
"25.2000","6.2764","84.7751","6.2764","4.1843","20.4573"
"25.2800","6.2970","85.0419","6.2970","4.1980","20.5217"
"25.3600","6.3169","85.2885","6.3169","4.2112","20.5812"
"25.4400","6.3374","85.5414","6.3374","4.2249","20.6422"
"25.5200","6.3583","85.8103","6.3583","4.2389","20.7071"
"25.6000","6.3773","86.0546","6.3773","4.2516","20.7661"
"25.6800","6.3982","86.3259","6.3982","4.2655","20.8315"
"25.7600","6.4175","86.5755","6.4175","4.2783","20.8918"
"25.8400","6.4370","86.8176","6.4370","4.2914","20.9502"
"25.9200","6.4572","87.0786","6.4572","4.3048","21.0132"
"26.0000","6.4760","87.3082","6.4760","4.3174","21.0686"
"26.0800","6.4975","87.5834","6.4975","4.3317","21.1350"
"26.1600","6.5178","87.8363","6.5178","4.3452","21.1960"
"26.2400","6.5372","88.0889","6.5372","4.3582","21.2570"
"26.3200","6.5571","88.3330","6.5571","4.3714","21.3159"
"26.4000","6.5769","88.5850","6.5769","4.3846","21.3767"
"26.4800","6.5974","88.8352","6.5974","4.3983","21.4371"
"26.5600","6.6178","89.0949","6.6178","4.4119","21.4997"
"26.6400","6.6362","89.3262","6.6362","4.4242","21.5556"
"26.7200","6.6576","89.6049","6.6576","4.4384","21.6228"
"26.8000","6.6779","89.8601","6.6779","4.4519","21.6844"
"26.8800","6.6980","90.1153","6.6980","4.4653","21.7460"
"26.9600","6.7174","90.3503","6.7174","4.4783","21.8027"
"27.0400","6.7367","90.5867","6.7367","4.4911","21.8597"
"27.1200","6.7568","90.8359","6.7568","4.5045","21.9199"
"27.2000","6.7771","91.0937","6.7771","4.5181","21.9821"
"27.2800","6.7963","91.3463","6.7963","4.5309","22.0430"
"27.3600","6.8174","91.6147","6.8174","4.5449","22.1078"
"27.4400","6.8370","91.8568","6.8370","4.5580","22.1662"
"27.5200","6.8577","92.1127","6.8577","4.5718","22.2280"
"27.6000","6.8775","92.3607","6.8775","4.5850","22.2878"
"27.6800","6.8964","92.5944","6.8964","4.5976","22.3442"
"27.7600","6.9170","92.8558","6.9170","4.6114","22.4073"
"27.8400","6.9372","93.1036","6.9372","4.6248","22.4671"
"27.9200","6.9568","93.3472","6.9568","4.6379","22.5259"
"28.0000","6.9779","93.6320","6.9779","4.6519","22.5946"
"28.0800","6.9978","93.8630","6.9978","4.6652","22.6503"
"28.1600","7.0180","94.1145","7.0180","4.6787","22.7110"
"28.2400","7.0376","94.3526","7.0376","4.6917","22.7685"
"28.3200","7.0563","94.5921","7.0563","4.7042","22.8263"
"28.4000","7.0769","94.8550","7.0769","4.7179","22.8897"
"28.4800","7.0965","95.0884","7.0965","4.7310","22.9460"
"28.5600","7.1176","95.3601","7.1176","4.7450","23.0116"
"28.6400","7.1379","95.6167","7.1379","4.7586","23.0735"
"28.7200","7.1567","95.8327","7.1567","4.7711","23.1257"
"28.8000","7.1775","96.0966","7.1775","4.7850","23.1893"
"28.8800","7.1980","96.3535","7.1980","4.7987","23.2513"
"28.9600","7.2168","96.5803","7.2168","4.8112","23.3061"
"29.0400","7.2372","96.8371","7.2372","4.8248","23.3680"
"29.1200","7.2560","97.0616","7.2560","4.8373","23.4222"
"29.2000","7.2779","97.3377","7.2779","4.8519","23.4888"
"29.2800","7.2986","97.6053","7.2986","4.8657","23.5534"
"29.3600","7.3178","97.8281","7.3178","4.8786","23.6072"
"29.4400","7.3371","98.0614","7.3371","4.8914","23.6635"
"29.5200","7.3569","98.2994","7.3569","4.9046","23.7209"
"29.6000","7.3765","98.5414","7.3765","4.9176","23.7793"
"29.6800","7.3973","98.8006","7.3973","4.9315","23.8418"
"29.7600","7.4164","99.0291","7.4164","4.9443","23.8970"
"29.8400","7.4370","99.2826","7.4370","4.9580","23.9582"
"29.9200","7.4578","99.5456","7.4578","4.9719","24.0216"
"30.0000","7.4774","99.7920","7.4774","4.9850","24.0811"
"30.0800","7.4980","100.0391","7.4980","4.9987","24.1407"
"30.1600","7.5165","100.2491","7.5165","5.0110","24.1914"
"30.2400","7.5371","100.5084","7.5371","5.0248","24.2540"
"30.3200","7.5571","100.7448","7.5571","5.0381","24.3110"
"30.4000","7.5764","100.9925","7.5764","5.0509","24.3708"
"30.4800","7.5982","101.2679","7.5982","5.0655","24.4372"
"30.5600","7.6184","101.5071","7.6184","5.0789","24.4949"
"30.6400","7.6376","101.7346","7.6376","5.0918","24.5499"
"30.7200","7.6575","101.9710","7.6575","5.1050","24.6069"
"30.8000","7.6761","102.1890","7.6761","5.1174","24.6595"
"30.8800","7.6976","102.4552","7.6976","5.1317","24.7237"
"30.9600","7.7172","102.6918","7.7172","5.1448","24.7808"
"31.0400","7.7361","102.9128","7.7361","5.1574","24.8342"
"31.1200","7.7569","103.1755","7.7569","5.1712","24.8976"
"31.2000","7.7778","103.4282","7.7778","5.1852","24.9586"
"31.2800","7.7980","103.6693","7.7980","5.1986","25.0167"
"31.3600","7.8178","103.9052","7.8178","5.2119","25.0736"
"31.4400","7.8363","104.1294","7.8363","5.2242","25.1277"
"31.5200","7.8568","104.3748","7.8568","5.2378","25.1870"
"31.6000","7.8767","104.6210","7.8767","5.2511","25.2464"
"31.6800","7.8979","104.8832","7.8979","5.2652","25.3097"
"31.7600","7.9188","105.1215","7.9188","5.2792","25.3672"
"31.8400","7.9375","105.3521","7.9375","5.2917","25.4228"
"31.9200","7.9574","105.5838","7.9574","5.3050","25.4787"
"32.0000","7.9774","105.8253","7.9774","5.3183","25.5370"
"32.0800","7.9969","106.0585","7.9969","5.3313","25.5933"
"32.1600","8.0171","106.2974","8.0171","5.3447","25.6509"
"32.2400","8.0361","106.5165","8.0361","5.3574","25.7038"
"32.3200","8.0568","106.7570","8.0568","5.3712","25.7618"
"32.4000","8.0783","107.0205","8.0783","5.3856","25.8254"
"32.4800","8.0974","107.2553","8.0974","5.3983","25.8821"
"32.5600","8.1178","107.5062","8.1178","5.4119","25.9426"
"32.6400","8.1365","107.7059","8.1365","5.4243","25.9908"
"32.7200","8.1567","107.9534","8.1567","5.4378","26.0505"
"32.8000","8.1773","108.2097","8.1773","5.4515","26.1124"
"32.8800","8.1968","108.4298","8.1968","5.4645","26.1655"
"32.9600","8.2172","108.6729","8.2172","5.4781","26.2242"
"33.0400","8.2382","108.9108","8.2382","5.4921","26.2816"
"33.1200","8.2570","109.1406","8.2570","5.5046","26.3370"
"33.2000","8.2776","109.3816","8.2776","5.5184","26.3952"
"33.2800","8.2970","109.6050","8.2970","5.5313","26.4491"
"33.3600","8.3176","109.8529","8.3176","5.5451","26.5089"
"33.4400","8.3369","110.0744","8.3369","5.5579","26.5624"
"33.5200","8.3558","110.2962","8.3558","5.5705","26.6159"
"33.6000","8.3769","110.5546","8.3769","5.5846","26.6782"
"33.6800","8.3978","110.8009","8.3978","5.5986","26.7377"
"33.7600","8.4178","111.0273","8.4178","5.6119","26.7923"
"33.8400","8.4378","111.2510","8.4378","5.6252","26.8463"
"33.9200","8.4560","111.4536","8.4560","5.6373","26.8952"
"34.0000","8.4769","111.7009","8.4769","5.6513","26.9548"
"34.0800","8.4975","111.9462","8.4975","5.6650","27.0141"
"34.1600","8.5168","112.1746","8.5168","5.6779","27.0692"
"34.2400","8.5379","112.4248","8.5379","5.6919","27.1295"
"34.3200","8.5577","112.6398","8.5577","5.7052","27.1814"
"34.4000","8.5781","112.8835","8.5781","5.7187","27.2402"
"34.4800","8.5978","113.0959","8.5978","5.7318","27.2915"
"34.5600","8.6166","113.3074","8.6166","5.7444","27.3425"
"34.6400","8.6368","113.5518","8.6368","5.7579","27.4015"
"34.7200","8.6566","113.7667","8.6566","5.7711","27.4533"
"34.8000","8.6764","114.0003","8.6764","5.7843","27.5097"
"34.8800","8.6979","114.2608","8.6979","5.7986","27.5726"
"34.9600","8.7174","114.4787","8.7174","5.8116","27.6252"
"35.0400","8.7380","114.7118","8.7380","5.8253","27.6814"
"35.1200","8.7571","114.9245","8.7571","5.8381","27.7328"
"35.2000","8.7763","115.1460","8.7763","5.8509","27.7862"
"35.2800","8.7969","115.3868","8.7969","5.8646","27.8443"
"35.3600","8.8170","115.6110","8.8170","5.8780","27.8984"
"35.4400","8.8371","115.8414","8.8371","5.8914","27.9540"
"35.5200","8.8583","116.0771","8.8583","5.9055","28.0109"
"35.6000","8.8770","116.2843","8.8770","5.9180","28.0609"
"35.6800","8.8978","116.5301","8.8978","5.9319","28.1202"
"35.7600","8.9173","116.7328","8.9173","5.9449","28.1691"
"35.8400","8.9368","116.9597","8.9368","5.9579","28.2239"
"35.9200","8.9570","117.1912","8.9570","5.9713","28.2797"
"36.0000","8.9762","117.4074","8.9762","5.9841","28.3319"
"36.0800","8.9977","117.6442","8.9977","5.9985","28.3891"
"36.1600","9.0179","117.8721","9.0179","6.0120","28.4441"
"36.2400","9.0371","118.0839","9.0371","6.0248","28.4952"
"36.3200","9.0569","118.3054","9.0569","6.0379","28.5486"
"36.4000","9.0769","118.5266","9.0769","6.0513","28.6020"
"36.4800","9.0971","118.7513","9.0971","6.0647","28.6562"
"36.5600","9.1178","118.9888","9.1178","6.0785","28.7135"
"36.6400","9.1365","119.1893","9.1365","6.0910","28.7619"
"36.7200","9.1578","119.4411","9.1578","6.1052","28.8227"
"36.8000","9.1779","119.6510","9.1779","6.1186","28.8733"
"36.8800","9.1980","119.8784","9.1980","6.1320","28.9282"
"36.9600","9.2174","120.0947","9.2174","6.1449","28.9804"
"37.0400","9.2367","120.2993","9.2367","6.1578","29.0298"
"37.1200","9.2569","120.5179","9.2569","6.1713","29.0825"
"37.2000","9.2774","120.7524","9.2774","6.1849","29.1391"
"37.2800","9.2962","120.9571","9.2962","6.1975","29.1885"
"37.3600","9.3173","121.2010","9.3173","6.2115","29.2473"
"37.4400","9.3374","121.4141","9.3374","6.2249","29.2988"
"37.5200","9.3579","121.6331","9.3579","6.2386","29.3516"
"37.6000","9.3776","121.8529","9.3776","6.2517","29.4047"
"37.6800","9.3965","122.0437","9.3965","6.2643","29.4507"
"37.7600","9.4170","122.2525","9.4170","6.2780","29.5011"
"37.8400","9.4369","122.4521","9.4369","6.2913","29.5493"
"37.9200","9.4567","122.6817","9.4567","6.3045","29.6046"
"38.0000","9.4778","122.9156","9.4778","6.3186","29.6611"
"38.0800","9.4977","123.1279","9.4977","6.3318","29.7123"
"38.1600","9.5179","123.3534","9.5179","6.3453","29.7667"
"38.2400","9.5375","123.5501","9.5375","6.3583","29.8142"
"38.3200","9.5562","123.7495","9.5562","6.3708","29.8623"
"38.4000","9.5772","123.9728","9.5772","6.3848","29.9162"
"38.4800","9.5963","124.1727","9.5963","6.3975","29.9645"
"38.5600","9.6169","124.3950","9.6169","6.4113","30.0181"
"38.6400","9.6370","124.6124","9.6370","6.4247","30.0706"
"38.7200","9.6576","124.8282","9.6576","6.4384","30.1226"
"38.8000","9.6776","125.0522","9.6776","6.4517","30.1767"
"38.8800","9.6976","125.2625","9.6976","6.4651","30.2274"
"38.9600","9.7168","125.4571","9.7168","6.4779","30.2744"
"39.0400","9.7375","125.6788","9.7375","6.4917","30.3279"
"39.1200","9.7562","125.8675","9.7562","6.5042","30.3734"
"39.2000","9.7776","126.0971","9.7776","6.5184","30.4288"
"39.2800","9.7984","126.3241","9.7984","6.5323","30.4836"
"39.3600","9.8181","126.5296","9.8181","6.5454","30.5332"
"39.4400","9.8371","126.7305","9.8371","6.5581","30.5817"
"39.5200","9.8570","126.9317","9.8570","6.5713","30.6302"
"39.6000","9.8769","127.1302","9.8769","6.5846","30.6781"
"39.6800","9.8975","127.3486","9.8975","6.5984","30.7308"
"39.7600","9.9163","127.5341","9.9163","6.6109","30.7756"
"39.8400","9.9369","127.7482","9.9369","6.6246","30.8273"
"39.9200","9.9577","127.9689","9.9577","6.6385","30.8805"
"40.0000","9.9777","128.1680","9.9777","6.6518","30.9286"
"40.0800","9.9977","128.3698","9.9977","6.6651","30.9773"
"40.1600","10.0167","128.5217","10.0167","6.6778","31.0139"
"40.2400","10.0371","128.7300","10.0371","6.6914","31.0642"
"40.3200","10.0569","128.9235","10.0569","6.7046","31.1109"
"40.4000","10.0768","129.1335","10.0768","6.7179","31.1616"
"40.4800","10.0980","129.3789","10.0980","6.7320","31.2208"
"40.5600","10.1184","129.5600","10.1184","6.7456","31.2645"
"40.6400","10.1374","129.7451","10.1374","6.7583","31.3091"
"40.7200","10.1573","129.9438","10.1573","6.7715","31.3571"
"40.8000","10.1763","130.1287","10.1763","6.7842","31.4017"
"40.8800","10.1976","130.3549","10.1976","6.7984","31.4563"
"40.9600","10.2169","130.5336","10.2169","6.8113","31.4994"
"41.0400","10.2363","130.7353","10.2363","6.8242","31.5481"
"41.1200","10.2567","130.9445","10.2567","6.8378","31.5986"
"41.2000","10.2770","131.1324","10.2770","6.8513","31.6439"
"41.2800","10.2978","131.3518","10.2978","6.8652","31.6969"
"41.3600","10.3184","131.5559","10.3184","6.8789","31.7461"
"41.4400","10.3361","131.7129","10.3361","6.8907","31.7840"
"41.5200","10.3567","131.9241","10.3567","6.9045","31.8350"
"41.6000","10.3769","132.1139","10.3769","6.9179","31.8808"
"41.6800","10.3980","132.3284","10.3980","6.9320","31.9325"
"41.7600","10.4188","132.5314","10.4188","6.9459","31.9815"
"41.8400","10.4376","132.7024","10.4376","6.9584","32.0228"
"41.9200","10.4574","132.8830","10.4574","6.9716","32.0664"
"42.0000","10.4775","133.0756","10.4775","6.9850","32.1128"
"42.0800","10.4969","133.2580","10.4969","6.9980","32.1569"
"42.1600","10.5170","133.4502","10.5170","7.0113","32.2032"
"42.2400","10.5361","133.6089","10.5361","7.0241","32.2415"
"42.3200","10.5567","133.8197","10.5567","7.0378","32.2924"
"42.4000","10.5785","134.0302","10.5785","7.0523","32.3432"
"42.4800","10.5975","134.2094","10.5975","7.0650","32.3864"
"42.5600","10.6178","134.3954","10.6178","7.0786","32.4313"
"42.6400","10.6365","134.5648","10.6365","7.0910","32.4722"
"42.7200","10.6571","134.7487","10.6571","7.1047","32.5166"
"42.8000","10.6775","134.9368","10.6775","7.1183","32.5620"
"42.8800","10.6970","135.0983","10.6970","7.1313","32.6010"
"42.9600","10.7173","135.2845","10.7173","7.1449","32.6459"
"43.0400","10.7381","135.4700","10.7381","7.1587","32.6906"
"43.1200","10.7573","135.6445","10.7573","7.1715","32.7328"
"43.2000","10.7775","135.8194","10.7775","7.1850","32.7750"
"43.2800","10.7971","135.9922","10.7971","7.1980","32.8167"
"43.3600","10.8179","136.1817","10.8179","7.2119","32.8624"
"43.4400","10.8367","136.3395","10.8367","7.2244","32.9005"
"43.5200","10.8554","136.4961","10.8554","7.2369","32.9382"
"43.6000","10.8769","136.6959","10.8769","7.2513","32.9865"
"43.6800","10.8974","136.8775","10.8974","7.2650","33.0303"
"43.7600","10.9179","137.0554","10.9179","7.2786","33.0732"
"43.8400","10.9378","137.2150","10.9378","7.2919","33.1117"
"43.9200","10.9564","137.3628","10.9564","7.3043","33.1474"
"44.0000","10.9770","137.5532","10.9770","7.3180","33.1933"
"44.0800","10.9975","137.7244","10.9975","7.3317","33.2347"
"44.1600","11.0172","137.8944","11.0172","7.3448","33.2757"
"44.2400","11.0376","138.0719","11.0376","7.3584","33.3185"
"44.3200","11.0573","138.2273","11.0573","7.3715","33.3560"
"44.4000","11.0783","138.3965","11.0783","7.3855","33.3968"
"44.4800","11.0978","138.5559","11.0978","7.3985","33.4353"
"44.5600","11.1167","138.7083","11.1167","7.4111","33.4721"
"44.6400","11.1369","138.8793","11.1369","7.4246","33.5134"
"44.7200","11.1567","139.0392","11.1567","7.4378","33.5519"
"44.8000","11.1763","139.1926","11.1763","7.4508","33.5890"
"44.8800","11.1981","139.3853","11.1981","7.4654","33.6354"
"44.9600","11.2174","139.5329","11.2174","7.4783","33.6711"
"45.0400","11.2378","139.6917","11.2378","7.4919","33.7094"
"45.1200","11.2569","139.8358","11.2569","7.5046","33.7442"
"45.2000","11.2769","139.9915","11.2769","7.5179","33.7817"
"45.2800","11.2970","140.1563","11.2970","7.5313","33.8215"
"45.3600","11.3170","140.2972","11.3170","7.5447","33.8555"
"45.4400","11.3373","140.4636","11.3373","7.5582","33.8957"
"45.5200","11.3585","140.6266","11.3585","7.5724","33.9350"
"45.6000","11.3774","140.7711","11.3774","7.5849","33.9698"
"45.6800","11.3978","140.9265","11.3978","7.5986","34.0074"
"45.7600","11.4173","141.0651","11.4173","7.6115","34.0408"
"45.8400","11.4367","141.2111","11.4367","7.6245","34.0760"
"45.9200","11.4565","141.3579","11.4565","7.6377","34.1115"
"46.0000","11.4758","141.4877","11.4758","7.6505","34.1428"
"46.0800","11.4976","141.6637","11.4976","7.6651","34.1852"
"46.1600","11.5182","141.8128","11.5182","7.6788","34.2212"
"46.2400","11.5373","141.9469","11.5373","7.6915","34.2536"
"46.3200","11.5568","142.0965","11.5568","7.7046","34.2897"
"46.4000","11.5769","142.2443","11.5769","7.7179","34.3254"
"46.4800","11.5972","142.3934","11.5972","7.7314","34.3613"
"46.5600","11.6179","142.5369","11.6179","7.7453","34.3960"
"46.6400","11.6365","142.6559","11.6365","7.7576","34.4247"
"46.7200","11.6580","142.8268","11.6580","7.7720","34.4659"
"46.8000","11.6776","142.9575","11.6776","7.7851","34.4975"
"46.8800","11.6978","143.1011","11.6978","7.7985","34.5321"
"46.9600","11.7173","143.2373","11.7173","7.8116","34.5650"
"47.0400","11.7368","143.3599","11.7368","7.8245","34.5946"
"47.1200","11.7568","143.4977","11.7568","7.8379","34.6278"
"47.2000","11.7773","143.6393","11.7773","7.8515","34.6620"
"47.2800","11.7963","143.7614","11.7963","7.8642","34.6915"
"47.3600","11.8174","143.9283","11.8174","7.8783","34.7317"
"47.4400","11.8372","144.0524","11.8372","7.8915","34.7617"
"47.5200","11.8578","144.1772","11.8578","7.9052","34.7918"
"47.6000","11.8773","144.2995","11.8773","7.9182","34.8213"
"47.6800","11.8967","144.4327","11.8967","7.9312","34.8535"
"47.7600","11.9173","144.5600","11.9173","7.9448","34.8842"
"47.8400","11.9371","144.6863","11.9371","7.9581","34.9147"
"47.9200","11.9568","144.8213","11.9568","7.9712","34.9472"
"48.0000","11.9781","144.9704","11.9781","7.9854","34.9832"
"48.0800","11.9979","145.0739","11.9979","7.9986","35.0082"
"48.1600","12.0177","145.1819","12.0177","8.0118","35.0342"
"48.2400","12.0375","145.2957","12.0375","8.0250","35.0617"
"48.3200","12.0563","145.4176","12.0563","8.0375","35.0911"
"48.4000","12.0772","145.5520","12.0772","8.0515","35.1236"
"48.4800","12.0965","145.6663","12.0965","8.0643","35.1511"
"48.5600","12.1171","145.7852","12.1171","8.0781","35.1798"
"48.6400","12.1376","145.9141","12.1376","8.0917","35.2109"
"48.7200","12.1576","146.0223","12.1576","8.1050","35.2370"
"48.8000","12.1774","146.1370","12.1774","8.1182","35.2647"
"48.8800","12.1975","146.2472","12.1975","8.1317","35.2913"
"48.9600","12.2165","146.3511","12.2165","8.1443","35.3164"
"49.0400","12.2372","146.4665","12.2372","8.1582","35.3442"
"49.1200","12.2563","146.5530","12.2563","8.1708","35.3651"
"49.2000","12.2781","146.6887","12.2781","8.1854","35.3978"
"49.2800","12.2985","146.8057","12.2985","8.1990","35.4261"
"49.3600","12.3179","146.9128","12.3179","8.2120","35.4519"
"49.4400","12.3371","146.9980","12.3371","8.2247","35.4725"
"49.5200","12.3569","147.0933","12.3569","8.2379","35.4955"
"49.6000","12.3768","147.1877","12.3768","8.2512","35.5183"
"49.6800","12.3974","147.3000","12.3974","8.2650","35.5454"
"49.7600","12.4164","147.3791","12.4164","8.2776","35.5645"
"49.8400","12.4368","147.4940","12.4368","8.2912","35.5922"
"49.9200","12.4579","147.5943","12.4579","8.3053","35.6164"
"50.0000","12.4778","147.7011","12.4778","8.3185","35.6422"
"50.0800","12.4977","147.7932","12.4977","8.3318","35.6644"
"50.1600","12.5164","147.8771","12.5164","8.3442","35.6846"
"50.2400","12.5370","147.9723","12.5370","8.3580","35.7076"
"50.3200","12.5571","148.0629","12.5571","8.3714","35.7295"
"50.4000","12.5771","148.1747","12.5771","8.3847","35.7564"
"50.4800","12.5980","148.2823","12.5980","8.3987","35.7824"
"50.5600","12.6183","148.3722","12.6183","8.4122","35.8041"
"50.6400","12.6375","148.4402","12.6375","8.4250","35.8205"
"50.7200","12.6577","148.5256","12.6577","8.4384","35.8411"
"50.8000","12.6760","148.5948","12.6760","8.4507","35.8578"
"50.8800","12.6975","148.7093","12.6975","8.4650","35.8854"
"50.9600","12.7168","148.7739","12.7168","8.4778","35.9010"
"51.0400","12.7366","148.8607","12.7366","8.4911","35.9220"
"51.1200","12.7572","148.9589","12.7572","8.5048","35.9457"
"51.2000","12.7776","149.0479","12.7776","8.5184","35.9671"
"51.2800","12.7979","149.1314","12.7979","8.5319","35.9873"
"51.3600","12.8179","149.2052","12.8179","8.5453","36.0051"
"51.4400","12.8360","149.2642","12.8360","8.5573","36.0193"
"51.5200","12.8562","149.3481","12.8562","8.5708","36.0396"
"51.6000","12.8766","149.4235","12.8766","8.5844","36.0578"
"51.6800","12.8979","149.5314","12.8979","8.5986","36.0838"
"51.7600","12.9188","149.6257","12.9188","8.6125","36.1066"
"51.8400","12.9376","149.6731","12.9376","8.6251","36.1180"
"51.9200","12.9576","149.7458","12.9576","8.6384","36.1356"
"52.0000","12.9774","149.8214","12.9774","8.6516","36.1538"
"52.0800","12.9971","149.8853","12.9971","8.6648","36.1692"
"52.1600","13.0172","149.9827","13.0172","8.6782","36.1927"
"52.2400","13.0365","150.0370","13.0365","8.6910","36.2058"
"52.3200","13.0567","150.1187","13.0567","8.7045","36.2256"
"52.4000","13.0780","150.2068","13.0780","8.7187","36.2468"
"52.4800","13.0975","150.2736","13.0975","8.7317","36.2629"
"52.5600","13.1177","150.3436","13.1177","8.7451","36.2798"
"52.6400","13.1368","150.3965","13.1368","8.7578","36.2926"
"52.7200","13.1568","150.4687","13.1568","8.7712","36.3100"
"52.8000","13.1772","150.5341","13.1772","8.7848","36.3258"
"52.8800","13.1971","150.6061","13.1971","8.7981","36.3432"
"52.9600","13.2174","150.6727","13.2174","8.8116","36.3592"
"53.0400","13.2382","150.7469","13.2382","8.8255","36.3771"
"53.1200","13.2574","150.8032","13.2574","8.8383","36.3907"
"53.2000","13.2775","150.8824","13.2775","8.8517","36.4099"
"53.2800","13.2973","150.9347","13.2973","8.8649","36.4225"
"53.3600","13.3174","150.9997","13.3174","8.8782","36.4382"
"53.4400","13.3371","151.0530","13.3371","8.8914","36.4510"
"53.5200","13.3559","151.1046","13.3559","8.9039","36.4635"
"53.6000","13.3767","151.1704","13.3767","8.9178","36.4793"
"53.6800","13.3979","151.2428","13.3979","8.9319","36.4968"
"53.7600","13.4177","151.2951","13.4177","8.9451","36.5094"
"53.8400","13.4377","151.3550","13.4377","8.9585","36.5239"
"53.9200","13.4564","151.3960","13.4564","8.9709","36.5338"
"54.0000","13.4771","151.4641","13.4771","8.9847","36.5502"
"54.0800","13.4974","151.5265","13.4974","8.9983","36.5653"
"54.1600","13.5170","151.5703","13.5170","9.0113","36.5759"
"54.2400","13.5375","151.6404","13.5375","9.0250","36.5927"
"54.3200","13.5572","151.6804","13.5572","9.0381","36.6024"
"54.4000","13.5783","151.7403","13.5783","9.0522","36.6169"
"54.4800","13.5978","151.7914","13.5978","9.0652","36.6292"
"54.5600","13.6167","151.8300","13.6167","9.0778","36.6385"
"54.6400","13.6367","151.8876","13.6367","9.0911","36.6524"
"54.7200","13.6566","151.9309","13.6566","9.1044","36.6629"
"54.8000","13.6766","151.9875","13.6766","9.1177","36.6765"
"54.8800","13.6981","152.0485","13.6981","9.1320","36.6912"
"54.9600","13.7172","152.0908","13.7172","9.1448","36.7014"
"55.0400","13.7379","152.1396","13.7379","9.1586","36.7132"
"55.1200","13.7571","152.1653","13.7571","9.1714","36.7194"
"55.2000","13.7764","152.2283","13.7764","9.1843","36.7346"
"55.2800","13.7968","152.2752","13.7968","9.1979","36.7460"
"55.3600","13.8170","152.3320","13.8170","9.2114","36.7597"
"55.4400","13.8374","152.3806","13.8374","9.2250","36.7714"
"55.5200","13.8583","152.4348","13.8583","9.2389","36.7845"
"55.6000","13.8775","152.4625","13.8775","9.2517","36.7911"
"55.6800","13.8979","152.5126","13.8979","9.2653","36.8032"
"55.7600","13.9173","152.5418","13.9173","9.2782","36.8103"
"55.8400","13.9366","152.5888","13.9366","9.2911","36.8216"
"55.9200","13.9568","152.6299","13.9568","9.3045","36.8315"
"56.0000","13.9761","152.6650","13.9761","9.3174","36.8400"
"56.0800","13.9976","152.7191","13.9976","9.3317","36.8531"
"56.1600","14.0181","152.7710","14.0181","9.3454","36.8656"
"56.2400","14.0372","152.8007","14.0372","9.3581","36.8728"
"56.3200","14.0572","152.8411","14.0572","9.3714","36.8825"
"56.4000","14.0768","152.8743","14.0768","9.3846","36.8905"
"56.4800","14.0973","152.9208","14.0973","9.3982","36.9017"
"56.5600","14.1178","152.9500","14.1178","9.4118","36.9088"
"56.6400","14.1358","152.9805","14.1358","9.4239","36.9161"
"56.7200","14.1576","153.0417","14.1576","9.4384","36.9309"
"56.8000","14.1781","153.0891","14.1781","9.4521","36.9423"
"56.8800","14.1984","153.1284","14.1984","9.4656","36.9518"
"56.9600","14.2175","153.1582","14.2175","9.4783","36.9590"
"57.0400","14.2367","153.1724","14.2367","9.4911","36.9625"
"57.1200","14.2571","153.2141","14.2571","9.5047","36.9725"
"57.2000","14.2773","153.2354","14.2773","9.5182","36.9777"
"57.2800","14.2959","153.2702","14.2959","9.5306","36.9860"
"57.3600","14.3174","153.3279","14.3174","9.5449","37.0000"
"57.4400","14.3372","153.3510","14.3372","9.5581","37.0055"
"57.5200","14.3577","153.3918","14.3577","9.5718","37.0154"
"57.6000","14.3776","153.4274","14.3776","9.5851","37.0240"
"57.6800","14.3966","153.4477","14.3966","9.5977","37.0289"
"57.7600","14.4172","153.4778","14.4172","9.6114","37.0362"
"57.8400","14.4372","153.5151","14.4372","9.6248","37.0452"
"57.9200","14.4570","153.5434","14.4570","9.6380","37.0520"
"58.0000","14.4780","153.5796","14.4780","9.6520","37.0607"
"58.0800","14.4976","153.5969","14.4976","9.6651","37.0649"
"58.1600","14.5174","153.6114","14.5174","9.6783","37.0684"
"58.2400","14.5376","153.6460","14.5376","9.6917","37.0767"
"58.3200","14.5564","153.6636","14.5564","9.7043","37.0810"
"58.4000","14.5768","153.6988","14.5768","9.7179","37.0895"
"58.4800","14.5964","153.7186","14.5964","9.7310","37.0942"
"58.5600","14.6170","153.7581","14.6170","9.7447","37.1038"
"58.6400","14.6376","153.7805","14.6376","9.7584","37.1092"
"58.7200","14.6574","153.7994","14.6574","9.7716","37.1138"
"58.8000","14.6774","153.8388","14.6774","9.7849","37.1233"
"58.8800","14.6976","153.8566","14.6976","9.7984","37.1276"
"58.9600","14.7168","153.8783","14.7168","9.8112","37.1328"
"59.0400","14.7372","153.9162","14.7372","9.8248","37.1420"
"59.1200","14.7561","153.9268","14.7561","9.8374","37.1445"
"59.2000","14.7771","153.9635","14.7771","9.8514","37.1533"
"59.2800","14.7988","153.9970","14.7988","9.8659","37.1614"
"59.3600","14.8183","154.0204","14.8183","9.8789","37.1671"
"59.4400","14.8374","154.0452","14.8374","9.8916","37.1731"
"59.5200","14.8566","154.0496","14.8566","9.9044","37.1741"
"59.6000","14.8768","154.0747","14.8768","9.9179","37.1802"
"59.6800","14.8973","154.1020","14.8973","9.9316","37.1868"
"59.7600","14.9162","154.1080","14.9162","9.9442","37.1882"
"59.8400","14.9372","154.1483","14.9372","9.9581","37.1979"
"59.9200","14.9576","154.1707","14.9576","9.9718","37.2034"
"60.0000","14.9771","154.1924","14.9771","9.9847","37.2086"
"60.0800","14.9976","154.2217","14.9976","9.9984","37.2157"
"60.0890","15.0000","154.2166","15.0000","10.0000","37.2144"