File: data/instron_tests/metamaterials/250327/250327_1467_BULK_m2_2mmTransition.is_comp_Exports/250327_1467_BULK_m2_2mmTransition_4_1.csv
Results Table 1
,Compression Axis,H*,V*,Height,Thickness,Width,Area,Fixture separation,Specimen label
,,,,(mm),(mm),(mm),(mm^2),(mm),
"4","X","","","148.00","28.00","148.00","4144.00","150.00","1467_BULK_m2_2mmTransition"

Results Table 2
,Modulus (Segment 0 % - 5 %),Compression Axis
,(kPa),
"4","497.22","X"

Time,Displacement,Force,Compressive displacement,Compressive strain (Displacement),Compressive stress
(s),(mm),(N),(mm),(%),(kPa)
"0.0000","0.0000","-0.0967","0.0000","0.0000","-0.0233"
"0.0800","0.0014","-0.0825","0.0014","0.0009","-0.0199"
"0.1600","0.0114","0.1205","0.0114","0.0076","0.0291"
"0.2400","0.0317","0.5455","0.0317","0.0211","0.1316"
"0.3200","0.0517","0.9103","0.0517","0.0344","0.2197"
"0.4000","0.0701","1.2521","0.0701","0.0467","0.3021"
"0.4800","0.0909","1.6355","0.0909","0.0606","0.3947"
"0.5600","0.1122","2.0231","0.1122","0.0748","0.4882"
"0.6400","0.1311","2.3576","0.1311","0.0874","0.5689"
"0.7200","0.1509","2.7249","0.1509","0.1006","0.6575"
"0.8000","0.1707","3.0659","0.1707","0.1138","0.7399"
"0.8800","0.1915","3.4395","0.1915","0.1277","0.8300"
"0.9600","0.2115","3.7841","0.2115","0.1410","0.9132"
"1.0400","0.2303","4.1076","0.2303","0.1536","0.9912"
"1.1200","0.2511","4.4835","0.2511","0.1674","1.0819"
"1.2000","0.2720","4.8329","0.2720","0.1813","1.1662"
"1.2800","0.2918","5.1710","0.2918","0.1945","1.2478"
"1.3600","0.3118","5.5179","0.3118","0.2078","1.3315"
"1.4400","0.3304","5.8229","0.3304","0.2202","1.4051"
"1.5200","0.3510","6.1637","0.3510","0.2340","1.4874"
"1.6000","0.3713","6.5216","0.3713","0.2476","1.5737"
"1.6800","0.3909","6.8584","0.3909","0.2606","1.6550"
"1.7600","0.4123","7.2190","0.4123","0.2748","1.7420"
"1.8400","0.4318","7.5393","0.4318","0.2879","1.8193"
"1.9200","0.4516","7.8647","0.4516","0.3011","1.8978"
"2.0000","0.4717","8.2013","0.4717","0.3144","1.9791"
"2.0800","0.4909","8.5104","0.4909","0.3272","2.0537"
"2.1600","0.5111","8.8477","0.5111","0.3407","2.1351"
"2.2400","0.5308","9.1643","0.5308","0.3539","2.2115"
"2.3200","0.5504","9.4965","0.5504","0.3669","2.2916"
"2.4000","0.5715","9.8494","0.5715","0.3810","2.3768"
"2.4800","0.5916","10.1806","0.5916","0.3944","2.4567"
"2.5600","0.6123","10.5075","0.6123","0.4082","2.5356"
"2.6400","0.6313","10.8097","0.6313","0.4209","2.6085"
"2.7200","0.6505","11.1309","0.6505","0.4336","2.6860"
"2.8000","0.6710","11.4708","0.6710","0.4473","2.7681"
"2.8800","0.6909","11.7823","0.6909","0.4606","2.8432"
"2.9600","0.7111","12.1070","0.7111","0.4741","2.9216"
"3.0400","0.7326","12.4529","0.7326","0.4884","3.0050"
"3.1200","0.7516","12.7553","0.7516","0.5011","3.0780"
"3.2000","0.7717","13.0731","0.7717","0.5144","3.1547"
"3.2800","0.7918","13.3999","0.7918","0.5279","3.2336"
"3.3600","0.8114","13.7095","0.8114","0.5409","3.3083"
"3.4400","0.8309","14.0165","0.8309","0.5539","3.3824"
"3.5200","0.8497","14.3132","0.8497","0.5664","3.4540"
"3.6000","0.8712","14.6576","0.8712","0.5808","3.5371"
"3.6800","0.8926","14.9926","0.8926","0.5951","3.6179"
"3.7600","0.9116","15.2958","0.9116","0.6077","3.6911"
"3.8400","0.9312","15.6004","0.9312","0.6208","3.7646"
"3.9200","0.9508","15.9038","0.9508","0.6339","3.8378"
"4.0000","0.9706","16.2220","0.9706","0.6470","3.9146"
"4.0800","0.9917","16.5543","0.9917","0.6611","3.9948"
"4.1600","1.0107","16.8495","1.0107","0.6738","4.0660"
"4.2400","1.0323","17.1918","1.0323","0.6882","4.1486"
"4.3200","1.0519","17.4955","1.0519","0.7013","4.2219"
"4.4000","1.0718","17.7964","1.0718","0.7145","4.2945"
"4.4800","1.0914","18.1032","1.0914","0.7276","4.3685"
"4.5600","1.1109","18.4012","1.1109","0.7406","4.4404"
"4.6400","1.1311","18.7078","1.1311","0.7541","4.5144"
"4.7200","1.1512","19.0156","1.1512","0.7675","4.5887"
"4.8000","1.1701","19.3167","1.1701","0.7801","4.6614"
"4.8800","1.1914","19.6463","1.1914","0.7943","4.7409"
"4.9600","1.2116","19.9544","1.2116","0.8077","4.8152"
"5.0400","1.2318","20.2600","1.2318","0.8212","4.8890"
"5.1200","1.2516","20.5612","1.2516","0.8344","4.9617"
"5.2000","1.2705","20.8535","1.2705","0.8470","5.0322"
"5.2800","1.2914","21.1748","1.2914","0.8609","5.1098"
"5.3600","1.3116","21.4874","1.3116","0.8744","5.1852"
"5.4400","1.3313","21.7900","1.3313","0.8876","5.2582"
"5.5200","1.3517","22.1027","1.3517","0.9011","5.3337"
"5.6000","1.3713","22.3983","1.3713","0.9142","5.4050"
"5.6800","1.3923","22.7095","1.3923","0.9282","5.4801"
"5.7600","1.4124","23.0116","1.4124","0.9416","5.5530"
"5.8400","1.4308","23.2930","1.4308","0.9539","5.6209"
"5.9200","1.4512","23.5970","1.4512","0.9675","5.6943"
"6.0000","1.4702","23.8801","1.4702","0.9801","5.7626"
"6.0800","1.4912","24.2012","1.4912","0.9941","5.8401"
"6.1600","1.5120","24.5178","1.5120","1.0080","5.9165"
"6.2400","1.5317","24.8136","1.5317","1.0211","5.9878"
"6.3200","1.5512","25.0960","1.5512","1.0341","6.0560"
"6.4000","1.5714","25.4026","1.5714","1.0476","6.1300"
"6.4800","1.5904","25.7033","1.5904","1.0603","6.2025"
"6.5600","1.6114","26.0141","1.6114","1.0743","6.2775"
"6.6400","1.6306","26.2885","1.6306","1.0871","6.3437"
"6.7200","1.6522","26.6159","1.6522","1.1015","6.4227"
"6.8000","1.6722","26.9086","1.6722","1.1148","6.4934"
"6.8800","1.6916","27.2090","1.6916","1.1277","6.5659"
"6.9600","1.7118","27.5118","1.7118","1.1412","6.6389"
"7.0400","1.7312","27.7927","1.7312","1.1541","6.7067"
"7.1200","1.7507","28.0789","1.7507","1.1672","6.7758"
"7.2000","1.7712","28.3843","1.7712","1.1808","6.8495"
"7.2800","1.7904","28.6595","1.7904","1.1936","6.9159"
"7.3600","1.8113","28.9757","1.8113","1.2075","6.9922"
"7.4400","1.8319","29.2775","1.8319","1.2213","7.0650"
"7.5200","1.8513","29.5690","1.8513","1.2342","7.1354"
"7.6000","1.8716","29.8679","1.8716","1.2477","7.2075"
"7.6800","1.8908","30.1353","1.8908","1.2605","7.2720"
"7.7600","1.9116","30.4597","1.9116","1.2744","7.3503"
"7.8400","1.9314","30.7504","1.9314","1.2876","7.4205"
"7.9200","1.9510","31.0426","1.9510","1.3007","7.4910"
"8.0000","1.9716","31.3509","1.9716","1.3144","7.5654"
"8.0800","1.9920","31.6360","1.9920","1.3280","7.6342"
"8.1600","2.0120","31.9273","2.0120","1.3413","7.7045"
"8.2400","2.0318","32.2117","2.0318","1.3546","7.7731"
"8.3200","2.0504","32.4768","2.0504","1.3669","7.8371"
"8.4000","2.0713","32.7789","2.0713","1.3809","7.9100"
"8.4800","2.0912","33.0767","2.0912","1.3942","7.9818"
"8.5600","2.1110","33.3604","2.1110","1.4073","8.0503"
"8.6400","2.1312","33.6633","2.1312","1.4208","8.1234"
"8.7200","2.1518","33.9541","2.1518","1.4345","8.1936"
"8.8000","2.1717","34.2473","2.1717","1.4478","8.2643"
"8.8800","2.1923","34.5479","2.1923","1.4615","8.3369"
"8.9600","2.2107","34.8140","2.2107","1.4738","8.4011"
"9.0400","2.2311","35.1017","2.2311","1.4874","8.4705"
"9.1200","2.2508","35.3820","2.2508","1.5005","8.5381"
"9.2000","2.2714","35.6799","2.2714","1.5143","8.6100"
"9.2800","2.2925","35.9856","2.2925","1.5283","8.6838"
"9.3600","2.3117","36.2695","2.3117","1.5412","8.7523"
"9.4400","2.3321","36.5583","2.3321","1.5547","8.8220"
"9.5200","2.3515","36.8272","2.3515","1.5677","8.8869"
"9.6000","2.3703","37.1023","2.3703","1.5802","8.9533"
"9.6800","2.3908","37.3922","2.3908","1.5939","9.0232"
"9.7600","2.4108","37.6827","2.4108","1.6072","9.0933"
"9.8400","2.4309","37.9663","2.4309","1.6206","9.1617"
"9.9200","2.4521","38.2681","2.4521","1.6347","9.2346"
"10.0000","2.4714","38.5545","2.4714","1.6476","9.3037"
"10.0800","2.4921","38.8524","2.4921","1.6614","9.3756"
"10.1600","2.5110","39.1047","2.5110","1.6740","9.4365"
"10.2400","2.5307","39.3968","2.5307","1.6871","9.5070"
"10.3200","2.5508","39.6893","2.5508","1.7005","9.5775"
"10.4000","2.5707","39.9667","2.5707","1.7138","9.6445"
"10.4800","2.5918","40.2647","2.5918","1.7279","9.7164"
"10.5600","2.6130","40.5814","2.6130","1.7420","9.7928"
"10.6400","2.6315","40.8390","2.6315","1.7543","9.8550"
"10.7200","2.6510","41.1117","2.6510","1.7673","9.9208"
"10.8000","2.6704","41.3872","2.6704","1.7803","9.9873"
"10.8800","2.6918","41.6882","2.6918","1.7945","10.0599"
"10.9600","2.7117","41.9643","2.7117","1.8078","10.1265"
"11.0400","2.7303","42.2251","2.7303","1.8202","10.1894"
"11.1200","2.7511","42.5250","2.7511","1.8341","10.2618"
"11.2000","2.7718","42.8198","2.7718","1.8479","10.3330"
"11.2800","2.7919","43.1099","2.7919","1.8613","10.4030"
"11.3600","2.8118","43.3949","2.8118","1.8746","10.4718"
"11.4400","2.8305","43.6476","2.8305","1.8870","10.5327"
"11.5200","2.8509","43.9364","2.8509","1.9006","10.6024"
"11.6000","2.8715","44.2322","2.8715","1.9143","10.6738"
"11.6800","2.8907","44.5124","2.8907","1.9271","10.7414"
"11.7600","2.9122","44.8151","2.9122","1.9415","10.8145"
"11.8400","2.9318","45.0846","2.9318","1.9545","10.8795"
"11.9200","2.9522","45.3648","2.9522","1.9682","10.9471"
"12.0000","2.9714","45.6360","2.9714","1.9810","11.0125"
"12.0800","2.9908","45.9074","2.9908","1.9938","11.0780"
"12.1600","3.0112","46.1947","3.0112","2.0075","11.1474"
"12.2400","3.0308","46.4721","3.0308","2.0206","11.2143"
"12.3200","3.0499","46.7385","3.0499","2.0333","11.2786"
"12.4000","3.0716","47.0585","3.0716","2.0477","11.3558"
"12.4800","3.0918","47.3268","3.0918","2.0612","11.4206"
"12.5600","3.1123","47.6141","3.1123","2.0748","11.4899"
"12.6400","3.1313","47.8745","3.1313","2.0876","11.5527"
"12.7200","3.1504","48.1419","3.1504","2.1003","11.6173"
"12.8000","3.1709","48.4319","3.1709","2.1139","11.6872"
"12.8800","3.1912","48.7193","3.1912","2.1275","11.7566"
"12.9600","3.2115","49.0027","3.2115","2.1410","11.8250"
"13.0400","3.2325","49.3111","3.2325","2.1550","11.8994"
"13.1200","3.2513","49.5706","3.2513","2.1676","11.9620"
"13.2000","3.2714","49.8482","3.2714","2.1809","12.0290"
"13.2800","3.2918","50.1319","3.2918","2.1945","12.0975"
"13.3600","3.3113","50.4049","3.3113","2.2075","12.1634"
"13.4400","3.3312","50.6809","3.3312","2.2208","12.2299"
"13.5200","3.3499","50.8856","3.3499","2.2333","12.2793"
"13.6000","3.3711","51.1891","3.3711","2.2474","12.3526"
"13.6800","3.3923","51.4836","3.3923","2.2616","12.4237"
"13.7600","3.4119","51.7666","3.4119","2.2746","12.4919"
"13.8400","3.4314","52.0396","3.4314","2.2876","12.5578"
"13.9200","3.4510","52.3020","3.4510","2.3006","12.6211"
"14.0000","3.4707","52.5800","3.4707","2.3138","12.6882"
"14.0800","3.4917","52.8665","3.4917","2.3278","12.7574"
"14.1600","3.5106","53.1293","3.5106","2.3404","12.8208"
"14.2400","3.5317","53.4186","3.5317","2.3544","12.8906"
"14.3200","3.5520","53.7002","3.5520","2.3680","12.9585"
"14.4000","3.5717","53.9819","3.5717","2.3811","13.0265"
"14.4800","3.5915","54.2512","3.5915","2.3943","13.0915"
"14.5600","3.6111","54.5135","3.6111","2.4074","13.1548"
"14.6400","3.6312","54.7897","3.6312","2.4208","13.2215"
"14.7200","3.6509","55.0588","3.6509","2.4339","13.2864"
"14.8000","3.6696","55.3176","3.6696","2.4464","13.3488"
"14.8800","3.6916","55.6244","3.6916","2.4611","13.4229"
"14.9600","3.7120","55.8986","3.7120","2.4746","13.4891"
"15.0400","3.7317","56.1642","3.7317","2.4878","13.5531"
"15.1200","3.7513","56.4195","3.7513","2.5008","13.6148"
"15.2000","3.7705","56.6832","3.7705","2.5137","13.6784"
"15.2800","3.7914","56.9702","3.7914","2.5276","13.7476"
"15.3600","3.8112","57.2413","3.8112","2.5408","13.8131"
"15.4400","3.8309","57.5032","3.8309","2.5539","13.8763"
"15.5200","3.8516","57.7946","3.8516","2.5677","13.9466"
"15.6000","3.8721","58.0626","3.8721","2.5814","14.0112"
"15.6800","3.8921","58.3349","3.8921","2.5947","14.0770"
"15.7600","3.9122","58.5972","3.9122","2.6081","14.1402"
"15.8400","3.9307","58.8487","3.9307","2.6204","14.2009"
"15.9200","3.9509","59.1286","3.9509","2.6340","14.2685"
"16.0000","3.9705","59.3967","3.9705","2.6470","14.3332"
"16.0800","3.9913","59.6825","3.9913","2.6608","14.4022"
"16.1600","4.0120","59.9583","4.0120","2.6747","14.4687"
"16.2400","4.0313","60.2084","4.0313","2.6876","14.5291"
"16.3200","4.0514","60.4800","4.0514","2.7009","14.5946"
"16.4000","4.0717","60.7478","4.0717","2.7144","14.6592"
"16.4800","4.0905","61.0068","4.0905","2.7270","14.7217"
"16.5600","4.1115","61.2884","4.1115","2.7410","14.7897"
"16.6400","4.1306","61.5356","4.1306","2.7537","14.8493"
"16.7200","4.1516","61.8230","4.1516","2.7677","14.9187"
"16.8000","4.1721","62.0932","4.1721","2.7814","14.9839"
"16.8800","4.1919","62.3687","4.1919","2.7946","15.0504"
"16.9600","4.2117","62.5993","4.2117","2.8078","15.1060"
"17.0400","4.2312","62.8476","4.2312","2.8208","15.1659"
"17.1200","4.2507","63.1110","4.2507","2.8338","15.2295"
"17.2000","4.2712","63.3768","4.2712","2.8475","15.2936"
"17.2800","4.2900","63.6189","4.2900","2.8600","15.3521"
"17.3600","4.3115","63.9220","4.3115","2.8743","15.4252"
"17.4400","4.3319","64.1956","4.3319","2.8880","15.4912"
"17.5200","4.3513","64.4578","4.3513","2.9009","15.5545"
"17.6000","4.3714","64.7271","4.3714","2.9143","15.6195"
"17.6800","4.3906","64.9753","4.3906","2.9271","15.6794"
"17.7600","4.4114","65.2519","4.4114","2.9409","15.7461"
"17.8400","4.4316","65.5033","4.4316","2.9544","15.8068"
"17.9200","4.4508","65.7495","4.4508","2.9672","15.8662"
"18.0000","4.4713","66.0277","4.4713","2.9809","15.9333"
"18.0800","4.4920","66.2988","4.4920","2.9947","15.9987"
"18.1600","4.5113","66.5606","4.5113","3.0076","16.0619"
"18.2400","4.5319","66.8291","4.5319","3.0213","16.1267"
"18.3200","4.5506","67.0777","4.5506","3.0337","16.1867"
"18.4000","4.5715","67.3583","4.5715","3.0476","16.2544"
"18.4800","4.5912","67.6237","4.5912","3.0608","16.3185"
"18.5600","4.6110","67.8903","4.6110","3.0740","16.3828"
"18.6400","4.6312","68.1668","4.6312","3.0875","16.4495"
"18.7200","4.6515","68.4288","4.6515","3.1010","16.5127"
"18.8000","4.6715","68.6959","4.6715","3.1143","16.5772"
"18.8800","4.6923","68.9692","4.6923","3.1282","16.6432"
"18.9600","4.7106","69.2116","4.7106","3.1404","16.7016"
"19.0400","4.7312","69.4936","4.7312","3.1541","16.7697"
"19.1200","4.7508","69.7446","4.7508","3.1672","16.8303"
"19.2000","4.7710","69.9848","4.7710","3.1807","16.8882"
"19.2800","4.7925","70.2730","4.7925","3.1950","16.9578"
"19.3600","4.8120","70.5256","4.8120","3.2080","17.0187"
"19.4400","4.8321","70.7930","4.8321","3.2214","17.0832"
"19.5200","4.8516","71.0394","4.8516","3.2344","17.1427"
"19.6000","4.8707","71.3098","4.8707","3.2471","17.2080"
"19.6800","4.8912","71.5761","4.8912","3.2608","17.2722"
"19.7600","4.9106","71.8306","4.9106","3.2737","17.3336"
"19.8400","4.9309","72.1031","4.9309","3.2872","17.3994"
"19.9200","4.9522","72.3849","4.9522","3.3015","17.4674"
"20.0000","4.9711","72.6244","4.9711","3.3141","17.5252"
"20.0800","4.9916","72.8969","4.9916","3.3278","17.5909"
"20.1600","5.0111","73.1440","5.0111","3.3407","17.6506"
"20.2400","5.0310","73.4078","5.0310","3.3540","17.7142"
"20.3200","5.0508","73.6669","5.0508","3.3672","17.7768"
"20.4000","5.0706","73.9235","5.0706","3.3804","17.8387"
"20.4800","5.0919","74.2044","5.0919","3.3946","17.9065"
"20.5600","5.1126","74.4643","5.1126","3.4084","17.9692"
"20.6400","5.1315","74.7140","5.1315","3.4210","18.0294"
"20.7200","5.1514","74.9696","5.1514","3.4342","18.0911"
"20.8000","5.1708","75.2206","5.1708","3.4472","18.1517"
"20.8800","5.1915","75.4917","5.1915","3.4610","18.2171"
"20.9600","5.2115","75.7428","5.2115","3.4743","18.2777"
"21.0400","5.2297","75.9711","5.2297","3.4865","18.3328"
"21.1200","5.2508","76.2379","5.2508","3.5005","18.3972"
"21.2000","5.2720","76.4315","5.2720","3.5147","18.4439"
"21.2800","5.2917","76.6934","5.2917","3.5278","18.5071"
"21.3600","5.3119","76.9670","5.3119","3.5413","18.5731"
"21.4400","5.3305","77.1936","5.3305","3.5537","18.6278"
"21.5200","5.3509","77.4594","5.3509","3.5673","18.6919"
"21.6000","5.3716","77.7411","5.3716","3.5810","18.7599"
"21.6800","5.3910","78.0011","5.3910","3.5940","18.8226"
"21.7600","5.4123","78.2855","5.4123","3.6082","18.8913"
"21.8400","5.4317","78.5168","5.4317","3.6212","18.9471"
"21.9200","5.4517","78.7713","5.4517","3.6345","19.0085"
"22.0000","5.4714","79.0336","5.4714","3.6476","19.0718"
"22.0800","5.4910","79.2887","5.4910","3.6607","19.1334"
"22.1600","5.5115","79.5566","5.5115","3.6743","19.1980"
"22.2400","5.5309","79.8038","5.5309","3.6873","19.2577"
"22.3200","5.5500","80.0540","5.5500","3.7000","19.3180"
"22.4000","5.5720","80.3446","5.5720","3.7147","19.3882"
"22.4800","5.5916","80.5913","5.5916","3.7278","19.4477"
"22.5600","5.6120","80.8518","5.6120","3.7413","19.5106"
"22.6400","5.6313","81.0932","5.6313","3.7542","19.5688"
"22.7200","5.6504","81.3476","5.6504","3.7669","19.6302"
"22.8000","5.6710","81.6113","5.6710","3.7807","19.6939"
"22.8800","5.6913","81.8771","5.6913","3.7942","19.7580"
"22.9600","5.7114","82.1325","5.7114","3.8076","19.8196"
"23.0400","5.7325","82.4094","5.7325","3.8217","19.8864"
"23.1200","5.7514","82.6412","5.7514","3.8342","19.9424"
"23.2000","5.7717","82.8866","5.7717","3.8478","20.0016"
"23.2800","5.7914","83.1395","5.7914","3.8609","20.0626"
"23.3600","5.8111","83.3937","5.8111","3.8741","20.1240"
"23.4400","5.8308","83.6446","5.8308","3.8872","20.1845"
"23.5200","5.8500","83.8809","5.8500","3.9000","20.2415"
"23.6000","5.8713","84.1576","5.8713","3.9142","20.3083"
"23.6800","5.8926","84.4475","5.8926","3.9284","20.3783"
"23.7600","5.9119","84.6887","5.9119","3.9412","20.4365"
"23.8400","5.9312","84.9299","5.9312","3.9541","20.4947"
"23.9200","5.9510","85.1805","5.9510","3.9674","20.5552"
"24.0000","5.9707","85.4308","5.9707","3.9805","20.6156"
"24.0800","5.9918","85.6997","5.9918","3.9945","20.6804"
"24.1600","6.0105","85.9382","6.0105","4.0070","20.7380"
"24.2400","6.0321","86.2153","6.0321","4.0214","20.8049"
"24.3200","6.0520","86.4689","6.0520","4.0347","20.8661"
"24.4000","6.0718","86.7202","6.0718","4.0479","20.9267"
"24.4800","6.0914","86.9684","6.0914","4.0609","20.9866"
"24.5600","6.1114","87.2160","6.1114","4.0743","21.0463"
"24.6400","6.1312","87.4502","6.1312","4.0875","21.1028"
"24.7200","6.1515","87.7057","6.1515","4.1010","21.1645"
"24.8000","6.1697","87.9302","6.1697","4.1131","21.2187"
"24.8800","6.1914","88.2277","6.1914","4.1276","21.2905"
"24.9600","6.2115","88.4746","6.2115","4.1410","21.3501"
"25.0400","6.2319","88.7307","6.2319","4.1546","21.4118"
"25.1200","6.2514","88.9759","6.2514","4.1676","21.4710"
"25.2000","6.2705","89.2250","6.2705","4.1803","21.5311"
"25.2800","6.2913","89.4815","6.2913","4.1942","21.5930"
"25.3600","6.3115","89.7338","6.3115","4.2077","21.6539"
"25.4400","6.3310","89.9781","6.3310","4.2207","21.7129"
"25.5200","6.3516","90.2427","6.3516","4.2344","21.7767"
"25.6000","6.3718","90.4812","6.3718","4.2479","21.8343"
"25.6800","6.3920","90.7358","6.3920","4.2613","21.8957"
"25.7600","6.4118","90.9858","6.4118","4.2745","21.9560"
"25.8400","6.4304","91.2098","6.4304","4.2869","22.0101"
"25.9200","6.4514","91.4756","6.4514","4.3009","22.0742"
"26.0000","6.4704","91.7126","6.4704","4.3136","22.1314"
"26.0800","6.4913","91.9715","6.4913","4.3275","22.1939"
"26.1600","6.5125","92.2447","6.5125","4.3416","22.2598"
"26.2400","6.5315","92.4808","6.5315","4.3544","22.3168"
"26.3200","6.5512","92.7109","6.5512","4.3675","22.3723"
"26.4000","6.5714","92.9695","6.5714","4.3809","22.4347"
"26.4800","6.5908","93.2130","6.5908","4.3939","22.4935"
"26.5600","6.6119","93.4895","6.6119","4.4079","22.5602"
"26.6400","6.6306","93.7091","6.6306","4.4204","22.6132"
"26.7200","6.6513","93.9792","6.6513","4.4342","22.6784"
"26.8000","6.6722","94.2306","6.6722","4.4482","22.7391"
"26.8800","6.6919","94.4796","6.6919","4.4613","22.7991"
"26.9600","6.7117","94.7227","6.7117","4.4744","22.8578"
"27.0400","6.7312","94.9595","6.7312","4.4874","22.9149"
"27.1200","6.7508","95.2066","6.7508","4.5005","22.9746"
"27.2000","6.7713","95.4597","6.7713","4.5142","23.0356"
"27.2800","6.7903","95.6883","6.7903","4.5269","23.0908"
"27.3600","6.8114","95.9569","6.8114","4.5409","23.1556"
"27.4400","6.8319","96.2112","6.8319","4.5546","23.2170"
"27.5200","6.8513","96.4516","6.8513","4.5675","23.2750"
"27.6000","6.8715","96.6964","6.8715","4.5810","23.3341"
"27.6800","6.8905","96.9213","6.8905","4.5937","23.3883"
"27.7600","6.9114","97.1748","6.9114","4.6076","23.4495"
"27.8400","6.9315","97.4292","6.9315","4.6210","23.5109"
"27.9200","6.9507","97.6608","6.9507","4.6338","23.5668"
"28.0000","6.9712","97.9159","6.9712","4.6475","23.6283"
"28.0800","6.9922","98.1742","6.9922","4.6615","23.6907"
"28.1600","7.0117","98.3987","7.0117","4.6745","23.7449"
"28.2400","7.0312","98.6383","7.0312","4.6875","23.8027"
"28.3200","7.0506","98.8654","7.0506","4.7004","23.8575"
"28.4000","7.0715","99.1342","7.0715","4.7144","23.9223"
"28.4800","7.0913","99.3636","7.0913","4.7275","23.9777"
"28.5600","7.1109","99.5984","7.1109","4.7406","24.0344"
"28.6400","7.1312","99.8599","7.1312","4.7542","24.0975"
"28.7200","7.1515","100.0949","7.1515","4.7677","24.1542"
"28.8000","7.1716","100.3449","7.1716","4.7811","24.2145"
"28.8800","7.1922","100.5957","7.1922","4.7948","24.2750"
"28.9600","7.2108","100.8179","7.2108","4.8072","24.3287"
"29.0400","7.2313","101.0723","7.2313","4.8208","24.3900"
"29.1200","7.2508","101.3025","7.2508","4.8339","24.4456"
"29.2000","7.2712","101.5573","7.2712","4.8475","24.5071"
"29.2800","7.2929","101.8222","7.2929","4.8619","24.5710"
"29.3600","7.3119","102.0471","7.3119","4.8746","24.6253"
"29.4400","7.3318","102.2862","7.3318","4.8879","24.6830"
"29.5200","7.3515","102.5100","7.3515","4.9010","24.7370"
"29.6000","7.3703","102.7357","7.3703","4.9135","24.7914"
"29.6800","7.3909","102.9966","7.3909","4.9273","24.8544"
"29.7600","7.4108","103.2334","7.4108","4.9406","24.9115"
"29.8400","7.4311","103.4794","7.4311","4.9540","24.9709"
"29.9200","7.4521","103.7301","7.4521","4.9681","25.0314"
"30.0000","7.4715","103.9782","7.4715","4.9810","25.0913"
"30.0800","7.4921","104.2244","7.4921","4.9947","25.1507"
"30.1600","7.5110","104.4384","7.5110","5.0073","25.2023"
"30.2400","7.5308","104.6794","7.5308","5.0205","25.2605"
"30.3200","7.5507","104.9247","7.5507","5.0338","25.3197"
"30.4000","7.5708","105.1565","7.5708","5.0472","25.3756"
"30.4800","7.5918","105.4161","7.5918","5.0612","25.4383"
"30.5600","7.6128","105.6840","7.6128","5.0752","25.5029"
"30.6400","7.6317","105.8997","7.6317","5.0878","25.5550"
"30.7200","7.6512","106.1296","7.6512","5.1008","25.6104"
"30.8000","7.6705","106.3549","7.6705","5.1137","25.6648"
"30.8800","7.6914","106.6043","7.6914","5.1276","25.7250"
"30.9600","7.7116","106.8387","7.7116","5.1410","25.7815"
"31.0400","7.7302","107.0685","7.7302","5.1535","25.8370"
"31.1200","7.7514","107.3295","7.7514","5.1676","25.9000"
"31.2000","7.7721","107.5873","7.7721","5.1814","25.9622"
"31.2800","7.7918","107.8210","7.7918","5.1945","26.0186"
"31.3600","7.8115","108.0536","7.8115","5.2077","26.0747"
"31.4400","7.8305","108.2660","7.8305","5.2203","26.1260"
"31.5200","7.8512","108.5105","7.8512","5.2341","26.1850"
"31.6000","7.8715","108.7531","7.8715","5.2476","26.2435"
"31.6800","7.8911","108.9936","7.8911","5.2607","26.3015"
"31.7600","7.9123","109.2597","7.9123","5.2749","26.3658"
"31.8400","7.9319","109.4763","7.9319","5.2879","26.4180"
"31.9200","7.9520","109.7112","7.9520","5.3013","26.4747"
"32.0000","7.9714","109.9325","7.9714","5.3143","26.5281"
"32.0800","7.9909","110.1670","7.9909","5.3273","26.5847"
"32.1600","8.0113","110.4224","8.0113","5.3409","26.6463"
"32.2400","8.0309","110.6306","8.0309","5.3539","26.6966"
"32.3200","8.0500","110.8575","8.0500","5.3667","26.7513"
"32.4000","8.0721","111.1346","8.0721","5.3814","26.8182"
"32.4800","8.0914","111.3545","8.0914","5.3943","26.8712"
"32.5600","8.1124","111.6013","8.1124","5.4082","26.9308"
"32.6400","8.1314","111.8221","8.1314","5.4209","26.9841"
"32.7200","8.1503","112.0427","8.1503","5.4335","27.0373"
"32.8000","8.1707","112.2930","8.1707","5.4471","27.0977"
"32.8800","8.1911","112.5221","8.1911","5.4608","27.1530"
"32.9600","8.2115","112.7558","8.2115","5.4743","27.2094"
"33.0400","8.2323","113.0038","8.2323","5.4882","27.2693"
"33.1200","8.2512","113.2213","8.2512","5.5008","27.3217"
"33.2000","8.2717","113.4635","8.2717","5.5145","27.3802"
"33.2800","8.2915","113.6983","8.2915","5.5277","27.4368"
"33.3600","8.3113","113.9360","8.3113","5.5409","27.4942"
"33.4400","8.3306","114.1539","8.3306","5.5538","27.5468"
"33.5200","8.3495","114.3530","8.3495","5.5663","27.5948"
"33.6000","8.3710","114.6181","8.3710","5.5807","27.6588"
"33.6800","8.3923","114.8646","8.3923","5.5949","27.7183"
"33.7600","8.4122","115.0982","8.4122","5.6081","27.7747"
"33.8400","8.4314","115.3226","8.4314","5.6209","27.8288"
"33.9200","8.4507","115.5287","8.4507","5.6338","27.8786"
"34.0000","8.4706","115.7585","8.4706","5.6471","27.9340"
"34.0800","8.4917","116.0063","8.4917","5.6611","27.9938"
"34.1600","8.5106","116.2227","8.5106","5.6737","28.0460"
"34.2400","8.5318","116.4685","8.5318","5.6879","28.1053"
"34.3200","8.5521","116.7018","8.5521","5.7014","28.1616"
"34.4000","8.5721","116.9315","8.5721","5.7147","28.2171"
"34.4800","8.5915","117.1484","8.5915","5.7277","28.2694"
"34.5600","8.6110","117.3643","8.6110","5.7407","28.3215"
"34.6400","8.6311","117.5908","8.6311","5.7541","28.3762"
"34.7200","8.6513","117.8126","8.6513","5.7675","28.4297"
"34.8000","8.6701","118.0279","8.6701","5.7800","28.4816"
"34.8800","8.6915","118.2811","8.6915","5.7943","28.5427"
"34.9600","8.7117","118.5088","8.7117","5.8078","28.5977"
"35.0400","8.7319","118.7357","8.7319","5.8213","28.6524"
"35.1200","8.7515","118.9416","8.7515","5.8344","28.7021"
"35.2000","8.7704","119.1571","8.7704","5.8469","28.7541"
"35.2800","8.7913","119.3974","8.7913","5.8609","28.8121"
"35.3600","8.8116","119.6293","8.8116","5.8744","28.8681"
"35.4400","8.8309","119.8396","8.8309","5.8872","28.9188"
"35.5200","8.8515","120.0807","8.8515","5.9010","28.9770"
"35.6000","8.8719","120.2979","8.8719","5.9146","29.0294"
"35.6800","8.8922","120.5302","8.8922","5.9281","29.0855"
"35.7600","8.9121","120.7435","8.9121","5.9414","29.1370"
"35.8400","8.9305","120.9436","8.9305","5.9536","29.1852"
"35.9200","8.9510","121.1725","8.9510","5.9673","29.2405"
"36.0000","8.9702","121.3892","8.9702","5.9802","29.2928"
"36.0800","8.9912","121.6240","8.9912","5.9941","29.3494"
"36.1600","9.0115","121.8498","9.0115","6.0077","29.4039"
"36.2400","9.0317","122.0697","9.0317","6.0211","29.4570"
"36.3200","9.0512","122.2834","9.0512","6.0341","29.5085"
"36.4000","9.0715","122.5080","9.0715","6.0477","29.5627"
"36.4800","9.0908","122.7088","9.0908","6.0606","29.6112"
"36.5600","9.1115","122.9455","9.1115","6.0743","29.6683"
"36.6400","9.1305","123.1379","9.1305","6.0870","29.7147"
"36.7200","9.1517","123.3839","9.1517","6.1011","29.7741"
"36.8000","9.1726","123.6219","9.1726","6.1151","29.8315"
"36.8800","9.1920","123.8320","9.1920","6.1280","29.8822"
"36.9600","9.2116","124.0476","9.2116","6.1411","29.9343"
"37.0400","9.2311","124.2586","9.2311","6.1541","29.9852"
"37.1200","9.2508","124.4766","9.2508","6.1672","30.0378"
"37.2000","9.2714","124.7094","9.2714","6.1809","30.0940"
"37.2800","9.2902","124.9009","9.2902","6.1935","30.1402"
"37.3600","9.3112","125.1370","9.3112","6.2075","30.1972"
"37.4400","9.3321","125.3735","9.3321","6.2214","30.2542"
"37.5200","9.3515","125.5784","9.3515","6.2343","30.3037"
"37.6000","9.3713","125.8063","9.3713","6.2475","30.3587"
"37.6800","9.3906","125.9977","9.3906","6.2604","30.4048"
"37.7600","9.4116","126.2353","9.4116","6.2744","30.4622"
"37.8400","9.4311","126.4405","9.4311","6.2874","30.5117"
"37.9200","9.4505","126.6526","9.4505","6.3003","30.5629"
"38.0000","9.4711","126.8837","9.4711","6.3141","30.6186"
"38.0800","9.4922","127.1167","9.4922","6.3281","30.6749"
"38.1600","9.5120","127.3276","9.5120","6.3413","30.7258"
"38.2400","9.5318","127.5332","9.5318","6.3546","30.7754"
"38.3200","9.5501","127.7212","9.5501","6.3667","30.8207"
"38.4000","9.5716","127.9675","9.5716","6.3811","30.8802"
"38.4800","9.5912","128.1596","9.5912","6.3941","30.9265"
"38.5600","9.6108","128.3342","9.6108","6.4072","30.9687"
"38.6400","9.6308","128.5677","9.6308","6.4206","31.0250"
"38.7200","9.6517","128.7877","9.6517","6.4344","31.0781"
"38.8000","9.6718","129.0089","9.6718","6.4479","31.1315"
"38.8800","9.6922","129.2282","9.6922","6.4615","31.1844"
"38.9600","9.7105","129.4158","9.7105","6.4737","31.2297"
"39.0400","9.7314","129.6458","9.7314","6.4876","31.2852"
"39.1200","9.7509","129.8507","9.7509","6.5006","31.3346"
"39.2000","9.7711","130.0662","9.7711","6.5140","31.3866"
"39.2800","9.7923","130.3004","9.7923","6.5282","31.4431"
"39.3600","9.8120","130.5093","9.8120","6.5413","31.4936"
"39.4400","9.8320","130.7129","9.8320","6.5547","31.5427"
"39.5200","9.8515","130.9128","9.8515","6.5677","31.5909"
"39.6000","9.8706","131.1024","9.8706","6.5804","31.6367"
"39.6800","9.8910","131.3332","9.8910","6.5940","31.6924"
"39.7600","9.9108","131.5218","9.9108","6.6072","31.7379"
"39.8400","9.9308","131.7417","9.9308","6.6206","31.7909"
"39.9200","9.9523","131.9696","9.9523","6.6349","31.8459"
"40.0000","9.9713","132.1675","9.9713","6.6475","31.8937"
"40.0800","9.9918","132.3799","9.9918","6.6612","31.9449"
"40.1600","10.0108","132.5750","10.0108","6.6739","31.9920"
"40.2400","10.0312","132.7901","10.0312","6.6875","32.0439"
"40.3200","10.0507","132.9920","10.0507","6.7004","32.0927"
"40.4000","10.0707","133.1840","10.0707","6.7138","32.1390"
"40.4800","10.0918","133.4107","10.0918","6.7279","32.1937"
"40.5600","10.1130","133.6367","10.1130","6.7420","32.2482"
"40.6400","10.1315","133.8154","10.1315","6.7543","32.2914"
"40.7200","10.1512","134.0196","10.1512","6.7675","32.3406"
"40.8000","10.1705","134.2094","10.1705","6.7804","32.3864"
"40.8800","10.1915","134.4307","10.1915","6.7944","32.4398"
"40.9600","10.2116","134.6280","10.2116","6.8077","32.4874"
"41.0400","10.2302","134.8129","10.2302","6.8202","32.5321"
"41.1200","10.2510","135.0255","10.2510","6.8340","32.5834"
"41.2000","10.2718","135.2011","10.2718","6.8479","32.6258"
"41.2800","10.2917","135.3968","10.2917","6.8611","32.6730"
"41.3600","10.3113","135.5895","10.3113","6.8742","32.7195"
"41.4400","10.3305","135.7735","10.3305","6.8870","32.7639"
"41.5200","10.3510","135.9881","10.3510","6.9007","32.8157"
"41.6000","10.3717","136.1908","10.3717","6.9145","32.8646"
"41.6800","10.3915","136.3967","10.3915","6.9277","32.9143"
"41.7600","10.4124","136.6107","10.4124","6.9416","32.9659"
"41.8400","10.4319","136.7832","10.4319","6.9546","33.0075"
"41.9200","10.4520","136.9772","10.4520","6.9680","33.0544"
"42.0000","10.4714","137.1675","10.4714","6.9809","33.1003"
"42.0800","10.4913","137.3651","10.4913","6.9942","33.1480"
"42.1600","10.5111","137.5529","10.5111","7.0074","33.1933"
"42.2400","10.5309","137.7456","10.5309","7.0206","33.2398"
"42.3200","10.5501","137.9167","10.5501","7.0334","33.2811"
"42.4000","10.5717","138.1489","10.5717","7.0478","33.3371"
"42.4800","10.5917","138.3270","10.5917","7.0611","33.3801"
"42.5600","10.6124","138.5317","10.6124","7.0750","33.4295"
"42.6400","10.6313","138.6887","10.6313","7.0875","33.4673"
"42.7200","10.6506","138.8781","10.6506","7.1004","33.5131"
"42.8000","10.6707","139.0577","10.6707","7.1138","33.5564"
"42.8800","10.6911","139.2520","10.6911","7.1274","33.6033"
"42.9600","10.7115","139.4444","10.7115","7.1410","33.6497"
"43.0400","10.7323","139.6314","10.7323","7.1549","33.6948"
"43.1200","10.7511","139.8028","10.7511","7.1674","33.7362"
"43.2000","10.7719","140.0039","10.7719","7.1812","33.7847"
"43.2800","10.7918","140.1778","10.7918","7.1945","33.8267"
"43.3600","10.8116","140.3598","10.8116","7.2078","33.8706"
"43.4400","10.8307","140.5260","10.8307","7.2205","33.9107"
"43.5200","10.8496","140.6886","10.8496","7.2330","33.9500"
"43.6000","10.8711","140.8919","10.8711","7.2474","33.9990"
"43.6800","10.8922","141.0921","10.8922","7.2614","34.0473"
"43.7600","10.9115","141.2520","10.9115","7.2743","34.0859"
"43.8400","10.9310","141.4191","10.9310","7.2873","34.1262"
"43.9200","10.9512","141.5994","10.9512","7.3008","34.1697"
"44.0000","10.9712","141.7408","10.9712","7.3141","34.2039"
"44.0800","10.9917","141.9195","10.9917","7.3278","34.2470"
"44.1600","11.0108","142.0845","11.0108","7.3405","34.2868"
"44.2400","11.0320","142.2702","11.0320","7.3547","34.3316"
"44.3200","11.0518","142.4324","11.0518","7.3679","34.3707"
"44.4000","11.0719","142.6100","11.0719","7.3813","34.4136"
"44.4800","11.0915","142.7738","11.0915","7.3943","34.4531"
"44.5600","11.1112","142.9329","11.1112","7.4074","34.4915"
"44.6400","11.1310","143.1016","11.1310","7.4207","34.5322"
"44.7200","11.1513","143.2728","11.1513","7.4342","34.5736"
"44.8000","11.1699","143.4162","11.1699","7.4466","34.6082"
"44.8800","11.1917","143.6163","11.1917","7.4611","34.6565"
"44.9600","11.2116","143.7673","11.2116","7.4744","34.6929"
"45.0400","11.2318","143.9301","11.2318","7.4878","34.7322"
"45.1200","11.2513","144.0824","11.2513","7.5008","34.7689"
"45.2000","11.2705","144.2238","11.2705","7.5137","34.8031"
"45.2800","11.2915","144.4051","11.2915","7.5277","34.8468"
"45.3600","11.3115","144.5621","11.3115","7.5410","34.8847"
"45.4400","11.3310","144.7175","11.3310","7.5540","34.9222"
"45.5200","11.3516","144.8855","11.3516","7.5678","34.9627"
"45.6000","11.3716","145.0192","11.3716","7.5811","34.9950"
"45.6800","11.3921","145.1734","11.3921","7.5948","35.0322"
"45.7600","11.4123","145.3238","11.4123","7.6082","35.0685"
"45.8400","11.4306","145.4567","11.4306","7.6204","35.1006"
"45.9200","11.4510","145.6154","11.4510","7.6340","35.1389"
"46.0000","11.4703","145.7490","11.4703","7.6469","35.1711"
"46.0800","11.4909","145.9041","11.4909","7.6606","35.2085"
"46.1600","11.5116","146.0540","11.5116","7.6744","35.2447"
"46.2400","11.5318","146.2051","11.5318","7.6878","35.2811"
"46.3200","11.5514","146.3443","11.5514","7.7009","35.3147"
"46.4000","11.5715","146.4826","11.5715","7.7144","35.3481"
"46.4800","11.5907","146.6086","11.5907","7.7271","35.3785"
"46.5600","11.6115","146.7742","11.6115","7.7410","35.4185"
"46.6400","11.6304","146.8869","11.6304","7.7536","35.4457"
"46.7200","11.6521","147.0433","11.6521","7.7680","35.4834"
"46.8000","11.6724","147.1829","11.6724","7.7816","35.5171"
"46.8800","11.6917","147.3130","11.6917","7.7945","35.5485"
"46.9600","11.7115","147.4453","11.7115","7.8077","35.5804"
"47.0400","11.7312","147.5647","11.7312","7.8208","35.6092"
"47.1200","11.7509","147.6936","11.7509","7.8339","35.6403"
"47.2000","11.7712","147.8290","11.7712","7.8475","35.6730"
"47.2800","11.7906","147.9501","11.7906","7.8604","35.7022"
"47.3600","11.8114","148.0866","11.8114","7.8742","35.7352"
"47.4400","11.8321","148.2201","11.8321","7.8881","35.7674"
"47.5200","11.8512","148.3422","11.8512","7.9008","35.7969"
"47.6000","11.8714","148.4686","11.8714","7.9143","35.8274"
"47.6800","11.8906","148.5729","11.8906","7.9270","35.8525"
"47.7600","11.9116","148.7219","11.9116","7.9411","35.8885"
"47.8400","11.9315","148.8349","11.9315","7.9544","35.9158"
"47.9200","11.9505","148.9503","11.9505","7.9670","35.9436"
"48.0000","11.9716","149.0886","11.9716","7.9810","35.9770"
"48.0800","11.9923","149.2042","11.9923","7.9949","36.0049"
"48.1600","12.0117","149.3218","12.0117","8.0078","36.0333"
"48.2400","12.0318","149.4309","12.0318","8.0212","36.0596"
"48.3200","12.0504","149.5165","12.0504","8.0336","36.0802"
"48.4000","12.0714","149.6377","12.0714","8.0476","36.1095"
"48.4800","12.0913","149.7528","12.0913","8.0609","36.1373"
"48.5600","12.1109","149.8665","12.1109","8.0739","36.1647"
"48.6400","12.1306","149.9685","12.1306","8.0871","36.1893"
"48.7200","12.1520","150.0835","12.1520","8.1013","36.2171"
"48.8000","12.1719","150.1811","12.1719","8.1146","36.2406"
"48.8800","12.1920","150.2885","12.1920","8.1280","36.2665"
"48.9600","12.2104","150.3638","12.2104","8.1403","36.2847"
"49.0400","12.2313","150.4818","12.2313","8.1542","36.3132"
"49.1200","12.2509","150.5798","12.2509","8.1673","36.3368"
"49.2000","12.2713","150.6790","12.2713","8.1808","36.3608"
"49.2800","12.2926","150.7864","12.2926","8.1951","36.3867"
"49.3600","12.3120","150.8802","12.3120","8.2080","36.4093"
"49.4400","12.3320","150.9561","12.3320","8.2213","36.4276"
"49.5200","12.3513","151.0406","12.3513","8.2342","36.4480"
"49.6000","12.3704","151.1256","12.3704","8.2470","36.4685"
"49.6800","12.3910","151.2207","12.3910","8.2606","36.4915"
"49.7600","12.4109","151.3004","12.4109","8.2739","36.5107"
"49.8400","12.4309","151.3974","12.4309","8.2873","36.5341"
"49.9200","12.4523","151.4919","12.4523","8.3015","36.5569"
"50.0000","12.4713","151.5647","12.4713","8.3142","36.5745"
"50.0800","12.4920","151.6396","12.4920","8.3280","36.5926"
"50.1600","12.5109","151.7018","12.5109","8.3406","36.6076"
"50.2400","12.5308","151.7749","12.5308","8.3539","36.6252"
"50.3200","12.5507","151.8653","12.5507","8.3671","36.6470"
"50.4000","12.5709","151.9426","12.5709","8.3806","36.6657"
"50.4800","12.5920","152.0359","12.5920","8.3946","36.6882"
"50.5600","12.6131","152.1182","12.6131","8.4087","36.7081"
"50.6400","12.6315","152.1771","12.6315","8.4210","36.7223"
"50.7200","12.6515","152.2510","12.6515","8.4343","36.7401"
"50.8000","12.6704","152.3132","12.6704","8.4469","36.7551"
"50.8800","12.6915","152.3909","12.6915","8.4610","36.7739"
"50.9600","12.7114","152.4508","12.7114","8.4743","36.7883"
"51.0400","12.7304","152.5157","12.7304","8.4869","36.8040"
"51.1200","12.7514","152.5965","12.7514","8.5009","36.8235"
"51.2000","12.7717","152.6668","12.7717","8.5144","36.8404"
"51.2800","12.7919","152.7292","12.7919","8.5280","36.8555"
"51.3600","12.8117","152.8020","12.8117","8.5411","36.8731"
"51.4400","12.8304","152.8397","12.8304","8.5536","36.8822"
"51.5200","12.8507","152.9073","12.8507","8.5671","36.8985"
"51.6000","12.8716","152.9675","12.8716","8.5811","36.9130"
"51.6800","12.8905","153.0191","12.8905","8.5937","36.9255"
"51.7600","12.9125","153.1021","12.9125","8.6083","36.9455"
"51.8400","12.9321","153.1433","12.9321","8.6214","36.9554"
"51.9200","12.9520","153.1955","12.9520","8.6347","36.9680"
"52.0000","12.9715","153.2413","12.9715","8.6477","36.9791"
"52.0800","12.9910","153.2870","12.9910","8.6607","36.9901"
"52.1600","13.0114","153.3531","13.0114","8.6743","37.0061"
"52.2400","13.0313","153.4130","13.0313","8.6875","37.0205"
"52.3200","13.0502","153.4494","13.0502","8.7001","37.0293"
"52.4000","13.0716","153.5226","13.0716","8.7144","37.0469"
"52.4800","13.0918","153.5616","13.0918","8.7279","37.0564"
"52.5600","13.1124","153.6084","13.1124","8.7416","37.0677"
"52.6400","13.1314","153.6379","13.1314","8.7542","37.0748"
"52.7200","13.1504","153.6752","13.1504","8.7669","37.0838"
"52.8000","13.1705","153.7217","13.1705","8.7803","37.0950"
"52.8800","13.1913","153.7778","13.1913","8.7942","37.1085"
"52.9600","13.2117","153.8214","13.2117","8.8078","37.1191"
"53.0400","13.2323","153.8642","13.2323","8.8215","37.1294"
"53.1200","13.2514","153.8925","13.2514","8.8343","37.1362"
"53.2000","13.2716","153.9364","13.2716","8.8477","37.1468"
"53.2800","13.2921","153.9849","13.2921","8.8614","37.1585"
"53.3600","13.3113","154.0039","13.3113","8.8742","37.1631"
"53.4400","13.3311","154.0351","13.3311","8.8874","37.1706"
"53.5200","13.3497","154.0458","13.3497","8.8998","37.1732"
"53.6000","13.3710","154.0927","13.3710","8.9140","37.1845"
"53.6800","13.3922","154.1435","13.3922","8.9281","37.1968"
"53.7600","13.4119","154.1769","13.4119","8.9413","37.2049"
"53.8400","13.4315","154.2019","13.4315","8.9544","37.2109"
"53.9200","13.4505","154.2088","13.4505","8.9670","37.2126"
"54.0000","13.4708","154.2407","13.4708","8.9805","37.2202"
"54.0800","13.4919","154.2846","13.4919","8.9946","37.2308"
"54.1600","13.5107","154.3052","13.5107","9.0071","37.2358"
"54.2400","13.5320","154.3446","13.5320","9.0213","37.2453"
"54.3200","13.5517","154.3734","13.5517","9.0345","37.2523"
"54.4000","13.5719","154.3965","13.5719","9.0479","37.2578"
"54.4800","13.5916","154.4204","13.5916","9.0611","37.2636"
"54.5600","13.6111","154.4306","13.6111","9.0740","37.2661"
"54.6400","13.6312","154.4614","13.6312","9.0875","37.2735"
"54.7200","13.6513","154.4774","13.6513","9.1009","37.2774"
"54.8000","13.6699","154.4842","13.6699","9.1133","37.2790"
"54.8800","13.6917","154.5378","13.6917","9.1278","37.2919"
"54.9600","13.7116","154.5446","13.7116","9.1411","37.2936"
"55.0400","13.7319","154.5640","13.7319","9.1546","37.2983"
"55.1200","13.7515","154.5800","13.7515","9.1676","37.3021"
"55.2000","13.7705","154.5909","13.7705","9.1804","37.3047"
"55.2800","13.7910","154.6163","13.7910","9.1940","37.3109"
"55.3600","13.8112","154.6252","13.8112","9.2075","37.3130"
"55.4400","13.8310","154.6360","13.8310","9.2207","37.3156"
"55.5200","13.8521","154.6619","13.8521","9.2347","37.3219"
"55.6000","13.8716","154.6572","13.8716","9.2477","37.3207"
"55.6800","13.8922","154.6777","13.8922","9.2615","37.3257"
"55.7600","13.9124","154.6872","13.9124","9.2749","37.3280"
"55.8400","13.9304","154.6902","13.9304","9.2869","37.3287"
"55.9200","13.9506","154.7126","13.9506","9.3004","37.3341"
"56.0000","13.9705","154.7259","13.9705","9.3137","37.3373"
"56.0800","13.9914","154.7590","13.9914","9.3276","37.3453"
"56.1600","14.0118","154.7710","14.0118","9.3412","37.3482"
"56.2400","14.0312","154.7713","14.0312","9.3541","37.3483"
"56.3200","14.0513","154.7872","14.0513","9.3675","37.3521"
"56.4000","14.0717","154.8072","14.0717","9.3811","37.3570"
"56.4800","14.0910","154.8181","14.0910","9.3940","37.3596"
"56.5600","14.1113","154.8342","14.1113","9.4075","37.3635"
"56.6400","14.1305","154.8305","14.1305","9.4203","37.3626"
"56.7200","14.1515","154.8485","14.1515","9.4344","37.3669"
"56.8000","14.1723","154.8662","14.1723","9.4482","37.3712"
"56.8800","14.1923","154.8828","14.1923","9.4615","37.3752"
"56.9600","14.2115","154.8736","14.2115","9.4744","37.3730"
"57.0400","14.2310","154.8778","14.2310","9.4874","37.3740"
"57.1200","14.2510","154.8817","14.2510","9.5006","37.3749"
"57.2000","14.2715","154.8924","14.2715","9.5143","37.3775"
"57.2800","14.2899","154.8819","14.2899","9.5266","37.3750"
"57.3600","14.3113","154.9088","14.3113","9.5409","37.3815"
"57.4400","14.3322","154.9236","14.3322","9.5548","37.3850"
"57.5200","14.3514","154.9249","14.3514","9.5676","37.3853"
"57.6000","14.3717","154.9308","14.3717","9.5811","37.3868"
"57.6800","14.3906","154.9247","14.3906","9.5937","37.3853"
"57.7600","14.4114","154.9378","14.4114","9.6076","37.3885"
"57.8400","14.4316","154.9388","14.4316","9.6211","37.3887"
"57.9200","14.4507","154.9478","14.4507","9.6338","37.3909"
"58.0000","14.4716","154.9613","14.4716","9.6477","37.3941"
"58.0800","14.4921","154.9776","14.4921","9.6614","37.3981"
"58.1600","14.5115","154.9738","14.5115","9.6743","37.3971"
"58.2400","14.5314","154.9807","14.5314","9.6876","37.3988"
"58.3200","14.5507","154.9772","14.5507","9.7004","37.3980"
"58.4000","14.5712","154.9849","14.5712","9.7142","37.3998"
"58.4800","14.5910","154.9887","14.5910","9.7273","37.4008"
"58.5600","14.6106","154.9914","14.6106","9.7404","37.4014"
"58.6400","14.6306","154.9977","14.6306","9.7537","37.4029"
"58.7200","14.6515","155.0024","14.6515","9.7677","37.4040"
"58.8000","14.6719","155.0125","14.6719","9.7812","37.4065"
"58.8800","14.6922","155.0210","14.6922","9.7948","37.4085"
"58.9600","14.7108","155.0179","14.7108","9.8072","37.4078"
"59.0400","14.7311","155.0261","14.7311","9.8207","37.4098"
"59.1200","14.7508","155.0247","14.7508","9.8339","37.4094"
"59.2000","14.7712","155.0389","14.7712","9.8475","37.4129"
"59.2800","14.7924","155.0510","14.7924","9.8616","37.4158"
"59.3600","14.8122","155.0509","14.8122","9.8748","37.4158"
"59.4400","14.8320","155.0415","14.8320","9.8880","37.4135"
"59.5200","14.8514","155.0383","14.8514","9.9009","37.4127"
"59.6000","14.8704","155.0381","14.8704","9.9136","37.4127"
"59.6800","14.8909","155.0497","14.8909","9.9273","37.4155"
"59.7600","14.9105","155.0491","14.9105","9.9403","37.4153"
"59.8400","14.9312","155.0571","14.9312","9.9542","37.4172"
"59.9200","14.9524","155.0603","14.9524","9.9682","37.4180"
"60.0000","14.9709","155.0591","14.9709","9.9806","37.4177"
"60.0800","14.9917","155.0568","14.9917","9.9945","37.4172"
"60.1130","15.0001","155.0589","15.0001","10.0001","37.4177"