File: data/instron_tests/metamaterials/250327/250327_1467_BULK_m2_2mmTransition.is_comp_Exports/250327_1467_BULK_m2_2mmTransition_6_1.csv
Results Table 1
,Compression Axis,H*,V*,Height,Thickness,Width,Area,Fixture separation,Specimen label
,,,,(mm),(mm),(mm),(mm^2),(mm),
"6","X","","","148.00","28.00","148.00","4144.00","150.00","1467_BULK_m2_2mmTransition"

Results Table 2
,Modulus (Segment 0 % - 5 %),Compression Axis
,(kPa),
"6","508.03","X"

Time,Displacement,Force,Compressive displacement,Compressive strain (Displacement),Compressive stress
(s),(mm),(N),(mm),(%),(kPa)
"0.0000","0.0000","-7.4424","0.0000","0.0000","-1.7959"
"0.0800","0.0012","-7.3924","0.0012","0.0008","-1.7839"
"0.1600","0.0173","-7.0537","0.0173","0.0115","-1.7021"
"0.2400","0.0381","-6.6637","0.0381","0.0254","-1.6080"
"0.3200","0.0580","-6.3141","0.0580","0.0386","-1.5237"
"0.4000","0.0772","-5.9324","0.0772","0.0515","-1.4316"
"0.4800","0.0983","-5.5397","0.0983","0.0655","-1.3368"
"0.5600","0.1180","-5.1923","0.1180","0.0787","-1.2530"
"0.6400","0.1376","-4.8255","0.1376","0.0917","-1.1645"
"0.7200","0.1571","-4.4797","0.1571","0.1048","-1.0810"
"0.8000","0.1766","-4.1442","0.1766","0.1177","-1.0001"
"0.8800","0.1973","-3.7762","0.1973","0.1315","-0.9112"
"0.9600","0.2171","-3.4212","0.2171","0.1448","-0.8256"
"1.0400","0.2362","-3.0954","0.2362","0.1575","-0.7470"
"1.1200","0.2572","-2.7177","0.2572","0.1714","-0.6558"
"1.2000","0.2774","-2.3743","0.2774","0.1849","-0.5730"
"1.2800","0.2979","-2.0395","0.2979","0.1986","-0.4922"
"1.3600","0.3178","-1.7011","0.3178","0.2119","-0.4105"
"1.4400","0.3362","-1.3772","0.3362","0.2241","-0.3323"
"1.5200","0.3568","-1.0309","0.3568","0.2379","-0.2488"
"1.6000","0.3768","-0.6989","0.3768","0.2512","-0.1687"
"1.6800","0.3975","-0.3441","0.3975","0.2650","-0.0830"
"1.7600","0.4187","0.0085","0.4187","0.2792","0.0021"
"1.8400","0.4374","0.3163","0.4374","0.2916","0.0763"
"1.9200","0.4576","0.6453","0.4576","0.3050","0.1557"
"2.0000","0.4776","0.9791","0.4776","0.3184","0.2363"
"2.0800","0.4966","1.2857","0.4966","0.3311","0.3103"
"2.1600","0.5170","1.6268","0.5170","0.3447","0.3926"
"2.2400","0.5361","1.9336","0.5361","0.3574","0.4666"
"2.3200","0.5570","2.2692","0.5570","0.3713","0.5476"
"2.4000","0.5784","2.6218","0.5784","0.3856","0.6327"
"2.4800","0.5976","2.9359","0.5976","0.3984","0.7085"
"2.5600","0.6174","3.2561","0.6174","0.4116","0.7857"
"2.6400","0.6365","3.5590","0.6365","0.4243","0.8588"
"2.7200","0.6566","3.8903","0.6566","0.4378","0.9388"
"2.8000","0.6774","4.2198","0.6774","0.4516","1.0183"
"2.8800","0.6967","4.5268","0.6967","0.4645","1.0924"
"2.9600","0.7178","4.8674","0.7178","0.4785","1.1746"
"3.0400","0.7383","5.1950","0.7383","0.4922","1.2536"
"3.1200","0.7571","5.4897","0.7571","0.5047","1.3247"
"3.2000","0.7774","5.8249","0.7774","0.5182","1.4056"
"3.2800","0.7974","6.1394","0.7974","0.5316","1.4815"
"3.3600","0.8179","6.4563","0.8179","0.5453","1.5580"
"3.4400","0.8364","6.7413","0.8364","0.5576","1.6268"
"3.5200","0.8555","7.0570","0.8555","0.5703","1.7029"
"3.6000","0.8773","7.3978","0.8773","0.5849","1.7852"
"3.6800","0.8982","7.7154","0.8982","0.5988","1.8618"
"3.7600","0.9174","8.0167","0.9174","0.6116","1.9345"
"3.8400","0.9374","8.3135","0.9374","0.6250","2.0062"
"3.9200","0.9563","8.6009","0.9563","0.6376","2.0755"
"4.0000","0.9770","8.9322","0.9770","0.6513","2.1555"
"4.0800","0.9973","9.2542","0.9973","0.6649","2.2332"
"4.1600","1.0171","9.5733","1.0171","0.6780","2.3102"
"4.2400","1.0380","9.9104","1.0380","0.6920","2.3915"
"4.3200","1.0574","10.2030","1.0574","0.7050","2.4621"
"4.4000","1.0779","10.5310","1.0779","0.7186","2.5413"
"4.4800","1.0978","10.8327","1.0978","0.7319","2.6141"
"4.5600","1.1164","11.1313","1.1164","0.7443","2.6861"
"4.6400","1.1366","11.4491","1.1366","0.7577","2.7628"
"4.7200","1.1566","11.7595","1.1566","0.7711","2.8377"
"4.8000","1.1767","12.0793","1.1767","0.7845","2.9149"
"4.8800","1.1979","12.4230","1.1979","0.7986","2.9978"
"4.9600","1.2174","12.7066","1.2174","0.8116","3.0663"
"5.0400","1.2378","13.0195","1.2378","0.8252","3.1418"
"5.1200","1.2573","13.3312","1.2573","0.8382","3.2170"
"5.2000","1.2759","13.6172","1.2759","0.8506","3.2860"
"5.2800","1.2970","13.9510","1.2970","0.8647","3.3666"
"5.3600","1.3173","14.2593","1.3173","0.8782","3.4410"
"5.4400","1.3377","14.5723","1.3377","0.8918","3.5165"
"5.5200","1.3584","14.8878","1.3584","0.9056","3.5926"
"5.6000","1.3774","15.1858","1.3774","0.9183","3.6645"
"5.6800","1.3978","15.4979","1.3978","0.9318","3.7398"
"5.7600","1.4173","15.8003","1.4173","0.9449","3.8128"
"5.8400","1.4369","16.0984","1.4369","0.9579","3.8847"
"5.9200","1.4570","16.4029","1.4570","0.9713","3.9582"
"6.0000","1.4760","16.6906","1.4760","0.9840","4.0277"
"6.0800","1.4974","17.0132","1.4974","0.9983","4.1055"
"6.1600","1.5181","17.3366","1.5181","1.0121","4.1835"
"6.2400","1.5373","17.6334","1.5373","1.0249","4.2552"
"6.3200","1.5569","17.9400","1.5569","1.0379","4.3292"
"6.4000","1.5768","18.2381","1.5768","1.0512","4.4011"
"6.4800","1.5971","18.5370","1.5971","1.0647","4.4732"
"6.5600","1.6178","18.8538","1.6178","1.0785","4.5497"
"6.6400","1.6362","19.1247","1.6362","1.0908","4.6150"
"6.7200","1.6578","19.4566","1.6578","1.1052","4.6951"
"6.8000","1.6780","19.7730","1.6780","1.1187","4.7715"
"6.8800","1.6979","20.0657","1.6979","1.1319","4.8421"
"6.9600","1.7171","20.3600","1.7171","1.1447","4.9131"
"7.0400","1.7367","20.6463","1.7367","1.1578","4.9822"
"7.1200","1.7569","20.9489","1.7569","1.1713","5.0552"
"7.2000","1.7775","21.2620","1.7775","1.1850","5.1308"
"7.2800","1.7964","21.5542","1.7964","1.1976","5.2013"
"7.3600","1.8173","21.8646","1.8173","1.2116","5.2762"
"7.4400","1.8372","22.1676","1.8372","1.2248","5.3493"
"7.5200","1.8575","22.4640","1.8575","1.2383","5.4209"
"7.6000","1.8774","22.7666","1.8774","1.2516","5.4939"
"7.6800","1.8967","23.0472","1.8967","1.2645","5.5616"
"7.7600","1.9174","23.3649","1.9174","1.2783","5.6382"
"7.8400","1.9372","23.6526","1.9372","1.2914","5.7077"
"7.9200","1.9566","23.9373","1.9566","1.3044","5.7764"
"8.0000","1.9780","24.2670","1.9780","1.3187","5.8559"
"8.0800","1.9978","24.5484","1.9978","1.3319","5.9238"
"8.1600","2.0178","24.8449","2.0178","1.3452","5.9954"
"8.2400","2.0376","25.1324","2.0376","1.3584","6.0648"
"8.3200","2.0563","25.4129","2.0563","1.3709","6.1325"
"8.4000","2.0772","25.7304","2.0772","1.3848","6.2091"
"8.4800","2.0968","26.0155","2.0968","1.3979","6.2779"
"8.5600","2.1173","26.3045","2.1173","1.4116","6.3476"
"8.6400","2.1377","26.6140","2.1377","1.4251","6.4223"
"8.7200","2.1575","26.9071","2.1575","1.4383","6.4930"
"8.8000","2.1775","27.2025","2.1775","1.4516","6.5643"
"8.8800","2.1975","27.5003","2.1975","1.4650","6.6362"
"8.9600","2.2165","27.7750","2.2165","1.4776","6.7025"
"9.0400","2.2371","28.0867","2.2371","1.4914","6.7777"
"9.1200","2.2564","28.3534","2.2564","1.5043","6.8420"
"9.2000","2.2779","28.6807","2.2779","1.5186","6.9210"
"9.2800","2.2985","28.9819","2.2985","1.5323","6.9937"
"9.3600","2.3178","29.2746","2.3178","1.5452","7.0643"
"9.4400","2.3376","29.5698","2.3376","1.5584","7.1356"
"9.5200","2.3567","29.8489","2.3567","1.5711","7.2029"
"9.6000","2.3764","30.1347","2.3764","1.5842","7.2719"
"9.6800","2.3973","30.4462","2.3973","1.5982","7.3470"
"9.7600","2.4162","30.7106","2.4162","1.6108","7.4109"
"9.8400","2.4370","31.0308","2.4370","1.6246","7.4881"
"9.9200","2.4578","31.3395","2.4578","1.6385","7.5626"
"10.0000","2.4776","31.6283","2.4776","1.6517","7.6323"
"10.0800","2.4976","31.9226","2.4976","1.6651","7.7033"
"10.1600","2.5164","32.1794","2.5164","1.6776","7.7653"
"10.2400","2.5369","32.4814","2.5369","1.6913","7.8382"
"10.3200","2.5572","32.7756","2.5572","1.7048","7.9092"
"10.4000","2.5767","33.0628","2.5767","1.7178","7.9785"
"10.4800","2.5980","33.3797","2.5980","1.7320","8.0550"
"10.5600","2.6185","33.6759","2.6185","1.7457","8.1264"
"10.6400","2.6376","33.9465","2.6376","1.7584","8.1917"
"10.7200","2.6574","34.2297","2.6574","1.7716","8.2601"
"10.8000","2.6765","34.5095","2.6765","1.7843","8.3276"
"10.8800","2.6977","34.8188","2.6977","1.7985","8.4022"
"10.9600","2.7172","35.0938","2.7172","1.8114","8.4686"
"11.0400","2.7363","35.3714","2.7363","1.8242","8.5356"
"11.1200","2.7567","35.6653","2.7567","1.8378","8.6065"
"11.2000","2.7776","35.9674","2.7776","1.8518","8.6794"
"11.2800","2.7981","36.2631","2.7981","1.8654","8.7508"
"11.3600","2.8179","36.5407","2.8179","1.8786","8.8177"
"11.4400","2.8360","36.8051","2.8360","1.8906","8.8815"
"11.5200","2.8568","37.1151","2.8568","1.9045","8.9564"
"11.6000","2.8770","37.4049","2.8770","1.9180","9.0263"
"11.6800","2.8978","37.7091","2.8978","1.9319","9.0997"
"11.7600","2.9184","37.9992","2.9184","1.9456","9.1697"
"11.8400","2.9375","38.2678","2.9375","1.9583","9.2345"
"11.9200","2.9577","38.5486","2.9577","1.9718","9.3023"
"12.0000","2.9773","38.8384","2.9773","1.9849","9.3722"
"12.0800","2.9968","39.1162","2.9968","1.9979","9.4392"
"12.1600","3.0169","39.4159","3.0169","2.0112","9.5116"
"12.2400","3.0360","39.6810","3.0360","2.0240","9.5755"
"12.3200","3.0568","39.9872","3.0568","2.0379","9.6494"
"12.4000","3.0784","40.3004","3.0784","2.0523","9.7250"
"12.4800","3.0973","40.5561","3.0973","2.0649","9.7867"
"12.5600","3.1176","40.8547","3.1176","2.0784","9.8588"
"12.6400","3.1367","41.1182","3.1367","2.0911","9.9223"
"12.7200","3.1568","41.4043","3.1568","2.1045","9.9914"
"12.8000","3.1772","41.6985","3.1772","2.1181","10.0624"
"12.8800","3.1968","41.9779","3.1968","2.1312","10.1298"
"12.9600","3.2174","42.2727","3.2174","2.1449","10.2009"
"13.0400","3.2386","42.5867","3.2386","2.1591","10.2767"
"13.1200","3.2576","42.8497","3.2576","2.1717","10.3402"
"13.2000","3.2774","43.1283","3.2774","2.1850","10.4074"
"13.2800","3.2968","43.3953","3.2968","2.1979","10.4718"
"13.3600","3.3175","43.6889","3.3175","2.2117","10.5427"
"13.4400","3.3372","43.9599","3.3372","2.2248","10.6081"
"13.5200","3.3558","44.2240","3.3558","2.2372","10.6718"
"13.6000","3.3768","44.5187","3.3768","2.2512","10.7429"
"13.6800","3.3981","44.8351","3.3981","2.2654","10.8193"
"13.7600","3.4178","45.1136","3.4178","2.2785","10.8865"
"13.8400","3.4377","45.3899","3.4377","2.2918","10.9532"
"13.9200","3.4564","45.6431","3.4564","2.3043","11.0143"
"14.0000","3.4770","45.9415","3.4770","2.3180","11.0863"
"14.0800","3.4974","46.2238","3.4974","2.3316","11.1544"
"14.1600","3.5168","46.5047","3.5168","2.3445","11.2222"
"14.2400","3.5378","46.8110","3.5378","2.3585","11.2961"
"14.3200","3.5573","47.0799","3.5573","2.3716","11.3610"
"14.4000","3.5781","47.3727","3.5781","2.3854","11.4316"
"14.4800","3.5979","47.6382","3.5979","2.3986","11.4957"
"14.5600","3.6169","47.9079","3.6169","2.4112","11.5608"
"14.6400","3.6365","48.1811","3.6365","2.4243","11.6267"
"14.7200","3.6562","48.4537","3.6562","2.4374","11.6925"
"14.8000","3.6761","48.7453","3.6761","2.4508","11.7629"
"14.8800","3.6983","49.0569","3.6983","2.4655","11.8381"
"14.9600","3.7175","49.3248","3.7175","2.4783","11.9027"
"15.0400","3.7375","49.5999","3.7375","2.4917","11.9691"
"15.1200","3.7571","49.8625","3.7571","2.5047","12.0325"
"15.2000","3.7767","50.1401","3.7767","2.5178","12.0994"
"15.2800","3.7971","50.4333","3.7971","2.5314","12.1702"
"15.3600","3.8167","50.7010","3.8167","2.5445","12.2348"
"15.4400","3.8376","50.9937","3.8376","2.5584","12.3054"
"15.5200","3.8583","51.2809","3.8583","2.5722","12.3747"
"15.6000","3.8770","51.5355","3.8770","2.5846","12.4362"
"15.6800","3.8979","51.8297","3.8979","2.5986","12.5072"
"15.7600","3.9175","52.0962","3.9175","2.6117","12.5715"
"15.8400","3.9368","52.3622","3.9368","2.6245","12.6357"
"15.9200","3.9571","52.6462","3.9571","2.6380","12.7042"
"16.0000","3.9763","52.9091","3.9763","2.6509","12.7676"
"16.0800","3.9975","53.2090","3.9975","2.6650","12.8400"
"16.1600","4.0180","53.4831","4.0180","2.6786","12.9062"
"16.2400","4.0373","53.7506","4.0373","2.6915","12.9707"
"16.3200","4.0572","54.0304","4.0572","2.7048","13.0382"
"16.4000","4.0769","54.2981","4.0769","2.7179","13.1028"
"16.4800","4.0971","54.5702","4.0971","2.7314","13.1685"
"16.5600","4.1177","54.8693","4.1177","2.7452","13.2407"
"16.6400","4.1365","55.1185","4.1365","2.7577","13.3008"
"16.7200","4.1573","55.4136","4.1573","2.7716","13.3720"
"16.8000","4.1778","55.6990","4.1778","2.7852","13.4409"
"16.8800","4.1982","55.9685","4.1982","2.7988","13.5059"
"16.9600","4.2173","56.2375","4.2173","2.8115","13.5708"
"17.0400","4.2367","56.4955","4.2367","2.8245","13.6331"
"17.1200","4.2569","56.7765","4.2569","2.8380","13.7009"
"17.2000","4.2773","57.0463","4.2773","2.8515","13.7660"
"17.2800","4.2958","57.3052","4.2958","2.8639","13.8285"
"17.3600","4.3175","57.6110","4.3175","2.8783","13.9023"
"17.4400","4.3374","57.8858","4.3374","2.8916","13.9686"
"17.5200","4.3577","58.1599","4.3577","2.9051","14.0347"
"17.6000","4.3774","58.4267","4.3774","2.9183","14.0991"
"17.6800","4.3967","58.6900","4.3967","2.9311","14.1626"
"17.7600","4.4173","58.9794","4.4173","2.9449","14.2325"
"17.8400","4.4371","59.2491","4.4371","2.9581","14.2976"
"17.9200","4.4568","59.5187","4.4568","2.9712","14.3626"
"18.0000","4.4777","59.8090","4.4777","2.9851","14.4327"
"18.0800","4.4975","60.0738","4.4975","2.9983","14.4966"
"18.1600","4.5182","60.3487","4.5182","3.0121","14.5629"
"18.2400","4.5376","60.6042","4.5376","3.0250","14.6246"
"18.3200","4.5556","60.8533","4.5556","3.0371","14.6847"
"18.4000","4.5771","61.1517","4.5771","3.0514","14.7567"
"18.4800","4.5966","61.4101","4.5966","3.0644","14.8190"
"18.5600","4.6175","61.6928","4.6175","3.0783","14.8873"
"18.6400","4.6376","61.9692","4.6376","3.0917","14.9540"
"18.7200","4.6570","62.2273","4.6570","3.1047","15.0162"
"18.8000","4.6773","62.5050","4.6773","3.1182","15.0832"
"18.8800","4.6977","62.7825","4.6977","3.1318","15.1502"
"18.9600","4.7167","63.0386","4.7167","3.1444","15.2120"
"19.0400","4.7372","63.3273","4.7372","3.1581","15.2817"
"19.1200","4.7564","63.5751","4.7564","3.1709","15.3415"
"19.2000","4.7777","63.8735","4.7777","3.1851","15.4135"
"19.2800","4.7985","64.1447","4.7985","3.1990","15.4789"
"19.3600","4.8179","64.4141","4.8179","3.2120","15.5439"
"19.4400","4.8370","64.6612","4.8370","3.2247","15.6036"
"19.5200","4.8569","64.9334","4.8569","3.2380","15.6693"
"19.6000","4.8770","65.2138","4.8770","3.2513","15.7369"
"19.6800","4.8975","65.4825","4.8975","3.2650","15.8018"
"19.7600","4.9161","65.7343","4.9161","3.2774","15.8625"
"19.8400","4.9372","66.0169","4.9372","3.2915","15.9307"
"19.9200","4.9580","66.3050","4.9580","3.3053","16.0002"
"20.0000","4.9773","66.5655","4.9773","3.3182","16.0631"
"20.0800","4.9974","66.8329","4.9974","3.3316","16.1276"
"20.1600","5.0166","67.0840","5.0166","3.3444","16.1882"
"20.2400","5.0372","67.3454","5.0372","3.3581","16.2513"
"20.3200","5.0573","67.6230","5.0573","3.3715","16.3183"
"20.4000","5.0767","67.8957","5.0767","3.3845","16.3841"
"20.4800","5.0981","68.1875","5.0981","3.3988","16.4545"
"20.5600","5.1181","68.4436","5.1181","3.4121","16.5163"
"20.6400","5.1376","68.7100","5.1376","3.4251","16.5806"
"20.7200","5.1575","68.9624","5.1575","3.4383","16.6415"
"20.8000","5.1763","69.2187","5.1763","3.4508","16.7034"
"20.8800","5.1974","69.5040","5.1974","3.4650","16.7722"
"20.9600","5.2173","69.7589","5.2173","3.4782","16.8337"
"21.0400","5.2361","70.0065","5.2361","3.4907","16.8935"
"21.1200","5.2559","70.2793","5.2559","3.5040","16.9593"
"21.2000","5.2775","70.5676","5.2775","3.5183","17.0289"
"21.2800","5.2981","70.8369","5.2981","3.5320","17.0938"
"21.3600","5.3179","71.0932","5.3179","3.5453","17.1557"
"21.4400","5.3361","71.3253","5.3361","3.5574","17.2117"
"21.5200","5.3568","71.6144","5.3568","3.5712","17.2815"
"21.6000","5.3769","71.8748","5.3769","3.5846","17.3443"
"21.6800","5.3977","72.1602","5.3977","3.5985","17.4132"
"21.7600","5.4186","72.4326","5.4186","3.6124","17.4789"
"21.8400","5.4375","72.6743","5.4375","3.6250","17.5372"
"21.9200","5.4572","72.9305","5.4572","3.6382","17.5991"
"22.0000","5.4772","73.1789","5.4772","3.6515","17.6590"
"22.0800","5.4970","73.4601","5.4970","3.6647","17.7269"
"22.1600","5.5174","73.7316","5.5174","3.6783","17.7924"
"22.2400","5.5360","73.9591","5.5360","3.6907","17.8473"
"22.3200","5.5568","74.2321","5.5568","3.7045","17.9131"
"22.4000","5.5783","74.5132","5.5783","3.7189","17.9810"
"22.4800","5.5973","74.7682","5.5973","3.7315","18.0425"
"22.5600","5.6175","75.0354","5.6175","3.7450","18.1070"
"22.6400","5.6366","75.2826","5.6366","3.7578","18.1666"
"22.7200","5.6569","75.5566","5.6569","3.7712","18.2328"
"22.8000","5.6773","75.8214","5.6773","3.7849","18.2967"
"22.8800","5.6970","76.0744","5.6970","3.7980","18.3577"
"22.9600","5.7175","76.3450","5.7175","3.8117","18.4230"
"23.0400","5.7383","76.6092","5.7383","3.8255","18.4868"
"23.1200","5.7573","76.8684","5.7573","3.8382","18.5493"
"23.2000","5.7781","77.1383","5.7781","3.8521","18.6145"
"23.2800","5.7969","77.3689","5.7969","3.8646","18.6701"
"23.3600","5.8169","77.6227","5.8169","3.8779","18.7313"
"23.4400","5.8367","77.8819","5.8367","3.8911","18.7939"
"23.5200","5.8561","78.1416","5.8561","3.9040","18.8566"
"23.6000","5.8774","78.4352","5.8774","3.9182","18.9274"
"23.6800","5.8982","78.6980","5.8982","3.9322","18.9908"
"23.7600","5.9176","78.9511","5.9176","3.9451","19.0519"
"23.8400","5.9374","79.2036","5.9374","3.9583","19.1128"
"23.9200","5.9565","79.4296","5.9565","3.9710","19.1674"
"24.0000","5.9770","79.7059","5.9770","3.9846","19.2341"
"24.0800","5.9974","79.9701","5.9974","3.9983","19.2978"
"24.1600","6.0169","80.2294","6.0169","4.0113","19.3604"
"24.2400","6.0379","80.5099","6.0379","4.0253","19.4281"
"24.3200","6.0576","80.7625","6.0576","4.0384","19.4890"
"24.4000","6.0782","81.0210","6.0782","4.0521","19.5514"
"24.4800","6.0978","81.2696","6.0978","4.0652","19.6114"
"24.5600","6.1171","81.5121","6.1171","4.0780","19.6699"
"24.6400","6.1367","81.7635","6.1367","4.0912","19.7306"
"24.7200","6.1564","82.0115","6.1564","4.1042","19.7904"
"24.8000","6.1762","82.2783","6.1762","4.1174","19.8548"
"24.8800","6.1981","82.5616","6.1981","4.1321","19.9232"
"24.9600","6.2171","82.8071","6.2171","4.1448","19.9824"
"25.0400","6.2378","83.0625","6.2378","4.1585","20.0440"
"25.1200","6.2571","83.3109","6.2571","4.1714","20.1040"
"25.2000","6.2766","83.5708","6.2766","4.1844","20.1667"
"25.2800","6.2970","83.8392","6.2970","4.1980","20.2315"
"25.3600","6.3169","84.0876","6.3169","4.2113","20.2914"
"25.4400","6.3377","84.3465","6.3377","4.2251","20.3539"
"25.5200","6.3582","84.6155","6.3582","4.2388","20.4188"
"25.6000","6.3774","84.8645","6.3774","4.2516","20.4789"
"25.6800","6.3979","85.1212","6.3979","4.2653","20.5408"
"25.7600","6.4174","85.3708","6.4174","4.2783","20.6011"
"25.8400","6.4368","85.6143","6.4368","4.2912","20.6598"
"25.9200","6.4571","85.8728","6.4571","4.3048","20.7222"
"26.0000","6.4758","86.1108","6.4758","4.3172","20.7796"
"26.0800","6.4977","86.3830","6.4977","4.3318","20.8453"
"26.1600","6.5183","86.6508","6.5183","4.3455","20.9099"
"26.2400","6.5371","86.8766","6.5371","4.3581","20.9644"
"26.3200","6.5570","87.1416","6.5570","4.3713","21.0284"
"26.4000","6.5770","87.3960","6.5770","4.3847","21.0898"
"26.4800","6.5974","87.6447","6.5974","4.3983","21.1498"
"26.5600","6.6180","87.9046","6.6180","4.4120","21.2125"
"26.6400","6.6362","88.1395","6.6362","4.4242","21.2692"
"26.7200","6.6575","88.4164","6.6575","4.4383","21.3360"
"26.8000","6.6779","88.6726","6.6779","4.4519","21.3978"
"26.8800","6.6978","88.9198","6.6978","4.4652","21.4575"
"26.9600","6.7174","89.1673","6.7174","4.4782","21.5172"
"27.0400","6.7367","89.4050","6.7367","4.4911","21.5746"
"27.1200","6.7567","89.6530","6.7567","4.5045","21.6344"
"27.2000","6.7772","89.9118","6.7772","4.5181","21.6969"
"27.2800","6.7964","90.1589","6.7964","4.5309","21.7565"
"27.3600","6.8174","90.4265","6.8174","4.5449","21.8211"
"27.4400","6.8371","90.6719","6.8371","4.5581","21.8803"
"27.5200","6.8577","90.9353","6.8577","4.5718","21.9438"
"27.6000","6.8775","91.1762","6.8775","4.5850","22.0020"
"27.6800","6.8965","91.4139","6.8965","4.5976","22.0593"
"27.7600","6.9170","91.6698","6.9170","4.6113","22.1211"
"27.8400","6.9372","91.9189","6.9372","4.6248","22.1812"
"27.9200","6.9569","92.1672","6.9569","4.6379","22.2411"
"28.0000","6.9779","92.4450","6.9779","4.6520","22.3082"
"28.0800","6.9978","92.6822","6.9978","4.6652","22.3654"
"28.1600","7.0178","92.9231","7.0178","4.6785","22.4235"
"28.2400","7.0376","93.1690","7.0376","4.6918","22.4829"
"28.3200","7.0563","93.4047","7.0563","4.7042","22.5397"
"28.4000","7.0768","93.6596","7.0768","4.7179","22.6013"
"28.4800","7.0967","93.9044","7.0967","4.7311","22.6603"
"28.5600","7.1176","94.1727","7.1176","4.7451","22.7251"
"28.6400","7.1380","94.4245","7.1380","4.7587","22.7858"
"28.7200","7.1571","94.6590","7.1571","4.7714","22.8424"
"28.8000","7.1774","94.9113","7.1774","4.7849","22.9033"
"28.8800","7.1978","95.1606","7.1978","4.7985","22.9635"
"28.9600","7.2169","95.3981","7.2169","4.8112","23.0208"
"29.0400","7.2374","95.6531","7.2374","4.8249","23.0823"
"29.1200","7.2561","95.8777","7.2561","4.8374","23.1365"
"29.2000","7.2777","96.1463","7.2777","4.8518","23.2013"
"29.2800","7.2986","96.4106","7.2986","4.8658","23.2651"
"29.3600","7.3179","96.6526","7.3179","4.8786","23.3235"
"29.4400","7.3370","96.8802","7.3370","4.8914","23.3784"
"29.5200","7.3569","97.1304","7.3569","4.9046","23.4388"
"29.6000","7.3764","97.3658","7.3764","4.9176","23.4956"
"29.6800","7.3975","97.6233","7.3975","4.9317","23.5577"
"29.7600","7.4164","97.8472","7.4164","4.9443","23.6118"
"29.8400","7.4371","98.1052","7.4371","4.9581","23.6740"
"29.9200","7.4578","98.3567","7.4578","4.9718","23.7347"
"30.0000","7.4776","98.6109","7.4776","4.9851","23.7961"
"30.0800","7.4977","98.8574","7.4977","4.9985","23.8555"
"30.1600","7.5164","99.0792","7.5164","5.0109","23.9091"
"30.2400","7.5372","99.3240","7.5372","5.0248","23.9681"
"30.3200","7.5571","99.5685","7.5571","5.0381","24.0271"
"30.4000","7.5767","99.8164","7.5767","5.0511","24.0870"
"30.4800","7.5981","100.0835","7.5981","5.0654","24.1514"
"30.5600","7.6181","100.3255","7.6181","5.0788","24.2098"
"30.6400","7.6377","100.5523","7.6377","5.0918","24.2645"
"30.7200","7.6576","100.7927","7.6576","5.1051","24.3226"
"30.8000","7.6762","101.0065","7.6762","5.1175","24.3742"
"30.8800","7.6975","101.2667","7.6975","5.1316","24.4370"
"30.9600","7.7173","101.5046","7.7173","5.1449","24.4944"
"31.0400","7.7367","101.7465","7.7367","5.1578","24.5527"
"31.1200","7.7572","102.0056","7.7572","5.1715","24.6153"
"31.2000","7.7777","102.2489","7.7777","5.1852","24.6740"
"31.2800","7.7977","102.4795","7.7977","5.1985","24.7296"
"31.3600","7.8177","102.7226","7.8177","5.2118","24.7883"
"31.4400","7.8362","102.9409","7.8362","5.2241","24.8410"
"31.5200","7.8567","103.1950","7.8567","5.2378","24.9023"
"31.6000","7.8768","103.4387","7.8768","5.2512","24.9611"
"31.6800","7.8977","103.7066","7.8977","5.2651","25.0257"
"31.7600","7.9190","103.9577","7.9190","5.2793","25.0863"
"31.8400","7.9376","104.1767","7.9376","5.2918","25.1392"
"31.9200","7.9573","104.4042","7.9573","5.3049","25.1941"
"32.0000","7.9771","104.6413","7.9771","5.3181","25.2513"
"32.0800","7.9968","104.8842","7.9968","5.3312","25.3099"
"32.1600","8.0171","105.1211","8.0171","5.3448","25.3670"
"32.2400","8.0361","105.3349","8.0361","5.3574","25.4187"
"32.3200","8.0569","105.5987","8.0569","5.3712","25.4823"
"32.4000","8.0783","105.8601","8.0783","5.3856","25.5454"
"32.4800","8.0973","106.0818","8.0973","5.3982","25.5989"
"32.5600","8.1179","106.3361","8.1179","5.4119","25.6603"
"32.6400","8.1364","106.5398","8.1364","5.4243","25.7094"
"32.7200","8.1565","106.7758","8.1565","5.4377","25.7664"
"32.8000","8.1771","107.0234","8.1771","5.4514","25.8261"
"32.8800","8.1969","107.2594","8.1969","5.4646","25.8831"
"32.9600","8.2174","107.5039","8.2174","5.4783","25.9421"
"33.0400","8.2384","107.7539","8.2384","5.4922","26.0024"
"33.1200","8.2575","107.9813","8.2575","5.5050","26.0573"
"33.2000","8.2776","108.2250","8.2776","5.5184","26.1161"
"33.2800","8.2969","108.4336","8.2969","5.5313","26.1664"
"33.3600","8.3175","108.6787","8.3175","5.5450","26.2256"
"33.4400","8.3368","108.9030","8.3368","5.5579","26.2797"
"33.5200","8.3555","109.1133","8.3555","5.5703","26.3304"
"33.6000","8.3770","109.3755","8.3770","5.5846","26.3937"
"33.6800","8.3982","109.6320","8.3982","5.5988","26.4556"
"33.7600","8.4180","109.8593","8.4180","5.6120","26.5105"
"33.8400","8.4375","110.0745","8.4375","5.6250","26.5624"
"33.9200","8.4562","110.2826","8.4562","5.6374","26.6126"
"34.0000","8.4770","110.5306","8.4770","5.6513","26.6724"
"34.0800","8.4972","110.7684","8.4972","5.6648","26.7298"
"34.1600","8.5169","110.9963","8.5169","5.6779","26.7848"
"34.2400","8.5379","111.2592","8.5379","5.6920","26.8483"
"34.3200","8.5576","111.4624","8.5576","5.7051","26.8973"
"34.4000","8.5781","111.7072","8.5781","5.7187","26.9564"
"34.4800","8.5977","111.9209","8.5977","5.7318","27.0079"
"34.5600","8.6165","112.1327","8.6165","5.7444","27.0590"
"34.6400","8.6367","112.3735","8.6367","5.7578","27.1171"
"34.7200","8.6566","112.6041","8.6566","5.7711","27.1728"
"34.8000","8.6764","112.8405","8.6764","5.7843","27.2298"
"34.8800","8.6980","113.0893","8.6980","5.7987","27.2899"
"34.9600","8.7172","113.3056","8.7172","5.8114","27.3421"
"35.0400","8.7379","113.5325","8.7379","5.8253","27.3968"
"35.1200","8.7572","113.7495","8.7572","5.8381","27.4492"
"35.2000","8.7766","113.9770","8.7766","5.8511","27.5041"
"35.2800","8.7970","114.2102","8.7970","5.8646","27.5604"
"35.3600","8.8171","114.4346","8.8171","5.8780","27.6145"
"35.4400","8.8373","114.6629","8.8373","5.8915","27.6696"
"35.5200","8.8583","114.9020","8.8583","5.9056","27.7273"
"35.6000","8.8773","115.1122","8.8773","5.9182","27.7780"
"35.6800","8.8979","115.3505","8.8979","5.9319","27.8355"
"35.7600","8.9173","115.5598","8.9173","5.9449","27.8861"
"35.8400","8.9362","115.7705","8.9362","5.9575","27.9369"
"35.9200","8.9567","116.0034","8.9567","5.9712","27.9931"
"36.0000","8.9760","116.2157","8.9760","5.9840","28.0443"
"36.0800","8.9978","116.4640","8.9978","5.9985","28.1043"
"36.1600","9.0183","116.7018","9.0183","6.0122","28.1616"
"36.2400","9.0373","116.9030","9.0373","6.0248","28.2102"
"36.3200","9.0568","117.1241","9.0568","6.0379","28.2635"
"36.4000","9.0768","117.3445","9.0768","6.0512","28.3167"
"36.4800","9.0972","117.5742","9.0972","6.0648","28.3721"
"36.5600","9.1177","117.7968","9.1177","6.0785","28.4259"
"36.6400","9.1365","118.0061","9.1365","6.0910","28.4764"
"36.7200","9.1578","118.2518","9.1578","6.1052","28.5357"
"36.8000","9.1780","118.4798","9.1780","6.1187","28.5907"
"36.8800","9.1980","118.6920","9.1980","6.1320","28.6419"
"36.9600","9.2174","118.9098","9.2174","6.1449","28.6945"
"37.0400","9.2367","119.1165","9.2367","6.1578","28.7443"
"37.1200","9.2567","119.3278","9.2567","6.1711","28.7953"
"37.2000","9.2773","119.5556","9.2773","6.1849","28.8503"
"37.2800","9.2962","119.7677","9.2962","6.1975","28.9015"
"37.3600","9.3175","120.0047","9.3175","6.2116","28.9587"
"37.4400","9.3372","120.2160","9.3372","6.2248","29.0096"
"37.5200","9.3580","120.4450","9.3580","6.2387","29.0649"
"37.6000","9.3775","120.6475","9.3775","6.2517","29.1138"
"37.6800","9.3966","120.8485","9.3966","6.2644","29.1623"
"37.7600","9.4170","121.0785","9.4170","6.2780","29.2178"
"37.8400","9.4369","121.2882","9.4369","6.2913","29.2684"
"37.9200","9.4568","121.5049","9.4568","6.3045","29.3207"
"38.0000","9.4778","121.7148","9.4778","6.3186","29.3713"
"38.0800","9.4977","121.9239","9.4977","6.3318","29.4218"
"38.1600","9.5178","122.1447","9.5178","6.3452","29.4751"
"38.2400","9.5371","122.3413","9.5371","6.3581","29.5225"
"38.3200","9.5564","122.5494","9.5564","6.3709","29.5727"
"38.4000","9.5774","122.7907","9.5774","6.3849","29.6310"
"38.4800","9.5963","122.9779","9.5963","6.3975","29.6761"
"38.5600","9.6174","123.2110","9.6174","6.4116","29.7324"
"38.6400","9.6373","123.4161","9.6373","6.4249","29.7819"
"38.7200","9.6574","123.6341","9.6574","6.4383","29.8345"
"38.8000","9.6774","123.8467","9.6774","6.4516","29.8858"
"38.8800","9.6978","124.0652","9.6978","6.4652","29.9385"
"38.9600","9.7168","124.2666","9.7168","6.4779","29.9871"
"39.0400","9.7376","124.4890","9.7376","6.4917","30.0408"
"39.1200","9.7562","124.6715","9.7562","6.5041","30.0848"
"39.2000","9.7779","124.9089","9.7779","6.5186","30.1421"
"39.2800","9.7986","125.1299","9.7986","6.5324","30.1954"
"39.3600","9.8180","125.3269","9.8180","6.5453","30.2430"
"39.4400","9.8370","125.5221","9.8370","6.5580","30.2901"
"39.5200","9.8570","125.7303","9.8570","6.5713","30.3403"
"39.6000","9.8765","125.9242","9.8765","6.5844","30.3871"
"39.6800","9.8976","126.1521","9.8976","6.5984","30.4421"
"39.7600","9.9163","126.3287","9.9163","6.6109","30.4847"
"39.8400","9.9369","126.5470","9.9369","6.6246","30.5374"
"39.9200","9.9578","126.7645","9.9578","6.6385","30.5899"
"40.0000","9.9776","126.9652","9.9776","6.6517","30.6383"
"40.0800","9.9976","127.1250","9.9976","6.6651","30.6769"
"40.1600","10.0164","127.3111","10.0164","6.6776","30.7218"
"40.2400","10.0374","127.5306","10.0374","6.6916","30.7748"
"40.3200","10.0571","127.7172","10.0571","6.7047","30.8198"
"40.4000","10.0768","127.9286","10.0768","6.7179","30.8708"
"40.4800","10.0979","128.1667","10.0979","6.7320","30.9283"
"40.5600","10.1185","128.3568","10.1185","6.7457","30.9741"
"40.6400","10.1377","128.5398","10.1377","6.7585","31.0183"
"40.7200","10.1573","128.7383","10.1573","6.7715","31.0662"
"40.8000","10.1761","128.9191","10.1761","6.7841","31.1098"
"40.8800","10.1971","129.1317","10.1971","6.7981","31.1611"
"40.9600","10.2168","129.3250","10.2168","6.8112","31.2078"
"41.0400","10.2367","129.5242","10.2367","6.8244","31.2558"
"41.1200","10.2570","129.7341","10.2570","6.8380","31.3065"
"41.2000","10.2775","129.9314","10.2775","6.8516","31.3541"
"41.2800","10.2980","130.1348","10.2980","6.8653","31.4032"
"41.3600","10.3179","130.3213","10.3179","6.8786","31.4482"
"41.4400","10.3362","130.4846","10.3362","6.8908","31.4876"
"41.5200","10.3568","130.6988","10.3568","6.9046","31.5393"
"41.6000","10.3769","130.8884","10.3769","6.9179","31.5850"
"41.6800","10.3979","131.0977","10.3979","6.9319","31.6356"
"41.7600","10.4186","131.2990","10.4186","6.9457","31.6841"
"41.8400","10.4377","131.4690","10.4377","6.9585","31.7251"
"41.9200","10.4575","131.6540","10.4575","6.9716","31.7698"
"42.0000","10.4773","131.8462","10.4773","6.9848","31.8162"
"42.0800","10.4972","132.0426","10.4972","6.9981","31.8636"
"42.1600","10.5168","132.2213","10.5168","7.0112","31.9067"
"42.2400","10.5360","132.3945","10.5360","7.0240","31.9485"
"42.3200","10.5566","132.5878","10.5566","7.0377","31.9951"
"42.4000","10.5784","132.8005","10.5784","7.0523","32.0465"
"42.4800","10.5976","132.9710","10.5976","7.0651","32.0876"
"42.5600","10.6178","133.1527","10.6178","7.0785","32.1314"
"42.6400","10.6365","133.3083","10.6365","7.0910","32.1690"
"42.7200","10.6570","133.4897","10.6570","7.1047","32.2128"
"42.8000","10.6773","133.6786","10.6773","7.1182","32.2584"
"42.8800","10.6969","133.8522","10.6969","7.1312","32.3002"
"42.9600","10.7175","134.0400","10.7175","7.1450","32.3456"
"43.0400","10.7384","134.2362","10.7384","7.1589","32.3929"
"43.1200","10.7572","134.3978","10.7572","7.1715","32.4319"
"43.2000","10.7776","134.5829","10.7776","7.1851","32.4766"
"43.2800","10.7971","134.7479","10.7971","7.1981","32.5164"
"43.3600","10.8180","134.9376","10.8180","7.2120","32.5622"
"43.4400","10.8367","135.0988","10.8367","7.2245","32.6011"
"43.5200","10.8554","135.2480","10.8554","7.2369","32.6371"
"43.6000","10.8768","135.4551","10.8768","7.2512","32.6870"
"43.6800","10.8974","135.6416","10.8974","7.2649","32.7321"
"43.7600","10.9180","135.8152","10.9180","7.2786","32.7739"
"43.8400","10.9381","135.9964","10.9381","7.2921","32.8177"
"43.9200","10.9568","136.1392","10.9568","7.3045","32.8521"
"44.0000","10.9769","136.3165","10.9769","7.3179","32.8949"
"44.0800","10.9974","136.4808","10.9974","7.3316","32.9346"
"44.1600","11.0171","136.6523","11.0171","7.3447","32.9759"
"44.2400","11.0377","136.8352","11.0377","7.3585","33.0201"
"44.3200","11.0572","136.9878","11.0572","7.3715","33.0569"
"44.4000","11.0781","137.1684","11.0781","7.3854","33.1005"
"44.4800","11.0978","137.3275","11.0978","7.3986","33.1389"
"44.5600","11.1166","137.4815","11.1166","7.4111","33.1760"
"44.6400","11.1370","137.6682","11.1370","7.4247","33.2211"
"44.7200","11.1568","137.8192","11.1568","7.4379","33.2575"
"44.8000","11.1762","137.9716","11.1762","7.4508","33.2943"
"44.8800","11.1981","138.1621","11.1981","7.4654","33.3403"
"44.9600","11.2173","138.3096","11.2173","7.4782","33.3759"
"45.0400","11.2378","138.4576","11.2378","7.4918","33.4116"
"45.1200","11.2568","138.6094","11.2568","7.5045","33.4482"
"45.2000","11.2768","138.7815","11.2768","7.5179","33.4897"
"45.2800","11.2973","138.9395","11.2973","7.5315","33.5279"
"45.3600","11.3168","139.0843","11.3168","7.5445","33.5628"
"45.4400","11.3372","139.2472","11.3372","7.5582","33.6021"
"45.5200","11.3584","139.4299","11.3584","7.5723","33.6462"
"45.6000","11.3772","139.5625","11.3772","7.5848","33.6782"
"45.6800","11.3979","139.7231","11.3979","7.5986","33.7170"
"45.7600","11.4175","139.8690","11.4175","7.6116","33.7522"
"45.8400","11.4369","140.0166","11.4369","7.6246","33.7878"
"45.9200","11.4564","140.1599","11.4564","7.6376","33.8224"
"46.0000","11.4756","140.2992","11.4756","7.6504","33.8560"
"46.0800","11.4978","140.4687","11.4978","7.6652","33.8969"
"46.1600","11.5182","140.6402","11.5182","7.6788","33.9383"
"46.2400","11.5375","140.7750","11.5375","7.6917","33.9708"
"46.3200","11.5571","140.9169","11.5571","7.7048","34.0050"
"46.4000","11.5769","141.0527","11.5769","7.7179","34.0378"
"46.4800","11.5973","141.2142","11.5973","7.7315","34.0768"
"46.5600","11.6179","141.3603","11.6179","7.7452","34.1120"
"46.6400","11.6364","141.4900","11.6364","7.7576","34.1433"
"46.7200","11.6582","141.6670","11.6582","7.7721","34.1861"
"46.8000","11.6778","141.7945","11.6778","7.7852","34.2168"
"46.8800","11.6977","141.9340","11.6977","7.7984","34.2505"
"46.9600","11.7172","142.0753","11.7172","7.8114","34.2846"
"47.0400","11.7368","142.2019","11.7368","7.8245","34.3151"
"47.1200","11.7568","142.3367","11.7568","7.8379","34.3477"
"47.2000","11.7774","142.4793","11.7774","7.8516","34.3821"
"47.2800","11.7963","142.6143","11.7963","7.8642","34.4146"
"47.3600","11.8175","142.7675","11.8175","7.8783","34.4516"
"47.4400","11.8371","142.8951","11.8371","7.8914","34.4824"
"47.5200","11.8577","143.0392","11.8577","7.9051","34.5172"
"47.6000","11.8774","143.1630","11.8774","7.9183","34.5471"
"47.6800","11.8967","143.2961","11.8967","7.9311","34.5792"
"47.7600","11.9173","143.4193","11.9173","7.9449","34.6089"
"47.8400","11.9369","143.5550","11.9369","7.9579","34.6416"
"47.9200","11.9569","143.6762","11.9569","7.9712","34.6709"
"48.0000","11.9781","143.8244","11.9781","7.9854","34.7066"
"48.0800","11.9979","143.9507","11.9979","7.9986","34.7371"
"48.1600","12.0177","144.0682","12.0177","8.0118","34.7655"
"48.2400","12.0377","144.1932","12.0377","8.0251","34.7957"
"48.3200","12.0562","144.3023","12.0562","8.0375","34.8220"
"48.4000","12.0771","144.4440","12.0771","8.0514","34.8562"
"48.4800","12.0963","144.5519","12.0963","8.0642","34.8822"
"48.5600","12.1175","144.6953","12.1175","8.0783","34.9168"
"48.6400","12.1378","144.8149","12.1378","8.0919","34.9457"
"48.7200","12.1575","144.9212","12.1575","8.1050","34.9713"
"48.8000","12.1774","145.0448","12.1774","8.1183","35.0012"
"48.8800","12.1974","145.1582","12.1974","8.1316","35.0285"
"48.9600","12.2160","145.2520","12.2160","8.1440","35.0512"
"49.0400","12.2373","145.3939","12.2373","8.1582","35.0854"
"49.1200","12.2564","145.4799","12.2564","8.1709","35.1062"
"49.2000","12.2781","145.6225","12.2781","8.1854","35.1406"
"49.2800","12.2985","145.7339","12.2985","8.1990","35.1675"
"49.3600","12.3180","145.8438","12.3180","8.2120","35.1940"
"49.4400","12.3371","145.9411","12.3371","8.2247","35.2174"
"49.5200","12.3569","146.0350","12.3569","8.2379","35.2401"
"49.6000","12.3769","146.1504","12.3769","8.2513","35.2680"
"49.6800","12.3975","146.2629","12.3975","8.2650","35.2951"
"49.7600","12.4163","146.3576","12.4163","8.2775","35.3180"
"49.8400","12.4369","146.4642","12.4369","8.2912","35.3437"
"49.9200","12.4579","146.5833","12.4579","8.3052","35.3724"
"50.0000","12.4777","146.6831","12.4777","8.3185","35.3965"
"50.0800","12.4975","146.7867","12.4975","8.3317","35.4215"
"50.1600","12.5164","146.8622","12.5164","8.3443","35.4397"
"50.2400","12.5371","146.9678","12.5371","8.3581","35.4652"
"50.3200","12.5572","147.0614","12.5572","8.3714","35.4878"
"50.4000","12.5772","147.1740","12.5772","8.3848","35.5150"
"50.4800","12.5980","147.2858","12.5980","8.3986","35.5419"
"50.5600","12.6183","147.3763","12.6183","8.4122","35.5638"
"50.6400","12.6377","147.4445","12.6377","8.4251","35.5802"
"50.7200","12.6575","147.5410","12.6575","8.4384","35.6035"
"50.8000","12.6760","147.6088","12.6760","8.4507","35.6199"
"50.8800","12.6975","147.7253","12.6975","8.4650","35.6480"
"50.9600","12.7166","147.7979","12.7166","8.4777","35.6655"
"51.0400","12.7366","147.8973","12.7366","8.4911","35.6895"
"51.1200","12.7573","148.0104","12.7573","8.5049","35.7168"
"51.2000","12.7775","148.0932","12.7775","8.5183","35.7368"
"51.2800","12.7979","148.1790","12.7979","8.5319","35.7575"
"51.3600","12.8180","148.2664","12.8180","8.5453","35.7786"
"51.4400","12.8360","148.3360","12.8360","8.5573","35.7954"
"51.5200","12.8565","148.4332","12.8565","8.5710","35.8188"
"51.6000","12.8765","148.5182","12.8765","8.5844","35.8393"
"51.6800","12.8980","148.6197","12.8980","8.5987","35.8638"
"51.7600","12.9189","148.7175","12.9189","8.6126","35.8874"
"51.8400","12.9376","148.7860","12.9376","8.6251","35.9040"
"51.9200","12.9575","148.8577","12.9575","8.6383","35.9213"
"52.0000","12.9772","148.9371","12.9772","8.6515","35.9404"
"52.0800","12.9969","149.0268","12.9969","8.6646","35.9621"
"52.1600","13.0173","149.1206","13.0173","8.6782","35.9847"
"52.2400","13.0365","149.1854","13.0365","8.6910","36.0003"
"52.3200","13.0567","149.2686","13.0567","8.7045","36.0204"
"52.4000","13.0784","149.3720","13.0784","8.7189","36.0454"
"52.4800","13.0978","149.4397","13.0978","8.7319","36.0617"
"52.5600","13.1178","149.5124","13.1178","8.7452","36.0792"
"52.6400","13.1365","149.5749","13.1365","8.7576","36.0943"
"52.7200","13.1568","149.6484","13.1568","8.7712","36.1121"
"52.8000","13.1770","149.7405","13.1770","8.7847","36.1343"
"52.8800","13.1970","149.8074","13.1970","8.7980","36.1504"
"52.9600","13.2174","149.8816","13.2174","8.8116","36.1683"
"53.0400","13.2381","149.9640","13.2381","8.8254","36.1882"
"53.1200","13.2574","150.0334","13.2574","8.8382","36.2050"
"53.2000","13.2777","150.1081","13.2777","8.8518","36.2230"
"53.2800","13.2972","150.1716","13.2972","8.8648","36.2383"
"53.3600","13.3173","150.2295","13.3173","8.8782","36.2523"
"53.4400","13.3369","150.2932","13.3369","8.8913","36.2677"
"53.5200","13.3557","150.3490","13.3557","8.9038","36.2811"
"53.6000","13.3769","150.4366","13.3769","8.9179","36.3023"
"53.6800","13.3980","150.5174","13.3980","8.9320","36.3218"
"53.7600","13.4177","150.5785","13.4177","8.9451","36.3365"
"53.8400","13.4377","150.6383","13.4377","8.9584","36.3509"
"53.9200","13.4564","150.6879","13.4564","8.9709","36.3629"
"54.0000","13.4772","150.7509","13.4772","8.9848","36.3781"
"54.0800","13.4973","150.8171","13.4973","8.9982","36.3941"
"54.1600","13.5168","150.8734","13.5168","9.0112","36.4077"
"54.2400","13.5380","150.9538","13.5380","9.0253","36.4271"
"54.3200","13.5574","151.0096","13.5574","9.0382","36.4405"
"54.4000","13.5779","151.0614","13.5779","9.0519","36.4531"
"54.4800","13.5979","151.1182","13.5979","9.0653","36.4668"
"54.5600","13.6168","151.1718","13.6168","9.0779","36.4797"
"54.6400","13.6369","151.2248","13.6369","9.0913","36.4925"
"54.7200","13.6565","151.2771","13.6565","9.1043","36.5051"
"54.8000","13.6762","151.3443","13.6762","9.1175","36.5213"
"54.8800","13.6982","151.4179","13.6982","9.1321","36.5391"
"54.9600","13.7174","151.4604","13.7174","9.1449","36.5493"
"55.0400","13.7378","151.5080","13.7378","9.1585","36.5608"
"55.1200","13.7572","151.5599","13.7572","9.1715","36.5733"
"55.2000","13.7766","151.6118","13.7766","9.1844","36.5859"
"55.2800","13.7969","151.6697","13.7969","9.1980","36.5998"
"55.3600","13.8169","151.7255","13.8169","9.2113","36.6133"
"55.4400","13.8373","151.7760","13.8373","9.2249","36.6255"
"55.5200","13.8583","151.8310","13.8583","9.2389","36.6388"
"55.6000","13.8772","151.8804","13.8772","9.2515","36.6507"
"55.6800","13.8981","151.9384","13.8981","9.2654","36.6647"
"55.7600","13.9173","151.9755","13.9173","9.2782","36.6736"
"55.8400","13.9366","152.0278","13.9366","9.2911","36.6862"
"55.9200","13.9569","152.0870","13.9569","9.3046","36.7005"
"56.0000","13.9761","152.1225","13.9761","9.3174","36.7091"
"56.0800","13.9977","152.1809","13.9977","9.3318","36.7232"
"56.1600","14.0182","152.2326","14.0182","9.3455","36.7357"
"56.2400","14.0375","152.2715","14.0375","9.3583","36.7451"
"56.3200","14.0570","152.3057","14.0570","9.3713","36.7533"
"56.4000","14.0766","152.3501","14.0766","9.3844","36.7640"
"56.4800","14.0974","152.4030","14.0974","9.3983","36.7768"
"56.5600","14.1179","152.4538","14.1179","9.4120","36.7890"
"56.6400","14.1363","152.4902","14.1363","9.4242","36.7978"
"56.7200","14.1576","152.5520","14.1576","9.4384","36.8127"
"56.8000","14.1780","152.5993","14.1780","9.4520","36.8241"
"56.8800","14.1984","152.6529","14.1984","9.4656","36.8371"
"56.9600","14.2173","152.6812","14.2173","9.4782","36.8439"
"57.0400","14.2366","152.7152","14.2366","9.4911","36.8521"
"57.1200","14.2570","152.7603","14.2570","9.5047","36.8630"
"57.2000","14.2770","152.7918","14.2770","9.5180","36.8706"
"57.2800","14.2960","152.8438","14.2960","9.5306","36.8831"
"57.3600","14.3176","152.9126","14.3176","9.5450","36.8998"
"57.4400","14.3374","152.9399","14.3374","9.5582","36.9064"
"57.5200","14.3579","152.9903","14.3579","9.5719","36.9185"
"57.6000","14.3776","153.0133","14.3776","9.5851","36.9241"
"57.6800","14.3965","153.0508","14.3965","9.5977","36.9331"
"57.7600","14.4171","153.0900","14.4171","9.6114","36.9426"
"57.8400","14.4371","153.1270","14.4371","9.6247","36.9515"
"57.9200","14.4571","153.1745","14.4571","9.6380","36.9630"
"58.0000","14.4778","153.2312","14.4778","9.6519","36.9766"
"58.0800","14.4977","153.2514","14.4977","9.6651","36.9815"
"58.1600","14.5175","153.2840","14.5175","9.6784","36.9894"
"58.2400","14.5375","153.3115","14.5375","9.6916","36.9960"
"58.3200","14.5565","153.3577","14.5565","9.7043","37.0072"
"58.4000","14.5770","153.3943","14.5770","9.7180","37.0160"
"58.4800","14.5963","153.4204","14.5963","9.7309","37.0223"
"58.5600","14.6170","153.4667","14.6170","9.7447","37.0335"
"58.6400","14.6377","153.5175","14.6377","9.7585","37.0457"
"58.7200","14.6574","153.5471","14.6574","9.7716","37.0529"
"58.8000","14.6773","153.5827","14.6773","9.7849","37.0615"
"58.8800","14.6972","153.6130","14.6972","9.7982","37.0688"
"58.9600","14.7169","153.6566","14.7169","9.8113","37.0793"
"59.0400","14.7373","153.6912","14.7373","9.8249","37.0876"
"59.1200","14.7564","153.7102","14.7564","9.8376","37.0922"
"59.2000","14.7776","153.7490","14.7776","9.8517","37.1016"
"59.2800","14.7986","153.7934","14.7986","9.8657","37.1123"
"59.3600","14.8182","153.8284","14.8182","9.8788","37.1208"
"59.4400","14.8371","153.8431","14.8371","9.8914","37.1243"
"59.5200","14.8567","153.8751","14.8567","9.9045","37.1320"
"59.6000","14.8767","153.9015","14.8767","9.9178","37.1384"
"59.6800","14.8976","153.9444","14.8976","9.9317","37.1487"
"59.7600","14.9164","153.9518","14.9164","9.9442","37.1505"
"59.8400","14.9373","153.9998","14.9373","9.9582","37.1621"
"59.9200","14.9577","154.0275","14.9577","9.9718","37.1688"
"60.0000","14.9771","154.0489","14.9771","9.9847","37.1740"
"60.0800","14.9977","154.0759","14.9977","9.9985","37.1805"
"60.0890","15.0001","154.0796","15.0001","10.0000","37.1814"