File: data/instron_tests/metamaterials/250331/250331_2046_BULK_m1.is_comp_Exports/250331_2046_BULK_m1_6_1.csv
Results Table 1
,Compresson Axis,H*,V*,Height,Thickness,Width,Area,Fixture separation,Specimen label
,,,,(mm),(mm),(mm),(mm^2),(mm),
"6","X","","","150.00","28.00","150.00","4200.00","150.00","2046_BULK_m1"

Results Table 2
,Modulus (Segment 0 % - 5 %),Compresson Axis
,(kPa),
"6","1950.92","X"

Time,Displacement,Force,Compressive displacement,Compressive strain (Displacement),Compressive stress
(s),(mm),(N),(mm),(%),(kPa)
"0.0000","0.0000","0.1472","0.0000","0.0000","0.0350"
"0.0800","0.0012","0.2447","0.0012","0.0008","0.0583"
"0.1600","0.0176","1.4934","0.0176","0.0117","0.3556"
"0.2400","0.0377","2.8949","0.0377","0.0252","0.6893"
"0.3200","0.0574","4.2166","0.0574","0.0383","1.0040"
"0.4000","0.0769","5.5182","0.0769","0.0513","1.3138"
"0.4800","0.0982","6.9100","0.0982","0.0655","1.6452"
"0.5600","0.1179","8.1529","0.1179","0.0786","1.9412"
"0.6400","0.1375","9.3976","0.1375","0.0917","2.2375"
"0.7200","0.1574","10.6401","0.1574","0.1049","2.5334"
"0.8000","0.1769","11.8451","0.1769","0.1179","2.8203"
"0.8800","0.1975","13.1197","0.1975","0.1316","3.1237"
"0.9600","0.2169","14.2970","0.2169","0.1446","3.4041"
"1.0400","0.2360","15.4676","0.2360","0.1573","3.6828"
"1.1200","0.2571","16.7715","0.2571","0.1714","3.9932"
"1.2000","0.2774","17.9933","0.2774","0.1850","4.2841"
"1.2800","0.2977","19.1846","0.2977","0.1984","4.5678"
"1.3600","0.3172","20.3411","0.3172","0.2115","4.8431"
"1.4400","0.3362","21.4490","0.3362","0.2241","5.1069"
"1.5200","0.3565","22.6508","0.3565","0.2377","5.3931"
"1.6000","0.3769","23.8597","0.3769","0.2513","5.6809"
"1.6800","0.3977","25.1096","0.3977","0.2652","5.9785"
"1.7600","0.4183","26.3142","0.4183","0.2789","6.2653"
"1.8400","0.4373","27.4016","0.4373","0.2915","6.5242"
"1.9200","0.4575","28.5849","0.4575","0.3050","6.8059"
"2.0000","0.4777","29.7486","0.4777","0.3185","7.0830"
"2.0800","0.4968","30.8559","0.4968","0.3312","7.3466"
"2.1600","0.5168","32.0246","0.5168","0.3445","7.6249"
"2.2400","0.5360","33.1009","0.5360","0.3574","7.8812"
"2.3200","0.5570","34.3468","0.5570","0.3713","8.1778"
"2.4000","0.5782","35.5934","0.5782","0.3855","8.4746"
"2.4800","0.5976","36.6959","0.5976","0.3984","8.7371"
"2.5600","0.6175","37.8350","0.6175","0.4116","9.0083"
"2.6400","0.6366","38.9262","0.6366","0.4244","9.2682"
"2.7200","0.6562","40.0693","0.6562","0.4375","9.5403"
"2.8000","0.6768","41.2726","0.6768","0.4512","9.8268"
"2.8800","0.6968","42.4144","0.6968","0.4645","10.0987"
"2.9600","0.7176","43.6232","0.7176","0.4784","10.3865"
"3.0400","0.7381","44.7997","0.7381","0.4920","10.6666"
"3.1200","0.7573","45.9039","0.7573","0.5049","10.9295"
"3.2000","0.7774","47.0737","0.7774","0.5183","11.2080"
"3.2800","0.7967","48.1601","0.7967","0.5312","11.4667"
"3.3600","0.8174","49.3859","0.8174","0.5449","11.7585"
"3.4400","0.8371","50.4962","0.8371","0.5581","12.0229"
"3.5200","0.8559","51.5885","0.8559","0.5706","12.2830"
"3.6000","0.8775","52.8606","0.8775","0.5850","12.5859"
"3.6800","0.8977","54.0309","0.8977","0.5984","12.8645"
"3.7600","0.9173","55.1556","0.9173","0.6115","13.1323"
"3.8400","0.9370","56.2995","0.9370","0.6247","13.4046"
"3.9200","0.9561","57.3682","0.9561","0.6374","13.6591"
"4.0000","0.9767","58.5846","0.9767","0.6512","13.9487"
"4.0800","0.9971","59.7618","0.9971","0.6648","14.2290"
"4.1600","1.0170","60.9217","1.0170","0.6780","14.5052"
"4.2400","1.0379","62.1496","1.0379","0.6919","14.7975"
"4.3200","1.0576","63.2651","1.0576","0.7051","15.0631"
"4.4000","1.0780","64.4501","1.0780","0.7187","15.3453"
"4.4800","1.0978","65.5835","1.0978","0.7319","15.6151"
"4.5600","1.1166","66.6444","1.1166","0.7444","15.8677"
"4.6400","1.1368","67.8276","1.1368","0.7578","16.1494"
"4.7200","1.1565","68.9463","1.1565","0.7710","16.4158"
"4.8000","1.1765","70.1311","1.1765","0.7843","16.6979"
"4.8800","1.1981","71.4014","1.1981","0.7987","17.0003"
"4.9600","1.2174","72.4987","1.2174","0.8116","17.2616"
"5.0400","1.2376","73.6680","1.2376","0.8250","17.5400"
"5.1200","1.2567","74.7763","1.2567","0.8378","17.8039"
"5.2000","1.2763","75.9217","1.2763","0.8508","18.0766"
"5.2800","1.2969","77.1405","1.2969","0.8646","18.3668"
"5.3600","1.3168","78.2807","1.3168","0.8778","18.6383"
"5.4400","1.3373","79.5075","1.3373","0.8916","18.9304"
"5.5200","1.3584","80.7540","1.3584","0.9056","19.2271"
"5.6000","1.3773","81.8313","1.3773","0.9182","19.4836"
"5.6800","1.3978","83.0326","1.3978","0.9318","19.7697"
"5.7600","1.4175","84.1719","1.4175","0.9450","20.0409"
"5.8400","1.4368","85.2994","1.4368","0.9579","20.3094"
"5.9200","1.4569","86.4614","1.4569","0.9712","20.5860"
"6.0000","1.4760","87.5759","1.4760","0.9840","20.8514"
"6.0800","1.4974","88.8560","1.4974","0.9983","21.1562"
"6.1600","1.5180","90.0712","1.5180","1.0120","21.4455"
"6.2400","1.5374","91.1954","1.5374","1.0250","21.7132"
"6.3200","1.5570","92.3345","1.5570","1.0380","21.9844"
"6.4000","1.5760","93.4099","1.5760","1.0507","22.2404"
"6.4800","1.5968","94.6670","1.5968","1.0645","22.5398"
"6.5600","1.6180","95.9148","1.6180","1.0787","22.8369"
"6.6400","1.6363","96.9524","1.6363","1.0909","23.0839"
"6.7200","1.6576","98.2169","1.6576","1.1050","23.3850"
"6.8000","1.6778","99.4035","1.6778","1.1185","23.6675"
"6.8800","1.6982","100.5711","1.6982","1.1321","23.9455"
"6.9600","1.7175","101.6860","1.7175","1.1450","24.2110"
"7.0400","1.7370","102.8017","1.7370","1.1580","24.4766"
"7.1200","1.7566","103.9570","1.7566","1.1711","24.7517"
"7.2000","1.7770","105.1591","1.7770","1.1847","25.0379"
"7.2800","1.7960","106.2591","1.7960","1.1973","25.2998"
"7.3600","1.8173","107.5509","1.8173","1.2116","25.6074"
"7.4400","1.8373","108.7132","1.8373","1.2249","25.8841"
"7.5200","1.8578","109.9134","1.8578","1.2385","26.1699"
"7.6000","1.8771","111.0276","1.8771","1.2514","26.4352"
"7.6800","1.8964","112.1501","1.8964","1.2643","26.7024"
"7.7600","1.9171","113.3719","1.9171","1.2781","26.9933"
"7.8400","1.9370","114.5376","1.9370","1.2913","27.2708"
"7.9200","1.9565","115.6842","1.9565","1.3043","27.5438"
"8.0000","1.9781","116.9790","1.9781","1.3187","27.8522"
"8.0800","1.9982","118.1339","1.9982","1.3321","28.1271"
"8.1600","2.0182","119.2950","2.0182","1.3454","28.4036"
"8.2400","2.0376","120.4143","2.0376","1.3584","28.6701"
"8.3200","2.0563","121.5156","2.0563","1.3709","28.9323"
"8.4000","2.0772","122.7440","2.0772","1.3848","29.2248"
"8.4800","2.0964","123.8608","2.0964","1.3976","29.4907"
"8.5600","2.1172","125.1089","2.1172","1.4115","29.7878"
"8.6400","2.1377","126.3119","2.1377","1.4251","30.0743"
"8.7200","2.1571","127.4262","2.1571","1.4381","30.3396"
"8.8000","2.1767","128.5692","2.1767","1.4511","30.6117"
"8.8800","2.1976","129.8093","2.1976","1.4651","30.9070"
"8.9600","2.2168","130.9300","2.2168","1.4779","31.1738"
"9.0400","2.2373","132.1304","2.2373","1.4915","31.4596"
"9.1200","2.2561","133.2077","2.2561","1.5041","31.7161"
"9.2000","2.2777","134.5153","2.2777","1.5184","32.0275"
"9.2800","2.2982","135.7178","2.2982","1.5321","32.3138"
"9.3600","2.3180","136.8690","2.3180","1.5453","32.5879"
"9.4400","2.3374","137.9884","2.3374","1.5583","32.8544"
"9.5200","2.3568","139.1119","2.3568","1.5712","33.1219"
"9.6000","2.3766","140.2834","2.3766","1.5844","33.4008"
"9.6800","2.3973","141.5038","2.3973","1.5982","33.6914"
"9.7600","2.4164","142.5959","2.4164","1.6109","33.9514"
"9.8400","2.4371","143.8190","2.4371","1.6247","34.2426"
"9.9200","2.4575","145.0056","2.4575","1.6383","34.5251"
"10.0000","2.4774","146.1825","2.4774","1.6516","34.8054"
"10.0800","2.4976","147.3489","2.4976","1.6651","35.0831"
"10.1600","2.5168","148.4960","2.5168","1.6779","35.3562"
"10.2400","2.5371","149.6805","2.5371","1.6914","35.6382"
"10.3200","2.5571","150.8505","2.5571","1.7047","35.9168"
"10.4000","2.5765","151.9741","2.5765","1.7177","36.1843"
"10.4800","2.5975","153.2222","2.5975","1.7317","36.4815"
"10.5600","2.6178","154.3817","2.6178","1.7452","36.7576"
"10.6400","2.6377","155.5507","2.6377","1.7585","37.0359"
"10.7200","2.6578","156.7176","2.6578","1.7719","37.3137"
"10.8000","2.6764","157.7670","2.6764","1.7843","37.5636"
"10.8800","2.6973","159.0079","2.6973","1.7982","37.8590"
"10.9600","2.7169","160.1233","2.7169","1.8113","38.1246"
"11.0400","2.7364","161.2590","2.7364","1.8243","38.3950"
"11.1200","2.7568","162.4548","2.7568","1.8379","38.6797"
"11.2000","2.7772","163.6281","2.7772","1.8515","38.9591"
"11.2800","2.7978","164.8331","2.7978","1.8652","39.2460"
"11.3600","2.8178","165.9755","2.8178","1.8785","39.5180"
"11.4400","2.8359","166.9864","2.8359","1.8906","39.7587"
"11.5200","2.8564","168.1812","2.8564","1.9043","40.0431"
"11.6000","2.8768","169.3529","2.8768","1.9179","40.3221"
"11.6800","2.8973","170.5516","2.8973","1.9315","40.6075"
"11.7600","2.9182","171.7634","2.9182","1.9455","40.8960"
"11.8400","2.9375","172.8487","2.9375","1.9583","41.1544"
"11.9200","2.9574","173.9806","2.9574","1.9716","41.4240"
"12.0000","2.9773","175.1471","2.9773","1.9849","41.7017"
"12.0800","2.9971","176.2834","2.9971","1.9981","41.9722"
"12.1600","3.0168","177.4075","3.0168","2.0112","42.2399"
"12.2400","3.0360","178.4954","3.0360","2.0240","42.4989"
"12.3200","3.0569","179.7353","3.0569","2.0380","42.7941"
"12.4000","3.0783","180.9837","3.0783","2.0522","43.0913"
"12.4800","3.0976","182.0675","3.0976","2.0650","43.3494"
"12.5600","3.1175","183.2025","3.1175","2.0783","43.6197"
"12.6400","3.1363","184.2491","3.1363","2.0909","43.8688"
"12.7200","3.1567","185.4396","3.1567","2.1045","44.1523"
"12.8000","3.1770","186.6142","3.1770","2.1180","44.4319"
"12.8800","3.1968","187.7422","3.1968","2.1312","44.7005"
"12.9600","3.2176","188.9324","3.2176","2.1450","44.9839"
"13.0400","3.2384","190.1423","3.2384","2.1589","45.2720"
"13.1200","3.2572","191.2052","3.2572","2.1715","45.5251"
"13.2000","3.2776","192.3835","3.2776","2.1851","45.8056"
"13.2800","3.2969","193.4481","3.2969","2.1980","46.0591"
"13.3600","3.3174","194.6326","3.3174","2.2116","46.3411"
"13.4400","3.3372","195.7481","3.3372","2.2248","46.6067"
"13.5200","3.3561","196.7986","3.3561","2.2374","46.8568"
"13.6000","3.3771","198.0254","3.3771","2.2514","47.1489"
"13.6800","3.3978","199.1995","3.3978","2.2652","47.4285"
"13.7600","3.4175","200.3247","3.4175","2.2784","47.6964"
"13.8400","3.4375","201.4400","3.4375","2.2916","47.9619"
"13.9200","3.4559","202.4404","3.4559","2.3039","48.2001"
"14.0000","3.4770","203.6797","3.4770","2.3180","48.4952"
"14.0800","3.4974","204.8186","3.4974","2.3316","48.7663"
"14.1600","3.5169","205.9233","3.5169","2.3446","49.0294"
"14.2400","3.5376","207.1041","3.5376","2.3584","49.3105"
"14.3200","3.5571","208.1804","3.5571","2.3714","49.5668"
"14.4000","3.5780","209.3818","3.5780","2.3853","49.8528"
"14.4800","3.5976","210.4793","3.5976","2.3984","50.1141"
"14.5600","3.6166","211.5132","3.6166","2.4111","50.3603"
"14.6400","3.6365","212.6441","3.6365","2.4243","50.6296"
"14.7200","3.6564","213.7625","3.6564","2.4376","50.8958"
"14.8000","3.6763","214.8961","3.6763","2.4509","51.1657"
"14.8800","3.6980","216.1502","3.6980","2.4653","51.4643"
"14.9600","3.7173","217.1975","3.7173","2.4782","51.7137"
"15.0400","3.7374","218.3255","3.7374","2.4916","51.9823"
"15.1200","3.7569","219.4049","3.7569","2.5046","52.2393"
"15.2000","3.7764","220.4884","3.7764","2.5176","52.4972"
"15.2800","3.7967","221.6345","3.7967","2.5311","52.7701"
"15.3600","3.8165","222.7216","3.8165","2.5443","53.0290"
"15.4400","3.8374","223.9139","3.8374","2.5583","53.3128"
"15.5200","3.8583","225.0871","3.8583","2.5722","53.5922"
"15.6000","3.8772","226.0891","3.8772","2.5848","53.8307"
"15.6800","3.8976","227.2389","3.8976","2.5984","54.1045"
"15.7600","3.9175","228.3450","3.9175","2.6117","54.3678"
"15.8400","3.9370","229.4216","3.9370","2.6247","54.6242"
"15.9200","3.9568","230.5002","3.9568","2.6379","54.8810"
"16.0000","3.9759","231.5456","3.9759","2.6506","55.1299"
"16.0800","3.9974","232.7701","3.9974","2.6649","55.4215"
"16.1600","4.0180","233.9188","4.0180","2.6787","55.6949"
"16.2400","4.0374","234.9492","4.0374","2.6916","55.9403"
"16.3200","4.0571","236.0357","4.0571","2.7047","56.1990"
"16.4000","4.0769","237.1015","4.0769","2.7179","56.4527"
"16.4800","4.0971","238.2435","4.0971","2.7314","56.7246"
"16.5600","4.1177","239.3629","4.1177","2.7451","56.9912"
"16.6400","4.1357","240.3137","4.1357","2.7571","57.2175"
"16.7200","4.1576","241.5594","4.1576","2.7717","57.5141"
"16.8000","4.1778","242.6693","4.1778","2.7852","57.7784"
"16.8800","4.1981","243.7670","4.1981","2.7987","58.0398"
"16.9600","4.2174","244.8059","4.2174","2.8116","58.2871"
"17.0400","4.2368","245.8503","4.2368","2.8245","58.5358"
"17.1200","4.2567","246.9420","4.2567","2.8378","58.7957"
"17.2000","4.2772","248.0574","4.2772","2.8514","59.0613"
"17.2800","4.2961","249.0792","4.2961","2.8641","59.3046"
"17.3600","4.3175","250.2870","4.3175","2.8783","59.5921"
"17.4400","4.3370","251.3101","4.3370","2.8913","59.8357"
"17.5200","4.3575","252.4306","4.3575","2.9050","60.1025"
"17.6000","4.3771","253.4820","4.3771","2.9181","60.3529"
"17.6800","4.3964","254.5083","4.3964","2.9309","60.5972"
"17.7600","4.4168","255.6105","4.4168","2.9446","60.8596"
"17.8400","4.4370","256.7167","4.4370","2.9580","61.1230"
"17.9200","4.4566","257.7644","4.4566","2.9711","61.3725"
"18.0000","4.4776","258.9291","4.4776","2.9851","61.6498"
"18.0800","4.4979","259.9992","4.4979","2.9986","61.9046"
"18.1600","4.5181","261.0979","4.5181","3.0120","62.1662"
"18.2400","4.5378","262.1407","4.5378","3.0252","62.4144"
"18.3200","4.5562","263.0964","4.5562","3.0375","62.6420"
"18.4000","4.5769","264.2330","4.5769","3.0513","62.9126"
"18.4800","4.5961","265.2264","4.5961","3.0641","63.1491"
"18.5600","4.6175","266.4188","4.6175","3.0783","63.4330"
"18.6400","4.6378","267.5087","4.6378","3.0918","63.6925"
"18.7200","4.6573","268.5197","4.6573","3.1049","63.9333"
"18.8000","4.6769","269.5560","4.6769","3.1180","64.1800"
"18.8800","4.6970","270.6238","4.6970","3.1313","64.4342"
"18.9600","4.7163","271.6504","4.7163","3.1442","64.6787"
"19.0400","4.7374","272.8015","4.7374","3.1583","64.9527"
"19.1200","4.7559","273.7270","4.7559","3.1706","65.1731"
"19.2000","4.7776","274.9351","4.7776","3.1851","65.4607"
"19.2800","4.7988","276.0677","4.7988","3.1992","65.7304"
"19.3600","4.8182","277.0939","4.8182","3.2121","65.9747"
"19.4400","4.8373","278.0674","4.8373","3.2249","66.2065"
"19.5200","4.8568","279.0677","4.8568","3.2379","66.4447"
"19.6000","4.8772","280.1668","4.8772","3.2515","66.7064"
"19.6800","4.8976","281.2332","4.8976","3.2651","66.9603"
"19.7600","4.9163","282.1638","4.9163","3.2775","67.1818"
"19.8400","4.9368","283.2707","4.9368","3.2912","67.4454"
"19.9200","4.9575","284.3533","4.9575","3.3050","67.7032"
"20.0000","4.9777","285.4235","4.9777","3.3185","67.9580"
"20.0800","4.9975","286.4297","4.9975","3.3317","68.1976"
"20.1600","5.0166","287.3873","5.0166","3.3444","68.4255"
"20.2400","5.0372","288.4738","5.0372","3.3581","68.6842"
"20.3200","5.0565","289.4479","5.0565","3.3710","68.9162"
"20.4000","5.0762","290.4665","5.0762","3.3841","69.1587"
"20.4800","5.0979","291.6460","5.0979","3.3986","69.4395"
"20.5600","5.1183","292.6667","5.1183","3.4122","69.6825"
"20.6400","5.1375","293.6509","5.1375","3.4250","69.9169"
"20.7200","5.1575","294.6791","5.1575","3.4384","70.1617"
"20.8000","5.1764","295.6209","5.1764","3.4509","70.3859"
"20.8800","5.1976","296.7479","5.1976","3.4650","70.6543"
"20.9600","5.2168","297.7069","5.2168","3.4779","70.8826"
"21.0400","5.2363","298.6987","5.2363","3.4908","71.1187"
"21.1200","5.2567","299.7781","5.2567","3.5044","71.3758"
"21.2000","5.2775","300.8504","5.2775","3.5184","71.6311"
"21.2800","5.2978","301.8785","5.2978","3.5319","71.8758"
"21.3600","5.3177","302.8769","5.3177","3.5451","72.1136"
"21.4400","5.3362","303.7862","5.3362","3.5575","72.3300"
"21.5200","5.3566","304.8349","5.3566","3.5711","72.5797"
"21.6000","5.3767","305.8969","5.3767","3.5844","72.8326"
"21.6800","5.3978","307.0146","5.3978","3.5986","73.0987"
"21.7600","5.4184","308.0518","5.4184","3.6122","73.3457"
"21.8400","5.4374","308.9822","5.4374","3.6249","73.5672"
"21.9200","5.4576","309.9918","5.4576","3.6384","73.8076"
"22.0000","5.4773","310.9884","5.4773","3.6515","74.0449"
"22.0800","5.4963","311.9139","5.4963","3.6642","74.2652"
"22.1600","5.5168","312.9823","5.5168","3.6779","74.5196"
"22.2400","5.5366","313.9470","5.5366","3.6910","74.7493"
"22.3200","5.5571","314.9957","5.5571","3.7047","74.9990"
"22.4000","5.5781","316.0675","5.5781","3.7187","75.2542"
"22.4800","5.5974","317.0126","5.5974","3.7316","75.4792"
"22.5600","5.6177","318.0378","5.6177","3.7451","75.7233"
"22.6400","5.6366","318.9437","5.6366","3.7577","75.9390"
"22.7200","5.6567","319.9725","5.6567","3.7712","76.1839"
"22.8000","5.6765","320.9580","5.6765","3.7843","76.4186"
"22.8800","5.6965","321.9338","5.6965","3.7977","76.6509"
"22.9600","5.7173","322.9958","5.7173","3.8115","76.9038"
"23.0400","5.7387","324.0863","5.7387","3.8258","77.1634"
"23.1200","5.7578","325.0288","5.7578","3.8385","77.3878"
"23.2000","5.7774","325.9905","5.7774","3.8516","77.6168"
"23.2800","5.7967","326.9162","5.7967","3.8645","77.8372"
"23.3600","5.8174","327.9569","5.8174","3.8782","78.0850"
"23.4400","5.8373","328.9235","5.8373","3.8915","78.3151"
"23.5200","5.8560","329.8286","5.8560","3.9040","78.5306"
"23.6000","5.8771","330.9007","5.8771","3.9181","78.7859"
"23.6800","5.8978","331.9303","5.8978","3.9319","79.0310"
"23.7600","5.9174","332.8786","5.9174","3.9450","79.2568"
"23.8400","5.9374","333.8645","5.9374","3.9583","79.4916"
"23.9200","5.9565","334.7567","5.9565","3.9710","79.7040"
"24.0000","5.9771","335.8004","5.9771","3.9847","79.9525"
"24.0800","5.9976","336.7973","5.9976","3.9984","80.1898"
"24.1600","6.0165","337.7088","6.0165","4.0110","80.4069"
"24.2400","6.0377","338.7615","6.0377","4.0251","80.6575"
"24.3200","6.0572","339.6949","6.0572","4.0382","80.8797"
"24.4000","6.0784","340.7550","6.0784","4.0522","81.1321"
"24.4800","6.0977","341.6674","6.0977","4.0652","81.3494"
"24.5600","6.1163","342.5160","6.1163","4.0775","81.5514"
"24.6400","6.1365","343.5064","6.1365","4.0910","81.7872"
"24.7200","6.1567","344.4694","6.1567","4.1045","82.0165"
"24.8000","6.1768","345.4680","6.1768","4.1179","82.2543"
"24.8800","6.1982","346.5271","6.1982","4.1322","82.5064"
"24.9600","6.2170","347.3748","6.2170","4.1447","82.7083"
"25.0400","6.2378","348.3950","6.2378","4.1585","82.9512"
"25.1200","6.2569","349.2713","6.2569","4.1712","83.1598"
"25.2000","6.2763","350.2116","6.2763","4.1842","83.3837"
"25.2800","6.2968","351.2402","6.2968","4.1979","83.6286"
"25.3600","6.3166","352.1556","6.3166","4.2111","83.8466"
"25.4400","6.3375","353.1856","6.3375","4.2250","84.0918"
"25.5200","6.3581","354.1743","6.3581","4.2387","84.3272"
"25.6000","6.3774","355.0697","6.3774","4.2516","84.5404"
"25.6800","6.3975","356.0323","6.3975","4.2650","84.7696"
"25.7600","6.4174","356.9574","6.4174","4.2783","84.9899"
"25.8400","6.4368","357.8722","6.4368","4.2912","85.2077"
"25.9200","6.4570","358.8245","6.4570","4.3047","85.4344"
"26.0000","6.4760","359.6888","6.4760","4.3173","85.6402"
"26.0800","6.4973","360.7453","6.4973","4.3316","85.8917"
"26.1600","6.5179","361.7364","6.5179","4.3453","86.1277"
"26.2400","6.5377","362.6505","6.5377","4.3585","86.3454"
"26.3200","6.5574","363.5669","6.5574","4.3716","86.5635"
"26.4000","6.5768","364.4322","6.5768","4.3845","86.7696"
"26.4800","6.5972","365.4255","6.5972","4.3981","87.0061"
"26.5600","6.6175","366.3646","6.6175","4.4116","87.2297"
"26.6400","6.6358","367.1844","6.6358","4.4239","87.4249"
"26.7200","6.6576","368.2565","6.6576","4.4384","87.6801"
"26.8000","6.6778","369.2033","6.6778","4.4519","87.9056"
"26.8800","6.6986","370.1979","6.6986","4.4657","88.1424"
"26.9600","6.7173","371.0069","6.7173","4.4782","88.3350"
"27.0400","6.7367","371.8823","6.7367","4.4911","88.5434"
"27.1200","6.7567","372.8257","6.7567","4.5045","88.7680"
"27.2000","6.7769","373.7774","6.7769","4.5180","88.9946"
"27.2800","6.7963","374.6508","6.7963","4.5309","89.2026"
"27.3600","6.8173","375.6620","6.8173","4.5449","89.4433"
"27.4400","6.8377","376.5831","6.8377","4.5585","89.6626"
"27.5200","6.8577","377.4977","6.8577","4.5718","89.8804"
"27.6000","6.8772","378.3797","6.8772","4.5848","90.0904"
"27.6800","6.8964","379.2276","6.8964","4.5976","90.2923"
"27.7600","6.9169","380.1874","6.9169","4.6112","90.5208"
"27.8400","6.9367","381.0833","6.9367","4.6244","90.7341"
"27.9200","6.9567","381.9990","6.9567","4.6378","90.9521"
"28.0000","6.9779","383.0179","6.9779","4.6519","91.1947"
"28.0800","6.9982","383.9295","6.9982","4.6655","91.4118"
"28.1600","7.0180","384.7994","7.0180","4.6787","91.6189"
"28.2400","7.0375","385.6544","7.0375","4.6917","91.8225"
"28.3200","7.0562","386.4706","7.0562","4.7041","92.0168"
"28.4000","7.0770","387.4456","7.0770","4.7180","92.2490"
"28.4800","7.0964","388.2944","7.0964","4.7309","92.4511"
"28.5600","7.1174","389.2752","7.1174","4.7450","92.6846"
"28.6400","7.1373","390.1744","7.1373","4.7582","92.8987"
"28.7200","7.1572","391.0399","7.1572","4.7715","93.1047"
"28.8000","7.1772","391.9321","7.1772","4.7848","93.3172"
"28.8800","7.1975","392.8376","7.1975","4.7984","93.5328"
"28.9600","7.2168","393.6871","7.2168","4.8112","93.7350"
"29.0400","7.2369","394.5805","7.2369","4.8246","93.9477"
"29.1200","7.2556","395.3655","7.2556","4.8371","94.1347"
"29.2000","7.2777","396.4330","7.2777","4.8518","94.3888"
"29.2800","7.2985","397.3723","7.2985","4.8657","94.6125"
"29.3600","7.3183","398.2454","7.3183","4.8788","94.8203"
"29.4400","7.3373","399.0243","7.3373","4.8916","95.0058"
"29.5200","7.3566","399.8449","7.3566","4.9044","95.2012"
"29.6000","7.3763","400.7072","7.3763","4.9176","95.4065"
"29.6800","7.3973","401.6497","7.3973","4.9315","95.6309"
"29.7600","7.4168","402.4745","7.4168","4.9445","95.8273"
"29.8400","7.4372","403.3642","7.4372","4.9581","96.0391"
"29.9200","7.4575","404.2549","7.4575","4.9716","96.2512"
"30.0000","7.4773","405.1176","7.4773","4.9849","96.4566"
"30.0800","7.4979","406.0114","7.4979","4.9986","96.6694"
"30.1600","7.5165","406.7697","7.5165","5.0110","96.8499"
"30.2400","7.5373","407.6840","7.5373","5.0249","97.0676"
"30.3200","7.5568","408.5041","7.5568","5.0379","97.2629"
"30.4000","7.5764","409.3385","7.5764","5.0510","97.4616"
"30.4800","7.5974","410.2779","7.5974","5.0649","97.6852"
"30.5600","7.6185","411.2172","7.6185","5.0790","97.9089"
"30.6400","7.6380","412.0108","7.6380","5.0920","98.0978"
"30.7200","7.6574","412.8222","7.6574","5.1049","98.2910"
"30.8000","7.6764","413.5966","7.6764","5.1176","98.4754"
"30.8800","7.6976","414.5403","7.6976","5.1317","98.7001"
"30.9600","7.7168","415.3132","7.7168","5.1445","98.8841"
"31.0400","7.7363","416.1321","7.7363","5.1576","99.0791"
"31.1200","7.7566","416.9964","7.7566","5.1711","99.2849"
"31.2000","7.7778","417.9244","7.7778","5.1852","99.5058"
"31.2800","7.7980","418.7690","7.7980","5.1987","99.7069"
"31.3600","7.8178","419.5759","7.8178","5.2118","99.8990"
"31.4400","7.8362","420.3168","7.8362","5.2242","100.0754"
"31.5200","7.8569","421.2015","7.8569","5.2379","100.2861"
"31.6000","7.8765","422.0083","7.8765","5.2510","100.4782"
"31.6800","7.8977","422.9486","7.8977","5.2651","100.7021"
"31.7600","7.9185","423.8339","7.9185","5.2790","100.9128"
"31.8400","7.9375","424.5810","7.9375","5.2917","101.0907"
"31.9200","7.9573","425.3813","7.9573","5.3048","101.2813"
"32.0000","7.9774","426.2361","7.9774","5.3183","101.4848"
"32.0800","7.9974","427.0655","7.9974","5.3316","101.6823"
"32.1600","8.0171","427.8699","8.0171","5.3447","101.8738"
"32.2400","8.0361","428.6113","8.0361","5.3574","102.0503"
"32.3200","8.0566","429.4957","8.0566","5.3711","102.2609"
"32.4000","8.0779","430.4007","8.0779","5.3852","102.4764"
"32.4800","8.0975","431.2022","8.0975","5.3983","102.6672"
"32.5600","8.1177","432.0294","8.1177","5.4118","102.8641"
"32.6400","8.1363","432.7187","8.1363","5.4242","103.0283"
"32.7200","8.1560","433.5473","8.1560","5.4373","103.2256"
"32.8000","8.1764","434.4007","8.1764","5.4509","103.4287"
"32.8800","8.1967","435.2292","8.1967","5.4645","103.6260"
"32.9600","8.2174","436.0749","8.2174","5.4782","103.8274"
"33.0400","8.2384","436.9602","8.2384","5.4923","104.0381"
"33.1200","8.2575","437.7003","8.2575","5.5050","104.2144"
"33.2000","8.2775","438.5064","8.2775","5.5183","104.4063"
"33.2800","8.2967","439.2496","8.2967","5.5311","104.5832"
"33.3600","8.3176","440.1195","8.3176","5.5451","104.7904"
"33.4400","8.3368","440.8549","8.3368","5.5579","104.9655"
"33.5200","8.3563","441.6369","8.3563","5.5709","105.1516"
"33.6000","8.3767","442.4590","8.3767","5.5845","105.3474"
"33.6800","8.3979","443.3586","8.3979","5.5986","105.5616"
"33.7600","8.4181","444.1633","8.4181","5.6121","105.7532"
"33.8400","8.4378","444.9284","8.4378","5.6252","105.9353"
"33.9200","8.4562","445.5970","8.4562","5.6375","106.0945"
"34.0000","8.4766","446.4316","8.4766","5.6511","106.2932"
"34.0800","8.4972","447.2563","8.4972","5.6648","106.4896"
"34.1600","8.5170","448.0458","8.5170","5.6780","106.6776"
"34.2400","8.5377","448.8812","8.5377","5.6918","106.8765"
"34.3200","8.5575","449.6357","8.5575","5.7050","107.0561"
"34.4000","8.5781","450.4628","8.5781","5.7187","107.2530"
"34.4800","8.5976","451.2040","8.5976","5.7317","107.4295"
"34.5600","8.6170","451.9440","8.6170","5.7447","107.6057"
"34.6400","8.6368","452.7080","8.6368","5.7579","107.7876"
"34.7200","8.6563","453.4377","8.6563","5.7709","107.9614"
"34.8000","8.6767","454.2754","8.6767","5.7845","108.1608"
"34.8800","8.6978","455.1302","8.6978","5.7985","108.3643"
"34.9600","8.7170","455.8124","8.7170","5.8113","108.5268"
"35.0400","8.7374","456.6197","8.7374","5.8249","108.7190"
"35.1200","8.7569","457.3526","8.7569","5.8379","108.8935"
"35.2000","8.7768","458.1303","8.7768","5.8512","109.0787"
"35.2800","8.7966","458.8808","8.7966","5.8644","109.2573"
"35.3600","8.8165","459.6310","8.8165","5.8777","109.4359"
"35.4400","8.8372","460.4543","8.8372","5.8915","109.6320"
"35.5200","8.8584","461.3032","8.8584","5.9056","109.8341"
"35.6000","8.8779","462.0152","8.8779","5.9186","110.0036"
"35.6800","8.8976","462.7499","8.8976","5.9317","110.1786"
"35.7600","8.9172","463.4759","8.9172","5.9448","110.3514"
"35.8400","8.9367","464.2071","8.9367","5.9578","110.5255"
"35.9200","8.9567","464.9668","8.9567","5.9711","110.7064"
"36.0000","8.9757","465.6523","8.9757","5.9838","110.8696"
"36.0800","8.9977","466.5752","8.9977","5.9984","111.0893"
"36.1600","9.0179","467.3338","9.0179","6.0119","111.2700"
"36.2400","9.0372","468.0177","9.0372","6.0248","111.4328"
"36.3200","9.0568","468.7523","9.0568","6.0379","111.6077"
"36.4000","9.0770","469.5168","9.0770","6.0514","111.7897"
"36.4800","9.0968","470.2405","9.0968","6.0646","111.9620"
"36.5600","9.1173","471.0273","9.1173","6.0782","112.1493"
"36.6400","9.1362","471.7014","9.1362","6.0908","112.3098"
"36.7200","9.1576","472.5635","9.1576","6.1051","112.5151"
"36.8000","9.1782","473.3776","9.1782","6.1188","112.7089"
"36.8800","9.1985","474.1211","9.1985","6.1323","112.8860"
"36.9600","9.2173","474.7605","9.2173","6.1449","113.0382"
"37.0400","9.2369","475.4425","9.2369","6.1579","113.2006"
"37.1200","9.2569","476.1943","9.2569","6.1712","113.3796"
"37.2000","9.2771","476.9368","9.2771","6.1848","113.5564"
"37.2800","9.2958","477.6016","9.2958","6.1972","113.7147"
"37.3600","9.3175","478.4703","9.3175","6.2116","113.9215"
"37.4400","9.3375","479.1929","9.3375","6.2250","114.0935"
"37.5200","9.3581","479.9664","9.3581","6.2388","114.2777"
"37.6000","9.3773","480.6025","9.3773","6.2515","114.4292"
"37.6800","9.3962","481.2559","9.3962","6.2641","114.5847"
"37.7600","9.4168","482.0369","9.4168","6.2779","114.7707"
"37.8400","9.4367","482.7585","9.4367","6.2911","114.9425"
"37.9200","9.4568","483.5074","9.4568","6.3045","115.1208"
"38.0000","9.4776","484.2976","9.4776","6.3184","115.3089"
"38.0800","9.4982","485.0439","9.4982","6.3321","115.4866"
"38.1600","9.5180","485.7351","9.5180","6.3454","115.6512"
"38.2400","9.5374","486.3987","9.5374","6.3582","115.8092"
"38.3200","9.5562","487.0528","9.5562","6.3708","115.9649"
"38.4000","9.5770","487.8285","9.5770","6.3847","116.1496"
"38.4800","9.5959","488.4521","9.5959","6.3973","116.2981"
"38.5600","9.6173","489.2742","9.6173","6.4115","116.4939"
"38.6400","9.6376","489.9961","9.6376","6.4250","116.6657"
"38.7200","9.6574","490.6724","9.6574","6.4382","116.8268"
"38.8000","9.6769","491.3401","9.6769","6.4513","116.9857"
"38.8800","9.6976","492.0909","9.6976","6.4650","117.1645"
"38.9600","9.7167","492.7410","9.7167","6.4778","117.3193"
"39.0400","9.7368","493.4435","9.7368","6.4912","117.4866"
"39.1200","9.7562","494.0909","9.7562","6.5041","117.6407"
"39.2000","9.7776","494.9026","9.7776","6.5184","117.8339"
"39.2800","9.7983","495.6395","9.7983","6.5322","118.0094"
"39.3600","9.8183","496.3257","9.8183","6.5455","118.1728"
"39.4400","9.8369","496.8900","9.8369","6.5580","118.3071"
"39.5200","9.8568","497.5783","9.8568","6.5712","118.4710"
"39.6000","9.8773","498.3209","9.8773","6.5849","118.6478"
"39.6800","9.8976","499.0211","9.8976","6.5984","118.8145"
"39.7600","9.9161","499.5876","9.9161","6.6108","118.9494"
"39.8400","9.9369","500.3329","9.9369","6.6246","119.1269"
"39.9200","9.9576","501.0490","9.9576","6.6384","119.2974"
"40.0000","9.9770","501.6993","9.9770","6.6513","119.4522"
"40.0800","9.9977","502.4194","9.9977","6.6651","119.6237"
"40.1600","10.0169","503.0288","10.0169","6.6779","119.7688"
"40.2400","10.0373","503.7284","10.0373","6.6915","119.9353"
"40.3200","10.0568","504.3749","10.0568","6.7046","120.0893"
"40.4000","10.0768","505.0505","10.0768","6.7179","120.2501"
"40.4800","10.0977","505.7806","10.0977","6.7318","120.4240"
"40.5600","10.1181","506.4534","10.1181","6.7454","120.5841"
"40.6400","10.1375","507.0860","10.1375","6.7583","120.7348"
"40.7200","10.1573","507.7415","10.1573","6.7716","120.8908"
"40.8000","10.1763","508.3297","10.1763","6.7842","121.0309"
"40.8800","10.1975","509.0674","10.1975","6.7984","121.2065"
"40.9600","10.2167","509.6567","10.2167","6.8111","121.3468"
"41.0400","10.2365","510.3173","10.2365","6.8244","121.5041"
"41.1200","10.2564","510.9607","10.2564","6.8376","121.6573"
"41.2000","10.2775","511.6931","10.2775","6.8517","121.8317"
"41.2800","10.2981","512.3787","10.2981","6.8654","121.9949"
"41.3600","10.3181","513.0214","10.3181","6.8787","122.1480"
"41.4400","10.3365","513.5474","10.3365","6.8910","122.2732"
"41.5200","10.3562","514.1708","10.3562","6.9042","122.4216"
"41.6000","10.3764","514.8342","10.3764","6.9176","122.5796"
"41.6800","10.3978","515.5818","10.3978","6.9319","122.7576"
"41.7600","10.4186","516.2620","10.4186","6.9457","122.9195"
"41.8400","10.4377","516.8212","10.4377","6.9585","123.0527"
"41.9200","10.4575","517.4362","10.4575","6.9717","123.1991"
"42.0000","10.4773","518.0616","10.4773","6.9849","123.3480"
"42.0800","10.4970","518.6884","10.4970","6.9980","123.4972"
"42.1600","10.5172","519.3643","10.5172","7.0114","123.6582"
"42.2400","10.5360","519.8761","10.5360","7.0240","123.7800"
"42.3200","10.5563","520.5406","10.5563","7.0376","123.9382"
"42.4000","10.5776","521.2537","10.5776","7.0517","124.1080"
"42.4800","10.5981","521.9160","10.5981","7.0654","124.2657"
"42.5600","10.6179","522.5025","10.6179","7.0786","124.4054"
"42.6400","10.6365","523.0095","10.6365","7.0910","124.5261"
"42.7200","10.6570","523.6851","10.6570","7.1047","124.6869"
"42.8000","10.6768","524.2836","10.6768","7.1178","124.8294"
"42.8800","10.6965","524.8624","10.6965","7.1310","124.9672"
"42.9600","10.7176","525.5530","10.7176","7.1451","125.1317"
"43.0400","10.7387","526.2198","10.7387","7.1591","125.2904"
"43.1200","10.7572","526.7145","10.7572","7.1715","125.4082"
"43.2000","10.7772","527.3242","10.7772","7.1848","125.5534"
"43.2800","10.7970","527.9006","10.7970","7.1980","125.6906"
"43.3600","10.8176","528.5590","10.8176","7.2117","125.8474"
"43.4400","10.8366","529.0868","10.8366","7.2244","125.9730"
"43.5200","10.8560","529.6587","10.8560","7.2373","126.1092"
"43.6000","10.8772","530.3378","10.8772","7.2515","126.2709"
"43.6800","10.8980","530.9571","10.8980","7.2653","126.4184"
"43.7600","10.9173","531.4928","10.9173","7.2782","126.5459"
"43.8400","10.9374","532.0894","10.9374","7.2916","126.6880"
"43.9200","10.9562","532.5662","10.9562","7.3041","126.8015"
"44.0000","10.9765","533.1956","10.9765","7.3177","126.9513"
"44.0800","10.9972","533.8152","10.9972","7.3315","127.0989"
"44.1600","11.0172","534.4096","11.0172","7.3448","127.2404"
"44.2400","11.0375","534.9918","11.0375","7.3584","127.3790"
"44.3200","11.0572","535.5242","11.0572","7.3714","127.5057"
"44.4000","11.0781","536.1522","11.0781","7.3854","127.6553"
"44.4800","11.0979","536.7121","11.0979","7.3986","127.7886"
"44.5600","11.1171","537.2192","11.1171","7.4114","127.9093"
"44.6400","11.1365","537.7734","11.1365","7.4244","128.0413"
"44.7200","11.1565","538.3395","11.1565","7.4377","128.1761"
"44.8000","11.1767","538.9319","11.1767","7.4511","128.3171"
"44.8800","11.1981","539.5839","11.1981","7.4654","128.4724"
"44.9600","11.2170","540.0366","11.2170","7.4780","128.5801"
"45.0400","11.2374","540.6185","11.2374","7.4916","128.7187"
"45.1200","11.2571","541.1388","11.2571","7.5047","128.8426"
"45.2000","11.2768","541.6776","11.2768","7.5179","128.9708"
"45.2800","11.2967","542.2188","11.2967","7.5311","129.0997"
"45.3600","11.3172","542.7841","11.3172","7.5448","129.2343"
"45.4400","11.3375","543.3452","11.3375","7.5583","129.3679"
"45.5200","11.3582","543.9396","11.3582","7.5721","129.5094"
"45.6000","11.3774","544.4070","11.3774","7.5849","129.6207"
"45.6800","11.3979","544.9765","11.3979","7.5986","129.7563"
"45.7600","11.4173","545.4586","11.4173","7.6116","129.8711"
"45.8400","11.4368","545.9692","11.4368","7.6245","129.9927"
"45.9200","11.4564","546.4526","11.4564","7.6376","130.1078"
"46.0000","11.4757","546.9299","11.4757","7.6505","130.2214"
"46.0800","11.4975","547.5815","11.4975","7.6650","130.3765"
"46.1600","11.5181","548.1266","11.5181","7.6787","130.5064"
"46.2400","11.5374","548.5984","11.5374","7.6916","130.6187"
"46.3200","11.5570","549.1011","11.5570","7.7047","130.7383"
"46.4000","11.5768","549.5811","11.5768","7.7179","130.8526"
"46.4800","11.5967","550.0988","11.5967","7.7312","130.9759"
"46.5600","11.6174","550.6483","11.6174","7.7449","131.1067"
"46.6400","11.6361","551.0825","11.6361","7.7574","131.2101"
"46.7200","11.6574","551.6703","11.6574","7.7716","131.3501"
"46.8000","11.6779","552.2086","11.6779","7.7853","131.4782"
"46.8800","11.6985","552.7477","11.6985","7.7990","131.6066"
"46.9600","11.7173","553.1658","11.7173","7.8115","131.7061"
"47.0400","11.7370","553.6355","11.7370","7.8247","131.8180"
"47.1200","11.7568","554.1207","11.7568","7.8379","131.9335"
"47.2000","11.7771","554.6468","11.7771","7.8514","132.0588"
"47.2800","11.7958","555.0597","11.7958","7.8639","132.1571"
"47.3600","11.8174","555.6763","11.8174","7.8782","132.3039"
"47.4400","11.8375","556.1530","11.8375","7.8917","132.4174"
"47.5200","11.8577","556.6508","11.8577","7.9051","132.5359"
"47.6000","11.8776","557.1293","11.8776","7.9184","132.6498"
"47.6800","11.8967","557.5637","11.8967","7.9312","132.7533"
"47.7600","11.9168","558.0236","11.9168","7.9446","132.8627"
"47.8400","11.9366","558.5042","11.9366","7.9578","132.9772"
"47.9200","11.9570","559.0157","11.9570","7.9713","133.0990"
"48.0000","11.9780","559.5565","11.9780","7.9853","133.2277"
"48.0800","11.9980","560.0037","11.9980","7.9986","133.3342"
"48.1600","12.0179","560.4602","12.0179","8.0120","133.4429"
"48.2400","12.0377","560.9124","12.0377","8.0251","133.5506"
"48.3200","12.0566","561.3157","12.0566","8.0377","133.6466"
"48.4000","12.0770","561.8039","12.0770","8.0513","133.7628"
"48.4800","12.0963","562.2221","12.0963","8.0642","133.8624"
"48.5600","12.1176","562.7672","12.1176","8.0784","133.9922"
"48.6400","12.1377","563.2209","12.1377","8.0918","134.1002"
"48.7200","12.1573","563.6407","12.1573","8.1049","134.2002"
"48.8000","12.1773","564.0847","12.1773","8.1182","134.3059"
"48.8800","12.1976","564.5455","12.1976","8.1317","134.4156"
"48.9600","12.2166","564.9236","12.2166","8.1444","134.5056"
"49.0400","12.2366","565.3616","12.2366","8.1578","134.6099"
"49.1200","12.2563","565.7654","12.2563","8.1709","134.7061"
"49.2000","12.2777","566.3043","12.2777","8.1851","134.8343"
"49.2800","12.2981","566.7601","12.2981","8.1987","134.9429"
"49.3600","12.3182","567.1893","12.3182","8.2121","135.0451"
"49.4400","12.3372","567.5441","12.3372","8.2248","135.1295"
"49.5200","12.3568","567.9323","12.3568","8.2379","135.2220"
"49.6000","12.3769","568.3677","12.3769","8.2513","135.3256"
"49.6800","12.3976","568.8328","12.3976","8.2650","135.4364"
"49.7600","12.4159","569.1338","12.4159","8.2773","135.5080"
"49.8400","12.4366","569.5966","12.4366","8.2911","135.6182"
"49.9200","12.4577","570.0667","12.4577","8.3051","135.7302"
"50.0000","12.4776","570.4781","12.4776","8.3184","135.8281"
"50.0800","12.4978","570.8809","12.4978","8.3318","135.9240"
"50.1600","12.5166","571.1997","12.5166","8.3444","135.9999"
"50.2400","12.5372","571.6289","12.5372","8.3581","136.1021"
"50.3200","12.5569","572.0186","12.5569","8.3713","136.1949"
"50.4000","12.5769","572.4152","12.5769","8.3846","136.2893"
"50.4800","12.5975","572.8516","12.5975","8.3983","136.3932"
"50.5600","12.6181","573.2541","12.6181","8.4121","136.4891"
"50.6400","12.6377","573.6081","12.6377","8.4251","136.5734"
"50.7200","12.6578","573.9943","12.6578","8.4385","136.6653"
"50.8000","12.6762","574.2671","12.6762","8.4508","136.7303"
"50.8800","12.6973","574.6977","12.6973","8.4649","136.8328"
"50.9600","12.7166","575.0184","12.7166","8.4778","136.9092"
"51.0400","12.7365","575.3842","12.7365","8.4910","136.9962"
"51.1200","12.7567","575.7673","12.7567","8.5045","137.0874"
"51.2000","12.7778","576.1774","12.7778","8.5186","137.1851"
"51.2800","12.7979","576.5292","12.7979","8.5319","137.2689"
"51.3600","12.8179","576.8695","12.8179","8.5453","137.3499"
"51.4400","12.8363","577.1028","12.8363","8.5576","137.4054"
"51.5200","12.8565","577.4591","12.8565","8.5710","137.4903"
"51.6000","12.8763","577.7697","12.8763","8.5842","137.5642"
"51.6800","12.8975","578.1771","12.8975","8.5984","137.6612"
"51.7600","12.9184","578.5232","12.9184","8.6123","137.7436"
"51.8400","12.9378","578.7860","12.9378","8.6252","137.8062"
"51.9200","12.9576","579.0469","12.9576","8.6384","137.8683"
"52.0000","12.9773","579.3219","12.9773","8.6515","137.9338"
"52.0800","12.9974","579.6262","12.9974","8.6649","138.0062"
"52.1600","13.0168","579.8695","13.0168","8.6779","138.0642"
"52.2400","13.0361","580.1017","13.0361","8.6907","138.1195"
"52.3200","13.0565","580.4217","13.0565","8.7043","138.1956"
"52.4000","13.0782","580.8208","13.0782","8.7188","138.2907"
"52.4800","13.0978","581.0587","13.0978","8.7319","138.3473"
"52.5600","13.1178","581.3043","13.1178","8.7452","138.4058"
"52.6400","13.1364","581.4678","13.1364","8.7576","138.4447"
"52.7200","13.1566","581.7484","13.1566","8.7710","138.5115"
"52.8000","13.1763","581.9915","13.1763","8.7842","138.5694"
"52.8800","13.1968","582.2725","13.1968","8.7979","138.6363"
"52.9600","13.2178","582.5631","13.2178","8.8119","138.7055"
"53.0400","13.2383","582.8125","13.2383","8.8255","138.7649"
"53.1200","13.2574","583.0139","13.2574","8.8383","138.8128"
"53.2000","13.2769","583.2263","13.2769","8.8513","138.8634"
"53.2800","13.2969","583.4567","13.2969","8.8646","138.9183"
"53.3600","13.3179","583.7565","13.3179","8.8786","138.9897"
"53.4400","13.3371","583.9196","13.3371","8.8914","139.0285"
"53.5200","13.3561","584.0924","13.3561","8.9041","139.0696"
"53.6000","13.3770","584.3589","13.3770","8.9180","139.1331"
"53.6800","13.3979","584.6047","13.3979","8.9319","139.1916"
"53.7600","13.4179","584.8016","13.4179","8.9453","139.2385"
"53.8400","13.4375","584.9502","13.4375","8.9583","139.2739"
"53.9200","13.4562","585.0427","13.4562","8.9708","139.2959"
"54.0000","13.4771","585.2795","13.4771","8.9847","139.3523"
"54.0800","13.4974","585.4412","13.4974","8.9983","139.3908"
"54.1600","13.5173","585.6310","13.5173","9.0116","139.4360"
"54.2400","13.5375","585.7938","13.5375","9.0250","139.4747"
"54.3200","13.5573","585.9295","13.5573","9.0382","139.5070"
"54.4000","13.5781","586.1398","13.5781","9.0521","139.5571"
"54.4800","13.5980","586.2809","13.5980","9.0653","139.5907"
"54.5600","13.6172","586.3806","13.6172","9.0781","139.6144"
"54.6400","13.6366","586.4921","13.6366","9.0910","139.6410"
"54.7200","13.6564","586.6320","13.6564","9.1043","139.6743"
"54.8000","13.6767","586.8334","13.6767","9.1178","139.7222"
"54.8800","13.6982","587.0568","13.6982","9.1322","139.7754"
"54.9600","13.7171","587.1013","13.7171","9.1447","139.7860"
"55.0400","13.7376","587.2670","13.7376","9.1584","139.8255"
"55.1200","13.7569","587.3631","13.7569","9.1713","139.8484"
"55.2000","13.7768","587.4960","13.7768","9.1845","139.8800"
"55.2800","13.7967","587.5773","13.7967","9.1978","139.8993"
"55.3600","13.8169","587.6597","13.8169","9.2113","139.9190"
"55.4400","13.8368","587.7640","13.8368","9.2245","139.9438"
"55.5200","13.8580","587.9402","13.8580","9.2387","139.9858"
"55.6000","13.8778","588.0263","13.8778","9.2518","140.0063"
"55.6800","13.8981","588.1442","13.8981","9.2654","140.0343"
"55.7600","13.9174","588.2028","13.9174","9.2783","140.0483"
"55.8400","13.9371","588.3132","13.9371","9.2914","140.0746"
"55.9200","13.9566","588.3907","13.9566","9.3044","140.0930"
"56.0000","13.9759","588.4415","13.9759","9.3172","140.1051"
"56.0800","13.9972","588.6137","13.9972","9.3315","140.1461"
"56.1600","14.0180","588.7542","14.0180","9.3453","140.1796"
"56.2400","14.0376","588.8121","14.0376","9.3584","140.1934"
"56.3200","14.0570","588.8583","14.0570","9.3713","140.2044"
"56.4000","14.0769","588.9130","14.0769","9.3846","140.2174"
"56.4800","14.0971","589.0000","14.0971","9.3981","140.2381"
"56.5600","14.1173","589.0544","14.1173","9.4115","140.2511"
"56.6400","14.1358","589.0195","14.1358","9.4239","140.2427"
"56.7200","14.1576","589.1644","14.1576","9.4384","140.2773"
"56.8000","14.1779","589.1984","14.1779","9.4519","140.2853"
"56.8800","14.1984","589.2279","14.1984","9.4656","140.2924"
"56.9600","14.2175","589.1907","14.2175","9.4784","140.2835"
"57.0400","14.2370","589.1554","14.2370","9.4913","140.2751"
"57.1200","14.2570","589.1320","14.2570","9.5047","140.2695"
"57.2000","14.2770","589.0435","14.2770","9.5180","140.2485"
"57.2800","14.2963","588.9830","14.2963","9.5309","140.2340"
"57.3600","14.3170","589.0020","14.3170","9.5447","140.2386"
"57.4400","14.3372","588.9845","14.3372","9.5582","140.2344"
"57.5200","14.3577","588.9924","14.3577","9.5718","140.2363"
"57.6000","14.3775","588.9620","14.3775","9.5850","140.2290"
"57.6800","14.3965","588.8933","14.3965","9.5976","140.2127"
"57.7600","14.4168","588.8910","14.4168","9.6112","140.2121"
"57.8400","14.4367","588.8713","14.4367","9.6245","140.2075"
"57.9200","14.4572","588.8821","14.4572","9.6381","140.2100"
"58.0000","14.4776","588.8714","14.4776","9.6518","140.2075"
"58.0800","14.4980","588.8380","14.4980","9.6653","140.1995"
"58.1600","14.5175","588.7384","14.5175","9.6783","140.1758"
"58.2400","14.5369","588.6569","14.5369","9.6913","140.1564"
"58.3200","14.5566","588.5839","14.5566","9.7044","140.1390"
"58.4000","14.5770","588.5082","14.5770","9.7180","140.1210"
"58.4800","14.5962","588.3607","14.5962","9.7308","140.0859"
"58.5600","14.6173","588.2328","14.6173","9.7449","140.0554"
"58.6400","14.6378","588.1320","14.6378","9.7585","140.0314"
"58.7200","14.6573","587.9828","14.6573","9.7715","139.9959"
"58.8000","14.6773","587.8708","14.6773","9.7848","139.9692"
"58.8800","14.6972","587.7777","14.6972","9.7982","139.9471"
"58.9600","14.7168","587.6714","14.7168","9.8112","139.9218"
"59.0400","14.7368","587.6023","14.7368","9.8245","139.9053"
"59.1200","14.7560","587.4764","14.7560","9.8373","139.8753"
"59.2000","14.7778","587.4728","14.7778","9.8519","139.8745"
"59.2800","14.7985","587.4087","14.7985","9.8656","139.8592"
"59.3600","14.8180","587.2978","14.8180","9.8787","139.8328"
"59.4400","14.8372","587.1517","14.8372","9.8914","139.7980"
"59.5200","14.8570","587.0530","14.8570","9.9047","139.7745"
"59.6000","14.8771","586.9566","14.8771","9.9181","139.7516"
"59.6800","14.8971","586.8484","14.8971","9.9314","139.7258"
"59.7600","14.9163","586.6777","14.9164","9.9442","139.6852"
"59.8400","14.9374","586.6097","14.9374","9.9583","139.6690"
"59.9200","14.9577","586.4500","14.9577","9.9718","139.6309"
"60.0000","14.9775","586.1714","14.9775","9.9850","139.5646"
"60.0800","14.9977","585.9624","14.9977","9.9985","139.5149"
"60.0890","15.0000","585.9457","15.0000","10.0000","139.5109"