File: data/instron_tests/metamaterials/250331/250331_2046_BULK_m1.is_comp_Exports/250331_2046_BULK_m1_1_1.csv
Results Table 1
,Compresson Axis,H*,V*,Height,Thickness,Width,Area,Fixture separation,Specimen label
,,,,(mm),(mm),(mm),(mm^2),(mm),
"1","Y","","","150.00","28.00","150.00","4200.00","150.00","2046_BULK_m1"

Results Table 2
,Modulus (Segment 0 % - 5 %),Compresson Axis
,(kPa),
"1","1545.97","Y"

Time,Displacement,Force,Compressive displacement,Compressive strain (Displacement),Compressive stress
(s),(mm),(N),(mm),(%),(kPa)
"0.0000","0.0000","-2.9876","0.0000","0.0000","-0.7113"
"0.0800","0.0014","-2.9129","0.0014","0.0009","-0.6935"
"0.1600","0.0106","-2.3436","0.0106","0.0071","-0.5580"
"0.2400","0.0307","-1.1289","0.0307","0.0205","-0.2688"
"0.3200","0.0504","0.0131","0.0504","0.0336","0.0031"
"0.4000","0.0685","1.0038","0.0685","0.0457","0.2390"
"0.4800","0.0898","2.2146","0.0898","0.0599","0.5273"
"0.5600","0.1116","3.4222","0.1116","0.0744","0.8148"
"0.6400","0.1306","4.4435","0.1306","0.0870","1.0580"
"0.7200","0.1503","5.4973","0.1503","0.1002","1.3089"
"0.8000","0.1698","6.5228","0.1698","0.1132","1.5530"
"0.8800","0.1903","7.6190","0.1903","0.1269","1.8141"
"0.9600","0.2108","8.6803","0.2108","0.1405","2.0667"
"1.0400","0.2293","9.6376","0.2293","0.1529","2.2947"
"1.1200","0.2499","10.6979","0.2499","0.1666","2.5471"
"1.2000","0.2709","11.7855","0.2709","0.1806","2.8061"
"1.2800","0.2908","12.7952","0.2908","0.1938","3.0465"
"1.3600","0.3110","13.8178","0.3110","0.2074","3.2900"
"1.4400","0.3293","14.6828","0.3293","0.2196","3.4959"
"1.5200","0.3496","15.6780","0.3496","0.2331","3.7329"
"1.6000","0.3710","16.7420","0.3710","0.2473","3.9862"
"1.6800","0.3900","17.6782","0.3900","0.2600","4.2091"
"1.7600","0.4111","18.7207","0.4111","0.2741","4.4573"
"1.8400","0.4310","19.6852","0.4310","0.2873","4.6869"
"1.9200","0.4509","20.6577","0.4509","0.3006","4.9185"
"2.0000","0.4704","21.5894","0.4704","0.3136","5.1403"
"2.0800","0.4899","22.5328","0.4899","0.3266","5.3650"
"2.1600","0.5103","23.5295","0.5103","0.3402","5.6023"
"2.2400","0.5303","24.4888","0.5303","0.3536","5.8307"
"2.3200","0.5491","25.3736","0.5491","0.3661","6.0413"
"2.4000","0.5711","26.4483","0.5711","0.3807","6.2972"
"2.4800","0.5906","27.3222","0.5906","0.3937","6.5053"
"2.5600","0.6113","28.2970","0.6113","0.4076","6.7374"
"2.6400","0.6307","29.1809","0.6307","0.4204","6.9478"
"2.7200","0.6495","30.0659","0.6495","0.4330","7.1585"
"2.8000","0.6696","31.0065","0.6696","0.4464","7.3825"
"2.8800","0.6901","31.9792","0.6901","0.4601","7.6141"
"2.9600","0.7106","32.9454","0.7106","0.4737","7.8442"
"3.0400","0.7317","33.9582","0.7317","0.4878","8.0853"
"3.1200","0.7504","34.7981","0.7504","0.5003","8.2853"
"3.2000","0.7708","35.7684","0.7708","0.5139","8.5163"
"3.2800","0.7906","36.6801","0.7906","0.5271","8.7334"
"3.3600","0.8100","37.5910","0.8100","0.5400","8.9502"
"3.4400","0.8303","38.5270","0.8303","0.5535","9.1731"
"3.5200","0.8494","39.3996","0.8494","0.5663","9.3809"
"3.6000","0.8702","40.3865","0.8702","0.5802","9.6158"
"3.6800","0.8909","41.3432","0.8909","0.5939","9.8436"
"3.7600","0.9106","42.2446","0.9106","0.6071","10.0582"
"3.8400","0.9299","43.1126","0.9299","0.6199","10.2649"
"3.9200","0.9495","44.0000","0.9495","0.6330","10.4762"
"4.0000","0.9696","44.9316","0.9696","0.6464","10.6980"
"4.0800","0.9910","45.9239","0.9910","0.6607","10.9343"
"4.1600","1.0101","46.7784","1.0101","0.6734","11.1377"
"4.2400","1.0312","47.7654","1.0312","0.6875","11.3727"
"4.3200","1.0508","48.6477","1.0508","0.7006","11.5828"
"4.4000","1.0709","49.5713","1.0709","0.7140","11.8027"
"4.4800","1.0910","50.4752","1.0910","0.7273","12.0179"
"4.5600","1.1103","51.3305","1.1103","0.7402","12.2215"
"4.6400","1.1303","52.2315","1.1303","0.7535","12.4361"
"4.7200","1.1506","53.1468","1.1506","0.7670","12.6540"
"4.8000","1.1692","53.9777","1.1692","0.7794","12.8518"
"4.8800","1.1906","54.9725","1.1906","0.7937","13.0887"
"4.9600","1.2109","55.8964","1.2109","0.8073","13.3087"
"5.0400","1.2308","56.7952","1.2308","0.8205","13.5227"
"5.1200","1.2505","57.6819","1.2505","0.8337","13.7338"
"5.2000","1.2693","58.5039","1.2693","0.8462","13.9295"
"5.2800","1.2904","59.4760","1.2904","0.8603","14.1610"
"5.3600","1.3105","60.3683","1.3105","0.8737","14.3734"
"5.4400","1.3298","61.2277","1.3298","0.8865","14.5780"
"5.5200","1.3505","62.1878","1.3505","0.9003","14.8066"
"5.6000","1.3711","63.1094","1.3711","0.9141","15.0260"
"5.6800","1.3915","64.0290","1.3915","0.9276","15.2450"
"5.7600","1.4113","64.9060","1.4113","0.9409","15.4538"
"5.8400","1.4296","65.7085","1.4296","0.9531","15.6449"
"5.9200","1.4503","66.6431","1.4503","0.9669","15.8674"
"6.0000","1.4697","67.4815","1.4697","0.9798","16.0670"
"6.0800","1.4903","68.4238","1.4903","0.9935","16.2914"
"6.1600","1.5107","69.3308","1.5107","1.0071","16.5073"
"6.2400","1.5305","70.1977","1.5305","1.0203","16.7137"
"6.3200","1.5505","71.0829","1.5505","1.0337","16.9245"
"6.4000","1.5708","71.9854","1.5708","1.0472","17.1394"
"6.4800","1.5894","72.7893","1.5894","1.0596","17.3308"
"6.5600","1.6105","73.7575","1.6105","1.0737","17.5613"
"6.6400","1.6294","74.5659","1.6294","1.0863","17.7538"
"6.7200","1.6504","75.5426","1.6504","1.1003","17.9863"
"6.8000","1.6717","76.5075","1.6717","1.1145","18.2161"
"6.8800","1.6915","77.4138","1.6915","1.1277","18.4319"
"6.9600","1.7112","78.2833","1.7112","1.1408","18.6389"
"7.0400","1.7302","79.1071","1.7302","1.1535","18.8350"
"7.1200","1.7494","79.9599","1.7494","1.1662","19.0381"
"7.2000","1.7700","80.9062","1.7700","1.1800","19.2634"
"7.2800","1.7896","81.7598","1.7896","1.1931","19.4666"
"7.3600","1.8108","82.7424","1.8108","1.2072","19.7006"
"7.4400","1.8314","83.6690","1.8314","1.2209","19.9212"
"7.5200","1.8505","84.5216","1.8505","1.2336","20.1242"
"7.6000","1.8705","85.4174","1.8705","1.2470","20.3375"
"7.6800","1.8896","86.2457","1.8896","1.2597","20.5347"
"7.7600","1.9105","87.2082","1.9105","1.2737","20.7639"
"7.8400","1.9303","88.0887","1.9303","1.2868","20.9735"
"7.9200","1.9498","88.9547","1.9498","1.2999","21.1797"
"8.0000","1.9706","89.9530","1.9706","1.3137","21.4174"
"8.0800","1.9916","90.9115","1.9916","1.3277","21.6456"
"8.1600","2.0112","91.8024","2.0112","1.3408","21.8577"
"8.2400","2.0310","92.6812","2.0310","1.3540","22.0670"
"8.3200","2.0493","93.4747","2.0493","1.3662","22.2559"
"8.4000","2.0706","94.4790","2.0706","1.3804","22.4950"
"8.4800","2.0906","95.3789","2.0906","1.3937","22.7093"
"8.5600","2.1100","96.2493","2.1100","1.4066","22.9165"
"8.6400","2.1302","97.1755","2.1302","1.4201","23.1370"
"8.7200","2.1507","98.1026","2.1507","1.4338","23.3578"
"8.8000","2.1708","99.0258","2.1708","1.4472","23.5776"
"8.8800","2.1911","99.9443","2.1911","1.4607","23.7963"
"8.9600","2.2098","100.7695","2.2098","1.4732","23.9927"
"9.0400","2.2298","101.6731","2.2298","1.4866","24.2079"
"9.1200","2.2494","102.5394","2.2494","1.4996","24.4141"
"9.2000","2.2701","103.4965","2.2701","1.5134","24.6420"
"9.2800","2.2918","104.5056","2.2918","1.5278","24.8823"
"9.3600","2.3113","105.3741","2.3113","1.5409","25.0891"
"9.4400","2.3309","106.2501","2.3309","1.5540","25.2976"
"9.5200","2.3506","107.1420","2.3506","1.5671","25.5100"
"9.6000","2.3698","107.9933","2.3698","1.5799","25.7127"
"9.6800","2.3902","108.9329","2.3902","1.5935","25.9364"
"9.7600","2.4097","109.8028","2.4097","1.6065","26.1435"
"9.8400","2.4301","110.7402","2.4301","1.6200","26.3667"
"9.9200","2.4514","111.7137","2.4514","1.6342","26.5985"
"10.0000","2.4704","112.5473","2.4704","1.6469","26.7970"
"10.0800","2.4910","113.4911","2.4910","1.6607","27.0217"
"10.1600","2.5104","114.3873","2.5104","1.6736","27.2351"
"10.2400","2.5301","115.2949","2.5301","1.6868","27.4512"
"10.3200","2.5497","116.1785","2.5497","1.6998","27.6615"
"10.4000","2.5695","117.0559","2.5695","1.7130","27.8705"
"10.4800","2.5907","118.0409","2.5907","1.7271","28.1050"
"10.5600","2.6118","119.0115","2.6118","1.7412","28.3361"
"10.6400","2.6311","119.8644","2.6311","1.7541","28.5391"
"10.7200","2.6502","120.7103","2.6502","1.7668","28.7406"
"10.8000","2.6697","121.5783","2.6697","1.7798","28.9472"
"10.8800","2.6906","122.5548","2.6906","1.7937","29.1797"
"10.9600","2.7106","123.4318","2.7106","1.8071","29.3885"
"11.0400","2.7291","124.2488","2.7291","1.8194","29.5830"
"11.1200","2.7500","125.2045","2.7500","1.8333","29.8106"
"11.2000","2.7708","126.1727","2.7708","1.8472","30.0411"
"11.2800","2.7907","127.0518","2.7907","1.8605","30.2504"
"11.3600","2.8104","127.9338","2.8104","1.8736","30.4604"
"11.4400","2.8297","128.7694","2.8297","1.8865","30.6594"
"11.5200","2.8501","129.6949","2.8501","1.9001","30.8797"
"11.6000","2.8704","130.6078","2.8704","1.9136","31.0971"
"11.6800","2.8897","131.4695","2.8897","1.9265","31.3023"
"11.7600","2.9111","132.4586","2.9111","1.9408","31.5378"
"11.8400","2.9306","133.3149","2.9306","1.9538","31.7416"
"11.9200","2.9508","134.2177","2.9508","1.9672","31.9566"
"12.0000","2.9705","135.1057","2.9705","1.9803","32.1680"
"12.0800","2.9901","135.9992","2.9901","1.9934","32.3808"
"12.1600","3.0107","136.9292","3.0107","2.0071","32.6022"
"12.2400","3.0301","137.7794","3.0301","2.0201","32.8046"
"12.3200","3.0491","138.6274","3.0491","2.0328","33.0065"
"12.4000","3.0708","139.6377","3.0708","2.0472","33.2471"
"12.4800","3.0908","140.5123","3.0908","2.0605","33.4553"
"12.5600","3.1116","141.4566","3.1116","2.0744","33.6802"
"12.6400","3.1308","142.3045","3.1308","2.0872","33.8820"
"12.7200","3.1495","143.1236","3.1495","2.0996","34.0771"
"12.8000","3.1695","144.0221","3.1695","2.1130","34.2910"
"12.8800","3.1899","144.9411","3.1899","2.1266","34.5098"
"12.9600","3.2105","145.8723","3.2105","2.1403","34.7315"
"13.0400","3.2317","146.8375","3.2317","2.1545","34.9613"
"13.1200","3.2506","147.6460","3.2506","2.1671","35.1538"
"13.2000","3.2707","148.5453","3.2707","2.1805","35.3679"
"13.2800","3.2906","149.4248","3.2906","2.1937","35.5773"
"13.3600","3.3102","150.3104","3.3102","2.2068","35.7882"
"13.4400","3.3302","151.2059","3.3302","2.2201","36.0014"
"13.5200","3.3490","152.0121","3.3490","2.2327","36.1933"
"13.6000","3.3701","152.9737","3.3701","2.2467","36.4223"
"13.6800","3.3912","153.9349","3.3912","2.2608","36.6512"
"13.7600","3.4111","154.8033","3.4111","2.2740","36.8579"
"13.8400","3.4300","155.6163","3.4300","2.2867","37.0515"
"13.9200","3.4495","156.4544","3.4495","2.2997","37.2510"
"14.0000","3.4697","157.3782","3.4697","2.3131","37.4710"
"14.0800","3.4907","158.3240","3.4907","2.3271","37.6962"
"14.1600","3.5097","159.1485","3.5097","2.3398","37.8925"
"14.2400","3.5309","160.1030","3.5309","2.3539","38.1198"
"14.3200","3.5508","160.9781","3.5508","2.3672","38.3281"
"14.4000","3.5707","161.8516","3.5707","2.3805","38.5361"
"14.4800","3.5903","162.7141","3.5903","2.3936","38.7414"
"14.5600","3.6101","163.5752","3.6101","2.4067","38.9465"
"14.6400","3.6303","164.4715","3.6303","2.4202","39.1599"
"14.7200","3.6502","165.3499","3.6502","2.4335","39.3690"
"14.8000","3.6690","166.1744","3.6690","2.4460","39.5653"
"14.8800","3.6902","167.1483","3.6902","2.4601","39.7972"
"14.9600","3.7109","168.0690","3.7109","2.4739","40.0164"
"15.0400","3.7310","168.9572","3.7310","2.4873","40.2279"
"15.1200","3.7504","169.7979","3.7504","2.5003","40.4281"
"15.2000","3.7693","170.6108","3.7693","2.5128","40.6216"
"15.2800","3.7903","171.5506","3.7903","2.5269","40.8454"
"15.3600","3.8103","172.4299","3.8103","2.5402","41.0547"
"15.4400","3.8300","173.2964","3.8300","2.5533","41.2611"
"15.5200","3.8508","174.2305","3.8508","2.5672","41.4834"
"15.6000","3.8710","175.1152","3.8710","2.5807","41.6941"
"15.6800","3.8914","176.0287","3.8914","2.5943","41.9116"
"15.7600","3.9114","176.8977","3.9114","2.6076","42.1185"
"15.8400","3.9297","177.6771","3.9297","2.6198","42.3041"
"15.9200","3.9502","178.5873","3.9502","2.6335","42.5208"
"16.0000","3.9696","179.4188","3.9696","2.6464","42.7188"
"16.0800","3.9903","180.3466","3.9903","2.6602","42.9397"
"16.1600","4.0107","181.2573","4.0107","2.6738","43.1565"
"16.2400","4.0306","182.0964","4.0306","2.6870","43.3563"
"16.3200","4.0505","182.9641","4.0505","2.7003","43.5629"
"16.4000","4.0708","183.8504","4.0708","2.7139","43.7739"
"16.4800","4.0898","184.6686","4.0898","2.7265","43.9687"
"16.5600","4.1100","185.5438","4.1100","2.7400","44.1771"
"16.6400","4.1293","186.3788","4.1293","2.7529","44.3759"
"16.7200","4.1507","187.3360","4.1507","2.7671","44.6038"
"16.8000","4.1714","188.2437","4.1714","2.7809","44.8199"
"16.8800","4.1911","189.0962","4.1911","2.7941","45.0229"
"16.9600","4.2105","189.9187","4.2105","2.8070","45.2187"
"17.0400","4.2304","190.7776","4.2304","2.8202","45.4232"
"17.1200","4.2500","191.6351","4.2500","2.8333","45.6274"
"17.2000","4.2701","192.5152","4.2701","2.8467","45.8370"
"17.2800","4.2895","193.3326","4.2895","2.8597","46.0316"
"17.3600","4.3106","194.2842","4.3106","2.8737","46.2581"
"17.4400","4.3312","195.1660","4.3312","2.8874","46.4681"
"17.5200","4.3504","195.9960","4.3504","2.9003","46.6657"
"17.6000","4.3703","196.8471","4.3703","2.9136","46.8684"
"17.6800","4.3898","197.6747","4.3898","2.9265","47.0654"
"17.7600","4.4105","198.6044","4.4105","2.9404","47.2868"
"17.8400","4.4303","199.4483","4.4303","2.9536","47.4877"
"17.9200","4.4498","200.2796","4.4498","2.9665","47.6856"
"18.0000","4.4703","201.1823","4.4703","2.9802","47.9005"
"18.0800","4.4918","202.1353","4.4918","2.9945","48.1274"
"18.1600","4.5112","202.9470","4.5112","3.0074","48.3207"
"18.2400","4.5309","203.7892","4.5309","3.0206","48.5212"
"18.3200","4.5496","204.5518","4.5496","3.0331","48.7028"
"18.4000","4.5706","205.4692","4.5706","3.0470","48.9212"
"18.4800","4.5902","206.3031","4.5902","3.0601","49.1198"
"18.5600","4.6101","207.1681","4.6101","3.0734","49.3257"
"18.6400","4.6297","207.9926","4.6297","3.0865","49.5220"
"18.7200","4.6504","208.8823","4.6504","3.1003","49.7339"
"18.8000","4.6711","209.7783","4.6711","3.1141","49.9472"
"18.8800","4.6912","210.6310","4.6912","3.1275","50.1502"
"18.9600","4.7098","211.3807","4.7098","3.1399","50.3287"
"19.0400","4.7302","212.2681","4.7302","3.1535","50.5400"
"19.1200","4.7498","213.0757","4.7498","3.1665","50.7323"
"19.2000","4.7703","213.9802","4.7703","3.1802","50.9477"
"19.2800","4.7915","214.9022","4.7915","3.1944","51.1672"
"19.3600","4.8109","215.7046","4.8109","3.2073","51.3582"
"19.4400","4.8309","216.5473","4.8309","3.2206","51.5589"
"19.5200","4.8508","217.3837","4.8508","3.2339","51.7580"
"19.6000","4.8703","218.2004","4.8703","3.2469","51.9525"
"19.6800","4.8905","219.0953","4.8905","3.2604","52.1656"
"19.7600","4.9099","219.8712","4.9099","3.2733","52.3503"
"19.8400","4.9300","220.7407","4.9300","3.2867","52.5573"
"19.9200","4.9509","221.6304","4.9509","3.3006","52.7691"
"20.0000","4.9705","222.4459","4.9705","3.3137","52.9633"
"20.0800","4.9914","223.3280","4.9914","3.3276","53.1733"
"20.1600","5.0105","224.0836","5.0105","3.3403","53.3532"
"20.2400","5.0296","224.8663","5.0296","3.3531","53.5396"
"20.3200","5.0492","225.6810","5.0492","3.3662","53.7336"
"20.4000","5.0697","226.5394","5.0697","3.3798","53.9380"
"20.4800","5.0910","227.4555","5.0910","3.3940","54.1561"
"20.5600","5.1119","228.3304","5.1119","3.4079","54.3644"
"20.6400","5.1307","229.1017","5.1307","3.4205","54.5480"
"20.7200","5.1506","229.9241","5.1506","3.4337","54.7438"
"20.8000","5.1697","230.7011","5.1697","3.4465","54.9288"
"20.8800","5.1904","231.5911","5.1904","3.4603","55.1407"
"20.9600","5.2107","232.4590","5.2107","3.4738","55.3474"
"21.0400","5.2295","233.2067","5.2295","3.4864","55.5254"
"21.1200","5.2499","234.0522","5.2499","3.4999","55.7267"
"21.2000","5.2707","234.9305","5.2707","3.5138","55.9358"
"21.2800","5.2908","235.7585","5.2908","3.5272","56.1330"
"21.3600","5.3104","236.5486","5.3104","3.5403","56.3211"
"21.4400","5.3292","237.2844","5.3292","3.5528","56.4963"
"21.5200","5.3503","238.1907","5.3503","3.5669","56.7121"
"21.6000","5.3707","239.0272","5.3707","3.5805","56.9112"
"21.6800","5.3900","239.8128","5.3900","3.5933","57.0983"
"21.7600","5.4111","240.6998","5.4111","3.6074","57.3095"
"21.8400","5.4309","241.4951","5.4309","3.6206","57.4988"
"21.9200","5.4511","242.3053","5.4511","3.6340","57.6917"
"22.0000","5.4703","243.0770","5.4703","3.6468","57.8755"
"22.0800","5.4899","243.8721","5.4899","3.6599","58.0648"
"22.1600","5.5107","244.7387","5.5107","3.6738","58.2711"
"22.2400","5.5303","245.5187","5.5303","3.6868","58.4568"
"22.3200","5.5492","246.2838","5.5492","3.6994","58.6390"
"22.4000","5.5705","247.2023","5.5705","3.7137","58.8577"
"22.4800","5.5905","247.9980","5.5905","3.7270","59.0471"
"22.5600","5.6115","248.8693","5.6115","3.7410","59.2546"
"22.6400","5.6307","249.6478","5.6307","3.7538","59.4400"
"22.7200","5.6495","250.3932","5.6495","3.7664","59.6174"
"22.8000","5.6694","251.2053","5.6694","3.7796","59.8108"
"22.8800","5.6902","252.0674","5.6902","3.7935","60.0161"
"22.9600","5.7109","252.9124","5.7109","3.8073","60.2172"
"23.0400","5.7316","253.7746","5.7316","3.8210","60.4225"
"23.1200","5.7506","254.5061","5.7506","3.8338","60.5967"
"23.2000","5.7707","255.3174","5.7707","3.8471","60.7898"
"23.2800","5.7906","256.1012","5.7906","3.8604","60.9765"
"23.3600","5.8101","256.8910","5.8101","3.8734","61.1645"
"23.4400","5.8303","257.6965","5.8303","3.8868","61.3563"
"23.5200","5.8490","258.4159","5.8490","3.8993","61.5276"
"23.6000","5.8702","259.2991","5.8702","3.9135","61.7379"
"23.6800","5.8912","260.1599","5.8912","3.9275","61.9428"
"23.7600","5.9110","260.9431","5.9110","3.9407","62.1293"
"23.8400","5.9303","261.6914","5.9303","3.9535","62.3075"
"23.9200","5.9499","262.4541","5.9499","3.9666","62.4891"
"24.0000","5.9697","263.2556","5.9697","3.9798","62.6799"
"24.0800","5.9901","264.0794","5.9901","3.9934","62.8761"
"24.1600","6.0099","264.8530","6.0099","4.0066","63.0602"
"24.2400","6.0314","265.7389","6.0314","4.0209","63.2712"
"24.3200","6.0510","266.4955","6.0510","4.0340","63.4513"
"24.4000","6.0712","267.3143","6.0712","4.0474","63.6463"
"24.4800","6.0902","268.0439","6.0902","4.0602","63.8200"
"24.5600","6.1104","268.8606","6.1104","4.0736","64.0144"
"24.6400","6.1305","269.6460","6.1305","4.0870","64.2014"
"24.7200","6.1505","270.4359","6.1505","4.1004","64.3895"
"24.8000","6.1694","271.1519","6.1694","4.1129","64.5600"
"24.8800","6.1905","272.0244","6.1905","4.1270","64.7677"
"24.9600","6.2108","272.8144","6.2108","4.1406","64.9558"
"25.0400","6.2312","273.6266","6.2312","4.1541","65.1492"
"25.1200","6.2502","274.3404","6.2502","4.1668","65.3191"
"25.2000","6.2691","275.0575","6.2691","4.1794","65.4899"
"25.2800","6.2903","275.9078","6.2903","4.1935","65.6923"
"25.3600","6.3105","276.7075","6.3105","4.2070","65.8827"
"25.4400","6.3300","277.4593","6.3300","4.2200","66.0617"
"25.5200","6.3505","278.2828","6.3505","4.2336","66.2578"
"25.6000","6.3711","279.0817","6.3711","4.2474","66.4480"
"25.6800","6.3910","279.8589","6.3910","4.2606","66.6331"
"25.7600","6.4115","280.6605","6.4115","4.2743","66.8239"
"25.8400","6.4297","281.3315","6.4297","4.2865","66.9837"
"25.9200","6.4504","282.1570","6.4504","4.3003","67.1802"
"26.0000","6.4695","282.8657","6.4695","4.3130","67.3490"
"26.0800","6.4900","283.6878","6.4900","4.3267","67.5447"
"26.1600","6.5108","284.5236","6.5108","4.3405","67.7437"
"26.2400","6.5311","285.2933","6.5311","4.3540","67.9270"
"26.3200","6.5506","286.0357","6.5506","4.3670","68.1037"
"26.4000","6.5707","286.8048","6.5707","4.3804","68.2869"
"26.4800","6.5900","287.5521","6.5900","4.3934","68.4648"
"26.5600","6.6103","288.3400","6.6103","4.4069","68.6524"
"26.6400","6.6295","289.0456","6.6295","4.4197","68.8204"
"26.7200","6.6505","289.8868","6.6505","4.4337","69.0207"
"26.8000","6.6714","290.7118","6.6714","4.4476","69.2171"
"26.8800","6.6912","291.4651","6.6912","4.4608","69.3965"
"26.9600","6.7105","292.1686","6.7105","4.4737","69.5639"
"27.0400","6.7303","292.9267","6.7303","4.4869","69.7444"
"27.1200","6.7497","293.6601","6.7497","4.4998","69.9191"
"27.2000","6.7700","294.4347","6.7700","4.5133","70.1035"
"27.2800","6.7892","295.1425","6.7892","4.5261","70.2720"
"27.3600","6.8109","296.0097","6.8109","4.5406","70.4785"
"27.4400","6.8313","296.8018","6.8313","4.5542","70.6671"
"27.5200","6.8503","297.5025","6.8503","4.5669","70.8339"
"27.6000","6.8704","298.2635","6.8704","4.5803","71.0151"
"27.6800","6.8896","298.9610","6.8896","4.5930","71.1812"
"27.7600","6.9104","299.7703","6.9104","4.6070","71.3739"
"27.8400","6.9302","300.5137","6.9302","4.6201","71.5509"
"27.9200","6.9496","301.2131","6.9496","4.6331","71.7174"
"28.0000","6.9705","302.0352","6.9705","4.6470","71.9131"
"28.0800","6.9914","302.8295","6.9914","4.6609","72.1023"
"28.1600","7.0109","303.5518","7.0109","4.6740","72.2743"
"28.2400","7.0309","304.3052","7.0309","4.6873","72.4536"
"28.3200","7.0496","304.9602","7.0496","4.6998","72.6096"
"28.4000","7.0707","305.7770","7.0707","4.7138","72.8040"
"28.4800","7.0903","306.4879","7.0903","4.7268","72.9733"
"28.5600","7.1097","307.2183","7.1097","4.7398","73.1472"
"28.6400","7.1302","307.9850","7.1302","4.7534","73.3298"
"28.7200","7.1509","308.7662","7.1509","4.7672","73.5158"
"28.8000","7.1709","309.5143","7.1709","4.7806","73.6939"
"28.8800","7.1912","310.2625","7.1912","4.7942","73.8720"
"28.9600","7.2096","310.9048","7.2096","4.8064","74.0249"
"29.0400","7.2301","311.6805","7.2301","4.8201","74.2096"
"29.1200","7.2496","312.3732","7.2496","4.8330","74.3746"
"29.2000","7.2699","313.1520","7.2699","4.8466","74.5600"
"29.2800","7.2915","313.9912","7.2915","4.8610","74.7598"
"29.3600","7.3111","314.6878","7.3111","4.8741","74.9257"
"29.4400","7.3313","315.4208","7.3313","4.8875","75.1002"
"29.5200","7.3506","316.1040","7.3506","4.9004","75.2629"
"29.6000","7.3700","316.8007","7.3700","4.9133","75.4287"
"29.6800","7.3901","317.5423","7.3901","4.9267","75.6053"
"29.7600","7.4100","318.2421","7.4100","4.9400","75.7719"
"29.8400","7.4291","318.9008","7.4291","4.9527","75.9288"
"29.9200","7.4512","319.7578","7.4512","4.9675","76.1328"
"30.0000","7.4706","320.4317","7.4706","4.9804","76.2933"
"30.0800","7.4912","321.1810","7.4912","4.9941","76.4717"
"30.1600","7.5106","321.8729","7.5106","5.0071","76.6364"
"30.2400","7.5300","322.5430","7.5300","5.0200","76.7960"
"30.3200","7.5495","323.2345","7.5495","5.0330","76.9606"
"30.4000","7.5695","323.9297","7.5695","5.0463","77.1261"
"30.4800","7.5908","324.7393","7.5908","5.0605","77.3189"
"30.5600","7.6122","325.5206","7.6122","5.0748","77.5049"
"30.6400","7.6312","326.1592","7.6312","5.0874","77.6570"
"30.7200","7.6506","326.8211","7.6506","5.1004","77.8145"
"30.8000","7.6698","327.4904","7.6698","5.1132","77.9739"
"30.8800","7.6906","328.2563","7.6906","5.1271","78.1563"
"30.9600","7.7104","328.9382","7.7104","5.1402","78.3186"
"31.0400","7.7292","329.5679","7.7292","5.1528","78.4685"
"31.1200","7.7504","330.3367","7.7504","5.1669","78.6516"
"31.2000","7.7708","331.0766","7.7708","5.1805","78.8278"
"31.2800","7.7908","331.7828","7.7908","5.1939","78.9959"
"31.3600","7.8109","332.4989","7.8109","5.2072","79.1664"
"31.4400","7.8297","333.0949","7.8297","5.2198","79.3083"
"31.5200","7.8493","333.7879","7.8493","5.2329","79.4733"
"31.6000","7.8709","334.5901","7.8709","5.2472","79.6643"
"31.6800","7.8904","335.2566","7.8904","5.2603","79.8230"
"31.7600","7.9113","336.0085","7.9113","5.2742","80.0020"
"31.8400","7.9308","336.6644","7.9308","5.2872","80.1582"
"31.9200","7.9512","337.3778","7.9512","5.3008","80.3281"
"32.0000","7.9706","338.0421","7.9706","5.3137","80.4862"
"32.0800","7.9903","338.6964","7.9903","5.3268","80.6420"
"32.1600","8.0103","339.3937","8.0103","5.3402","80.8080"
"32.2400","8.0299","340.0498","8.0299","5.3533","80.9642"
"32.3200","8.0495","340.7251","8.0495","5.3663","81.1250"
"32.4000","8.0709","341.5207","8.0709","5.3806","81.3145"
"32.4800","8.0906","342.1636","8.0906","5.3938","81.4675"
"32.5600","8.1114","342.9061","8.1114","5.4076","81.6443"
"32.6400","8.1306","343.5134","8.1306","5.4204","81.7889"
"32.7200","8.1495","344.1350","8.1495","5.4330","81.9369"
"32.8000","8.1690","344.7798","8.1690","5.4460","82.0904"
"32.8800","8.1892","345.4777","8.1892","5.4595","82.2566"
"32.9600","8.2108","346.2601","8.2108","5.4739","82.4429"
"33.0400","8.2321","347.0031","8.2321","5.4881","82.6198"
"33.1200","8.2506","347.5660","8.2506","5.5004","82.7538"
"33.2000","8.2707","348.2406","8.2707","5.5138","82.9144"
"33.2800","8.2906","348.8976","8.2906","5.5271","83.0708"
"33.3600","8.3105","349.5815","8.3105","5.5403","83.2337"
"33.4400","8.3303","350.2204","8.3303","5.5535","83.3858"
"33.5200","8.3489","350.7938","8.3489","5.5659","83.5223"
"33.6000","8.3701","351.5326","8.3701","5.5801","83.6982"
"33.6800","8.3913","352.2814","8.3913","5.5942","83.8765"
"33.7600","8.4112","352.9153","8.4112","5.6075","84.0275"
"33.8400","8.4300","353.4936","8.4300","5.6200","84.1651"
"33.9200","8.4497","354.1362","8.4497","5.6331","84.3182"
"34.0000","8.4697","354.8157","8.4697","5.6464","84.4799"
"34.0800","8.4908","355.5442","8.4908","5.6605","84.6534"
"34.1600","8.5099","356.1377","8.5099","5.6732","84.7947"
"34.2400","8.5309","356.8581","8.5309","5.6873","84.9662"
"34.3200","8.5510","357.5113","8.5510","5.7007","85.1217"
"34.4000","8.5709","358.1552","8.5709","5.7140","85.2751"
"34.4800","8.5907","358.7950","8.5907","5.7271","85.4274"
"34.5600","8.6103","359.4061","8.6103","5.7402","85.5729"
"34.6400","8.6302","360.0523","8.6302","5.7534","85.7267"
"34.7200","8.6503","360.7053","8.6503","5.7669","85.8822"
"34.8000","8.6692","361.2806","8.6692","5.7795","86.0192"
"34.8800","8.6903","362.0046","8.6903","5.7935","86.1916"
"34.9600","8.7109","362.6731","8.7109","5.8073","86.3507"
"35.0400","8.7310","363.3123","8.7310","5.8207","86.5029"
"35.1200","8.7499","363.8605","8.7499","5.8333","86.6335"
"35.2000","8.7693","364.4543","8.7693","5.8462","86.7748"
"35.2800","8.7903","365.1374","8.7903","5.8602","86.9375"
"35.3600","8.8104","365.7699","8.8104","5.8736","87.0881"
"35.4400","8.8302","366.4039","8.8302","5.8868","87.2390"
"35.5200","8.8508","367.0724","8.8508","5.9006","87.3982"
"35.6000","8.8710","367.6871","8.8710","5.9140","87.5445"
"35.6800","8.8914","368.3499","8.8914","5.9276","87.7024"
"35.7600","8.9116","368.9720","8.9116","5.9411","87.8505"
"35.8400","8.9296","369.4782","8.9296","5.9531","87.9710"
"35.9200","8.9498","370.1228","8.9498","5.9666","88.1245"
"36.0000","8.9695","370.7493","8.9695","5.9797","88.2737"
"36.0800","8.9903","371.4267","8.9903","5.9935","88.4349"
"36.1600","9.0107","372.0628","9.0107","6.0071","88.5864"
"36.2400","9.0308","372.6761","9.0308","6.0205","88.7324"
"36.3200","9.0507","373.2772","9.0507","6.0338","88.8755"
"36.4000","9.0707","373.8915","9.0707","6.0471","89.0218"
"36.4800","9.0897","374.4461","9.0897","6.0598","89.1538"
"36.5600","9.1100","375.0845","9.1100","6.0734","89.3058"
"36.6400","9.1294","375.6541","9.1294","6.0863","89.4415"
"36.7200","9.1511","376.3687","9.1511","6.1007","89.6116"
"36.8000","9.1715","377.0070","9.1715","6.1143","89.7636"
"36.8800","9.1912","377.5937","9.1912","6.1275","89.9033"
"36.9600","9.2107","378.1492","9.2107","6.1404","90.0355"
"37.0400","9.2303","378.7309","9.2303","6.1535","90.1740"
"37.1200","9.2502","379.3430","9.2502","6.1668","90.3198"
"37.2000","9.2699","379.9250","9.2699","6.1799","90.4583"
"37.2800","9.2892","380.4807","9.2892","6.1928","90.5906"
"37.3600","9.3103","381.1455","9.3103","6.2069","90.7489"
"37.4400","9.3314","381.7957","9.3314","6.2209","90.9038"
"37.5200","9.3507","382.3474","9.3507","6.2338","91.0351"
"37.6000","9.3702","382.9063","9.3702","6.2468","91.1682"
"37.6800","9.3897","383.4613","9.3897","6.2598","91.3003"
"37.7600","9.4108","384.1303","9.4108","6.2738","91.4596"
"37.8400","9.4304","384.6803","9.4304","6.2869","91.5905"
"37.9200","9.4496","385.2273","9.4496","6.2997","91.7208"
"38.0000","9.4703","385.8597","9.4703","6.3136","91.8714"
"38.0800","9.4915","386.5148","9.4915","6.3277","92.0273"
"38.1600","9.5109","387.0503","9.5109","6.3406","92.1548"
"38.2400","9.5310","387.6322","9.5310","6.3540","92.2934"
"38.3200","9.5495","388.1100","9.5495","6.3663","92.4071"
"38.4000","9.5705","388.7531","9.5705","6.3803","92.5603"
"38.4800","9.5901","389.3081","9.5901","6.3934","92.6924"
"38.5600","9.6100","389.8842","9.6100","6.4066","92.8296"
"38.6400","9.6299","390.4446","9.6299","6.4199","92.9630"
"38.7200","9.6505","391.0559","9.6505","6.4337","93.1085"
"38.8000","9.6708","391.6430","9.6708","6.4472","93.2483"
"38.8800","9.6913","392.2236","9.6913","6.4608","93.3866"
"38.9600","9.7097","392.6856","9.7097","6.4731","93.4966"
"39.0400","9.7301","393.2819","9.7301","6.4867","93.6385"
"39.1200","9.7498","393.8174","9.7498","6.4999","93.7660"
"39.2000","9.7700","394.4233","9.7700","6.5133","93.9103"
"39.2800","9.7916","395.0821","9.7916","6.5277","94.0672"
"39.3600","9.8109","395.5890","9.8109","6.5406","94.1878"
"39.4400","9.8310","396.1468","9.8310","6.5540","94.3207"
"39.5200","9.8504","396.6586","9.8504","6.5670","94.4425"
"39.6000","9.8700","397.2063","9.8700","6.5800","94.5729"
"39.6800","9.8898","397.7558","9.8898","6.5932","94.7038"
"39.7600","9.9097","398.2875","9.9097","6.6065","94.8303"
"39.8400","9.9303","398.8938","9.9303","6.6202","94.9747"
"39.9200","9.9510","399.4706","9.9510","6.6340","95.1120"
"40.0000","9.9700","399.9710","9.9700","6.6467","95.2312"
"40.0800","9.9913","400.6034","9.9913","6.6609","95.3818"
"40.1600","10.0103","401.0766","10.0103","6.6735","95.4944"
"40.2400","10.0303","401.6187","10.0303","6.6869","95.6235"
"40.3200","10.0494","402.0982","10.0494","6.6996","95.7377"
"40.4000","10.0696","402.6363","10.0696","6.7131","95.8658"
"40.4800","10.0908","403.2565","10.0908","6.7272","96.0134"
"40.5600","10.1119","403.8528","10.1119","6.7413","96.1554"
"40.6400","10.1307","404.3030","10.1307","6.7538","96.2626"
"40.7200","10.1505","404.8256","10.1505","6.7670","96.3870"
"40.8000","10.1700","405.3064","10.1700","6.7800","96.5015"
"40.8800","10.1905","405.8904","10.1905","6.7937","96.6406"
"40.9600","10.2101","406.3782","10.2101","6.8068","96.7567"
"41.0400","10.2292","406.8588","10.2292","6.8194","96.8711"
"41.1200","10.2505","407.4665","10.2505","6.8336","97.0158"
"41.2000","10.2710","408.0336","10.2710","6.8473","97.1509"
"41.2800","10.2910","408.5605","10.2910","6.8607","97.2763"
"41.3600","10.3108","409.0631","10.3108","6.8739","97.3960"
"41.4400","10.3299","409.5120","10.3299","6.8866","97.5029"
"41.5200","10.3501","410.0548","10.3501","6.9001","97.6321"
"41.6000","10.3705","410.5863","10.3705","6.9137","97.7586"
"41.6800","10.3899","411.0862","10.3899","6.9266","97.8777"
"41.7600","10.4113","411.6796","10.4113","6.9409","98.0189"
"41.8400","10.4307","412.1400","10.4307","6.9538","98.1286"
"41.9200","10.4510","412.6512","10.4510","6.9674","98.2503"
"42.0000","10.4705","413.1323","10.4705","6.9803","98.3648"
"42.0800","10.4904","413.6375","10.4904","6.9936","98.4851"
"42.1600","10.5104","414.1454","10.5104","7.0069","98.6060"
"42.2400","10.5296","414.5870","10.5296","7.0197","98.7112"
"42.3200","10.5491","415.0909","10.5491","7.0327","98.8312"
"42.4000","10.5707","415.7023","10.5707","7.0472","98.9767"
"42.4800","10.5908","416.1844","10.5908","7.0605","99.0915"
"42.5600","10.6116","416.7212","10.6116","7.0744","99.2193"
"42.6400","10.6307","417.1755","10.6307","7.0871","99.3275"
"42.7200","10.6498","417.6212","10.6498","7.0999","99.4336"
"42.8000","10.6694","418.0991","10.6694","7.1129","99.5474"
"42.8800","10.6898","418.6219","10.6898","7.1266","99.6719"
"42.9600","10.7109","419.1867","10.7109","7.1406","99.8064"
"43.0400","10.7313","419.6910","10.7313","7.1542","99.9264"
"43.1200","10.7506","420.1226","10.7506","7.1671","100.0292"
"43.2000","10.7711","420.6365","10.7711","7.1807","100.1516"
"43.2800","10.7908","421.0944","10.7908","7.1939","100.2606"
"43.3600","10.8102","421.5481","10.8102","7.2068","100.3686"
"43.4400","10.8301","422.0267","10.8301","7.2201","100.4826"
"43.5200","10.8489","422.4205","10.8489","7.2326","100.5763"
"43.6000","10.8708","423.0356","10.8708","7.2472","100.7228"
"43.6800","10.8911","423.5250","10.8911","7.2608","100.8393"
"43.7600","10.9110","423.9763","10.9110","7.2740","100.9467"
"43.8400","10.9303","424.4106","10.9303","7.2869","101.0501"
"43.9200","10.9499","424.8443","10.9499","7.3000","101.1534"
"44.0000","10.9697","425.3216","10.9697","7.3131","101.2670"
"44.0800","10.9907","425.8415","10.9907","7.3271","101.3908"
"44.1600","11.0097","426.2495","11.0097","7.3398","101.4880"
"44.2400","11.0311","426.7892","11.0311","7.3540","101.6165"
"44.3200","11.0507","427.2221","11.0507","7.3671","101.7196"
"44.4000","11.0711","427.7093","11.0711","7.3807","101.8355"
"44.4800","11.0905","428.1285","11.0905","7.3937","101.9353"
"44.5600","11.1102","428.5608","11.1102","7.4068","102.0383"
"44.6400","11.1303","429.0292","11.1303","7.4202","102.1498"
"44.7200","11.1499","429.4641","11.1499","7.4333","102.2534"
"44.8000","11.1689","429.8652","11.1689","7.4460","102.3488"
"44.8800","11.1908","430.4594","11.1908","7.4605","102.4903"
"44.9600","11.2113","430.9067","11.2113","7.4742","102.5968"
"45.0400","11.2311","431.3508","11.2311","7.4874","102.7026"
"45.1200","11.2503","431.7378","11.2503","7.5002","102.7947"
"45.2000","11.2695","432.1396","11.2695","7.5130","102.8904"
"45.2800","11.2903","432.6300","11.2903","7.5268","103.0071"
"45.3600","11.3103","433.0721","11.3103","7.5402","103.1124"
"45.4400","11.3300","433.5156","11.3300","7.5533","103.2180"
"45.5200","11.3508","434.0087","11.3508","7.5672","103.3354"
"45.6000","11.3708","434.4181","11.3708","7.5806","103.4329"
"45.6800","11.3918","434.9333","11.3918","7.5945","103.5556"
"45.7600","11.4113","435.3336","11.4113","7.6076","103.6509"
"45.8400","11.4297","435.6909","11.4297","7.6198","103.7359"
"45.9200","11.4501","436.1504","11.4501","7.6334","103.8453"
"46.0000","11.4692","436.5320","11.4692","7.6461","103.9362"
"46.0800","11.4906","437.0599","11.4906","7.6604","104.0619"
"46.1600","11.5105","437.4994","11.5105","7.6737","104.1665"
"46.2400","11.5310","437.9313","11.5310","7.6873","104.2693"
"46.3200","11.5507","438.3360","11.5507","7.7005","104.3657"
"46.4000","11.5703","438.7303","11.5703","7.7136","104.4596"
"46.4800","11.5894","439.1210","11.5894","7.7263","104.5526"
"46.5600","11.6103","439.6038","11.6103","7.7402","104.6676"
"46.6400","11.6292","439.9459","11.6292","7.7528","104.7490"
"46.7200","11.6506","440.4636","11.6506","7.7671","104.8723"
"46.8000","11.6713","440.9281","11.6713","7.7809","104.9829"
"46.8800","11.6916","441.3529","11.6916","7.7944","105.0840"
"46.9600","11.7108","441.7025","11.7108","7.8072","105.1673"
"47.0400","11.7300","442.0676","11.7300","7.8200","105.2542"
"47.1200","11.7498","442.4768","11.7498","7.8332","105.3516"
"47.2000","11.7701","442.9171","11.7701","7.8467","105.4564"
"47.2800","11.7896","443.2961","11.7896","7.8597","105.5467"
"47.3600","11.8107","443.7837","11.8107","7.8738","105.6628"
"47.4400","11.8314","444.2159","11.8314","7.8876","105.7657"
"47.5200","11.8506","444.5778","11.8506","7.9004","105.8519"
"47.6000","11.8706","444.9679","11.8706","7.9137","105.9447"
"47.6800","11.8894","445.2886","11.8894","7.9263","106.0211"
"47.7600","11.9105","445.7756","11.9105","7.9403","106.1371"
"47.8400","11.9305","446.1601","11.9305","7.9536","106.2286"
"47.9200","11.9501","446.5387","11.9501","7.9668","106.3187"
"48.0000","11.9706","446.9674","11.9706","7.9804","106.4208"
"48.0800","11.9914","447.4014","11.9914","7.9943","106.5241"
"48.1600","12.0111","447.7683","12.0111","8.0074","106.6115"
"48.2400","12.0310","448.1318","12.0310","8.0206","106.6981"
"48.3200","12.0495","448.4136","12.0495","8.0330","106.7652"
"48.4000","12.0707","448.8819","12.0707","8.0471","106.8766"
"48.4800","12.0905","449.2469","12.0905","8.0603","106.9636"
"48.5600","12.1100","449.6029","12.1100","8.0733","107.0483"
"48.6400","12.1300","449.9991","12.1300","8.0866","107.1426"
"48.7200","12.1509","450.4344","12.1509","8.1006","107.2463"
"48.8000","12.1708","450.8045","12.1708","8.1138","107.3344"
"48.8800","12.1909","451.1931","12.1909","8.1273","107.4269"
"48.9600","12.2099","451.5036","12.2099","8.1399","107.5009"
"49.0400","12.2303","451.9002","12.2303","8.1535","107.5953"
"49.1200","12.2497","452.2236","12.2497","8.1664","107.6723"
"49.2000","12.2701","452.6505","12.2701","8.1800","107.7739"
"49.2800","12.2914","453.0966","12.2914","8.1943","107.8801"
"49.3600","12.3109","453.4283","12.3109","8.2073","107.9591"
"49.4400","12.3314","453.7993","12.3314","8.2209","108.0474"
"49.5200","12.3506","454.1321","12.3506","8.2337","108.1267"
"49.6000","12.3701","454.4760","12.3701","8.2467","108.2086"
"49.6800","12.3902","454.8558","12.3902","8.2601","108.2990"
"49.7600","12.4099","455.1799","12.4099","8.2733","108.3762"
"49.8400","12.4298","455.5406","12.4298","8.2865","108.4620"
"49.9200","12.4510","455.9763","12.4510","8.3007","108.5658"
"50.0000","12.4702","456.2892","12.4702","8.3135","108.6403"
"50.0800","12.4913","456.7049","12.4913","8.3275","108.7393"
"50.1600","12.5101","456.9763","12.5101","8.3401","108.8039"
"50.2400","12.5302","457.3485","12.5302","8.3535","108.8925"
"50.3200","12.5495","457.6649","12.5495","8.3663","108.9678"
"50.4000","12.5695","458.0206","12.5695","8.3797","109.0525"
"50.4800","12.5907","458.4501","12.5907","8.3938","109.1548"
"50.5600","12.6120","458.8734","12.6121","8.4080","109.2556"
"50.6400","12.6309","459.1418","12.6309","8.4206","109.3195"
"50.7200","12.6505","459.4637","12.6505","8.4337","109.3961"
"50.8000","12.6696","459.7497","12.6696","8.4464","109.4642"
"50.8800","12.6907","460.1701","12.6907","8.4605","109.5643"
"50.9600","12.7105","460.4859","12.7105","8.4737","109.6395"
"51.0400","12.7293","460.7542","12.7293","8.4862","109.7034"
"51.1200","12.7503","461.1548","12.7503","8.5002","109.7988"
"51.2000","12.7707","461.5163","12.7707","8.5138","109.8848"
"51.2800","12.7908","461.8595","12.7908","8.5272","109.9665"
"51.3600","12.8108","462.2178","12.8108","8.5406","110.0518"
"51.4400","12.8301","462.4792","12.8301","8.5534","110.1141"
"51.5200","12.8500","462.8060","12.8500","8.5667","110.1919"
"51.6000","12.8705","463.1723","12.8705","8.5804","110.2791"
"51.6800","12.8900","463.4716","12.8900","8.5933","110.3504"
"51.7600","12.9112","463.8762","12.9112","8.6074","110.4467"
"51.8400","12.9308","464.1679","12.9308","8.6206","110.5162"
"51.9200","12.9514","464.5200","12.9514","8.6343","110.6000"
"52.0000","12.9705","464.7985","12.9705","8.6470","110.6663"
"52.0800","12.9903","465.1100","12.9903","8.6602","110.7405"
"52.1600","13.0103","465.4253","13.0103","8.6735","110.8155"
"52.2400","13.0303","465.7364","13.0303","8.6868","110.8896"
"52.3200","13.0492","466.0167","13.0492","8.6995","110.9564"
"52.4000","13.0704","466.4273","13.0704","8.7136","111.0541"
"52.4800","13.0907","466.7448","13.0907","8.7272","111.1297"
"52.5600","13.1114","467.0839","13.1114","8.7409","111.2105"
"52.6400","13.1309","467.3553","13.1309","8.7540","111.2751"
"52.7200","13.1495","467.5863","13.1495","8.7663","111.3301"
"52.8000","13.1693","467.8848","13.1693","8.7795","111.4011"
"52.8800","13.1898","468.2304","13.1898","8.7932","111.4834"
"52.9600","13.2108","468.5868","13.2108","8.8072","111.5683"
"53.0400","13.2320","468.9515","13.2320","8.8213","111.6551"
"53.1200","13.2509","469.1669","13.2509","8.8339","111.7064"
"53.2000","13.2707","469.4641","13.2707","8.8471","111.7772"
"53.2800","13.2906","469.7405","13.2906","8.8604","111.8430"
"53.3600","13.3105","470.0666","13.3105","8.8737","111.9206"
"53.4400","13.3305","470.3724","13.3305","8.8870","111.9934"
"53.5200","13.3489","470.5667","13.3489","8.8993","112.0397"
"53.6000","13.3705","470.9609","13.3705","8.9137","112.1335"
"53.6800","13.3914","471.2982","13.3914","8.9276","112.2139"
"53.7600","13.4111","471.5523","13.4111","8.9408","112.2743"
"53.8400","13.4301","471.7821","13.4301","8.9534","112.3291"
"53.9200","13.4500","472.0683","13.4500","8.9666","112.3972"
"54.0000","13.4699","472.3685","13.4699","8.9799","112.4687"
"54.0800","13.4907","472.6924","13.4907","8.9938","112.5458"
"54.1600","13.5095","472.9076","13.5095","9.0064","112.5970"
"54.2400","13.5311","473.2837","13.5311","9.0208","112.6866"
"54.3200","13.5511","473.5495","13.5511","9.0341","112.7499"
"54.4000","13.5708","473.8175","13.5708","9.0472","112.8137"
"54.4800","13.5906","474.0722","13.5906","9.0604","112.8743"
"54.5600","13.6103","474.3385","13.6103","9.0736","112.9377"
"54.6400","13.6301","474.6048","13.6301","9.0868","113.0012"
"54.7200","13.6504","474.8989","13.6504","9.1003","113.0712"
"54.8000","13.6694","475.1275","13.6694","9.1129","113.1256"
"54.8800","13.6906","475.4803","13.6906","9.1271","113.2096"
"54.9600","13.7109","475.7415","13.7109","9.1406","113.2718"
"55.0400","13.7310","476.0172","13.7310","9.1540","113.3374"
"55.1200","13.7504","476.2389","13.7504","9.1669","113.3902"
"55.2000","13.7695","476.4459","13.7695","9.1796","113.4395"
"55.2800","13.7902","476.7413","13.7902","9.1934","113.5098"
"55.3600","13.8101","476.9976","13.8101","9.2067","113.5708"
"55.4400","13.8297","477.2513","13.8297","9.2198","113.6312"
"55.5200","13.8508","477.5761","13.8508","9.2339","113.7086"
"55.6000","13.8712","477.8145","13.8712","9.2474","113.7654"
"55.6800","13.8915","478.0765","13.8915","9.2610","113.8277"
"55.7600","13.9113","478.3103","13.9113","9.2742","113.8834"
"55.8400","13.9298","478.4616","13.9298","9.2865","113.9194"
"55.9200","13.9501","478.7008","13.9501","9.3001","113.9764"
"56.0000","13.9694","478.8837","13.9694","9.3129","114.0199"
"56.0800","13.9902","479.1927","13.9902","9.3268","114.0935"
"56.1600","14.0111","479.4892","14.0111","9.3407","114.1641"
"56.2400","14.0308","479.6856","14.0308","9.3539","114.2109"
"56.3200","14.0507","479.8966","14.0507","9.3671","114.2611"
"56.4000","14.0705","480.1084","14.0705","9.3803","114.3115"
"56.4800","14.0897","480.3079","14.0897","9.3932","114.3590"
"56.5600","14.1100","480.5627","14.1100","9.4067","114.4197"
"56.6400","14.1296","480.7545","14.1296","9.4197","114.4654"
"56.7200","14.1507","481.0441","14.1507","9.4338","114.5343"
"56.8000","14.1716","481.3055","14.1716","9.4477","114.5966"
"56.8800","14.1911","481.5013","14.1911","9.4608","114.6432"
"56.9600","14.2107","481.6833","14.2107","9.4738","114.6865"
"57.0400","14.2301","481.8717","14.2301","9.4867","114.7314"
"57.1200","14.2500","482.0934","14.2500","9.5000","114.7842"
"57.2000","14.2699","482.3195","14.2699","9.5133","114.8380"
"57.2800","14.2893","482.4795","14.2893","9.5262","114.8761"
"57.3600","14.3102","482.7605","14.3102","9.5401","114.9430"
"57.4400","14.3314","483.0155","14.3314","9.5543","115.0037"
"57.5200","14.3505","483.1704","14.3505","9.5670","115.0406"
"57.6000","14.3703","483.3654","14.3703","9.5802","115.0870"
"57.6800","14.3898","483.5463","14.3898","9.5932","115.1301"
"57.7600","14.4106","483.7996","14.4106","9.6071","115.1904"
"57.8400","14.4300","483.9510","14.4300","9.6200","115.2264"
"57.9200","14.4491","484.1086","14.4491","9.6327","115.2639"
"58.0000","14.4707","484.3782","14.4707","9.6471","115.3281"
"58.0800","14.4918","484.6092","14.4918","9.6612","115.3831"
"58.1600","14.5115","484.7778","14.5115","9.6743","115.4233"
"58.2400","14.5303","484.8805","14.5303","9.6869","115.4477"
"58.3200","14.5496","485.0077","14.5496","9.6997","115.4780"
"58.4000","14.5702","485.2204","14.5702","9.7134","115.5287"
"58.4800","14.5905","485.4073","14.5905","9.7270","115.5732"
"58.5600","14.6100","485.5603","14.6100","9.7400","115.6096"
"58.6400","14.6300","485.7264","14.6300","9.7533","115.6491"
"58.7200","14.6505","485.9126","14.6505","9.7670","115.6935"
"58.8000","14.6709","486.1060","14.6709","9.7806","115.7395"
"58.8800","14.6912","486.2664","14.6912","9.7941","115.7777"
"58.9600","14.7100","486.3688","14.7100","9.8067","115.8021"
"59.0400","14.7299","486.5140","14.7299","9.8199","115.8367"
"59.1200","14.7498","486.6648","14.7498","9.8332","115.8726"
"59.2000","14.7702","486.8791","14.7702","9.8468","115.9236"
"59.2800","14.7914","487.1011","14.7914","9.8609","115.9765"
"59.3600","14.8112","487.2330","14.8112","9.8741","116.0079"
"59.4400","14.8312","487.3817","14.8312","9.8875","116.0433"
"59.5200","14.8508","487.5152","14.8508","9.9005","116.0751"
"59.6000","14.8700","487.6375","14.8700","9.9134","116.1042"
"59.6800","14.8901","487.8025","14.8901","9.9267","116.1435"
"59.7600","14.9098","487.9183","14.9098","9.9399","116.1710"
"59.8400","14.9301","488.1017","14.9301","9.9534","116.2147"
"59.9200","14.9508","488.2791","14.9508","9.9672","116.2569"
"60.0000","14.9702","488.3773","14.9702","9.9801","116.2803"
"60.0800","14.9913","488.5592","14.9913","9.9942","116.3236"
"60.1170","15.0002","488.6050","15.0002","10.0002","116.3345"