File: data/instron_tests/metamaterial_samples/509_NS_m1.is_comp_Exports/509_NS_m1_2_1.csv
Sample text inputs : Sample No.,Sample choice input : Leading Direction,Sample choice input : Mode,Specimen choice input : Direction,Specimen properties : Height,Specimen properties : Thickness,Specimen properties : Width,Test : Rate 1
,,,,(mm),(mm),(mm),(mm/min)
"509","Normal-Shear","Unimode","1","150.00","25.00","150.00","15.00"

Time,Displacement,Compressive displacement,Compressive strain (Displacement),Compressive stress,Force
(s),(mm),(mm),(%),(kPa),(N)
"0.0000","-0.0001","-0.0001","-0.0001","-0.9338","-3.4552"
"0.0800","0.0012","0.0012","0.0008","-0.9240","-3.4189"
"0.1600","0.0097","0.0097","0.0065","-0.8789","-3.2520"
"0.2400","0.0296","0.0296","0.0198","-0.7868","-2.9112"
"0.3200","0.0498","0.0498","0.0332","-0.7001","-2.5905"
"0.4000","0.0683","0.0683","0.0455","-0.6285","-2.3253"
"0.4800","0.0886","0.0886","0.0590","-0.5568","-2.0603"
"0.5600","0.1096","0.1096","0.0731","-0.4888","-1.8085"
"0.6400","0.1294","0.1294","0.0863","-0.4303","-1.5922"
"0.7200","0.1493","0.1493","0.0996","-0.3709","-1.3724"
"0.8000","0.1686","0.1686","0.1124","-0.3160","-1.1692"
"0.8800","0.1897","0.1897","0.1264","-0.2507","-0.9276"
"0.9600","0.2100","0.2100","0.1400","-0.1898","-0.7022"
"1.0400","0.2292","0.2292","0.1528","-0.1321","-0.4887"
"1.1200","0.2497","0.2497","0.1665","-0.0677","-0.2505"
"1.2000","0.2700","0.2700","0.1800","-0.0095","-0.0353"
"1.2800","0.2907","0.2907","0.1938","0.0429","0.1586"
"1.3600","0.3101","0.3101","0.2067","0.1005","0.3719"
"1.4400","0.3285","0.3285","0.2190","0.1564","0.5787"
"1.5200","0.3489","0.3489","0.2326","0.2211","0.8181"
"1.6000","0.3689","0.3689","0.2459","0.2775","1.0266"
"1.6800","0.3894","0.3894","0.2596","0.3320","1.2284"
"1.7600","0.4106","0.4106","0.2737","0.4011","1.4841"
"1.8400","0.4290","0.4290","0.2860","0.4529","1.6758"
"1.9200","0.4498","0.4498","0.2999","0.5185","1.9184"
"2.0000","0.4696","0.4696","0.3131","0.5843","2.1618"
"2.0800","0.4892","0.4892","0.3261","0.6521","2.4129"
"2.1600","0.5094","0.5094","0.3396","0.7188","2.6597"
"2.2400","0.5289","0.5289","0.3526","0.7849","2.9043"
"2.3200","0.5493","0.5493","0.3662","0.8563","3.1684"
"2.4000","0.5710","0.5710","0.3807","0.9377","3.4695"
"2.4800","0.5901","0.5901","0.3934","1.0078","3.7288"
"2.5600","0.6098","0.6098","0.4065","1.0823","4.0046"
"2.6400","0.6289","0.6289","0.4193","1.1544","4.2714"
"2.7200","0.6486","0.6486","0.4324","1.2352","4.5702"
"2.8000","0.6692","0.6692","0.4462","1.3169","4.8725"
"2.8800","0.6885","0.6885","0.4590","1.3982","5.1733"
"2.9600","0.7097","0.7097","0.4732","1.4832","5.4879"
"3.0400","0.7304","0.7304","0.4869","1.5735","5.8221"
"3.1200","0.7494","0.7494","0.4996","1.6521","6.1126"
"3.2000","0.7697","0.7697","0.5131","1.7418","6.4446"
"3.2800","0.7893","0.7893","0.5262","1.8217","6.7402"
"3.3600","0.8098","0.8098","0.5399","1.9165","7.0911"
"3.4400","0.8298","0.8298","0.5532","2.0050","7.4185"
"3.5200","0.8487","0.8487","0.5658","2.0938","7.7470"
"3.6000","0.8705","0.8705","0.5803","2.1953","8.1226"
"3.6800","0.8903","0.8903","0.5936","2.2886","8.4679"
"3.7600","0.9104","0.9104","0.6069","2.3824","8.8150"
"3.8400","0.9296","0.9296","0.6198","2.4690","9.1352"
"3.9200","0.9489","0.9489","0.6326","2.5633","9.4842"
"4.0000","0.9696","0.9696","0.6464","2.6557","9.8261"
"4.0800","0.9896","0.9896","0.6597","2.7587","10.2073"
"4.1600","1.0082","1.0082","0.6721","2.8513","10.5498"
"4.2400","1.0292","1.0292","0.6861","2.9597","10.9509"
"4.3200","1.0495","1.0495","0.6997","3.0642","11.3374"
"4.4000","1.0703","1.0703","0.7135","3.1719","11.7359"
"4.4800","1.0902","1.0902","0.7268","3.2771","12.1254"
"4.5600","1.1086","1.1086","0.7391","3.3720","12.4765"
"4.6400","1.1291","1.1291","0.7527","3.4822","12.8841"
"4.7200","1.1494","1.1494","0.7662","3.5977","13.3115"
"4.8000","1.1698","1.1698","0.7798","3.7091","13.7238"
"4.8800","1.1910","1.1910","0.7940","3.8365","14.1950"
"4.9600","1.2097","1.2097","0.8064","3.9347","14.5585"
"5.0400","1.2298","1.2298","0.8199","4.0512","14.9893"
"5.1200","1.2500","1.2500","0.8333","4.1654","15.4122"
"5.2000","1.2690","1.2690","0.8460","4.2755","15.8195"
"5.2800","1.2892","1.2892","0.8595","4.3952","16.2622"
"5.3600","1.3085","1.3085","0.8723","4.5061","16.6726"
"5.4400","1.3289","1.3289","0.8859","4.6289","17.1271"
"5.5200","1.3499","1.3499","0.8999","4.7573","17.6022"
"5.6000","1.3698","1.3698","0.9132","4.8755","18.0393"
"5.6800","1.3901","1.3901","0.9267","5.0005","18.5018"
"5.7600","1.4099","1.4099","0.9399","5.1165","18.9309"
"5.8400","1.4289","1.4289","0.9526","5.2325","19.3601"
"5.9200","1.4495","1.4495","0.9664","5.3662","19.8551"
"6.0000","1.4686","1.4686","0.9791","5.4833","20.2881"
"6.0800","1.4904","1.4904","0.9936","5.6226","20.8036"
"6.1600","1.5107","1.5107","1.0071","5.7543","21.2908"
"6.2400","1.5299","1.5299","1.0199","5.8767","21.7436"
"6.3200","1.5493","1.5493","1.0329","6.0032","22.2117"
"6.4000","1.5695","1.5695","1.0464","6.1375","22.7088"
"6.4800","1.5894","1.5894","1.0596","6.2623","23.1705"
"6.5600","1.6095","1.6095","1.0730","6.3993","23.6773"
"6.6400","1.6281","1.6281","1.0854","6.5245","24.1407"
"6.7200","1.6497","1.6497","1.0998","6.6747","24.6964"
"6.8000","1.6708","1.6708","1.1139","6.8140","25.2117"
"6.8800","1.6895","1.6895","1.1263","6.9350","25.6595"
"6.9600","1.7091","1.7091","1.1394","7.0702","26.1599"
"7.0400","1.7288","1.7288","1.1525","7.2077","26.6684"
"7.1200","1.7497","1.7497","1.1665","7.3598","27.2314"
"7.2000","1.7698","1.7698","1.1798","7.5023","27.7585"
"7.2800","1.7894","1.7894","1.1929","7.6355","28.2513"
"7.3600","1.8100","1.8100","1.2067","7.7871","28.8121"
"7.4400","1.8302","1.8302","1.2201","7.9285","29.3354"
"7.5200","1.8500","1.8500","1.2333","8.0750","29.8774"
"7.6000","1.8700","1.8700","1.2467","8.2208","30.4169"
"7.6800","1.8888","1.8888","1.2592","8.3564","30.9186"
"7.7600","1.9096","1.9096","1.2731","8.5043","31.4660"
"7.8400","1.9288","1.9288","1.2858","8.6467","31.9929"
"7.9200","1.9483","1.9483","1.2989","8.7929","32.5337"
"8.0000","1.9690","1.9690","1.3127","8.9504","33.1164"
"8.0800","1.9903","1.9903","1.3268","9.1084","33.7010"
"8.1600","2.0101","2.0101","1.3400","9.2610","34.2657"
"8.2400","2.0300","2.0300","1.3533","9.4036","34.7934"
"8.3200","2.0484","2.0484","1.3656","9.5429","35.3088"
"8.4000","2.0692","2.0692","1.3795","9.7047","35.9074"
"8.4800","2.0894","2.0894","1.3929","9.8582","36.4752"
"8.5600","2.1104","2.1104","1.4069","10.0182","37.0672"
"8.6400","2.1308","2.1308","1.4205","10.1723","37.6373"
"8.7200","2.1494","2.1494","1.4329","10.3132","38.1588"
"8.8000","2.1700","2.1700","1.4467","10.4713","38.7438"
"8.8800","2.1899","2.1899","1.4600","10.6258","39.3156"
"8.9600","2.2092","2.2092","1.4728","10.7750","39.8675"
"9.0400","2.2289","2.2289","1.4859","10.9261","40.4266"
"9.1200","2.2485","2.2485","1.4990","11.0744","40.9753"
"9.2000","2.2696","2.2696","1.5131","11.2410","41.5916"
"9.2800","2.2908","2.2908","1.5272","11.4081","42.2100"
"9.3600","2.3095","2.3095","1.5397","11.5528","42.7455"
"9.4400","2.3298","2.3298","1.5532","11.7090","43.3234"
"9.5200","2.3487","2.3487","1.5658","11.8554","43.8649"
"9.6000","2.3696","2.3696","1.5798","12.0205","44.4757"
"9.6800","2.3898","2.3898","1.5932","12.1782","45.0592"
"9.7600","2.4092","2.4092","1.6062","12.3259","45.6058"
"9.8400","2.4295","2.4295","1.6197","12.4879","46.2053"
"9.9200","2.4506","2.4506","1.6337","12.6554","46.8251"
"10.0000","2.4699","2.4699","1.6466","12.8053","47.3795"
"10.0800","2.4902","2.4902","1.6601","12.9715","47.9946"
"10.1600","2.5094","2.5094","1.6729","13.1188","48.5395"
"10.2400","2.5296","2.5296","1.6864","13.2801","49.1365"
"10.3200","2.5484","2.5484","1.6989","13.4255","49.6742"
"10.4000","2.5679","2.5679","1.7120","13.5794","50.2437"
"10.4800","2.5900","2.5900","1.7267","13.7625","50.9213"
"10.5600","2.6107","2.6107","1.7404","13.9256","51.5245"
"10.6400","2.6297","2.6297","1.7532","14.0731","52.0706"
"10.7200","2.6495","2.6495","1.7663","14.2324","52.6599"
"10.8000","2.6683","2.6683","1.7789","14.3818","53.2128"
"10.8800","2.6896","2.6896","1.7931","14.5560","53.8570"
"10.9600","2.7099","2.7099","1.8066","14.7186","54.4588"
"11.0400","2.7291","2.7291","1.8194","14.8713","55.0239"
"11.1200","2.7501","2.7501","1.8334","15.0468","55.6730"
"11.2000","2.7700","2.7700","1.8467","15.2052","56.2592"
"11.2800","2.7906","2.7906","1.8604","15.3702","56.8696"
"11.3600","2.8099","2.8099","1.8732","15.5233","57.4362"
"11.4400","2.8291","2.8291","1.8860","15.6764","58.0029"
"11.5200","2.8488","2.8488","1.8992","15.8408","58.6110"
"11.6000","2.8690","2.8690","1.9127","16.0006","59.2022"
"11.6800","2.8891","2.8891","1.9261","16.1676","59.8199"
"11.7600","2.9107","2.9107","1.9405","16.3458","60.4795"
"11.8400","2.9293","2.9293","1.9529","16.4900","61.0129"
"11.9200","2.9499","2.9499","1.9666","16.6555","61.6252"
"12.0000","2.9693","2.9693","1.9796","16.8126","62.2067"
"12.0800","2.9893","2.9893","1.9929","16.9759","62.8109"
"12.1600","3.0092","3.0092","2.0061","17.1388","63.4135"
"12.2400","3.0291","3.0291","2.0194","17.2979","64.0024"
"12.3200","3.0495","3.0495","2.0330","17.4660","64.6241"
"12.4000","3.0710","3.0710","2.0474","17.6472","65.2945"
"12.4800","3.0901","3.0901","2.0601","17.8006","65.8621"
"12.5600","3.1103","3.1103","2.0735","17.9653","66.4717"
"12.6400","3.1291","3.1291","2.0861","18.1108","67.0101"
"12.7200","3.1488","3.1488","2.0992","18.2724","67.6079"
"12.8000","3.1692","3.1692","2.1128","18.4396","68.2264"
"12.8800","3.1889","3.1889","2.1260","18.6050","68.8384"
"12.9600","3.2100","3.2100","2.1400","18.7765","69.4729"
"13.0400","3.2301","3.2301","2.1534","18.9389","70.0741"
"13.1200","3.2496","3.2496","2.1664","19.0954","70.6531"
"13.2000","3.2698","3.2698","2.1798","19.2628","71.2722"
"13.2800","3.2898","3.2898","2.1932","19.4216","71.8600"
"13.3600","3.3096","3.3096","2.2064","19.5805","72.4479"
"13.4400","3.3294","3.3294","2.2196","19.7393","73.0354"
"13.5200","3.3489","3.3489","2.2326","19.8981","73.6230"
"13.6000","3.3702","3.3702","2.2468","20.0728","74.2694"
"13.6800","3.3903","3.3903","2.2602","20.2365","74.8750"
"13.7600","3.4102","3.4102","2.2735","20.3981","75.4729"
"13.8400","3.4295","3.4295","2.2863","20.5506","76.0372"
"13.9200","3.4488","3.4488","2.2992","20.7063","76.6134"
"14.0000","3.4695","3.4695","2.3130","20.8745","77.2358"
"14.0800","3.4896","3.4896","2.3264","21.0345","77.8276"
"14.1600","3.5081","3.5081","2.3387","21.1842","78.3814"
"14.2400","3.5293","3.5293","2.3529","21.3579","79.0241"
"14.3200","3.5496","3.5496","2.3664","21.5219","79.6310"
"14.4000","3.5703","3.5703","2.3802","21.6894","80.2508"
"14.4800","3.5900","3.5900","2.3933","21.8475","80.8359"
"14.5600","3.6089","3.6089","2.4059","22.0001","81.4004"
"14.6400","3.6294","3.6294","2.4196","22.1722","82.0372"
"14.7200","3.6492","3.6492","2.4328","22.3308","82.6239"
"14.8000","3.6692","3.6692","2.4461","22.4926","83.2228"
"14.8800","3.6905","3.6905","2.4603","22.6637","83.8559"
"14.9600","3.7099","3.7099","2.4733","22.8138","84.4109"
"15.0400","3.7302","3.7302","2.4868","22.9809","85.0294"
"15.1200","3.7498","3.7498","2.4999","23.1336","85.5942"
"15.2000","3.7688","3.7688","2.5125","23.2875","86.1638"
"15.2800","3.7895","3.7895","2.5263","23.4573","86.7921"
"15.3600","3.8085","3.8085","2.5390","23.6037","87.3336"
"15.4400","3.8292","3.8292","2.5528","23.7703","87.9502"
"15.5200","3.8496","3.8496","2.5664","23.9360","88.5632"
"15.6000","3.8698","3.8698","2.5798","24.0951","89.1520"
"15.6800","3.8900","3.8900","2.5933","24.2575","89.7529"
"15.7600","3.9096","3.9096","2.6064","24.4126","90.3265"
"15.8400","3.9288","3.9288","2.6192","24.5630","90.8833"
"15.9200","3.9493","3.9493","2.6329","24.7287","91.4963"
"16.0000","3.9688","3.9688","2.6459","24.8835","92.0690"
"16.0800","3.9903","3.9903","2.6602","25.0584","92.7160"
"16.1600","4.0104","4.0104","2.6736","25.2166","93.3014"
"16.2400","4.0299","4.0299","2.6866","25.3720","93.8762"
"16.3200","4.0496","4.0496","2.6997","25.5294","94.4587"
"16.4000","4.0694","4.0694","2.7129","25.6829","95.0267"
"16.4800","4.0894","4.0894","2.7263","25.8419","95.6151"
"16.5600","4.1095","4.1095","2.7397","26.0032","96.2120"
"16.6400","4.1284","4.1284","2.7523","26.1492","96.7519"
"16.7200","4.1496","4.1496","2.7664","26.3246","97.4010"
"16.8000","4.1701","4.1701","2.7800","26.4852","97.9952"
"16.8800","4.1899","4.1899","2.7933","26.6414","98.5733"
"16.9600","4.2099","4.2099","2.8066","26.7970","99.1489"
"17.0400","4.2285","4.2285","2.8190","26.9382","99.6714"
"17.1200","4.2494","4.2494","2.8329","27.1058","100.2914"
"17.2000","4.2699","4.2699","2.8466","27.2685","100.8936"
"17.2800","4.2893","4.2893","2.8595","27.4194","101.4519"
"17.3600","4.3102","4.3102","2.8734","27.5871","102.0723"
"17.4400","4.3303","4.3303","2.8869","27.7485","102.6694"
"17.5200","4.3498","4.3498","2.8999","27.8993","103.2275"
"17.6000","4.3700","4.3700","2.9133","28.0563","103.8083"
"17.6800","4.3886","4.3886","2.9258","28.1990","104.3363"
"17.7600","4.4092","4.4092","2.9395","28.3595","104.9300"
"17.8400","4.4287","4.4287","2.9525","28.5075","105.4778"
"17.9200","4.4488","4.4488","2.9658","28.6652","106.0612"
"18.0000","4.4699","4.4699","2.9799","28.8337","106.6846"
"18.0800","4.4900","4.4900","2.9933","28.9896","107.2616"
"18.1600","4.5097","4.5097","3.0065","29.1412","107.8225"
"18.2400","4.5298","4.5298","3.0199","29.2972","108.3995"
"18.3200","4.5485","4.5485","3.0323","29.4410","108.9318"
"18.4000","4.5694","4.5694","3.0463","29.6064","109.5437"
"18.4800","4.5890","4.5890","3.0593","29.7567","110.0999"
"18.5600","4.6099","4.6099","3.0733","29.9185","110.6985"
"18.6400","4.6306","4.6306","3.0870","30.0804","111.2973"
"18.7200","4.6499","4.6499","3.0999","30.2276","111.8421"
"18.8000","4.6698","4.6698","3.1132","30.3783","112.3999"
"18.8800","4.6896","4.6896","3.1264","30.5329","112.9718"
"18.9600","4.7092","4.7092","3.1395","30.6830","113.5273"
"19.0400","4.7290","4.7290","3.1526","30.8382","114.1014"
"19.1200","4.7486","4.7486","3.1658","30.9870","114.6520"
"19.2000","4.7690","4.7690","3.1793","31.1449","115.2361"
"19.2800","4.7907","4.7907","3.1938","31.3131","115.8583"
"19.3600","4.8097","4.8097","3.2064","31.4569","116.3907"
"19.4400","4.8297","4.8297","3.2198","31.6079","116.9491"
"19.5200","4.8487","4.8487","3.2325","31.7523","117.4837"
"19.6000","4.8694","4.8694","3.2463","31.9115","118.0727"
"19.6800","4.8896","4.8896","3.2598","32.0671","118.6484"
"19.7600","4.9089","4.9089","3.2726","32.2113","119.1819"
"19.8400","4.9298","4.9298","3.2865","32.3727","119.7789"
"19.9200","4.9503","4.9503","3.3002","32.5259","120.3458"
"20.0000","4.9698","4.9698","3.3132","32.6752","120.8981"
"20.0800","4.9904","4.9904","3.3269","32.8313","121.4759"
"20.1600","5.0091","5.0091","3.3394","32.9671","121.9783"
"20.2400","5.0290","5.0290","3.3527","33.1180","122.5366"
"20.3200","5.0492","5.0492","3.3661","33.2706","123.1014"
"20.4000","5.0683","5.0683","3.3789","33.4155","123.6372"
"20.4800","5.0896","5.0896","3.3931","33.5809","124.2494"
"20.5600","5.1102","5.1102","3.4068","33.7371","124.8271"
"20.6400","5.1297","5.1297","3.4198","33.8803","125.3572"
"20.7200","5.1498","5.1498","3.4332","34.0314","125.9163"
"20.8000","5.1684","5.1684","3.4456","34.1658","126.4135"
"20.8800","5.1898","5.1898","3.4599","34.3302","127.0219"
"20.9600","5.2099","5.2099","3.4732","34.4769","127.5646"
"21.0400","5.2289","5.2289","3.4859","34.6211","128.0982"
"21.1200","5.2500","5.2500","3.5000","34.7822","128.6941"
"21.2000","5.2701","5.2701","3.5134","34.9332","129.2527"
"21.2800","5.2906","5.2906","3.5271","35.0864","129.8195"
"21.3600","5.3099","5.3099","3.5400","35.2246","130.3310"
"21.4400","5.3287","5.3287","3.5525","35.3647","130.8495"
"21.5200","5.3488","5.3488","3.5659","35.5157","131.4081"
"21.6000","5.3691","5.3691","3.5794","35.6661","131.9645"
"21.6800","5.3892","5.3892","3.5928","35.8183","132.5276"
"21.7600","5.4104","5.4104","3.6069","35.9773","133.1160"
"21.8400","5.4292","5.4292","3.6195","36.1113","133.6118"
"21.9200","5.4499","5.4499","3.6333","36.2661","134.1847"
"22.0000","5.4695","5.4695","3.6463","36.4109","134.7203"
"22.0800","5.4896","5.4896","3.6597","36.5629","135.2828"
"22.1600","5.5094","5.5094","3.6729","36.7074","135.8174"
"22.2400","5.5290","5.5290","3.6860","36.8473","136.3349"
"22.3200","5.5492","5.5492","3.6995","36.9973","136.8900"
"22.4000","5.5709","5.5709","3.7139","37.1592","137.4890"
"22.4800","5.5900","5.5900","3.7267","37.2963","137.9962"
"22.5600","5.6101","5.6101","3.7401","37.4430","138.5390"
"22.6400","5.6289","5.6289","3.7526","37.5745","139.0258"
"22.7200","5.6490","5.6490","3.7660","37.7260","139.5862"
"22.8000","5.6697","5.6697","3.7798","37.8776","140.1472"
"22.8800","5.6884","5.6884","3.7923","38.0117","140.6433"
"22.9600","5.7096","5.7096","3.8064","38.1678","141.2209"
"23.0400","5.7302","5.7302","3.8202","38.3192","141.7809"
"23.1200","5.7496","5.7496","3.8331","38.4573","142.2922"
"23.2000","5.7697","5.7697","3.8464","38.6070","142.8458"
"23.2800","5.7895","5.7895","3.8596","38.7478","143.3669"
"23.3600","5.8093","5.8093","3.8729","38.8939","143.9075"
"23.4400","5.8300","5.8300","3.8867","39.0425","144.4571"
"23.5200","5.8485","5.8485","3.8990","39.1752","144.9482"
"23.6000","5.8700","5.8700","3.9133","39.3320","145.5284"
"23.6800","5.8906","5.8906","3.9271","39.4848","146.0936"
"23.7600","5.9105","5.9105","3.9404","39.6233","146.6061"
"23.8400","5.9297","5.9297","3.9531","39.7605","147.1139"
"23.9200","5.9491","5.9491","3.9660","39.8970","147.6189"
"24.0000","5.9695","5.9695","3.9797","40.0449","148.1661"
"24.0800","5.9896","5.9896","3.9931","40.1869","148.6915"
"24.1600","6.0082","6.0082","4.0055","40.3195","149.1823"
"24.2400","6.0296","6.0296","4.0197","40.4755","149.7595"
"24.3200","6.0496","6.0496","4.0331","40.6170","150.2830"
"24.4000","6.0706","6.0706","4.0471","40.7664","150.8357"
"24.4800","6.0901","6.0901","4.0601","40.9017","151.3363"
"24.5600","6.1088","6.1088","4.0726","41.0304","151.8125"
"24.6400","6.1290","6.1290","4.0860","41.1745","152.3456"
"24.7200","6.1491","6.1491","4.0994","41.3170","152.8729"
"24.8000","6.1697","6.1697","4.1131","41.4643","153.4179"
"24.8800","6.1910","6.1910","4.1273","41.6220","154.0014"
"24.9600","6.2101","6.2101","4.1401","41.7528","154.4853"
"25.0400","6.2299","6.2299","4.1533","41.8891","154.9898"
"25.1200","6.2498","6.2498","4.1665","42.0292","155.5082"
"25.2000","6.2687","6.2687","4.1791","42.1592","155.9889"
"25.2800","6.2895","6.2895","4.1930","42.3076","156.5383"
"25.3600","6.3085","6.3085","4.2057","42.4373","157.0180"
"25.4400","6.3288","6.3288","4.2192","42.5778","157.5379"
"25.5200","6.3496","6.3496","4.2330","42.7226","158.0736"
"25.6000","6.3698","6.3698","4.2466","42.8666","158.6064"
"25.6800","6.3900","6.3900","4.2600","43.0071","159.1262"
"25.7600","6.4094","6.4094","4.2730","43.1378","159.6100"
"25.8400","6.4284","6.4284","4.2856","43.2684","160.0930"
"25.9200","6.4495","6.4495","4.2997","43.4159","160.6388"
"26.0000","6.4689","6.4689","4.3126","43.5453","161.1176"
"26.0800","6.4905","6.4905","4.3270","43.6993","161.6873"
"26.1600","6.5107","6.5107","4.3405","43.8400","162.2080"
"26.2400","6.5300","6.5300","4.3533","43.9708","162.6920"
"26.3200","6.5492","6.5492","4.3662","44.0983","163.1635"
"26.4000","6.5694","6.5694","4.3796","44.2415","163.6937"
"26.4800","6.5897","6.5897","4.3931","44.3839","164.2205"
"26.5600","6.6098","6.6098","4.4065","44.5219","164.7310"
"26.6400","6.6284","6.6284","4.4189","44.6443","165.1837"
"26.7200","6.6496","6.6496","4.4331","44.7901","165.7233"
"26.8000","6.6703","6.6703","4.4469","44.9346","166.2580"
"26.8800","6.6898","6.6898","4.4599","45.0667","166.7468"
"26.9600","6.7091","6.7091","4.4727","45.1951","167.2218"
"27.0400","6.7285","6.7285","4.4857","45.3237","167.6977"
"27.1200","6.7495","6.7495","4.4997","45.4719","168.2460"
"27.2000","6.7700","6.7700","4.5133","45.6096","168.7557"
"27.2800","6.7896","6.7896","4.5264","45.7431","169.2493"
"27.3600","6.8102","6.8102","4.5401","45.8835","169.7689"
"27.4400","6.8299","6.8299","4.5533","46.0105","170.2388"
"27.5200","6.8497","6.8497","4.5665","46.1441","170.7331"
"27.6000","6.8702","6.8702","4.5801","46.2787","171.2312"
"27.6800","6.8888","6.8888","4.5925","46.3992","171.6772"
"27.7600","6.9097","6.9097","4.6065","46.5416","172.2038"
"27.8400","6.9287","6.9287","4.6191","46.6693","172.6766"
"27.9200","6.9488","6.9488","4.6325","46.8048","173.1777"
"28.0000","6.9698","6.9698","4.6465","46.9471","173.7044"
"28.0800","6.9898","6.9898","4.6598","47.0746","174.1762"
"28.1600","7.0093","7.0093","4.6729","47.1994","174.6379"
"28.2400","7.0301","7.0301","4.6867","47.3392","175.1550"
"28.3200","7.0489","7.0489","4.6992","47.4613","175.6069"
"28.4000","7.0695","7.0695","4.7130","47.5993","176.1175"
"28.4800","7.0892","7.0892","4.7262","47.7288","176.5964"
"28.5600","7.1101","7.1101","4.7400","47.8661","177.1047"
"28.6400","7.1305","7.1305","4.7537","48.0013","177.6050"
"28.7200","7.1498","7.1498","4.7666","48.1237","178.0576"
"28.8000","7.1697","7.1697","4.7798","48.2518","178.5315"
"28.8800","7.1901","7.1901","4.7934","48.3904","179.0444"
"28.9600","7.2096","7.2096","4.8064","48.5137","179.5008"
"29.0400","7.2291","7.2291","4.8194","48.6401","179.9685"
"29.1200","7.2479","7.2479","4.8319","48.7536","180.3882"
"29.2000","7.2689","7.2689","4.8459","48.8928","180.9035"
"29.2800","7.2910","7.2910","4.8607","49.0401","181.4485"
"29.3600","7.3096","7.3096","4.8730","49.1585","181.8864"
"29.4400","7.3297","7.3297","4.8865","49.2866","182.3604"
"29.5200","7.3489","7.3489","4.8993","49.4078","182.8090"
"29.6000","7.3699","7.3699","4.9133","49.5411","183.3021"
"29.6800","7.3894","7.3894","4.9263","49.6635","183.7550"
"29.7600","7.4090","7.4090","4.9393","49.7858","184.2075"
"29.8400","7.4297","7.4297","4.9532","49.9193","184.7014"
"29.9200","7.4507","7.4507","4.9671","50.0553","185.2047"
"30.0000","7.4699","7.4699","4.9799","50.1739","185.6435"
"30.0800","7.4902","7.4902","4.9935","50.3087","186.1422"
"30.1600","7.5087","7.5087","5.0058","50.4138","186.5310"
"30.2400","7.5290","7.5290","5.0194","50.5376","186.9891"
"30.3200","7.5493","7.5493","5.0329","50.6694","187.4768"
"30.4000","7.5684","7.5684","5.0456","50.7855","187.9064"
"30.4800","7.5897","7.5897","5.0598","50.9235","188.4168"
"30.5600","7.6104","7.6104","5.0736","51.0535","188.8980"
"30.6400","7.6301","7.6301","5.0867","51.1742","189.3445"
"30.7200","7.6499","7.6499","5.0999","51.2944","189.7892"
"30.8000","7.6686","7.6686","5.1124","51.4082","190.2102"
"30.8800","7.6898","7.6898","5.1265","51.5419","190.7050"
"30.9600","7.7097","7.7097","5.1398","51.6603","191.1432"
"31.0400","7.7293","7.7293","5.1529","51.7820","191.5933"
"31.1200","7.7502","7.7502","5.1668","51.9141","192.0820"
"31.2000","7.7698","7.7698","5.1798","52.0285","192.5054"
"31.2800","7.7906","7.7906","5.1938","52.1571","192.9812"
"31.3600","7.8100","7.8100","5.2067","52.2724","193.4079"
"31.4400","7.8288","7.8288","5.2192","52.3844","193.8222"
"31.5200","7.8486","7.8486","5.2324","52.5020","194.2573"
"31.6000","7.8689","7.8689","5.2460","52.6266","194.7185"
"31.6800","7.8893","7.8893","5.2595","52.7511","195.1789"
"31.7600","7.9105","7.9105","5.2737","52.8802","195.6568"
"31.8400","7.9294","7.9294","5.2862","52.9887","196.0583"
"31.9200","7.9500","7.9500","5.3000","53.1110","196.5108"
"32.0000","7.9693","7.9693","5.3129","53.2235","196.9269"
"32.0800","7.9892","7.9892","5.3261","53.3427","197.3680"
"32.1600","8.0089","8.0089","5.3393","53.4607","197.8047"
"32.2400","8.0289","8.0289","5.3526","53.5754","198.2290"
"32.3200","8.0498","8.0498","5.3665","53.6992","198.6870"
"32.4000","8.0711","8.0711","5.3808","53.8262","199.1568"
"32.4800","8.0902","8.0902","5.3935","53.9354","199.5609"
"32.5600","8.1101","8.1101","5.4067","54.0544","200.0013"
"32.6400","8.1292","8.1292","5.4195","54.1589","200.3880"
"32.7200","8.1489","8.1489","5.4326","54.2708","200.8019"
"32.8000","8.1694","8.1694","5.4463","54.3889","201.2389"
"32.8800","8.1885","8.1885","5.4590","54.4941","201.6281"
"32.9600","8.2093","8.2093","5.4729","54.6132","202.0687"
"33.0400","8.2301","8.2301","5.4867","54.7349","202.5191"
"33.1200","8.2492","8.2492","5.4995","54.8361","202.8935"
"33.2000","8.2698","8.2698","5.5132","54.9566","203.3395"
"33.2800","8.2898","8.2898","5.5265","55.0609","203.7252"
"33.3600","8.3095","8.3095","5.5397","55.1711","204.1330"
"33.4400","8.3299","8.3299","5.5533","55.2835","204.5489"
"33.5200","8.3483","8.3483","5.5655","55.3826","204.9157"
"33.6000","8.3699","8.3699","5.5799","55.5057","205.3713"
"33.6800","8.3905","8.3905","5.5937","55.6210","205.7975"
"33.7600","8.4107","8.4107","5.6071","55.7294","206.1988"
"33.8400","8.4295","8.4295","5.6196","55.8249","206.5520"
"33.9200","8.4486","8.4486","5.6324","55.9226","206.9135"
"34.0000","8.4692","8.4692","5.6461","56.0350","207.3297"
"34.0800","8.4899","8.4899","5.6599","56.1476","207.7462"
"34.1600","8.5084","8.5084","5.6723","56.2428","208.0985"
"34.2400","8.5292","8.5292","5.6861","56.3593","208.5294"
"34.3200","8.5493","8.5493","5.6996","56.4630","208.9131"
"34.4000","8.5704","8.5704","5.7136","56.5796","209.3444"
"34.4800","8.5901","8.5901","5.7267","56.6790","209.7121"
"34.5600","8.6090","8.6090","5.7394","56.7768","210.0740"
"34.6400","8.6293","8.6293","5.7529","56.8799","210.4557"
"34.7200","8.6494","8.6494","5.7663","56.9859","210.8477"
"34.8000","8.6699","8.6699","5.7799","57.0907","211.2355"
"34.8800","8.6907","8.6907","5.7938","57.2020","211.6473"
"34.9600","8.7102","8.7102","5.8068","57.2987","212.0052"
"35.0400","8.7301","8.7301","5.8201","57.3993","212.3773"
"35.1200","8.7496","8.7496","5.8330","57.4925","212.7224"
"35.2000","8.7690","8.7690","5.8460","57.5926","213.0925"
"35.2800","8.7896","8.7896","5.8597","57.6960","213.4751"
"35.3600","8.8085","8.8085","5.8723","57.7833","213.7980"
"35.4400","8.8292","8.8292","5.8861","57.8905","214.1949"
"35.5200","8.8500","8.8500","5.9000","57.9950","214.5814"
"35.6000","8.8699","8.8699","5.9133","58.0901","214.9333"
"35.6800","8.8901","8.8901","5.9267","58.1883","215.2968"
"35.7600","8.9097","8.9097","5.9398","58.2806","215.6382"
"35.8400","8.9286","8.9286","5.9524","58.3678","215.9608"
"35.9200","8.9494","8.9494","5.9662","58.4693","216.3364"
"36.0000","8.9687","8.9687","5.9791","58.5570","216.6611"
"36.0800","8.9906","8.9906","5.9937","58.6677","217.0706"
"36.1600","9.0106","9.0106","6.0071","58.7589","217.4078"
"36.2400","9.0295","9.0295","6.0197","58.8421","217.7159"
"36.3200","9.0496","9.0496","6.0330","58.9359","218.0627"
"36.4000","9.0696","9.0696","6.0464","59.0236","218.3872"
"36.4800","9.0895","9.0895","6.0597","59.1179","218.7361"
"36.5600","9.1098","9.1098","6.0732","59.2070","219.0658"
"36.6400","9.1282","9.1282","6.0855","59.2841","219.3511"
"36.7200","9.1495","9.1495","6.0996","59.3857","219.7271"
"36.8000","9.1703","9.1703","6.1135","59.4819","220.0831"
"36.8800","9.1902","9.1902","6.1268","59.5662","220.3951"
"36.9600","9.2095","9.2095","6.1397","59.6445","220.6846"
"37.0400","9.2285","9.2285","6.1523","59.7246","220.9809"
"37.1200","9.2494","9.2494","6.1663","59.8155","221.3175"
"37.2000","9.2697","9.2697","6.1798","59.9052","221.6492"
"37.2800","9.2895","9.2895","6.1930","59.9875","221.9536"
"37.3600","9.3102","9.3102","6.2068","60.0787","222.2913"
"37.4400","9.3300","9.3300","6.2200","60.1560","222.5772"
"37.5200","9.3498","9.3498","6.2332","60.2349","222.8690"
"37.6000","9.3702","9.3702","6.2468","60.3178","223.1759"
"37.6800","9.3890","9.3890","6.2593","60.3855","223.4264"
"37.7600","9.4097","9.4097","6.2732","60.4705","223.7409"
"37.8400","9.4288","9.4288","6.2859","60.5409","224.0012"
"37.9200","9.4483","9.4483","6.2989","60.6167","224.2818"
"38.0000","9.4695","9.4695","6.3130","60.7063","224.6133"
"38.0800","9.4902","9.4902","6.3268","60.7854","224.9059"
"38.1600","9.5101","9.5101","6.3401","60.8551","225.1638"
"38.2400","9.5299","9.5299","6.3533","60.9254","225.4241"
"38.3200","9.5484","9.5484","6.3656","60.9889","225.6588"
"38.4000","9.5693","9.5693","6.3795","61.0701","225.9594"
"38.4800","9.5890","9.5890","6.3926","61.1375","226.2087"
"38.5600","9.6100","9.6100","6.4067","61.2188","226.5094"
"38.6400","9.6308","9.6308","6.4205","61.2935","226.7858"
"38.7200","9.6496","9.6496","6.4330","61.3586","227.0270"
"38.8000","9.6698","9.6698","6.4466","61.4291","227.2878"
"38.8800","9.6898","9.6898","6.4599","61.4958","227.5346"
"38.9600","9.7092","9.7092","6.4728","61.5604","227.7734"
"39.0400","9.7290","9.7290","6.4860","61.6275","228.0217"
"39.1200","9.7483","9.7483","6.4989","61.6884","228.2473"
"39.2000","9.7693","9.7693","6.5129","61.7627","228.5219"
"39.2800","9.7907","9.7907","6.5271","61.8408","228.8111"
"39.3600","9.8095","9.8095","6.5396","61.8966","229.0173"
"39.4400","9.8299","9.8299","6.5533","61.9639","229.2665"
"39.5200","9.8489","9.8489","6.5660","62.0194","229.4716"
"39.6000","9.8694","9.8694","6.5796","62.0867","229.7207"
"39.6800","9.8896","9.8896","6.5931","62.1497","229.9538"
"39.7600","9.9089","9.9089","6.6059","62.2036","230.1532"
"39.8400","9.9294","9.9294","6.6196","62.2706","230.4011"
"39.9200","9.9507","9.9507","6.6338","62.3378","230.6497"
"40.0000","9.9701","9.9701","6.6467","62.3862","230.8290"
"40.0800","9.9900","9.9900","6.6600","62.4449","231.0460"
"40.1600","10.0088","10.0088","6.6726","62.4916","231.2191"
"40.2400","10.0291","10.0291","6.6861","62.5522","231.4430"
"40.3200","10.0493","10.0493","6.6995","62.6146","231.6738"
"40.4000","10.0687","10.0687","6.7124","62.6674","231.8692"
"40.4800","10.0900","10.0900","6.7266","62.7306","232.1030"
"40.5600","10.1103","10.1103","6.7402","62.7872","232.3127"
"40.6400","10.1298","10.1298","6.7532","62.8333","232.4833"
"40.7200","10.1498","10.1498","6.7665","62.8885","232.6873"
"40.8000","10.1685","10.1685","6.7790","62.9299","232.8406"
"40.8800","10.1894","10.1894","6.7929","62.9896","233.0615"
"40.9600","10.2096","10.2096","6.8064","63.0386","233.2428"
"41.0400","10.2292","10.2292","6.8195","63.0858","233.4175"
"41.1200","10.2502","10.2502","6.8335","63.1392","233.6150"
"41.2000","10.2699","10.2699","6.8466","63.1801","233.7663"
"41.2800","10.2905","10.2905","6.8603","63.2284","233.9453"
"41.3600","10.3101","10.3101","6.8734","63.2706","234.1012"
"41.4400","10.3291","10.3291","6.8861","63.3122","234.2551"
"41.5200","10.3488","10.3488","6.8992","63.3518","234.4015"
"41.6000","10.3691","10.3691","6.9127","63.3969","234.5687"
"41.6800","10.3888","10.3888","6.9259","63.4421","234.7358"
"41.7600","10.4106","10.4106","6.9404","63.4983","234.9437"
"41.8400","10.4293","10.4293","6.9529","63.5309","235.0643"
"41.9200","10.4500","10.4500","6.9667","63.5751","235.2277"
"42.0000","10.4691","10.4691","6.9794","63.6082","235.3504"
"42.0800","10.4891","10.4891","6.9928","63.6499","235.5048"
"42.1600","10.5092","10.5092","7.0062","63.6917","235.6593"
"42.2400","10.5292","10.5292","7.0194","63.7275","235.7918"
"42.3200","10.5496","10.5496","7.0331","63.7710","235.9527"
"42.4000","10.5710","10.5710","7.0474","63.8170","236.1230"
"42.4800","10.5902","10.5902","7.0601","63.8501","236.2453"
"42.5600","10.6101","10.6101","7.0734","63.8833","236.3681"
"42.6400","10.6292","10.6292","7.0861","63.9105","236.4690"
"42.7200","10.6491","10.6491","7.0994","63.9497","236.6140"
"42.8000","10.6695","10.6695","7.1130","63.9870","236.7521"
"42.8800","10.6887","10.6887","7.1258","64.0144","236.8533"
"42.9600","10.7095","10.7095","7.1397","64.0533","236.9973"
"43.0400","10.7298","10.7298","7.1532","64.0860","237.1181"
"43.1200","10.7497","10.7497","7.1665","64.1190","237.2402"
"43.2000","10.7698","10.7698","7.1799","64.1515","237.3605"
"43.2800","10.7897","10.7897","7.1931","64.1765","237.4529"
"43.3600","10.8095","10.8095","7.2063","64.2017","237.5464"
"43.4400","10.8299","10.8299","7.2199","64.2356","237.6718"
"43.5200","10.8484","10.8484","7.2323","64.2563","237.7482"
"43.6000","10.8699","10.8699","7.2466","64.2974","237.9003"
"43.6800","10.8897","10.8897","7.2598","64.3245","238.0005"
"43.7600","10.9107","10.9107","7.2738","64.3569","238.1204"
"43.8400","10.9297","10.9297","7.2865","64.3803","238.2072"
"43.9200","10.9491","10.9491","7.2994","64.4044","238.2964"
"44.0000","10.9695","10.9695","7.3130","64.4368","238.4162"
"44.0800","10.9899","10.9899","7.3266","64.4656","238.5227"
"44.1600","11.0081","11.0081","7.3387","64.4837","238.5896"
"44.2400","11.0292","11.0292","7.3528","64.5202","238.7247"
"44.3200","11.0495","11.0495","7.3663","64.5476","238.8262"
"44.4000","11.0704","11.0704","7.3802","64.5794","238.9436"
"44.4800","11.0898","11.0898","7.3932","64.5977","239.0114"
"44.5600","11.1088","11.1088","7.4059","64.6201","239.0943"
"44.6400","11.1292","11.1292","7.4195","64.6488","239.2005"
"44.7200","11.1494","11.1494","7.4330","64.6729","239.2899"
"44.8000","11.1697","11.1697","7.4465","64.7019","239.3969"
"44.8800","11.1906","11.1906","7.4604","64.7319","239.5079"
"44.9600","11.2104","11.2104","7.4736","64.7506","239.5773"
"45.0400","11.2299","11.2299","7.4866","64.7710","239.6526"
"45.1200","11.2499","11.2499","7.4999","64.7920","239.7305"
"45.2000","11.2690","11.2690","7.5127","64.8092","239.7940"
"45.2800","11.2899","11.2899","7.5266","64.8390","239.9041"
"45.3600","11.3084","11.3084","7.5389","64.8492","239.9420"
"45.4400","11.3287","11.3287","7.5525","64.8741","240.0343"
"45.5200","11.3496","11.3496","7.5664","64.9033","240.1422"
"45.6000","11.3701","11.3701","7.5801","64.9302","240.2416"
"45.6800","11.3902","11.3902","7.5935","64.9475","240.3059"
"45.7600","11.4098","11.4098","7.6066","64.9632","240.3640"
"45.8400","11.4289","11.4289","7.6193","64.9779","240.4182"
"45.9200","11.4495","11.4495","7.6330","65.0027","240.5098"
"46.0000","11.4683","11.4683","7.6455","65.0102","240.5376"
"46.0800","11.4898","11.4898","7.6598","65.0389","240.6440"
"46.1600","11.5108","11.5108","7.6739","65.0647","240.7393"
"46.2400","11.5302","11.5302","7.6868","65.0771","240.7853"
"46.3200","11.5496","11.5496","7.6997","65.0891","240.8296"
"46.4000","11.5695","11.5695","7.7130","65.1063","240.8932"
"46.4800","11.5894","11.5894","7.7263","65.1218","240.9507"
"46.5600","11.6095","11.6095","7.7397","65.1385","241.0123"
"46.6400","11.6282","11.6282","7.7521","65.1481","241.0481"
"46.7200","11.6493","11.6493","7.7662","65.1708","241.1318"
"46.8000","11.6707","11.6707","7.7805","65.1939","241.2175"
"46.8800","11.6902","11.6902","7.7935","65.2066","241.2646"
"46.9600","11.7089","11.7089","7.8059","65.2104","241.2785"
"47.0400","11.7284","11.7284","7.8190","65.2215","241.3196"
"47.1200","11.7496","11.7496","7.8331","65.2419","241.3949"
"47.2000","11.7699","11.7699","7.8466","65.2584","241.4560"
"47.2800","11.7897","11.7897","7.8598","65.2703","241.5003"
"47.3600","11.8100","11.8100","7.8733","65.2897","241.5721"
"47.4400","11.8298","11.8298","7.8865","65.2982","241.6033"
"47.5200","11.8495","11.8495","7.8997","65.3111","241.6512"
"47.6000","11.8705","11.8705","7.9136","65.3299","241.7207"
"47.6800","11.8893","11.8893","7.9262","65.3365","241.7449"
"47.7600","11.9097","11.9097","7.9398","65.3480","241.7876"
"47.8400","11.9286","11.9286","7.9524","65.3537","241.8085"
"47.9200","11.9488","11.9488","7.9659","65.3722","241.8770"
"48.0000","11.9698","11.9698","7.9798","65.3899","241.9426"
"48.0800","11.9903","11.9903","7.9935","65.4003","241.9813"
"48.1600","12.0101","12.0101","8.0067","65.4097","242.0161"
"48.2400","12.0302","12.0302","8.0201","65.4201","242.0545"
"48.3200","12.0485","12.0485","8.0323","65.4228","242.0644"
"48.4000","12.0694","12.0694","8.0463","65.4437","242.1418"
"48.4800","12.0894","12.0894","8.0596","65.4525","242.1743"
"48.5600","12.1099","12.1099","8.0733","65.4658","242.2234"
"48.6400","12.1304","12.1304","8.0869","65.4774","242.2662"
"48.7200","12.1497","12.1497","8.0998","65.4816","242.2817"
"48.8000","12.1696","12.1696","8.1131","65.4905","242.3148"
"48.8800","12.1895","12.1895","8.1263","65.5000","242.3500"
"48.9600","12.2088","12.2088","8.1392","65.5062","242.3728"
"49.0400","12.2294","12.2294","8.1529","65.5215","242.4294"
"49.1200","12.2485","12.2485","8.1656","65.5228","242.4343"
"49.2000","12.2695","12.2695","8.1797","65.5368","242.4860"
"49.2800","12.2908","12.2908","8.1939","65.5524","242.5438"
"49.3600","12.3098","12.3098","8.2065","65.5536","242.5484"
"49.4400","12.3296","12.3296","8.2197","65.5573","242.5619"
"49.5200","12.3488","12.3488","8.2325","65.5616","242.5781"
"49.6000","12.3698","12.3698","8.2465","65.5789","242.6420"
"49.6800","12.3899","12.3899","8.2599","65.5814","242.6513"
"49.7600","12.4092","12.4092","8.2728","65.5875","242.6736"
"49.8400","12.4295","12.4295","8.2863","65.5949","242.7011"
"49.9200","12.4508","12.4508","8.3005","65.6098","242.7562"
"50.0000","12.4699","12.4699","8.3133","65.6142","242.7725"
"50.0800","12.4905","12.4905","8.3270","65.6256","242.8148"
"50.1600","12.5090","12.5090","8.3393","65.6208","242.7970"
"50.2400","12.5294","12.5294","8.3529","65.6299","242.8307"
"50.3200","12.5486","12.5486","8.3658","65.6310","242.8345"
"50.4000","12.5686","12.5686","8.3791","65.6427","242.8781"
"50.4800","12.5898","12.5898","8.3932","65.6581","242.9351"
"50.5600","12.6102","12.6102","8.4068","65.6657","242.9631"
"50.6400","12.6298","12.6298","8.4199","65.6699","242.9786"
"50.7200","12.6500","12.6500","8.4333","65.6760","243.0013"
"50.8000","12.6688","12.6688","8.4458","65.6760","243.0012"
"50.8800","12.6895","12.6895","8.4597","65.6882","243.0464"
"50.9600","12.7098","12.7098","8.4732","65.6941","243.0683"
"51.0400","12.7293","12.7293","8.4862","65.6982","243.0834"
"51.1200","12.7502","12.7502","8.5001","65.7109","243.1303"
"51.2000","12.7696","12.7696","8.5131","65.7131","243.1384"
"51.2800","12.7905","12.7905","8.5270","65.7225","243.1734"
"51.3600","12.8095","12.8095","8.5397","65.7200","243.1641"
"51.4400","12.8292","12.8292","8.5528","65.7268","243.1891"
"51.5200","12.8491","12.8491","8.5660","65.7312","243.2056"
"51.6000","12.8690","12.8690","8.5793","65.7315","243.2066"
"51.6800","12.8890","12.8890","8.5926","65.7411","243.2420"
"51.7600","12.9106","12.9106","8.6070","65.7545","243.2918"
"51.8400","12.9290","12.9290","8.6193","65.7482","243.2684"
"51.9200","12.9500","12.9500","8.6334","65.7597","243.3108"
"52.0000","12.9695","12.9695","8.6464","65.7601","243.3125"
"52.0800","12.9893","12.9893","8.6596","65.7675","243.3399"
"52.1600","13.0091","13.0091","8.6727","65.7680","243.3415"
"52.2400","13.0291","13.0291","8.6861","65.7696","243.3475"
"52.3200","13.0497","13.0497","8.6998","65.7781","243.3790"
"52.4000","13.0710","13.0710","8.7140","65.7887","243.4183"
"52.4800","13.0902","13.0902","8.7268","65.7865","243.4100"
"52.5600","13.1098","13.1098","8.7399","65.7859","243.4077"
"52.6400","13.1294","13.1294","8.7529","65.7852","243.4052"
"52.7200","13.1490","13.1490","8.7660","65.7849","243.4040"
"52.8000","13.1695","13.1695","8.7796","65.7814","243.3911"
"52.8800","13.1888","13.1888","8.7925","65.7789","243.3819"
"52.9600","13.2098","13.2098","8.8065","65.7792","243.3829"
"53.0400","13.2303","13.2303","8.8202","65.7789","243.3818"
"53.1200","13.2496","13.2496","8.8331","65.7733","243.3613"
"53.2000","13.2694","13.2694","8.8463","65.7688","243.3446"
"53.2800","13.2894","13.2894","8.8596","65.7630","243.3232"
"53.3600","13.3096","13.3096","8.8731","65.7622","243.3202"
"53.4400","13.3300","13.3300","8.8867","65.7583","243.3058"
"53.5200","13.3486","13.3486","8.8990","65.7487","243.2701"
"53.6000","13.3702","13.3702","8.9134","65.7512","243.2793"
"53.6800","13.3900","13.3900","8.9267","65.7447","243.2553"
"53.7600","13.4105","13.4105","8.9404","65.7397","243.2369"
"53.8400","13.4292","13.4292","8.9528","65.7238","243.1782"
"53.9200","13.4490","13.4490","8.9660","65.7156","243.1479"
"54.0000","13.4695","13.4695","8.9797","65.7097","243.1261"
"54.0800","13.4900","13.4900","8.9933","65.7044","243.1062"
"54.1600","13.5083","13.5083","9.0056","65.6901","243.0534"
"54.2400","13.5296","13.5296","9.0197","65.6918","243.0596"
"54.3200","13.5494","13.5494","9.0329","65.6752","242.9984"
"54.4000","13.5704","13.5704","9.0469","65.6706","242.9813"
"54.4800","13.5900","13.5900","9.0600","65.6585","242.9365"
"54.5600","13.6089","13.6089","9.0726","65.6449","242.8860"
"54.6400","13.6291","13.6291","9.0861","65.6344","242.8471"
"54.7200","13.6494","13.6494","9.0996","65.6273","242.8210"
"54.8000","13.6699","13.6699","9.1133","65.6181","242.7872"
"54.8800","13.6908","13.6908","9.1272","65.6129","242.7678"
"54.9600","13.7099","13.7099","9.1399","65.5917","242.6893"
"55.0400","13.7301","13.7301","9.1534","65.5779","242.6381"
"55.1200","13.7500","13.7500","9.1667","65.5593","242.5695"
"55.2000","13.7687","13.7687","9.1792","65.5450","242.5166"
"55.2800","13.7894","13.7894","9.1929","65.5293","242.4585"
"55.3600","13.8085","13.8085","9.2056","65.5082","242.3805"
"55.4400","13.8293","13.8293","9.2195","65.4993","242.3473"
"55.5200","13.8496","13.8496","9.2331","65.4852","242.2954"
"55.6000","13.8701","13.8701","9.2467","65.4716","242.2450"
"55.6800","13.8900","13.8900","9.2600","65.4551","242.1840"
"55.7600","13.9096","13.9096","9.2731","65.4364","242.1148"
"55.8400","13.9290","13.9290","9.2860","65.4180","242.0465"
"55.9200","13.9495","13.9495","9.2997","65.4067","242.0049"
"56.0000","13.9686","13.9686","9.3124","65.3828","241.9164"
"56.0800","13.9904","13.9904","9.3269","65.3758","241.8906"
"56.1600","14.0107","14.0107","9.3405","65.3627","241.8421"
"56.2400","14.0298","14.0298","9.3532","65.3412","241.7625"
"56.3200","14.0496","14.0496","9.3664","65.3232","241.6959"
"56.4000","14.0692","14.0692","9.3794","65.2995","241.6082"
"56.4800","14.0895","14.0895","9.3930","65.2875","241.5638"
"56.5600","14.1102","14.1102","9.4068","65.2664","241.4856"
"56.6400","14.1283","14.1283","9.4188","65.2409","241.3912"
"56.7200","14.1494","14.1494","9.4330","65.2274","241.3413"
"56.8000","14.1703","14.1703","9.4469","65.2082","241.2704"
"56.8800","14.1900","14.1900","9.4600","65.1889","241.1990"
"56.9600","14.2095","14.2095","9.4730","65.1647","241.1095"
"57.0400","14.2281","14.2281","9.4854","65.1352","241.0003"
"57.1200","14.2493","14.2492","9.4995","65.1262","240.9668"
"57.2000","14.2698","14.2698","9.5132","65.1089","240.9030"
"57.2800","14.2898","14.2898","9.5265","65.0872","240.8227"
"57.3600","14.3103","14.3103","9.5402","65.0680","240.7515"
"57.4400","14.3300","14.3300","9.5533","65.0449","240.6661"
"57.5200","14.3499","14.3499","9.5666","65.0184","240.5680"
"57.6000","14.3700","14.3700","9.5800","64.9944","240.4794"
"57.6800","14.3891","14.3891","9.5927","64.9712","240.3936"
"57.7600","14.4097","14.4097","9.6065","64.9485","240.3094"
"57.8400","14.4288","14.4288","9.6192","64.9220","240.2113"
"57.9200","14.4486","14.4486","9.6324","64.9012","240.1344"
"58.0000","14.4696","14.4696","9.6464","64.8842","240.0714"
"58.0800","14.4899","14.4899","9.6599","64.8557","239.9659"
"58.1600","14.5101","14.5101","9.6734","64.8283","239.8648"
"58.2400","14.5299","14.5299","9.6866","64.7994","239.7577"
"58.3200","14.5485","14.5485","9.6990","64.7658","239.6333"
"58.4000","14.5695","14.5695","9.7130","64.7471","239.5641"
"58.4800","14.5894","14.5894","9.7263","64.7202","239.4648"
"58.5600","14.6101","14.6101","9.7401","64.6972","239.3796"
"58.6400","14.6302","14.6302","9.7535","64.6685","239.2736"
"58.7200","14.6496","14.6496","9.7664","64.6402","239.1688"
"58.8000","14.6701","14.6701","9.7801","64.6140","239.0718"
"58.8800","14.6898","14.6898","9.7932","64.5866","238.9703"
"58.9600","14.7093","14.7093","9.8062","64.5577","238.8636"
"59.0400","14.7290","14.7290","9.8193","64.5283","238.7549"
"59.1200","14.7484","14.7484","9.8323","64.4973","238.6398"
"59.2000","14.7696","14.7696","9.8464","64.4751","238.5580"
"59.2800","14.7909","14.7909","9.8606","64.4463","238.4512"
"59.3600","14.8094","14.8094","9.8729","64.4122","238.3253"
"59.4400","14.8296","14.8296","9.8864","64.3848","238.2236"
"59.5200","14.8490","14.8490","9.8994","64.3514","238.1001"
"59.6000","14.8699","14.8699","9.9132","64.3224","237.9930"
"59.6800","14.8899","14.8899","9.9266","64.2927","237.8829"
"59.7600","14.9092","14.9092","9.9395","64.2590","237.7583"
"59.8400","14.9297","14.9297","9.9531","64.2294","237.6487"
"59.9200","14.9505","14.9505","9.9670","64.1960","237.5253"
"60.0000","14.9700","14.9700","9.9800","64.1576","237.3832"
"60.0800","14.9899","14.9899","9.9932","64.1230","237.2549"
"60.1200","15.0000","15.0000","10.0000","64.1028","237.1803"