File: data/instron_tests/metamaterial_samples/509_NS_m1.is_comp_Exports/509_NS_m1_6_1.csv
Sample text inputs : Sample No.,Sample choice input : Leading Direction,Sample choice input : Mode,Specimen choice input : Direction,Specimen properties : Height,Specimen properties : Thickness,Specimen properties : Width,Test : Rate 1
,,,,(mm),(mm),(mm),(mm/min)
"509","Normal-Shear","Unimode","1","150.00","25.00","150.00","15.00"

Time,Displacement,Compressive displacement,Compressive strain (Displacement),Compressive stress,Force
(s),(mm),(mm),(%),(kPa),(N)
"0.0000","0.0000","0.0000","0.0000","-1.6762","-6.2020"
"0.0800","0.0014","0.0014","0.0010","-1.6689","-6.1748"
"0.1600","0.0192","0.0192","0.0128","-1.6402","-6.0689"
"0.2400","0.0399","0.0399","0.0266","-1.6089","-5.9530"
"0.3200","0.0587","0.0587","0.0391","-1.5834","-5.8585"
"0.4000","0.0781","0.0781","0.0521","-1.5621","-5.7798"
"0.4800","0.0995","0.0995","0.0663","-1.5398","-5.6974"
"0.5600","0.1189","0.1189","0.0793","-1.5225","-5.6332"
"0.6400","0.1386","0.1386","0.0924","-1.5068","-5.5751"
"0.7200","0.1590","0.1590","0.1060","-1.4861","-5.4984"
"0.8000","0.1776","0.1776","0.1184","-1.4695","-5.4372"
"0.8800","0.1981","0.1981","0.1320","-1.4478","-5.3570"
"0.9600","0.2178","0.2178","0.1452","-1.4277","-5.2824"
"1.0400","0.2380","0.2380","0.1586","-1.4040","-5.1950"
"1.1200","0.2589","0.2589","0.1726","-1.3825","-5.1154"
"1.2000","0.2783","0.2783","0.1856","-1.3562","-5.0180"
"1.2800","0.2989","0.2989","0.1993","-1.3316","-4.9269"
"1.3600","0.3187","0.3187","0.2124","-1.3057","-4.8312"
"1.4400","0.3381","0.3381","0.2254","-1.2798","-4.7354"
"1.5200","0.3585","0.3585","0.2390","-1.2513","-4.6299"
"1.6000","0.3776","0.3776","0.2518","-1.2279","-4.5432"
"1.6800","0.3985","0.3985","0.2657","-1.1977","-4.4313"
"1.7600","0.4201","0.4201","0.2801","-1.1743","-4.3450"
"1.8400","0.4389","0.4389","0.2926","-1.1450","-4.2363"
"1.9200","0.4588","0.4588","0.3059","-1.1190","-4.1402"
"2.0000","0.4780","0.4780","0.3187","-1.0950","-4.0516"
"2.0800","0.4985","0.4985","0.3323","-1.0677","-3.9504"
"2.1600","0.5189","0.5189","0.3460","-1.0426","-3.8577"
"2.2400","0.5373","0.5373","0.3582","-1.0183","-3.7676"
"2.3200","0.5580","0.5580","0.3720","-0.9917","-3.6691"
"2.4000","0.5789","0.5789","0.3860","-0.9604","-3.5536"
"2.4800","0.5988","0.5988","0.3992","-0.9318","-3.4475"
"2.5600","0.6191","0.6191","0.4127","-0.9067","-3.3549"
"2.6400","0.6377","0.6377","0.4252","-0.8818","-3.2628"
"2.7200","0.6584","0.6584","0.4389","-0.8515","-3.1505"
"2.8000","0.6786","0.6786","0.4524","-0.8240","-3.0487"
"2.8800","0.6978","0.6978","0.4652","-0.7925","-2.9322"
"2.9600","0.7191","0.7191","0.4794","-0.7601","-2.8125"
"3.0400","0.7389","0.7389","0.4926","-0.7348","-2.7187"
"3.1200","0.7586","0.7586","0.5057","-0.7075","-2.6179"
"3.2000","0.7786","0.7786","0.5191","-0.6805","-2.5178"
"3.2800","0.7977","0.7977","0.5318","-0.6517","-2.4113"
"3.3600","0.8187","0.8187","0.5458","-0.6229","-2.3048"
"3.4400","0.8383","0.8383","0.5588","-0.5931","-2.1946"
"3.5200","0.8573","0.8573","0.5715","-0.5631","-2.0833"
"3.6000","0.8780","0.8780","0.5853","-0.5347","-1.9784"
"3.6800","0.8987","0.8987","0.5992","-0.5051","-1.8687"
"3.7600","0.9194","0.9194","0.6130","-0.4763","-1.7622"
"3.8400","0.9392","0.9392","0.6261","-0.4465","-1.6520"
"3.9200","0.9576","0.9576","0.6384","-0.4185","-1.5486"
"4.0000","0.9782","0.9782","0.6521","-0.3848","-1.4237"
"4.0800","0.9980","0.9980","0.6653","-0.3555","-1.3152"
"4.1600","1.0186","1.0186","0.6791","-0.3247","-1.2014"
"4.2400","1.0396","1.0396","0.6931","-0.2920","-1.0804"
"4.3200","1.0588","1.0588","0.7059","-0.2636","-0.9753"
"4.4000","1.0788","1.0788","0.7192","-0.2316","-0.8570"
"4.4800","1.0988","1.0988","0.7325","-0.2000","-0.7399"
"4.5600","1.1183","1.1183","0.7455","-0.1714","-0.6342"
"4.6400","1.1383","1.1383","0.7588","-0.1387","-0.5132"
"4.7200","1.1572","1.1572","0.7715","-0.1104","-0.4083"
"4.8000","1.1779","1.1779","0.7853","-0.0773","-0.2858"
"4.8800","1.1996","1.1996","0.7997","-0.0452","-0.1671"
"4.9600","1.2187","1.2187","0.8125","-0.0104","-0.0384"
"5.0400","1.2386","1.2386","0.8257","0.0236","0.0874"
"5.1200","1.2579","1.2579","0.8386","0.0546","0.2022"
"5.2000","1.2783","1.2783","0.8522","0.0849","0.3140"
"5.2800","1.2985","1.2985","0.8656","0.1208","0.4471"
"5.3600","1.3183","1.3183","0.8789","0.1525","0.5641"
"5.4400","1.3391","1.3391","0.8927","0.1907","0.7057"
"5.5200","1.3593","1.3593","0.9062","0.2243","0.8300"
"5.6000","1.3783","1.3783","0.9188","0.2609","0.9654"
"5.6800","1.3988","1.3988","0.9325","0.2928","1.0834"
"5.7600","1.4178","1.4178","0.9452","0.3253","1.2037"
"5.8400","1.4389","1.4389","0.9593","0.3618","1.3385"
"5.9200","1.4582","1.4582","0.9721","0.3970","1.4691"
"6.0000","1.4770","1.4770","0.9846","0.4318","1.5977"
"6.0800","1.4984","1.4984","0.9989","0.4712","1.7435"
"6.1600","1.5194","1.5194","1.0130","0.5071","1.8761"
"6.2400","1.5387","1.5387","1.0258","0.5420","2.0054"
"6.3200","1.5583","1.5583","1.0389","0.5787","2.1413"
"6.4000","1.5775","1.5775","1.0516","0.6113","2.2618"
"6.4800","1.5984","1.5984","1.0656","0.6524","2.4138"
"6.5600","1.6192","1.6192","1.0794","0.6895","2.5512"
"6.6400","1.6384","1.6384","1.0922","0.7268","2.6893"
"6.7200","1.6590","1.6590","1.1060","0.7613","2.8166"
"6.8000","1.6787","1.6787","1.1191","0.7967","2.9476"
"6.8800","1.6992","1.6992","1.1328","0.8355","3.0912"
"6.9600","1.7191","1.7191","1.1460","0.8720","3.2264"
"7.0400","1.7381","1.7381","1.1587","0.9078","3.3588"
"7.1200","1.7581","1.7581","1.1721","0.9466","3.5025"
"7.2000","1.7777","1.7777","1.1851","0.9840","3.6407"
"7.2800","1.7978","1.7978","1.1985","1.0194","3.7719"
"7.3600","1.8194","1.8194","1.2129","1.0578","3.9139"
"7.4400","1.8385","1.8385","1.2257","1.0931","4.0445"
"7.5200","1.8591","1.8591","1.2394","1.1311","4.1850"
"7.6000","1.8783","1.8783","1.2522","1.1681","4.3218"
"7.6800","1.8978","1.8978","1.2652","1.2078","4.4690"
"7.7600","1.9183","1.9183","1.2789","1.2447","4.6053"
"7.8400","1.9378","1.9378","1.2919","1.2825","4.7451"
"7.9200","1.9589","1.9589","1.3059","1.3142","4.8625"
"8.0000","1.9796","1.9796","1.3197","1.3550","5.0136"
"8.0800","1.9988","1.9988","1.3325","1.3944","5.1592"
"8.1600","2.0191","2.0191","1.3461","1.4315","5.2965"
"8.2400","2.0386","2.0386","1.3591","1.4680","5.4317"
"8.3200","2.0581","2.0581","1.3721","1.5056","5.5706"
"8.4000","2.0781","2.0781","1.3854","1.5440","5.7129"
"8.4800","2.0968","2.0968","1.3978","1.5796","5.8446"
"8.5600","2.1186","2.1186","1.4124","1.6145","5.9735"
"8.6400","2.1396","2.1396","1.4264","1.6560","6.1272"
"8.7200","2.1587","2.1587","1.4391","1.6976","6.2811"
"8.8000","2.1784","2.1784","1.4523","1.7349","6.4192"
"8.8800","2.1982","2.1982","1.4655","1.7751","6.5679"
"8.9600","2.2182","2.2182","1.4788","1.8125","6.7062"
"9.0400","2.2389","2.2389","1.4926","1.8490","6.8412"
"9.1200","2.2577","2.2577","1.5051","1.8857","6.9771"
"9.2000","2.2788","2.2788","1.5192","1.9218","7.1106"
"9.2800","2.2989","2.2989","1.5326","1.9640","7.2668"
"9.3600","2.3195","2.3195","1.5463","2.0028","7.4105"
"9.4400","2.3384","2.3384","1.5589","2.0411","7.5521"
"9.5200","2.3581","2.3581","1.5721","2.0805","7.6978"
"9.6000","2.3782","2.3782","1.5855","2.1181","7.8370"
"9.6800","2.3988","2.3988","1.5992","2.1566","7.9793"
"9.7600","2.4175","2.4175","1.6117","2.1948","8.1209"
"9.8400","2.4387","2.4387","1.6258","2.2335","8.2639"
"9.9200","2.4583","2.4583","1.6389","2.2700","8.3990"
"10.0000","2.4787","2.4787","1.6525","2.3100","8.5471"
"10.0800","2.4989","2.4989","1.6660","2.3509","8.6983"
"10.1600","2.5180","2.5180","1.6787","2.3883","8.8367"
"10.2400","2.5383","2.5383","1.6922","2.4266","8.9785"
"10.3200","2.5584","2.5584","1.7056","2.4664","9.1255"
"10.4000","2.5782","2.5782","1.7188","2.5046","9.2672"
"10.4800","2.5991","2.5991","1.7327","2.5438","9.4122"
"10.5600","2.6193","2.6193","1.7462","2.5819","9.5529"
"10.6400","2.6399","2.6399","1.7599","2.6210","9.6978"
"10.7200","2.6591","2.6591","1.7727","2.6568","9.8302"
"10.8000","2.6773","2.6773","1.7849","2.6936","9.9665"
"10.8800","2.6983","2.6983","1.7989","2.7354","10.1208"
"10.9600","2.7177","2.7177","1.8118","2.7742","10.2647"
"11.0400","2.7386","2.7386","1.8257","2.8124","10.4058"
"11.1200","2.7587","2.7587","1.8392","2.8492","10.5421"
"11.2000","2.7785","2.7785","1.8523","2.8844","10.6722"
"11.2800","2.7989","2.7989","1.8659","2.9248","10.8216"
"11.3600","2.8189","2.8189","1.8793","2.9612","10.9563"
"11.4400","2.8378","2.8378","1.8919","3.0021","11.1079"
"11.5200","2.8583","2.8583","1.9055","3.0419","11.2549"
"11.6000","2.8776","2.8776","1.9184","3.0794","11.3939"
"11.6800","2.8993","2.8993","1.9329","3.1217","11.5503"
"11.7600","2.9197","2.9197","1.9465","3.1623","11.7006"
"11.8400","2.9386","2.9386","1.9591","3.1979","11.8322"
"11.9200","2.9588","2.9588","1.9725","3.2351","11.9700"
"12.0000","2.9783","2.9783","1.9855","3.2732","12.1109"
"12.0800","2.9982","2.9982","1.9988","3.3119","12.2539"
"12.1600","3.0186","3.0186","2.0124","3.3526","12.4045"
"12.2400","3.0375","3.0375","2.0250","3.3899","12.5427"
"12.3200","3.0582","3.0582","2.0388","3.4302","12.6916"
"12.4000","3.0789","3.0789","2.0526","3.4709","12.8422"
"12.4800","3.0986","3.0986","2.0657","3.5109","12.9905"
"12.5600","3.1189","3.1189","2.0792","3.5484","13.1290"
"12.6400","3.1379","3.1379","2.0919","3.5841","13.2611"
"12.7200","3.1585","3.1585","2.1057","3.6229","13.4049"
"12.8000","3.1784","3.1784","2.1189","3.6607","13.5447"
"12.8800","3.1977","3.1977","2.1318","3.7023","13.6984"
"12.9600","3.2184","3.2184","2.1456","3.7415","13.8435"
"13.0400","3.2395","3.2395","2.1597","3.7833","13.9981"
"13.1200","3.2591","3.2591","2.1728","3.8219","14.1410"
"13.2000","3.2787","3.2787","2.1858","3.8602","14.2826"
"13.2800","3.2975","3.2975","2.1983","3.8949","14.4112"
"13.3600","3.3187","3.3187","2.2125","3.9325","14.5503"
"13.4400","3.3382","3.3382","2.2255","3.9709","14.6923"
"13.5200","3.3575","3.3575","2.2383","4.0094","14.8348"
"13.6000","3.3782","3.3782","2.2522","4.0502","14.9859"
"13.6800","3.3988","3.3988","2.2658","4.0893","15.1302"
"13.7600","3.4193","3.4193","2.2795","4.1304","15.2827"
"13.8400","3.4393","3.4393","2.2928","4.1669","15.4175"
"13.9200","3.4573","3.4573","2.3049","4.2057","15.5611"
"14.0000","3.4785","3.4785","2.3190","4.2465","15.7121"
"14.0800","3.4985","3.4985","2.3323","4.2840","15.8508"
"14.1600","3.5187","3.5187","2.3458","4.3242","15.9995"
"14.2400","3.5394","3.5394","2.3596","4.3640","16.1466"
"14.3200","3.5587","3.5587","2.3725","4.4026","16.2894"
"14.4000","3.5788","3.5788","2.3859","4.4352","16.4103"
"14.4800","3.5989","3.5989","2.3992","4.4766","16.5635"
"14.5600","3.6182","3.6182","2.4121","4.5195","16.7222"
"14.6400","3.6381","3.6381","2.4254","4.5568","16.8603"
"14.7200","3.6574","3.6574","2.4383","4.5921","16.9906"
"14.8000","3.6780","3.6780","2.4520","4.6323","17.1393"
"14.8800","3.6993","3.6993","2.4662","4.6726","17.2886"
"14.9600","3.7185","3.7185","2.4790","4.7096","17.4255"
"15.0400","3.7389","3.7389","2.4926","4.7521","17.5828"
"15.1200","3.7580","3.7580","2.5053","4.7872","17.7128"
"15.2000","3.7778","3.7778","2.5185","4.8279","17.8633"
"15.2800","3.7985","3.7985","2.5323","4.8680","18.0115"
"15.3600","3.8185","3.8185","2.5457","4.9073","18.1569"
"15.4400","3.8391","3.8391","2.5594","4.9476","18.3062"
"15.5200","3.8598","3.8598","2.5732","4.9870","18.4519"
"15.6000","3.8781","3.8781","2.5854","5.0237","18.5879"
"15.6800","3.8985","3.8985","2.5990","5.0616","18.7279"
"15.7600","3.9178","3.9178","2.6119","5.0952","18.8521"
"15.8400","3.9386","3.9386","2.6258","5.1361","19.0035"
"15.9200","3.9581","3.9581","2.6387","5.1752","19.1483"
"16.0000","3.9772","3.9772","2.6515","5.2132","19.2889"
"16.0800","3.9986","3.9986","2.6657","5.2545","19.4415"
"16.1600","4.0196","4.0196","2.6798","5.2985","19.6043"
"16.2400","4.0389","4.0389","2.6926","5.3351","19.7400"
"16.3200","4.0586","4.0586","2.7057","5.3728","19.8793"
"16.4000","4.0773","4.0773","2.7182","5.4098","20.0162"
"16.4800","4.0983","4.0983","2.7322","5.4498","20.1642"
"16.5600","4.1190","4.1190","2.7460","5.4900","20.3131"
"16.6400","4.1382","4.1382","2.7588","5.5307","20.4637"
"16.7200","4.1590","4.1590","2.7727","5.5736","20.6225"
"16.8000","4.1788","4.1788","2.7859","5.6089","20.7530"
"16.8800","4.1991","4.1991","2.7994","5.6483","20.8987"
"16.9600","4.2188","4.2188","2.8125","5.6838","21.0302"
"17.0400","4.2380","4.2380","2.8253","5.7237","21.1777"
"17.1200","4.2582","4.2582","2.8388","5.7612","21.3164"
"17.2000","4.2777","4.2777","2.8518","5.8008","21.4629"
"17.2800","4.2973","4.2973","2.8649","5.8367","21.5959"
"17.3600","4.3190","4.3190","2.8793","5.8814","21.7610"
"17.4400","4.3387","4.3387","2.8925","5.9197","21.9030"
"17.5200","4.3588","4.3588","2.9059","5.9540","22.0297"
"17.6000","4.3784","4.3784","2.9189","5.9933","22.1753"
"17.6800","4.3977","4.3977","2.9318","6.0306","22.3131"
"17.7600","4.4185","4.4185","2.9457","6.0744","22.4752"
"17.8400","4.4382","4.4382","2.9588","6.1107","22.6097"
"17.9200","4.4584","4.4584","2.9723","6.1484","22.7491"
"18.0000","4.4797","4.4797","2.9864","6.1893","22.9006"
"18.0800","4.4989","4.4989","2.9992","6.2287","23.0460"
"18.1600","4.5191","4.5191","3.0127","6.2695","23.1973"
"18.2400","4.5386","4.5386","3.0258","6.3054","23.3300"
"18.3200","4.5579","4.5579","3.0386","6.3442","23.4736"
"18.4000","4.5774","4.5774","3.0516","6.3836","23.6192"
"18.4800","4.5972","4.5972","3.0648","6.4198","23.7534"
"18.5600","4.6188","4.6188","3.0792","6.4600","23.9022"
"18.6400","4.6396","4.6396","3.0931","6.5009","24.0532"
"18.7200","4.6587","4.6587","3.1058","6.5398","24.1974"
"18.8000","4.6785","4.6785","3.1190","6.5784","24.3400"
"18.8800","4.6979","4.6979","3.1320","6.6165","24.4811"
"18.9600","4.7184","4.7184","3.1456","6.6552","24.6242"
"19.0400","4.7390","4.7390","3.1593","6.6945","24.7698"
"19.1200","4.7576","4.7576","3.1717","6.7329","24.9118"
"19.2000","4.7788","4.7788","3.1859","6.7733","25.0613"
"19.2800","4.7991","4.7991","3.1994","6.8134","25.2096"
"19.3600","4.8192","4.8192","3.2128","6.8527","25.3552"
"19.4400","4.8386","4.8386","3.2257","6.8922","25.5012"
"19.5200","4.8579","4.8579","3.2386","6.9268","25.6291"
"19.6000","4.8782","4.8782","3.2521","6.9621","25.7598"
"19.6800","4.8984","4.8984","3.2656","7.0002","25.9006"
"19.7600","4.9173","4.9173","3.2782","7.0419","26.0550"
"19.8400","4.9386","4.9386","3.2924","7.0835","26.2088"
"19.9200","4.9583","4.9583","3.3056","7.1197","26.3431"
"20.0000","4.9788","4.9788","3.3192","7.1591","26.4886"
"20.0800","4.9989","4.9989","3.3326","7.1990","26.6362"
"20.1600","5.0182","5.0182","3.3455","7.2388","26.7836"
"20.2400","5.0386","5.0386","3.3591","7.2762","26.9220"
"20.3200","5.0584","5.0584","3.3723","7.3143","27.0629"
"20.4000","5.0778","5.0778","3.3852","7.3518","27.2016"
"20.4800","5.0991","5.0991","3.3994","7.3972","27.3697"
"20.5600","5.1193","5.1193","3.4129","7.4350","27.5093"
"20.6400","5.1392","5.1392","3.4262","7.4720","27.6464"
"20.7200","5.1589","5.1589","3.4392","7.5079","27.7794"
"20.8000","5.1773","5.1773","3.4515","7.5455","27.9184"
"20.8800","5.1980","5.1980","3.4653","7.5878","28.0750"
"20.9600","5.2177","5.2177","3.4784","7.6263","28.2173"
"21.0400","5.2384","5.2384","3.4922","7.6659","28.3638"
"21.1200","5.2588","5.2588","3.5058","7.7045","28.5066"
"21.2000","5.2782","5.2782","3.5188","7.7433","28.6502"
"21.2800","5.2989","5.2989","3.5326","7.7827","28.7959"
"21.3600","5.3192","5.3192","3.5461","7.8226","28.9438"
"21.4400","5.3381","5.3381","3.5587","7.8612","29.0865"
"21.5200","5.3584","5.3584","3.5723","7.9014","29.2353"
"21.6000","5.3776","5.3776","3.5851","7.9384","29.3721"
"21.6800","5.3990","5.3990","3.5993","7.9767","29.5138"
"21.7600","5.4198","5.4198","3.6132","8.0156","29.6578"
"21.8400","5.4391","5.4391","3.6260","8.0552","29.8044"
"21.9200","5.4589","5.4589","3.6393","8.0937","29.9467"
"22.0000","5.4782","5.4782","3.6521","8.1311","30.0851"
"22.0800","5.4980","5.4980","3.6653","8.1674","30.2194"
"22.1600","5.5186","5.5186","3.6791","8.2091","30.3736"
"22.2400","5.5373","5.5373","3.6916","8.2441","30.5032"
"22.3200","5.5582","5.5582","3.7055","8.2844","30.6521"
"22.4000","5.5789","5.5789","3.7193","8.3231","30.7953"
"22.4800","5.5987","5.5987","3.7324","8.3646","30.9492"
"22.5600","5.6192","5.6192","3.7461","8.4057","31.1010"
"22.6400","5.6380","5.6380","3.7586","8.4402","31.2287"
"22.7200","5.6577","5.6577","3.7718","8.4772","31.3655"
"22.8000","5.6783","5.6783","3.7855","8.5154","31.5071"
"22.8800","5.6983","5.6983","3.7989","8.5573","31.6621"
"22.9600","5.7197","5.7197","3.8131","8.6016","31.8257"
"23.0400","5.7396","5.7396","3.8264","8.6373","31.9581"
"23.1200","5.7588","5.7588","3.8392","8.6725","32.0884"
"23.2000","5.7785","5.7785","3.8523","8.7116","32.2329"
"23.2800","5.7977","5.7977","3.8651","8.7485","32.3696"
"23.3600","5.8187","5.8187","3.8791","8.7905","32.5247"
"23.4400","5.8382","5.8382","3.8922","8.8275","32.6618"
"23.5200","5.8575","5.8575","3.9050","8.8675","32.8099"
"23.6000","5.8781","5.8781","3.9187","8.9049","32.9481"
"23.6800","5.8982","5.8982","3.9321","8.9438","33.0920"
"23.7600","5.9188","5.9188","3.9459","8.9809","33.2295"
"23.8400","5.9394","5.9394","3.9596","9.0203","33.3751"
"23.9200","5.9576","5.9576","3.9718","9.0586","33.5167"
"24.0000","5.9781","5.9781","3.9854","9.0975","33.6606"
"24.0800","5.9981","5.9981","3.9987","9.1348","33.7988"
"24.1600","6.0186","6.0186","4.0124","9.1739","33.9435"
"24.2400","6.0396","6.0396","4.0264","9.2169","34.1024"
"24.3200","6.0586","6.0586","4.0391","9.2522","34.2330"
"24.4000","6.0788","6.0788","4.0525","9.2896","34.3716"
"24.4800","6.0988","6.0988","4.0658","9.3298","34.5203"
"24.5600","6.1183","6.1183","4.0789","9.3695","34.6672"
"24.6400","6.1382","6.1382","4.0921","9.4096","34.8155"
"24.7200","6.1575","6.1575","4.1050","9.4466","34.9525"
"24.8000","6.1782","6.1782","4.1188","9.4837","35.0896"
"24.8800","6.1994","6.1994","4.1329","9.5288","35.2565"
"24.9600","6.2187","6.2187","4.1458","9.5654","35.3918"
"25.0400","6.2384","6.2384","4.1590","9.6037","35.5338"
"25.1200","6.2577","6.2577","4.1718","9.6411","35.6723"
"25.2000","6.2781","6.2781","4.1854","9.6812","35.8204"
"25.2800","6.2988","6.2988","4.1992","9.7203","35.9651"
"25.3600","6.3184","6.3184","4.2123","9.7577","36.1035"
"25.4400","6.3391","6.3391","4.2261","9.7984","36.2540"
"25.5200","6.3596","6.3596","4.2397","9.8369","36.3966"
"25.6000","6.3781","6.3781","4.2521","9.8748","36.5367"
"25.6800","6.3988","6.3988","4.2659","9.9166","36.6914"
"25.7600","6.4181","6.4181","4.2787","9.9526","36.8245"
"25.8400","6.4386","6.4386","4.2924","9.9897","36.9620"
"25.9200","6.4584","6.4584","4.3056","10.0285","37.1053"
"26.0000","6.4772","6.4772","4.3182","10.0655","37.2425"
"26.0800","6.4978","6.4978","4.3319","10.1039","37.3845"
"26.1600","6.5191","6.5191","4.3461","10.1462","37.5411"
"26.2400","6.5390","6.5390","4.3593","10.1861","37.6885"
"26.3200","6.5587","6.5587","4.3725","10.2226","37.8238"
"26.4000","6.5777","6.5777","4.3852","10.2585","37.9565"
"26.4800","6.5986","6.5986","4.3991","10.2984","38.1042"
"26.5600","6.6189","6.6189","4.4126","10.3383","38.2518"
"26.6400","6.6380","6.6380","4.4253","10.3743","38.3848"
"26.7200","6.6590","6.6590","4.4394","10.4179","38.5462"
"26.8000","6.6789","6.6789","4.4526","10.4571","38.6912"
"26.8800","6.6994","6.6994","4.4663","10.4943","38.8287"
"26.9600","6.7192","6.7192","4.4794","10.5331","38.9725"
"27.0400","6.7381","6.7381","4.4921","10.5720","39.1164"
"27.1200","6.7583","6.7583","4.5055","10.6120","39.2643"
"27.2000","6.7778","6.7778","4.5186","10.6486","39.3997"
"27.2800","6.7972","6.7972","4.5315","10.6878","39.5447"
"27.3600","6.8192","6.8192","4.5462","10.7307","39.7037"
"27.4400","6.8386","6.8386","4.5590","10.7670","39.8378"
"27.5200","6.8591","6.8591","4.5727","10.8057","39.9810"
"27.6000","6.8785","6.8785","4.5857","10.8423","40.1164"
"27.6800","6.8978","6.8978","4.5985","10.8822","40.2640"
"27.7600","6.9183","6.9183","4.6122","10.9216","40.4100"
"27.8400","6.9376","6.9376","4.6251","10.9582","40.5454"
"27.9200","6.9583","6.9583","4.6388","10.9982","40.6932"
"28.0000","6.9796","6.9796","4.6530","11.0415","40.8535"
"28.0800","6.9991","6.9991","4.6660","11.0778","40.9878"
"28.1600","7.0194","7.0194","4.6796","11.1151","41.1259"
"28.2400","7.0389","7.0389","4.6926","11.1535","41.2678"
"28.3200","7.0577","7.0577","4.7051","11.1912","41.4074"
"28.4000","7.0782","7.0782","4.7188","11.2299","41.5507"
"28.4800","7.0971","7.0971","4.7314","11.2663","41.6854"
"28.5600","7.1186","7.1186","4.7457","11.3076","41.8382"
"28.6400","7.1398","7.1398","4.7598","11.3511","41.9990"
"28.7200","7.1590","7.1590","4.7727","11.3865","42.1300"
"28.8000","7.1782","7.1782","4.7855","11.4227","42.2638"
"28.8800","7.1980","7.1980","4.7987","11.4606","42.4042"
"28.9600","7.2185","7.2185","4.8123","11.5011","42.5539"
"29.0400","7.2390","7.2390","4.8260","11.5377","42.6896"
"29.1200","7.2574","7.2574","4.8383","11.5754","42.8291"
"29.2000","7.2791","7.2791","4.8527","11.6185","42.9884"
"29.2800","7.2994","7.2994","4.8662","11.6595","43.1401"
"29.3600","7.3192","7.3192","4.8794","11.6961","43.2757"
"29.4400","7.3385","7.3385","4.8923","11.7335","43.4141"
"29.5200","7.3579","7.3579","4.9053","11.7698","43.5484"
"29.6000","7.3782","7.3782","4.9188","11.8109","43.7004"
"29.6800","7.3986","7.3986","4.9324","11.8464","43.8317"
"29.7600","7.4175","7.4175","4.9450","11.8863","43.9792"
"29.8400","7.4387","7.4387","4.9591","11.9273","44.1310"
"29.9200","7.4582","7.4582","4.9722","11.9655","44.2722"
"30.0000","7.4786","7.4786","4.9857","12.0042","44.4156"
"30.0800","7.4990","7.4990","4.9993","12.0444","44.5642"
"30.1600","7.5179","7.5179","5.0119","12.0805","44.6979"
"30.2400","7.5384","7.5384","5.0256","12.1170","44.8328"
"30.3200","7.5583","7.5583","5.0389","12.1584","44.9862"
"30.4000","7.5780","7.5780","5.0520","12.1972","45.1296"
"30.4800","7.5995","7.5995","5.0663","12.2390","45.2844"
"30.5600","7.6192","7.6192","5.0794","12.2742","45.4145"
"30.6400","7.6393","7.6393","5.0929","12.3140","45.5616"
"30.7200","7.6592","7.6592","5.1061","12.3512","45.6995"
"30.8000","7.6773","7.6773","5.1182","12.3897","45.8421"
"30.8800","7.6979","7.6979","5.1319","12.4310","45.9947"
"30.9600","7.7176","7.7176","5.1451","12.4680","46.1315"
"31.0400","7.7380","7.7380","5.1587","12.5055","46.2705"
"31.1200","7.7588","7.7588","5.1725","12.5459","46.4199"
"31.2000","7.7787","7.7787","5.1858","12.5841","46.5613"
"31.2800","7.7987","7.7987","5.1991","12.6244","46.7101"
"31.3600","7.8188","7.8188","5.2125","12.6628","46.8525"
"31.4400","7.8379","7.8379","5.2253","12.6985","46.9845"
"31.5200","7.8587","7.8587","5.2391","12.7389","47.1341"
"31.6000","7.8776","7.8776","5.2517","12.7777","47.2776"
"31.6800","7.8989","7.8989","5.2659","12.8176","47.4253"
"31.7600","7.9198","7.9198","5.2798","12.8573","47.5719"
"31.8400","7.9391","7.9391","5.2927","12.8962","47.7158"
"31.9200","7.9584","7.9584","5.3056","12.9309","47.8445"
"32.0000","7.9782","7.9782","5.3188","12.9708","47.9921"
"32.0800","7.9983","7.9983","5.3322","13.0075","48.1279"
"32.1600","8.0188","8.0188","5.3459","13.0477","48.2763"
"32.2400","8.0373","8.0373","5.3582","13.0820","48.4035"
"32.3200","8.0582","8.0582","5.3721","13.1264","48.5678"
"32.4000","8.0788","8.0788","5.3859","13.1637","48.7058"
"32.4800","8.0984","8.0984","5.3989","13.2051","48.8590"
"32.5600","8.1194","8.1194","5.4129","13.2457","49.0089"
"32.6400","8.1379","8.1379","5.4252","13.2794","49.1338"
"32.7200","8.1585","8.1585","5.4390","13.3175","49.2746"
"32.8000","8.1787","8.1787","5.4525","13.3547","49.4123"
"32.8800","8.1982","8.1982","5.4655","13.3981","49.5728"
"32.9600","8.2192","8.2192","5.4795","13.4409","49.7312"
"33.0400","8.2394","8.2394","5.4929","13.4790","49.8724"
"33.1200","8.2586","8.2586","5.5058","13.5143","50.0031"
"33.2000","8.2786","8.2786","5.5191","13.5523","50.1435"
"33.2800","8.2977","8.2977","5.5318","13.5913","50.2879"
"33.3600","8.3188","8.3188","5.5459","13.6312","50.4355"
"33.4400","8.3383","8.3383","5.5589","13.6679","50.5711"
"33.5200","8.3577","8.3577","5.5718","13.7056","50.7109"
"33.6000","8.3779","8.3779","5.5853","13.7466","50.8625"
"33.6800","8.3983","8.3983","5.5989","13.7864","51.0095"
"33.7600","8.4192","8.4192","5.6128","13.8263","51.1572"
"33.8400","8.4394","8.4394","5.6263","13.8633","51.2941"
"33.9200","8.4578","8.4578","5.6385","13.9031","51.4416"
"34.0000","8.4782","8.4782","5.6521","13.9412","51.5825"
"34.0800","8.4982","8.4982","5.6654","13.9820","51.7333"
"34.1600","8.5188","8.5188","5.6792","14.0199","51.8737"
"34.2400","8.5400","8.5400","5.6933","14.0599","52.0215"
"34.3200","8.5588","8.5588","5.7059","14.0941","52.1483"
"34.4000","8.5788","8.5788","5.7192","14.1353","52.3007"
"34.4800","8.5989","8.5989","5.7326","14.1747","52.4466"
"34.5600","8.6181","8.6181","5.7454","14.2128","52.5873"
"34.6400","8.6380","8.6380","5.7587","14.2543","52.7410"
"34.7200","8.6573","8.6573","5.7715","14.2887","52.8682"
"34.8000","8.6781","8.6781","5.7854","14.3276","53.0123"
"34.8800","8.6995","8.6995","5.7997","14.3695","53.1670"
"34.9600","8.7185","8.7185","5.8124","14.4091","53.3135"
"35.0400","8.7388","8.7388","5.8259","14.4457","53.4490"
"35.1200","8.7579","8.7579","5.8386","14.4852","53.5951"
"35.2000","8.7779","8.7779","5.8519","14.5255","53.7443"
"35.2800","8.7983","8.7983","5.8655","14.5651","53.8910"
"35.3600","8.8185","8.8185","5.8790","14.6041","54.0352"
"35.4400","8.8393","8.8393","5.8929","14.6441","54.1833"
"35.5200","8.8600","8.8600","5.9067","14.6870","54.3418"
"35.6000","8.8782","8.8782","5.9188","14.7216","54.4700"
"35.6800","8.8983","8.8983","5.9322","14.7607","54.6147"
"35.7600","8.9180","8.9180","5.9454","14.7993","54.7575"
"35.8400","8.9389","8.9389","5.9593","14.8406","54.9104"
"35.9200","8.9582","8.9582","5.9721","14.8757","55.0402"
"36.0000","8.9767","8.9767","5.9845","14.9119","55.1739"
"36.0800","8.9982","8.9982","5.9988","14.9555","55.3355"
"36.1600","9.0197","9.0197","6.0131","14.9980","55.4926"
"36.2400","9.0391","9.0391","6.0260","15.0360","55.6331"
"36.3200","9.0586","9.0586","6.0391","15.0725","55.7681"
"36.4000","9.0775","9.0775","6.0517","15.1083","55.9008"
"36.4800","9.0984","9.0984","6.0656","15.1489","56.0509"
"36.5600","9.1190","9.1190","6.0793","15.1879","56.1953"
"36.6400","9.1381","9.1381","6.0921","15.2276","56.3423"
"36.7200","9.1590","9.1590","6.1060","15.2683","56.4927"
"36.8000","9.1787","9.1787","6.1191","15.3065","56.6339"
"36.8800","9.1991","9.1991","6.1328","15.3441","56.7731"
"36.9600","9.2187","9.2187","6.1458","15.3822","56.9140"
"37.0400","9.2378","9.2378","6.1585","15.4192","57.0509"
"37.1200","9.2579","9.2579","6.1719","15.4590","57.1982"
"37.2000","9.2777","9.2777","6.1851","15.4982","57.3432"
"37.2800","9.2976","9.2976","6.1984","15.5369","57.4866"
"37.3600","9.3195","9.3195","6.2130","15.5813","57.6507"
"37.4400","9.3386","9.3386","6.2258","15.6171","57.7833"
"37.5200","9.3590","9.3590","6.2393","15.6558","57.9263"
"37.6000","9.3785","9.3785","6.2524","15.6953","58.0728"
"37.6800","9.3978","9.3978","6.2652","15.7340","58.2159"
"37.7600","9.4183","9.4183","6.2789","15.7735","58.3619"
"37.8400","9.4381","9.4381","6.2921","15.8118","58.5037"
"37.9200","9.4586","9.4586","6.3057","15.8522","58.6530"
"38.0000","9.4795","9.4795","6.3197","15.8909","58.7963"
"38.0800","9.4988","9.4988","6.3325","15.9292","58.9380"
"38.1600","9.5189","9.5189","6.3459","15.9678","59.0807"
"38.2400","9.5384","9.5384","6.3590","16.0082","59.2304"
"38.3200","9.5576","9.5576","6.3717","16.0436","59.3614"
"38.4000","9.5779","9.5779","6.3853","16.0848","59.5137"
"38.4800","9.5972","9.5972","6.3981","16.1208","59.6470"
"38.5600","9.6189","9.6189","6.4126","16.1633","59.8040"
"38.6400","9.6397","9.6397","6.4265","16.2049","59.9581"
"38.7200","9.6588","9.6588","6.4392","16.2437","60.1016"
"38.8000","9.6786","9.6786","6.4524","16.2817","60.2424"
"38.8800","9.6981","9.6981","6.4654","16.3205","60.3859"
"38.9600","9.7180","9.7180","6.4787","16.3587","60.5272"
"39.0400","9.7389","9.7389","6.4926","16.3985","60.6744"
"39.1200","9.7578","9.7578","6.5052","16.4362","60.8138"
"39.2000","9.7791","9.7791","6.5194","16.4779","60.9683"
"39.2800","9.7992","9.7992","6.5328","16.5177","61.1156"
"39.3600","9.8193","9.8193","6.5462","16.5536","61.2483"
"39.4400","9.8384","9.8384","6.5589","16.5934","61.3956"
"39.5200","9.8579","9.8579","6.5720","16.6282","61.5243"
"39.6000","9.8781","9.8781","6.5854","16.6708","61.6821"
"39.6800","9.8986","9.8986","6.5991","16.7078","61.8190"
"39.7600","9.9174","9.9174","6.6116","16.7489","61.9711"
"39.8400","9.9389","9.9389","6.6259","16.7934","62.1355"
"39.9200","9.9587","9.9587","6.6392","16.8309","62.2743"
"40.0000","9.9788","9.9788","6.6525","16.8681","62.4120"
"40.0800","9.9984","9.9984","6.6656","16.9059","62.5517"
"40.1600","10.0177","10.0177","6.6785","16.9455","62.6985"
"40.2400","10.0386","10.0386","6.6924","16.9854","62.8461"
"40.3200","10.0585","10.0585","6.7056","17.0262","62.9971"
"40.4000","10.0780","10.0780","6.7187","17.0647","63.1394"
"40.4800","10.0991","10.0991","6.7327","17.1049","63.2882"
"40.5600","10.1192","10.1192","6.7461","17.1438","63.4321"
"40.6400","10.1392","10.1392","6.7594","17.1839","63.5805"
"40.7200","10.1590","10.1590","6.7727","17.2230","63.7252"
"40.8000","10.1775","10.1775","6.7850","17.2583","63.8556"
"40.8800","10.1983","10.1983","6.7989","17.3009","64.0135"
"40.9600","10.2175","10.2175","6.8116","17.3392","64.1549"
"41.0400","10.2383","10.2383","6.8256","17.3784","64.3000"
"41.1200","10.2587","10.2587","6.8391","17.4179","64.4461"
"41.2000","10.2782","10.2782","6.8521","17.4569","64.5905"
"41.2800","10.2986","10.2986","6.8657","17.4990","64.7461"
"41.3600","10.3192","10.3192","6.8795","17.5374","64.8885"
"41.4400","10.3382","10.3382","6.8921","17.5769","65.0345"
"41.5200","10.3585","10.3585","6.9057","17.6150","65.1755"
"41.6000","10.3777","10.3777","6.9185","17.6516","65.3110"
"41.6800","10.3988","10.3988","6.9326","17.6922","65.4612"
"41.7600","10.4195","10.4195","6.9463","17.7331","65.6123"
"41.8400","10.4392","10.4392","6.9595","17.7733","65.7613"
"41.9200","10.4586","10.4586","6.9724","17.8112","65.9015"
"42.0000","10.4781","10.4781","6.9854","17.8494","66.0427"
"42.0800","10.4982","10.4982","6.9988","17.8888","66.1884"
"42.1600","10.5187","10.5187","7.0125","17.9289","66.3368"
"42.2400","10.5373","10.5373","7.0249","17.9650","66.4705"
"42.3200","10.5582","10.5582","7.0388","18.0042","66.6154"
"42.4000","10.5790","10.5790","7.0527","18.0467","66.7727"
"42.4800","10.5986","10.5986","7.0657","18.0896","66.9315"
"42.5600","10.6189","10.6189","7.0793","18.1281","67.0738"
"42.6400","10.6378","10.6378","7.0919","18.1629","67.2028"
"42.7200","10.6584","10.6584","7.1056","18.2036","67.3532"
"42.8000","10.6784","10.6784","7.1189","18.2405","67.4898"
"42.8800","10.6980","10.6980","7.1320","18.2816","67.6419"
"42.9600","10.7191","10.7191","7.1461","18.3239","67.7985"
"43.0400","10.7394","10.7394","7.1596","18.3650","67.9504"
"43.1200","10.7589","10.7589","7.1726","18.3999","68.0796"
"43.2000","10.7788","10.7788","7.1859","18.4414","68.2330"
"43.2800","10.7976","10.7976","7.1984","18.4769","68.3646"
"43.3600","10.8188","10.8188","7.2125","18.5192","68.5211"
"43.4400","10.8383","10.8383","7.2255","18.5575","68.6629"
"43.5200","10.8577","10.8577","7.2385","18.5978","68.8120"
"43.6000","10.8778","10.8778","7.2519","18.6376","68.9592"
"43.6800","10.8989","10.8989","7.2659","18.6815","69.1216"
"43.7600","10.9191","10.9191","7.2794","18.7184","69.2582"
"43.8400","10.9388","10.9388","7.2926","18.7539","69.3896"
"43.9200","10.9576","10.9576","7.3051","18.7928","69.5333"
"44.0000","10.9783","10.9783","7.3189","18.8343","69.6871"
"44.0800","10.9982","10.9982","7.3322","18.8741","69.8342"
"44.1600","11.0188","11.0188","7.3459","18.9149","69.9851"
"44.2400","11.0396","11.0396","7.3597","18.9559","70.1367"
"44.3200","11.0591","11.0591","7.3727","18.9961","70.2854"
"44.4000","11.0789","11.0789","7.3859","19.0307","70.4136"
"44.4800","11.0987","11.0987","7.3991","19.0689","70.5549"
"44.5600","11.1183","11.1183","7.4122","19.1119","70.7140"
"44.6400","11.1381","11.1381","7.4254","19.1498","70.8543"
"44.7200","11.1572","11.1572","7.4381","19.1863","70.9892"
"44.8000","11.1781","11.1781","7.4521","19.2270","71.1401"
"44.8800","11.1996","11.1996","7.4664","19.2718","71.3056"
"44.9600","11.2188","11.2188","7.4792","19.3106","71.4494"
"45.0400","11.2389","11.2389","7.4926","19.3505","71.5970"
"45.1200","11.2572","11.2572","7.5048","19.3879","71.7354"
"45.2000","11.2779","11.2779","7.5186","19.4260","71.8760"
"45.2800","11.2985","11.2985","7.5323","19.4683","72.0328"
"45.3600","11.3183","11.3183","7.5456","19.5082","72.1802"
"45.4400","11.3390","11.3390","7.5593","19.5496","72.3335"
"45.5200","11.3596","11.3596","7.5731","19.5893","72.4803"
"45.6000","11.3782","11.3782","7.5855","19.6273","72.6210"
"45.6800","11.3989","11.3989","7.5992","19.6706","72.7812"
"45.7600","11.4183","11.4183","7.6122","19.7073","72.9170"
"45.8400","11.4386","11.4386","7.6258","19.7473","73.0649"
"45.9200","11.4581","11.4581","7.6387","19.7809","73.1895"
"46.0000","11.4770","11.4770","7.6513","19.8214","73.3393"
"46.0800","11.4983","11.4983","7.6655","19.8646","73.4991"
"46.1600","11.5192","11.5192","7.6794","19.9070","73.6558"
"46.2400","11.5388","11.5388","7.6925","19.9467","73.8028"
"46.3200","11.5587","11.5587","7.7058","19.9832","73.9378"
"46.4000","11.5774","11.5774","7.7182","20.0188","74.0697"
"46.4800","11.5977","11.5977","7.7318","20.0595","74.2203"
"46.5600","11.6190","11.6190","7.7460","20.1003","74.3711"
"46.6400","11.6387","11.6387","7.7591","20.1438","74.5321"
"46.7200","11.6592","11.6592","7.7728","20.1855","74.6862"
"46.8000","11.6788","11.6788","7.7859","20.2219","74.8211"
"46.8800","11.6994","11.6994","7.7996","20.2605","74.9639"
"46.9600","11.7190","11.7190","7.8127","20.3013","75.1147"
"47.0400","11.7383","11.7383","7.8255","20.3412","75.2626"
"47.1200","11.7582","11.7582","7.8388","20.3788","75.4017"
"47.2000","11.7778","11.7778","7.8519","20.4159","75.5390"
"47.2800","11.7973","11.7973","7.8649","20.4579","75.6943"
"47.3600","11.8195","11.8195","7.8797","20.5031","75.8615"
"47.4400","11.8388","11.8388","7.8925","20.5390","75.9942"
"47.5200","11.8590","11.8590","7.9060","20.5779","76.1383"
"47.6000","11.8781","11.8781","7.9188","20.6159","76.2787"
"47.6800","11.8981","11.8981","7.9321","20.6565","76.4291"
"47.7600","11.9183","11.9183","7.9456","20.6999","76.5896"
"47.8400","11.9383","11.9383","7.9589","20.7380","76.7305"
"47.9200","11.9586","11.9586","7.9724","20.7752","76.8681"
"48.0000","11.9795","11.9795","7.9863","20.8185","77.0285"
"48.0800","11.9987","11.9987","7.9991","20.8558","77.1665"
"48.1600","12.0193","12.0193","8.0129","20.8986","77.3246"
"48.2400","12.0384","12.0384","8.0256","20.9360","77.4631"
"48.3200","12.0579","12.0579","8.0386","20.9745","77.6056"
"48.4000","12.0780","12.0780","8.0520","21.0147","77.7543"
"48.4800","12.0967","12.0967","8.0645","21.0506","77.8874"
"48.5600","12.1186","12.1186","8.0791","21.0949","78.0511"
"48.6400","12.1393","12.1393","8.0929","21.1366","78.2054"
"48.7200","12.1588","12.1588","8.1059","21.1803","78.3672"
"48.8000","12.1782","12.1782","8.1188","21.2157","78.4980"
"48.8800","12.1978","12.1978","8.1319","21.2509","78.6283"
"48.9600","12.2185","12.2185","8.1457","21.2939","78.7875"
"49.0400","12.2392","12.2392","8.1594","21.3339","78.9355"
"49.1200","12.2574","12.2574","8.1716","21.3693","79.0666"
"49.2000","12.2792","12.2792","8.1861","21.4144","79.2334"
"49.2800","12.2992","12.2992","8.1995","21.4564","79.3886"
"49.3600","12.3193","12.3193","8.2129","21.4957","79.5341"
"49.4400","12.3387","12.3387","8.2258","21.5360","79.6833"
"49.5200","12.3581","12.3581","8.2387","21.5731","79.8205"
"49.6000","12.3782","12.3782","8.2521","21.6108","79.9600"
"49.6800","12.3986","12.3986","8.2658","21.6497","80.1037"
"49.7600","12.4172","12.4172","8.2781","21.6900","80.2531"
"49.8400","12.4384","12.4384","8.2923","21.7330","80.4121"
"49.9200","12.4583","12.4583","8.3055","21.7711","80.5532"
"50.0000","12.4787","12.4787","8.3191","21.8120","80.7046"
"50.0800","12.4990","12.4990","8.3326","21.8537","80.8587"
"50.1600","12.5180","12.5180","8.3453","21.8928","81.0033"
"50.2400","12.5386","12.5386","8.3591","21.9318","81.1475"
"50.3200","12.5585","12.5585","8.3723","21.9734","81.3015"
"50.4000","12.5782","12.5782","8.3855","22.0111","81.4412"
"50.4800","12.5993","12.5993","8.3995","22.0556","81.6056"
"50.5600","12.6190","12.6190","8.4127","22.0904","81.7345"
"50.6400","12.6391","12.6391","8.4261","22.1314","81.8862"
"50.7200","12.6588","12.6588","8.4392","22.1686","82.0239"
"50.8000","12.6774","12.6774","8.4516","22.2078","82.1689"
"50.8800","12.6982","12.6982","8.4655","22.2502","82.3256"
"50.9600","12.7174","12.7174","8.4783","22.2877","82.4645"
"51.0400","12.7382","12.7382","8.4922","22.3298","82.6202"
"51.1200","12.7588","12.7588","8.5059","22.3709","82.7722"
"51.2000","12.7789","12.7789","8.5192","22.4094","82.9147"
"51.2800","12.7986","12.7986","8.5324","22.4491","83.0617"
"51.3600","12.8186","12.8186","8.5457","22.4891","83.2097"
"51.4400","12.8379","12.8379","8.5586","22.5287","83.3563"
"51.5200","12.8588","12.8588","8.5725","22.5695","83.5072"
"51.6000","12.8772","12.8772","8.5848","22.6054","83.6398"
"51.6800","12.8993","12.8993","8.5995","22.6516","83.8108"
"51.7600","12.9200","12.9200","8.6133","22.6891","83.9498"
"51.8400","12.9390","12.9390","8.6260","22.7303","84.1019"
"51.9200","12.9584","12.9584","8.6389","22.7677","84.2404"
"52.0000","12.9782","12.9782","8.6521","22.8062","84.3829"
"52.0800","12.9981","12.9981","8.6654","22.8462","84.5310"
"52.1600","13.0189","13.0189","8.6793","22.8872","84.6827"
"52.2400","13.0374","13.0374","8.6916","22.9225","84.8134"
"52.3200","13.0581","13.0581","8.7054","22.9645","84.9685"
"52.4000","13.0790","13.0790","8.7193","23.0099","85.1366"
"52.4800","13.0988","13.0988","8.7326","23.0495","85.2832"
"52.5600","13.1188","13.1188","8.7459","23.0854","85.4158"
"52.6400","13.1378","13.1378","8.7585","23.1245","85.5608"
"52.7200","13.1585","13.1585","8.7724","23.1645","85.7088"
"52.8000","13.1788","13.1788","8.7859","23.2067","85.8650"
"52.8800","13.1979","13.1979","8.7986","23.2440","86.0028"
"52.9600","13.2192","13.2192","8.8128","23.2913","86.1779"
"53.0400","13.2394","13.2394","8.8262","23.3293","86.3182"
"53.1200","13.2586","13.2586","8.8391","23.3676","86.4601"
"53.2000","13.2787","13.2787","8.8525","23.4073","86.6072"
"53.2800","13.2975","13.2975","8.8650","23.4429","86.7386"
"53.3600","13.3186","13.3186","8.8791","23.4855","86.8962"
"53.4400","13.3382","13.3382","8.8921","23.5241","87.0392"
"53.5200","13.3579","13.3579","8.9052","23.5639","87.1865"
"53.6000","13.3783","13.3783","8.9189","23.6071","87.3463"
"53.6800","13.3985","13.3985","8.9324","23.6463","87.4913"
"53.7600","13.4192","13.4192","8.9461","23.6867","87.6407"
"53.8400","13.4392","13.4392","8.9595","23.7260","87.7862"
"53.9200","13.4575","13.4575","8.9716","23.7614","87.9170"
"54.0000","13.4782","13.4782","8.9855","23.8042","88.0755"
"54.0800","13.4981","13.4981","8.9987","23.8441","88.2233"
"54.1600","13.5189","13.5189","9.0126","23.8847","88.3734"
"54.2400","13.5398","13.5398","9.0265","23.9287","88.5361"
"54.3200","13.5585","13.5585","9.0390","23.9641","88.6673"
"54.4000","13.5790","13.5790","9.0526","24.0047","88.8175"
"54.4800","13.5989","13.5989","9.0659","24.0460","88.9701"
"54.5600","13.6184","13.6184","9.0789","24.0847","89.1133"
"54.6400","13.6384","13.6384","9.0922","24.1280","89.2738"
"54.7200","13.6577","13.6577","9.1051","24.1632","89.4037"
"54.8000","13.6780","13.6780","9.1187","24.2023","89.5486"
"54.8800","13.6992","13.6992","9.1328","24.2463","89.7112"
"54.9600","13.7187","13.7187","9.1458","24.2853","89.8558"
"55.0400","13.7391","13.7391","9.1594","24.3254","90.0039"
"55.1200","13.7576","13.7576","9.1718","24.3610","90.1358"
"55.2000","13.7776","13.7776","9.1850","24.4047","90.2974"
"55.2800","13.7984","13.7984","9.1989","24.4468","90.4531"
"55.3600","13.8183","13.8183","9.2122","24.4849","90.5943"
"55.4400","13.8393","13.8393","9.2262","24.5298","90.7604"
"55.5200","13.8598","13.8598","9.2399","24.5685","90.9034"
"55.6000","13.8784","13.8784","9.2523","24.6048","91.0376"
"55.6800","13.8983","13.8983","9.2655","24.6460","91.1901"
"55.7600","13.9179","13.9179","9.2786","24.6840","91.3307"
"55.8400","13.9387","13.9387","9.2924","24.7232","91.4759"
"55.9200","13.9585","13.9585","9.3056","24.7621","91.6199"
"56.0000","13.9770","13.9770","9.3180","24.7991","91.7568"
"56.0800","13.9984","13.9984","9.3323","24.8428","91.9184"
"56.1600","14.0191","14.0191","9.3461","24.8837","92.0699"
"56.2400","14.0389","14.0389","9.3593","24.9243","92.2200"
"56.3200","14.0587","14.0587","9.3725","24.9626","92.3618"
"56.4000","14.0773","14.0773","9.3849","24.9957","92.4840"
"56.4800","14.0979","14.0979","9.3986","25.0368","92.6362"
"56.5600","14.1190","14.1190","9.4126","25.0810","92.7999"
"56.6400","14.1384","14.1384","9.4256","25.1198","92.9433"
"56.7200","14.1589","14.1589","9.4393","25.1632","93.1038"
"56.8000","14.1783","14.1783","9.4522","25.1993","93.2376"
"56.8800","14.1995","14.1995","9.4663","25.2417","93.3943"
"56.9600","14.2196","14.2196","9.4797","25.2825","93.5451"
"57.0400","14.2381","14.2381","9.4921","25.3194","93.6818"
"57.1200","14.2580","14.2580","9.5054","25.3565","93.8191"
"57.2000","14.2778","14.2778","9.5186","25.3964","93.9668"
"57.2800","14.2979","14.2979","9.5319","25.4372","94.1178"
"57.3600","14.3195","14.3195","9.5464","25.4838","94.2901"
"57.4400","14.3384","14.3384","9.5589","25.5184","94.4180"
"57.5200","14.3589","14.3589","9.5726","25.5579","94.5644"
"57.6000","14.3785","14.3785","9.5857","25.5960","94.7051"
"57.6800","14.3979","14.3979","9.5986","25.6360","94.8532"
"57.7600","14.4185","14.4185","9.6123","25.6795","95.0141"
"57.8400","14.4384","14.4383","9.6256","25.7175","95.1547"
"57.9200","14.4587","14.4587","9.6391","25.7524","95.2837"
"58.0000","14.4794","14.4794","9.6529","25.7958","95.4444"
"58.0800","14.4988","14.4988","9.6659","25.8355","95.5912"
"58.1600","14.5193","14.5193","9.6795","25.8772","95.7458"
"58.2400","14.5385","14.5385","9.6923","25.9130","95.8779"
"58.3200","14.5579","14.5579","9.7053","25.9534","96.0277"
"58.4000","14.5778","14.5778","9.7185","25.9920","96.1705"
"58.4800","14.5973","14.5973","9.7316","26.0299","96.3106"
"58.5600","14.6187","14.6187","9.7458","26.0704","96.4603"
"58.6400","14.6394","14.6394","9.7596","26.1120","96.6143"
"58.7200","14.6585","14.6585","9.7724","26.1517","96.7613"
"58.8000","14.6784","14.6784","9.7856","26.1893","96.9002"
"58.8800","14.6980","14.6980","9.7987","26.2274","97.0413"
"58.9600","14.7184","14.7184","9.8123","26.2690","97.1954"
"59.0400","14.7390","14.7390","9.8260","26.3077","97.3387"
"59.1200","14.7575","14.7575","9.8383","26.3457","97.4789"
"59.2000","14.7789","14.7789","9.8526","26.3885","97.6374"
"59.2800","14.7991","14.7991","9.8661","26.4293","97.7884"
"59.3600","14.8189","14.8189","9.8792","26.4665","97.9259"
"59.4400","14.8387","14.8387","9.8925","26.5064","98.0735"
"59.5200","14.8581","14.8581","9.9054","26.5436","98.2113"
"59.6000","14.8783","14.8783","9.9189","26.5801","98.3464"
"59.6800","14.8986","14.8986","9.9324","26.6228","98.5044"
"59.7600","14.9174","14.9174","9.9450","26.6601","98.6423"
"59.8400","14.9383","14.9383","9.9589","26.7014","98.7953"
"59.9200","14.9585","14.9585","9.9723","26.7399","98.9376"
"60.0000","14.9788","14.9788","9.9859","26.7786","99.0809"
"60.0800","14.9988","14.9988","9.9992","26.8188","99.2296"
"60.0850","15.0001","15.0001","10.0001","26.8208","99.2370"