File: data/instron_tests/250106_metamaterial_foam_test_data/250106_metamaterial_foams_1_1.csv
Results Table 1


Results Table 2


Time,Displacement,Compressive displacement,Compressive strain (Displacement),Compressive stress,Force
(s),(mm),(mm),(%),(kPa),(N)
"0.0000","0.6083","-0.0096","-0.0064","-0.0276","-0.1035"
"0.0600","0.6098","-0.0080","-0.0054","-0.0223","-0.0837"
"0.1200","0.6248","0.0069","0.0046","0.0433","0.1622"
"0.1800","0.6563","0.0384","0.0257","0.1815","0.6807"
"0.2400","0.6865","0.0687","0.0460","0.3034","1.1379"
"0.3000","0.7145","0.0967","0.0647","0.4121","1.5453"
"0.3600","0.7444","0.1266","0.0847","0.5282","1.9809"
"0.4200","0.7739","0.1560","0.1044","0.6373","2.3899"
"0.4800","0.8051","0.1873","0.1254","0.7551","2.8316"
"0.5400","0.8344","0.2166","0.1450","0.8627","3.2351"
"0.6000","0.8637","0.2458","0.1646","0.9666","3.6249"
"0.6600","0.8943","0.2764","0.1850","1.0807","4.0525"
"0.7200","0.9241","0.3063","0.2050","1.1897","4.4614"
"0.7800","0.9553","0.3374","0.2259","1.3042","4.8907"
"0.8400","0.9851","0.3673","0.2458","1.4129","5.2984"
"0.9000","1.0143","0.3965","0.2654","1.5140","5.6773"
"0.9600","1.0440","0.4261","0.2853","1.6180","6.0677"
"1.0200","1.0731","0.4553","0.3048","1.7225","6.4594"
"1.0800","1.1045","0.4866","0.3258","1.8353","6.8823"
"1.1400","1.1346","0.5168","0.3459","1.9433","7.2875"
"1.2000","1.1643","0.5465","0.3658","2.0506","7.6897"
"1.2600","1.1941","0.5763","0.3858","2.1573","8.0900"
"1.3200","1.2237","0.6058","0.4056","2.2612","8.4796"
"1.3800","1.2540","0.6362","0.4259","2.3703","8.8886"
"1.4400","1.2848","0.6670","0.4465","2.4808","9.3032"
"1.5000","1.3151","0.6973","0.4668","2.5923","9.7213"
"1.5600","1.3437","0.7259","0.4859","2.6906","10.0897"
"1.6200","1.3738","0.7559","0.5060","2.8003","10.5012"
"1.6800","1.4038","0.7860","0.5261","2.9099","10.9120"
"1.7400","1.4346","0.8168","0.5468","3.0181","11.3179"
"1.8000","1.4650","0.8471","0.5671","3.1251","11.7191"
"1.8600","1.4941","0.8762","0.5866","3.2331","12.1241"
"1.9200","1.5242","0.9064","0.6068","3.3445","12.5419"
"1.9800","1.5542","0.9364","0.6268","3.4532","12.9495"
"2.0400","1.5859","0.9680","0.6480","3.5697","13.3865"
"2.1000","1.6155","0.9976","0.6678","3.6757","13.7839"
"2.1600","1.6438","1.0260","0.6868","3.7759","14.1596"
"2.2200","1.6745","1.0566","0.7073","3.8882","14.5808"
"2.2800","1.7036","1.0858","0.7268","3.9933","14.9750"
"2.3400","1.7348","1.1170","0.7477","4.1116","15.4184"
"2.4000","1.7649","1.1470","0.7678","4.2197","15.8238"
"2.4600","1.7944","1.1766","0.7876","4.3252","16.2194"
"2.5200","1.8237","1.2059","0.8072","4.4339","16.6273"
"2.5800","1.8535","1.2357","0.8272","4.5411","17.0290"
"2.6400","1.8854","1.2675","0.8485","4.6612","17.4794"
"2.7000","1.9153","1.2974","0.8685","4.7723","17.8961"
"2.7600","1.9448","1.3269","0.8883","4.8815","18.3056"
"2.8200","1.9738","1.3559","0.9077","4.9879","18.7048"
"2.8800","2.0040","1.3861","0.9279","5.1018","19.1317"
"2.9400","2.0344","1.4165","0.9483","5.2145","19.5544"
"3.0000","2.0645","1.4466","0.9684","5.3257","19.9715"
"3.0600","2.0950","1.4771","0.9888","5.4418","20.4067"
"3.1200","2.1239","1.5061","1.0082","5.5478","20.8043"
"3.1800","2.1542","1.5363","1.0285","5.6630","21.2361"
"3.2400","2.1841","1.5662","1.0485","5.7749","21.6557"
"3.3000","2.2155","1.5976","1.0695","5.8921","22.0955"
"3.3600","2.2452","1.6273","1.0894","6.0035","22.5132"
"3.4200","2.2741","1.6563","1.1087","6.1108","22.9156"
"3.4800","2.3048","1.6869","1.1293","6.2294","23.3601"
"3.5400","2.3337","1.7158","1.1486","6.3370","23.7638"
"3.6000","2.3644","1.7466","1.1692","6.4566","24.2121"
"3.6600","2.3948","1.7769","1.1895","6.5714","24.6429"
"3.7200","2.4241","1.8063","1.2092","6.6855","25.0708"
"3.7800","2.4542","1.8364","1.2293","6.7995","25.4980"
"3.8400","2.4837","1.8659","1.2491","6.9135","25.9256"
"3.9000","2.5157","1.8978","1.2704","7.0398","26.3994"
"3.9600","2.5449","1.9270","1.2900","7.1509","26.8158"
"4.0200","2.5746","1.9568","1.3099","7.2662","27.2483"
"4.0800","2.6049","1.9871","1.3302","7.3855","27.6956"
"4.1400","2.6335","2.0157","1.3493","7.4928","28.0978"
"4.2000","2.6642","2.0464","1.3699","7.6158","28.5594"
"4.2600","2.6950","2.0771","1.3905","7.7367","29.0128"
"4.3200","2.7249","2.1070","1.4105","7.8539","29.4522"
"4.3800","2.7536","2.1358","1.4297","7.9661","29.8728"
"4.4400","2.7840","2.1662","1.4501","8.0848","30.3180"
"4.5000","2.8146","2.1968","1.4706","8.2091","30.7841"
"4.5600","2.8454","2.2275","1.4912","8.3321","31.2455"
"4.6200","2.8751","2.2573","1.5111","8.4490","31.6837"
"4.6800","2.9048","2.2869","1.5309","8.5666","32.1249"
"4.7400","2.9339","2.3160","1.5504","8.6819","32.5573"
"4.8000","2.9632","2.3454","1.5700","8.7959","32.9845"
"4.8600","2.9954","2.3776","1.5916","8.9262","33.4732"
"4.9200","3.0246","2.4068","1.6111","9.0394","33.8977"
"4.9800","3.0536","2.4357","1.6305","9.1537","34.3264"
"5.0400","3.0843","2.4665","1.6511","9.2775","34.7906"
"5.1000","3.1140","2.4962","1.6710","9.3940","35.2276"
"5.1600","3.1452","2.5274","1.6919","9.5209","35.7034"
"5.2200","3.1752","2.5573","1.7119","9.6410","36.1537"
"5.2800","3.2047","2.5868","1.7317","9.7563","36.5860"
"5.3400","3.2345","2.6167","1.7517","9.8758","37.0342"
"5.4000","3.2634","2.6455","1.7710","9.9891","37.4590"
"5.4600","3.2951","2.6772","1.7922","10.1184","37.9441"
"5.5200","3.3246","2.7068","1.8120","10.2378","38.3919"
"5.5800","3.3543","2.7364","1.8318","10.3562","38.8357"
"5.6400","3.3844","2.7665","1.8520","10.4773","39.2898"
"5.7000","3.4143","2.7964","1.8720","10.5963","39.7362"
"5.7600","3.4452","2.8273","1.8927","10.7212","40.2046"
"5.8200","3.4753","2.8575","1.9129","10.8438","40.6643"
"5.8800","3.5054","2.8876","1.9330","10.9642","41.1156"
"5.9400","3.5341","2.9163","1.9522","11.0780","41.5424"
"6.0000","3.5635","2.9457","1.9719","11.1987","41.9953"
"6.0600","3.5944","2.9766","1.9926","11.3277","42.4790"
"6.1200","3.6249","3.0070","2.0130","11.4484","42.9314"
"6.1800","3.6544","3.0365","2.0327","11.5681","43.3804"
"6.2400","3.6841","3.0662","2.0526","11.6885","43.8318"
"6.3000","3.7142","3.0964","2.0728","11.8127","44.2976"
"6.3600","3.7438","3.1260","2.0926","11.9340","44.7525"
"6.4200","3.7755","3.1577","2.1138","12.0661","45.2479"
"6.4800","3.8050","3.1872","2.1336","12.1842","45.6909"
"6.5400","3.8343","3.2165","2.1532","12.3040","46.1400"
"6.6000","3.8640","3.2462","2.1731","12.4212","46.5793"
"6.6600","3.8933","3.2755","2.1927","12.5410","47.0288"
"6.7200","3.9249","3.3070","2.2138","12.6754","47.5326"
"6.7800","3.9545","3.3366","2.2336","12.7959","47.9847"
"6.8400","3.9839","3.3660","2.2533","12.9168","48.4379"
"6.9000","4.0143","3.3965","2.2737","13.0431","48.9115"
"6.9600","4.0441","3.4263","2.2936","13.1678","49.3793"
"7.0200","4.0756","3.4578","2.3147","13.3024","49.8840"
"7.0800","4.1051","3.4872","2.3344","13.4214","50.3303"
"7.1400","4.1344","3.5165","2.3540","13.5426","50.7849"
"7.2000","4.1640","3.5461","2.3739","13.6678","51.2541"
"7.2600","4.1936","3.5757","2.3937","13.7870","51.7013"
"7.3200","4.2243","3.6065","2.4142","13.9161","52.1852"
"7.3800","4.2546","3.6367","2.4345","14.0428","52.6605"
"7.4400","4.2848","3.6670","2.4548","14.1683","53.1313"
"7.5000","4.3138","3.6959","2.4741","14.2877","53.5789"
"7.5600","4.3438","3.7259","2.4942","14.4146","54.0549"
"7.6200","4.3743","3.7564","2.5146","14.5402","54.5257"
"7.6800","4.4050","3.7872","2.5352","14.6686","55.0073"
"7.7400","4.4351","3.8173","2.5554","14.7934","55.4751"
"7.8000","4.4641","3.8462","2.5748","14.9117","55.9190"
"7.8600","4.4946","3.8768","2.5952","15.0419","56.4071"
"7.9200","4.5241","3.9062","2.6149","15.1644","56.8666"
"7.9800","4.5545","3.9367","2.6353","15.2933","57.3499"
"8.0400","4.5849","3.9671","2.6556","15.4213","57.8299"
"8.1000","4.6138","3.9960","2.6750","15.5405","58.2769"
"8.1600","4.6441","4.0262","2.6953","15.6694","58.7602"
"8.2200","4.6745","4.0566","2.7156","15.7994","59.2477"
"8.2800","4.7059","4.0880","2.7366","15.9328","59.7481"
"8.3400","4.7351","4.1173","2.7562","16.0539","60.2021"
"8.4000","4.7643","4.1464","2.7757","16.1737","60.6514"
"8.4600","4.7944","4.1766","2.7959","16.3039","61.1395"
"8.5200","4.8236","4.2057","2.8154","16.4242","61.5909"
"8.5800","4.8545","4.2367","2.8361","16.5592","62.0969"
"8.6400","4.8850","4.2671","2.8565","16.6877","62.5790"
"8.7000","4.9148","4.2970","2.8765","16.8151","63.0565"
"8.7600","4.9438","4.3260","2.8959","16.9361","63.5103"
"8.8200","4.9738","4.3560","2.9160","17.0618","63.9817"
"8.8800","5.0050","4.3871","2.9369","17.1976","64.4909"
"8.9400","5.0348","4.4169","2.9568","17.3206","64.9523"
"9.0000","5.0649","4.4470","2.9769","17.4505","65.4392"
"9.0600","5.0944","4.4766","2.9967","17.5758","65.9094"
"9.1200","5.1244","4.5066","3.0168","17.7032","66.3871"
"9.1800","5.1536","4.5357","3.0363","17.8280","66.8550"
"9.2400","5.1848","4.5670","3.0573","17.9640","67.3651"
"9.3000","5.2158","4.5980","3.0780","18.0992","67.8721"
"9.3600","5.2435","4.6256","3.0965","18.2127","68.2977"
"9.4200","5.2742","4.6564","3.1171","18.3456","68.7959"
"9.4800","5.3044","4.6866","3.1373","18.4781","69.2928"
"9.5400","5.3352","4.7174","3.1579","18.6112","69.7922"
"9.6000","5.3650","4.7472","3.1779","18.7390","70.2711"
"9.6600","5.3946","4.7767","3.1977","18.8654","70.7453"
"9.7200","5.4245","4.8067","3.2177","18.9916","71.2183"
"9.7800","5.4526","4.8348","3.2365","19.1120","71.6699"
"9.8400","5.4848","4.8670","3.2581","19.2592","72.2220"
"9.9000","5.5153","4.8974","3.2785","19.3876","72.7036"
"9.9600","5.5437","4.9259","3.2975","19.5073","73.1523"
"10.0200","5.5736","4.9557","3.3175","19.6387","73.6451"
"10.0800","5.6042","4.9863","3.3380","19.7737","74.1515"
"10.1400","5.6353","5.0174","3.3588","19.9126","74.6721"
"10.2000","5.6650","5.0471","3.3787","20.0405","75.1518"
"10.2600","5.6947","5.0769","3.3986","20.1705","75.6394"
"10.3200","5.7244","5.1065","3.4184","20.2994","76.1227"
"10.3800","5.7534","5.1355","3.4379","20.4212","76.5797"
"10.4400","5.7841","5.1662","3.4584","20.5596","77.0986"
"10.5000","5.8151","5.1972","3.4791","20.6946","77.6046"
"10.5600","5.8443","5.2265","3.4987","20.8193","78.0725"
"10.6200","5.8737","5.2559","3.5184","20.9491","78.5591"
"10.6800","5.9044","5.2865","3.5389","21.0854","79.0703"
"10.7400","5.9345","5.3167","3.5591","21.2187","79.5703"
"10.8000","5.9652","5.3473","3.5796","21.3541","80.0780"
"10.8600","5.9952","5.3773","3.5997","21.4850","80.5689"
"10.9200","6.0240","5.4062","3.6190","21.6093","81.0349"
"10.9800","6.0541","5.4363","3.6392","21.7453","81.5448"
"11.0400","6.0835","5.4657","3.6589","21.8734","82.0252"
"11.1000","6.1151","5.4972","3.6800","22.0172","82.5643"
"11.1600","6.1445","5.5267","3.6997","22.1450","83.0436"
"11.2200","6.1739","5.5561","3.7194","22.2718","83.5192"
"11.2800","6.2046","5.5867","3.7399","22.4113","84.0423"
"11.3400","6.2337","5.6159","3.7594","22.5387","84.5200"
"11.4000","6.2649","5.6471","3.7803","22.6800","85.0499"
"11.4600","6.2953","5.6774","3.8006","22.8153","85.5574"
"11.5200","6.3245","5.7067","3.8202","22.9428","86.0354"
"11.5800","6.3536","5.7358","3.8397","23.0726","86.5222"
"11.6400","6.3836","5.7658","3.8597","23.2042","87.0157"
"11.7000","6.4146","5.7968","3.8805","23.3452","87.5443"
"11.7600","6.4446","5.8267","3.9005","23.4804","88.0517"
"11.8200","6.4745","5.8566","3.9206","23.6136","88.5511"
"11.8800","6.5040","5.8861","3.9403","23.7447","89.0427"
"11.9400","6.5338","5.9160","3.9603","23.8803","89.5511"
"12.0000","6.5646","5.9467","3.9809","24.0200","90.0749"
"12.0600","6.5954","5.9776","4.0015","24.1593","90.5975"
"12.1200","6.6253","6.0074","4.0215","24.2957","91.1090"
"12.1800","6.6542","6.0364","4.0409","24.4253","91.5948"
"12.2400","6.6839","6.0660","4.0608","24.5593","92.0975"
"12.3000","6.7140","6.0962","4.0809","24.6987","92.6200"
"12.3600","6.7449","6.1270","4.1016","24.8370","93.1387"
"12.4200","6.7745","6.1567","4.1214","24.9716","93.6437"
"12.4800","6.8039","6.1860","4.1411","25.1067","94.1501"
"12.5400","6.8344","6.2165","4.1615","25.2450","94.6688"
"12.6000","6.8642","6.2463","4.1814","25.3830","95.1862"
"12.6600","6.8956","6.2777","4.2025","25.5289","95.7334"
"12.7200","6.9252","6.3074","4.2223","25.6604","96.2265"
"12.7800","6.9542","6.3363","4.2417","25.7906","96.7147"
"12.8400","6.9841","6.3662","4.2617","25.9272","97.2270"
"12.9000","7.0133","6.3955","4.2813","26.0594","97.7226"
"12.9600","7.0442","6.4264","4.3020","26.2019","98.2572"
"13.0200","7.0749","6.4570","4.3225","26.3425","98.7843"
"13.0800","7.1045","6.4867","4.3423","26.4772","99.2895"
"13.1400","7.1336","6.5157","4.3618","26.6084","99.7816"
"13.2000","7.1638","6.5460","4.3820","26.7465","100.2995"
"13.2600","7.1944","6.5765","4.4025","26.8894","100.8352"
"13.3200","7.2252","6.6074","4.4231","27.0322","101.3708"
"13.3800","7.2554","6.6376","4.4434","27.1762","101.9107"
"13.4400","7.2845","6.6666","4.4628","27.3078","102.4041"
"13.5000","7.3142","6.6964","4.4827","27.4423","102.9087"
"13.5600","7.3434","6.7256","4.5023","27.5780","103.4175"
"13.6200","7.3749","6.7570","4.5233","27.7249","103.9684"
"13.6800","7.4056","6.7877","4.5439","27.8675","104.5032"
"13.7400","7.4337","6.8158","4.5627","27.9946","104.9796"
"13.8000","7.4642","6.8463","4.5831","28.1386","105.5198"
"13.8600","7.4946","6.8768","4.6035","28.2802","106.0509"
"13.9200","7.5254","6.9076","4.6241","28.4247","106.5925"
"13.9800","7.5548","6.9370","4.6438","28.5572","107.0893"
"14.0400","7.5843","6.9665","4.6635","28.6950","107.6062"
"14.1000","7.6146","6.9967","4.6838","28.8378","108.1418"
"14.1600","7.6427","7.0248","4.7026","28.9644","108.6164"
"14.2200","7.6743","7.0565","4.7238","29.1195","109.1980"
"14.2800","7.7057","7.0879","4.7448","29.2690","109.7589"
"14.3400","7.7343","7.1164","4.7639","29.3953","110.2325"
"14.4000","7.7639","7.1460","4.7837","29.5334","110.7503"
"14.4600","7.7941","7.1763","4.8040","29.6744","111.2788"
"14.5200","7.8254","7.2076","4.8249","29.8251","111.8441"
"14.5800","7.8551","7.2372","4.8448","29.9657","112.3715"
"14.6400","7.8853","7.2675","4.8650","30.1096","112.9109"
"14.7000","7.9149","7.2970","4.8848","30.2486","113.4322"
"14.7600","7.9432","7.3254","4.9038","30.3762","113.9107"
"14.8200","7.9741","7.3562","4.9244","30.5247","114.4675"
"14.8800","8.0058","7.3879","4.9457","30.6822","115.0582"
"14.9400","8.0345","7.4167","4.9649","30.8134","115.5504"
"15.0000","8.0634","7.4456","4.9842","30.9481","116.0555"
"15.0600","8.0948","7.4769","5.0052","31.1026","116.6348"
"15.1200","8.1248","7.5069","5.0253","31.2448","117.1680"
"15.1800","8.1545","7.5366","5.0452","31.3850","117.6938"
"15.2400","8.1850","7.5672","5.0656","31.5323","118.2462"
"15.3000","8.2146","7.5968","5.0855","31.6762","118.7857"
"15.3600","8.2438","7.6260","5.1050","31.8153","119.3074"
"15.4200","8.2730","7.6552","5.1245","31.9529","119.8234"
"15.4800","8.3052","7.6874","5.1461","32.1124","120.4216"
"15.5400","8.3347","7.7168","5.1658","32.2515","120.9433"
"15.6000","8.3635","7.7457","5.1851","32.3854","121.4452"
"15.6600","8.3946","7.7767","5.2059","32.5394","122.0226"
"15.7200","8.4243","7.8064","5.2258","32.6814","122.5553"
"15.7800","8.4552","7.8373","5.2465","32.8320","123.1201"
"15.8400","8.4853","7.8674","5.2667","32.9776","123.6661"
"15.9000","8.5146","7.8967","5.2863","33.1161","124.1855"
"15.9600","8.5442","7.9264","5.3061","33.2591","124.7217"
"16.0200","8.5734","7.9555","5.3256","33.3985","125.2445"
"16.0800","8.6049","7.9871","5.3467","33.5576","125.8410"
"16.1400","8.6346","8.0168","5.3666","33.7008","126.3779"
"16.2000","8.6643","8.0465","5.3865","33.8454","126.9202"
"16.2600","8.6944","8.0766","5.4066","33.9919","127.4698"
"16.3200","8.7241","8.1062","5.4265","34.1339","128.0023"
"16.3800","8.7545","8.1366","5.4469","34.2831","128.5616"
"16.4400","8.7852","8.1673","5.4674","34.4330","129.1237"
"16.5000","8.8150","8.1971","5.4874","34.5794","129.6729"
"16.5600","8.8442","8.2264","5.5069","34.7235","130.2131"
"16.6200","8.8738","8.2559","5.5267","34.8676","130.7535"
"16.6800","8.9035","8.2856","5.5466","35.0135","131.3006"
"16.7400","8.9347","8.3168","5.5675","35.1669","131.8759"
"16.8000","8.9649","8.3470","5.5877","35.3151","132.4316"
"16.8600","8.9943","8.3764","5.6074","35.4577","132.9665"
"16.9200","9.0243","8.4064","5.6275","35.6059","133.5220"
"16.9800","9.0540","8.4361","5.6473","35.7502","134.0631"
"17.0400","9.0856","8.4677","5.6685","35.9121","134.6705"
"17.1000","9.1153","8.4975","5.6884","36.0572","135.2144"
"17.1600","9.1439","8.5261","5.7076","36.1933","135.7249"
"17.2200","9.1747","8.5568","5.7281","36.3473","136.3023"
"17.2800","9.2036","8.5857","5.7475","36.4882","136.8306"
"17.3400","9.2344","8.6166","5.7682","36.6460","137.4226"
"17.4000","9.2647","8.6468","5.7884","36.7955","137.9833"
"17.4600","9.2947","8.6768","5.8085","36.9436","138.5385"
"17.5200","9.3243","8.7064","5.8283","37.0941","139.1027"
"17.5800","9.3535","8.7357","5.8479","37.2362","139.6358"
"17.6400","9.3852","8.7674","5.8691","37.3985","140.2443"
"17.7000","9.4154","8.7975","5.8893","37.5481","140.8053"
"17.7600","9.4438","8.8260","5.9083","37.6849","141.3183"
"17.8200","9.4737","8.8559","5.9283","37.8340","141.8774"
"17.8800","9.5041","8.8862","5.9487","37.9851","142.4441"
"17.9400","9.5343","8.9164","5.9689","38.1380","143.0177"
"18.0000","9.5646","8.9468","5.9892","38.2910","143.5912"
"18.0600","9.5945","8.9767","6.0092","38.4392","144.1472"
"18.1200","9.6237","9.0058","6.0287","38.5852","144.6945"
"18.1800","9.6537","9.0358","6.0488","38.7367","145.2626"
"18.2400","9.6847","9.0669","6.0696","38.8966","145.8624"
"18.3000","9.7157","9.0978","6.0903","39.0515","146.4431"
"18.3600","9.7449","9.1271","6.1099","39.1973","146.9897"
"18.4200","9.7742","9.1563","6.1295","39.3423","147.5337"
"18.4800","9.8046","9.1867","6.1498","39.4982","148.1181"
"18.5400","9.8340","9.2162","6.1695","39.6463","148.6735"
"18.6000","9.8649","9.2470","6.1902","39.8056","149.2709"
"18.6600","9.8952","9.2773","6.2105","39.9595","149.8483"
"18.7200","9.9242","9.3064","6.2299","40.1009","150.3783"
"18.7800","9.9542","9.3363","6.2500","40.2542","150.9533"
"18.8400","9.9842","9.3663","6.2700","40.4080","151.5298"
"18.9000","10.0157","9.3978","6.2911","40.5721","152.1453"
"18.9600","10.0450","9.4272","6.3108","40.7214","152.7052"
"19.0200","10.0747","9.4569","6.3306","40.8745","153.2794"
"19.0800","10.1042","9.4864","6.3504","41.0235","153.8381"
"19.1400","10.1332","9.5153","6.3698","41.1672","154.3772"
"19.2000","10.1644","9.5466","6.3907","41.3300","154.9873"
"19.2600","10.1949","9.5770","6.4111","41.4886","155.5823"
"19.3200","10.2247","9.6069","6.4311","41.6413","156.1549"
"19.3800","10.2537","9.6359","6.4505","41.7877","156.7037"
"19.4400","10.2843","9.6664","6.4709","41.9469","157.3008"
"19.5000","10.3147","9.6968","6.4913","42.1049","157.8932"
"19.5600","10.3448","9.7270","6.5115","42.2568","158.4629"
"19.6200","10.3753","9.7574","6.5319","42.4162","159.0607"
"19.6800","10.4043","9.7865","6.5513","42.5634","159.6127"
"19.7400","10.4339","9.8160","6.5711","42.7151","160.1817"
"19.8000","10.4634","9.8455","6.5908","42.8694","160.7603"
"19.8600","10.4953","9.8774","6.6122","43.0441","161.4154"
"19.9200","10.5253","9.9074","6.6323","43.1960","161.9848"
"19.9800","10.5535","9.9357","6.6512","43.3372","162.5144"
"20.0400","10.5844","9.9666","6.6719","43.5015","163.1305"
"20.1000","10.6146","9.9967","6.6920","43.6597","163.7238"
"20.1600","10.6455","10.0276","6.7127","43.8230","164.3364"
"20.2200","10.6749","10.0571","6.7325","43.9751","164.9065"
"20.2800","10.7046","10.0867","6.7523","44.1264","165.4739"
"20.3400","10.7344","10.1166","6.7723","44.2825","166.0596"
"20.4000","10.7632","10.1453","6.7915","44.4282","166.6058"
"20.4600","10.7948","10.1770","6.8127","44.6025","167.2593"
"20.5200","10.8248","10.2069","6.8328","44.7570","167.8387"
"20.5800","10.8539","10.2360","6.8522","44.9075","168.4030"
"20.6400","10.8840","10.2662","6.8724","45.0676","169.0036"
"20.7000","10.9139","10.2960","6.8924","45.2228","169.5856"
"20.7600","10.9452","10.3274","6.9134","45.3968","170.2381"
"20.8200","10.9752","10.3574","6.9335","45.5535","170.8255"
"20.8800","11.0054","10.3876","6.9537","45.7127","171.4226"
"20.9400","11.0337","10.4159","6.9726","45.8580","171.9676"
"21.0000","11.0635","10.4456","6.9926","46.0161","172.5605"
"21.0600","11.0938","10.4760","7.0129","46.1769","173.1634"
"21.1200","11.1249","10.5071","7.0337","46.3426","173.7847"
"21.1800","11.1546","10.5367","7.0535","46.4982","174.3684"
"21.2400","11.1840","10.5662","7.0733","46.6554","174.9578"
"21.3000","11.2147","10.5968","7.0938","46.8208","175.5780"
"21.3600","11.2441","10.6262","7.1135","46.9737","176.1512"
"21.4200","11.2751","10.6572","7.1342","47.1420","176.7824"
"21.4800","11.3051","10.6873","7.1543","47.2993","177.3722"
"21.5400","11.3339","10.7160","7.1736","47.4479","177.9295"
"21.6000","11.3638","10.7460","7.1936","47.6103","178.5386"
"21.6600","11.3936","10.7757","7.2135","47.7703","179.1385"
"21.7200","11.4246","10.8068","7.2343","47.9414","179.7803"
"21.7800","11.4548","10.8369","7.2545","48.1026","180.3848"
"21.8400","11.4842","10.8664","7.2742","48.2586","180.9699"
"21.9000","11.5142","10.8963","7.2943","48.4208","181.5781"
"21.9600","11.5435","10.9256","7.3139","48.5775","182.1655"
"22.0200","11.5756","10.9577","7.3354","48.7571","182.8391"
"22.0800","11.6056","10.9878","7.3555","48.9185","183.4442"
"22.1400","11.6347","11.0169","7.3750","49.0720","184.0200"
"22.2000","11.6643","11.0464","7.3947","49.2310","184.6162"
"22.2600","11.6940","11.0761","7.4146","49.3909","185.2158"
"22.3200","11.7244","11.1066","7.4350","49.5579","185.8423"
"22.3800","11.7547","11.1368","7.4552","49.7231","186.4614"
"22.4400","11.7850","11.1672","7.4756","49.8900","187.0875"
"22.5000","11.8138","11.1960","7.4949","50.0426","187.6596"
"22.5600","11.8438","11.2260","7.5149","50.2055","188.2704"
"22.6200","11.8745","11.2567","7.5355","50.3764","188.9114"
"22.6800","11.9058","11.2879","7.5564","50.5480","189.5552"
"22.7400","11.9350","11.3172","7.5760","50.7072","190.1518"
"22.8000","11.9642","11.3464","7.5955","50.8651","190.7442"
"22.8600","11.9943","11.3764","7.6157","51.0313","191.3673"
"22.9200","12.0235","11.4056","7.6352","51.1895","191.9605"
"22.9800","12.0543","11.4364","7.6558","51.3604","192.6015"
"23.0400","12.0846","11.4668","7.6761","51.5273","193.2273"
"23.1000","12.1135","11.4957","7.6955","51.6820","193.8076"
"23.1600","12.1436","11.5257","7.7156","51.8477","194.4290"
"23.2200","12.1737","11.5559","7.7358","52.0173","195.0647"
"23.2800","12.2052","11.5873","7.7568","52.1977","195.7412"
"23.3400","12.2350","11.6171","7.7768","52.3589","196.3459"
"23.4000","12.2641","11.6462","7.7963","52.5159","196.9346"
"23.4600","12.2944","11.6765","7.8166","52.6873","197.5773"
"23.5200","12.3236","11.7058","7.8361","52.8454","198.1701"
"23.5800","12.3541","11.7363","7.8566","53.0182","198.8181"
"23.6400","12.3852","11.7674","7.8774","53.1939","199.4770"
"23.7000","12.4151","11.7973","7.8974","53.3577","200.0913"
"23.7600","12.4442","11.8264","7.9169","53.5187","200.6950"
"23.8200","12.4735","11.8556","7.9364","53.6767","201.2876"
"23.8800","12.5052","11.8873","7.9577","53.8611","201.9790"
"23.9400","12.5353","11.9174","7.9778","54.0269","202.6010"
"24.0000","12.5646","11.9468","7.9975","54.1894","203.2101"
"24.0600","12.5944","11.9766","8.0174","54.3577","203.8412"
"24.1200","12.6240","12.0062","8.0372","54.5211","204.4542"
"24.1800","12.6532","12.0353","8.0567","54.6835","205.0630"
"24.2400","12.6847","12.0669","8.0779","54.8657","205.7463"
"24.3000","12.7154","12.0975","8.0984","55.0391","206.3965"
"24.3600","12.7439","12.1261","8.1175","55.1967","206.9877"
"24.4200","12.7737","12.1559","8.1374","55.3674","207.6277"
"24.4800","12.8043","12.1865","8.1579","55.5426","208.2849"
"24.5400","12.8353","12.2174","8.1786","55.7232","208.9621"
"24.6000","12.8651","12.2473","8.1986","55.8903","209.5887"
"24.6600","12.8946","12.2767","8.2183","56.0535","210.2007"
"24.7200","12.9247","12.3068","8.2385","56.2262","210.8481"
"24.7800","12.9531","12.3352","8.2575","56.3836","211.4386"
"24.8400","12.9845","12.3667","8.2785","56.5702","212.1383"
"24.9000","13.0152","12.3973","8.2991","56.7463","212.7985"
"24.9600","13.0439","12.4261","8.3183","56.9037","213.3888"
"25.0200","13.0740","12.4561","8.3384","57.0790","214.0464"
"25.0800","13.1040","12.4862","8.3585","57.2476","214.6783"
"25.1400","13.1354","12.5175","8.3795","57.4295","215.3606"
"25.2000","13.1652","12.5474","8.3995","57.6038","216.0143"
"25.2600","13.1948","12.5770","8.4193","57.7745","216.6543"
"25.3200","13.2239","12.6060","8.4388","57.9367","217.2627"
"25.3800","13.2536","12.6358","8.4587","58.1065","217.8992"
"25.4400","13.2841","12.6662","8.4791","58.2832","218.5619"
"25.5000","13.3146","12.6967","8.4995","58.4573","219.2148"
"25.5600","13.3448","12.7269","8.5197","58.6332","219.8745"
"25.6200","13.3739","12.7560","8.5392","58.7997","220.4989"
"25.6800","13.4043","12.7864","8.5595","58.9787","221.1699"
"25.7400","13.4343","12.8164","8.5796","59.1542","221.8281"
"25.8000","13.4653","12.8474","8.6004","59.3359","222.5095"
"25.8600","13.4957","12.8778","8.6207","59.5126","223.1722"
"25.9200","13.5243","12.9065","8.6399","59.6758","223.7843"
"25.9800","13.5539","12.9360","8.6597","59.8475","224.4283"
"26.0400","13.5838","12.9659","8.6797","60.0253","225.0948"
"26.1000","13.6151","12.9972","8.7007","60.2128","225.7979"
"26.1600","13.6447","13.0268","8.7205","60.3828","226.4355"
"26.2200","13.6740","13.0561","8.7401","60.5523","227.0712"
"26.2800","13.7045","13.0866","8.7605","60.7325","227.7467"
"26.3400","13.7337","13.1158","8.7800","60.9024","228.3839"
"26.4000","13.7655","13.1477","8.8014","61.1023","229.1337"
"26.4600","13.7952","13.1773","8.8212","61.2726","229.7722"
"26.5200","13.8248","13.2070","8.8411","61.4460","230.4225"
"26.5800","13.8542","13.2363","8.8607","61.6177","231.0665"
"26.6400","13.8834","13.2655","8.8803","61.7860","231.6976"
"26.7000","13.9145","13.2966","8.9011","61.9766","232.4124"
"26.7600","13.9445","13.3267","8.9212","62.1537","233.0764"
"26.8200","13.9745","13.3566","8.9412","62.3317","233.7440"
"26.8800","14.0044","13.3865","8.9613","62.5093","234.4098"
"26.9400","14.0337","13.4159","8.9809","62.6798","235.0493"
"27.0000","14.0644","13.4466","9.0015","62.8661","235.7478"
"27.0600","14.0953","13.4775","9.0222","63.0500","236.4377"
"27.1200","14.1253","13.5074","9.0422","63.2282","237.1056"
"27.1800","14.1544","13.5366","9.0617","63.4066","237.7749"
"27.2400","14.1843","13.5664","9.0817","63.5844","238.4415"
"27.3000","14.2137","13.5959","9.1014","63.7591","239.0966"
"27.3600","14.2447","13.6268","9.1221","63.9465","239.7995"
"27.4200","14.2748","13.6569","9.1423","64.1261","240.4731"
"27.4800","14.3039","13.6861","9.1618","64.2963","241.1109"
"27.5400","14.3341","13.7162","9.1820","64.4787","241.7952"
"27.6000","14.3639","13.7461","9.2020","64.6575","242.4655"
"27.6600","14.3958","13.7779","9.2233","64.8552","243.2071"
"27.7200","14.4252","13.8073","9.2429","65.0257","243.8465"
"27.7800","14.4540","13.8361","9.2622","65.1928","244.4729"
"27.8400","14.4841","13.8663","9.2824","65.3772","245.1644"
"27.9000","14.5136","13.8958","9.3022","65.5510","245.8163"
"27.9600","14.5440","13.9261","9.3225","65.7346","246.5047"
"28.0200","14.5750","13.9572","9.3433","65.9278","247.2293"
"28.0800","14.6049","13.9870","9.3633","66.1074","247.9027"
"28.1400","14.6338","14.0159","9.3826","66.2777","248.5413"
"28.2000","14.6636","14.0457","9.4026","66.4557","249.2088"
"28.2600","14.6952","14.0774","9.4237","66.6536","249.9509"
"28.3200","14.7251","14.1072","9.4437","66.8315","250.6183"
"28.3800","14.7549","14.1370","9.4637","67.0113","251.2925"
"28.4400","14.7844","14.1665","9.4834","67.1876","251.9536"
"28.5000","14.8137","14.1959","9.5031","67.3624","252.6088"
"28.5600","14.8439","14.2261","9.5233","67.5484","253.3065"
"28.6200","14.8747","14.2569","9.5439","67.7352","254.0071"
"28.6800","14.9051","14.2872","9.5642","67.9237","254.7140"
"28.7400","14.9335","14.3156","9.5832","68.0900","255.3374"
"28.8000","14.9642","14.3464","9.6038","68.2878","256.0793"
"28.8600","14.9949","14.3771","9.6244","68.4777","256.7914"
"28.9200","15.0254","14.4076","9.6448","68.6646","257.4923"
"28.9800","15.0549","14.4370","9.6645","68.8423","258.1585"
"29.0400","15.0845","14.4666","9.6843","69.0227","258.8353"
"29.1000","15.1146","14.4967","9.7045","69.2078","259.5291"
"29.1600","15.1432","14.5253","9.7236","69.3806","260.1772"
"29.2200","15.1746","14.5567","9.7446","69.5827","260.9353"
"29.2800","15.2054","14.5875","9.7652","69.7730","261.6488"
"29.3400","15.2338","14.6160","9.7843","69.9388","262.2706"
"29.4000","15.2636","14.6458","9.8043","70.1240","262.9649"
"29.4600","15.2940","14.6761","9.8246","70.3129","263.6734"
"29.5200","15.3254","14.7076","9.8456","70.5141","264.4280"
"29.5800","15.3549","14.7370","9.8653","70.6907","265.0901"
"29.6400","15.3848","14.7670","9.8854","70.8800","265.7998"
"29.7000","15.4147","14.7969","9.9054","71.0651","266.4942"
"29.7600","15.4429","14.8251","9.9243","71.2293","267.1099"
"29.8200","15.4735","14.8557","9.9447","71.4258","267.8468"
"29.8800","15.5053","14.8875","9.9660","71.6296","268.6110"
"29.9400","15.5347","14.9168","9.9857","71.8077","269.2788"
"30.0000","15.5635","14.9457","10.0050","71.9831","269.9366"
"30.0600","15.5943","14.9765","10.0256","72.1785","270.6693"
"30.1200","15.6251","15.0072","10.0462","72.3740","271.4025"
"30.1800","15.6549","15.0371","10.0662","72.5568","272.0880"
"30.2400","15.6851","15.0672","10.0864","72.7434","272.7878"
"30.3000","15.7145","15.0966","10.1060","72.9264","273.4739"
"30.3600","15.7444","15.1265","10.1261","73.1146","274.1797"
"30.4200","15.7736","15.1558","10.1456","73.2941","274.8528"
"30.4800","15.8048","15.1870","10.1665","73.4941","275.6027"
"30.5400","15.8343","15.2164","10.1862","73.6732","276.2745"
"30.6000","15.8633","15.2455","10.2057","73.8501","276.9379"
"30.6600","15.8943","15.2765","10.2264","74.0556","277.7084"
"30.7200","15.9242","15.3064","10.2465","74.2400","278.3999"
"30.7800","15.9554","15.3375","10.2673","74.4392","279.1470"
"30.8400","15.9851","15.3673","10.2872","74.6238","279.8393"
"30.9000","16.0147","15.3969","10.3070","74.8048","280.5179"
"30.9600","16.0442","15.4264","10.3268","74.9873","281.2024"
"31.0200","16.0734","15.4555","10.3463","75.1679","281.8797"
"31.0800","16.1045","15.4866","10.3671","75.3699","282.6371"
"31.1400","16.1348","15.5169","10.3874","75.5608","283.3531"
"31.2000","16.1641","15.5463","10.4070","75.7430","284.0364"
"31.2600","16.1942","15.5764","10.4272","75.9331","284.7492"
"31.3200","16.2241","15.6063","10.4472","76.1190","285.4464"
"31.3800","16.2549","15.6370","10.4678","76.3165","286.1870"
"31.4400","16.2853","15.6674","10.4882","76.5091","286.9089"
"31.5000","16.3152","15.6973","10.5082","76.7021","287.6327"
"31.5600","16.3441","15.7263","10.5276","76.8783","288.2935"
"31.6200","16.3736","15.7558","10.5473","77.0609","288.9784"
"31.6800","16.4042","15.7863","10.5678","77.2569","289.7133"
"31.7400","16.4348","15.8170","10.5883","77.4483","290.4311"
"31.8000","16.4647","15.8468","10.6082","77.6357","291.1337"
"31.8600","16.4941","15.8763","10.6280","77.8192","291.8219"
"31.9200","16.5242","15.9064","10.6481","78.0102","292.5382"
"31.9800","16.5539","15.9361","10.6680","78.1964","293.2367"
"32.0400","16.5855","15.9677","10.6891","78.4002","294.0007"
"32.1000","16.6147","15.9968","10.7087","78.5757","294.6589"
"32.1600","16.6440","16.0261","10.7283","78.7560","295.3348"
"32.2200","16.6746","16.0567","10.7487","78.9496","296.0608"
"32.2800","16.7035","16.0857","10.7681","79.1277","296.7288"
"32.3400","16.7344","16.1165","10.7888","79.3266","297.4748"
"32.4000","16.7650","16.1471","10.8093","79.5198","298.1994"
"32.4600","16.7948","16.1769","10.8292","79.7045","298.8918"
"32.5200","16.8238","16.2059","10.8486","79.8804","299.5516"
"32.5800","16.8534","16.2355","10.8685","80.0606","300.2274"
"32.6400","16.8853","16.2674","10.8898","80.2693","301.0098"
"32.7000","16.9155","16.2976","10.9100","80.4566","301.7121"
"32.7600","16.9445","16.3266","10.9294","80.6310","302.3664"
"32.8200","16.9742","16.3563","10.9493","80.8184","303.0688"
"32.8800","17.0041","16.3862","10.9693","81.0021","303.7580"
"32.9400","17.0343","16.4165","10.9896","81.1906","304.4649"
"33.0000","17.0647","16.4468","11.0099","81.3770","305.1636"
"33.0600","17.0945","16.4767","11.0299","81.5585","305.8442"
"33.1200","17.1239","16.5061","11.0496","81.7375","306.5155"
"33.1800","17.1539","16.5361","11.0697","81.9244","307.2165"
"33.2400","17.1843","16.5664","11.0900","82.1089","307.9085"
"33.3000","17.2153","16.5975","11.1107","82.3016","308.6311"
"33.3600","17.2450","16.6272","11.1306","82.4778","309.2917"
"33.4200","17.2736","16.6558","11.1498","82.6468","309.9254"
"33.4800","17.3046","16.6867","11.1705","82.8410","310.6538"
"33.5400","17.3332","16.7153","11.1896","83.0048","311.2680"
"33.6000","17.3642","16.7464","11.2104","83.2023","312.0086"
"33.6600","17.3952","16.7774","11.2312","83.3907","312.7152"
"33.7200","17.4241","16.8062","11.2505","83.5549","313.3310"
"33.7800","17.4540","16.8361","11.2705","83.7365","314.0118"
"33.8400","17.4837","16.8659","11.2904","83.9124","314.6716"
"33.9000","17.5157","16.8978","11.3118","84.1120","315.4200"
"33.9600","17.5452","16.9274","11.3316","84.2816","316.0559"
"34.0200","17.5743","16.9565","11.3511","84.4468","316.6754"
"34.0800","17.6043","16.9865","11.3712","84.6236","317.3384"
"34.1400","17.6335","17.0157","11.3907","84.7844","317.9416"
"34.2000","17.6644","17.0466","11.4114","84.9734","318.6502"
"34.2600","17.6953","17.0775","11.4321","85.1556","319.3334"
"34.3200","17.7248","17.1070","11.4518","85.3180","319.9426"
"34.3800","17.7536","17.1358","11.4711","85.4739","320.5269"
"34.4400","17.7836","17.1657","11.4911","85.6406","321.1522"
"34.5000","17.8140","17.1962","11.5116","85.8142","321.8031"
"34.5600","17.8454","17.2276","11.5325","85.9939","322.4771"
"34.6200","17.8756","17.2577","11.5527","86.1607","323.1027"
"34.6800","17.9047","17.2868","11.5722","86.3174","323.6901"
"34.7400","17.9337","17.3158","11.5916","86.4701","324.2628"
"34.8000","17.9634","17.3456","11.6115","86.6333","324.8751"
"34.8600","17.9955","17.3776","11.6330","86.8188","325.5706"
"34.9200","18.0250","17.4071","11.6527","86.9715","326.1430"
"34.9800","18.0532","17.4353","11.6716","87.1105","326.6646"
"35.0400","18.0845","17.4667","11.6926","87.2862","327.3234"
"35.1000","18.1147","17.4968","11.7128","87.4462","327.9232"
"35.1600","18.1451","17.5273","11.7332","87.6054","328.5203"
"35.2200","18.1753","17.5574","11.7534","87.7613","329.1050"
"35.2800","18.2048","17.5870","11.7731","87.9097","329.6615"
"35.3400","18.2345","17.6167","11.7930","88.0572","330.2144"
"35.4000","18.2631","17.6453","11.8122","88.1943","330.7287"
"35.4600","18.2950","17.6771","11.8335","88.3684","331.3815"
"35.5200","18.3253","17.7074","11.8538","88.5169","331.9383"
"35.5800","18.3538","17.7360","11.8729","88.6439","332.4145"
"35.6400","18.3843","17.7664","11.8933","88.7970","332.9889"
"35.7000","18.4142","17.7964","11.9133","88.9345","333.5042"
"35.7600","18.4447","17.8268","11.9337","89.0811","334.0541"
"35.8200","18.4748","17.8570","11.9539","89.2212","334.5796"
"35.8800","18.5054","17.8876","11.9744","89.3643","335.1162"
"35.9400","18.5341","17.9163","11.9936","89.4863","335.5735"
"36.0000","18.5633","17.9455","12.0131","89.6133","336.0500"
"36.0600","18.5942","17.9763","12.0338","89.7598","336.5991"
"36.1200","18.6249","18.0071","12.0544","89.8920","337.0950"
"36.1800","18.6544","18.0366","12.0741","90.0122","337.5457"
"36.2400","18.6841","18.0663","12.0940","90.1337","338.0012"
"36.3000","18.7143","18.0965","12.1142","90.2602","338.4757"
"36.3600","18.7446","18.1267","12.1345","90.3817","338.9314"
"36.4200","18.7751","18.1573","12.1549","90.5015","339.3806"
"36.4800","18.8053","18.1874","12.1751","90.6155","339.8082"
"36.5400","18.8343","18.2165","12.1945","90.7125","340.1718"
"36.6000","18.8642","18.2464","12.2145","90.8273","340.6025"
"36.6600","18.8942","18.2764","12.2346","90.9368","341.0130"
"36.7200","18.9250","18.3071","12.2552","91.0463","341.4237"
"36.7800","18.9551","18.3372","12.2754","91.1491","341.8091"
"36.8400","18.9845","18.3666","12.2951","91.2344","342.1290"
"36.9000","19.0139","18.3961","12.3148","91.3228","342.4604"
"36.9600","19.0432","18.4254","12.3344","91.4065","342.7743"
"37.0200","19.0754","18.4575","12.3559","91.5186","343.1948"
"37.0800","19.1055","18.4876","12.3761","91.6031","343.5117"
"37.1400","19.1348","18.5170","12.3957","91.6749","343.7809"
"37.2000","19.1642","18.5463","12.4154","91.7481","344.0555"
"37.2600","19.1935","18.5757","12.4350","91.8142","344.3034"
"37.3200","19.2240","18.6061","12.4554","91.8890","344.5838"
"37.3800","19.2544","18.6366","12.4758","91.9586","344.8448"
"37.4400","19.2850","18.6672","12.4962","92.0260","345.0974"
"37.5000","19.3142","18.6964","12.5158","92.0745","345.2794"
"37.5600","19.3441","18.7262","12.5358","92.1312","345.4921"
"37.6200","19.3746","18.7568","12.5563","92.1859","345.6971"
"37.6800","19.4056","18.7878","12.5770","92.2350","345.8813"
"37.7400","19.4349","18.8171","12.5966","92.2627","345.9850"
"37.8000","19.4642","18.8464","12.6162","92.2873","346.0775"
"37.8600","19.4944","18.8765","12.6364","92.3168","346.1880"
"37.9200","19.5238","18.9060","12.6561","92.3336","346.2510"
"37.9800","19.5547","18.9369","12.6768","92.3567","346.3377"
"38.0400","19.5850","18.9671","12.6970","92.3676","346.3784"
"38.1000","19.6139","18.9961","12.7164","92.3590","346.3462"
"38.1600","19.6437","19.0259","12.7364","92.3528","346.3232"
"38.2200","19.6740","19.0562","12.7567","92.3491","346.3090"
"38.2800","19.7055","19.0876","12.7777","92.3480","346.3048"
"38.3400","19.7352","19.1174","12.7976","92.3165","346.1870"
"38.4000","19.7646","19.1468","12.8173","92.2743","346.0287"
"38.4600","19.7946","19.1768","12.8374","92.2351","345.8815"
"38.5200","19.8234","19.2056","12.8567","92.1719","345.6447"
"38.5800","19.8543","19.2364","12.8773","92.1266","345.4749"
"38.6400","19.8853","19.2675","12.8981","92.0734","345.2754"
"38.7000","19.9150","19.2971","12.9180","91.9879","344.9546"
"38.7600","19.9440","19.3261","12.9374","91.8912","344.5919"
"38.8200","19.9739","19.3560","12.9574","91.7857","344.1964"
"38.8800","20.0051","19.3872","12.9783","91.6871","343.8268"
"38.9400","20.0354","19.4175","12.9986","91.5609","343.3533"
"39.0000","20.0647","19.4469","13.0182","91.4185","342.8193"
"39.0600","20.0945","19.4766","13.0381","91.2631","342.2366"
"39.1200","20.1239","19.5061","13.0578","91.0853","341.5700"
"39.1800","20.1530","19.5352","13.0773","90.8894","340.8352"
"39.2400","20.1846","19.5668","13.0985","90.7014","340.1302"
"39.3000","20.2150","19.5972","13.1188","90.4844","339.3164"
"39.3600","20.2435","19.6257","13.1379","90.2354","338.3829"
"39.4200","20.2737","19.6559","13.1581","89.9893","337.4600"
"39.4800","20.3045","19.6867","13.1787","89.7337","336.5016"
"39.5400","20.3359","19.7181","13.1997","89.4616","335.4811"
"39.6000","20.3651","19.7472","13.2193","89.1457","334.2965"
"39.6600","20.3948","19.7770","13.2392","88.8130","333.0486"
"39.7200","20.4246","19.8067","13.2591","88.4589","331.7207"
"39.7800","20.4531","19.8353","13.2782","88.0599","330.2248"
"39.8400","20.4843","19.8665","13.2991","87.6337","328.6263"
"39.9000","20.5150","19.8972","13.3196","87.1499","326.8121"
"39.9600","20.5441","19.9262","13.3391","86.5981","324.7427"
"40.0200","20.5741","19.9563","13.3592","85.9876","322.4534"
"40.0800","20.6043","19.9864","13.3794","85.2690","319.7589"
"40.1400","20.6354","20.0175","13.4002","84.4650","316.7438"
"40.2000","20.6655","20.0477","13.4204","83.5091","313.1589"
"40.2600","20.6949","20.0771","13.4401","82.3519","308.8195"
"40.2730","20.7011","20.0833","13.4442","82.0605","307.7268"