File: data/instron_tests/250106_metamaterial_foam_test_data/clean_250106_metamaterial_foams_2_1.csv
Time,Displacement,Compressive displacement,Compressive strain (Displacement),Compressive stress,Force
(s),(mm),(mm),(%),(kPa),(N)
"0.0000","0.1096","-0.0095","-0.0063","-0.0025","-0.0095"
"0.0600","0.1112","-0.0079","-0.0052","0.0005","0.0020"
"0.1200","0.1253","0.0062","0.0042","0.0315","0.1182"
"0.1800","0.1566","0.0375","0.0250","0.1046","0.3921"
"0.2400","0.1869","0.0678","0.0452","0.1679","0.6295"
"0.3000","0.2164","0.0973","0.0649","0.2305","0.8644"
"0.3600","0.2446","0.1255","0.0837","0.2865","1.0745"
"0.4200","0.2750","0.1559","0.1040","0.3478","1.3042"
"0.4800","0.3051","0.1860","0.1241","0.4067","1.5250"
"0.5400","0.3357","0.2167","0.1446","0.4670","1.7511"
"0.6000","0.3661","0.2470","0.1648","0.5244","1.9664"
"0.6600","0.3951","0.2760","0.1842","0.5802","2.1758"
"0.7200","0.4250","0.3059","0.2041","0.6335","2.3756"
"0.7800","0.4534","0.3343","0.2230","0.6879","2.5795"
"0.8400","0.4857","0.3666","0.2446","0.7503","2.8137"
"0.9000","0.5158","0.3967","0.2647","0.8031","3.0117"
"0.9600","0.5443","0.4252","0.2837","0.8560","3.2099"
"1.0200","0.5746","0.4555","0.3039","0.9112","3.4171"
"1.0800","0.6049","0.4858","0.3241","0.9673","3.6274"
"1.1400","0.6358","0.5167","0.3447","1.0247","3.8427"
"1.2000","0.6656","0.5465","0.3646","1.0801","4.0502"
"1.2600","0.6958","0.5767","0.3848","1.1410","4.2788"
"1.3200","0.7248","0.6057","0.4041","1.1924","4.4716"
"1.3800","0.7542","0.6351","0.4237","1.2471","4.6767"
"1.4400","0.7850","0.6660","0.4443","1.3065","4.8995"
"1.5000","0.8152","0.6961","0.4644","1.3623","5.1085"
"1.5600","0.8451","0.7261","0.4844","1.4207","5.3276"
"1.6200","0.8741","0.7550","0.5037","1.4752","5.5322"
"1.6800","0.9049","0.7858","0.5243","1.5366","5.7624"
"1.7400","0.9349","0.8158","0.5443","1.5905","5.9642"
"1.8000","0.9656","0.8466","0.5648","1.6490","6.1839"
"1.8600","0.9958","0.8768","0.5850","1.7069","6.4007"
"1.9200","1.0246","0.9055","0.6041","1.7604","6.6016"
"1.9800","1.0547","0.9356","0.6242","1.8208","6.8282"
"2.0400","1.0840","0.9649","0.6438","1.8766","7.0372"
"2.1000","1.1155","0.9964","0.6648","1.9402","7.2757"
"2.1600","1.1450","1.0259","0.6845","1.9942","7.4782"
"2.2200","1.1747","1.0556","0.7043","2.0500","7.6875"
"2.2800","1.2053","1.0862","0.7247","2.1077","7.9040"
"2.3400","1.2341","1.1150","0.7439","2.1626","8.1098"
"2.4000","1.2657","1.1466","0.7650","2.2256","8.3461"
"2.4600","1.2954","1.1763","0.7849","2.2825","8.5595"
"2.5200","1.3253","1.2062","0.8048","2.3389","8.7710"
"2.5800","1.3546","1.2355","0.8243","2.3926","8.9724"
"2.6400","1.3841","1.2650","0.8440","2.4503","9.1885"
"2.7000","1.4149","1.2958","0.8646","2.5117","9.4188"
"2.7600","1.4454","1.3263","0.8849","2.5687","9.6326"
"2.8200","1.4754","1.3563","0.9049","2.6284","9.8565"
"2.8800","1.5046","1.3855","0.9244","2.6845","10.0670"
"2.9400","1.5345","1.4154","0.9443","2.7421","10.2829"
"3.0000","1.5655","1.4464","0.9651","2.8041","10.5153"
"3.0600","1.5963","1.4772","0.9856","2.8621","10.7328"
"3.1200","1.6260","1.5069","1.0054","2.9214","10.9552"
"3.1800","1.6544","1.5353","1.0243","2.9735","11.1504"
"3.2400","1.6848","1.5657","1.0446","3.0371","11.3893"
"3.3000","1.7145","1.5954","1.0645","3.0952","11.6071"
"3.3600","1.7455","1.6264","1.0851","3.1524","11.8214"
"3.4200","1.7754","1.6563","1.1051","3.2113","12.0424"
"3.4800","1.8049","1.6858","1.1248","3.2684","12.2566"
"3.5400","1.8347","1.7156","1.1447","3.3264","12.4742"
"3.6000","1.8645","1.7454","1.1645","3.3857","12.6964"
"3.6600","1.8965","1.7774","1.1859","3.4516","12.9435"
"3.7200","1.9261","1.8070","1.2057","3.5098","13.1618"
"3.7800","1.9547","1.8356","1.2247","3.5626","13.3597"
"3.8400","1.9849","1.8658","1.2448","3.6234","13.5876"
"3.9000","2.0145","1.8954","1.2646","3.6836","13.8134"
"3.9600","2.0453","1.9262","1.2851","3.7459","14.0470"
"4.0200","2.0754","1.9563","1.3052","3.8062","14.2734"
"4.0800","2.1051","1.9860","1.3251","3.8653","14.4949"
"4.1400","2.1345","2.0154","1.3447","3.9254","14.7203"
"4.2000","2.1644","2.0453","1.3646","3.9845","14.9419"
"4.2600","2.1958","2.0767","1.3856","4.0461","15.1727"
"4.3200","2.2260","2.1069","1.4057","4.1081","15.4055"
"4.3800","2.2556","2.1365","1.4255","4.1678","15.6292"
"4.4400","2.2849","2.1658","1.4450","4.2259","15.8470"
"4.5000","2.3147","2.1956","1.4649","4.2873","16.0774"
"4.5600","2.3443","2.2252","1.4846","4.3456","16.2960"
"4.6200","2.3753","2.2562","1.5053","4.4085","16.5318"
"4.6800","2.4059","2.2868","1.5258","4.4727","16.7725"
"4.7400","2.4343","2.3153","1.5447","4.5280","16.9800"
"4.8000","2.4648","2.3457","1.5651","4.5920","17.2201"
"4.8600","2.4951","2.3760","1.5852","4.6529","17.4484"
"4.9200","2.5258","2.4067","1.6058","4.7149","17.6810"
"4.9800","2.5554","2.4364","1.6255","4.7724","17.8964"
"5.0400","2.5852","2.4661","1.6454","4.8339","18.1273"
"5.1000","2.6157","2.4966","1.6657","4.8953","18.3573"
"5.1600","2.6440","2.5250","1.6846","4.9512","18.5671"
"5.2200","2.6754","2.5563","1.7056","5.0163","18.8110"
"5.2800","2.7059","2.5868","1.7259","5.0786","19.0446"
"5.3400","2.7346","2.6155","1.7451","5.1331","19.2491"
"5.4000","2.7645","2.6454","1.7650","5.1937","19.4764"
"5.4600","2.7946","2.6755","1.7851","5.2549","19.7058"
"5.5200","2.8265","2.7074","1.8064","5.3226","19.9599"
"5.5800","2.8555","2.7365","1.8258","5.3811","20.1791"
"5.6400","2.8856","2.7665","1.8458","5.4407","20.4027"
"5.7000","2.9155","2.7964","1.8657","5.5017","20.6313"
"5.7600","2.9437","2.8246","1.8845","5.5551","20.8315"
"5.8200","2.9746","2.8556","1.9052","5.6187","21.0699"
"5.8800","3.0059","2.8868","1.9261","5.6827","21.3101"
"5.9400","3.0351","2.9160","1.9456","5.7425","21.5343"
"6.0000","3.0645","2.9454","1.9652","5.8011","21.7541"
"6.0600","3.0948","2.9757","1.9854","5.8642","21.9909"
"6.1200","3.1254","3.0063","2.0058","5.9261","22.2229"
"6.1800","3.1558","3.0367","2.0261","5.9875","22.4531"
"6.2400","3.1859","3.0668","2.0462","6.0487","22.6827"
"6.3000","3.2150","3.0959","2.0656","6.1067","22.9001"
"6.3600","3.2454","3.1263","2.0859","6.1723","23.1460"
"6.4200","3.2745","3.1554","2.1053","6.2305","23.3644"
"6.4800","3.3051","3.1860","2.1257","6.2912","23.5921"
"6.5400","3.3355","3.2164","2.1460","6.3536","23.8260"
"6.6000","3.3646","3.2455","2.1654","6.4129","24.0485"
"6.6600","3.3954","3.2763","2.1859","6.4773","24.2899"
"6.7200","3.4247","3.3056","2.2055","6.5367","24.5126"
"6.7800","3.4562","3.3371","2.2265","6.6011","24.7541"
"6.8400","3.4861","3.3670","2.2464","6.6635","24.9881"
"6.9000","3.5153","3.3962","2.2660","6.7210","25.2037"
"6.9600","3.5447","3.4256","2.2856","6.7812","25.4295"
"7.0200","3.5742","3.4551","2.3053","6.8440","25.6651"
"7.0800","3.6055","3.4864","2.3261","6.9089","25.9084"
"7.1400","3.6351","3.5161","2.3459","6.9703","26.1387"
"7.2000","3.6649","3.5458","2.3658","7.0329","26.3735"
"7.2600","3.6952","3.5761","2.3859","7.0946","26.6048"
"7.3200","3.7246","3.6055","2.4056","7.1538","26.8268"
"7.3800","3.7556","3.6365","2.4263","7.2199","27.0747"
"7.4400","3.7860","3.6669","2.4465","7.2817","27.3065"
"7.5000","3.8155","3.6964","2.4663","7.3440","27.5399"
"7.5600","3.8448","3.7257","2.4858","7.4030","27.7611"
"7.6200","3.8744","3.7553","2.5055","7.4663","27.9984"
"7.6800","3.9049","3.7858","2.5259","7.5299","28.2371"
"7.7400","3.9352","3.8162","2.5461","7.5910","28.4662"
"7.8000","3.9652","3.8461","2.5661","7.6536","28.7010"
"7.8600","3.9941","3.8751","2.5854","7.7143","28.9288"
"7.9200","4.0249","3.9058","2.6060","7.7795","29.1731"
"7.9800","4.0548","3.9357","2.6259","7.8413","29.4049"
"8.0400","4.0864","3.9673","2.6469","7.9085","29.6567"
"8.1000","4.1156","3.9965","2.6665","7.9700","29.8876"
"8.1600","4.1447","4.0256","2.6859","8.0292","30.1095"
"8.2200","4.1747","4.0556","2.7059","8.0914","30.3429"
"8.2800","4.2041","4.0850","2.7255","8.1527","30.5727"
"8.3400","4.2354","4.1163","2.7464","8.2203","30.8260"
"8.4000","4.2653","4.1463","2.7664","8.2833","31.0624"
"8.4600","4.2949","4.1758","2.7861","8.3439","31.2898"
"8.5200","4.3246","4.2056","2.8059","8.4058","31.5217"
"8.5800","4.3544","4.2353","2.8258","8.4680","31.7549"
"8.6400","4.3859","4.2669","2.8468","8.5343","32.0037"
"8.7000","4.4161","4.2970","2.8669","8.5976","32.2411"
"8.7600","4.4455","4.3264","2.8866","8.6604","32.4764"
"8.8200","4.4750","4.3559","2.9062","8.7209","32.7032"
"8.8800","4.5051","4.3860","2.9263","8.7833","32.9375"
"8.9400","4.5347","4.4156","2.9461","8.8422","33.1584"
"9.0000","4.5651","4.4460","2.9664","8.9080","33.4051"
"9.0600","4.5957","4.4766","2.9868","8.9735","33.6505"
"9.1200","4.6247","4.5056","3.0061","9.0325","33.8720"
"9.1800","4.6542","4.5351","3.0258","9.0963","34.1110"
"9.2400","4.6849","4.5658","3.0463","9.1595","34.3479"
"9.3000","4.7164","4.5973","3.0673","9.2254","34.5953"
"9.3600","4.7455","4.6264","3.0867","9.2863","34.8236"
"9.4200","4.7746","4.6556","3.1062","9.3458","35.0466"
"9.4800","4.8050","4.6859","3.1264","9.4106","35.2897"
"9.5400","4.8343","4.7152","3.1460","9.4728","35.5232"
"9.6000","4.8653","4.7462","3.1666","9.5368","35.7629"
"9.6600","4.8956","4.7766","3.1869","9.6020","36.0074"
"9.7200","4.9248","4.8057","3.2064","9.6607","36.2276"
"9.7800","4.9548","4.8357","3.2263","9.7244","36.4666"
"9.8400","4.9847","4.8657","3.2463","9.7878","36.7041"
"9.9000","5.0162","4.8971","3.2673","9.8557","36.9591"
"9.9600","5.0457","4.9266","3.2870","9.9179","37.1920"
"10.0200","5.0752","4.9561","3.3067","9.9798","37.4242"
"10.0800","5.1054","4.9863","3.3268","10.0443","37.6659"
"10.1400","5.1342","5.0151","3.3461","10.1054","37.8951"
"10.2000","5.1651","5.0460","3.3667","10.1698","38.1367"
"10.2600","5.1962","5.0771","3.3874","10.2404","38.4015"
"10.3200","5.2256","5.1066","3.4071","10.3022","38.6333"
"10.3800","5.2538","5.1347","3.4259","10.3608","38.8531"
"10.4400","5.2847","5.1656","3.4465","10.4263","39.0985"
"10.5000","5.3154","5.1964","3.4670","10.4915","39.3430"
"10.5600","5.3455","5.2265","3.4871","10.5570","39.5888"
"10.6200","5.3759","5.2568","3.5073","10.6222","39.8333"
"10.6800","5.4052","5.2861","3.5269","10.6841","40.0652"
"10.7400","5.4342","5.3151","3.5462","10.7477","40.3039"
"10.8000","5.4639","5.3448","3.5661","10.8097","40.5365"
"10.8600","5.4960","5.3769","3.5874","10.8807","40.8027"
"10.9200","5.5258","5.4067","3.6074","10.9429","41.0360"
"10.9800","5.5539","5.4348","3.6261","11.0017","41.2564"
"11.0400","5.5849","5.4658","3.6467","11.0706","41.5147"
"11.1000","5.6152","5.4961","3.6670","11.1354","41.7577"
"11.1600","5.6458","5.5267","3.6874","11.2032","42.0120"
"11.2200","5.6758","5.5567","3.7074","11.2678","42.2543"
"11.2800","5.7053","5.5862","3.7271","11.3297","42.4863"
"11.3400","5.7350","5.6159","3.7469","11.3929","42.7234"
"11.4000","5.7637","5.6446","3.7660","11.4531","42.9491"
"11.4600","5.7958","5.6767","3.7875","11.5274","43.2278"
"11.5200","5.8250","5.7059","3.8070","11.5874","43.4527"
"11.5800","5.8543","5.7352","3.8265","11.6496","43.6861"
"11.6400","5.8849","5.7658","3.8469","11.7188","43.9455"
"11.7000","5.9148","5.7958","3.8669","11.7805","44.1770"
"11.7600","5.9458","5.8267","3.8875","11.8499","44.4372"
"11.8200","5.9759","5.8568","3.9076","11.9159","44.6845"
"11.8800","6.0055","5.8864","3.9274","11.9787","44.9202"
"11.9400","6.0348","5.9157","3.9469","12.0439","45.1646"
"12.0000","6.0643","5.9452","3.9666","12.1079","45.4046"
"12.0600","6.0949","5.9758","3.9870","12.1764","45.6614"
"12.1200","6.1256","6.0065","4.0075","12.2425","45.9094"
"12.1800","6.1553","6.0362","4.0273","12.3068","46.1505"
"12.2400","6.1844","6.0653","4.0467","12.3712","46.3920"
"12.3000","6.2151","6.0960","4.0672","12.4401","46.6504"
"12.3600","6.2448","6.1257","4.0871","12.5035","46.8883"
"12.4200","6.2759","6.1568","4.1078","12.5727","47.1476"
"12.4800","6.3057","6.1866","4.1277","12.6363","47.3862"
"12.5400","6.3344","6.2154","4.1469","12.6975","47.6155"
"12.6000","6.3647","6.2456","4.1671","12.7664","47.8739"
"12.6600","6.3941","6.2750","4.1867","12.8284","48.1067"
"12.7200","6.4256","6.3065","4.2077","12.9016","48.3811"
"12.7800","6.4556","6.3365","4.2277","12.9660","48.6225"
"12.8400","6.4848","6.3657","4.2472","13.0280","48.8551"
"12.9000","6.5146","6.3955","4.2671","13.0949","49.1059"
"12.9600","6.5437","6.4246","4.2865","13.1558","49.3343"
"13.0200","6.5762","6.4571","4.3081","13.2314","49.6177"
"13.0800","6.6063","6.4872","4.3282","13.2992","49.8720"
"13.1400","6.6358","6.5167","4.3479","13.3641","50.1152"
"13.2000","6.6650","6.5459","4.3674","13.4309","50.3659"
"13.2600","6.6943","6.5752","4.3869","13.4903","50.5885"
"13.3200","6.7249","6.6058","4.4074","13.5598","50.8492"
"13.3800","6.7553","6.6362","4.4276","13.6284","51.1064"
"13.4400","6.7855","6.6664","4.4478","13.6962","51.3607"
"13.5000","6.8145","6.6954","4.4671","13.7604","51.6015"
"13.5600","6.8445","6.7254","4.4872","13.8270","51.8512"
"13.6200","6.8754","6.7563","4.5078","13.8966","52.1123"
"13.6800","6.9062","6.7871","4.5283","13.9653","52.3698"
"13.7400","6.9356","6.8165","4.5479","14.0268","52.6005"
"13.8000","6.9648","6.8457","4.5675","14.0933","52.8498"
"13.8600","6.9950","6.8760","4.5876","14.1630","53.1113"
"13.9200","7.0243","6.9052","4.6071","14.2263","53.3486"
"13.9800","7.0552","6.9361","4.6277","14.2971","53.6140"
"14.0400","7.0856","6.9666","4.6481","14.3645","53.8667"
"14.1000","7.1141","6.9950","4.6670","14.4264","54.0988"
"14.1600","7.1443","7.0252","4.6872","14.4949","54.3560"
"14.2200","7.1748","7.0557","4.7075","14.5625","54.6093"
"14.2800","7.2059","7.0868","4.7283","14.6364","54.8867"
"14.3400","7.2362","7.1171","4.7485","14.7034","55.1379"
"14.4000","7.2652","7.1461","4.7678","14.7655","55.3705"
"14.4600","7.2952","7.1761","4.7879","14.8347","55.6300"
"14.5200","7.3241","7.2050","4.8072","14.8980","55.8676"
"14.5800","7.3547","7.2356","4.8276","14.9695","56.1356"
"14.6400","7.3860","7.2670","4.8485","15.0425","56.4095"
"14.7000","7.4158","7.2967","4.8683","15.1072","56.6519"
"14.7600","7.4443","7.3252","4.8874","15.1728","56.8981"
"14.8200","7.4743","7.3552","4.9074","15.2386","57.1448"
"14.8800","7.5060","7.3869","4.9285","15.3127","57.4226"
"14.9400","7.5359","7.4168","4.9485","15.3802","57.6756"
"15.0000","7.5650","7.4459","4.9679","15.4439","57.9145"
"15.0600","7.5954","7.4763","4.9882","15.5147","58.1801"
"15.1200","7.6249","7.5058","5.0078","15.5804","58.4266"
"15.1800","7.6542","7.5351","5.0274","15.6496","58.6859"
"15.2400","7.6855","7.5664","5.0483","15.7193","58.9473"
"15.3000","7.7161","7.5971","5.0687","15.7886","59.2073"
"15.3600","7.7445","7.6255","5.0877","15.8521","59.4453"
"15.4200","7.7743","7.6552","5.1075","15.9194","59.6976"
"15.4800","7.8048","7.6857","5.1279","15.9888","59.9579"
"15.5400","7.8361","7.7171","5.1488","16.0605","60.2268"
"15.6000","7.8661","7.7470","5.1688","16.1278","60.4791"
"15.6600","7.8952","7.7762","5.1882","16.1941","60.7277"
"15.7200","7.9254","7.8063","5.2083","16.2624","60.9840"
"15.7800","7.9537","7.8346","5.2272","16.3247","61.2176"
"15.8400","7.9855","7.8664","5.2484","16.4030","61.5113"
"15.9000","8.0163","7.8972","5.2690","16.4737","61.7765"
"15.9600","8.0447","7.9256","5.2879","16.5356","62.0086"
"16.0200","8.0748","7.9557","5.3080","16.6055","62.2706"
"16.0800","8.1051","7.9860","5.3283","16.6741","62.5280"
"16.1400","8.1358","8.0167","5.3487","16.7475","62.8031"
"16.2000","8.1655","8.0464","5.3685","16.8160","63.0601"
"16.2600","8.1955","8.0764","5.3885","16.8874","63.3277"
"16.3200","8.2249","8.1058","5.4081","16.9560","63.5850"
"16.3800","8.2541","8.1350","5.4277","17.0195","63.8233"
"16.4400","8.2849","8.1658","5.4482","17.0951","64.1067"
"16.5000","8.3154","8.1963","5.4685","17.1621","64.3581"
"16.5600","8.3448","8.2257","5.4882","17.2307","64.6151"
"16.6200","8.3745","8.2554","5.5080","17.3001","64.8754"
"16.6800","8.4053","8.2862","5.5285","17.3732","65.1497"
"16.7400","8.4351","8.3160","5.5484","17.4437","65.4139"
"16.8000","8.4659","8.3468","5.5689","17.5153","65.6823"
"16.8600","8.4963","8.3772","5.5892","17.5850","65.9439"
"16.9200","8.5246","8.4055","5.6081","17.6510","66.1913"
"16.9800","8.5549","8.4359","5.6284","17.7226","66.4597"
"17.0400","8.5846","8.4655","5.6481","17.7936","66.7259"
"17.1000","8.6158","8.4967","5.6690","17.8683","67.0062"
"17.1600","8.6447","8.5257","5.6883","17.9346","67.2546"
"17.2200","8.6746","8.5555","5.7082","18.0040","67.5148"
"17.2800","8.7054","8.5864","5.7288","18.0771","67.7891"
"17.3400","8.7343","8.6153","5.7481","18.1455","68.0457"
"17.4000","8.7658","8.6467","5.7691","18.2226","68.3348"
"17.4600","8.7959","8.6768","5.7891","18.2917","68.5940"
"17.5200","8.8251","8.7060","5.8086","18.3608","68.8528"
"17.5800","8.8549","8.7359","5.8285","18.4331","69.1239"
"17.6400","8.8840","8.7649","5.8479","18.5000","69.3749"
"17.7000","8.9149","8.7958","5.8685","18.5744","69.6541"
"17.7600","8.9456","8.8265","5.8890","18.6472","69.9268"
"17.8200","8.9754","8.8563","5.9089","18.7180","70.1927"
"17.8800","9.0048","8.8857","5.9285","18.7877","70.4539"
"17.9400","9.0348","8.9157","5.9485","18.8574","70.7152"
"18.0000","9.0652","8.9461","5.9688","18.9318","70.9942"
"18.0600","9.0960","8.9769","5.9894","19.0041","71.2655"
"18.1200","9.1259","9.0068","6.0093","19.0774","71.5404"
"18.1800","9.1546","9.0355","6.0285","19.1444","71.7917"
"18.2400","9.1849","9.0658","6.0487","19.2183","72.0687"
"18.3000","9.2145","9.0954","6.0684","19.2906","72.3399"
"18.3600","9.2453","9.1262","6.0890","19.3633","72.6124"
"18.4200","9.2754","9.1563","6.1091","19.4356","72.8835"
"18.4800","9.3048","9.1857","6.1287","19.5069","73.1507"
"18.5400","9.3349","9.2158","6.1488","19.5799","73.4248"
"18.6000","9.3645","9.2454","6.1685","19.6518","73.6944"
"18.6600","9.3962","9.2771","6.1896","19.7298","73.9868"
"18.7200","9.4256","9.3065","6.2093","19.8005","74.2518"
"18.7800","9.4546","9.3356","6.2286","19.8684","74.5066"
"18.8400","9.4844","9.3653","6.2485","19.9396","74.7736"
"18.9000","9.5136","9.3945","6.2680","20.0100","75.0376"
"18.9600","9.5456","9.4265","6.2893","20.0911","75.3417"
"19.0200","9.5752","9.4562","6.3091","20.1631","75.6118"
"19.0800","9.6049","9.4858","6.3289","20.2332","75.8743"
"19.1400","9.6345","9.5154","6.3486","20.3041","76.1403"
"19.2000","9.6644","9.5453","6.3686","20.3774","76.4152"
"19.2600","9.6963","9.5772","6.3899","20.4575","76.7157"
"19.3200","9.7258","9.6067","6.4096","20.5286","76.9821"
"19.3800","9.7556","9.6366","6.4295","20.6027","77.2601"
"19.4400","9.7855","9.6664","6.4494","20.6739","77.5270"
"19.5000","9.8148","9.6957","6.4689","20.7443","77.7910"
"19.5600","9.8450","9.7259","6.4891","20.8184","78.0691"
"19.6200","9.8756","9.7565","6.5095","20.8949","78.3559"
"19.6800","9.9061","9.7870","6.5299","20.9698","78.6368"
"19.7400","9.9345","9.8154","6.5488","21.0352","78.8821"
"19.8000","9.9651","9.8460","6.5692","21.1154","79.1828"
"19.8600","9.9953","9.8762","6.5894","21.1887","79.4575"
"19.9200","10.0258","9.9067","6.6097","21.2635","79.7381"
"19.9800","10.0555","9.9364","6.6295","21.3368","80.0130"
"20.0400","10.0848","9.9658","6.6491","21.4090","80.2839"
"20.1000","10.1152","9.9961","6.6694","21.4836","80.5633"
"20.1600","10.1438","10.0247","6.6884","21.5543","80.8288"
"20.2200","10.1749","10.0558","6.7092","21.6340","81.1274"
"20.2800","10.2060","10.0869","6.7300","21.7128","81.4229"
"20.3400","10.2347","10.1156","6.7491","21.7795","81.6730"
"20.4000","10.2643","10.1452","6.7689","21.8539","81.9522"
"20.4600","10.2949","10.1758","6.7893","21.9314","82.2428"
"20.5200","10.3260","10.2069","6.8100","22.0106","82.5397"
"20.5800","10.3556","10.2365","6.8297","22.0853","82.8197"
"20.6400","10.3856","10.2665","6.8498","22.1598","83.0991"
"20.7000","10.4155","10.2964","6.8697","22.2351","83.3818"
"20.7600","10.4438","10.3247","6.8886","22.3018","83.6319"
"20.8200","10.4750","10.3559","6.9094","22.3824","83.9338"
"20.8800","10.5060","10.3869","6.9301","22.4631","84.2367"
"20.9400","10.5354","10.4163","6.9497","22.5363","84.5110"
"21.0000","10.5643","10.4452","6.9690","22.6063","84.7735"
"21.0600","10.5950","10.4759","6.9895","22.6847","85.0678"
"21.1200","10.6258","10.5067","7.0100","22.7633","85.3625"
"21.1800","10.6555","10.5364","7.0299","22.8368","85.6379"
"21.2400","10.6860","10.5669","7.0502","22.9178","85.9417"
"21.3000","10.7152","10.5962","7.0697","22.9899","86.2120"
"21.3600","10.7450","10.6259","7.0895","23.0659","86.4972"
"21.4200","10.7741","10.6550","7.1090","23.1385","86.7694"
"21.4800","10.8055","10.6865","7.1300","23.2225","87.0842"
"21.5400","10.8352","10.7162","7.1498","23.2955","87.3583"
"21.6000","10.8642","10.7451","7.1691","23.3664","87.6240"
"21.6600","10.8947","10.7756","7.1894","23.4467","87.9252"
"21.7200","10.9248","10.8058","7.2096","23.5221","88.2079"
"21.7800","10.9560","10.8369","7.2303","23.6053","88.5201"
"21.8400","10.9861","10.8670","7.2504","23.6821","88.8078"
"21.9000","11.0152","10.8961","7.2698","23.7534","89.0754"
"21.9600","11.0447","10.9256","7.2895","23.8310","89.3663"
"22.0200","11.0739","10.9549","7.3090","23.9038","89.6391"
"22.0800","11.1055","10.9864","7.3301","23.9871","89.9516"
"22.1400","11.1354","11.0163","7.3500","24.0652","90.2445"
"22.2000","11.1652","11.0461","7.3699","24.1428","90.5355"
"22.2600","11.1950","11.0759","7.3898","24.2207","90.8275"
"22.3200","11.2245","11.1054","7.4095","24.2944","91.1040"
"22.3800","11.2554","11.1363","7.4301","24.3753","91.4075"
"22.4400","11.2861","11.1670","7.4506","24.4563","91.7112"
"22.5000","11.3156","11.1966","7.4703","24.5326","91.9972"
"22.5600","11.3443","11.2252","7.4894","24.6050","92.2687"
"22.6200","11.3744","11.2553","7.5095","24.6845","92.5667"
"22.6800","11.4047","11.2857","7.5298","24.7638","92.8642"
"22.7400","11.4349","11.3158","7.5499","24.8413","93.1548"
"22.8000","11.4652","11.3461","7.5701","24.9196","93.4484"
"22.8600","11.4949","11.3758","7.5899","24.9974","93.7404"
"22.9200","11.5247","11.4056","7.6098","25.0746","94.0297"
"22.9800","11.5546","11.4355","7.6297","25.1537","94.3262"
"23.0400","11.5866","11.4675","7.6511","25.2390","94.6464"
"23.1000","11.6161","11.4971","7.6708","25.3152","94.9319"
"23.1600","11.6447","11.5256","7.6898","25.3856","95.1960"
"23.2200","11.6752","11.5562","7.7102","25.4689","95.5085"
"23.2800","11.7044","11.5853","7.7297","25.5446","95.7922"
"23.3400","11.7355","11.6164","7.7504","25.6304","96.1141"
"23.4000","11.7654","11.6463","7.7704","25.7074","96.4028"
"23.4600","11.7950","11.6759","7.7901","25.7828","96.6855"
"23.5200","11.8248","11.7057","7.8100","25.8627","96.9850"
"23.5800","11.8541","11.7350","7.8295","25.9365","97.2619"
"23.6400","11.8858","11.7667","7.8507","26.0246","97.5921"
"23.7000","11.9167","11.7977","7.8714","26.1095","97.9105"
"23.7600","11.9453","11.8262","7.8904","26.1824","98.1840"
"23.8200","11.9745","11.8555","7.9099","26.2586","98.4697"
"23.8800","12.0044","11.8853","7.9298","26.3354","98.7576"
"23.9400","12.0346","11.9156","7.9500","26.4162","99.0608"
"24.0000","12.0650","11.9459","7.9703","26.4981","99.3678"
"24.0600","12.0954","11.9764","7.9906","26.5778","99.6667"
"24.1200","12.1240","12.0049","8.0096","26.6536","99.9508"
"24.1800","12.1544","12.0354","8.0299","26.7369","100.2634"
"24.2400","12.1846","12.0655","8.0501","26.8162","100.5606"
"24.3000","12.2159","12.0968","8.0709","26.9017","100.8812"
"24.3600","12.2454","12.1263","8.0906","26.9783","101.1688"
"24.4200","12.2742","12.1551","8.1099","27.0544","101.4538"
"24.4800","12.3053","12.1862","8.1306","27.1395","101.7732"
"24.5400","12.3343","12.2152","8.1499","27.2169","102.0635"
"24.6000","12.3655","12.2464","8.1708","27.3031","102.3868"
"24.6600","12.3960","12.2769","8.1911","27.3841","102.6905"
"24.7200","12.4250","12.3059","8.2105","27.4595","102.9730"
"24.7800","12.4550","12.3359","8.2305","27.5405","103.2770"
"24.8400","12.4844","12.3653","8.2501","27.6205","103.5768"
"24.9000","12.5163","12.3972","8.2714","27.7104","103.9139"
"24.9600","12.5457","12.4267","8.2910","27.7882","104.2059"
"25.0200","12.5752","12.4561","8.3107","27.8663","104.4987"
"25.0800","12.6053","12.4862","8.3307","27.9504","104.8139"
"25.1400","12.6340","12.5149","8.3499","28.0243","105.0911"
"25.2000","12.6647","12.5456","8.3704","28.1105","105.4145"
"25.2600","12.6957","12.5766","8.3910","28.1974","105.7403"
"25.3200","12.7253","12.6063","8.4108","28.2763","106.0361"
"25.3800","12.7545","12.6354","8.4303","28.3577","106.3415"
"25.4400","12.7845","12.6655","8.4503","28.4373","106.6399"
"25.5000","12.8153","12.6962","8.4708","28.5250","106.9687"
"25.5600","12.8457","12.7267","8.4912","28.6089","107.2833"
"25.6200","12.8759","12.7568","8.5113","28.6902","107.5884"
"25.6800","12.9048","12.7857","8.5306","28.7689","107.8835"
"25.7400","12.9348","12.8157","8.5506","28.8525","108.1968"
"25.8000","12.9639","12.8448","8.5700","28.9322","108.4959"
"25.8600","12.9958","12.8767","8.5913","29.0236","108.8384"
"25.9200","13.0257","12.9067","8.6113","29.1040","109.1399"
"25.9800","13.0539","12.9348","8.6301","29.1792","109.4220"
"26.0400","13.0851","12.9660","8.6509","29.2688","109.7578"
"26.1000","13.1152","12.9961","8.6709","29.3533","110.0747"
"26.1600","13.1460","13.0269","8.6915","29.4407","110.4025"
"26.2200","13.1760","13.0569","8.7115","29.5237","110.7139"
"26.2800","13.2053","13.0862","8.7311","29.6037","111.0138"
"26.3400","13.2348","13.1157","8.7507","29.6843","111.3163"
"26.4000","13.2639","13.1448","8.7702","29.7658","111.6217"
"26.4600","13.2957","13.1767","8.7914","29.8604","111.9763"
"26.5200","13.3253","13.2062","8.8111","29.9413","112.2800"
"26.5800","13.3543","13.2352","8.8305","30.0212","112.5797"
"26.6400","13.3848","13.2658","8.8509","30.1089","112.9085"
"26.7000","13.4147","13.2957","8.8708","30.1900","113.2124"
"26.7600","13.4455","13.3264","8.8913","30.2789","113.5457"
"26.8200","13.4756","13.3566","8.9114","30.3630","113.8614"
"26.8800","13.5062","13.3871","8.9319","30.4541","114.2030"
"26.9400","13.5353","13.4162","8.9513","30.5348","114.5056"
"27.0000","13.5641","13.4450","8.9705","30.6133","114.8000"
"27.0600","13.5948","13.4757","8.9910","30.7030","115.1361"
"27.1200","13.6256","13.5065","9.0115","30.7900","115.4625"
"27.1800","13.6553","13.5362","9.0313","30.8724","115.7716"
"27.2400","13.6846","13.5655","9.0509","30.9574","116.0901"
"27.3000","13.7151","13.5960","9.0712","31.0449","116.4182"
"27.3600","13.7452","13.6261","9.0913","31.1328","116.7478"
"27.4200","13.7759","13.6568","9.1118","31.2188","117.0706"
"27.4800","13.8057","13.6866","9.1317","31.3018","117.3817"
"27.5400","13.8349","13.7158","9.1511","31.3852","117.6946"
"27.6000","13.8650","13.7459","9.1712","31.4711","118.0168"
"27.6600","13.8940","13.7750","9.1906","31.5549","118.3307"
"27.7200","13.9253","13.8062","9.2115","31.6470","118.6761"
"27.7800","13.9554","13.8363","9.2316","31.7331","118.9993"
"27.8400","13.9847","13.8656","9.2511","31.8162","119.3106"
"27.9000","14.0148","13.8957","9.2712","31.9015","119.6305"
"27.9600","14.0438","13.9247","9.2905","31.9848","119.9429"
"28.0200","14.0761","13.9570","9.3121","32.0839","120.3146"
"28.0800","14.1061","13.9870","9.3321","32.1703","120.6388"
"28.1400","14.1355","14.0164","9.3517","32.2559","120.9594"
"28.2000","14.1651","14.0460","9.3715","32.3407","121.2777"
"28.2600","14.1944","14.0753","9.3910","32.4217","121.5816"
"28.3200","14.2247","14.1057","9.4112","32.5115","121.9182"
"28.3800","14.2552","14.1361","9.4316","32.6022","122.2582"
"28.4400","14.2858","14.1667","9.4520","32.6932","122.5993"
"28.5000","14.3146","14.1955","9.4712","32.7738","122.9018"
"28.5600","14.3444","14.2253","9.4911","32.8608","123.2282"
"28.6200","14.3755","14.2564","9.5118","32.9532","123.5746"
"28.6800","14.4061","14.2870","9.5323","33.0429","123.9107"
"28.7400","14.4353","14.3162","9.5517","33.1249","124.2185"
"28.8000","14.4644","14.3454","9.5712","33.2103","124.5386"
"28.8600","14.4951","14.3760","9.5916","33.3021","124.8827"
"28.9200","14.5246","14.4055","9.6113","33.3905","125.2143"
"28.9800","14.5551","14.4360","9.6317","33.4785","125.5445"
"29.0400","14.5860","14.4669","9.6523","33.5713","125.8925"
"29.1000","14.6146","14.4955","9.6713","33.6510","126.1912"
"29.1600","14.6444","14.5253","9.6912","33.7369","126.5134"
"29.2200","14.6745","14.5554","9.7113","33.8297","126.8613"
"29.2800","14.7065","14.5874","9.7326","33.9280","127.2301"
"29.3400","14.7356","14.6165","9.7521","34.0111","127.5415"
"29.4000","14.7650","14.6459","9.7717","34.0945","127.8544"
"29.4600","14.7950","14.6759","9.7917","34.1847","128.1926"
"29.5200","14.8238","14.7047","9.8109","34.2668","128.5006"
"29.5800","14.8550","14.7359","9.8317","34.3632","128.8621"
"29.6400","14.8858","14.7667","9.8523","34.4587","129.2203"
"29.7000","14.9155","14.7965","9.8721","34.5468","129.5504"
"29.7600","14.9446","14.8256","9.8916","34.6309","129.8659"
"29.8200","14.9749","14.8558","9.9117","34.7212","130.2045"
"29.8800","15.0059","14.8868","9.9324","34.8154","130.5577"
"29.9400","15.0359","14.9168","9.9524","34.9057","130.8963"
"30.0000","15.0655","14.9464","9.9722","34.9956","131.2334"
"30.0600","15.0951","14.9760","9.9919","35.0821","131.5580"
"30.1200","15.1248","15.0057","10.0117","35.1722","131.8959"
"30.1800","15.1541","15.0350","10.0313","35.2592","132.2220"
"30.2400","15.1856","15.0665","10.0523","35.3586","132.5947"
"30.3000","15.2160","15.0969","10.0726","35.4507","132.9403"
"30.3600","15.2443","15.1252","10.0915","35.5303","133.2386"
"30.4200","15.2747","15.1556","10.1117","35.6240","133.5900"
"30.4800","15.3047","15.1857","10.1318","35.7164","133.9363"
"30.5400","15.3360","15.2169","10.1527","35.8128","134.2982"
"30.6000","15.3656","15.2466","10.1724","35.9004","134.6264"
"30.6600","15.3948","15.2757","10.1919","35.9842","134.9409"
"30.7200","15.4250","15.3059","10.2121","36.0750","135.2812"
"30.7800","15.4537","15.3346","10.2312","36.1618","135.6068"
"30.8400","15.4853","15.3662","10.2523","36.2615","135.9806"
"30.9000","15.5161","15.3970","10.2728","36.3555","136.3330"
"30.9600","15.5446","15.4255","10.2918","36.4376","136.6412"
"31.0200","15.5747","15.4556","10.3119","36.5301","136.9879"
"31.0800","15.6049","15.4859","10.3321","36.6226","137.3347"
"31.1400","15.6358","15.5167","10.3527","36.7172","137.6896"
"31.2000","15.6659","15.5468","10.3728","36.8107","138.0403"
"31.2600","15.6956","15.5765","10.3926","36.9010","138.3789"
"31.3200","15.7248","15.6058","10.4121","36.9880","138.7050"
"31.3800","15.7541","15.6350","10.4316","37.0759","139.0348"
"31.4400","15.7852","15.6661","10.4523","37.1736","139.4010"
"31.5000","15.8156","15.6966","10.4727","37.2688","139.7579"
"31.5600","15.8452","15.7261","10.4924","37.3589","140.0957"
"31.6200","15.8740","15.7550","10.5117","37.4444","140.4167"
"31.6800","15.9049","15.7858","10.5323","37.5419","140.7821"
"31.7400","15.9351","15.8161","10.5524","37.6338","141.1266"
"31.8000","15.9653","15.8462","10.5726","37.7247","141.4675"
"31.8600","15.9958","15.8767","10.5929","37.8184","141.8188"
"31.9200","16.0249","15.9058","10.6123","37.9043","142.1411"
"31.9800","16.0547","15.9356","10.6322","37.9959","142.4846"
"32.0400","16.0845","15.9654","10.6521","38.0859","142.8221"
"32.1000","16.1156","15.9965","10.6728","38.1834","143.1879"
"32.1600","16.1451","16.0260","10.6925","38.2709","143.5161"
"32.2200","16.1746","16.0555","10.7122","38.3585","143.8444"
"32.2800","16.2055","16.0864","10.7328","38.4547","144.2053"
"32.3400","16.2346","16.1155","10.7522","38.5405","144.5269"
"32.4000","16.2662","16.1472","10.7733","38.6409","144.9035"
"32.4600","16.2961","16.1770","10.7932","38.7306","145.2396"
"32.5200","16.3254","16.2063","10.8128","38.8177","145.5664"
"32.5800","16.3543","16.2352","10.8321","38.9038","145.8891"
"32.6400","16.3839","16.2648","10.8518","38.9924","146.2214"
"32.7000","16.4156","16.2965","10.8730","39.0935","146.6005"
"32.7600","16.4452","16.3262","10.8928","39.1839","146.9395"
"32.8200","16.4753","16.3562","10.9128","39.2792","147.2971"
"32.8800","16.5050","16.3859","10.9326","39.3703","147.6386"
"32.9400","16.5345","16.4154","10.9523","39.4522","147.9459"
"33.0000","16.5652","16.4461","10.9728","39.5445","148.2921"
"33.0600","16.5961","16.4770","10.9934","39.6395","148.6482"
"33.1200","16.6260","16.5070","11.0134","39.7296","148.9860"
"33.1800","16.6545","16.5354","11.0324","39.8130","149.2987"
"33.2400","16.6842","16.5651","11.0522","39.9035","149.6381"
"33.3000","16.7149","16.5958","11.0727","39.9981","149.9930"
"33.3600","16.7454","16.6263","11.0930","40.0902","150.3382"
"33.4200","16.7755","16.6564","11.1131","40.1831","150.6865"
"33.4800","16.8047","16.6856","11.1326","40.2697","151.0114"
"33.5400","16.8347","16.7156","11.1526","40.3635","151.3630"
"33.6000","16.8646","16.7455","11.1725","40.4553","151.7073"
"33.6600","16.8962","16.7771","11.1936","40.5561","152.0853"
"33.7200","16.9259","16.8068","11.2135","40.6475","152.4282"
"33.7800","16.9549","16.8358","11.2328","40.7319","152.7448"
"33.8400","16.9849","16.8658","11.2528","40.8254","153.0954"
"33.9000","17.0142","16.8951","11.2724","40.9144","153.4290"
"33.9600","17.0455","16.9264","11.2932","41.0173","153.8150"
"34.0200","17.0755","16.9564","11.3133","41.1076","154.1534"
"34.0800","17.1050","16.9859","11.3329","41.1966","154.4874"
"34.1400","17.1340","17.0149","11.3523","41.2844","154.8165"
"34.2000","17.1645","17.0454","11.3726","41.3795","155.1731"
"34.2600","17.1960","17.0770","11.3937","41.4809","155.5535"
"34.3200","17.2257","17.1066","11.4134","41.5696","155.8859"
"34.3800","17.2552","17.1361","11.4331","41.6589","156.2211"
"34.4400","17.2848","17.1657","11.4529","41.7513","156.5675"
"34.5000","17.3141","17.1950","11.4724","41.8362","156.8858"
"34.5600","17.3441","17.2250","11.4925","41.9291","157.2340"
"34.6200","17.3754","17.2563","11.5134","42.0297","157.6116"
"34.6800","17.4058","17.2867","11.5336","42.1206","157.9523"
"34.7400","17.4344","17.3153","11.5527","42.2065","158.2746"
"34.8000","17.4648","17.3457","11.5730","42.3024","158.6340"
"34.8600","17.4953","17.3762","11.5933","42.3976","158.9910"
"34.9200","17.5262","17.4071","11.6140","42.4929","159.3486"
"34.9800","17.5554","17.4363","11.6334","42.5754","159.6577"
"35.0400","17.5850","17.4659","11.6532","42.6669","160.0008"
"35.1000","17.6155","17.4964","11.6735","42.7598","160.3493"
"35.1600","17.6439","17.5248","11.6925","42.8410","160.6538"
"35.2200","17.6753","17.5563","11.7135","42.9437","161.0389"
"35.2800","17.7062","17.5871","11.7341","43.0354","161.3827"
"35.3400","17.7346","17.6156","11.7530","43.1166","161.6874"
"35.4000","17.7645","17.6454","11.7730","43.2062","162.0233"
"35.4600","17.7947","17.6756","11.7931","43.2960","162.3601"
"35.5200","17.8258","17.7067","11.8138","43.3933","162.7249"
"35.5800","17.8555","17.7364","11.8337","43.4799","163.0498"
"35.6400","17.8851","17.7661","11.8534","43.5666","163.3748"
"35.7000","17.9152","17.7961","11.8735","43.6576","163.7161"
"35.7600","17.9437","17.8246","11.8925","43.7360","164.0100"
"35.8200","17.9751","17.8560","11.9135","43.8358","164.3842"
"35.8800","18.0062","17.8871","11.9342","43.9301","164.7378"
"35.9400","18.0353","17.9162","11.9536","44.0138","165.0517"
"36.0000","18.0638","17.9447","11.9727","44.0962","165.3606"
"36.0600","18.0950","17.9759","11.9934","44.1910","165.7162"
"36.1200","18.1258","18.0067","12.0140","44.2867","166.0751"
"36.1800","18.1561","18.0370","12.0343","44.3741","166.4028"
"36.2400","18.1861","18.0670","12.0542","44.4611","166.7291"
"36.3000","18.2154","18.0964","12.0738","44.5468","167.0506"
"36.3600","18.2451","18.1260","12.0936","44.6333","167.3749"
"36.4200","18.2741","18.1550","12.1130","44.7164","167.6865"
"36.4800","18.3055","18.1864","12.1339","44.8103","168.0387"
"36.5400","18.3356","18.2165","12.1540","44.8972","168.3645"
"36.6000","18.3643","18.2453","12.1732","44.9764","168.6614"
"36.6600","18.3952","18.2761","12.1937","45.0673","169.0023"
"36.7200","18.4249","18.3058","12.2136","45.1552","169.3319"
"36.7800","18.4562","18.3372","12.2345","45.2490","169.6836"
"36.8400","18.4860","18.3669","12.2543","45.3322","169.9959"
"36.9000","18.5150","18.3959","12.2737","45.4098","170.2869"
"36.9600","18.5447","18.4256","12.2935","45.4943","170.6037"
"37.0200","18.5739","18.4548","12.3130","45.5733","170.8998"
"37.0800","18.6052","18.4861","12.3339","45.6660","171.2473"
"37.1400","18.6353","18.5162","12.3540","45.7493","171.5600"
"37.2000","18.6649","18.5459","12.3737","45.8337","171.8765"
"37.2600","18.6948","18.5757","12.3936","45.9177","172.1914"
"37.3200","18.7252","18.6061","12.4139","46.0037","172.5137"
"37.3800","18.7558","18.6368","12.4344","46.0876","172.8287"
"37.4400","18.7858","18.6667","12.4544","46.1685","173.1319"
"37.5000","18.8160","18.6969","12.4745","46.2523","173.4462"
"37.5600","18.8447","18.7257","12.4937","46.3233","173.7125"
"37.6200","18.8744","18.7553","12.5135","46.4033","174.0122"
"37.6800","18.9046","18.7855","12.5336","46.4839","174.3147"
"37.7400","18.9356","18.8165","12.5543","46.5685","174.6319"
"37.8000","18.9660","18.8469","12.5746","46.6492","174.9345"
"37.8600","18.9947","18.8756","12.5937","46.7192","175.1969"
"37.9200","19.0245","18.9054","12.6136","46.7961","175.4855"
"37.9800","19.0546","18.9355","12.6337","46.8731","175.7740"
"38.0400","19.0862","18.9671","12.6548","46.9565","176.0870"
"38.1000","19.1157","18.9966","12.6745","47.0285","176.3568"
"38.1600","19.1450","19.0259","12.6940","47.0969","176.6135"
"38.2200","19.1750","19.0559","12.7141","47.1699","176.8872"
"38.2800","19.2041","19.0850","12.7335","47.2400","177.1498"
"38.3400","19.2351","19.1160","12.7542","47.3170","177.4389"
"38.4000","19.2651","19.1460","12.7741","47.3872","177.7021"
"38.4600","19.2953","19.1762","12.7943","47.4581","177.9680"
"38.5200","19.3253","19.2062","12.8143","47.5275","178.2282"
"38.5800","19.3541","19.2350","12.8335","47.5890","178.4586"
"38.6400","19.3860","19.2669","12.8548","47.6661","178.7480"
"38.7000","19.4164","19.2973","12.8751","47.7357","179.0089"
"38.7600","19.4452","19.3262","12.8943","47.7935","179.2257"
"38.8200","19.4750","19.3559","12.9142","47.8557","179.4589"
"38.8800","19.5043","19.3852","12.9338","47.9150","179.6812"
"38.9400","19.5348","19.4157","12.9541","47.9806","179.9271"
"39.0000","19.5654","19.4463","12.9745","48.0431","180.1616"
"39.0600","19.5958","19.4767","12.9948","48.1038","180.3891"
"39.1200","19.6244","19.5053","13.0139","48.1519","180.5697"
"39.1800","19.6545","19.5354","13.0339","48.2094","180.7853"
"39.2400","19.6849","19.5658","13.0543","48.2652","180.9944"
"39.3000","19.7160","19.5970","13.0750","48.3224","181.2092"
"39.3600","19.7457","19.6266","13.0948","48.3720","181.3949"
"39.4200","19.7748","19.6557","13.1142","48.4157","181.5587"
"39.4800","19.8054","19.6863","13.1346","48.4701","181.7627"
"39.5400","19.8344","19.7154","13.1540","48.5142","181.9284"
"39.6000","19.8651","19.7460","13.1745","48.5645","182.1170"
"39.6600","19.8957","19.7766","13.1949","48.6146","182.3047"
"39.7200","19.9249","19.8058","13.2143","48.6499","182.4373"
"39.7800","19.9549","19.8358","13.2344","48.6885","182.5818"
"39.8100","19.9696","19.8505","13.2442","48.7091","182.6591"