File: data/instron_tests/metamaterials/250327/250327_1467_BULK_m2_NoTransition.is_comp_Exports/250327_1467_BULK_m2_NoTransition_5_1.csv
Results Table 1
,Compression Axis,H*,V*,Height,Thickness,Width,Area,Fixture separation,Specimen label
,,,,(mm),(mm),(mm),(mm^2),(mm),
"5","X","","","149.00","28.00","149.00","4172.00","150.00","1467_BULK_m2_NoTransition"

Results Table 2
,Modulus (Segment 0 % - 5 %),Compression Axis
,(kPa),
"5","796.68","X"

Time,Displacement,Force,Compressive displacement,Compressive strain (Displacement),Compressive stress
(s),(mm),(N),(mm),(%),(kPa)
"0.0000","0.0000","-11.6861","0.0000","0.0000","-2.8011"
"0.0800","0.0012","-11.6556","0.0012","0.0008","-2.7938"
"0.1600","0.0175","-11.1109","0.0175","0.0117","-2.6632"
"0.2400","0.0387","-10.5256","0.0387","0.0258","-2.5229"
"0.3200","0.0582","-9.9578","0.0582","0.0388","-2.3868"
"0.4000","0.0771","-9.3987","0.0771","0.0514","-2.2528"
"0.4800","0.0982","-8.7915","0.0982","0.0655","-2.1073"
"0.5600","0.1181","-8.2423","0.1181","0.0787","-1.9756"
"0.6400","0.1380","-7.7020","0.1380","0.0920","-1.8461"
"0.7200","0.1572","-7.1806","0.1572","0.1048","-1.7211"
"0.8000","0.1763","-6.6639","0.1763","0.1175","-1.5973"
"0.8800","0.1976","-6.0929","0.1976","0.1317","-1.4604"
"0.9600","0.2173","-5.5730","0.2173","0.1448","-1.3358"
"1.0400","0.2364","-5.0561","0.2364","0.1576","-1.2119"
"1.1200","0.2572","-4.5149","0.2572","0.1715","-1.0822"
"1.2000","0.2774","-3.9880","0.2774","0.1849","-0.9559"
"1.2800","0.2981","-3.4480","0.2981","0.1987","-0.8265"
"1.3600","0.3178","-2.9409","0.3178","0.2119","-0.7049"
"1.4400","0.3363","-2.4739","0.3363","0.2242","-0.5930"
"1.5200","0.3568","-1.9379","0.3568","0.2378","-0.4645"
"1.6000","0.3771","-1.4227","0.3771","0.2514","-0.3410"
"1.6800","0.3976","-0.8876","0.3976","0.2651","-0.2127"
"1.7600","0.4186","-0.3544","0.4186","0.2790","-0.0850"
"1.8400","0.4377","0.1276","0.4377","0.2918","0.0306"
"1.9200","0.4576","0.6253","0.4576","0.3051","0.1499"
"2.0000","0.4775","1.1275","0.4775","0.3183","0.2703"
"2.0800","0.4970","1.6174","0.4970","0.3313","0.3877"
"2.1600","0.5171","2.1229","0.5171","0.3447","0.5088"
"2.2400","0.5361","2.5910","0.5361","0.3574","0.6211"
"2.3200","0.5569","3.1207","0.5569","0.3713","0.7480"
"2.4000","0.5784","3.6491","0.5784","0.3856","0.8747"
"2.4800","0.5973","4.1226","0.5973","0.3982","0.9882"
"2.5600","0.6177","4.6318","0.6177","0.4118","1.1102"
"2.6400","0.6365","5.0966","0.6365","0.4243","1.2216"
"2.7200","0.6569","5.6133","0.6569","0.4379","1.3455"
"2.8000","0.6775","6.1270","0.6775","0.4517","1.4686"
"2.8800","0.6969","6.6045","0.6969","0.4646","1.5830"
"2.9600","0.7176","7.1048","0.7176","0.4784","1.7030"
"3.0400","0.7382","7.6093","0.7382","0.4921","1.8239"
"3.1200","0.7573","8.0850","0.7573","0.5048","1.9379"
"3.2000","0.7775","8.5764","0.7775","0.5183","2.0557"
"3.2800","0.7971","9.0628","0.7971","0.5314","2.1723"
"3.3600","0.8180","9.5787","0.8180","0.5454","2.2960"
"3.4400","0.8372","10.0378","0.8372","0.5582","2.4060"
"3.5200","0.8552","10.4880","0.8552","0.5701","2.5139"
"3.6000","0.8770","11.0288","0.8770","0.5847","2.6435"
"3.6800","0.8985","11.5677","0.8985","0.5990","2.7727"
"3.7600","0.9178","12.0283","0.9178","0.6119","2.8831"
"3.8400","0.9374","12.5105","0.9374","0.6249","2.9987"
"3.9200","0.9564","12.9658","0.9564","0.6376","3.1078"
"4.0000","0.9770","13.4817","0.9770","0.6514","3.2315"
"4.0800","0.9975","13.9777","0.9975","0.6650","3.3504"
"4.1600","1.0170","14.4575","1.0170","0.6780","3.4654"
"4.2400","1.0380","14.9784","1.0380","0.6920","3.5902"
"4.3200","1.0576","15.4441","1.0576","0.7051","3.7019"
"4.4000","1.0780","15.9351","1.0780","0.7187","3.8195"
"4.4800","1.0978","16.4132","1.0978","0.7319","3.9341"
"4.5600","1.1168","16.8752","1.1168","0.7446","4.0449"
"4.6400","1.1371","17.3732","1.1371","0.7581","4.1642"
"4.7200","1.1565","17.8270","1.1565","0.7710","4.2730"
"4.8000","1.1762","18.3139","1.1762","0.7841","4.3897"
"4.8800","1.1981","18.8501","1.1981","0.7987","4.5182"
"4.9600","1.2176","19.3072","1.2176","0.8117","4.6278"
"5.0400","1.2378","19.7952","1.2378","0.8252","4.7448"
"5.1200","1.2572","20.2506","1.2572","0.8381","4.8539"
"5.2000","1.2765","20.7218","1.2765","0.8510","4.9669"
"5.2800","1.2973","21.2222","1.2973","0.8649","5.0868"
"5.3600","1.3171","21.6985","1.3171","0.8780","5.2010"
"5.4400","1.3374","22.1902","1.3374","0.8916","5.3188"
"5.5200","1.3584","22.6929","1.3584","0.9056","5.4393"
"5.6000","1.3775","23.1521","1.3775","0.9184","5.5494"
"5.6800","1.3979","23.6423","1.3979","0.9319","5.6669"
"5.7600","1.4176","24.1023","1.4176","0.9451","5.7772"
"5.8400","1.4370","24.5712","1.4370","0.9580","5.8895"
"5.9200","1.4570","25.0494","1.4570","0.9713","6.0042"
"6.0000","1.4762","25.5061","1.4762","0.9841","6.1136"
"6.0800","1.4971","26.0025","1.4971","0.9981","6.2326"
"6.1600","1.5182","26.5106","1.5182","1.0121","6.3544"
"6.2400","1.5378","26.9790","1.5378","1.0252","6.4667"
"6.3200","1.5571","27.4397","1.5571","1.0381","6.5771"
"6.4000","1.5767","27.8959","1.5767","1.0511","6.6865"
"6.4800","1.5973","28.3873","1.5973","1.0649","6.8042"
"6.5600","1.6177","28.8710","1.6177","1.0785","6.9202"
"6.6400","1.6360","29.3026","1.6360","1.0907","7.0236"
"6.7200","1.6579","29.8401","1.6579","1.1053","7.1525"
"6.8000","1.6784","30.3200","1.6784","1.1189","7.2675"
"6.8800","1.6982","30.7884","1.6982","1.1322","7.3798"
"6.9600","1.7168","31.2271","1.7168","1.1445","7.4849"
"7.0400","1.7366","31.6798","1.7366","1.1577","7.5934"
"7.1200","1.7566","32.1659","1.7566","1.1711","7.7099"
"7.2000","1.7778","32.6670","1.7778","1.1852","7.8301"
"7.2800","1.7965","33.1146","1.7965","1.1977","7.9374"
"7.3600","1.8178","33.6305","1.8178","1.2119","8.0610"
"7.4400","1.8374","34.0780","1.8374","1.2249","8.1683"
"7.5200","1.8575","34.5502","1.8575","1.2383","8.2814"
"7.6000","1.8774","35.0206","1.8774","1.2516","8.3942"
"7.6800","1.8969","35.4863","1.8969","1.2646","8.5058"
"7.7600","1.9175","35.9704","1.9175","1.2783","8.6219"
"7.8400","1.9371","36.4297","1.9371","1.2914","8.7320"
"7.9200","1.9565","36.8873","1.9565","1.3044","8.8416"
"8.0000","1.9780","37.4093","1.9780","1.3187","8.9667"
"8.0800","1.9980","37.8672","1.9980","1.3320","9.0765"
"8.1600","2.0181","38.3359","2.0181","1.3454","9.1889"
"8.2400","2.0376","38.7783","2.0376","1.3584","9.2949"
"8.3200","2.0563","39.2250","2.0563","1.3709","9.4020"
"8.4000","2.0772","39.7166","2.0772","1.3848","9.5198"
"8.4800","2.0965","40.1683","2.0965","1.3977","9.6281"
"8.5600","2.1177","40.6683","2.1177","1.4118","9.7479"
"8.6400","2.1379","41.1440","2.1379","1.4253","9.8619"
"8.7200","2.1574","41.5868","2.1574","1.4382","9.9681"
"8.8000","2.1776","42.0623","2.1776","1.4518","10.0821"
"8.8800","2.1977","42.5126","2.1977","1.4651","10.1900"
"8.9600","2.2165","42.9534","2.2165","1.4777","10.2956"
"9.0400","2.2375","43.4452","2.2375","1.4917","10.4135"
"9.1200","2.2565","43.8781","2.2565","1.5043","10.5173"
"9.2000","2.2779","44.3903","2.2779","1.5186","10.6400"
"9.2800","2.2987","44.8699","2.2987","1.5325","10.7550"
"9.3600","2.3171","45.2798","2.3171","1.5447","10.8533"
"9.4400","2.3369","45.7247","2.3369","1.5579","10.9599"
"9.5200","2.3572","46.1995","2.3572","1.5715","11.0737"
"9.6000","2.3774","46.6669","2.3774","1.5849","11.1857"
"9.6800","2.3976","47.1372","2.3976","1.5984","11.2985"
"9.7600","2.4161","47.5506","2.4161","1.6108","11.3975"
"9.8400","2.4374","48.0532","2.4374","1.6249","11.5180"
"9.9200","2.4577","48.5264","2.4577","1.6385","11.6315"
"10.0000","2.4776","48.9864","2.4776","1.6518","11.7417"
"10.0800","2.4979","49.4545","2.4979","1.6652","11.8539"
"10.1600","2.5168","49.8782","2.5168","1.6779","11.9555"
"10.2400","2.5370","50.3353","2.5370","1.6914","12.0650"
"10.3200","2.5572","50.8090","2.5572","1.7048","12.1786"
"10.4000","2.5767","51.2556","2.5767","1.7178","12.2856"
"10.4800","2.5980","51.7577","2.5980","1.7320","12.4060"
"10.5600","2.6184","52.2183","2.6184","1.7456","12.5164"
"10.6400","2.6381","52.6679","2.6381","1.7587","12.6241"
"10.7200","2.6576","53.0981","2.6576","1.7717","12.7273"
"10.8000","2.6762","53.5306","2.6762","1.7841","12.8309"
"10.8800","2.6977","54.0304","2.6977","1.7985","12.9507"
"10.9600","2.7169","54.4615","2.7169","1.8113","13.0541"
"11.0400","2.7362","54.9021","2.7362","1.8242","13.1597"
"11.1200","2.7570","55.3881","2.7570","1.8380","13.2761"
"11.2000","2.7777","55.8482","2.7777","1.8518","13.3864"
"11.2800","2.7980","56.3114","2.7980","1.8654","13.4975"
"11.3600","2.8182","56.7654","2.8182","1.8788","13.6063"
"11.4400","2.8362","57.1691","2.8362","1.8908","13.7031"
"11.5200","2.8571","57.6455","2.8571","1.9047","13.8172"
"11.6000","2.8770","58.0877","2.8770","1.9180","13.9232"
"11.6800","2.8978","58.5705","2.8978","1.9319","14.0389"
"11.7600","2.9182","59.0255","2.9182","1.9454","14.1480"
"11.8400","2.9373","59.4102","2.9373","1.9582","14.2402"
"11.9200","2.9576","59.8665","2.9576","1.9717","14.3496"
"12.0000","2.9776","60.3279","2.9776","1.9851","14.4602"
"12.0800","2.9972","60.7814","2.9972","1.9981","14.5689"
"12.1600","3.0171","61.2412","3.0171","2.0114","14.6791"
"12.2400","3.0363","61.6639","3.0363","2.0242","14.7804"
"12.3200","3.0569","62.1360","3.0569","2.0379","14.8936"
"12.4000","3.0783","62.6078","3.0783","2.0522","15.0067"
"12.4800","3.0975","63.0097","3.0975","2.0650","15.1030"
"12.5600","3.1179","63.4739","3.1179","2.0786","15.2143"
"12.6400","3.1369","63.8956","3.1369","2.0912","15.3153"
"12.7200","3.1567","64.3452","3.1567","2.1045","15.4231"
"12.8000","3.1771","64.8144","3.1771","2.1180","15.5356"
"12.8800","3.1970","65.2599","3.1970","2.1314","15.6423"
"12.9600","3.2174","65.7169","3.2174","2.1450","15.7519"
"13.0400","3.2383","66.1993","3.2383","2.1589","15.8675"
"13.1200","3.2573","66.6185","3.2573","2.1715","15.9680"
"13.2000","3.2777","67.0356","3.2777","2.1851","16.0680"
"13.2800","3.2969","67.4666","3.2969","2.1980","16.1713"
"13.3600","3.3178","67.9383","3.3178","2.2119","16.2844"
"13.4400","3.3373","68.3729","3.3373","2.2249","16.3885"
"13.5200","3.3561","68.7875","3.3561","2.2374","16.4879"
"13.6000","3.3771","69.2784","3.3771","2.2514","16.6056"
"13.6800","3.3979","69.7441","3.3979","2.2653","16.7172"
"13.7600","3.4180","70.1998","3.4180","2.2787","16.8264"
"13.8400","3.4377","70.6334","3.4377","2.2918","16.9303"
"13.9200","3.4564","71.0501","3.4564","2.3043","17.0302"
"14.0000","3.4772","71.5059","3.4772","2.3181","17.1395"
"14.0800","3.4976","71.9403","3.4976","2.3317","17.2436"
"14.1600","3.5168","72.3659","3.5168","2.3445","17.3456"
"14.2400","3.5378","72.8346","3.5378","2.3585","17.4579"
"14.3200","3.5575","73.2806","3.5575","2.3717","17.5649"
"14.4000","3.5780","73.7315","3.5780","2.3853","17.6729"
"14.4800","3.5980","74.1828","3.5980","2.3987","17.7811"
"14.5600","3.6170","74.6012","3.6170","2.4113","17.8814"
"14.6400","3.6368","75.0405","3.6368","2.4245","17.9867"
"14.7200","3.6564","75.4791","3.6564","2.4376","18.0918"
"14.8000","3.6762","75.9144","3.6762","2.4508","18.1962"
"14.8800","3.6980","76.3892","3.6980","2.4653","18.3100"
"14.9600","3.7173","76.7951","3.7173","2.4782","18.4073"
"15.0400","3.7379","77.2582","3.7379","2.4920","18.5183"
"15.1200","3.7571","77.6796","3.7571","2.5047","18.6193"
"15.2000","3.7766","78.1187","3.7766","2.5177","18.7245"
"15.2800","3.7973","78.5912","3.7973","2.5316","18.8378"
"15.3600","3.8169","79.0112","3.8169","2.5446","18.9384"
"15.4400","3.8372","79.4644","3.8372","2.5581","19.0471"
"15.5200","3.8583","79.9322","3.8583","2.5722","19.1592"
"15.6000","3.8775","80.3506","3.8775","2.5850","19.2595"
"15.6800","3.8978","80.8008","3.8978","2.5985","19.3674"
"15.7600","3.9173","81.2089","3.9173","2.6115","19.4652"
"15.8400","3.9371","81.6389","3.9371","2.6247","19.5683"
"15.9200","3.9572","82.0818","3.9572","2.6381","19.6745"
"16.0000","3.9761","82.5010","3.9761","2.6507","19.7749"
"16.0800","3.9975","82.9767","3.9975","2.6650","19.8890"
"16.1600","4.0182","83.4347","4.0182","2.6788","19.9987"
"16.2400","4.0377","83.8623","4.0377","2.6918","20.1012"
"16.3200","4.0573","84.2922","4.0573","2.7049","20.2043"
"16.4000","4.0770","84.7017","4.0770","2.7180","20.3024"
"16.4800","4.0972","85.1572","4.0972","2.7315","20.4116"
"16.5600","4.1177","85.6036","4.1177","2.7452","20.5186"
"16.6400","4.1365","86.0086","4.1365","2.7577","20.6157"
"16.7200","4.1579","86.4804","4.1579","2.7720","20.7288"
"16.8000","4.1779","86.9181","4.1779","2.7853","20.8337"
"16.8800","4.1976","87.3539","4.1976","2.7984","20.9381"
"16.9600","4.2173","87.7727","4.2173","2.8115","21.0385"
"17.0400","4.2369","88.1938","4.2369","2.8246","21.1394"
"17.1200","4.2567","88.6155","4.2567","2.8378","21.2405"
"17.2000","4.2774","89.0659","4.2774","2.8516","21.3485"
"17.2800","4.2965","89.4810","4.2965","2.8643","21.4480"
"17.3600","4.3177","89.9581","4.3177","2.8785","21.5624"
"17.4400","4.3373","90.3746","4.3373","2.8915","21.6622"
"17.5200","4.3577","90.8214","4.3577","2.9052","21.7693"
"17.6000","4.3773","91.2425","4.3773","2.9182","21.8702"
"17.6800","4.3968","91.6584","4.3968","2.9312","21.9699"
"17.7600","4.4174","92.1114","4.4174","2.9449","22.0785"
"17.8400","4.4373","92.5311","4.4373","2.9582","22.1791"
"17.9200","4.4567","92.9501","4.4567","2.9711","22.2795"
"18.0000","4.4775","93.4224","4.4775","2.9850","22.3927"
"18.0800","4.4981","93.8478","4.4981","2.9987","22.4947"
"18.1600","4.5179","94.2717","4.5179","3.0120","22.5963"
"18.2400","4.5375","94.6832","4.5375","3.0250","22.6949"
"18.3200","4.5563","95.0816","4.5563","3.0375","22.7904"
"18.4000","4.5775","95.5472","4.5775","3.0516","22.9020"
"18.4800","4.5964","95.9443","4.5964","3.0642","22.9972"
"18.5600","4.6172","96.3955","4.6172","3.0781","23.1053"
"18.6400","4.6375","96.8357","4.6375","3.0917","23.2109"
"18.7200","4.6576","97.2557","4.6576","3.1051","23.3115"
"18.8000","4.6774","97.6755","4.6774","3.1183","23.4122"
"18.8800","4.6977","98.1159","4.6977","3.1318","23.5177"
"18.9600","4.7168","98.5112","4.7168","3.1445","23.6125"
"19.0400","4.7374","98.9689","4.7374","3.1583","23.7222"
"19.1200","4.7562","99.3558","4.7562","3.1708","23.8149"
"19.2000","4.7780","99.8433","4.7780","3.1853","23.9317"
"19.2800","4.7987","100.2821","4.7987","3.1991","24.0369"
"19.3600","4.8180","100.6947","4.8180","3.2120","24.1358"
"19.4400","4.8370","101.0823","4.8370","3.2247","24.2287"
"19.5200","4.8571","101.5089","4.8571","3.2380","24.3310"
"19.6000","4.8772","101.9489","4.8772","3.2514","24.4365"
"19.6800","4.8977","102.3938","4.8977","3.2652","24.5431"
"19.7600","4.9162","102.7684","4.9162","3.2775","24.6329"
"19.8400","4.9373","103.2296","4.9373","3.2915","24.7434"
"19.9200","4.9579","103.6673","4.9579","3.3053","24.8483"
"20.0000","4.9777","104.0909","4.9777","3.3185","24.9499"
"20.0800","4.9977","104.5184","4.9977","3.3318","25.0524"
"20.1600","5.0164","104.8981","5.0164","3.3443","25.1434"
"20.2400","5.0370","105.3373","5.0370","3.3580","25.2486"
"20.3200","5.0572","105.7670","5.0572","3.3715","25.3516"
"20.4000","5.0766","106.1781","5.0766","3.3844","25.4502"
"20.4800","5.0978","106.6455","5.0978","3.3985","25.5622"
"20.5600","5.1183","107.0791","5.1183","3.4122","25.6661"
"20.6400","5.1374","107.4699","5.1374","3.4249","25.7598"
"20.7200","5.1571","107.8837","5.1571","3.4381","25.8590"
"20.8000","5.1766","108.2876","5.1766","3.4510","25.9558"
"20.8800","5.1978","108.7440","5.1978","3.4652","26.0652"
"20.9600","5.2170","109.1416","5.2170","3.4780","26.1605"
"21.0400","5.2365","109.5665","5.2365","3.4910","26.2623"
"21.1200","5.2567","109.9887","5.2567","3.5044","26.3635"
"21.2000","5.2775","110.4400","5.2775","3.5183","26.4717"
"21.2800","5.2980","110.8614","5.2980","3.5320","26.5727"
"21.3600","5.3180","111.2828","5.3180","3.5453","26.6737"
"21.4400","5.3362","111.6572","5.3362","3.5575","26.7635"
"21.5200","5.3568","112.0993","5.3568","3.5712","26.8694"
"21.6000","5.3768","112.5331","5.3768","3.5845","26.9734"
"21.6800","5.3980","112.9860","5.3980","3.5986","27.0820"
"21.7600","5.4186","113.4201","5.4186","3.6124","27.1860"
"21.8400","5.4377","113.8155","5.4377","3.6251","27.2808"
"21.9200","5.4576","114.2174","5.4576","3.6384","27.3771"
"22.0000","5.4776","114.6470","5.4776","3.6517","27.4801"
"22.0800","5.4969","115.0505","5.4969","3.6646","27.5768"
"22.1600","5.5174","115.4894","5.5174","3.6783","27.6820"
"22.2400","5.5364","115.8699","5.5364","3.6909","27.7732"
"22.3200","5.5566","116.2882","5.5566","3.7044","27.8735"
"22.4000","5.5782","116.7578","5.5782","3.7188","27.9861"
"22.4800","5.5977","117.1664","5.5977","3.7318","28.0840"
"22.5600","5.6178","117.5875","5.6178","3.7452","28.1849"
"22.6400","5.6367","117.9812","5.6367","3.7578","28.2793"
"22.7200","5.6569","118.4067","5.6569","3.7713","28.3813"
"22.8000","5.6772","118.8374","5.6772","3.7848","28.4845"
"22.8800","5.6968","119.2355","5.6968","3.7979","28.5800"
"22.9600","5.7167","119.6450","5.7167","3.8111","28.6781"
"23.0400","5.7383","120.1100","5.7383","3.8256","28.7895"
"23.1200","5.7579","120.5137","5.7579","3.8386","28.8863"
"23.2000","5.7779","120.9326","5.7779","3.8520","28.9867"
"23.2800","5.7969","121.3059","5.7969","3.8646","29.0762"
"23.3600","5.8178","121.7554","5.8178","3.8786","29.1840"
"23.4400","5.8369","122.1324","5.8369","3.8912","29.2743"
"23.5200","5.8557","122.5309","5.8557","3.9038","29.3698"
"23.6000","5.8771","122.9962","5.8771","3.9180","29.4813"
"23.6800","5.8983","123.4381","5.8983","3.9322","29.5873"
"23.7600","5.9178","123.8399","5.9178","3.9452","29.6836"
"23.8400","5.9375","124.2422","5.9375","3.9583","29.7800"
"23.9200","5.9564","124.6108","5.9564","3.9709","29.8683"
"24.0000","5.9771","125.0561","5.9771","3.9848","29.9751"
"24.0800","5.9975","125.4832","5.9975","3.9984","30.0775"
"24.1600","6.0172","125.8966","6.0173","4.0115","30.1766"
"24.2400","6.0380","126.3373","6.0380","4.0254","30.2822"
"24.3200","6.0574","126.7233","6.0574","4.0383","30.3747"
"24.4000","6.0781","127.1569","6.0781","4.0521","30.4787"
"24.4800","6.0978","127.5646","6.0978","4.0652","30.5764"
"24.5600","6.1172","127.9697","6.1172","4.0782","30.6735"
"24.6400","6.1370","128.3783","6.1370","4.0914","30.7714"
"24.7200","6.1567","128.7768","6.1567","4.1045","30.8669"
"24.8000","6.1764","129.1865","6.1764","4.1176","30.9651"
"24.8800","6.1981","129.6504","6.1981","4.1321","31.0763"
"24.9600","6.2173","130.0296","6.2173","4.1449","31.1672"
"25.0400","6.2379","130.4586","6.2379","4.1586","31.2700"
"25.1200","6.2573","130.8555","6.2573","4.1716","31.3652"
"25.2000","6.2764","131.2422","6.2764","4.1843","31.4579"
"25.2800","6.2968","131.6601","6.2968","4.1978","31.5580"
"25.3600","6.3170","132.0695","6.3170","4.2113","31.6561"
"25.4400","6.3376","132.5033","6.3376","4.2251","31.7601"
"25.5200","6.3581","132.9240","6.3581","4.2388","31.8610"
"25.6000","6.3775","133.3109","6.3775","4.2517","31.9537"
"25.6800","6.3976","133.7327","6.3976","4.2651","32.0548"
"25.7600","6.4174","134.1315","6.4174","4.2782","32.1504"
"25.8400","6.4369","134.5263","6.4369","4.2913","32.2450"
"25.9200","6.4573","134.9451","6.4573","4.3049","32.3454"
"26.0000","6.4759","135.3114","6.4759","4.3173","32.4332"
"26.0800","6.4977","135.7718","6.4977","4.3318","32.5436"
"26.1600","6.5183","136.1944","6.5183","4.3455","32.6449"
"26.2400","6.5374","136.5717","6.5374","4.3583","32.7353"
"26.3200","6.5572","136.9805","6.5572","4.3715","32.8333"
"26.4000","6.5770","137.3725","6.5770","4.3846","32.9272"
"26.4800","6.5975","137.8006","6.5975","4.3983","33.0299"
"26.5600","6.6179","138.2074","6.6179","4.4119","33.1274"
"26.6400","6.6365","138.5800","6.6365","4.4243","33.2167"
"26.7200","6.6578","139.0205","6.6578","4.4385","33.3223"
"26.8000","6.6779","139.4410","6.6779","4.4520","33.4231"
"26.8800","6.6980","139.8391","6.6980","4.4653","33.5185"
"26.9600","6.7175","140.2439","6.7175","4.4783","33.6155"
"27.0400","6.7367","140.6156","6.7367","4.4912","33.7046"
"27.1200","6.7568","141.0264","6.7568","4.5046","33.8031"
"27.2000","6.7774","141.4525","6.7774","4.5183","33.9052"
"27.2800","6.7963","141.8385","6.7963","4.5309","33.9977"
"27.3600","6.8176","142.2923","6.8176","4.5451","34.1065"
"27.4400","6.8374","142.6708","6.8374","4.5582","34.1972"
"27.5200","6.8576","143.0882","6.8576","4.5718","34.2973"
"27.6000","6.8777","143.4877","6.8777","4.5851","34.3930"
"27.6800","6.8973","143.8875","6.8973","4.5982","34.4888"
"27.7600","6.9172","144.2847","6.9172","4.6115","34.5841"
"27.8400","6.9369","144.6802","6.9369","4.6246","34.6789"
"27.9200","6.9569","145.0969","6.9569","4.6379","34.7787"
"28.0000","6.9782","145.5345","6.9782","4.6521","34.8836"
"28.0800","6.9975","145.9121","6.9975","4.6650","34.9741"
"28.1600","7.0179","146.3186","7.0179","4.6786","35.0716"
"28.2400","7.0379","146.7090","7.0379","4.6919","35.1652"
"28.3200","7.0563","147.0862","7.0563","4.7042","35.2556"
"28.4000","7.0772","147.5088","7.0772","4.7181","35.3569"
"28.4800","7.0963","147.8795","7.0963","4.7309","35.4457"
"28.5600","7.1175","148.3186","7.1175","4.7450","35.5509"
"28.6400","7.1377","148.7278","7.1377","4.7585","35.6491"
"28.7200","7.1574","149.1176","7.1574","4.7716","35.7425"
"28.8000","7.1774","149.5118","7.1774","4.7849","35.8370"
"28.8800","7.1977","149.9230","7.1977","4.7985","35.9355"
"28.9600","7.2168","150.2879","7.2168","4.8112","36.0230"
"29.0400","7.2370","150.6942","7.2370","4.8247","36.1204"
"29.1200","7.2563","151.0770","7.2563","4.8375","36.2121"
"29.2000","7.2782","151.5285","7.2782","4.8521","36.3203"
"29.2800","7.2986","151.9352","7.2986","4.8657","36.4178"
"29.3600","7.3180","152.3166","7.3180","4.8787","36.5092"
"29.4400","7.3374","152.6945","7.3374","4.8916","36.5998"
"29.5200","7.3569","153.0712","7.3569","4.9046","36.6901"
"29.6000","7.3769","153.4654","7.3769","4.9179","36.7846"
"29.6800","7.3975","153.8690","7.3975","4.9316","36.8814"
"29.7600","7.4161","154.2228","7.4161","4.9441","36.9662"
"29.8400","7.4370","154.6534","7.4370","4.9580","37.0694"
"29.9200","7.4583","155.0899","7.4583","4.9722","37.1740"
"30.0000","7.4780","155.4654","7.4780","4.9853","37.2640"
"30.0800","7.4979","155.8688","7.4979","4.9986","37.3607"
"30.1600","7.5167","156.2240","7.5167","5.0111","37.4458"
"30.2400","7.5370","156.6281","7.5370","5.0247","37.5427"
"30.3200","7.5573","157.0191","7.5573","5.0382","37.6364"
"30.4000","7.5768","157.4075","7.5768","5.0512","37.7295"
"30.4800","7.5978","157.8273","7.5978","5.0652","37.8301"
"30.5600","7.6180","158.2134","7.6180","5.0787","37.9227"
"30.6400","7.6375","158.5828","7.6375","5.0917","38.0112"
"30.7200","7.6578","158.9800","7.6578","5.1052","38.1064"
"30.8000","7.6764","159.3351","7.6764","5.1176","38.1915"
"30.8800","7.6976","159.7500","7.6976","5.1318","38.2910"
"30.9600","7.7174","160.1312","7.7174","5.1449","38.3824"
"31.0400","7.7364","160.4986","7.7364","5.1576","38.4704"
"31.1200","7.7569","160.9056","7.7569","5.1713","38.5680"
"31.2000","7.7777","161.3107","7.7777","5.1851","38.6651"
"31.2800","7.7980","161.6988","7.7980","5.1987","38.7581"
"31.3600","7.8181","162.0888","7.8181","5.2121","38.8516"
"31.4400","7.8365","162.4383","7.8365","5.2243","38.9353"
"31.5200","7.8566","162.8289","7.8566","5.2378","39.0290"
"31.6000","7.8765","163.2186","7.8765","5.2510","39.1224"
"31.6800","7.8981","163.6649","7.8981","5.2654","39.2294"
"31.7600","7.9189","164.0750","7.9189","5.2793","39.3277"
"31.8400","7.9378","164.4242","7.9378","5.2919","39.4114"
"31.9200","7.9577","164.8016","7.9577","5.3051","39.5018"
"32.0000","7.9773","165.1781","7.9773","5.3182","39.5921"
"32.0800","7.9969","165.5616","7.9969","5.3312","39.6840"
"32.1600","8.0173","165.9718","8.0173","5.3449","39.7823"
"32.2400","8.0362","166.3099","8.0362","5.3575","39.8633"
"32.3200","8.0568","166.7140","8.0568","5.3712","39.9602"
"32.4000","8.0785","167.1482","8.0785","5.3856","40.0643"
"32.4800","8.0976","167.5134","8.0976","5.3984","40.1518"
"32.5600","8.1175","167.8938","8.1175","5.4117","40.2430"
"32.6400","8.1365","168.2498","8.1365","5.4243","40.3283"
"32.7200","8.1570","168.6480","8.1570","5.4380","40.4238"
"32.8000","8.1767","169.0304","8.1767","5.4512","40.5154"
"32.8800","8.1968","169.4150","8.1968","5.4646","40.6076"
"32.9600","8.2176","169.8190","8.2176","5.4784","40.7044"
"33.0400","8.2382","170.2167","8.2382","5.4921","40.7998"
"33.1200","8.2571","170.5714","8.2571","5.5047","40.8848"
"33.2000","8.2773","170.9610","8.2773","5.5182","40.9782"
"33.2800","8.2970","171.3265","8.2970","5.5313","41.0658"
"33.3600","8.3177","171.7316","8.3177","5.5452","41.1629"
"33.4400","8.3373","172.1022","8.3373","5.5582","41.2517"
"33.5200","8.3560","172.4453","8.3560","5.5707","41.3340"
"33.6000","8.3771","172.8661","8.3771","5.5847","41.4348"
"33.6800","8.3982","173.2784","8.3982","5.5988","41.5337"
"33.7600","8.4179","173.6478","8.4179","5.6120","41.6222"
"33.8400","8.4377","174.0225","8.4377","5.6251","41.7120"
"33.9200","8.4563","174.3463","8.4563","5.6376","41.7896"
"34.0000","8.4774","174.7644","8.4774","5.6516","41.8898"
"34.0800","8.4971","175.1291","8.4971","5.6647","41.9773"
"34.1600","8.5169","175.5116","8.5169","5.6779","42.0689"
"34.2400","8.5382","175.9212","8.5382","5.6922","42.1671"
"34.3200","8.5577","176.2777","8.5577","5.7051","42.2526"
"34.4000","8.5781","176.6597","8.5781","5.7187","42.3441"
"34.4800","8.5978","177.0180","8.5978","5.7319","42.4300"
"34.5600","8.6166","177.3637","8.6166","5.7444","42.5129"
"34.6400","8.6368","177.7424","8.6368","5.7579","42.6036"
"34.7200","8.6567","178.1129","8.6567","5.7712","42.6925"
"34.8000","8.6762","178.4803","8.6762","5.7841","42.7805"
"34.8800","8.6982","178.9141","8.6982","5.7988","42.8845"
"34.9600","8.7173","179.2549","8.7173","5.8116","42.9662"
"35.0400","8.7379","179.6325","8.7379","5.8253","43.0567"
"35.1200","8.7571","179.9718","8.7571","5.8381","43.1380"
"35.2000","8.7768","180.3519","8.7768","5.8512","43.2291"
"35.2800","8.7972","180.7334","8.7972","5.8648","43.3206"
"35.3600","8.8169","181.0943","8.8169","5.8780","43.4071"
"35.4400","8.8374","181.4750","8.8374","5.8916","43.4983"
"35.5200","8.8577","181.8472","8.8577","5.9051","43.5875"
"35.6000","8.8774","182.2057","8.8774","5.9183","43.6735"
"35.6800","8.8984","182.6085","8.8984","5.9323","43.7700"
"35.7600","8.9177","182.9494","8.9177","5.9451","43.8517"
"35.8400","8.9370","183.3062","8.9370","5.9580","43.9372"
"35.9200","8.9567","183.6651","8.9567","5.9711","44.0233"
"36.0000","8.9760","184.0117","8.9760","5.9840","44.1063"
"36.0800","8.9977","184.4296","8.9977","5.9985","44.2065"
"36.1600","9.0182","184.8011","9.0182","6.0121","44.2956"
"36.2400","9.0374","185.1511","9.0374","6.0249","44.3795"
"36.3200","9.0571","185.5101","9.0571","6.0381","44.4655"
"36.4000","9.0767","185.8564","9.0767","6.0511","44.5485"
"36.4800","9.0971","186.2421","9.0971","6.0647","44.6410"
"36.5600","9.1178","186.6132","9.1178","6.0785","44.7299"
"36.6400","9.1366","186.9484","9.1366","6.0911","44.8103"
"36.7200","9.1581","187.3495","9.1581","6.1054","44.9064"
"36.8000","9.1779","187.7038","9.1779","6.1186","44.9913"
"36.8800","9.1981","188.0752","9.1981","6.1321","45.0803"
"36.9600","9.2177","188.4360","9.2177","6.1452","45.1668"
"37.0400","9.2369","188.7599","9.2369","6.1579","45.2445"
"37.1200","9.2565","189.1144","9.2565","6.1710","45.3294"
"37.2000","9.2776","189.4975","9.2776","6.1851","45.4213"
"37.2800","9.2964","189.8264","9.2964","6.1976","45.5001"
"37.3600","9.3176","190.2272","9.3176","6.2117","45.5962"
"37.4400","9.3373","190.5785","9.3373","6.2249","45.6804"
"37.5200","9.3581","190.9445","9.3581","6.2387","45.7681"
"37.6000","9.3775","191.2802","9.3775","6.2517","45.8486"
"37.6800","9.3968","191.6204","9.3968","6.2645","45.9301"
"37.7600","9.4167","191.9837","9.4167","6.2778","46.0172"
"37.8400","9.4368","192.3353","9.4368","6.2912","46.1015"
"37.9200","9.4569","192.7004","9.4569","6.3046","46.1890"
"38.0000","9.4785","193.1025","9.4785","6.3190","46.2854"
"38.0800","9.4980","193.4303","9.4980","6.3320","46.3639"
"38.1600","9.5179","193.7771","9.5179","6.3452","46.4471"
"38.2400","9.5377","194.1247","9.5377","6.3585","46.5304"
"38.3200","9.5563","194.4426","9.5563","6.3709","46.6066"
"38.4000","9.5771","194.8233","9.5771","6.3847","46.6978"
"38.4800","9.5964","195.1555","9.5964","6.3976","46.7774"
"38.5600","9.6174","195.5350","9.6174","6.4116","46.8684"
"38.6400","9.6375","195.8883","9.6375","6.4250","46.9531"
"38.7200","9.6573","196.2274","9.6573","6.4382","47.0344"
"38.8000","9.6774","196.5804","9.6774","6.4516","47.1190"
"38.8800","9.6976","196.9325","9.6976","6.4651","47.2034"
"38.9600","9.7167","197.2551","9.7167","6.4778","47.2807"
"39.0400","9.7375","197.6308","9.7375","6.4917","47.3708"
"39.1200","9.7562","197.9345","9.7562","6.5041","47.4435"
"39.2000","9.7781","198.3443","9.7781","6.5187","47.5418"
"39.2800","9.7984","198.6916","9.7984","6.5323","47.6250"
"39.3600","9.8182","199.0285","9.8182","6.5455","47.7058"
"39.4400","9.8373","199.3466","9.8373","6.5582","47.7820"
"39.5200","9.8570","199.6806","9.8570","6.5714","47.8621"
"39.6000","9.8769","200.0193","9.8769","6.5846","47.9433"
"39.6800","9.8977","200.3871","9.8977","6.5985","48.0314"
"39.7600","9.9165","200.6905","9.9165","6.6110","48.1041"
"39.8400","9.9371","201.0521","9.9371","6.6248","48.1908"
"39.9200","9.9574","201.3904","9.9574","6.6383","48.2719"
"40.0000","9.9773","201.7425","9.9773","6.6516","48.3563"
"40.0800","9.9979","202.0902","9.9979","6.6653","48.4397"
"40.1600","10.0166","202.3961","10.0166","6.6778","48.5130"
"40.2400","10.0373","202.7404","10.0373","6.6915","48.5955"
"40.3200","10.0572","203.0708","10.0572","6.7048","48.6747"
"40.4000","10.0767","203.4039","10.0767","6.7178","48.7545"
"40.4800","10.0980","203.7837","10.0980","6.7320","48.8456"
"40.5600","10.1184","204.1172","10.1184","6.7456","48.9255"
"40.6400","10.1378","204.4394","10.1378","6.7585","49.0027"
"40.7200","10.1578","204.7672","10.1578","6.7719","49.0813"
"40.8000","10.1762","205.0582","10.1762","6.7841","49.1510"
"40.8800","10.1977","205.4260","10.1977","6.7985","49.2392"
"40.9600","10.2171","205.7427","10.2171","6.8114","49.3151"
"41.0400","10.2367","206.0569","10.2367","6.8244","49.3904"
"41.1200","10.2567","206.4003","10.2567","6.8378","49.4727"
"41.2000","10.2774","206.7372","10.2774","6.8516","49.5535"
"41.2800","10.2977","207.0900","10.2977","6.8651","49.6381"
"41.3600","10.3182","207.4291","10.3182","6.8788","49.7193"
"41.4400","10.3365","207.7160","10.3365","6.8910","49.7881"
"41.5200","10.3570","208.0632","10.3570","6.9046","49.8713"
"41.6000","10.3768","208.3741","10.3768","6.9178","49.9458"
"41.6800","10.3976","208.7200","10.3976","6.9318","50.0288"
"41.7600","10.4185","209.0624","10.4185","6.9457","50.1108"
"41.8400","10.4378","209.3615","10.4378","6.9585","50.1825"
"41.9200","10.4578","209.6692","10.4578","6.9718","50.2563"
"42.0000","10.4773","209.9871","10.4773","6.9849","50.3325"
"42.0800","10.4971","210.3115","10.4971","6.9981","50.4102"
"42.1600","10.5172","210.6350","10.5172","7.0115","50.4878"
"42.2400","10.5359","210.9034","10.5359","7.0239","50.5521"
"42.3200","10.5564","211.2461","10.5564","7.0376","50.6343"
"42.4000","10.5782","211.6122","10.5782","7.0522","50.7220"
"42.4800","10.5981","211.9296","10.5981","7.0654","50.7981"
"42.5600","10.6184","212.2405","10.6184","7.0789","50.8726"
"42.6400","10.6365","212.5006","10.6365","7.0910","50.9350"
"42.7200","10.6570","212.8399","10.6570","7.1047","51.0163"
"42.8000","10.6774","213.1654","10.6774","7.1182","51.0943"
"42.8800","10.6970","213.4775","10.6970","7.1314","51.1691"
"42.9600","10.7177","213.8017","10.7177","7.1451","51.2468"
"43.0400","10.7384","214.1231","10.7384","7.1589","51.3238"
"43.1200","10.7572","214.4016","10.7572","7.1715","51.3906"
"43.2000","10.7777","214.7258","10.7777","7.1851","51.4683"
"43.2800","10.7973","215.0108","10.7973","7.1982","51.5366"
"43.3600","10.8178","215.3373","10.8178","7.2119","51.6149"
"43.4400","10.8373","215.6168","10.8373","7.2249","51.6819"
"43.5200","10.8556","215.8867","10.8556","7.2370","51.7466"
"43.6000","10.8767","216.2161","10.8767","7.2511","51.8255"
"43.6800","10.8981","216.5642","10.8981","7.2654","51.9090"
"43.7600","10.9179","216.8534","10.9179","7.2786","51.9783"
"43.8400","10.9375","217.1432","10.9375","7.2916","52.0478"
"43.9200","10.9565","217.4035","10.9565","7.3043","52.1101"
"44.0000","10.9773","217.7296","10.9773","7.3182","52.1883"
"44.0800","10.9974","218.0229","10.9974","7.3316","52.2586"
"44.1600","11.0167","218.3189","11.0167","7.3445","52.3296"
"44.2400","11.0381","218.6459","11.0381","7.3587","52.4079"
"44.3200","11.0576","218.9305","11.0576","7.3717","52.4761"
"44.4000","11.0779","219.2203","11.0779","7.3853","52.5456"
"44.4800","11.0975","219.5065","11.0975","7.3983","52.6142"
"44.5600","11.1168","219.7793","11.1168","7.4112","52.6796"
"44.6400","11.1368","220.0874","11.1368","7.4245","52.7535"
"44.7200","11.1570","220.3845","11.1570","7.4380","52.8247"
"44.8000","11.1762","220.6575","11.1762","7.4508","52.8901"
"44.8800","11.1976","220.9832","11.1976","7.4650","52.9682"
"44.9600","11.2176","221.2638","11.2176","7.4784","53.0354"
"45.0400","11.2383","221.5637","11.2383","7.4922","53.1073"
"45.1200","11.2575","221.8221","11.2575","7.5050","53.1693"
"45.2000","11.2769","222.1014","11.2769","7.5180","53.2362"
"45.2800","11.2971","222.3955","11.2971","7.5314","53.3067"
"45.3600","11.3169","222.6691","11.3169","7.5446","53.3723"
"45.4400","11.3375","222.9684","11.3375","7.5583","53.4440"
"45.5200","11.3586","223.2700","11.3586","7.5724","53.5163"
"45.6000","11.3773","223.5209","11.3773","7.5849","53.5764"
"45.6800","11.3978","223.8158","11.3978","7.5985","53.6471"
"45.7600","11.4173","224.0766","11.4173","7.6115","53.7096"
"45.8400","11.4370","224.3497","11.4370","7.6247","53.7751"
"45.9200","11.4571","224.6408","11.4571","7.6381","53.8449"
"46.0000","11.4759","224.8833","11.4759","7.6506","53.9030"
"46.0800","11.4974","225.1892","11.4974","7.6649","53.9763"
"46.1600","11.5180","225.4820","11.5180","7.6787","54.0465"
"46.2400","11.5376","225.7463","11.5376","7.6918","54.1099"
"46.3200","11.5571","226.0028","11.5571","7.7047","54.1713"
"46.4000","11.5767","226.2545","11.5767","7.7178","54.2317"
"46.4800","11.5974","226.5553","11.5974","7.7316","54.3038"
"46.5600","11.6179","226.8355","11.6179","7.7453","54.3709"
"46.6400","11.6362","227.0724","11.6362","7.7575","54.4277"
"46.7200","11.6582","227.3909","11.6582","7.7721","54.5040"
"46.8000","11.6782","227.6625","11.6782","7.7855","54.5691"
"46.8800","11.6979","227.9129","11.6979","7.7986","54.6292"
"46.9600","11.7171","228.1507","11.7171","7.8114","54.6862"
"47.0400","11.7368","228.4013","11.7368","7.8245","54.7462"
"47.1200","11.7569","228.6629","11.7569","7.8380","54.8090"
"47.2000","11.7774","228.9431","11.7774","7.8516","54.8761"
"47.2800","11.7964","229.1847","11.7964","7.8643","54.9340"
"47.3600","11.8179","229.4919","11.8179","7.8786","55.0076"
"47.4400","11.8372","229.7324","11.8372","7.8915","55.0653"
"47.5200","11.8572","229.9827","11.8572","7.9048","55.1253"
"47.6000","11.8778","230.2510","11.8778","7.9185","55.1896"
"47.6800","11.8969","230.4802","11.8969","7.9313","55.2445"
"47.7600","11.9173","230.7472","11.9173","7.9448","55.3085"
"47.8400","11.9371","230.9883","11.9371","7.9581","55.3663"
"47.9200","11.9569","231.2421","11.9569","7.9712","55.4271"
"48.0000","11.9781","231.5305","11.9781","7.9854","55.4963"
"48.0800","11.9982","231.7738","11.9982","7.9988","55.5546"
"48.1600","12.0180","232.0073","12.0180","8.0120","55.6106"
"48.2400","12.0378","232.2564","12.0378","8.0252","55.6703"
"48.3200","12.0564","232.4759","12.0564","8.0376","55.7229"
"48.4000","12.0771","232.7426","12.0771","8.0514","55.7868"
"48.4800","12.0964","232.9673","12.0964","8.0643","55.8407"
"48.5600","12.1176","233.2375","12.1176","8.0784","55.9055"
"48.6400","12.1378","233.4913","12.1378","8.0919","55.9663"
"48.7200","12.1574","233.7174","12.1574","8.1050","56.0205"
"48.8000","12.1775","233.9577","12.1775","8.1183","56.0781"
"48.8800","12.1977","234.2029","12.1977","8.1318","56.1368"
"48.9600","12.2165","234.4173","12.2165","8.1443","56.1882"
"49.0400","12.2374","234.6735","12.2374","8.1582","56.2496"
"49.1200","12.2566","234.8843","12.2566","8.1711","56.3002"
"49.2000","12.2781","235.1540","12.2781","8.1854","56.3648"
"49.2800","12.2984","235.3934","12.2984","8.1989","56.4222"
"49.3600","12.3177","235.6069","12.3177","8.2118","56.4734"
"49.4400","12.3370","235.8099","12.3370","8.2247","56.5220"
"49.5200","12.3572","236.0519","12.3572","8.2381","56.5800"
"49.6000","12.3772","236.2739","12.3772","8.2515","56.6333"
"49.6800","12.3976","236.5106","12.3976","8.2651","56.6900"
"49.7600","12.4161","236.6958","12.4161","8.2774","56.7344"
"49.8400","12.4369","236.9425","12.4369","8.2913","56.7935"
"49.9200","12.4573","237.1704","12.4573","8.3049","56.8481"
"50.0000","12.4780","237.4160","12.4780","8.3187","56.9070"
"50.0800","12.4981","237.6325","12.4981","8.3321","56.9589"
"50.1600","12.5166","237.8084","12.5166","8.3444","57.0011"
"50.2400","12.5371","238.0360","12.5371","8.3581","57.0556"
"50.3200","12.5570","238.2537","12.5570","8.3713","57.1078"
"50.4000","12.5768","238.4792","12.5768","8.3846","57.1618"
"50.4800","12.5982","238.7412","12.5982","8.3988","57.2246"
"50.5600","12.6185","238.9479","12.6185","8.4123","57.2742"
"50.6400","12.6378","239.1435","12.6378","8.4252","57.3211"
"50.7200","12.6577","239.3443","12.6577","8.4384","57.3692"
"50.8000","12.6763","239.5237","12.6763","8.4509","57.4122"
"50.8800","12.6978","239.7735","12.6978","8.4652","57.4721"
"50.9600","12.7169","239.9428","12.7169","8.4779","57.5127"
"51.0400","12.7367","240.1583","12.7367","8.4911","57.5643"
"51.1200","12.7567","240.3840","12.7567","8.5045","57.6184"
"51.2000","12.7777","240.6103","12.7777","8.5185","57.6727"
"51.2800","12.7981","240.8217","12.7981","8.5321","57.7233"
"51.3600","12.8180","241.0232","12.8180","8.5453","57.7716"
"51.4400","12.8363","241.1900","12.8363","8.5575","57.8116"
"51.5200","12.8567","241.3983","12.8567","8.5711","57.8615"
"51.6000","12.8768","241.6033","12.8768","8.5845","57.9107"
"51.6800","12.8976","241.8300","12.8976","8.5984","57.9650"
"51.7600","12.9186","242.0438","12.9186","8.6124","58.0163"
"51.8400","12.9377","242.2173","12.9377","8.6251","58.0578"
"51.9200","12.9579","242.4187","12.9579","8.6386","58.1061"
"52.0000","12.9775","242.5991","12.9775","8.6517","58.1493"
"52.0800","12.9972","242.7996","12.9972","8.6648","58.1974"
"52.1600","13.0169","242.9927","13.0169","8.6779","58.2437"
"52.2400","13.0365","243.1757","13.0365","8.6910","58.2876"
"52.3200","13.0570","243.3857","13.0570","8.7047","58.3379"
"52.4000","13.0785","243.5983","13.0785","8.7190","58.3889"
"52.4800","13.0979","243.7842","13.0979","8.7319","58.4334"
"52.5600","13.1179","243.9625","13.1179","8.7453","58.4762"
"52.6400","13.1366","244.1247","13.1366","8.7577","58.5150"
"52.7200","13.1568","244.3140","13.1568","8.7712","58.5604"
"52.8000","13.1771","244.5047","13.1771","8.7847","58.6061"
"52.8800","13.1969","244.6737","13.1969","8.7980","58.6466"
"52.9600","13.2177","244.8749","13.2177","8.8118","58.6949"
"53.0400","13.2383","245.0635","13.2383","8.8255","58.7400"
"53.1200","13.2577","245.2294","13.2577","8.8385","58.7798"
"53.2000","13.2778","245.4138","13.2778","8.8519","58.8240"
"53.2800","13.2966","245.5638","13.2966","8.8644","58.8600"
"53.3600","13.3177","245.7573","13.3177","8.8785","58.9064"
"53.4400","13.3374","245.9265","13.3374","8.8916","58.9469"
"53.5200","13.3558","246.0657","13.3558","8.9039","58.9803"
"53.6000","13.3766","246.2608","13.3766","8.9177","59.0270"
"53.6800","13.3980","246.4578","13.3980","8.9320","59.0743"
"53.7600","13.4179","246.6174","13.4179","8.9452","59.1125"
"53.8400","13.4375","246.7903","13.4375","8.9583","59.1539"
"53.9200","13.4565","246.9182","13.4565","8.9710","59.1846"
"54.0000","13.4773","247.1060","13.4773","8.9849","59.2296"
"54.0800","13.4976","247.2830","13.4976","8.9984","59.2721"
"54.1600","13.5171","247.4426","13.5171","9.0114","59.3103"
"54.2400","13.5378","247.6267","13.5378","9.0252","59.3544"
"54.3200","13.5577","247.7746","13.5577","9.0385","59.3899"
"54.4000","13.5780","247.9408","13.5780","9.0520","59.4297"
"54.4800","13.5978","248.0959","13.5978","9.0652","59.4669"
"54.5600","13.6171","248.2300","13.6171","9.0780","59.4991"
"54.6400","13.6371","248.3841","13.6371","9.0914","59.5360"
"54.7200","13.6566","248.5269","13.6566","9.1044","59.5702"
"54.8000","13.6766","248.6895","13.6766","9.1177","59.6092"
"54.8800","13.6982","248.8910","13.6982","9.1321","59.6575"
"54.9600","13.7171","249.0145","13.7171","9.1447","59.6871"
"55.0400","13.7379","249.1794","13.7379","9.1586","59.7266"
"55.1200","13.7571","249.3107","13.7571","9.1714","59.7581"
"55.2000","13.7766","249.4595","13.7766","9.1844","59.7937"
"55.2800","13.7972","249.6297","13.7972","9.1981","59.8346"
"55.3600","13.8171","249.7594","13.8171","9.2114","59.8656"
"55.4400","13.8373","249.9100","13.8373","9.2248","59.9017"
"55.5200","13.8584","250.0856","13.8584","9.2389","59.9438"
"55.6000","13.8776","250.2149","13.8776","9.2518","59.9748"
"55.6800","13.8979","250.3630","13.8979","9.2652","60.0103"
"55.7600","13.9173","250.4850","13.9173","9.2782","60.0396"
"55.8400","13.9365","250.6166","13.9365","9.2910","60.0711"
"55.9200","13.9567","250.7591","13.9567","9.3045","60.1052"
"56.0000","13.9759","250.8821","13.9759","9.3173","60.1347"
"56.0800","13.9974","251.0468","13.9974","9.3316","60.1742"
"56.1600","14.0183","251.2082","14.0183","9.3455","60.2129"
"56.2400","14.0377","251.3322","14.0377","9.3585","60.2426"
"56.3200","14.0574","251.4625","14.0574","9.3716","60.2738"
"56.4000","14.0766","251.5706","14.0766","9.3844","60.2998"
"56.4800","14.0973","251.7334","14.0973","9.3982","60.3388"
"56.5600","14.1180","251.8723","14.1180","9.4120","60.3721"
"56.6400","14.1365","251.9772","14.1365","9.4244","60.3972"
"56.7200","14.1580","252.1470","14.1580","9.4387","60.4379"
"56.8000","14.1780","252.2677","14.1780","9.4520","60.4669"
"56.8800","14.1982","252.3957","14.1982","9.4655","60.4975"
"56.9600","14.2176","252.5216","14.2176","9.4784","60.5277"
"57.0400","14.2369","252.6250","14.2369","9.4913","60.5525"
"57.1200","14.2569","252.7455","14.2569","9.5046","60.5814"
"57.2000","14.2772","252.8758","14.2772","9.5181","60.6126"
"57.2800","14.2963","252.9921","14.2963","9.5309","60.6405"
"57.3600","14.3176","253.1464","14.3176","9.5451","60.6775"
"57.4400","14.3373","253.2463","14.3373","9.5582","60.7014"
"57.5200","14.3576","253.3791","14.3576","9.5717","60.7332"
"57.6000","14.3777","253.4909","14.3777","9.5851","60.7600"
"57.6800","14.3969","253.6007","14.3969","9.5980","60.7864"
"57.7600","14.4174","253.7275","14.4174","9.6116","60.8168"
"57.8400","14.4369","253.8283","14.4369","9.6246","60.8409"
"57.9200","14.4568","253.9530","14.4568","9.6379","60.8708"
"58.0000","14.4780","254.0934","14.4780","9.6520","60.9045"
"58.0800","14.4979","254.1984","14.4979","9.6653","60.9296"
"58.1600","14.5180","254.3110","14.5180","9.6787","60.9566"
"58.2400","14.5375","254.4028","14.5375","9.6917","60.9786"
"58.3200","14.5563","254.4875","14.5563","9.7042","60.9989"
"58.4000","14.5766","254.5981","14.5766","9.7177","61.0254"
"58.4800","14.5966","254.7063","14.5966","9.7311","61.0514"
"58.5600","14.6173","254.8383","14.6173","9.7449","61.0830"
"58.6400","14.6380","254.9501","14.6380","9.7587","61.1098"
"58.7200","14.6572","255.0313","14.6572","9.7714","61.1293"
"58.8000","14.6777","255.1440","14.6777","9.7851","61.1563"
"58.8800","14.6976","255.2485","14.6976","9.7984","61.1813"
"58.9600","14.7172","255.3361","14.7172","9.8114","61.2023"
"59.0400","14.7369","255.4364","14.7369","9.8246","61.2264"
"59.1200","14.7561","255.5099","14.7561","9.8374","61.2440"
"59.2000","14.7781","255.6413","14.7781","9.8521","61.2755"
"59.2800","14.7987","255.7492","14.7987","9.8658","61.3013"
"59.3600","14.8183","255.8412","14.8183","9.8788","61.3234"
"59.4400","14.8373","255.9028","14.8373","9.8916","61.3382"
"59.5200","14.8565","255.9813","14.8565","9.9043","61.3570"
"59.6000","14.8770","256.0732","14.8770","9.9180","61.3790"
"59.6800","14.8975","256.1748","14.8975","9.9317","61.4034"
"59.7600","14.9161","256.2030","14.9161","9.9441","61.4101"
"59.8400","14.9369","256.3031","14.9369","9.9579","61.4341"
"59.9200","14.9580","256.4126","14.9580","9.9720","61.4604"
"60.0000","14.9779","256.4920","14.9779","9.9853","61.4794"
"60.0800","14.9974","256.5607","14.9974","9.9983","61.4959"
"60.0900","15.0000","256.5758","15.0000","10.0000","61.4995"