File: data/instron_tests/metamaterials/250327/250327_1467_BULK_m2_NoTransition.is_comp_Exports/250327_1467_BULK_m2_NoTransition_4_1.csv
Results Table 1
,Compression Axis,H*,V*,Height,Thickness,Width,Area,Fixture separation,Specimen label
,,,,(mm),(mm),(mm),(mm^2),(mm),
"4","X","","","149.00","28.00","149.00","4172.00","150.00","1467_BULK_m2_NoTransition"

Results Table 2
,Modulus (Segment 0 % - 5 %),Compression Axis
,(kPa),
"4","794.64","X"

Time,Displacement,Force,Compressive displacement,Compressive strain (Displacement),Compressive stress
(s),(mm),(N),(mm),(%),(kPa)
"0.0000","0.0000","-1.4591","0.0000","0.0000","-0.3497"
"0.0800","0.0016","-1.4219","0.0016","0.0011","-0.3408"
"0.1600","0.0121","-1.0758","0.0121","0.0081","-0.2579"
"0.2400","0.0327","-0.4394","0.0327","0.0218","-0.1053"
"0.3200","0.0525","0.1586","0.0525","0.0350","0.0380"
"0.4000","0.0708","0.7116","0.0708","0.0472","0.1706"
"0.4800","0.0913","1.3093","0.0913","0.0609","0.3138"
"0.5600","0.1124","1.9219","0.1124","0.0750","0.4607"
"0.6400","0.1319","2.4261","0.1319","0.0879","0.5815"
"0.7200","0.1516","2.9797","0.1516","0.1011","0.7142"
"0.8000","0.1709","3.5116","0.1709","0.1139","0.8417"
"0.8800","0.1921","4.1034","0.1921","0.1280","0.9835"
"0.9600","0.2124","4.6640","0.2124","0.1416","1.1179"
"1.0400","0.2310","5.1828","0.2310","0.1540","1.2423"
"1.1200","0.2517","5.7358","0.2517","0.1678","1.3748"
"1.2000","0.2723","6.2910","0.2723","0.1815","1.5079"
"1.2800","0.2923","6.8234","0.2923","0.1949","1.6355"
"1.3600","0.3126","7.3705","0.3126","0.2084","1.7667"
"1.4400","0.3312","7.8577","0.3312","0.2208","1.8834"
"1.5200","0.3515","8.3957","0.3515","0.2343","2.0124"
"1.6000","0.3720","8.9405","0.3720","0.2480","2.1430"
"1.6800","0.3917","9.4632","0.3917","0.2612","2.2683"
"1.7600","0.4128","10.0292","0.4128","0.2752","2.4039"
"1.8400","0.4324","10.5297","0.4324","0.2882","2.5239"
"1.9200","0.4526","11.0420","0.4526","0.3017","2.6467"
"2.0000","0.4722","11.5587","0.4722","0.3148","2.7705"
"2.0800","0.4916","12.0606","0.4916","0.3277","2.8908"
"2.1600","0.5118","12.5943","0.5118","0.3412","3.0188"
"2.2400","0.5312","13.0885","0.5312","0.3541","3.1372"
"2.3200","0.5508","13.6013","0.5508","0.3672","3.2602"
"2.4000","0.5726","14.1854","0.5726","0.3818","3.4001"
"2.4800","0.5925","14.6857","0.5925","0.3950","3.5201"
"2.5600","0.6127","15.1994","0.6127","0.4085","3.6432"
"2.6400","0.6317","15.6691","0.6317","0.4211","3.7558"
"2.7200","0.6506","16.1550","0.6506","0.4337","3.8722"
"2.8000","0.6712","16.6913","0.6712","0.4475","4.0008"
"2.8800","0.6921","17.2166","0.6921","0.4614","4.1267"
"2.9600","0.7123","17.7297","0.7123","0.4749","4.2497"
"3.0400","0.7333","18.2706","0.7333","0.4889","4.3793"
"3.1200","0.7518","18.7338","0.7518","0.5012","4.4904"
"3.2000","0.7724","19.2581","0.7724","0.5150","4.6160"
"3.2800","0.7921","19.7438","0.7921","0.5281","4.7324"
"3.3600","0.8120","20.2604","0.8120","0.5413","4.8563"
"3.4400","0.8321","20.7524","0.8321","0.5547","4.9742"
"3.5200","0.8499","21.1944","0.8499","0.5666","5.0802"
"3.6000","0.8714","21.7431","0.8714","0.5809","5.2117"
"3.6800","0.8932","22.2954","0.8932","0.5954","5.3441"
"3.7600","0.9125","22.7780","0.9125","0.6083","5.4597"
"3.8400","0.9318","23.2512","0.9318","0.6212","5.5731"
"3.9200","0.9513","23.7259","0.9513","0.6342","5.6869"
"4.0000","0.9712","24.2373","0.9712","0.6475","5.8095"
"4.0800","0.9923","24.7594","0.9923","0.6615","5.9347"
"4.1600","1.0111","25.2203","1.0111","0.6741","6.0451"
"4.2400","1.0328","25.7656","1.0328","0.6886","6.1758"
"4.3200","1.0525","26.2549","1.0525","0.7017","6.2931"
"4.4000","1.0726","26.7504","1.0726","0.7151","6.4119"
"4.4800","1.0921","27.2263","1.0921","0.7281","6.5260"
"4.5600","1.1120","27.7116","1.1120","0.7413","6.6423"
"4.6400","1.1319","28.1954","1.1319","0.7546","6.7583"
"4.7200","1.1519","28.6898","1.1519","0.7679","6.8767"
"4.8000","1.1708","29.1627","1.1708","0.7805","6.9901"
"4.8800","1.1923","29.6999","1.1923","0.7949","7.1189"
"4.9600","1.2124","30.1866","1.2124","0.8083","7.2355"
"5.0400","1.2320","30.6481","1.2320","0.8213","7.3461"
"5.1200","1.2517","31.1274","1.2517","0.8345","7.4610"
"5.2000","1.2713","31.6062","1.2713","0.8475","7.5758"
"5.2800","1.2921","32.1205","1.2921","0.8614","7.6991"
"5.3600","1.3122","32.6050","1.3122","0.8748","7.8152"
"5.4400","1.3319","33.0780","1.3319","0.8879","7.9286"
"5.5200","1.3523","33.5772","1.3523","0.9015","8.0482"
"5.6000","1.3721","34.0525","1.3721","0.9147","8.1622"
"5.6800","1.3926","34.5405","1.3926","0.9284","8.2791"
"5.7600","1.4130","35.0324","1.4130","0.9420","8.3970"
"5.8400","1.4312","35.4682","1.4312","0.9542","8.5015"
"5.9200","1.4516","35.9624","1.4516","0.9677","8.6199"
"6.0000","1.4708","36.4169","1.4708","0.9805","8.7289"
"6.0800","1.4920","36.9365","1.4920","0.9947","8.8534"
"6.1600","1.5126","37.4302","1.5126","1.0084","8.9718"
"6.2400","1.5322","37.8935","1.5322","1.0214","9.0828"
"6.3200","1.5520","38.3681","1.5520","1.0347","9.1966"
"6.4000","1.5719","38.8365","1.5719","1.0479","9.3088"
"6.4800","1.5911","39.2981","1.5911","1.0607","9.4195"
"6.5600","1.6125","39.8155","1.6125","1.0750","9.5435"
"6.6400","1.6306","40.2340","1.6306","1.0871","9.6438"
"6.7200","1.6524","40.7713","1.6524","1.1016","9.7726"
"6.8000","1.6735","41.2746","1.6735","1.1157","9.8932"
"6.8800","1.6928","41.7327","1.6928","1.1285","10.0030"
"6.9600","1.7116","42.1716","1.7116","1.1411","10.1082"
"7.0400","1.7317","42.6486","1.7317","1.1545","10.2226"
"7.1200","1.7515","43.1258","1.7515","1.1677","10.3370"
"7.2000","1.7720","43.6176","1.7720","1.1813","10.4548"
"7.2800","1.7911","44.0627","1.7911","1.1940","10.5615"
"7.3600","1.8124","44.5742","1.8124","1.2082","10.6841"
"7.4400","1.8324","45.0441","1.8324","1.2216","10.7968"
"7.5200","1.8519","45.5146","1.8519","1.2346","10.9095"
"7.6000","1.8721","45.9878","1.8721","1.2481","11.0230"
"7.6800","1.8914","46.4317","1.8914","1.2609","11.1294"
"7.7600","1.9122","46.9521","1.9122","1.2748","11.2541"
"7.8400","1.9324","47.4239","1.9324","1.2883","11.3672"
"7.9200","1.9511","47.8551","1.9511","1.3007","11.4705"
"8.0000","1.9719","48.3625","1.9719","1.3146","11.5922"
"8.0800","1.9929","48.8525","1.9929","1.3286","11.7096"
"8.1600","2.0126","49.3077","2.0126","1.3417","11.8187"
"8.2400","2.0325","49.7415","2.0325","1.3550","11.9227"
"8.3200","2.0508","50.1451","2.0508","1.3672","12.0194"
"8.4000","2.0718","50.6391","2.0718","1.3812","12.1379"
"8.4800","2.0918","51.1042","2.0918","1.3945","12.2493"
"8.5600","2.1117","51.5754","2.1117","1.4078","12.3623"
"8.6400","2.1320","52.0414","2.1320","1.4214","12.4740"
"8.7200","2.1521","52.5060","2.1521","1.4347","12.5853"
"8.8000","2.1722","52.9718","2.1722","1.4481","12.6970"
"8.8800","2.1927","53.4471","2.1927","1.4618","12.8109"
"8.9600","2.2112","53.9031","2.2112","1.4741","12.9202"
"9.0400","2.2319","54.3835","2.2319","1.4879","13.0354"
"9.1200","2.2515","54.8352","2.2515","1.5010","13.1436"
"9.2000","2.2720","55.3130","2.2720","1.5147","13.2581"
"9.2800","2.2934","55.8147","2.2934","1.5289","13.3784"
"9.3600","2.3124","56.2350","2.3124","1.5416","13.4791"
"9.4400","2.3323","56.6910","2.3323","1.5549","13.5885"
"9.5200","2.3522","57.1522","2.3522","1.5681","13.6990"
"9.6000","2.3713","57.5975","2.3713","1.5809","13.8057"
"9.6800","2.3910","58.0397","2.3910","1.5940","13.9117"
"9.7600","2.4109","58.4858","2.4109","1.6073","14.0186"
"9.8400","2.4317","58.9831","2.4317","1.6211","14.1378"
"9.9200","2.4527","59.4617","2.4527","1.6351","14.2526"
"10.0000","2.4719","59.9018","2.4719","1.6480","14.3581"
"10.0800","2.4929","60.3775","2.4929","1.6619","14.4721"
"10.1600","2.5118","60.8034","2.5118","1.6746","14.5742"
"10.2400","2.5316","61.2491","2.5316","1.6877","14.6810"
"10.3200","2.5518","61.7315","2.5518","1.7012","14.7966"
"10.4000","2.5713","62.1602","2.5713","1.7142","14.8994"
"10.4800","2.5924","62.6567","2.5924","1.7283","15.0184"
"10.5600","2.6135","63.1334","2.6135","1.7423","15.1326"
"10.6400","2.6325","63.5579","2.6325","1.7550","15.2344"
"10.7200","2.6519","63.9919","2.6519","1.7680","15.3384"
"10.8000","2.6710","64.4114","2.6710","1.7806","15.4390"
"10.8800","2.6919","64.8912","2.6919","1.7946","15.5540"
"10.9600","2.7123","65.3581","2.7123","1.8082","15.6659"
"11.0400","2.7307","65.7598","2.7307","1.8205","15.7622"
"11.1200","2.7515","66.2361","2.7515","1.8343","15.8763"
"11.2000","2.7727","66.7269","2.7727","1.8485","15.9940"
"11.2800","2.7925","67.1601","2.7925","1.8617","16.0978"
"11.3600","2.8124","67.6081","2.8124","1.8749","16.2052"
"11.4400","2.8311","68.0098","2.8311","1.8874","16.3015"
"11.5200","2.8516","68.4791","2.8516","1.9011","16.4140"
"11.6000","2.8720","68.9290","2.8720","1.9147","16.5218"
"11.6800","2.8918","69.3883","2.8918","1.9278","16.6319"
"11.7600","2.9127","69.8579","2.9127","1.9418","16.7445"
"11.8400","2.9323","70.2952","2.9323","1.9549","16.8493"
"11.9200","2.9527","70.7483","2.9527","1.9684","16.9579"
"12.0000","2.9722","71.1904","2.9722","1.9815","17.0639"
"12.0800","2.9917","71.6329","2.9917","1.9944","17.1699"
"12.1600","3.0118","72.0907","3.0118","2.0078","17.2797"
"12.2400","3.0311","72.5057","3.0311","2.0207","17.3791"
"12.3200","3.0508","72.9647","3.0508","2.0339","17.4891"
"12.4000","3.0726","73.4614","3.0726","2.0484","17.6082"
"12.4800","3.0920","73.8880","3.0920","2.0614","17.7105"
"12.5600","3.1129","74.3519","3.1129","2.0753","17.8216"
"12.6400","3.1320","74.7742","3.1320","2.0880","17.9229"
"12.7200","3.1511","75.2093","3.1511","2.1007","18.0272"
"12.8000","3.1715","75.6808","3.1715","2.1143","18.1402"
"12.8800","3.1918","76.1298","3.1918","2.1279","18.2478"
"12.9600","3.2121","76.5822","3.2121","2.1414","18.3562"
"13.0400","3.2329","77.0684","3.2329","2.1553","18.4728"
"13.1200","3.2521","77.4803","3.2521","2.1680","18.5715"
"13.2000","3.2722","77.9308","3.2722","2.1815","18.6795"
"13.2800","3.2921","78.3770","3.2921","2.1947","18.7864"
"13.3600","3.3119","78.8249","3.3119","2.2079","18.8938"
"13.4400","3.3321","79.2739","3.3321","2.2214","19.0014"
"13.5200","3.3506","79.6718","3.3506","2.2337","19.0968"
"13.6000","3.3718","80.1542","3.3718","2.2479","19.2124"
"13.6800","3.3927","80.6229","3.3927","2.2618","19.3248"
"13.7600","3.4123","81.0569","3.4123","2.2749","19.4288"
"13.8400","3.4322","81.5000","3.4322","2.2881","19.5350"
"13.9200","3.4515","81.9070","3.4515","2.3010","19.6326"
"14.0000","3.4716","82.3782","3.4716","2.3144","19.7455"
"14.0800","3.4922","82.8195","3.4922","2.3282","19.8513"
"14.1600","3.5111","83.2429","3.5111","2.3407","19.9528"
"14.2400","3.5325","83.7325","3.5325","2.3550","20.0701"
"14.3200","3.5526","84.1805","3.5526","2.3684","20.1775"
"14.4000","3.5724","84.6152","3.5724","2.3816","20.2817"
"14.4800","3.5920","85.0465","3.5920","2.3947","20.3851"
"14.5600","3.6114","85.4681","3.6114","2.4076","20.4861"
"14.6400","3.6318","85.9221","3.6318","2.4212","20.5949"
"14.7200","3.6518","86.3497","3.6518","2.4345","20.6974"
"14.8000","3.6704","86.7525","3.6704","2.4470","20.7940"
"14.8800","3.6918","87.2452","3.6918","2.4612","20.9121"
"14.9600","3.7123","87.6992","3.7123","2.4749","21.0209"
"15.0400","3.7324","88.1340","3.7324","2.4883","21.1251"
"15.1200","3.7519","88.5503","3.7519","2.5013","21.2249"
"15.2000","3.7709","88.9659","3.7709","2.5139","21.3245"
"15.2800","3.7921","89.4345","3.7921","2.5280","21.4368"
"15.3600","3.8120","89.8706","3.8120","2.5413","21.5414"
"15.4400","3.8317","90.3009","3.8317","2.5544","21.6445"
"15.5200","3.8524","90.7667","3.8524","2.5683","21.7562"
"15.6000","3.8721","91.1766","3.8721","2.5814","21.8544"
"15.6800","3.8927","91.6418","3.8927","2.5951","21.9659"
"15.7600","3.9125","92.0590","3.9125","2.6084","22.0659"
"15.8400","3.9313","92.4629","3.9313","2.6209","22.1627"
"15.9200","3.9518","92.9063","3.9518","2.6345","22.2690"
"16.0000","3.9709","93.3090","3.9709","2.6473","22.3655"
"16.0800","3.9919","93.7700","3.9919","2.6613","22.4760"
"16.1600","4.0126","94.1900","4.0126","2.6751","22.5767"
"16.2400","4.0321","94.6059","4.0321","2.6881","22.6764"
"16.3200","4.0522","95.0573","4.0522","2.7015","22.7846"
"16.4000","4.0721","95.4909","4.0721","2.7147","22.8885"
"16.4800","4.0913","95.9040","4.0913","2.7275","22.9875"
"16.5600","4.1120","96.3615","4.1120","2.7414","23.0972"
"16.6400","4.1312","96.7596","4.1312","2.7541","23.1926"
"16.7200","4.1523","97.2329","4.1523","2.7682","23.3061"
"16.8000","4.1729","97.6820","4.1729","2.7819","23.4137"
"16.8800","4.1925","98.1058","4.1925","2.7950","23.5153"
"16.9600","4.2120","98.5215","4.2120","2.8080","23.6149"
"17.0400","4.2318","98.9518","4.2318","2.8212","23.7181"
"17.1200","4.2509","99.3453","4.2509","2.8339","23.8124"
"17.2000","4.2719","99.7785","4.2719","2.8479","23.9162"
"17.2800","4.2912","100.1844","4.2912","2.8608","24.0135"
"17.3600","4.3122","100.6520","4.3122","2.8748","24.1256"
"17.4400","4.3324","101.0807","4.3324","2.8883","24.2284"
"17.5200","4.3520","101.5085","4.3520","2.9013","24.3309"
"17.6000","4.3720","101.9421","4.3720","2.9147","24.4348"
"17.6800","4.3914","102.3595","4.3914","2.9276","24.5349"
"17.7600","4.4122","102.7977","4.4122","2.9415","24.6399"
"17.8400","4.4322","103.2391","4.4322","2.9548","24.7457"
"17.9200","4.4511","103.6375","4.4511","2.9674","24.8412"
"18.0000","4.4718","104.0868","4.4718","2.9812","24.9489"
"18.0800","4.4930","104.5549","4.4930","2.9953","25.0611"
"18.1600","4.5125","104.9642","4.5125","3.0083","25.1592"
"18.2400","4.5324","105.3893","4.5324","3.0216","25.2611"
"18.3200","4.5509","105.7526","4.5509","3.0339","25.3482"
"18.4000","4.5721","106.2140","4.5721","3.0481","25.4588"
"18.4800","4.5916","106.6259","4.5916","3.0611","25.5575"
"18.5600","4.6115","107.0590","4.6115","3.0743","25.6613"
"18.6400","4.6317","107.5042","4.6317","3.0878","25.7680"
"18.7200","4.6522","107.9382","4.6522","3.1014","25.8721"
"18.8000","4.6723","108.3704","4.6723","3.1149","25.9757"
"18.8800","4.6929","108.8183","4.6929","3.1286","26.0830"
"18.9600","4.7113","109.1943","4.7113","3.1408","26.1731"
"19.0400","4.7317","109.6285","4.7317","3.1545","26.2772"
"19.1200","4.7514","110.0516","4.7514","3.1676","26.3786"
"19.2000","4.7721","110.5082","4.7721","3.1814","26.4881"
"19.2800","4.7930","110.9580","4.7930","3.1953","26.5959"
"19.3600","4.8127","111.3619","4.8127","3.2085","26.6927"
"19.4400","4.8326","111.7557","4.8326","3.2218","26.7871"
"19.5200","4.8519","112.1706","4.8519","3.2346","26.8865"
"19.6000","4.8715","112.5774","4.8715","3.2477","26.9840"
"19.6800","4.8920","113.0462","4.8920","3.2614","27.0964"
"19.7600","4.9112","113.4330","4.9112","3.2741","27.1891"
"19.8400","4.9315","113.8624","4.9315","3.2877","27.2920"
"19.9200","4.9523","114.3155","4.9523","3.3015","27.4006"
"20.0000","4.9721","114.7201","4.9721","3.3147","27.4976"
"20.0800","4.9926","115.1571","4.9926","3.3284","27.6024"
"20.1600","5.0115","115.5450","5.0115","3.3410","27.6953"
"20.2400","5.0317","115.9716","5.0317","3.3545","27.7976"
"20.3200","5.0515","116.3812","5.0515","3.3677","27.8958"
"20.4000","5.0710","116.7825","5.0710","3.3807","27.9920"
"20.4800","5.0921","117.2336","5.0921","3.3947","28.1001"
"20.5600","5.1134","117.6901","5.1134","3.4089","28.2095"
"20.6400","5.1322","118.0765","5.1322","3.4215","28.3021"
"20.7200","5.1518","118.4806","5.1518","3.4346","28.3990"
"20.8000","5.1710","118.8818","5.1710","3.4473","28.4952"
"20.8800","5.1922","119.3342","5.1922","3.4614","28.6036"
"20.9600","5.2122","119.7643","5.2122","3.4748","28.7067"
"21.0400","5.2310","120.1407","5.2310","3.4873","28.7969"
"21.1200","5.2512","120.5533","5.2512","3.5008","28.8958"
"21.2000","5.2721","121.0080","5.2721","3.5147","29.0048"
"21.2800","5.2925","121.4313","5.2925","3.5283","29.1063"
"21.3600","5.3126","121.8582","5.3126","3.5417","29.2086"
"21.4400","5.3310","122.2209","5.3310","3.5540","29.2955"
"21.5200","5.3516","122.6647","5.3516","3.5677","29.4019"
"21.6000","5.3719","123.0972","5.3719","3.5812","29.5056"
"21.6800","5.3918","123.5239","5.3918","3.5945","29.6078"
"21.7600","5.4131","123.9887","5.4131","3.6087","29.7193"
"21.8400","5.4327","124.3715","5.4327","3.6218","29.8110"
"21.9200","5.4526","124.7856","5.4526","3.6351","29.9102"
"22.0000","5.4720","125.1931","5.4720","3.6480","30.0079"
"22.0800","5.4916","125.6018","5.4916","3.6611","30.1059"
"22.1600","5.5120","126.0291","5.5120","3.6747","30.2083"
"22.2400","5.5317","126.4285","5.5317","3.6878","30.3040"
"22.3200","5.5505","126.8147","5.5505","3.7003","30.3966"
"22.4000","5.5715","127.2664","5.5715","3.7144","30.5049"
"22.4800","5.5924","127.6993","5.5924","3.7282","30.6086"
"22.5600","5.6130","128.1225","5.6130","3.7420","30.7101"
"22.6400","5.6319","128.4986","5.6319","3.7546","30.8002"
"22.7200","5.6511","128.8976","5.6511","3.7674","30.8959"
"22.8000","5.6715","129.3262","5.6715","3.7810","30.9986"
"22.8800","5.6918","129.7518","5.6918","3.7945","31.1006"
"22.9600","5.7121","130.1763","5.7121","3.8081","31.2024"
"23.0400","5.7331","130.6236","5.7331","3.8220","31.3096"
"23.1200","5.7520","131.0108","5.7520","3.8347","31.4024"
"23.2000","5.7725","131.4225","5.7725","3.8483","31.5011"
"23.2800","5.7921","131.8265","5.7921","3.8614","31.5979"
"23.3600","5.8121","132.2449","5.8121","3.8747","31.6982"
"23.4400","5.8318","132.6414","5.8318","3.8879","31.7932"
"23.5200","5.8500","133.0018","5.8500","3.9000","31.8796"
"23.6000","5.8718","133.4776","5.8718","3.9145","31.9937"
"23.6800","5.8934","133.9476","5.8934","3.9290","32.1063"
"23.7600","5.9125","134.3349","5.9125","3.9417","32.1992"
"23.8400","5.9319","134.7370","5.9319","3.9546","32.2955"
"23.9200","5.9515","135.1235","5.9515","3.9677","32.3882"
"24.0000","5.9712","135.5283","5.9712","3.9808","32.4852"
"24.0800","5.9924","135.9753","5.9924","3.9949","32.5923"
"24.1600","6.0115","136.3691","6.0115","4.0077","32.6867"
"24.2400","6.0327","136.8135","6.0327","4.0218","32.7933"
"24.3200","6.0525","137.2204","6.0525","4.0350","32.8908"
"24.4000","6.0724","137.6286","6.0724","4.0483","32.9886"
"24.4800","6.0921","138.0430","6.0921","4.0614","33.0880"
"24.5600","6.1120","138.4374","6.1120","4.0746","33.1825"
"24.6400","6.1319","138.8412","6.1319","4.0879","33.2793"
"24.7200","6.1514","139.2337","6.1514","4.1009","33.3734"
"24.8000","6.1702","139.6127","6.1702","4.1135","33.4642"
"24.8800","6.1923","140.0983","6.1923","4.1282","33.5806"
"24.9600","6.2122","140.4861","6.2122","4.1415","33.6736"
"25.0400","6.2327","140.9130","6.2327","4.1551","33.7759"
"25.1200","6.2521","141.3031","6.2521","4.1681","33.8694"
"25.2000","6.2713","141.6830","6.2713","4.1808","33.9604"
"25.2800","6.2921","142.1183","6.2921","4.1947","34.0648"
"25.3600","6.3120","142.5227","6.3120","4.2080","34.1617"
"25.4400","6.3317","142.9265","6.3317","4.2211","34.2585"
"25.5200","6.3521","143.3545","6.3521","4.2347","34.3611"
"25.6000","6.3723","143.7556","6.3723","4.2482","34.4572"
"25.6800","6.3925","144.1606","6.3925","4.2617","34.5543"
"25.7600","6.4126","144.5733","6.4126","4.2751","34.6532"
"25.8400","6.4312","144.9496","6.4312","4.2875","34.7434"
"25.9200","6.4522","145.3854","6.4522","4.3014","34.8479"
"26.0000","6.4709","145.7452","6.4709","4.3140","34.9341"
"26.0800","6.4921","146.1941","6.4921","4.3280","35.0417"
"26.1600","6.5127","146.6028","6.5127","4.3418","35.1397"
"26.2400","6.5320","146.9902","6.5320","4.3547","35.2326"
"26.3200","6.5519","147.3823","6.5519","4.3680","35.3265"
"26.4000","6.5722","147.8010","6.5722","4.3815","35.4269"
"26.4800","6.5915","148.1830","6.5915","4.3943","35.5185"
"26.5600","6.6123","148.6079","6.6123","4.4082","35.6203"
"26.6400","6.6310","148.9744","6.6310","4.4207","35.7081"
"26.7200","6.6525","149.4162","6.6525","4.4350","35.8140"
"26.8000","6.6729","149.8266","6.6729","4.4486","35.9124"
"26.8800","6.6921","150.2162","6.6921","4.4614","36.0058"
"26.9600","6.7120","150.6174","6.7120","4.4747","36.1020"
"27.0400","6.7318","150.9938","6.7318","4.4879","36.1922"
"27.1200","6.7512","151.3826","6.7512","4.5008","36.2854"
"27.2000","6.7719","151.8075","6.7719","4.5146","36.3872"
"27.2800","6.7910","152.1758","6.7910","4.5273","36.4755"
"27.3600","6.8123","152.6163","6.8123","4.5415","36.5811"
"27.4400","6.8325","153.0228","6.8325","4.5550","36.6785"
"27.5200","6.8518","153.4049","6.8518","4.5679","36.7701"
"27.6000","6.8721","153.8247","6.8721","4.5814","36.8707"
"27.6800","6.8913","154.1959","6.8913","4.5942","36.9597"
"27.7600","6.9123","154.6247","6.9123","4.6082","37.0625"
"27.8400","6.9323","155.0185","6.9323","4.6215","37.1569"
"27.9200","6.9515","155.3995","6.9515","4.6344","37.2482"
"28.0000","6.9722","155.8210","6.9722","4.6482","37.3492"
"28.0800","6.9929","156.2352","6.9929","4.6620","37.4485"
"28.1600","7.0123","156.6059","7.0123","4.6749","37.5374"
"28.2400","7.0324","157.0099","7.0324","4.6883","37.6342"
"28.3200","7.0509","157.3631","7.0509","4.7006","37.7189"
"28.4000","7.0719","157.7930","7.0719","4.7146","37.8219"
"28.4800","7.0917","158.1836","7.0917","4.7278","37.9155"
"28.5600","7.1114","158.5742","7.1114","4.7410","38.0092"
"28.6400","7.1317","158.9803","7.1317","4.7545","38.1065"
"28.7200","7.1522","159.3789","7.1522","4.7681","38.2020"
"28.8000","7.1720","159.7641","7.1720","4.7813","38.2944"
"28.8800","7.1927","160.1801","7.1927","4.7951","38.3941"
"28.9600","7.2111","160.5253","7.2111","4.8074","38.4768"
"29.0400","7.2318","160.9440","7.2318","4.8212","38.5772"
"29.1200","7.2512","161.3035","7.2512","4.8341","38.6634"
"29.2000","7.2719","161.7302","7.2719","4.8480","38.7656"
"29.2800","7.2933","162.1588","7.2933","4.8622","38.8684"
"29.3600","7.3126","162.5280","7.3126","4.8751","38.9569"
"29.4400","7.3324","162.9048","7.3324","4.8883","39.0472"
"29.5200","7.3520","163.2803","7.3520","4.9014","39.1372"
"29.6000","7.3712","163.6509","7.3712","4.9141","39.2260"
"29.6800","7.3918","164.0696","7.3918","4.9278","39.3264"
"29.7600","7.4112","164.4373","7.4112","4.9408","39.4145"
"29.8400","7.4316","164.8329","7.4316","4.9544","39.5093"
"29.9200","7.4528","165.2597","7.4528","4.9686","39.6116"
"30.0000","7.4719","165.6277","7.4719","4.9813","39.6998"
"30.0800","7.4929","166.0573","7.4929","4.9952","39.8028"
"30.1600","7.5114","166.3888","7.5114","5.0076","39.8823"
"30.2400","7.5315","166.7795","7.5315","5.0210","39.9759"
"30.3200","7.5518","167.1851","7.5518","5.0345","40.0731"
"30.4000","7.5712","167.5482","7.5712","5.0475","40.1602"
"30.4800","7.5924","167.9647","7.5924","5.0616","40.2600"
"30.5600","7.6136","168.3879","7.6136","5.0757","40.3614"
"30.6400","7.6325","168.7481","7.6325","5.0884","40.4478"
"30.7200","7.6521","169.1206","7.6521","5.1014","40.5371"
"30.8000","7.6711","169.4740","7.6711","5.1141","40.6218"
"30.8800","7.6922","169.8957","7.6922","5.1282","40.7228"
"30.9600","7.7124","170.2780","7.7124","5.1416","40.8145"
"31.0400","7.7308","170.6188","7.7308","5.1539","40.8962"
"31.1200","7.7514","171.0295","7.7514","5.1676","40.9946"
"31.2000","7.7724","171.4548","7.7724","5.1816","41.0966"
"31.2800","7.7924","171.8340","7.7924","5.1949","41.1875"
"31.3600","7.8126","172.2233","7.8126","5.2084","41.2808"
"31.4400","7.8310","172.5556","7.8310","5.2207","41.3604"
"31.5200","7.8517","172.9597","7.8517","5.2345","41.4573"
"31.6000","7.8720","173.3443","7.8720","5.2480","41.5494"
"31.6800","7.8919","173.7375","7.8919","5.2612","41.6437"
"31.7600","7.9132","174.1662","7.9132","5.2755","41.7465"
"31.8400","7.9326","174.5223","7.9326","5.2884","41.8318"
"31.9200","7.9524","174.8997","7.9524","5.3016","41.9223"
"32.0000","7.9719","175.2678","7.9719","5.3146","42.0105"
"32.0800","7.9915","175.6278","7.9915","5.3277","42.0968"
"32.1600","8.0118","176.0279","8.0118","5.3412","42.1927"
"32.2400","8.0315","176.3929","8.0315","5.3543","42.2802"
"32.3200","8.0509","176.7547","8.0509","5.3673","42.3669"
"32.4000","8.0726","177.1833","8.0726","5.3818","42.4696"
"32.4800","8.0921","177.5361","8.0921","5.3947","42.5542"
"32.5600","8.1127","177.9323","8.1127","5.4084","42.6492"
"32.6400","8.1319","178.2868","8.1319","5.4212","42.7341"
"32.7200","8.1512","178.6523","8.1512","5.4341","42.8218"
"32.8000","8.1714","179.0407","8.1714","5.4476","42.9148"
"32.8800","8.1916","179.4111","8.1916","5.4611","43.0036"
"32.9600","8.2120","179.8140","8.2120","5.4747","43.1002"
"33.0400","8.2331","180.2148","8.2331","5.4887","43.1963"
"33.1200","8.2519","180.5512","8.2519","5.5013","43.2769"
"33.2000","8.2725","180.9450","8.2725","5.5150","43.3713"
"33.2800","8.2920","181.3093","8.2920","5.5280","43.4586"
"33.3600","8.3118","181.6858","8.3118","5.5412","43.5489"
"33.4400","8.3315","182.0593","8.3315","5.5543","43.6384"
"33.5200","8.3505","182.3949","8.3505","5.5670","43.7188"
"33.6000","8.3718","182.8109","8.3718","5.5812","43.8185"
"33.6800","8.3930","183.2212","8.3930","5.5953","43.9169"
"33.7600","8.4126","183.5816","8.4126","5.6084","44.0033"
"33.8400","8.4321","183.9416","8.4321","5.6214","44.0895"
"33.9200","8.4510","184.2702","8.4510","5.6340","44.1683"
"34.0000","8.4714","184.6719","8.4714","5.6476","44.2646"
"34.0800","8.4922","185.0633","8.4922","5.6614","44.3584"
"34.1600","8.5113","185.4110","8.5113","5.6742","44.4417"
"34.2400","8.5327","185.8378","8.5327","5.6885","44.5441"
"34.3200","8.5527","186.2026","8.5527","5.7018","44.6315"
"34.4000","8.5726","186.5732","8.5726","5.7151","44.7203"
"34.4800","8.5918","186.9087","8.5918","5.7279","44.8007"
"34.5600","8.6113","187.2491","8.6113","5.7408","44.8823"
"34.6400","8.6318","187.6431","8.6318","5.7545","44.9768"
"34.7200","8.6519","188.0009","8.6519","5.7679","45.0625"
"34.8000","8.6705","188.3365","8.6705","5.7803","45.1430"
"34.8800","8.6920","188.7592","8.6920","5.7946","45.2443"
"34.9600","8.7122","189.1222","8.7122","5.8082","45.3313"
"35.0400","8.7326","189.4934","8.7326","5.8217","45.4203"
"35.1200","8.7523","189.8492","8.7523","5.8349","45.5056"
"35.2000","8.7711","190.1843","8.7711","5.8474","45.5859"
"35.2800","8.7919","190.5678","8.7919","5.8613","45.6778"
"35.3600","8.8119","190.9376","8.8119","5.8746","45.7664"
"35.4400","8.8317","191.2926","8.8317","5.8878","45.8515"
"35.5200","8.8524","191.6913","8.8524","5.9016","45.9471"
"35.6000","8.8724","192.0440","8.8724","5.9149","46.0316"
"35.6800","8.8926","192.4121","8.8926","5.9284","46.1199"
"35.7600","8.9126","192.7688","8.9126","5.9417","46.2054"
"35.8400","8.9313","193.1072","8.9313","5.9542","46.2865"
"35.9200","8.9517","193.4862","8.9517","5.9678","46.3773"
"36.0000","8.9709","193.8216","8.9709","5.9806","46.4577"
"36.0800","8.9922","194.2275","8.9922","5.9948","46.5550"
"36.1600","9.0127","194.5936","9.0127","6.0085","46.6428"
"36.2400","9.0321","194.9350","9.0321","6.0214","46.7246"
"36.3200","9.0518","195.2821","9.0518","6.0346","46.8078"
"36.4000","9.0720","195.6437","9.0720","6.0480","46.8945"
"36.4800","9.0912","195.9969","9.0912","6.0608","46.9791"
"36.5600","9.1122","196.3763","9.1122","6.0748","47.0701"
"36.6400","9.1312","196.7041","9.1312","6.0874","47.1486"
"36.7200","9.1527","197.1088","9.1527","6.1018","47.2456"
"36.8000","9.1730","197.4688","9.1730","6.1154","47.3319"
"36.8800","9.1925","197.8107","9.1925","6.1283","47.4139"
"36.9600","9.2121","198.1478","9.2121","6.1414","47.4947"
"37.0400","9.2317","198.4912","9.2317","6.1545","47.5770"
"37.1200","9.2513","198.8365","9.2513","6.1675","47.6598"
"37.2000","9.2719","199.2154","9.2719","6.1813","47.7506"
"37.2800","9.2910","199.5350","9.2910","6.1940","47.8272"
"37.3600","9.3121","199.9243","9.3121","6.2080","47.9205"
"37.4400","9.3325","200.2858","9.3325","6.2217","48.0071"
"37.5200","9.3521","200.6308","9.3521","6.2347","48.0898"
"37.6000","9.3719","200.9744","9.3719","6.2479","48.1722"
"37.6800","9.3913","201.3102","9.3913","6.2609","48.2527"
"37.7600","9.4122","201.6764","9.4122","6.2748","48.3405"
"37.8400","9.4317","202.0193","9.4317","6.2878","48.4227"
"37.9200","9.4511","202.3516","9.4511","6.3007","48.5023"
"38.0000","9.4720","202.7406","9.4720","6.3147","48.5955"
"38.0800","9.4927","203.0954","9.4927","6.3284","48.6806"
"38.1600","9.5125","203.4335","9.5125","6.3417","48.7616"
"38.2400","9.5327","203.7868","9.5327","6.3551","48.8463"
"38.3200","9.5509","204.0772","9.5509","6.3673","48.9159"
"38.4000","9.5720","204.4556","9.5720","6.3813","49.0066"
"38.4800","9.5917","204.7888","9.5917","6.3945","49.0865"
"38.5600","9.6117","205.1368","9.6117","6.4078","49.1699"
"38.6400","9.6317","205.5016","9.6317","6.4211","49.2573"
"38.7200","9.6521","205.8473","9.6521","6.4347","49.3402"
"38.8000","9.6723","206.1844","9.6723","6.4482","49.4210"
"38.8800","9.6925","206.5433","9.6925","6.4617","49.5070"
"38.9600","9.7113","206.8393","9.7113","6.4742","49.5780"
"39.0400","9.7319","207.2095","9.7319","6.4879","49.6667"
"39.1200","9.7513","207.5279","9.7513","6.5009","49.7430"
"39.2000","9.7721","207.9032","9.7721","6.5147","49.8330"
"39.2800","9.7932","208.2710","9.7932","6.5288","49.9212"
"39.3600","9.8124","208.5855","9.8124","6.5416","49.9965"
"39.4400","9.8325","208.9280","9.8325","6.5550","50.0786"
"39.5200","9.8520","209.2466","9.8520","6.5680","50.1550"
"39.6000","9.8715","209.5738","9.8715","6.5810","50.2334"
"39.6800","9.8915","209.9212","9.8915","6.5943","50.3167"
"39.7600","9.9111","210.2215","9.9111","6.6074","50.3887"
"39.8400","9.9314","210.5693","9.9314","6.6210","50.4720"
"39.9200","9.9526","210.9387","9.9526","6.6350","50.5606"
"40.0000","9.9720","211.2634","9.9720","6.6480","50.6384"
"40.0800","9.9928","211.6215","9.9928","6.6619","50.7242"
"40.1600","10.0114","211.9093","10.0114","6.6743","50.7932"
"40.2400","10.0316","212.2428","10.0316","6.6877","50.8732"
"40.3200","10.0512","212.5650","10.0512","6.7008","50.9504"
"40.4000","10.0714","212.8995","10.0714","6.7143","51.0306"
"40.4800","10.0920","213.2466","10.0920","6.7280","51.1138"
"40.5600","10.1137","213.6261","10.1137","6.7424","51.2047"
"40.6400","10.1323","213.9063","10.1323","6.7549","51.2719"
"40.7200","10.1523","214.2343","10.1523","6.7682","51.3505"
"40.8000","10.1710","214.5183","10.1710","6.7807","51.4186"
"40.8800","10.1923","214.8895","10.1923","6.7949","51.5075"
"40.9600","10.2125","215.2154","10.2125","6.8083","51.5857"
"41.0400","10.2310","215.4935","10.2310","6.8207","51.6523"
"41.1200","10.2513","215.8282","10.2513","6.8342","51.7325"
"41.2000","10.2722","216.1785","10.2722","6.8482","51.8165"
"41.2800","10.2922","216.4975","10.2922","6.8614","51.8930"
"41.3600","10.3127","216.8531","10.3127","6.8752","51.9782"
"41.4400","10.3314","217.1229","10.3314","6.8876","52.0429"
"41.5200","10.3517","217.4529","10.3517","6.9011","52.1220"
"41.6000","10.3720","217.7716","10.3720","6.9147","52.1984"
"41.6800","10.3914","218.0928","10.3914","6.9276","52.2753"
"41.7600","10.4129","218.4406","10.4129","6.9419","52.3587"
"41.8400","10.4325","218.7308","10.4325","6.9550","52.4283"
"41.9200","10.4529","219.0624","10.4529","6.9686","52.5078"
"42.0000","10.4719","219.3391","10.4719","6.9813","52.5741"
"42.0800","10.4913","219.6349","10.4913","6.9942","52.6450"
"42.1600","10.5118","219.9653","10.5118","7.0078","52.7242"
"42.2400","10.5313","220.2538","10.5313","7.0208","52.7933"
"42.3200","10.5508","220.5565","10.5508","7.0339","52.8659"
"42.4000","10.5726","220.9169","10.5726","7.0484","52.9523"
"42.4800","10.5923","221.2083","10.5923","7.0615","53.0221"
"42.5600","10.6130","221.5375","10.6130","7.0753","53.1010"
"42.6400","10.6318","221.8030","10.6318","7.0879","53.1647"
"42.7200","10.6512","222.0994","10.6512","7.1008","53.2357"
"42.8000","10.6712","222.3993","10.6712","7.1141","53.3076"
"42.8800","10.6915","222.7243","10.6915","7.1276","53.3855"
"42.9600","10.7125","223.0592","10.7125","7.1417","53.4658"
"43.0400","10.7335","223.3813","10.7335","7.1557","53.5430"
"43.1200","10.7521","223.6392","10.7521","7.1681","53.6048"
"43.2000","10.7723","223.9482","10.7723","7.1816","53.6789"
"43.2800","10.7925","224.2397","10.7925","7.1950","53.7487"
"43.3600","10.8123","224.5404","10.8123","7.2082","53.8208"
"43.4400","10.8320","224.8305","10.8320","7.2213","53.8903"
"43.5200","10.8500","225.0638","10.8500","7.2333","53.9463"
"43.6000","10.8714","225.3956","10.8714","7.2476","54.0258"
"43.6800","10.8926","225.7270","10.8926","7.2618","54.1052"
"43.7600","10.9125","226.0065","10.9125","7.2750","54.1722"
"43.8400","10.9320","226.2902","10.9320","7.2880","54.2402"
"43.9200","10.9515","226.5621","10.9515","7.3010","54.3054"
"44.0000","10.9715","226.8596","10.9715","7.3143","54.3767"
"44.0800","10.9924","227.1590","10.9924","7.3282","54.4485"
"44.1600","11.0112","227.4153","11.0112","7.3408","54.5099"
"44.2400","11.0327","227.7351","11.0327","7.3551","54.5865"
"44.3200","11.0523","228.0104","11.0523","7.3682","54.6525"
"44.4000","11.0726","228.3009","11.0726","7.3817","54.7222"
"44.4800","11.0919","228.5634","11.0919","7.3946","54.7851"
"44.5600","11.1115","228.8320","11.1115","7.4077","54.8495"
"44.6400","11.1316","229.1194","11.1316","7.4210","54.9184"
"44.7200","11.1520","229.4083","11.1520","7.4346","54.9876"
"44.8000","11.1705","229.6565","11.1705","7.4470","55.0471"
"44.8800","11.1922","229.9899","11.1922","7.4614","55.1270"
"44.9600","11.2127","230.2668","11.2127","7.4751","55.1934"
"45.0400","11.2329","230.5379","11.2329","7.4886","55.2584"
"45.1200","11.2516","230.7749","11.2516","7.5010","55.3152"
"45.2000","11.2712","231.0315","11.2712","7.5141","55.3767"
"45.2800","11.2922","231.3320","11.2922","7.5281","55.4487"
"45.3600","11.3121","231.5989","11.3121","7.5414","55.5127"
"45.4400","11.3317","231.8629","11.3317","7.5545","55.5760"
"45.5200","11.3527","232.1586","11.3527","7.5684","55.6468"
"45.6000","11.3720","232.3848","11.3720","7.5813","55.7010"
"45.6800","11.3927","232.6691","11.3927","7.5951","55.7692"
"45.7600","11.4127","232.9364","11.4127","7.6085","55.8333"
"45.8400","11.4312","233.1610","11.4312","7.6208","55.8871"
"45.9200","11.4518","233.4420","11.4518","7.6345","55.9545"
"46.0000","11.4707","233.6661","11.4707","7.6471","56.0082"
"46.0800","11.4919","233.9656","11.4919","7.6612","56.0800"
"46.1600","11.5124","234.2419","11.5124","7.6749","56.1462"
"46.2400","11.5323","234.4778","11.5323","7.6882","56.2027"
"46.3200","11.5520","234.7255","11.5520","7.7013","56.2621"
"46.4000","11.5719","234.9812","11.5719","7.7146","56.3234"
"46.4800","11.5914","235.2257","11.5914","7.7276","56.3820"
"46.5600","11.6123","235.5160","11.6123","7.7415","56.4516"
"46.6400","11.6311","235.7332","11.6311","7.7540","56.5037"
"46.7200","11.6526","236.0159","11.6526","7.7684","56.5714"
"46.8000","11.6731","236.2795","11.6731","7.7821","56.6346"
"46.8800","11.6923","236.5037","11.6923","7.7949","56.6883"
"46.9600","11.7119","236.7392","11.7119","7.8079","56.7448"
"47.0400","11.7317","236.9716","11.7317","7.8211","56.8005"
"47.1200","11.7515","237.2053","11.7515","7.8343","56.8565"
"47.2000","11.7718","237.4598","11.7718","7.8479","56.9175"
"47.2800","11.7910","237.6758","11.7910","7.8607","56.9693"
"47.3600","11.8122","237.9490","11.8122","7.8748","57.0348"
"47.4400","11.8326","238.1902","11.8326","7.8884","57.0926"
"47.5200","11.8515","238.3948","11.8515","7.9010","57.1416"
"47.6000","11.8722","238.6622","11.8722","7.9148","57.2057"
"47.6800","11.8914","238.8701","11.8914","7.9276","57.2555"
"47.7600","11.9122","239.1201","11.9122","7.9415","57.3155"
"47.8400","11.9321","239.3467","11.9321","7.9547","57.3698"
"47.9200","11.9514","239.5603","11.9514","7.9676","57.4210"
"48.0000","11.9723","239.8146","11.9723","7.9815","57.4819"
"48.0800","11.9932","240.0620","11.9932","7.9955","57.5412"
"48.1600","12.0125","240.2609","12.0125","8.0083","57.5889"
"48.2400","12.0323","240.4769","12.0323","8.0215","57.6407"
"48.3200","12.0509","240.6648","12.0509","8.0339","57.6857"
"48.4000","12.0722","240.9213","12.0722","8.0481","57.7472"
"48.4800","12.0916","241.1212","12.0916","8.0611","57.7951"
"48.5600","12.1118","241.3492","12.1118","8.0745","57.8498"
"48.6400","12.1319","241.5772","12.1319","8.0880","57.9044"
"48.7200","12.1520","241.7746","12.1520","8.1013","57.9517"
"48.8000","12.1721","241.9935","12.1721","8.1147","58.0042"
"48.8800","12.1927","242.2068","12.1927","8.1285","58.0553"
"48.9600","12.2113","242.3892","12.2113","8.1409","58.0990"
"49.0400","12.2318","242.6095","12.2318","8.1545","58.1518"
"49.1200","12.2517","242.8111","12.2517","8.1678","58.2002"
"49.2000","12.2721","243.0419","12.2721","8.1814","58.2555"
"49.2800","12.2932","243.2683","12.2932","8.1955","58.3098"
"49.3600","12.3124","243.4401","12.3124","8.2083","58.3509"
"49.4400","12.3323","243.6265","12.3323","8.2215","58.3956"
"49.5200","12.3518","243.8129","12.3518","8.2345","58.4403"
"49.6000","12.3715","244.0070","12.3715","8.2477","58.4868"
"49.6800","12.3917","244.2215","12.3917","8.2612","58.5382"
"49.7600","12.4110","244.3872","12.4110","8.2740","58.5779"
"49.8400","12.4315","244.5966","12.4315","8.2877","58.6281"
"49.9200","12.4526","244.8090","12.4526","8.3017","58.6791"
"50.0000","12.4721","245.0027","12.4721","8.3147","58.7255"
"50.0800","12.4929","245.1994","12.4929","8.3286","58.7726"
"50.1600","12.5115","245.3428","12.5115","8.3410","58.8070"
"50.2400","12.5317","245.5210","12.5317","8.3545","58.8497"
"50.3200","12.5511","245.7023","12.5511","8.3674","58.8932"
"50.4000","12.5712","245.8772","12.5712","8.3808","58.9351"
"50.4800","12.5922","246.0809","12.5922","8.3948","58.9839"
"50.5600","12.6138","246.2956","12.6138","8.4092","59.0354"
"50.6400","12.6325","246.4529","12.6325","8.4217","59.0731"
"50.7200","12.6523","246.6167","12.6523","8.4348","59.1123"
"50.8000","12.6710","246.7542","12.6710","8.4473","59.1453"
"50.8800","12.6923","246.9591","12.6923","8.4616","59.1944"
"50.9600","12.7121","247.1195","12.7121","8.4747","59.2329"
"51.0400","12.7309","247.2616","12.7309","8.4873","59.2669"
"51.1200","12.7516","247.4536","12.7516","8.5011","59.3129"
"51.2000","12.7722","247.6360","12.7722","8.5148","59.3567"
"51.2800","12.7927","247.8221","12.7927","8.5285","59.4013"
"51.3600","12.8125","247.9803","12.8125","8.5417","59.4392"
"51.4400","12.8312","248.1044","12.8312","8.5541","59.4689"
"51.5200","12.8516","248.2788","12.8516","8.5677","59.5107"
"51.6000","12.8719","248.4437","12.8719","8.5813","59.5503"
"51.6800","12.8918","248.6124","12.8918","8.5945","59.5907"
"51.7600","12.9130","248.7915","12.9130","8.6086","59.6336"
"51.8400","12.9322","248.9342","12.9322","8.6215","59.6678"
"51.9200","12.9527","249.0902","12.9527","8.6352","59.7052"
"52.0000","12.9721","249.2307","12.9721","8.6481","59.7389"
"52.0800","12.9917","249.3679","12.9917","8.6612","59.7718"
"52.1600","13.0116","249.5131","13.0116","8.6744","59.8066"
"52.2400","13.0317","249.6808","13.0317","8.6878","59.8468"
"52.3200","13.0511","249.8138","13.0511","8.7007","59.8787"
"52.4000","13.0726","249.9927","13.0726","8.7150","59.9215"
"52.4800","13.0923","250.1256","13.0923","8.7282","59.9534"
"52.5600","13.1130","250.2675","13.1130","8.7420","59.9874"
"52.6400","13.1318","250.3820","13.1318","8.7545","60.0149"
"52.7200","13.1512","250.5105","13.1512","8.7674","60.0456"
"52.8000","13.1714","250.6560","13.1714","8.7810","60.0805"
"52.8800","13.1915","250.7943","13.1915","8.7943","60.1137"
"52.9600","13.2121","250.9409","13.2121","8.8081","60.1488"
"53.0400","13.2330","251.0872","13.2330","8.8220","60.1839"
"53.1200","13.2523","251.1981","13.2523","8.8349","60.2105"
"53.2000","13.2725","251.3249","13.2725","8.8484","60.2409"
"53.2800","13.2919","251.4351","13.2919","8.8612","60.2673"
"53.3600","13.3120","251.5751","13.3120","8.8747","60.3008"
"53.4400","13.3320","251.6967","13.3320","8.8880","60.3300"
"53.5200","13.3504","251.7955","13.3504","8.9003","60.3537"
"53.6000","13.3718","251.9454","13.3718","8.9145","60.3896"
"53.6800","13.3928","252.0863","13.3928","8.9286","60.4234"
"53.7600","13.4124","252.2084","13.4124","8.9416","60.4526"
"53.8400","13.4320","252.3140","13.4320","8.9547","60.4779"
"53.9200","13.4516","252.4177","13.4516","8.9677","60.5028"
"54.0000","13.4715","252.5412","13.4715","8.9810","60.5324"
"54.0800","13.4923","252.6667","13.4923","8.9949","60.5625"
"54.1600","13.5113","252.7628","13.5113","9.0075","60.5855"
"54.2400","13.5324","252.9073","13.5324","9.0216","60.6202"
"54.3200","13.5525","253.0265","13.5525","9.0350","60.6487"
"54.4000","13.5725","253.1372","13.5725","9.0483","60.6753"
"54.4800","13.5919","253.2381","13.5919","9.0612","60.6994"
"54.5600","13.6117","253.3374","13.6117","9.0745","60.7232"
"54.6400","13.6321","253.4565","13.6321","9.0880","60.7518"
"54.7200","13.6519","253.5518","13.6519","9.1012","60.7746"
"54.8000","13.6706","253.6319","13.6706","9.1137","60.7938"
"54.8800","13.6921","253.7897","13.6921","9.1281","60.8317"
"54.9600","13.7124","253.8848","13.7124","9.1416","60.8545"
"55.0400","13.7326","253.9937","13.7326","9.1551","60.8806"
"55.1200","13.7520","254.0840","13.7520","9.1680","60.9022"
"55.2000","13.7710","254.1606","13.7711","9.1807","60.9206"
"55.2800","13.7918","254.2664","13.7918","9.1946","60.9459"
"55.3600","13.8116","254.3535","13.8116","9.2077","60.9668"
"55.4400","13.8313","254.4429","13.8313","9.2208","60.9882"
"55.5200","13.8527","254.5677","13.8527","9.2352","61.0181"
"55.6000","13.8725","254.6540","13.8725","9.2483","61.0388"
"55.6800","13.8926","254.7502","13.8926","9.2618","61.0619"
"55.7600","13.9128","254.8331","13.9128","9.2752","61.0818"
"55.8400","13.9316","254.9045","13.9316","9.2878","61.0989"
"55.9200","13.9516","254.9847","13.9516","9.3011","61.1181"
"56.0000","13.9706","255.0447","13.9706","9.3137","61.1325"
"56.0800","13.9918","255.1708","13.9918","9.3279","61.1627"
"56.1600","14.0125","255.2635","14.0125","9.3417","61.1849"
"56.2400","14.0323","255.3383","14.0323","9.3549","61.2029"
"56.3200","14.0521","255.4023","14.0521","9.3681","61.2182"
"56.4000","14.0719","255.4881","14.0719","9.3813","61.2388"
"56.4800","14.0913","255.5601","14.0913","9.3942","61.2560"
"56.5600","14.1123","255.6660","14.1123","9.4082","61.2814"
"56.6400","14.1311","255.7064","14.1311","9.4208","61.2911"
"56.7200","14.1525","255.8069","14.1525","9.4350","61.3152"
"56.8000","14.1729","255.8882","14.1729","9.4486","61.3347"
"56.8800","14.1926","255.9582","14.1926","9.4617","61.3514"
"56.9600","14.2121","256.0243","14.2121","9.4748","61.3673"
"57.0400","14.2316","256.0830","14.2316","9.4877","61.3814"
"57.1200","14.2513","256.1443","14.2513","9.5009","61.3960"
"57.2000","14.2717","256.2329","14.2717","9.5144","61.4173"
"57.2800","14.2908","256.2809","14.2908","9.5272","61.4288"
"57.3600","14.3120","256.3766","14.3120","9.5413","61.4517"
"57.4400","14.3324","256.4495","14.3324","9.5550","61.4692"
"57.5200","14.3521","256.5050","14.3521","9.5681","61.4825"
"57.6000","14.3721","256.5763","14.3721","9.5814","61.4996"
"57.6800","14.3913","256.6060","14.3913","9.5942","61.5067"
"57.7600","14.4124","256.7030","14.4124","9.6083","61.5300"
"57.8400","14.4320","256.7392","14.4320","9.6214","61.5386"
"57.9200","14.4512","256.7884","14.4512","9.6341","61.5504"
"58.0000","14.4721","256.8731","14.4721","9.6481","61.5707"
"58.0800","14.4924","256.9300","14.4924","9.6616","61.5844"
"58.1600","14.5126","256.9903","14.5126","9.6750","61.5988"
"58.2400","14.5323","257.0299","14.5323","9.6882","61.6083"
"58.3200","14.5513","257.0550","14.5513","9.7009","61.6143"
"58.4000","14.5720","257.1244","14.5720","9.7147","61.6310"
"58.4800","14.5917","257.1660","14.5917","9.7278","61.6409"
"58.5600","14.6113","257.2170","14.6113","9.7408","61.6532"
"58.6400","14.6320","257.2820","14.6320","9.7546","61.6687"
"58.7200","14.6519","257.3264","14.6519","9.7679","61.6794"
"58.8000","14.6724","257.3903","14.6724","9.7816","61.6947"
"58.8800","14.6927","257.4307","14.6927","9.7951","61.7044"
"58.9600","14.7117","257.4704","14.7117","9.8078","61.7139"
"59.0400","14.7317","257.5127","14.7317","9.8211","61.7240"
"59.1200","14.7512","257.5535","14.7512","9.8341","61.7338"
"59.2000","14.7720","257.6133","14.7720","9.8480","61.7482"
"59.2800","14.7932","257.6875","14.7932","9.8621","61.7659"
"59.3600","14.8126","257.7129","14.8126","9.8751","61.7720"
"59.4400","14.8323","257.7491","14.8323","9.8882","61.7807"
"59.5200","14.8518","257.7755","14.8518","9.9012","61.7870"
"59.6000","14.8713","257.8197","14.8713","9.9142","61.7976"
"59.6800","14.8918","257.8764","14.8918","9.9279","61.8112"
"59.7600","14.9111","257.8831","14.9111","9.9407","61.8128"
"59.8400","14.9314","257.9345","14.9314","9.9543","61.8251"
"59.9200","14.9528","257.9996","14.9528","9.9685","61.8408"
"60.0000","14.9721","258.0268","14.9721","9.9814","61.8473"
"60.0800","14.9921","258.0691","14.9921","9.9947","61.8574"
"60.1120","15.0000","258.0851","15.0000","10.0000","61.8612"