File: data/instron_tests/metamaterials/250327/250327_1467_BULK_m2_NoTransition.is_comp_Exports/250327_1467_BULK_m2_NoTransition_6_1.csv
Results Table 1
,Compression Axis,H*,V*,Height,Thickness,Width,Area,Fixture separation,Specimen label
,,,,(mm),(mm),(mm),(mm^2),(mm),
"6","X","","","149.00","28.00","149.00","4172.00","150.00","1467_BULK_m2_NoTransition"

Results Table 2
,Modulus (Segment 0 % - 5 %),Compression Axis
,(kPa),
"6","812.02","X"

Time,Displacement,Force,Compressive displacement,Compressive strain (Displacement),Compressive stress
(s),(mm),(N),(mm),(%),(kPa)
"0.0000","0.0000","-21.7408","0.0000","0.0000","-5.2111"
"0.0800","0.0012","-21.6761","0.0012","0.0008","-5.1956"
"0.1600","0.0173","-21.1509","0.0173","0.0115","-5.0697"
"0.2400","0.0384","-20.5705","0.0384","0.0256","-4.9306"
"0.3200","0.0581","-20.0060","0.0581","0.0387","-4.7953"
"0.4000","0.0774","-19.4673","0.0774","0.0516","-4.6662"
"0.4800","0.0981","-18.8923","0.0981","0.0654","-4.5284"
"0.5600","0.1183","-18.3589","0.1183","0.0788","-4.4005"
"0.6400","0.1379","-17.8311","0.1379","0.0920","-4.2740"
"0.7200","0.1574","-17.3207","0.1574","0.1049","-4.1517"
"0.8000","0.1763","-16.8161","0.1763","0.1175","-4.0307"
"0.8800","0.1973","-16.2610","0.1973","0.1315","-3.8977"
"0.9600","0.2174","-15.7368","0.2174","0.1449","-3.7720"
"1.0400","0.2364","-15.2354","0.2364","0.1576","-3.6518"
"1.1200","0.2571","-14.6913","0.2571","0.1714","-3.5214"
"1.2000","0.2774","-14.1806","0.2774","0.1849","-3.3990"
"1.2800","0.2981","-13.6379","0.2981","0.1987","-3.2689"
"1.3600","0.3179","-13.1353","0.3179","0.2119","-3.1484"
"1.4400","0.3364","-12.6451","0.3364","0.2243","-3.0309"
"1.5200","0.3569","-12.1236","0.3569","0.2379","-2.9059"
"1.6000","0.3774","-11.6016","0.3774","0.2516","-2.7808"
"1.6800","0.3976","-11.0756","0.3976","0.2651","-2.6547"
"1.7600","0.4186","-10.5551","0.4186","0.2790","-2.5300"
"1.8400","0.4375","-10.0766","0.4375","0.2917","-2.4153"
"1.9200","0.4576","-9.5687","0.4576","0.3051","-2.2935"
"2.0000","0.4775","-9.0710","0.4775","0.3183","-2.1743"
"2.0800","0.4966","-8.6194","0.4966","0.3310","-2.0660"
"2.1600","0.5169","-8.0973","0.5169","0.3446","-1.9409"
"2.2400","0.5361","-7.6132","0.5361","0.3574","-1.8248"
"2.3200","0.5571","-7.0743","0.5571","0.3714","-1.6957"
"2.4000","0.5783","-6.5420","0.5783","0.3855","-1.5681"
"2.4800","0.5978","-6.0495","0.5978","0.3986","-1.4500"
"2.5600","0.6177","-5.5760","0.6177","0.4118","-1.3365"
"2.6400","0.6366","-5.1195","0.6366","0.4244","-1.2271"
"2.7200","0.6568","-4.5867","0.6568","0.4379","-1.0994"
"2.8000","0.6772","-4.0776","0.6772","0.4515","-0.9774"
"2.8800","0.6968","-3.5853","0.6968","0.4646","-0.8594"
"2.9600","0.7178","-3.0559","0.7178","0.4785","-0.7325"
"3.0400","0.7383","-2.5488","0.7383","0.4922","-0.6109"
"3.1200","0.7574","-2.0802","0.7574","0.5049","-0.4986"
"3.2000","0.7776","-1.5715","0.7776","0.5184","-0.3767"
"3.2800","0.7970","-1.0934","0.7970","0.5313","-0.2621"
"3.3600","0.8179","-0.5741","0.8179","0.5453","-0.1376"
"3.4400","0.8375","-0.1016","0.8375","0.5583","-0.0244"
"3.5200","0.8553","0.3427","0.8553","0.5702","0.0821"
"3.6000","0.8768","0.8900","0.8768","0.5845","0.2133"
"3.6800","0.8985","1.4377","0.8985","0.5990","0.3446"
"3.7600","0.9180","1.9085","0.9180","0.6120","0.4575"
"3.8400","0.9373","2.3924","0.9373","0.6249","0.5735"
"3.9200","0.9564","2.8453","0.9564","0.6376","0.6820"
"4.0000","0.9771","3.3661","0.9771","0.6514","0.8068"
"4.0800","0.9975","3.8652","0.9975","0.6650","0.9265"
"4.1600","1.0168","4.3429","1.0168","0.6779","1.0410"
"4.2400","1.0379","4.8750","1.0379","0.6919","1.1685"
"4.3200","1.0575","5.3376","1.0575","0.7050","1.2794"
"4.4000","1.0780","5.8361","1.0780","0.7187","1.3989"
"4.4800","1.0981","6.3302","1.0981","0.7321","1.5173"
"4.5600","1.1170","6.7884","1.1170","0.7447","1.6271"
"4.6400","1.1370","7.2928","1.1370","0.7580","1.7480"
"4.7200","1.1566","7.7635","1.1566","0.7711","1.8609"
"4.8000","1.1766","8.2473","1.1766","0.7844","1.9768"
"4.8800","1.1980","8.7745","1.1980","0.7987","2.1032"
"4.9600","1.2173","9.2350","1.2173","0.8115","2.2136"
"5.0400","1.2377","9.7373","1.2377","0.8251","2.3340"
"5.1200","1.2572","10.2140","1.2572","0.8381","2.4482"
"5.2000","1.2767","10.7014","1.2767","0.8511","2.5651"
"5.2800","1.2972","11.1980","1.2972","0.8648","2.6841"
"5.3600","1.3169","11.6733","1.3169","0.8779","2.7980"
"5.4400","1.3375","12.1730","1.3375","0.8917","2.9178"
"5.5200","1.3583","12.6786","1.3583","0.9055","3.0390"
"5.6000","1.3776","13.1580","1.3776","0.9184","3.1539"
"5.6800","1.3981","13.6484","1.3981","0.9321","3.2714"
"5.7600","1.4175","14.1127","1.4175","0.9450","3.3827"
"5.8400","1.4370","14.5878","1.4370","0.9580","3.4966"
"5.9200","1.4570","15.0717","1.4570","0.9713","3.6126"
"6.0000","1.4761","15.5303","1.4761","0.9841","3.7225"
"6.0800","1.4973","16.0465","1.4973","0.9982","3.8462"
"6.1600","1.5183","16.5604","1.5183","1.0122","3.9694"
"6.2400","1.5377","17.0217","1.5377","1.0251","4.0800"
"6.3200","1.5572","17.4990","1.5572","1.0381","4.1944"
"6.4000","1.5766","17.9628","1.5766","1.0511","4.3056"
"6.4800","1.5974","18.4747","1.5974","1.0649","4.4283"
"6.5600","1.6179","18.9581","1.6179","1.0786","4.5441"
"6.6400","1.6358","19.3936","1.6358","1.0905","4.6485"
"6.7200","1.6578","19.9413","1.6578","1.1052","4.7798"
"6.8000","1.6785","20.4378","1.6785","1.1190","4.8988"
"6.8800","1.6985","20.9175","1.6985","1.1323","5.0138"
"6.9600","1.7171","21.3542","1.7171","1.1447","5.1184"
"7.0400","1.7367","21.8180","1.7367","1.1578","5.2296"
"7.1200","1.7567","22.2966","1.7567","1.1711","5.3443"
"7.2000","1.7773","22.8006","1.7773","1.1849","5.4651"
"7.2800","1.7965","23.2586","1.7965","1.1976","5.5749"
"7.3600","1.8179","23.7930","1.8179","1.2119","5.7030"
"7.4400","1.8373","24.2419","1.8373","1.2248","5.8106"
"7.5200","1.8575","24.7253","1.8575","1.2383","5.9265"
"7.6000","1.8774","25.2093","1.8774","1.2516","6.0425"
"7.6800","1.8969","25.6682","1.8969","1.2646","6.1525"
"7.7600","1.9175","26.1734","1.9175","1.2783","6.2736"
"7.8400","1.9372","26.6418","1.9372","1.2915","6.3859"
"7.9200","1.9568","27.1135","1.9568","1.3045","6.4989"
"8.0000","1.9776","27.6257","1.9776","1.3184","6.6217"
"8.0800","1.9982","28.1039","1.9982","1.3321","6.7363"
"8.1600","2.0180","28.5832","2.0180","1.3454","6.8512"
"8.2400","2.0377","29.0375","2.0377","1.3585","6.9601"
"8.3200","2.0565","29.4954","2.0565","1.3710","7.0698"
"8.4000","2.0772","29.9945","2.0772","1.3848","7.1895"
"8.4800","2.0966","30.4415","2.0966","1.3977","7.2966"
"8.5600","2.1176","30.9465","2.1176","1.4118","7.4177"
"8.6400","2.1377","31.4188","2.1377","1.4251","7.5309"
"8.7200","2.1574","31.8903","2.1574","1.4383","7.6439"
"8.8000","2.1776","32.3693","2.1776","1.4517","7.7587"
"8.8800","2.1975","32.8358","2.1975","1.4650","7.8705"
"8.9600","2.2162","33.2833","2.2162","1.4775","7.9778"
"9.0400","2.2374","33.7839","2.2374","1.4916","8.0978"
"9.1200","2.2565","34.2342","2.2565","1.5044","8.2057"
"9.2000","2.2782","34.7529","2.2782","1.5188","8.3300"
"9.2800","2.2989","35.2285","2.2989","1.5326","8.4440"
"9.3600","2.3177","35.6768","2.3177","1.5452","8.5515"
"9.4400","2.3370","36.1151","2.3370","1.5580","8.6565"
"9.5200","2.3570","36.5892","2.3570","1.5713","8.7702"
"9.6000","2.3773","37.0879","2.3773","1.5849","8.8897"
"9.6800","2.3976","37.5659","2.3976","1.5984","9.0043"
"9.7600","2.4160","37.9846","2.4160","1.6107","9.1046"
"9.8400","2.4372","38.4918","2.4372","1.6248","9.2262"
"9.9200","2.4578","38.9813","2.4578","1.6386","9.3435"
"10.0000","2.4777","39.4542","2.4777","1.6518","9.4569"
"10.0800","2.4981","39.9305","2.4981","1.6654","9.5711"
"10.1600","2.5168","40.3476","2.5168","1.6779","9.6710"
"10.2400","2.5369","40.8207","2.5369","1.6913","9.7845"
"10.3200","2.5571","41.2939","2.5571","1.7047","9.8979"
"10.4000","2.5766","41.7508","2.5766","1.7178","10.0074"
"10.4800","2.5981","42.2647","2.5981","1.7320","10.1306"
"10.5600","2.6184","42.7405","2.6184","1.7456","10.2446"
"10.6400","2.6382","43.1892","2.6382","1.7588","10.3522"
"10.7200","2.6576","43.6369","2.6576","1.7717","10.4595"
"10.8000","2.6764","44.0784","2.6764","1.7843","10.5653"
"10.8800","2.6976","44.5719","2.6976","1.7984","10.6836"
"10.9600","2.7171","45.0331","2.7171","1.8114","10.7941"
"11.0400","2.7364","45.4799","2.7364","1.8243","10.9012"
"11.1200","2.7568","45.9647","2.7568","1.8379","11.0174"
"11.2000","2.7779","46.4590","2.7779","1.8519","11.1359"
"11.2800","2.7980","46.9259","2.7980","1.8653","11.2478"
"11.3600","2.8180","47.3823","2.8180","1.8786","11.3572"
"11.4400","2.8363","47.7944","2.8363","1.8909","11.4560"
"11.5200","2.8565","48.2712","2.8565","1.9043","11.5703"
"11.6000","2.8769","48.7439","2.8769","1.9179","11.6836"
"11.6800","2.8980","49.2460","2.8980","1.9320","11.8039"
"11.7600","2.9188","49.7236","2.9188","1.9459","11.9184"
"11.8400","2.9375","50.1490","2.9375","1.9584","12.0204"
"11.9200","2.9575","50.6172","2.9575","1.9717","12.1326"
"12.0000","2.9776","51.0826","2.9776","1.9851","12.2442"
"12.0800","2.9970","51.5386","2.9970","1.9980","12.3535"
"12.1600","3.0170","52.0056","3.0170","2.0113","12.4654"
"12.2400","3.0363","52.4335","3.0363","2.0242","12.5679"
"12.3200","3.0570","52.9204","3.0570","2.0380","12.6847"
"12.4000","3.0783","53.4071","3.0783","2.0522","12.8013"
"12.4800","3.0974","53.8505","3.0974","2.0649","12.9076"
"12.5600","3.1179","54.3267","3.1179","2.0786","13.0217"
"12.6400","3.1369","54.7526","3.1369","2.0913","13.1238"
"12.7200","3.1568","55.2136","3.1568","2.1045","13.2343"
"12.8000","3.1771","55.6837","3.1771","2.1181","13.3470"
"12.8800","3.1969","56.1356","3.1969","2.1313","13.4553"
"12.9600","3.2175","56.6127","3.2175","2.1450","13.5697"
"13.0400","3.2386","57.1123","3.2386","2.1591","13.6894"
"13.1200","3.2576","57.5443","3.2576","2.1717","13.7930"
"13.2000","3.2777","58.0051","3.2777","2.1851","13.9034"
"13.2800","3.2969","58.4324","3.2969","2.1979","14.0058"
"13.3600","3.3175","58.9178","3.3175","2.2117","14.1222"
"13.4400","3.3373","59.3589","3.3373","2.2248","14.2279"
"13.5200","3.3559","59.7920","3.3559","2.2373","14.3317"
"13.6000","3.3772","60.2851","3.3772","2.2515","14.4499"
"13.6800","3.3980","60.7303","3.3980","2.2653","14.5566"
"13.7600","3.4178","61.1291","3.4178","2.2785","14.6522"
"13.8400","3.4377","61.5945","3.4377","2.2918","14.7638"
"13.9200","3.4565","62.0115","3.4565","2.3043","14.8637"
"14.0000","3.4773","62.4966","3.4773","2.3182","14.9800"
"14.0800","3.4976","62.9665","3.4976","2.3317","15.0926"
"14.1600","3.5167","63.4033","3.5167","2.3445","15.1973"
"14.2400","3.5379","63.8943","3.5379","2.3586","15.3150"
"14.3200","3.5577","64.3395","3.5577","2.3718","15.4217"
"14.4000","3.5781","64.8084","3.5781","2.3854","15.5341"
"14.4800","3.5978","65.2201","3.5978","2.3986","15.6328"
"14.5600","3.6169","65.6262","3.6169","2.4112","15.7301"
"14.6400","3.6371","66.0998","3.6371","2.4247","15.8437"
"14.7200","3.6565","66.5330","3.6565","2.4377","15.9475"
"14.8000","3.6763","66.9939","3.6763","2.4509","16.0580"
"14.8800","3.6979","67.5020","3.6979","2.4653","16.1798"
"14.9600","3.7174","67.9231","3.7174","2.4782","16.2807"
"15.0400","3.7377","68.3828","3.7377","2.4918","16.3909"
"15.1200","3.7572","68.8113","3.7572","2.5048","16.4936"
"15.2000","3.7764","69.2514","3.7764","2.5176","16.5991"
"15.2800","3.7971","69.7267","3.7971","2.5314","16.7130"
"15.3600","3.8169","70.1358","3.8169","2.5446","16.8111"
"15.4400","3.8373","70.5927","3.8373","2.5582","16.9206"
"15.5200","3.8585","71.0773","3.8585","2.5723","17.0368"
"15.6000","3.8775","71.5063","3.8775","2.5850","17.1396"
"15.6800","3.8977","71.9653","3.8977","2.5985","17.2496"
"15.7600","3.9174","72.4107","3.9174","2.6116","17.3564"
"15.8400","3.9371","72.8624","3.9371","2.6247","17.4646"
"15.9200","3.9571","73.3033","3.9571","2.6381","17.5703"
"16.0000","3.9759","73.7194","3.9759","2.6506","17.6700"
"16.0800","3.9975","74.2149","3.9975","2.6650","17.7888"
"16.1600","4.0184","74.6909","4.0184","2.6789","17.9029"
"16.2400","4.0377","75.0954","4.0377","2.6918","17.9999"
"16.3200","4.0573","75.5203","4.0573","2.7049","18.1017"
"16.4000","4.0769","75.9640","4.0769","2.7179","18.2080"
"16.4800","4.0973","76.4306","4.0973","2.7315","18.3199"
"16.5600","4.1179","76.8743","4.1179","2.7452","18.4262"
"16.6400","4.1365","77.3033","4.1365","2.7577","18.5291"
"16.7200","4.1579","77.7950","4.1579","2.7720","18.6469"
"16.8000","4.1779","78.2381","4.1779","2.7853","18.7531"
"16.8800","4.1978","78.6740","4.1978","2.7986","18.8576"
"16.9600","4.2175","79.1193","4.2175","2.8117","18.9644"
"17.0400","4.2368","79.5348","4.2368","2.8245","19.0640"
"17.1200","4.2566","79.9615","4.2566","2.8377","19.1662"
"17.2000","4.2774","80.4118","4.2774","2.8516","19.2742"
"17.2800","4.2964","80.8487","4.2964","2.8643","19.3789"
"17.3600","4.3175","81.3268","4.3175","2.8783","19.4935"
"17.4400","4.3372","81.7557","4.3372","2.8915","19.5963"
"17.5200","4.3574","82.1931","4.3574","2.9049","19.7011"
"17.6000","4.3775","82.6514","4.3775","2.9183","19.8110"
"17.6800","4.3969","83.0799","4.3969","2.9313","19.9137"
"17.7600","4.4174","83.5297","4.4174","2.9449","20.0215"
"17.8400","4.4374","83.9770","4.4374","2.9583","20.1287"
"17.9200","4.4567","84.4031","4.4567","2.9712","20.2308"
"18.0000","4.4776","84.8635","4.4776","2.9851","20.3412"
"18.0800","4.4982","85.3153","4.4982","2.9988","20.4495"
"18.1600","4.5180","85.7377","4.5180","3.0120","20.5507"
"18.2400","4.5376","86.1577","4.5376","3.0250","20.6514"
"18.3200","4.5563","86.5732","4.5563","3.0376","20.7510"
"18.4000","4.5775","87.0521","4.5775","3.0517","20.8658"
"18.4800","4.5965","87.4710","4.5965","3.0643","20.9662"
"18.5600","4.6173","87.9375","4.6173","3.0782","21.0780"
"18.6400","4.6375","88.3863","4.6375","3.0917","21.1856"
"18.7200","4.6574","88.8166","4.6574","3.1049","21.2887"
"18.8000","4.6775","89.2526","4.6775","3.1183","21.3932"
"18.8800","4.6977","89.6939","4.6977","3.1318","21.4990"
"18.9600","4.7168","90.1064","4.7168","3.1445","21.5979"
"19.0400","4.7373","90.5530","4.7373","3.1582","21.7049"
"19.1200","4.7561","90.9555","4.7561","3.1707","21.8014"
"19.2000","4.7779","91.4558","4.7779","3.1853","21.9213"
"19.2800","4.7985","91.9073","4.7985","3.1990","22.0296"
"19.3600","4.8181","92.3273","4.8181","3.2121","22.1302"
"19.4400","4.8372","92.7367","4.8372","3.2248","22.2283"
"19.5200","4.8570","93.1569","4.8570","3.2380","22.3291"
"19.6000","4.8771","93.6010","4.8771","3.2514","22.4355"
"19.6800","4.8978","94.0654","4.8978","3.2652","22.5468"
"19.7600","4.9162","94.4429","4.9162","3.2775","22.6373"
"19.8400","4.9373","94.9048","4.9373","3.2916","22.7480"
"19.9200","4.9580","95.3639","4.9580","3.3053","22.8581"
"20.0000","4.9777","95.7873","4.9777","3.3184","22.9596"
"20.0800","4.9979","96.2313","4.9979","3.3319","23.0660"
"20.1600","5.0164","96.6018","5.0164","3.3443","23.1548"
"20.2400","5.0369","97.0530","5.0369","3.3579","23.2629"
"20.3200","5.0573","97.5002","5.0573","3.3715","23.3701"
"20.4000","5.0768","97.9128","5.0768","3.3846","23.4690"
"20.4800","5.0978","98.3763","5.0978","3.3985","23.5801"
"20.5600","5.1183","98.8186","5.1183","3.4122","23.6861"
"20.6400","5.1377","99.2314","5.1377","3.4252","23.7851"
"20.7200","5.1576","99.6556","5.1576","3.4384","23.8868"
"20.8000","5.1766","100.0635","5.1766","3.4511","23.9845"
"20.8800","5.1977","100.5188","5.1977","3.4651","24.0937"
"20.9600","5.2169","100.9317","5.2169","3.4780","24.1926"
"21.0400","5.2360","101.3249","5.2360","3.4906","24.2869"
"21.1200","5.2562","101.7613","5.2562","3.5041","24.3915"
"21.2000","5.2777","102.2388","5.2777","3.5185","24.5060"
"21.2800","5.2982","102.6673","5.2982","3.5321","24.6087"
"21.3600","5.3181","103.0880","5.3181","3.5454","24.7095"
"21.4400","5.3362","103.4736","5.3362","3.5575","24.8019"
"21.5200","5.3568","103.9227","5.3568","3.5712","24.9096"
"21.6000","5.3768","104.3604","5.3768","3.5846","25.0145"
"21.6800","5.3977","104.8144","5.3977","3.5985","25.1233"
"21.7600","5.4186","105.2730","5.4186","3.6124","25.2332"
"21.8400","5.4378","105.6703","5.4378","3.6252","25.3284"
"21.9200","5.4576","106.0745","5.4576","3.6384","25.4253"
"22.0000","5.4775","106.5019","5.4775","3.6517","25.5278"
"22.0800","5.4970","106.9244","5.4970","3.6647","25.6291"
"22.1600","5.5176","107.3953","5.5176","3.6784","25.7419"
"22.2400","5.5363","107.7677","5.5363","3.6908","25.8312"
"22.3200","5.5566","108.2153","5.5566","3.7044","25.9385"
"22.4000","5.5782","108.6839","5.5782","3.7188","26.0508"
"22.4800","5.5976","109.1037","5.5976","3.7317","26.1514"
"22.5600","5.6179","109.5325","5.6179","3.7453","26.2542"
"22.6400","5.6366","109.9084","5.6366","3.7577","26.3443"
"22.7200","5.6568","110.3399","5.6568","3.7712","26.4477"
"22.8000","5.6771","110.7818","5.6771","3.7847","26.5537"
"22.8800","5.6970","111.1940","5.6970","3.7980","26.6524"
"22.9600","5.7174","111.6439","5.7174","3.8116","26.7603"
"23.0400","5.7384","112.0939","5.7384","3.8256","26.8681"
"23.1200","5.7574","112.4895","5.7574","3.8383","26.9630"
"23.2000","5.7777","112.9235","5.7777","3.8518","27.0670"
"23.2800","5.7967","113.3122","5.7967","3.8645","27.1602"
"23.3600","5.8175","113.7613","5.8175","3.8783","27.2678"
"23.4400","5.8372","114.1561","5.8372","3.8915","27.3624"
"23.5200","5.8556","114.5465","5.8556","3.9038","27.4560"
"23.6000","5.8775","115.0393","5.8775","3.9183","27.5741"
"23.6800","5.8986","115.4901","5.8986","3.9324","27.6822"
"23.7600","5.9179","115.8915","5.9179","3.9452","27.7784"
"23.8400","5.9379","116.3158","5.9379","3.9586","27.8801"
"23.9200","5.9567","116.6943","5.9567","3.9711","27.9708"
"24.0000","5.9770","117.1338","5.9770","3.9847","28.0762"
"24.0800","5.9975","117.5584","5.9975","3.9983","28.1780"
"24.1600","6.0171","117.9747","6.0171","4.0114","28.2777"
"24.2400","6.0381","118.4314","6.0381","4.0254","28.3872"
"24.3200","6.0575","118.8236","6.0575","4.0384","28.4812"
"24.4000","6.0782","119.2626","6.0782","4.0521","28.5864"
"24.4800","6.0979","119.6792","6.0979","4.0653","28.6863"
"24.5600","6.1171","120.0772","6.1171","4.0780","28.7817"
"24.6400","6.1371","120.5013","6.1371","4.0914","28.8833"
"24.7200","6.1566","120.9059","6.1566","4.1044","28.9803"
"24.8000","6.1764","121.3189","6.1764","4.1176","29.0793"
"24.8800","6.1981","121.8018","6.1981","4.1321","29.1951"
"24.9600","6.2174","122.1823","6.2174","4.1450","29.2863"
"25.0400","6.2378","122.6133","6.2378","4.1585","29.3896"
"25.1200","6.2571","123.0180","6.2571","4.1714","29.4866"
"25.2000","6.2769","123.4441","6.2769","4.1846","29.5887"
"25.2800","6.2971","123.8756","6.2971","4.1981","29.6921"
"25.3600","6.3168","124.2805","6.3168","4.2112","29.7892"
"25.4400","6.3372","124.7023","6.3372","4.2248","29.8903"
"25.5200","6.3586","125.1584","6.3586","4.2390","29.9996"
"25.6000","6.3777","125.5528","6.3777","4.2518","30.0941"
"25.6800","6.3972","125.9536","6.3972","4.2648","30.1902"
"25.7600","6.4175","126.3758","6.4175","4.2783","30.2914"
"25.8400","6.4373","126.7988","6.4373","4.2915","30.3928"
"25.9200","6.4575","127.2165","6.4575","4.3050","30.4929"
"26.0000","6.4761","127.5937","6.4761","4.3174","30.5834"
"26.0800","6.4977","128.0523","6.4977","4.3318","30.6933"
"26.1600","6.5185","128.4906","6.5185","4.3456","30.7983"
"26.2400","6.5376","128.8749","6.5376","4.3584","30.8904"
"26.3200","6.5570","129.2787","6.5570","4.3713","30.9872"
"26.4000","6.5768","129.6923","6.5768","4.3846","31.0864"
"26.4800","6.5974","130.1316","6.5974","4.3983","31.1917"
"26.5600","6.6180","130.5443","6.6180","4.4120","31.2906"
"26.6400","6.6367","130.9292","6.6367","4.4245","31.3828"
"26.7200","6.6577","131.3810","6.6577","4.4385","31.4911"
"26.8000","6.6777","131.7937","6.6777","4.4518","31.5901"
"26.8800","6.6979","132.2099","6.6979","4.4653","31.6898"
"26.9600","6.7174","132.6131","6.7174","4.4783","31.7865"
"27.0400","6.7367","132.9921","6.7367","4.4911","31.8773"
"27.1200","6.7568","133.4079","6.7568","4.5045","31.9770"
"27.2000","6.7773","133.8436","6.7773","4.5182","32.0814"
"27.2800","6.7963","134.2416","6.7963","4.5309","32.1768"
"27.3600","6.8177","134.6966","6.8177","4.5451","32.2859"
"27.4400","6.8373","135.0886","6.8373","4.5582","32.3798"
"27.5200","6.8574","135.5081","6.8574","4.5716","32.4804"
"27.6000","6.8778","135.9304","6.8778","4.5852","32.5816"
"27.6800","6.8970","136.3203","6.8970","4.5980","32.6751"
"27.7600","6.9171","136.7305","6.9171","4.6114","32.7734"
"27.8400","6.9371","137.1491","6.9371","4.6247","32.8737"
"27.9200","6.9570","137.5573","6.9570","4.6380","32.9716"
"28.0000","6.9782","138.0086","6.9782","4.6521","33.0797"
"28.0800","6.9978","138.3865","6.9978","4.6652","33.1703"
"28.1600","7.0177","138.8038","7.0177","4.6785","33.2703"
"28.2400","7.0380","139.2114","7.0380","4.6920","33.3680"
"28.3200","7.0566","139.5915","7.0566","4.7044","33.4591"
"28.4000","7.0773","140.0243","7.0773","4.7182","33.5629"
"28.4800","7.0965","140.4069","7.0965","4.7310","33.6546"
"28.5600","7.1173","140.8399","7.1173","4.7449","33.7584"
"28.6400","7.1377","141.2504","7.1377","4.7584","33.8568"
"28.7200","7.1574","141.6530","7.1574","4.7716","33.9533"
"28.8000","7.1775","142.0669","7.1775","4.7850","34.0525"
"28.8800","7.1977","142.4697","7.1977","4.7985","34.1490"
"28.9600","7.2167","142.8487","7.2167","4.8111","34.2399"
"29.0400","7.2371","143.2731","7.2371","4.8247","34.3416"
"29.1200","7.2564","143.6549","7.2564","4.8376","34.4331"
"29.2000","7.2781","144.1081","7.2781","4.8521","34.5417"
"29.2800","7.2986","144.5223","7.2986","4.8657","34.6410"
"29.3600","7.3181","144.9068","7.3181","4.8787","34.7332"
"29.4400","7.3374","145.3025","7.3374","4.8916","34.8280"
"29.5200","7.3568","145.6867","7.3568","4.9045","34.9201"
"29.6000","7.3770","146.0999","7.3770","4.9180","35.0191"
"29.6800","7.3975","146.5118","7.3975","4.9317","35.1179"
"29.7600","7.4162","146.8758","7.4162","4.9441","35.2051"
"29.8400","7.4370","147.3095","7.4370","4.9580","35.3091"
"29.9200","7.4580","147.7359","7.4580","4.9720","35.4113"
"30.0000","7.4779","148.1384","7.4779","4.9853","35.5078"
"30.0800","7.4981","148.5330","7.4981","4.9987","35.6023"
"30.1600","7.5165","148.8808","7.5165","5.0110","35.6857"
"30.2400","7.5371","149.2878","7.5371","5.0247","35.7833"
"30.3200","7.5570","149.6866","7.5570","5.0380","35.8789"
"30.4000","7.5765","150.0782","7.5765","5.0510","35.9727"
"30.4800","7.5980","150.5241","7.5980","5.0653","36.0796"
"30.5600","7.6186","150.9402","7.6186","5.0791","36.1793"
"30.6400","7.6385","151.3428","7.6385","5.0923","36.2758"
"30.7200","7.6579","151.7087","7.6579","5.1053","36.3635"
"30.8000","7.6762","152.0604","7.6762","5.1174","36.4478"
"30.8800","7.6972","152.4943","7.6972","5.1315","36.5518"
"30.9600","7.7173","152.8987","7.7173","5.1448","36.6488"
"31.0400","7.7364","153.2745","7.7364","5.1576","36.7389"
"31.1200","7.7571","153.7039","7.7571","5.1714","36.8418"
"31.2000","7.7776","154.1107","7.7776","5.1851","36.9393"
"31.2800","7.7979","154.5154","7.7979","5.1986","37.0363"
"31.3600","7.8182","154.9185","7.8182","5.2121","37.1329"
"31.4400","7.8365","155.2640","7.8365","5.2243","37.2157"
"31.5200","7.8569","155.6743","7.8569","5.2379","37.3141"
"31.6000","7.8768","156.0752","7.8768","5.2512","37.4102"
"31.6800","7.8980","156.5096","7.8980","5.2653","37.5143"
"31.7600","7.9186","156.9182","7.9186","5.2791","37.6122"
"31.8400","7.9378","157.2853","7.9378","5.2919","37.7002"
"31.9200","7.9578","157.6833","7.9578","5.3052","37.7956"
"32.0000","7.9776","158.0765","7.9776","5.3184","37.8899"
"32.0800","7.9968","158.4566","7.9968","5.3312","37.9810"
"32.1600","8.0171","158.8620","8.0171","5.3448","38.0781"
"32.2400","8.0364","159.2258","8.0364","5.3576","38.1653"
"32.3200","8.0567","159.6383","8.0567","5.3712","38.2642"
"32.4000","8.0782","160.0683","8.0782","5.3855","38.3673"
"32.4800","8.0977","160.4480","8.0977","5.3984","38.4583"
"32.5600","8.1177","160.8477","8.1177","5.4118","38.5541"
"32.6400","8.1362","161.1897","8.1362","5.4242","38.6361"
"32.7200","8.1569","161.6019","8.1569","5.4379","38.7349"
"32.8000","8.1769","162.0055","8.1769","5.4512","38.8316"
"32.8800","8.1971","162.3974","8.1971","5.4647","38.9255"
"32.9600","8.2179","162.8137","8.2179","5.4786","39.0253"
"33.0400","8.2382","163.2085","8.2382","5.4921","39.1200"
"33.1200","8.2571","163.5694","8.2571","5.5047","39.2065"
"33.2000","8.2779","163.9910","8.2779","5.5186","39.3075"
"33.2800","8.2969","164.3437","8.2969","5.5313","39.3921"
"33.3600","8.3176","164.7555","8.3176","5.5450","39.4908"
"33.4400","8.3374","165.1408","8.3374","5.5582","39.5831"
"33.5200","8.3560","165.4986","8.3560","5.5706","39.6689"
"33.6000","8.3769","165.9167","8.3769","5.5846","39.7691"
"33.6800","8.3982","166.3384","8.3982","5.5988","39.8702"
"33.7600","8.4178","166.6978","8.4178","5.6119","39.9563"
"33.8400","8.4376","167.0829","8.4376","5.6251","40.0486"
"33.9200","8.4564","167.4312","8.4564","5.6376","40.1321"
"34.0000","8.4773","167.8493","8.4773","5.6515","40.2323"
"34.0800","8.4975","168.2307","8.4975","5.6650","40.3237"
"34.1600","8.5170","168.6052","8.5170","5.6780","40.4135"
"34.2400","8.5377","169.0219","8.5377","5.6918","40.5134"
"34.3200","8.5577","169.3920","8.5577","5.7051","40.6021"
"34.4000","8.5782","169.7900","8.5782","5.7188","40.6975"
"34.4800","8.5978","170.1541","8.5978","5.7319","40.7848"
"34.5600","8.6169","170.5090","8.6169","5.7446","40.8698"
"34.6400","8.6368","170.8934","8.6368","5.7579","40.9620"
"34.7200","8.6567","171.2592","8.6567","5.7711","41.0497"
"34.8000","8.6761","171.6407","8.6761","5.7841","41.1411"
"34.8800","8.6979","172.0738","8.6979","5.7986","41.2449"
"34.9600","8.7173","172.4259","8.7173","5.8115","41.3293"
"35.0400","8.7380","172.8238","8.7380","5.8254","41.4247"
"35.1200","8.7572","173.1808","8.7572","5.8382","41.5103"
"35.2000","8.7770","173.5493","8.7770","5.8513","41.5986"
"35.2800","8.7974","173.9488","8.7974","5.8649","41.6943"
"35.3600","8.8167","174.2960","8.8167","5.8778","41.7776"
"35.4400","8.8375","174.6921","8.8375","5.8917","41.8725"
"35.5200","8.8583","175.0961","8.8583","5.9056","41.9694"
"35.6000","8.8775","175.4524","8.8775","5.9183","42.0548"
"35.6800","8.8980","175.8432","8.8980","5.9320","42.1484"
"35.7600","8.9177","176.2081","8.9177","5.9451","42.2359"
"35.8400","8.9371","176.5681","8.9371","5.9580","42.3222"
"35.9200","8.9568","176.9374","8.9568","5.9712","42.4107"
"36.0000","8.9760","177.2849","8.9760","5.9840","42.4940"
"36.0800","8.9975","177.6965","8.9975","5.9983","42.5926"
"36.1600","9.0180","178.0812","9.0180","6.0120","42.6849"
"36.2400","9.0377","178.4640","9.0377","6.0251","42.7766"
"36.3200","9.0571","178.8122","9.0571","6.0381","42.8601"
"36.4000","9.0769","179.1742","9.0769","6.0513","42.9468"
"36.4800","9.0972","179.5556","9.0972","6.0648","43.0383"
"36.5600","9.1178","179.9471","9.1178","6.0785","43.1321"
"36.6400","9.1366","180.2930","9.1366","6.0911","43.2150"
"36.7200","9.1582","180.6989","9.1582","6.1055","43.3123"
"36.8000","9.1779","181.0765","9.1779","6.1186","43.4028"
"36.8800","9.1984","181.4523","9.1984","6.1322","43.4929"
"36.9600","9.2174","181.7974","9.2174","6.1449","43.5756"
"37.0400","9.2368","182.1442","9.2368","6.1579","43.6587"
"37.1200","9.2566","182.5058","9.2566","6.1711","43.7454"
"37.2000","9.2775","182.9034","9.2775","6.1850","43.8407"
"37.2800","9.2961","183.2344","9.2961","6.1974","43.9200"
"37.3600","9.3178","183.6565","9.3178","6.2119","44.0212"
"37.4400","9.3372","183.9943","9.3372","6.2248","44.1022"
"37.5200","9.3578","184.3722","9.3578","6.2386","44.1928"
"37.6000","9.3775","184.7237","9.3775","6.2516","44.2770"
"37.6800","9.3968","185.0774","9.3968","6.2645","44.3618"
"37.7600","9.4173","185.4550","9.4173","6.2782","44.4523"
"37.8400","9.4370","185.8098","9.4370","6.2913","44.5374"
"37.9200","9.4569","186.1861","9.4569","6.3046","44.6275"
"38.0000","9.4781","186.5805","9.4781","6.3187","44.7221"
"38.0800","9.4980","186.9355","9.4980","6.3320","44.8072"
"38.1600","9.5179","187.2786","9.5179","6.3453","44.8894"
"38.2400","9.5378","187.6398","9.5378","6.3586","44.9760"
"38.3200","9.5561","187.9660","9.5561","6.3707","45.0542"
"38.4000","9.5771","188.3593","9.5771","6.3847","45.1485"
"38.4800","9.5965","188.7002","9.5965","6.3977","45.2302"
"38.5600","9.6175","189.0885","9.6175","6.4116","45.3232"
"38.6400","9.6375","189.4484","9.6375","6.4250","45.4095"
"38.7200","9.6574","189.8026","9.6574","6.4383","45.4944"
"38.8000","9.6774","190.1589","9.6774","6.4516","45.5798"
"38.8800","9.6975","190.5092","9.6975","6.4650","45.6637"
"38.9600","9.7165","190.8539","9.7165","6.4777","45.7464"
"39.0400","9.7376","191.2372","9.7376","6.4918","45.8383"
"39.1200","9.7563","191.5541","9.7563","6.5042","45.9142"
"39.2000","9.7783","191.9696","9.7783","6.5189","46.0138"
"39.2800","9.7984","192.3181","9.7984","6.5323","46.0973"
"39.3600","9.8181","192.6684","9.8181","6.5454","46.1813"
"39.4400","9.8373","192.9934","9.8373","6.5582","46.2592"
"39.5200","9.8570","193.3379","9.8570","6.5714","46.3418"
"39.6000","9.8770","193.6810","9.8770","6.5847","46.4240"
"39.6800","9.8974","194.0436","9.8974","6.5982","46.5109"
"39.7600","9.9161","194.3584","9.9161","6.6108","46.5864"
"39.8400","9.9365","194.7091","9.9365","6.6243","46.6704"
"39.9200","9.9573","195.0866","9.9573","6.6382","46.7609"
"40.0000","9.9783","195.4761","9.9783","6.6522","46.8543"
"40.0800","9.9985","195.8186","9.9985","6.6657","46.9364"
"40.1600","10.0166","196.1163","10.0166","6.6777","47.0077"
"40.2400","10.0373","196.4877","10.0373","6.6915","47.0968"
"40.3200","10.0573","196.8179","10.0573","6.7048","47.1759"
"40.4000","10.0767","197.1513","10.0767","6.7178","47.2558"
"40.4800","10.0978","197.5381","10.0978","6.7319","47.3485"
"40.5600","10.1184","197.8858","10.1184","6.7456","47.4319"
"40.6400","10.1380","198.2091","10.1380","6.7587","47.5094"
"40.7200","10.1578","198.5419","10.1578","6.7719","47.5891"
"40.8000","10.1762","198.8448","10.1762","6.7842","47.6617"
"40.8800","10.1976","199.2246","10.1976","6.7984","47.7528"
"40.9600","10.2171","199.5408","10.2171","6.8114","47.8286"
"41.0400","10.2367","199.8710","10.2367","6.8245","47.9077"
"41.1200","10.2568","200.2157","10.2568","6.8378","47.9904"
"41.2000","10.2775","200.5630","10.2775","6.8517","48.0736"
"41.2800","10.2977","200.8994","10.2977","6.8651","48.1542"
"41.3600","10.3180","201.2373","10.3180","6.8787","48.2352"
"41.4400","10.3365","201.5369","10.3365","6.8910","48.3070"
"41.5200","10.3571","201.8979","10.3571","6.9047","48.3935"
"41.6000","10.3769","202.2118","10.3769","6.9179","48.4688"
"41.6800","10.3975","202.5614","10.3975","6.9317","48.5526"
"41.7600","10.4186","202.9225","10.4186","6.9458","48.6392"
"41.8400","10.4377","203.2288","10.4377","6.9585","48.7126"
"41.9200","10.4576","203.5475","10.4576","6.9718","48.7889"
"42.0000","10.4774","203.8738","10.4774","6.9849","48.8672"
"42.0800","10.4967","204.1885","10.4967","6.9978","48.9426"
"42.1600","10.5176","204.5446","10.5176","7.0117","49.0279"
"42.2400","10.5362","204.8291","10.5362","7.0241","49.0961"
"42.3200","10.5568","205.1796","10.5568","7.0379","49.1802"
"42.4000","10.5785","205.5382","10.5785","7.0523","49.2661"
"42.4800","10.5978","205.8548","10.5978","7.0652","49.3420"
"42.5600","10.6180","206.1815","10.6180","7.0787","49.4203"
"42.6400","10.6366","206.4625","10.6366","7.0911","49.4877"
"42.7200","10.6570","206.8019","10.6570","7.1047","49.5690"
"42.8000","10.6771","207.1270","10.6771","7.1181","49.6469"
"42.8800","10.6968","207.4427","10.6968","7.1312","49.7226"
"42.9600","10.7177","207.7832","10.7177","7.1451","49.8042"
"43.0400","10.7385","208.1357","10.7385","7.1590","49.8887"
"43.1200","10.7572","208.4209","10.7572","7.1714","49.9571"
"43.2000","10.7778","208.7697","10.7778","7.1852","50.0407"
"43.2800","10.7971","209.0592","10.7971","7.1981","50.1101"
"43.3600","10.8177","209.3940","10.8177","7.2118","50.1903"
"43.4400","10.8374","209.6921","10.8374","7.2249","50.2618"
"43.5200","10.8559","209.9810","10.8559","7.2372","50.3310"
"43.6000","10.8767","210.3136","10.8767","7.2511","50.4107"
"43.6800","10.8980","210.6746","10.8980","7.2654","50.4973"
"43.7600","10.9181","210.9888","10.9181","7.2787","50.5726"
"43.8400","10.9378","211.2843","10.9378","7.2919","50.6434"
"43.9200","10.9563","211.5544","10.9563","7.3042","50.7082"
"44.0000","10.9772","211.8965","10.9772","7.3182","50.7902"
"44.0800","10.9974","212.1982","10.9974","7.3316","50.8625"
"44.1600","11.0168","212.4910","11.0168","7.3445","50.9326"
"44.2400","11.0379","212.8329","11.0379","7.3586","51.0146"
"44.3200","11.0575","213.1215","11.0575","7.3717","51.0838"
"44.4000","11.0780","213.4292","11.0780","7.3853","51.1575"
"44.4800","11.0980","213.7444","11.0980","7.3987","51.2331"
"44.5600","11.1171","214.0169","11.1171","7.4114","51.2984"
"44.6400","11.1367","214.3108","11.1367","7.4245","51.3688"
"44.7200","11.1569","214.6215","11.1569","7.4379","51.4433"
"44.8000","11.1762","214.9220","11.1762","7.4508","51.5153"
"44.8800","11.1975","215.2442","11.1975","7.4650","51.5926"
"44.9600","11.2174","215.5420","11.2174","7.4783","51.6639"
"45.0400","11.2383","215.8495","11.2383","7.4922","51.7376"
"45.1200","11.2574","216.1187","11.2574","7.5049","51.8022"
"45.2000","11.2771","216.4289","11.2771","7.5181","51.8765"
"45.2800","11.2972","216.7298","11.2972","7.5315","51.9487"
"45.3600","11.3171","217.0177","11.3171","7.5447","52.0177"
"45.4400","11.3373","217.3194","11.3373","7.5582","52.0900"
"45.5200","11.3586","217.6405","11.3586","7.5724","52.1670"
"45.6000","11.3774","217.8986","11.3774","7.5849","52.2288"
"45.6800","11.3980","218.2207","11.3980","7.5987","52.3060"
"45.7600","11.4174","218.4845","11.4174","7.6116","52.3693"
"45.8400","11.4371","218.7762","11.4371","7.6248","52.4392"
"45.9200","11.4572","219.0702","11.4572","7.6382","52.5096"
"46.0000","11.4757","219.3150","11.4757","7.6505","52.5683"
"46.0800","11.4973","219.6487","11.4973","7.6649","52.6483"
"46.1600","11.5182","219.9536","11.5182","7.6788","52.7214"
"46.2400","11.5375","220.2218","11.5375","7.6917","52.7857"
"46.3200","11.5570","220.4987","11.5570","7.7047","52.8520"
"46.4000","11.5767","220.7655","11.5767","7.7178","52.9160"
"46.4800","11.5971","221.0648","11.5971","7.7314","52.9877"
"46.5600","11.6180","221.3693","11.6180","7.7454","53.0607"
"46.6400","11.6362","221.6127","11.6362","7.7575","53.1191"
"46.7200","11.6581","221.9370","11.6581","7.7720","53.1968"
"46.8000","11.6784","222.2263","11.6784","7.7856","53.2661"
"46.8800","11.6981","222.4924","11.6981","7.7987","53.3299"
"46.9600","11.7171","222.7521","11.7171","7.8114","53.3922"
"47.0400","11.7369","223.0238","11.7369","7.8246","53.4573"
"47.1200","11.7569","223.2876","11.7569","7.8379","53.5205"
"47.2000","11.7774","223.5752","11.7774","7.8516","53.5895"
"47.2800","11.7967","223.8390","11.7967","7.8645","53.6527"
"47.3600","11.8179","224.1628","11.8179","7.8786","53.7303"
"47.4400","11.8372","224.3970","11.8372","7.8915","53.7864"
"47.5200","11.8575","224.6830","11.8575","7.9050","53.8550"
"47.6000","11.8777","224.9624","11.8777","7.9184","53.9220"
"47.6800","11.8968","225.2142","11.8968","7.9312","53.9823"
"47.7600","11.9174","225.4872","11.9174","7.9449","54.0478"
"47.8400","11.9371","225.7574","11.9371","7.9580","54.1125"
"47.9200","11.9569","226.0092","11.9569","7.9713","54.1729"
"48.0000","11.9782","226.3281","11.9782","7.9855","54.2493"
"48.0800","11.9982","226.5706","11.9982","7.9988","54.3074"
"48.1600","12.0175","226.8161","12.0175","8.0117","54.3663"
"48.2400","12.0377","227.0842","12.0377","8.0251","54.4305"
"48.3200","12.0565","227.3296","12.0565","8.0377","54.4894"
"48.4000","12.0773","227.6013","12.0773","8.0515","54.5545"
"48.4800","12.0965","227.8445","12.0965","8.0644","54.6128"
"48.5600","12.1175","228.1274","12.1175","8.0784","54.6806"
"48.6400","12.1380","228.3970","12.1380","8.0920","54.7452"
"48.7200","12.1572","228.6377","12.1572","8.1048","54.8029"
"48.8000","12.1774","228.9021","12.1774","8.1183","54.8663"
"48.8800","12.1977","229.1614","12.1977","8.1318","54.9284"
"48.9600","12.2165","229.3920","12.2165","8.1443","54.9837"
"49.0400","12.2374","229.6672","12.2374","8.1582","55.0497"
"49.1200","12.2565","229.8950","12.2565","8.1710","55.1043"
"49.2000","12.2780","230.1872","12.2780","8.1853","55.1743"
"49.2800","12.2988","230.4440","12.2988","8.1992","55.2359"
"49.3600","12.3178","230.6693","12.3178","8.2119","55.2899"
"49.4400","12.3371","230.8948","12.3371","8.2247","55.3439"
"49.5200","12.3571","231.1517","12.3571","8.2380","55.4055"
"49.6000","12.3772","231.3878","12.3772","8.2515","55.4621"
"49.6800","12.3976","231.6462","12.3976","8.2651","55.5240"
"49.7600","12.4163","231.8503","12.4163","8.2775","55.5729"
"49.8400","12.4371","232.1156","12.4371","8.2914","55.6365"
"49.9200","12.4577","232.3766","12.4577","8.3051","55.6991"
"50.0000","12.4778","232.6301","12.4778","8.3186","55.7599"
"50.0800","12.4981","232.8647","12.4981","8.3321","55.8161"
"50.1600","12.5167","233.0615","12.5167","8.3444","55.8633"
"50.2400","12.5372","233.3053","12.5372","8.3581","55.9217"
"50.3200","12.5568","233.5266","12.5568","8.3712","55.9747"
"50.4000","12.5767","233.7905","12.5767","8.3845","56.0380"
"50.4800","12.5981","234.0703","12.5981","8.3988","56.1051"
"50.5600","12.6184","234.2914","12.6184","8.4123","56.1580"
"50.6400","12.6379","234.5109","12.6379","8.4253","56.2107"
"50.7200","12.6577","234.7346","12.6577","8.4385","56.2643"
"50.8000","12.6763","234.9269","12.6763","8.4509","56.3104"
"50.8800","12.6976","235.1911","12.6976","8.4651","56.3737"
"50.9600","12.7168","235.3990","12.7168","8.4779","56.4235"
"51.0400","12.7362","235.6143","12.7362","8.4908","56.4752"
"51.1200","12.7569","235.8647","12.7569","8.5046","56.5352"
"51.2000","12.7779","236.1093","12.7779","8.5186","56.5938"
"51.2800","12.7978","236.3140","12.7978","8.5319","56.6429"
"51.3600","12.8180","236.5502","12.8180","8.5453","56.6995"
"51.4400","12.8363","236.7410","12.8363","8.5575","56.7452"
"51.5200","12.8567","236.9706","12.8567","8.5711","56.8002"
"51.6000","12.8766","237.1840","12.8766","8.5844","56.8514"
"51.6800","12.8980","237.4499","12.8980","8.5987","56.9151"
"51.7600","12.9186","237.6717","12.9186","8.6124","56.9683"
"51.8400","12.9378","237.8726","12.9378","8.6252","57.0164"
"51.9200","12.9580","238.0977","12.9580","8.6387","57.0704"
"52.0000","12.9776","238.3024","12.9776","8.6517","57.1195"
"52.0800","12.9972","238.5160","12.9972","8.6648","57.1707"
"52.1600","13.0171","238.7267","13.0171","8.6780","57.2212"
"52.2400","13.0368","238.9419","13.0368","8.6912","57.2728"
"52.3200","13.0569","239.1540","13.0569","8.7046","57.3236"
"52.4000","13.0783","239.3904","13.0783","8.7189","57.3802"
"52.4800","13.0981","239.6014","13.0981","8.7321","57.4308"
"52.5600","13.1181","239.8045","13.1181","8.7454","57.4795"
"52.6400","13.1365","239.9640","13.1365","8.7577","57.5177"
"52.7200","13.1566","240.1791","13.1566","8.7711","57.5693"
"52.8000","13.1772","240.4051","13.1772","8.7848","57.6235"
"52.8800","13.1967","240.5844","13.1967","8.7978","57.6665"
"52.9600","13.2177","240.8171","13.2177","8.8118","57.7222"
"53.0400","13.2384","241.0218","13.2384","8.8256","57.7713"
"53.1200","13.2577","241.2072","13.2577","8.8385","57.8157"
"53.2000","13.2779","241.4134","13.2779","8.8519","57.8652"
"53.2800","13.2967","241.5736","13.2967","8.8645","57.9036"
"53.3600","13.3177","241.7980","13.3177","8.8785","57.9573"
"53.4400","13.3373","241.9815","13.3373","8.8915","58.0013"
"53.5200","13.3558","242.1541","13.3558","8.9038","58.0427"
"53.6000","13.3771","242.3855","13.3771","8.9181","58.0982"
"53.6800","13.3980","242.5862","13.3980","8.9320","58.1462"
"53.7600","13.4179","242.7694","13.4179","8.9453","58.1902"
"53.8400","13.4375","242.9566","13.4375","8.9584","58.2351"
"53.9200","13.4564","243.1132","13.4564","8.9709","58.2726"
"54.0000","13.4769","243.3137","13.4769","8.9846","58.3206"
"54.0800","13.4977","243.5242","13.4977","8.9985","58.3711"
"54.1600","13.5172","243.6930","13.5172","9.0114","58.4116"
"54.2400","13.5380","243.9037","13.5380","9.0254","58.4620"
"54.3200","13.5576","244.0730","13.5576","9.0384","58.5026"
"54.4000","13.5781","244.2551","13.5781","9.0521","58.5463"
"54.4800","13.5978","244.4241","13.5978","9.0652","58.5868"
"54.5600","13.6170","244.5753","13.6170","9.0780","58.6230"
"54.6400","13.6370","244.7690","13.6370","9.0913","58.6695"
"54.7200","13.6564","244.9277","13.6564","9.1043","58.7075"
"54.8000","13.6764","245.1195","13.6764","9.1176","58.7535"
"54.8800","13.6980","245.3282","13.6980","9.1320","58.8035"
"54.9600","13.7174","245.4924","13.7174","9.1449","58.8429"
"55.0400","13.7382","245.6778","13.7382","9.1588","58.8873"
"55.1200","13.7573","245.8298","13.7573","9.1715","58.9237"
"55.2000","13.7767","246.0012","13.7767","9.1845","58.9648"
"55.2800","13.7970","246.1857","13.7970","9.1980","59.0090"
"55.3600","13.8171","246.3478","13.8171","9.2114","59.0479"
"55.4400","13.8373","246.5217","13.8373","9.2248","59.0896"
"55.5200","13.8586","246.7160","13.8586","9.2390","59.1361"
"55.6000","13.8775","246.8557","13.8775","9.2517","59.1696"
"55.6800","13.8977","247.0419","13.8977","9.2651","59.2143"
"55.7600","13.9173","247.1952","13.9173","9.2782","59.2510"
"55.8400","13.9371","247.3654","13.9371","9.2914","59.2918"
"55.9200","13.9572","247.5328","13.9572","9.3048","59.3319"
"56.0000","13.9758","247.6579","13.9758","9.3172","59.3619"
"56.0800","13.9971","247.8542","13.9971","9.3314","59.4090"
"56.1600","14.0182","248.0405","14.0182","9.3455","59.4536"
"56.2400","14.0373","248.1792","14.0373","9.3582","59.4869"
"56.3200","14.0570","248.3398","14.0570","9.3713","59.5254"
"56.4000","14.0769","248.4895","14.0769","9.3846","59.5612"
"56.4800","14.0972","248.6655","14.0972","9.3981","59.6034"
"56.5600","14.1182","248.8364","14.1182","9.4121","59.6444"
"56.6400","14.1366","248.9637","14.1366","9.4244","59.6749"
"56.7200","14.1582","249.1548","14.1582","9.4388","59.7207"
"56.8000","14.1780","249.3148","14.1780","9.4520","59.7591"
"56.8800","14.1983","249.4761","14.1983","9.4655","59.7977"
"56.9600","14.2180","249.6339","14.2180","9.4787","59.8355"
"57.0400","14.2368","249.7458","14.2368","9.4912","59.8624"
"57.1200","14.2567","249.9025","14.2567","9.5045","59.8999"
"57.2000","14.2772","250.0571","14.2772","9.5181","59.9370"
"57.2800","14.2967","250.2063","14.2967","9.5311","59.9727"
"57.3600","14.3173","250.3696","14.3173","9.5449","60.0119"
"57.4400","14.3373","250.5084","14.3373","9.5582","60.0452"
"57.5200","14.3576","250.6554","14.3576","9.5717","60.0804"
"57.6000","14.3775","250.8052","14.3775","9.5850","60.1163"
"57.6800","14.3969","250.9398","14.3969","9.5979","60.1486"
"57.7600","14.4174","251.0764","14.4174","9.6116","60.1813"
"57.8400","14.4368","251.2135","14.4368","9.6245","60.2142"
"57.9200","14.4568","251.3633","14.4568","9.6379","60.2501"
"58.0000","14.4780","251.5379","14.4780","9.6520","60.2919"
"58.0800","14.4981","251.6720","14.4981","9.6654","60.3241"
"58.1600","14.5179","251.8014","14.5179","9.6786","60.3551"
"58.2400","14.5375","251.9267","14.5375","9.6917","60.3851"
"58.3200","14.5564","252.0399","14.5564","9.7043","60.4123"
"58.4000","14.5772","252.1999","14.5772","9.7182","60.4506"
"58.4800","14.5963","252.3050","14.5963","9.7309","60.4758"
"58.5600","14.6169","252.4537","14.6169","9.7446","60.5114"
"58.6400","14.6374","252.6025","14.6374","9.7583","60.5471"
"58.7200","14.6574","252.7276","14.6574","9.7716","60.5771"
"58.8000","14.6778","252.8673","14.6778","9.7852","60.6106"
"58.8800","14.6980","253.0012","14.6980","9.7987","60.6427"
"58.9600","14.7172","253.1068","14.7172","9.8115","60.6680"
"59.0400","14.7371","253.2348","14.7371","9.8247","60.6987"
"59.1200","14.7561","253.3340","14.7561","9.8374","60.7224"
"59.2000","14.7779","253.4985","14.7779","9.8520","60.7619"
"59.2800","14.7987","253.6310","14.7987","9.8658","60.7936"
"59.3600","14.8182","253.7511","14.8182","9.8788","60.8224"
"59.4400","14.8372","253.8557","14.8372","9.8915","60.8475"
"59.5200","14.8569","253.9512","14.8569","9.9046","60.8704"
"59.6000","14.8773","254.0910","14.8773","9.9182","60.9039"
"59.6800","14.8975","254.2058","14.8975","9.9317","60.9314"
"59.7600","14.9161","254.2849","14.9161","9.9441","60.9504"
"59.8400","14.9371","254.4088","14.9371","9.9581","60.9801"
"59.9200","14.9581","254.5532","14.9581","9.9721","61.0147"
"60.0000","14.9778","254.6594","14.9778","9.9852","61.0401"
"60.0800","14.9975","254.7652","14.9975","9.9983","61.0655"
"60.0900","15.0001","254.7772","15.0001","10.0000","61.0684"