File: data/instron_tests/metamaterials/250327/250327_1467_BULK_m2_NoTransition.is_comp_Exports/250327_1467_BULK_m2_NoTransition_3_1.csv
Results Table 1
,Compression Axis,H*,V*,Height,Thickness,Width,Area,Fixture separation,Specimen label
,,,,(mm),(mm),(mm),(mm^2),(mm),
"3","Y","","","149.00","28.00","149.00","4172.00","150.00","1467_BULK_m2_NoTransition"

Results Table 2
,Modulus (Segment 0 % - 5 %),Compression Axis
,(kPa),
"3","788.27","Y"

Time,Displacement,Force,Compressive displacement,Compressive strain (Displacement),Compressive stress
(s),(mm),(N),(mm),(%),(kPa)
"0.0000","0.0000","-17.8701","0.0000","0.0000","-4.2833"
"0.0800","0.0012","-17.8347","0.0012","0.0008","-4.2749"
"0.1600","0.0177","-17.3048","0.0177","0.0118","-4.1478"
"0.2400","0.0386","-16.7223","0.0386","0.0257","-4.0082"
"0.3200","0.0581","-16.1545","0.0581","0.0387","-3.8721"
"0.4000","0.0772","-15.6004","0.0772","0.0515","-3.7393"
"0.4800","0.0985","-15.0077","0.0985","0.0656","-3.5973"
"0.5600","0.1184","-14.4681","0.1184","0.0790","-3.4679"
"0.6400","0.1380","-13.9495","0.1380","0.0920","-3.3436"
"0.7200","0.1572","-13.4424","0.1572","0.1048","-3.2221"
"0.8000","0.1765","-12.9246","0.1765","0.1177","-3.0979"
"0.8800","0.1978","-12.3641","0.1978","0.1318","-2.9636"
"0.9600","0.2172","-11.8636","0.2172","0.1448","-2.8436"
"1.0400","0.2366","-11.3478","0.2366","0.1577","-2.7200"
"1.1200","0.2574","-10.8120","0.2574","0.1716","-2.5916"
"1.2000","0.2774","-10.2984","0.2774","0.1850","-2.4684"
"1.2800","0.2982","-9.7739","0.2982","0.1988","-2.3427"
"1.3600","0.3180","-9.2677","0.3180","0.2120","-2.2214"
"1.4400","0.3365","-8.7976","0.3365","0.2243","-2.1087"
"1.5200","0.3569","-8.2863","0.3569","0.2379","-1.9862"
"1.6000","0.3769","-7.7773","0.3769","0.2513","-1.8642"
"1.6800","0.3979","-7.2524","0.3979","0.2652","-1.7383"
"1.7600","0.4187","-6.7290","0.4187","0.2791","-1.6129"
"1.8400","0.4376","-6.2536","0.4376","0.2918","-1.4989"
"1.9200","0.4577","-5.7505","0.4577","0.3052","-1.3783"
"2.0000","0.4777","-5.2623","0.4777","0.3184","-1.2613"
"2.0800","0.4973","-4.7738","0.4973","0.3315","-1.1443"
"2.1600","0.5173","-4.2736","0.5173","0.3448","-1.0243"
"2.2400","0.5361","-3.8170","0.5361","0.3574","-0.9149"
"2.3200","0.5572","-3.2958","0.5572","0.3715","-0.7900"
"2.4000","0.5788","-2.7571","0.5788","0.3859","-0.6609"
"2.4800","0.5979","-2.2864","0.5979","0.3986","-0.5480"
"2.5600","0.6177","-1.7987","0.6177","0.4118","-0.4311"
"2.6400","0.6367","-1.3474","0.6367","0.4244","-0.3230"
"2.7200","0.6569","-0.8503","0.6569","0.4380","-0.2038"
"2.8000","0.6772","-0.3538","0.6772","0.4515","-0.0848"
"2.8800","0.6973","0.1211","0.6973","0.4649","0.0290"
"2.9600","0.7179","0.6275","0.7179","0.4786","0.1504"
"3.0400","0.7385","1.1252","0.7385","0.4923","0.2697"
"3.1200","0.7576","1.5900","0.7576","0.5051","0.3811"
"3.2000","0.7778","2.0759","0.7778","0.5185","0.4976"
"3.2800","0.7972","2.5366","0.7972","0.5314","0.6080"
"3.3600","0.8181","3.0490","0.8181","0.5454","0.7308"
"3.4400","0.8370","3.4875","0.8370","0.5580","0.8359"
"3.5200","0.8555","3.9398","0.8555","0.5703","0.9443"
"3.6000","0.8773","4.4765","0.8773","0.5848","1.0730"
"3.6800","0.8984","4.9951","0.8984","0.5990","1.1973"
"3.7600","0.9179","5.4521","0.9179","0.6120","1.3068"
"3.8400","0.9374","5.9179","0.9374","0.6249","1.4185"
"3.9200","0.9565","6.3725","0.9565","0.6377","1.5275"
"4.0000","0.9772","6.8791","0.9772","0.6514","1.6489"
"4.0800","0.9976","7.3746","0.9976","0.6650","1.7677"
"4.1600","1.0171","7.8448","1.0171","0.6781","1.8803"
"4.2400","1.0382","8.3539","1.0382","0.6922","2.0024"
"4.3200","1.0578","8.8179","1.0578","0.7052","2.1136"
"4.4000","1.0784","9.3004","1.0784","0.7190","2.2292"
"4.4800","1.0979","9.7618","1.0979","0.7319","2.3398"
"4.5600","1.1169","10.2156","1.1169","0.7446","2.4486"
"4.6400","1.1372","10.7057","1.1372","0.7582","2.5661"
"4.7200","1.1568","11.1706","1.1568","0.7712","2.6775"
"4.8000","1.1769","11.6503","1.1769","0.7846","2.7925"
"4.8800","1.1983","12.1694","1.1983","0.7988","2.9169"
"4.9600","1.2171","12.6087","1.2171","0.8114","3.0222"
"5.0400","1.2374","13.0818","1.2374","0.8249","3.1356"
"5.1200","1.2575","13.5566","1.2575","0.8383","3.2494"
"5.2000","1.2773","14.0310","1.2773","0.8515","3.3631"
"5.2800","1.2976","14.5186","1.2976","0.8651","3.4800"
"5.3600","1.3172","14.9603","1.3172","0.8781","3.5859"
"5.4400","1.3378","15.4615","1.3378","0.8918","3.7060"
"5.5200","1.3586","15.9526","1.3586","0.9057","3.8237"
"5.6000","1.3778","16.4070","1.3778","0.9185","3.9326"
"5.6800","1.3982","16.8809","1.3982","0.9321","4.0462"
"5.7600","1.4174","17.3338","1.4174","0.9449","4.1548"
"5.8400","1.4371","17.8047","1.4371","0.9581","4.2677"
"5.9200","1.4571","18.2746","1.4571","0.9714","4.3803"
"6.0000","1.4762","18.7137","1.4762","0.9842","4.4855"
"6.0800","1.4977","19.2250","1.4977","0.9985","4.6081"
"6.1600","1.5181","19.7078","1.5181","1.0121","4.7238"
"6.2400","1.5376","20.1732","1.5376","1.0250","4.8354"
"6.3200","1.5574","20.6415","1.5574","1.0383","4.9476"
"6.4000","1.5769","21.0912","1.5769","1.0512","5.0554"
"6.4800","1.5975","21.5811","1.5975","1.0650","5.1728"
"6.5600","1.6179","22.0550","1.6179","1.0786","5.2864"
"6.6400","1.6364","22.4759","1.6364","1.0909","5.3873"
"6.7200","1.6581","23.0019","1.6581","1.1054","5.5134"
"6.8000","1.6784","23.4678","1.6784","1.1190","5.6251"
"6.8800","1.6981","23.9207","1.6981","1.1321","5.7336"
"6.9600","1.7171","24.3645","1.7171","1.1447","5.8400"
"7.0400","1.7369","24.8130","1.7369","1.1580","5.9475"
"7.1200","1.7571","25.3002","1.7571","1.1714","6.0643"
"7.2000","1.7777","25.7793","1.7777","1.1851","6.1791"
"7.2800","1.7965","26.2117","1.7965","1.1977","6.2828"
"7.3600","1.8177","26.7169","1.8177","1.2118","6.4039"
"7.4400","1.8376","27.1728","1.8376","1.2251","6.5131"
"7.5200","1.8579","27.6413","1.8579","1.2386","6.6254"
"7.6000","1.8776","28.0967","1.8776","1.2517","6.7346"
"7.6800","1.8970","28.5496","1.8970","1.2647","6.8431"
"7.7600","1.9176","29.0224","1.9176","1.2784","6.9565"
"7.8400","1.9374","29.4839","1.9374","1.2916","7.0671"
"7.9200","1.9571","29.9409","1.9571","1.3047","7.1766"
"8.0000","1.9781","30.4405","1.9781","1.3187","7.2964"
"8.0800","1.9981","30.8774","1.9981","1.3321","7.4011"
"8.1600","2.0182","31.3532","2.0182","1.3455","7.5151"
"8.2400","2.0378","31.8025","2.0378","1.3586","7.6228"
"8.3200","2.0564","32.2194","2.0564","1.3709","7.7228"
"8.4000","2.0774","32.7293","2.0774","1.3849","7.8450"
"8.4800","2.0971","33.1818","2.0971","1.3980","7.9535"
"8.5600","2.1178","33.6550","2.1178","1.4119","8.0669"
"8.6400","2.1380","34.1200","2.1380","1.4253","8.1783"
"8.7200","2.1574","34.5587","2.1574","1.4383","8.2835"
"8.8000","2.1775","35.0291","2.1775","1.4517","8.3962"
"8.8800","2.1978","35.4787","2.1978","1.4652","8.5040"
"8.9600","2.2168","35.9187","2.2168","1.4779","8.6095"
"9.0400","2.2374","36.4026","2.2374","1.4916","8.7255"
"9.1200","2.2566","36.8248","2.2566","1.5044","8.8267"
"9.2000","2.2781","37.3352","2.2781","1.5188","8.9490"
"9.2800","2.2988","37.8197","2.2988","1.5325","9.0651"
"9.3600","2.3179","38.2517","2.3179","1.5453","9.1687"
"9.4400","2.3374","38.6950","2.3374","1.5583","9.2749"
"9.5200","2.3572","39.1611","2.3572","1.5715","9.3867"
"9.6000","2.3770","39.6113","2.3770","1.5847","9.4946"
"9.6800","2.3978","40.0905","2.3978","1.5985","9.6094"
"9.7600","2.4164","40.5008","2.4164","1.6109","9.7078"
"9.8400","2.4370","40.9699","2.4370","1.6247","9.8202"
"9.9200","2.4574","41.4290","2.4574","1.6382","9.9303"
"10.0000","2.4776","41.8855","2.4776","1.6517","10.0397"
"10.0800","2.4984","42.3667","2.4984","1.6656","10.1550"
"10.1600","2.5173","42.7758","2.5173","1.6782","10.2531"
"10.2400","2.5373","43.2304","2.5373","1.6915","10.3620"
"10.3200","2.5573","43.6852","2.5573","1.7049","10.4710"
"10.4000","2.5771","44.1259","2.5771","1.7181","10.5767"
"10.4800","2.5982","44.6093","2.5982","1.7321","10.6926"
"10.5600","2.6186","45.0604","2.6186","1.7458","10.8007"
"10.6400","2.6383","45.5073","2.6383","1.7589","10.9078"
"10.7200","2.6577","45.9387","2.6577","1.7718","11.0112"
"10.8000","2.6763","46.3496","2.6763","1.7842","11.1097"
"10.8800","2.6978","46.8570","2.6978","1.7985","11.2313"
"10.9600","2.7173","47.2959","2.7173","1.8116","11.3365"
"11.0400","2.7367","47.7219","2.7367","1.8244","11.4386"
"11.1200","2.7573","48.1981","2.7573","1.8382","11.5528"
"11.2000","2.7779","48.6598","2.7779","1.8519","11.6634"
"11.2800","2.7980","49.1168","2.7980","1.8653","11.7730"
"11.3600","2.8182","49.5654","2.8182","1.8788","11.8805"
"11.4400","2.8363","49.9685","2.8363","1.8908","11.9771"
"11.5200","2.8568","50.4348","2.8568","1.9045","12.0889"
"11.6000","2.8771","50.8998","2.8771","1.9181","12.2003"
"11.6800","2.8981","51.3738","2.8981","1.9321","12.3139"
"11.7600","2.9186","51.8368","2.9186","1.9457","12.4249"
"11.8400","2.9377","52.2469","2.9377","1.9585","12.5232"
"11.9200","2.9577","52.6961","2.9577","1.9718","12.6309"
"12.0000","2.9776","53.1428","2.9776","1.9850","12.7380"
"12.0800","2.9973","53.5866","2.9973","1.9982","12.8443"
"12.1600","3.0173","54.0472","3.0173","2.0116","12.9547"
"12.2400","3.0363","54.4582","3.0363","2.0242","13.0533"
"12.3200","3.0570","54.9359","3.0570","2.0380","13.1678"
"12.4000","3.0786","55.4212","3.0786","2.0524","13.2841"
"12.4800","3.0977","55.8464","3.0977","2.0651","13.3860"
"12.5600","3.1180","56.2916","3.1180","2.0787","13.4927"
"12.6400","3.1365","56.6926","3.1365","2.0910","13.5888"
"12.7200","3.1569","57.1424","3.1569","2.1046","13.6966"
"12.8000","3.1775","57.6195","3.1775","2.1184","13.8110"
"12.8800","3.1975","58.0612","3.1975","2.1316","13.9169"
"12.9600","3.2176","58.5146","3.2176","2.1451","14.0256"
"13.0400","3.2386","58.9934","3.2386","2.1591","14.1403"
"13.1200","3.2577","59.4089","3.2577","2.1718","14.2399"
"13.2000","3.2780","59.8581","3.2780","2.1854","14.3476"
"13.2800","3.2972","60.2719","3.2972","2.1981","14.4468"
"13.3600","3.3178","60.7244","3.3178","2.2119","14.5552"
"13.4400","3.3375","61.1595","3.3375","2.2250","14.6595"
"13.5200","3.3562","61.5667","3.3562","2.2375","14.7571"
"13.6000","3.3772","62.0462","3.3772","2.2515","14.8721"
"13.6800","3.3981","62.5211","3.3981","2.2654","14.9859"
"13.7600","3.4179","62.9425","3.4179","2.2786","15.0869"
"13.8400","3.4378","63.3857","3.4378","2.2918","15.1931"
"13.9200","3.4566","63.7800","3.4566","2.3044","15.2876"
"14.0000","3.4774","64.2417","3.4774","2.3182","15.3983"
"14.0800","3.4976","64.6663","3.4976","2.3317","15.5001"
"14.1600","3.5169","65.0880","3.5169","2.3446","15.6012"
"14.2400","3.5382","65.5682","3.5382","2.3588","15.7162"
"14.3200","3.5578","65.9917","3.5578","2.3719","15.8178"
"14.4000","3.5783","66.4405","3.5783","2.3856","15.9253"
"14.4800","3.5980","66.8741","3.5980","2.3987","16.0293"
"14.5600","3.6168","67.2799","3.6168","2.4112","16.1265"
"14.6400","3.6369","67.7225","3.6369","2.4246","16.2326"
"14.7200","3.6566","68.1500","3.6566","2.4377","16.3351"
"14.8000","3.6765","68.5633","3.6765","2.4510","16.4342"
"14.8800","3.6982","69.0531","3.6982","2.4654","16.5516"
"14.9600","3.7176","69.4639","3.7176","2.4784","16.6500"
"15.0400","3.7381","69.9122","3.7381","2.4921","16.7575"
"15.1200","3.7572","70.3302","3.7572","2.5048","16.8577"
"15.2000","3.7768","70.7648","3.7768","2.5178","16.9618"
"15.2800","3.7976","71.2330","3.7976","2.5318","17.0741"
"15.3600","3.8170","71.6408","3.8170","2.5447","17.1718"
"15.4400","3.8373","72.0822","3.8373","2.5582","17.2776"
"15.5200","3.8584","72.5450","3.8584","2.5723","17.3886"
"15.6000","3.8778","72.9423","3.8778","2.5852","17.4838"
"15.6800","3.8979","73.3873","3.8979","2.5986","17.5904"
"15.7600","3.9176","73.8029","3.9176","2.6117","17.6901"
"15.8400","3.9371","74.2367","3.9371","2.6248","17.7940"
"15.9200","3.9574","74.6853","3.9574","2.6383","17.9016"
"16.0000","3.9765","75.0884","3.9765","2.6510","17.9982"
"16.0800","3.9976","75.5527","3.9976","2.6651","18.1095"
"16.1600","4.0184","76.0068","4.0184","2.6790","18.2183"
"16.2400","4.0377","76.4299","4.0377","2.6918","18.3197"
"16.3200","4.0574","76.8532","4.0574","2.7049","18.4212"
"16.4000","4.0772","77.2704","4.0772","2.7182","18.5212"
"16.4800","4.0972","77.7048","4.0972","2.7315","18.6253"
"16.5600","4.1177","78.1490","4.1177","2.7452","18.7318"
"16.6400","4.1368","78.5669","4.1368","2.7578","18.8320"
"16.7200","4.1580","79.0400","4.1580","2.7720","18.9454"
"16.8000","4.1781","79.4687","4.1781","2.7854","19.0481"
"16.8800","4.1982","79.9039","4.1982","2.7988","19.1524"
"16.9600","4.2173","80.3237","4.2173","2.8115","19.2530"
"17.0400","4.2371","80.7279","4.2371","2.8247","19.3499"
"17.1200","4.2570","81.1700","4.2570","2.8380","19.4559"
"17.2000","4.2776","81.6128","4.2776","2.8517","19.5620"
"17.2800","4.2964","82.0214","4.2964","2.8643","19.6600"
"17.3600","4.3177","82.4859","4.3177","2.8785","19.7713"
"17.4400","4.3373","82.8997","4.3373","2.8915","19.8705"
"17.5200","4.3579","83.3513","4.3579","2.9053","19.9787"
"17.6000","4.3777","83.7832","4.3777","2.9185","20.0823"
"17.6800","4.3967","84.1840","4.3967","2.9312","20.1783"
"17.7600","4.4173","84.6258","4.4173","2.9448","20.2842"
"17.8400","4.4374","85.0590","4.4374","2.9583","20.3881"
"17.9200","4.4569","85.4829","4.4569","2.9713","20.4897"
"18.0000","4.4775","85.9378","4.4775","2.9850","20.5987"
"18.0800","4.4978","86.3592","4.4978","2.9986","20.6997"
"18.1600","4.5184","86.7947","4.5184","3.0123","20.8041"
"18.2400","4.5377","87.2006","4.5377","3.0252","20.9014"
"18.3200","4.5566","87.6066","4.5566","3.0377","20.9987"
"18.4000","4.5774","88.0634","4.5774","3.0516","21.1082"
"18.4800","4.5967","88.4696","4.5967","3.0645","21.2056"
"18.5600","4.6178","88.9312","4.6178","3.0785","21.3162"
"18.6400","4.6380","89.3690","4.6380","3.0920","21.4211"
"18.7200","4.6574","89.7769","4.6574","3.1049","21.5189"
"18.8000","4.6777","90.2112","4.6777","3.1185","21.6230"
"18.8800","4.6979","90.6433","4.6979","3.1319","21.7266"
"18.9600","4.7169","91.0476","4.7169","3.1446","21.8235"
"19.0400","4.7375","91.4942","4.7375","3.1584","21.9305"
"19.1200","4.7563","91.8817","4.7563","3.1709","22.0234"
"19.2000","4.7780","92.3480","4.7780","3.1853","22.1352"
"19.2800","4.7987","92.7938","4.7987","3.1991","22.2420"
"19.3600","4.8181","93.1483","4.8181","3.2121","22.3270"
"19.4400","4.8373","93.5532","4.8373","3.2249","22.4241"
"19.5200","4.8573","93.9870","4.8573","3.2382","22.5280"
"19.6000","4.8771","94.4182","4.8771","3.2514","22.6314"
"19.6800","4.8974","94.8603","4.8974","3.2649","22.7374"
"19.7600","4.9164","95.2563","4.9164","3.2776","22.8323"
"19.8400","4.9375","95.7198","4.9375","3.2917","22.9434"
"19.9200","4.9581","96.1530","4.9581","3.3054","23.0472"
"20.0000","4.9779","96.5682","4.9779","3.3186","23.1467"
"20.0800","4.9976","96.9844","4.9976","3.3318","23.2465"
"20.1600","5.0168","97.3769","5.0168","3.3445","23.3406"
"20.2400","5.0374","97.8138","5.0374","3.3582","23.4453"
"20.3200","5.0575","98.2402","5.0575","3.3717","23.5475"
"20.4000","5.0767","98.6435","5.0767","3.3845","23.6442"
"20.4800","5.0980","99.1114","5.0980","3.3986","23.7563"
"20.5600","5.1184","99.4833","5.1184","3.4123","23.8455"
"20.6400","5.1381","99.8979","5.1381","3.4254","23.9448"
"20.7200","5.1577","100.3045","5.1577","3.4384","24.0423"
"20.8000","5.1765","100.6915","5.1765","3.4510","24.1351"
"20.8800","5.1974","101.1429","5.1974","3.4650","24.2433"
"20.9600","5.2171","101.5560","5.2171","3.4781","24.3423"
"21.0400","5.2369","101.9737","5.2369","3.4913","24.4424"
"21.1200","5.2569","102.3995","5.2569","3.5046","24.5445"
"21.2000","5.2777","102.8257","5.2777","3.5185","24.6466"
"21.2800","5.2981","103.2620","5.2981","3.5321","24.7512"
"21.3600","5.3182","103.6745","5.3182","3.5455","24.8501"
"21.4400","5.3363","104.0424","5.3363","3.5575","24.9383"
"21.5200","5.3570","104.4791","5.3570","3.5713","25.0429"
"21.6000","5.3768","104.8982","5.3768","3.5846","25.1434"
"21.6800","5.3981","105.3604","5.3981","3.5987","25.2542"
"21.7600","5.4189","105.7881","5.4189","3.6126","25.3567"
"21.8400","5.4378","106.1378","5.4378","3.6252","25.4405"
"21.9200","5.4575","106.5482","5.4575","3.6384","25.5389"
"22.0000","5.4778","106.9792","5.4778","3.6519","25.6422"
"22.0800","5.4973","107.3967","5.4973","3.6649","25.7422"
"22.1600","5.5178","107.8390","5.5178","3.6786","25.8483"
"22.2400","5.5363","108.1941","5.5363","3.6909","25.9334"
"22.3200","5.5566","108.6332","5.5566","3.7044","26.0386"
"22.4000","5.5783","109.0898","5.5783","3.7189","26.1481"
"22.4800","5.5979","109.5102","5.5979","3.7320","26.2488"
"22.5600","5.6179","109.9314","5.6179","3.7453","26.3498"
"22.6400","5.6366","110.3052","5.6366","3.7577","26.4394"
"22.7200","5.6572","110.7425","5.6572","3.7715","26.5442"
"22.8000","5.6775","111.1633","5.6775","3.7850","26.6451"
"22.8800","5.6973","111.5698","5.6973","3.7982","26.7425"
"22.9600","5.7177","111.9945","5.7177","3.8118","26.8443"
"23.0400","5.7384","112.4166","5.7384","3.8256","26.9455"
"23.1200","5.7572","112.7804","5.7572","3.8382","27.0327"
"23.2000","5.7776","113.2061","5.7776","3.8518","27.1347"
"23.2800","5.7973","113.6148","5.7973","3.8649","27.2327"
"23.3600","5.8181","114.0366","5.8181","3.8787","27.3338"
"23.4400","5.8371","114.4166","5.8371","3.8914","27.4249"
"23.5200","5.8559","114.8089","5.8559","3.9039","27.5189"
"23.6000","5.8776","115.2888","5.8776","3.9184","27.6339"
"23.6800","5.8984","115.7117","5.8984","3.9323","27.7353"
"23.7600","5.9180","116.1117","5.9180","3.9453","27.8312"
"23.8400","5.9377","116.5017","5.9377","3.9585","27.9247"
"23.9200","5.9567","116.8883","5.9567","3.9711","28.0173"
"24.0000","5.9773","117.3173","5.9773","3.9849","28.1202"
"24.0800","5.9975","117.7253","5.9975","3.9983","28.2180"
"24.1600","6.0171","118.1326","6.0171","4.0114","28.3156"
"24.2400","6.0380","118.5688","6.0380","4.0253","28.4201"
"24.3200","6.0580","118.9705","6.0580","4.0386","28.5164"
"24.4000","6.0784","119.3831","6.0784","4.0523","28.6153"
"24.4800","6.0980","119.7817","6.0980","4.0653","28.7109"
"24.5600","6.1173","120.1774","6.1173","4.0782","28.8057"
"24.6400","6.1372","120.5882","6.1372","4.0914","28.9042"
"24.7200","6.1569","120.9920","6.1569","4.1046","29.0010"
"24.8000","6.1765","121.3869","6.1765","4.1176","29.0956"
"24.8800","6.1980","121.8362","6.1980","4.1320","29.2033"
"24.9600","6.2173","122.2205","6.2173","4.1449","29.2954"
"25.0400","6.2382","122.6407","6.2382","4.1588","29.3962"
"25.1200","6.2573","123.0172","6.2573","4.1715","29.4864"
"25.2000","6.2770","123.4256","6.2770","4.1847","29.5843"
"25.2800","6.2972","123.8424","6.2972","4.1981","29.6842"
"25.3600","6.3170","124.2393","6.3170","4.2113","29.7793"
"25.4400","6.3376","124.6612","6.3376","4.2251","29.8804"
"25.5200","6.3584","125.0840","6.3584","4.2389","29.9818"
"25.6000","6.3773","125.4587","6.3773","4.2516","30.0716"
"25.6800","6.3981","125.8901","6.3981","4.2654","30.1750"
"25.7600","6.4179","126.2827","6.4179","4.2786","30.2691"
"25.8400","6.4372","126.6789","6.4372","4.2915","30.3641"
"25.9200","6.4572","127.0631","6.4572","4.3048","30.4562"
"26.0000","6.4762","127.4435","6.4762","4.3175","30.5473"
"26.0800","6.4979","127.8897","6.4979","4.3319","30.6543"
"26.1600","6.5183","128.3082","6.5183","4.3455","30.7546"
"26.2400","6.5376","128.6912","6.5376","4.3584","30.8464"
"26.3200","6.5574","129.0895","6.5574","4.3716","30.9419"
"26.4000","6.5772","129.4801","6.5772","4.3848","31.0355"
"26.4800","6.5975","129.8987","6.5975","4.3983","31.1358"
"26.5600","6.6182","130.3129","6.6182","4.4121","31.2351"
"26.6400","6.6368","130.6766","6.6368","4.4245","31.3223"
"26.7200","6.6578","131.1021","6.6578","4.4385","31.4243"
"26.8000","6.6780","131.5134","6.6780","4.4520","31.5229"
"26.8800","6.6982","131.9174","6.6982","4.4655","31.6197"
"26.9600","6.7176","132.3004","6.7176","4.4784","31.7115"
"27.0400","6.7368","132.6791","6.7368","4.4912","31.8023"
"27.1200","6.7569","133.0776","6.7569","4.5046","31.8978"
"27.2000","6.7775","133.4902","6.7775","4.5184","31.9967"
"27.2800","6.7963","133.8663","6.7963","4.5309","32.0868"
"27.3600","6.8177","134.3120","6.8177","4.5451","32.1937"
"27.4400","6.8375","134.6991","6.8375","4.5583","32.2865"
"27.5200","6.8580","135.1061","6.8580","4.5720","32.3840"
"27.6000","6.8778","135.4910","6.8778","4.5852","32.4763"
"27.6800","6.8970","135.8822","6.8970","4.5980","32.5700"
"27.7600","6.9175","136.2817","6.9175","4.6117","32.6658"
"27.8400","6.9373","136.6839","6.9373","4.6248","32.7622"
"27.9200","6.9571","137.0732","6.9571","4.6381","32.8555"
"28.0000","6.9785","137.5117","6.9785","4.6523","32.9606"
"28.0800","6.9979","137.8819","6.9979","4.6653","33.0494"
"28.1600","7.0181","138.2804","7.0181","4.6787","33.1449"
"28.2400","7.0378","138.6632","7.0378","4.6919","33.2366"
"28.3200","7.0562","139.0069","7.0562","4.7041","33.3190"
"28.4000","7.0772","139.4344","7.0772","4.7181","33.4215"
"28.4800","7.0968","139.8092","7.0968","4.7312","33.5113"
"28.5600","7.1176","140.2238","7.1176","4.7451","33.6107"
"28.6400","7.1377","140.6256","7.1377","4.7585","33.7070"
"28.7200","7.1575","141.0206","7.1575","4.7716","33.8017"
"28.8000","7.1776","141.4073","7.1776","4.7850","33.8944"
"28.8800","7.1979","141.7991","7.1979","4.7986","33.9883"
"28.9600","7.2168","142.1598","7.2168","4.8112","34.0747"
"29.0400","7.2374","142.5742","7.2374","4.8249","34.1741"
"29.1200","7.2565","142.9321","7.2565","4.8377","34.2599"
"29.2000","7.2782","143.3745","7.2782","4.8521","34.3659"
"29.2800","7.2988","143.7700","7.2988","4.8658","34.4607"
"29.3600","7.3182","144.1523","7.3182","4.8788","34.5523"
"29.4400","7.3375","144.5203","7.3375","4.8917","34.6405"
"29.5200","7.3569","144.8774","7.3569","4.9046","34.7261"
"29.6000","7.3772","145.2758","7.3772","4.9181","34.8216"
"29.6800","7.3975","145.6637","7.3975","4.9316","34.9146"
"29.7600","7.4164","146.0300","7.4164","4.9443","35.0024"
"29.8400","7.4373","146.4325","7.4373","4.9582","35.0989"
"29.9200","7.4580","146.8468","7.4580","4.9720","35.1982"
"30.0000","7.4781","147.2470","7.4781","4.9854","35.2941"
"30.0800","7.4981","147.6370","7.4981","4.9987","35.3876"
"30.1600","7.5169","147.9718","7.5169","5.0113","35.4678"
"30.2400","7.5372","148.3609","7.5372","5.0248","35.5611"
"30.3200","7.5575","148.7509","7.5575","5.0383","35.6546"
"30.4000","7.5771","149.1275","7.5771","5.0514","35.7448"
"30.4800","7.5982","149.5540","7.5982","5.0655","35.8471"
"30.5600","7.6186","149.9350","7.6186","5.0791","35.9384"
"30.6400","7.6380","150.3000","7.6380","5.0920","36.0259"
"30.7200","7.6577","150.6712","7.6577","5.1051","36.1149"
"30.8000","7.6763","151.0157","7.6763","5.1175","36.1974"
"30.8800","7.6975","151.4357","7.6975","5.1317","36.2981"
"30.9600","7.7174","151.8050","7.7174","5.1450","36.3866"
"31.0400","7.7370","152.1776","7.7370","5.1580","36.4759"
"31.1200","7.7571","152.5800","7.7571","5.1714","36.5724"
"31.2000","7.7779","152.9735","7.7779","5.1852","36.6667"
"31.2800","7.7982","153.3604","7.7982","5.1988","36.7594"
"31.3600","7.8180","153.7315","7.8180","5.2120","36.8484"
"31.4400","7.8363","154.0746","7.8363","5.2242","36.9306"
"31.5200","7.8570","154.4796","7.8570","5.2380","37.0277"
"31.6000","7.8769","154.8557","7.8769","5.2513","37.1179"
"31.6800","7.8984","155.2757","7.8984","5.2656","37.2185"
"31.7600","7.9191","155.6736","7.9191","5.2794","37.3139"
"31.8400","7.9378","156.0147","7.9378","5.2919","37.3957"
"31.9200","7.9575","156.3805","7.9575","5.3050","37.4833"
"32.0000","7.9773","156.7506","7.9773","5.3182","37.5721"
"32.0800","7.9971","157.1165","7.9971","5.3314","37.6598"
"32.1600","8.0172","157.5013","8.0172","5.3448","37.7520"
"32.2400","8.0364","157.8531","8.0364","5.3576","37.8363"
"32.3200","8.0570","158.2470","8.0570","5.3714","37.9307"
"32.4000","8.0786","158.6641","8.0786","5.3857","38.0307"
"32.4800","8.0977","159.0230","8.0977","5.3984","38.1167"
"32.5600","8.1178","159.3945","8.1178","5.4119","38.2058"
"32.6400","8.1369","159.7485","8.1369","5.4246","38.2906"
"32.7200","8.1571","160.1313","8.1571","5.4381","38.3824"
"32.8000","8.1770","160.5094","8.1770","5.4513","38.4730"
"32.8800","8.1971","160.8808","8.1971","5.4647","38.5620"
"32.9600","8.2174","161.2720","8.2174","5.4783","38.6558"
"33.0400","8.2385","161.6753","8.2385","5.4923","38.7525"
"33.1200","8.2575","162.0203","8.2575","5.5050","38.8352"
"33.2000","8.2780","162.4064","8.2780","5.5186","38.9277"
"33.2800","8.2972","162.7551","8.2972","5.5315","39.0113"
"33.3600","8.3175","163.1292","8.3175","5.5450","39.1010"
"33.4400","8.3372","163.4738","8.3372","5.5582","39.1836"
"33.5200","8.3564","163.8314","8.3564","5.5709","39.2693"
"33.6000","8.3772","164.2336","8.3772","5.5848","39.3657"
"33.6800","8.3983","164.6336","8.3983","5.5989","39.4615"
"33.7600","8.4182","164.9963","8.4182","5.6121","39.5485"
"33.8400","8.4379","165.3523","8.4379","5.6253","39.6338"
"33.9200","8.4564","165.6718","8.4564","5.6376","39.7104"
"34.0000","8.4772","166.0522","8.4772","5.6515","39.8016"
"34.0800","8.4975","166.4284","8.4975","5.6650","39.8918"
"34.1600","8.5172","166.7988","8.5172","5.6781","39.9805"
"34.2400","8.5382","167.1946","8.5382","5.6921","40.0754"
"34.3200","8.5577","167.5432","8.5577","5.7051","40.1590"
"34.4000","8.5782","167.9097","8.5782","5.7188","40.2468"
"34.4800","8.5980","168.2647","8.5980","5.7320","40.3319"
"34.5600","8.6167","168.5986","8.6167","5.7445","40.4119"
"34.6400","8.6371","168.9712","8.6371","5.7581","40.5012"
"34.7200","8.6568","169.3176","8.6568","5.7712","40.5843"
"34.8000","8.6765","169.6761","8.6765","5.7843","40.6702"
"34.8800","8.6983","170.0955","8.6983","5.7989","40.7707"
"34.9600","8.7174","170.4232","8.7174","5.8116","40.8493"
"35.0400","8.7381","170.8045","8.7381","5.8254","40.9407"
"35.1200","8.7574","171.1372","8.7574","5.8383","41.0204"
"35.2000","8.7769","171.4881","8.7769","5.8513","41.1045"
"35.2800","8.7972","171.8734","8.7972","5.8648","41.1969"
"35.3600","8.8171","172.2204","8.8171","5.8781","41.2801"
"35.4400","8.8374","172.5868","8.8374","5.8916","41.3679"
"35.5200","8.8586","172.9635","8.8586","5.9058","41.4582"
"35.6000","8.8772","173.2809","8.8772","5.9182","41.5342"
"35.6800","8.8978","173.6601","8.8978","5.9319","41.6252"
"35.7600","8.9177","174.0051","8.9177","5.9452","41.7078"
"35.8400","8.9372","174.3553","8.9372","5.9582","41.7918"
"35.9200","8.9569","174.7052","8.9569","5.9713","41.8756"
"36.0000","8.9764","175.0498","8.9764","5.9842","41.9582"
"36.0800","8.9979","175.4357","8.9979","5.9986","42.0507"
"36.1600","9.0186","175.8086","9.0186","6.0124","42.1401"
"36.2400","9.0379","176.1412","9.0379","6.0253","42.2198"
"36.3200","9.0573","176.4717","9.0573","6.0382","42.2991"
"36.4000","9.0768","176.8021","9.0768","6.0512","42.3783"
"36.4800","9.0973","177.1834","9.0973","6.0648","42.4697"
"36.5600","9.1181","177.5523","9.1181","6.0787","42.5581"
"36.6400","9.1365","177.8677","9.1365","6.0910","42.6337"
"36.7200","9.1581","178.2628","9.1581","6.1054","42.7284"
"36.8000","9.1782","178.6068","9.1782","6.1188","42.8108"
"36.8800","9.1983","178.9592","9.1983","6.1322","42.8953"
"36.9600","9.2176","179.2971","9.2176","6.1451","42.9763"
"37.0400","9.2370","179.6075","9.2370","6.1580","43.0507"
"37.1200","9.2568","179.9599","9.2568","6.1712","43.1352"
"37.2000","9.2776","180.3268","9.2776","6.1851","43.2231"
"37.2800","9.2967","180.6522","9.2967","6.1978","43.3011"
"37.3600","9.3177","181.0368","9.3177","6.2118","43.3933"
"37.4400","9.3372","181.3605","9.3372","6.2248","43.4709"
"37.5200","9.3580","181.7261","9.3580","6.2387","43.5585"
"37.6000","9.3776","182.0526","9.3776","6.2518","43.6368"
"37.6800","9.3969","182.3842","9.3969","6.2646","43.7162"
"37.7600","9.4172","182.7305","9.4172","6.2781","43.7993"
"37.8400","9.4371","183.0683","9.4371","6.2914","43.8802"
"37.9200","9.4569","183.4148","9.4569","6.3046","43.9633"
"38.0000","9.4782","183.8030","9.4782","6.3188","44.0563"
"38.0800","9.4978","184.1088","9.4978","6.3319","44.1296"
"38.1600","9.5179","184.4569","9.5179","6.3453","44.2131"
"38.2400","9.5380","184.7861","9.5380","6.3586","44.2920"
"38.3200","9.5565","185.1032","9.5565","6.3710","44.3680"
"38.4000","9.5777","185.4715","9.5777","6.3851","44.4563"
"38.4800","9.5967","185.7751","9.5967","6.3978","44.5290"
"38.5600","9.6176","186.1351","9.6176","6.4117","44.6153"
"38.6400","9.6378","186.4754","9.6378","6.4252","44.6969"
"38.7200","9.6574","186.7995","9.6574","6.4383","44.7746"
"38.8000","9.6775","187.1311","9.6775","6.4517","44.8540"
"38.8800","9.6978","187.4833","9.6978","6.4652","44.9385"
"38.9600","9.7169","187.7969","9.7169","6.4779","45.0136"
"39.0400","9.7377","188.1522","9.7377","6.4918","45.0988"
"39.1200","9.7564","188.4437","9.7564","6.5043","45.1687"
"39.2000","9.7783","188.8215","9.7783","6.5188","45.2592"
"39.2800","9.7985","189.1629","9.7985","6.5324","45.3411"
"39.3600","9.8183","189.4857","9.8183","6.5456","45.4184"
"39.4400","9.8376","189.8010","9.8376","6.5584","45.4940"
"39.5200","9.8574","190.1199","9.8574","6.5716","45.5705"
"39.6000","9.8771","190.4413","9.8771","6.5848","45.6475"
"39.6800","9.8974","190.7804","9.8974","6.5982","45.7288"
"39.7600","9.9165","191.0754","9.9165","6.6110","45.7995"
"39.8400","9.9372","191.4343","9.9372","6.6248","45.8855"
"39.9200","9.9578","191.7669","9.9578","6.6385","45.9652"
"40.0000","9.9780","192.1035","9.9780","6.6520","46.0459"
"40.0800","9.9979","192.4186","9.9979","6.6653","46.1214"
"40.1600","10.0166","192.7118","10.0166","6.6777","46.1917"
"40.2400","10.0375","193.0602","10.0375","6.6916","46.2752"
"40.3200","10.0574","193.3724","10.0574","6.7049","46.3501"
"40.4000","10.0771","193.6920","10.0771","6.7180","46.4267"
"40.4800","10.0980","194.0461","10.0980","6.7320","46.5115"
"40.5600","10.1184","194.3675","10.1184","6.7456","46.5886"
"40.6400","10.1379","194.6733","10.1379","6.7586","46.6619"
"40.7200","10.1578","194.9862","10.1578","6.7718","46.7369"
"40.8000","10.1765","195.2738","10.1765","6.7843","46.8058"
"40.8800","10.1979","195.6265","10.1979","6.7986","46.8903"
"40.9600","10.2169","195.9106","10.2169","6.8113","46.9584"
"41.0400","10.2361","196.2081","10.2361","6.8241","47.0297"
"41.1200","10.2572","196.5639","10.2572","6.8381","47.1150"
"41.2000","10.2779","196.8875","10.2779","6.8519","47.1926"
"41.2800","10.2981","197.2189","10.2981","6.8654","47.2720"
"41.3600","10.3184","197.5362","10.3184","6.8790","47.3481"
"41.4400","10.3365","197.7993","10.3365","6.8910","47.4111"
"41.5200","10.3570","198.1198","10.3570","6.9047","47.4880"
"41.6000","10.3770","198.4289","10.3770","6.9180","47.5621"
"41.6800","10.3980","198.7716","10.3980","6.9320","47.6442"
"41.7600","10.4188","199.0956","10.4188","6.9459","47.7219"
"41.8400","10.4378","199.3717","10.4378","6.9586","47.7880"
"41.9200","10.4579","199.6729","10.4579","6.9719","47.8602"
"42.0000","10.4776","199.9790","10.4776","6.9851","47.9336"
"42.0800","10.4972","200.2789","10.4972","6.9981","48.0055"
"42.1600","10.5174","200.5949","10.5174","7.0116","48.0812"
"42.2400","10.5364","200.8647","10.5364","7.0243","48.1459"
"42.3200","10.5568","201.1797","10.5568","7.0379","48.2214"
"42.4000","10.5784","201.5262","10.5784","7.0523","48.3044"
"42.4800","10.5978","201.8217","10.5978","7.0652","48.3753"
"42.5600","10.6182","202.1258","10.6182","7.0788","48.4482"
"42.6400","10.6367","202.3827","10.6367","7.0911","48.5098"
"42.7200","10.6571","202.6974","10.6571","7.1047","48.5852"
"42.8000","10.6775","203.0215","10.6775","7.1183","48.6629"
"42.8800","10.6972","203.3113","10.6972","7.1314","48.7323"
"42.9600","10.7178","203.6208","10.7178","7.1452","48.8065"
"43.0400","10.7386","203.9349","10.7386","7.1591","48.8818"
"43.1200","10.7576","204.2051","10.7576","7.1717","48.9466"
"43.2000","10.7778","204.5076","10.7778","7.1852","49.0191"
"43.2800","10.7973","204.7863","10.7973","7.1982","49.0859"
"43.3600","10.8181","205.1040","10.8181","7.2121","49.1620"
"43.4400","10.8373","205.3602","10.8373","7.2249","49.2234"
"43.5200","10.8555","205.6084","10.8555","7.2370","49.2829"
"43.6000","10.8770","205.9404","10.8770","7.2513","49.3625"
"43.6800","10.8981","206.2613","10.8981","7.2654","49.4394"
"43.7600","10.9176","206.5237","10.9176","7.2784","49.5023"
"43.8400","10.9379","206.8280","10.9379","7.2919","49.5753"
"43.9200","10.9568","207.0810","10.9568","7.3046","49.6359"
"44.0000","10.9775","207.3775","10.9775","7.3184","49.7070"
"44.0800","10.9977","207.6704","10.9977","7.3318","49.7772"
"44.1600","11.0173","207.9580","11.0173","7.3448","49.8461"
"44.2400","11.0382","208.2559","11.0382","7.3588","49.9175"
"44.3200","11.0576","208.5181","11.0576","7.3717","49.9804"
"44.4000","11.0783","208.8137","11.0783","7.3856","50.0512"
"44.4800","11.0980","209.0831","11.0980","7.3987","50.1158"
"44.5600","11.1169","209.3368","11.1169","7.4113","50.1766"
"44.6400","11.1368","209.6193","11.1368","7.4246","50.2443"
"44.7200","11.1570","209.8987","11.1570","7.4380","50.3113"
"44.8000","11.1765","210.1864","11.1765","7.4510","50.3802"
"44.8800","11.1983","210.4999","11.1983","7.4655","50.4554"
"44.9600","11.2177","210.7542","11.2177","7.4785","50.5163"
"45.0400","11.2382","211.0257","11.2382","7.4921","50.5814"
"45.1200","11.2573","211.2832","11.2573","7.5048","50.6431"
"45.2000","11.2772","211.5652","11.2772","7.5181","50.7107"
"45.2800","11.2974","211.8502","11.2974","7.5316","50.7791"
"45.3600","11.3172","212.1016","11.3172","7.5448","50.8393"
"45.4400","11.3374","212.3753","11.3374","7.5583","50.9049"
"45.5200","11.3586","212.6687","11.3586","7.5724","50.9752"
"45.6000","11.3775","212.9050","11.3775","7.5850","51.0319"
"45.6800","11.3980","213.1915","11.3980","7.5986","51.1006"
"45.7600","11.4177","213.4552","11.4177","7.6118","51.1638"
"45.8400","11.4371","213.7145","11.4371","7.6248","51.2259"
"45.9200","11.4573","213.9774","11.4573","7.6382","51.2889"
"46.0000","11.4756","214.1981","11.4756","7.6504","51.3418"
"46.0800","11.4974","214.5016","11.4974","7.6649","51.4146"
"46.1600","11.5183","214.7875","11.5183","7.6789","51.4831"
"46.2400","11.5379","215.0446","11.5379","7.6919","51.5447"
"46.3200","11.5574","215.2873","11.5574","7.7049","51.6029"
"46.4000","11.5771","215.5377","11.5771","7.7181","51.6629"
"46.4800","11.5977","215.8154","11.5977","7.7318","51.7295"
"46.5600","11.6181","216.0747","11.6181","7.7454","51.7916"
"46.6400","11.6364","216.2992","11.6364","7.7576","51.8454"
"46.7200","11.6583","216.6145","11.6583","7.7722","51.9210"
"46.8000","11.6783","216.8689","11.6783","7.7855","51.9820"
"46.8800","11.6982","217.1223","11.6982","7.7988","52.0427"
"46.9600","11.7173","217.3631","11.7173","7.8116","52.1004"
"47.0400","11.7370","217.6015","11.7370","7.8246","52.1576"
"47.1200","11.7571","217.8640","11.7571","7.8381","52.2205"
"47.2000","11.7775","218.1180","11.7775","7.8516","52.2814"
"47.2800","11.7965","218.3603","11.7965","7.8644","52.3395"
"47.3600","11.8179","218.6487","11.8179","7.8786","52.4086"
"47.4400","11.8375","218.8726","11.8375","7.8916","52.4623"
"47.5200","11.8578","219.1364","11.8578","7.9052","52.5255"
"47.6000","11.8777","219.3810","11.8777","7.9185","52.5841"
"47.6800","11.8968","219.6183","11.8968","7.9312","52.6410"
"47.7600","11.9178","219.8874","11.9178","7.9452","52.7055"
"47.8400","11.9373","220.1149","11.9373","7.9582","52.7601"
"47.9200","11.9572","220.3603","11.9572","7.9714","52.8189"
"48.0000","11.9781","220.6306","11.9781","7.9854","52.8836"
"48.0800","11.9982","220.8633","11.9982","7.9988","52.9394"
"48.1600","12.0181","221.1086","12.0181","8.0121","52.9982"
"48.2400","12.0376","221.3306","12.0376","8.0251","53.0514"
"48.3200","12.0567","221.5647","12.0567","8.0378","53.1076"
"48.4000","12.0774","221.8173","12.0774","8.0516","53.1681"
"48.4800","12.0965","222.0368","12.0965","8.0643","53.2207"
"48.5600","12.1177","222.3005","12.1177","8.0784","53.2839"
"48.6400","12.1377","222.5381","12.1378","8.0918","53.3409"
"48.7200","12.1577","222.7633","12.1577","8.1051","53.3948"
"48.8000","12.1776","223.0043","12.1776","8.1184","53.4526"
"48.8800","12.1979","223.2399","12.1979","8.1320","53.5091"
"48.9600","12.2168","223.4515","12.2168","8.1445","53.5598"
"49.0400","12.2376","223.7019","12.2376","8.1584","53.6198"
"49.1200","12.2567","223.9043","12.2567","8.1711","53.6683"
"49.2000","12.2784","224.1830","12.2784","8.1856","53.7351"
"49.2800","12.2986","224.4119","12.2986","8.1991","53.7900"
"49.3600","12.3181","224.6315","12.3181","8.2121","53.8426"
"49.4400","12.3373","224.8351","12.3373","8.2249","53.8914"
"49.5200","12.3570","225.0432","12.3570","8.2380","53.9413"
"49.6000","12.3773","225.2836","12.3773","8.2515","53.9989"
"49.6800","12.3977","225.5115","12.3977","8.2651","54.0536"
"49.7600","12.4161","225.6974","12.4161","8.2774","54.0981"
"49.8400","12.4373","225.9541","12.4373","8.2915","54.1597"
"49.9200","12.4579","226.1879","12.4579","8.3052","54.2157"
"50.0000","12.4782","226.4252","12.4782","8.3188","54.2726"
"50.0800","12.4982","226.6303","12.4982","8.3321","54.3217"
"50.1600","12.5167","226.8091","12.5167","8.3445","54.3646"
"50.2400","12.5371","227.0379","12.5371","8.3581","54.4195"
"50.3200","12.5571","227.2531","12.5571","8.3714","54.4710"
"50.4000","12.5773","227.4893","12.5773","8.3848","54.5276"
"50.4800","12.5981","227.7254","12.5981","8.3987","54.5842"
"50.5600","12.6186","227.9446","12.6186","8.4124","54.6368"
"50.6400","12.6379","228.1378","12.6379","8.4253","54.6831"
"50.7200","12.6579","228.3463","12.6579","8.4386","54.7331"
"50.8000","12.6764","228.5294","12.6764","8.4509","54.7769"
"50.8800","12.6980","228.7748","12.6980","8.4653","54.8358"
"50.9600","12.7170","228.9539","12.7170","8.4780","54.8787"
"51.0400","12.7369","229.1640","12.7369","8.4913","54.9291"
"51.1200","12.7572","229.3793","12.7572","8.5048","54.9807"
"51.2000","12.7777","229.5917","12.7777","8.5185","55.0316"
"51.2800","12.7981","229.8035","12.7981","8.5321","55.0823"
"51.3600","12.8184","230.0134","12.8184","8.5456","55.1326"
"51.4400","12.8365","230.1783","12.8365","8.5577","55.1722"
"51.5200","12.8566","230.3862","12.8566","8.5710","55.2220"
"51.6000","12.8767","230.5993","12.8767","8.5845","55.2731"
"51.6800","12.8980","230.8222","12.8980","8.5987","55.3265"
"51.7600","12.9188","231.0279","12.9188","8.6125","55.3758"
"51.8400","12.9378","231.2040","12.9378","8.6252","55.4180"
"51.9200","12.9579","231.4091","12.9579","8.6386","55.4672"
"52.0000","12.9777","231.6008","12.9777","8.6518","55.5131"
"52.0800","12.9973","231.7902","12.9973","8.6649","55.5585"
"52.1600","13.0178","232.0135","13.0178","8.6785","55.6121"
"52.2400","13.0365","232.1734","13.0365","8.6910","55.6504"
"52.3200","13.0570","232.3778","13.0570","8.7046","55.6994"
"52.4000","13.0786","232.5986","13.0786","8.7191","55.7523"
"52.4800","13.0979","232.7861","13.0979","8.7319","55.7972"
"52.5600","13.1179","232.9665","13.1179","8.7453","55.8405"
"52.6400","13.1368","233.1340","13.1368","8.7579","55.8806"
"52.7200","13.1571","233.3322","13.1571","8.7714","55.9282"
"52.8000","13.1774","233.5330","13.1774","8.7849","55.9763"
"52.8800","13.1970","233.7081","13.1970","8.7980","56.0182"
"52.9600","13.2178","233.9102","13.2178","8.8119","56.0667"
"53.0400","13.2382","234.1046","13.2382","8.8255","56.1133"
"53.1200","13.2578","234.2785","13.2578","8.8385","56.1550"
"53.2000","13.2781","234.4774","13.2781","8.8521","56.2026"
"53.2800","13.2971","234.6356","13.2971","8.8647","56.2406"
"53.3600","13.3176","234.8215","13.3176","8.8784","56.2851"
"53.4400","13.3375","234.9993","13.3375","8.8916","56.3277"
"53.5200","13.3561","235.1598","13.3561","8.9041","56.3662"
"53.6000","13.3772","235.3629","13.3772","8.9181","56.4149"
"53.6800","13.3981","235.5558","13.3981","8.9321","56.4611"
"53.7600","13.4177","235.7242","13.4177","8.9451","56.5015"
"53.8400","13.4374","235.8858","13.4374","8.9583","56.5402"
"53.9200","13.4568","236.0465","13.4568","8.9712","56.5787"
"54.0000","13.4775","236.2346","13.4775","8.9850","56.6238"
"54.0800","13.4977","236.4119","13.4977","8.9985","56.6663"
"54.1600","13.5173","236.5714","13.5173","9.0115","56.7046"
"54.2400","13.5381","236.7759","13.5381","9.0254","56.7536"
"54.3200","13.5578","236.9274","13.5578","9.0386","56.7899"
"54.4000","13.5781","237.0995","13.5781","9.0521","56.8311"
"54.4800","13.5979","237.2692","13.5979","9.0653","56.8718"
"54.5600","13.6172","237.4225","13.6172","9.0781","56.9086"
"54.6400","13.6373","237.6045","13.6373","9.0916","56.9522"
"54.7200","13.6570","237.7551","13.6570","9.1046","56.9883"
"54.8000","13.6765","237.9120","13.6765","9.1177","57.0259"
"54.8800","13.6984","238.1232","13.6984","9.1323","57.0765"
"54.9600","13.7175","238.2667","13.7175","9.1450","57.1109"
"55.0400","13.7379","238.4334","13.7379","9.1586","57.1509"
"55.1200","13.7573","238.5766","13.7573","9.1715","57.1852"
"55.2000","13.7770","238.7382","13.7770","9.1846","57.2239"
"55.2800","13.7973","238.9003","13.7973","9.1982","57.2628"
"55.3600","13.8170","239.0414","13.8170","9.2113","57.2966"
"55.4400","13.8376","239.2104","13.8376","9.2251","57.3371"
"55.5200","13.8586","239.3885","13.8586","9.2391","57.3798"
"55.6000","13.8776","239.5231","13.8776","9.2517","57.4121"
"55.6800","13.8980","239.6761","13.8980","9.2654","57.4487"
"55.7600","13.9174","239.8167","13.9174","9.2783","57.4824"
"55.8400","13.9373","239.9677","13.9373","9.2916","57.5186"
"55.9200","13.9573","240.1156","13.9573","9.3048","57.5541"
"56.0000","13.9762","240.2428","13.9762","9.3175","57.5846"
"56.0800","13.9971","240.4031","13.9971","9.3314","57.6230"
"56.1600","14.0180","240.5757","14.0180","9.3453","57.6644"
"56.2400","14.0379","240.7143","14.0379","9.3586","57.6976"
"56.3200","14.0574","240.8426","14.0574","9.3716","57.7283"
"56.4000","14.0769","240.9705","14.0769","9.3846","57.7590"
"56.4800","14.0975","241.1410","14.0975","9.3984","57.7999"
"56.5600","14.1181","241.2840","14.1181","9.4121","57.8341"
"56.6400","14.1366","241.4069","14.1366","9.4244","57.8636"
"56.7200","14.1581","241.5754","14.1581","9.4387","57.9040"
"56.8000","14.1782","241.7224","14.1782","9.4521","57.9392"
"56.8800","14.1985","241.8657","14.1985","9.4657","57.9736"
"56.9600","14.2176","241.9785","14.2176","9.4784","58.0006"
"57.0400","14.2370","242.1134","14.2370","9.4913","58.0329"
"57.1200","14.2568","242.2365","14.2568","9.5046","58.0624"
"57.2000","14.2774","242.3922","14.2774","9.5183","58.0998"
"57.2800","14.2964","242.5188","14.2964","9.5309","58.1301"
"57.3600","14.3176","242.6902","14.3176","9.5451","58.1712"
"57.4400","14.3376","242.8173","14.3376","9.5584","58.2016"
"57.5200","14.3579","242.9527","14.3579","9.5719","58.2341"
"57.6000","14.3778","243.0910","14.3778","9.5852","58.2673"
"57.6800","14.3970","243.2010","14.3970","9.5980","58.2936"
"57.7600","14.4174","243.3422","14.4174","9.6116","58.3275"
"57.8400","14.4372","243.4621","14.4372","9.6248","58.3562"
"57.9200","14.4571","243.6086","14.4571","9.6381","58.3913"
"58.0000","14.4783","243.7676","14.4783","9.6522","58.4294"
"58.0800","14.4982","243.8952","14.4982","9.6655","58.4600"
"58.1600","14.5182","244.0183","14.5182","9.6788","58.4895"
"58.2400","14.5377","244.1306","14.5377","9.6918","58.5164"
"58.3200","14.5566","244.2442","14.5566","9.7044","58.5437"
"58.4000","14.5772","244.3841","14.5772","9.7181","58.5772"
"58.4800","14.5965","244.4945","14.5965","9.7310","58.6037"
"58.5600","14.6172","244.6318","14.6172","9.7448","58.6366"
"58.6400","14.6383","244.7752","14.6383","9.7589","58.6710"
"58.7200","14.6574","244.8927","14.6574","9.7716","58.6991"
"58.8000","14.6776","245.0124","14.6776","9.7851","58.7278"
"58.8800","14.6977","245.1395","14.6977","9.7985","58.7583"
"58.9600","14.7173","245.2509","14.7173","9.8115","58.7850"
"59.0400","14.7368","245.3490","14.7368","9.8245","58.8085"
"59.1200","14.7563","245.4587","14.7563","9.8375","58.8348"
"59.2000","14.7781","245.6166","14.7781","9.8521","58.8726"
"59.2800","14.7988","245.7335","14.7988","9.8659","58.9006"
"59.3600","14.8184","245.8472","14.8184","9.8789","58.9279"
"59.4400","14.8375","245.9447","14.8375","9.8917","58.9513"
"59.5200","14.8569","246.0381","14.8569","9.9046","58.9737"
"59.6000","14.8771","246.1502","14.8771","9.9180","59.0005"
"59.6800","14.8976","246.2748","14.8976","9.9318","59.0304"
"59.7600","14.9164","246.3556","14.9164","9.9443","59.0498"
"59.8400","14.9372","246.4784","14.9372","9.9582","59.0792"
"59.9200","14.9583","246.6061","14.9583","9.9722","59.1098"
"60.0000","14.9777","246.6972","14.9777","9.9852","59.1316"
"60.0800","14.9977","246.8038","14.9977","9.9984","59.1572"
"60.0900","15.0002","246.8136","15.0002","10.0002","59.1595"