File: data/instron_tests/metamaterials/250327/250327_1467_BULK_m2_NoTransition.is_comp_Exports/250327_1467_BULK_m2_NoTransition_1_1.csv
Results Table 1
,Compression Axis,H*,V*,Height,Thickness,Width,Area,Fixture separation,Specimen label
,,,,(mm),(mm),(mm),(mm^2),(mm),
"1","Y","","","149.00","28.00","149.00","4172.00","150.00","1467_BULK_m2_NoTransition"

Results Table 2
,Modulus (Segment 0 % - 5 %),Compression Axis
,(kPa),
"1","782.90","Y"

Time,Displacement,Force,Compressive displacement,Compressive strain (Displacement),Compressive stress
(s),(mm),(N),(mm),(%),(kPa)
"0.0000","0.0000","-1.6105","0.0000","0.0000","-0.3860"
"0.0800","0.0016","-1.5813","0.0016","0.0011","-0.3790"
"0.1600","0.0120","-1.2340","0.0120","0.0080","-0.2958"
"0.2400","0.0325","-0.5859","0.0325","0.0216","-0.1404"
"0.3200","0.0524","-0.0071","0.0524","0.0349","-0.0017"
"0.4000","0.0707","0.5202","0.0707","0.0472","0.1247"
"0.4800","0.0916","1.1204","0.0916","0.0611","0.2685"
"0.5600","0.1129","1.7256","0.1129","0.0753","0.4136"
"0.6400","0.1322","2.2666","0.1322","0.0881","0.5433"
"0.7200","0.1514","2.8039","0.1514","0.1009","0.6721"
"0.8000","0.1710","3.3422","0.1710","0.1140","0.8011"
"0.8800","0.1921","3.9172","0.1921","0.1281","0.9389"
"0.9600","0.2122","4.4578","0.2122","0.1415","1.0685"
"1.0400","0.2308","4.9573","0.2308","0.1539","1.1882"
"1.1200","0.2517","5.5087","0.2517","0.1678","1.3204"
"1.2000","0.2723","6.0682","0.2723","0.1815","1.4545"
"1.2800","0.2923","6.5934","0.2923","0.1949","1.5804"
"1.3600","0.3125","7.1354","0.3125","0.2083","1.7103"
"1.4400","0.3313","7.6127","0.3313","0.2209","1.8247"
"1.5200","0.3517","8.1512","0.3517","0.2345","1.9538"
"1.6000","0.3719","8.6672","0.3719","0.2479","2.0775"
"1.6800","0.3916","9.1727","0.3916","0.2611","2.1986"
"1.7600","0.4130","9.7354","0.4130","0.2753","2.3335"
"1.8400","0.4324","10.2214","0.4324","0.2883","2.4500"
"1.9200","0.4522","10.7296","0.4522","0.3015","2.5718"
"2.0000","0.4723","11.2377","0.4723","0.3148","2.6936"
"2.0800","0.4916","11.7247","0.4916","0.3277","2.8103"
"2.1600","0.5117","12.2424","0.5117","0.3411","2.9344"
"2.2400","0.5314","12.7369","0.5314","0.3543","3.0529"
"2.3200","0.5509","13.2356","0.5509","0.3673","3.1725"
"2.4000","0.5728","13.7881","0.5728","0.3819","3.3049"
"2.4800","0.5923","14.2678","0.5923","0.3948","3.4199"
"2.5600","0.6130","14.7876","0.6130","0.4086","3.5445"
"2.6400","0.6318","15.2487","0.6318","0.4212","3.6550"
"2.7200","0.6510","15.7271","0.6510","0.4340","3.7697"
"2.8000","0.6714","16.2561","0.6714","0.4476","3.8965"
"2.8800","0.6920","16.7645","0.6920","0.4613","4.0183"
"2.9600","0.7117","17.2354","0.7117","0.4745","4.1312"
"3.0400","0.7329","17.7703","0.7329","0.4886","4.2594"
"3.1200","0.7521","18.2411","0.7521","0.5014","4.3723"
"3.2000","0.7723","18.7471","0.7723","0.5149","4.4936"
"3.2800","0.7923","19.2237","0.7923","0.5282","4.6078"
"3.3600","0.8126","19.7311","0.8126","0.5418","4.7294"
"3.4400","0.8316","20.1958","0.8316","0.5544","4.8408"
"3.5200","0.8498","20.6272","0.8498","0.5665","4.9442"
"3.6000","0.8718","21.1771","0.8718","0.5812","5.0760"
"3.6800","0.8933","21.7204","0.8933","0.5955","5.2062"
"3.7600","0.9123","22.1852","0.9123","0.6082","5.3176"
"3.8400","0.9317","22.6543","0.9317","0.6211","5.4301"
"3.9200","0.9515","23.1277","0.9515","0.6343","5.5436"
"4.0000","0.9713","23.6100","0.9713","0.6475","5.6592"
"4.0800","0.9921","24.1160","0.9921","0.6614","5.7804"
"4.1600","1.0113","24.5905","1.0113","0.6742","5.8942"
"4.2400","1.0331","25.1256","1.0331","0.6888","6.0224"
"4.3200","1.0525","25.5842","1.0525","0.7017","6.1324"
"4.4000","1.0727","26.0736","1.0727","0.7151","6.2497"
"4.4800","1.0923","26.5438","1.0923","0.7282","6.3624"
"4.5600","1.1114","26.9857","1.1114","0.7409","6.4683"
"4.6400","1.1317","27.4729","1.1317","0.7544","6.5851"
"4.7200","1.1519","27.9599","1.1519","0.7680","6.7018"
"4.8000","1.1708","28.3993","1.1708","0.7805","6.8071"
"4.8800","1.1920","28.9177","1.1920","0.7947","6.9314"
"4.9600","1.2123","29.3993","1.2123","0.8082","7.0468"
"5.0400","1.2324","29.8030","1.2324","0.8216","7.1436"
"5.1200","1.2522","30.2771","1.2522","0.8348","7.2572"
"5.2000","1.2713","30.7254","1.2713","0.8475","7.3647"
"5.2800","1.2919","31.2216","1.2919","0.8612","7.4836"
"5.3600","1.3122","31.6942","1.3122","0.8748","7.5969"
"5.4400","1.3317","32.1673","1.3317","0.8878","7.7103"
"5.5200","1.3525","32.6623","1.3525","0.9017","7.8289"
"5.6000","1.3719","33.1049","1.3719","0.9146","7.9350"
"5.6800","1.3925","33.5979","1.3925","0.9283","8.0532"
"5.7600","1.4130","34.0864","1.4130","0.9420","8.1703"
"5.8400","1.4314","34.5155","1.4314","0.9543","8.2731"
"5.9200","1.4520","34.9958","1.4520","0.9680","8.3883"
"6.0000","1.4709","35.4329","1.4709","0.9806","8.4930"
"6.0800","1.4919","35.9309","1.4919","0.9946","8.6124"
"6.1600","1.5125","36.4204","1.5125","1.0083","8.7297"
"6.2400","1.5323","36.8786","1.5323","1.0215","8.8396"
"6.3200","1.5518","37.3307","1.5518","1.0345","8.9479"
"6.4000","1.5720","37.7967","1.5720","1.0480","9.0596"
"6.4800","1.5911","38.2508","1.5911","1.0608","9.1685"
"6.5600","1.6123","38.7490","1.6123","1.0749","9.2879"
"6.6400","1.6311","39.1803","1.6311","1.0874","9.3913"
"6.7200","1.6525","39.6840","1.6525","1.1017","9.5120"
"6.8000","1.6732","40.1658","1.6732","1.1155","9.6275"
"6.8800","1.6925","40.6147","1.6925","1.1283","9.7351"
"6.9600","1.7118","41.0491","1.7118","1.1412","9.8392"
"7.0400","1.7317","41.5129","1.7317","1.1545","9.9504"
"7.1200","1.7514","41.9593","1.7514","1.1676","10.0574"
"7.2000","1.7721","42.4477","1.7721","1.1814","10.1744"
"7.2800","1.7909","42.8664","1.7909","1.1939","10.2748"
"7.3600","1.8122","43.3756","1.8122","1.2082","10.3968"
"7.4400","1.8324","43.8423","1.8324","1.2216","10.5087"
"7.5200","1.8518","44.2920","1.8518","1.2346","10.6165"
"7.6000","1.8721","44.7601","1.8721","1.2481","10.7287"
"7.6800","1.8912","45.1926","1.8912","1.2608","10.8323"
"7.7600","1.9124","45.6882","1.9124","1.2749","10.9512"
"7.8400","1.9321","46.1347","1.9321","1.2880","11.0582"
"7.9200","1.9513","46.5897","1.9513","1.3009","11.1672"
"8.0000","1.9713","47.0569","1.9713","1.3142","11.2792"
"8.0800","1.9930","47.5608","1.9930","1.3287","11.4000"
"8.1600","2.0130","48.0178","2.0130","1.3420","11.5095"
"8.2400","2.0330","48.4667","2.0330","1.3553","11.6171"
"8.3200","2.0508","48.8638","2.0508","1.3672","11.7123"
"8.4000","2.0718","49.3466","2.0718","1.3812","11.8280"
"8.4800","2.0915","49.8010","2.0915","1.3944","11.9370"
"8.5600","2.1123","50.3254","2.1123","1.4082","12.0627"
"8.6400","2.1320","50.7784","2.1320","1.4214","12.1712"
"8.7200","2.1521","51.2144","2.1521","1.4347","12.2758"
"8.8000","2.1725","51.6937","2.1725","1.4484","12.3906"
"8.8800","2.1926","52.1468","2.1926","1.4617","12.4992"
"8.9600","2.2111","52.5574","2.2111","1.4741","12.5977"
"9.0400","2.2317","53.0321","2.2317","1.4878","12.7114"
"9.1200","2.2515","53.4769","2.2515","1.5010","12.8180"
"9.2000","2.2721","53.9461","2.2721","1.5147","12.9305"
"9.2800","2.2931","54.4203","2.2931","1.5287","13.0442"
"9.3600","2.3125","54.8495","2.3125","1.5417","13.1471"
"9.4400","2.3326","55.2969","2.3326","1.5551","13.2543"
"9.5200","2.3519","55.7303","2.3519","1.5680","13.3582"
"9.6000","2.3709","56.1629","2.3709","1.5806","13.4619"
"9.6800","2.3916","56.6287","2.3916","1.5944","13.5735"
"9.7600","2.4114","57.0659","2.4114","1.6076","13.6783"
"9.8400","2.4316","57.5152","2.4316","1.6211","13.7860"
"9.9200","2.4526","57.9922","2.4526","1.6351","13.9003"
"10.0000","2.4721","58.4336","2.4721","1.6481","14.0061"
"10.0800","2.4928","58.9042","2.4928","1.6619","14.1189"
"10.1600","2.5117","59.3223","2.5117","1.6745","14.2192"
"10.2400","2.5318","59.7846","2.5318","1.6878","14.3300"
"10.3200","2.5513","60.2087","2.5513","1.7009","14.4316"
"10.4000","2.5707","60.6432","2.5707","1.7138","14.5358"
"10.4800","2.5925","61.1201","2.5925","1.7284","14.6501"
"10.5600","2.6136","61.5849","2.6136","1.7424","14.7615"
"10.6400","2.6322","61.9814","2.6322","1.7548","14.8565"
"10.7200","2.6520","62.4235","2.6520","1.7680","14.9625"
"10.8000","2.6712","62.8417","2.6712","1.7808","15.0627"
"10.8800","2.6922","63.3265","2.6922","1.7948","15.1789"
"10.9600","2.7123","63.7753","2.7123","1.8082","15.2865"
"11.0400","2.7309","64.1839","2.7309","1.8206","15.3844"
"11.1200","2.7515","64.6343","2.7515","1.8343","15.4924"
"11.2000","2.7725","65.1224","2.7725","1.8483","15.6094"
"11.2800","2.7926","65.5673","2.7926","1.8618","15.7160"
"11.3600","2.8128","66.0069","2.8128","1.8752","15.8214"
"11.4400","2.8313","66.4072","2.8313","1.8875","15.9174"
"11.5200","2.8514","66.8637","2.8514","1.9010","16.0268"
"11.6000","2.8722","67.3327","2.8722","1.9148","16.1392"
"11.6800","2.8918","67.7778","2.8918","1.9278","16.2459"
"11.7600","2.9129","68.2610","2.9129","1.9419","16.3617"
"11.8400","2.9321","68.6719","2.9321","1.9547","16.4602"
"11.9200","2.9526","69.1222","2.9526","1.9684","16.5681"
"12.0000","2.9721","69.5524","2.9721","1.9814","16.6712"
"12.0800","2.9917","69.9793","2.9917","1.9945","16.7736"
"12.1600","3.0119","70.4332","3.0119","2.0079","16.8824"
"12.2400","3.0311","70.8526","3.0311","2.0207","16.9829"
"12.3200","3.0506","71.2940","3.0506","2.0337","17.0887"
"12.4000","3.0725","71.7979","3.0725","2.0483","17.2095"
"12.4800","3.0920","72.2299","3.0920","2.0614","17.3130"
"12.5600","3.1128","72.6866","3.1128","2.0752","17.4225"
"12.6400","3.1320","73.1014","3.1320","2.0880","17.5219"
"12.7200","3.1510","73.5153","3.1510","2.1007","17.6211"
"12.8000","3.1714","73.9657","3.1714","2.1143","17.7291"
"12.8800","3.1916","74.4070","3.1916","2.1277","17.8348"
"12.9600","3.2122","74.8684","3.2122","2.1415","17.9454"
"13.0400","3.2334","75.3507","3.2334","2.1556","18.0610"
"13.1200","3.2520","75.7515","3.2520","2.1680","18.1571"
"13.2000","3.2723","76.1998","3.2723","2.1815","18.2646"
"13.2800","3.2921","76.6487","3.2921","2.1947","18.3722"
"13.3600","3.3119","77.0844","3.3119","2.2080","18.4766"
"13.4400","3.3319","77.5281","3.3319","2.2213","18.5830"
"13.5200","3.3506","77.9208","3.3506","2.2337","18.6771"
"13.6000","3.3719","78.4009","3.3719","2.2479","18.7922"
"13.6800","3.3928","78.8663","3.3928","2.2619","18.9037"
"13.7600","3.4124","79.2937","3.4124","2.2750","19.0062"
"13.8400","3.4320","79.7253","3.4320","2.2880","19.1096"
"13.9200","3.4516","80.1548","3.4516","2.3011","19.2125"
"14.0000","3.4714","80.5943","3.4714","2.3143","19.3179"
"14.0800","3.4923","81.0644","3.4923","2.3282","19.4306"
"14.1600","3.5113","81.4608","3.5113","2.3409","19.5256"
"14.2400","3.5325","81.9302","3.5325","2.3550","19.6381"
"14.3200","3.5524","82.3693","3.5524","2.3683","19.7434"
"14.4000","3.5722","82.7911","3.5722","2.3814","19.8445"
"14.4800","3.5924","83.2379","3.5924","2.3949","19.9515"
"14.5600","3.6119","83.6524","3.6119","2.4079","20.0509"
"14.6400","3.6317","84.0896","3.6317","2.4211","20.1557"
"14.7200","3.6513","84.5168","3.6513","2.4342","20.2581"
"14.8000","3.6704","84.9237","3.6704","2.4469","20.3556"
"14.8800","3.6922","85.4324","3.6922","2.4615","20.4776"
"14.9600","3.7125","85.8613","3.7125","2.4750","20.5804"
"15.0400","3.7324","86.2879","3.7324","2.4883","20.6826"
"15.1200","3.7516","86.6904","3.7516","2.5011","20.7791"
"15.2000","3.7710","87.1177","3.7710","2.5140","20.8815"
"15.2800","3.7923","87.5857","3.7923","2.5282","20.9937"
"15.3600","3.8116","88.0005","3.8116","2.5411","21.0931"
"15.4400","3.8317","88.4455","3.8317","2.5545","21.1998"
"15.5200","3.8526","88.9155","3.8526","2.5684","21.3124"
"15.6000","3.8722","89.3226","3.8722","2.5815","21.4100"
"15.6800","3.8925","89.7694","3.8925","2.5950","21.5171"
"15.7600","3.9130","90.2011","3.9130","2.6086","21.6206"
"15.8400","3.9313","90.5978","3.9313","2.6209","21.7157"
"15.9200","3.9516","91.0334","3.9516","2.6344","21.8201"
"16.0000","3.9712","91.4610","3.9712","2.6475","21.9226"
"16.0800","3.9919","91.9218","3.9919","2.6613","22.0330"
"16.1600","4.0125","92.3685","4.0125","2.6750","22.1401"
"16.2400","4.0322","92.7947","4.0322","2.6881","22.2423"
"16.3200","4.0521","93.2128","4.0521","2.7014","22.3425"
"16.4000","4.0721","93.6352","4.0721","2.7148","22.4437"
"16.4800","4.0913","94.0589","4.0913","2.7276","22.5453"
"16.5600","4.1119","94.5149","4.1119","2.7413","22.6546"
"16.6400","4.1313","94.9144","4.1313","2.7542","22.7503"
"16.7200","4.1524","95.3753","4.1524","2.7683","22.8608"
"16.8000","4.1727","95.8126","4.1727","2.7818","22.9656"
"16.8800","4.1925","96.2461","4.1925","2.7950","23.0695"
"16.9600","4.2119","96.6607","4.2119","2.8080","23.1689"
"17.0400","4.2317","97.0785","4.2317","2.8211","23.2690"
"17.1200","4.2513","97.5023","4.2513","2.8342","23.3706"
"17.2000","4.2718","97.9394","4.2718","2.8479","23.4754"
"17.2800","4.2907","98.3302","4.2907","2.8605","23.5691"
"17.3600","4.3121","98.8148","4.3121","2.8747","23.6852"
"17.4400","4.3326","99.2489","4.3326","2.8884","23.7893"
"17.5200","4.3521","99.6743","4.3521","2.9014","23.8912"
"17.6000","4.3721","100.0937","4.3721","2.9147","23.9918"
"17.6800","4.3912","100.4976","4.3912","2.9275","24.0886"
"17.7600","4.4122","100.9454","4.4122","2.9415","24.1959"
"17.8400","4.4321","101.3632","4.4321","2.9548","24.2961"
"17.9200","4.4511","101.7554","4.4511","2.9674","24.3901"
"18.0000","4.4720","102.2133","4.4720","2.9813","24.4998"
"18.0800","4.4927","102.6415","4.4927","2.9951","24.6025"
"18.1600","4.5126","103.0100","4.5126","3.0084","24.6908"
"18.2400","4.5327","103.4467","4.5327","3.0218","24.7955"
"18.3200","4.5509","103.8252","4.5509","3.0339","24.8862"
"18.4000","4.5720","104.2826","4.5720","3.0480","24.9958"
"18.4800","4.5917","104.6950","4.5917","3.0611","25.0947"
"18.5600","4.6115","105.1335","4.6115","3.0743","25.1998"
"18.6400","4.6317","105.5666","4.6317","3.0878","25.3036"
"18.7200","4.6522","105.9935","4.6522","3.1014","25.4059"
"18.8000","4.6724","106.4194","4.6724","3.1149","25.5080"
"18.8800","4.6929","106.8487","4.6929","3.1286","25.6109"
"18.9600","4.7114","107.2435","4.7114","3.1409","25.7055"
"19.0400","4.7317","107.6806","4.7317","3.1545","25.8103"
"19.1200","4.7515","108.0978","4.7515","3.1676","25.9103"
"19.2000","4.7721","108.5457","4.7721","3.1814","26.0177"
"19.2800","4.7932","109.0037","4.7932","3.1954","26.1275"
"19.3600","4.8125","109.4065","4.8125","3.2084","26.2240"
"19.4400","4.8324","109.8111","4.8324","3.2216","26.3210"
"19.5200","4.8520","110.2195","4.8520","3.2347","26.4189"
"19.6000","4.8714","110.6306","4.8714","3.2476","26.5174"
"19.6800","4.8920","111.0869","4.8920","3.2613","26.6268"
"19.7600","4.9111","111.4611","4.9111","3.2741","26.7165"
"19.8400","4.9317","111.8298","4.9317","3.2878","26.8048"
"19.9200","4.9529","112.2938","4.9529","3.3019","26.9160"
"20.0000","4.9719","112.6971","4.9719","3.3146","27.0127"
"20.0800","4.9923","113.1162","4.9923","3.3282","27.1132"
"20.1600","5.0115","113.5170","5.0115","3.3410","27.2093"
"20.2400","5.0317","113.9511","5.0317","3.3544","27.3133"
"20.3200","5.0517","114.3667","5.0517","3.3678","27.4129"
"20.4000","5.0714","114.7719","5.0714","3.3810","27.5101"
"20.4800","5.0923","115.2198","5.0923","3.3948","27.6174"
"20.5600","5.1133","115.6710","5.1133","3.4089","27.7255"
"20.6400","5.1324","116.0671","5.1324","3.4216","27.8205"
"20.7200","5.1520","116.4701","5.1520","3.4346","27.9171"
"20.8000","5.1706","116.8444","5.1706","3.4471","28.0068"
"20.8800","5.1919","117.2941","5.1919","3.4613","28.1146"
"20.9600","5.2125","117.7294","5.2125","3.4750","28.2189"
"21.0400","5.2312","118.1092","5.2312","3.4875","28.3100"
"21.1200","5.2514","118.5281","5.2514","3.5009","28.4104"
"21.2000","5.2720","118.9641","5.2720","3.5147","28.5149"
"21.2800","5.2924","119.3950","5.2924","3.5283","28.6182"
"21.3600","5.3125","119.8118","5.3125","3.5417","28.7181"
"21.4400","5.3309","120.1712","5.3309","3.5539","28.8042"
"21.5200","5.3516","120.6152","5.3516","3.5677","28.9106"
"21.6000","5.3721","121.0412","5.3721","3.5814","29.0128"
"21.6800","5.3915","121.3690","5.3915","3.5944","29.0913"
"21.7600","5.4132","121.8495","5.4132","3.6088","29.2065"
"21.8400","5.4326","122.2410","5.4326","3.6217","29.3003"
"21.9200","5.4522","122.6417","5.4522","3.6348","29.3964"
"22.0000","5.4719","123.0502","5.4719","3.6479","29.4943"
"22.0800","5.4917","123.4603","5.4917","3.6611","29.5926"
"22.1600","5.5122","123.9148","5.5122","3.6748","29.7015"
"22.2400","5.5313","124.2785","5.5313","3.6875","29.7887"
"22.3200","5.5507","124.6974","5.5507","3.7004","29.8891"
"22.4000","5.5724","125.1609","5.5724","3.7150","30.0002"
"22.4800","5.5921","125.5556","5.5921","3.7281","30.0948"
"22.5600","5.6127","125.9832","5.6127","3.7418","30.1973"
"22.6400","5.6320","126.3651","5.6320","3.7546","30.2888"
"22.7200","5.6511","126.7549","5.6511","3.7674","30.3823"
"22.8000","5.6715","127.1806","5.6715","3.7810","30.4843"
"22.8800","5.6920","127.6044","5.6920","3.7946","30.5859"
"22.9600","5.7122","128.0210","5.7122","3.8082","30.6858"
"23.0400","5.7326","128.4301","5.7326","3.8217","30.7838"
"23.1200","5.7515","128.8055","5.7515","3.8344","30.8738"
"23.2000","5.7730","129.2613","5.7730","3.8487","30.9831"
"23.2800","5.7924","129.6370","5.7924","3.8616","31.0731"
"23.3600","5.8121","130.0434","5.8121","3.8747","31.1705"
"23.4400","5.8315","130.4282","5.8315","3.8876","31.2628"
"23.5200","5.8502","130.7399","5.8502","3.9001","31.3375"
"23.6000","5.8721","131.2113","5.8721","3.9147","31.4505"
"23.6800","5.8933","131.6625","5.8933","3.9289","31.5586"
"23.7600","5.9125","132.0380","5.9125","3.9416","31.6486"
"23.8400","5.9318","132.4299","5.9318","3.9545","31.7426"
"23.9200","5.9514","132.8249","5.9514","3.9676","31.8372"
"24.0000","5.9714","133.2378","5.9714","3.9810","31.9362"
"24.0800","5.9923","133.6692","5.9923","3.9949","32.0396"
"24.1600","6.0114","134.0515","6.0114","4.0076","32.1312"
"24.2400","6.0326","134.4916","6.0326","4.0218","32.2367"
"24.3200","6.0524","134.8912","6.0524","4.0349","32.3325"
"24.4000","6.0727","135.3102","6.0727","4.0485","32.4329"
"24.4800","6.0920","135.6958","6.0920","4.0613","32.5254"
"24.5600","6.1118","136.0849","6.1118","4.0746","32.6186"
"24.6400","6.1319","136.4986","6.1319","4.0879","32.7178"
"24.7200","6.1519","136.8946","6.1519","4.1012","32.8127"
"24.8000","6.1705","137.2626","6.1705","4.1137","32.9009"
"24.8800","6.1918","137.7058","6.1918","4.1279","33.0071"
"24.9600","6.2118","138.1075","6.2118","4.1412","33.1034"
"25.0400","6.2329","138.5546","6.2329","4.1552","33.2106"
"25.1200","6.2524","138.9343","6.2524","4.1682","33.3016"
"25.2000","6.2711","139.3015","6.2711","4.1807","33.3896"
"25.2800","6.2919","139.6660","6.2919","4.1946","33.4770"
"25.3600","6.3114","140.0499","6.3114","4.2076","33.5690"
"25.4400","6.3323","140.4840","6.3323","4.2215","33.6731"
"25.5200","6.3524","140.8915","6.3524","4.2349","33.7707"
"25.6000","6.3722","141.2823","6.3722","4.2481","33.8644"
"25.6800","6.3929","141.7124","6.3929","4.2620","33.9675"
"25.7600","6.4129","142.0936","6.4129","4.2753","34.0589"
"25.8400","6.4313","142.4664","6.4313","4.2875","34.1482"
"25.9200","6.4517","142.8734","6.4517","4.3011","34.2458"
"26.0000","6.4709","143.2427","6.4709","4.3139","34.3343"
"26.0800","6.4921","143.6851","6.4921","4.3280","34.4403"
"26.1600","6.5130","144.0979","6.5130","4.3420","34.5393"
"26.2400","6.5318","144.4663","6.5318","4.3545","34.6276"
"26.3200","6.5518","144.8654","6.5518","4.3679","34.7232"
"26.4000","6.5723","145.2771","6.5723","4.3815","34.8219"
"26.4800","6.5917","145.6613","6.5917","4.3944","34.9140"
"26.5600","6.6122","146.0836","6.6122","4.4081","35.0152"
"26.6400","6.6312","146.4478","6.6312","4.4208","35.1025"
"26.7200","6.6523","146.8790","6.6523","4.4349","35.2059"
"26.8000","6.6729","147.2898","6.6729","4.4486","35.3044"
"26.8800","6.6925","147.6671","6.6925","4.4616","35.3948"
"26.9600","6.7120","148.0512","6.7120","4.4747","35.4869"
"27.0400","6.7316","148.3763","6.7316","4.4877","35.5648"
"27.1200","6.7512","148.7689","6.7512","4.5008","35.6589"
"27.2000","6.7717","149.1880","6.7717","4.5144","35.7593"
"27.2800","6.7910","149.5671","6.7910","4.5273","35.8502"
"27.3600","6.8123","150.0055","6.8123","4.5416","35.9553"
"27.4400","6.8324","150.3948","6.8324","4.5549","36.0486"
"27.5200","6.8521","150.7850","6.8521","4.5681","36.1421"
"27.6000","6.8725","151.2000","6.8725","4.5816","36.2416"
"27.6800","6.8914","151.5475","6.8914","4.5943","36.3249"
"27.7600","6.9121","151.9648","6.9121","4.6081","36.4249"
"27.8400","6.9319","152.3467","6.9319","4.6213","36.5165"
"27.9200","6.9515","152.7334","6.9515","4.6343","36.6091"
"28.0000","6.9720","153.1538","6.9720","4.6480","36.7099"
"28.0800","6.9927","153.5596","6.9927","4.6618","36.8072"
"28.1600","7.0121","153.9220","7.0121","4.6747","36.8940"
"28.2400","7.0323","154.3219","7.0323","4.6882","36.9899"
"28.3200","7.0510","154.6637","7.0510","4.7007","37.0718"
"28.4000","7.0720","155.0880","7.0720","4.7146","37.1735"
"28.4800","7.0917","155.4626","7.0917","4.7278","37.2633"
"28.5600","7.1117","155.8632","7.1117","4.7411","37.3593"
"28.6400","7.1319","156.2644","7.1319","4.7546","37.4555"
"28.7200","7.1522","156.6478","7.1522","4.7681","37.5474"
"28.8000","7.1723","157.0347","7.1723","4.7815","37.6402"
"28.8800","7.1927","157.3780","7.1927","4.7951","37.7224"
"28.9600","7.2113","157.7310","7.2113","4.8076","37.8070"
"29.0400","7.2318","158.1355","7.2318","4.8212","37.9040"
"29.1200","7.2513","158.5181","7.2513","4.8342","37.9957"
"29.2000","7.2720","158.9232","7.2720","4.8480","38.0928"
"29.2800","7.2931","159.3402","7.2931","4.8620","38.1928"
"29.3600","7.3128","159.7233","7.3128","4.8752","38.2846"
"29.4400","7.3325","160.0933","7.3325","4.8883","38.3733"
"29.5200","7.3522","160.4687","7.3522","4.9015","38.4633"
"29.6000","7.3712","160.8267","7.3712","4.9141","38.5491"
"29.6800","7.3915","161.2315","7.3915","4.9276","38.6461"
"29.7600","7.4114","161.5942","7.4114","4.9409","38.7330"
"29.8400","7.4316","161.9969","7.4316","4.9544","38.8295"
"29.9200","7.4528","162.4072","7.4528","4.9685","38.9279"
"30.0000","7.4721","162.7707","7.4721","4.9814","39.0150"
"30.0800","7.4925","163.1722","7.4925","4.9950","39.1113"
"30.1600","7.5116","163.5336","7.5116","5.0077","39.1979"
"30.2400","7.5316","163.9260","7.5316","5.0211","39.2919"
"30.3200","7.5516","164.3060","7.5516","5.0344","39.3830"
"30.4000","7.5712","164.6637","7.5712","5.0475","39.4688"
"30.4800","7.5923","165.0779","7.5923","5.0615","39.5681"
"30.5600","7.6136","165.4999","7.6136","5.0757","39.6692"
"30.6400","7.6325","165.8374","7.6325","5.0883","39.7501"
"30.7200","7.6520","166.1952","7.6520","5.1013","39.8359"
"30.8000","7.6708","166.4867","7.6708","5.1139","39.9057"
"30.8800","7.6923","166.9223","7.6923","5.1282","40.0101"
"30.9600","7.7123","167.3014","7.7123","5.1416","40.1010"
"31.0400","7.7310","167.6497","7.7310","5.1540","40.1845"
"31.1200","7.7516","168.0497","7.7516","5.1677","40.2804"
"31.2000","7.7726","168.4581","7.7726","5.1818","40.3783"
"31.2800","7.7927","168.8374","7.7927","5.1951","40.4692"
"31.3600","7.8125","169.2131","7.8125","5.2083","40.5592"
"31.4400","7.8312","169.5353","7.8312","5.2208","40.6365"
"31.5200","7.8515","169.9193","7.8515","5.2343","40.7285"
"31.6000","7.8720","170.3120","7.8720","5.2480","40.8226"
"31.6800","7.8917","170.6925","7.8917","5.2612","40.9138"
"31.7600","7.9132","171.1130","7.9132","5.2755","41.0146"
"31.8400","7.9327","171.4648","7.9327","5.2885","41.0989"
"31.9200","7.9524","171.8257","7.9524","5.3016","41.1854"
"32.0000","7.9720","172.1885","7.9720","5.3146","41.2724"
"32.0800","7.9913","172.5386","7.9913","5.3275","41.3563"
"32.1600","8.0119","172.9389","8.0119","5.3413","41.4523"
"32.2400","8.0315","173.2889","8.0315","5.3544","41.5362"
"32.3200","8.0508","173.6428","8.0508","5.3672","41.6210"
"32.4000","8.0725","174.0797","8.0725","5.3817","41.7257"
"32.4800","8.0921","174.4226","8.0921","5.3948","41.8079"
"32.5600","8.1128","174.8154","8.1128","5.4086","41.9021"
"32.6400","8.1319","175.1492","8.1319","5.4213","41.9821"
"32.7200","8.1510","175.5054","8.1510","5.4340","42.0674"
"32.8000","8.1712","175.8754","8.1712","5.4475","42.1561"
"32.8800","8.1917","176.2641","8.1917","5.4612","42.2493"
"32.9600","8.2119","176.6259","8.2119","5.4746","42.3360"
"33.0400","8.2329","177.0207","8.2329","5.4886","42.4307"
"33.1200","8.2521","177.3303","8.2521","5.5014","42.5049"
"33.2000","8.2726","177.7168","8.2726","5.5150","42.5975"
"33.2800","8.2920","178.0689","8.2920","5.5280","42.6819"
"33.3600","8.3120","178.4435","8.3120","5.5414","42.7717"
"33.4400","8.3319","178.7981","8.3319","5.5546","42.8567"
"33.5200","8.3502","179.1184","8.3502","5.5668","42.9335"
"33.6000","8.3715","179.5126","8.3715","5.5810","43.0280"
"33.6800","8.3931","179.9264","8.3931","5.5954","43.1271"
"33.7600","8.4126","180.2785","8.4126","5.6084","43.2115"
"33.8400","8.4318","180.6195","8.4318","5.6212","43.2933"
"33.9200","8.4513","180.9485","8.4513","5.6342","43.3721"
"34.0000","8.4713","181.3161","8.4713","5.6475","43.4602"
"34.0800","8.4921","181.7050","8.4921","5.6614","43.5534"
"34.1600","8.5113","182.0450","8.5113","5.6742","43.6349"
"34.2400","8.5325","182.4399","8.5325","5.6883","43.7296"
"34.3200","8.5527","182.8007","8.5527","5.7018","43.8161"
"34.4000","8.5726","183.1558","8.5726","5.7151","43.9012"
"34.4800","8.5922","183.5021","8.5922","5.7281","43.9842"
"34.5600","8.6118","183.8426","8.6118","5.7412","44.0658"
"34.6400","8.6319","184.2046","8.6319","5.7546","44.1526"
"34.7200","8.6517","184.5548","8.6517","5.7678","44.2365"
"34.8000","8.6707","184.8899","8.6707","5.7805","44.3169"
"34.8800","8.6920","185.2967","8.6920","5.7947","44.4144"
"34.9600","8.7124","185.6543","8.7124","5.8082","44.5001"
"35.0400","8.7326","186.0027","8.7326","5.8217","44.5836"
"35.1200","8.7520","186.3388","8.7520","5.8347","44.6642"
"35.2000","8.7711","186.6759","8.7711","5.8474","44.7449"
"35.2800","8.7918","187.0327","8.7918","5.8612","44.8305"
"35.3600","8.8120","187.3712","8.8120","5.8747","44.9116"
"35.4400","8.8315","187.7267","8.8315","5.8877","44.9968"
"35.5200","8.8525","188.1087","8.8525","5.9017","45.0884"
"35.6000","8.8724","188.4529","8.8724","5.9149","45.1709"
"35.6800","8.8927","188.8190","8.8927","5.9285","45.2586"
"35.7600","8.9128","189.1617","8.9128","5.9419","45.3408"
"35.8400","8.9311","189.4680","8.9311","5.9541","45.4142"
"35.9200","8.9515","189.8366","8.9515","5.9677","45.5026"
"36.0000","8.9708","190.1647","8.9708","5.9805","45.5812"
"36.0800","8.9919","190.5524","8.9919","5.9946","45.6741"
"36.1600","9.0126","190.9088","9.0126","6.0084","45.7595"
"36.2400","9.0317","191.2211","9.0317","6.0211","45.8344"
"36.3200","9.0518","191.5878","9.0518","6.0345","45.9223"
"36.4000","9.0722","191.9361","9.0722","6.0481","46.0058"
"36.4800","9.0915","192.2638","9.0915","6.0610","46.0843"
"36.5600","9.1123","192.6374","9.1123","6.0749","46.1739"
"36.6400","9.1312","192.9492","9.1312","6.0875","46.2486"
"36.7200","9.1524","193.3169","9.1524","6.1016","46.3367"
"36.8000","9.1732","193.6851","9.1732","6.1155","46.4250"
"36.8800","9.1929","194.0280","9.1929","6.1286","46.5072"
"36.9600","9.2120","194.3435","9.2120","6.1414","46.5828"
"37.0400","9.2317","194.6689","9.2317","6.1545","46.6608"
"37.1200","9.2516","195.0169","9.2516","6.1677","46.7442"
"37.2000","9.2720","195.3676","9.2720","6.1813","46.8283"
"37.2800","9.2911","195.6775","9.2911","6.1941","46.9026"
"37.3600","9.3120","196.0491","9.3120","6.2080","46.9916"
"37.4400","9.3325","196.3839","9.3325","6.2217","47.0719"
"37.5200","9.3520","196.7119","9.3520","6.2347","47.1505"
"37.6000","9.3720","197.0462","9.3720","6.2480","47.2306"
"37.6800","9.3913","197.3537","9.3913","6.2608","47.3044"
"37.7600","9.4122","197.7155","9.4122","6.2748","47.3911"
"37.8400","9.4317","198.0351","9.4317","6.2878","47.4677"
"37.9200","9.4511","198.3549","9.4511","6.3007","47.5443"
"38.0000","9.4721","198.7255","9.4721","6.3147","47.6332"
"38.0800","9.4929","199.0746","9.4929","6.3286","47.7168"
"38.1600","9.5125","199.3893","9.5125","6.3417","47.7922"
"38.2400","9.5323","199.7236","9.5323","6.3548","47.8724"
"38.3200","9.5508","200.0093","9.5508","6.3672","47.9409"
"38.4000","9.5722","200.3826","9.5722","6.3815","48.0303"
"38.4800","9.5915","200.6972","9.5915","6.3943","48.1057"
"38.5600","9.6115","201.0402","9.6115","6.4077","48.1880"
"38.6400","9.6313","201.3552","9.6313","6.4208","48.2635"
"38.7200","9.6517","201.6941","9.6517","6.4345","48.3447"
"38.8000","9.6725","202.0450","9.6725","6.4483","48.4288"
"38.8800","9.6929","202.3755","9.6929","6.4619","48.5080"
"38.9600","9.7115","202.6606","9.7115","6.4743","48.5764"
"39.0400","9.7321","203.0117","9.7321","6.4881","48.6605"
"39.1200","9.7514","203.3137","9.7514","6.5010","48.7329"
"39.2000","9.7723","203.6491","9.7723","6.5149","48.8133"
"39.2800","9.7928","203.9985","9.7928","6.5285","48.8971"
"39.3600","9.8124","204.3064","9.8124","6.5416","48.9708"
"39.4400","9.8326","204.6270","9.8326","6.5551","49.0477"
"39.5200","9.8520","204.9348","9.8520","6.5680","49.1215"
"39.6000","9.8713","205.2348","9.8713","6.5809","49.1934"
"39.6800","9.8916","205.5688","9.8916","6.5944","49.2734"
"39.7600","9.9114","205.8685","9.9114","6.6076","49.3453"
"39.8400","9.9315","206.1989","9.9315","6.6210","49.4245"
"39.9200","9.9528","206.5569","9.9528","6.6352","49.5103"
"40.0000","9.9720","206.8554","9.9720","6.6480","49.5818"
"40.0800","9.9925","207.1844","9.9925","6.6617","49.6607"
"40.1600","10.0114","207.4592","10.0114","6.6743","49.7266"
"40.2400","10.0318","207.7839","10.0318","6.6879","49.8044"
"40.3200","10.0515","208.0981","10.0515","6.7010","49.8797"
"40.4000","10.0712","208.4004","10.0712","6.7141","49.9522"
"40.4800","10.0924","208.7511","10.0924","6.7282","50.0362"
"40.5600","10.1136","209.0954","10.1136","6.7424","50.1187"
"40.6400","10.1325","209.3784","10.1325","6.7550","50.1866"
"40.7200","10.1519","209.6705","10.1519","6.7679","50.2566"
"40.8000","10.1710","209.9514","10.1710","6.7807","50.3239"
"40.8800","10.1922","210.2908","10.1922","6.7948","50.4053"
"40.9600","10.2118","210.5848","10.2118","6.8078","50.4757"
"41.0400","10.2306","210.8657","10.2306","6.8204","50.5431"
"41.1200","10.2517","211.1951","10.2517","6.8345","50.6220"
"41.2000","10.2722","211.5144","10.2722","6.8481","50.6986"
"41.2800","10.2926","211.8243","10.2926","6.8617","50.7728"
"41.3600","10.3130","212.1669","10.3130","6.8753","50.8550"
"41.4400","10.3314","212.4067","10.3314","6.8876","50.9124"
"41.5200","10.3516","212.7231","10.3516","6.9011","50.9883"
"41.6000","10.3719","213.0285","10.3719","6.9146","51.0615"
"41.6800","10.3917","213.3370","10.3917","6.9278","51.1354"
"41.7600","10.4130","213.6691","10.4130","6.9420","51.2150"
"41.8400","10.4325","213.9363","10.4325","6.9550","51.2791"
"41.9200","10.4526","214.2348","10.4526","6.9684","51.3506"
"42.0000","10.4720","214.5150","10.4720","6.9814","51.4178"
"42.0800","10.4917","214.8011","10.4917","6.9945","51.4864"
"42.1600","10.5116","215.0939","10.5116","7.0077","51.5565"
"42.2400","10.5313","215.3860","10.5313","7.0208","51.6266"
"42.3200","10.5509","215.6700","10.5509","7.0339","51.6946"
"42.4000","10.5725","216.0126","10.5725","7.0483","51.7768"
"42.4800","10.5924","216.2881","10.5924","7.0616","51.8428"
"42.5600","10.6129","216.5865","10.6129","7.0752","51.9143"
"42.6400","10.6318","216.8388","10.6318","7.0878","51.9748"
"42.7200","10.6513","217.1248","10.6513","7.1009","52.0433"
"42.8000","10.6716","217.4203","10.6716","7.1144","52.1142"
"42.8800","10.6918","217.7152","10.6918","7.1279","52.1849"
"42.9600","10.7122","218.0123","10.7122","7.1415","52.2561"
"43.0400","10.7332","218.3156","10.7332","7.1555","52.3288"
"43.1200","10.7520","218.5654","10.7520","7.1680","52.3886"
"43.2000","10.7723","218.8545","10.7723","7.1815","52.4579"
"43.2800","10.7923","219.1327","10.7923","7.1948","52.5246"
"43.3600","10.8123","219.4202","10.8123","7.2082","52.5935"
"43.4400","10.8314","219.6701","10.8314","7.2209","52.6534"
"43.5200","10.8499","219.8971","10.8499","7.2332","52.7078"
"43.6000","10.8717","220.2220","10.8717","7.2478","52.7857"
"43.6800","10.8928","220.5261","10.8928","7.2618","52.8586"
"43.7600","10.9127","220.7908","10.9127","7.2751","52.9221"
"43.8400","10.9320","221.0575","10.9320","7.2880","52.9860"
"43.9200","10.9515","221.2977","10.9515","7.3010","53.0435"
"44.0000","10.9714","221.5681","10.9714","7.3143","53.1084"
"44.0800","10.9922","221.8479","10.9922","7.3281","53.1754"
"44.1600","11.0113","222.0971","11.0113","7.3409","53.2352"
"44.2400","11.0327","222.3981","11.0327","7.3551","53.3073"
"44.3200","11.0523","222.6463","11.0523","7.3682","53.3668"
"44.4000","11.0728","222.9300","11.0728","7.3819","53.4348"
"44.4800","11.0921","223.1739","11.0921","7.3947","53.4933"
"44.5600","11.1117","223.4099","11.1117","7.4078","53.5498"
"44.6400","11.1319","223.6918","11.1319","7.4212","53.6174"
"44.7200","11.1522","223.9382","11.1522","7.4348","53.6765"
"44.8000","11.1706","224.1693","11.1706","7.4471","53.7319"
"44.8800","11.1922","224.4757","11.1922","7.4615","53.8053"
"44.9600","11.2123","224.7168","11.2123","7.4749","53.8631"
"45.0400","11.2327","224.9831","11.2327","7.4884","53.9269"
"45.1200","11.2520","225.2091","11.2520","7.5013","53.9811"
"45.2000","11.2712","225.4439","11.2712","7.5141","54.0374"
"45.2800","11.2922","225.7110","11.2922","7.5281","54.1014"
"45.3600","11.3118","225.9565","11.3118","7.5412","54.1602"
"45.4400","11.3317","226.2066","11.3317","7.5545","54.2202"
"45.5200","11.3525","226.4689","11.3525","7.5683","54.2830"
"45.6000","11.3721","226.7064","11.3721","7.5814","54.3400"
"45.6800","11.3923","226.9424","11.3923","7.5949","54.3966"
"45.7600","11.4124","227.1877","11.4124","7.6083","54.4553"
"45.8400","11.4312","227.3989","11.4312","7.6208","54.5060"
"45.9200","11.4518","227.6499","11.4518","7.6345","54.5661"
"46.0000","11.4708","227.8607","11.4708","7.6472","54.6167"
"46.0800","11.4921","228.1410","11.4921","7.6614","54.6838"
"46.1600","11.5126","228.3884","11.5126","7.6750","54.7432"
"46.2400","11.5320","228.5995","11.5320","7.6880","54.7937"
"46.3200","11.5519","228.8217","11.5519","7.7013","54.8470"
"46.4000","11.5721","229.0520","11.5721","7.7147","54.9022"
"46.4800","11.5914","229.2734","11.5914","7.7276","54.9553"
"46.5600","11.6126","229.5353","11.6126","7.7417","55.0180"
"46.6400","11.6311","229.7205","11.6311","7.7541","55.0624"
"46.7200","11.6527","230.0027","11.6527","7.7685","55.1301"
"46.8000","11.6731","230.2184","11.6731","7.7821","55.1818"
"46.8800","11.6922","230.4297","11.6922","7.7948","55.2324"
"46.9600","11.7118","230.6428","11.7118","7.8079","55.2835"
"47.0400","11.7318","230.8563","11.7318","7.8212","55.3347"
"47.1200","11.7516","231.0651","11.7516","7.8344","55.3847"
"47.2000","11.7718","231.2936","11.7718","7.8479","55.4395"
"47.2800","11.7910","231.4900","11.7910","7.8607","55.4866"
"47.3600","11.8120","231.7396","11.8120","7.8747","55.5464"
"47.4400","11.8325","231.9644","11.8325","7.8884","55.6003"
"47.5200","11.8519","232.1706","11.8519","7.9013","55.6497"
"47.6000","11.8722","232.3891","11.8722","7.9148","55.7021"
"47.6800","11.8913","232.5767","11.8913","7.9275","55.7471"
"47.7600","11.9124","232.8091","11.9124","7.9416","55.8028"
"47.8400","11.9320","233.0138","11.9320","7.9547","55.8518"
"47.9200","11.9513","233.1956","11.9513","7.9675","55.8954"
"48.0000","11.9721","233.4396","11.9721","7.9814","55.9539"
"48.0800","11.9931","233.6530","11.9931","7.9954","56.0050"
"48.1600","12.0125","233.8406","12.0125","8.0084","56.0500"
"48.2400","12.0320","234.0220","12.0320","8.0213","56.0935"
"48.3200","12.0511","234.2001","12.0511","8.0340","56.1362"
"48.4000","12.0722","234.4318","12.0722","8.0481","56.1917"
"48.4800","12.0917","234.6073","12.0917","8.0611","56.2338"
"48.5600","12.1117","234.8119","12.1117","8.0744","56.2828"
"48.6400","12.1320","235.0126","12.1320","8.0880","56.3309"
"48.7200","12.1522","235.1997","12.1522","8.1014","56.3758"
"48.8000","12.1724","235.3955","12.1724","8.1149","56.4227"
"48.8800","12.1927","235.5871","12.1927","8.1285","56.4686"
"48.9600","12.2112","235.7467","12.2112","8.1408","56.5069"
"49.0400","12.2317","235.9466","12.2317","8.1545","56.5548"
"49.1200","12.2514","236.1272","12.2514","8.1676","56.5981"
"49.2000","12.2724","236.3382","12.2724","8.1816","56.6486"
"49.2800","12.2932","236.5341","12.2932","8.1954","56.6956"
"49.3600","12.3126","236.7011","12.3126","8.2084","56.7356"
"49.4400","12.3325","236.8649","12.3325","8.2216","56.7749"
"49.5200","12.3519","237.0306","12.3519","8.2346","56.8146"
"49.6000","12.3714","237.2007","12.3714","8.2476","56.8554"
"49.6800","12.3917","237.4028","12.3917","8.2611","56.9038"
"49.7600","12.4111","237.5498","12.4111","8.2741","56.9391"
"49.8400","12.4316","237.7363","12.4316","8.2877","56.9838"
"49.9200","12.4528","237.9388","12.4528","8.3018","57.0323"
"50.0000","12.4721","238.0944","12.4721","8.3147","57.0696"
"50.0800","12.4925","238.2574","12.4925","8.3284","57.1087"
"50.1600","12.5115","238.3977","12.5115","8.3410","57.1423"
"50.2400","12.5316","238.5625","12.5316","8.3544","57.1818"
"50.3200","12.5511","238.7293","12.5511","8.3674","57.2218"
"50.4000","12.5713","238.8964","12.5713","8.3809","57.2619"
"50.4800","12.5929","239.0923","12.5929","8.3953","57.3088"
"50.5600","12.6137","239.2690","12.6137","8.4091","57.3511"
"50.6400","12.6322","239.3910","12.6322","8.4215","57.3804"
"50.7200","12.6521","239.5466","12.6521","8.4347","57.4177"
"50.8000","12.6711","239.6693","12.6711","8.4474","57.4471"
"50.8800","12.6922","239.8553","12.6922","8.4615","57.4917"
"50.9600","12.7121","240.0026","12.7121","8.4747","57.5270"
"51.0400","12.7309","240.1273","12.7309","8.4873","57.5569"
"51.1200","12.7517","240.3089","12.7517","8.5011","57.6004"
"51.2000","12.7724","240.4666","12.7724","8.5149","57.6382"
"51.2800","12.7922","240.6013","12.7922","8.5281","57.6705"
"51.3600","12.8125","240.7569","12.8125","8.5417","57.7078"
"51.4400","12.8313","240.8630","12.8313","8.5542","57.7332"
"51.5200","12.8514","241.0209","12.8514","8.5676","57.7711"
"51.6000","12.8719","241.1702","12.8719","8.5813","57.8069"
"51.6800","12.8917","241.3319","12.8917","8.5945","57.8456"
"51.7600","12.9132","241.4996","12.9132","8.6088","57.8858"
"51.8400","12.9327","241.6203","12.9327","8.6218","57.9147"
"51.9200","12.9529","241.7626","12.9529","8.6352","57.9489"
"52.0000","12.9721","241.8781","12.9721","8.6481","57.9765"
"52.0800","12.9915","242.0079","12.9915","8.6610","58.0076"
"52.1600","13.0118","242.1546","13.0118","8.6745","58.0428"
"52.2400","13.0319","242.2985","13.0319","8.6879","58.0773"
"52.3200","13.0510","242.4087","13.0510","8.7006","58.1037"
"52.4000","13.0724","242.5729","13.0724","8.7149","58.1431"
"52.4800","13.0923","242.6916","13.0923","8.7282","58.1715"
"52.5600","13.1130","242.8159","13.1130","8.7420","58.2013"
"52.6400","13.1318","242.9113","13.1318","8.7545","58.2242"
"52.7200","13.1509","243.0311","13.1509","8.7673","58.2529"
"52.8000","13.1715","243.1725","13.1715","8.7810","58.2868"
"52.8800","13.1917","243.2888","13.1917","8.7945","58.3147"
"52.9600","13.2121","243.4178","13.2121","8.8081","58.3456"
"53.0400","13.2330","243.5527","13.2330","8.8220","58.3779"
"53.1200","13.2522","243.6583","13.2522","8.8348","58.4032"
"53.2000","13.2724","243.7768","13.2724","8.8483","58.4316"
"53.2800","13.2922","243.8849","13.2922","8.8614","58.4576"
"53.3600","13.3119","244.0144","13.3119","8.8746","58.4886"
"53.4400","13.3318","244.1217","13.3318","8.8879","58.5143"
"53.5200","13.3505","244.2046","13.3505","8.9003","58.5342"
"53.6000","13.3717","244.3397","13.3717","8.9145","58.5666"
"53.6800","13.3924","244.4679","13.3924","8.9283","58.5973"
"53.7600","13.4123","244.5743","13.4123","8.9415","58.6228"
"53.8400","13.4320","244.6796","13.4320","8.9546","58.6480"
"53.9200","13.4514","244.7605","13.4514","8.9676","58.6674"
"54.0000","13.4716","244.8608","13.4716","8.9811","58.6915"
"54.0800","13.4923","244.9841","13.4923","8.9949","58.7210"
"54.1600","13.5115","245.0837","13.5115","9.0077","58.7449"
"54.2400","13.5327","245.2003","13.5327","9.0218","58.7729"
"54.3200","13.5524","245.2957","13.5524","9.0349","58.7957"
"54.4000","13.5728","245.4005","13.5728","9.0485","58.8208"
"54.4800","13.5923","245.4889","13.5923","9.0616","58.8420"
"54.5600","13.6117","245.5701","13.6117","9.0745","58.8615"
"54.6400","13.6319","245.6624","13.6319","9.0879","58.8836"
"54.7200","13.6519","245.7456","13.6519","9.1013","58.9035"
"54.8000","13.6705","245.8180","13.6705","9.1137","58.9209"
"54.8800","13.6922","245.9563","13.6922","9.1281","58.9541"
"54.9600","13.7123","246.0400","13.7123","9.1415","58.9741"
"55.0400","13.7326","246.1309","13.7326","9.1551","58.9959"
"55.1200","13.7520","246.2014","13.7520","9.1680","59.0128"
"55.2000","13.7710","246.2679","13.7710","9.1807","59.0287"
"55.2800","13.7920","246.3758","13.7920","9.1946","59.0546"
"55.3600","13.8120","246.4697","13.8120","9.2080","59.0771"
"55.4400","13.8318","246.5377","13.8318","9.2212","59.0934"
"55.5200","13.8525","246.6440","13.8525","9.2350","59.1189"
"55.6000","13.8723","246.7078","13.8723","9.2482","59.1342"
"55.6800","13.8926","246.8011","13.8926","9.2618","59.1566"
"55.7600","13.9127","246.8726","13.9127","9.2751","59.1737"
"55.8400","13.9312","246.9243","13.9312","9.2875","59.1861"
"55.9200","13.9513","247.0040","13.9513","9.3009","59.2052"
"56.0000","13.9704","247.0604","13.9704","9.3136","59.2187"
"56.0800","13.9920","247.1789","13.9920","9.3280","59.2471"
"56.1600","14.0128","247.2790","14.0128","9.3419","59.2711"
"56.2400","14.0322","247.3214","14.0322","9.3548","59.2813"
"56.3200","14.0520","247.3885","14.0520","9.3680","59.2973"
"56.4000","14.0720","247.4653","14.0720","9.3813","59.3157"
"56.4800","14.0916","247.5433","14.0916","9.3944","59.3344"
"56.5600","14.1124","247.6429","14.1124","9.4083","59.3583"
"56.6400","14.1310","247.6737","14.1310","9.4207","59.3657"
"56.7200","14.1523","247.7716","14.1523","9.4349","59.3892"
"56.8000","14.1730","247.8484","14.1730","9.4487","59.4076"
"56.8800","14.1927","247.9132","14.1927","9.4618","59.4231"
"56.9600","14.2120","247.9694","14.2120","9.4747","59.4366"
"57.0400","14.2318","248.0301","14.2318","9.4879","59.4511"
"57.1200","14.2515","248.0958","14.2515","9.5010","59.4669"
"57.2000","14.2719","248.1690","14.2719","9.5146","59.4844"
"57.2800","14.2908","248.2099","14.2908","9.5272","59.4942"
"57.3600","14.3119","248.3031","14.3119","9.5412","59.5166"
"57.4400","14.3324","248.3695","14.3324","9.5549","59.5325"
"57.5200","14.3521","248.4293","14.3521","9.5680","59.5468"
"57.6000","14.3723","248.4990","14.3723","9.5815","59.5635"
"57.6800","14.3916","248.5172","14.3916","9.5944","59.5679"
"57.7600","14.4121","248.5959","14.4121","9.6081","59.5868"
"57.8400","14.4321","248.6512","14.4321","9.6214","59.6000"
"57.9200","14.4516","248.7071","14.4516","9.6344","59.6134"
"58.0000","14.4720","248.7745","14.4720","9.6480","59.6295"
"58.0800","14.4929","248.8422","14.4929","9.6619","59.6458"
"58.1600","14.5121","248.8752","14.5121","9.6747","59.6537"
"58.2400","14.5316","248.9247","14.5316","9.6877","59.6656"
"58.3200","14.5514","248.9655","14.5514","9.7009","59.6753"
"58.4000","14.5720","249.0249","14.5720","9.7146","59.6896"
"58.4800","14.5917","249.0646","14.5917","9.7278","59.6991"
"58.5600","14.6113","249.1134","14.6113","9.7409","59.7108"
"58.6400","14.6318","249.1704","14.6318","9.7545","59.7245"
"58.7200","14.6523","249.2189","14.6523","9.7682","59.7361"
"58.8000","14.6722","249.2566","14.6722","9.7815","59.7451"
"58.8800","14.6928","249.3130","14.6928","9.7952","59.7586"
"58.9600","14.7114","249.3233","14.7114","9.8076","59.7611"
"59.0400","14.7316","249.3733","14.7316","9.8211","59.7731"
"59.1200","14.7514","249.4086","14.7514","9.8343","59.7815"
"59.2000","14.7718","249.4601","14.7718","9.8479","59.7939"
"59.2800","14.7931","249.5284","14.7931","9.8620","59.8103"
"59.3600","14.8128","249.5610","14.8128","9.8752","59.8181"
"59.4400","14.8324","249.5790","14.8324","9.8882","59.8224"
"59.5200","14.8520","249.6184","14.8520","9.9014","59.8318"
"59.6000","14.8711","249.6392","14.8711","9.9141","59.8368"
"59.6800","14.8917","249.6862","14.8917","9.9278","59.8481"
"59.7600","14.9111","249.6932","14.9111","9.9407","59.8498"
"59.8400","14.9317","249.7456","14.9317","9.9545","59.8623"
"59.9200","14.9530","249.7977","14.9530","9.9687","59.8748"
"60.0000","14.9716","249.8086","14.9716","9.9811","59.8774"
"60.0800","14.9925","249.8588","14.9925","9.9950","59.8894"
"60.1110","15.0002","249.8784","15.0002","10.0002","59.8942"