File: data/instron_tests/metamaterials/250327/250327_1467_BULK_m2_NoTransition.is_comp_Exports/250327_1467_BULK_m2_NoTransition_2_1.csv
Results Table 1
,Compression Axis,H*,V*,Height,Thickness,Width,Area,Fixture separation,Specimen label
,,,,(mm),(mm),(mm),(mm^2),(mm),
"2","Y","","","149.00","28.00","149.00","4172.00","150.00","1467_BULK_m2_NoTransition"

Results Table 2
,Modulus (Segment 0 % - 5 %),Compression Axis
,(kPa),
"2","787.28","Y"

Time,Displacement,Force,Compressive displacement,Compressive strain (Displacement),Compressive stress
(s),(mm),(N),(mm),(%),(kPa)
"0.0000","0.0000","-12.5656","0.0000","0.0000","-3.0119"
"0.0800","0.0012","-12.5300","0.0012","0.0008","-3.0034"
"0.1600","0.0176","-11.9991","0.0176","0.0118","-2.8761"
"0.2400","0.0383","-11.3835","0.0383","0.0255","-2.7286"
"0.3200","0.0576","-10.8499","0.0576","0.0384","-2.6007"
"0.4000","0.0771","-10.2882","0.0771","0.0514","-2.4660"
"0.4800","0.0985","-9.6676","0.0985","0.0657","-2.3172"
"0.5600","0.1183","-9.1252","0.1183","0.0788","-2.1873"
"0.6400","0.1377","-8.5954","0.1377","0.0918","-2.0603"
"0.7200","0.1573","-8.0482","0.1573","0.1048","-1.9291"
"0.8000","0.1766","-7.5260","0.1766","0.1177","-1.8039"
"0.8800","0.1975","-6.9614","0.1975","0.1316","-1.6686"
"0.9600","0.2171","-6.4479","0.2171","0.1447","-1.5455"
"1.0400","0.2365","-5.9260","0.2365","0.1577","-1.4204"
"1.1200","0.2573","-5.3732","0.2573","0.1715","-1.2879"
"1.2000","0.2775","-4.8569","0.2775","0.1850","-1.1642"
"1.2800","0.2980","-4.3231","0.2980","0.1987","-1.0362"
"1.3600","0.3180","-3.8150","0.3180","0.2120","-0.9144"
"1.4400","0.3364","-3.3380","0.3364","0.2243","-0.8001"
"1.5200","0.3568","-2.8075","0.3568","0.2379","-0.6729"
"1.6000","0.3768","-2.2898","0.3768","0.2512","-0.5489"
"1.6800","0.3976","-1.7540","0.3976","0.2650","-0.4204"
"1.7600","0.4190","-1.2220","0.4190","0.2793","-0.2929"
"1.8400","0.4374","-0.7553","0.4374","0.2916","-0.1810"
"1.9200","0.4577","-0.2495","0.4577","0.3051","-0.0598"
"2.0000","0.4776","0.2472","0.4776","0.3184","0.0592"
"2.0800","0.4968","0.7348","0.4968","0.3312","0.1761"
"2.1600","0.5172","1.2535","0.5172","0.3448","0.3005"
"2.2400","0.5361","1.7185","0.5361","0.3574","0.4119"
"2.3200","0.5571","2.2493","0.5571","0.3714","0.5392"
"2.4000","0.5787","2.7847","0.5787","0.3858","0.6675"
"2.4800","0.5975","3.2561","0.5975","0.3983","0.7805"
"2.5600","0.6175","3.7530","0.6175","0.4117","0.8996"
"2.6400","0.6367","4.2125","0.6367","0.4244","1.0097"
"2.7200","0.6569","4.7231","0.6569","0.4379","1.1321"
"2.8000","0.6771","5.2124","0.6771","0.4514","1.2494"
"2.8800","0.6965","5.6806","0.6965","0.4643","1.3616"
"2.9600","0.7178","6.2098","0.7178","0.4785","1.4884"
"3.0400","0.7384","6.7078","0.7384","0.4923","1.6078"
"3.1200","0.7573","7.1748","0.7573","0.5049","1.7197"
"3.2000","0.7774","7.6632","0.7774","0.5183","1.8368"
"3.2800","0.7971","8.1380","0.7971","0.5314","1.9506"
"3.3600","0.8182","8.6568","0.8182","0.5454","2.0750"
"3.4400","0.8368","9.0876","0.8368","0.5578","2.1782"
"3.5200","0.8553","9.5513","0.8553","0.5702","2.2894"
"3.6000","0.8772","10.0914","0.8772","0.5848","2.4188"
"3.6800","0.8985","10.6221","0.8985","0.5990","2.5460"
"3.7600","0.9178","11.0846","0.9178","0.6119","2.6569"
"3.8400","0.9376","11.5663","0.9376","0.6251","2.7724"
"3.9200","0.9564","12.0084","0.9564","0.6376","2.8783"
"4.0000","0.9772","12.5235","0.9772","0.6515","3.0018"
"4.0800","0.9973","13.0135","0.9973","0.6649","3.1192"
"4.1600","1.0173","13.5017","1.0173","0.6782","3.2363"
"4.2400","1.0383","14.0237","1.0383","0.6922","3.3614"
"4.3200","1.0576","14.4701","1.0576","0.7051","3.4684"
"4.4000","1.0781","14.9587","1.0781","0.7187","3.5855"
"4.4800","1.0979","15.4448","1.0979","0.7319","3.7020"
"4.5600","1.1167","15.8973","1.1167","0.7445","3.8105"
"4.6400","1.1368","16.3702","1.1368","0.7578","3.9238"
"4.7200","1.1567","16.8458","1.1567","0.7712","4.0378"
"4.8000","1.1765","17.3260","1.1765","0.7843","4.1529"
"4.8800","1.1978","17.8459","1.1978","0.7986","4.2775"
"4.9600","1.2173","18.2958","1.2173","0.8115","4.3854"
"5.0400","1.2378","18.7797","1.2378","0.8252","4.5014"
"5.1200","1.2573","19.2445","1.2573","0.8382","4.6128"
"5.2000","1.2764","19.7001","1.2764","0.8509","4.7220"
"5.2800","1.2970","20.2062","1.2970","0.8647","4.8433"
"5.3600","1.3173","20.6797","1.3173","0.8782","4.9568"
"5.4400","1.3376","21.1583","1.3376","0.8918","5.0715"
"5.5200","1.3584","21.6598","1.3584","0.9056","5.1917"
"5.6000","1.3775","22.1074","1.3775","0.9184","5.2990"
"5.6800","1.3980","22.5959","1.3980","0.9320","5.4161"
"5.7600","1.4175","23.0526","1.4175","0.9450","5.5255"
"5.8400","1.4371","23.5288","1.4371","0.9581","5.6397"
"5.9200","1.4570","23.9939","1.4570","0.9713","5.7512"
"6.0000","1.4760","24.4435","1.4760","0.9840","5.8590"
"6.0800","1.4975","24.9623","1.4975","0.9983","5.9833"
"6.1600","1.5180","25.4441","1.5180","1.0120","6.0988"
"6.2400","1.5376","25.9102","1.5376","1.0250","6.2105"
"6.3200","1.5573","26.3732","1.5573","1.0382","6.3215"
"6.4000","1.5768","26.8254","1.5768","1.0512","6.4299"
"6.4800","1.5971","27.3130","1.5971","1.0647","6.5467"
"6.5600","1.6180","27.8045","1.6180","1.0787","6.6645"
"6.6400","1.6362","28.2210","1.6362","1.0908","6.7644"
"6.7200","1.6580","28.7540","1.6580","1.1053","6.8921"
"6.8000","1.6782","29.2274","1.6782","1.1188","7.0056"
"6.8800","1.6979","29.6761","1.6979","1.1319","7.1132"
"6.9600","1.7173","30.1255","1.7173","1.1448","7.2209"
"7.0400","1.7369","30.5841","1.7369","1.1579","7.3308"
"7.1200","1.7570","31.0517","1.7570","1.1713","7.4429"
"7.2000","1.7775","31.5298","1.7775","1.1850","7.5575"
"7.2800","1.7964","31.9816","1.7964","1.1976","7.6658"
"7.3600","1.8176","32.4873","1.8176","1.2117","7.7870"
"7.4400","1.8373","32.9448","1.8373","1.2248","7.8966"
"7.5200","1.8578","33.4303","1.8578","1.2385","8.0130"
"7.6000","1.8772","33.8646","1.8772","1.2515","8.1171"
"7.6800","1.8966","34.3118","1.8966","1.2644","8.2243"
"7.7600","1.9177","34.8072","1.9177","1.2785","8.3430"
"7.8400","1.9374","35.2567","1.9374","1.2916","8.4508"
"7.9200","1.9567","35.6955","1.9567","1.3045","8.5560"
"8.0000","1.9780","36.2065","1.9780","1.3187","8.6784"
"8.0800","1.9980","36.6340","1.9980","1.3320","8.7809"
"8.1600","2.0181","37.0937","2.0181","1.3454","8.8911"
"8.2400","2.0377","37.5347","2.0377","1.3584","8.9968"
"8.3200","2.0562","37.9659","2.0562","1.3708","9.1002"
"8.4000","2.0772","38.4587","2.0772","1.3848","9.2183"
"8.4800","2.0968","38.8970","2.0968","1.3979","9.3233"
"8.5600","2.1174","39.3756","2.1174","1.4116","9.4381"
"8.6400","2.1378","39.8465","2.1378","1.4252","9.5509"
"8.7200","2.1574","40.3058","2.1574","1.4383","9.6610"
"8.8000","2.1776","40.7757","2.1776","1.4517","9.7737"
"8.8800","2.1976","41.2256","2.1976","1.4651","9.8815"
"8.9600","2.2165","41.6683","2.2165","1.4777","9.9876"
"9.0400","2.2373","42.1466","2.2373","1.4915","10.1023"
"9.1200","2.2565","42.5923","2.2565","1.5043","10.2091"
"9.2000","2.2779","43.0860","2.2779","1.5186","10.3274"
"9.2800","2.2987","43.5657","2.2987","1.5324","10.4424"
"9.3600","2.3178","44.0028","2.3178","1.5452","10.5472"
"9.4400","2.3374","44.4550","2.3374","1.5583","10.6556"
"9.5200","2.3569","44.8830","2.3569","1.5712","10.7582"
"9.6000","2.3767","45.3454","2.3767","1.5845","10.8690"
"9.6800","2.3975","45.8279","2.3975","1.5983","10.9846"
"9.7600","2.4163","46.2508","2.4163","1.6109","11.0860"
"9.8400","2.4370","46.7292","2.4370","1.6247","11.2007"
"9.9200","2.4572","47.1693","2.4572","1.6381","11.3062"
"10.0000","2.4775","47.6332","2.4775","1.6516","11.4174"
"10.0800","2.4983","48.0963","2.4983","1.6656","11.5284"
"10.1600","2.5173","48.5391","2.5173","1.6782","11.6345"
"10.2400","2.5372","48.9809","2.5372","1.6915","11.7404"
"10.3200","2.5572","49.4345","2.5572","1.7048","11.8491"
"10.4000","2.5767","49.8746","2.5767","1.7178","11.9546"
"10.4800","2.5981","50.3864","2.5981","1.7321","12.0773"
"10.5600","2.6183","50.8242","2.6183","1.7456","12.1822"
"10.6400","2.6378","51.2534","2.6378","1.7586","12.2851"
"10.7200","2.6574","51.6862","2.6574","1.7716","12.3888"
"10.8000","2.6764","52.1201","2.6764","1.7843","12.4928"
"10.8800","2.6976","52.5986","2.6976","1.7984","12.6075"
"10.9600","2.7173","53.0370","2.7173","1.8115","12.7126"
"11.0400","2.7364","53.4615","2.7364","1.8243","12.8144"
"11.1200","2.7569","53.9390","2.7569","1.8380","12.9288"
"11.2000","2.7776","54.4125","2.7776","1.8517","13.0423"
"11.2800","2.7981","54.8721","2.7981","1.8654","13.1525"
"11.3600","2.8182","55.3162","2.8182","1.8788","13.2589"
"11.4400","2.8363","55.7188","2.8363","1.8909","13.3554"
"11.5200","2.8567","56.1895","2.8567","1.9044","13.4682"
"11.6000","2.8770","56.6397","2.8770","1.9180","13.5761"
"11.6800","2.8980","57.1203","2.8980","1.9320","13.6914"
"11.7600","2.9186","57.5850","2.9186","1.9457","13.8027"
"11.8400","2.9375","58.0020","2.9375","1.9583","13.9027"
"11.9200","2.9576","58.4499","2.9576","1.9718","14.0100"
"12.0000","2.9774","58.8986","2.9774","1.9850","14.1176"
"12.0800","2.9972","59.3529","2.9972","1.9982","14.2265"
"12.1600","3.0171","59.7988","3.0171","2.0114","14.3334"
"12.2400","3.0361","60.1979","3.0361","2.0240","14.4290"
"12.3200","3.0567","60.6644","3.0567","2.0378","14.5408"
"12.4000","3.0783","61.1610","3.0783","2.0522","14.6599"
"12.4800","3.0971","61.5685","3.0971","2.0647","14.7575"
"12.5600","3.1178","62.0367","3.1178","2.0786","14.8698"
"12.6400","3.1364","62.4310","3.1364","2.0910","14.9643"
"12.7200","3.1568","62.8816","3.1568","2.1046","15.0723"
"12.8000","3.1774","63.3465","3.1774","2.1183","15.1837"
"12.8800","3.1970","63.7672","3.1970","2.1313","15.2846"
"12.9600","3.2175","64.2232","3.2175","2.1450","15.3939"
"13.0400","3.2386","64.6738","3.2386","2.1591","15.5019"
"13.1200","3.2577","65.0927","3.2577","2.1718","15.6023"
"13.2000","3.2777","65.5393","3.2777","2.1851","15.7093"
"13.2800","3.2970","65.9646","3.2970","2.1980","15.8113"
"13.3600","3.3177","66.4318","3.3177","2.2118","15.9233"
"13.4400","3.3372","66.8532","3.3372","2.2248","16.0243"
"13.5200","3.3561","67.2728","3.3561","2.2374","16.1248"
"13.6000","3.3771","67.7469","3.3771","2.2514","16.2385"
"13.6800","3.3980","68.2133","3.3980","2.2653","16.3503"
"13.7600","3.4179","68.6135","3.4179","2.2786","16.4462"
"13.8400","3.4377","69.0511","3.4377","2.2918","16.5511"
"13.9200","3.4565","69.4480","3.4565","2.3044","16.6462"
"14.0000","3.4772","69.9252","3.4772","2.3181","16.7606"
"14.0800","3.4974","70.3599","3.4974","2.3316","16.8648"
"14.1600","3.5169","70.8001","3.5169","2.3446","16.9703"
"14.2400","3.5379","71.2662","3.5379","2.3586","17.0820"
"14.3200","3.5576","71.6987","3.5576","2.3717","17.1857"
"14.4000","3.5782","72.1386","3.5782","2.3855","17.2911"
"14.4800","3.5978","72.5689","3.5978","2.3985","17.3943"
"14.5600","3.6168","72.9601","3.6168","2.4112","17.4880"
"14.6400","3.6366","73.3827","3.6366","2.4244","17.5893"
"14.7200","3.6563","73.8172","3.6563","2.4376","17.6935"
"14.8000","3.6762","74.2690","3.6762","2.4508","17.8018"
"14.8800","3.6981","74.7582","3.6981","2.4654","17.9190"
"14.9600","3.7175","75.1599","3.7175","2.4783","18.0153"
"15.0400","3.7378","75.6095","3.7378","2.4918","18.1231"
"15.1200","3.7568","76.0137","3.7568","2.5045","18.2200"
"15.2000","3.7767","76.4589","3.7767","2.5178","18.3267"
"15.2800","3.7974","76.9134","3.7974","2.5316","18.4356"
"15.3600","3.8168","77.3145","3.8168","2.5445","18.5318"
"15.4400","3.8374","77.7635","3.8374","2.5583","18.6394"
"15.5200","3.8585","78.2262","3.8585","2.5723","18.7503"
"15.6000","3.8774","78.6421","3.8774","2.5850","18.8500"
"15.6800","3.8978","79.0867","3.8978","2.5985","18.9565"
"15.7600","3.9177","79.5158","3.9177","2.6118","19.0594"
"15.8400","3.9371","79.9288","3.9371","2.6248","19.1584"
"15.9200","3.9572","80.3715","3.9572","2.6381","19.2645"
"16.0000","3.9762","80.7714","3.9762","2.6508","19.3604"
"16.0800","3.9975","81.2472","3.9975","2.6650","19.4744"
"16.1600","4.0183","81.7058","4.0183","2.6789","19.5843"
"16.2400","4.0376","82.1168","4.0376","2.6917","19.6828"
"16.3200","4.0574","82.5476","4.0574","2.7049","19.7861"
"16.4000","4.0770","82.9569","4.0770","2.7180","19.8842"
"16.4800","4.0970","83.3973","4.0970","2.7314","19.9898"
"16.5600","4.1177","83.8489","4.1177","2.7452","20.0980"
"16.6400","4.1366","84.2443","4.1366","2.7577","20.1928"
"16.7200","4.1577","84.7076","4.1577","2.7718","20.3038"
"16.8000","4.1778","85.1515","4.1778","2.7852","20.4102"
"16.8800","4.1981","85.5859","4.1981","2.7987","20.5144"
"16.9600","4.2172","85.9927","4.2172","2.8115","20.6119"
"17.0400","4.2369","86.4103","4.2369","2.8246","20.7120"
"17.1200","4.2569","86.8282","4.2569","2.8379","20.8121"
"17.2000","4.2772","87.2781","4.2772","2.8515","20.9200"
"17.2800","4.2962","87.6849","4.2962","2.8641","21.0175"
"17.3600","4.3175","88.1565","4.3175","2.8784","21.1305"
"17.4400","4.3373","88.5784","4.3373","2.8915","21.2316"
"17.5200","4.3578","89.0228","4.3578","2.9052","21.3382"
"17.6000","4.3774","89.4344","4.3774","2.9183","21.4368"
"17.6800","4.3963","89.8332","4.3963","2.9309","21.5324"
"17.7600","4.4172","90.2899","4.4172","2.9448","21.6419"
"17.8400","4.4374","90.7260","4.4374","2.9582","21.7464"
"17.9200","4.4571","91.1512","4.4571","2.9714","21.8483"
"18.0000","4.4777","91.5835","4.4777","2.9851","21.9519"
"18.0800","4.4978","92.0181","4.4978","2.9985","22.0561"
"18.1600","4.5182","92.4555","4.5182","3.0122","22.1609"
"18.2400","4.5376","92.8546","4.5376","3.0251","22.2566"
"18.3200","4.5563","93.2502","4.5563","3.0376","22.3514"
"18.4000","4.5773","93.7112","4.5773","3.0516","22.4619"
"18.4800","4.5965","94.1281","4.5965","3.0643","22.5619"
"18.5600","4.6175","94.5848","4.6175","3.0783","22.6713"
"18.6400","4.6378","95.0154","4.6378","3.0918","22.7746"
"18.7200","4.6575","95.4342","4.6575","3.1050","22.8749"
"18.8000","4.6776","95.8552","4.6776","3.1184","22.9758"
"18.8800","4.6978","96.2839","4.6978","3.1319","23.0786"
"18.9600","4.7166","96.6749","4.7166","3.1444","23.1723"
"19.0400","4.7372","97.0505","4.7372","3.1581","23.2623"
"19.1200","4.7562","97.4679","4.7562","3.1708","23.3624"
"19.2000","4.7778","97.9378","4.7778","3.1852","23.4750"
"19.2800","4.7988","98.3861","4.7988","3.1992","23.5825"
"19.3600","4.8180","98.8019","4.8180","3.2120","23.6821"
"19.4400","4.8371","99.1964","4.8371","3.2247","23.7767"
"19.5200","4.8568","99.6207","4.8568","3.2379","23.8784"
"19.6000","4.8770","100.0489","4.8770","3.2513","23.9810"
"19.6800","4.8976","100.4987","4.8976","3.2650","24.0889"
"19.7600","4.9162","100.8741","4.9162","3.2775","24.1788"
"19.8400","4.9372","101.3278","4.9372","3.2915","24.2876"
"19.9200","4.9578","101.7726","4.9578","3.3052","24.3942"
"20.0000","4.9780","102.1970","4.9780","3.3186","24.4959"
"20.0800","4.9977","102.6088","4.9977","3.3318","24.5946"
"20.1600","5.0167","102.9992","5.0167","3.3445","24.6882"
"20.2400","5.0374","103.4339","5.0374","3.3583","24.7924"
"20.3200","5.0574","103.8436","5.0574","3.3716","24.8906"
"20.4000","5.0766","104.2156","5.0766","3.3844","24.9798"
"20.4800","5.0979","104.6526","5.0979","3.3986","25.0845"
"20.5600","5.1183","105.0765","5.1183","3.4122","25.1861"
"20.6400","5.1380","105.4990","5.1380","3.4253","25.2874"
"20.7200","5.1575","105.9067","5.1575","3.4383","25.3851"
"20.8000","5.1763","106.2970","5.1763","3.4509","25.4787"
"20.8800","5.1973","106.7417","5.1973","3.4649","25.5853"
"20.9600","5.2167","107.1316","5.2167","3.4778","25.6787"
"21.0400","5.2366","107.5596","5.2366","3.4911","25.7813"
"21.1200","5.2567","107.9827","5.2567","3.5045","25.8827"
"21.2000","5.2776","108.4249","5.2776","3.5184","25.9887"
"21.2800","5.2980","108.8438","5.2980","3.5320","26.0891"
"21.3600","5.3180","109.2529","5.3180","3.5453","26.1872"
"21.4400","5.3361","109.6244","5.3361","3.5574","26.2762"
"21.5200","5.3568","110.0736","5.3568","3.5712","26.3839"
"21.6000","5.3769","110.5059","5.3769","3.5846","26.4875"
"21.6800","5.3979","110.9531","5.3979","3.5986","26.5947"
"21.7600","5.4186","111.3792","5.4186","3.6124","26.6968"
"21.8400","5.4378","111.7350","5.4378","3.6252","26.7821"
"21.9200","5.4575","112.1274","5.4575","3.6383","26.8762"
"22.0000","5.4773","112.5499","5.4773","3.6516","26.9775"
"22.0800","5.4972","112.9703","5.4972","3.6648","27.0782"
"22.1600","5.5174","113.3947","5.5174","3.6783","27.1799"
"22.2400","5.5359","113.7645","5.5359","3.6906","27.2686"
"22.3200","5.5566","114.2061","5.5566","3.7044","27.3744"
"22.4000","5.5782","114.6681","5.5782","3.7188","27.4852"
"22.4800","5.5978","115.0771","5.5978","3.7318","27.5832"
"22.5600","5.6177","115.4814","5.6177","3.7451","27.6801"
"22.6400","5.6365","115.8538","5.6365","3.7576","27.7694"
"22.7200","5.6571","116.2866","5.6571","3.7714","27.8731"
"22.8000","5.6772","116.7177","5.6772","3.7848","27.9764"
"22.8800","5.6972","117.1271","5.6972","3.7981","28.0746"
"22.9600","5.7173","117.5405","5.7173","3.8116","28.1737"
"23.0400","5.7384","117.9749","5.7384","3.8256","28.2778"
"23.1200","5.7573","118.3639","5.7573","3.8382","28.3710"
"23.2000","5.7780","118.8006","5.7780","3.8520","28.4757"
"23.2800","5.7971","119.1369","5.7971","3.8648","28.5563"
"23.3600","5.8171","119.5392","5.8171","3.8781","28.6527"
"23.4400","5.8366","119.9287","5.8366","3.8910","28.7461"
"23.5200","5.8560","120.3385","5.8560","3.9040","28.8443"
"23.6000","5.8774","120.7974","5.8774","3.9183","28.9543"
"23.6800","5.8985","121.2503","5.8985","3.9323","29.0629"
"23.7600","5.9179","121.6391","5.9179","3.9453","29.1561"
"23.8400","5.9378","122.0464","5.9378","3.9585","29.2537"
"23.9200","5.9568","122.4256","5.9568","3.9712","29.3446"
"24.0000","5.9769","122.8408","5.9769","3.9846","29.4441"
"24.0800","5.9973","123.2593","5.9973","3.9982","29.5444"
"24.1600","6.0169","123.6614","6.0169","4.0113","29.6408"
"24.2400","6.0381","124.1070","6.0381","4.0254","29.7476"
"24.3200","6.0577","124.4961","6.0577","4.0385","29.8409"
"24.4000","6.0783","124.9143","6.0783","4.0522","29.9411"
"24.4800","6.0979","125.3249","6.0979","4.0653","30.0395"
"24.5600","6.1172","125.7133","6.1172","4.0781","30.1326"
"24.6400","6.1368","126.0799","6.1368","4.0912","30.2205"
"24.7200","6.1568","126.4707","6.1568","4.1045","30.3142"
"24.8000","6.1763","126.8815","6.1763","4.1175","30.4126"
"24.8800","6.1980","127.3422","6.1980","4.1320","30.5231"
"24.9600","6.2172","127.7206","6.2172","4.1448","30.6138"
"25.0400","6.2379","128.1432","6.2379","4.1586","30.7151"
"25.1200","6.2573","128.5258","6.2573","4.1715","30.8068"
"25.2000","6.2769","128.9473","6.2769","4.1846","30.9078"
"25.2800","6.2968","129.3497","6.2968","4.1978","31.0043"
"25.3600","6.3171","129.7540","6.3171","4.2114","31.1012"
"25.4400","6.3376","130.1679","6.3376","4.2251","31.2004"
"25.5200","6.3586","130.5907","6.3586","4.2391","31.3017"
"25.6000","6.3775","130.9676","6.3775","4.2516","31.3920"
"25.6800","6.3978","131.3860","6.3978","4.2652","31.4923"
"25.7600","6.4173","131.7577","6.4173","4.2782","31.5814"
"25.8400","6.4369","132.1494","6.4369","4.2913","31.6753"
"25.9200","6.4574","132.5634","6.4574","4.3050","31.7745"
"26.0000","6.4760","132.9163","6.4760","4.3173","31.8591"
"26.0800","6.4978","133.3607","6.4978","4.3319","31.9657"
"26.1600","6.5185","133.7725","6.5185","4.3457","32.0643"
"26.2400","6.5375","134.1450","6.5375","4.3583","32.1537"
"26.3200","6.5569","134.5282","6.5569","4.3713","32.2455"
"26.4000","6.5771","134.9291","6.5771","4.3847","32.3416"
"26.4800","6.5974","135.3509","6.5974","4.3983","32.4427"
"26.5600","6.6180","135.7565","6.6180","4.4120","32.5399"
"26.6400","6.6363","136.1103","6.6363","4.4242","32.6247"
"26.7200","6.6576","136.5515","6.6576","4.4384","32.7305"
"26.8000","6.6779","136.9626","6.6779","4.4519","32.8290"
"26.8800","6.6980","137.3492","6.6980","4.4653","32.9217"
"26.9600","6.7176","137.7410","6.7176","4.4784","33.0156"
"27.0400","6.7368","138.1015","6.7368","4.4912","33.1020"
"27.1200","6.7567","138.4979","6.7567","4.5045","33.1970"
"27.2000","6.7772","138.9115","6.7772","4.5181","33.2961"
"27.2800","6.7963","139.2879","6.7963","4.5309","33.3864"
"27.3600","6.8178","139.7405","6.8178","4.5452","33.4949"
"27.4400","6.8372","140.1139","6.8372","4.5581","33.5843"
"27.5200","6.8576","140.5257","6.8576","4.5718","33.6831"
"27.6000","6.8777","140.9235","6.8777","4.5852","33.7784"
"27.6800","6.8969","141.2897","6.8969","4.5980","33.8662"
"27.7600","6.9172","141.6915","6.9172","4.6115","33.9625"
"27.8400","6.9373","142.0862","6.9373","4.6248","34.0571"
"27.9200","6.9571","142.4810","6.9571","4.6381","34.1517"
"28.0000","6.9782","142.8988","6.9782","4.6521","34.2519"
"28.0800","6.9975","143.2699","6.9975","4.6650","34.3408"
"28.1600","7.0181","143.6822","7.0181","4.6787","34.4396"
"28.2400","7.0377","144.0508","7.0377","4.6918","34.5280"
"28.3200","7.0564","144.4180","7.0564","4.7042","34.6160"
"28.4000","7.0772","144.8445","7.0772","4.7182","34.7183"
"28.4800","7.0962","145.1858","7.0962","4.7308","34.8000"
"28.5600","7.1175","145.6119","7.1175","4.7450","34.9022"
"28.6400","7.1379","146.0164","7.1379","4.7586","34.9991"
"28.7200","7.1574","146.3842","7.1574","4.7716","35.0873"
"28.8000","7.1774","146.7679","7.1774","4.7849","35.1793"
"28.8800","7.1978","147.1638","7.1978","4.7985","35.2742"
"28.9600","7.2167","147.5262","7.2167","4.8111","35.3610"
"29.0400","7.2372","147.9349","7.2372","4.8248","35.4590"
"29.1200","7.2563","148.2848","7.2563","4.8375","35.5429"
"29.2000","7.2779","148.7211","7.2779","4.8519","35.6474"
"29.2800","7.2986","149.1219","7.2986","4.8657","35.7435"
"29.3600","7.3179","149.4932","7.3179","4.8786","35.8325"
"29.4400","7.3373","149.8669","7.3373","4.8915","35.9221"
"29.5200","7.3570","150.2366","7.3570","4.9046","36.0107"
"29.6000","7.3767","150.6163","7.3767","4.9178","36.1017"
"29.6800","7.3975","151.0129","7.3975","4.9316","36.1968"
"29.7600","7.4164","151.3803","7.4164","4.9443","36.2848"
"29.8400","7.4370","151.7793","7.4370","4.9580","36.3805"
"29.9200","7.4579","152.1910","7.4579","4.9719","36.4791"
"30.0000","7.4778","152.5689","7.4778","4.9852","36.5697"
"30.0800","7.4981","152.9657","7.4981","4.9987","36.6648"
"30.1600","7.5166","153.3035","7.5166","5.0111","36.7458"
"30.2400","7.5373","153.6954","7.5373","5.0248","36.8397"
"30.3200","7.5572","154.0849","7.5572","5.0382","36.9331"
"30.4000","7.5769","154.4602","7.5769","5.0513","37.0231"
"30.4800","7.5979","154.8923","7.5979","5.0653","37.1266"
"30.5600","7.6185","155.2634","7.6185","5.0790","37.2156"
"30.6400","7.6382","155.6418","7.6382","5.0921","37.3063"
"30.7200","7.6576","155.9927","7.6576","5.1050","37.3904"
"30.8000","7.6760","156.3205","7.6760","5.1174","37.4690"
"30.8800","7.6977","156.7505","7.6977","5.1318","37.5720"
"30.9600","7.7171","157.1121","7.7171","5.1448","37.6587"
"31.0400","7.7364","157.4703","7.7364","5.1576","37.7446"
"31.1200","7.7573","157.8858","7.7573","5.1715","37.8442"
"31.2000","7.7778","158.2664","7.7778","5.1852","37.9354"
"31.2800","7.7981","158.6486","7.7981","5.1987","38.0270"
"31.3600","7.8181","159.0283","7.8181","5.2121","38.1180"
"31.4400","7.8362","159.3481","7.8362","5.2241","38.1947"
"31.5200","7.8567","159.7433","7.8567","5.2378","38.2894"
"31.6000","7.8769","160.1273","7.8769","5.2512","38.3814"
"31.6800","7.8980","160.5356","7.8980","5.2653","38.4793"
"31.7600","7.9187","160.9280","7.9187","5.2791","38.5733"
"31.8400","7.9378","161.2772","7.9378","5.2919","38.6570"
"31.9200","7.9574","161.6411","7.9574","5.3050","38.7443"
"32.0000","7.9775","162.0170","7.9775","5.3184","38.8344"
"32.0800","7.9967","162.3722","7.9967","5.3311","38.9195"
"32.1600","8.0169","162.7501","8.0169","5.3446","39.0101"
"32.2400","8.0364","163.0952","8.0364","5.3576","39.0928"
"32.3200","8.0568","163.4856","8.0568","5.3712","39.1864"
"32.4000","8.0784","163.9052","8.0784","5.3856","39.2870"
"32.4800","8.0977","164.2657","8.0977","5.3985","39.3734"
"32.5600","8.1178","164.6410","8.1178","5.4119","39.4633"
"32.6400","8.1365","164.9677","8.1365","5.4244","39.5416"
"32.7200","8.1569","165.3620","8.1569","5.4379","39.6362"
"32.8000","8.1770","165.7407","8.1770","5.4513","39.7269"
"32.8800","8.1969","166.0981","8.1969","5.4646","39.8126"
"32.9600","8.2175","166.4865","8.2175","5.4783","39.9057"
"33.0400","8.2383","166.8745","8.2383","5.4922","39.9987"
"33.1200","8.2576","167.2362","8.2576","5.5051","40.0854"
"33.2000","8.2777","167.6074","8.2777","5.5185","40.1743"
"33.2800","8.2968","167.9412","8.2968","5.5312","40.2544"
"33.3600","8.3177","168.3463","8.3177","5.5451","40.3515"
"33.4400","8.3374","168.6941","8.3374","5.5583","40.4348"
"33.5200","8.3561","169.0372","8.3561","5.5707","40.5171"
"33.6000","8.3765","169.4103","8.3765","5.5844","40.6065"
"33.6800","8.3983","169.8189","8.3983","5.5989","40.7044"
"33.7600","8.4179","170.1662","8.4179","5.6119","40.7877"
"33.8400","8.4376","170.5279","8.4376","5.6251","40.8744"
"33.9200","8.4560","170.8371","8.4560","5.6374","40.9485"
"34.0000","8.4769","171.2216","8.4769","5.6513","41.0406"
"34.0800","8.4974","171.6071","8.4974","5.6650","41.1330"
"34.1600","8.5172","171.9771","8.5172","5.6781","41.2217"
"34.2400","8.5379","172.3596","8.5379","5.6920","41.3134"
"34.3200","8.5576","172.7095","8.5576","5.7051","41.3973"
"34.4000","8.5782","173.0745","8.5782","5.7188","41.4848"
"34.4800","8.5979","173.4209","8.5979","5.7319","41.5678"
"34.5600","8.6167","173.7499","8.6167","5.7445","41.6467"
"34.6400","8.6370","174.1211","8.6370","5.7580","41.7356"
"34.7200","8.6567","174.4695","8.6567","5.7711","41.8192"
"34.8000","8.6763","174.8252","8.6763","5.7842","41.9044"
"34.8800","8.6981","175.2338","8.6981","5.7987","42.0023"
"34.9600","8.7175","175.5807","8.7175","5.8117","42.0855"
"35.0400","8.7380","175.9283","8.7380","5.8253","42.1688"
"35.1200","8.7573","176.2757","8.7573","5.8382","42.2521"
"35.2000","8.7769","176.6184","8.7769","5.8513","42.3342"
"35.2800","8.7970","176.9843","8.7970","5.8647","42.4219"
"35.3600","8.8168","177.3365","8.8168","5.8779","42.5063"
"35.4400","8.8374","177.7033","8.8374","5.8916","42.5943"
"35.5200","8.8585","178.0821","8.8585","5.9057","42.6851"
"35.6000","8.8771","178.4052","8.8771","5.9181","42.7625"
"35.6800","8.8981","178.7766","8.8981","5.9321","42.8515"
"35.7600","8.9175","179.1080","8.9175","5.9450","42.9310"
"35.8400","8.9366","179.4300","8.9366","5.9577","43.0082"
"35.9200","8.9565","179.7866","8.9565","5.9710","43.0936"
"36.0000","8.9762","180.1314","8.9762","5.9841","43.1763"
"36.0800","8.9978","180.5172","8.9978","5.9985","43.2687"
"36.1600","9.0182","180.8829","9.0182","6.0122","43.3564"
"36.2400","9.0374","181.2094","9.0374","6.0249","43.4346"
"36.3200","9.0572","181.5510","9.0572","6.0381","43.5165"
"36.4000","9.0768","181.8857","9.0768","6.0512","43.5968"
"36.4800","9.0972","182.2576","9.0972","6.0648","43.6859"
"36.5600","9.1179","182.6142","9.1179","6.0786","43.7714"
"36.6400","9.1366","182.9347","9.1366","6.0911","43.8482"
"36.7200","9.1581","183.3208","9.1581","6.1054","43.9408"
"36.8000","9.1779","183.6645","9.1779","6.1186","44.0231"
"36.8800","9.1981","184.0154","9.1981","6.1321","44.1072"
"36.9600","9.2175","184.3416","9.2175","6.1450","44.1854"
"37.0400","9.2369","184.6667","9.2369","6.1579","44.2634"
"37.1200","9.2569","185.0177","9.2569","6.1713","44.3475"
"37.2000","9.2774","185.3612","9.2774","6.1849","44.4298"
"37.2800","9.2964","185.6969","9.2964","6.1976","44.5103"
"37.3600","9.3175","186.0721","9.3175","6.2117","44.6002"
"37.4400","9.3373","186.3944","9.3373","6.2249","44.6775"
"37.5200","9.3580","186.7494","9.3580","6.2387","44.7626"
"37.6000","9.3775","187.0730","9.3775","6.2517","44.8401"
"37.6800","9.3968","187.4066","9.3968","6.2645","44.9201"
"37.7600","9.4172","187.7578","9.4172","6.2781","45.0043"
"37.8400","9.4369","188.0878","9.4369","6.2912","45.0834"
"37.9200","9.4568","188.4303","9.4568","6.3045","45.1655"
"38.0000","9.4781","188.8059","9.4781","6.3187","45.2555"
"38.0800","9.4979","189.1243","9.4979","6.3320","45.3318"
"38.1600","9.5180","189.4617","9.5180","6.3453","45.4127"
"38.2400","9.5374","189.7722","9.5374","6.3583","45.4871"
"38.3200","9.5560","190.0661","9.5560","6.3706","45.5576"
"38.4000","9.5772","190.4377","9.5772","6.3848","45.6466"
"38.4800","9.5964","190.7501","9.5964","6.3976","45.7215"
"38.5600","9.6176","191.1167","9.6176","6.4118","45.8094"
"38.6400","9.6375","191.4498","9.6375","6.4250","45.8892"
"38.7200","9.6575","191.7752","9.6575","6.4384","45.9672"
"38.8000","9.6774","192.1109","9.6774","6.4516","46.0477"
"38.8800","9.6978","192.4453","9.6978","6.4652","46.1278"
"38.9600","9.7170","192.7645","9.7170","6.4780","46.2043"
"39.0400","9.7376","193.1029","9.7376","6.4917","46.2854"
"39.1200","9.7562","193.3905","9.7562","6.5041","46.3544"
"39.2000","9.7781","193.7749","9.7781","6.5187","46.4465"
"39.2800","9.7985","194.1220","9.7985","6.5323","46.5297"
"39.3600","9.8182","194.4413","9.8182","6.5455","46.6062"
"39.4400","9.8375","194.7391","9.8375","6.5583","46.6776"
"39.5200","9.8570","195.0523","9.8570","6.5713","46.7527"
"39.6000","9.8767","195.3703","9.8767","6.5845","46.8289"
"39.6800","9.8975","195.7215","9.8975","6.5983","46.9131"
"39.7600","9.9164","196.0091","9.9164","6.6110","46.9821"
"39.8400","9.9371","196.3552","9.9371","6.6248","47.0650"
"39.9200","9.9576","196.6900","9.9576","6.6384","47.1453"
"40.0000","9.9779","197.0277","9.9779","6.6519","47.2262"
"40.0800","9.9976","197.3428","9.9976","6.6651","47.3017"
"40.1600","10.0166","197.6272","10.0166","6.6777","47.3699"
"40.2400","10.0374","197.9647","10.0374","6.6916","47.4508"
"40.3200","10.0570","198.2790","10.0570","6.7047","47.5261"
"40.4000","10.0768","198.5932","10.0768","6.7179","47.6014"
"40.4800","10.0980","198.9493","10.0980","6.7320","47.6868"
"40.5600","10.1185","199.2639","10.1185","6.7457","47.7622"
"40.6400","10.1377","199.5579","10.1377","6.7585","47.8327"
"40.7200","10.1575","199.8652","10.1575","6.7717","47.9063"
"40.8000","10.1761","200.1391","10.1761","6.7841","47.9720"
"40.8800","10.1972","200.4852","10.1972","6.7981","48.0549"
"40.9600","10.2166","200.7755","10.2166","6.8111","48.1245"
"41.0400","10.2369","201.0979","10.2369","6.8246","48.2018"
"41.1200","10.2569","201.4175","10.2569","6.8380","48.2784"
"41.2000","10.2776","201.7313","10.2776","6.8517","48.3536"
"41.2800","10.2980","202.0544","10.2980","6.8654","48.4311"
"41.3600","10.3181","202.3617","10.3181","6.8787","48.5047"
"41.4400","10.3363","202.6316","10.3363","6.8909","48.5694"
"41.5200","10.3570","202.9697","10.3570","6.9046","48.6504"
"41.6000","10.3768","203.2647","10.3768","6.9179","48.7212"
"41.6800","10.3979","203.5977","10.3979","6.9319","48.8010"
"41.7600","10.4188","203.9262","10.4188","6.9459","48.8797"
"41.8400","10.4377","204.1948","10.4377","6.9585","48.9441"
"41.9200","10.4577","204.5002","10.4577","6.9718","49.0173"
"42.0000","10.4774","204.7900","10.4774","6.9849","49.0868"
"42.0800","10.4972","205.0951","10.4972","6.9981","49.1599"
"42.1600","10.5170","205.3898","10.5170","7.0113","49.2305"
"42.2400","10.5361","205.6687","10.5361","7.0241","49.2974"
"42.3200","10.5567","205.9797","10.5567","7.0378","49.3719"
"42.4000","10.5786","206.3354","10.5786","7.0524","49.4572"
"42.4800","10.5979","206.6090","10.5979","7.0653","49.5228"
"42.5600","10.6177","206.9046","10.6177","7.0785","49.5936"
"42.6400","10.6365","207.1571","10.6365","7.0910","49.6541"
"42.7200","10.6569","207.4760","10.6569","7.1046","49.7306"
"42.8000","10.6774","207.7974","10.6774","7.1182","49.8076"
"42.8800","10.6971","208.0749","10.6971","7.1314","49.8741"
"42.9600","10.7175","208.3711","10.7175","7.1450","49.9451"
"43.0400","10.7384","208.6907","10.7384","7.1589","50.0217"
"43.1200","10.7575","208.9511","10.7575","7.1716","50.0841"
"43.2000","10.7777","209.2550","10.7777","7.1851","50.1570"
"43.2800","10.7970","209.5163","10.7970","7.1980","50.2196"
"43.3600","10.8179","209.8231","10.8179","7.2119","50.2932"
"43.4400","10.8365","210.0638","10.8365","7.2243","50.3509"
"43.5200","10.8556","210.3299","10.8556","7.2371","50.4147"
"43.6000","10.8770","210.6520","10.8770","7.2513","50.4919"
"43.6800","10.8982","210.9664","10.8982","7.2655","50.5672"
"43.7600","10.9182","211.2446","10.9182","7.2788","50.6339"
"43.8400","10.9379","211.5333","10.9379","7.2919","50.7031"
"43.9200","10.9566","211.7725","10.9566","7.3044","50.7604"
"44.0000","10.9771","212.0613","10.9771","7.3181","50.8296"
"44.0800","10.9975","212.3509","10.9975","7.3317","50.8991"
"44.1600","11.0172","212.6286","11.0172","7.3448","50.9656"
"44.2400","11.0379","212.9209","11.0379","7.3586","51.0357"
"44.3200","11.0574","213.1819","11.0574","7.3716","51.0983"
"44.4000","11.0781","213.4605","11.0781","7.3854","51.1650"
"44.4800","11.0977","213.7274","11.0977","7.3985","51.2290"
"44.5600","11.1167","213.9868","11.1167","7.4111","51.2912"
"44.6400","11.1369","214.2753","11.1369","7.4246","51.3603"
"44.7200","11.1571","214.5460","11.1571","7.4380","51.4252"
"44.8000","11.1762","214.7962","11.1762","7.4508","51.4852"
"44.8800","11.1979","215.1047","11.1979","7.4653","51.5591"
"44.9600","11.2174","215.3547","11.2174","7.4783","51.6191"
"45.0400","11.2382","215.6302","11.2382","7.4922","51.6851"
"45.1200","11.2571","215.8713","11.2571","7.5047","51.7429"
"45.2000","11.2772","216.1476","11.2772","7.5181","51.8091"
"45.2800","11.2970","216.4144","11.2970","7.5314","51.8731"
"45.3600","11.3168","216.6614","11.3168","7.5445","51.9323"
"45.4400","11.3373","216.9469","11.3373","7.5582","52.0007"
"45.5200","11.3583","217.2193","11.3583","7.5722","52.0660"
"45.6000","11.3774","217.4558","11.3774","7.5850","52.1227"
"45.6800","11.3975","217.6966","11.3975","7.5983","52.1804"
"45.7600","11.4172","217.9488","11.4172","7.6114","52.2408"
"45.8400","11.4371","218.2079","11.4371","7.6247","52.3029"
"45.9200","11.4572","218.4581","11.4572","7.6381","52.3629"
"46.0000","11.4761","218.6954","11.4761","7.6508","52.4198"
"46.0800","11.4978","218.9821","11.4978","7.6652","52.4885"
"46.1600","11.5180","219.2572","11.5180","7.6786","52.5545"
"46.2400","11.5376","219.4992","11.5376","7.6918","52.6125"
"46.3200","11.5571","219.7351","11.5571","7.7048","52.6690"
"46.4000","11.5767","219.9663","11.5767","7.7178","52.7244"
"46.4800","11.5975","220.2398","11.5975","7.7317","52.7900"
"46.5600","11.6180","220.4922","11.6180","7.7454","52.8505"
"46.6400","11.6363","220.7033","11.6363","7.7575","52.9011"
"46.7200","11.6583","221.0093","11.6583","7.7722","52.9744"
"46.8000","11.6780","221.2406","11.6780","7.7853","53.0299"
"46.8800","11.6980","221.4764","11.6980","7.7987","53.0864"
"46.9600","11.7174","221.7121","11.7174","7.8116","53.1429"
"47.0400","11.7370","221.9429","11.7370","7.8247","53.1982"
"47.1200","11.7569","222.1785","11.7569","7.8379","53.2547"
"47.2000","11.7774","222.4298","11.7774","7.8516","53.3149"
"47.2800","11.7964","222.6585","11.7964","7.8643","53.3697"
"47.3600","11.8176","222.9270","11.8176","7.8784","53.4341"
"47.4400","11.8374","223.1549","11.8374","7.8916","53.4887"
"47.5200","11.8577","223.4010","11.8577","7.9051","53.5477"
"47.6000","11.8776","223.6323","11.8776","7.9184","53.6031"
"47.6800","11.8967","223.8607","11.8967","7.9312","53.6579"
"47.7600","11.9173","224.1049","11.9173","7.9449","53.7164"
"47.8400","11.9370","224.3299","11.9370","7.9580","53.7704"
"47.9200","11.9570","224.5632","11.9570","7.9713","53.8263"
"48.0000","11.9780","224.8241","11.9780","7.9853","53.8888"
"48.0800","11.9981","225.0421","11.9981","7.9987","53.9411"
"48.1600","12.0177","225.2635","12.0177","8.0118","53.9941"
"48.2400","12.0376","225.4795","12.0376","8.0250","54.0459"
"48.3200","12.0562","225.6784","12.0562","8.0374","54.0936"
"48.4000","12.0773","225.9425","12.0773","8.0515","54.1569"
"48.4800","12.0967","226.1440","12.0967","8.0644","54.2052"
"48.5600","12.1177","226.3886","12.1177","8.0785","54.2638"
"48.6400","12.1380","226.6220","12.1380","8.0920","54.3198"
"48.7200","12.1575","226.8243","12.1575","8.1050","54.3682"
"48.8000","12.1774","227.0484","12.1774","8.1183","54.4220"
"48.8800","12.1977","227.2676","12.1977","8.1318","54.4745"
"48.9600","12.2167","227.4653","12.2167","8.1445","54.5219"
"49.0400","12.2372","227.7050","12.2372","8.1582","54.5793"
"49.1200","12.2564","227.8975","12.2564","8.1709","54.6255"
"49.2000","12.2783","228.1566","12.2783","8.1855","54.6876"
"49.2800","12.2986","228.3713","12.2986","8.1990","54.7391"
"49.3600","12.3181","228.5729","12.3181","8.2120","54.7874"
"49.4400","12.3373","228.7695","12.3373","8.2248","54.8345"
"49.5200","12.3568","228.9636","12.3568","8.2379","54.8810"
"49.6000","12.3771","229.1850","12.3771","8.2514","54.9341"
"49.6800","12.3976","229.4097","12.3976","8.2650","54.9880"
"49.7600","12.4161","229.5900","12.4161","8.2774","55.0312"
"49.8400","12.4371","229.8272","12.4371","8.2914","55.0880"
"49.9200","12.4578","230.0488","12.4578","8.3052","55.1411"
"50.0000","12.4778","230.2671","12.4778","8.3186","55.1935"
"50.0800","12.4978","230.4559","12.4978","8.3319","55.2387"
"50.1600","12.5165","230.6307","12.5165","8.3444","55.2806"
"50.2400","12.5371","230.8490","12.5371","8.3581","55.3329"
"50.3200","12.5570","231.0412","12.5570","8.3713","55.3790"
"50.4000","12.5771","231.2649","12.5771","8.3847","55.4326"
"50.4800","12.5981","231.5114","12.5981","8.3987","55.4917"
"50.5600","12.6186","231.6978","12.6186","8.4124","55.5364"
"50.6400","12.6378","231.8760","12.6378","8.4252","55.5791"
"50.7200","12.6576","232.0495","12.6576","8.4384","55.6207"
"50.8000","12.6764","232.2215","12.6764","8.4509","55.6619"
"50.8800","12.6976","232.4432","12.6976","8.4651","55.7151"
"50.9600","12.7169","232.6063","12.7169","8.4779","55.7541"
"51.0400","12.7369","232.8118","12.7369","8.4913","55.8034"
"51.1200","12.7570","233.0117","12.7570","8.5047","55.8513"
"51.2000","12.7775","233.2047","12.7775","8.5183","55.8976"
"51.2800","12.7979","233.4030","12.7979","8.5319","55.9451"
"51.3600","12.8182","233.5825","12.8182","8.5455","55.9881"
"51.4400","12.8362","233.7272","12.8362","8.5574","56.0228"
"51.5200","12.8569","233.9422","12.8569","8.5713","56.0743"
"51.6000","12.8767","234.1181","12.8767","8.5844","56.1165"
"51.6800","12.8979","234.3336","12.8979","8.5986","56.1682"
"51.7600","12.9184","234.5231","12.9184","8.6123","56.2136"
"51.8400","12.9379","234.6884","12.9379","8.6253","56.2532"
"51.9200","12.9577","234.8668","12.9577","8.6385","56.2960"
"52.0000","12.9773","235.0498","12.9773","8.6516","56.3398"
"52.0800","12.9971","235.2232","12.9971","8.6648","56.3814"
"52.1600","13.0174","235.4277","13.0174","8.6783","56.4304"
"52.2400","13.0364","235.5735","13.0364","8.6909","56.4654"
"52.3200","13.0568","235.7574","13.0568","8.7046","56.5094"
"52.4000","13.0783","235.9693","13.0783","8.7189","56.5602"
"52.4800","13.0979","236.1346","13.0979","8.7319","56.5999"
"52.5600","13.1181","236.3123","13.1181","8.7454","56.6425"
"52.6400","13.1367","236.4461","13.1367","8.7578","56.6745"
"52.7200","13.1567","236.6227","13.1567","8.7711","56.7168"
"52.8000","13.1772","236.8118","13.1772","8.7848","56.7622"
"52.8800","13.1969","236.9671","13.1969","8.7979","56.7994"
"52.9600","13.2176","237.1530","13.2176","8.8117","56.8440"
"53.0400","13.2382","237.3299","13.2382","8.8255","56.8864"
"53.1200","13.2578","237.4905","13.2578","8.8385","56.9249"
"53.2000","13.2777","237.6655","13.2777","8.8518","56.9668"
"53.2800","13.2970","237.8075","13.2970","8.8647","57.0008"
"53.3600","13.3176","237.9901","13.3176","8.8784","57.0446"
"53.4400","13.3372","238.1400","13.3372","8.8915","57.0805"
"53.5200","13.3558","238.2792","13.3558","8.9039","57.1139"
"53.6000","13.3769","238.4731","13.3769","8.9179","57.1604"
"53.6800","13.3981","238.6584","13.3981","8.9321","57.2048"
"53.7600","13.4178","238.8044","13.4178","8.9452","57.2398"
"53.8400","13.4377","238.9617","13.4377","8.9584","57.2775"
"53.9200","13.4563","239.0858","13.4563","8.9709","57.3072"
"54.0000","13.4771","239.2558","13.4771","8.9848","57.3480"
"54.0800","13.4976","239.4345","13.4976","8.9984","57.3908"
"54.1600","13.5170","239.5766","13.5170","9.0113","57.4249"
"54.2400","13.5380","239.7686","13.5380","9.0253","57.4709"
"54.3200","13.5576","239.8971","13.5576","9.0384","57.5017"
"54.4000","13.5783","240.0614","13.5783","9.0522","57.5411"
"54.4800","13.5979","240.2080","13.5979","9.0653","57.5762"
"54.5600","13.6170","240.3333","13.6170","9.0780","57.6062"
"54.6400","13.6371","240.4929","13.6371","9.0914","57.6445"
"54.7200","13.6567","240.6227","13.6567","9.1045","57.6756"
"54.8000","13.6764","240.7687","13.6764","9.1176","57.7106"
"54.8800","13.6980","240.9579","13.6980","9.1320","57.7560"
"54.9600","13.7173","241.0831","13.7173","9.1449","57.7860"
"55.0400","13.7379","241.2335","13.7379","9.1586","57.8220"
"55.1200","13.7572","241.3586","13.7572","9.1714","57.8520"
"55.2000","13.7768","241.4968","13.7768","9.1845","57.8851"
"55.2800","13.7971","241.6494","13.7971","9.1980","57.9217"
"55.3600","13.8169","241.7769","13.8169","9.2112","57.9523"
"55.4400","13.8375","241.9300","13.8375","9.2250","57.9890"
"55.5200","13.8584","242.0782","13.8584","9.2390","58.0245"
"55.6000","13.8773","242.1940","13.8773","9.2515","58.0522"
"55.6800","13.8978","242.3429","13.8978","9.2652","58.0879"
"55.7600","13.9173","242.4580","13.9173","9.2782","58.1155"
"55.8400","13.9368","242.5882","13.9368","9.2912","58.1467"
"55.9200","13.9570","242.7158","13.9570","9.3047","58.1773"
"56.0000","13.9761","242.8299","13.9761","9.3174","58.2047"
"56.0800","13.9975","242.9789","13.9975","9.3317","58.2404"
"56.1600","14.0179","243.1254","14.0179","9.3452","58.2755"
"56.2400","14.0377","243.2494","14.0377","9.3585","58.3052"
"56.3200","14.0570","243.3621","14.0570","9.3713","58.3322"
"56.4000","14.0765","243.4622","14.0765","9.3843","58.3562"
"56.4800","14.0974","243.6140","14.0974","9.3983","58.3926"
"56.5600","14.1181","243.7476","14.1181","9.4121","58.4246"
"56.6400","14.1367","243.8436","14.1367","9.4245","58.4477"
"56.7200","14.1579","243.9814","14.1579","9.4386","58.4807"
"56.8000","14.1781","244.1070","14.1781","9.4521","58.5108"
"56.8800","14.1985","244.2298","14.1985","9.4657","58.5402"
"56.9600","14.2174","244.3299","14.2174","9.4782","58.5642"
"57.0400","14.2367","244.4292","14.2367","9.4912","58.5880"
"57.1200","14.2568","244.5410","14.2568","9.5046","58.6148"
"57.2000","14.2773","244.6706","14.2773","9.5182","58.6459"
"57.2800","14.2962","244.7733","14.2962","9.5308","58.6705"
"57.3600","14.3175","244.9087","14.3175","9.5450","58.7029"
"57.4400","14.3374","245.0148","14.3374","9.5583","58.7284"
"57.5200","14.3580","245.1312","14.3580","9.5720","58.7563"
"57.6000","14.3775","245.2224","14.3775","9.5850","58.7781"
"57.6800","14.3967","245.3299","14.3967","9.5978","58.8039"
"57.7600","14.4172","245.4388","14.4172","9.6115","58.8300"
"57.8400","14.4372","245.5514","14.4372","9.6248","58.8570"
"57.9200","14.4569","245.6590","14.4569","9.6379","58.8828"
"58.0000","14.4780","245.7975","14.4780","9.6520","58.9160"
"58.0800","14.4978","245.8907","14.4978","9.6652","58.9383"
"58.1600","14.5178","245.9853","14.5178","9.6786","58.9610"
"58.2400","14.5374","246.0753","14.5374","9.6916","58.9826"
"58.3200","14.5564","246.1666","14.5564","9.7043","59.0045"
"58.4000","14.5772","246.2827","14.5772","9.7181","59.0323"
"58.4800","14.5965","246.3652","14.5965","9.7310","59.0521"
"58.5600","14.6172","246.4907","14.6172","9.7448","59.0821"
"58.6400","14.6379","246.6039","14.6379","9.7586","59.1093"
"58.7200","14.6573","246.6864","14.6573","9.7716","59.1290"
"58.8000","14.6775","246.7912","14.6775","9.7850","59.1542"
"58.8800","14.6978","246.8921","14.6978","9.7985","59.1784"
"58.9600","14.7166","246.9573","14.7166","9.8111","59.1940"
"59.0400","14.7369","247.0621","14.7369","9.8246","59.2191"
"59.1200","14.7565","247.1407","14.7565","9.8376","59.2379"
"59.2000","14.7779","247.2661","14.7779","9.8519","59.2680"
"59.2800","14.7988","247.3717","14.7988","9.8659","59.2933"
"59.3600","14.8182","247.4441","14.8182","9.8788","59.3107"
"59.4400","14.8373","247.5120","14.8373","9.8916","59.3269"
"59.5200","14.8567","247.5816","14.8567","9.9045","59.3436"
"59.6000","14.8768","247.6741","14.8768","9.9179","59.3658"
"59.6800","14.8976","247.7764","14.8976","9.9317","59.3903"
"59.7600","14.9164","247.8267","14.9164","9.9443","59.4024"
"59.8400","14.9373","247.9402","14.9373","9.9582","59.4296"
"59.9200","14.9578","248.0217","14.9578","9.9719","59.4491"
"60.0000","14.9774","248.0918","14.9774","9.9849","59.4659"
"60.0800","14.9975","248.1853","14.9975","9.9983","59.4883"
"60.0900","15.0001","248.1969","15.0001","10.0001","59.4911"