File: data/instron_tests/metamaterial_samples/553_VERT_m1.is_comp_Exports/553_VERT_m1_1_1.csv
Sample text inputs : Sample No.,Sample choice input : Leading Direction,Sample choice input : Mode,Specimen choice input : Direction,Specimen properties : Height,Specimen properties : Thickness,Specimen properties : Width,Test : Rate 1
,,,,(mm),(mm),(mm),(mm/min)
"553","Vertical","Unimode","1","147.00","25.00","150.00","15.00"

Time,Displacement,Compressive displacement,Compressive strain (Displacement),Compressive stress,Force
(s),(mm),(mm),(%),(kPa),(N)
"0.0000","0.0000","0.0000","0.0000","-0.4465","-1.6408"
"0.0800","0.0014","0.0014","0.0009","-0.4305","-1.5821"
"0.1600","0.0191","0.0191","0.0127","-0.3096","-1.1379"
"0.2400","0.0388","0.0388","0.0259","-0.1754","-0.6445"
"0.3200","0.0591","0.0591","0.0394","-0.0475","-0.1744"
"0.4000","0.0782","0.0782","0.0521","0.0641","0.2356"
"0.4800","0.0985","0.0985","0.0657","0.1786","0.6565"
"0.5600","0.1185","0.1185","0.0790","0.2896","1.0641"
"0.6400","0.1374","0.1374","0.0916","0.3882","1.4267"
"0.7200","0.1582","0.1582","0.1055","0.4875","1.7917"
"0.8000","0.1781","0.1781","0.1187","0.5874","2.1588"
"0.8800","0.1977","0.1977","0.1318","0.6795","2.4972"
"0.9600","0.2193","0.2193","0.1462","0.7753","2.8492"
"1.0400","0.2386","0.2386","0.1590","0.8541","3.1389"
"1.1200","0.2590","0.2590","0.1726","0.9419","3.4617"
"1.2000","0.2783","0.2783","0.1856","1.0251","3.7674"
"1.2800","0.2974","0.2974","0.1983","1.1135","4.0920"
"1.3600","0.3177","0.3177","0.2118","1.2046","4.4267"
"1.4400","0.3370","0.3370","0.2247","1.2847","4.7214"
"1.5200","0.3582","0.3582","0.2388","1.3855","5.0917"
"1.6000","0.3790","0.3790","0.2527","1.4758","5.4234"
"1.6800","0.3978","0.3978","0.2652","1.5651","5.7517"
"1.7600","0.4184","0.4184","0.2789","1.6612","6.1050"
"1.8400","0.4382","0.4382","0.2921","1.7545","6.4479"
"1.9200","0.4579","0.4579","0.3053","1.8530","6.8098"
"2.0000","0.4779","0.4779","0.3186","1.9421","7.1373"
"2.0800","0.4969","0.4969","0.3313","2.0303","7.4614"
"2.1600","0.5183","0.5183","0.3455","2.1318","7.8345"
"2.2400","0.5394","0.5394","0.3596","2.2322","8.2032"
"2.3200","0.5584","0.5584","0.3722","2.3215","8.5317"
"2.4000","0.5784","0.5784","0.3856","2.4170","8.8824"
"2.4800","0.5977","0.5977","0.3985","2.5065","9.2113"
"2.5600","0.6178","0.6178","0.4119","2.6074","9.5823"
"2.6400","0.6382","0.6382","0.4255","2.7085","9.9538"
"2.7200","0.6572","0.6572","0.4381","2.8076","10.3178"
"2.8000","0.6782","0.6782","0.4522","2.9172","10.7206"
"2.8800","0.6985","0.6985","0.4656","3.0238","11.1126"
"2.9600","0.7183","0.7183","0.4789","3.1316","11.5087"
"3.0400","0.7391","0.7391","0.4927","3.2434","11.9197"
"3.1200","0.7574","0.7574","0.5049","3.3374","12.2649"
"3.2000","0.7779","0.7779","0.5186","3.4561","12.7011"
"3.2800","0.7982","0.7982","0.5321","3.5618","13.0897"
"3.3600","0.8177","0.8177","0.5451","3.6792","13.5211"
"3.4400","0.8390","0.8390","0.5593","3.7992","13.9622"
"3.5200","0.8588","0.8588","0.5726","3.9087","14.3643"
"3.6000","0.8790","0.8790","0.5860","4.0237","14.7872"
"3.6800","0.8983","0.8983","0.5989","4.1373","15.2047"
"3.7600","0.9172","0.9172","0.6114","4.2468","15.6071"
"3.8400","0.9379","0.9379","0.6253","4.3730","16.0708"
"3.9200","0.9581","0.9581","0.6387","4.4962","16.5235"
"4.0000","0.9769","0.9769","0.6513","4.6077","16.9332"
"4.0800","0.9981","0.9981","0.6654","4.7419","17.4264"
"4.1600","1.0181","1.0181","0.6788","4.8624","17.8692"
"4.2400","1.0387","1.0387","0.6925","4.9926","18.3476"
"4.3200","1.0584","1.0584","0.7056","5.1159","18.8010"
"4.4000","1.0774","1.0774","0.7182","5.2320","19.2275"
"4.4800","1.0977","1.0977","0.7318","5.3624","19.7070"
"4.5600","1.1177","1.1177","0.7451","5.4900","20.1758"
"4.6400","1.1384","1.1384","0.7589","5.6274","20.6808"
"4.7200","1.1596","1.1596","0.7731","5.7638","21.1819"
"4.8000","1.1783","1.1783","0.7856","5.8830","21.6199"
"4.8800","1.1984","1.1984","0.7989","6.0179","22.1159"
"4.9600","1.2181","1.2181","0.8121","6.1484","22.5952"
"5.0400","1.2379","1.2379","0.8253","6.2825","23.0881"
"5.1200","1.2580","1.2580","0.8387","6.4179","23.5858"
"5.2000","1.2771","1.2771","0.8514","6.5459","24.0561"
"5.2800","1.2977","1.2977","0.8652","6.6878","24.5778"
"5.3600","1.3187","1.3187","0.8791","6.8337","25.1137"
"5.4400","1.3384","1.3384","0.8923","6.9702","25.6153"
"5.5200","1.3587","1.3587","0.9058","7.1134","26.1418"
"5.6000","1.3778","1.3778","0.9185","7.2433","26.6191"
"5.6800","1.3974","1.3974","0.9316","7.3817","27.1276"
"5.7600","1.4184","1.4184","0.9456","7.5333","27.6847"
"5.8400","1.4376","1.4376","0.9584","7.6676","28.1784"
"5.9200","1.4591","1.4591","0.9727","7.8216","28.7442"
"6.0000","1.4789","1.4789","0.9859","7.9612","29.2575"
"6.0800","1.4986","1.4986","0.9991","8.1002","29.7683"
"6.1600","1.5180","1.5180","1.0120","8.2366","30.2695"
"6.2400","1.5377","1.5377","1.0251","8.3764","30.7833"
"6.3200","1.5577","1.5577","1.0385","8.5232","31.3226"
"6.4000","1.5785","1.5785","1.0523","8.6702","31.8631"
"6.4800","1.5969","1.5969","1.0646","8.8031","32.3515"
"6.5600","1.6179","1.6179","1.0786","8.9585","32.9226"
"6.6400","1.6386","1.6386","1.0924","9.1099","33.4787"
"6.7200","1.6594","1.6594","1.1063","9.2652","34.0495"
"6.8000","1.6788","1.6788","1.1192","9.4051","34.5637"
"6.8800","1.6973","1.6973","1.1315","9.5400","35.0595"
"6.9600","1.7178","1.7178","1.1452","9.6938","35.6246"
"7.0400","1.7381","1.7381","1.1587","9.8513","36.2036"
"7.1200","1.7577","1.7577","1.1718","9.9989","36.7458"
"7.2000","1.7784","1.7784","1.1856","10.1613","37.3429"
"7.2800","1.7987","1.7987","1.1991","10.3124","37.8982"
"7.3600","1.8187","1.8187","1.2125","10.4660","38.4626"
"7.4400","1.8386","1.8386","1.2257","10.6174","39.0190"
"7.5200","1.8572","1.8572","1.2382","10.7610","39.5467"
"7.6000","1.8780","1.8780","1.2520","10.9244","40.1471"
"7.6800","1.8970","1.8970","1.2647","11.0674","40.6726"
"7.7600","1.9177","1.9177","1.2785","11.2335","41.2831"
"7.8400","1.9387","1.9387","1.2924","11.4015","41.9007"
"7.9200","1.9588","1.9588","1.3059","11.5571","42.4723"
"8.0000","1.9781","1.9781","1.3187","11.7063","43.0207"
"8.0800","1.9978","1.9978","1.3319","11.8615","43.5912"
"8.1600","2.0171","2.0171","1.3448","12.0127","44.1465"
"8.2400","2.0386","2.0386","1.3591","12.1896","44.7968"
"8.3200","2.0577","2.0577","1.3718","12.3346","45.3297"
"8.4000","2.0789","2.0789","1.3859","12.5072","45.9640"
"8.4800","2.0989","2.0989","1.3993","12.6643","46.5413"
"8.5600","2.1186","2.1186","1.4124","12.8226","47.1229"
"8.6400","2.1382","2.1382","1.4255","12.9766","47.6891"
"8.7200","2.1578","2.1578","1.4385","13.1298","48.2519"
"8.8000","2.1780","2.1780","1.4520","13.2930","48.8516"
"8.8800","2.1986","2.1986","1.4657","13.4565","49.4526"
"8.9600","2.2170","2.2170","1.4780","13.5955","49.9636"
"9.0400","2.2380","2.2380","1.4920","13.7684","50.5990"
"9.1200","2.2591","2.2591","1.5061","13.9394","51.2273"
"9.2000","2.2783","2.2783","1.5189","14.0905","51.7827"
"9.2800","2.2979","2.2979","1.5320","14.2471","52.3581"
"9.3600","2.3172","2.3172","1.5448","14.4000","52.9202"
"9.4400","2.3385","2.3385","1.5590","14.5740","53.5595"
"9.5200","2.3587","2.3587","1.5725","14.7385","54.1640"
"9.6000","2.3780","2.3780","1.5853","14.8916","54.7265"
"9.6800","2.3983","2.3983","1.5989","15.0573","55.3356"
"9.7600","2.4190","2.4190","1.6127","15.2234","55.9462"
"9.8400","2.4385","2.4385","1.6257","15.3802","56.5222"
"9.9200","2.4588","2.4588","1.6392","15.5459","57.1313"
"10.0000","2.4771","2.4771","1.6514","15.6890","57.6570"
"10.0800","2.4982","2.4982","1.6655","15.8645","58.3022"
"10.1600","2.5176","2.5176","1.6784","16.0209","58.8768"
"10.2400","2.5378","2.5378","1.6918","16.1854","59.4813"
"10.3200","2.5582","2.5582","1.7055","16.3524","60.0949"
"10.4000","2.5784","2.5784","1.7189","16.5130","60.6854"
"10.4800","2.5981","2.5981","1.7321","16.6737","61.2759"
"10.5600","2.6185","2.6185","1.7457","16.8390","61.8835"
"10.6400","2.6374","2.6374","1.7583","16.9927","62.4482"
"10.7200","2.6583","2.6583","1.7722","17.1678","63.0918"
"10.8000","2.6778","2.6778","1.7852","17.3264","63.6745"
"10.8800","2.6979","2.6979","1.7986","17.4910","64.2794"
"10.9600","2.7188","2.7188","1.8126","17.6635","64.9133"
"11.0400","2.7382","2.7382","1.8255","17.8223","65.4970"
"11.1200","2.7593","2.7593","1.8395","17.9938","66.1270"
"11.2000","2.7785","2.7785","1.8523","18.1494","66.6991"
"11.2800","2.7974","2.7974","1.8649","18.3036","67.2659"
"11.3600","2.8174","2.8174","1.8783","18.4705","67.8791"
"11.4400","2.8374","2.8374","1.8916","18.6342","68.4808"
"11.5200","2.8582","2.8582","1.9055","18.8115","69.1324"
"11.6000","2.8796","2.8796","1.9197","18.9858","69.7730"
"11.6800","2.8979","2.8979","1.9319","19.1327","70.3128"
"11.7600","2.9183","2.9183","1.9456","19.3042","70.9430"
"11.8400","2.9380","2.9380","1.9587","19.4637","71.5292"
"11.9200","2.9583","2.9583","1.9722","19.6339","72.1545"
"12.0000","2.9779","2.9779","1.9853","19.7957","72.7494"
"12.0800","2.9973","2.9973","1.9982","19.9529","73.3268"
"12.1600","3.0179","3.0179","2.0119","20.1271","73.9670"
"12.2400","3.0397","3.0397","2.0265","20.3093","74.6368"
"12.3200","3.0589","3.0589","2.0393","20.4668","75.2157"
"12.4000","3.0787","3.0787","2.0525","20.6295","75.8135"
"12.4800","3.0972","3.0972","2.0648","20.7751","76.3486"
"12.5600","3.1180","3.1180","2.0786","20.9527","77.0012"
"12.6400","3.1383","3.1383","2.0922","21.1178","77.6078"
"12.7200","3.1570","3.1570","2.1047","21.2766","78.1914"
"12.8000","3.1787","3.1787","2.1191","21.4689","78.8983"
"12.8800","3.1987","3.1987","2.1325","21.6316","79.4961"
"12.9600","3.2185","3.2185","2.1456","21.7921","80.0859"
"13.0400","3.2385","3.2385","2.1590","21.9570","80.6920"
"13.1200","3.2578","3.2578","2.1718","22.1127","81.2640"
"13.2000","3.2782","3.2782","2.1855","22.2814","81.8841"
"13.2800","3.2978","3.2978","2.1985","22.4375","82.4580"
"13.3600","3.3170","3.3170","2.2114","22.5960","83.0402"
"13.4400","3.3392","3.3392","2.2261","22.7805","83.7185"
"13.5200","3.3591","3.3591","2.2394","22.9423","84.3129"
"13.6000","3.3791","3.3791","2.2527","23.1037","84.9060"
"13.6800","3.3983","3.3983","2.2655","23.2586","85.4753"
"13.7600","3.4170","3.4170","2.2780","23.4097","86.0305"
"13.8400","3.4376","3.4376","2.2917","23.5830","86.6677"
"13.9200","3.4578","3.4578","2.3052","23.7450","87.2630"
"14.0000","3.4777","3.4777","2.3184","23.9087","87.8646"
"14.0800","3.4988","3.4988","2.3326","24.0825","88.5032"
"14.1600","3.5179","3.5179","2.3453","24.2351","89.0642"
"14.2400","3.5387","3.5387","2.3591","24.4037","89.6836"
"14.3200","3.5586","3.5586","2.3724","24.5678","90.2867"
"14.4000","3.5776","3.5776","2.3851","24.7221","90.8538"
"14.4800","3.5973","3.5973","2.3982","24.8801","91.4344"
"14.5600","3.6173","3.6173","2.4116","25.0460","92.0442"
"14.6400","3.6381","3.6381","2.4254","25.2179","92.6757"
"14.7200","3.6598","3.6598","2.4398","25.3958","93.3295"
"14.8000","3.6784","3.6784","2.4523","25.5444","93.8758"
"14.8800","3.6986","3.6986","2.4657","25.7078","94.4762"
"14.9600","3.7181","3.7181","2.4787","25.8633","95.0478"
"15.0400","3.7376","3.7376","2.4917","26.0226","95.6330"
"15.1200","3.7588","3.7588","2.5058","26.2055","96.3051"
"15.2000","3.7771","3.7771","2.5181","26.3464","96.8229"
"15.2800","3.7979","3.7979","2.5320","26.5165","97.4480"
"15.3600","3.8187","3.8187","2.5458","26.6874","98.0764"
"15.4400","3.8385","3.8385","2.5590","26.8444","98.6531"
"15.5200","3.8581","3.8581","2.5721","27.0022","99.2332"
"15.6000","3.8778","3.8778","2.5852","27.1563","99.7996"
"15.6800","3.8976","3.8976","2.5984","27.3179","100.3934"
"15.7600","3.9181","3.9181","2.6121","27.4823","100.9976"
"15.8400","3.9373","3.9373","2.6249","27.6365","101.5642"
"15.9200","3.9590","3.9590","2.6393","27.8160","102.2236"
"16.0000","3.9790","3.9790","2.6526","27.9753","102.8094"
"16.0800","3.9986","3.9986","2.6657","28.1331","103.3891"
"16.1600","4.0179","4.0179","2.6786","28.2887","103.9608"
"16.2400","4.0379","4.0379","2.6919","28.4471","104.5433"
"16.3200","4.0580","4.0580","2.7054","28.6085","105.1362"
"16.4000","4.0780","4.0780","2.7186","28.7693","105.7273"
"16.4800","4.0969","4.0969","2.7313","28.9186","106.2758"
"16.5600","4.1184","4.1184","2.7456","29.0958","106.9271"
"16.6400","4.1385","4.1385","2.7590","29.2537","107.5075"
"16.7200","4.1591","4.1591","2.7727","29.4215","108.1240"
"16.8000","4.1789","4.1789","2.7860","29.5763","108.6928"
"16.8800","4.1976","4.1976","2.7984","29.7246","109.2379"
"16.9600","4.2181","4.2181","2.8121","29.8848","109.8267"
"17.0400","4.2377","4.2377","2.8251","30.0424","110.4059"
"17.1200","4.2578","4.2578","2.8386","30.2046","111.0021"
"17.2000","4.2788","4.2788","2.8525","30.3748","111.6274"
"17.2800","4.2983","4.2983","2.8655","30.5257","112.1820"
"17.3600","4.3188","4.3188","2.8792","30.6925","112.7948"
"17.4400","4.3390","4.3390","2.8927","30.8510","113.3776"
"17.5200","4.3573","4.3573","2.9049","30.9930","113.8991"
"17.6000","4.3780","4.3780","2.9186","31.1591","114.5097"
"17.6800","4.3969","4.3969","2.9313","31.3053","115.0468"
"17.7600","4.4177","4.4177","2.9451","31.4746","115.6693"
"17.8400","4.4386","4.4386","2.9591","31.6429","116.2878"
"17.9200","4.4587","4.4587","2.9724","31.7975","116.8558"
"18.0000","4.4781","4.4781","2.9854","31.9512","117.4208"
"18.0800","4.4983","4.4983","2.9989","32.1109","118.0076"
"18.1600","4.5173","4.5173","3.0116","32.2622","118.5635"
"18.2400","4.5382","4.5382","3.0255","32.4287","119.1756"
"18.3200","4.5575","4.5575","3.0383","32.5750","119.7130"
"18.4000","4.5786","4.5786","3.0524","32.7490","120.3525"
"18.4800","4.5991","4.5991","3.0661","32.9086","120.9391"
"18.5600","4.6184","4.6184","3.0789","33.0616","121.5013"
"18.6400","4.6382","4.6382","3.0922","33.2151","122.0656"
"18.7200","4.6583","4.6583","3.1055","33.3734","122.6471"
"18.8000","4.6780","4.6780","3.1186","33.5262","123.2088"
"18.8800","4.6977","4.6977","3.1318","33.6847","123.7911"
"18.9600","4.7167","4.7167","3.1445","33.8275","124.3162"
"19.0400","4.7379","4.7379","3.1586","34.0001","124.9504"
"19.1200","4.7590","4.7590","3.1726","34.1638","125.5519"
"19.2000","4.7783","4.7783","3.1856","34.3157","126.1102"
"19.2800","4.7986","4.7986","3.1991","34.4702","126.6781"
"19.3600","4.8172","4.8172","3.2115","34.6101","127.1920"
"19.4400","4.8381","4.8381","3.2254","34.7767","127.8044"
"19.5200","4.8585","4.8585","3.2390","34.9351","128.3864"
"19.6000","4.8776","4.8776","3.2517","35.0836","128.9324"
"19.6800","4.8982","4.8982","3.2655","35.2455","129.5272"
"19.7600","4.9191","4.9191","3.2794","35.4095","130.1300"
"19.8400","4.9388","4.9388","3.2925","35.5591","130.6798"
"19.9200","4.9587","4.9587","3.3058","35.7098","131.2336"
"20.0000","4.9773","4.9773","3.3182","35.8487","131.7439"
"20.0800","4.9983","4.9983","3.3322","36.0150","132.3552"
"20.1600","5.0180","5.0180","3.3453","36.1628","132.8983"
"20.2400","5.0373","5.0373","3.3582","36.3125","133.4485"
"20.3200","5.0582","5.0582","3.3721","36.4792","134.0610"
"20.4000","5.0783","5.0783","3.3855","36.6293","134.6126"
"20.4800","5.0982","5.0982","3.3988","36.7815","135.1721"
"20.5600","5.1186","5.1186","3.4124","36.9377","135.7461"
"20.6400","5.1374","5.1374","3.4250","37.0786","136.2637"
"20.7200","5.1583","5.1583","3.4389","37.2407","136.8596"
"20.8000","5.1775","5.1775","3.4517","37.3841","137.3865"
"20.8800","5.1977","5.1977","3.4651","37.5423","137.9680"
"20.9600","5.2191","5.2191","3.4794","37.7083","138.5781"
"21.0400","5.2389","5.2389","3.4926","37.8558","139.1202"
"21.1200","5.2590","5.2590","3.5060","38.0089","139.6828"
"21.2000","5.2784","5.2784","3.5189","38.1560","140.2232"
"21.2800","5.2975","5.2975","3.5317","38.2991","140.7493"
"21.3600","5.3174","5.3174","3.5449","38.4502","141.3047"
"21.4400","5.3372","5.3372","3.5581","38.5960","141.8403"
"21.5200","5.3582","5.3582","3.5721","38.7589","142.4390"
"21.6000","5.3792","5.3792","3.5862","38.9200","143.0311"
"21.6800","5.3980","5.3980","3.5987","39.0581","143.5386"
"21.7600","5.4186","5.4186","3.6124","39.2111","144.1008"
"21.8400","5.4379","5.4379","3.6253","39.3582","144.6414"
"21.9200","5.4584","5.4584","3.6389","39.5147","145.2164"
"22.0000","5.4781","5.4781","3.6521","39.6609","145.7538"
"22.0800","5.4970","5.4970","3.6647","39.7981","146.2581"
"22.1600","5.5179","5.5179","3.6786","39.9575","146.8437"
"22.2400","5.5392","5.5392","3.6928","40.1158","147.4254"
"22.3200","5.5588","5.5588","3.7059","40.2632","147.9674"
"22.4000","5.5787","5.5787","3.7191","40.4091","148.5036"
"22.4800","5.5974","5.5974","3.7316","40.5436","148.9979"
"22.5600","5.6180","5.6180","3.7454","40.7005","149.5742"
"22.6400","5.6383","5.6383","3.7589","40.8486","150.1186"
"22.7200","5.6571","5.6571","3.7714","40.9862","150.6243"
"22.8000","5.6779","5.6779","3.7853","41.1414","151.1946"
"22.8800","5.6986","5.6986","3.7991","41.2956","151.7612"
"22.9600","5.7183","5.7183","3.8122","41.4396","152.2904"
"23.0400","5.7386","5.7386","3.8257","41.5900","152.8434"
"23.1200","5.7578","5.7578","3.8386","41.7304","153.3594"
"23.2000","5.7781","5.7781","3.8521","41.8796","153.9075"
"23.2800","5.7980","5.7980","3.8653","42.0237","154.4373"
"23.3600","5.8175","5.8175","3.8784","42.1706","154.9768"
"23.4400","5.8391","5.8391","3.8928","42.3341","155.5778"
"23.5200","5.8591","5.8591","3.9060","42.4801","156.1143"
"23.6000","5.8794","5.8794","3.9196","42.6289","156.6613"
"23.6800","5.8984","5.8984","3.9323","42.7642","157.1583"
"23.7600","5.9173","5.9173","3.9448","42.8963","157.6438"
"23.8400","5.9376","5.9376","3.9584","43.0460","158.1939"
"23.9200","5.9581","5.9581","3.9720","43.1966","158.7477"
"24.0000","5.9777","5.9777","3.9851","43.3399","159.2742"
"24.0800","5.9984","5.9984","3.9989","43.4909","159.8292"
"24.1600","6.0179","6.0179","4.0120","43.6290","160.3366"
"24.2400","6.0387","6.0387","4.0258","43.7799","160.8911"
"24.3200","6.0584","6.0584","4.0389","43.9216","161.4120"
"24.4000","6.0778","6.0778","4.0519","44.0578","161.9124"
"24.4800","6.0974","6.0974","4.0649","44.1983","162.4286"
"24.5600","6.1175","6.1175","4.0784","44.3404","162.9510"
"24.6400","6.1384","6.1384","4.0923","44.4955","163.5211"
"24.7200","6.1598","6.1598","4.1066","44.6515","164.0941"
"24.8000","6.1783","6.1783","4.1188","44.7785","164.5609"
"24.8800","6.1985","6.1985","4.1324","44.9250","165.0995"
"24.9600","6.2176","6.2176","4.1451","45.0555","165.5789"
"25.0400","6.2372","6.2372","4.1581","45.1971","166.0994"
"25.1200","6.2583","6.2583","4.1722","45.3495","166.6595"
"25.2000","6.2771","6.2771","4.1847","45.4769","167.1277"
"25.2800","6.2978","6.2978","4.1986","45.6255","167.6736"
"25.3600","6.3187","6.3187","4.2124","45.7772","168.2314"
"25.4400","6.3383","6.3383","4.2256","45.9154","168.7390"
"25.5200","6.3586","6.3586","4.2391","46.0618","169.2770"
"25.6000","6.3779","6.3779","4.2520","46.1936","169.7614"
"25.6800","6.3975","6.3975","4.2650","46.3293","170.2600"
"25.7600","6.4184","6.4184","4.2789","46.4837","170.8277"
"25.8400","6.4375","6.4375","4.2916","46.6156","171.3123"
"25.9200","6.4591","6.4591","4.3061","46.7724","171.8887"
"26.0000","6.4792","6.4792","4.3195","46.9114","172.3993"
"26.0800","6.4985","6.4985","4.3323","47.0422","172.8801"
"26.1600","6.5177","6.5177","4.3451","47.1797","173.3853"
"26.2400","6.5381","6.5381","4.3587","47.3218","173.9075"
"26.3200","6.5586","6.5586","4.3724","47.4671","174.4417"
"26.4000","6.5784","6.5784","4.3856","47.6035","174.9430"
"26.4800","6.5969","6.5969","4.3979","47.7310","175.4115"
"26.5600","6.6177","6.6177","4.4118","47.8775","175.9496"
"26.6400","6.6379","6.6379","4.4253","48.0186","176.4683"
"26.7200","6.6594","6.6594","4.4396","48.1714","177.0300"
"26.8000","6.6789","6.6789","4.4526","48.3021","177.5101"
"26.8800","6.6973","6.6973","4.4648","48.4236","177.9569"
"26.9600","6.7179","6.7179","4.4786","48.5705","178.4967"
"27.0400","6.7381","6.7381","4.4921","48.7086","179.0042"
"27.1200","6.7575","6.7575","4.5050","48.8422","179.4953"
"27.2000","6.7783","6.7783","4.5188","48.9874","180.0288"
"27.2800","6.7982","6.7982","4.5321","49.1194","180.5138"
"27.3600","6.8187","6.8187","4.5458","49.2585","181.0249"
"27.4400","6.8389","6.8389","4.5593","49.3970","181.5341"
"27.5200","6.8577","6.8577","4.5718","49.5222","181.9942"
"27.6000","6.8781","6.8781","4.5854","49.6644","182.5168"
"27.6800","6.8971","6.8971","4.5981","49.7922","182.9865"
"27.7600","6.9179","6.9179","4.6120","49.9381","183.5226"
"27.8400","6.9388","6.9388","4.6259","50.0858","184.0653"
"27.9200","6.9585","6.9585","4.6390","50.2134","184.5342"
"28.0000","6.9784","6.9784","4.6522","50.3463","185.0226"
"28.0800","6.9982","6.9982","4.6655","50.4793","185.5113"
"28.1600","7.0173","7.0173","4.6782","50.6066","185.9793"
"28.2400","7.0382","7.0382","4.6922","50.7521","186.5138"
"28.3200","7.0576","7.0576","4.7050","50.8781","186.9771"
"28.4000","7.0787","7.0787","4.7192","51.0228","187.5087"
"28.4800","7.0991","7.0991","4.7327","51.1602","188.0138"
"28.5600","7.1187","7.1187","4.7458","51.2905","188.4928"
"28.6400","7.1385","7.1385","4.7590","51.4272","188.9951"
"28.7200","7.1581","7.1581","4.7721","51.5562","189.4692"
"28.8000","7.1777","7.1777","4.7852","51.6858","189.9455"
"28.8800","7.1980","7.1980","4.7986","51.8211","190.4427"
"28.9600","7.2170","7.2170","4.8113","51.9416","190.8852"
"29.0400","7.2380","7.2380","4.8254","52.0855","191.4141"
"29.1200","7.2588","7.2588","4.8392","52.2256","191.9290"
"29.2000","7.2785","7.2785","4.8523","52.3605","192.4247"
"29.2800","7.2985","7.2985","4.8657","52.4880","192.8935"
"29.3600","7.3173","7.3173","4.8782","52.6080","193.3342"
"29.4400","7.3383","7.3383","4.8922","52.7479","193.8484"
"29.5200","7.3578","7.3578","4.9052","52.8733","194.3092"
"29.6000","7.3773","7.3773","4.9182","52.9986","194.7698"
"29.6800","7.3985","7.3985","4.9323","53.1442","195.3050"
"29.7600","7.4191","7.4191","4.9461","53.2802","195.8047"
"29.8400","7.4387","7.4387","4.9591","53.4060","196.2671"
"29.9200","7.4586","7.4586","4.9724","53.5324","196.7317"
"30.0000","7.4772","7.4772","4.9848","53.6495","197.1620"
"30.0800","7.4981","7.4981","4.9987","53.7883","197.6719"
"30.1600","7.5179","7.5179","5.0119","53.9153","198.1389"
"30.2400","7.5373","7.5373","5.0249","54.0414","198.6021"
"30.3200","7.5585","7.5585","5.0390","54.1807","199.1140"
"30.4000","7.5786","7.5786","5.0524","54.3094","199.5872"
"30.4800","7.5982","7.5982","5.0654","54.4312","200.0345"
"30.5600","7.6187","7.6187","5.0792","54.5658","200.5294"
"30.6400","7.6374","7.6374","5.0916","54.6839","200.9633"
"30.7200","7.6586","7.6586","5.1057","54.8240","201.4783"
"30.8000","7.6779","7.6779","5.1186","54.9439","201.9190"
"30.8800","7.6980","7.6980","5.1320","55.0737","202.3958"
"30.9600","7.7188","7.7188","5.1459","55.2102","202.8976"
"31.0400","7.7387","7.7387","5.1591","55.3333","203.3499"
"31.1200","7.7590","7.7590","5.1726","55.4622","203.8234"
"31.2000","7.7781","7.7781","5.1854","55.5808","204.2595"
"31.2800","7.7972","7.7972","5.1981","55.7012","204.7020"
"31.3600","7.8176","7.8176","5.2117","55.8348","205.1928"
"31.4400","7.8375","7.8375","5.2250","55.9569","205.6416"
"31.5200","7.8579","7.8579","5.2386","56.0925","206.1401"
"31.6000","7.8792","7.8792","5.2528","56.2295","206.6435"
"31.6800","7.8981","7.8981","5.2654","56.3438","207.0636"
"31.7600","7.9186","7.9186","5.2791","56.4757","207.5480"
"31.8400","7.9379","7.9379","5.2919","56.5919","207.9751"
"31.9200","7.9581","7.9581","5.3054","56.7227","208.4559"
"32.0000","7.9778","7.9778","5.3185","56.8422","208.8953"
"32.0800","7.9976","7.9976","5.3317","56.9647","209.3452"
"32.1600","8.0183","8.0183","5.3455","57.0974","209.8328"
"32.2400","8.0396","8.0396","5.3597","57.2323","210.3287"
"32.3200","8.0584","8.0584","5.3722","57.3455","210.7446"
"32.4000","8.0784","8.0784","5.3856","57.4702","211.2029"
"32.4800","8.0972","8.0972","5.3982","57.5810","211.6100"
"32.5600","8.1180","8.1180","5.4120","57.7134","212.0969"
"32.6400","8.1383","8.1383","5.4255","57.8382","212.5555"
"32.7200","8.1572","8.1572","5.4381","57.9500","212.9663"
"32.8000","8.1780","8.1780","5.4520","58.0835","213.4567"
"32.8800","8.1985","8.1985","5.4656","58.2090","213.9182"
"32.9600","8.2182","8.2182","5.4788","58.3280","214.3552"
"33.0400","8.2386","8.2386","5.4924","58.4565","214.8275"
"33.1200","8.2578","8.2578","5.5052","58.5644","215.2242"
"33.2000","8.2780","8.2780","5.5187","58.6884","215.6798"
"33.2800","8.2978","8.2978","5.5319","58.8047","216.1074"
"33.3600","8.3174","8.3174","5.5449","58.9264","216.5545"
"33.4400","8.3393","8.3393","5.5595","59.0701","217.0826"
"33.5200","8.3595","8.3595","5.5730","59.1882","217.5168"
"33.6000","8.3791","8.3791","5.5861","59.3025","217.9368"
"33.6800","8.3979","8.3979","5.5986","59.4106","218.3341"
"33.7600","8.4172","8.4172","5.6114","59.5235","218.7488"
"33.8400","8.4378","8.4378","5.6252","59.6478","219.2058"
"33.9200","8.4582","8.4582","5.6388","59.7685","219.6492"
"34.0000","8.4773","8.4773","5.6516","59.8783","220.0527"
"34.0800","8.4982","8.4982","5.6655","60.0067","220.5245"
"34.1600","8.5180","8.5180","5.6786","60.1194","220.9388"
"34.2400","8.5391","8.5391","5.6928","60.2485","221.4133"
"34.3200","8.5585","8.5585","5.7057","60.3584","221.8171"
"34.4000","8.5777","8.5777","5.7185","60.4673","222.2174"
"34.4800","8.5976","8.5976","5.7317","60.5832","222.6433"
"34.5600","8.6169","8.6169","5.7446","60.6884","223.0298"
"34.6400","8.6387","8.6387","5.7591","60.8209","223.5170"
"34.7200","8.6598","8.6598","5.7732","60.9501","223.9916"
"34.8000","8.6789","8.6789","5.7859","61.0554","224.3787"
"34.8800","8.6983","8.6983","5.7989","61.1625","224.7721"
"34.9600","8.7181","8.7181","5.8121","61.2740","225.1821"
"35.0400","8.7377","8.7377","5.8251","61.3889","225.6041"
"35.1200","8.7584","8.7584","5.8389","61.5094","226.0471"
"35.2000","8.7769","8.7769","5.8513","61.6046","226.3971"
"35.2800","8.7977","8.7977","5.8651","61.7242","226.8364"
"35.3600","8.8185","8.8185","5.8790","61.8416","227.2681"
"35.4400","8.8385","8.8385","5.8923","61.9568","227.6913"
"35.5200","8.8587","8.8587","5.9058","62.0694","228.1050"
"35.6000","8.8781","8.8781","5.9187","62.1733","228.4869"
"35.6800","8.8976","8.8976","5.9317","62.2822","228.8870"
"35.7600","8.9181","8.9181","5.9454","62.3994","229.3179"
"35.8400","8.9374","8.9374","5.9582","62.5044","229.7035"
"35.9200","8.9592","8.9592","5.9728","62.6328","230.1757"
"36.0000","8.9791","8.9791","5.9861","62.7414","230.5747"
"36.0800","8.9987","8.9987","5.9991","62.8487","230.9689"
"36.1600","9.0179","9.0179","6.0119","62.9530","231.3525"
"36.2400","9.0378","9.0378","6.0252","63.0596","231.7439"
"36.3200","9.0584","9.0584","6.0389","63.1737","232.1635"
"36.4000","9.0783","9.0783","6.0522","63.2793","232.5515"
"36.4800","9.0969","9.0969","6.0646","63.3797","232.9202"
"36.5600","9.1179","9.1179","6.0786","63.4995","233.3607"
"36.6400","9.1383","9.1383","6.0922","63.6086","233.7617"
"36.7200","9.1592","9.1592","6.1061","63.7252","234.1903"
"36.8000","9.1788","9.1788","6.1192","63.8278","234.5670"
"36.8800","9.1975","9.1975","6.1316","63.9204","234.9076"
"36.9600","9.2179","9.2179","6.1452","64.0311","235.3145"
"37.0400","9.2377","9.2377","6.1585","64.1371","235.7039"
"37.1200","9.2577","9.2577","6.1718","64.2466","236.1062"
"37.2000","9.2785","9.2785","6.1856","64.3566","236.5107"
"37.2800","9.2988","9.2988","6.1992","64.4638","236.9046"
"37.3600","9.3187","9.3187","6.2125","64.5681","237.2878"
"37.4400","9.3388","9.3388","6.2258","64.6734","237.6747"
"37.5200","9.3579","9.3579","6.2386","64.7758","238.0512"
"37.6000","9.3780","9.3780","6.2520","64.8783","238.4278"
"37.6800","9.3970","9.3970","6.2647","64.9714","238.7701"
"37.7600","9.4176","9.4176","6.2784","65.0812","239.1735"
"37.8400","9.4388","9.4388","6.2925","65.1965","239.5970"
"37.9200","9.4589","9.4589","6.3059","65.2987","239.9726"
"38.0000","9.4784","9.4784","6.3190","65.3939","240.3225"
"38.0800","9.4982","9.4982","6.3321","65.4923","240.6844"
"38.1600","9.5170","9.5170","6.3446","65.5852","241.0257"
"38.2400","9.5383","9.5383","6.3589","65.7006","241.4498"
"38.3200","9.5576","9.5576","6.3717","65.7895","241.7764"
"38.4000","9.5786","9.5786","6.3857","65.8999","242.1822"
"38.4800","9.5990","9.5990","6.3993","65.9995","242.5481"
"38.5600","9.6184","9.6184","6.4123","66.0945","242.8973"
"38.6400","9.6384","9.6384","6.4256","66.1928","243.2586"
"38.7200","9.6579","9.6579","6.4386","66.2842","243.5945"
"38.8000","9.6779","9.6779","6.4519","66.3837","243.9599"
"38.8800","9.6977","9.6977","6.4652","66.4793","244.3115"
"38.9600","9.7167","9.7167","6.4778","66.5665","244.6319"
"39.0400","9.7379","9.7379","6.4919","66.6755","245.0324"
"39.1200","9.7593","9.7593","6.5062","66.7836","245.4297"
"39.2000","9.7787","9.7787","6.5191","66.8734","245.7597"
"39.2800","9.7984","9.7984","6.5322","66.9625","246.0873"
"39.3600","9.8169","9.8169","6.5446","67.0433","246.3840"
"39.4400","9.8379","9.8379","6.5586","67.1481","246.7692"
"39.5200","9.8584","9.8584","6.5723","67.2471","247.1331"
"39.6000","9.8781","9.8781","6.5854","67.3370","247.4636"
"39.6800","9.8984","9.8984","6.5989","67.4342","247.8208"
"39.7600","9.9191","9.9191","6.6127","67.5284","248.1670"
"39.8400","9.9384","9.9384","6.6256","67.6156","248.4875"
"39.9200","9.9588","9.9588","6.6392","67.7045","248.8139"
"40.0000","9.9773","9.9773","6.6515","67.7790","249.0878"
"40.0800","9.9979","9.9979","6.6653","67.8784","249.4530"
"40.1600","10.0179","10.0179","6.6786","67.9697","249.7885"
"40.2400","10.0375","10.0375","6.6917","68.0564","250.1072"
"40.3200","10.0583","10.0583","6.7055","68.1537","250.4648"
"40.4000","10.0784","10.0784","6.7189","68.2393","250.7793"
"40.4800","10.0982","10.0982","6.7322","68.3255","251.0962"
"40.5600","10.1185","10.1185","6.7457","68.4148","251.4243"
"40.6400","10.1373","10.1373","6.7582","68.4900","251.7009"
"40.7200","10.1581","10.1581","6.7721","68.5837","252.0452"
"40.8000","10.1777","10.1777","6.7851","68.6638","252.3394"
"40.8800","10.1983","10.1983","6.7989","68.7599","252.6925"
"40.9600","10.2190","10.2190","6.8127","68.8503","253.0250"
"41.0400","10.2389","10.2389","6.8259","68.9335","253.3307"
"41.1200","10.2589","10.2589","6.8393","69.0161","253.6342"
"41.2000","10.2782","10.2782","6.8521","69.0926","253.9153"
"41.2800","10.2977","10.2977","6.8651","69.1737","254.2133"
"41.3600","10.3177","10.3177","6.8785","69.2583","254.5241"
"41.4400","10.3372","10.3372","6.8915","69.3350","254.8061"
"41.5200","10.3580","10.3580","6.9053","69.4258","255.1399"
"41.6000","10.3792","10.3792","6.9194","69.5171","255.4752"
"41.6800","10.3974","10.3974","6.9316","69.5803","255.7075"
"41.7600","10.4183","10.4183","6.9456","69.6668","256.0256"
"41.8400","10.4380","10.4380","6.9587","69.7456","256.3150"
"41.9200","10.4583","10.4583","6.9722","69.8259","256.6102"
"42.0000","10.4778","10.4778","6.9852","69.9012","256.8867"
"42.0800","10.4975","10.4975","6.9983","69.9728","257.1501"
"42.1600","10.5179","10.5179","7.0119","70.0542","257.4492"
"42.2400","10.5396","10.5396","7.0264","70.1480","257.7938"
"42.3200","10.5587","10.5587","7.0391","70.2138","258.0357"
"42.4000","10.5786","10.5786","7.0524","70.2884","258.3097"
"42.4800","10.5973","10.5973","7.0649","70.3536","258.5494"
"42.5600","10.6181","10.6181","7.0787","70.4359","258.8520"
"42.6400","10.6384","10.6384","7.0923","70.5089","259.1203"
"42.7200","10.6571","10.6571","7.1047","70.5731","259.3561"
"42.8000","10.6779","10.6779","7.1186","70.6507","259.6412"
"42.8800","10.6987","10.6987","7.1324","70.7319","259.9398"
"42.9600","10.7187","10.7187","7.1458","70.8011","260.1942"
"43.0400","10.7387","10.7387","7.1591","70.8708","260.4502"
"43.1200","10.7579","10.7579","7.1719","70.9307","260.6702"
"43.2000","10.7779","10.7779","7.1853","71.0045","260.9417"
"43.2800","10.7981","10.7981","7.1987","71.0744","261.1983"
"43.3600","10.8175","10.8175","7.2117","71.1415","261.4449"
"43.4400","10.8393","10.8393","7.2262","71.2273","261.7604"
"43.5200","10.8589","10.8589","7.2393","71.2901","261.9909"
"43.6000","10.8796","10.8796","7.2530","71.3580","262.2405"
"43.6800","10.8982","10.8982","7.2655","71.4139","262.4461"
"43.7600","10.9173","10.9173","7.2782","71.4709","262.6557"
"43.8400","10.9374","10.9374","7.2916","71.5386","262.9044"
"43.9200","10.9580","10.9580","7.3053","71.6086","263.1618"
"44.0000","10.9773","10.9773","7.3182","71.6675","263.3779"
"44.0800","10.9986","10.9986","7.3324","71.7423","263.6530"
"44.1600","11.0179","11.0179","7.3453","71.7959","263.8498"
"44.2400","11.0388","11.0388","7.3592","71.8622","264.0935"
"44.3200","11.0583","11.0583","7.3722","71.9193","264.3036"
"44.4000","11.0777","11.0777","7.3851","71.9765","264.5137"
"44.4800","11.0974","11.0974","7.3983","72.0343","264.7260"
"44.5600","11.1175","11.1175","7.4116","72.0939","264.9452"
"44.6400","11.1384","11.1384","7.4256","72.1671","265.2141"
"44.7200","11.1599","11.1599","7.4399","72.2356","265.4659"
"44.8000","11.1786","11.1786","7.4524","72.2807","265.6316"
"44.8800","11.1985","11.1985","7.4657","72.3355","265.8328"
"44.9600","11.2184","11.2184","7.4789","72.3881","266.0263"
"45.0400","11.2377","11.2377","7.4918","72.4404","266.2184"
"45.1200","11.2583","11.2583","7.5056","72.5005","266.4393"
"45.2000","11.2770","11.2770","7.5180","72.5413","266.5891"
"45.2800","11.2978","11.2978","7.5319","72.6017","266.8112"
"45.3600","11.3187","11.3187","7.5458","72.6645","267.0421"
"45.4400","11.3389","11.3389","7.5593","72.7188","267.2414"
"45.5200","11.3585","11.3585","7.5723","72.7675","267.4206"
"45.6000","11.3780","11.3780","7.5853","72.8127","267.5867"
"45.6800","11.3974","11.3974","7.5983","72.8632","267.7721"
"45.7600","11.4182","11.4182","7.6121","72.9188","267.9767"
"45.8400","11.4375","11.4375","7.6250","72.9640","268.1425"
"45.9200","11.4593","11.4593","7.6395","73.0281","268.3782"
"46.0000","11.4789","11.4789","7.6526","73.0697","268.5313"
"46.0800","11.4985","11.4985","7.6656","73.1174","268.7065"
"46.1600","11.5178","11.5178","7.6786","73.1588","268.8587"
"46.2400","11.5381","11.5381","7.6921","73.2076","269.0380"
"46.3200","11.5584","11.5584","7.7056","73.2566","269.2181"
"46.4000","11.5783","11.5783","7.7188","73.2995","269.3756"
"46.4800","11.5968","11.5968","7.7312","73.3383","269.5184"
"46.5600","11.6176","11.6176","7.7451","73.3891","269.7048"
"46.6400","11.6382","11.6382","7.7588","73.4390","269.8883"
"46.7200","11.6593","11.6593","7.7729","73.4927","270.0856"
"46.8000","11.6788","11.6788","7.7859","73.5312","270.2273"
"46.8800","11.6971","11.6971","7.7981","73.5622","270.3412"
"46.9600","11.7173","11.7173","7.8115","73.6094","270.5146"
"47.0400","11.7381","11.7381","7.8254","73.6673","270.7274"
"47.1200","11.7582","11.7582","7.8388","73.7103","270.8852"
"47.2000","11.7788","11.7788","7.8526","73.7582","271.0613"
"47.2800","11.7985","11.7985","7.8657","73.7915","271.1838"
"47.3600","11.8187","11.8187","7.8791","73.8364","271.3489"
"47.4400","11.8390","11.8390","7.8926","73.8753","271.4916"
"47.5200","11.8577","11.8577","7.9052","73.9093","271.6168"
"47.6000","11.8781","11.8781","7.9187","73.9496","271.7648"
"47.6800","11.8970","11.8970","7.9313","73.9805","271.8782"
"47.7600","11.9177","11.9177","7.9451","74.0272","272.0499"
"47.8400","11.9383","11.9383","7.9589","74.0700","272.2073"
"47.9200","11.9588","11.9588","7.9725","74.1057","272.3385"
"48.0000","11.9784","11.9784","7.9856","74.1405","272.4664"
"48.0800","11.9982","11.9982","7.9988","74.1709","272.5780"
"48.1600","12.0173","12.0173","8.0115","74.2047","272.7024"
"48.2400","12.0382","12.0382","8.0255","74.2484","272.8629"
"48.3200","12.0575","12.0575","8.0383","74.2763","272.9653"
"48.4000","12.0788","12.0788","8.0525","74.3216","273.1317"
"48.4800","12.0989","12.0989","8.0660","74.3546","273.2531"
"48.5600","12.1185","12.1185","8.0790","74.3865","273.3705"
"48.6400","12.1383","12.1383","8.0922","74.4150","273.4751"
"48.7200","12.1584","12.1584","8.1056","74.4506","273.6060"
"48.8000","12.1781","12.1781","8.1187","74.4822","273.7220"
"48.8800","12.1979","12.1979","8.1320","74.5128","273.8346"
"48.9600","12.2168","12.2168","8.1445","74.5358","273.9191"
"49.0400","12.2383","12.2383","8.1589","74.5823","274.0899"
"49.1200","12.2592","12.2592","8.1728","74.6201","274.2288"
"49.2000","12.2785","12.2785","8.1857","74.6442","274.3175"
"49.2800","12.2982","12.2982","8.1988","74.6733","274.4243"
"49.3600","12.3174","12.3174","8.2116","74.6948","274.5032"
"49.4400","12.3384","12.3384","8.2256","74.7309","274.6360"
"49.5200","12.3585","12.3585","8.2390","74.7613","274.7477"
"49.6000","12.3778","12.3778","8.2519","74.7826","274.8261"
"49.6800","12.3976","12.3976","8.2651","74.8089","274.9226"
"49.7600","12.4190","12.4190","8.2793","74.8485","275.0683"
"49.8400","12.4390","12.4390","8.2927","74.8729","275.1580"
"49.9200","12.4589","12.4589","8.3059","74.9012","275.2619"
"50.0000","12.4772","12.4772","8.3181","74.9161","275.3165"
"50.0800","12.4982","12.4982","8.3321","74.9489","275.4372"
"50.1600","12.5177","12.5177","8.3451","74.9677","275.5063"
"50.2400","12.5376","12.5376","8.3584","74.9961","275.6105"
"50.3200","12.5578","12.5578","8.3719","75.0213","275.7034"
"50.4000","12.5784","12.5784","8.3856","75.0447","275.7894"
"50.4800","12.5983","12.5983","8.3988","75.0647","275.8626"
"50.5600","12.6184","12.6184","8.4122","75.0860","275.9412"
"50.6400","12.6373","12.6373","8.4249","75.1022","276.0007"
"50.7200","12.6580","12.6580","8.4387","75.1296","276.1014"
"50.8000","12.6779","12.6779","8.4519","75.1458","276.1607"
"50.8800","12.6982","12.6982","8.4654","75.1656","276.2336"
"50.9600","12.7190","12.7190","8.4793","75.1879","276.3155"
"51.0400","12.7387","12.7387","8.4925","75.2054","276.3799"
"51.1200","12.7591","12.7591","8.5061","75.2226","276.4432"
"51.2000","12.7785","12.7785","8.5190","75.2376","276.4983"
"51.2800","12.7975","12.7975","8.5317","75.2538","276.5577"
"51.3600","12.8176","12.8176","8.5451","75.2760","276.6394"
"51.4400","12.8374","12.8374","8.5583","75.2894","276.6885"
"51.5200","12.8578","12.8578","8.5719","75.3164","276.7879"
"51.6000","12.8795","12.8795","8.5863","75.3476","276.9023"
"51.6800","12.8982","12.8982","8.5988","75.3553","276.9306"
"51.7600","12.9184","12.9184","8.6122","75.3697","276.9837"
"51.8400","12.9379","12.9379","8.6252","75.3823","277.0300"
"51.9200","12.9582","12.9582","8.6388","75.4018","277.1015"
"52.0000","12.9780","12.9780","8.6520","75.4166","277.1561"
"52.0800","12.9973","12.9973","8.6649","75.4242","277.1841"
"52.1600","13.0183","13.0183","8.6789","75.4460","277.2639"
"52.2400","13.0395","13.0395","8.6930","75.4652","277.3347"
"52.3200","13.0588","13.0588","8.7059","75.4744","277.3684"
"52.4000","13.0786","13.0786","8.7191","75.4845","277.4054"
"52.4800","13.0976","13.0976","8.7317","75.4874","277.4162"
"52.5600","13.1180","13.1180","8.7453","75.5078","277.4913"
"52.6400","13.1383","13.1383","8.7589","75.5205","277.5380"
"52.7200","13.1568","13.1568","8.7712","75.5217","277.5422"
"52.8000","13.1780","13.1780","8.7853","75.5427","277.6193"
"52.8800","13.1990","13.1990","8.7993","75.5626","277.6927"
"52.9600","13.2187","13.2187","8.8125","75.5680","277.7124"
"53.0400","13.2386","13.2386","8.8258","75.5776","277.7476"
"53.1200","13.2576","13.2576","8.8384","75.5766","277.7440"
"53.2000","13.2781","13.2781","8.8521","75.5888","277.7888"
"53.2800","13.2982","13.2982","8.8655","75.5934","277.8059"
"53.3600","13.3171","13.3171","8.8781","75.5969","277.8185"
"53.4400","13.3391","13.3391","8.8927","75.6127","277.8768"
"53.5200","13.3591","13.3591","8.9061","75.6156","277.8875"
"53.6000","13.3794","13.3794","8.9196","75.6181","277.8967"
"53.6800","13.3983","13.3983","8.9322","75.6136","277.8801"
"53.7600","13.4171","13.4171","8.9447","75.6085","277.8612"
"53.8400","13.4375","13.4375","8.9583","75.6141","277.8818"
"53.9200","13.4581","13.4581","8.9720","75.6196","277.9021"
"54.0000","13.4771","13.4771","8.9847","75.6198","277.9027"
"54.0800","13.4981","13.4981","8.9987","75.6302","277.9409"
"54.1600","13.5180","13.5180","9.0120","75.6324","277.9490"
"54.2400","13.5391","13.5391","9.0261","75.6406","277.9794"
"54.3200","13.5583","13.5583","9.0389","75.6383","277.9709"
"54.4000","13.5778","13.5778","9.0519","75.6407","277.9796"
"54.4800","13.5976","13.5976","9.0651","75.6368","277.9651"
"54.5600","13.6179","13.6179","9.0786","75.6387","277.9720"
"54.6400","13.6382","13.6382","9.0922","75.6453","277.9966"
"54.7200","13.6600","13.6600","9.1066","75.6548","278.0315"
"54.8000","13.6787","13.6787","9.1191","75.6482","278.0071"
"54.8800","13.6984","13.6984","9.1323","75.6445","277.9934"
"54.9600","13.7179","13.7179","9.1453","75.6407","277.9797"
"55.0400","13.7379","13.7379","9.1586","75.6434","277.9894"
"55.1200","13.7584","13.7584","9.1723","75.6458","277.9983"
"55.2000","13.7772","13.7772","9.1848","75.6376","277.9684"
"55.2800","13.7980","13.7980","9.1987","75.6440","277.9915"
"55.3600","13.8187","13.8187","9.2124","75.6477","278.0052"
"55.4400","13.8388","13.8388","9.2259","75.6484","278.0080"
"55.5200","13.8583","13.8583","9.2389","75.6423","277.9855"
"55.6000","13.8779","13.8779","9.2519","75.6335","277.9532"
"55.6800","13.8975","13.8975","9.2650","75.6321","277.9479"
"55.7600","13.9181","13.9181","9.2788","75.6307","277.9429"
"55.8400","13.9373","13.9373","9.2915","75.6237","277.9173"
"55.9200","13.9594","13.9594","9.3063","75.6315","277.9458"
"56.0000","13.9790","13.9790","9.3193","75.6223","277.9121"
"56.0800","13.9983","13.9983","9.3322","75.6137","277.8802"
"56.1600","14.0180","14.0180","9.3453","75.6084","277.8609"
"56.2400","14.0381","14.0381","9.3587","75.6013","277.8347"
"56.3200","14.0582","14.0582","9.3721","75.5947","277.8105"
"56.4000","14.0785","14.0785","9.3856","75.5907","277.7958"
"56.4800","14.0968","14.0968","9.3979","75.5786","277.7512"
"56.5600","14.1180","14.1180","9.4120","75.5800","277.7564"
"56.6400","14.1384","14.1384","9.4256","75.5732","277.7314"
"56.7200","14.1591","14.1591","9.4394","75.5672","277.7093"
"56.8000","14.1787","14.1787","9.4525","75.5561","277.6685"
"56.8800","14.1976","14.1976","9.4650","75.5391","277.6063"
"56.9600","14.2178","14.2178","9.4785","75.5346","277.5895"
"57.0400","14.2380","14.2380","9.4920","75.5262","277.5589"
"57.1200","14.2579","14.2579","9.5053","75.5174","277.5263"
"57.2000","14.2788","14.2788","9.5192","75.5159","277.5210"
"57.2800","14.2985","14.2985","9.5323","75.5009","277.4657"
"57.3600","14.3189","14.3189","9.5459","75.4935","277.4384"
"57.4400","14.3391","14.3391","9.5594","75.4796","277.3875"
"57.5200","14.3575","14.3575","9.5717","75.4620","277.3228"
"57.6000","14.3779","14.3779","9.5853","75.4504","277.2803"
"57.6800","14.3972","14.3972","9.5981","75.4335","277.2182"
"57.7600","14.4175","14.4175","9.6117","75.4223","277.1768"
"57.8400","14.4387","14.4387","9.6258","75.4153","277.1511"
"57.9200","14.4588","14.4588","9.6392","75.3973","277.0850"
"58.0000","14.4782","14.4782","9.6521","75.3776","277.0126"
"58.0800","14.4982","14.4982","9.6655","75.3609","276.9512"
"58.1600","14.5174","14.5174","9.6782","75.3449","276.8926"
"58.2400","14.5384","14.5384","9.6923","75.3362","276.8604"
"58.3200","14.5579","14.5579","9.7053","75.3101","276.7646"
"58.4000","14.5786","14.5786","9.7191","75.2938","276.7048"
"58.4800","14.5989","14.5989","9.7326","75.2738","276.6314"
"58.5600","14.6184","14.6184","9.7456","75.2481","276.5367"
"58.6400","14.6383","14.6383","9.7589","75.2246","276.4505"
"58.7200","14.6584","14.6584","9.7722","75.1968","276.3484"
"58.8000","14.6780","14.6780","9.7853","75.1753","276.2692"
"58.8800","14.6980","14.6980","9.7987","75.1521","276.1838"
"58.9600","14.7168","14.7168","9.8112","75.1205","276.0677"
"59.0400","14.7379","14.7379","9.8253","75.1074","276.0199"
"59.1200","14.7591","14.7591","9.8394","75.0884","275.9497"
"59.2000","14.7783","14.7783","9.8522","75.0605","275.8472"
"59.2800","14.7984","14.7984","9.8656","75.0365","275.7591"
"59.3600","14.8175","14.8175","9.8783","75.0040","275.6399"
"59.4400","14.8381","14.8381","9.8921","74.9829","275.5622"
"59.5200","14.8585","14.8585","9.9057","74.9580","275.4705"
"59.6000","14.8777","14.8777","9.9185","74.9296","275.3663"
"59.6800","14.8983","14.8983","9.9322","74.9040","275.2724"
"59.7600","14.9190","14.9190","9.9460","74.8766","275.1715"
"59.8400","14.9385","14.9385","9.9590","74.8391","275.0338"
"59.9200","14.9586","14.9586","9.9724","74.8074","274.9171"
"60.0000","14.9772","14.9772","9.9848","74.7660","274.7652"
"60.0800","14.9978","14.9978","9.9985","74.7387","274.6649"
"60.0900","15.0002","15.0002","10.0001","74.7363","274.6557"