File: data/instron_tests/metamaterial_samples/553_VERT_m1.is_comp_Exports/553_VERT_m1_5_1.csv
Sample text inputs : Sample No.,Sample choice input : Leading Direction,Sample choice input : Mode,Specimen choice input : Direction,Specimen properties : Height,Specimen properties : Thickness,Specimen properties : Width,Test : Rate 1
,,,,(mm),(mm),(mm),(mm/min)
"553","Vertical","Unimode","1","147.00","25.00","150.00","15.00"

Time,Displacement,Compressive displacement,Compressive strain (Displacement),Compressive stress,Force
(s),(mm),(mm),(%),(kPa),(N)
"0.0000","0.0000","0.0000","0.0000","-0.8105","-3.0393"
"0.0800","0.0014","0.0014","0.0010","-0.8092","-3.0345"
"0.1600","0.0117","0.0117","0.0078","-0.7857","-2.9466"
"0.2400","0.0311","0.0311","0.0208","-0.7478","-2.8044"
"0.3200","0.0511","0.0511","0.0341","-0.7062","-2.6482"
"0.4000","0.0708","0.0708","0.0472","-0.6710","-2.5161"
"0.4800","0.0897","0.0897","0.0598","-0.6324","-2.3714"
"0.5600","0.1106","0.1106","0.0737","-0.5926","-2.2223"
"0.6400","0.1304","0.1304","0.0869","-0.5612","-2.1043"
"0.7200","0.1511","0.1511","0.1007","-0.5223","-1.9586"
"0.8000","0.1721","0.1721","0.1147","-0.4869","-1.8258"
"0.8800","0.1919","0.1919","0.1279","-0.4534","-1.7002"
"0.9600","0.2122","0.2122","0.1415","-0.4188","-1.5704"
"1.0400","0.2312","0.2312","0.1541","-0.3868","-1.4504"
"1.1200","0.2510","0.2510","0.1673","-0.3549","-1.3310"
"1.2000","0.2712","0.2712","0.1808","-0.3235","-1.2130"
"1.2800","0.2910","0.2910","0.1940","-0.2921","-1.0952"
"1.3600","0.3118","0.3118","0.2079","-0.2579","-0.9672"
"1.4400","0.3327","0.3327","0.2218","-0.2253","-0.8449"
"1.5200","0.3516","0.3516","0.2344","-0.1939","-0.7270"
"1.6000","0.3719","0.3719","0.2479","-0.1586","-0.5949"
"1.6800","0.3911","0.3911","0.2607","-0.1315","-0.4930"
"1.7600","0.4118","0.4118","0.2745","-0.0978","-0.3666"
"1.8400","0.4316","0.4316","0.2877","-0.0697","-0.2612"
"1.9200","0.4503","0.4503","0.3002","-0.0398","-0.1494"
"2.0000","0.4712","0.4712","0.3142","-0.0079","-0.0297"
"2.0800","0.4925","0.4925","0.3283","0.0266","0.0998"
"2.1600","0.5119","0.5119","0.3413","0.0596","0.2233"
"2.2400","0.5317","0.5317","0.3545","0.0920","0.3452"
"2.3200","0.5503","0.5503","0.3668","0.1205","0.4520"
"2.4000","0.5714","0.5714","0.3809","0.1540","0.5774"
"2.4800","0.5924","0.5924","0.3949","0.1907","0.7152"
"2.5600","0.6116","0.6116","0.4077","0.2252","0.8444"
"2.6400","0.6318","0.6318","0.4212","0.2602","0.9758"
"2.7200","0.6516","0.6516","0.4344","0.2909","1.0907"
"2.8000","0.6726","0.6726","0.4484","0.3263","1.2237"
"2.8800","0.6922","0.6922","0.4614","0.3602","1.3508"
"2.9600","0.7110","0.7110","0.4740","0.3952","1.4819"
"3.0400","0.7309","0.7309","0.4872","0.4258","1.5967"
"3.1200","0.7508","0.7508","0.5006","0.4641","1.7404"
"3.2000","0.7710","0.7710","0.5140","0.5016","1.8812"
"3.2800","0.7925","0.7925","0.5283","0.5399","2.0248"
"3.3600","0.8116","0.8116","0.5411","0.5680","2.1301"
"3.4400","0.8322","0.8322","0.5548","0.6052","2.2696"
"3.5200","0.8515","0.8515","0.5676","0.6396","2.3984"
"3.6000","0.8711","0.8711","0.5807","0.6778","2.5418"
"3.6800","0.8918","0.8918","0.5945","0.7166","2.6873"
"3.7600","0.9114","0.9114","0.6076","0.7485","2.8069"
"3.8400","0.9316","0.9316","0.6211","0.7828","2.9354"
"3.9200","0.9526","0.9526","0.6351","0.8152","3.0570"
"4.0000","0.9720","0.9720","0.6480","0.8515","3.1930"
"4.0800","0.9926","0.9926","0.6617","0.8849","3.3183"
"4.1600","1.0116","1.0116","0.6744","0.9199","3.4495"
"4.2400","1.0308","1.0308","0.6872","0.9529","3.5735"
"4.3200","1.0512","1.0512","0.7008","0.9889","3.7082"
"4.4000","1.0706","1.0706","0.7138","1.0249","3.8434"
"4.4800","1.0919","1.0919","0.7279","1.0624","3.9842"
"4.5600","1.1125","1.1125","0.7417","1.1000","4.1249"
"4.6400","1.1315","1.1315","0.7543","1.1380","4.2676"
"4.7200","1.1512","1.1512","0.7675","1.1741","4.4027"
"4.8000","1.1710","1.1710","0.7807","1.2114","4.5429"
"4.8800","1.1913","1.1913","0.7942","1.2480","4.6799"
"4.9600","1.2121","1.2121","0.8081","1.2832","4.8121"
"5.0400","1.2306","1.2306","0.8204","1.3190","4.9461"
"5.1200","1.2521","1.2521","0.8347","1.3597","5.0990"
"5.2000","1.2723","1.2723","0.8482","1.3996","5.2486"
"5.2800","1.2924","1.2924","0.8616","1.4354","5.3828"
"5.3600","1.3112","1.3112","0.8741","1.4714","5.5177"
"5.4400","1.3310","1.3310","0.8873","1.5048","5.6429"
"5.5200","1.3513","1.3513","0.9009","1.5418","5.7817"
"5.6000","1.3718","1.3718","0.9145","1.5814","5.9301"
"5.6800","1.3904","1.3904","0.9270","1.6172","6.0646"
"5.7600","1.4120","1.4120","0.9413","1.6588","6.2206"
"5.8400","1.4318","1.4318","0.9545","1.6959","6.3596"
"5.9200","1.4523","1.4523","0.9682","1.7324","6.4966"
"6.0000","1.4722","1.4722","0.9815","1.7707","6.6401"
"6.0800","1.4910","1.4910","0.9940","1.8083","6.7811"
"6.1600","1.5114","1.5114","1.0076","1.8473","6.9272"
"6.2400","1.5313","1.5313","1.0209","1.8826","7.0599"
"6.3200","1.5511","1.5511","1.0341","1.9216","7.2060"
"6.4000","1.5727","1.5727","1.0485","1.9628","7.3605"
"6.4800","1.5924","1.5924","1.0616","2.0015","7.5056"
"6.5600","1.6125","1.6125","1.0750","2.0386","7.6446"
"6.6400","1.6323","1.6323","1.0882","2.0760","7.7849"
"6.7200","1.6505","1.6505","1.1003","2.1136","7.9261"
"6.8000","1.6715","1.6715","1.1143","2.1519","8.0695"
"6.8800","1.6910","1.6910","1.1273","2.1908","8.2154"
"6.9600","1.7116","1.7116","1.1411","2.2246","8.3421"
"7.0400","1.7319","1.7319","1.1546","2.2674","8.5026"
"7.1200","1.7515","1.7515","1.1677","2.3068","8.6505"
"7.2000","1.7718","1.7718","1.1812","2.3438","8.7892"
"7.2800","1.7920","1.7920","1.1947","2.3821","8.9329"
"7.3600","1.8111","1.8111","1.2074","2.4221","9.0830"
"7.4400","1.8316","1.8316","1.2211","2.4634","9.2378"
"7.5200","1.8506","1.8506","1.2338","2.4964","9.3614"
"7.6000","1.8719","1.8719","1.2479","2.5381","9.5177"
"7.6800","1.8929","1.8929","1.2619","2.5772","9.6647"
"7.7600","1.9117","1.9117","1.2744","2.6135","9.8004"
"7.8400","1.9312","1.9312","1.2874","2.6531","9.9490"
"7.9200","1.9515","1.9515","1.3010","2.6903","10.0885"
"8.0000","1.9711","1.9711","1.3141","2.7283","10.2310"
"8.0800","1.9915","1.9915","1.3277","2.7714","10.3926"
"8.1600","2.0103","2.0103","1.3402","2.8088","10.5331"
"8.2400","2.0318","2.0318","1.3545","2.8508","10.6904"
"8.3200","2.0522","2.0522","1.3681","2.8887","10.8326"
"8.4000","2.0717","2.0717","1.3811","2.9268","10.9755"
"8.4800","2.0918","2.0918","1.3945","2.9675","11.1281"
"8.5600","2.1113","2.1113","1.4075","3.0091","11.2843"
"8.6400","2.1322","2.1322","1.4215","3.0492","11.4347"
"8.7200","2.1517","2.1517","1.4345","3.0875","11.5779"
"8.8000","2.1709","2.1709","1.4472","3.1241","11.7154"
"8.8800","2.1921","2.1921","1.4614","3.1707","11.8900"
"8.9600","2.2125","2.2125","1.4750","3.2094","12.0354"
"9.0400","2.2321","2.2321","1.4880","3.2476","12.1786"
"9.1200","2.2517","2.2517","1.5011","3.2846","12.3173"
"9.2000","2.2708","2.2708","1.5139","3.3253","12.4700"
"9.2800","2.2918","2.2918","1.5279","3.3669","12.6258"
"9.3600","2.3114","2.3114","1.5409","3.4038","12.7642"
"9.4400","2.3305","2.3305","1.5537","3.4442","12.9159"
"9.5200","2.3511","2.3511","1.5674","3.4869","13.0758"
"9.6000","2.3716","2.3716","1.5811","3.5249","13.2182"
"9.6800","2.3922","2.3922","1.5948","3.5664","13.3741"
"9.7600","2.4125","2.4125","1.6083","3.6053","13.5200"
"9.8400","2.4306","2.4306","1.6204","3.6438","13.6642"
"9.9200","2.4511","2.4511","1.6341","3.6846","13.8174"
"10.0000","2.4709","2.4709","1.6473","3.7207","13.9525"
"10.0800","2.4917","2.4917","1.6612","3.7637","14.1138"
"10.1600","2.5130","2.5130","1.6753","3.8049","14.2685"
"10.2400","2.5319","2.5319","1.6880","3.8440","14.4148"
"10.3200","2.5518","2.5518","1.7012","3.8836","14.5634"
"10.4000","2.5717","2.5717","1.7145","3.9226","14.7097"
"10.4800","2.5911","2.5911","1.7274","3.9659","14.8723"
"10.5600","2.6113","2.6113","1.7409","4.0064","15.0238"
"10.6400","2.6303","2.6303","1.7536","4.0423","15.1588"
"10.7200","2.6511","2.6511","1.7674","4.0846","15.3171"
"10.8000","2.6731","2.6731","1.7821","4.1262","15.4732"
"10.8800","2.6920","2.6920","1.7947","4.1671","15.6265"
"10.9600","2.7122","2.7122","1.8081","4.2079","15.7797"
"11.0400","2.7312","2.7312","1.8208","4.2475","15.9282"
"11.1200","2.7509","2.7509","1.8339","4.2864","16.0740"
"11.2000","2.7712","2.7712","1.8475","4.3302","16.2382"
"11.2800","2.7914","2.7914","1.8609","4.3690","16.3839"
"11.3600","2.8117","2.8117","1.8745","4.4091","16.5343"
"11.4400","2.8325","2.8325","1.8883","4.4554","16.7077"
"11.5200","2.8516","2.8516","1.9011","4.4951","16.8567"
"11.6000","2.8720","2.8720","1.9146","4.5361","17.0104"
"11.6800","2.8910","2.8910","1.9274","4.5732","17.1493"
"11.7600","2.9118","2.9118","1.9412","4.6144","17.3040"
"11.8400","2.9314","2.9314","1.9543","4.6565","17.4620"
"11.9200","2.9502","2.9502","1.9668","4.6948","17.6054"
"12.0000","2.9715","2.9715","1.9810","4.7400","17.7749"
"12.0800","2.9923","2.9923","1.9949","4.7849","17.9435"
"12.1600","3.0118","3.0118","2.0079","4.8240","18.0899"
"12.2400","3.0317","3.0317","2.0211","4.8640","18.2398"
"12.3200","3.0507","3.0507","2.0338","4.9000","18.3748"
"12.4000","3.0719","3.0719","2.0479","4.9420","18.5327"
"12.4800","3.0919","3.0919","2.0612","4.9851","18.6939"
"12.5600","3.1111","3.1111","2.0741","5.0268","18.8506"
"12.6400","3.1319","3.1319","2.0880","5.0720","19.0200"
"12.7200","3.1518","3.1518","2.1012","5.1123","19.1711"
"12.8000","3.1723","3.1723","2.1149","5.1548","19.3305"
"12.8800","3.1920","3.1920","2.1280","5.1918","19.4691"
"12.9600","3.2109","3.2109","2.1406","5.2339","19.6272"
"13.0400","3.2308","3.2308","2.1539","5.2732","19.7747"
"13.1200","3.2509","3.2509","2.1673","5.3132","19.9244"
"13.2000","3.2711","3.2711","2.1807","5.3560","20.0850"
"13.2800","3.2924","3.2924","2.1949","5.4009","20.2533"
"13.3600","3.3117","3.3117","2.2078","5.4408","20.4029"
"13.4400","3.3320","3.3320","2.2213","5.4792","20.5469"
"13.5200","3.3513","3.3513","2.2342","5.5227","20.7102"
"13.6000","3.3708","3.3708","2.2472","5.5633","20.8623"
"13.6800","3.3915","3.3915","2.2610","5.6061","21.0228"
"13.7600","3.4114","3.4114","2.2743","5.6483","21.1810"
"13.8400","3.4316","3.4316","2.2878","5.6900","21.3375"
"13.9200","3.4527","3.4527","2.3018","5.7337","21.5014"
"14.0000","3.4720","3.4720","2.3147","5.7743","21.6536"
"14.0800","3.4921","3.4921","2.3281","5.8168","21.8129"
"14.1600","3.5114","3.5114","2.3410","5.8575","21.9655"
"14.2400","3.5308","3.5308","2.3539","5.8960","22.1100"
"14.3200","3.5513","3.5513","2.3675","5.9380","22.2674"
"14.4000","3.5704","3.5704","2.3803","5.9772","22.4146"
"14.4800","3.5920","3.5920","2.3946","6.0223","22.5837"
"14.5600","3.6126","3.6126","2.4084","6.0653","22.7448"
"14.6400","3.6315","3.6315","2.4210","6.1058","22.8968"
"14.7200","3.6514","3.6514","2.4342","6.1481","23.0555"
"14.8000","3.6712","3.6712","2.4474","6.1884","23.2065"
"14.8800","3.6915","3.6915","2.4610","6.2328","23.3731"
"14.9600","3.7120","3.7120","2.4747","6.2746","23.5296"
"15.0400","3.7306","3.7306","2.4871","6.3153","23.6822"
"15.1200","3.7519","3.7519","2.5013","6.3571","23.8392"
"15.2000","3.7724","3.7724","2.5150","6.4025","24.0092"
"15.2800","3.7926","3.7926","2.5284","6.4429","24.1608"
"15.3600","3.8115","3.8115","2.5410","6.4835","24.3132"
"15.4400","3.8306","3.8306","2.5537","6.5211","24.4541"
"15.5200","3.8512","3.8512","2.5675","6.5639","24.6147"
"15.6000","3.8719","3.8719","2.5812","6.6079","24.7797"
"15.6800","3.8906","3.8906","2.5937","6.6490","24.9339"
"15.7600","3.9119","3.9119","2.6079","6.6953","25.1075"
"15.8400","3.9317","3.9317","2.6211","6.7363","25.2610"
"15.9200","3.9522","3.9522","2.6348","6.7802","25.4258"
"16.0000","3.9721","3.9721","2.6480","6.8230","25.5863"
"16.0800","3.9913","3.9913","2.6609","6.8602","25.7256"
"16.1600","4.0115","4.0115","2.6743","6.9048","25.8928"
"16.2400","4.0311","4.0311","2.6874","6.9447","26.0425"
"16.3200","4.0510","4.0510","2.7007","6.9893","26.2099"
"16.4000","4.0724","4.0724","2.7150","7.0381","26.3927"
"16.4800","4.0922","4.0922","2.7281","7.0765","26.5370"
"16.5600","4.1124","4.1124","2.7416","7.1193","26.6972"
"16.6400","4.1319","4.1319","2.7546","7.1582","26.8433"
"16.7200","4.1505","4.1505","2.7670","7.1990","26.9963"
"16.8000","4.1714","4.1714","2.7809","7.2437","27.1637"
"16.8800","4.1909","4.1909","2.7939","7.2830","27.3114"
"16.9600","4.2115","4.2115","2.8077","7.3266","27.4749"
"17.0400","4.2319","4.2319","2.8212","7.3707","27.6401"
"17.1200","4.2516","4.2516","2.8344","7.4122","27.7957"
"17.2000","4.2717","4.2717","2.8478","7.4561","27.9602"
"17.2800","4.2924","4.2924","2.8616","7.5018","28.1318"
"17.3600","4.3114","4.3114","2.8742","7.5425","28.2843"
"17.4400","4.3312","4.3312","2.8875","7.5839","28.4397"
"17.5200","4.3503","4.3503","2.9002","7.6220","28.5824"
"17.6000","4.3722","4.3722","2.9148","7.6703","28.7636"
"17.6800","4.3930","4.3930","2.9287","7.7151","28.9316"
"17.7600","4.4119","4.4119","2.9413","7.7581","29.0929"
"17.8400","4.4319","4.4319","2.9546","7.7992","29.2469"
"17.9200","4.4514","4.4514","2.9676","7.8382","29.3934"
"18.0000","4.4712","4.4712","2.9808","7.8826","29.5596"
"18.0800","4.4917","4.4917","2.9945","7.9255","29.7206"
"18.1600","4.5108","4.5108","3.0072","7.9659","29.8721"
"18.2400","4.5319","4.5319","3.0213","8.0108","30.0405"
"18.3200","4.5519","4.5519","3.0346","8.0498","30.1869"
"18.4000","4.5714","4.5714","3.0476","8.0944","30.3540"
"18.4800","4.5920","4.5920","3.0613","8.1412","30.5296"
"18.5600","4.6111","4.6111","3.0741","8.1816","30.6811"
"18.6400","4.6315","4.6315","3.0876","8.2219","30.8320"
"18.7200","4.6516","4.6516","3.1010","8.2650","30.9938"
"18.8000","4.6711","4.6711","3.1141","8.3095","31.1605"
"18.8800","4.6922","4.6922","3.1281","8.3573","31.3400"
"18.9600","4.7127","4.7127","3.1418","8.4012","31.5044"
"19.0400","4.7322","4.7322","3.1548","8.4409","31.6534"
"19.1200","4.7518","4.7518","3.1679","8.4813","31.8049"
"19.2000","4.7710","4.7710","3.1807","8.5232","31.9618"
"19.2800","4.7917","4.7917","3.1945","8.5649","32.1185"
"19.3600","4.8110","4.8110","3.2073","8.6082","32.2807"
"19.4400","4.8306","4.8306","3.2204","8.6510","32.4414"
"19.5200","4.8512","4.8512","3.2341","8.6978","32.6167"
"19.6000","4.8718","4.8718","3.2479","8.7384","32.7691"
"19.6800","4.8921","4.8921","3.2614","8.7821","32.9330"
"19.7600","4.9124","4.9124","3.2750","8.8233","33.0874"
"19.8400","4.9307","4.9307","3.2872","8.8648","33.2432"
"19.9200","4.9511","4.9511","3.3007","8.9099","33.4123"
"20.0000","4.9710","4.9710","3.3140","8.9543","33.5786"
"20.0800","4.9917","4.9917","3.3278","8.9976","33.7409"
"20.1600","5.0127","5.0127","3.3418","9.0435","33.9132"
"20.2400","5.0321","5.0321","3.3547","9.0849","34.0685"
"20.3200","5.0517","5.0517","3.3678","9.1263","34.2237"
"20.4000","5.0716","5.0716","3.3811","9.1682","34.3806"
"20.4800","5.0915","5.0915","3.3943","9.2129","34.5484"
"20.5600","5.1112","5.1112","3.4074","9.2584","34.7188"
"20.6400","5.1307","5.1307","3.4204","9.2989","34.8707"
"20.7200","5.1512","5.1512","3.4341","9.3424","35.0341"
"20.8000","5.1723","5.1723","3.4482","9.3867","35.2003"
"20.8800","5.1914","5.1914","3.4609","9.4335","35.3754"
"20.9600","5.2125","5.2125","3.4750","9.4773","35.5397"
"21.0400","5.2313","5.2313","3.4875","9.5155","35.6830"
"21.1200","5.2511","5.2511","3.5007","9.5593","35.8472"
"21.2000","5.2710","5.2710","3.5140","9.6017","36.0062"
"21.2800","5.2909","5.2909","3.5273","9.6456","36.1711"
"21.3600","5.3122","5.3122","3.5415","9.6922","36.3457"
"21.4400","5.3329","5.3329","3.5553","9.7366","36.5121"
"21.5200","5.3516","5.3516","3.5677","9.7797","36.6740"
"21.6000","5.3719","5.3719","3.5813","9.8253","36.8448"
"21.6800","5.3912","5.3912","3.5942","9.8643","36.9909"
"21.7600","5.4118","5.4118","3.6079","9.9088","37.1580"
"21.8400","5.4314","5.4314","3.6209","9.9530","37.3239"
"21.9200","5.4504","5.4504","3.6336","9.9943","37.4788"
"22.0000","5.4717","5.4717","3.6478","10.0404","37.6515"
"22.0800","5.4923","5.4923","3.6615","10.0887","37.8325"
"22.1600","5.5119","5.5119","3.6746","10.1266","37.9748"
"22.2400","5.5320","5.5320","3.6880","10.1730","38.1487"
"22.3200","5.5505","5.5505","3.7003","10.2130","38.2988"
"22.4000","5.5717","5.5717","3.7144","10.2588","38.4706"
"22.4800","5.5920","5.5920","3.7280","10.3046","38.6422"
"22.5600","5.6112","5.6112","3.7408","10.3471","38.8015"
"22.6400","5.6321","5.6321","3.7548","10.3926","38.9724"
"22.7200","5.6516","5.6516","3.7677","10.4334","39.1253"
"22.8000","5.6724","5.6724","3.7816","10.4796","39.2986"
"22.8800","5.6922","5.6922","3.7948","10.5229","39.4607"
"22.9600","5.7113","5.7113","3.8075","10.5673","39.6273"
"23.0400","5.7311","5.7311","3.8207","10.6103","39.7887"
"23.1200","5.7511","5.7511","3.8341","10.6538","39.9516"
"23.2000","5.7705","5.7705","3.8470","10.6980","40.1175"
"23.2800","5.7923","5.7923","3.8615","10.7464","40.2990"
"23.3600","5.8114","5.8114","3.8743","10.7875","40.4530"
"23.4400","5.8315","5.8315","3.8877","10.8311","40.6165"
"23.5200","5.8516","5.8516","3.9011","10.8748","40.7805"
"23.6000","5.8712","5.8712","3.9141","10.9196","40.9483"
"23.6800","5.8916","5.8916","3.9277","10.9666","41.1249"
"23.7600","5.9112","5.9112","3.9408","11.0077","41.2789"
"23.8400","5.9317","5.9317","3.9545","11.0521","41.4455"
"23.9200","5.9528","5.9528","3.9685","11.1020","41.6326"
"24.0000","5.9722","5.9722","3.9814","11.1477","41.8039"
"24.0800","5.9917","5.9917","3.9945","11.1876","41.9537"
"24.1600","6.0114","6.0114","4.0076","11.2301","42.1127"
"24.2400","6.0310","6.0310","4.0207","11.2737","42.2764"
"24.3200","6.0516","6.0516","4.0344","11.3215","42.4556"
"24.4000","6.0705","6.0705","4.0470","11.3619","42.6071"
"24.4800","6.0919","6.0919","4.0613","11.4084","42.7814"
"24.5600","6.1127","6.1127","4.0752","11.4564","42.9614"
"24.6400","6.1318","6.1318","4.0879","11.5001","43.1252"
"24.7200","6.1514","6.1514","4.1009","11.5421","43.2828"
"24.8000","6.1712","6.1712","4.1141","11.5856","43.4461"
"24.8800","6.1917","6.1917","4.1278","11.6328","43.6231"
"24.9600","6.2125","6.2125","4.1416","11.6770","43.7889"
"25.0400","6.2307","6.2307","4.1538","11.7195","43.9482"
"25.1200","6.2513","6.2513","4.1675","11.7644","44.1165"
"25.2000","6.2723","6.2723","4.1815","11.8143","44.3036"
"25.2800","6.2927","6.2927","4.1952","11.8605","44.4767"
"25.3600","6.3118","6.3118","4.2079","11.9036","44.6385"
"25.4400","6.3309","6.3309","4.2206","11.9449","44.7933"
"25.5200","6.3511","6.3511","4.2340","11.9889","44.9584"
"25.6000","6.3718","6.3718","4.2479","12.0373","45.1399"
"25.6800","6.3904","6.3904","4.2603","12.0755","45.2833"
"25.7600","6.4120","6.4120","4.2747","12.1280","45.4800"
"25.8400","6.4315","6.4315","4.2877","12.1691","45.6343"
"25.9200","6.4521","6.4521","4.3014","12.2183","45.8187"
"26.0000","6.4717","6.4717","4.3145","12.2636","45.9886"
"26.0800","6.4911","6.4911","4.3274","12.3038","46.1394"
"26.1600","6.5117","6.5117","4.3411","12.3519","46.3195"
"26.2400","6.5314","6.5314","4.3543","12.3970","46.4889"
"26.3200","6.5508","6.5508","4.3672","12.4419","46.6572"
"26.4000","6.5724","6.5724","4.3816","12.4943","46.8537"
"26.4800","6.5924","6.5924","4.3949","12.5365","47.0120"
"26.5600","6.6122","6.6122","4.4081","12.5804","47.1767"
"26.6400","6.6317","6.6317","4.4211","12.6210","47.3287"
"26.7200","6.6506","6.6506","4.4337","12.6690","47.5089"
"26.8000","6.6717","6.6717","4.4478","12.7171","47.6890"
"26.8800","6.6910","6.6910","4.4606","12.7611","47.8540"
"26.9600","6.7118","6.7118","4.4745","12.8066","48.0246"
"27.0400","6.7315","6.7315","4.4877","12.8502","48.1884"
"27.1200","6.7517","6.7517","4.5011","12.8972","48.3646"
"27.2000","6.7718","6.7718","4.5146","12.9412","48.5296"
"27.2800","6.7922","6.7922","4.5282","12.9871","48.7018"
"27.3600","6.8111","6.8111","4.5407","13.0299","48.8623"
"27.4400","6.8312","6.8312","4.5541","13.0760","49.0348"
"27.5200","6.8502","6.8502","4.5668","13.1176","49.1911"
"27.6000","6.8722","6.8722","4.5815","13.1708","49.3905"
"27.6800","6.8934","6.8934","4.5956","13.2188","49.5705"
"27.7600","6.9123","6.9123","4.6082","13.2625","49.7346"
"27.8400","6.9314","6.9314","4.6209","13.3047","49.8928"
"27.9200","6.9512","6.9512","4.6341","13.3497","50.0614"
"28.0000","6.9710","6.9710","4.6473","13.3929","50.2234"
"28.0800","6.9916","6.9916","4.6610","13.4391","50.3967"
"28.1600","7.0104","7.0104","4.6736","13.4837","50.5639"
"28.2400","7.0315","7.0315","4.6877","13.5345","50.7545"
"28.3200","7.0520","7.0520","4.7013","13.5829","50.9360"
"28.4000","7.0717","7.0717","4.7144","13.6276","51.1034"
"28.4800","7.0916","7.0916","4.7277","13.6714","51.2677"
"28.5600","7.1107","7.1107","4.7405","13.7138","51.4266"
"28.6400","7.1322","7.1322","4.7548","13.7618","51.6068"
"28.7200","7.1518","7.1518","4.7679","13.8059","51.7722"
"28.8000","7.1711","7.1711","4.7807","13.8528","51.9480"
"28.8800","7.1920","7.1920","4.7946","13.9032","52.1368"
"28.9600","7.2126","7.2126","4.8084","13.9511","52.3167"
"29.0400","7.2324","7.2324","4.8216","13.9970","52.4886"
"29.1200","7.2521","7.2521","4.8347","14.0425","52.6593"
"29.2000","7.2710","7.2710","4.8473","14.0842","52.8156"
"29.2800","7.2919","7.2919","4.8613","14.1330","52.9989"
"29.3600","7.3112","7.3112","4.8741","14.1774","53.1653"
"29.4400","7.3307","7.3307","4.8871","14.2219","53.3323"
"29.5200","7.3513","7.3513","4.9008","14.2739","53.5270"
"29.6000","7.3720","7.3720","4.9147","14.3202","53.7009"
"29.6800","7.3924","7.3924","4.9282","14.3652","53.8695"
"29.7600","7.4125","7.4125","4.9417","14.4111","54.0416"
"29.8400","7.4304","7.4304","4.9536","14.4540","54.2024"
"29.9200","7.4509","7.4509","4.9673","14.5017","54.3815"
"30.0000","7.4714","7.4714","4.9809","14.5487","54.5575"
"30.0800","7.4921","7.4921","4.9947","14.5971","54.7393"
"30.1600","7.5129","7.5129","5.0086","14.6452","54.9195"
"30.2400","7.5321","7.5321","5.0214","14.6880","55.0801"
"30.3200","7.5516","7.5516","5.0344","14.7348","55.2556"
"30.4000","7.5717","7.5717","5.0478","14.7810","55.4289"
"30.4800","7.5913","7.5913","5.0609","14.8270","55.6014"
"30.5600","7.6115","7.6115","5.0744","14.8771","55.7891"
"30.6400","7.6306","7.6306","5.0871","14.9179","55.9422"
"30.7200","7.6511","7.6511","5.1008","14.9659","56.1221"
"30.8000","7.6723","7.6723","5.1149","15.0149","56.3057"
"30.8800","7.6913","7.6913","5.1276","15.0625","56.4845"
"30.9600","7.7120","7.7120","5.1414","15.1101","56.6628"
"31.0400","7.7309","7.7309","5.1539","15.1525","56.8221"
"31.1200","7.7513","7.7513","5.1676","15.1986","56.9948"
"31.2000","7.7715","7.7715","5.1810","15.2471","57.1765"
"31.2800","7.7911","7.7911","5.1941","15.2936","57.3509"
"31.3600","7.8118","7.8118","5.2079","15.3423","57.5338"
"31.4400","7.8328","7.8328","5.2219","15.3918","57.7193"
"31.5200","7.8518","7.8518","5.2345","15.4366","57.8874"
"31.6000","7.8719","7.8719","5.2479","15.4838","58.0644"
"31.6800","7.8911","7.8911","5.2608","15.5256","58.2209"
"31.7600","7.9120","7.9120","5.2747","15.5734","58.4002"
"31.8400","7.9314","7.9314","5.2876","15.6209","58.5784"
"31.9200","7.9502","7.9502","5.3001","15.6642","58.7409"
"32.0000","7.9717","7.9717","5.3145","15.7177","58.9413"
"32.0800","7.9925","7.9925","5.3283","15.7680","59.1301"
"32.1600","8.0121","8.0121","5.3414","15.8124","59.2967"
"32.2400","8.0318","8.0318","5.3545","15.8582","59.4684"
"32.3200","8.0507","8.0507","5.3671","15.8999","59.6244"
"32.4000","8.0712","8.0712","5.3808","15.9496","59.8111"
"32.4800","8.0920","8.0920","5.3946","15.9978","59.9916"
"32.5600","8.1114","8.1114","5.4076","16.0454","60.1704"
"32.6400","8.1321","8.1321","5.4214","16.0950","60.3564"
"32.7200","8.1517","8.1517","5.4344","16.1416","60.5312"
"32.8000","8.1722","8.1722","5.4481","16.1886","60.7071"
"32.8800","8.1918","8.1918","5.4612","16.2328","60.8731"
"32.9600","8.2110","8.2110","5.4740","16.2797","61.0487"
"33.0400","8.2311","8.2311","5.4874","16.3275","61.2281"
"33.1200","8.2511","8.2511","5.5007","16.3725","61.3968"
"33.2000","8.2705","8.2705","5.5137","16.4196","61.5737"
"33.2800","8.2918","8.2918","5.5279","16.4703","61.7635"
"33.3600","8.3116","8.3116","5.5411","16.5172","61.9395"
"33.4400","8.3323","8.3323","5.5549","16.5666","62.1248"
"33.5200","8.3514","8.3514","5.5676","16.6108","62.2904"
"33.6000","8.3709","8.3709","5.5806","16.6572","62.4644"
"33.6800","8.3911","8.3911","5.5941","16.7068","62.6505"
"33.7600","8.4111","8.4111","5.6074","16.7543","62.8287"
"33.8400","8.4316","8.4316","5.6211","16.8018","63.0068"
"33.9200","8.4527","8.4527","5.6351","16.8512","63.1922"
"34.0000","8.4720","8.4720","5.6480","16.8994","63.3727"
"34.0800","8.4925","8.4925","5.6617","16.9496","63.5610"
"34.1600","8.5115","8.5115","5.6743","16.9919","63.7196"
"34.2400","8.5309","8.5309","5.6873","17.0394","63.8977"
"34.3200","8.5516","8.5516","5.7010","17.0904","64.0892"
"34.4000","8.5707","8.5707","5.7138","17.1368","64.2631"
"34.4800","8.5920","8.5920","5.7280","17.1871","64.4517"
"34.5600","8.6126","8.6126","5.7417","17.2367","64.6378"
"34.6400","8.6316","8.6316","5.7544","17.2835","64.8132"
"34.7200","8.6511","8.6511","5.7674","17.3270","64.9763"
"34.8000","8.6711","8.6711","5.7808","17.3757","65.1587"
"34.8800","8.6913","8.6913","5.7942","17.4243","65.3412"
"34.9600","8.7122","8.7122","5.8081","17.4775","65.5408"
"35.0400","8.7306","8.7306","5.8204","17.5218","65.7066"
"35.1200","8.7521","8.7521","5.8347","17.5782","65.9183"
"35.2000","8.7723","8.7723","5.8482","17.6226","66.0849"
"35.2800","8.7926","8.7926","5.8617","17.6711","66.2666"
"35.3600","8.8116","8.8116","5.8744","17.7169","66.4385"
"35.4400","8.8310","8.8310","5.8874","17.7627","66.6101"
"35.5200","8.8512","8.8512","5.9008","17.8107","66.7902"
"35.6000","8.8717","8.8717","5.9145","17.8595","66.9730"
"35.6800","8.8904","8.8904","5.9269","17.9075","67.1532"
"35.7600","8.9119","8.9119","5.9413","17.9622","67.3582"
"35.8400","8.9313","8.9313","5.9542","18.0051","67.5191"
"35.9200","8.9518","8.9518","5.9679","18.0559","67.7095"
"36.0000","8.9719","8.9719","5.9812","18.1023","67.8837"
"36.0800","8.9910","8.9910","5.9940","18.1504","68.0641"
"36.1600","9.0116","9.0116","6.0078","18.1998","68.2491"
"36.2400","9.0312","9.0312","6.0208","18.2472","68.4271"
"36.3200","9.0512","9.0512","6.0341","18.2974","68.6151"
"36.4000","9.0728","9.0728","6.0485","18.3517","68.8190"
"36.4800","9.0923","9.0923","6.0615","18.3986","68.9949"
"36.5600","9.1123","9.1123","6.0749","18.4446","69.1671"
"36.6400","9.1318","9.1318","6.0879","18.4926","69.3472"
"36.7200","9.1504","9.1504","6.1002","18.5398","69.5242"
"36.8000","9.1716","9.1716","6.1144","18.5914","69.7179"
"36.8800","9.1909","9.1909","6.1273","18.6385","69.8944"
"36.9600","9.2116","9.2116","6.1410","18.6896","70.0862"
"37.0400","9.2320","9.2320","6.1547","18.7407","70.2777"
"37.1200","9.2518","9.2518","6.1679","18.7889","70.4583"
"37.2000","9.2718","9.2718","6.1812","18.8391","70.6467"
"37.2800","9.2921","9.2921","6.1948","18.8879","70.8296"
"37.3600","9.3112","9.3112","6.2075","18.9350","71.0061"
"37.4400","9.3314","9.3314","6.2209","18.9840","71.1900"
"37.5200","9.3502","9.3502","6.2335","19.0303","71.3634"
"37.6000","9.3723","9.3723","6.2482","19.0850","71.5686"
"37.6800","9.3930","9.3930","6.2620","19.1361","71.7605"
"37.7600","9.4124","9.4124","6.2749","19.1841","71.9405"
"37.8400","9.4316","9.4316","6.2877","19.2317","72.1190"
"37.9200","9.4511","9.4511","6.3008","19.2785","72.2945"
"38.0000","9.4710","9.4710","6.3140","19.3278","72.4791"
"38.0800","9.4915","9.4915","6.3277","19.3794","72.6727"
"38.1600","9.5104","9.5104","6.3403","19.4253","72.8449"
"38.2400","9.5314","9.5314","6.3542","19.4770","73.0388"
"38.3200","9.5522","9.5522","6.3681","19.5300","73.2374"
"38.4000","9.5718","9.5718","6.3812","19.5799","73.4245"
"38.4800","9.5921","9.5921","6.3947","19.6315","73.6181"
"38.5600","9.6107","9.6107","6.4071","19.6761","73.7856"
"38.6400","9.6318","9.6318","6.4212","19.7286","73.9823"
"38.7200","9.6513","9.6513","6.4342","19.7752","74.1571"
"38.8000","9.6710","9.6710","6.4473","19.8278","74.3544"
"38.8800","9.6924","9.6924","6.4616","19.8827","74.5601"
"38.9600","9.7124","9.7124","6.4749","19.9301","74.7377"
"39.0400","9.7320","9.7320","6.4880","19.9782","74.9183"
"39.1200","9.7523","9.7523","6.5015","20.0281","75.1053"
"39.2000","9.7709","9.7709","6.5140","20.0741","75.2777"
"39.2800","9.7917","9.7917","6.5278","20.1266","75.4746"
"39.3600","9.8111","9.8111","6.5407","20.1758","75.6594"
"39.4400","9.8308","9.8308","6.5539","20.2260","75.8473"
"39.5200","9.8509","9.8509","6.5673","20.2794","76.0478"
"39.6000","9.8719","9.8719","6.5813","20.3296","76.2358"
"39.6800","9.8923","9.8923","6.5949","20.3835","76.4383"
"39.7600","9.9128","9.9128","6.6085","20.4321","76.6204"
"39.8400","9.9307","9.9307","6.6205","20.4803","76.8011"
"39.9200","9.9510","9.9510","6.6340","20.5253","76.9698"
"40.0000","9.9711","9.9711","6.6474","20.5798","77.1743"
"40.0800","9.9920","9.9920","6.6613","20.6326","77.3722"
"40.1600","10.0132","10.0132","6.6755","20.6884","77.5813"
"40.2400","10.0319","10.0319","6.6879","20.7343","77.7538"
"40.3200","10.0519","10.0519","6.7013","20.7843","77.9412"
"40.4000","10.0716","10.0716","6.7144","20.8361","78.1352"
"40.4800","10.0913","10.0913","6.7275","20.8845","78.3167"
"40.5600","10.1112","10.1112","6.7408","20.9351","78.5068"
"40.6400","10.1305","10.1305","6.7537","20.9810","78.6786"
"40.7200","10.1511","10.1511","6.7674","21.0357","78.8839"
"40.8000","10.1722","10.1722","6.7815","21.0893","79.0850"
"40.8800","10.1915","10.1915","6.7943","21.1393","79.2724"
"40.9600","10.2126","10.2126","6.8084","21.1960","79.4849"
"41.0400","10.2308","10.2308","6.8205","21.2379","79.6419"
"41.1200","10.2507","10.2507","6.8338","21.2896","79.8362"
"41.2000","10.2712","10.2712","6.8475","21.3446","80.0421"
"41.2800","10.2912","10.2912","6.8608","21.3932","80.2245"
"41.3600","10.3118","10.3118","6.8745","21.4457","80.4213"
"41.4400","10.3325","10.3325","6.8883","21.4984","80.6191"
"41.5200","10.3516","10.3516","6.9011","21.5503","80.8138"
"41.6000","10.3720","10.3720","6.9147","21.6033","81.0122"
"41.6800","10.3911","10.3911","6.9274","21.6529","81.1982"
"41.7600","10.4116","10.4116","6.9411","21.7045","81.3917"
"41.8400","10.4315","10.4315","6.9543","21.7556","81.5834"
"41.9200","10.4504","10.4504","6.9669","21.8050","81.7686"
"42.0000","10.4718","10.4718","6.9812","21.8630","81.9864"
"42.0800","10.4924","10.4924","6.9950","21.9153","82.1823"
"42.1600","10.5122","10.5122","7.0082","21.9650","82.3689"
"42.2400","10.5318","10.5318","7.0212","22.0169","82.5635"
"42.3200","10.5506","10.5506","7.0337","22.0628","82.7355"
"42.4000","10.5715","10.5715","7.0477","22.1178","82.9419"
"42.4800","10.5920","10.5920","7.0613","22.1722","83.1457"
"42.5600","10.6113","10.6113","7.0742","22.2207","83.3278"
"42.6400","10.6322","10.6322","7.0881","22.2780","83.5424"
"42.7200","10.6518","10.6518","7.1012","22.3270","83.7263"
"42.8000","10.6724","10.6724","7.1149","22.3803","83.9263"
"42.8800","10.6921","10.6921","7.1281","22.4301","84.1128"
"42.9600","10.7112","10.7112","7.1408","22.4803","84.3010"
"43.0400","10.7312","10.7312","7.1541","22.5323","84.4962"
"43.1200","10.7512","10.7512","7.1675","22.5847","84.6927"
"43.2000","10.7706","10.7706","7.1804","22.6364","84.8864"
"43.2800","10.7924","10.7924","7.1949","22.6950","85.1064"
"43.3600","10.8116","10.8116","7.2077","22.7427","85.2850"
"43.4400","10.8321","10.8321","7.2214","22.7937","85.4762"
"43.5200","10.8511","10.8511","7.2341","22.8427","85.6603"
"43.6000","10.8713","10.8713","7.2476","22.8974","85.8653"
"43.6800","10.8915","10.8915","7.2610","22.9515","86.0681"
"43.7600","10.9116","10.9116","7.2744","23.0041","86.2652"
"43.8400","10.9316","10.9316","7.2877","23.0559","86.4595"
"43.9200","10.9527","10.9527","7.3018","23.1115","86.6679"
"44.0000","10.9715","10.9715","7.3144","23.1620","86.8576"
"44.0800","10.9925","10.9925","7.3283","23.2183","87.0685"
"44.1600","11.0118","11.0118","7.3412","23.2709","87.2657"
"44.2400","11.0307","11.0307","7.3538","23.3174","87.4403"
"44.3200","11.0512","11.0512","7.3675","23.3721","87.6453"
"44.4000","11.0704","11.0704","7.3803","23.4216","87.8309"
"44.4800","11.0919","11.0919","7.3946","23.4807","88.0527"
"44.5600","11.1125","11.1125","7.4084","23.5375","88.2655"
"44.6400","11.1319","11.1319","7.4213","23.5866","88.4496"
"44.7200","11.1511","11.1511","7.4341","23.6375","88.6406"
"44.8000","11.1708","11.1708","7.4472","23.6885","88.8318"
"44.8800","11.1915","11.1915","7.4610","23.7441","89.0404"
"44.9600","11.2124","11.2124","7.4749","23.7975","89.2408"
"45.0400","11.2307","11.2307","7.4871","23.8471","89.4265"
"45.1200","11.2520","11.2520","7.5013","23.9050","89.6439"
"45.2000","11.2722","11.2722","7.5148","23.9583","89.8437"
"45.2800","11.2924","11.2924","7.5283","24.0131","90.0491"
"45.3600","11.3116","11.3116","7.5411","24.0647","90.2427"
"45.4400","11.3310","11.3310","7.5540","24.1150","90.4311"
"45.5200","11.3513","11.3513","7.5676","24.1664","90.6241"
"45.6000","11.3717","11.3717","7.5812","24.2230","90.8363"
"45.6800","11.3905","11.3905","7.5937","24.2736","91.0260"
"45.7600","11.4118","11.4118","7.6079","24.3355","91.2581"
"45.8400","11.4317","11.4317","7.6211","24.3868","91.4504"
"45.9200","11.4518","11.4518","7.6345","24.4396","91.6485"
"46.0000","11.4723","11.4723","7.6482","24.4941","91.8529"
"46.0800","11.4910","11.4910","7.6606","24.5455","92.0456"
"46.1600","11.5112","11.5112","7.6741","24.5992","92.2472"
"46.2400","11.5313","11.5313","7.6875","24.6553","92.4574"
"46.3200","11.5512","11.5512","7.7008","24.7080","92.6552"
"46.4000","11.5725","11.5725","7.7150","24.7664","92.8742"
"46.4800","11.5924","11.5924","7.7283","24.8190","93.0714"
"46.5600","11.6123","11.6123","7.7415","24.8730","93.2736"
"46.6400","11.6319","11.6319","7.7546","24.9223","93.4585"
"46.7200","11.6505","11.6505","7.7670","24.9723","93.6463"
"46.8000","11.6716","11.6716","7.7810","25.0324","93.8714"
"46.8800","11.6908","11.6908","7.7939","25.0839","94.0646"
"46.9600","11.7117","11.7117","7.8078","25.1399","94.2748"
"47.0400","11.7319","11.7319","7.8213","25.1966","94.4872"
"47.1200","11.7520","11.7520","7.8346","25.2497","94.6865"
"47.2000","11.7717","11.7717","7.8478","25.3010","94.8789"
"47.2800","11.7919","11.7919","7.8613","25.3563","95.0862"
"47.3600","11.8112","11.8112","7.8741","25.4102","95.2881"
"47.4400","11.8320","11.8320","7.8880","25.4657","95.4964"
"47.5200","11.8504","11.8504","7.9003","25.5154","95.6827"
"47.6000","11.8718","11.8718","7.9145","25.5738","95.9017"
"47.6800","11.8931","11.8931","7.9287","25.6345","96.1293"
"47.7600","11.9127","11.9127","7.9418","25.6884","96.3316"
"47.8400","11.9315","11.9315","7.9543","25.7386","96.5197"
"47.9200","11.9513","11.9513","7.9675","25.7913","96.7173"
"48.0000","11.9710","11.9710","7.9807","25.8432","96.9122"
"48.0800","11.9915","11.9915","7.9943","25.9017","97.1314"
"48.1600","12.0106","12.0106","8.0071","25.9495","97.3105"
"48.2400","12.0311","12.0311","8.0208","26.0088","97.5328"
"48.3200","12.0516","12.0516","8.0344","26.0627","97.7353"
"48.4000","12.0720","12.0720","8.0480","26.1202","97.9509"
"48.4800","12.0922","12.0922","8.0614","26.1758","98.1593"
"48.5600","12.1109","12.1109","8.0739","26.2252","98.3446"
"48.6400","12.1317","12.1317","8.0878","26.2835","98.5631"
"48.7200","12.1520","12.1520","8.1013","26.3372","98.7646"
"48.8000","12.1711","12.1711","8.1141","26.3927","98.9726"
"48.8800","12.1920","12.1920","8.1280","26.4554","99.2077"
"48.9600","12.2124","12.2124","8.1416","26.5096","99.4111"
"49.0400","12.2319","12.2319","8.1546","26.5606","99.6023"
"49.1200","12.2519","12.2519","8.1679","26.6165","99.8119"
"49.2000","12.2707","12.2707","8.1805","26.6657","99.9962"
"49.2800","12.2919","12.2919","8.1946","26.7269","100.2257"
"49.3600","12.3114","12.3114","8.2076","26.7793","100.4222"
"49.4400","12.3308","12.3308","8.2205","26.8341","100.6280"
"49.5200","12.3510","12.3510","8.2340","26.8926","100.8473"
"49.6000","12.3719","12.3719","8.2479","26.9485","101.0569"
"49.6800","12.3922","12.3922","8.2615","27.0046","101.2672"
"49.7600","12.4123","12.4123","8.2749","27.0601","101.4755"
"49.8400","12.4304","12.4304","8.2869","27.1104","101.6640"
"49.9200","12.4513","12.4513","8.3009","27.1713","101.8922"
"50.0000","12.4716","12.4716","8.3144","27.2303","102.1138"
"50.0800","12.4921","12.4921","8.3281","27.2864","102.3239"
"50.1600","12.5129","12.5129","8.3420","27.3449","102.5434"
"50.2400","12.5320","12.5320","8.3547","27.3982","102.7433"
"50.3200","12.5522","12.5522","8.3681","27.4540","102.9523"
"50.4000","12.5720","12.5720","8.3814","27.5100","103.1625"
"50.4800","12.5914","12.5914","8.3943","27.5668","103.3756"
"50.5600","12.6112","12.6112","8.4075","27.6213","103.5799"
"50.6400","12.6306","12.6306","8.4204","27.6748","103.7805"
"50.7200","12.6511","12.6511","8.4340","27.7328","103.9982"
"50.8000","12.6726","12.6726","8.4484","27.7944","104.2289"
"50.8800","12.6919","12.6919","8.4612","27.8497","104.4362"
"50.9600","12.7121","12.7121","8.4747","27.9062","104.6484"
"51.0400","12.7312","12.7312","8.4875","27.9571","104.8391"
"51.1200","12.7505","12.7505","8.5003","28.0119","105.0446"
"51.2000","12.7711","12.7711","8.5141","28.0696","105.2609"
"51.2800","12.7916","12.7916","8.5277","28.1297","105.4864"
"51.3600","12.8120","12.8120","8.5413","28.1874","105.7026"
"51.4400","12.8325","12.8325","8.5550","28.2444","105.9166"
"51.5200","12.8519","12.8519","8.5679","28.3027","106.1352"
"51.6000","12.8717","12.8717","8.5811","28.3588","106.3453"
"51.6800","12.8911","12.8911","8.5941","28.4101","106.5381"
"51.7600","12.9117","12.9117","8.6078","28.4713","106.7674"
"51.8400","12.9315","12.9315","8.6210","28.5250","106.9687"
"51.9200","12.9502","12.9502","8.6334","28.5785","107.1694"
"52.0000","12.9715","12.9715","8.6477","28.6418","107.4067"
"52.0800","12.9924","12.9924","8.6616","28.7019","107.6320"
"52.1600","13.0118","13.0118","8.6746","28.7573","107.8399"
"52.2400","13.0319","13.0319","8.6879","28.8158","108.0592"
"52.3200","13.0507","13.0507","8.7005","28.8665","108.2492"
"52.4000","13.0716","13.0716","8.7144","28.9266","108.4746"
"52.4800","13.0922","13.0922","8.7281","28.9832","108.6869"
"52.5600","13.1112","13.1112","8.7408","29.0415","108.9056"
"52.6400","13.1321","13.1321","8.7547","29.1014","109.1302"
"52.7200","13.1517","13.1517","8.7678","29.1571","109.3390"
"52.8000","13.1724","13.1724","8.7816","29.2176","109.5661"
"52.8800","13.1921","13.1921","8.7947","29.2773","109.7897"
"52.9600","13.2113","13.2113","8.8075","29.3295","109.9857"
"53.0400","13.2312","13.2312","8.8208","29.3880","110.2050"
"53.1200","13.2509","13.2509","8.8339","29.4419","110.4073"
"53.2000","13.2709","13.2709","8.8473","29.5026","110.6348"
"53.2800","13.2925","13.2925","8.8616","29.5664","110.8738"
"53.3600","13.3114","13.3114","8.8742","29.6189","111.0707"
"53.4400","13.3319","13.3319","8.8879","29.6790","111.2962"
"53.5200","13.3518","13.3518","8.9012","29.7345","111.5044"
"53.6000","13.3711","13.3711","8.9141","29.7907","111.7153"
"53.6800","13.3914","13.3914","8.9276","29.8521","111.9453"
"53.7600","13.4114","13.4114","8.9410","29.9093","112.1599"
"53.8400","13.4312","13.4312","8.9541","29.9646","112.3674"
"53.9200","13.4524","13.4524","8.9683","30.0266","112.5996"
"54.0000","13.4717","13.4717","8.9811","30.0838","112.8142"
"54.0800","13.4920","13.4920","8.9946","30.1418","113.0319"
"54.1600","13.5114","13.5114","9.0076","30.1979","113.2422"
"54.2400","13.5310","13.5310","9.0206","30.2545","113.4545"
"54.3200","13.5514","13.5514","9.0343","30.3128","113.6730"
"54.4000","13.5702","13.5702","9.0468","30.3681","113.8802"
"54.4800","13.5918","13.5918","9.0612","30.4321","114.1205"
"54.5600","13.6125","13.6125","9.0750","30.4932","114.3494"
"54.6400","13.6317","13.6317","9.0878","30.5480","114.5549"
"54.7200","13.6513","13.6513","9.1008","30.6051","114.7689"
"54.8000","13.6711","13.6711","9.1140","30.6625","114.9845"
"54.8800","13.6915","13.6915","9.1277","30.7251","115.2192"
"54.9600","13.7123","13.7123","9.1415","30.7831","115.4367"
"55.0400","13.7306","13.7306","9.1537","30.8402","115.6507"
"55.1200","13.7520","13.7520","9.1680","30.9041","115.8903"
"55.2000","13.7724","13.7724","9.1816","30.9649","116.1183"
"55.2800","13.7926","13.7926","9.1951","31.0242","116.3408"
"55.3600","13.8119","13.8119","9.2079","31.0829","116.5608"
"55.4400","13.8308","13.8308","9.2205","31.1344","116.7538"
"55.5200","13.8509","13.8509","9.2339","31.1914","116.9678"
"55.6000","13.8714","13.8714","9.2476","31.2532","117.1995"
"55.6800","13.8906","13.8906","9.2604","31.3111","117.4167"
"55.7600","13.9119","13.9119","9.2746","31.3802","117.6757"
"55.8400","13.9316","13.9316","9.2877","31.4370","117.8889"
"55.9200","13.9523","13.9523","9.3015","31.4963","118.1112"
"56.0000","13.9720","13.9720","9.3147","31.5527","118.3225"
"56.0800","13.9909","13.9909","9.3273","31.6118","118.5441"
"56.1600","14.0115","14.0115","9.3410","31.6707","118.7650"
"56.2400","14.0313","14.0313","9.3542","31.7301","118.9879"
"56.3200","14.0512","14.0512","9.3674","31.7904","119.2140"
"56.4000","14.0720","14.0720","9.3813","31.8550","119.4564"
"56.4800","14.0918","14.0918","9.3946","31.9114","119.6677"
"56.5600","14.1118","14.1118","9.4079","31.9680","119.8799"
"56.6400","14.1320","14.1320","9.4213","32.0306","120.1148"
"56.7200","14.1509","14.1509","9.4340","32.0875","120.3281"
"56.8000","14.1713","14.1713","9.4475","32.1493","120.5598"
"56.8800","14.1910","14.1910","9.4607","32.2071","120.7767"
"56.9600","14.2112","14.2112","9.4742","32.2667","121.0001"
"57.0400","14.2319","14.2319","9.4880","32.3306","121.2399"
"57.1200","14.2516","14.2516","9.5011","32.3919","121.4695"
"57.2000","14.2717","14.2717","9.5145","32.4521","121.6954"
"57.2800","14.2922","14.2922","9.5281","32.5151","121.9318"
"57.3600","14.3109","14.3109","9.5406","32.5684","122.1317"
"57.4400","14.3310","14.3310","9.5540","32.6311","122.3667"
"57.5200","14.3507","14.3507","9.5671","32.6869","122.5758"
"57.6000","14.3723","14.3723","9.5815","32.7550","122.8311"
"57.6800","14.3931","14.3931","9.5954","32.8167","123.0626"
"57.7600","14.4124","14.4124","9.6083","32.8752","123.2819"
"57.8400","14.4317","14.4317","9.6211","32.9348","123.5054"
"57.9200","14.4510","14.4510","9.6340","32.9898","123.7119"
"58.0000","14.4709","14.4709","9.6473","33.0509","123.9408"
"58.0800","14.4918","14.4918","9.6612","33.1127","124.1725"
"58.1600","14.5105","14.5105","9.6737","33.1703","124.3886"
"58.2400","14.5316","14.5316","9.6877","33.2353","124.6324"
"58.3200","14.5520","14.5520","9.7013","33.2952","124.8572"
"58.4000","14.5715","14.5715","9.7143","33.3543","125.0788"
"58.4800","14.5920","14.5920","9.7280","33.4185","125.3194"
"58.5600","14.6110","14.6110","9.7406","33.4735","125.5255"
"58.6400","14.6318","14.6318","9.7545","33.5378","125.7666"
"58.7200","14.6516","14.6516","9.7677","33.5983","125.9935"
"58.8000","14.6711","14.6711","9.7807","33.6594","126.2226"
"58.8800","14.6918","14.6918","9.7945","33.7256","126.4711"
"58.9600","14.7123","14.7123","9.8082","33.7860","126.6976"
"59.0400","14.7323","14.7323","9.8215","33.8457","126.9214"
"59.1200","14.7520","14.7520","9.8347","33.9034","127.1377"
"59.2000","14.7705","14.7705","9.8470","33.9577","127.3415"
"59.2800","14.7916","14.7916","9.8611","34.0259","127.5970"
"59.3600","14.8112","14.8112","9.8742","34.0815","127.8057"
"59.4400","14.8306","14.8306","9.8871","34.1443","128.0410"
"59.5200","14.8511","14.8511","9.9007","34.2090","128.2837"
"59.6000","14.8720","14.8720","9.9147","34.2720","128.5199"
"59.6800","14.8922","14.8922","9.9281","34.3333","128.7500"
"59.7600","14.9124","14.9124","9.9416","34.3944","128.9790"
"59.8400","14.9305","14.9305","9.9537","34.4512","129.1918"
"59.9200","14.9510","14.9510","9.9673","34.5125","129.4218"
"60.0000","14.9710","14.9710","9.9807","34.5736","129.6511"
"60.0800","14.9922","14.9922","9.9948","34.6413","129.9048"
"60.1090","15.0000","15.0000","10.0000","34.6650","129.9938"