File: data/instron_tests/metamaterial_samples/553_VERT_m1.is_comp_Exports/553_VERT_m1_4_1.csv
Sample text inputs : Sample No.,Sample choice input : Leading Direction,Sample choice input : Mode,Specimen choice input : Direction,Specimen properties : Height,Specimen properties : Thickness,Specimen properties : Width,Test : Rate 1
,,,,(mm),(mm),(mm),(mm/min)
"553","Vertical","Unimode","1","147.00","25.00","150.00","15.00"

Time,Displacement,Compressive displacement,Compressive strain (Displacement),Compressive stress,Force
(s),(mm),(mm),(%),(kPa),(N)
"0.0000","0.0000","0.0000","0.0000","-0.2131","-0.7992"
"0.0800","0.0023","0.0023","0.0015","-0.2109","-0.7907"
"0.1600","0.0178","0.0178","0.0119","-0.1735","-0.6507"
"0.2400","0.0373","0.0373","0.0249","-0.1292","-0.4847"
"0.3200","0.0572","0.0572","0.0381","-0.0872","-0.3268"
"0.4000","0.0764","0.0764","0.0509","-0.0465","-0.1745"
"0.4800","0.0964","0.0964","0.0643","-0.0051","-0.0191"
"0.5600","0.1167","0.1167","0.0778","0.0321","0.1205"
"0.6400","0.1358","0.1358","0.0905","0.0776","0.2912"
"0.7200","0.1567","0.1567","0.1044","0.1195","0.4481"
"0.8000","0.1776","0.1776","0.1184","0.1603","0.6010"
"0.8800","0.1982","0.1982","0.1321","0.2017","0.7563"
"0.9600","0.2179","0.2179","0.1452","0.2396","0.8986"
"1.0400","0.2367","0.2367","0.1578","0.2758","1.0342"
"1.1200","0.2572","0.2572","0.1715","0.3133","1.1747"
"1.2000","0.2773","0.2773","0.1849","0.3542","1.3281"
"1.2800","0.2970","0.2970","0.1980","0.3938","1.4768"
"1.3600","0.3179","0.3179","0.2119","0.4343","1.6285"
"1.4400","0.3379","0.3379","0.2253","0.4715","1.7681"
"1.5200","0.3581","0.3581","0.2387","0.5084","1.9066"
"1.6000","0.3781","0.3781","0.2520","0.5475","2.0530"
"1.6800","0.3968","0.3968","0.2645","0.5834","2.1877"
"1.7600","0.4174","0.4174","0.2783","0.6188","2.3206"
"1.8400","0.4366","0.4366","0.2911","0.6545","2.4542"
"1.9200","0.4565","0.4565","0.3043","0.6912","2.5919"
"2.0000","0.4774","0.4774","0.3183","0.7274","2.7279"
"2.0800","0.4983","0.4983","0.3322","0.7654","2.8704"
"2.1600","0.5175","0.5175","0.3450","0.7993","2.9972"
"2.2400","0.5373","0.5373","0.3582","0.8366","3.1373"
"2.3200","0.5563","0.5563","0.3709","0.8741","3.2778"
"2.4000","0.5776","0.5776","0.3851","0.9109","3.4159"
"2.4800","0.5974","0.5974","0.3983","0.9478","3.5541"
"2.5600","0.6179","0.6179","0.4119","0.9848","3.6930"
"2.6400","0.6379","0.6379","0.4253","1.0217","3.8314"
"2.7200","0.6574","0.6574","0.4383","1.0569","3.9635"
"2.8000","0.6778","0.6778","0.4519","1.0917","4.0940"
"2.8800","0.6971","0.6971","0.4647","1.1259","4.2221"
"2.9600","0.7171","0.7171","0.4781","1.1657","4.3714"
"3.0400","0.7374","0.7374","0.4916","1.2021","4.5079"
"3.1200","0.7563","0.7563","0.5042","1.2352","4.6322"
"3.2000","0.7773","0.7773","0.5182","1.2724","4.7714"
"3.2800","0.7984","0.7984","0.5323","1.3105","4.9144"
"3.3600","0.8173","0.8173","0.5449","1.3466","5.0497"
"3.4400","0.8375","0.8375","0.5583","1.3860","5.1974"
"3.5200","0.8567","0.8567","0.5712","1.4196","5.3233"
"3.6000","0.8775","0.8775","0.5850","1.4584","5.4689"
"3.6800","0.8976","0.8976","0.5984","1.4965","5.6118"
"3.7600","0.9172","0.9172","0.6115","1.5347","5.7553"
"3.8400","0.9376","0.9376","0.6250","1.5715","5.8931"
"3.9200","0.9585","0.9585","0.6390","1.6089","6.0333"
"4.0000","0.9783","0.9783","0.6522","1.6475","6.1780"
"4.0800","0.9982","0.9982","0.6655","1.6844","6.3163"
"4.1600","1.0166","1.0166","0.6778","1.7189","6.4459"
"4.2400","1.0373","1.0373","0.6916","1.7543","6.5785"
"4.3200","1.0574","1.0574","0.7049","1.7934","6.7254"
"4.4000","1.0764","1.0764","0.7176","1.8310","6.8663"
"4.4800","1.0977","1.0977","0.7318","1.8730","7.0236"
"4.5600","1.1180","1.1180","0.7453","1.9073","7.1525"
"4.6400","1.1373","1.1373","0.7582","1.9461","7.2978"
"4.7200","1.1574","1.1574","0.7716","1.9846","7.4423"
"4.8000","1.1766","1.1766","0.7844","2.0165","7.5620"
"4.8800","1.1976","1.1976","0.7984","2.0553","7.7074"
"4.9600","1.2175","1.2175","0.8117","2.0927","7.8475"
"5.0400","1.2370","1.2370","0.8247","2.1307","7.9901"
"5.1200","1.2580","1.2580","0.8387","2.1689","8.1334"
"5.2000","1.2776","1.2776","0.8518","2.2043","8.2660"
"5.2800","1.2984","1.2984","0.8656","2.2442","8.4159"
"5.3600","1.3178","1.3178","0.8786","2.2764","8.5367"
"5.4400","1.3363","1.3363","0.8909","2.3117","8.6687"
"5.5200","1.3563","1.3563","0.9042","2.3513","8.8175"
"5.6000","1.3771","1.3771","0.9180","2.3892","8.9597"
"5.6800","1.3968","1.3968","0.9312","2.4308","9.1154"
"5.7600","1.4187","1.4187","0.9458","2.4733","9.2750"
"5.8400","1.4372","1.4372","0.9581","2.5061","9.3978"
"5.9200","1.4580","1.4580","0.9720","2.5463","9.5487"
"6.0000","1.4775","1.4775","0.9850","2.5828","9.6854"
"6.0800","1.4971","1.4971","0.9981","2.6250","9.8438"
"6.1600","1.5169","1.5169","1.0112","2.6608","9.9778"
"6.2400","1.5367","1.5367","1.0245","2.6977","10.1164"
"6.3200","1.5574","1.5574","1.0382","2.7372","10.2646"
"6.4000","1.5790","1.5790","1.0526","2.7789","10.4207"
"6.4800","1.5979","1.5979","1.0653","2.8183","10.5686"
"6.5600","1.6182","1.6182","1.0788","2.8600","10.7252"
"6.6400","1.6371","1.6371","1.0914","2.8930","10.8486"
"6.7200","1.6569","1.6569","1.1046","2.9324","10.9965"
"6.8000","1.6777","1.6777","1.1185","2.9733","11.1498"
"6.8800","1.6966","1.6966","1.1310","3.0077","11.2790"
"6.9600","1.7174","1.7174","1.1449","3.0523","11.4460"
"7.0400","1.7381","1.7381","1.1588","3.0925","11.5969"
"7.1200","1.7575","1.7575","1.1717","3.1285","11.7319"
"7.2000","1.7778","1.7778","1.1852","3.1697","11.8862"
"7.2800","1.7972","1.7972","1.1981","3.2041","12.0153"
"7.3600","1.8174","1.8174","1.2116","3.2456","12.1709"
"7.4400","1.8377","1.8377","1.2251","3.2850","12.3187"
"7.5200","1.8562","1.8562","1.2375","3.3229","12.4608"
"7.6000","1.8780","1.8780","1.2520","3.3654","12.6202"
"7.6800","1.8984","1.8984","1.2656","3.3997","12.7487"
"7.7600","1.9181","1.9181","1.2787","3.4390","12.8963"
"7.8400","1.9375","1.9375","1.2917","3.4780","13.0426"
"7.9200","1.9564","1.9564","1.3043","3.5161","13.1856"
"8.0000","1.9768","1.9768","1.3179","3.5563","13.3362"
"8.0800","1.9967","1.9967","1.3312","3.5946","13.4797"
"8.1600","2.0160","2.0160","1.3440","3.6374","13.6401"
"8.2400","2.0378","2.0378","1.3585","3.6783","13.7935"
"8.3200","2.0576","2.0576","1.3718","3.7155","13.9331"
"8.4000","2.0782","2.0782","1.3855","3.7562","14.0857"
"8.4800","2.0981","2.0981","1.3987","3.7956","14.2334"
"8.5600","2.1169","2.1169","1.4113","3.8358","14.3841"
"8.6400","2.1369","2.1369","1.4246","3.8760","14.5349"
"8.7200","2.1570","2.1570","1.4380","3.9160","14.6850"
"8.8000","2.1770","2.1770","1.4513","3.9533","14.8247"
"8.8800","2.1986","2.1986","1.4657","3.9991","14.9966"
"8.9600","2.2178","2.2178","1.4785","4.0383","15.1437"
"9.0400","2.2380","2.2380","1.4920","4.0786","15.2948"
"9.1200","2.2579","2.2579","1.5053","4.1170","15.4386"
"9.2000","2.2773","2.2773","1.5182","4.1590","15.5963"
"9.2800","2.2974","2.2974","1.5316","4.2010","15.7538"
"9.3600","2.3165","2.3165","1.5443","4.2354","15.8827"
"9.4400","2.3370","2.3370","1.5580","4.2780","16.0425"
"9.5200","2.3577","2.3577","1.5718","4.3168","16.1880"
"9.6000","2.3777","2.3777","1.5851","4.3610","16.3538"
"9.6800","2.3978","2.3978","1.5986","4.4017","16.5064"
"9.7600","2.4174","2.4174","1.6116","4.4409","16.6536"
"9.8400","2.4364","2.4364","1.6243","4.4779","16.7923"
"9.9200","2.4571","2.4571","1.6381","4.5198","16.9493"
"10.0000","2.4765","2.4765","1.6510","4.5558","17.0843"
"10.0800","2.4983","2.4983","1.6655","4.5992","17.2470"
"10.1600","2.5186","2.5186","1.6791","4.6402","17.4006"
"10.2400","2.5378","2.5378","1.6918","4.6818","17.5569"
"10.3200","2.5574","2.5574","1.7049","4.7214","17.7054"
"10.4000","2.5770","2.5770","1.7180","4.7634","17.8628"
"10.4800","2.5973","2.5973","1.7315","4.8039","18.0147"
"10.5600","2.6177","2.6177","1.7452","4.8441","18.1653"
"10.6400","2.6360","2.6360","1.7573","4.8776","18.2911"
"10.7200","2.6572","2.6572","1.7715","4.9218","18.4568"
"10.8000","2.6778","2.6778","1.7852","4.9654","18.6202"
"10.8800","2.6976","2.6976","1.7984","5.0059","18.7722"
"10.9600","2.7184","2.7184","1.8123","5.0484","18.9317"
"11.0400","2.7369","2.7369","1.8246","5.0839","19.0647"
"11.1200","2.7570","2.7570","1.8380","5.1265","19.2244"
"11.2000","2.7776","2.7776","1.8517","5.1671","19.3766"
"11.2800","2.7971","2.7971","1.8648","5.2081","19.5303"
"11.3600","2.8178","2.8178","1.8785","5.2528","19.6979"
"11.4400","2.8383","2.8383","1.8922","5.2911","19.8418"
"11.5200","2.8578","2.8578","1.9052","5.3336","20.0010"
"11.6000","2.8780","2.8780","1.9187","5.3730","20.1489"
"11.6800","2.8966","2.8966","1.9311","5.4130","20.2988"
"11.7600","2.9175","2.9175","1.9450","5.4559","20.4595"
"11.8400","2.9366","2.9366","1.9577","5.4943","20.6035"
"11.9200","2.9564","2.9564","1.9710","5.5358","20.7592"
"12.0000","2.9775","2.9775","1.9850","5.5814","20.9301"
"12.0800","2.9979","2.9979","1.9986","5.6225","21.0845"
"12.1600","3.0178","3.0178","2.0119","5.6562","21.2107"
"12.2400","3.0377","3.0377","2.0252","5.6940","21.3526"
"12.3200","3.0563","3.0563","2.0376","5.7367","21.5125"
"12.4000","3.0776","3.0776","2.0517","5.7815","21.6808"
"12.4800","3.0970","3.0970","2.0647","5.8211","21.8292"
"12.5600","3.1177","3.1177","2.0784","5.8643","21.9912"
"12.6400","3.1381","3.1381","2.0921","5.9059","22.1470"
"12.7200","3.1573","3.1573","2.1049","5.9476","22.3036"
"12.8000","3.1778","3.1778","2.1185","5.9883","22.4563"
"12.8800","3.1977","3.1977","2.1318","6.0283","22.6060"
"12.9600","3.2171","3.2171","2.1448","6.0686","22.7574"
"13.0400","3.2368","3.2368","2.1579","6.1101","22.9127"
"13.1200","3.2560","3.2560","2.1707","6.1482","23.0558"
"13.2000","3.2773","3.2773","2.1848","6.1880","23.2051"
"13.2800","3.2984","3.2984","2.1989","6.2308","23.3655"
"13.3600","3.3173","3.3173","2.2115","6.2735","23.5256"
"13.4400","3.3375","3.3375","2.2250","6.3150","23.6813"
"13.5200","3.3564","3.3564","2.2376","6.3516","23.8186"
"13.6000","3.3773","3.3773","2.2515","6.3952","23.9819"
"13.6800","3.3979","3.3979","2.2653","6.4386","24.1449"
"13.7600","3.4168","3.4168","2.2779","6.4807","24.3026"
"13.8400","3.4376","3.4376","2.2917","6.5202","24.4508"
"13.9200","3.4585","3.4585","2.3057","6.5675","24.6279"
"14.0000","3.4780","3.4780","2.3187","6.6083","24.7812"
"14.0800","3.4978","3.4978","2.3319","6.6493","24.9348"
"14.1600","3.5167","3.5167","2.3445","6.6869","25.0757"
"14.2400","3.5373","3.5373","2.3582","6.7272","25.2269"
"14.3200","3.5573","3.5573","2.3715","6.7688","25.3829"
"14.4000","3.5765","3.5765","2.3843","6.8080","25.5300"
"14.4800","3.5976","3.5976","2.3984","6.8525","25.6970"
"14.5600","3.6179","3.6179","2.4119","6.8940","25.8526"
"14.6400","3.6374","3.6374","2.4250","6.9328","25.9980"
"14.7200","3.6575","3.6575","2.4383","6.9762","26.1609"
"14.8000","3.6767","3.6767","2.4511","7.0150","26.3061"
"14.8800","3.6977","3.6977","2.4651","7.0588","26.4706"
"14.9600","3.7176","3.7176","2.4784","7.0998","26.6242"
"15.0400","3.7367","3.7367","2.4911","7.1400","26.7749"
"15.1200","3.7578","3.7578","2.5052","7.1866","26.9497"
"15.2000","3.7780","3.7780","2.5187","7.2271","27.1016"
"15.2800","3.7985","3.7985","2.5324","7.2711","27.2666"
"15.3600","3.8177","3.8177","2.5451","7.3087","27.4077"
"15.4400","3.8364","3.8364","2.5576","7.3495","27.5607"
"15.5200","3.8567","3.8567","2.5711","7.3937","27.7265"
"15.6000","3.8769","3.8769","2.5846","7.4338","27.8766"
"15.6800","3.8970","3.8970","2.5980","7.4772","28.0396"
"15.7600","3.9181","3.9181","2.6121","7.5202","28.2008"
"15.8400","3.9372","3.9372","2.6248","7.5577","28.3412"
"15.9200","3.9576","3.9576","2.6384","7.5993","28.4974"
"16.0000","3.9775","3.9775","2.6516","7.6423","28.6585"
"16.0800","3.9976","3.9976","2.6651","7.6877","28.8288"
"16.1600","4.0170","4.0170","2.6780","7.7276","28.9784"
"16.2400","4.0364","4.0364","2.6910","7.7702","29.1384"
"16.3200","4.0574","4.0574","2.7049","7.8128","29.2979"
"16.4000","4.0789","4.0789","2.7193","7.8563","29.4611"
"16.4800","4.0976","4.0976","2.7317","7.8984","29.6191"
"16.5600","4.1178","4.1178","2.7452","7.9398","29.7743"
"16.6400","4.1370","4.1370","2.7580","7.9790","29.9211"
"16.7200","4.1569","4.1569","2.7712","8.0212","30.0795"
"16.8000","4.1774","4.1774","2.7849","8.0648","30.2429"
"16.8800","4.1964","4.1964","2.7976","8.1046","30.3924"
"16.9600","4.2175","4.2175","2.8116","8.1510","30.5663"
"17.0400","4.2380","4.2380","2.8253","8.1939","30.7270"
"17.1200","4.2575","4.2575","2.8383","8.2345","30.8793"
"17.2000","4.2776","4.2776","2.8517","8.2794","31.0479"
"17.2800","4.2975","4.2975","2.8650","8.3193","31.1974"
"17.3600","4.3174","4.3174","2.8782","8.3589","31.3458"
"17.4400","4.3374","4.3374","2.8916","8.4007","31.5025"
"17.5200","4.3562","4.3562","2.9042","8.4422","31.6582"
"17.6000","4.3782","4.3782","2.9188","8.4881","31.8303"
"17.6800","4.3983","4.3983","2.9322","8.5323","31.9960"
"17.7600","4.4182","4.4182","2.9455","8.5734","32.1502"
"17.8400","4.4378","4.4378","2.9585","8.6206","32.3271"
"17.9200","4.4567","4.4567","2.9711","8.6568","32.4629"
"18.0000","4.4770","4.4770","2.9847","8.6995","32.6231"
"18.0800","4.4975","4.4975","2.9983","8.7420","32.7824"
"18.1600","4.5167","4.5167","3.0111","8.7848","32.9429"
"18.2400","4.5376","4.5376","3.0250","8.8311","33.1166"
"18.3200","4.5573","4.5573","3.0382","8.8714","33.2679"
"18.4000","4.5782","4.5782","3.0521","8.9121","33.4203"
"18.4800","4.5975","4.5975","3.0650","8.9548","33.5804"
"18.5600","4.6165","4.6165","3.0777","8.9965","33.7368"
"18.6400","4.6373","4.6373","3.0915","9.0404","33.9013"
"18.7200","4.6573","4.6573","3.1049","9.0846","34.0671"
"18.8000","4.6774","4.6774","3.1183","9.1244","34.2166"
"18.8800","4.6985","4.6985","3.1323","9.1680","34.3798"
"18.9600","4.7179","4.7179","3.1453","9.2110","34.5412"
"19.0400","4.7380","4.7380","3.1587","9.2514","34.6927"
"19.1200","4.7576","4.7576","3.1717","9.2924","34.8466"
"19.2000","4.7767","4.7767","3.1844","9.3354","35.0079"
"19.2800","4.7971","4.7971","3.1981","9.3788","35.1705"
"19.3600","4.8164","4.8164","3.2109","9.4195","35.3231"
"19.4400","4.8370","4.8370","3.2247","9.4624","35.4839"
"19.5200","4.8578","4.8578","3.2386","9.5057","35.6463"
"19.6000","4.8774","4.8774","3.2516","9.5500","35.8126"
"19.6800","4.8978","4.8978","3.2652","9.5925","35.9720"
"19.7600","4.9178","4.9178","3.2785","9.6345","36.1294"
"19.8400","4.9365","4.9365","3.2910","9.6773","36.2899"
"19.9200","4.9570","4.9570","3.3047","9.7218","36.4567"
"20.0000","4.9765","4.9765","3.3177","9.7640","36.6150"
"20.0800","4.9984","4.9984","3.3322","9.8080","36.7799"
"20.1600","5.0186","5.0186","3.3457","9.8524","36.9466"
"20.2400","5.0377","5.0377","3.3585","9.8931","37.0992"
"20.3200","5.0569","5.0569","3.3713","9.9333","37.2499"
"20.4000","5.0773","5.0773","3.3849","9.9790","37.4214"
"20.4800","5.0975","5.0975","3.3984","10.0207","37.5778"
"20.5600","5.1178","5.1178","3.4118","10.0669","37.7508"
"20.6400","5.1359","5.1359","3.4240","10.1030","37.8863"
"20.7200","5.1570","5.1570","3.4380","10.1478","38.0541"
"20.8000","5.1774","5.1774","3.4516","10.1934","38.2251"
"20.8800","5.1973","5.1973","3.4648","10.2362","38.3857"
"20.9600","5.2181","5.2181","3.4788","10.2813","38.5550"
"21.0400","5.2369","5.2369","3.4913","10.3200","38.7001"
"21.1200","5.2573","5.2573","3.5049","10.3614","38.8554"
"21.2000","5.2773","5.2773","3.5182","10.4053","39.0198"
"21.2800","5.2969","5.2969","3.5313","10.4509","39.1910"
"21.3600","5.3178","5.3178","3.5452","10.4973","39.3647"
"21.4400","5.3382","5.3382","3.5588","10.5414","39.5302"
"21.5200","5.3579","5.3579","3.5719","10.5848","39.6929"
"21.6000","5.3779","5.3779","3.5853","10.6257","39.8465"
"21.6800","5.3967","5.3967","3.5978","10.6668","40.0004"
"21.7600","5.4176","5.4176","3.6117","10.7099","40.1620"
"21.8400","5.4368","5.4368","3.6245","10.7533","40.3247"
"21.9200","5.4571","5.4571","3.6380","10.7978","40.4918"
"22.0000","5.4775","5.4775","3.6517","10.8457","40.6713"
"22.0800","5.4978","5.4978","3.6652","10.8861","40.8228"
"22.1600","5.5177","5.5177","3.6785","10.9289","40.9836"
"22.2400","5.5379","5.5379","3.6919","10.9714","41.1427"
"22.3200","5.5563","5.5563","3.7042","11.0132","41.2997"
"22.4000","5.5775","5.5775","3.7183","11.0599","41.4746"
"22.4800","5.5973","5.5973","3.7315","11.1006","41.6272"
"22.5600","5.6178","5.6178","3.7452","11.1453","41.7948"
"22.6400","5.6380","5.6380","3.7587","11.1878","41.9544"
"22.7200","5.6575","5.6575","3.7717","11.2342","42.1283"
"22.8000","5.6782","5.6782","3.7854","11.2801","42.3005"
"22.8800","5.6978","5.6978","3.7985","11.3217","42.4564"
"22.9600","5.7170","5.7170","3.8114","11.3630","42.6113"
"23.0400","5.7370","5.7370","3.8246","11.4069","42.7759"
"23.1200","5.7557","5.7557","3.8371","11.4485","42.9318"
"23.2000","5.7768","5.7768","3.8512","11.4942","43.1031"
"23.2800","5.7988","5.7988","3.8659","11.5398","43.2741"
"23.3600","5.8174","5.8174","3.8783","11.5817","43.4314"
"23.4400","5.8376","5.8376","3.8917","11.6239","43.5897"
"23.5200","5.8566","5.8566","3.9044","11.6678","43.7541"
"23.6000","5.8776","5.8776","3.9184","11.7133","43.9250"
"23.6800","5.8975","5.8975","3.9317","11.7564","44.0867"
"23.7600","5.9168","5.9168","3.9446","11.8003","44.2512"
"23.8400","5.9376","5.9376","3.9584","11.8465","44.4244"
"23.9200","5.9587","5.9587","3.9725","11.8929","44.5982"
"24.0000","5.9780","5.9780","3.9853","11.9342","44.7533"
"24.0800","5.9974","5.9974","3.9983","11.9763","44.9111"
"24.1600","6.0166","6.0166","4.0111","12.0178","45.0669"
"24.2400","6.0375","6.0375","4.0250","12.0629","45.2360"
"24.3200","6.0577","6.0577","4.0385","12.1051","45.3942"
"24.4000","6.0763","6.0763","4.0509","12.1494","45.5601"
"24.4800","6.0974","6.0974","4.0650","12.1966","45.7372"
"24.5600","6.1179","6.1179","4.0786","12.2410","45.9036"
"24.6400","6.1373","6.1373","4.0915","12.2814","46.0553"
"24.7200","6.1576","6.1576","4.1051","12.3267","46.2252"
"24.8000","6.1772","6.1772","4.1181","12.3690","46.3837"
"24.8800","6.1978","6.1978","4.1319","12.4153","46.5572"
"24.9600","6.2176","6.2176","4.1450","12.4556","46.7084"
"25.0400","6.2365","6.2365","4.1577","12.4998","46.8743"
"25.1200","6.2577","6.2577","4.1718","12.5512","47.0671"
"25.2000","6.2782","6.2782","4.1854","12.5940","47.2275"
"25.2800","6.2986","6.2986","4.1990","12.6358","47.3842"
"25.3600","6.3177","6.3177","4.2118","12.6779","47.5420"
"25.4400","6.3364","6.3364","4.2243","12.7216","47.7058"
"25.5200","6.3567","6.3567","4.2378","12.7678","47.8791"
"25.6000","6.3766","6.3766","4.2511","12.8098","48.0369"
"25.6800","6.3968","6.3968","4.2645","12.8536","48.2009"
"25.7600","6.4185","6.4185","4.2790","12.9034","48.3877"
"25.8400","6.4372","6.4372","4.2915","12.9457","48.5465"
"25.9200","6.4580","6.4580","4.3053","12.9915","48.7181"
"26.0000","6.4776","6.4776","4.3184","13.0340","48.8777"
"26.0800","6.4969","6.4969","4.3313","13.0771","49.0390"
"26.1600","6.5170","6.5170","4.3446","13.1253","49.2197"
"26.2400","6.5367","6.5367","4.3578","13.1655","49.3708"
"26.3200","6.5572","6.5572","4.3715","13.2113","49.5424"
"26.4000","6.5792","6.5792","4.3861","13.2596","49.7235"
"26.4800","6.5979","6.5979","4.3986","13.3029","49.8858"
"26.5600","6.6176","6.6176","4.4117","13.3470","50.0512"
"26.6400","6.6369","6.6369","4.4246","13.3906","50.2148"
"26.7200","6.6573","6.6573","4.4382","13.4380","50.3925"
"26.8000","6.6774","6.6774","4.4516","13.4809","50.5536"
"26.8800","6.6964","6.6964","4.4643","13.5234","50.7128"
"26.9600","6.7175","6.7175","4.4783","13.5658","50.8716"
"27.0400","6.7378","6.7378","4.4918","13.6143","51.0537"
"27.1200","6.7575","6.7575","4.5050","13.6570","51.2137"
"27.2000","6.7776","6.7776","4.5184","13.7032","51.3871"
"27.2800","6.7975","6.7975","4.5317","13.7481","51.5554"
"27.3600","6.8173","6.8173","4.5448","13.7909","51.7159"
"27.4400","6.8372","6.8372","4.5582","13.8378","51.8919"
"27.5200","6.8562","6.8562","4.5708","13.8783","52.0435"
"27.6000","6.8783","6.8783","4.5856","13.9306","52.2397"
"27.6800","6.8987","6.8987","4.5992","13.9771","52.4141"
"27.7600","6.9184","6.9184","4.6122","14.0201","52.5755"
"27.8400","6.9371","6.9371","4.6248","14.0626","52.7349"
"27.9200","6.9565","6.9565","4.6377","14.1055","52.8956"
"28.0000","6.9769","6.9769","4.6513","14.1504","53.0641"
"28.0800","6.9972","6.9972","4.6648","14.1953","53.2325"
"28.1600","7.0162","7.0162","4.6775","14.2371","53.3891"
"28.2400","7.0377","7.0377","4.6918","14.2899","53.5869"
"28.3200","7.0575","7.0575","4.7050","14.3352","53.7569"
"28.4000","7.0780","7.0780","4.7187","14.3779","53.9170"
"28.4800","7.0977","7.0977","4.7318","14.4217","54.0813"
"28.5600","7.1169","7.1169","4.7446","14.4660","54.2475"
"28.6400","7.1374","7.1374","4.7582","14.5114","54.4179"
"28.7200","7.1572","7.1572","4.7715","14.5562","54.5856"
"28.8000","7.1773","7.1773","4.7849","14.6033","54.7625"
"28.8800","7.1984","7.1984","4.7989","14.6523","54.9462"
"28.9600","7.2180","7.2180","4.8120","14.6972","55.1143"
"29.0400","7.2379","7.2379","4.8253","14.7391","55.2714"
"29.1200","7.2576","7.2576","4.8384","14.7839","55.4398"
"29.2000","7.2768","7.2768","4.8512","14.8259","55.5971"
"29.2800","7.2973","7.2973","4.8649","14.8748","55.7804"
"29.3600","7.3165","7.3165","4.8777","14.9180","55.9426"
"29.4400","7.3369","7.3369","4.8913","14.9621","56.1077"
"29.5200","7.3576","7.3576","4.9051","15.0115","56.2933"
"29.6000","7.3778","7.3778","4.9185","15.0580","56.4673"
"29.6800","7.3981","7.3981","4.9321","15.1047","56.6425"
"29.7600","7.4180","7.4180","4.9454","15.1500","56.8126"
"29.8400","7.4366","7.4366","4.9577","15.1945","56.9794"
"29.9200","7.4571","7.4571","4.9714","15.2395","57.1483"
"30.0000","7.4768","7.4768","4.9845","15.2832","57.3121"
"30.0800","7.4984","7.4984","4.9989","15.3311","57.4915"
"30.1600","7.5186","7.5186","5.0124","15.3795","57.6732"
"30.2400","7.5380","7.5380","5.0253","15.4246","57.8421"
"30.3200","7.5570","7.5570","5.0380","15.4667","58.0003"
"30.4000","7.5773","7.5773","5.0515","15.5109","58.1658"
"30.4800","7.5975","7.5975","5.0650","15.5582","58.3433"
"30.5600","7.6177","7.6177","5.0785","15.6055","58.5206"
"30.6400","7.6358","7.6358","5.0905","15.6447","58.6675"
"30.7200","7.6569","7.6569","5.1046","15.6940","58.8526"
"30.8000","7.6775","7.6775","5.1183","15.7409","59.0283"
"30.8800","7.6981","7.6981","5.1321","15.7895","59.2108"
"30.9600","7.7186","7.7186","5.1457","15.8371","59.3890"
"31.0400","7.7366","7.7366","5.1577","15.8750","59.5314"
"31.1200","7.7571","7.7571","5.1714","15.9224","59.7088"
"31.2000","7.7776","7.7776","5.1850","15.9681","59.8804"
"31.2800","7.7966","7.7966","5.1978","16.0136","60.0510"
"31.3600","7.8175","7.8175","5.2117","16.0622","60.2331"
"31.4400","7.8378","7.8378","5.2252","16.1093","60.4099"
"31.5200","7.8580","7.8580","5.2386","16.1548","60.5807"
"31.6000","7.8780","7.8780","5.2520","16.2002","60.7508"
"31.6800","7.8967","7.8967","5.2645","16.2425","60.9095"
"31.7600","7.9179","7.9179","5.2786","16.2919","61.0947"
"31.8400","7.9367","7.9367","5.2911","16.3343","61.2535"
"31.9200","7.9565","7.9565","5.3043","16.3813","61.4298"
"32.0000","7.9777","7.9777","5.3185","16.4338","61.6268"
"32.0800","7.9982","7.9982","5.3321","16.4792","61.7972"
"32.1600","8.0178","8.0178","5.3452","16.5218","61.9567"
"32.2400","8.0375","8.0375","5.3583","16.5666","62.1247"
"32.3200","8.0562","8.0562","5.3708","16.6119","62.2947"
"32.4000","8.0773","8.0773","5.3848","16.6594","62.4729"
"32.4800","8.0974","8.0974","5.3983","16.7080","62.6549"
"32.5600","8.1179","8.1179","5.4119","16.7558","62.8341"
"32.6400","8.1383","8.1383","5.4255","16.8037","63.0138"
"32.7200","8.1575","8.1575","5.4383","16.8498","63.1868"
"32.8000","8.1778","8.1778","5.4518","16.8935","63.3505"
"32.8800","8.1976","8.1976","5.4651","16.9392","63.5222"
"32.9600","8.2171","8.2171","5.4781","16.9832","63.6868"
"33.0400","8.2368","8.2368","5.4912","17.0306","63.8647"
"33.1200","8.2560","8.2560","5.5040","17.0717","64.0190"
"33.2000","8.2770","8.2770","5.5180","17.1209","64.2035"
"33.2800","8.2985","8.2985","5.5323","17.1729","64.3985"
"33.3600","8.3175","8.3175","5.5450","17.2178","64.5667"
"33.4400","8.3376","8.3376","5.5584","17.2640","64.7401"
"33.5200","8.3568","8.3568","5.5712","17.3087","64.9077"
"33.6000","8.3771","8.3771","5.5847","17.3551","65.0817"
"33.6800","8.3970","8.3970","5.5980","17.4031","65.2617"
"33.7600","8.4170","8.4170","5.6113","17.4483","65.4312"
"33.8400","8.4377","8.4377","5.6251","17.4948","65.6054"
"33.9200","8.4585","8.4585","5.6390","17.5455","65.7957"
"34.0000","8.4776","8.4776","5.6517","17.5915","65.9682"
"34.0800","8.4978","8.4978","5.6652","17.6387","66.1452"
"34.1600","8.5165","8.5165","5.6777","17.6797","66.2988"
"34.2400","8.5372","8.5372","5.6915","17.7306","66.4898"
"34.3200","8.5578","8.5578","5.7052","17.7787","66.6702"
"34.4000","8.5765","8.5765","5.7177","17.8219","66.8323"
"34.4800","8.5976","8.5976","5.7317","17.8722","67.0208"
"34.5600","8.6180","8.6180","5.7453","17.9186","67.1948"
"34.6400","8.6374","8.6374","5.7583","17.9651","67.3693"
"34.7200","8.6573","8.6573","5.7715","18.0118","67.5443"
"34.8000","8.6766","8.6766","5.7844","18.0569","67.7135"
"34.8800","8.6976","8.6976","5.7984","18.1067","67.9003"
"34.9600","8.7177","8.7177","5.8118","18.1559","68.0846"
"35.0400","8.7369","8.7369","5.8246","18.2009","68.2535"
"35.1200","8.7581","8.7581","5.8387","18.2536","68.4511"
"35.2000","8.7780","8.7780","5.8520","18.2961","68.6105"
"35.2800","8.7983","8.7983","5.8655","18.3429","68.7859"
"35.3600","8.8176","8.8176","5.8784","18.3882","68.9556"
"35.4400","8.8367","8.8367","5.8912","18.4322","69.1206"
"35.5200","8.8569","8.8569","5.9046","18.4833","69.3125"
"35.6000","8.8769","8.8769","5.9179","18.5310","69.4912"
"35.6800","8.8967","8.8967","5.9312","18.5770","69.6639"
"35.7600","8.9182","8.9182","5.9455","18.6284","69.8564"
"35.8400","8.9373","8.9373","5.9582","18.6742","70.0283"
"35.9200","8.9579","8.9579","5.9719","18.7214","70.2051"
"36.0000","8.9771","8.9771","5.9847","18.7652","70.3697"
"36.0800","8.9970","8.9970","5.9980","18.8140","70.5526"
"36.1600","9.0169","9.0169","6.0113","18.8619","70.7321"
"36.2400","9.0366","9.0366","6.0244","18.9092","70.9093"
"36.3200","9.0575","9.0575","6.0384","18.9577","71.0914"
"36.4000","9.0790","9.0790","6.0527","19.0107","71.2902"
"36.4800","9.0979","9.0979","6.0652","19.0563","71.4610"
"36.5600","9.1176","9.1176","6.0784","19.1012","71.6294"
"36.6400","9.1369","9.1369","6.0913","19.1474","71.8028"
"36.7200","9.1568","9.1568","6.1045","19.1958","71.9842"
"36.8000","9.1775","9.1775","6.1183","19.2447","72.1678"
"36.8800","9.1964","9.1964","6.1309","19.2886","72.3321"
"36.9600","9.2174","9.2174","6.1449","19.3396","72.5237"
"37.0400","9.2381","9.2381","6.1587","19.3900","72.7125"
"37.1200","9.2577","9.2577","6.1718","19.4388","72.8955"
"37.2000","9.2775","9.2775","6.1850","19.4874","73.0779"
"37.2800","9.2975","9.2975","6.1983","19.5346","73.2546"
"37.3600","9.3173","9.3173","6.2116","19.5794","73.4229"
"37.4400","9.3373","9.3373","6.2249","19.6285","73.6067"
"37.5200","9.3561","9.3561","6.2374","19.6726","73.7723"
"37.6000","9.3783","9.3783","6.2522","19.7289","73.9832"
"37.6800","9.3984","9.3984","6.2656","19.7788","74.1706"
"37.7600","9.4184","9.4184","6.2790","19.8264","74.3489"
"37.8400","9.4373","9.4373","6.2915","19.8699","74.5121"
"37.9200","9.4568","9.4568","6.3045","19.9151","74.6815"
"38.0000","9.4769","9.4769","6.3179","19.9641","74.8654"
"38.0800","9.4974","9.4974","6.3316","20.0125","75.0470"
"38.1600","9.5163","9.5163","6.3442","20.0614","75.2302"
"38.2400","9.5376","9.5376","6.3584","20.1153","75.4323"
"38.3200","9.5576","9.5576","6.3717","20.1616","75.6061"
"38.4000","9.5782","9.5782","6.3855","20.2094","75.7853"
"38.4800","9.5978","9.5978","6.3985","20.2572","75.9644"
"38.5600","9.6167","9.6167","6.4111","20.3057","76.1463"
"38.6400","9.6373","9.6373","6.4249","20.3555","76.3330"
"38.7200","9.6572","9.6572","6.4381","20.4018","76.5066"
"38.8000","9.6774","9.6774","6.4516","20.4504","76.6889"
"38.8800","9.6987","9.6987","6.4658","20.5056","76.8961"
"38.9600","9.7172","9.7172","6.4781","20.5470","77.0511"
"39.0400","9.7373","9.7373","6.4915","20.5951","77.2316"
"39.1200","9.7579","9.7579","6.5052","20.6442","77.4158"
"39.2000","9.7772","9.7772","6.5181","20.6939","77.6020"
"39.2800","9.7973","9.7973","6.5316","20.7462","77.7981"
"39.3600","9.8164","9.8164","6.5443","20.7893","77.9598"
"39.4400","9.8370","9.8370","6.5580","20.8403","78.1510"
"39.5200","9.8575","9.8575","6.5716","20.8909","78.3410"
"39.6000","9.8778","9.8778","6.5852","20.9410","78.5288"
"39.6800","9.8984","9.8984","6.5989","20.9950","78.7312"
"39.7600","9.9179","9.9179","6.6119","21.0381","78.8930"
"39.8400","9.9365","9.9365","6.6243","21.0863","79.0738"
"39.9200","9.9569","9.9569","6.6379","21.1358","79.2592"
"40.0000","9.9766","9.9766","6.6511","21.1846","79.4423"
"40.0800","9.9984","9.9984","6.6656","21.2407","79.6524"
"40.1600","10.0189","10.0189","6.6793","21.2892","79.8346"
"40.2400","10.0378","10.0378","6.6919","21.3364","80.0115"
"40.3200","10.0571","10.0571","6.7048","21.3829","80.1859"
"40.4000","10.0772","10.0772","6.7182","21.4293","80.3598"
"40.4800","10.0973","10.0973","6.7315","21.4801","80.5502"
"40.5600","10.1176","10.1176","6.7450","21.5292","80.7346"
"40.6400","10.1361","10.1361","6.7574","21.5756","80.9085"
"40.7200","10.1572","10.1572","6.7715","21.6292","81.1093"
"40.8000","10.1776","10.1776","6.7851","21.6807","81.3025"
"40.8800","10.1979","10.1979","6.7986","21.7300","81.4874"
"40.9600","10.2184","10.2184","6.8123","21.7811","81.6791"
"41.0400","10.2368","10.2368","6.8245","21.8254","81.8452"
"41.1200","10.2569","10.2569","6.8379","21.8728","82.0231"
"41.2000","10.2772","10.2772","6.8514","21.9249","82.2182"
"41.2800","10.2969","10.2969","6.8646","21.9750","82.4062"
"41.3600","10.3169","10.3169","6.8779","22.0262","82.5981"
"41.4400","10.3381","10.3381","6.8921","22.0795","82.7981"
"41.5200","10.3580","10.3580","6.9053","22.1290","82.9836"
"41.6000","10.3783","10.3783","6.9189","22.1780","83.1675"
"41.6800","10.3967","10.3967","6.9312","22.2242","83.3408"
"41.7600","10.4173","10.4173","6.9449","22.2749","83.5309"
"41.8400","10.4366","10.4366","6.9578","22.3230","83.7113"
"41.9200","10.4566","10.4566","6.9711","22.3734","83.9002"
"42.0000","10.4776","10.4776","6.9851","22.4289","84.1082"
"42.0800","10.4981","10.4981","6.9987","22.4788","84.2954"
"42.1600","10.5180","10.5180","7.0120","22.5295","84.4856"
"42.2400","10.5379","10.5379","7.0252","22.5769","84.6632"
"42.3200","10.5561","10.5561","7.0374","22.6227","84.8352"
"42.4000","10.5774","10.5774","7.0516","22.6786","85.0449"
"42.4800","10.5971","10.5971","7.0648","22.7267","85.2252"
"42.5600","10.6176","10.6176","7.0784","22.7776","85.4161"
"42.6400","10.6380","10.6380","7.0920","22.8262","85.5982"
"42.7200","10.6576","10.6576","7.1051","22.8758","85.7842"
"42.8000","10.6779","10.6779","7.1186","22.9273","85.9775"
"42.8800","10.6979","10.6979","7.1319","22.9761","86.1605"
"42.9600","10.7172","10.7172","7.1448","23.0290","86.3588"
"43.0400","10.7372","10.7372","7.1581","23.0791","86.5465"
"43.1200","10.7564","10.7564","7.1709","23.1232","86.7119"
"43.2000","10.7772","10.7772","7.1848","23.1752","86.9069"
"43.2800","10.7987","10.7987","7.1991","23.2297","87.1115"
"43.3600","10.8175","10.8175","7.2116","23.2798","87.2991"
"43.4400","10.8377","10.8377","7.2251","23.3294","87.4854"
"43.5200","10.8566","10.8566","7.2377","23.3765","87.6620"
"43.6000","10.8775","10.8775","7.2517","23.4291","87.8593"
"43.6800","10.8976","10.8976","7.2651","23.4800","88.0501"
"43.7600","10.9172","10.9172","7.2781","23.5289","88.2335"
"43.8400","10.9372","10.9372","7.2915","23.5803","88.4262"
"43.9200","10.9580","10.9580","7.3053","23.6348","88.6304"
"44.0000","10.9778","10.9778","7.3185","23.6864","88.8239"
"44.0800","10.9984","10.9984","7.3323","23.7385","89.0195"
"44.1600","11.0164","11.0164","7.3443","23.7789","89.1707"
"44.2400","11.0368","11.0368","7.3579","23.8303","89.3637"
"44.3200","11.0572","11.0572","7.3715","23.8842","89.5659"
"44.4000","11.0766","11.0766","7.3844","23.9341","89.7528"
"44.4800","11.0973","11.0973","7.3982","23.9899","89.9621"
"44.5600","11.1182","11.1182","7.4121","24.0428","90.1606"
"44.6400","11.1377","11.1377","7.4251","24.0910","90.3414"
"44.7200","11.1571","11.1571","7.4381","24.1401","90.5255"
"44.8000","11.1764","11.1764","7.4509","24.1874","90.7027"
"44.8800","11.1975","11.1975","7.4650","24.2420","90.9076"
"44.9600","11.2178","11.2178","7.4785","24.2964","91.1115"
"45.0400","11.2370","11.2370","7.4914","24.3456","91.2959"
"45.1200","11.2580","11.2580","7.5053","24.3986","91.4946"
"45.2000","11.2779","11.2779","7.5186","24.4524","91.6966"
"45.2800","11.2984","11.2984","7.5323","24.5029","91.8858"
"45.3600","11.3177","11.3177","7.5451","24.5538","92.0767"
"45.4400","11.3367","11.3367","7.5578","24.6017","92.2562"
"45.5200","11.3569","11.3569","7.5713","24.6526","92.4473"
"45.6000","11.3771","11.3771","7.5847","24.7052","92.6443"
"45.6800","11.3968","11.3968","7.5979","24.7553","92.8325"
"45.7600","11.4181","11.4181","7.6121","24.8118","93.0441"
"45.8400","11.4373","11.4373","7.6249","24.8583","93.2186"
"45.9200","11.4580","11.4580","7.6386","24.9134","93.4254"
"46.0000","11.4777","11.4777","7.6518","24.9646","93.6172"
"46.0800","11.4970","11.4970","7.6646","25.0165","93.8117"
"46.1600","11.5167","11.5167","7.6778","25.0671","94.0015"
"46.2400","11.5366","11.5366","7.6911","25.1170","94.1886"
"46.3200","11.5575","11.5575","7.7050","25.1734","94.4003"
"46.4000","11.5787","11.5787","7.7191","25.2288","94.6081"
"46.4800","11.5979","11.5979","7.7319","25.2785","94.7945"
"46.5600","11.6177","11.6177","7.7451","25.3305","94.9893"
"46.6400","11.6370","11.6370","7.7580","25.3793","95.1724"
"46.7200","11.6569","11.6569","7.7712","25.4324","95.3716"
"46.8000","11.6776","11.6776","7.7850","25.4869","95.5758"
"46.8800","11.6964","11.6964","7.7976","25.5341","95.7528"
"46.9600","11.7175","11.7175","7.8116","25.5912","95.9669"
"47.0400","11.7383","11.7383","7.8255","25.6468","96.1755"
"47.1200","11.7577","11.7577","7.8385","25.6961","96.3602"
"47.2000","11.7772","11.7772","7.8515","25.7491","96.5590"
"47.2800","11.7969","11.7969","7.8646","25.7976","96.7409"
"47.3600","11.8174","11.8174","7.8782","25.8543","96.9536"
"47.4400","11.8381","11.8381","7.8921","25.9065","97.1494"
"47.5200","11.8562","11.8562","7.9041","25.9550","97.3314"
"47.6000","11.8781","11.8781","7.9187","26.0148","97.5556"
"47.6800","11.8985","11.8985","7.9323","26.0668","97.7507"
"47.7600","11.9184","11.9184","7.9456","26.1176","97.9410"
"47.8400","11.9373","11.9373","7.9582","26.1693","98.1350"
"47.9200","11.9568","11.9568","7.9712","26.2161","98.3104"
"48.0000","11.9768","11.9768","7.9846","26.2713","98.5175"
"48.0800","11.9975","11.9975","7.9984","26.3248","98.7181"
"48.1600","12.0164","12.0164","8.0109","26.3744","98.9039"
"48.2400","12.0372","12.0372","8.0248","26.4336","99.1259"
"48.3200","12.0571","12.0571","8.0381","26.4849","99.3186"
"48.4000","12.0784","12.0784","8.0523","26.5412","99.5294"
"48.4800","12.0979","12.0979","8.0653","26.5896","99.7109"
"48.5600","12.1167","12.1167","8.0778","26.6415","99.9056"
"48.6400","12.1374","12.1374","8.0916","26.6983","100.1185"
"48.7200","12.1573","12.1573","8.1049","26.7517","100.3188"
"48.8000","12.1771","12.1771","8.1181","26.8052","100.5194"
"48.8800","12.1987","12.1987","8.1325","26.8641","100.7405"
"48.9600","12.2180","12.2180","8.1453","26.9123","100.9210"
"49.0400","12.2378","12.2378","8.1585","26.9655","101.1206"
"49.1200","12.2574","12.2574","8.1716","27.0152","101.3072"
"49.2000","12.2765","12.2765","8.1843","27.0662","101.4981"
"49.2800","12.2977","12.2977","8.1985","27.1245","101.7168"
"49.3600","12.3163","12.3163","8.2109","27.1728","101.8979"
"49.4400","12.3370","12.3370","8.2247","27.2279","102.1045"
"49.5200","12.3577","12.3577","8.2385","27.2824","102.3090"
"49.6000","12.3777","12.3777","8.2518","27.3390","102.5213"
"49.6800","12.3979","12.3979","8.2653","27.3949","102.7310"
"49.7600","12.4177","12.4177","8.2784","27.4468","102.9256"
"49.8400","12.4365","12.4365","8.2910","27.4967","103.1126"
"49.9200","12.4574","12.4574","8.3049","27.5543","103.3286"
"50.0000","12.4768","12.4768","8.3178","27.6075","103.5281"
"50.0800","12.4985","12.4985","8.3323","27.6689","103.7584"
"50.1600","12.5188","12.5188","8.3459","27.7222","103.9584"
"50.2400","12.5376","12.5376","8.3584","27.7739","104.1522"
"50.3200","12.5574","12.5574","8.3716","27.8252","104.3443"
"50.4000","12.5775","12.5775","8.3850","27.8796","104.5484"
"50.4800","12.5971","12.5971","8.3981","27.9331","104.7492"
"50.5600","12.6176","12.6176","8.4117","27.9892","104.9595"
"50.6400","12.6360","12.6360","8.4240","28.0372","105.1394"
"50.7200","12.6573","12.6573","8.4382","28.0959","105.3597"
"50.8000","12.6781","12.6781","8.4521","28.1543","105.5787"
"50.8800","12.6981","12.6981","8.4654","28.2078","105.7794"
"50.9600","12.7179","12.7179","8.4786","28.2618","105.9817"
"51.0400","12.7366","12.7366","8.4911","28.3117","106.1688"
"51.1200","12.7569","12.7569","8.5046","28.3655","106.3705"
"51.2000","12.7775","12.7775","8.5183","28.4222","106.5832"
"51.2800","12.7973","12.7973","8.5315","28.4802","106.8007"
"51.3600","12.8178","12.8178","8.5452","28.5383","107.0188"
"51.4400","12.8378","12.8378","8.5586","28.5922","107.2209"
"51.5200","12.8577","12.8577","8.5718","28.6456","107.4211"
"51.6000","12.8780","12.8780","8.5853","28.6998","107.6243"
"51.6800","12.8969","12.8969","8.5979","28.7512","107.8168"
"51.7600","12.9174","12.9174","8.6116","28.8088","108.0329"
"51.8400","12.9368","12.9368","8.6245","28.8604","108.2265"
"51.9200","12.9564","12.9564","8.6376","28.9175","108.4405"
"52.0000","12.9776","12.9776","8.6517","28.9783","108.6688"
"52.0800","12.9978","12.9978","8.6652","29.0331","108.8742"
"52.1600","13.0175","13.0175","8.6784","29.0846","109.0673"
"52.2400","13.0379","13.0379","8.6919","29.1402","109.2759"
"52.3200","13.0563","13.0563","8.7042","29.1924","109.4715"
"52.4000","13.0773","13.0773","8.7182","29.2538","109.7017"
"52.4800","13.0972","13.0972","8.7315","29.3052","109.8943"
"52.5600","13.1179","13.1179","8.7452","29.3659","110.1222"
"52.6400","13.1381","13.1381","8.7587","29.4231","110.3365"
"52.7200","13.1575","13.1575","8.7717","29.4767","110.5377"
"52.8000","13.1780","13.1780","8.7853","29.5336","110.7512"
"52.8800","13.1978","13.1978","8.7985","29.5884","110.9564"
"52.9600","13.2169","13.2169","8.8113","29.6419","111.1572"
"53.0400","13.2373","13.2373","8.8248","29.6996","111.3736"
"53.1200","13.2563","13.2563","8.8375","29.7504","111.5638"
"53.2000","13.2773","13.2773","8.8515","29.8094","111.7851"
"53.2800","13.2984","13.2984","8.8656","29.8695","112.0105"
"53.3600","13.3173","13.3173","8.8782","29.9218","112.2066"
"53.4400","13.3375","13.3375","8.8917","29.9801","112.4253"
"53.5200","13.3570","13.3570","8.9047","30.0327","112.6225"
"53.6000","13.3772","13.3772","8.9182","30.0887","112.8328"
"53.6800","13.3975","13.3975","8.9317","30.1471","113.0515"
"53.7600","13.4167","13.4167","8.9444","30.1966","113.2374"
"53.8400","13.4377","13.4377","8.9585","30.2597","113.4738"
"53.9200","13.4586","13.4586","8.9724","30.3181","113.6930"
"54.0000","13.4776","13.4776","8.9851","30.3698","113.8868"
"54.0800","13.4976","13.4976","8.9984","30.4253","114.0950"
"54.1600","13.5167","13.5167","9.0112","30.4788","114.2955"
"54.2400","13.5373","13.5373","9.0249","30.5391","114.5215"
"54.3200","13.5572","13.5572","9.0381","30.5947","114.7302"
"54.4000","13.5763","13.5763","9.0508","30.6523","114.9463"
"54.4800","13.5975","13.5975","9.0650","30.7109","115.1660"
"54.5600","13.6179","13.6179","9.0786","30.7690","115.3836"
"54.6400","13.6375","13.6375","9.0917","30.8214","115.5801"
"54.7200","13.6572","13.6572","9.1048","30.8799","115.7998"
"54.8000","13.6767","13.6767","9.1178","30.9324","115.9966"
"54.8800","13.6975","13.6975","9.1317","30.9948","116.2305"
"54.9600","13.7174","13.7174","9.1450","31.0504","116.4388"
"55.0400","13.7368","13.7368","9.1579","31.1074","116.6526"
"55.1200","13.7579","13.7579","9.1720","31.1686","116.8822"
"55.2000","13.7780","13.7780","9.1853","31.2239","117.0895"
"55.2800","13.7986","13.7986","9.1991","31.2816","117.3060"
"55.3600","13.8178","13.8178","9.2119","31.3352","117.5071"
"55.4400","13.8363","13.8363","9.2242","31.3875","117.7030"
"55.5200","13.8565","13.8565","9.2377","31.4456","117.9211"
"55.6000","13.8767","13.8767","9.2511","31.5042","118.1409"
"55.6800","13.8969","13.8969","9.2646","31.5632","118.3620"
"55.7600","13.9182","13.9182","9.2788","31.6231","118.5868"
"55.8400","13.9371","13.9371","9.2914","31.6781","118.7929"
"55.9200","13.9581","13.9581","9.3054","31.7373","119.0149"
"56.0000","13.9774","13.9774","9.3183","31.7918","119.2191"
"56.0800","13.9969","13.9969","9.3313","31.8478","119.4293"
"56.1600","14.0166","14.0166","9.3444","31.9048","119.6429"
"56.2400","14.0367","14.0367","9.3578","31.9620","119.8575"
"56.3200","14.0575","14.0575","9.3716","32.0236","120.0886"
"56.4000","14.0790","14.0790","9.3860","32.0881","120.3304"
"56.4800","14.0977","14.0977","9.3984","32.1425","120.5345"
"56.5600","14.1176","14.1176","9.4117","32.1984","120.7439"
"56.6400","14.1371","14.1371","9.4247","32.2567","120.9626"
"56.7200","14.1567","14.1567","9.4378","32.3113","121.1672"
"56.8000","14.1773","14.1773","9.4515","32.3723","121.3960"
"56.8800","14.1966","14.1966","9.4644","32.4254","121.5953"
"56.9600","14.2172","14.2172","9.4781","32.4857","121.8215"
"57.0400","14.2380","14.2380","9.4920","32.5477","122.0538"
"57.1200","14.2575","14.2575","9.5050","32.6040","122.2649"
"57.2000","14.2779","14.2779","9.5186","32.6676","122.5033"
"57.2800","14.2972","14.2972","9.5315","32.7220","122.7073"
"57.3600","14.3170","14.3170","9.5446","32.7776","122.9159"
"57.4400","14.3375","14.3375","9.5583","32.8382","123.1431"
"57.5200","14.3566","14.3566","9.5711","32.8943","123.3535"
"57.6000","14.3784","14.3784","9.5856","32.9611","123.6043"
"57.6800","14.3984","14.3984","9.5989","33.0184","123.8189"
"57.7600","14.4183","14.4183","9.6122","33.0754","124.0326"
"57.8400","14.4373","14.4373","9.6248","33.1282","124.2309"
"57.9200","14.4565","14.4565","9.6377","33.1838","124.4392"
"58.0000","14.4770","14.4770","9.6513","33.2463","124.6736"
"58.0800","14.4974","14.4974","9.6650","33.3059","124.8973"
"58.1600","14.5162","14.5162","9.6775","33.3606","125.1021"
"58.2400","14.5374","14.5374","9.6916","33.4262","125.3481"
"58.3200","14.5573","14.5573","9.7049","33.4828","125.5603"
"58.4000","14.5780","14.5780","9.7187","33.5441","125.7903"
"58.4800","14.5979","14.5979","9.7319","33.5999","125.9997"
"58.5600","14.6163","14.6163","9.7442","33.6539","126.2020"
"58.6400","14.6373","14.6373","9.7582","33.7181","126.4427"
"58.7200","14.6572","14.6572","9.7715","33.7777","126.6665"
"58.8000","14.6772","14.6772","9.7848","33.8387","126.8953"
"58.8800","14.6986","14.6986","9.7991","33.9008","127.1282"
"58.9600","14.7182","14.7182","9.8121","33.9571","127.3391"
"59.0400","14.7377","14.7377","9.8251","34.0137","127.5514"
"59.1200","14.7575","14.7575","9.8383","34.0677","127.7539"
"59.2000","14.7766","14.7766","9.8511","34.1283","127.9812"
"59.2800","14.7974","14.7974","9.8649","34.1904","128.2141"
"59.3600","14.8163","14.8163","9.8775","34.2465","128.4243"
"59.4400","14.8371","14.8371","9.8914","34.3087","128.6576"
"59.5200","14.8577","14.8577","9.9052","34.3736","128.9010"
"59.6000","14.8775","14.8775","9.9184","34.4307","129.1150"
"59.6800","14.8979","14.8979","9.9319","34.4944","129.3540"
"59.7600","14.9176","14.9176","9.9451","34.5516","129.5686"
"59.8400","14.9367","14.9367","9.9578","34.6086","129.7822"
"59.9200","14.9573","14.9573","9.9715","34.6739","130.0271"
"60.0000","14.9762","14.9762","9.9841","34.7267","130.2253"
"60.0800","14.9985","14.9985","9.9990","34.7968","130.4878"
"60.0860","15.0000","15.0000","10.0000","34.8017","130.5062"