File: data/instron_tests/metamaterial_samples/553_VERT_m1.is_comp_Exports/553_VERT_m1_2_1.csv
Sample text inputs : Sample No.,Sample choice input : Leading Direction,Sample choice input : Mode,Specimen choice input : Direction,Specimen properties : Height,Specimen properties : Thickness,Specimen properties : Width,Test : Rate 1
,,,,(mm),(mm),(mm),(mm/min)
"553","Vertical","Unimode","1","147.00","25.00","150.00","15.00"

Time,Displacement,Compressive displacement,Compressive strain (Displacement),Compressive stress,Force
(s),(mm),(mm),(%),(kPa),(N)
"0.0000","0.0000","0.0000","0.0000","-0.8353","-3.0697"
"0.0800","0.0014","0.0014","0.0009","-0.8225","-3.0227"
"0.1600","0.0195","0.0195","0.0130","-0.7123","-2.6177"
"0.2400","0.0391","0.0391","0.0261","-0.5976","-2.1960"
"0.3200","0.0593","0.0593","0.0395","-0.4944","-1.8171"
"0.4000","0.0785","0.0785","0.0523","-0.3993","-1.4674"
"0.4800","0.0987","0.0987","0.0658","-0.3089","-1.1351"
"0.5600","0.1187","0.1187","0.0791","-0.2230","-0.8195"
"0.6400","0.1378","0.1378","0.0919","-0.1377","-0.5062"
"0.7200","0.1582","0.1582","0.1055","-0.0524","-0.1924"
"0.8000","0.1784","0.1784","0.1189","0.0251","0.0924"
"0.8800","0.1980","0.1980","0.1320","0.0946","0.3476"
"0.9600","0.2193","0.2193","0.1462","0.1846","0.6785"
"1.0400","0.2389","0.2389","0.1593","0.2568","0.9436"
"1.1200","0.2589","0.2589","0.1726","0.3303","1.2137"
"1.2000","0.2782","0.2782","0.1855","0.3955","1.4534"
"1.2800","0.2976","0.2976","0.1984","0.4718","1.7339"
"1.3600","0.3180","0.3180","0.2120","0.5504","2.0229"
"1.4400","0.3377","0.3377","0.2251","0.6233","2.2908"
"1.5200","0.3585","0.3585","0.2390","0.7061","2.5948"
"1.6000","0.3792","0.3792","0.2528","0.7865","2.8903"
"1.6800","0.3981","0.3981","0.2654","0.8591","3.1574"
"1.7600","0.4186","0.4186","0.2791","0.9449","3.4724"
"1.8400","0.4385","0.4385","0.2923","1.0257","3.7693"
"1.9200","0.4581","0.4581","0.3054","1.1064","4.0660"
"2.0000","0.4778","0.4778","0.3185","1.1868","4.3615"
"2.0800","0.4973","0.4973","0.3315","1.2712","4.6715"
"2.1600","0.5188","0.5188","0.3458","1.3650","5.0163"
"2.2400","0.5398","0.5398","0.3599","1.4591","5.3623"
"2.3200","0.5589","0.5589","0.3726","1.5403","5.6608"
"2.4000","0.5784","0.5784","0.3856","1.6259","5.9751"
"2.4800","0.5980","0.5980","0.3987","1.7123","6.2929"
"2.5600","0.6181","0.6181","0.4120","1.8022","6.6229"
"2.6400","0.6388","0.6388","0.4259","1.8928","6.9562"
"2.7200","0.6574","0.6574","0.4383","1.9702","7.2404"
"2.8000","0.6783","0.6783","0.4522","2.0660","7.5927"
"2.8800","0.6988","0.6988","0.4658","2.1553","7.9205"
"2.9600","0.7186","0.7186","0.4791","2.2500","8.2686"
"3.0400","0.7393","0.7393","0.4928","2.3487","8.6315"
"3.1200","0.7575","0.7575","0.5050","2.4296","8.9288"
"3.2000","0.7780","0.7780","0.5187","2.5336","9.3110"
"3.2800","0.7984","0.7984","0.5322","2.6286","9.6602"
"3.3600","0.8178","0.8178","0.5452","2.7318","10.0395"
"3.4400","0.8394","0.8394","0.5596","2.8362","10.4230"
"3.5200","0.8591","0.8591","0.5727","2.9332","10.7795"
"3.6000","0.8793","0.8793","0.5862","3.0345","11.1516"
"3.6800","0.8985","0.8985","0.5990","3.1302","11.5036"
"3.7600","0.9170","0.9170","0.6113","3.2252","11.8526"
"3.8400","0.9379","0.9379","0.6253","3.3386","12.2694"
"3.9200","0.9582","0.9582","0.6388","3.4443","12.6579"
"4.0000","0.9777","0.9777","0.6518","3.5553","13.0659"
"4.0800","0.9988","0.9988","0.6658","3.6680","13.4800"
"4.1600","1.0183","1.0183","0.6788","3.7756","13.8754"
"4.2400","1.0391","1.0391","0.6927","3.8937","14.3094"
"4.3200","1.0587","1.0587","0.7058","4.0019","14.7068"
"4.4000","1.0774","1.0774","0.7183","4.1112","15.1087"
"4.4800","1.0979","1.0979","0.7319","4.2346","15.5622"
"4.5600","1.1181","1.1181","0.7454","4.3538","16.0000"
"4.6400","1.1387","1.1387","0.7591","4.4794","16.4619"
"4.7200","1.1599","1.1599","0.7732","4.6064","16.9286"
"4.8000","1.1785","1.1785","0.7856","4.7189","17.3418"
"4.8800","1.1988","1.1988","0.7992","4.8436","17.8002"
"4.9600","1.2185","1.2185","0.8124","4.9631","18.2395"
"5.0400","1.2383","1.2383","0.8255","5.0891","18.7026"
"5.1200","1.2585","1.2585","0.8390","5.2172","19.1731"
"5.2000","1.2773","1.2773","0.8515","5.3289","19.5839"
"5.2800","1.2982","1.2982","0.8655","5.4664","20.0888"
"5.3600","1.3190","1.3190","0.8793","5.6037","20.5936"
"5.4400","1.3386","1.3386","0.8924","5.7319","21.0647"
"5.5200","1.3587","1.3587","0.9058","5.8595","21.5338"
"5.6000","1.3781","1.3781","0.9187","5.9836","21.9898"
"5.6800","1.3978","1.3978","0.9319","6.1168","22.4794"
"5.7600","1.4184","1.4184","0.9456","6.2540","22.9834"
"5.8400","1.4377","1.4377","0.9585","6.3819","23.4534"
"5.9200","1.4594","1.4594","0.9729","6.5317","24.0042"
"6.0000","1.4792","1.4792","0.9861","6.6627","24.4854"
"6.0800","1.4984","1.4984","0.9989","6.7879","24.9455"
"6.1600","1.5184","1.5184","1.0123","6.9257","25.4521"
"6.2400","1.5381","1.5381","1.0254","7.0573","25.9356"
"6.3200","1.5583","1.5583","1.0389","7.1958","26.4444"
"6.4000","1.5785","1.5785","1.0524","7.3351","26.9564"
"6.4800","1.5971","1.5971","1.0647","7.4645","27.4320"
"6.5600","1.6179","1.6179","1.0786","7.6121","27.9745"
"6.6400","1.6388","1.6388","1.0925","7.7567","28.5058"
"6.7200","1.6597","1.6597","1.1065","7.9021","29.0402"
"6.8000","1.6789","1.6789","1.1193","8.0350","29.5285"
"6.8800","1.6976","1.6976","1.1317","8.1645","30.0047"
"6.9600","1.7180","1.7180","1.1453","8.3121","30.5468"
"7.0400","1.7382","1.7382","1.1588","8.4590","31.0869"
"7.1200","1.7579","1.7579","1.1719","8.6011","31.6092"
"7.2000","1.7791","1.7791","1.1861","8.7555","32.1764"
"7.2800","1.7988","1.7988","1.1992","8.8929","32.6815"
"7.3600","1.8190","1.8190","1.2127","9.0421","33.2298"
"7.4400","1.8390","1.8390","1.2260","9.1849","33.7545"
"7.5200","1.8576","1.8576","1.2384","9.3200","34.2511"
"7.6000","1.8783","1.8783","1.2522","9.4747","34.8194"
"7.6800","1.8974","1.8974","1.2649","9.6147","35.3340"
"7.7600","1.9180","1.9180","1.2786","9.7725","35.9139"
"7.8400","1.9388","1.9388","1.2925","9.9315","36.4982"
"7.9200","1.9589","1.9589","1.3060","10.0804","37.0455"
"8.0000","1.9785","1.9785","1.3190","10.2262","37.5812"
"8.0800","1.9982","1.9982","1.3321","10.3745","38.1262"
"8.1600","2.0173","2.0173","1.3448","10.5223","38.6694"
"8.2400","2.0388","2.0388","1.3592","10.6903","39.2870"
"8.3200","2.0580","2.0580","1.3720","10.8350","39.8187"
"8.4000","2.0793","2.0793","1.3862","11.0006","40.4272"
"8.4800","2.0991","2.0991","1.3994","11.1495","40.9745"
"8.5600","2.1182","2.1182","1.4121","11.2964","41.5144"
"8.6400","2.1386","2.1386","1.4257","11.4528","42.0891"
"8.7200","2.1584","2.1584","1.4390","11.6086","42.6617"
"8.8000","2.1783","2.1783","1.4522","11.7615","43.2234"
"8.8800","2.1983","2.1983","1.4655","11.9172","43.7959"
"8.9600","2.2171","2.2171","1.4781","12.0608","44.3236"
"9.0400","2.2384","2.2384","1.4922","12.2309","44.9484"
"9.1200","2.2594","2.2594","1.5062","12.3957","45.5544"
"9.2000","2.2786","2.2786","1.5190","12.5432","46.0961"
"9.2800","2.2983","2.2983","1.5322","12.6962","46.6585"
"9.3600","2.3175","2.3175","1.5450","12.8415","47.1925"
"9.4400","2.3387","2.3387","1.5592","13.0128","47.8221"
"9.5200","2.3591","2.3591","1.5727","13.1726","48.4094"
"9.6000","2.3780","2.3780","1.5853","13.3183","48.9449"
"9.6800","2.3984","2.3984","1.5990","13.4805","49.5408"
"9.7600","2.4191","2.4191","1.6128","13.6451","50.1456"
"9.8400","2.4392","2.4392","1.6261","13.8013","50.7198"
"9.9200","2.4591","2.4591","1.6394","13.9590","51.2995"
"10.0000","2.4773","2.4773","1.6516","14.1002","51.8181"
"10.0800","2.4985","2.4985","1.6657","14.2698","52.4414"
"10.1600","2.5178","2.5178","1.6785","14.4254","53.0133"
"10.2400","2.5379","2.5379","1.6919","14.5854","53.6014"
"10.3200","2.5585","2.5585","1.7056","14.7518","54.2127"
"10.4000","2.5787","2.5787","1.7191","14.9109","54.7976"
"10.4800","2.5983","2.5983","1.7322","15.0653","55.3648"
"10.5600","2.6189","2.6189","1.7459","15.2315","55.9758"
"10.6400","2.6377","2.6377","1.7585","15.3806","56.5237"
"10.7200","2.6585","2.6585","1.7724","15.5517","57.1525"
"10.8000","2.6780","2.6780","1.7853","15.7061","57.7198"
"10.8800","2.6983","2.6983","1.7989","15.8686","58.3172"
"10.9600","2.7192","2.7192","1.8128","16.0385","58.9416"
"11.0400","2.7384","2.7384","1.8256","16.1908","59.5012"
"11.1200","2.7591","2.7591","1.8394","16.3546","60.1032"
"11.2000","2.7787","2.7787","1.8525","16.5126","60.6837"
"11.2800","2.7978","2.7978","1.8652","16.6637","61.2392"
"11.3600","2.8178","2.8178","1.8785","16.8275","61.8409"
"11.4400","2.8376","2.8376","1.8918","16.9874","62.4286"
"11.5200","2.8582","2.8582","1.9055","17.1581","63.0560"
"11.6000","2.8798","2.8798","1.9198","17.3329","63.6984"
"11.6800","2.8983","2.8983","1.9322","17.4806","64.2412"
"11.7600","2.9187","2.9187","1.9458","17.6447","64.8441"
"11.8400","2.9379","2.9379","1.9586","17.7967","65.4030"
"11.9200","2.9586","2.9586","1.9724","17.9653","66.0223"
"12.0000","2.9782","2.9782","1.9855","18.1224","66.5998"
"12.0800","2.9974","2.9974","1.9983","18.2758","67.1635"
"12.1600","3.0184","3.0184","2.0123","18.4530","67.8148"
"12.2400","3.0403","3.0403","2.0269","18.6456","68.5227"
"12.3200","3.0590","3.0590","2.0393","18.7926","69.0627"
"12.4000","3.0789","3.0789","2.0526","18.9549","69.6593"
"12.4800","3.0977","3.0977","2.0651","19.1030","70.2036"
"12.5600","3.1182","3.1182","2.0788","19.2746","70.8342"
"12.6400","3.1386","3.1386","2.0924","19.4375","71.4328"
"12.7200","3.1574","3.1574","2.1049","19.5871","71.9828"
"12.8000","3.1782","3.1782","2.1188","19.7603","72.6189"
"12.8800","3.1989","3.1989","2.1326","19.9300","73.2427"
"12.9600","3.2186","3.2186","2.1457","20.0884","73.8248"
"13.0400","3.2389","3.2389","2.1593","20.2538","74.4327"
"13.1200","3.2579","3.2579","2.1719","20.4061","74.9926"
"13.2000","3.2785","3.2785","2.1857","20.5751","75.6133"
"13.2800","3.2984","3.2984","2.1989","20.7327","76.1927"
"13.3600","3.3175","3.3175","2.2117","20.8891","76.7676"
"13.4400","3.3394","3.3394","2.2262","21.0711","77.4364"
"13.5200","3.3591","3.3591","2.2394","21.2273","78.0103"
"13.6000","3.3794","3.3794","2.2529","21.3910","78.6118"
"13.6800","3.3985","3.3985","2.2657","21.5454","79.1793"
"13.7600","3.4174","3.4174","2.2783","21.6954","79.7305"
"13.8400","3.4378","3.4378","2.2919","21.8639","80.3497"
"13.9200","3.4579","3.4579","2.3053","22.0277","80.9518"
"14.0000","3.4779","3.4779","2.3186","22.1901","81.5487"
"14.0800","3.4992","3.4992","2.3328","22.3614","82.1781"
"14.1600","3.5178","3.5178","2.3452","22.5039","82.7018"
"14.2400","3.5386","3.5386","2.3591","22.6711","83.3162"
"14.3200","3.5587","3.5587","2.3725","22.8330","83.9114"
"14.4000","3.5778","3.5778","2.3852","22.9841","84.4667"
"14.4800","3.5983","3.5983","2.3989","23.1609","85.1162"
"14.5600","3.6177","3.6177","2.4118","23.3113","85.6689"
"14.6400","3.6384","3.6384","2.4256","23.4802","86.2898"
"14.7200","3.6599","3.6599","2.4400","23.6563","86.9370"
"14.8000","3.6788","3.6788","2.4525","23.8027","87.4749"
"14.8800","3.6987","3.6987","2.4658","23.9604","88.0543"
"14.9600","3.7184","3.7184","2.4789","24.1183","88.6348"
"15.0400","3.7379","3.7379","2.4919","24.2736","89.2054"
"15.1200","3.7585","3.7585","2.5056","24.4407","89.8195"
"15.2000","3.7773","3.7773","2.5182","24.5882","90.3615"
"15.2800","3.7982","3.7982","2.5322","24.7565","90.9802"
"15.3600","3.8189","3.8189","2.5459","24.9224","91.5899"
"15.4400","3.8385","3.8385","2.5590","25.0770","92.1581"
"15.5200","3.8586","3.8586","2.5724","25.2406","92.7593"
"15.6000","3.8779","3.8779","2.5853","25.3858","93.2928"
"15.6800","3.8979","3.8979","2.5986","25.5479","93.8885"
"15.7600","3.9185","3.9185","2.6123","25.7108","94.4873"
"15.8400","3.9376","3.9376","2.6251","25.8629","95.0463"
"15.9200","3.9593","3.9593","2.6395","26.0414","95.7021"
"16.0000","3.9791","3.9791","2.6528","26.1962","96.2710"
"16.0800","3.9990","3.9990","2.6660","26.3555","96.8563"
"16.1600","4.0183","4.0183","2.6789","26.5080","97.4168"
"16.2400","4.0380","4.0380","2.6920","26.6615","97.9811"
"16.3200","4.0584","4.0584","2.7056","26.8237","98.5773"
"16.4000","4.0785","4.0785","2.7190","26.9825","99.1607"
"16.4800","4.0970","4.0970","2.7313","27.1275","99.6937"
"16.5600","4.1184","4.1184","2.7456","27.3012","100.3318"
"16.6400","4.1388","4.1388","2.7592","27.4604","100.9169"
"16.7200","4.1593","4.1593","2.7729","27.6222","101.5117"
"16.8000","4.1791","4.1791","2.7861","27.7762","102.0776"
"16.8800","4.1978","4.1978","2.7985","27.9221","102.6136"
"16.9600","4.2178","4.2178","2.8119","28.0786","103.1889"
"17.0400","4.2383","4.2383","2.8255","28.2385","103.7764"
"17.1200","4.2582","4.2582","2.8388","28.3966","104.3576"
"17.2000","4.2792","4.2792","2.8528","28.5674","104.9853"
"17.2800","4.2986","4.2986","2.8658","28.7164","105.5328"
"17.3600","4.3191","4.3191","2.8794","28.8788","106.1297"
"17.4400","4.3389","4.3389","2.8926","29.0332","106.6972"
"17.5200","4.3576","4.3576","2.9051","29.1787","107.2317"
"17.6000","4.3782","4.3782","2.9188","29.3441","107.8394"
"17.6800","4.3972","4.3972","2.9315","29.4911","108.3798"
"17.7600","4.4182","4.4182","2.9454","29.6587","108.9959"
"17.8400","4.4390","4.4390","2.9593","29.8244","109.6046"
"17.9200","4.4587","4.4587","2.9725","29.9824","110.1853"
"18.0000","4.4787","4.4787","2.9858","30.1377","110.7561"
"18.0800","4.4983","4.4983","2.9989","30.2889","111.3118"
"18.1600","4.5177","4.5177","3.0118","30.4422","111.8749"
"18.2400","4.5387","4.5387","3.0258","30.6093","112.4893"
"18.3200","4.5577","4.5577","3.0385","30.7537","113.0199"
"18.4000","4.5789","4.5789","3.0526","30.9224","113.6397"
"18.4800","4.5992","4.5992","3.0661","31.0803","114.2201"
"18.5600","4.6186","4.6186","3.0791","31.2318","114.7769"
"18.6400","4.6386","4.6386","3.0924","31.3883","115.3519"
"18.7200","4.6585","4.6585","3.1056","31.5420","115.9170"
"18.8000","4.6781","4.6781","3.1187","31.6956","116.4813"
"18.8800","4.6980","4.6980","3.1320","31.8484","117.0430"
"18.9600","4.7168","4.7168","3.1445","31.9915","117.5686"
"19.0400","4.7382","4.7382","3.1588","32.1654","118.2077"
"19.1200","4.7594","4.7594","3.1729","32.3291","118.8093"
"19.2000","4.7787","4.7787","3.1858","32.4776","119.3552"
"19.2800","4.7984","4.7984","3.1990","32.6300","119.9151"
"19.3600","4.8173","4.8173","3.2115","32.7691","120.4265"
"19.4400","4.8382","4.8382","3.2255","32.9332","121.0294"
"19.5200","4.8590","4.8590","3.2393","33.0960","121.6279"
"19.6000","4.8780","4.8780","3.2520","33.2409","122.1604"
"19.6800","4.8983","4.8983","3.2655","33.4007","122.7474"
"19.7600","4.9193","4.9193","3.2795","33.5631","123.3444"
"19.8400","4.9392","4.9392","3.2928","33.7161","123.9066"
"19.9200","4.9589","4.9589","3.3059","33.8649","124.4533"
"20.0000","4.9777","4.9777","3.3184","34.0037","124.9638"
"20.0800","4.9983","4.9983","3.3322","34.1647","125.5552"
"20.1600","5.0181","5.0181","3.3454","34.3135","126.1022"
"20.2400","5.0378","5.0378","3.3585","34.4666","126.6646"
"20.3200","5.0585","5.0585","3.3724","34.6282","127.2586"
"20.4000","5.0785","5.0785","3.3856","34.7792","127.8135"
"20.4800","5.0984","5.0984","3.3990","34.9313","128.3725"
"20.5600","5.1189","5.1189","3.4126","35.0884","128.9501"
"20.6400","5.1375","5.1375","3.4250","35.2292","129.4672"
"20.7200","5.1587","5.1587","3.4391","35.3902","130.0591"
"20.8000","5.1778","5.1778","3.4519","35.5290","130.5689"
"20.8800","5.1980","5.1980","3.4653","35.6851","131.1426"
"20.9600","5.2191","5.2191","3.4794","35.8500","131.7488"
"21.0400","5.2391","5.2391","3.4928","36.0008","132.3031"
"21.1200","5.2594","5.2594","3.5062","36.1547","132.8686"
"21.2000","5.2786","5.2786","3.5191","36.3006","133.4045"
"21.2800","5.2975","5.2975","3.5317","36.4391","133.9136"
"21.3600","5.3177","5.3177","3.5451","36.5905","134.4700"
"21.4400","5.3375","5.3375","3.5583","36.7396","135.0180"
"21.5200","5.3584","5.3584","3.5723","36.8983","135.6011"
"21.6000","5.3796","5.3796","3.5864","37.0598","136.1949"
"21.6800","5.3982","5.3982","3.5988","37.1946","136.6901"
"21.7600","5.4185","5.4185","3.6124","37.3496","137.2598"
"21.8400","5.4382","5.4382","3.6254","37.4934","137.7882"
"21.9200","5.4584","5.4584","3.6389","37.6448","138.3446"
"22.0000","5.4780","5.4780","3.6520","37.7886","138.8733"
"22.0800","5.4973","5.4973","3.6649","37.9287","139.3880"
"22.1600","5.5183","5.5183","3.6788","38.0876","139.9721"
"22.2400","5.5399","5.5399","3.6932","38.2515","140.5742"
"22.3200","5.5589","5.5589","3.7059","38.3902","141.0839"
"22.4000","5.5788","5.5788","3.7192","38.5367","141.6225"
"22.4800","5.5975","5.5975","3.7316","38.6703","142.1134"
"22.5600","5.6182","5.6182","3.7454","38.8263","142.6867"
"22.6400","5.6385","5.6385","3.7590","38.9771","143.2407"
"22.7200","5.6577","5.6577","3.7718","39.1176","143.7572"
"22.8000","5.6781","5.6781","3.7854","39.2692","144.3141"
"22.8800","5.6987","5.6987","3.7992","39.4211","144.8727"
"22.9600","5.7187","5.7187","3.8125","39.5705","145.4215"
"23.0400","5.7388","5.7388","3.8259","39.7182","145.9642"
"23.1200","5.7582","5.7582","3.8388","39.8560","146.4706"
"23.2000","5.7784","5.7784","3.8523","40.0054","147.0199"
"23.2800","5.7982","5.7982","3.8655","40.1485","147.5458"
"23.3600","5.8175","5.8175","3.8783","40.2905","148.0676"
"23.4400","5.8396","5.8396","3.8930","40.4604","148.6918"
"23.5200","5.8596","5.8596","3.9064","40.6073","149.2317"
"23.6000","5.8795","5.8795","3.9197","40.7480","149.7490"
"23.6800","5.8986","5.8986","3.9324","40.8844","150.2501"
"23.7600","5.9175","5.9175","3.9450","41.0212","150.7529"
"23.8400","5.9379","5.9379","3.9586","41.1698","151.2989"
"23.9200","5.9584","5.9584","3.9723","41.3162","151.8372"
"24.0000","5.9780","5.9780","3.9853","41.4595","152.3635"
"24.0800","5.9985","5.9985","3.9990","41.6070","152.9057"
"24.1600","6.0181","6.0181","4.0120","41.7476","153.4223"
"24.2400","6.0390","6.0390","4.0260","41.8986","153.9772"
"24.3200","6.0587","6.0587","4.0391","42.0370","154.4861"
"24.4000","6.0782","6.0782","4.0521","42.1775","155.0022"
"24.4800","6.0978","6.0978","4.0652","42.3142","155.5048"
"24.5600","6.1178","6.1178","4.0785","42.4575","156.0314"
"24.6400","6.1384","6.1384","4.0923","42.6045","156.5716"
"24.7200","6.1598","6.1598","4.1065","42.7607","157.1457"
"24.8000","6.1787","6.1787","4.1192","42.8928","157.6309"
"24.8800","6.1987","6.1987","4.1325","43.0343","158.1509"
"24.9600","6.2183","6.2183","4.1455","43.1718","158.6564"
"25.0400","6.2379","6.2379","4.1586","43.3129","159.1750"
"25.1200","6.2584","6.2584","4.1722","43.4579","159.7077"
"25.2000","6.2771","6.2771","4.1847","43.5840","160.1711"
"25.2800","6.2980","6.2980","4.1987","43.7325","160.7168"
"25.3600","6.3188","6.3188","4.2126","43.8815","161.2647"
"25.4400","6.3385","6.3385","4.2257","44.0192","161.7707"
"25.5200","6.3589","6.3589","4.2393","44.1653","162.3074"
"25.6000","6.3783","6.3783","4.2522","44.2980","162.7952"
"25.6800","6.3977","6.3977","4.2651","44.4362","163.3029"
"25.7600","6.4184","6.4184","4.2789","44.5842","163.8468"
"25.8400","6.4378","6.4378","4.2919","44.7212","164.3506"
"25.9200","6.4594","6.4594","4.3063","44.8762","164.9200"
"26.0000","6.4794","6.4794","4.3196","45.0158","165.4330"
"26.0800","6.4991","6.4991","4.3327","45.1519","165.9332"
"26.1600","6.5178","6.5178","4.3452","45.2796","166.4025"
"26.2400","6.5381","6.5381","4.3587","45.4201","166.9188"
"26.3200","6.5587","6.5587","4.3725","45.5680","167.4625"
"26.4000","6.5787","6.5787","4.3858","45.7053","167.9670"
"26.4800","6.5970","6.5970","4.3980","45.8309","168.4286"
"26.5600","6.6180","6.6180","4.4120","45.9815","168.9820"
"26.6400","6.6383","6.6383","4.4256","46.1192","169.4879"
"26.7200","6.6593","6.6593","4.4395","46.2681","170.0353"
"26.8000","6.6792","6.6792","4.4528","46.4037","170.5338"
"26.8800","6.6972","6.6972","4.4648","46.5186","170.9558"
"26.9600","6.7175","6.7175","4.4783","46.6595","171.4736"
"27.0400","6.7382","6.7382","4.4921","46.8043","172.0058"
"27.1200","6.7582","6.7582","4.5055","46.9448","172.5222"
"27.2000","6.7793","6.7793","4.5196","47.0922","173.0640"
"27.2800","6.7990","6.7990","4.5327","47.2222","173.5415"
"27.3600","6.8190","6.8190","4.5460","47.3568","174.0362"
"27.4400","6.8389","6.8389","4.5593","47.4896","174.5244"
"27.5200","6.8574","6.8574","4.5716","47.6128","174.9770"
"27.6000","6.8784","6.8784","4.5856","47.7604","175.5196"
"27.6800","6.8976","6.8976","4.5984","47.8889","175.9915"
"27.7600","6.9182","6.9182","4.6122","48.0306","176.5125"
"27.8400","6.9388","6.9388","4.6259","48.1751","177.0433"
"27.9200","6.9588","6.9588","4.6392","48.3086","177.5341"
"28.0000","6.9784","6.9784","4.6523","48.4363","178.0033"
"28.0800","6.9986","6.9986","4.6657","48.5750","178.5131"
"28.1600","7.0178","7.0178","4.6785","48.7028","178.9827"
"28.2400","7.0385","7.0385","4.6923","48.8428","179.4972"
"28.3200","7.0576","7.0576","4.7051","48.9666","179.9522"
"28.4000","7.0790","7.0790","4.7193","49.1127","180.4893"
"28.4800","7.0995","7.0995","4.7330","49.2501","180.9941"
"28.5600","7.1189","7.1189","4.7459","49.3781","181.4644"
"28.6400","7.1385","7.1385","4.7590","49.5066","181.9366"
"28.7200","7.1585","7.1585","4.7723","49.6444","182.4431"
"28.8000","7.1783","7.1783","4.7856","49.7749","182.9228"
"28.8800","7.1984","7.1984","4.7989","49.9094","183.4171"
"28.9600","7.2171","7.2171","4.8114","50.0246","183.8403"
"29.0400","7.2381","7.2381","4.8254","50.1667","184.3627"
"29.1200","7.2592","7.2592","4.8394","50.3085","184.8838"
"29.2000","7.2786","7.2786","4.8524","50.4357","185.3513"
"29.2800","7.2981","7.2981","4.8654","50.5604","185.8095"
"29.3600","7.3180","7.3180","4.8787","50.6901","186.2860"
"29.4400","7.3388","7.3388","4.8925","50.8276","186.7913"
"29.5200","7.3587","7.3587","4.9058","50.9585","187.2723"
"29.6000","7.3780","7.3780","4.9187","51.0827","187.7288"
"29.6800","7.3983","7.3983","4.9322","51.2138","188.2109"
"29.7600","7.4196","7.4196","4.9464","51.3551","188.7300"
"29.8400","7.4389","7.4389","4.9593","51.4784","189.1830"
"29.9200","7.4590","7.4590","4.9727","51.6096","189.6653"
"30.0000","7.4774","7.4774","4.9850","51.7218","190.0775"
"30.0800","7.4983","7.4983","4.9989","51.8619","190.5925"
"30.1600","7.5180","7.5180","5.0120","51.9862","191.0491"
"30.2400","7.5376","7.5376","5.0251","52.1140","191.5188"
"30.3200","7.5586","7.5586","5.0391","52.2525","192.0279"
"30.4000","7.5789","7.5789","5.0526","52.3788","192.4920"
"30.4800","7.5982","7.5982","5.0655","52.4982","192.9308"
"30.5600","7.6187","7.6187","5.0791","52.6302","193.4159"
"30.6400","7.6378","7.6378","5.0918","52.7501","193.8567"
"30.7200","7.6587","7.6587","5.1058","52.8907","194.3734"
"30.8000","7.6780","7.6780","5.1187","53.0118","194.8185"
"30.8800","7.6980","7.6980","5.1320","53.1393","195.2870"
"30.9600","7.7191","7.7191","5.1461","53.2787","195.7991"
"31.0400","7.7391","7.7391","5.1594","53.4021","196.2526"
"31.1200","7.7593","7.7593","5.1729","53.5278","196.7148"
"31.2000","7.7786","7.7786","5.1857","53.6472","197.1534"
"31.2800","7.7974","7.7974","5.1983","53.7643","197.5836"
"31.3600","7.8178","7.8178","5.2118","53.8955","198.0660"
"31.4400","7.8377","7.8377","5.2251","54.0212","198.5280"
"31.5200","7.8579","7.8579","5.2386","54.1494","198.9992"
"31.6000","7.8793","7.8793","5.2529","54.2873","199.5059"
"31.6800","7.8986","7.8986","5.2657","54.4074","199.9473"
"31.7600","7.9191","7.9191","5.2794","54.5357","200.4186"
"31.8400","7.9382","7.9382","5.2922","54.6542","200.8544"
"31.9200","7.9585","7.9585","5.3057","54.7777","201.3079"
"32.0000","7.9780","7.9780","5.3186","54.8999","201.7570"
"32.0800","7.9976","7.9976","5.3318","55.0188","202.1942"
"32.1600","8.0186","8.0186","5.3457","55.1535","202.6892"
"32.2400","8.0402","8.0402","5.3601","55.2902","203.1914"
"32.3200","8.0589","8.0589","5.3726","55.4031","203.6062"
"32.4000","8.0784","8.0784","5.3856","55.5216","204.0420"
"32.4800","8.0975","8.0975","5.3983","55.6327","204.4500"
"32.5600","8.1181","8.1181","5.4121","55.7630","204.9289"
"32.6400","8.1385","8.1385","5.4257","55.8866","205.3833"
"32.7200","8.1574","8.1574","5.4383","55.9993","205.7973"
"32.8000","8.1779","8.1779","5.4520","56.1268","206.2661"
"32.8800","8.1989","8.1989","5.4659","56.2569","206.7440"
"32.9600","8.2186","8.2186","5.4791","56.3747","207.1772"
"33.0400","8.2388","8.2388","5.4925","56.4969","207.6260"
"33.1200","8.2581","8.2581","5.5054","56.6094","208.0394"
"33.2000","8.2782","8.2782","5.5188","56.7312","208.4873"
"33.2800","8.2981","8.2981","5.5320","56.8470","208.9128"
"33.3600","8.3175","8.3175","5.5450","56.9651","209.3466"
"33.4400","8.3398","8.3398","5.5599","57.1057","209.8634"
"33.5200","8.3597","8.3597","5.5732","57.2244","210.2996"
"33.6000","8.3793","8.3793","5.5862","57.3369","210.7129"
"33.6800","8.3983","8.3983","5.5989","57.4458","211.1133"
"33.7600","8.4175","8.4175","5.6117","57.5555","211.5166"
"33.8400","8.4380","8.4380","5.6253","57.6797","211.9728"
"33.9200","8.4584","8.4584","5.6389","57.8001","212.4154"
"34.0000","8.4779","8.4779","5.6519","57.9140","212.8338"
"34.0800","8.4980","8.4980","5.6653","58.0313","213.2650"
"34.1600","8.5179","8.5179","5.6786","58.1424","213.6732"
"34.2400","8.5396","8.5396","5.6931","58.2761","214.1646"
"34.3200","8.5587","8.5587","5.7058","58.3795","214.5448"
"34.4000","8.5782","8.5782","5.7188","58.4939","214.9650"
"34.4800","8.5980","8.5980","5.7320","58.6083","215.3855"
"34.5600","8.6176","8.6176","5.7451","58.7190","215.7923"
"34.6400","8.6386","8.6386","5.7591","58.8458","216.2584"
"34.7200","8.6599","8.6599","5.7732","58.9693","216.7123"
"34.8000","8.6788","8.6788","5.7858","59.0734","217.0949"
"34.8800","8.6987","8.6987","5.7991","59.1847","217.5039"
"34.9600","8.7183","8.7183","5.8122","59.2949","217.9087"
"35.0400","8.7380","8.7380","5.8253","59.4094","218.3295"
"35.1200","8.7586","8.7586","5.8390","59.5285","218.7674"
"35.2000","8.7774","8.7774","5.8516","59.6271","219.1296"
"35.2800","8.7981","8.7981","5.8654","59.7460","219.5665"
"35.3600","8.8187","8.8187","5.8791","59.8645","220.0020"
"35.4400","8.8388","8.8388","5.8925","59.9817","220.4328"
"35.5200","8.8593","8.8593","5.9062","60.0956","220.8512"
"35.6000","8.8781","8.8781","5.9188","60.1925","221.2074"
"35.6800","8.8977","8.8977","5.9318","60.3022","221.6107"
"35.7600","8.9182","8.9182","5.9455","60.4169","222.0320"
"35.8400","8.9375","8.9375","5.9584","60.5231","222.4226"
"35.9200","8.9595","8.9595","5.9730","60.6526","222.8984"
"36.0000","8.9795","8.9795","5.9864","60.7599","223.2927"
"36.0800","8.9991","8.9991","5.9994","60.8676","223.6885"
"36.1600","9.0180","9.0180","6.0120","60.9689","224.0607"
"36.2400","9.0383","9.0383","6.0256","61.0762","224.4550"
"36.3200","9.0585","9.0585","6.0390","61.1878","224.8653"
"36.4000","9.0786","9.0786","6.0524","61.2944","225.2571"
"36.4800","9.0971","9.0971","6.0647","61.3911","225.6124"
"36.5600","9.1183","9.1183","6.0789","61.5119","226.0561"
"36.6400","9.1383","9.1383","6.0922","61.6153","226.4362"
"36.7200","9.1595","9.1595","6.1063","61.7363","226.8811"
"36.8000","9.1788","9.1788","6.1192","61.8311","227.2294"
"36.8800","9.1974","9.1974","6.1316","61.9279","227.5850"
"36.9600","9.2179","9.2179","6.1453","62.0355","227.9804"
"37.0400","9.2383","9.2383","6.1589","62.1458","228.3859"
"37.1200","9.2582","9.2582","6.1722","62.2509","228.7719"
"37.2000","9.2787","9.2787","6.1858","62.3602","229.1738"
"37.2800","9.2989","9.2989","6.1993","62.4648","229.5582"
"37.3600","9.3191","9.3191","6.2128","62.5702","229.9454"
"37.4400","9.3389","9.3389","6.2259","62.6677","230.3039"
"37.5200","9.3580","9.3580","6.2387","62.7754","230.6997"
"37.6000","9.3784","9.3784","6.2523","62.8784","231.0780"
"37.6800","9.3973","9.3973","6.2648","62.9695","231.4131"
"37.7600","9.4178","9.4178","6.2786","63.0777","231.8104"
"37.8400","9.4389","9.4389","6.2926","63.1890","232.2195"
"37.9200","9.4590","9.4590","6.3060","63.2887","232.5860"
"38.0000","9.4787","9.4787","6.3191","63.3849","232.9396"
"38.0800","9.4983","9.4983","6.3322","63.4786","233.2840"
"38.1600","9.5172","9.5172","6.3448","63.5727","233.6296"
"38.2400","9.5385","9.5385","6.3590","63.6852","234.0431"
"38.3200","9.5579","9.5579","6.3719","63.7773","234.3815"
"38.4000","9.5790","9.5790","6.3860","63.8838","234.7730"
"38.4800","9.5992","9.5992","6.3995","63.9827","235.1364"
"38.5600","9.6185","9.6185","6.4123","64.0749","235.4754"
"38.6400","9.6385","9.6385","6.4257","64.1723","235.8331"
"38.7200","9.6582","9.6582","6.4388","64.2645","236.1719"
"38.8000","9.6781","9.6781","6.4521","64.3625","236.5321"
"38.8800","9.6981","9.6981","6.4654","64.4575","236.8814"
"38.9600","9.7171","9.7171","6.4781","64.5456","237.2051"
"39.0400","9.7381","9.7381","6.4921","64.6484","237.5831"
"39.1200","9.7591","9.7591","6.5061","64.7509","237.9597"
"39.2000","9.7791","9.7791","6.5194","64.8456","238.3078"
"39.2800","9.7991","9.7992","6.5328","64.9384","238.6486"
"39.3600","9.8174","9.8174","6.5450","65.0145","238.9282"
"39.4400","9.8385","9.8385","6.5590","65.1169","239.3047"
"39.5200","9.8585","9.8585","6.5723","65.2112","239.6512"
"39.6000","9.8780","9.8780","6.5854","65.3000","239.9774"
"39.6800","9.8987","9.8987","6.5991","65.3997","240.3438"
"39.7600","9.9194","9.9194","6.6129","65.4968","240.7008"
"39.8400","9.9386","9.9386","6.6258","65.5772","240.9962"
"39.9200","9.9589","9.9589","6.6393","65.6692","241.3341"
"40.0000","9.9775","9.9775","6.6517","65.7456","241.6150"
"40.0800","9.9985","9.9985","6.6656","65.8483","241.9926"
"40.1600","10.0181","10.0181","6.6787","65.9365","242.3165"
"40.2400","10.0377","10.0377","6.6918","66.0223","242.6319"
"40.3200","10.0586","10.0586","6.7057","66.1213","242.9957"
"40.4000","10.0786","10.0786","6.7191","66.2064","243.3087"
"40.4800","10.0985","10.0985","6.7323","66.2965","243.6398"
"40.5600","10.1187","10.1187","6.7458","66.3836","243.9597"
"40.6400","10.1375","10.1375","6.7583","66.4606","244.2426"
"40.7200","10.1583","10.1583","6.7722","66.5546","244.5882"
"40.8000","10.1779","10.1779","6.7853","66.6349","244.8832"
"40.8800","10.1985","10.1985","6.7990","66.7300","245.2328"
"40.9600","10.2194","10.2194","6.8130","66.8224","245.5723"
"41.0400","10.2392","10.2392","6.8261","66.9042","245.8731"
"41.1200","10.2591","10.2591","6.8394","66.9838","246.1656"
"41.2000","10.2784","10.2784","6.8523","67.0609","246.4486"
"41.2800","10.2978","10.2978","6.8652","67.1453","246.7591"
"41.3600","10.3180","10.3180","6.8786","67.2305","247.0722"
"41.4400","10.3374","10.3374","6.8916","67.3027","247.3372"
"41.5200","10.3579","10.3579","6.9052","67.3912","247.6628"
"41.6000","10.3795","10.3795","6.9197","67.4856","248.0097"
"41.6800","10.3983","10.3983","6.9322","67.5575","248.2738"
"41.7600","10.4187","10.4187","6.9458","67.6388","248.5726"
"41.8400","10.4381","10.4381","6.9587","67.7129","248.8447"
"41.9200","10.4584","10.4584","6.9723","67.7977","249.1566"
"42.0000","10.4779","10.4779","6.9853","67.8729","249.4330"
"42.0800","10.4975","10.4975","6.9984","67.9469","249.7047"
"42.1600","10.5185","10.5185","7.0123","68.0336","250.0235"
"42.2400","10.5401","10.5401","7.0267","68.1218","250.3476"
"42.3200","10.5590","10.5590","7.0393","68.1894","250.5959"
"42.4000","10.5788","10.5788","7.0525","68.2645","250.8721"
"42.4800","10.5975","10.5975","7.0650","68.3290","251.1090"
"42.5600","10.6182","10.6182","7.0788","68.4106","251.4091"
"42.6400","10.6386","10.6386","7.0924","68.4901","251.7009"
"42.7200","10.6576","10.6576","7.1051","68.5549","251.9391"
"42.8000","10.6779","10.6779","7.1186","68.6331","252.2267"
"42.8800","10.6989","10.6989","7.1326","68.7163","252.5323"
"42.9600","10.7189","10.7189","7.1459","68.7859","252.7880"
"43.0400","10.7389","10.7389","7.1593","68.8610","253.0640"
"43.1200","10.7581","10.7581","7.1721","68.9204","253.2824"
"43.2000","10.7781","10.7781","7.1854","68.9935","253.5512"
"43.2800","10.7983","10.7983","7.1989","69.0657","253.8165"
"43.3600","10.8176","10.8176","7.2117","69.1338","254.0667"
"43.4400","10.8398","10.8398","7.2265","69.2271","254.4095"
"43.5200","10.8588","10.8588","7.2392","69.2855","254.6243"
"43.6000","10.8796","10.8796","7.2531","69.3600","254.8979"
"43.6800","10.8985","10.8985","7.2657","69.4181","255.1116"
"43.7600","10.9175","10.9175","7.2783","69.4775","255.3300"
"43.8400","10.9377","10.9377","7.2918","69.5514","255.6013"
"43.9200","10.9583","10.9583","7.3055","69.6181","255.8465"
"44.0000","10.9776","10.9776","7.3184","69.6815","256.0795"
"44.0800","10.9988","10.9988","7.3325","69.7574","256.3586"
"44.1600","11.0181","11.0181","7.3454","69.8157","256.5726"
"44.2400","11.0392","11.0392","7.3595","69.8878","256.8377"
"44.3200","11.0586","11.0586","7.3724","69.9451","257.0481"
"44.4000","11.0780","11.0780","7.3854","70.0103","257.2879"
"44.4800","11.0979","11.0979","7.3986","70.0711","257.5114"
"44.5600","11.1178","11.1178","7.4119","70.1322","257.7360"
"44.6400","11.1388","11.1388","7.4259","70.2009","257.9885"
"44.7200","11.1601","11.1601","7.4401","70.2726","258.2520"
"44.8000","11.1786","11.1786","7.4524","70.3200","258.4261"
"44.8800","11.1985","11.1985","7.4657","70.3818","258.6530"
"44.9600","11.2185","11.2185","7.4790","70.4415","258.8726"
"45.0400","11.2382","11.2382","7.4922","70.5012","259.0918"
"45.1200","11.2584","11.2584","7.5056","70.5591","259.3046"
"45.2000","11.2764","11.2764","7.5176","70.5992","259.4521"
"45.2800","11.2980","11.2980","7.5320","70.6721","259.7199"
"45.3600","11.3191","11.3191","7.5461","70.7386","259.9644"
"45.4400","11.3398","11.3398","7.5599","70.8091","260.2235"
"45.5200","11.3593","11.3593","7.5729","70.8617","260.4166"
"45.6000","11.3783","11.3783","7.5855","70.9044","260.5737"
"45.6800","11.3976","11.3976","7.5984","70.9601","260.7782"
"45.7600","11.4180","11.4180","7.6120","71.0198","260.9979"
"45.8400","11.4376","11.4376","7.6251","71.0729","261.1928"
"45.9200","11.4596","11.4596","7.6398","71.1438","261.4533"
"46.0000","11.4792","11.4792","7.6528","71.1940","261.6381"
"46.0800","11.4987","11.4987","7.6658","71.2423","261.8153"
"46.1600","11.5181","11.5181","7.6787","71.2965","262.0147"
"46.2400","11.5382","11.5382","7.6921","71.3491","262.2080"
"46.3200","11.5583","11.5583","7.7055","71.4056","262.4155"
"46.4000","11.5783","11.5783","7.7189","71.4578","262.6073"
"46.4800","11.5973","11.5973","7.7315","71.5041","262.7775"
"46.5600","11.6177","11.6177","7.7451","71.5605","262.9850"
"46.6400","11.6384","11.6384","7.7589","71.6202","263.2041"
"46.7200","11.6596","11.6596","7.7731","71.6799","263.4236"
"46.8000","11.6791","11.6791","7.7860","71.7220","263.5784"
"46.8800","11.6977","11.6977","7.7985","71.7637","263.7317"
"46.9600","11.7180","11.7180","7.8120","71.8142","263.9173"
"47.0400","11.7382","11.7382","7.8254","71.8680","264.1150"
"47.1200","11.7583","11.7583","7.8389","71.9186","264.3009"
"47.2000","11.7789","11.7789","7.8526","71.9711","264.4937"
"47.2800","11.7988","11.7988","7.8659","72.0174","264.6638"
"47.3600","11.8188","11.8188","7.8792","72.0655","264.8408"
"47.4400","11.8391","11.8391","7.8927","72.1119","265.0111"
"47.5200","11.8578","11.8578","7.9052","72.1512","265.1557"
"47.6000","11.8778","11.8778","7.9185","72.1953","265.3178"
"47.6800","11.8972","11.8972","7.9315","72.2388","265.4777"
"47.7600","11.9183","11.9183","7.9455","72.2943","265.6816"
"47.8400","11.9390","11.9390","7.9593","72.3437","265.8630"
"47.9200","11.9590","11.9590","7.9727","72.3884","266.0273"
"48.0000","11.9787","11.9787","7.9858","72.4286","266.1750"
"48.0800","11.9986","11.9986","7.9991","72.4704","266.3287"
"48.1600","12.0173","12.0173","8.0116","72.5068","266.4625"
"48.2400","12.0383","12.0383","8.0255","72.5564","266.6449"
"48.3200","12.0578","12.0578","8.0385","72.5939","266.7828"
"48.4000","12.0789","12.0789","8.0526","72.6450","266.9703"
"48.4800","12.0993","12.0993","8.0662","72.6851","267.1178"
"48.5600","12.1187","12.1187","8.0791","72.7272","267.2725"
"48.6400","12.1385","12.1385","8.0923","72.7654","267.4127"
"48.7200","12.1586","12.1586","8.1057","72.8057","267.5611"
"48.8000","12.1782","12.1782","8.1188","72.8404","267.6886"
"48.8800","12.1988","12.1988","8.1325","72.8901","267.8711"
"48.9600","12.2171","12.2171","8.1447","72.9170","267.9701"
"49.0400","12.2382","12.2382","8.1588","72.9657","268.1490"
"49.1200","12.2593","12.2593","8.1728","73.0090","268.3082"
"49.2000","12.2792","12.2792","8.1861","73.0473","268.4490"
"49.2800","12.2987","12.2987","8.1991","73.0796","268.5675"
"49.3600","12.3174","12.3174","8.2116","73.1061","268.6650"
"49.4400","12.3387","12.3387","8.2258","73.1546","268.8430"
"49.5200","12.3590","12.3590","8.2394","73.1918","268.9798"
"49.6000","12.3780","12.3780","8.2520","73.2237","269.0970"
"49.6800","12.3986","12.3986","8.2657","73.2655","269.2509"
"49.7600","12.4190","12.4190","8.2794","73.2966","269.3652"
"49.8400","12.4390","12.4390","8.2927","73.3323","269.4960"
"49.9200","12.4592","12.4592","8.3062","73.3637","269.6116"
"50.0000","12.4768","12.4768","8.3179","73.3790","269.6679"
"50.0800","12.4984","12.4984","8.3322","73.4267","269.8433"
"50.1600","12.5180","12.5180","8.3453","73.4511","269.9327"
"50.2400","12.5381","12.5381","8.3588","73.4886","270.0707"
"50.3200","12.5583","12.5583","8.3722","73.5190","270.1822"
"50.4000","12.5788","12.5788","8.3859","73.5489","270.2922"
"50.4800","12.5984","12.5984","8.3990","73.5757","270.3907"
"50.5600","12.6185","12.6185","8.4123","73.6039","270.4942"
"50.6400","12.6375","12.6375","8.4250","73.6268","270.5784"
"50.7200","12.6585","12.6585","8.4390","73.6655","270.7206"
"50.8000","12.6783","12.6783","8.4522","73.6979","270.8396"
"50.8800","12.6984","12.6984","8.4656","73.7283","270.9514"
"50.9600","12.7193","12.7193","8.4796","73.7627","271.0781"
"51.0400","12.7389","12.7389","8.4926","73.7876","271.1694"
"51.1200","12.7593","12.7593","8.5062","73.8155","271.2718"
"51.2000","12.7787","12.7787","8.5192","73.8352","271.3445"
"51.2800","12.7979","12.7979","8.5319","73.8599","271.4352"
"51.3600","12.8178","12.8178","8.5452","73.8875","271.5365"
"51.4400","12.8375","12.8375","8.5583","73.9091","271.6161"
"51.5200","12.8580","12.8580","8.5720","73.9413","271.7342"
"51.6000","12.8795","12.8795","8.5864","73.9740","271.8544"
"51.6800","12.8984","12.8984","8.5990","73.9858","271.8976"
"51.7600","12.9187","12.9187","8.6125","74.0121","271.9944"
"51.8400","12.9382","12.9382","8.6255","74.0254","272.0434"
"51.9200","12.9584","12.9584","8.6389","74.0484","272.1280"
"52.0000","12.9778","12.9778","8.6519","74.0654","272.1904"
"52.0800","12.9976","12.9976","8.6651","74.0867","272.2687"
"52.1600","13.0186","13.0186","8.6791","74.1161","272.3767"
"52.2400","13.0398","13.0398","8.6932","74.1446","272.4813"
"52.3200","13.0591","13.0591","8.7060","74.1610","272.5416"
"52.4000","13.0781","13.0781","8.7187","74.1745","272.5913"
"52.4800","13.0977","13.0977","8.7318","74.1913","272.6531"
"52.5600","13.1186","13.1186","8.7457","74.2153","272.7411"
"52.6400","13.1387","13.1387","8.7591","74.2352","272.8143"
"52.7200","13.1576","13.1576","8.7717","74.2474","272.8591"
"52.8000","13.1783","13.1783","8.7855","74.2728","272.9525"
"52.8800","13.1992","13.1992","8.7995","74.2970","273.0414"
"52.9600","13.2189","13.2189","8.8126","74.3119","273.0963"
"53.0400","13.2388","13.2388","8.8259","74.3289","273.1588"
"53.1200","13.2579","13.2579","8.8386","74.3375","273.1902"
"53.2000","13.2785","13.2785","8.8523","74.3604","273.2745"
"53.2800","13.2984","13.2984","8.8656","74.3732","273.3214"
"53.3600","13.3173","13.3173","8.8782","74.3871","273.3726"
"53.4400","13.3394","13.3394","8.8929","74.4176","273.4847"
"53.5200","13.3593","13.3593","8.9062","74.4292","273.5272"
"53.6000","13.3798","13.3798","8.9198","74.4462","273.5897"
"53.6800","13.3986","13.3986","8.9324","74.4520","273.6111"
"53.7600","13.4176","13.4176","8.9450","74.4627","273.6504"
"53.8400","13.4377","13.4377","8.9585","74.4790","273.7104"
"53.9200","13.4582","13.4582","8.9722","74.4932","273.7626"
"54.0000","13.4776","13.4776","8.9850","74.5068","273.8124"
"54.0800","13.4987","13.4987","8.9991","74.5278","273.8896"
"54.1600","13.5178","13.5178","9.0119","74.5295","273.8958"
"54.2400","13.5394","13.5394","9.0262","74.5513","273.9760"
"54.3200","13.5585","13.5585","9.0390","74.5560","273.9932"
"54.4000","13.5779","13.5779","9.0520","74.5663","274.0310"
"54.4800","13.5979","13.5979","9.0652","74.5820","274.0887"
"54.5600","13.6181","13.6181","9.0787","74.5899","274.1180"
"54.6400","13.6388","13.6388","9.0925","74.6061","274.1773"
"54.7200","13.6602","13.6602","9.1068","74.6249","274.2463"
"54.8000","13.6786","13.6786","9.1191","74.6243","274.2444"
"54.8800","13.6986","13.6986","9.1324","74.6334","274.2778"
"54.9600","13.7183","13.7183","9.1456","74.6404","274.3034"
"55.0400","13.7381","13.7381","9.1587","74.6498","274.3381"
"55.1200","13.7582","13.7582","9.1721","74.6607","274.3781"
"55.2000","13.7772","13.7772","9.1848","74.6620","274.3827"
"55.2800","13.7979","13.7979","9.1986","74.6731","274.4238"
"55.3600","13.8188","13.8188","9.2125","74.6857","274.4701"
"55.4400","13.8392","13.8392","9.2261","74.7003","274.5237"
"55.5200","13.8591","13.8591","9.2394","74.7054","274.5422"
"55.6000","13.8782","13.8782","9.2522","74.7030","274.5334"
"55.6800","13.8979","13.8979","9.2653","74.7114","274.5644"
"55.7600","13.9186","13.9186","9.2790","74.7179","274.5883"
"55.8400","13.9374","13.9374","9.2916","74.7169","274.5847"
"55.9200","13.9595","13.9595","9.3064","74.7379","274.6620"
"56.0000","13.9793","13.9793","9.3195","74.7393","274.6670"
"56.0800","13.9988","13.9988","9.3326","74.7436","274.6828"
"56.1600","14.0181","14.0181","9.3454","74.7444","274.6859"
"56.2400","14.0381","14.0381","9.3588","74.7484","274.7002"
"56.3200","14.0586","14.0586","9.3724","74.7574","274.7334"
"56.4000","14.0789","14.0789","9.3859","74.7628","274.7532"
"56.4800","14.0971","14.0971","9.3980","74.7558","274.7275"
"56.5600","14.1182","14.1182","9.4122","74.7659","274.7645"
"56.6400","14.1389","14.1389","9.4259","74.7669","274.7685"
"56.7200","14.1593","14.1593","9.4395","74.7689","274.7756"
"56.8000","14.1789","14.1789","9.4526","74.7613","274.7477"
"56.8800","14.1976","14.1976","9.4651","74.7540","274.7209"
"56.9600","14.2181","14.2181","9.4788","74.7520","274.7138"
"57.0400","14.2382","14.2382","9.4921","74.7509","274.7097"
"57.1200","14.2584","14.2584","9.5056","74.7485","274.7007"
"57.2000","14.2791","14.2791","9.5194","74.7530","274.7172"
"57.2800","14.2988","14.2988","9.5326","74.7435","274.6824"
"57.3600","14.3192","14.3192","9.5461","74.7423","274.6780"
"57.4400","14.3391","14.3391","9.5594","74.7347","274.6499"
"57.5200","14.3574","14.3574","9.5716","74.7254","274.6158"
"57.6000","14.3782","14.3782","9.5855","74.7284","274.6267"
"57.6800","14.3975","14.3975","9.5983","74.7181","274.5890"
"57.7600","14.4180","14.4180","9.6120","74.7158","274.5806"
"57.8400","14.4390","14.4390","9.6260","74.7121","274.5670"
"57.9200","14.4588","14.4588","9.6392","74.7023","274.5308"
"58.0000","14.4785","14.4785","9.6523","74.6922","274.4937"
"58.0800","14.4984","14.4984","9.6656","74.6804","274.4505"
"58.1600","14.5175","14.5175","9.6783","74.6662","274.3982"
"58.2400","14.5385","14.5385","9.6923","74.6630","274.3867"
"58.3200","14.5581","14.5581","9.7054","74.6512","274.3432"
"58.4000","14.5790","14.5790","9.7194","74.6437","274.3156"
"58.4800","14.5991","14.5991","9.7327","74.6308","274.2684"
"58.5600","14.6187","14.6187","9.7458","74.6187","274.2238"
"58.6400","14.6387","14.6387","9.7591","74.6054","274.1749"
"58.7200","14.6585","14.6585","9.7724","74.5898","274.1176"
"58.8000","14.6783","14.6783","9.7855","74.5759","274.0665"
"58.8800","14.6981","14.6981","9.7987","74.5641","274.0232"
"58.9600","14.7170","14.7170","9.8113","74.5419","273.9415"
"59.0400","14.7383","14.7383","9.8255","74.5384","273.9286"
"59.1200","14.7593","14.7593","9.8395","74.5287","273.8931"
"59.2000","14.7786","14.7786","9.8524","74.5085","273.8188"
"59.2800","14.7987","14.7987","9.8658","74.4912","273.7553"
"59.3600","14.8178","14.8178","9.8785","74.4696","273.6758"
"59.4400","14.8385","14.8385","9.8924","74.4584","273.6347"
"59.5200","14.8588","14.8588","9.9059","74.4415","273.5725"
"59.6000","14.8781","14.8781","9.9187","74.4235","273.5065"
"59.6800","14.8986","14.8986","9.9324","74.4093","273.4540"
"59.7600","14.9189","14.9189","9.9459","74.3881","273.3763"
"59.8400","14.9386","14.9386","9.9591","74.3690","273.3062"
"59.9200","14.9587","14.9587","9.9724","74.3459","273.2213"
"60.0000","14.9777","14.9777","9.9851","74.3210","273.1296"
"60.0800","14.9984","14.9984","9.9990","74.2962","273.0384"
"60.0870","15.0001","15.0001","10.0001","74.2924","273.0246"