File: data/instron_tests/metamaterial_samples/553_VERT_m1.is_comp_Exports/553_VERT_m1_6_1.csv
Sample text inputs : Sample No.,Sample choice input : Leading Direction,Sample choice input : Mode,Specimen choice input : Direction,Specimen properties : Height,Specimen properties : Thickness,Specimen properties : Width,Test : Rate 1
,,,,(mm),(mm),(mm),(mm/min)
"553","Vertical","Unimode","1","147.00","25.00","150.00","15.00"

Time,Displacement,Compressive displacement,Compressive strain (Displacement),Compressive stress,Force
(s),(mm),(mm),(%),(kPa),(N)
"0.0000","-0.0002","-0.0002","-0.0001","-0.8168","-3.0631"
"0.0800","0.0011","0.0011","0.0007","-0.8171","-3.0643"
"0.1600","0.0100","0.0100","0.0067","-0.8030","-3.0113"
"0.2400","0.0292","0.0292","0.0195","-0.7627","-2.8601"
"0.3200","0.0500","0.0500","0.0333","-0.7247","-2.7177"
"0.4000","0.0694","0.0694","0.0463","-0.6881","-2.5803"
"0.4800","0.0880","0.0880","0.0586","-0.6517","-2.4439"
"0.5600","0.1088","0.1088","0.0726","-0.6134","-2.3003"
"0.6400","0.1286","0.1286","0.0857","-0.5797","-2.1737"
"0.7200","0.1493","0.1493","0.0995","-0.5432","-2.0368"
"0.8000","0.1704","0.1704","0.1136","-0.5102","-1.9134"
"0.8800","0.1900","0.1900","0.1267","-0.4769","-1.7885"
"0.9600","0.2105","0.2105","0.1404","-0.4432","-1.6620"
"1.0400","0.2297","0.2297","0.1531","-0.4109","-1.5410"
"1.1200","0.2493","0.2493","0.1662","-0.3802","-1.4257"
"1.2000","0.2691","0.2691","0.1794","-0.3495","-1.3105"
"1.2800","0.2894","0.2894","0.1930","-0.3187","-1.1951"
"1.3600","0.3101","0.3101","0.2068","-0.2862","-1.0733"
"1.4400","0.3311","0.3311","0.2207","-0.2555","-0.9580"
"1.5200","0.3498","0.3498","0.2332","-0.2243","-0.8412"
"1.6000","0.3701","0.3701","0.2467","-0.1953","-0.7324"
"1.6800","0.3895","0.3895","0.2597","-0.1622","-0.6083"
"1.7600","0.4099","0.4099","0.2733","-0.1320","-0.4952"
"1.8400","0.4297","0.4297","0.2864","-0.0986","-0.3697"
"1.9200","0.4485","0.4485","0.2990","-0.0655","-0.2456"
"2.0000","0.4696","0.4696","0.3131","-0.0332","-0.1246"
"2.0800","0.4908","0.4908","0.3272","0.0020","0.0076"
"2.1600","0.5103","0.5103","0.3402","0.0344","0.1290"
"2.2400","0.5296","0.5296","0.3531","0.0650","0.2436"
"2.3200","0.5488","0.5488","0.3659","0.0949","0.3559"
"2.4000","0.5697","0.5697","0.3798","0.1304","0.4888"
"2.4800","0.5907","0.5907","0.3938","0.1658","0.6218"
"2.5600","0.6097","0.6097","0.4065","0.2019","0.7573"
"2.6400","0.6297","0.6297","0.4198","0.2368","0.8882"
"2.7200","0.6500","0.6500","0.4333","0.2707","1.0151"
"2.8000","0.6711","0.6711","0.4474","0.3096","1.1608"
"2.8800","0.6904","0.6904","0.4603","0.3420","1.2824"
"2.9600","0.7093","0.7093","0.4728","0.3708","1.3904"
"3.0400","0.7295","0.7295","0.4864","0.4059","1.5220"
"3.1200","0.7497","0.7497","0.4998","0.4424","1.6591"
"3.2000","0.7690","0.7690","0.5127","0.4758","1.7844"
"3.2800","0.7905","0.7905","0.5270","0.5160","1.9350"
"3.3600","0.8100","0.8100","0.5400","0.5497","2.0615"
"3.4400","0.8304","0.8304","0.5536","0.5860","2.1975"
"3.5200","0.8499","0.8499","0.5666","0.6193","2.3225"
"3.6000","0.8691","0.8691","0.5794","0.6554","2.4579"
"3.6800","0.8899","0.8899","0.5933","0.6921","2.5952"
"3.7600","0.9098","0.9098","0.6066","0.7253","2.7199"
"3.8400","0.9299","0.9299","0.6200","0.7617","2.8565"
"3.9200","0.9506","0.9506","0.6337","0.7996","2.9984"
"4.0000","0.9701","0.9701","0.6467","0.8384","3.1441"
"4.0800","0.9911","0.9911","0.6608","0.8713","3.2673"
"4.1600","1.0103","1.0103","0.6735","0.9079","3.4046"
"4.2400","1.0289","1.0289","0.6859","0.9391","3.5215"
"4.3200","1.0493","1.0493","0.6995","0.9788","3.6705"
"4.4000","1.0688","1.0688","0.7125","1.0108","3.7906"
"4.4800","1.0903","1.0903","0.7269","1.0498","3.9366"
"4.5600","1.1107","1.1107","0.7405","1.0862","4.0732"
"4.6400","1.1300","1.1300","0.7533","1.1220","4.2076"
"4.7200","1.1495","1.1495","0.7663","1.1542","4.3283"
"4.8000","1.1694","1.1694","0.7796","1.1877","4.4539"
"4.8800","1.1895","1.1895","0.7930","1.2231","4.5865"
"4.9600","1.2103","1.2103","0.8069","1.2584","4.7189"
"5.0400","1.2289","1.2289","0.8192","1.2931","4.8492"
"5.1200","1.2504","1.2504","0.8336","1.3340","5.0025"
"5.2000","1.2703","1.2703","0.8469","1.3666","5.1247"
"5.2800","1.2907","1.2907","0.8604","1.4041","5.2653"
"5.3600","1.3103","1.3103","0.8735","1.4400","5.3999"
"5.4400","1.3296","1.3296","0.8864","1.4740","5.5275"
"5.5200","1.3493","1.3493","0.8995","1.5097","5.6614"
"5.6000","1.3700","1.3700","0.9133","1.5477","5.8038"
"5.6800","1.3888","1.3888","0.9259","1.5848","5.9430"
"5.7600","1.4104","1.4104","0.9402","1.6285","6.1067"
"5.8400","1.4305","1.4305","0.9537","1.6612","6.2296"
"5.9200","1.4502","1.4502","0.9668","1.6967","6.3627"
"6.0000","1.4702","1.4702","0.9802","1.7327","6.4976"
"6.0800","1.4892","1.4892","0.9928","1.7678","6.6294"
"6.1600","1.5097","1.5097","1.0064","1.8054","6.7703"
"6.2400","1.5297","1.5297","1.0198","1.8431","6.9116"
"6.3200","1.5492","1.5492","1.0328","1.8819","7.0573"
"6.4000","1.5706","1.5706","1.0471","1.9238","7.2142"
"6.4800","1.5909","1.5909","1.0606","1.9605","7.3518"
"6.5600","1.6107","1.6107","1.0738","1.9973","7.4898"
"6.6400","1.6306","1.6306","1.0870","2.0343","7.6288"
"6.7200","1.6487","1.6487","1.0991","2.0706","7.7647"
"6.8000","1.6699","1.6699","1.1132","2.1093","7.9097"
"6.8800","1.6895","1.6895","1.1263","2.1451","8.0441"
"6.9600","1.7098","1.7098","1.1399","2.1825","8.1844"
"7.0400","1.7298","1.7298","1.1532","2.2222","8.3332"
"7.1200","1.7498","1.7498","1.1666","2.2582","8.4681"
"7.2000","1.7702","1.7702","1.1802","2.2975","8.6156"
"7.2800","1.7905","1.7905","1.1936","2.3368","8.7628"
"7.3600","1.8091","1.8091","1.2061","2.3715","8.8930"
"7.4400","1.8299","1.8299","1.2199","2.4137","9.0513"
"7.5200","1.8485","1.8485","1.2323","2.4456","9.1710"
"7.6000","1.8695","1.8695","1.2463","2.4860","9.3224"
"7.6800","1.8913","1.8913","1.2609","2.5275","9.4783"
"7.7600","1.9105","1.9105","1.2737","2.5647","9.6177"
"7.8400","1.9301","1.9301","1.2867","2.6013","9.7548"
"7.9200","1.9499","1.9499","1.3000","2.6407","9.9028"
"8.0000","1.9694","1.9694","1.3129","2.6801","10.0504"
"8.0800","1.9896","1.9896","1.3264","2.7182","10.1933"
"8.1600","2.0088","2.0088","1.3392","2.7539","10.3272"
"8.2400","2.0300","2.0300","1.3534","2.7954","10.4827"
"8.3200","2.0508","2.0508","1.3672","2.8341","10.6279"
"8.4000","2.0697","2.0697","1.3798","2.8721","10.7705"
"8.4800","2.0902","2.0902","1.3935","2.9130","10.9236"
"8.5600","2.1093","2.1093","1.4062","2.9480","11.0552"
"8.6400","2.1298","2.1298","1.4198","2.9881","11.2053"
"8.7200","2.1500","2.1500","1.4333","3.0262","11.3484"
"8.8000","2.1693","2.1693","1.4462","3.0661","11.4979"
"8.8800","2.1904","2.1904","1.4603","3.1079","11.6546"
"8.9600","2.2110","2.2110","1.4740","3.1472","11.8019"
"9.0400","2.2302","2.2302","1.4868","3.1864","11.9488"
"9.1200","2.2500","2.2500","1.5000","3.2212","12.0796"
"9.2000","2.2690","2.2690","1.5127","3.2587","12.2202"
"9.2800","2.2900","2.2900","1.5267","3.2990","12.3714"
"9.3600","2.3098","2.3098","1.5399","3.3384","12.5189"
"9.4400","2.3287","2.3287","1.5525","3.3778","12.6668"
"9.5200","2.3493","2.3493","1.5662","3.4217","12.8312"
"9.6000","2.3701","2.3701","1.5801","3.4611","12.9791"
"9.6800","2.3905","2.3905","1.5937","3.4999","13.1248"
"9.7600","2.4105","2.4105","1.6070","3.5405","13.2770"
"9.8400","2.4289","2.4289","1.6192","3.5768","13.4129"
"9.9200","2.4496","2.4496","1.6330","3.6181","13.5678"
"10.0000","2.4696","2.4696","1.6464","3.6575","13.7156"
"10.0800","2.4899","2.4899","1.6599","3.6969","13.8632"
"10.1600","2.5109","2.5109","1.6739","3.7417","14.0312"
"10.2400","2.5301","2.5301","1.6868","3.7793","14.1723"
"10.3200","2.5501","2.5501","1.7001","3.8166","14.3123"
"10.4000","2.5700","2.5700","1.7133","3.8589","14.4709"
"10.4800","2.5894","2.5894","1.7263","3.8980","14.6176"
"10.5600","2.6101","2.6101","1.7401","3.9415","14.7805"
"10.6400","2.6290","2.6290","1.7527","3.9765","14.9117"
"10.7200","2.6492","2.6492","1.7661","4.0182","15.0681"
"10.8000","2.6709","2.6709","1.7806","4.0575","15.2158"
"10.8800","2.6901","2.6901","1.7934","4.1009","15.3783"
"10.9600","2.7107","2.7107","1.8072","4.1403","15.5261"
"11.0400","2.7297","2.7297","1.8198","4.1799","15.6746"
"11.1200","2.7492","2.7492","1.8328","4.2178","15.8168"
"11.2000","2.7694","2.7694","1.8463","4.2610","15.9787"
"11.2800","2.7898","2.7898","1.8599","4.3018","16.1316"
"11.3600","2.8101","2.8101","1.8734","4.3408","16.2781"
"11.4400","2.8308","2.8308","1.8872","4.3814","16.4302"
"11.5200","2.8497","2.8497","1.8998","4.4199","16.5745"
"11.6000","2.8702","2.8702","1.9134","4.4622","16.7331"
"11.6800","2.8895","2.8895","1.9263","4.5015","16.8807"
"11.7600","2.9098","2.9098","1.9398","4.5413","17.0298"
"11.8400","2.9297","2.9297","1.9531","4.5796","17.1733"
"11.9200","2.9486","2.9486","1.9657","4.6192","17.3219"
"12.0000","2.9698","2.9698","1.9799","4.6629","17.4860"
"12.0800","2.9907","2.9907","1.9938","4.7049","17.6433"
"12.1600","3.0100","3.0100","2.0067","4.7435","17.7882"
"12.2400","3.0298","3.0298","2.0198","4.7848","17.9429"
"12.3200","3.0490","3.0490","2.0327","4.8225","18.0843"
"12.4000","3.0699","3.0699","2.0466","4.8657","18.2463"
"12.4800","3.0903","3.0903","2.0602","4.9057","18.3962"
"12.5600","3.1094","3.1094","2.0730","4.9450","18.5439"
"12.6400","3.1302","3.1302","2.0868","4.9900","18.7125"
"12.7200","3.1503","3.1503","2.1002","5.0313","18.8675"
"12.8000","3.1701","3.1701","2.1134","5.0679","19.0046"
"12.8800","3.1900","3.1900","2.1267","5.1093","19.1599"
"12.9600","3.2096","3.2096","2.1397","5.1513","19.3173"
"13.0400","3.2297","3.2297","2.1531","5.1916","19.4684"
"13.1200","3.2493","3.2493","2.1662","5.2320","19.6198"
"13.2000","3.2686","3.2686","2.1790","5.2713","19.7673"
"13.2800","3.2902","3.2902","2.1934","5.3174","19.9402"
"13.3600","3.3102","3.3102","2.2068","5.3589","20.0959"
"13.4400","3.3304","3.3304","2.2203","5.3987","20.2452"
"13.5200","3.3499","3.3499","2.2333","5.4388","20.3954"
"13.6000","3.3688","3.3688","2.2459","5.4776","20.5409"
"13.6800","3.3898","3.3898","2.2599","5.5220","20.7076"
"13.7600","3.4098","3.4098","2.2732","5.5617","20.8563"
"13.8400","3.4299","3.4299","2.2866","5.6027","21.0099"
"13.9200","3.4509","3.4509","2.3006","5.6463","21.1737"
"14.0000","3.4703","3.4703","2.3135","5.6883","21.3310"
"14.0800","3.4907","3.4907","2.3271","5.7303","21.4886"
"14.1600","3.5099","3.5099","2.3399","5.7701","21.6379"
"14.2400","3.5289","3.5289","2.3526","5.8088","21.7828"
"14.3200","3.5494","3.5494","2.3662","5.8515","21.9431"
"14.4000","3.5688","3.5688","2.3792","5.8916","22.0934"
"14.4800","3.5901","3.5901","2.3934","5.9347","22.2550"
"14.5600","3.6110","3.6110","2.4073","5.9770","22.4136"
"14.6400","3.6298","3.6298","2.4199","6.0201","22.5753"
"14.7200","3.6496","3.6496","2.4331","6.0619","22.7323"
"14.8000","3.6696","3.6696","2.4464","6.1028","22.8854"
"14.8800","3.6896","3.6896","2.4597","6.1428","23.0356"
"14.9600","3.7103","3.7103","2.4736","6.1877","23.2040"
"15.0400","3.7287","3.7287","2.4858","6.2247","23.3428"
"15.1200","3.7501","3.7501","2.5000","6.2679","23.5046"
"15.2000","3.7706","3.7706","2.5137","6.3112","23.6669"
"15.2800","3.7906","3.7906","2.5271","6.3537","23.8263"
"15.3600","3.8100","3.8100","2.5400","6.3940","23.9776"
"15.4400","3.8293","3.8293","2.5529","6.4330","24.1236"
"15.5200","3.8493","3.8493","2.5662","6.4754","24.2827"
"15.6000","3.8701","3.8701","2.5801","6.5180","24.4423"
"15.6800","3.8888","3.8888","2.5925","6.5588","24.5955"
"15.7600","3.9102","3.9102","2.6068","6.6028","24.7604"
"15.8400","3.9300","3.9300","2.6200","6.6471","24.9267"
"15.9200","3.9503","3.9503","2.6336","6.6863","25.0737"
"16.0000","3.9702","3.9702","2.6468","6.7287","25.2325"
"16.0800","3.9894","3.9894","2.6596","6.7665","25.3743"
"16.1600","4.0100","4.0100","2.6733","6.8122","25.5456"
"16.2400","4.0297","4.0297","2.6865","6.8521","25.6954"
"16.3200","4.0493","4.0493","2.6995","6.8956","25.8583"
"16.4000","4.0707","4.0707","2.7138","6.9419","26.0321"
"16.4800","4.0906","4.0906","2.7271","6.9804","26.1767"
"16.5600","4.1105","4.1105","2.7403","7.0208","26.3279"
"16.6400","4.1303","4.1303","2.7535","7.0619","26.4822"
"16.7200","4.1488","4.1488","2.7658","7.1029","26.6360"
"16.8000","4.1697","4.1697","2.7798","7.1465","26.7995"
"16.8800","4.1892","4.1892","2.7928","7.1865","26.9494"
"16.9600","4.2096","4.2096","2.8064","7.2325","27.1218"
"17.0400","4.2301","4.2301","2.8201","7.2748","27.2807"
"17.1200","4.2499","4.2499","2.8333","7.3172","27.4394"
"17.2000","4.2700","4.2700","2.8467","7.3587","27.5952"
"17.2800","4.2907","4.2907","2.8605","7.4040","27.7650"
"17.3600","4.3095","4.3095","2.8730","7.4452","27.9193"
"17.4400","4.3297","4.3297","2.8865","7.4863","28.0736"
"17.5200","4.3485","4.3485","2.8990","7.5256","28.2211"
"17.6000","4.3703","4.3703","2.9135","7.5716","28.3936"
"17.6800","4.3914","4.3914","2.9276","7.6145","28.5544"
"17.7600","4.4104","4.4104","2.9403","7.6579","28.7173"
"17.8400","4.4302","4.4302","2.9535","7.6983","28.8687"
"17.9200","4.4496","4.4496","2.9664","7.7422","29.0333"
"18.0000","4.4692","4.4692","2.9795","7.7805","29.1769"
"18.0800","4.4901","4.4901","2.9934","7.8252","29.3446"
"18.1600","4.5088","4.5088","3.0059","7.8639","29.4896"
"18.2400","4.5298","4.5298","3.0199","7.9101","29.6628"
"18.3200","4.5507","4.5507","3.0338","7.9527","29.8225"
"18.4000","4.5699","4.5699","3.0466","7.9946","29.9797"
"18.4800","4.5902","4.5902","3.0601","8.0392","30.1469"
"18.5600","4.6093","4.6093","3.0729","8.0786","30.2947"
"18.6400","4.6297","4.6297","3.0865","8.1203","30.4512"
"18.7200","4.6498","4.6498","3.0999","8.1620","30.6076"
"18.8000","4.6694","4.6694","3.1129","8.2067","30.7750"
"18.8800","4.6904","4.6904","3.1269","8.2514","30.9426"
"18.9600","4.7112","4.7112","3.1408","8.2973","31.1150"
"19.0400","4.7305","4.7305","3.1536","8.3366","31.2622"
"19.1200","4.7501","4.7501","3.1667","8.3790","31.4211"
"19.2000","4.7691","4.7691","3.1794","8.4203","31.5760"
"19.2800","4.7900","4.7900","3.1934","8.4639","31.7394"
"19.3600","4.8095","4.8095","3.2063","8.5053","31.8948"
"19.4400","4.8286","4.8286","3.2191","8.5475","32.0532"
"19.5200","4.8494","4.8494","3.2330","8.5919","32.2195"
"19.6000","4.8702","4.8702","3.2468","8.6341","32.3777"
"19.6800","4.8902","4.8902","3.2602","8.6776","32.5409"
"19.7600","4.9106","4.9106","3.2738","8.7197","32.6989"
"19.8400","4.9293","4.9293","3.2862","8.7604","32.8516"
"19.9200","4.9495","4.9495","3.2997","8.8055","33.0205"
"20.0000","4.9694","4.9694","3.3129","8.8474","33.1776"
"20.0800","4.9899","4.9899","3.3266","8.8922","33.3457"
"20.1600","5.0110","5.0110","3.3407","8.9394","33.5226"
"20.2400","5.0303","5.0303","3.3535","8.9800","33.6750"
"20.3200","5.0504","5.0504","3.3669","9.0194","33.8227"
"20.4000","5.0698","5.0698","3.3799","9.0604","33.9767"
"20.4800","5.0893","5.0893","3.3929","9.1074","34.1526"
"20.5600","5.1099","5.1099","3.4066","9.1512","34.3168"
"20.6400","5.1290","5.1290","3.4193","9.1898","34.4617"
"20.7200","5.1493","5.1493","3.4329","9.2343","34.6284"
"20.8000","5.1706","5.1706","3.4471","9.2800","34.8001"
"20.8800","5.1897","5.1897","3.4598","9.3224","34.9588"
"20.9600","5.2109","5.2109","3.4739","9.3700","35.1375"
"21.0400","5.2300","5.2300","3.4866","9.4097","35.2866"
"21.1200","5.2492","5.2492","3.4995","9.4503","35.4385"
"21.2000","5.2691","5.2691","3.5127","9.4942","35.6034"
"21.2800","5.2893","5.2893","3.5262","9.5380","35.7676"
"21.3600","5.3104","5.3104","3.5402","9.5830","35.9364"
"21.4400","5.3313","5.3313","3.5542","9.6285","36.1069"
"21.5200","5.3498","5.3498","3.5665","9.6700","36.2624"
"21.6000","5.3701","5.3701","3.5800","9.7145","36.4294"
"21.6800","5.3896","5.3896","3.5931","9.7542","36.5782"
"21.7600","5.4098","5.4098","3.6066","9.7974","36.7404"
"21.8400","5.4298","5.4298","3.6199","9.8399","36.8997"
"21.9200","5.4488","5.4488","3.6325","9.8804","37.0516"
"22.0000","5.4700","5.4700","3.6467","9.9286","37.2322"
"22.0800","5.4907","5.4907","3.6605","9.9747","37.4050"
"22.1600","5.5102","5.5102","3.6735","10.0155","37.5580"
"22.2400","5.5301","5.5301","3.6868","10.0604","37.7266"
"22.3200","5.5489","5.5489","3.6993","10.1017","37.8813"
"22.4000","5.5697","5.5697","3.7131","10.1457","38.0466"
"22.4800","5.5904","5.5904","3.7269","10.1901","38.2128"
"22.5600","5.6095","5.6095","3.7397","10.2328","38.3729"
"22.6400","5.6303","5.6303","3.7536","10.2782","38.5433"
"22.7200","5.6500","5.6500","3.7667","10.3200","38.6999"
"22.8000","5.6706","5.6706","3.7804","10.3640","38.8649"
"22.8800","5.6905","5.6905","3.7936","10.4083","39.0311"
"22.9600","5.7091","5.7091","3.8060","10.4500","39.1874"
"23.0400","5.7294","5.7294","3.8196","10.4946","39.3546"
"23.1200","5.7497","5.7497","3.8331","10.5396","39.5235"
"23.2000","5.7686","5.7686","3.8457","10.5810","39.6789"
"23.2800","5.7905","5.7905","3.8603","10.6304","39.8639"
"23.3600","5.8098","5.8098","3.8732","10.6706","40.0147"
"23.4400","5.8304","5.8304","3.8870","10.7148","40.1806"
"23.5200","5.8498","5.8498","3.8999","10.7555","40.3331"
"23.6000","5.8693","5.8693","3.9128","10.8011","40.5040"
"23.6800","5.8897","5.8897","3.9265","10.8472","40.6770"
"23.7600","5.9095","5.9095","3.9397","10.8912","40.8420"
"23.8400","5.9299","5.9299","3.9533","10.9340","41.0025"
"23.9200","5.9511","5.9511","3.9674","10.9801","41.1752"
"24.0000","5.9703","5.9703","3.9802","11.0218","41.3318"
"24.0800","5.9903","5.9903","3.9935","11.0662","41.4984"
"24.1600","6.0097","6.0097","4.0064","11.1079","41.6545"
"24.2400","6.0287","6.0287","4.0191","11.1497","41.8114"
"24.3200","6.0501","6.0501","4.0334","11.2003","42.0013"
"24.4000","6.0690","6.0690","4.0460","11.2403","42.1511"
"24.4800","6.0903","6.0903","4.0602","11.2866","42.3249"
"24.5600","6.1109","6.1109","4.0739","11.3343","42.5035"
"24.6400","6.1299","6.1299","4.0866","11.3772","42.6644"
"24.7200","6.1497","6.1497","4.0998","11.4223","42.8336"
"24.8000","6.1696","6.1696","4.1130","11.4667","43.0002"
"24.8800","6.1899","6.1899","4.1266","11.5086","43.1574"
"24.9600","6.2105","6.2105","4.1404","11.5556","43.3335"
"25.0400","6.2288","6.2288","4.1525","11.5957","43.4838"
"25.1200","6.2499","6.2499","4.1666","11.6441","43.6654"
"25.2000","6.2705","6.2705","4.1803","11.6921","43.8453"
"25.2800","6.2910","6.2910","4.1940","11.7372","44.0146"
"25.3600","6.3101","6.3101","4.2067","11.7795","44.1731"
"25.4400","6.3291","6.3291","4.2194","11.8219","44.3323"
"25.5200","6.3492","6.3492","4.2328","11.8633","44.4874"
"25.6000","6.3703","6.3703","4.2469","11.9129","44.6733"
"25.6800","6.3885","6.3885","4.2590","11.9543","44.8285"
"25.7600","6.4100","6.4100","4.2733","12.0039","45.0147"
"25.8400","6.4303","6.4303","4.2869","12.0493","45.1848"
"25.9200","6.4504","6.4504","4.3003","12.0944","45.3539"
"26.0000","6.4703","6.4703","4.3135","12.1389","45.5207"
"26.0800","6.4893","6.4893","4.3262","12.1822","45.6834"
"26.1600","6.5098","6.5098","4.3399","12.2285","45.8568"
"26.2400","6.5296","6.5296","4.3531","12.2726","46.0222"
"26.3200","6.5491","6.5491","4.3661","12.3164","46.1865"
"26.4000","6.5706","6.5706","4.3804","12.3681","46.3804"
"26.4800","6.5907","6.5907","4.3938","12.4109","46.5410"
"26.5600","6.6106","6.6106","4.4071","12.4544","46.7040"
"26.6400","6.6303","6.6303","4.4202","12.4977","46.8663"
"26.7200","6.6487","6.6487","4.4325","12.5418","47.0317"
"26.8000","6.6699","6.6699","4.4466","12.5922","47.2209"
"26.8800","6.6893","6.6893","4.4595","12.6350","47.3812"
"26.9600","6.7100","6.7100","4.4733","12.6825","47.5592"
"27.0400","6.7299","6.7299","4.4866","12.7284","47.7317"
"27.1200","6.7496","6.7496","4.4998","12.7717","47.8940"
"27.2000","6.7702","6.7702","4.5134","12.8168","48.0630"
"27.2800","6.7906","6.7906","4.5270","12.8623","48.2337"
"27.3600","6.8093","6.8093","4.5395","12.9065","48.3994"
"27.4400","6.8294","6.8294","4.5530","12.9526","48.5723"
"27.5200","6.8483","6.8483","4.5656","12.9944","48.7291"
"27.6000","6.8703","6.8703","4.5802","13.0452","48.9195"
"27.6800","6.8919","6.8919","4.5946","13.0950","49.1064"
"27.7600","6.9108","6.9108","4.6072","13.1393","49.2722"
"27.8400","6.9297","6.9297","4.6198","13.1803","49.4260"
"27.9200","6.9495","6.9495","4.6330","13.2249","49.5933"
"28.0000","6.9692","6.9692","4.6461","13.2701","49.7628"
"28.0800","6.9898","6.9898","4.6599","13.3158","49.9343"
"28.1600","7.0087","7.0087","4.6725","13.3589","50.0960"
"28.2400","7.0297","7.0297","4.6864","13.4074","50.2779"
"28.3200","7.0501","7.0501","4.7001","13.4535","50.4505"
"28.4000","7.0694","7.0694","4.7129","13.4993","50.6223"
"28.4800","7.0905","7.0905","4.7270","13.5477","50.8040"
"28.5600","7.1095","7.1095","4.7397","13.5891","50.9590"
"28.6400","7.1303","7.1303","4.7535","13.6385","51.1445"
"28.7200","7.1501","7.1501","4.7668","13.6821","51.3080"
"28.8000","7.1694","7.1694","4.7796","13.7259","51.4720"
"28.8800","7.1903","7.1903","4.7935","13.7748","51.6557"
"28.9600","7.2109","7.2109","4.8073","13.8243","51.8413"
"29.0400","7.2303","7.2303","4.8202","13.8680","52.0050"
"29.1200","7.2505","7.2505","4.8337","13.9151","52.1816"
"29.2000","7.2693","7.2693","4.8462","13.9568","52.3380"
"29.2800","7.2901","7.2901","4.8601","14.0064","52.5239"
"29.3600","7.3098","7.3098","4.8732","14.0518","52.6944"
"29.4400","7.3287","7.3287","4.8858","14.0948","52.8554"
"29.5200","7.3493","7.3493","4.8995","14.1445","53.0419"
"29.6000","7.3702","7.3702","4.9135","14.1894","53.2104"
"29.6800","7.3908","7.3908","4.9272","14.2380","53.3927"
"29.7600","7.4108","7.4108","4.9405","14.2838","53.5642"
"29.8400","7.4288","7.4288","4.9525","14.3247","53.7176"
"29.9200","7.4494","7.4494","4.9662","14.3731","53.8993"
"30.0000","7.4695","7.4695","4.9797","14.4217","54.0814"
"30.0800","7.4900","7.4900","4.9934","14.4664","54.2491"
"30.1600","7.5111","7.5111","5.0074","14.5162","54.4358"
"30.2400","7.5303","7.5303","5.0202","14.5606","54.6023"
"30.3200","7.5503","7.5503","5.0335","14.6058","54.7716"
"30.4000","7.5701","7.5701","5.0468","14.6530","54.9489"
"30.4800","7.5895","7.5895","5.0597","14.6988","55.1206"
"30.5600","7.6097","7.6097","5.0731","14.7459","55.2971"
"30.6400","7.6292","7.6292","5.0861","14.7895","55.4606"
"30.7200","7.6490","7.6490","5.0993","14.8339","55.6271"
"30.8000","7.6706","7.6706","5.1137","14.8859","55.8220"
"30.8800","7.6898","7.6898","5.1266","14.9296","55.9858"
"30.9600","7.7107","7.7107","5.1405","14.9786","56.1698"
"31.0400","7.7297","7.7297","5.1531","15.0220","56.3326"
"31.1200","7.7491","7.7491","5.1660","15.0700","56.5124"
"31.2000","7.7694","7.7694","5.1796","15.1182","56.6932"
"31.2800","7.7893","7.7893","5.1929","15.1627","56.8603"
"31.3600","7.8102","7.8102","5.2068","15.2149","57.0557"
"31.4400","7.8314","7.8314","5.2209","15.2616","57.2309"
"31.5200","7.8500","7.8500","5.2333","15.3076","57.4034"
"31.6000","7.8701","7.8701","5.2467","15.3531","57.5742"
"31.6800","7.8894","7.8894","5.2596","15.3976","57.7411"
"31.7600","7.9101","7.9101","5.2734","15.4458","57.9216"
"31.8400","7.9298","7.9298","5.2865","15.4917","58.0940"
"31.9200","7.9485","7.9485","5.2990","15.5363","58.2611"
"32.0000","7.9698","7.9698","5.3132","15.5892","58.4597"
"32.0800","7.9908","7.9908","5.3272","15.6397","58.6489"
"32.1600","8.0102","8.0102","5.3401","15.6854","58.8201"
"32.2400","8.0298","8.0298","5.3532","15.7301","58.9878"
"32.3200","8.0491","8.0491","5.3660","15.7732","59.1497"
"32.4000","8.0696","8.0696","5.3797","15.8210","59.3287"
"32.4800","8.0904","8.0904","5.3936","15.8706","59.5149"
"32.5600","8.1096","8.1096","5.4064","15.9169","59.6886"
"32.6400","8.1305","8.1305","5.4203","15.9712","59.8921"
"32.7200","8.1502","8.1502","5.4335","16.0165","60.0618"
"32.8000","8.1704","8.1704","5.4469","16.0630","60.2362"
"32.8800","8.1902","8.1902","5.4601","16.1093","60.4100"
"32.9600","8.2093","8.2093","5.4729","16.1550","60.5813"
"33.0400","8.2294","8.2294","5.4863","16.1993","60.7473"
"33.1200","8.2495","8.2495","5.4997","16.2477","60.9289"
"33.2000","8.2680","8.2680","5.5120","16.2911","61.0915"
"33.2800","8.2901","8.2901","5.5268","16.3461","61.2979"
"33.3600","8.3101","8.3101","5.5401","16.3917","61.4689"
"33.4400","8.3306","8.3306","5.5537","16.4376","61.6409"
"33.5200","8.3501","8.3501","5.5667","16.4859","61.8223"
"33.6000","8.3693","8.3693","5.5795","16.5315","61.9931"
"33.6800","8.3896","8.3896","5.5931","16.5814","62.1801"
"33.7600","8.4097","8.4097","5.6065","16.6300","62.3626"
"33.8400","8.4301","8.4301","5.6201","16.6764","62.5365"
"33.9200","8.4507","8.4507","5.6338","16.7280","62.7300"
"34.0000","8.4703","8.4703","5.6468","16.7748","62.9054"
"34.0800","8.4905","8.4905","5.6603","16.8217","63.0814"
"34.1600","8.5100","8.5100","5.6733","16.8681","63.2553"
"34.2400","8.5289","8.5289","5.6860","16.9162","63.4359"
"34.3200","8.5496","8.5496","5.6998","16.9647","63.6176"
"34.4000","8.5688","8.5688","5.7126","17.0083","63.7812"
"34.4800","8.5900","8.5900","5.7267","17.0596","63.9734"
"34.5600","8.6111","8.6111","5.7407","17.1100","64.1625"
"34.6400","8.6301","8.6301","5.7534","17.1538","64.3267"
"34.7200","8.6493","8.6493","5.7662","17.2004","64.5017"
"34.8000","8.6693","8.6693","5.7796","17.2505","64.6894"
"34.8800","8.6895","8.6895","5.7930","17.2979","64.8671"
"34.9600","8.7105","8.7105","5.8070","17.3494","65.0604"
"35.0400","8.7288","8.7288","5.8192","17.3917","65.2188"
"35.1200","8.7504","8.7504","5.8336","17.4460","65.4226"
"35.2000","8.7708","8.7708","5.8472","17.4998","65.6244"
"35.2800","8.7907","8.7907","5.8605","17.5470","65.8013"
"35.3600","8.8099","8.8099","5.8733","17.5928","65.9730"
"35.4400","8.8293","8.8293","5.8862","17.6391","66.1466"
"35.5200","8.8496","8.8496","5.8997","17.6861","66.3228"
"35.6000","8.8697","8.8697","5.9131","17.7340","66.5026"
"35.6800","8.8883","8.8883","5.9255","17.7788","66.6705"
"35.7600","8.9103","8.9103","5.9402","17.8378","66.8918"
"35.8400","8.9303","8.9303","5.9535","17.8853","67.0699"
"35.9200","8.9503","8.9503","5.9669","17.9314","67.2428"
"36.0000","8.9700","8.9700","5.9800","17.9800","67.4251"
"36.0800","8.9892","8.9892","5.9928","18.0244","67.5913"
"36.1600","9.0100","9.0100","6.0066","18.0753","67.7822"
"36.2400","9.0295","9.0295","6.0197","18.1207","67.9528"
"36.3200","9.0492","9.0492","6.0328","18.1693","68.1349"
"36.4000","9.0708","9.0708","6.0472","18.2273","68.3522"
"36.4800","9.0906","9.0906","6.0604","18.2757","68.5339"
"36.5600","9.1106","9.1106","6.0737","18.3231","68.7117"
"36.6400","9.1303","9.1303","6.0868","18.3691","68.8842"
"36.7200","9.1487","9.1487","6.0991","18.4154","69.0577"
"36.8000","9.1700","9.1700","6.1133","18.4667","69.2502"
"36.8800","9.1893","9.1893","6.1262","18.5158","69.4342"
"36.9600","9.2098","9.2098","6.1399","18.5663","69.6235"
"37.0400","9.2297","9.2297","6.1532","18.6158","69.8093"
"37.1200","9.2502","9.2502","6.1668","18.6671","70.0016"
"37.2000","9.2703","9.2703","6.1802","18.7170","70.1889"
"37.2800","9.2905","9.2905","6.1937","18.7637","70.3638"
"37.3600","9.3094","9.3094","6.2063","18.8126","70.5474"
"37.4400","9.3296","9.3296","6.2198","18.8626","70.7347"
"37.5200","9.3485","9.3485","6.2324","18.9056","70.8961"
"37.6000","9.3703","9.3703","6.2469","18.9606","71.1022"
"37.6800","9.3915","9.3915","6.2610","19.0122","71.2958"
"37.7600","9.4105","9.4105","6.2737","19.0627","71.4852"
"37.8400","9.4299","9.4299","6.2866","19.1109","71.6657"
"37.9200","9.4497","9.4497","6.2998","19.1587","71.8453"
"38.0000","9.4692","9.4692","6.3128","19.2064","72.0238"
"38.0800","9.4896","9.4896","6.3264","19.2566","72.2121"
"38.1600","9.5087","9.5087","6.3391","19.3043","72.3912"
"38.2400","9.5296","9.5296","6.3530","19.3577","72.5914"
"38.3200","9.5507","9.5507","6.3671","19.4105","72.7894"
"38.4000","9.5697","9.5697","6.3798","19.4605","72.9767"
"38.4800","9.5902","9.5902","6.3935","19.5116","73.1686"
"38.5600","9.6088","9.6088","6.4058","19.5557","73.3339"
"38.6400","9.6300","9.6300","6.4200","19.6077","73.5288"
"38.7200","9.6501","9.6501","6.4334","19.6608","73.7278"
"38.8000","9.6696","9.6696","6.4464","19.7092","73.9093"
"38.8800","9.6904","9.6904","6.4603","19.7611","74.1039"
"38.9600","9.7109","9.7109","6.4740","19.8122","74.2958"
"39.0400","9.7299","9.7299","6.4866","19.8604","74.4765"
"39.1200","9.7502","9.7502","6.5002","19.9098","74.6619"
"39.2000","9.7693","9.7693","6.5129","19.9576","74.8409"
"39.2800","9.7904","9.7904","6.5270","20.0092","75.0346"
"39.3600","9.8097","9.8097","6.5398","20.0572","75.2147"
"39.4400","9.8290","9.8290","6.5526","20.1088","75.4082"
"39.5200","9.8494","9.8494","6.5663","20.1632","75.6121"
"39.6000","9.8701","9.8701","6.5801","20.2126","75.7973"
"39.6800","9.8905","9.8905","6.5937","20.2636","75.9885"
"39.7600","9.9109","9.9109","6.6073","20.3164","76.1864"
"39.8400","9.9291","9.9291","6.6194","20.3608","76.3531"
"39.9200","9.9493","9.9493","6.6329","20.4127","76.5477"
"40.0000","9.9694","9.9694","6.6463","20.4635","76.7380"
"40.0800","9.9899","9.9899","6.6599","20.5168","76.9382"
"40.1600","10.0114","10.0114","6.6742","20.5712","77.1422"
"40.2400","10.0303","10.0303","6.6869","20.6187","77.3201"
"40.3200","10.0502","10.0502","6.7001","20.6695","77.5108"
"40.4000","10.0700","10.0700","6.7134","20.7201","77.7004"
"40.4800","10.0897","10.0897","6.7265","20.7717","77.8937"
"40.5600","10.1094","10.1094","6.7396","20.8221","78.0829"
"40.6400","10.1288","10.1288","6.7525","20.8705","78.2643"
"40.7200","10.1493","10.1493","6.7662","20.9228","78.4604"
"40.8000","10.1702","10.1702","6.7801","20.9769","78.6633"
"40.8800","10.1896","10.1896","6.7931","21.0291","78.8593"
"40.9600","10.2110","10.2110","6.8073","21.0819","79.0571"
"41.0400","10.2298","10.2298","6.8199","21.1312","79.2420"
"41.1200","10.2491","10.2491","6.8327","21.1779","79.4170"
"41.2000","10.2692","10.2692","6.8461","21.2313","79.6175"
"41.2800","10.2897","10.2897","6.8598","21.2830","79.8114"
"41.3600","10.3100","10.3100","6.8733","21.3348","80.0054"
"41.4400","10.3308","10.3308","6.8872","21.3896","80.2111"
"41.5200","10.3494","10.3494","6.8996","21.4393","80.3974"
"41.6000","10.3705","10.3705","6.9136","21.4934","80.6002"
"41.6800","10.3897","10.3897","6.9265","21.5433","80.7872"
"41.7600","10.4099","10.4099","6.9400","21.5930","80.9738"
"41.8400","10.4297","10.4297","6.9531","21.6451","81.1693"
"41.9200","10.4486","10.4486","6.9657","21.6947","81.3550"
"42.0000","10.4700","10.4700","6.9800","21.7481","81.5554"
"42.0800","10.4907","10.4907","6.9938","21.8059","81.7722"
"42.1600","10.5104","10.5104","7.0070","21.8550","81.9563"
"42.2400","10.5299","10.5299","7.0200","21.9072","82.1520"
"42.3200","10.5490","10.5490","7.0327","21.9533","82.3249"
"42.4000","10.5696","10.5696","7.0464","22.0095","82.5357"
"42.4800","10.5903","10.5903","7.0602","22.0627","82.7353"
"42.5600","10.6094","10.6094","7.0730","22.1127","82.9228"
"42.6400","10.6305","10.6305","7.0870","22.1684","83.1316"
"42.7200","10.6500","10.6500","7.1000","22.2174","83.3154"
"42.8000","10.6704","10.6704","7.1136","22.2699","83.5123"
"42.8800","10.6902","10.6902","7.1268","22.3223","83.7088"
"42.9600","10.7097","10.7097","7.1398","22.3734","83.9003"
"43.0400","10.7298","10.7298","7.1532","22.4300","84.1125"
"43.1200","10.7496","10.7496","7.1664","22.4813","84.3048"
"43.2000","10.7682","10.7682","7.1788","22.5300","84.4875"
"43.2800","10.7901","10.7901","7.1934","22.5883","84.7062"
"43.3600","10.8102","10.8102","7.2068","22.6398","84.8993"
"43.4400","10.8309","10.8309","7.2206","22.6911","85.0915"
"43.5200","10.8500","10.8500","7.2334","22.7414","85.2804"
"43.6000","10.8692","10.8692","7.2461","22.7925","85.4718"
"43.6800","10.8897","10.8897","7.2598","22.8496","85.6861"
"43.7600","10.9098","10.9098","7.2732","22.9028","85.8857"
"43.8400","10.9298","10.9298","7.2865","22.9546","86.0797"
"43.9200","10.9509","10.9509","7.3006","23.0116","86.2936"
"44.0000","10.9699","10.9699","7.3133","23.0608","86.4782"
"44.0800","10.9907","10.9907","7.3271","23.1157","86.6837"
"44.1600","11.0103","11.0103","7.3402","23.1693","86.8850"
"44.2400","11.0286","11.0286","7.3524","23.2151","87.0565"
"44.3200","11.0494","11.0494","7.3663","23.2721","87.2705"
"44.4000","11.0686","11.0686","7.3791","23.3204","87.4515"
"44.4800","11.0901","11.0901","7.3934","23.3804","87.6765"
"44.5600","11.1109","11.1109","7.4073","23.4365","87.8870"
"44.6400","11.1305","11.1305","7.4203","23.4879","88.0796"
"44.7200","11.1495","11.1495","7.4330","23.5380","88.2675"
"44.8000","11.1693","11.1693","7.4462","23.5908","88.4657"
"44.8800","11.1894","11.1894","7.4596","23.6463","88.6737"
"44.9600","11.2109","11.2109","7.4739","23.7031","88.8868"
"45.0400","11.2289","11.2289","7.4859","23.7499","89.0623"
"45.1200","11.2503","11.2503","7.5002","23.8077","89.2790"
"45.2000","11.2707","11.2707","7.5138","23.8628","89.4855"
"45.2800","11.2905","11.2905","7.5270","23.9192","89.6969"
"45.3600","11.3102","11.3102","7.5401","23.9719","89.8947"
"45.4400","11.3293","11.3293","7.5528","24.0196","90.0736"
"45.5200","11.3494","11.3494","7.5663","24.0729","90.2733"
"45.6000","11.3701","11.3701","7.5800","24.1290","90.4837"
"45.6800","11.3888","11.3888","7.5925","24.1825","90.6843"
"45.7600","11.4096","11.4096","7.6064","24.2399","90.8998"
"45.8400","11.4301","11.4301","7.6201","24.2960","91.1102"
"45.9200","11.4507","11.4507","7.6338","24.3512","91.3171"
"46.0000","11.4705","11.4705","7.6470","24.4037","91.5137"
"46.0800","11.4890","11.4890","7.6593","24.4524","91.6964"
"46.1600","11.5097","11.5097","7.6731","24.5081","91.9054"
"46.2400","11.5299","11.5299","7.6866","24.5636","92.1135"
"46.3200","11.5494","11.5494","7.6996","24.6159","92.3095"
"46.4000","11.5704","11.5704","7.7136","24.6759","92.5348"
"46.4800","11.5907","11.5907","7.7271","24.7284","92.7316"
"46.5600","11.6107","11.6107","7.7405","24.7828","92.9355"
"46.6400","11.6304","11.6304","7.7536","24.8346","93.1298"
"46.7200","11.6487","11.6487","7.7658","24.8858","93.3219"
"46.8000","11.6698","11.6698","7.7799","24.9452","93.5445"
"46.8800","11.6893","11.6893","7.7929","24.9971","93.7391"
"46.9600","11.7098","11.7098","7.8065","25.0557","93.9590"
"47.0400","11.7302","11.7302","7.8201","25.1093","94.1597"
"47.1200","11.7502","11.7502","7.8335","25.1614","94.3553"
"47.2000","11.7698","11.7698","7.8465","25.2172","94.5647"
"47.2800","11.7902","11.7902","7.8601","25.2706","94.7648"
"47.3600","11.8093","11.8093","7.8729","25.3269","94.9757"
"47.4400","11.8301","11.8301","7.8867","25.3832","95.1870"
"47.5200","11.8489","11.8489","7.8993","25.4326","95.3721"
"47.6000","11.8699","11.8699","7.9132","25.4911","95.5916"
"47.6800","11.8914","11.8914","7.9276","25.5513","95.8172"
"47.7600","11.9110","11.9110","7.9407","25.6062","96.0233"
"47.8400","11.9300","11.9300","7.9534","25.6580","96.2176"
"47.9200","11.9497","11.9497","7.9664","25.7129","96.4234"
"48.0000","11.9693","11.9693","7.9795","25.7630","96.6114"
"48.0800","11.9897","11.9897","7.9931","25.8219","96.8323"
"48.1600","12.0088","12.0088","8.0059","25.8716","97.0186"
"48.2400","12.0295","12.0295","8.0197","25.9296","97.2361"
"48.3200","12.0503","12.0503","8.0335","25.9888","97.4578"
"48.4000","12.0699","12.0699","8.0466","26.0436","97.6635"
"48.4800","12.0905","12.0905","8.0604","26.1023","97.8835"
"48.5600","12.1091","12.1091","8.0727","26.1499","98.0622"
"48.6400","12.1296","12.1296","8.0864","26.2036","98.2636"
"48.7200","12.1501","12.1501","8.1001","26.2601","98.4754"
"48.8000","12.1696","12.1696","8.1130","26.3159","98.6848"
"48.8800","12.1902","12.1902","8.1268","26.3730","98.8988"
"48.9600","12.2108","12.2108","8.1406","26.4288","99.1079"
"49.0400","12.2300","12.2300","8.1533","26.4816","99.3062"
"49.1200","12.2501","12.2501","8.1667","26.5366","99.5123"
"49.2000","12.2691","12.2691","8.1794","26.5897","99.7115"
"49.2800","12.2901","12.2901","8.1934","26.6513","99.9425"
"49.3600","12.3095","12.3095","8.2063","26.7058","100.1468"
"49.4400","12.3288","12.3288","8.2192","26.7583","100.3437"
"49.5200","12.3494","12.3494","8.2329","26.8212","100.5797"
"49.6000","12.3706","12.3706","8.2471","26.8806","100.8022"
"49.6800","12.3906","12.3906","8.2604","26.9344","101.0041"
"49.7600","12.4105","12.4105","8.2737","26.9915","101.2183"
"49.8400","12.4287","12.4287","8.2858","27.0412","101.4045"
"49.9200","12.4496","12.4496","8.2998","27.0989","101.6207"
"50.0000","12.4697","12.4697","8.3131","27.1555","101.8332"
"50.0800","12.4902","12.4902","8.3268","27.2152","102.0570"
"50.1600","12.5109","12.5109","8.3406","27.2754","102.2827"
"50.2400","12.5303","12.5303","8.3535","27.3269","102.4757"
"50.3200","12.5505","12.5505","8.3670","27.3834","102.6878"
"50.4000","12.5703","12.5703","8.3802","27.4388","102.8955"
"50.4800","12.5896","12.5896","8.3931","27.4963","103.1109"
"50.5600","12.6099","12.6099","8.4066","27.5576","103.3408"
"50.6400","12.6292","12.6292","8.4195","27.6095","103.5356"
"50.7200","12.6492","12.6492","8.4328","27.6656","103.7459"
"50.8000","12.6710","12.6710","8.4473","27.7300","103.9874"
"50.8800","12.6902","12.6902","8.4601","27.7840","104.1899"
"50.9600","12.7102","12.7102","8.4735","27.8395","104.3983"
"51.0400","12.7296","12.7296","8.4864","27.8919","104.5946"
"51.1200","12.7491","12.7491","8.4994","27.9480","104.8048"
"51.2000","12.7692","12.7692","8.5128","28.0063","105.0235"
"51.2800","12.7895","12.7895","8.5263","28.0644","105.2415"
"51.3600","12.8104","12.8104","8.5402","28.1252","105.4697"
"51.4400","12.8310","12.8310","8.5540","28.1836","105.6884"
"51.5200","12.8498","12.8498","8.5665","28.2371","105.8889"
"51.6000","12.8701","12.8701","8.5800","28.2950","106.1063"
"51.6800","12.8896","12.8896","8.5931","28.3499","106.3121"
"51.7600","12.9100","12.9100","8.6067","28.4073","106.5275"
"51.8400","12.9298","12.9298","8.6198","28.4633","106.7374"
"51.9200","12.9483","12.9483","8.6322","28.5159","106.9348"
"52.0000","12.9698","12.9698","8.6466","28.5807","107.1777"
"52.0800","12.9907","12.9907","8.6604","28.6404","107.4016"
"52.1600","13.0101","13.0101","8.6734","28.6950","107.6064"
"52.2400","13.0300","13.0300","8.6867","28.7523","107.8210"
"52.3200","13.0492","13.0492","8.6994","28.8053","108.0199"
"52.4000","13.0698","13.0698","8.7132","28.8679","108.2548"
"52.4800","13.0906","13.0906","8.7271","28.9274","108.4776"
"52.5600","13.1095","13.1095","8.7397","28.9828","108.6857"
"52.6400","13.1303","13.1303","8.7535","29.0448","108.9182"
"52.7200","13.1500","13.1500","8.7667","29.1015","109.1308"
"52.8000","13.1707","13.1707","8.7805","29.1583","109.3436"
"52.8800","13.1904","13.1904","8.7936","29.2168","109.5630"
"52.9600","13.2093","13.2093","8.8062","29.2705","109.7644"
"53.0400","13.2295","13.2295","8.8197","29.3309","109.9908"
"53.1200","13.2494","13.2494","8.8330","29.3882","110.2059"
"53.2000","13.2689","13.2689","8.8459","29.4439","110.4148"
"53.2800","13.2904","13.2904","8.8603","29.5096","110.6609"
"53.3600","13.3095","13.3095","8.8730","29.5639","110.8644"
"53.4400","13.3302","13.3302","8.8868","29.6246","111.0923"
"53.5200","13.3504","13.3504","8.9003","29.6811","111.3040"
"53.6000","13.3693","13.3693","8.9129","29.7384","111.5191"
"53.6800","13.3896","13.3896","8.9264","29.7981","111.7428"
"53.7600","13.4096","13.4096","8.9398","29.8571","111.9641"
"53.8400","13.4299","13.4299","8.9533","29.9163","112.1861"
"53.9200","13.4507","13.4507","8.9672","29.9774","112.4153"
"54.0000","13.4699","13.4699","8.9800","30.0313","112.6174"
"54.0800","13.4903","13.4903","8.9936","30.0916","112.8436"
"54.1600","13.5099","13.5099","9.0066","30.1479","113.0547"
"54.2400","13.5290","13.5290","9.0193","30.2046","113.2674"
"54.3200","13.5495","13.5495","9.0330","30.2657","113.4964"
"54.4000","13.5685","13.5685","9.0457","30.3219","113.7070"
"54.4800","13.5901","13.5901","9.0601","30.3855","113.9455"
"54.5600","13.6110","13.6110","9.0740","30.4475","114.1782"
"54.6400","13.6301","13.6301","9.0867","30.5022","114.3831"
"54.7200","13.6496","13.6496","9.0997","30.5599","114.5997"
"54.8000","13.6692","13.6692","9.1128","30.6184","114.8190"
"54.8800","13.6896","13.6896","9.1264","30.6770","115.0386"
"54.9600","13.7103","13.7103","9.1402","30.7411","115.2791"
"55.0400","13.7291","13.7291","9.1527","30.7967","115.4878"
"55.1200","13.7504","13.7504","9.1669","30.8628","115.7353"
"55.2000","13.7708","13.7708","9.1806","30.9205","115.9520"
"55.2800","13.7908","13.7908","9.1939","30.9835","116.1881"
"55.3600","13.8102","13.8102","9.2068","31.0423","116.4085"
"55.4400","13.8291","13.8291","9.2194","31.0943","116.6036"
"55.5200","13.8491","13.8491","9.2328","31.1532","116.8246"
"55.6000","13.8697","13.8697","9.2465","31.2146","117.0548"
"55.6800","13.8887","13.8887","9.2591","31.2735","117.2758"
"55.7600","13.9101","13.9101","9.2734","31.3419","117.5320"
"55.8400","13.9304","13.9304","9.2869","31.4020","117.7575"
"55.9200","13.9500","13.9500","9.3000","31.4607","117.9777"
"56.0000","13.9701","13.9701","9.3134","31.5189","118.1960"
"56.0800","13.9892","13.9892","9.3261","31.5760","118.4099"
"56.1600","14.0094","14.0094","9.3396","31.6349","118.6309"
"56.2400","14.0297","14.0297","9.3531","31.6956","118.8587"
"56.3200","14.0495","14.0495","9.3663","31.7569","119.0884"
"56.4000","14.0701","14.0701","9.3801","31.8217","119.3314"
"56.4800","14.0905","14.0905","9.3937","31.8810","119.5536"
"56.5600","14.1107","14.1107","9.4071","31.9407","119.7777"
"56.6400","14.1301","14.1301","9.4201","31.9984","119.9940"
"56.7200","14.1490","14.1490","9.4327","32.0544","120.2040"
"56.8000","14.1695","14.1695","9.4463","32.1173","120.4399"
"56.8800","14.1893","14.1893","9.4596","32.1775","120.6658"
"56.9600","14.2097","14.2097","9.4731","32.2402","120.9007"
"57.0400","14.2300","14.2300","9.4867","32.3037","121.1387"
"57.1200","14.2497","14.2497","9.4998","32.3594","121.3478"
"57.2000","14.2704","14.2704","9.5136","32.4260","121.5974"
"57.2800","14.2905","14.2905","9.5270","32.4852","121.8195"
"57.3600","14.3093","14.3093","9.5395","32.5454","122.0453"
"57.4400","14.3294","14.3294","9.5529","32.6040","122.2650"
"57.5200","14.3487","14.3487","9.5658","32.6628","122.4853"
"57.6000","14.3705","14.3705","9.5803","32.7296","122.7362"
"57.6800","14.3914","14.3914","9.5943","32.7956","122.9835"
"57.7600","14.4106","14.4106","9.6070","32.8543","123.2038"
"57.8400","14.4299","14.4299","9.6199","32.9100","123.4127"
"57.9200","14.4494","14.4494","9.6330","32.9690","123.6337"
"58.0000","14.4693","14.4693","9.6462","33.0307","123.8652"
"58.0800","14.4900","14.4900","9.6600","33.0958","124.1092"
"58.1600","14.5088","14.5088","9.6725","33.1482","124.3058"
"58.2400","14.5298","14.5298","9.6865","33.2151","124.5566"
"58.3200","14.5506","14.5506","9.7004","33.2801","124.8005"
"58.4000","14.5698","14.5698","9.7132","33.3375","125.0155"
"58.4800","14.5902","14.5902","9.7268","33.4005","125.2519"
"58.5600","14.6093","14.6093","9.7395","33.4573","125.4649"
"58.6400","14.6299","14.6299","9.7533","33.5221","125.7078"
"58.7200","14.6493","14.6493","9.7662","33.5807","125.9276"
"58.8000","14.6691","14.6691","9.7794","33.6415","126.1554"
"58.8800","14.6904","14.6904","9.7936","33.7096","126.4109"
"58.9600","14.7114","14.7114","9.8076","33.7761","126.6604"
"59.0400","14.7302","14.7302","9.8201","33.8305","126.8645"
"59.1200","14.7501","14.7501","9.8334","33.8911","127.0915"
"59.2000","14.7688","14.7688","9.8459","33.9460","127.2976"
"59.2800","14.7900","14.7900","9.8600","34.0132","127.5494"
"59.3600","14.8099","14.8099","9.8732","34.0727","127.7728"
"59.4400","14.8287","14.8287","9.8858","34.1307","127.9902"
"59.5200","14.8491","14.8491","9.8994","34.1985","128.2443"
"59.6000","14.8704","14.8704","9.9136","34.2647","128.4927"
"59.6800","14.8905","14.8905","9.9270","34.3250","128.7187"
"59.7600","14.9107","14.9107","9.9405","34.3870","128.9512"
"59.8400","14.9289","14.9289","9.9526","34.4415","129.1555"
"59.9200","14.9494","14.9494","9.9663","34.5044","129.3916"
"60.0000","14.9693","14.9693","9.9796","34.5681","129.6303"
"60.0800","14.9905","14.9905","9.9937","34.6363","129.8860"
"60.1160","15.0001","15.0001","10.0001","34.6657","129.9964"