File: data/instron_tests/553_VERT_m1.is_comp_Exports/553_VERT_m1_3_1.csv
Sample text inputs : Sample No.,Sample choice input : Leading Direction,Sample choice input : Mode,Specimen choice input : Direction,Specimen properties : Height,Specimen properties : Thickness,Specimen properties : Width,Test : Rate 1
,,,,(mm),(mm),(mm),(mm/min)
"553","Vertical","Unimode","1","147.00","25.00","150.00","15.00"

Time,Displacement,Compressive displacement,Compressive strain (Displacement),Compressive stress,Force
(s),(mm),(mm),(%),(kPa),(N)
"0.0000","0.0000","0.0000","0.0000","-0.8537","-3.1372"
"0.0800","0.0014","0.0014","0.0009","-0.8475","-3.1146"
"0.1600","0.0111","0.0111","0.0074","-0.7885","-2.8976"
"0.2400","0.0299","0.0299","0.0200","-0.6799","-2.4985"
"0.3200","0.0511","0.0511","0.0341","-0.5733","-2.1069"
"0.4000","0.0711","0.0711","0.0474","-0.4796","-1.7625"
"0.4800","0.0897","0.0897","0.0598","-0.3912","-1.4377"
"0.5600","0.1100","0.1100","0.0733","-0.3043","-1.1184"
"0.6400","0.1301","0.1301","0.0867","-0.2203","-0.8096"
"0.7200","0.1509","0.1509","0.1006","-0.1330","-0.4887"
"0.8000","0.1715","0.1715","0.1143","-0.0607","-0.2230"
"0.8800","0.1904","0.1904","0.1269","0.0053","0.0195"
"0.9600","0.2111","0.2111","0.1408","0.0864","0.3176"
"1.0400","0.2317","0.2317","0.1545","0.1580","0.5807"
"1.1200","0.2520","0.2520","0.1680","0.2327","0.8551"
"1.2000","0.2711","0.2711","0.1808","0.3053","1.1218"
"1.2800","0.2902","0.2902","0.1935","0.3665","1.3470"
"1.3600","0.3107","0.3107","0.2072","0.4415","1.6226"
"1.4400","0.3308","0.3308","0.2205","0.5096","1.8728"
"1.5200","0.3498","0.3498","0.2332","0.5750","2.1132"
"1.6000","0.3715","0.3715","0.2477","0.6557","2.4095"
"1.6800","0.3910","0.3910","0.2606","0.7121","2.6171"
"1.7600","0.4118","0.4118","0.2746","0.7803","2.8676"
"1.8400","0.4317","0.4317","0.2878","0.8508","3.1265"
"1.9200","0.4507","0.4507","0.3004","0.9198","3.3803"
"2.0000","0.4706","0.4706","0.3137","0.9914","3.6433"
"2.0800","0.4904","0.4904","0.3269","1.0660","3.9177"
"2.1600","0.5109","0.5109","0.3406","1.1449","4.2074"
"2.2400","0.5324","0.5324","0.3549","1.2275","4.5109"
"2.3200","0.5514","0.5514","0.3676","1.3007","4.7801"
"2.4000","0.5716","0.5716","0.3811","1.3827","5.0814"
"2.4800","0.5913","0.5913","0.3942","1.4597","5.3643"
"2.5600","0.6103","0.6103","0.4068","1.5401","5.6598"
"2.6400","0.6309","0.6309","0.4206","1.6291","5.9869"
"2.7200","0.6502","0.6502","0.4335","1.7107","6.2869"
"2.8000","0.6709","0.6709","0.4473","1.8002","6.6158"
"2.8800","0.6914","0.6914","0.4610","1.8905","6.9478"
"2.9600","0.7110","0.7110","0.4740","1.9743","7.2555"
"3.0400","0.7314","0.7314","0.4876","2.0646","7.5874"
"3.1200","0.7508","0.7508","0.5005","2.1459","7.8862"
"3.2000","0.7697","0.7697","0.5131","2.2356","8.2158"
"3.2800","0.7908","0.7908","0.5272","2.3345","8.5791"
"3.3600","0.8110","0.8110","0.5407","2.4237","8.9072"
"3.4400","0.8323","0.8323","0.5549","2.5257","9.2819"
"3.5200","0.8524","0.8524","0.5683","2.6198","9.6279"
"3.6000","0.8718","0.8718","0.5812","2.7113","9.9642"
"3.6800","0.8911","0.8911","0.5940","2.8037","10.3037"
"3.7600","0.9102","0.9102","0.6068","2.8950","10.6392"
"3.8400","0.9303","0.9303","0.6202","2.9945","11.0047"
"3.9200","0.9513","0.9513","0.6342","3.0986","11.3875"
"4.0000","0.9701","0.9701","0.6467","3.1919","11.7302"
"4.0800","0.9910","0.9910","0.6607","3.3057","12.1484"
"4.1600","1.0114","1.0114","0.6743","3.4083","12.5255"
"4.2400","1.0313","1.0313","0.6875","3.5160","12.9211"
"4.3200","1.0515","1.0515","0.7010","3.6218","13.3100"
"4.4000","1.0703","1.0703","0.7136","3.7203","13.6720"
"4.4800","1.0911","1.0911","0.7274","3.8357","14.0961"
"4.5600","1.1110","1.1110","0.7407","3.9451","14.4982"
"4.6400","1.1308","1.1308","0.7539","4.0613","14.9251"
"4.7200","1.1517","1.1517","0.7678","4.1819","15.3686"
"4.8000","1.1717","1.1717","0.7811","4.2939","15.7801"
"4.8800","1.1914","1.1914","0.7943","4.4109","16.2102"
"4.9600","1.2115","1.2115","0.8077","4.5298","16.6471"
"5.0400","1.2305","1.2305","0.8203","4.6423","17.0604"
"5.1200","1.2516","1.2516","0.8344","4.7783","17.5604"
"5.2000","1.2706","1.2706","0.8471","4.8907","17.9733"
"5.2800","1.2902","1.2902","0.8602","5.0105","18.4138"
"5.3600","1.3108","1.3108","0.8739","5.1420","18.8969"
"5.4400","1.3313","1.3313","0.8875","5.2662","19.3532"
"5.5200","1.3519","1.3519","0.9013","5.3947","19.8255"
"5.6000","1.3718","1.3718","0.9145","5.5163","20.2724"
"5.6800","1.3899","1.3899","0.9266","5.6320","20.6976"
"5.7600","1.4106","1.4106","0.9404","5.7676","21.1958"
"5.8400","1.4304","1.4304","0.9536","5.8883","21.6396"
"5.9200","1.4520","1.4520","0.9680","6.0334","22.1726"
"6.0000","1.4726","1.4726","0.9817","6.1672","22.6644"
"6.0800","1.4912","1.4912","0.9941","6.2845","23.0954"
"6.1600","1.5112","1.5112","1.0075","6.4121","23.5646"
"6.2400","1.5312","1.5312","1.0208","6.5438","24.0485"
"6.3200","1.5508","1.5508","1.0338","6.6770","24.5379"
"6.4000","1.5710","1.5710","1.0473","6.8140","25.0416"
"6.4800","1.5900","1.5900","1.0600","6.9365","25.4918"
"6.5600","1.6107","1.6107","1.0738","7.0800","26.0191"
"6.6400","1.6312","1.6312","1.0875","7.2200","26.5335"
"6.7200","1.6510","1.6510","1.1007","7.3592","27.0450"
"6.8000","1.6719","1.6719","1.1146","7.4997","27.5616"
"6.8800","1.6906","1.6906","1.1271","7.6209","28.0069"
"6.9600","1.7108","1.7108","1.1406","7.7593","28.5156"
"7.0400","1.7309","1.7309","1.1539","7.8969","29.0209"
"7.1200","1.7505","1.7505","1.1670","8.0339","29.5245"
"7.2000","1.7711","1.7711","1.1807","8.1772","30.0514"
"7.2800","1.7920","1.7920","1.1947","8.3240","30.5906"
"7.3600","1.8112","1.8112","1.2075","8.4608","31.0935"
"7.4400","1.8316","1.8316","1.2211","8.6062","31.6278"
"7.5200","1.8503","1.8503","1.2336","8.7339","32.0971"
"7.6000","1.8714","1.8714","1.2476","8.8899","32.6703"
"7.6800","1.8910","1.8910","1.2607","9.0298","33.1844"
"7.7600","1.9100","1.9100","1.2734","9.1677","33.6914"
"7.8400","1.9305","1.9305","1.2870","9.3225","34.2602"
"7.9200","1.9519","1.9519","1.3013","9.4801","34.8392"
"8.0000","1.9716","1.9716","1.3144","9.6273","35.3803"
"8.0800","1.9911","1.9911","1.3274","9.7717","35.9111"
"8.1600","2.0099","2.0099","1.3400","9.9094","36.4170"
"8.2400","2.0312","2.0312","1.3541","10.0740","37.0218"
"8.3200","2.0516","2.0516","1.3677","10.2243","37.5743"
"8.4000","2.0712","2.0712","1.3808","10.3724","38.1186"
"8.4800","2.0917","2.0917","1.3944","10.5260","38.6831"
"8.5600","2.1111","2.1111","1.4074","10.6656","39.1961"
"8.6400","2.1321","2.1321","1.4214","10.8285","39.7946"
"8.7200","2.1514","2.1514","1.4343","10.9740","40.3293"
"8.8000","2.1707","2.1707","1.4472","11.1184","40.8602"
"8.8800","2.1905","2.1905","1.4604","11.2682","41.4107"
"8.9600","2.2097","2.2097","1.4732","11.4117","41.9380"
"9.0400","2.2306","2.2306","1.4870","11.5753","42.5391"
"9.1200","2.2524","2.2524","1.5016","11.7433","43.1567"
"9.2000","2.2712","2.2712","1.5141","11.8816","43.6650"
"9.2800","2.2916","2.2916","1.5277","12.0368","44.2354"
"9.3600","2.3106","2.3106","1.5404","12.1802","44.7622"
"9.4400","2.3309","2.3309","1.5539","12.3411","45.3536"
"9.5200","2.3510","2.3510","1.5674","12.4992","45.9347"
"9.6000","2.3710","2.3710","1.5807","12.6468","46.4769"
"9.6800","2.3915","2.3915","1.5944","12.8054","47.0600"
"9.7600","2.4120","2.4120","1.6080","12.9643","47.6438"
"9.8400","2.4315","2.4315","1.6210","13.1126","48.1889"
"9.9200","2.4518","2.4518","1.6345","13.2708","48.7701"
"10.0000","2.4707","2.4707","1.6471","13.4129","49.2925"
"10.0800","2.4907","2.4907","1.6604","13.5692","49.8668"
"10.1600","2.5108","2.5108","1.6739","13.7257","50.4420"
"10.2400","2.5299","2.5299","1.6866","13.8772","50.9989"
"10.3200","2.5514","2.5514","1.7010","14.0498","51.6331"
"10.4000","2.5717","2.5717","1.7145","14.2084","52.2159"
"10.4800","2.5909","2.5909","1.7272","14.3548","52.7539"
"10.5600","2.6106","2.6106","1.7404","14.5115","53.3298"
"10.6400","2.6306","2.6306","1.7537","14.6662","53.8982"
"10.7200","2.6513","2.6513","1.7675","14.8350","54.5185"
"10.8000","2.6716","2.6716","1.7811","14.9926","55.0977"
"10.8800","2.6901","2.6901","1.7934","15.1391","55.6361"
"10.9600","2.7116","2.7116","1.8077","15.3123","56.2727"
"11.0400","2.7314","2.7314","1.8210","15.4699","56.8518"
"11.1200","2.7522","2.7522","1.8348","15.6338","57.4541"
"11.2000","2.7715","2.7715","1.8477","15.7862","58.0142"
"11.2800","2.7904","2.7904","1.8603","15.9344","58.5589"
"11.3600","2.8104","2.8104","1.8736","16.0935","59.1437"
"11.4400","2.8312","2.8312","1.8875","16.2601","59.7558"
"11.5200","2.8498","2.8498","1.8999","16.4060","60.2919"
"11.6000","2.8717","2.8717","1.9145","16.5878","60.9602"
"11.6800","2.8914","2.8914","1.9276","16.7424","61.5283"
"11.7600","2.9119","2.9119","1.9413","16.9054","62.1274"
"11.8400","2.9313","2.9313","1.9542","17.0583","62.6892"
"11.9200","2.9505","2.9505","1.9670","17.2140","63.2614"
"12.0000","2.9707","2.9707","1.9805","17.3765","63.8587"
"12.0800","2.9907","2.9907","1.9938","17.5345","64.4393"
"12.1600","3.0107","3.0107","2.0072","17.6969","65.0359"
"12.2400","3.0320","3.0320","2.0214","17.8776","65.7001"
"12.3200","3.0521","3.0521","2.0347","18.0404","66.2985"
"12.4000","3.0720","3.0720","2.0480","18.2004","66.8866"
"12.4800","3.0914","3.0914","2.0609","18.3548","67.4540"
"12.5600","3.1101","3.1101","2.0734","18.5053","68.0069"
"12.6400","3.1311","3.1311","2.0874","18.6758","68.6335"
"12.7200","3.1501","3.1501","2.1001","18.8258","69.1848"
"12.8000","3.1711","3.1711","2.1141","18.9960","69.8102"
"12.8800","3.1917","3.1917","2.1278","19.1620","70.4202"
"12.9600","3.2111","3.2111","2.1407","19.3151","70.9830"
"13.0400","3.2311","3.2311","2.1541","19.4782","71.5825"
"13.1200","3.2513","3.2513","2.1675","19.6388","72.1727"
"13.2000","3.2708","3.2708","2.1806","19.7976","72.7563"
"13.2800","3.2913","3.2913","2.1942","19.9620","73.3602"
"13.3600","3.3099","3.3099","2.2066","20.1079","73.8965"
"13.4400","3.3317","3.3317","2.2211","20.2876","74.5570"
"13.5200","3.3524","3.3524","2.2350","20.4528","75.1641"
"13.6000","3.3718","3.3718","2.2479","20.6084","75.7357"
"13.6800","3.3911","3.3911","2.2607","20.7618","76.2996"
"13.7600","3.4104","3.4104","2.2736","20.9149","76.8621"
"13.8400","3.4304","3.4304","2.2869","21.0751","77.4510"
"13.9200","3.4512","3.4512","2.3008","21.2445","78.0736"
"14.0000","3.4699","3.4699","2.3133","21.3928","78.6186"
"14.0800","3.4904","3.4904","2.3269","21.5558","79.2177"
"14.1600","3.5114","3.5114","2.3409","21.7252","79.8401"
"14.2400","3.5319","3.5319","2.3546","21.8889","80.4417"
"14.3200","3.5517","3.5517","2.3678","22.0437","81.0105"
"14.4000","3.5705","3.5705","2.3803","22.1916","81.5541"
"14.4800","3.5909","3.5909","2.3940","22.3616","82.1789"
"14.5600","3.6111","3.6111","2.4074","22.5231","82.7724"
"14.6400","3.6305","3.6305","2.4204","22.6807","83.3518"
"14.7200","3.6514","3.6514","2.4343","22.8519","83.9806"
"14.8000","3.6718","3.6718","2.4479","23.0104","84.5632"
"14.8800","3.6916","3.6916","2.4610","23.1699","85.1494"
"14.9600","3.7115","3.7115","2.4744","23.3259","85.7227"
"15.0400","3.7302","3.7302","2.4868","23.4728","86.2626"
"15.1200","3.7513","3.7513","2.5008","23.6443","86.8928"
"15.2000","3.7704","3.7704","2.5136","23.7930","87.4393"
"15.2800","3.7903","3.7903","2.5269","23.9546","88.0332"
"15.3600","3.8111","3.8111","2.5408","24.1250","88.6593"
"15.4400","3.8314","3.8314","2.5543","24.2841","89.2441"
"15.5200","3.8516","3.8516","2.5677","24.4464","89.8404"
"15.6000","3.8716","3.8716","2.5811","24.6043","90.4207"
"15.6800","3.8900","3.8900","2.5933","24.7440","90.9342"
"15.7600","3.9105","3.9105","2.6070","24.9120","91.5515"
"15.8400","3.9303","3.9303","2.6202","25.0656","92.1162"
"15.9200","3.9516","3.9516","2.6344","25.2367","92.7448"
"16.0000","3.9723","3.9723","2.6482","25.4005","93.3467"
"16.0800","3.9914","3.9914","2.6609","25.5536","93.9094"
"16.1600","4.0112","4.0112","2.6741","25.7089","94.4800"
"16.2400","4.0311","4.0311","2.6874","25.8657","95.0565"
"16.3200","4.0507","4.0507","2.7005","26.0221","95.6311"
"16.4000","4.0707","4.0707","2.7138","26.1801","96.2117"
"16.4800","4.0900","4.0900","2.7267","26.3274","96.7534"
"16.5600","4.1109","4.1109","2.7406","26.4933","97.3628"
"16.6400","4.1320","4.1320","2.7547","26.6614","97.9807"
"16.7200","4.1513","4.1513","2.7675","26.8141","98.5417"
"16.8000","4.1716","4.1716","2.7811","26.9720","99.1222"
"16.8800","4.1906","4.1906","2.7937","27.1189","99.6618"
"16.9600","4.2109","4.2109","2.8072","27.2785","100.2487"
"17.0400","4.2307","4.2307","2.8204","27.4332","100.8170"
"17.1200","4.2506","4.2506","2.8337","27.5886","101.3880"
"17.2000","4.2714","4.2714","2.8476","27.7558","102.0026"
"17.2800","4.2919","4.2919","2.8613","27.9163","102.5925"
"17.3600","4.3111","4.3111","2.8740","28.0667","103.1450"
"17.4400","4.3317","4.3317","2.8878","28.2325","103.7546"
"17.5200","4.3503","4.3503","2.9002","28.3695","104.2579"
"17.6000","4.3714","4.3714","2.9142","28.5391","104.8811"
"17.6800","4.3907","4.3907","2.9271","28.6859","105.4205"
"17.7600","4.4098","4.4098","2.9399","28.8391","105.9837"
"17.8400","4.4309","4.4309","2.9539","29.0058","106.5964"
"17.9200","4.4518","4.4518","2.9679","29.1702","107.2006"
"18.0000","4.4715","4.4715","2.9810","29.3250","107.7693"
"18.0800","4.4913","4.4913","2.9942","29.4798","108.3382"
"18.1600","4.5101","4.5101","3.0067","29.6229","108.8640"
"18.2400","4.5312","4.5312","3.0208","29.7928","109.4884"
"18.3200","4.5513","4.5513","3.0342","29.9466","110.0538"
"18.4000","4.5710","4.5710","3.0473","30.1007","110.6201"
"18.4800","4.5916","4.5916","3.0611","30.2614","111.2107"
"18.5600","4.6109","4.6109","3.0739","30.4070","111.7458"
"18.6400","4.6318","4.6318","3.0879","30.5717","112.3510"
"18.7200","4.6515","4.6515","3.1010","30.7204","112.8973"
"18.8000","4.6706","4.6706","3.1138","30.8657","113.4315"
"18.8800","4.6904","4.6904","3.1269","31.0221","114.0063"
"18.9600","4.7100","4.7100","3.1400","31.1692","114.5467"
"19.0400","4.7304","4.7304","3.1536","31.3295","115.1360"
"19.1200","4.7520","4.7520","3.1680","31.4995","115.7606"
"19.2000","4.7708","4.7708","3.1806","31.6382","116.2705"
"19.2800","4.7914","4.7914","3.1943","31.7981","116.8578"
"19.3600","4.8107","4.8107","3.2072","31.9405","117.3812"
"19.4400","4.8303","4.8303","3.2202","32.0939","117.9449"
"19.5200","4.8511","4.8511","3.2341","32.2561","118.5413"
"19.6000","4.8705","4.8705","3.2470","32.3983","119.0636"
"19.6800","4.8913","4.8913","3.2609","32.5604","119.6595"
"19.7600","4.9123","4.9123","3.2748","32.7197","120.2448"
"19.8400","4.9315","4.9315","3.2877","32.8672","120.7870"
"19.9200","4.9514","4.9514","3.3009","33.0203","121.3495"
"20.0000","4.9708","4.9708","3.3139","33.1660","121.8851"
"20.0800","4.9907","4.9907","3.3272","33.3179","122.4435"
"20.1600","5.0110","5.0110","3.3407","33.4707","123.0050"
"20.2400","5.0299","5.0299","3.3533","33.6129","123.5274"
"20.3200","5.0514","5.0514","3.3676","33.7803","124.1424"
"20.4000","5.0719","5.0719","3.3812","33.9354","124.7124"
"20.4800","5.0909","5.0909","3.3940","34.0753","125.2266"
"20.5600","5.1109","5.1109","3.4072","34.2319","125.8024"
"20.6400","5.1305","5.1305","3.4203","34.3752","126.3288"
"20.7200","5.1513","5.1513","3.4342","34.5357","126.9188"
"20.8000","5.1716","5.1716","3.4477","34.6868","127.4739"
"20.8800","5.1899","5.1899","3.4599","34.8211","127.9677"
"20.9600","5.2113","5.2113","3.4742","34.9896","128.5869"
"21.0400","5.2318","5.2318","3.4879","35.1417","129.1459"
"21.1200","5.2524","5.2524","3.5016","35.2986","129.7223"
"21.2000","5.2715","5.2715","3.5143","35.4405","130.2439"
"21.2800","5.2903","5.2903","3.5269","35.5778","130.7485"
"21.3600","5.3106","5.3106","3.5404","35.7296","131.3062"
"21.4400","5.3307","5.3307","3.5538","35.8779","131.8514"
"21.5200","5.3499","5.3499","3.5666","36.0227","132.3833"
"21.6000","5.3719","5.3719","3.5812","36.1907","133.0008"
"21.6800","5.3912","5.3912","3.5941","36.3284","133.5069"
"21.7600","5.4116","5.4116","3.6077","36.4812","134.0686"
"21.8400","5.4314","5.4314","3.6209","36.6276","134.6065"
"21.9200","5.4509","5.4509","3.6339","36.7736","135.1431"
"22.0000","5.4708","5.4708","3.6472","36.9195","135.6791"
"22.0800","5.4902","5.4902","3.6601","37.0610","136.1992"
"22.1600","5.5105","5.5105","3.6737","37.2143","136.7624"
"22.2400","5.5323","5.5323","3.6882","37.3823","137.3801"
"22.3200","5.5518","5.5518","3.7012","37.5196","137.8845"
"22.4000","5.5717","5.5717","3.7145","37.6644","138.4165"
"22.4800","5.5913","5.5913","3.7275","37.8060","138.9369"
"22.5600","5.6101","5.6101","3.7401","37.9450","139.4478"
"22.6400","5.6308","5.6308","3.7539","38.0962","140.0034"
"22.7200","5.6501","5.6501","3.7668","38.2359","140.5170"
"22.8000","5.6711","5.6711","3.7807","38.3924","141.0919"
"22.8800","5.6915","5.6915","3.7943","38.5439","141.6487"
"22.9600","5.7113","5.7113","3.8076","38.6878","142.1776"
"23.0400","5.7311","5.7311","3.8207","38.8309","142.7036"
"23.1200","5.7514","5.7514","3.8343","38.9796","143.2500"
"23.2000","5.7709","5.7709","3.8473","39.1198","143.7652"
"23.2800","5.7909","5.7909","3.8606","39.2649","144.2986"
"23.3600","5.8098","5.8098","3.8732","39.3975","144.7859"
"23.4400","5.8318","5.8318","3.8878","39.5642","145.3985"
"23.5200","5.8525","5.8525","3.9017","39.7141","145.9494"
"23.6000","5.8721","5.8721","3.9148","39.8570","146.4746"
"23.6800","5.8911","5.8911","3.9274","39.9930","146.9744"
"23.7600","5.9105","5.9105","3.9403","40.1284","147.4720"
"23.8400","5.9308","5.9308","3.9539","40.2809","148.0323"
"23.9200","5.9514","5.9514","3.9676","40.4292","148.5774"
"24.0000","5.9702","5.9702","3.9801","40.5606","149.0603"
"24.0800","5.9912","5.9912","3.9941","40.7140","149.6238"
"24.1600","6.0111","6.0111","4.0074","40.8528","150.1342"
"24.2400","6.0313","6.0313","4.0209","40.9972","150.6647"
"24.3200","6.0514","6.0514","4.0342","41.1396","151.1882"
"24.4000","6.0703","6.0703","4.0468","41.2721","151.6751"
"24.4800","6.0911","6.0911","4.0607","41.4210","152.2223"
"24.5600","6.1109","6.1109","4.0739","41.5591","152.7295"
"24.6400","6.1308","6.1308","4.0872","41.7020","153.2547"
"24.7200","6.1520","6.1520","4.1013","41.8563","153.8220"
"24.8000","6.1721","6.1721","4.1147","41.9975","154.3407"
"24.8800","6.1914","6.1914","4.1276","42.1290","154.8240"
"24.9600","6.2115","6.2115","4.1410","42.2703","155.3434"
"25.0400","6.2303","6.2303","4.1535","42.4027","155.8298"
"25.1200","6.2511","6.2511","4.1674","42.5546","156.3882"
"25.2000","6.2703","6.2703","4.1802","42.6851","156.8679"
"25.2800","6.2903","6.2903","4.1935","42.8257","157.3844"
"25.3600","6.3108","6.3108","4.2072","42.9716","157.9208"
"25.4400","6.3311","6.3311","4.2207","43.1116","158.4350"
"25.5200","6.3517","6.3517","4.2345","43.2551","158.9625"
"25.6000","6.3719","6.3719","4.2479","43.3976","159.4863"
"25.6800","6.3902","6.3902","4.2601","43.5238","159.9499"
"25.7600","6.4106","6.4106","4.2737","43.6680","160.4799"
"25.8400","6.4305","6.4305","4.2870","43.8110","161.0053"
"25.9200","6.4518","6.4518","4.3012","43.9629","161.5636"
"26.0000","6.4723","6.4723","4.3149","44.1057","162.0883"
"26.0800","6.4914","6.4914","4.3276","44.2342","162.5608"
"26.1600","6.5110","6.5110","4.3407","44.3689","163.0557"
"26.2400","6.5312","6.5312","4.3541","44.5071","163.5637"
"26.3200","6.5509","6.5509","4.3673","44.6438","164.0658"
"26.4000","6.5713","6.5713","4.3808","44.7867","164.5910"
"26.4800","6.5900","6.5900","4.3934","44.9139","165.0586"
"26.5600","6.6106","6.6106","4.4071","45.0574","165.5861"
"26.6400","6.6309","6.6309","4.4206","45.1975","166.1007"
"26.7200","6.6508","6.6508","4.4339","45.3347","166.6049"
"26.8000","6.6721","6.6721","4.4480","45.4857","167.1601"
"26.8800","6.6907","6.6907","4.4605","45.6065","167.6040"
"26.9600","6.7112","6.7112","4.4741","45.7478","168.1231"
"27.0400","6.7310","6.7310","4.4873","45.8829","168.6196"
"27.1200","6.7501","6.7501","4.5001","46.0089","169.0827"
"27.2000","6.7714","6.7714","4.5143","46.1632","169.6499"
"27.2800","6.7922","6.7922","4.5282","46.3032","170.1644"
"27.3600","6.8112","6.8112","4.5408","46.4316","170.6362"
"27.4400","6.8315","6.8315","4.5543","46.5695","171.1429"
"27.5200","6.8503","6.8503","4.5669","46.6938","171.5996"
"27.6000","6.8713","6.8713","4.5809","46.8389","172.1329"
"27.6800","6.8908","6.8908","4.5939","46.9674","172.6051"
"27.7600","6.9101","6.9101","4.6068","47.0979","173.0848"
"27.8400","6.9309","6.9309","4.6206","47.2440","173.6219"
"27.9200","6.9515","6.9515","4.6344","47.3856","174.1422"
"28.0000","6.9714","6.9714","4.6476","47.5176","174.6273"
"28.0800","6.9916","6.9916","4.6610","47.6520","175.1212"
"28.1600","7.0102","7.0102","4.6735","47.7718","175.5612"
"28.2400","7.0312","7.0312","4.6875","47.9175","176.0967"
"28.3200","7.0514","7.0514","4.7009","48.0507","176.5862"
"28.4000","7.0710","7.0710","4.7140","48.1803","177.0628"
"28.4800","7.0916","7.0916","4.7277","48.3191","177.5728"
"28.5600","7.1113","7.1113","4.7409","48.4465","178.0408"
"28.6400","7.1318","7.1318","4.7545","48.5841","178.5464"
"28.7200","7.1518","7.1518","4.7678","48.7187","179.0412"
"28.8000","7.1709","7.1709","4.7806","48.8425","179.4963"
"28.8800","7.1905","7.1905","4.7937","48.9711","179.9688"
"28.9600","7.2103","7.2103","4.8069","49.1000","180.4424"
"29.0400","7.2302","7.2302","4.8201","49.2332","180.9322"
"29.1200","7.2521","7.2521","4.8347","49.3817","181.4777"
"29.2000","7.2707","7.2707","4.8471","49.4958","181.8970"
"29.2800","7.2912","7.2912","4.8608","49.6289","182.3863"
"29.3600","7.3107","7.3107","4.8738","49.7561","182.8538"
"29.4400","7.3311","7.3311","4.8874","49.8913","183.3506"
"29.5200","7.3509","7.3509","4.9006","50.0200","183.8237"
"29.6000","7.3707","7.3707","4.9138","50.1475","184.2920"
"29.6800","7.3911","7.3911","4.9274","50.2807","184.7816"
"29.7600","7.4125","7.4125","4.9417","50.4227","185.3034"
"29.8400","7.4317","7.4317","4.9544","50.5437","185.7481"
"29.9200","7.4512","7.4512","4.9675","50.6691","186.2088"
"30.0000","7.4705","7.4705","4.9804","50.7907","186.6560"
"30.0800","7.4906","7.4906","4.9937","50.9227","187.1410"
"30.1600","7.5114","7.5114","5.0076","51.0576","187.6367"
"30.2400","7.5300","7.5300","5.0200","51.1723","188.0582"
"30.3200","7.5511","7.5511","5.0341","51.3107","188.5668"
"30.4000","7.5719","7.5719","5.0480","51.4495","189.0768"
"30.4800","7.5911","7.5911","5.0607","51.5689","189.5156"
"30.5600","7.6108","7.6108","5.0739","51.6937","189.9743"
"30.6400","7.6306","7.6306","5.0870","51.8178","190.4305"
"30.7200","7.6515","7.6515","5.1010","51.9520","190.9238"
"30.8000","7.6719","7.6719","5.1146","52.0836","191.4072"
"30.8800","7.6901","7.6901","5.1268","52.1940","191.8130"
"30.9600","7.7112","7.7112","5.1408","52.3331","192.3242"
"31.0400","7.7317","7.7317","5.1544","52.4607","192.7929"
"31.1200","7.7523","7.7523","5.1682","52.5926","193.2779"
"31.2000","7.7715","7.7715","5.1810","52.7073","193.6993"
"31.2800","7.7904","7.7904","5.1936","52.8217","194.1196"
"31.3600","7.8107","7.8107","5.2071","52.9496","194.5899"
"31.4400","7.8310","7.8310","5.2206","53.0756","195.0528"
"31.5200","7.8500","7.8500","5.2333","53.1946","195.4901"
"31.6000","7.8716","7.8716","5.2477","53.3346","196.0047"
"31.6800","7.8911","7.8911","5.2607","53.4514","196.4339"
"31.7600","7.9117","7.9117","5.2745","53.5809","196.9100"
"31.8400","7.9312","7.9312","5.2875","53.6983","197.3414"
"31.9200","7.9507","7.9507","5.3005","53.8200","197.7885"
"32.0000","7.9704","7.9704","5.3136","53.9391","198.2262"
"32.0800","7.9908","7.9908","5.3272","54.0655","198.6907"
"32.1600","8.0107","8.0107","5.3405","54.1859","199.1333"
"32.2400","8.0324","8.0324","5.3549","54.3264","199.6497"
"32.3200","8.0517","8.0517","5.3678","54.4383","200.0609"
"32.4000","8.0715","8.0715","5.3810","54.5567","200.4960"
"32.4800","8.0911","8.0911","5.3941","54.6744","200.9284"
"32.5600","8.1101","8.1101","5.4067","54.7889","201.3493"
"32.6400","8.1310","8.1310","5.4206","54.9176","201.8221"
"32.7200","8.1501","8.1501","5.4334","55.0310","202.2391"
"32.8000","8.1711","8.1711","5.4474","55.1595","202.7112"
"32.8800","8.1915","8.1915","5.4610","55.2824","203.1628"
"32.9600","8.2112","8.2112","5.4741","55.3972","203.5846"
"33.0400","8.2312","8.2312","5.4875","55.5174","204.0264"
"33.1200","8.2515","8.2515","5.5010","55.6362","204.4631"
"33.2000","8.2707","8.2707","5.5138","55.7482","204.8747"
"33.2800","8.2908","8.2908","5.5272","55.8685","205.3166"
"33.3600","8.3095","8.3095","5.5397","55.9721","205.6974"
"33.4400","8.3319","8.3319","5.5546","56.1138","206.2182"
"33.5200","8.3529","8.3529","5.5686","56.2420","206.6895"
"33.6000","8.3721","8.3721","5.5814","56.3535","207.0990"
"33.6800","8.3907","8.3907","5.5938","56.4555","207.4740"
"33.7600","8.4104","8.4104","5.6069","56.5676","207.8861"
"33.8400","8.4306","8.4306","5.6204","56.6866","208.3233"
"33.9200","8.4515","8.4515","5.6344","56.8100","208.7766"
"34.0000","8.4702","8.4702","5.6468","56.9153","209.1636"
"34.0800","8.4908","8.4908","5.6605","57.0385","209.6165"
"34.1600","8.5113","8.5113","5.6742","57.1596","210.0616"
"34.2400","8.5316","8.5316","5.6877","57.2774","210.4946"
"34.3200","8.5514","8.5514","5.7010","57.3906","210.9106"
"34.4000","8.5701","8.5701","5.7134","57.4901","211.2762"
"34.4800","8.5910","8.5910","5.7273","57.6107","211.7192"
"34.5600","8.6112","8.6112","5.7408","57.7267","212.1457"
"34.6400","8.6308","8.6308","5.7539","57.8383","212.5558"
"34.7200","8.6516","8.6516","5.7678","57.9639","213.0172"
"34.8000","8.6722","8.6722","5.7814","58.0826","213.4536"
"34.8800","8.6917","8.6917","5.7945","58.1909","213.8515"
"34.9600","8.7114","8.7114","5.8076","58.2981","214.2455"
"35.0400","8.7304","8.7304","5.8202","58.4019","214.6269"
"35.1200","8.7511","8.7511","5.8340","58.5204","215.0624"
"35.2000","8.7705","8.7705","5.8470","58.6298","215.4644"
"35.2800","8.7906","8.7906","5.8604","58.7408","215.8725"
"35.3600","8.8111","8.8111","5.8740","58.8584","216.3045"
"35.4400","8.8312","8.8312","5.8875","58.9678","216.7066"
"35.5200","8.8519","8.8519","5.9012","59.0828","217.1293"
"35.6000","8.8719","8.8719","5.9146","59.1916","217.5291"
"35.6800","8.8899","8.8899","5.9266","59.2849","217.8720"
"35.7600","8.9106","8.9106","5.9404","59.4029","218.3057"
"35.8400","8.9302","8.9302","5.9535","59.5062","218.6855"
"35.9200","8.9519","8.9519","5.9679","59.6316","219.1461"
"36.0000","8.9727","8.9727","5.9818","59.7460","219.5666"
"36.0800","8.9916","8.9916","5.9944","59.8412","219.9166"
"36.1600","9.0109","9.0109","6.0073","59.9430","220.2906"
"36.2400","9.0311","9.0311","6.0207","60.0546","220.7007"
"36.3200","9.0511","9.0511","6.0340","60.1642","221.1033"
"36.4000","9.0713","9.0713","6.0475","60.2755","221.5126"
"36.4800","9.0900","9.0900","6.0600","60.3685","221.8542"
"36.5600","9.1106","9.1106","6.0738","60.4818","222.2705"
"36.6400","9.1317","9.1317","6.0878","60.5967","222.6927"
"36.7200","9.1511","9.1511","6.1008","60.6984","223.0665"
"36.8000","9.1716","9.1716","6.1144","60.8046","223.4568"
"36.8800","9.1906","9.1906","6.1271","60.8987","223.8026"
"36.9600","9.2108","9.2108","6.1406","61.0090","224.2082"
"37.0400","9.2309","9.2309","6.1539","61.1148","224.5970"
"37.1200","9.2506","9.2506","6.1671","61.2162","224.9695"
"37.2000","9.2711","9.2711","6.1807","61.3234","225.3635"
"37.2800","9.2917","9.2917","6.1945","61.4300","225.7553"
"37.3600","9.3114","9.3114","6.2076","61.5315","226.1281"
"37.4400","9.3316","9.3316","6.2210","61.6349","226.5082"
"37.5200","9.3504","9.3504","6.2336","61.7252","226.8401"
"37.6000","9.3716","9.3716","6.2477","61.8366","227.2495"
"37.6800","9.3908","9.3908","6.2605","61.9310","227.5963"
"37.7600","9.4100","9.4100","6.2734","62.0280","227.9529"
"37.8400","9.4308","9.4308","6.2872","62.1391","228.3613"
"37.9200","9.4518","9.4518","6.3012","62.2478","228.7607"
"38.0000","9.4719","9.4719","6.3146","62.3454","229.1195"
"38.0800","9.4912","9.4912","6.3275","62.4391","229.4636"
"38.1600","9.5099","9.5099","6.3399","62.5245","229.7776"
"38.2400","9.5308","9.5308","6.3539","62.6336","230.1785"
"38.3200","9.5513","9.5513","6.3675","62.7352","230.5520"
"38.4000","9.5710","9.5710","6.3807","62.8343","230.9160"
"38.4800","9.5918","9.5918","6.3945","62.9364","231.2912"
"38.5600","9.6113","9.6113","6.4075","63.0255","231.6187"
"38.6400","9.6318","9.6318","6.4212","63.1269","231.9913"
"38.7200","9.6514","9.6514","6.4343","63.2186","232.3282"
"38.8000","9.6708","9.6708","6.4472","63.3094","232.6622"
"38.8800","9.6907","9.6907","6.4605","63.4050","233.0132"
"38.9600","9.7103","9.7103","6.4735","63.4955","233.3458"
"39.0400","9.7301","9.7301","6.4867","63.5903","233.6945"
"39.1200","9.7520","9.7520","6.5014","63.7012","234.1019"
"39.2000","9.7713","9.7713","6.5142","63.7897","234.4271"
"39.2800","9.7918","9.7918","6.5279","63.8876","234.7870"
"39.3600","9.8109","9.8109","6.5406","63.9703","235.0907"
"39.4400","9.8305","9.8305","6.5537","64.0601","235.4209"
"39.5200","9.8499","9.8499","6.5666","64.1480","235.7440"
"39.6000","9.8706","9.8706","6.5804","64.2452","236.1010"
"39.6800","9.8914","9.8914","6.5943","64.3439","236.4639"
"39.7600","9.9124","9.9124","6.6083","64.4410","236.8205"
"39.8400","9.9314","9.9314","6.6209","64.5240","237.1258"
"39.9200","9.9516","9.9516","6.6344","64.6142","237.4571"
"40.0000","9.9706","9.9706","6.6471","64.6944","237.7518"
"40.0800","9.9906","9.9906","6.6604","64.7871","238.0925"
"40.1600","10.0108","10.0108","6.6739","64.8825","238.4432"
"40.2400","10.0301","10.0301","6.6867","64.9650","238.7465"
"40.3200","10.0514","10.0514","6.7010","65.0629","239.1061"
"40.4000","10.0718","10.0718","6.7145","65.1524","239.4351"
"40.4800","10.0911","10.0911","6.7274","65.2319","239.7272"
"40.5600","10.1108","10.1108","6.7405","65.3191","240.0476"
"40.6400","10.1304","10.1304","6.7536","65.3990","240.3414"
"40.7200","10.1511","10.1511","6.7674","65.4918","240.6823"
"40.8000","10.1714","10.1714","6.7810","65.5792","241.0035"
"40.8800","10.1903","10.1903","6.7935","65.6583","241.2942"
"40.9600","10.2116","10.2116","6.8077","65.7539","241.6455"
"41.0400","10.2320","10.2320","6.8213","65.8403","241.9632"
"41.1200","10.2521","10.2521","6.8347","65.9219","242.2629"
"41.2000","10.2710","10.2710","6.8473","65.9970","242.5391"
"41.2800","10.2906","10.2906","6.8604","66.0750","242.8258"
"41.3600","10.3108","10.3108","6.8739","66.1641","243.1531"
"41.4400","10.3311","10.3311","6.8874","66.2469","243.4576"
"41.5200","10.3501","10.3501","6.9000","66.3224","243.7350"
"41.6000","10.3714","10.3714","6.9143","66.4174","244.0841"
"41.6800","10.3910","10.3910","6.9273","66.4905","244.3526"
"41.7600","10.4116","10.4116","6.9410","66.5751","244.6634"
"41.8400","10.4315","10.4315","6.9543","66.6542","244.9541"
"41.9200","10.4507","10.4507","6.9671","66.7310","245.2365"
"42.0000","10.4707","10.4707","6.9805","66.8072","245.5164"
"42.0800","10.4904","10.4904","6.9936","66.8799","245.7838"
"42.1600","10.5108","10.5108","7.0072","66.9616","246.0839"
"42.2400","10.5319","10.5319","7.0213","67.0491","246.4054"
"42.3200","10.5513","10.5513","7.0342","67.1175","246.6569"
"42.4000","10.5719","10.5719","7.0480","67.2003","246.9612"
"42.4800","10.5914","10.5914","7.0609","67.2687","247.2123"
"42.5600","10.6103","10.6103","7.0735","67.3362","247.4604"
"42.6400","10.6310","10.6310","7.0873","67.4183","247.7623"
"42.7200","10.6502","10.6502","7.1001","67.4864","248.0124"
"42.8000","10.6711","10.6711","7.1141","67.5681","248.3128"
"42.8800","10.6915","10.6915","7.1276","67.6464","248.6005"
"42.9600","10.7115","10.7115","7.1410","67.7174","248.8613"
"43.0400","10.7310","10.7310","7.1540","67.7908","249.1313"
"43.1200","10.7513","10.7513","7.1676","67.8637","249.3989"
"43.2000","10.7708","10.7708","7.1805","67.9296","249.6415"
"43.2800","10.7908","10.7908","7.1939","68.0031","249.9115"
"43.3600","10.8097","10.8097","7.2065","68.0671","250.1468"
"43.4400","10.8319","10.8319","7.2213","68.1574","250.4785"
"43.5200","10.8524","10.8524","7.2349","68.2286","250.7400"
"43.6000","10.8721","10.8721","7.2481","68.2969","250.9911"
"43.6800","10.8909","10.8909","7.2606","68.3573","251.2130"
"43.7600","10.9105","10.9105","7.2737","68.4198","251.4428"
"43.8400","10.9305","10.9305","7.2870","68.4899","251.7005"
"43.9200","10.9512","10.9512","7.3008","68.5635","251.9707"
"44.0000","10.9701","10.9701","7.3134","68.6211","252.1827"
"44.0800","10.9910","10.9910","7.3273","68.6964","252.4593"
"44.1600","11.0113","11.0113","7.3409","68.7645","252.7095"
"44.2400","11.0315","11.0315","7.3543","68.8332","252.9621"
"44.3200","11.0515","11.0515","7.3677","68.8954","253.1907"
"44.4000","11.0704","11.0704","7.3802","68.9518","253.3977"
"44.4800","11.0912","11.0912","7.3941","69.0200","253.6484"
"44.5600","11.1105","11.1105","7.4070","69.0802","253.8698"
"44.6400","11.1309","11.1309","7.4206","69.1480","254.1187"
"44.7200","11.1519","11.1519","7.4346","69.2178","254.3755"
"44.8000","11.1722","11.1722","7.4482","69.2825","254.6131"
"44.8800","11.1912","11.1912","7.4608","69.3325","254.7968"
"44.9600","11.2117","11.2117","7.4745","69.3951","255.0269"
"45.0400","11.2306","11.2306","7.4871","69.4470","255.2177"
"45.1200","11.2512","11.2512","7.5008","69.5116","255.4550"
"45.2000","11.2703","11.2703","7.5135","69.5629","255.6435"
"45.2800","11.2903","11.2903","7.5269","69.6257","255.8746"
"45.3600","11.3105","11.3105","7.5404","69.6890","256.1070"
"45.4400","11.3315","11.3315","7.5543","69.7529","256.3418"
"45.5200","11.3519","11.3519","7.5679","69.8119","256.5586"
"45.6000","11.3721","11.3721","7.5814","69.8701","256.7726"
"45.6800","11.3903","11.3903","7.5935","69.9160","256.9412"
"45.7600","11.4103","11.4103","7.6069","69.9764","257.1632"
"45.8400","11.4302","11.4302","7.6201","70.0302","257.3611"
"45.9200","11.4518","11.4518","7.6345","70.1024","257.6262"
"46.0000","11.4725","11.4725","7.6483","70.1615","257.8434"
"46.0800","11.4915","11.4915","7.6610","70.2086","258.0167"
"46.1600","11.5111","11.5111","7.6741","70.2622","258.2135"
"46.2400","11.5310","11.5310","7.6873","70.3157","258.4101"
"46.3200","11.5510","11.5510","7.7007","70.3731","258.6210"
"46.4000","11.5709","11.5709","7.7139","70.4243","258.8092"
"46.4800","11.5900","11.5900","7.7267","70.4702","258.9781"
"46.5600","11.6108","11.6108","7.7405","70.5307","259.2002"
"46.6400","11.6315","11.6315","7.7543","70.5883","259.4120"
"46.7200","11.6513","11.6513","7.7675","70.6405","259.6039"
"46.8000","11.6721","11.6721","7.7814","70.6993","259.8199"
"46.8800","11.6905","11.6905","7.7937","70.7370","259.9586"
"46.9600","11.7105","11.7105","7.8070","70.7866","260.1406"
"47.0400","11.7300","11.7300","7.8200","70.8358","260.3217"
"47.1200","11.7511","11.7511","7.8340","70.8976","260.5488"
"47.2000","11.7715","11.7715","7.8476","70.9465","260.7283"
"47.2800","11.7919","11.7919","7.8613","70.9970","260.9140"
"47.3600","11.8114","11.8114","7.8742","71.0430","261.0830"
"47.4400","11.8318","11.8318","7.8878","71.0951","261.2743"
"47.5200","11.8507","11.8507","7.9005","71.1322","261.4108"
"47.6000","11.8715","11.8715","7.9144","71.1870","261.6124"
"47.6800","11.8907","11.8907","7.9272","71.2273","261.7603"
"47.7600","11.9099","11.9099","7.9399","71.2722","261.9254"
"47.8400","11.9309","11.9309","7.9539","71.3262","262.1238"
"47.9200","11.9517","11.9517","7.9678","71.3780","262.3142"
"48.0000","11.9718","11.9718","7.9812","71.4218","262.4751"
"48.0800","11.9916","11.9916","7.9944","71.4650","262.6339"
"48.1600","12.0098","12.0098","8.0066","71.4988","262.7582"
"48.2400","12.0309","12.0309","8.0206","71.5528","262.9566"
"48.3200","12.0512","12.0512","8.0341","71.5976","263.1211"
"48.4000","12.0709","12.0709","8.0473","71.6444","263.2931"
"48.4800","12.0916","12.0916","8.0610","71.6901","263.4612"
"48.5600","12.1112","12.1112","8.0741","71.7279","263.5999"
"48.6400","12.1319","12.1319","8.0879","71.7762","263.7775"
"48.7200","12.1516","12.1516","8.1011","71.8165","263.9258"
"48.8000","12.1709","12.1709","8.1139","71.8538","264.0626"
"48.8800","12.1905","12.1905","8.1270","71.8977","264.2242"
"48.9600","12.2104","12.2104","8.1403","71.9373","264.3694"
"49.0400","12.2304","12.2304","8.1536","71.9797","264.5256"
"49.1200","12.2522","12.2522","8.1681","72.0316","264.7161"
"49.2000","12.2712","12.2712","8.1808","72.0650","264.8390"
"49.2800","12.2918","12.2918","8.1946","72.1093","265.0015"
"49.3600","12.3107","12.3107","8.2071","72.1383","265.1082"
"49.4400","12.3309","12.3309","8.2206","72.1826","265.2709"
"49.5200","12.3509","12.3509","8.2340","72.2230","265.4196"
"49.6000","12.3708","12.3708","8.2472","72.2579","265.5479"
"49.6800","12.3906","12.3906","8.2604","72.2967","265.6903"
"49.7600","12.4123","12.4123","8.2749","72.3454","265.8695"
"49.8400","12.4314","12.4314","8.2876","72.3766","265.9840"
"49.9200","12.4518","12.4518","8.3012","72.4139","266.1210"
"50.0000","12.4706","12.4706","8.3137","72.4400","266.2169"
"50.0800","12.4906","12.4906","8.3270","72.4806","266.3660"
"50.1600","12.5110","12.5110","8.3407","72.5176","266.5023"
"50.2400","12.5300","12.5300","8.3533","72.5473","266.6114"
"50.3200","12.5512","12.5512","8.3675","72.5917","266.7744"
"50.4000","12.5718","12.5718","8.3812","72.6304","266.9167"
"50.4800","12.5914","12.5914","8.3943","72.6610","267.0292"
"50.5600","12.6108","12.6108","8.4072","72.6950","267.1542"
"50.6400","12.6304","12.6304","8.4203","72.7227","267.2560"
"50.7200","12.6511","12.6511","8.4341","72.7615","267.3987"
"50.8000","12.6718","12.6718","8.4478","72.8032","267.5516"
"50.8800","12.6905","12.6905","8.4603","72.8250","267.6318"
"50.9600","12.7116","12.7116","8.4744","72.8661","267.7831"
"51.0400","12.7315","12.7315","8.4877","72.8958","267.8922"
"51.1200","12.7522","12.7522","8.5015","72.9317","268.0241"
"51.2000","12.7714","12.7714","8.5143","72.9553","268.1108"
"51.2800","12.7904","12.7904","8.5269","72.9778","268.1935"
"51.3600","12.8108","12.8108","8.5405","73.0117","268.3181"
"51.4400","12.8311","12.8311","8.5541","73.0424","268.4310"
"51.5200","12.8501","12.8501","8.5667","73.0651","268.5143"
"51.6000","12.8714","12.8714","8.5809","73.1049","268.6605"
"51.6800","12.8910","12.8910","8.5940","73.1276","268.7437"
"51.7600","12.9117","12.9117","8.6078","73.1604","268.8643"
"51.8400","12.9314","12.9314","8.6210","73.1805","268.9382"
"51.9200","12.9505","12.9505","8.6337","73.2047","269.0274"
"52.0000","12.9704","12.9704","8.6470","73.2284","269.1143"
"52.0800","12.9906","12.9906","8.6604","73.2559","269.2153"
"52.1600","13.0108","13.0108","8.6739","73.2830","269.3149"
"52.2400","13.0322","13.0322","8.6881","73.3203","269.4523"
"52.3200","13.0519","13.0519","8.7012","73.3403","269.5255"
"52.4000","13.0717","13.0717","8.7145","73.3624","269.6067"
"52.4800","13.0913","13.0913","8.7275","73.3833","269.6835"
"52.5600","13.1103","13.1103","8.7402","73.4044","269.7612"
"52.6400","13.1312","13.1312","8.7541","73.4364","269.8788"
"52.7200","13.1500","13.1500","8.7666","73.4529","269.9394"
"52.8000","13.1713","13.1713","8.7809","73.4841","270.0541"
"52.8800","13.1918","13.1918","8.7946","73.5102","270.1500"
"52.9600","13.2116","13.2116","8.8077","73.5311","270.2267"
"53.0400","13.2311","13.2311","8.8208","73.5513","270.3008"
"53.1200","13.2511","13.2511","8.8341","73.5724","270.3784"
"53.2000","13.2707","13.2707","8.8471","73.5911","270.4474"
"53.2800","13.2915","13.2915","8.8610","73.6197","270.5524"
"53.3600","13.3096","13.3096","8.8731","73.6285","270.5849"
"53.4400","13.3317","13.3317","8.8878","73.6623","270.7089"
"53.5200","13.3524","13.3524","8.9016","73.6874","270.8013"
"53.6000","13.3721","13.3721","8.9147","73.7037","270.8612"
"53.6800","13.3910","13.3910","8.9274","73.7229","270.9318"
"53.7600","13.4106","13.4106","8.9404","73.7336","270.9709"
"53.8400","13.4305","13.4305","8.9536","73.7550","271.0497"
"53.9200","13.4512","13.4512","8.9675","73.7774","271.1320"
"54.0000","13.4699","13.4699","8.9800","73.7869","271.1669"
"54.0800","13.4909","13.4909","8.9939","73.8121","271.2595"
"54.1600","13.5109","13.5109","9.0073","73.8273","271.3152"
"54.2400","13.5318","13.5318","9.0212","73.8476","271.3901"
"54.3200","13.5516","13.5516","9.0344","73.8638","271.4495"
"54.4000","13.5702","13.5702","9.0468","73.8688","271.4678"
"54.4800","13.5910","13.5910","9.0607","73.8897","271.5445"
"54.5600","13.6112","13.6112","9.0741","73.9035","271.5953"
"54.6400","13.6311","13.6311","9.0874","73.9225","271.6651"
"54.7200","13.6518","13.6518","9.1012","73.9415","271.7352"
"54.8000","13.6720","13.6720","9.1147","73.9519","271.7733"
"54.8800","13.6913","13.6913","9.1275","73.9598","271.8021"
"54.9600","13.7115","13.7115","9.1410","73.9732","271.8516"
"55.0400","13.7305","13.7305","9.1536","73.9821","271.8841"
"55.1200","13.7513","13.7513","9.1675","73.9995","271.9483"
"55.2000","13.7702","13.7702","9.1801","74.0022","271.9582"
"55.2800","13.7902","13.7902","9.1935","74.0160","272.0087"
"55.3600","13.8107","13.8107","9.2071","74.0326","272.0700"
"55.4400","13.8316","13.8316","9.2210","74.0468","272.1220"
"55.5200","13.8517","13.8517","9.2345","74.0581","272.1634"
"55.6000","13.8716","13.8716","9.2478","74.0661","272.1930"
"55.6800","13.8901","13.8901","9.2601","74.0720","272.2146"
"55.7600","13.9106","13.9106","9.2738","74.0856","272.2646"
"55.8400","13.9304","13.9304","9.2869","74.0924","272.2897"
"55.9200","13.9518","13.9518","9.3012","74.1109","272.3576"
"56.0000","13.9725","13.9725","9.3150","74.1210","272.3945"
"56.0800","13.9915","13.9915","9.3277","74.1226","272.4005"
"56.1600","14.0112","14.0112","9.3408","74.1273","272.4178"
"56.2400","14.0313","14.0313","9.3542","74.1401","272.4649"
"56.3200","14.0510","14.0510","9.3673","74.1464","272.4880"
"56.4000","14.0715","14.0715","9.3810","74.1629","272.5485"
"56.4800","14.0899","14.0899","9.3933","74.1589","272.5341"
"56.5600","14.1107","14.1107","9.4072","74.1715","272.5802"
"56.6400","14.1323","14.1323","9.4215","74.1876","272.6394"
"56.7200","14.1515","14.1515","9.4343","74.1926","272.6579"
"56.8000","14.1715","14.1715","9.4476","74.1983","272.6787"
"56.8800","14.1904","14.1904","9.4603","74.1960","272.6702"
"56.9600","14.2108","14.2108","9.4739","74.2063","272.7080"
"57.0400","14.2309","14.2309","9.4873","74.2140","272.7363"
"57.1200","14.2508","14.2508","9.5005","74.2184","272.7526"
"57.2000","14.2711","14.2711","9.5141","74.2245","272.7750"
"57.2800","14.2921","14.2921","9.5280","74.2310","272.7988"
"57.3600","14.3114","14.3114","9.5409","74.2294","272.7929"
"57.4400","14.3315","14.3315","9.5543","74.2329","272.8060"
"57.5200","14.3505","14.3505","9.5670","74.2248","272.7760"
"57.6000","14.3712","14.3712","9.5808","74.2287","272.7903"
"57.6800","14.3910","14.3910","9.5940","74.2276","272.7863"
"57.7600","14.4099","14.4099","9.6066","74.2259","272.7802"
"57.8400","14.4309","14.4309","9.6206","74.2323","272.8036"
"57.9200","14.4517","14.4517","9.6345","74.2337","272.8088"
"58.0000","14.4714","14.4714","9.6476","74.2318","272.8020"
"58.0800","14.4914","14.4914","9.6609","74.2306","272.7973"
"58.1600","14.5101","14.5101","9.6734","74.2239","272.7729"
"58.2400","14.5310","14.5310","9.6873","74.2289","272.7910"
"58.3200","14.5514","14.5514","9.7009","74.2307","272.7977"
"58.4000","14.5711","14.5711","9.7141","74.2267","272.7830"
"58.4800","14.5916","14.5916","9.7277","74.2271","272.7845"
"58.5600","14.6112","14.6112","9.7408","74.2224","272.7674"
"58.6400","14.6318","14.6318","9.7546","74.2187","272.7538"
"58.7200","14.6516","14.6516","9.7677","74.2106","272.7239"
"58.8000","14.6707","14.6707","9.7805","74.1996","272.6835"
"58.8800","14.6906","14.6906","9.7937","74.1924","272.6570"
"58.9600","14.7102","14.7102","9.8068","74.1802","272.6121"
"59.0400","14.7304","14.7304","9.8203","74.1748","272.5923"
"59.1200","14.7521","14.7521","9.8347","74.1713","272.5797"
"59.2000","14.7710","14.7710","9.8473","74.1545","272.5179"
"59.2800","14.7917","14.7917","9.8611","74.1476","272.4923"
"59.3600","14.8109","14.8109","9.8739","74.1299","272.4274"
"59.4400","14.8307","14.8307","9.8871","74.1176","272.3823"
"59.5200","14.8510","14.8510","9.9007","74.1047","272.3347"
"59.6000","14.8706","14.8706","9.9138","74.0855","272.2643"
"59.6800","14.8910","14.8910","9.9273","74.0729","272.2178"
"59.7600","14.9124","14.9124","9.9416","74.0604","272.1721"
"59.8400","14.9313","14.9313","9.9542","74.0393","272.0942"
"59.9200","14.9513","14.9513","9.9675","74.0221","272.0311"
"60.0000","14.9706","14.9706","9.9804","73.9996","271.9484"
"60.0800","14.9909","14.9909","9.9940","73.9870","271.9022"
"60.1170","15.0002","15.0002","10.0001","73.9797","271.8753"