File: data/instron_tests/metamaterials/250421/250421_2224_BULK_m2.is_comp_Exports/250421_2224_BULK_m2_3_1.csv
Results Table 1
,Compresson Axis,H*,V*,Height,Thickness,Width,Area,Fixture separation,Specimen label
,,,,(mm),(mm),(mm),(mm^2),(mm),
"3","Y","","","150.00","28.00","150.00","4200.00","150.00","2224_BULK_m2"

Results Table 2
,Modulus (Segment 0 % - 2.5 %),Compresson Axis
,(kPa),
"3","798.69","Y"

Time,Displacement,Force,Compressive displacement,Compressive strain (Displacement),Compressive stress
(s),(mm),(N),(mm),(%),(kPa)
"0.0000","0.0001","-16.4588","0.0001","0.0001","-3.9188"
"0.0800","0.0013","-16.3283","0.0013","0.0008","-3.8877"
"0.1600","0.0176","-15.7704","0.0176","0.0117","-3.7549"
"0.2400","0.0379","-15.1272","0.0379","0.0253","-3.6017"
"0.3200","0.0583","-14.5229","0.0583","0.0389","-3.4578"
"0.4000","0.0775","-13.9653","0.0775","0.0516","-3.3251"
"0.4800","0.0985","-13.3583","0.0985","0.0656","-3.1805"
"0.5600","0.1183","-12.7937","0.1183","0.0789","-3.0461"
"0.6400","0.1378","-12.2527","0.1378","0.0919","-2.9173"
"0.7200","0.1578","-11.6959","0.1578","0.1052","-2.7847"
"0.8000","0.1776","-11.1633","0.1776","0.1184","-2.6579"
"0.8800","0.1980","-10.6061","0.1980","0.1320","-2.5253"
"0.9600","0.2180","-10.0717","0.2180","0.1453","-2.3980"
"1.0400","0.2365","-9.5615","0.2365","0.1576","-2.2765"
"1.1200","0.2576","-8.9998","0.2576","0.1717","-2.1428"
"1.2000","0.2781","-8.4571","0.2781","0.1854","-2.0136"
"1.2800","0.2980","-7.9320","0.2980","0.1987","-1.8886"
"1.3600","0.3182","-7.4080","0.3182","0.2121","-1.7638"
"1.4400","0.3367","-6.9308","0.3367","0.2245","-1.6502"
"1.5200","0.3572","-6.3994","0.3572","0.2382","-1.5237"
"1.6000","0.3778","-5.8832","0.3778","0.2519","-1.4008"
"1.6800","0.3977","-5.3642","0.3977","0.2651","-1.2772"
"1.7600","0.4186","-4.8195","0.4186","0.2791","-1.1475"
"1.8400","0.4380","-4.3439","0.4380","0.2920","-1.0343"
"1.9200","0.4582","-3.8398","0.4582","0.3054","-0.9142"
"2.0000","0.4784","-3.3323","0.4784","0.3189","-0.7934"
"2.0800","0.4972","-2.8731","0.4972","0.3314","-0.6841"
"2.1600","0.5174","-2.3679","0.5174","0.3449","-0.5638"
"2.2400","0.5369","-1.9006","0.5369","0.3579","-0.4525"
"2.3200","0.5570","-1.4043","0.5570","0.3713","-0.3343"
"2.4000","0.5787","-0.8690","0.5787","0.3858","-0.2069"
"2.4800","0.5982","-0.4004","0.5982","0.3988","-0.0953"
"2.5600","0.6185","0.0781","0.6185","0.4123","0.0186"
"2.6400","0.6377","0.5394","0.6377","0.4251","0.1284"
"2.7200","0.6566","0.9929","0.6566","0.4377","0.2364"
"2.8000","0.6772","1.5024","0.6772","0.4515","0.3577"
"2.8800","0.6976","1.9683","0.6976","0.4651","0.4686"
"2.9600","0.7182","2.4619","0.7182","0.4788","0.5862"
"3.0400","0.7388","2.9488","0.7388","0.4926","0.7021"
"3.1200","0.7575","3.3915","0.7575","0.5050","0.8075"
"3.2000","0.7781","3.8861","0.7781","0.5187","0.9253"
"3.2800","0.7979","4.3551","0.7979","0.5319","1.0369"
"3.3600","0.8177","4.8256","0.8177","0.5451","1.1490"
"3.4400","0.8375","5.2872","0.8375","0.5584","1.2589"
"3.5200","0.8564","5.7435","0.8564","0.5710","1.3675"
"3.6000","0.8777","6.2299","0.8777","0.5852","1.4833"
"3.6800","0.8988","6.7294","0.8988","0.5992","1.6022"
"3.7600","0.9178","7.1687","0.9178","0.6119","1.7068"
"3.8400","0.9377","7.6376","0.9377","0.6251","1.8185"
"3.9200","0.9570","8.0825","0.9570","0.6380","1.9244"
"4.0000","0.9768","8.5639","0.9768","0.6512","2.0390"
"4.0800","0.9982","9.0515","0.9982","0.6655","2.1551"
"4.1600","1.0171","9.4906","1.0171","0.6781","2.2597"
"4.2400","1.0384","9.9915","1.0384","0.6923","2.3789"
"4.3200","1.0586","10.4586","1.0586","0.7058","2.4901"
"4.4000","1.0784","10.9119","1.0784","0.7189","2.5981"
"4.4800","1.0980","11.3577","1.0980","0.7320","2.7042"
"4.5600","1.1172","11.7906","1.1172","0.7448","2.8073"
"4.6400","1.1374","12.2613","1.1374","0.7583","2.9194"
"4.7200","1.1577","12.7200","1.1577","0.7718","3.0286"
"4.8000","1.1764","13.1486","1.1764","0.7842","3.1306"
"4.8800","1.1982","13.6569","1.1982","0.7988","3.2516"
"4.9600","1.2184","14.1104","1.2184","0.8123","3.3596"
"5.0400","1.2384","14.5571","1.2384","0.8256","3.4660"
"5.1200","1.2579","15.0000","1.2579","0.8386","3.5714"
"5.2000","1.2766","15.4113","1.2766","0.8511","3.6694"
"5.2800","1.2976","15.8893","1.2976","0.8650","3.7832"
"5.3600","1.3178","16.3555","1.3178","0.8785","3.8942"
"5.4400","1.3376","16.7985","1.3376","0.8917","3.9996"
"5.5200","1.3585","17.2878","1.3585","0.9057","4.1161"
"5.6000","1.3782","17.7193","1.3782","0.9188","4.2189"
"5.6800","1.3986","18.1861","1.3986","0.9324","4.3300"
"5.7600","1.4184","18.6295","1.4184","0.9456","4.4356"
"5.8400","1.4371","19.0524","1.4371","0.9580","4.5363"
"5.9200","1.4576","19.5178","1.4576","0.9718","4.6471"
"6.0000","1.4770","19.9590","1.4770","0.9847","4.7521"
"6.0800","1.4979","20.4409","1.4979","0.9986","4.8669"
"6.1600","1.5187","20.9105","1.5187","1.0125","4.9787"
"6.2400","1.5378","21.3361","1.5378","1.0252","5.0800"
"6.3200","1.5574","21.7741","1.5574","1.0383","5.1843"
"6.4000","1.5775","22.2302","1.5775","1.0517","5.2929"
"6.4800","1.5967","22.6691","1.5967","1.0645","5.3974"
"6.5600","1.6179","23.1554","1.6179","1.0786","5.5132"
"6.6400","1.6368","23.5706","1.6368","1.0912","5.6120"
"6.7200","1.6579","24.0516","1.6579","1.1053","5.7266"
"6.8000","1.6788","24.5337","1.6788","1.1192","5.8414"
"6.8800","1.6984","24.9724","1.6984","1.1323","5.9458"
"6.9600","1.7176","25.4023","1.7176","1.1451","6.0482"
"7.0400","1.7375","25.8498","1.7375","1.1583","6.1547"
"7.1200","1.7573","26.2890","1.7573","1.1715","6.2593"
"7.2000","1.7781","26.7562","1.7781","1.1854","6.3705"
"7.2800","1.7971","27.1847","1.7971","1.1980","6.4725"
"7.3600","1.8178","27.6521","1.8178","1.2119","6.5838"
"7.4400","1.8382","28.1062","1.8382","1.2254","6.6920"
"7.5200","1.8580","28.5521","1.8580","1.2387","6.7981"
"7.6000","1.8780","29.0006","1.8780","1.2520","6.9049"
"7.6800","1.8974","29.4391","1.8974","1.2650","7.0093"
"7.7600","1.9179","29.8890","1.9179","1.2786","7.1164"
"7.8400","1.9377","30.3320","1.9377","1.2918","7.2219"
"7.9200","1.9568","30.7537","1.9568","1.3046","7.3223"
"8.0000","1.9777","31.2355","1.9777","1.3185","7.4370"
"8.0800","1.9987","31.6949","1.9987","1.3324","7.5464"
"8.1600","2.0188","32.1483","2.0188","1.3459","7.6544"
"8.2400","2.0384","32.5708","2.0384","1.3589","7.7549"
"8.3200","2.0567","32.9633","2.0567","1.3711","7.8484"
"8.4000","2.0780","33.4584","2.0780","1.3854","7.9663"
"8.4800","2.0974","33.8827","2.0974","1.3983","8.0673"
"8.5600","2.1175","34.3377","2.1175","1.4117","8.1757"
"8.6400","2.1378","34.7928","2.1378","1.4252","8.2840"
"8.7200","2.1581","35.2254","2.1581","1.4387","8.3870"
"8.8000","2.1780","35.6656","2.1780","1.4520","8.4918"
"8.8800","2.1983","36.1211","2.1983","1.4656","8.6003"
"8.9600","2.2169","36.5306","2.2169","1.4779","8.6978"
"9.0400","2.2376","36.9881","2.2376","1.4917","8.8067"
"9.1200","2.2571","37.4062","2.2571","1.5047","8.9062"
"9.2000","2.2776","37.8699","2.2776","1.5184","9.0166"
"9.2800","2.2991","38.3266","2.2991","1.5328","9.1254"
"9.3600","2.3187","38.7413","2.3187","1.5458","9.2241"
"9.4400","2.3382","39.1446","2.3382","1.5588","9.3201"
"9.5200","2.3576","39.5624","2.3576","1.5717","9.4196"
"9.6000","2.3772","39.9753","2.3772","1.5848","9.5179"
"9.6800","2.3971","40.3981","2.3971","1.5981","9.6186"
"9.7600","2.4167","40.8032","2.4167","1.6111","9.7150"
"9.8400","2.4378","41.2567","2.4378","1.6252","9.8230"
"9.9200","2.4586","41.6957","2.4586","1.6391","9.9276"
"10.0000","2.4777","42.0979","2.4777","1.6518","10.0233"
"10.0800","2.4984","42.5503","2.4984","1.6656","10.1310"
"10.1600","2.5179","42.9597","2.5179","1.6786","10.2285"
"10.2400","2.5372","43.3705","2.5372","1.6915","10.3263"
"10.3200","2.5573","43.8093","2.5573","1.7049","10.4308"
"10.4000","2.5770","44.2223","2.5770","1.7180","10.5291"
"10.4800","2.5982","44.6897","2.5982","1.7321","10.6404"
"10.5600","2.6192","45.1413","2.6192","1.7461","10.7479"
"10.6400","2.6380","45.5289","2.6380","1.7587","10.8402"
"10.7200","2.6577","45.9606","2.6577","1.7718","10.9430"
"10.8000","2.6771","46.3611","2.6771","1.7847","11.0384"
"10.8800","2.6983","46.8185","2.6983","1.7989","11.1473"
"10.9600","2.7181","47.2393","2.7181","1.8121","11.2475"
"11.0400","2.7366","47.6246","2.7366","1.8244","11.3392"
"11.1200","2.7573","48.0830","2.7573","1.8382","11.4483"
"11.2000","2.7781","48.5139","2.7781","1.8521","11.5509"
"11.2800","2.7981","48.9463","2.7981","1.8654","11.6539"
"11.3600","2.8182","49.3816","2.8182","1.8788","11.7575"
"11.4400","2.8367","49.7569","2.8367","1.8911","11.8469"
"11.5200","2.8571","50.2020","2.8571","1.9047","11.9529"
"11.6000","2.8777","50.6409","2.8777","1.9185","12.0574"
"11.6800","2.8976","51.0708","2.8976","1.9317","12.1597"
"11.7600","2.9187","51.5296","2.9187","1.9458","12.2690"
"11.8400","2.9381","51.9152","2.9381","1.9587","12.3608"
"11.9200","2.9583","52.3392","2.9583","1.9722","12.4617"
"12.0000","2.9780","52.7524","2.9780","1.9853","12.5601"
"12.0800","2.9974","53.1600","2.9974","1.9983","12.6572"
"12.1600","3.0178","53.6095","3.0178","2.0119","12.7642"
"12.2400","3.0373","54.0034","3.0373","2.0249","12.8579"
"12.3200","3.0568","54.4282","3.0568","2.0379","12.9591"
"12.4000","3.0784","54.8878","3.0784","2.0523","13.0685"
"12.4800","3.0978","55.2761","3.0978","2.0652","13.1610"
"12.5600","3.1185","55.7173","3.1185","2.0790","13.2660"
"12.6400","3.1378","56.1318","3.1378","2.0919","13.3647"
"12.7200","3.1572","56.5337","3.1572","2.1048","13.4604"
"12.8000","3.1772","56.9595","3.1772","2.1181","13.5618"
"12.8800","3.1975","57.3714","3.1975","2.1317","13.6599"
"12.9600","3.2179","57.8021","3.2179","2.1453","13.7624"
"13.0400","3.2389","58.2521","3.2389","2.1593","13.8696"
"13.1200","3.2578","58.6390","3.2578","2.1718","13.9617"
"13.2000","3.2781","59.0605","3.2781","2.1854","14.0620"
"13.2800","3.2977","59.4601","3.2977","2.1984","14.1572"
"13.3600","3.3174","59.8790","3.3174","2.2116","14.2569"
"13.4400","3.3377","60.2976","3.3377","2.2251","14.3566"
"13.5200","3.3564","60.6860","3.3564","2.2376","14.4491"
"13.6000","3.3779","61.1390","3.3779","2.2519","14.5569"
"13.6800","3.3987","61.5758","3.3987","2.2658","14.6609"
"13.7600","3.4180","61.9759","3.4180","2.2787","14.7562"
"13.8400","3.4377","62.3930","3.4377","2.2918","14.8555"
"13.9200","3.4571","62.7894","3.4571","2.3047","14.9499"
"14.0000","3.4774","63.2257","3.4774","2.3183","15.0537"
"14.0800","3.4981","63.6489","3.4981","2.3321","15.1545"
"14.1600","3.5171","64.0391","3.5171","2.3448","15.2474"
"14.2400","3.5383","64.4819","3.5383","2.3589","15.3528"
"14.3200","3.5582","64.8886","3.5582","2.3721","15.4497"
"14.4000","3.5783","65.3202","3.5783","2.3856","15.5524"
"14.4800","3.5978","65.7215","3.5978","2.3986","15.6480"
"14.5600","3.6173","66.1079","3.6173","2.4115","15.7400"
"14.6400","3.6372","66.5115","3.6372","2.4248","15.8361"
"14.7200","3.6575","66.9282","3.6575","2.4383","15.9353"
"14.8000","3.6768","67.3398","3.6768","2.4512","16.0333"
"14.8800","3.6980","67.7913","3.6980","2.4654","16.1408"
"14.9600","3.7181","68.1866","3.7181","2.4787","16.2349"
"15.0400","3.7382","68.6055","3.7382","2.4921","16.3346"
"15.1200","3.7579","69.0076","3.7579","2.5053","16.4304"
"15.2000","3.7767","69.4000","3.7767","2.5178","16.5238"
"15.2800","3.7977","69.8454","3.7977","2.5318","16.6299"
"15.3600","3.8175","70.2563","3.8175","2.5450","16.7277"
"15.4400","3.8377","70.6799","3.8377","2.5585","16.8286"
"15.5200","3.8586","71.1182","3.8586","2.5724","16.9329"
"15.6000","3.8782","71.5107","3.8782","2.5855","17.0264"
"15.6800","3.8985","71.9410","3.8985","2.5990","17.1288"
"15.7600","3.9184","72.3487","3.9184","2.6123","17.2259"
"15.8400","3.9371","72.7326","3.9371","2.6247","17.3173"
"15.9200","3.9577","73.1686","3.9577","2.6385","17.4211"
"16.0000","3.9768","73.5413","3.9768","2.6512","17.5098"
"16.0800","3.9977","73.9614","3.9977","2.6651","17.6099"
"16.1600","4.0188","74.4089","4.0188","2.6792","17.7164"
"16.2400","4.0379","74.7930","4.0379","2.6919","17.8079"
"16.3200","4.0576","75.2032","4.0576","2.7051","17.9055"
"16.4000","4.0776","75.6076","4.0776","2.7184","18.0018"
"16.4800","4.0968","76.0108","4.0968","2.7312","18.0978"
"16.5600","4.1181","76.4521","4.1181","2.7454","18.2029"
"16.6400","4.1368","76.8147","4.1368","2.7579","18.2892"
"16.7200","4.1581","77.2757","4.1581","2.7721","18.3990"
"16.8000","4.1785","77.6963","4.1785","2.7856","18.4991"
"16.8800","4.1982","78.1013","4.1982","2.7988","18.5956"
"16.9600","4.2179","78.4987","4.2179","2.8119","18.6902"
"17.0400","4.2376","78.8998","4.2376","2.8251","18.7857"
"17.1200","4.2575","79.3197","4.2575","2.8383","18.8857"
"17.2000","4.2777","79.7323","4.2777","2.8518","18.9839"
"17.2800","4.2960","80.0865","4.2960","2.8640","19.0682"
"17.3600","4.3178","80.5639","4.3178","2.8785","19.1819"
"17.4400","4.3385","80.9818","4.3385","2.8923","19.2814"
"17.5200","4.3581","81.3916","4.3581","2.9054","19.3789"
"17.6000","4.3780","81.7965","4.3780","2.9187","19.4754"
"17.6800","4.3972","82.1909","4.3972","2.9315","19.5693"
"17.7600","4.4180","82.6232","4.4180","2.9453","19.6722"
"17.8400","4.4376","83.0231","4.4376","2.9584","19.7674"
"17.9200","4.4570","83.4232","4.4570","2.9713","19.8627"
"18.0000","4.4781","83.8697","4.4781","2.9854","19.9690"
"18.0800","4.4987","84.2879","4.4987","2.9991","20.0686"
"18.1600","4.5185","84.6954","4.5185","3.0123","20.1656"
"18.2400","4.5383","85.0932","4.5383","3.0255","20.2603"
"18.3200","4.5566","85.4673","4.5566","3.0377","20.3494"
"18.4000","4.5780","85.9324","4.5780","3.0520","20.4601"
"18.4800","4.5973","86.3128","4.5973","3.0649","20.5507"
"18.5600","4.6173","86.7310","4.6173","3.0782","20.6502"
"18.6400","4.6379","87.1465","4.6379","3.0919","20.7492"
"18.7200","4.6579","87.5526","4.6579","3.1052","20.8459"
"18.8000","4.6777","87.9576","4.6777","3.1185","20.9423"
"18.8800","4.6985","88.3916","4.6985","3.1324","21.0456"
"18.9600","4.7170","88.7524","4.7170","3.1446","21.1315"
"19.0400","4.7374","89.1861","4.7374","3.1583","21.2348"
"19.1200","4.7564","89.5682","4.7564","3.1709","21.3258"
"19.2000","4.7776","90.0212","4.7776","3.1851","21.4336"
"19.2800","4.7994","90.4768","4.7994","3.1996","21.5421"
"19.3600","4.8189","90.8640","4.8189","3.2126","21.6343"
"19.4400","4.8383","91.2542","4.8383","3.2255","21.7272"
"19.5200","4.8576","91.6478","4.8576","3.2384","21.8209"
"19.6000","4.8773","92.0574","4.8773","3.2515","21.9184"
"19.6800","4.8977","92.4834","4.8977","3.2652","22.0199"
"19.7600","4.9170","92.8690","4.9170","3.2780","22.1117"
"19.8400","4.9373","93.2849","4.9373","3.2916","22.2107"
"19.9200","4.9581","93.7037","4.9581","3.3054","22.3104"
"20.0000","4.9772","94.0925","4.9772","3.3181","22.4030"
"20.0800","4.9984","94.5342","4.9984","3.3323","22.5081"
"20.1600","5.0175","94.9108","5.0175","3.3450","22.5978"
"20.2400","5.0376","95.3247","5.0376","3.3584","22.6964"
"20.3200","5.0573","95.7220","5.0573","3.3715","22.7909"
"20.4000","5.0771","96.1260","5.0771","3.3847","22.8871"
"20.4800","5.0983","96.5723","5.0983","3.3989","22.9934"
"20.5600","5.1190","96.9918","5.1190","3.4127","23.0933"
"20.6400","5.1378","97.3691","5.1378","3.4252","23.1831"
"20.7200","5.1581","97.7855","5.1581","3.4387","23.2823"
"20.8000","5.1771","98.1578","5.1771","3.4514","23.3709"
"20.8800","5.1980","98.5986","5.1980","3.4654","23.4759"
"20.9600","5.2181","98.9997","5.2181","3.4788","23.5714"
"21.0400","5.2366","99.3663","5.2366","3.4911","23.6586"
"21.1200","5.2574","99.8026","5.2574","3.5049","23.7625"
"21.2000","5.2781","100.2197","5.2781","3.5187","23.8618"
"21.2800","5.2981","100.6219","5.2981","3.5321","23.9576"
"21.3600","5.3182","101.0317","5.3182","3.5455","24.0552"
"21.4400","5.3367","101.3914","5.3367","3.5578","24.1408"
"21.5200","5.3572","101.8194","5.3572","3.5715","24.2427"
"21.6000","5.3777","102.2441","5.3777","3.5852","24.3438"
"21.6800","5.3976","102.6578","5.3977","3.5984","24.4423"
"21.7600","5.4187","103.0926","5.4187","3.6125","24.5459"
"21.8400","5.4378","103.4564","5.4378","3.6252","24.6325"
"21.9200","5.4583","103.8814","5.4583","3.6389","24.7337"
"22.0000","5.4782","104.2866","5.4782","3.6521","24.8301"
"22.0800","5.4978","104.6914","5.4978","3.6652","24.9265"
"22.1600","5.5178","105.0946","5.5178","3.6785","25.0225"
"22.2400","5.5371","105.4625","5.5371","3.6914","25.1101"
"22.3200","5.5568","105.8692","5.5568","3.7045","25.2070"
"22.4000","5.5778","106.2984","5.5778","3.7185","25.3092"
"22.4800","5.5974","106.6898","5.5974","3.7316","25.4023"
"22.5600","5.6186","107.1118","5.6186","3.7457","25.5028"
"22.6400","5.6375","107.4841","5.6375","3.7583","25.5914"
"22.7200","5.6568","107.8837","5.6568","3.7712","25.6866"
"22.8000","5.6771","108.3011","5.6771","3.7848","25.7860"
"22.8800","5.6976","108.7233","5.6976","3.7984","25.8865"
"22.9600","5.7184","109.1439","5.7184","3.8123","25.9866"
"23.0400","5.7389","109.5558","5.7389","3.8259","26.0847"
"23.1200","5.7575","109.9167","5.7575","3.8383","26.1706"
"23.2000","5.7779","110.3334","5.7779","3.8520","26.2699"
"23.2800","5.7980","110.7452","5.7980","3.8653","26.3679"
"23.3600","5.8178","111.1382","5.8178","3.8785","26.4615"
"23.4400","5.8378","111.5487","5.8378","3.8919","26.5592"
"23.5200","5.8567","111.9170","5.8567","3.9045","26.6469"
"23.6000","5.8779","112.3535","5.8779","3.9186","26.7508"
"23.6800","5.8988","112.7853","5.8988","3.9325","26.8537"
"23.7600","5.9183","113.1803","5.9183","3.9456","26.9477"
"23.8400","5.9379","113.5732","5.9379","3.9586","27.0412"
"23.9200","5.9567","113.9250","5.9567","3.9711","27.1250"
"24.0000","5.9768","114.3385","5.9768","3.9845","27.2234"
"24.0800","5.9983","114.7859","5.9983","3.9989","27.3300"
"24.1600","6.0172","115.1548","6.0172","4.0115","27.4178"
"24.2400","6.0381","115.5851","6.0381","4.0254","27.5203"
"24.3200","6.0587","116.0036","6.0587","4.0391","27.6199"
"24.4000","6.0789","116.4176","6.0789","4.0526","27.7185"
"24.4800","6.0982","116.8033","6.0982","4.0655","27.8103"
"24.5600","6.1172","117.1651","6.1172","4.0782","27.8965"
"24.6400","6.1373","117.5699","6.1373","4.0916","27.9928"
"24.7200","6.1578","117.9792","6.1578","4.1052","28.0903"
"24.8000","6.1765","118.3518","6.1765","4.1177","28.1790"
"24.8800","6.1973","118.7809","6.1973","4.1315","28.2812"
"24.9600","6.2181","119.1883","6.2181","4.1454","28.3782"
"25.0400","6.2388","119.6182","6.2388","4.1592","28.4805"
"25.1200","6.2580","119.9773","6.2580","4.1720","28.5660"
"25.2000","6.2765","120.3464","6.2765","4.1844","28.6539"
"25.2800","6.2976","120.7726","6.2976","4.1984","28.7554"
"25.3600","6.3177","121.1761","6.3177","4.2118","28.8515"
"25.4400","6.3377","121.5753","6.3377","4.2251","28.9465"
"25.5200","6.3584","122.0047","6.3584","4.2389","29.0487"
"25.6000","6.3783","122.3858","6.3783","4.2522","29.1395"
"25.6800","6.3985","122.7973","6.3985","4.2657","29.2375"
"25.7600","6.4184","123.1860","6.4184","4.2789","29.3300"
"25.8400","6.4371","123.5609","6.4371","4.2914","29.4193"
"25.9200","6.4575","123.9719","6.4575","4.3050","29.5171"
"26.0000","6.4769","124.3455","6.4769","4.3179","29.6061"
"26.0800","6.4980","124.7765","6.4980","4.3320","29.7087"
"26.1600","6.5188","125.2068","6.5188","4.3459","29.8111"
"26.2400","6.5381","125.5825","6.5381","4.3587","29.9006"
"26.3200","6.5579","125.9703","6.5579","4.3719","29.9929"
"26.4000","6.5774","126.3485","6.5774","4.3849","30.0830"
"26.4800","6.5970","126.7442","6.5970","4.3980","30.1772"
"26.5600","6.6180","127.1695","6.6180","4.4120","30.2785"
"26.6400","6.6371","127.5313","6.6371","4.4247","30.3646"
"26.7200","6.6580","127.9557","6.6580","4.4387","30.4657"
"26.8000","6.6785","128.3617","6.6785","4.4524","30.5623"
"26.8800","6.6983","128.7545","6.6983","4.4656","30.6558"
"26.9600","6.7182","129.1431","6.7182","4.4788","30.7483"
"27.0400","6.7378","129.5370","6.7378","4.4918","30.8422"
"27.1200","6.7574","129.9248","6.7574","4.5049","30.9345"
"27.2000","6.7778","130.3255","6.7778","4.5185","31.0299"
"27.2800","6.7963","130.6778","6.7963","4.5309","31.1138"
"27.3600","6.8176","131.1264","6.8176","4.5451","31.2206"
"27.4400","6.8385","131.5402","6.8385","4.5590","31.3191"
"27.5200","6.8580","131.9311","6.8580","4.5720","31.4122"
"27.6000","6.8777","132.3186","6.8777","4.5852","31.5044"
"27.6800","6.8970","132.6921","6.8970","4.5980","31.5934"
"27.7600","6.9178","133.1109","6.9178","4.6119","31.6931"
"27.8400","6.9379","133.5075","6.9379","4.6253","31.7875"
"27.9200","6.9566","133.8638","6.9566","4.6377","31.8723"
"28.0000","6.9779","134.3170","6.9779","4.6520","31.9803"
"28.0800","6.9992","134.7377","6.9992","4.6661","32.0804"
"28.1600","7.0189","135.1328","7.0189","4.6793","32.1745"
"28.2400","7.0383","135.5047","7.0383","4.6922","32.2630"
"28.3200","7.0568","135.8533","7.0568","4.7045","32.3460"
"28.4000","7.0777","136.2758","7.0777","4.7185","32.4466"
"28.4800","7.0974","136.6620","7.0974","4.7316","32.5386"
"28.5600","7.1173","137.0589","7.1173","4.7449","32.6331"
"28.6400","7.1378","137.4732","7.1378","4.7585","32.7317"
"28.7200","7.1580","137.8592","7.1580","4.7720","32.8236"
"28.8000","7.1777","138.2432","7.1777","4.7852","32.9150"
"28.8800","7.1983","138.6530","7.1983","4.7988","33.0126"
"28.9600","7.2168","139.0076","7.2168","4.8112","33.0970"
"29.0400","7.2373","139.4179","7.2373","4.8249","33.1947"
"29.1200","7.2568","139.7871","7.2568","4.8379","33.2826"
"29.2000","7.2778","140.2210","7.2778","4.8519","33.3859"
"29.2800","7.2991","140.6402","7.2991","4.8661","33.4858"
"29.3600","7.3185","141.0148","7.3185","4.8790","33.5750"
"29.4400","7.3380","141.4034","7.3380","4.8920","33.6675"
"29.5200","7.3578","141.7859","7.3578","4.9052","33.7586"
"29.6000","7.3773","142.1747","7.3773","4.9182","33.8511"
"29.6800","7.3976","142.5718","7.3976","4.9317","33.9457"
"29.7600","7.4169","142.9254","7.4169","4.9446","34.0298"
"29.8400","7.4371","143.3330","7.4371","4.9581","34.1269"
"29.9200","7.4585","143.7641","7.4585","4.9723","34.2296"
"30.0000","7.4777","144.1472","7.4777","4.9851","34.3208"
"30.0800","7.4983","144.5402","7.4983","4.9989","34.4143"
"30.1600","7.5174","144.9160","7.5174","5.0116","34.5038"
"30.2400","7.5373","145.2960","7.5373","5.0249","34.5943"
"30.3200","7.5573","145.6873","7.5573","5.0382","34.6875"
"30.4000","7.5773","146.0693","7.5773","5.0515","34.7784"
"30.4800","7.5983","146.4953","7.5983","5.0656","34.8798"
"30.5600","7.6191","146.8932","7.6191","5.0794","34.9746"
"30.6400","7.6379","147.2474","7.6379","5.0919","35.0589"
"30.7200","7.6579","147.6326","7.6579","5.1053","35.1506"
"30.8000","7.6773","148.0152","7.6773","5.1182","35.2417"
"30.8800","7.6985","148.4344","7.6985","5.1324","35.3415"
"30.9600","7.7181","148.8114","7.7181","5.1454","35.4313"
"31.0400","7.7369","149.1759","7.7369","5.1579","35.5181"
"31.1200","7.7575","149.5837","7.7575","5.1717","35.6152"
"31.2000","7.7783","149.9882","7.7783","5.1856","35.7115"
"31.2800","7.7982","150.3699","7.7982","5.1988","35.8023"
"31.3600","7.8183","150.7572","7.8183","5.2122","35.8946"
"31.4400","7.8369","151.1000","7.8369","5.2246","35.9762"
"31.5200","7.8572","151.4997","7.8572","5.2381","36.0714"
"31.6000","7.8776","151.8990","7.8776","5.2518","36.1664"
"31.6800","7.8977","152.3127","7.8977","5.2652","36.2649"
"31.7600","7.9189","152.7142","7.9189","5.2793","36.3605"
"31.8400","7.9381","153.0760","7.9381","5.2920","36.4467"
"31.9200","7.9579","153.4552","7.9579","5.3053","36.5370"
"32.0000","7.9782","153.8531","7.9782","5.3188","36.6317"
"32.0800","7.9977","154.2314","7.9977","5.3318","36.7218"
"32.1600","8.0176","154.6115","8.0176","5.3451","36.8123"
"32.2400","8.0372","154.9962","8.0372","5.3582","36.9039"
"32.3200","8.0566","155.3712","8.0566","5.3711","36.9931"
"32.4000","8.0784","155.8090","8.0784","5.3856","37.0974"
"32.4800","8.0976","156.1710","8.0976","5.3984","37.1836"
"32.5600","8.1185","156.5737","8.1185","5.4123","37.2795"
"32.6400","8.1377","156.9233","8.1377","5.4251","37.3627"
"32.7200","8.1571","157.2978","8.1571","5.4380","37.4519"
"32.8000","8.1771","157.6960","8.1771","5.4514","37.5467"
"32.8800","8.1976","158.0835","8.1976","5.4650","37.6389"
"32.9600","8.2181","158.4946","8.2181","5.4788","37.7368"
"33.0400","8.2386","158.8801","8.2386","5.4924","37.8286"
"33.1200","8.2573","159.2235","8.2573","5.5049","37.9104"
"33.2000","8.2783","159.6429","8.2783","5.5188","38.0102"
"33.2800","8.2979","160.0176","8.2979","5.5320","38.0994"
"33.3600","8.3179","160.3951","8.3179","5.5453","38.1893"
"33.4400","8.3378","160.7657","8.3378","5.5585","38.2776"
"33.5200","8.3564","161.1124","8.3564","5.5709","38.3601"
"33.6000","8.3777","161.5318","8.3777","5.5852","38.4599"
"33.6800","8.3991","161.9631","8.3991","5.5994","38.5626"
"33.7600","8.4181","162.3146","8.4181","5.6121","38.6463"
"33.8400","8.4376","162.6843","8.4376","5.6250","38.7344"
"33.9200","8.4568","163.0454","8.4568","5.6379","38.8203"
"34.0000","8.4774","163.4472","8.4774","5.6516","38.9160"
"34.0800","8.4984","163.8517","8.4984","5.6656","39.0123"
"34.1600","8.5170","164.1929","8.5170","5.6780","39.0935"
"34.2400","8.5381","164.6167","8.5381","5.6921","39.1945"
"34.3200","8.5583","164.9945","8.5583","5.7055","39.2844"
"34.4000","8.5783","165.3785","8.5783","5.7189","39.3758"
"34.4800","8.5981","165.7614","8.5981","5.7321","39.4670"
"34.5600","8.6175","166.1172","8.6175","5.7450","39.5517"
"34.6400","8.6372","166.4917","8.6372","5.7582","39.6409"
"34.7200","8.6575","166.8690","8.6575","5.7717","39.7307"
"34.8000","8.6767","167.2408","8.6767","5.7844","39.8192"
"34.8800","8.6978","167.6581","8.6978","5.7985","39.9186"
"34.9600","8.7181","168.0380","8.7181","5.8121","40.0091"
"35.0400","8.7386","168.4260","8.7386","5.8257","40.1014"
"35.1200","8.7579","168.7743","8.7579","5.8386","40.1844"
"35.2000","8.7766","169.1247","8.7766","5.8511","40.2678"
"35.2800","8.7973","169.5181","8.7973","5.8648","40.3614"
"35.3600","8.8176","169.9068","8.8176","5.8784","40.4540"
"35.4400","8.8376","170.2855","8.8376","5.8917","40.5442"
"35.5200","8.8584","170.6932","8.8584","5.9056","40.6412"
"35.6000","8.8778","171.0473","8.8778","5.9185","40.7256"
"35.6800","8.8985","171.4398","8.8985","5.9323","40.8190"
"35.7600","8.9184","171.8091","8.9184","5.9456","40.9069"
"35.8400","8.9370","172.1465","8.9370","5.9580","40.9873"
"35.9200","8.9574","172.5462","8.9574","5.9716","41.0824"
"36.0000","8.9770","172.9061","8.9770","5.9846","41.1681"
"36.0800","8.9982","173.3184","8.9982","5.9988","41.2663"
"36.1600","9.0188","173.7062","9.0188","6.0125","41.3586"
"36.2400","9.0380","174.0721","9.0380","6.0254","41.4457"
"36.3200","9.0577","174.4292","9.0577","6.0384","41.5308"
"36.4000","9.0773","174.7824","9.0773","6.0515","41.6149"
"36.4800","9.0967","175.1415","9.0967","6.0644","41.7004"
"36.5600","9.1178","175.5614","9.1178","6.0785","41.8003"
"36.6400","9.1369","175.9039","9.1369","6.0912","41.8819"
"36.7200","9.1583","176.3214","9.1583","6.1055","41.9813"
"36.8000","9.1788","176.7138","9.1788","6.1192","42.0747"
"36.8800","9.1984","177.0804","9.1984","6.1323","42.1620"
"36.9600","9.2181","177.4504","9.2181","6.1454","42.2501"
"37.0400","9.2377","177.8117","9.2377","6.1585","42.3361"
"37.1200","9.2575","178.1746","9.2575","6.1717","42.4225"
"37.2000","9.2779","178.5511","9.2779","6.1852","42.5122"
"37.2800","9.2963","178.8895","9.2963","6.1975","42.5927"
"37.3600","9.3178","179.3098","9.3178","6.2119","42.6928"
"37.4400","9.3383","179.6809","9.3383","6.2256","42.7812"
"37.5200","9.3579","180.0516","9.3579","6.2386","42.8694"
"37.6000","9.3777","180.4249","9.3777","6.2518","42.9583"
"37.6800","9.3969","180.7690","9.3969","6.2646","43.0402"
"37.7600","9.4179","181.1678","9.4179","6.2786","43.1352"
"37.8400","9.4377","181.5325","9.4377","6.2918","43.2220"
"37.9200","9.4570","181.8832","9.4570","6.3046","43.3055"
"38.0000","9.4775","182.2723","9.4775","6.3183","43.3982"
"38.0800","9.4988","182.6669","9.4988","6.3325","43.4921"
"38.1600","9.5185","183.0298","9.5185","6.3457","43.5785"
"38.2400","9.5386","183.3982","9.5386","6.3590","43.6662"
"38.3200","9.5568","183.7135","9.5568","6.3712","43.7413"
"38.4000","9.5781","184.1343","9.5781","6.3854","43.8415"
"38.4800","9.5976","184.4884","9.5976","6.3984","43.9258"
"38.5600","9.6175","184.8599","9.6175","6.4117","44.0143"
"38.6400","9.6377","185.2443","9.6377","6.4251","44.1058"
"38.7200","9.6579","185.6048","9.6579","6.4386","44.1916"
"38.8000","9.6778","185.9713","9.6778","6.4519","44.2789"
"38.8800","9.6983","186.3445","9.6983","6.4656","44.3677"
"38.9600","9.7170","186.6903","9.7170","6.4780","44.4501"
"39.0400","9.7378","187.0750","9.7378","6.4919","44.5417"
"39.1200","9.7568","187.4188","9.7568","6.5045","44.6235"
"39.2000","9.7776","187.8187","9.7776","6.5184","44.7187"
"39.2800","9.7989","188.2187","9.7989","6.5326","44.8140"
"39.3600","9.8186","188.5828","9.8186","6.5457","44.9007"
"39.4400","9.8384","188.9315","9.8384","6.5589","44.9837"
"39.5200","9.8579","189.2841","9.8579","6.5720","45.0676"
"39.6000","9.8773","189.6476","9.8773","6.5848","45.1542"
"39.6800","9.8975","190.0276","9.8975","6.5983","45.2447"
"39.7600","9.9167","190.3688","9.9167","6.6111","45.3259"
"39.8400","9.9373","190.7556","9.9373","6.6249","45.4180"
"39.9200","9.9587","191.1541","9.9587","6.6392","45.5129"
"40.0000","9.9774","191.4924","9.9774","6.6516","45.5934"
"40.0800","9.9981","191.8792","9.9981","6.6654","45.6855"
"40.1600","10.0173","192.2264","10.0173","6.6782","45.7682"
"40.2400","10.0375","192.5914","10.0375","6.6917","45.8551"
"40.3200","10.0569","192.9460","10.0569","6.7046","45.9395"
"40.4000","10.0770","193.3003","10.0770","6.7180","46.0239"
"40.4800","10.0983","193.7130","10.0983","6.7322","46.1222"
"40.5600","10.1196","194.1035","10.1196","6.7464","46.2151"
"40.6400","10.1377","194.4223","10.1377","6.7584","46.2910"
"40.7200","10.1579","194.7956","10.1579","6.7719","46.3799"
"40.8000","10.1773","195.1421","10.1773","6.7849","46.4624"
"40.8800","10.1984","195.5277","10.1984","6.7989","46.5542"
"40.9600","10.2180","195.8799","10.2180","6.8120","46.6381"
"41.0400","10.2368","196.2105","10.2368","6.8245","46.7168"
"41.1200","10.2572","196.5903","10.2572","6.8381","46.8072"
"41.2000","10.2781","196.9911","10.2781","6.8521","46.9026"
"41.2800","10.2983","197.3560","10.2983","6.8656","46.9895"
"41.3600","10.3183","197.7212","10.3183","6.8788","47.0765"
"41.4400","10.3370","198.0449","10.3370","6.8913","47.1535"
"41.5200","10.3573","198.4215","10.3573","6.9049","47.2432"
"41.6000","10.3776","198.7885","10.3776","6.9184","47.3306"
"41.6800","10.3975","199.1598","10.3975","6.9317","47.4190"
"41.7600","10.4190","199.5639","10.4190","6.9460","47.5152"
"41.8400","10.4379","199.8892","10.4379","6.9586","47.5927"
"41.9200","10.4584","200.2691","10.4584","6.9723","47.6831"
"42.0000","10.4781","200.6306","10.4781","6.9854","47.7692"
"42.0800","10.4977","200.9907","10.4977","6.9985","47.8549"
"42.1600","10.5175","201.3475","10.5175","7.0116","47.9399"
"42.2400","10.5370","201.7020","10.5370","7.0246","48.0243"
"42.3200","10.5568","202.0640","10.5568","7.0379","48.1105"
"42.4000","10.5784","202.4725","10.5784","7.0523","48.2077"
"42.4800","10.5980","202.8127","10.5980","7.0653","48.2887"
"42.5600","10.6183","203.1705","10.6183","7.0789","48.3739"
"42.6400","10.6370","203.4907","10.6370","7.0914","48.4502"
"42.7200","10.6569","203.8672","10.6569","7.1046","48.5398"
"42.8000","10.6771","204.2303","10.6771","7.1181","48.6263"
"42.8800","10.6977","204.6050","10.6977","7.1318","48.7155"
"42.9600","10.7183","204.9703","10.7183","7.1456","48.8024"
"43.0400","10.7389","205.3424","10.7389","7.1593","48.8910"
"43.1200","10.7573","205.6637","10.7573","7.1715","48.9675"
"43.2000","10.7782","206.0523","10.7782","7.1855","49.0601"
"43.2800","10.7979","206.3903","10.7979","7.1986","49.1405"
"43.3600","10.8178","206.7545","10.8178","7.2119","49.2273"
"43.4400","10.8376","207.1015","10.8376","7.2251","49.3099"
"43.5200","10.8565","207.4279","10.8565","7.2376","49.3876"
"43.6000","10.8778","207.8268","10.8778","7.2519","49.4826"
"43.6800","10.8986","208.2096","10.8986","7.2658","49.5737"
"43.7600","10.9181","208.5577","10.9181","7.2788","49.6566"
"43.8400","10.9378","208.9161","10.9378","7.2919","49.7419"
"43.9200","10.9572","209.2452","10.9572","7.3048","49.8203"
"44.0000","10.9770","209.6027","10.9770","7.3180","49.9054"
"44.0800","10.9979","209.9805","10.9979","7.3319","49.9953"
"44.1600","11.0171","210.3175","11.0171","7.3447","50.0756"
"44.2400","11.0387","210.7162","11.0387","7.3591","50.1705"
"44.3200","11.0584","211.0674","11.0584","7.3723","50.2542"
"44.4000","11.0789","211.4331","11.0789","7.3859","50.3412"
"44.4800","11.0979","211.7632","11.0979","7.3986","50.4198"
"44.5600","11.1174","212.0983","11.1174","7.4116","50.4996"
"44.6400","11.1373","212.4473","11.1373","7.4249","50.5827"
"44.7200","11.1575","212.8119","11.1575","7.4383","50.6695"
"44.8000","11.1768","213.1687","11.1768","7.4512","50.7545"
"44.8800","11.1981","213.5591","11.1981","7.4654","50.8474"
"44.9600","11.2180","213.9004","11.2180","7.4787","50.9287"
"45.0400","11.2383","214.2647","11.2383","7.4922","51.0154"
"45.1200","11.2577","214.5923","11.2577","7.5051","51.0934"
"45.2000","11.2765","214.9269","11.2765","7.5177","51.1731"
"45.2800","11.2977","215.3089","11.2977","7.5318","51.2640"
"45.3600","11.3177","215.6611","11.3177","7.5452","51.3479"
"45.4400","11.3373","216.0052","11.3373","7.5582","51.4298"
"45.5200","11.3586","216.3964","11.3586","7.5724","51.5230"
"45.6000","11.3783","216.7412","11.3783","7.5856","51.6051"
"45.6800","11.3985","217.0908","11.3985","7.5990","51.6883"
"45.7600","11.4184","217.4357","11.4184","7.6123","51.7704"
"45.8400","11.4369","217.7681","11.4369","7.6246","51.8496"
"45.9200","11.4571","218.1255","11.4571","7.6381","51.9347"
"46.0000","11.4768","218.4688","11.4768","7.6512","52.0164"
"46.0800","11.4982","218.8641","11.4982","7.6655","52.1105"
"46.1600","11.5185","219.2222","11.5185","7.6790","52.1958"
"46.2400","11.5380","219.5544","11.5380","7.6920","52.2749"
"46.3200","11.5578","219.9020","11.5578","7.7052","52.3576"
"46.4000","11.5776","220.2416","11.5776","7.7184","52.4385"
"46.4800","11.5970","220.5977","11.5970","7.7313","52.5233"
"46.5600","11.6182","220.9794","11.6182","7.7455","52.6142"
"46.6400","11.6366","221.2807","11.6366","7.7578","52.6859"
"46.7200","11.6582","221.6810","11.6582","7.7721","52.7812"
"46.8000","11.6787","222.0425","11.6787","7.7858","52.8673"
"46.8800","11.6984","222.3936","11.6984","7.7989","52.9509"
"46.9600","11.7181","222.7316","11.7181","7.8121","53.0313"
"47.0400","11.7377","223.0727","11.7377","7.8251","53.1125"
"47.1200","11.7574","223.4149","11.7574","7.8383","53.1940"
"47.2000","11.7777","223.7780","11.7777","7.8518","53.2805"
"47.2800","11.7966","224.0937","11.7966","7.8644","53.3556"
"47.3600","11.8177","224.4792","11.8177","7.8784","53.4474"
"47.4400","11.8382","224.8506","11.8382","7.8921","53.5359"
"47.5200","11.8580","225.1837","11.8580","7.9053","53.6152"
"47.6000","11.8781","225.5443","11.8781","7.9187","53.7010"
"47.6800","11.8971","225.8658","11.8971","7.9314","53.7776"
"47.7600","11.9181","226.2333","11.9181","7.9454","53.8651"
"47.8400","11.9377","226.5633","11.9377","7.9584","53.9436"
"47.9200","11.9567","226.8927","11.9567","7.9711","54.0221"
"48.0000","11.9779","227.2779","11.9779","7.9853","54.1138"
"48.0800","11.9986","227.6505","11.9986","7.9991","54.2025"
"48.1600","12.0185","227.9970","12.0185","8.0123","54.2850"
"48.2400","12.0384","228.3372","12.0384","8.0256","54.3660"
"48.3200","12.0567","228.6328","12.0567","8.0378","54.4364"
"48.4000","12.0778","229.0092","12.0778","8.0519","54.5260"
"48.4800","12.0976","229.3440","12.0976","8.0650","54.6057"
"48.5600","12.1176","229.7029","12.1176","8.0784","54.6912"
"48.6400","12.1378","230.0608","12.1378","8.0918","54.7764"
"48.7200","12.1583","230.4234","12.1583","8.1055","54.8627"
"48.8000","12.1780","230.7507","12.1780","8.1187","54.9406"
"48.8800","12.1984","231.1019","12.1984","8.1323","55.0243"
"48.9600","12.2169","231.4090","12.2169","8.1446","55.0974"
"49.0400","12.2375","231.7793","12.2375","8.1583","55.1855"
"49.1200","12.2570","232.1029","12.2570","8.1713","55.2626"
"49.2000","12.2779","232.4869","12.2779","8.1853","55.3540"
"49.2800","12.2992","232.8596","12.2992","8.1994","55.4428"
"49.3600","12.3185","233.1850","12.3185","8.2123","55.5202"
"49.4400","12.3383","233.5163","12.3383","8.2255","55.5991"
"49.5200","12.3576","233.8441","12.3576","8.2384","55.6772"
"49.6000","12.3774","234.1927","12.3774","8.2516","55.7602"
"49.6800","12.3978","234.5463","12.3978","8.2652","55.8444"
"49.7600","12.4168","234.8564","12.4168","8.2778","55.9182"
"49.8400","12.4371","235.2128","12.4371","8.2914","56.0031"
"49.9200","12.4585","235.5881","12.4585","8.3056","56.0924"
"50.0000","12.4776","235.9095","12.4776","8.3184","56.1689"
"50.0800","12.4983","236.2718","12.4983","8.3322","56.2552"
"50.1600","12.5172","236.5748","12.5172","8.3448","56.3273"
"50.2400","12.5376","236.9347","12.5376","8.3584","56.4130"
"50.3200","12.5572","237.2767","12.5572","8.3715","56.4944"
"50.4000","12.5771","237.6143","12.5771","8.3847","56.5748"
"50.4800","12.5982","237.9935","12.5982","8.3988","56.6651"
"50.5600","12.6190","238.3477","12.6190","8.4127","56.7495"
"50.6400","12.6378","238.6492","12.6378","8.4252","56.8212"
"50.7200","12.6579","238.9958","12.6579","8.4386","56.9038"
"50.8000","12.6768","239.2940","12.6768","8.4512","56.9748"
"50.8800","12.6982","239.6703","12.6982","8.4655","57.0644"
"50.9600","12.7180","240.0090","12.7180","8.4787","57.1450"
"51.0400","12.7370","240.3311","12.7370","8.4913","57.2217"
"51.1200","12.7575","240.6858","12.7575","8.5050","57.3061"
"51.2000","12.7783","241.0438","12.7783","8.5188","57.3914"
"51.2800","12.7983","241.3826","12.7983","8.5322","57.4720"
"51.3600","12.8184","241.7278","12.8184","8.5456","57.5542"
"51.4400","12.8370","242.0242","12.8370","8.5580","57.6248"
"51.5200","12.8573","242.3751","12.8573","8.5715","57.7084"
"51.6000","12.8774","242.7166","12.8774","8.5849","57.7897"
"51.6800","12.8972","243.0585","12.8972","8.5981","57.8711"
"51.7600","12.9191","243.4731","12.9191","8.6127","57.9698"
"51.8400","12.9384","243.7903","12.9384","8.6256","58.0453"
"51.9200","12.9584","244.1239","12.9584","8.6389","58.1247"
"52.0000","12.9779","244.4506","12.9779","8.6519","58.2025"
"52.0800","12.9976","244.7813","12.9976","8.6651","58.2813"
"52.1600","13.0175","245.1243","13.0175","8.6784","58.3629"
"52.2400","13.0373","245.4495","13.0373","8.6915","58.4403"
"52.3200","13.0568","245.7782","13.0568","8.7045","58.5186"
"52.4000","13.0786","246.1860","13.0786","8.7190","58.6157"
"52.4800","13.0981","246.5023","13.0981","8.7321","58.6910"
"52.5600","13.1186","246.8479","13.1186","8.7457","58.7733"
"52.6400","13.1376","247.1591","13.1376","8.7584","58.8474"
"52.7200","13.1570","247.4768","13.1570","8.7713","58.9231"
"52.8000","13.1769","247.8160","13.1769","8.7846","59.0038"
"52.8800","13.1971","248.1533","13.1971","8.7981","59.0841"
"52.9600","13.2179","248.5007","13.2179","8.8119","59.1668"
"53.0400","13.2392","248.8607","13.2392","8.8261","59.2526"
"53.1200","13.2579","249.1722","13.2579","8.8386","59.3267"
"53.2000","13.2780","249.5134","13.2780","8.8520","59.4080"
"53.2800","13.2977","249.8329","13.2977","8.8652","59.4840"
"53.3600","13.3175","250.1644","13.3175","8.8783","59.5629"
"53.4400","13.3380","250.5083","13.3380","8.8920","59.6448"
"53.5200","13.3565","250.8082","13.3565","8.9043","59.7162"
"53.6000","13.3778","251.1748","13.3778","8.9185","59.8035"
"53.6800","13.3988","251.5328","13.3988","8.9326","59.8888"
"53.7600","13.4181","251.8404","13.4181","8.9454","59.9620"
"53.8400","13.4377","252.1668","13.4377","8.9585","60.0397"
"53.9200","13.4569","252.4819","13.4569","8.9713","60.1147"
"54.0000","13.4774","252.8347","13.4774","8.9849","60.1987"
"54.0800","13.4985","253.1956","13.4985","8.9990","60.2847"
"54.1600","13.5171","253.4930","13.5171","9.0114","60.3555"
"54.2400","13.5385","253.8617","13.5385","9.0257","60.4433"
"54.3200","13.5581","254.1864","13.5581","9.0388","60.5206"
"54.4000","13.5786","254.5267","13.5786","9.0524","60.6016"
"54.4800","13.5983","254.8532","13.5983","9.0656","60.6793"
"54.5600","13.6175","255.1634","13.6175","9.0783","60.7532"
"54.6400","13.6376","255.4828","13.6376","9.0917","60.8292"
"54.7200","13.6576","255.8089","13.6576","9.1050","60.9069"
"54.8000","13.6765","256.1225","13.6765","9.1176","60.9815"
"54.8800","13.6980","256.4914","13.6980","9.1320","61.0694"
"54.9600","13.7179","256.8156","13.7179","9.1452","61.1466"
"55.0400","13.7384","257.1596","13.7384","9.1589","61.2285"
"55.1200","13.7579","257.4666","13.7579","9.1719","61.3016"
"55.2000","13.7769","257.7670","13.7769","9.1846","61.3731"
"55.2800","13.7975","258.1109","13.7975","9.1983","61.4550"
"55.3600","13.8176","258.4468","13.8176","9.2117","61.5350"
"55.4400","13.8371","258.7597","13.8371","9.2247","61.6095"
"55.5200","13.8582","259.1180","13.8582","9.2388","61.6948"
"55.6000","13.8782","259.4265","13.8782","9.2521","61.7682"
"55.6800","13.8986","259.7644","13.8986","9.2657","61.8487"
"55.7600","13.9184","260.0747","13.9184","9.2789","61.9226"
"55.8400","13.9371","260.3753","13.9371","9.2914","61.9941"
"55.9200","13.9574","260.7127","13.9574","9.3049","62.0745"
"56.0000","13.9768","261.0200","13.9768","9.3178","62.1476"
"56.0800","13.9979","261.3689","13.9979","9.3319","62.2307"
"56.1600","14.0188","261.7293","14.0188","9.3459","62.3165"
"56.2400","14.0377","262.0182","14.0377","9.3585","62.3853"
"56.3200","14.0577","262.3464","14.0577","9.3718","62.4634"
"56.4000","14.0778","262.6685","14.0778","9.3852","62.5401"
"56.4800","14.0969","262.9784","14.0969","9.3980","62.6139"
"56.5600","14.1176","263.3170","14.1176","9.4117","62.6945"
"56.6400","14.1367","263.5961","14.1367","9.4244","62.7610"
"56.7200","14.1581","263.9674","14.1581","9.4388","62.8494"
"56.8000","14.1791","264.3153","14.1791","9.4528","62.9322"
"56.8800","14.1984","264.6116","14.1984","9.4656","63.0028"
"56.9600","14.2178","264.9307","14.2178","9.4785","63.0787"
"57.0400","14.2377","265.2455","14.2377","9.4918","63.1537"
"57.1200","14.2574","265.5620","14.2574","9.5049","63.2291"
"57.2000","14.2777","265.8903","14.2777","9.5185","63.3072"
"57.2800","14.2964","266.1617","14.2964","9.5309","63.3718"
"57.3600","14.3176","266.5234","14.3176","9.5451","63.4579"
"57.4400","14.3385","266.8617","14.3385","9.5590","63.5385"
"57.5200","14.3578","267.1743","14.3578","9.5718","63.6129"
"57.6000","14.3779","267.5082","14.3779","9.5852","63.6924"
"57.6800","14.3971","267.7967","14.3971","9.5981","63.7611"
"57.7600","14.4179","268.1380","14.4179","9.6119","63.8424"
"57.8400","14.4378","268.4535","14.4378","9.6252","63.9175"
"57.9200","14.4571","268.7671","14.4571","9.6380","63.9922"
"58.0000","14.4783","269.1136","14.4783","9.6522","64.0747"
"58.0800","14.4988","269.4369","14.4988","9.6658","64.1516"
"58.1600","14.5183","269.7442","14.5183","9.6789","64.2248"
"58.2400","14.5381","270.0398","14.5381","9.6921","64.2952"
"58.3200","14.5567","270.3324","14.5567","9.7045","64.3649"
"58.4000","14.5770","270.6436","14.5770","9.7180","64.4389"
"58.4800","14.5974","270.9658","14.5974","9.7316","64.5157"
"58.5600","14.6177","271.2902","14.6177","9.7451","64.5929"
"58.6400","14.6379","271.6281","14.6379","9.7586","64.6733"
"58.7200","14.6581","271.9442","14.6581","9.7721","64.7486"
"58.8000","14.6781","272.2490","14.6781","9.7854","64.8212"
"58.8800","14.6983","272.5665","14.6983","9.7988","64.8968"
"58.9600","14.7171","272.8520","14.7171","9.8114","64.9648"
"59.0400","14.7374","273.1709","14.7374","9.8249","65.0407"
"59.1200","14.7570","273.4666","14.7570","9.8380","65.1111"
"59.2000","14.7781","273.8098","14.7781","9.8521","65.1928"
"59.2800","14.7992","274.1469","14.7992","9.8661","65.2731"
"59.3600","14.8185","274.4402","14.8185","9.8790","65.3429"
"59.4400","14.8382","274.7378","14.8382","9.8921","65.4138"
"59.5200","14.8579","275.0374","14.8579","9.9053","65.4851"
"59.6000","14.8771","275.3209","14.8771","9.9181","65.5526"
"59.6800","14.8974","275.6367","14.8974","9.9316","65.6278"
"59.7600","14.9169","275.9240","14.9169","9.9446","65.6962"
"59.8400","14.9372","276.2468","14.9372","9.9581","65.7730"
"59.9200","14.9583","276.5792","14.9583","9.9722","65.8522"
"60.0000","14.9776","276.8634","14.9776","9.9851","65.9199"
"60.0800","14.9979","277.1833","14.9979","9.9986","65.9960"
"60.0890","15.0001","277.2168","15.0001","10.0001","66.0040"