File: data/instron_tests/metamaterials/250421/250421_2224_BULK_m2.is_comp_Exports/250421_2224_BULK_m2_4_1.csv
Results Table 1
,Compresson Axis,H*,V*,Height,Thickness,Width,Area,Fixture separation,Specimen label
,,,,(mm),(mm),(mm),(mm^2),(mm),
"4","X","","","150.00","28.00","150.00","4200.00","150.00","2224_BULK_m2"

Results Table 2
,Modulus (Segment 0 % - 2.5 %),Compresson Axis
,(kPa),
"4","765.76","X"

Time,Displacement,Force,Compressive displacement,Compressive strain (Displacement),Compressive stress
(s),(mm),(N),(mm),(%),(kPa)
"0.0000","0.0000","-4.2493","0.0000","0.0000","-1.0117"
"0.0800","0.0012","-4.2068","0.0012","0.0008","-1.0016"
"0.1600","0.0174","-3.6884","0.0174","0.0116","-0.8782"
"0.2400","0.0379","-3.0858","0.0379","0.0253","-0.7347"
"0.3200","0.0574","-2.5355","0.0574","0.0383","-0.6037"
"0.4000","0.0768","-1.9800","0.0768","0.0512","-0.4714"
"0.4800","0.0983","-1.3778","0.0983","0.0655","-0.3280"
"0.5600","0.1179","-0.8525","0.1179","0.0786","-0.2030"
"0.6400","0.1370","-0.3462","0.1370","0.0913","-0.0824"
"0.7200","0.1572","0.2073","0.1572","0.1048","0.0494"
"0.8000","0.1771","0.7077","0.1771","0.1180","0.1685"
"0.8800","0.1974","1.2497","0.1974","0.1316","0.2975"
"0.9600","0.2177","1.7667","0.2177","0.1451","0.4206"
"1.0400","0.2359","2.2445","0.2359","0.1573","0.5344"
"1.1200","0.2570","2.7855","0.2570","0.1713","0.6632"
"1.2000","0.2774","3.3045","0.2774","0.1850","0.7868"
"1.2800","0.2973","3.7980","0.2973","0.1982","0.9043"
"1.3600","0.3173","4.2968","0.3173","0.2115","1.0230"
"1.4400","0.3363","4.7548","0.3363","0.2242","1.1321"
"1.5200","0.3567","5.2370","0.3567","0.2378","1.2469"
"1.6000","0.3772","5.7397","0.3772","0.2515","1.3666"
"1.6800","0.3970","6.2332","0.3970","0.2647","1.4841"
"1.7600","0.4179","6.7538","0.4179","0.2786","1.6080"
"1.8400","0.4378","7.2268","0.4378","0.2918","1.7207"
"1.9200","0.4576","7.6953","0.4576","0.3051","1.8322"
"2.0000","0.4776","8.1631","0.4776","0.3184","1.9436"
"2.0800","0.4964","8.5886","0.4964","0.3309","2.0449"
"2.1600","0.5163","9.0362","0.5163","0.3442","2.1515"
"2.2400","0.5367","9.5014","0.5367","0.3578","2.2622"
"2.3200","0.5567","9.9812","0.5567","0.3711","2.3765"
"2.4000","0.5778","10.4696","0.5778","0.3852","2.4928"
"2.4800","0.5974","10.9213","0.5974","0.3983","2.6003"
"2.5600","0.6181","11.3830","0.6181","0.4121","2.7102"
"2.6400","0.6371","11.8158","0.6371","0.4247","2.8133"
"2.7200","0.6560","12.2491","0.6560","0.4373","2.9165"
"2.8000","0.6765","12.7266","0.6765","0.4510","3.0301"
"2.8800","0.6969","13.1882","0.6969","0.4646","3.1400"
"2.9600","0.7175","13.6496","0.7175","0.4784","3.2499"
"3.0400","0.7384","14.1301","0.7384","0.4923","3.3643"
"3.1200","0.7570","14.5314","0.7570","0.5047","3.4599"
"3.2000","0.7772","14.9922","0.7772","0.5181","3.5696"
"3.2800","0.7972","15.4524","0.7972","0.5315","3.6792"
"3.3600","0.8170","15.8831","0.8170","0.5446","3.7817"
"3.4400","0.8369","16.3329","0.8369","0.5579","3.8888"
"3.5200","0.8559","16.7290","0.8559","0.5706","3.9831"
"3.6000","0.8770","17.2096","0.8770","0.5847","4.0975"
"3.6800","0.8983","17.6725","0.8983","0.5989","4.2077"
"3.7600","0.9173","18.0865","0.9173","0.6115","4.3063"
"3.8400","0.9370","18.5315","0.9370","0.6247","4.4123"
"3.9200","0.9564","18.9480","0.9564","0.6376","4.5114"
"4.0000","0.9760","19.3785","0.9760","0.6507","4.6139"
"4.0800","0.9975","19.8554","0.9975","0.6650","4.7275"
"4.1600","1.0167","20.2641","1.0167","0.6778","4.8248"
"4.2400","1.0379","20.7424","1.0379","0.6919","4.9387"
"4.3200","1.0580","21.1784","1.0580","0.7053","5.0425"
"4.4000","1.0778","21.6089","1.0778","0.7185","5.1450"
"4.4800","1.0968","22.0213","1.0968","0.7312","5.2432"
"4.5600","1.1163","22.4369","1.1163","0.7442","5.3421"
"4.6400","1.1373","22.8948","1.1373","0.7582","5.4512"
"4.7200","1.1572","23.3148","1.1572","0.7714","5.5511"
"4.8000","1.1763","23.7314","1.1763","0.7842","5.6503"
"4.8800","1.1974","24.2116","1.1974","0.7982","5.7647"
"4.9600","1.2175","24.6164","1.2175","0.8117","5.8610"
"5.0400","1.2379","25.0660","1.2379","0.8252","5.9681"
"5.1200","1.2574","25.4664","1.2574","0.8382","6.0634"
"5.2000","1.2763","25.8731","1.2763","0.8509","6.1603"
"5.2800","1.2970","26.3277","1.2970","0.8647","6.2685"
"5.3600","1.3171","26.7599","1.3171","0.8781","6.3714"
"5.4400","1.3367","27.1893","1.3367","0.8911","6.4736"
"5.5200","1.3577","27.6570","1.3577","0.9051","6.5850"
"5.6000","1.3778","28.0780","1.3778","0.9185","6.6852"
"5.6800","1.3979","28.5049","1.3979","0.9319","6.7869"
"5.7600","1.4179","28.9316","1.4179","0.9453","6.8885"
"5.8400","1.4365","29.3317","1.4365","0.9577","6.9837"
"5.9200","1.4568","29.7753","1.4568","0.9712","7.0894"
"6.0000","1.4762","30.1855","1.4762","0.9841","7.1870"
"6.0800","1.4969","30.6415","1.4969","0.9979","7.2956"
"6.1600","1.5177","31.0984","1.5177","1.0118","7.4044"
"6.2400","1.5377","31.5192","1.5377","1.0251","7.5046"
"6.3200","1.5572","31.9358","1.5572","1.0381","7.6038"
"6.4000","1.5770","32.3584","1.5770","1.0513","7.7044"
"6.4800","1.5962","32.7867","1.5962","1.0641","7.8063"
"6.5600","1.6173","33.2355","1.6173","1.0782","7.9132"
"6.6400","1.6362","33.6394","1.6362","1.0908","8.0094"
"6.7200","1.6573","34.0937","1.6573","1.1049","8.1175"
"6.8000","1.6778","34.5497","1.6778","1.1186","8.2261"
"6.8800","1.6977","34.9834","1.6977","1.1318","8.3294"
"6.9600","1.7174","35.3926","1.7174","1.1450","8.4268"
"7.0400","1.7370","35.8054","1.7370","1.1580","8.5251"
"7.1200","1.7566","36.2179","1.7566","1.1710","8.6233"
"7.2000","1.7770","36.6582","1.7770","1.1847","8.7281"
"7.2800","1.7962","37.0726","1.7962","1.1975","8.8268"
"7.3600","1.8175","37.5418","1.8175","1.2117","8.9385"
"7.4400","1.8375","37.9591","1.8375","1.2250","9.0379"
"7.5200","1.8573","38.3861","1.8573","1.2382","9.1396"
"7.6000","1.8774","38.8083","1.8774","1.2516","9.2401"
"7.6800","1.8965","39.2089","1.8965","1.2643","9.3355"
"7.7600","1.9172","39.6581","1.9172","1.2781","9.4424"
"7.8400","1.9372","40.0706","1.9372","1.2914","9.5406"
"7.9200","1.9561","40.4739","1.9561","1.3041","9.6366"
"8.0000","1.9771","40.9309","1.9771","1.3180","9.7455"
"8.0800","1.9981","41.3837","1.9981","1.3321","9.8533"
"8.1600","2.0180","41.7926","2.0180","1.3453","9.9506"
"8.2400","2.0376","42.2035","2.0376","1.3584","10.0485"
"8.3200","2.0562","42.5880","2.0562","1.3708","10.1400"
"8.4000","2.0776","43.0603","2.0776","1.3850","10.2525"
"8.4800","2.0970","43.4690","2.0970","1.3980","10.3498"
"8.5600","2.1170","43.9024","2.1170","1.4113","10.4529"
"8.6400","2.1372","44.3288","2.1372","1.4248","10.5545"
"8.7200","2.1573","44.7401","2.1573","1.4382","10.6524"
"8.8000","2.1771","45.1573","2.1771","1.4514","10.7517"
"8.8800","2.1978","45.6030","2.1978","1.4652","10.8578"
"8.9600","2.2164","45.9955","2.2164","1.4776","10.9513"
"9.0400","2.2366","46.4184","2.2366","1.4910","11.0520"
"9.1200","2.2561","46.8267","2.2561","1.5041","11.1492"
"9.2000","2.2774","47.2804","2.2774","1.5183","11.2572"
"9.2800","2.2988","47.7240","2.2988","1.5325","11.3629"
"9.3600","2.3178","48.1451","2.3178","1.5452","11.4631"
"9.4400","2.3376","48.5503","2.3376","1.5584","11.5596"
"9.5200","2.3573","48.9651","2.3573","1.5715","11.6584"
"9.6000","2.3766","49.3719","2.3766","1.5844","11.7552"
"9.6800","2.3971","49.8043","2.3971","1.5981","11.8582"
"9.7600","2.4162","50.1793","2.4162","1.6108","11.9475"
"9.8400","2.4368","50.6174","2.4368","1.6245","12.0517"
"9.9200","2.4581","51.0702","2.4581","1.6387","12.1596"
"10.0000","2.4771","51.4708","2.4771","1.6514","12.2549"
"10.0800","2.4977","51.8924","2.4977","1.6651","12.3553"
"10.1600","2.5169","52.2892","2.5169","1.6779","12.4498"
"10.2400","2.5366","52.6931","2.5366","1.6911","12.5460"
"10.3200","2.5565","53.1117","2.5565","1.7044","12.6456"
"10.4000","2.5764","53.5142","2.5764","1.7176","12.7415"
"10.4800","2.5975","53.9757","2.5975","1.7317","12.8513"
"10.5600","2.6187","54.4170","2.6187","1.7458","12.9564"
"10.6400","2.6376","54.8080","2.6376","1.7584","13.0495"
"10.7200","2.6570","55.1999","2.6570","1.7713","13.1428"
"10.8000","2.6766","55.5963","2.6766","1.7844","13.2372"
"10.8800","2.6976","56.0379","2.6976","1.7984","13.3424"
"10.9600","2.7178","56.4624","2.7178","1.8119","13.4434"
"11.0400","2.7363","56.8420","2.7363","1.8242","13.5338"
"11.1200","2.7567","57.2653","2.7567","1.8378","13.6346"
"11.2000","2.7774","57.7046","2.7774","1.8516","13.7392"
"11.2800","2.7975","58.1231","2.7975","1.8650","13.8388"
"11.3600","2.8176","58.5379","2.8176","1.8784","13.9376"
"11.4400","2.8363","58.9039","2.8363","1.8909","14.0247"
"11.5200","2.8565","59.3164","2.8565","1.9043","14.1229"
"11.6000","2.8770","59.7420","2.8770","1.9180","14.2243"
"11.6800","2.8966","60.1536","2.8966","1.9311","14.3223"
"11.7600","2.9181","60.6032","2.9181","1.9454","14.4293"
"11.8400","2.9374","60.9844","2.9374","1.9583","14.5201"
"11.9200","2.9575","61.3959","2.9575","1.9716","14.6181"
"12.0000","2.9775","61.8057","2.9775","1.9850","14.7156"
"12.0800","2.9969","62.2066","2.9969","1.9979","14.8111"
"12.1600","3.0171","62.6304","3.0171","2.0114","14.9120"
"12.2400","3.0366","63.0219","3.0366","2.0244","15.0052"
"12.3200","3.0562","63.4397","3.0562","2.0375","15.1047"
"12.4000","3.0779","63.9002","3.0779","2.0520","15.2143"
"12.4800","3.0972","64.2750","3.0972","2.0648","15.3036"
"12.5600","3.1179","64.7040","3.1179","2.0786","15.4057"
"12.6400","3.1372","65.0899","3.1372","2.0915","15.4976"
"12.7200","3.1563","65.4849","3.1563","2.1042","15.5916"
"12.8000","3.1766","65.9069","3.1766","2.1177","15.6921"
"12.8800","3.1968","66.3281","3.1968","2.1312","15.7924"
"12.9600","3.2172","66.7532","3.2172","2.1448","15.8936"
"13.0400","3.2382","67.1889","3.2382","2.1588","15.9974"
"13.1200","3.2575","67.5848","3.2575","2.1717","16.0916"
"13.2000","3.2774","67.9806","3.2774","2.1849","16.1859"
"13.2800","3.2973","68.3876","3.2973","2.1982","16.2828"
"13.3600","3.3170","68.7902","3.3170","2.2113","16.3786"
"13.4400","3.3371","69.1956","3.3371","2.2247","16.4751"
"13.5200","3.3559","69.5690","3.3559","2.2372","16.5640"
"13.6000","3.3771","70.0203","3.3771","2.2514","16.6715"
"13.6800","3.3981","70.4567","3.3981","2.2654","16.7754"
"13.7600","3.4174","70.8419","3.4174","2.2783","16.8671"
"13.8400","3.4371","71.2501","3.4371","2.2914","16.9643"
"13.9200","3.4563","71.6144","3.4563","2.3042","17.0511"
"14.0000","3.4766","72.0319","3.4766","2.3177","17.1505"
"14.0800","3.4975","72.4681","3.4975","2.3317","17.2543"
"14.1600","3.5165","72.8509","3.5165","2.3443","17.3455"
"14.2400","3.5379","73.2990","3.5379","2.3586","17.4521"
"14.3200","3.5576","73.6905","3.5576","2.3718","17.5453"
"14.4000","3.5776","74.0889","3.5776","2.3850","17.6402"
"14.4800","3.5970","74.4855","3.5970","2.3980","17.7346"
"14.5600","3.6170","74.8735","3.6170","2.4113","17.8270"
"14.6400","3.6372","75.2869","3.6372","2.4248","17.9254"
"14.7200","3.6569","75.6761","3.6569","2.4379","18.0181"
"14.8000","3.6757","76.0539","3.6757","2.4504","18.1081"
"14.8800","3.6971","76.5074","3.6971","2.4648","18.2161"
"14.9600","3.7175","76.9098","3.7175","2.4783","18.3119"
"15.0400","3.7378","77.3223","3.7378","2.4919","18.4101"
"15.1200","3.7576","77.7175","3.7576","2.5050","18.5042"
"15.2000","3.7761","78.0730","3.7761","2.5174","18.5888"
"15.2800","3.7969","78.4951","3.7969","2.5313","18.6893"
"15.3600","3.8171","78.9168","3.8171","2.5448","18.7897"
"15.4400","3.8368","79.3028","3.8368","2.5579","18.8816"
"15.5200","3.8576","79.7311","3.8576","2.5717","18.9836"
"15.6000","3.8776","80.1292","3.8776","2.5850","19.0784"
"15.6800","3.8980","80.5444","3.8980","2.5987","19.1773"
"15.7600","3.9178","80.9316","3.9178","2.6118","19.2694"
"15.8400","3.9364","81.2951","3.9364","2.6243","19.3560"
"15.9200","3.9570","81.7301","3.9570","2.6380","19.4596"
"16.0000","3.9763","82.1027","3.9763","2.6509","19.5483"
"16.0800","3.9971","82.5291","3.9971","2.6647","19.6498"
"16.1600","4.0177","82.9472","4.0177","2.6785","19.7493"
"16.2400","4.0372","83.3274","4.0372","2.6915","19.8398"
"16.3200","4.0571","83.7181","4.0571","2.7047","19.9329"
"16.4000","4.0772","84.1374","4.0772","2.7181","20.0327"
"16.4800","4.0963","84.5119","4.0963","2.7309","20.1219"
"16.5600","4.1173","84.9406","4.1173","2.7449","20.2239"
"16.6400","4.1363","85.2987","4.1363","2.7575","20.3092"
"16.7200","4.1575","85.7459","4.1575","2.7717","20.4157"
"16.8000","4.1782","86.1616","4.1782","2.7855","20.5147"
"16.8800","4.1977","86.5437","4.1977","2.7985","20.6056"
"16.9600","4.2174","86.9295","4.2174","2.8116","20.6975"
"17.0400","4.2368","87.3048","4.2368","2.8245","20.7869"
"17.1200","4.2563","87.6851","4.2563","2.8376","20.8774"
"17.2000","4.2773","88.1089","4.2773","2.8515","20.9783"
"17.2800","4.2958","88.4695","4.2958","2.8639","21.0642"
"17.3600","4.3171","88.9010","4.3171","2.8781","21.1669"
"17.4400","4.3378","89.3159","4.3378","2.8919","21.2657"
"17.5200","4.3574","89.7053","4.3574","2.9050","21.3584"
"17.6000","4.3773","90.0956","4.3773","2.9182","21.4513"
"17.6800","4.3964","90.4703","4.3964","2.9309","21.5406"
"17.7600","4.4175","90.8858","4.4175","2.9450","21.6395"
"17.8400","4.4374","91.2763","4.4374","2.9582","21.7325"
"17.9200","4.4562","91.6444","4.4562","2.9708","21.8201"
"18.0000","4.4771","92.0760","4.4771","2.9847","21.9228"
"18.0800","4.4984","92.4996","4.4984","2.9989","22.0237"
"18.1600","4.5179","92.8831","4.5179","3.0119","22.1150"
"18.2400","4.5376","93.2646","4.5376","3.0251","22.2059"
"18.3200","4.5560","93.6158","4.5560","3.0373","22.2895"
"18.4000","4.5772","94.0390","4.5772","3.0515","22.3902"
"18.4800","4.5968","94.4259","4.5968","3.0645","22.4823"
"18.5600","4.6168","94.8245","4.6168","3.0779","22.5773"
"18.6400","4.6370","95.2271","4.6370","3.0913","22.6731"
"18.7200","4.6572","95.6237","4.6572","3.1048","22.7676"
"18.8000","4.6773","96.0075","4.6773","3.1182","22.8589"
"18.8800","4.6979","96.4227","4.6979","3.1319","22.9578"
"18.9600","4.7165","96.7702","4.7165","3.1443","23.0405"
"19.0400","4.7367","97.1713","4.7367","3.1578","23.1360"
"19.1200","4.7564","97.5597","4.7564","3.1710","23.2285"
"19.2000","4.7774","97.9825","4.7774","3.1849","23.3292"
"19.2800","4.7985","98.4035","4.7985","3.1990","23.4294"
"19.3600","4.8177","98.7639","4.8177","3.2118","23.5152"
"19.4400","4.8374","99.1304","4.8374","3.2250","23.6025"
"19.5200","4.8572","99.5152","4.8572","3.2381","23.6941"
"19.6000","4.8767","99.8998","4.8767","3.2511","23.7857"
"19.6800","4.8975","100.3360","4.8975","3.2650","23.8895"
"19.7600","4.9165","100.6828","4.9165","3.2777","23.9721"
"19.8400","4.9370","101.0928","4.9370","3.2913","24.0697"
"19.9200","4.9579","101.4975","4.9579","3.3053","24.1661"
"20.0000","4.9769","101.8573","4.9769","3.3179","24.2517"
"20.0800","4.9978","102.2750","4.9978","3.3318","24.3512"
"20.1600","5.0164","102.6140","5.0164","3.3443","24.4319"
"20.2400","5.0368","103.0262","5.0368","3.3579","24.5300"
"20.3200","5.0568","103.4039","5.0568","3.3712","24.6200"
"20.4000","5.0762","103.7798","5.0762","3.3841","24.7095"
"20.4800","5.0974","104.2017","5.0974","3.3983","24.8099"
"20.5600","5.1185","104.6151","5.1185","3.4123","24.9084"
"20.6400","5.1371","104.9585","5.1371","3.4247","24.9901"
"20.7200","5.1573","105.3461","5.1573","3.4382","25.0824"
"20.8000","5.1767","105.7215","5.1767","3.4511","25.1718"
"20.8800","5.1975","106.1327","5.1975","3.4650","25.2697"
"20.9600","5.2174","106.5116","5.2174","3.4783","25.3599"
"21.0400","5.2361","106.8620","5.2361","3.4907","25.4433"
"21.1200","5.2567","107.2691","5.2567","3.5045","25.5403"
"21.2000","5.2775","107.6850","5.2775","3.5183","25.6393"
"21.2800","5.2972","108.0504","5.2972","3.5314","25.7263"
"21.3600","5.3175","108.4428","5.3175","3.5450","25.8197"
"21.4400","5.3364","108.7867","5.3364","3.5576","25.9016"
"21.5200","5.3569","109.1873","5.3569","3.5713","25.9970"
"21.6000","5.3770","109.5737","5.3770","3.5847","26.0890"
"21.6800","5.3968","109.9640","5.3968","3.5978","26.1819"
"21.7600","5.4181","110.3906","5.4181","3.6120","26.2835"
"21.8400","5.4374","110.7446","5.4374","3.6249","26.3678"
"21.9200","5.4578","111.1352","5.4578","3.6385","26.4608"
"22.0000","5.4772","111.5025","5.4772","3.6515","26.5482"
"22.0800","5.4967","111.8800","5.4967","3.6645","26.6381"
"22.1600","5.5173","112.2874","5.5173","3.6782","26.7351"
"22.2400","5.5364","112.6359","5.5364","3.6909","26.8181"
"22.3200","5.5565","113.0360","5.5565","3.7043","26.9133"
"22.4000","5.5781","113.4584","5.5781","3.7188","27.0139"
"22.4800","5.5972","113.8267","5.5972","3.7314","27.1016"
"22.5600","5.6181","114.2264","5.6181","3.7454","27.1968"
"22.6400","5.6371","114.5685","5.6371","3.7581","27.2782"
"22.7200","5.6555","114.9240","5.6555","3.7703","27.3629"
"22.8000","5.6762","115.3193","5.6762","3.7841","27.4570"
"22.8800","5.6971","115.7290","5.6971","3.7981","27.5545"
"22.9600","5.7178","116.1293","5.7178","3.8119","27.6498"
"23.0400","5.7386","116.5234","5.7386","3.8257","27.7437"
"23.1200","5.7570","116.8536","5.7570","3.8380","27.8223"
"23.2000","5.7773","117.2483","5.7773","3.8515","27.9163"
"23.2800","5.7974","117.6307","5.7974","3.8649","28.0073"
"23.3600","5.8169","118.0068","5.8169","3.8780","28.0969"
"23.4400","5.8370","118.3891","5.8370","3.8913","28.1879"
"23.5200","5.8557","118.7350","5.8557","3.9038","28.2702"
"23.6000","5.8774","119.1618","5.8774","3.9183","28.3719"
"23.6800","5.8983","119.5671","5.8983","3.9322","28.4683"
"23.7600","5.9174","119.9279","5.9174","3.9449","28.5543"
"23.8400","5.9374","120.3096","5.9374","3.9582","28.6451"
"23.9200","5.9564","120.6585","5.9564","3.9710","28.7282"
"24.0000","5.9760","121.0303","5.9760","3.9840","28.8167"
"24.0800","5.9975","121.4549","5.9975","3.9983","28.9178"
"24.1600","6.0165","121.8030","6.0165","4.0110","29.0007"
"24.2400","6.0377","122.2235","6.0377","4.0252","29.1008"
"24.3200","6.0577","122.5920","6.0577","4.0384","29.1886"
"24.4000","6.0781","122.9879","6.0781","4.0520","29.2828"
"24.4800","6.0977","123.3669","6.0977","4.0651","29.3731"
"24.5600","6.1167","123.7070","6.1167","4.0778","29.4541"
"24.6400","6.1370","124.0962","6.1370","4.0913","29.5467"
"24.7200","6.1572","124.4759","6.1572","4.1048","29.6371"
"24.8000","6.1759","124.8182","6.1759","4.1173","29.7186"
"24.8800","6.1976","125.2580","6.1976","4.1317","29.8233"
"24.9600","6.2173","125.6229","6.2173","4.1449","29.9102"
"25.0400","6.2378","126.0065","6.2378","4.1586","30.0015"
"25.1200","6.2575","126.3715","6.2575","4.1717","30.0885"
"25.2000","6.2755","126.6852","6.2755","4.1836","30.1632"
"25.2800","6.2968","127.1037","6.2968","4.1979","30.2628"
"25.3600","6.3172","127.4990","6.3172","4.2115","30.3569"
"25.4400","6.3371","127.8793","6.3371","4.2247","30.4475"
"25.5200","6.3576","128.2774","6.3576","4.2384","30.5422"
"25.6000","6.3773","128.6304","6.3773","4.2515","30.6263"
"25.6800","6.3980","129.0300","6.3980","4.2653","30.7214"
"25.7600","6.4182","129.4034","6.4182","4.2788","30.8103"
"25.8400","6.4364","129.7365","6.4364","4.2909","30.8896"
"25.9200","6.4566","130.1139","6.4566","4.3044","30.9795"
"26.0000","6.4764","130.4880","6.4764","4.3176","31.0686"
"26.0800","6.4972","130.8835","6.4972","4.3315","31.1627"
"26.1600","6.5176","131.2754","6.5176","4.3451","31.2560"
"26.2400","6.5374","131.6459","6.5374","4.3583","31.3443"
"26.3200","6.5574","132.0191","6.5574","4.3716","31.4331"
"26.4000","6.5771","132.3784","6.5771","4.3847","31.5187"
"26.4800","6.5962","132.7367","6.5962","4.3975","31.6040"
"26.5600","6.6171","133.1298","6.6171","4.4114","31.6976"
"26.6400","6.6365","133.4835","6.6365","4.4243","31.7818"
"26.7200","6.6574","133.8892","6.6574","4.4383","31.8784"
"26.8000","6.6782","134.2799","6.6782","4.4522","31.9714"
"26.8800","6.6980","134.6532","6.6980","4.4653","32.0603"
"26.9600","6.7177","135.0141","6.7177","4.4785","32.1462"
"27.0400","6.7369","135.3578","6.7369","4.4913","32.2280"
"27.1200","6.7566","135.7216","6.7566","4.5044","32.3147"
"27.2000","6.7773","136.1093","6.7773","4.5182","32.4070"
"27.2800","6.7961","136.4504","6.7961","4.5307","32.4882"
"27.3600","6.8171","136.8496","6.8171","4.5448","32.5832"
"27.4400","6.8376","137.2384","6.8376","4.5584","32.6758"
"27.5200","6.8574","137.6132","6.8574","4.5716","32.7651"
"27.6000","6.8773","137.9855","6.8773","4.5849","32.8537"
"27.6800","6.8964","138.3278","6.8964","4.5976","32.9352"
"27.7600","6.9170","138.7103","6.9170","4.6114","33.0263"
"27.8400","6.9372","139.0850","6.9372","4.6248","33.1155"
"27.9200","6.9567","139.4344","6.9567","4.6378","33.1987"
"28.0000","6.9772","139.8360","6.9772","4.6515","33.2943"
"28.0800","6.9983","140.2294","6.9983","4.6655","33.3880"
"28.1600","7.0180","140.5904","7.0180","4.6786","33.4739"
"28.2400","7.0376","140.9348","7.0376","4.6918","33.5559"
"28.3200","7.0562","141.2689","7.0562","4.7041","33.6355"
"28.4000","7.0771","141.6625","7.0771","4.7181","33.7292"
"28.4800","7.0970","142.0336","7.0970","4.7314","33.8175"
"28.5600","7.1167","142.3954","7.1167","4.7445","33.9037"
"28.6400","7.1369","142.7694","7.1369","4.7579","33.9927"
"28.7200","7.1572","143.1369","7.1572","4.7714","34.0802"
"28.8000","7.1771","143.5004","7.1771","4.7847","34.1668"
"28.8800","7.1976","143.8770","7.1976","4.7984","34.2564"
"28.9600","7.2163","144.2135","7.2163","4.8109","34.3366"
"29.0400","7.2368","144.5766","7.2368","4.8245","34.4230"
"29.1200","7.2561","144.9353","7.2561","4.8374","34.5084"
"29.2000","7.2771","145.3241","7.2771","4.8514","34.6010"
"29.2800","7.2985","145.7462","7.2985","4.8657","34.7015"
"29.3600","7.3182","146.0919","7.3182","4.8788","34.7838"
"29.4400","7.3377","146.4307","7.3377","4.8918","34.8645"
"29.5200","7.3569","146.7716","7.3569","4.9046","34.9456"
"29.6000","7.3764","147.1326","7.3764","4.9176","35.0316"
"29.6800","7.3973","147.5182","7.3973","4.9316","35.1234"
"29.7600","7.4165","147.8480","7.4165","4.9443","35.2019"
"29.8400","7.4364","148.2177","7.4364","4.9576","35.2899"
"29.9200","7.4576","148.6175","7.4576","4.9718","35.3851"
"30.0000","7.4770","148.9700","7.4770","4.9847","35.4690"
"30.0800","7.4979","149.3588","7.4979","4.9986","35.5616"
"30.1600","7.5166","149.6826","7.5166","5.0111","35.6387"
"30.2400","7.5364","150.0213","7.5364","5.0243","35.7193"
"30.3200","7.5567","150.3984","7.5567","5.0378","35.8091"
"30.4000","7.5766","150.7490","7.5766","5.0511","35.8926"
"30.4800","7.5978","151.1505","7.5978","5.0652","35.9882"
"30.5600","7.6186","151.5357","7.6186","5.0791","36.0799"
"30.6400","7.6376","151.8768","7.6376","5.0917","36.1611"
"30.7200","7.6573","152.2305","7.6573","5.1048","36.2454"
"30.8000","7.6766","152.5680","7.6766","5.1177","36.3257"
"30.8800","7.6975","152.9635","7.6975","5.1317","36.4199"
"30.9600","7.7175","153.3115","7.7175","5.1450","36.5027"
"31.0400","7.7360","153.6360","7.7360","5.1573","36.5800"
"31.1200","7.7567","154.0180","7.7567","5.1711","36.6709"
"31.2000","7.7778","154.4205","7.7778","5.1852","36.7668"
"31.2800","7.7978","154.7688","7.7978","5.1985","36.8497"
"31.3600","7.8176","155.1240","7.8176","5.2118","36.9343"
"31.4400","7.8362","155.4415","7.8362","5.2242","37.0099"
"31.5200","7.8570","155.8331","7.8570","5.2380","37.1031"
"31.6000","7.8774","156.2007","7.8774","5.2516","37.1906"
"31.6800","7.8967","156.5590","7.8967","5.2645","37.2759"
"31.7600","7.9182","156.9611","7.9182","5.2788","37.3717"
"31.8400","7.9376","157.3000","7.9376","5.2917","37.4524"
"31.9200","7.9575","157.6496","7.9575","5.3050","37.5356"
"32.0000","7.9773","157.9941","7.9773","5.3182","37.6177"
"32.0800","7.9970","158.3493","7.9970","5.3313","37.7022"
"32.1600","8.0168","158.7041","8.0168","5.3445","37.7867"
"32.2400","8.0367","159.0614","8.0367","5.3578","37.8718"
"32.3200","8.0561","159.4149","8.0561","5.3707","37.9559"
"32.4000","8.0778","159.8263","8.0778","5.3852","38.0539"
"32.4800","8.0971","160.1526","8.0971","5.3981","38.1316"
"32.5600","8.1179","160.5251","8.1179","5.4119","38.2203"
"32.6400","8.1369","160.8469","8.1369","5.4246","38.2969"
"32.7200","8.1560","161.1868","8.1560","5.4373","38.3778"
"32.8000","8.1765","161.5570","8.1765","5.4510","38.4660"
"32.8800","8.1967","161.9191","8.1967","5.4644","38.5522"
"32.9600","8.2176","162.3064","8.2176","5.4784","38.6444"
"33.0400","8.2387","162.6900","8.2387","5.4924","38.7357"
"33.1200","8.2571","163.0046","8.2571","5.5048","38.8106"
"33.2000","8.2774","163.3733","8.2774","5.5183","38.8984"
"33.2800","8.2971","163.7128","8.2971","5.5314","38.9792"
"33.3600","8.3169","164.0678","8.3169","5.5446","39.0638"
"33.4400","8.3371","164.4255","8.3371","5.5581","39.1489"
"33.5200","8.3558","164.7418","8.3558","5.5706","39.2242"
"33.6000","8.3771","165.1359","8.3771","5.5847","39.3181"
"33.6800","8.3984","165.5301","8.3984","5.5989","39.4119"
"33.7600","8.4176","165.8536","8.4176","5.6117","39.4889"
"33.8400","8.4370","166.2006","8.4370","5.6247","39.5716"
"33.9200","8.4564","166.5316","8.4564","5.6376","39.6504"
"34.0000","8.4765","166.8934","8.4765","5.6510","39.7365"
"34.0800","8.4977","167.2671","8.4977","5.6651","39.8255"
"34.1600","8.5167","167.6067","8.5167","5.6778","39.9064"
"34.2400","8.5378","167.9925","8.5378","5.6919","39.9982"
"34.3200","8.5577","168.3329","8.5577","5.7052","40.0793"
"34.4000","8.5776","168.6846","8.5776","5.7184","40.1630"
"34.4800","8.5971","169.0245","8.5971","5.7314","40.2439"
"34.5600","8.6167","169.3582","8.6167","5.7445","40.3234"
"34.6400","8.6368","169.7099","8.6368","5.7578","40.4071"
"34.7200","8.6570","170.0624","8.6570","5.7713","40.4911"
"34.8000","8.6758","170.3899","8.6758","5.7838","40.5690"
"34.8800","8.6974","170.7942","8.6974","5.7982","40.6653"
"34.9600","8.7175","171.1468","8.7175","5.8117","40.7492"
"35.0400","8.7379","171.5004","8.7379","5.8253","40.8334"
"35.1200","8.7575","171.8377","8.7575","5.8383","40.9137"
"35.2000","8.7759","172.1389","8.7759","5.8506","40.9854"
"35.2800","8.7965","172.5093","8.7965","5.8644","41.0736"
"35.3600","8.8170","172.8684","8.8170","5.8780","41.1591"
"35.4400","8.8368","173.2106","8.8368","5.8912","41.2406"
"35.5200","8.8574","173.5751","8.8574","5.9050","41.3274"
"35.6000","8.8777","173.9295","8.8777","5.9185","41.4118"
"35.6800","8.8980","174.2748","8.8980","5.9320","41.4940"
"35.7600","8.9179","174.6205","8.9179","5.9453","41.5763"
"35.8400","8.9365","174.9348","8.9365","5.9577","41.6511"
"35.9200","8.9566","175.2880","8.9566","5.9711","41.7352"
"36.0000","8.9761","175.6184","8.9761","5.9841","41.8139"
"36.0800","8.9972","176.0038","8.9972","5.9981","41.9057"
"36.1600","9.0180","176.3692","9.0180","6.0120","41.9927"
"36.2400","9.0373","176.6834","9.0373","6.0249","42.0675"
"36.3200","9.0573","177.0231","9.0573","6.0382","42.1483"
"36.4000","9.0772","177.3695","9.0772","6.0514","42.2308"
"36.4800","9.0962","177.6937","9.0962","6.0642","42.3080"
"36.5600","9.1172","178.0707","9.1172","6.0781","42.3978"
"36.6400","9.1363","178.3883","9.1363","6.0909","42.4734"
"36.7200","9.1576","178.7643","9.1576","6.1050","42.5629"
"36.8000","9.1778","179.1115","9.1778","6.1185","42.6456"
"36.8800","9.1977","179.4669","9.1977","6.1318","42.7302"
"36.9600","9.2174","179.7896","9.2174","6.1449","42.8070"
"37.0400","9.2371","180.1178","9.2371","6.1581","42.8852"
"37.1200","9.2567","180.4507","9.2567","6.1712","42.9645"
"37.2000","9.2773","180.8084","9.2773","6.1849","43.0496"
"37.2800","9.2959","181.1152","9.2959","6.1973","43.1227"
"37.3600","9.3175","181.5010","9.3175","6.2116","43.2145"
"37.4400","9.3375","181.8432","9.3375","6.2250","43.2960"
"37.5200","9.3567","182.1507","9.3567","6.2378","43.3692"
"37.6000","9.3773","182.5176","9.3773","6.2515","43.4566"
"37.6800","9.3966","182.8245","9.3966","6.2644","43.5297"
"37.7600","9.4174","183.1727","9.4174","6.2782","43.6125"
"37.8400","9.4372","183.5087","9.4372","6.2915","43.6925"
"37.9200","9.4562","183.8185","9.4562","6.3041","43.7663"
"38.0000","9.4772","184.2006","9.4772","6.3182","43.8573"
"38.0800","9.4981","184.5477","9.4981","6.3321","43.9399"
"38.1600","9.5179","184.8888","9.5179","6.3453","44.0212"
"38.2400","9.5380","185.2208","9.5380","6.3587","44.1002"
"38.3200","9.5560","185.4919","9.5560","6.3706","44.1647"
"38.4000","9.5773","185.8602","9.5773","6.3849","44.2524"
"38.4800","9.5969","186.1815","9.5969","6.3979","44.3289"
"38.5600","9.6168","186.5287","9.6168","6.4112","44.4116"
"38.6400","9.6368","186.8647","9.6368","6.4245","44.4916"
"38.7200","9.6573","187.2093","9.6573","6.4382","44.5736"
"38.8000","9.6773","187.5435","9.6773","6.4515","44.6532"
"38.8800","9.6977","187.8863","9.6977","6.4651","44.7348"
"38.9600","9.7166","188.2013","9.7166","6.4778","44.8098"
"39.0400","9.7370","188.5469","9.7370","6.4913","44.8921"
"39.1200","9.7563","188.8596","9.7563","6.5042","44.9666"
"39.2000","9.7771","189.2189","9.7771","6.5180","45.0521"
"39.2800","9.7983","189.5849","9.7983","6.5322","45.1393"
"39.3600","9.8177","189.8996","9.8177","6.5451","45.2142"
"39.4400","9.8378","190.2285","9.8378","6.5585","45.2925"
"39.5200","9.8572","190.5516","9.8572","6.5715","45.3694"
"39.6000","9.8766","190.8803","9.8766","6.5844","45.4477"
"39.6800","9.8971","191.2312","9.8971","6.5981","45.5312"
"39.7600","9.9164","191.5399","9.9164","6.6109","45.6047"
"39.8400","9.9366","191.8765","9.9366","6.6244","45.6849"
"39.9200","9.9582","192.2514","9.9582","6.6388","45.7742"
"40.0000","9.9768","192.5546","9.9768","6.6512","45.8463"
"40.0800","9.9972","192.8898","9.9972","6.6648","45.9261"
"40.1600","10.0165","193.2048","10.0165","6.6777","46.0011"
"40.2400","10.0372","193.5617","10.0372","6.6914","46.0861"
"40.3200","10.0567","193.8873","10.0567","6.7045","46.1636"
"40.4000","10.0764","194.2085","10.0764","6.7176","46.2401"
"40.4800","10.0977","194.5777","10.0977","6.7318","46.3280"
"40.5600","10.1187","194.9331","10.1187","6.7458","46.4126"
"40.6400","10.1371","195.2152","10.1371","6.7581","46.4798"
"40.7200","10.1572","195.5481","10.1572","6.7715","46.5591"
"40.8000","10.1766","195.8537","10.1766","6.7844","46.6318"
"40.8800","10.1976","196.2137","10.1976","6.7984","46.7175"
"40.9600","10.2177","196.5357","10.2177","6.8118","46.7942"
"41.0400","10.2362","196.8420","10.2362","6.8241","46.8671"
"41.1200","10.2566","197.1832","10.2566","6.8377","46.9484"
"41.2000","10.2776","197.5333","10.2776","6.8517","47.0317"
"41.2800","10.2977","197.8671","10.2977","6.8651","47.1112"
"41.3600","10.3177","198.1906","10.3177","6.8785","47.1882"
"41.4400","10.3366","198.4816","10.3366","6.8911","47.2575"
"41.5200","10.3567","198.8101","10.3567","6.9044","47.3357"
"41.6000","10.3770","199.1414","10.3770","6.9180","47.4146"
"41.6800","10.3968","199.4760","10.3968","6.9312","47.4943"
"41.7600","10.4182","199.8390","10.4182","6.9455","47.5807"
"41.8400","10.4374","200.1412","10.4374","6.9583","47.6527"
"41.9200","10.4577","200.4806","10.4577","6.9718","47.7335"
"42.0000","10.4775","200.8015","10.4775","6.9850","47.8099"
"42.0800","10.4971","201.1394","10.4971","6.9981","47.8903"
"42.1600","10.5167","201.4520","10.5167","7.0112","47.9648"
"42.2400","10.5364","201.7530","10.5364","7.0243","48.0364"
"42.3200","10.5560","202.0694","10.5560","7.0373","48.1118"
"42.4000","10.5776","202.4370","10.5776","7.0517","48.1993"
"42.4800","10.5971","202.7397","10.5971","7.0647","48.2714"
"42.5600","10.6180","203.0804","10.6180","7.0786","48.3525"
"42.6400","10.6370","203.3775","10.6370","7.0913","48.4232"
"42.7200","10.6563","203.6821","10.6563","7.1042","48.4957"
"42.8000","10.6766","204.0082","10.6766","7.1177","48.5734"
"42.8800","10.6968","204.3318","10.6968","7.1312","48.6504"
"42.9600","10.7177","204.6780","10.7177","7.1451","48.7329"
"43.0400","10.7387","205.0124","10.7387","7.1591","48.8125"
"43.1200","10.7570","205.2870","10.7570","7.1713","48.8778"
"43.2000","10.7772","205.6216","10.7772","7.1848","48.9575"
"43.2800","10.7974","205.9274","10.7974","7.1982","49.0303"
"43.3600","10.8172","206.2539","10.8172","7.2115","49.1081"
"43.4400","10.8370","206.5578","10.8370","7.2247","49.1804"
"43.5200","10.8560","206.8442","10.8560","7.2373","49.2486"
"43.6000","10.8772","207.2047","10.8772","7.2515","49.3345"
"43.6800","10.8980","207.5293","10.8980","7.2653","49.4117"
"43.7600","10.9177","207.8302","10.9177","7.2785","49.4834"
"43.8400","10.9371","208.1367","10.9371","7.2914","49.5564"
"43.9200","10.9566","208.4245","10.9566","7.3044","49.6249"
"44.0000","10.9765","208.7478","10.9765","7.3176","49.7019"
"44.0800","10.9972","209.0704","10.9972","7.3315","49.7787"
"44.1600","11.0165","209.3609","11.0165","7.3443","49.8478"
"44.2400","11.0378","209.7066","11.0378","7.3585","49.9301"
"44.3200","11.0577","210.0149","11.0577","7.3718","50.0035"
"44.4000","11.0777","210.3141","11.0777","7.3851","50.0748"
"44.4800","11.0971","210.6069","11.0971","7.3981","50.1445"
"44.5600","11.1171","210.9095","11.1171","7.4114","50.2165"
"44.6400","11.1370","211.2223","11.1370","7.4246","50.2910"
"44.7200","11.1573","211.5382","11.1573","7.4382","50.3662"
"44.8000","11.1760","211.8243","11.1760","7.4507","50.4344"
"44.8800","11.1975","212.1712","11.1975","7.4650","50.5169"
"44.9600","11.2174","212.4692","11.2174","7.4782","50.5879"
"45.0400","11.2380","212.7723","11.2380","7.4920","50.6601"
"45.1200","11.2572","213.0466","11.2572","7.5048","50.7254"
"45.2000","11.2758","213.3114","11.2758","7.5172","50.7884"
"45.2800","11.2970","213.6451","11.2970","7.5313","50.8679"
"45.3600","11.3173","213.9538","11.3173","7.5449","50.9414"
"45.4400","11.3370","214.2538","11.3370","7.5580","51.0128"
"45.5200","11.3575","214.5690","11.3575","7.5717","51.0879"
"45.6000","11.3775","214.8593","11.3775","7.5850","51.1570"
"45.6800","11.3983","215.1674","11.3983","7.5988","51.2303"
"45.7600","11.4179","215.4470","11.4179","7.6119","51.2969"
"45.8400","11.4364","215.7049","11.4364","7.6242","51.3583"
"45.9200","11.4568","216.0084","11.4568","7.6379","51.4306"
"46.0000","11.4760","216.2814","11.4760","7.6507","51.4956"
"46.0800","11.4972","216.6038","11.4972","7.6648","51.5723"
"46.1600","11.5179","216.9166","11.5179","7.6786","51.6468"
"46.2400","11.5374","217.1834","11.5374","7.6916","51.7103"
"46.3200","11.5570","217.4559","11.5570","7.7046","51.7752"
"46.4000","11.5771","217.7524","11.5771","7.7180","51.8458"
"46.4800","11.5963","218.0218","11.5963","7.7309","51.9099"
"46.5600","11.6171","218.3315","11.6171","7.7448","51.9837"
"46.6400","11.6360","218.5783","11.6360","7.7574","52.0425"
"46.7200","11.6577","218.8960","11.6577","7.7718","52.1181"
"46.8000","11.6780","219.1722","11.6780","7.7853","52.1839"
"46.8800","11.6978","219.4577","11.6978","7.7985","52.2518"
"46.9600","11.7175","219.7394","11.7175","7.8117","52.3189"
"47.0400","11.7371","219.9960","11.7371","7.8247","52.3800"
"47.1200","11.7567","220.2748","11.7567","7.8378","52.4464"
"47.2000","11.7770","220.5638","11.7770","7.8513","52.5152"
"47.2800","11.7962","220.8312","11.7962","7.8641","52.5789"
"47.3600","11.8171","221.1359","11.8171","7.8781","52.6514"
"47.4400","11.8377","221.4269","11.8377","7.8918","52.7207"
"47.5200","11.8571","221.6889","11.8571","7.9047","52.7831"
"47.6000","11.8770","221.9626","11.8770","7.9180","52.8482"
"47.6800","11.8963","222.2234","11.8963","7.9309","52.9103"
"47.7600","11.9174","222.5260","11.9174","7.9449","52.9824"
"47.8400","11.9374","222.8073","11.9374","7.9583","53.0494"
"47.9200","11.9566","223.0604","11.9566","7.9711","53.1096"
"48.0000","11.9773","223.3667","11.9773","7.9849","53.1825"
"48.0800","11.9981","223.6302","11.9981","7.9987","53.2453"
"48.1600","12.0177","223.9042","12.0177","8.0118","53.3105"
"48.2400","12.0378","224.1598","12.0378","8.0252","53.3714"
"48.3200","12.0563","224.3932","12.0563","8.0375","53.4269"
"48.4000","12.0771","224.6730","12.0771","8.0514","53.4936"
"48.4800","12.0971","224.9426","12.0971","8.0647","53.5578"
"48.5600","12.1169","225.2176","12.1169","8.0780","53.6232"
"48.6400","12.1372","225.4971","12.1372","8.0915","53.6898"
"48.7200","12.1574","225.7545","12.1574","8.1049","53.7511"
"48.8000","12.1775","226.0125","12.1775","8.1183","53.8125"
"48.8800","12.1980","226.2859","12.1980","8.1320","53.8776"
"48.9600","12.2165","226.5151","12.2165","8.1443","53.9322"
"49.0400","12.2366","226.7735","12.2366","8.1577","53.9937"
"49.1200","12.2564","227.0281","12.2564","8.1709","54.0543"
"49.2000","12.2772","227.3195","12.2772","8.1848","54.1237"
"49.2800","12.2986","227.6056","12.2986","8.1990","54.1918"
"49.3600","12.3179","227.8503","12.3179","8.2119","54.2501"
"49.4400","12.3376","228.0956","12.3376","8.2250","54.3085"
"49.5200","12.3571","228.3384","12.3571","8.2381","54.3663"
"49.6000","12.3768","228.5950","12.3768","8.2512","54.4274"
"49.6800","12.3970","228.8699","12.3970","8.2647","54.4928"
"49.7600","12.4166","229.1006","12.4166","8.2777","54.5478"
"49.8400","12.4364","229.3629","12.4364","8.2909","54.6102"
"49.9200","12.4576","229.6516","12.4576","8.3051","54.6790"
"50.0000","12.4771","229.8937","12.4771","8.3180","54.7366"
"50.0800","12.4976","230.1611","12.4976","8.3318","54.8003"
"50.1600","12.5166","230.3880","12.5166","8.3444","54.8543"
"50.2400","12.5370","230.6485","12.5370","8.3580","54.9163"
"50.3200","12.5564","230.9015","12.5564","8.3710","54.9765"
"50.4000","12.5765","231.1502","12.5765","8.3843","55.0358"
"50.4800","12.5974","231.4281","12.5974","8.3983","55.1019"
"50.5600","12.6188","231.7162","12.6188","8.4125","55.1705"
"50.6400","12.6373","231.9148","12.6373","8.4248","55.2178"
"50.7200","12.6572","232.1721","12.6572","8.4381","55.2791"
"50.8000","12.6760","232.3796","12.6760","8.4507","55.3285"
"50.8800","12.6974","232.6758","12.6974","8.4649","55.3990"
"50.9600","12.7177","232.9205","12.7177","8.4785","55.4573"
"51.0400","12.7365","233.1400","12.7365","8.4910","55.5095"
"51.1200","12.7570","233.4067","12.7570","8.5047","55.5730"
"51.2000","12.7777","233.6748","12.7777","8.5185","55.6369"
"51.2800","12.7977","233.9082","12.7977","8.5318","55.6924"
"51.3600","12.8175","234.1537","12.8175","8.5450","55.7509"
"51.4400","12.8364","234.3615","12.8364","8.5576","55.8003"
"51.5200","12.8569","234.6181","12.8569","8.5713","55.8615"
"51.6000","12.8770","234.8646","12.8770","8.5847","55.9202"
"51.6800","12.8965","235.1098","12.8965","8.5977","55.9785"
"51.7600","12.9181","235.4052","12.9181","8.6121","56.0489"
"51.8400","12.9378","235.6283","12.9378","8.6252","56.1020"
"51.9200","12.9577","235.8612","12.9577","8.6385","56.1574"
"52.0000","12.9773","236.0857","12.9773","8.6516","56.2109"
"52.0800","12.9970","236.3191","12.9970","8.6647","56.2664"
"52.1600","13.0168","236.5515","13.0168","8.6779","56.3218"
"52.2400","13.0369","236.8001","13.0369","8.6912","56.3810"
"52.3200","13.0562","237.0167","13.0562","8.7041","56.4325"
"52.4000","13.0776","237.3011","13.0776","8.7184","56.5003"
"52.4800","13.0974","237.5282","13.0974","8.7316","56.5543"
"52.5600","13.1180","237.7691","13.1180","8.7453","56.6117"
"52.6400","13.1371","237.9762","13.1371","8.7580","56.6610"
"52.7200","13.1564","238.1916","13.1564","8.7709","56.7123"
"52.8000","13.1765","238.4322","13.1765","8.7843","56.7696"
"52.8800","13.1966","238.6635","13.1966","8.7977","56.8246"
"52.9600","13.2175","238.9210","13.2175","8.8117","56.8859"
"53.0400","13.2386","239.1792","13.2386","8.8258","56.9474"
"53.1200","13.2574","239.3666","13.2574","8.8382","56.9921"
"53.2000","13.2770","239.5899","13.2770","8.8514","57.0452"
"53.2800","13.2973","239.8222","13.2973","8.8649","57.1005"
"53.3600","13.3172","240.0383","13.3172","8.8781","57.1520"
"53.4400","13.3371","240.2556","13.3371","8.8914","57.2037"
"53.5200","13.3556","240.4451","13.3556","8.9037","57.2488"
"53.6000","13.3772","240.7030","13.3772","8.9181","57.3102"
"53.6800","13.3983","240.9464","13.3983","8.9322","57.3682"
"53.7600","13.4175","241.1459","13.4175","8.9450","57.4157"
"53.8400","13.4372","241.3565","13.4372","8.9581","57.4658"
"53.9200","13.4565","241.5513","13.4565","8.9710","57.5122"
"54.0000","13.4766","241.7641","13.4766","8.9844","57.5629"
"54.0800","13.4978","242.0235","13.4978","8.9985","57.6246"
"54.1600","13.5164","242.1853","13.5164","9.0109","57.6632"
"54.2400","13.5377","242.4338","13.5377","9.0251","57.7223"
"54.3200","13.5578","242.6369","13.5578","9.0385","57.7707"
"54.4000","13.5778","242.8493","13.5778","9.0519","57.8213"
"54.4800","13.5973","243.0379","13.5973","9.0649","57.8662"
"54.5600","13.6169","243.2302","13.6169","9.0779","57.9120"
"54.6400","13.6372","243.4323","13.6372","9.0915","57.9601"
"54.7200","13.6570","243.6137","13.6570","9.1047","58.0033"
"54.8000","13.6756","243.7479","13.6756","9.1171","58.0352"
"54.8800","13.6972","243.9823","13.6972","9.1314","58.0910"
"54.9600","13.7175","244.1774","13.7175","9.1450","58.1375"
"55.0400","13.7377","244.3647","13.7377","9.1585","58.1821"
"55.1200","13.7573","244.5485","13.7573","9.1715","58.2258"
"55.2000","13.7762","244.7219","13.7762","9.1841","58.2671"
"55.2800","13.7970","244.9198","13.7970","9.1980","58.3142"
"55.3600","13.8170","245.0979","13.8170","9.2114","58.3567"
"55.4400","13.8368","245.2433","13.8368","9.2246","58.3913"
"55.5200","13.8577","245.3044","13.8577","9.2385","58.4058"
"55.6000","13.8776","245.4144","13.8776","9.2517","58.4320"
"55.6800","13.8977","245.5632","13.8977","9.2651","58.4674"
"55.7600","13.9177","245.7167","13.9177","9.2785","58.5040"
"55.8400","13.9363","245.8587","13.9363","9.2909","58.5378"
"55.9200","13.9566","246.0202","13.9566","9.3044","58.5762"
"56.0000","13.9763","246.1735","13.9763","9.3175","58.6127"
"56.0800","13.9973","246.3597","13.9973","9.3315","58.6571"
"56.1600","14.0180","246.5558","14.0180","9.3453","58.7038"
"56.2400","14.0374","246.6919","14.0374","9.3583","58.7362"
"56.3200","14.0573","246.8519","14.0573","9.3716","58.7743"
"56.4000","14.0771","247.0054","14.0771","9.3847","58.8108"
"56.4800","14.0964","247.1603","14.0964","9.3976","58.8477"
"56.5600","14.1169","247.3331","14.1169","9.4113","58.8888"
"56.6400","14.1361","247.4756","14.1361","9.4241","58.9228"
"56.7200","14.1574","247.6532","14.1574","9.4382","58.9650"
"56.8000","14.1782","247.8295","14.1782","9.4521","59.0070"
"56.8800","14.1979","247.9837","14.1979","9.4653","59.0438"
"56.9600","14.2175","248.1270","14.2175","9.4783","59.0779"
"57.0400","14.2371","248.2588","14.2371","9.4914","59.1092"
"57.1200","14.2568","248.3975","14.2568","9.5045","59.1423"
"57.2000","14.2769","248.5494","14.2769","9.5179","59.1784"
"57.2800","14.2960","248.6755","14.2960","9.5306","59.2084"
"57.3600","14.3171","248.8349","14.3171","9.5447","59.2464"
"57.4400","14.3378","248.9839","14.3378","9.5585","59.2819"
"57.5200","14.3570","249.0894","14.3570","9.5714","59.3070"
"57.6000","14.3772","249.2265","14.3772","9.5848","59.3396"
"57.6800","14.3964","249.3267","14.3964","9.5976","59.3635"
"57.7600","14.4176","249.4803","14.4176","9.6117","59.4001"
"57.8400","14.4371","249.5836","14.4371","9.6248","59.4247"
"57.9200","14.4562","249.6856","14.4562","9.6375","59.4490"
"58.0000","14.4772","249.8359","14.4772","9.6515","59.4847"
"58.0800","14.4981","249.9681","14.4981","9.6654","59.5162"
"58.1600","14.5178","250.0853","14.5178","9.6785","59.5441"
"58.2400","14.5374","250.2087","14.5374","9.6916","59.5735"
"58.3200","14.5561","250.3076","14.5561","9.7041","59.5970"
"58.4000","14.5766","250.4450","14.5766","9.7178","59.6298"
"58.4800","14.5969","250.5923","14.5969","9.7313","59.6648"
"58.5600","14.6171","250.7342","14.6171","9.7447","59.6986"
"58.6400","14.6376","250.8764","14.6376","9.7584","59.7325"
"58.7200","14.6572","250.9820","14.6572","9.7715","59.7576"
"58.8000","14.6776","251.1047","14.6776","9.7850","59.7868"
"58.8800","14.6977","251.2388","14.6977","9.7984","59.8188"
"58.9600","14.7165","251.3454","14.7165","9.8110","59.8441"
"59.0400","14.7368","251.4798","14.7368","9.8245","59.8761"
"59.1200","14.7562","251.6001","14.7562","9.8375","59.9048"
"59.2000","14.7772","251.7513","14.7772","9.8515","59.9408"
"59.2800","14.7986","251.9002","14.7986","9.8657","59.9762"
"59.3600","14.8178","251.9922","14.8178","9.8785","59.9981"
"59.4400","14.8377","252.1018","14.8377","9.8918","60.0242"
"59.5200","14.8572","252.2159","14.8572","9.9048","60.0514"
"59.6000","14.8767","252.3281","14.8767","9.9178","60.0781"
"59.6800","14.8969","252.4516","14.8969","9.9312","60.1075"
"59.7600","14.9162","252.5384","14.9162","9.9441","60.1282"
"59.8400","14.9366","252.6658","14.9366","9.9577","60.1585"
"59.9200","14.9577","252.7960","14.9577","9.9718","60.1895"
"60.0000","14.9769","252.8837","14.9769","9.9846","60.2104"
"60.0800","14.9975","252.9976","14.9975","9.9983","60.2375"
"60.0910","15.0002","253.0111","15.0002","10.0001","60.2407"