File: data/instron_tests/metamaterials/250421/250421_2224_BULK_m2.is_comp_Exports/250421_2224_BULK_m2_5_1.csv
Results Table 1
,Compresson Axis,H*,V*,Height,Thickness,Width,Area,Fixture separation,Specimen label
,,,,(mm),(mm),(mm),(mm^2),(mm),
"5","X","","","150.00","28.00","150.00","4200.00","150.00","2224_BULK_m2"

Results Table 2
,Modulus (Segment 0 % - 2.5 %),Compresson Axis
,(kPa),
"5","777.96","X"

Time,Displacement,Force,Compressive displacement,Compressive strain (Displacement),Compressive stress
(s),(mm),(N),(mm),(%),(kPa)
"0.0000","0.0000","-15.5928","0.0000","0.0000","-3.7126"
"0.0800","0.0011","-15.5032","0.0011","0.0008","-3.6912"
"0.1600","0.0173","-14.9873","0.0173","0.0115","-3.5684"
"0.2400","0.0378","-14.3731","0.0378","0.0252","-3.4222"
"0.3200","0.0575","-13.8010","0.0575","0.0383","-3.2859"
"0.4000","0.0765","-13.2782","0.0765","0.0510","-3.1615"
"0.4800","0.0984","-12.6629","0.0984","0.0656","-3.0150"
"0.5600","0.1181","-12.1415","0.1181","0.0787","-2.8908"
"0.6400","0.1372","-11.6346","0.1372","0.0915","-2.7702"
"0.7200","0.1571","-11.0950","0.1571","0.1047","-2.6417"
"0.8000","0.1769","-10.5826","0.1769","0.1180","-2.5197"
"0.8800","0.1975","-10.0542","0.1975","0.1317","-2.3939"
"0.9600","0.2178","-9.5376","0.2178","0.1452","-2.2709"
"1.0400","0.2360","-9.0687","0.2360","0.1573","-2.1592"
"1.1200","0.2571","-8.5129","0.2571","0.1714","-2.0269"
"1.2000","0.2777","-7.9886","0.2777","0.1851","-1.9021"
"1.2800","0.2977","-7.4906","0.2977","0.1985","-1.7835"
"1.3600","0.3173","-7.0037","0.3173","0.2116","-1.6675"
"1.4400","0.3363","-6.5294","0.3363","0.2242","-1.5546"
"1.5200","0.3567","-6.0162","0.3567","0.2378","-1.4324"
"1.6000","0.3774","-5.5026","0.3774","0.2516","-1.3101"
"1.6800","0.3967","-5.0218","0.3967","0.2645","-1.1957"
"1.7600","0.4181","-4.4878","0.4181","0.2787","-1.0685"
"1.8400","0.4377","-4.0161","0.4377","0.2918","-0.9562"
"1.9200","0.4573","-3.5456","0.4573","0.3048","-0.8442"
"2.0000","0.4774","-3.0499","0.4774","0.3182","-0.7262"
"2.0800","0.4970","-2.5779","0.4970","0.3313","-0.6138"
"2.1600","0.5169","-2.0892","0.5169","0.3446","-0.4974"
"2.2400","0.5366","-1.6280","0.5366","0.3577","-0.3876"
"2.3200","0.5564","-1.1402","0.5564","0.3709","-0.2715"
"2.4000","0.5777","-0.6239","0.5777","0.3852","-0.1485"
"2.4800","0.5975","-0.1559","0.5975","0.3983","-0.0371"
"2.5600","0.6178","0.3230","0.6178","0.4119","0.0769"
"2.6400","0.6373","0.7801","0.6373","0.4249","0.1857"
"2.7200","0.6560","1.2274","0.6560","0.4373","0.2922"
"2.8000","0.6766","1.7250","0.6766","0.4511","0.4107"
"2.8800","0.6970","2.2021","0.6970","0.4646","0.5243"
"2.9600","0.7180","2.6921","0.7180","0.4786","0.6410"
"3.0400","0.7383","3.1687","0.7383","0.4922","0.7544"
"3.1200","0.7570","3.5987","0.7570","0.5047","0.8568"
"3.2000","0.7774","4.0761","0.7774","0.5183","0.9705"
"3.2800","0.7975","4.5346","0.7975","0.5317","1.0797"
"3.3600","0.8171","4.9923","0.8171","0.5448","1.1886"
"3.4400","0.8370","5.4511","0.8370","0.5580","1.2979"
"3.5200","0.8561","5.8812","0.8561","0.5707","1.4003"
"3.6000","0.8773","6.3619","0.8773","0.5849","1.5147"
"3.6800","0.8981","6.8147","0.8981","0.5988","1.6225"
"3.7600","0.9175","7.2367","0.9175","0.6117","1.7230"
"3.8400","0.9370","7.6841","0.9370","0.6247","1.8296"
"3.9200","0.9568","8.1106","0.9568","0.6378","1.9311"
"4.0000","0.9762","8.5428","0.9762","0.6508","2.0340"
"4.0800","0.9974","9.0127","0.9974","0.6649","2.1459"
"4.1600","1.0168","9.4370","1.0168","0.6779","2.2469"
"4.2400","1.0379","9.9075","1.0379","0.6919","2.3589"
"4.3200","1.0581","10.3477","1.0581","0.7054","2.4637"
"4.4000","1.0775","10.7769","1.0775","0.7183","2.5659"
"4.4800","1.0968","11.2069","1.0968","0.7312","2.6683"
"4.5600","1.1169","11.6342","1.1169","0.7446","2.7700"
"4.6400","1.1372","12.0696","1.1372","0.7582","2.8737"
"4.7200","1.1570","12.5051","1.1570","0.7714","2.9774"
"4.8000","1.1761","12.9144","1.1761","0.7840","3.0749"
"4.8800","1.1974","13.3915","1.1974","0.7982","3.1885"
"4.9600","1.2175","13.8191","1.2175","0.8116","3.2903"
"5.0400","1.2377","14.2607","1.2377","0.8252","3.3954"
"5.1200","1.2575","14.6900","1.2575","0.8383","3.4976"
"5.2000","1.2761","15.0832","1.2761","0.8508","3.5912"
"5.2800","1.2972","15.5386","1.2972","0.8648","3.6997"
"5.3600","1.3174","15.9715","1.3174","0.8782","3.8027"
"5.4400","1.3368","16.3976","1.3368","0.8912","3.9042"
"5.5200","1.3576","16.8575","1.3576","0.9051","4.0137"
"5.6000","1.3777","17.2777","1.3777","0.9185","4.1137"
"5.6800","1.3980","17.7133","1.3980","0.9320","4.2175"
"5.7600","1.4180","18.1483","1.4180","0.9453","4.3210"
"5.8400","1.4367","18.5504","1.4367","0.9578","4.4168"
"5.9200","1.4569","18.9880","1.4569","0.9713","4.5210"
"6.0000","1.4763","19.4008","1.4763","0.9842","4.6192"
"6.0800","1.4974","19.8580","1.4974","0.9982","4.7281"
"6.1600","1.5178","20.3137","1.5178","1.0119","4.8366"
"6.2400","1.5376","20.7317","1.5376","1.0250","4.9361"
"6.3200","1.5573","21.1518","1.5573","1.0382","5.0361"
"6.4000","1.5771","21.5935","1.5771","1.0514","5.1413"
"6.4800","1.5961","21.9966","1.5961","1.0641","5.2373"
"6.5600","1.6173","22.4567","1.6173","1.0782","5.3468"
"6.6400","1.6364","22.8583","1.6364","1.0909","5.4424"
"6.7200","1.6574","23.3174","1.6574","1.1049","5.5518"
"6.8000","1.6783","23.7700","1.6783","1.1188","5.6595"
"6.8800","1.6978","24.1916","1.6978","1.1318","5.7599"
"6.9600","1.7173","24.5989","1.7173","1.1449","5.8569"
"7.0400","1.7370","25.0145","1.7370","1.1580","5.9558"
"7.1200","1.7565","25.4402","1.7565","1.1710","6.0572"
"7.2000","1.7770","25.8827","1.7770","1.1847","6.1625"
"7.2800","1.7964","26.2991","1.7964","1.1976","6.2617"
"7.3600","1.8177","26.7723","1.8177","1.2118","6.3743"
"7.4400","1.8375","27.1835","1.8375","1.2250","6.4722"
"7.5200","1.8570","27.6193","1.8570","1.2380","6.5760"
"7.6000","1.8774","28.0639","1.8774","1.2516","6.6819"
"7.6800","1.8967","28.4613","1.8967","1.2645","6.7765"
"7.7600","1.9173","28.9165","1.9173","1.2782","6.8849"
"7.8400","1.9372","29.3415","1.9372","1.2915","6.9861"
"7.9200","1.9564","29.7628","1.9564","1.3043","7.0864"
"8.0000","1.9770","30.2151","1.9770","1.3180","7.1941"
"8.0800","1.9982","30.6753","1.9982","1.3321","7.3037"
"8.1600","2.0181","31.1094","2.0181","1.3454","7.4070"
"8.2400","2.0378","31.5167","2.0378","1.3585","7.5040"
"8.3200","2.0561","31.9000","2.0561","1.3707","7.5952"
"8.4000","2.0774","32.3777","2.0774","1.3849","7.7090"
"8.4800","2.0970","32.7993","2.0970","1.3980","7.8094"
"8.5600","2.1168","33.2241","2.1168","1.4112","7.9105"
"8.6400","2.1372","33.6714","2.1372","1.4248","8.0170"
"8.7200","2.1575","34.1038","2.1575","1.4383","8.1200"
"8.8000","2.1773","34.5301","2.1773","1.4515","8.2215"
"8.8800","2.1979","34.9726","2.1979","1.4652","8.3268"
"8.9600","2.2167","35.3662","2.2167","1.4778","8.4205"
"9.0400","2.2370","35.8079","2.2370","1.4913","8.5257"
"9.1200","2.2560","36.2077","2.2560","1.5040","8.6209"
"9.2000","2.2773","36.6776","2.2773","1.5182","8.7328"
"9.2800","2.2988","37.1309","2.2988","1.5325","8.8407"
"9.3600","2.3178","37.5222","2.3178","1.5452","8.9339"
"9.4400","2.3377","37.9534","2.3377","1.5585","9.0365"
"9.5200","2.3576","38.4015","2.3576","1.5717","9.1432"
"9.6000","2.3769","38.8104","2.3769","1.5846","9.2406"
"9.6800","2.3974","39.2491","2.3974","1.5983","9.3450"
"9.7600","2.4163","39.6181","2.4163","1.6109","9.4329"
"9.8400","2.4365","40.0604","2.4365","1.6244","9.5382"
"9.9200","2.4581","40.5301","2.4581","1.6388","9.6500"
"10.0000","2.4770","40.9318","2.4770","1.6513","9.7457"
"10.0800","2.4977","41.3726","2.4977","1.6651","9.8506"
"10.1600","2.5170","41.7765","2.5170","1.6780","9.9468"
"10.2400","2.5367","42.1769","2.5367","1.6912","10.0421"
"10.3200","2.5564","42.6120","2.5564","1.7043","10.1457"
"10.4000","2.5763","43.0270","2.5763","1.7176","10.2445"
"10.4800","2.5977","43.5051","2.5977","1.7318","10.3584"
"10.5600","2.6187","43.9515","2.6187","1.7458","10.4646"
"10.6400","2.6376","44.3360","2.6376","1.7584","10.5562"
"10.7200","2.6571","44.7244","2.6571","1.7714","10.6487"
"10.8000","2.6763","45.1371","2.6763","1.7842","10.7469"
"10.8800","2.6977","45.6037","2.6977","1.7985","10.8580"
"10.9600","2.7179","46.0539","2.7179","1.8119","10.9652"
"11.0400","2.7365","46.4524","2.7365","1.8244","11.0601"
"11.1200","2.7568","46.8742","2.7568","1.8379","11.1605"
"11.2000","2.7774","47.2986","2.7774","1.8516","11.2616"
"11.2800","2.7976","47.7222","2.7976","1.8650","11.3624"
"11.3600","2.8176","48.1543","2.8176","1.8784","11.4653"
"11.4400","2.8364","48.5393","2.8364","1.8909","11.5570"
"11.5200","2.8566","48.9807","2.8566","1.9044","11.6621"
"11.6000","2.8772","49.4082","2.8772","1.9181","11.7639"
"11.6800","2.8969","49.8209","2.8969","1.9313","11.8621"
"11.7600","2.9184","50.2726","2.9184","1.9456","11.9697"
"11.8400","2.9372","50.6609","2.9372","1.9581","12.0621"
"11.9200","2.9579","51.1012","2.9579","1.9719","12.1669"
"12.0000","2.9778","51.5175","2.9778","1.9852","12.2661"
"12.0800","2.9969","51.9173","2.9969","1.9979","12.3613"
"12.1600","3.0169","52.3437","3.0169","2.0113","12.4628"
"12.2400","3.0366","52.7430","3.0366","2.0244","12.5579"
"12.3200","3.0562","53.1471","3.0562","2.0374","12.6541"
"12.4000","3.0781","53.6253","3.0781","2.0521","12.7679"
"12.4800","3.0974","54.0266","3.0974","2.0649","12.8635"
"12.5600","3.1179","54.4645","3.1179","2.0786","12.9677"
"12.6400","3.1372","54.8522","3.1372","2.0915","13.0600"
"12.7200","3.1564","55.2629","3.1564","2.1042","13.1578"
"12.8000","3.1766","55.6880","3.1766","2.1177","13.2591"
"12.8800","3.1968","56.1055","3.1968","2.1312","13.3584"
"12.9600","3.2173","56.5323","3.2173","2.1448","13.4601"
"13.0400","3.2385","56.9892","3.2385","2.1590","13.5689"
"13.1200","3.2575","57.4020","3.2575","2.1717","13.6671"
"13.2000","3.2774","57.8037","3.2774","2.1849","13.7628"
"13.2800","3.2971","58.2247","3.2971","2.1981","13.8630"
"13.3600","3.3173","58.6437","3.3173","2.2115","13.9628"
"13.4400","3.3371","59.0596","3.3371","2.2247","14.0618"
"13.5200","3.3558","59.4409","3.3558","2.2372","14.1526"
"13.6000","3.3772","59.8949","3.3772","2.2515","14.2607"
"13.6800","3.3982","60.3440","3.3982","2.2655","14.3676"
"13.7600","3.4173","60.7346","3.4173","2.2782","14.4606"
"13.8400","3.4371","61.1535","3.4371","2.2914","14.5604"
"13.9200","3.4566","61.5536","3.4566","2.3044","14.6556"
"14.0000","3.4768","61.9887","3.4768","2.3179","14.7592"
"14.0800","3.4977","62.4235","3.4977","2.3318","14.8627"
"14.1600","3.5163","62.8155","3.5163","2.3442","14.9561"
"14.2400","3.5380","63.2789","3.5380","2.3587","15.0664"
"14.3200","3.5577","63.6837","3.5577","2.3718","15.1628"
"14.4000","3.5775","64.0952","3.5775","2.3850","15.2608"
"14.4800","3.5977","64.5190","3.5977","2.3984","15.3617"
"14.5600","3.6169","64.9120","3.6169","2.4113","15.4552"
"14.6400","3.6366","65.3091","3.6366","2.4244","15.5498"
"14.7200","3.6569","65.7388","3.6569","2.4380","15.6521"
"14.8000","3.6761","66.1399","3.6761","2.4507","15.7476"
"14.8800","3.6973","66.5881","3.6973","2.4649","15.8543"
"14.9600","3.7175","66.9963","3.7175","2.4783","15.9515"
"15.0400","3.7377","67.4160","3.7377","2.4918","16.0514"
"15.1200","3.7576","67.8267","3.7576","2.5050","16.1492"
"15.2000","3.7761","68.2036","3.7761","2.5174","16.2390"
"15.2800","3.7970","68.6496","3.7970","2.5314","16.3451"
"15.3600","3.8172","69.0595","3.8172","2.5448","16.4427"
"15.4400","3.8370","69.4691","3.8370","2.5580","16.5403"
"15.5200","3.8577","69.9103","3.8577","2.5718","16.6453"
"15.6000","3.8778","70.3057","3.8778","2.5852","16.7394"
"15.6800","3.8979","70.7265","3.8979","2.5986","16.8397"
"15.7600","3.9179","71.1319","3.9179","2.6119","16.9362"
"15.8400","3.9364","71.5140","3.9364","2.6243","17.0271"
"15.9200","3.9571","71.9523","3.9571","2.6381","17.1315"
"16.0000","3.9764","72.3311","3.9764","2.6509","17.2217"
"16.0800","3.9971","72.7712","3.9971","2.6648","17.3265"
"16.1600","4.0178","73.2004","4.0178","2.6786","17.4287"
"16.2400","4.0374","73.5965","4.0374","2.6916","17.5230"
"16.3200","4.0571","73.9979","4.0571","2.7047","17.6186"
"16.4000","4.0771","74.4099","4.0771","2.7181","17.7166"
"16.4800","4.0964","74.8129","4.0964","2.7309","17.8126"
"16.5600","4.1173","75.2432","4.1173","2.7449","17.9150"
"16.6400","4.1363","75.6157","4.1363","2.7575","18.0037"
"16.7200","4.1576","76.0538","4.1576","2.7717","18.1081"
"16.8000","4.1783","76.4874","4.1783","2.7856","18.2113"
"16.8800","4.1978","76.8895","4.1978","2.7985","18.3070"
"16.9600","4.2174","77.2873","4.2174","2.8116","18.4017"
"17.0400","4.2371","77.6924","4.2371","2.8247","18.4982"
"17.1200","4.2568","78.0889","4.2568","2.8378","18.5926"
"17.2000","4.2772","78.5081","4.2772","2.8515","18.6924"
"17.2800","4.2960","78.8763","4.2960","2.8640","18.7801"
"17.3600","4.3174","79.3216","4.3174","2.8783","18.8861"
"17.4400","4.3377","79.7323","4.3377","2.8918","18.9839"
"17.5200","4.3569","80.1120","4.3569","2.9046","19.0743"
"17.6000","4.3775","80.5386","4.3775","2.9183","19.1759"
"17.6800","4.3966","80.9073","4.3966","2.9311","19.2636"
"17.7600","4.4176","81.3461","4.4176","2.9450","19.3681"
"17.8400","4.4375","81.7545","4.4375","2.9583","19.4654"
"17.9200","4.4564","82.1293","4.4564","2.9710","19.5546"
"18.0000","4.4771","82.5620","4.4771","2.9847","19.6576"
"18.0800","4.4982","82.9767","4.4982","2.9988","19.7564"
"18.1600","4.5179","83.3877","4.5179","3.0120","19.8542"
"18.2400","4.5377","83.7745","4.5377","3.0252","19.9463"
"18.3200","4.5559","84.1234","4.5559","3.0372","20.0294"
"18.4000","4.5774","84.5818","4.5774","3.0516","20.1385"
"18.4800","4.5970","84.9856","4.5970","3.0647","20.2347"
"18.5600","4.6167","85.3881","4.6167","3.0778","20.3305"
"18.6400","4.6371","85.8134","4.6371","3.0914","20.4318"
"18.7200","4.6573","86.2040","4.6573","3.1049","20.5248"
"18.8000","4.6771","86.6089","4.6771","3.1181","20.6212"
"18.8800","4.6980","87.0358","4.6980","3.1320","20.7228"
"18.9600","4.7165","87.4061","4.7165","3.1444","20.8110"
"19.0400","4.7367","87.8128","4.7367","3.1578","20.9078"
"19.1200","4.7565","88.2118","4.7565","3.1710","21.0028"
"19.2000","4.7774","88.6471","4.7774","3.1850","21.1065"
"19.2800","4.7987","89.0903","4.7987","3.1991","21.2120"
"19.3600","4.8180","89.4721","4.8180","3.2120","21.3029"
"19.4400","4.8375","89.8520","4.8375","3.2250","21.3933"
"19.5200","4.8574","90.2607","4.8574","3.2383","21.4906"
"19.6000","4.8768","90.6510","4.8768","3.2512","21.5836"
"19.6800","4.8977","91.0861","4.8977","3.2651","21.6872"
"19.7600","4.9163","91.4358","4.9163","3.2776","21.7704"
"19.8400","4.9368","91.8493","4.9368","3.2912","21.8689"
"19.9200","4.9580","92.2885","4.9580","3.3054","21.9735"
"20.0000","4.9772","92.6718","4.9772","3.3181","22.0647"
"20.0800","4.9978","93.0907","4.9978","3.3319","22.1645"
"20.1600","5.0167","93.4448","5.0167","3.3444","22.2488"
"20.2400","5.0369","93.8549","5.0369","3.3579","22.3464"
"20.3200","5.0564","94.2349","5.0564","3.3709","22.4369"
"20.4000","5.0759","94.6234","5.0759","3.3840","22.5294"
"20.4800","5.0980","95.0950","5.0980","3.3986","22.6417"
"20.5600","5.1187","95.4981","5.1187","3.4125","22.7376"
"20.6400","5.1371","95.8570","5.1371","3.4247","22.8231"
"20.7200","5.1572","96.2537","5.1572","3.4381","22.9176"
"20.8000","5.1766","96.6418","5.1766","3.4511","23.0100"
"20.8800","5.1977","97.0676","5.1977","3.4651","23.1113"
"20.9600","5.2174","97.4550","5.2174","3.4783","23.2036"
"21.0400","5.2362","97.8236","5.2362","3.4908","23.2913"
"21.1200","5.2567","98.2285","5.2567","3.5044","23.3877"
"21.2000","5.2776","98.6605","5.2776","3.5184","23.4906"
"21.2800","5.2974","99.0433","5.2974","3.5316","23.5817"
"21.3600","5.3176","99.4497","5.3176","3.5451","23.6785"
"21.4400","5.3365","99.8145","5.3365","3.5577","23.7654"
"21.5200","5.3568","100.2186","5.3568","3.5712","23.8616"
"21.6000","5.3771","100.6280","5.3771","3.5848","23.9590"
"21.6800","5.3972","101.0416","5.3972","3.5981","24.0575"
"21.7600","5.4182","101.4654","5.4182","3.6122","24.1584"
"21.8400","5.4375","101.8326","5.4375","3.6250","24.2459"
"21.9200","5.4576","102.2241","5.4576","3.6384","24.3391"
"22.0000","5.4775","102.6258","5.4775","3.6517","24.4347"
"22.0800","5.4971","103.0090","5.4971","3.6647","24.5260"
"22.1600","5.5172","103.4097","5.5172","3.6781","24.6214"
"22.2400","5.5367","103.7821","5.5367","3.6911","24.7100"
"22.3200","5.5563","104.1828","5.5563","3.7042","24.8054"
"22.4000","5.5777","104.6283","5.5777","3.7185","24.9115"
"22.4800","5.5971","104.9942","5.5971","3.7314","24.9986"
"22.5600","5.6178","105.4010","5.6178","3.7452","25.0955"
"22.6400","5.6368","105.7606","5.6368","3.7579","25.1811"
"22.7200","5.6564","106.1527","5.6564","3.7709","25.2744"
"22.8000","5.6766","106.5614","5.6766","3.7844","25.3718"
"22.8800","5.6968","106.9536","5.6968","3.7979","25.4652"
"22.9600","5.7177","107.3694","5.7177","3.8118","25.5642"
"23.0400","5.7387","107.7917","5.7387","3.8258","25.6647"
"23.1200","5.7569","108.1386","5.7569","3.8379","25.7473"
"23.2000","5.7775","108.5436","5.7775","3.8516","25.8437"
"23.2800","5.7973","108.9225","5.7973","3.8649","25.9339"
"23.3600","5.8171","109.3142","5.8171","3.8780","26.0272"
"23.4400","5.8371","109.7084","5.8371","3.8914","26.1210"
"23.5200","5.8559","110.0607","5.8559","3.9039","26.2049"
"23.6000","5.8774","110.4998","5.8774","3.9183","26.3095"
"23.6800","5.8985","110.9314","5.8985","3.9323","26.4122"
"23.7600","5.9176","111.3042","5.9176","3.9451","26.5010"
"23.8400","5.9372","111.6834","5.9372","3.9581","26.5913"
"23.9200","5.9565","112.0505","5.9565","3.9710","26.6787"
"24.0000","5.9762","112.4281","5.9762","3.9841","26.7686"
"24.0800","5.9975","112.8573","5.9975","3.9983","26.8708"
"24.1600","6.0166","113.2281","6.0166","4.0111","26.9591"
"24.2400","6.0381","113.6633","6.0381","4.0254","27.0627"
"24.3200","6.0579","114.0414","6.0579","4.0386","27.1527"
"24.4000","6.0780","114.4388","6.0780","4.0520","27.2473"
"24.4800","6.0976","114.8409","6.0976","4.0650","27.3431"
"24.5600","6.1170","115.2021","6.1170","4.0780","27.4291"
"24.6400","6.1370","115.5973","6.1370","4.0914","27.5232"
"24.7200","6.1572","115.9894","6.1572","4.1048","27.6165"
"24.8000","6.1759","116.3442","6.1759","4.1172","27.7010"
"24.8800","6.1975","116.7916","6.1975","4.1317","27.8075"
"24.9600","6.2175","117.1657","6.2175","4.1450","27.8966"
"25.0400","6.2374","117.5542","6.2374","4.1583","27.9891"
"25.1200","6.2575","117.9465","6.2575","4.1717","28.0825"
"25.2000","6.2762","118.2996","6.2762","4.1842","28.1666"
"25.2800","6.2971","118.7125","6.2971","4.1980","28.2649"
"25.3600","6.3169","119.0878","6.3169","4.2113","28.3542"
"25.4400","6.3369","119.4846","6.3369","4.2246","28.4487"
"25.5200","6.3577","119.9041","6.3577","4.2385","28.5486"
"25.6000","6.3776","120.2777","6.3776","4.2518","28.6376"
"25.6800","6.3980","120.6778","6.3980","4.2653","28.7328"
"25.7600","6.4182","121.0590","6.4182","4.2788","28.8236"
"25.8400","6.4365","121.4049","6.4365","4.2910","28.9059"
"25.9200","6.4571","121.8060","6.4571","4.3047","29.0014"
"26.0000","6.4765","122.1733","6.4765","4.3177","29.0889"
"26.0800","6.4973","122.5821","6.4973","4.3315","29.1862"
"26.1600","6.5177","122.9869","6.5177","4.3452","29.2826"
"26.2400","6.5374","123.3541","6.5374","4.3583","29.3700"
"26.3200","6.5575","123.7497","6.5575","4.3717","29.4642"
"26.4000","6.5773","124.1209","6.5773","4.3848","29.5526"
"26.4800","6.5962","124.4866","6.5962","4.3975","29.6397"
"26.5600","6.6171","124.9001","6.6171","4.4114","29.7381"
"26.6400","6.6364","125.2536","6.6364","4.4243","29.8223"
"26.7200","6.6576","125.6767","6.6576","4.4384","29.9230"
"26.8000","6.6782","126.0880","6.6782","4.4521","30.0210"
"26.8800","6.6981","126.4564","6.6981","4.4654","30.1087"
"26.9600","6.7177","126.8386","6.7177","4.4785","30.1997"
"27.0400","6.7372","127.2042","6.7372","4.4914","30.2867"
"27.1200","6.7567","127.5675","6.7567","4.5045","30.3732"
"27.2000","6.7773","127.9739","6.7773","4.5182","30.4700"
"27.2800","6.7961","128.3183","6.7961","4.5307","30.5520"
"27.3600","6.8171","128.7334","6.8171","4.5448","30.6508"
"27.4400","6.8379","129.1374","6.8379","4.5586","30.7470"
"27.5200","6.8575","129.5193","6.8575","4.5717","30.8379"
"27.6000","6.8773","129.8917","6.8773","4.5849","30.9266"
"27.6800","6.8965","130.2488","6.8965","4.5977","31.0116"
"27.7600","6.9170","130.6495","6.9170","4.6114","31.1070"
"27.8400","6.9371","131.0217","6.9371","4.6247","31.1956"
"27.9200","6.9566","131.3871","6.9566","4.6377","31.2826"
"28.0000","6.9774","131.8083","6.9774","4.6516","31.3829"
"28.0800","6.9982","132.2100","6.9982","4.6655","31.4786"
"28.1600","7.0181","132.5903","7.0181","4.6787","31.5691"
"28.2400","7.0379","132.9676","7.0379","4.6919","31.6590"
"28.3200","7.0562","133.2966","7.0562","4.7041","31.7373"
"28.4000","7.0772","133.7117","7.0772","4.7181","31.8361"
"28.4800","7.0970","134.0756","7.0970","4.7313","31.9228"
"28.5600","7.1166","134.4505","7.1166","4.7444","32.0120"
"28.6400","7.1368","134.8507","7.1368","4.7578","32.1073"
"28.7200","7.1572","135.2267","7.1572","4.7715","32.1968"
"28.8000","7.1773","135.6114","7.1773","4.7848","32.2884"
"28.8800","7.1976","135.9850","7.1976","4.7984","32.3774"
"28.9600","7.2164","136.3353","7.2164","4.8109","32.4608"
"29.0400","7.2369","136.7349","7.2369","4.8246","32.5559"
"29.1200","7.2563","137.0928","7.2563","4.8376","32.6412"
"29.2000","7.2772","137.5070","7.2772","4.8515","32.7398"
"29.2800","7.2986","137.9156","7.2986","4.8657","32.8371"
"29.3600","7.3181","138.2731","7.3181","4.8787","32.9222"
"29.4400","7.3378","138.6404","7.3378","4.8919","33.0096"
"29.5200","7.3571","138.9849","7.3571","4.9047","33.0916"
"29.6000","7.3766","139.3689","7.3766","4.9177","33.1831"
"29.6800","7.3973","139.7627","7.3973","4.9315","33.2768"
"29.7600","7.4168","140.1215","7.4168","4.9445","33.3623"
"29.8400","7.4364","140.4864","7.4364","4.9576","33.4491"
"29.9200","7.4579","140.9117","7.4579","4.9719","33.5504"
"30.0000","7.4769","141.2552","7.4769","4.9846","33.6322"
"30.0800","7.4976","141.6425","7.4976","4.9984","33.7244"
"30.1600","7.5169","141.9868","7.5169","5.0113","33.8064"
"30.2400","7.5370","142.3811","7.5370","5.0247","33.9003"
"30.3200","7.5567","142.7451","7.5567","5.0378","33.9869"
"30.4000","7.5764","143.1097","7.5764","5.0510","34.0737"
"30.4800","7.5979","143.5299","7.5979","5.0653","34.1738"
"30.5600","7.6187","143.9245","7.6187","5.0791","34.2677"
"30.6400","7.6374","144.2582","7.6374","5.0916","34.3472"
"30.7200","7.6572","144.6210","7.6572","5.1048","34.4336"
"30.8000","7.6767","144.9790","7.6767","5.1178","34.5188"
"30.8800","7.6976","145.3821","7.6976","5.1318","34.6148"
"30.9600","7.7176","145.7454","7.7176","5.1451","34.7013"
"31.0400","7.7360","146.0836","7.7360","5.1574","34.7818"
"31.1200","7.7565","146.4732","7.7565","5.1710","34.8746"
"31.2000","7.7778","146.8803","7.7778","5.1852","34.9715"
"31.2800","7.7979","147.2629","7.7979","5.1986","35.0626"
"31.3600","7.8179","147.6359","7.8179","5.2119","35.1514"
"31.4400","7.8362","147.9489","7.8362","5.2241","35.2259"
"31.5200","7.8568","148.3422","7.8568","5.2379","35.3196"
"31.6000","7.8774","148.7290","7.8774","5.2516","35.4117"
"31.6800","7.8969","149.1033","7.8969","5.2646","35.5008"
"31.7600","7.9181","149.5072","7.9181","5.2788","35.5970"
"31.8400","7.9380","149.8731","7.9380","5.2920","35.6841"
"31.9200","7.9579","150.2375","7.9579","5.3053","35.7708"
"32.0000","7.9773","150.5848","7.9773","5.3182","35.8535"
"32.0800","7.9970","150.9531","7.9970","5.3313","35.9412"
"32.1600","8.0171","151.3319","8.0171","5.3447","36.0314"
"32.2400","8.0367","151.6738","8.0367","5.3578","36.1128"
"32.3200","8.0562","152.0424","8.0562","5.3708","36.2006"
"32.4000","8.0777","152.4577","8.0777","5.3851","36.2994"
"32.4800","8.0975","152.8039","8.0975","5.3983","36.3819"
"32.5600","8.1180","153.1872","8.1180","5.4120","36.4731"
"32.6400","8.1372","153.5310","8.1372","5.4248","36.5550"
"32.7200","8.1560","153.8766","8.1560","5.4374","36.6373"
"32.8000","8.1764","154.2425","8.1764","5.4509","36.7244"
"32.8800","8.1967","154.6241","8.1967","5.4645","36.8153"
"32.9600","8.2177","155.0183","8.2177","5.4784","36.9091"
"33.0400","8.2387","155.4165","8.2387","5.4925","37.0039"
"33.1200","8.2570","155.7146","8.2570","5.5046","37.0749"
"33.2000","8.2774","156.0988","8.2774","5.5182","37.1664"
"33.2800","8.2972","156.4598","8.2972","5.5315","37.2523"
"33.3600","8.3172","156.8408","8.3172","5.5448","37.3431"
"33.4400","8.3370","157.1925","8.3370","5.5580","37.4268"
"33.5200","8.3557","157.5229","8.3557","5.5705","37.5055"
"33.6000","8.3772","157.9352","8.3772","5.5848","37.6036"
"33.6800","8.3983","158.3277","8.3983","5.5989","37.6971"
"33.7600","8.4177","158.6772","8.4177","5.6118","37.7803"
"33.8400","8.4371","159.0218","8.4371","5.6247","37.8623"
"33.9200","8.4564","159.3627","8.4564","5.6376","37.9435"
"34.0000","8.4765","159.7352","8.4765","5.6510","38.0322"
"34.0800","8.4979","160.1343","8.4979","5.6652","38.1272"
"34.1600","8.5168","160.4690","8.5168","5.6778","38.2069"
"34.2400","8.5378","160.8677","8.5378","5.6918","38.3018"
"34.3200","8.5579","161.2287","8.5579","5.7053","38.3878"
"34.4000","8.5779","161.5869","8.5779","5.7186","38.4731"
"34.4800","8.5972","161.9445","8.5972","5.7315","38.5582"
"34.5600","8.6169","162.2753","8.6169","5.7446","38.6370"
"34.6400","8.6369","162.6356","8.6369","5.7579","38.7228"
"34.7200","8.6571","163.0025","8.6571","5.7714","38.8101"
"34.8000","8.6761","163.3510","8.6761","5.7840","38.8931"
"34.8800","8.6975","163.7577","8.6975","5.7983","38.9899"
"34.9600","8.7176","164.1157","8.7176","5.8117","39.0752"
"35.0400","8.7377","164.4785","8.7377","5.8252","39.1615"
"35.1200","8.7574","164.8223","8.7574","5.8383","39.2434"
"35.2000","8.7762","165.1553","8.7762","5.8508","39.3227"
"35.2800","8.7965","165.5060","8.7965","5.8643","39.4062"
"35.3600","8.8170","165.8750","8.8170","5.8780","39.4941"
"35.4400","8.8371","166.2365","8.8371","5.8914","39.5801"
"35.5200","8.8578","166.6235","8.8578","5.9052","39.6723"
"35.6000","8.8777","166.9584","8.8777","5.9184","39.7520"
"35.6800","8.8980","167.3375","8.8980","5.9320","39.8423"
"35.7600","8.9180","167.6852","8.9180","5.9453","39.9250"
"35.8400","8.9364","167.9953","8.9364","5.9576","39.9989"
"35.9200","8.9568","168.3655","8.9568","5.9712","40.0870"
"36.0000","8.9761","168.7059","8.9761","5.9841","40.1681"
"36.0800","8.9970","169.0928","8.9970","5.9980","40.2602"
"36.1600","9.0180","169.4728","9.0180","6.0120","40.3507"
"36.2400","9.0375","169.7977","9.0375","6.0250","40.4280"
"36.3200","9.0571","170.1476","9.0571","6.0381","40.5113"
"36.4000","9.0770","170.4833","9.0770","6.0514","40.5913"
"36.4800","9.0960","170.8227","9.0960","6.0640","40.6721"
"36.5600","9.1173","171.2209","9.1173","6.0782","40.7669"
"36.6400","9.1365","171.5508","9.1365","6.0910","40.8454"
"36.7200","9.1577","171.9260","9.1577","6.1051","40.9348"
"36.8000","9.1780","172.2817","9.1780","6.1186","41.0194"
"36.8800","9.1979","172.6411","9.1979","6.1319","41.1050"
"36.9600","9.2174","172.9783","9.2174","6.1449","41.1853"
"37.0400","9.2371","173.3178","9.2371","6.1581","41.2661"
"37.1200","9.2570","173.6763","9.2570","6.1713","41.3515"
"37.2000","9.2775","174.0470","9.2775","6.1850","41.4397"
"37.2800","9.2961","174.3574","9.2961","6.1974","41.5137"
"37.3600","9.3174","174.7516","9.3174","6.2116","41.6075"
"37.4400","9.3378","175.1123","9.3378","6.2252","41.6934"
"37.5200","9.3566","175.4197","9.3566","6.2377","41.7666"
"37.6000","9.3774","175.7970","9.3774","6.2516","41.8564"
"37.6800","9.3968","176.1285","9.3968","6.2645","41.9354"
"37.7600","9.4173","176.4877","9.4173","6.2782","42.0209"
"37.8400","9.4373","176.8339","9.4373","6.2915","42.1033"
"37.9200","9.4565","177.1678","9.4565","6.3043","42.1828"
"38.0000","9.4775","177.5560","9.4775","6.3183","42.2752"
"38.0800","9.4982","177.9168","9.4982","6.3321","42.3611"
"38.1600","9.5176","178.2428","9.5176","6.3451","42.4388"
"38.2400","9.5379","178.5944","9.5379","6.3586","42.5225"
"38.3200","9.5559","178.8932","9.5559","6.3706","42.5936"
"38.4000","9.5773","179.2778","9.5773","6.3848","42.6852"
"38.4800","9.5970","179.6130","9.5970","6.3980","42.7650"
"38.5600","9.6169","179.9637","9.6169","6.4113","42.8485"
"38.6400","9.6369","180.3187","9.6369","6.4246","42.9330"
"38.7200","9.6573","180.6688","9.6573","6.4382","43.0164"
"38.8000","9.6773","181.0165","9.6773","6.4516","43.0992"
"38.8800","9.6978","181.3698","9.6978","6.4652","43.1833"
"38.9600","9.7166","181.6847","9.7166","6.4777","43.2583"
"39.0400","9.7371","182.0493","9.7371","6.4914","43.3451"
"39.1200","9.7564","182.3748","9.7564","6.5043","43.4226"
"39.2000","9.7772","182.7431","9.7772","6.5181","43.5103"
"39.2800","9.7983","183.1118","9.7983","6.5322","43.5980"
"39.3600","9.8179","183.4490","9.8179","6.5452","43.6783"
"39.4400","9.8378","183.7894","9.8378","6.5586","43.7594"
"39.5200","9.8572","184.1202","9.8572","6.5715","43.8381"
"39.6000","9.8766","184.4484","9.8766","6.5844","43.9163"
"39.6800","9.8970","184.8107","9.8970","6.5980","44.0026"
"39.7600","9.9166","185.1279","9.9166","6.6110","44.0781"
"39.8400","9.9367","185.4722","9.9367","6.6245","44.1601"
"39.9200","9.9577","185.8383","9.9577","6.6385","44.2472"
"40.0000","9.9772","186.1798","9.9772","6.6515","44.3285"
"40.0800","9.9976","186.5369","9.9976","6.6650","44.4135"
"40.1600","10.0169","186.8632","10.0169","6.6779","44.4912"
"40.2400","10.0372","187.2245","10.0372","6.6915","44.5773"
"40.3200","10.0569","187.5412","10.0569","6.7046","44.6527"
"40.4000","10.0764","187.8673","10.0764","6.7176","44.7303"
"40.4800","10.0974","188.2457","10.0974","6.7316","44.8204"
"40.5600","10.1187","188.6165","10.1187","6.7458","44.9087"
"40.6400","10.1374","188.9214","10.1374","6.7582","44.9813"
"40.7200","10.1573","189.2544","10.1573","6.7715","45.0606"
"40.8000","10.1766","189.5748","10.1766","6.7844","45.1368"
"40.8800","10.1978","189.9420","10.1978","6.7986","45.2243"
"40.9600","10.2177","190.2699","10.2177","6.8118","45.3024"
"41.0400","10.2362","190.5679","10.2362","6.8241","45.3733"
"41.1200","10.2566","190.9313","10.2566","6.8377","45.4598"
"41.2000","10.2775","191.2900","10.2775","6.8517","45.5452"
"41.2800","10.2975","191.6241","10.2975","6.8650","45.6248"
"41.3600","10.3179","191.9666","10.3179","6.8786","45.7063"
"41.4400","10.3364","192.2537","10.3364","6.8909","45.7747"
"41.5200","10.3568","192.6044","10.3568","6.9045","45.8582"
"41.6000","10.3772","192.9655","10.3772","6.9181","45.9442"
"41.6800","10.3970","193.2949","10.3970","6.9313","46.0226"
"41.7600","10.4181","193.6548","10.4181","6.9454","46.1083"
"41.8400","10.4376","193.9733","10.4376","6.9584","46.1841"
"41.9200","10.4578","194.3065","10.4578","6.9719","46.2635"
"42.0000","10.4774","194.6309","10.4774","6.9850","46.3407"
"42.0800","10.4973","194.9723","10.4973","6.9982","46.4220"
"42.1600","10.5167","195.2808","10.5167","7.0111","46.4954"
"42.2400","10.5364","195.5947","10.5364","7.0243","46.5702"
"42.3200","10.5558","195.9219","10.5558","7.0372","46.6481"
"42.4000","10.5776","196.3049","10.5776","7.0518","46.7393"
"42.4800","10.5977","196.6369","10.5977","7.0651","46.8183"
"42.5600","10.6182","196.9712","10.6182","7.0788","46.8979"
"42.6400","10.6370","197.2549","10.6370","7.0913","46.9654"
"42.7200","10.6565","197.5760","10.6565","7.1044","47.0419"
"42.8000","10.6767","197.9243","10.6767","7.1178","47.1248"
"42.8800","10.6972","198.2507","10.6972","7.1315","47.2025"
"42.9600","10.7177","198.5908","10.7177","7.1451","47.2835"
"43.0400","10.7386","198.9391","10.7386","7.1591","47.3665"
"43.1200","10.7572","199.2178","10.7572","7.1714","47.4328"
"43.2000","10.7773","199.5544","10.7773","7.1849","47.5130"
"43.2800","10.7972","199.8682","10.7972","7.1981","47.5877"
"43.3600","10.8171","200.1966","10.8171","7.2114","47.6658"
"43.4400","10.8372","200.5175","10.8372","7.2248","47.7423"
"43.5200","10.8559","200.7957","10.8559","7.2373","47.8085"
"43.6000","10.8772","201.1470","10.8772","7.2515","47.8921"
"43.6800","10.8982","201.4940","10.8982","7.2655","47.9748"
"43.7600","10.9177","201.7998","10.9177","7.2784","48.0476"
"43.8400","10.9371","202.1051","10.9371","7.2914","48.1203"
"43.9200","10.9567","202.4122","10.9567","7.3045","48.1934"
"44.0000","10.9766","202.7255","10.9766","7.3178","48.2680"
"44.0800","10.9973","203.0470","10.9973","7.3315","48.3445"
"44.1600","11.0164","203.3358","11.0164","7.3443","48.4133"
"44.2400","11.0381","203.6837","11.0381","7.3587","48.4961"
"44.3200","11.0576","203.9731","11.0576","7.3718","48.5650"
"44.4000","11.0778","204.2852","11.0778","7.3852","48.6393"
"44.4800","11.0972","204.5799","11.0972","7.3981","48.7095"
"44.5600","11.1172","204.8824","11.1172","7.4114","48.7815"
"44.6400","11.1369","205.1908","11.1369","7.4246","48.8549"
"44.7200","11.1572","205.5093","11.1572","7.4381","48.9308"
"44.8000","11.1762","205.8158","11.1762","7.4508","49.0038"
"44.8800","11.1975","206.1608","11.1975","7.4650","49.0859"
"44.9600","11.2176","206.4651","11.2176","7.4784","49.1584"
"45.0400","11.2376","206.7550","11.2376","7.4918","49.2274"
"45.1200","11.2571","207.0503","11.2571","7.5047","49.2977"
"45.2000","11.2766","207.3492","11.2766","7.5177","49.3689"
"45.2800","11.2968","207.6607","11.2968","7.5312","49.4430"
"45.3600","11.3170","207.9732","11.3170","7.5447","49.5174"
"45.4400","11.3370","208.2909","11.3370","7.5580","49.5931"
"45.5200","11.3577","208.6156","11.3577","7.5718","49.6704"
"45.6000","11.3778","208.9194","11.3778","7.5852","49.7427"
"45.6800","11.3982","209.2226","11.3982","7.5988","49.8149"
"45.7600","11.4181","209.5218","11.4181","7.6121","49.8861"
"45.8400","11.4366","209.7883","11.4366","7.6244","49.9496"
"45.9200","11.4568","210.0956","11.4568","7.6379","50.0228"
"46.0000","11.4757","210.3706","11.4757","7.6505","50.0882"
"46.0800","11.4973","210.7137","11.4973","7.6648","50.1699"
"46.1600","11.5181","211.0352","11.5181","7.6787","50.2465"
"46.2400","11.5374","211.3102","11.5374","7.6916","50.3119"
"46.3200","11.5571","211.5907","11.5571","7.7047","50.3787"
"46.4000","11.5772","211.8928","11.5772","7.7181","50.4507"
"46.4800","11.5963","212.1720","11.5963","7.7309","50.5171"
"46.5600","11.6171","212.4867","11.6171","7.7447","50.5921"
"46.6400","11.6362","212.7512","11.6362","7.7575","50.6550"
"46.7200","11.6576","213.0871","11.6576","7.7717","50.7350"
"46.8000","11.6782","213.3978","11.6782","7.7855","50.8090"
"46.8800","11.6979","213.6864","11.6979","7.7986","50.8777"
"46.9600","11.7176","213.9654","11.7176","7.8117","50.9441"
"47.0400","11.7369","214.2302","11.7369","7.8246","51.0072"
"47.1200","11.7569","214.5289","11.7569","7.8379","51.0783"
"47.2000","11.7773","214.8324","11.7773","7.8515","51.1506"
"47.2800","11.7965","215.1023","11.7965","7.8643","51.2148"
"47.3600","11.8172","215.4087","11.8172","7.8781","51.2878"
"47.4400","11.8376","215.7090","11.8376","7.8917","51.3593"
"47.5200","11.8571","216.0015","11.8571","7.9047","51.4289"
"47.6000","11.8774","216.2965","11.8774","7.9183","51.4992"
"47.6800","11.8965","216.5648","11.8965","7.9310","51.5630"
"47.7600","11.9174","216.8659","11.9174","7.9449","51.6347"
"47.8400","11.9375","217.1576","11.9375","7.9583","51.7042"
"47.9200","11.9566","217.4255","11.9566","7.9711","51.7680"
"48.0000","11.9769","217.7275","11.9769","7.9846","51.8399"
"48.0800","11.9980","218.0411","11.9980","7.9987","51.9145"
"48.1600","12.0181","218.3234","12.0181","8.0121","51.9818"
"48.2400","12.0378","218.5966","12.0378","8.0252","52.0468"
"48.3200","12.0563","218.8454","12.0563","8.0376","52.1061"
"48.4000","12.0772","219.1566","12.0772","8.0515","52.1801"
"48.4800","12.0970","219.4362","12.0970","8.0647","52.2467"
"48.5600","12.1170","219.7217","12.1170","8.0780","52.3147"
"48.6400","12.1373","220.0201","12.1373","8.0915","52.3857"
"48.7200","12.1575","220.2997","12.1575","8.1050","52.4523"
"48.8000","12.1775","220.5712","12.1775","8.1183","52.5169"
"48.8800","12.1978","220.8616","12.1978","8.1319","52.5861"
"48.9600","12.2166","221.1112","12.2166","8.1444","52.6455"
"49.0400","12.2366","221.4074","12.2366","8.1577","52.7160"
"49.1200","12.2563","221.6705","12.2563","8.1709","52.7787"
"49.2000","12.2774","221.9778","12.2774","8.1849","52.8519"
"49.2800","12.2984","222.2835","12.2984","8.1990","52.9246"
"49.3600","12.3178","222.5361","12.3178","8.2119","52.9848"
"49.4400","12.3378","222.8041","12.3378","8.2252","53.0486"
"49.5200","12.3573","223.0580","12.3573","8.2382","53.1090"
"49.6000","12.3766","223.3273","12.3766","8.2511","53.1732"
"49.6800","12.3970","223.6124","12.3970","8.2647","53.2411"
"49.7600","12.4165","223.8690","12.4165","8.2777","53.3021"
"49.8400","12.4367","224.1423","12.4367","8.2912","53.3672"
"49.9200","12.4577","224.4352","12.4577","8.3051","53.4370"
"50.0000","12.4773","224.7039","12.4773","8.3182","53.5009"
"50.0800","12.4977","224.9803","12.4977","8.3318","53.5667"
"50.1600","12.5167","225.2147","12.5167","8.3445","53.6225"
"50.2400","12.5371","225.4954","12.5371","8.3581","53.6894"
"50.3200","12.5567","225.7582","12.5567","8.3711","53.7520"
"50.4000","12.5763","226.0140","12.5763","8.3842","53.8129"
"50.4800","12.5977","226.3316","12.5977","8.3985","53.8885"
"50.5600","12.6188","226.6187","12.6188","8.4125","53.9568"
"50.6400","12.6376","226.8634","12.6376","8.4251","54.0151"
"50.7200","12.6574","227.1222","12.6574","8.4383","54.0767"
"50.8000","12.6760","227.3384","12.6760","8.4506","54.1282"
"50.8800","12.6971","227.6381","12.6971","8.4647","54.1995"
"50.9600","12.7176","227.9073","12.7176","8.4784","54.2637"
"51.0400","12.7366","228.1492","12.7366","8.4911","54.3212"
"51.1200","12.7571","228.4279","12.7571","8.5048","54.3876"
"51.2000","12.7778","228.7018","12.7778","8.5185","54.4528"
"51.2800","12.7976","228.9533","12.7976","8.5317","54.5127"
"51.3600","12.8179","229.2464","12.8179","8.5453","54.5825"
"51.4400","12.8365","229.4527","12.8365","8.5576","54.6316"
"51.5200","12.8569","229.7258","12.8569","8.5712","54.6966"
"51.6000","12.8771","229.9857","12.8771","8.5847","54.7585"
"51.6800","12.8968","230.2333","12.8968","8.5978","54.8175"
"51.7600","12.9183","230.5406","12.9183","8.6122","54.8906"
"51.8400","12.9376","230.7637","12.9376","8.6251","54.9437"
"51.9200","12.9579","231.0222","12.9579","8.6386","55.0053"
"52.0000","12.9774","231.2655","12.9774","8.6516","55.0632"
"52.0800","12.9971","231.5105","12.9971","8.6647","55.1216"
"52.1600","13.0169","231.7732","13.0169","8.6780","55.1841"
"52.2400","13.0368","232.0145","13.0368","8.6912","55.2415"
"52.3200","13.0564","232.2698","13.0564","8.7043","55.3023"
"52.4000","13.0781","232.5575","13.0781","8.7187","55.3708"
"52.4800","13.0977","232.7932","13.0977","8.7318","55.4269"
"52.5600","13.1181","233.0454","13.1181","8.7454","55.4870"
"52.6400","13.1371","233.2600","13.1371","8.7581","55.5381"
"52.7200","13.1562","233.4787","13.1562","8.7708","55.5902"
"52.8000","13.1764","233.7099","13.1764","8.7842","55.6452"
"52.8800","13.1968","233.9495","13.1968","8.7979","55.7023"
"52.9600","13.2177","234.2084","13.2177","8.8118","55.7639"
"53.0400","13.2386","234.4671","13.2386","8.8257","55.8255"
"53.1200","13.2575","234.6819","13.2575","8.8383","55.8766"
"53.2000","13.2772","234.9040","13.2772","8.8514","55.9295"
"53.2800","13.2969","235.1279","13.2969","8.8646","55.9828"
"53.3600","13.3173","235.3941","13.3173","8.8782","56.0462"
"53.4400","13.3371","235.6139","13.3371","8.8914","56.0986"
"53.5200","13.3558","235.8202","13.3558","8.9038","56.1477"
"53.6000","13.3774","236.0947","13.3774","8.9183","56.2130"
"53.6800","13.3983","236.3392","13.3983","8.9322","56.2712"
"53.7600","13.4173","236.5456","13.4173","8.9449","56.3204"
"53.8400","13.4371","236.7672","13.4371","8.9581","56.3731"
"53.9200","13.4566","236.9767","13.4566","8.9711","56.4230"
"54.0000","13.4767","237.1990","13.4767","8.9845","56.4760"
"54.0800","13.4977","237.4497","13.4977","8.9985","56.5356"
"54.1600","13.5167","237.6446","13.5167","9.0111","56.5820"
"54.2400","13.5377","237.8813","13.5377","9.0251","56.6384"
"54.3200","13.5576","238.0967","13.5576","9.0384","56.6897"
"54.4000","13.5778","238.3197","13.5778","9.0518","56.7428"
"54.4800","13.5977","238.5251","13.5977","9.0651","56.7917"
"54.5600","13.6172","238.6791","13.6172","9.0781","56.8284"
"54.6400","13.6371","238.7491","13.6371","9.0914","56.8450"
"54.7200","13.6572","238.9086","13.6572","9.1048","56.8830"
"54.8000","13.6758","239.0694","13.6758","9.1172","56.9213"
"54.8800","13.6971","239.3068","13.6971","9.1314","56.9778"
"54.9600","13.7175","239.4917","13.7175","9.1450","57.0218"
"55.0400","13.7378","239.6918","13.7378","9.1585","57.0695"
"55.1200","13.7573","239.8662","13.7573","9.1715","57.1110"
"55.2000","13.7764","240.0315","13.7764","9.1843","57.1504"
"55.2800","13.7973","240.2342","13.7973","9.1982","57.1986"
"55.3600","13.8170","240.4003","13.8170","9.2113","57.2382"
"55.4400","13.8367","240.5696","13.8367","9.2245","57.2785"
"55.5200","13.8579","240.7736","13.8579","9.2386","57.3270"
"55.6000","13.8778","240.9386","13.8778","9.2518","57.3663"
"55.6800","13.8979","241.1215","13.8979","9.2652","57.4099"
"55.7600","13.9178","241.2971","13.9178","9.2785","57.4517"
"55.8400","13.9365","241.4554","13.9365","9.2910","57.4894"
"55.9200","13.9566","241.6600","13.9566","9.3044","57.5381"
"56.0000","13.9762","241.8379","13.9762","9.3175","57.5804"
"56.0800","13.9972","242.0572","13.9972","9.3315","57.6327"
"56.1600","14.0182","242.2681","14.0182","9.3455","57.6829"
"56.2400","14.0374","242.4296","14.0374","9.3583","57.7213"
"56.3200","14.0571","242.6037","14.0571","9.3714","57.7628"
"56.4000","14.0772","242.7991","14.0772","9.3848","57.8093"
"56.4800","14.0967","242.9645","14.0967","9.3978","57.8487"
"56.5600","14.1169","243.1683","14.1169","9.4113","57.8972"
"56.6400","14.1361","243.3202","14.1361","9.4240","57.9334"
"56.7200","14.1575","243.5334","14.1575","9.4383","57.9841"
"56.8000","14.1784","243.7403","14.1784","9.4522","58.0334"
"56.8800","14.1979","243.9088","14.1979","9.4653","58.0735"
"56.9600","14.2175","244.0725","14.2175","9.4783","58.1125"
"57.0400","14.2370","244.2438","14.2370","9.4913","58.1533"
"57.1200","14.2569","244.4251","14.2569","9.5046","58.1965"
"57.2000","14.2769","244.6053","14.2769","9.5179","58.2393"
"57.2800","14.2961","244.7686","14.2961","9.5307","58.2782"
"57.3600","14.3173","244.9839","14.3173","9.5449","58.3295"
"57.4400","14.3378","245.1682","14.3378","9.5585","58.3734"
"57.5200","14.3572","245.3325","14.3572","9.5715","58.4125"
"57.6000","14.3774","245.5195","14.3774","9.5849","58.4570"
"57.6800","14.3967","245.6919","14.3967","9.5978","58.4981"
"57.7600","14.4176","245.8875","14.4176","9.6117","58.5446"
"57.8400","14.4373","246.0382","14.4373","9.6248","58.5805"
"57.9200","14.4562","246.1906","14.4562","9.6375","58.6168"
"58.0000","14.4774","246.4014","14.4774","9.6516","58.6670"
"58.0800","14.4981","246.5900","14.4981","9.6654","58.7119"
"58.1600","14.5179","246.7589","14.5179","9.6786","58.7521"
"58.2400","14.5371","246.8920","14.5371","9.6914","58.7838"
"58.3200","14.5559","247.0370","14.5559","9.7040","58.8183"
"58.4000","14.5773","247.2309","14.5773","9.7182","58.8645"
"58.4800","14.5971","247.4000","14.5971","9.7314","58.9048"
"58.5600","14.6167","247.5470","14.6167","9.7444","58.9398"
"58.6400","14.6372","247.7301","14.6372","9.7581","58.9834"
"58.7200","14.6576","247.9066","14.6576","9.7717","59.0254"
"58.8000","14.6774","248.0604","14.6774","9.7850","59.0620"
"58.8800","14.6978","248.2335","14.6978","9.7985","59.1032"
"58.9600","14.7166","248.3781","14.7166","9.8111","59.1376"
"59.0400","14.7368","248.5270","14.7368","9.8245","59.1731"
"59.1200","14.7563","248.6813","14.7563","9.8375","59.2098"
"59.2000","14.7774","248.8756","14.7774","9.8516","59.2561"
"59.2800","14.7986","249.0635","14.7986","9.8658","59.3008"
"59.3600","14.8179","249.1908","14.8179","9.8786","59.3311"
"59.4400","14.8378","249.3343","14.8378","9.8919","59.3653"
"59.5200","14.8572","249.4721","14.8572","9.9048","59.3981"
"59.6000","14.8765","249.6131","14.8765","9.9177","59.4317"
"59.6800","14.8972","249.7872","14.8972","9.9315","59.4731"
"59.7600","14.9163","249.9014","14.9163","9.9442","59.5003"
"59.8400","14.9368","250.0618","14.9368","9.9579","59.5385"
"59.9200","14.9581","250.2204","14.9581","9.9720","59.5763"
"60.0000","14.9768","250.3515","14.9768","9.9845","59.6075"
"60.0800","14.9974","250.4919","14.9974","9.9982","59.6409"
"60.0910","15.0001","250.5245","15.0001","10.0000","59.6487"