File: data/instron_tests/metamaterials/250421/250421_2224_BULK_m2.is_comp_Exports/250421_2224_BULK_m2_6_1.csv
Results Table 1
,Compresson Axis,H*,V*,Height,Thickness,Width,Area,Fixture separation,Specimen label
,,,,(mm),(mm),(mm),(mm^2),(mm),
"6","X","","","150.00","28.00","150.00","4200.00","150.00","2224_BULK_m2"

Results Table 2
,Modulus (Segment 0 % - 2.5 %),Compresson Axis
,(kPa),
"6","789.01","X"

Time,Displacement,Force,Compressive displacement,Compressive strain (Displacement),Compressive stress
(s),(mm),(N),(mm),(%),(kPa)
"0.0000","0.0000","-21.5493","0.0000","0.0000","-5.1308"
"0.0800","0.0011","-21.4512","0.0011","0.0008","-5.1074"
"0.1600","0.0175","-20.9230","0.0175","0.0116","-4.9817"
"0.2400","0.0378","-20.2979","0.0378","0.0252","-4.8328"
"0.3200","0.0574","-19.7221","0.0574","0.0383","-4.6957"
"0.4000","0.0766","-19.1792","0.0766","0.0510","-4.5665"
"0.4800","0.0982","-18.5695","0.0982","0.0655","-4.4213"
"0.5600","0.1183","-18.0281","0.1183","0.0788","-4.2924"
"0.6400","0.1369","-17.5136","0.1369","0.0913","-4.1699"
"0.7200","0.1570","-16.9695","0.1570","0.1047","-4.0404"
"0.8000","0.1769","-16.4485","0.1769","0.1180","-3.9163"
"0.8800","0.1976","-15.9034","0.1976","0.1317","-3.7865"
"0.9600","0.2178","-15.3726","0.2178","0.1452","-3.6601"
"1.0400","0.2361","-14.9011","0.2361","0.1574","-3.5479"
"1.1200","0.2569","-14.3472","0.2569","0.1713","-3.4160"
"1.2000","0.2774","-13.8149","0.2774","0.1850","-3.2893"
"1.2800","0.2976","-13.2958","0.2976","0.1984","-3.1657"
"1.3600","0.3173","-12.8022","0.3173","0.2115","-3.0481"
"1.4400","0.3364","-12.3190","0.3364","0.2242","-2.9331"
"1.5200","0.3568","-11.8002","0.3568","0.2379","-2.8096"
"1.6000","0.3774","-11.2753","0.3774","0.2516","-2.6846"
"1.6800","0.3971","-10.7715","0.3971","0.2647","-2.5646"
"1.7600","0.4179","-10.2437","0.4179","0.2786","-2.4390"
"1.8400","0.4377","-9.7515","0.4377","0.2918","-2.3218"
"1.9200","0.4578","-9.2623","0.4578","0.3052","-2.2053"
"2.0000","0.4770","-8.7822","0.4770","0.3180","-2.0910"
"2.0800","0.4965","-8.2977","0.4965","0.3310","-1.9757"
"2.1600","0.5169","-7.7866","0.5169","0.3446","-1.8540"
"2.2400","0.5366","-7.3166","0.5366","0.3577","-1.7420"
"2.3200","0.5563","-6.8167","0.5563","0.3709","-1.6230"
"2.4000","0.5780","-6.2894","0.5780","0.3853","-1.4975"
"2.4800","0.5975","-5.8152","0.5975","0.3983","-1.3846"
"2.5600","0.6180","-5.3269","0.6180","0.4120","-1.2683"
"2.6400","0.6373","-4.8548","0.6373","0.4249","-1.1559"
"2.7200","0.6558","-4.4016","0.6558","0.4372","-1.0480"
"2.8000","0.6767","-3.9001","0.6767","0.4511","-0.9286"
"2.8800","0.6969","-3.4076","0.6969","0.4646","-0.8113"
"2.9600","0.7177","-2.9038","0.7177","0.4785","-0.6914"
"3.0400","0.7383","-2.4213","0.7383","0.4922","-0.5765"
"3.1200","0.7570","-1.9768","0.7570","0.5047","-0.4707"
"3.2000","0.7774","-1.4845","0.7774","0.5183","-0.3535"
"3.2800","0.7975","-1.0044","0.7975","0.5317","-0.2391"
"3.3600","0.8172","-0.5338","0.8172","0.5448","-0.1271"
"3.4400","0.8369","-0.0718","0.8369","0.5579","-0.0171"
"3.5200","0.8559","0.3730","0.8559","0.5706","0.0888"
"3.6000","0.8772","0.8769","0.8772","0.5848","0.2088"
"3.6800","0.8982","1.3773","0.8982","0.5988","0.3279"
"3.7600","0.9173","1.8176","0.9173","0.6116","0.4328"
"3.8400","0.9372","2.2829","0.9372","0.6248","0.5435"
"3.9200","0.9567","2.7324","0.9567","0.6378","0.6506"
"4.0000","0.9765","3.1882","0.9765","0.6510","0.7591"
"4.0800","0.9973","3.6724","0.9973","0.6649","0.8744"
"4.1600","1.0169","4.1244","1.0169","0.6779","0.9820"
"4.2400","1.0379","4.6019","1.0379","0.6919","1.0957"
"4.3200","1.0580","5.0631","1.0580","0.7054","1.2055"
"4.4000","1.0778","5.4951","1.0778","0.7186","1.3084"
"4.4800","1.0971","5.9131","1.0971","0.7314","1.4079"
"4.5600","1.1162","6.3199","1.1162","0.7441","1.5047"
"4.6400","1.1373","6.8005","1.1373","0.7582","1.6192"
"4.7200","1.1571","7.2287","1.1571","0.7714","1.7211"
"4.8000","1.1763","7.6620","1.1763","0.7842","1.8243"
"4.8800","1.1974","8.1440","1.1974","0.7983","1.9390"
"4.9600","1.2176","8.5722","1.2176","0.8117","2.0410"
"5.0400","1.2378","9.0221","1.2378","0.8252","2.1481"
"5.1200","1.2572","9.4417","1.2572","0.8381","2.2480"
"5.2000","1.2762","9.8733","1.2762","0.8508","2.3508"
"5.2800","1.2974","10.3381","1.2974","0.8649","2.4614"
"5.3600","1.3173","10.7699","1.3173","0.8782","2.5643"
"5.4400","1.3368","11.1906","1.3368","0.8912","2.6644"
"5.5200","1.3574","11.6565","1.3574","0.9050","2.7753"
"5.6000","1.3776","12.0883","1.3776","0.9184","2.8782"
"5.6800","1.3984","12.5354","1.3984","0.9322","2.9846"
"5.7600","1.4180","12.9529","1.4180","0.9454","3.0840"
"5.8400","1.4367","13.3682","1.4367","0.9578","3.1829"
"5.9200","1.4568","13.8006","1.4568","0.9712","3.2859"
"6.0000","1.4763","14.2245","1.4763","0.9842","3.3868"
"6.0800","1.4974","14.6923","1.4974","0.9983","3.4982"
"6.1600","1.5179","15.1266","1.5179","1.0119","3.6016"
"6.2400","1.5374","15.5572","1.5374","1.0249","3.7041"
"6.3200","1.5573","15.9819","1.5573","1.0382","3.8052"
"6.4000","1.5771","16.4077","1.5771","1.0514","3.9066"
"6.4800","1.5961","16.8214","1.5961","1.0641","4.0051"
"6.5600","1.6173","17.2946","1.6173","1.0782","4.1178"
"6.6400","1.6363","17.6933","1.6363","1.0909","4.2127"
"6.7200","1.6575","18.1767","1.6575","1.1050","4.3278"
"6.8000","1.6780","18.6096","1.6780","1.1187","4.4308"
"6.8800","1.6978","19.0527","1.6978","1.1319","4.5364"
"6.9600","1.7176","19.4775","1.7176","1.1451","4.6375"
"7.0400","1.7370","19.8901","1.7370","1.1580","4.7357"
"7.1200","1.7564","20.3113","1.7564","1.1710","4.8360"
"7.2000","1.7769","20.7591","1.7769","1.1846","4.9426"
"7.2800","1.7963","21.1882","1.7963","1.1975","5.0448"
"7.3600","1.8177","21.6610","1.8177","1.2118","5.1574"
"7.4400","1.8377","22.0953","1.8377","1.2251","5.2608"
"7.5200","1.8570","22.5119","1.8570","1.2380","5.3600"
"7.6000","1.8774","22.9623","1.8774","1.2516","5.4672"
"7.6800","1.8967","23.3709","1.8967","1.2645","5.5645"
"7.7600","1.9173","23.8120","1.9173","1.2782","5.6695"
"7.8400","1.9371","24.2469","1.9371","1.2914","5.7731"
"7.9200","1.9565","24.6766","1.9565","1.3043","5.8754"
"8.0000","1.9771","25.1349","1.9771","1.3181","5.9845"
"8.0800","1.9981","25.5860","1.9981","1.3321","6.0919"
"8.1600","2.0179","26.0185","2.0179","1.3453","6.1949"
"8.2400","2.0379","26.4525","2.0379","1.3586","6.2982"
"8.3200","2.0563","26.8457","2.0563","1.3709","6.3918"
"8.4000","2.0775","27.3103","2.0775","1.3850","6.5024"
"8.4800","2.0969","27.7183","2.0969","1.3979","6.5996"
"8.5600","2.1167","28.1616","2.1167","1.4112","6.7051"
"8.6400","2.1373","28.6250","2.1373","1.4249","6.8155"
"8.7200","2.1574","29.0420","2.1574","1.4383","6.9148"
"8.8000","2.1774","29.4640","2.1774","1.4516","7.0152"
"8.8800","2.1977","29.9170","2.1977","1.4651","7.1231"
"8.9600","2.2166","30.3187","2.2166","1.4777","7.2187"
"9.0400","2.2370","30.7535","2.2370","1.4913","7.3223"
"9.1200","2.2566","31.1680","2.2566","1.5044","7.4209"
"9.2000","2.2774","31.6307","2.2774","1.5183","7.5311"
"9.2800","2.2986","32.0968","2.2986","1.5324","7.6421"
"9.3600","2.3178","32.4963","2.3178","1.5452","7.7372"
"9.4400","2.3378","32.9204","2.3378","1.5586","7.8382"
"9.5200","2.3575","33.3692","2.3575","1.5717","7.9451"
"9.6000","2.3762","33.7612","2.3762","1.5841","8.0384"
"9.6800","2.3970","34.2279","2.3970","1.5980","8.1495"
"9.7600","2.4164","34.6275","2.4164","1.6109","8.2447"
"9.8400","2.4370","35.0723","2.4370","1.6247","8.3505"
"9.9200","2.4581","35.5207","2.4581","1.6387","8.4573"
"10.0000","2.4770","35.9352","2.4770","1.6513","8.5560"
"10.0800","2.4977","36.3842","2.4977","1.6651","8.6629"
"10.1600","2.5171","36.7999","2.5171","1.6781","8.7619"
"10.2400","2.5369","37.2195","2.5369","1.6913","8.8618"
"10.3200","2.5567","37.6499","2.5567","1.7045","8.9643"
"10.4000","2.5764","38.0617","2.5764","1.7176","9.0623"
"10.4800","2.5975","38.5338","2.5975","1.7317","9.1747"
"10.5600","2.6188","38.9937","2.6188","1.7458","9.2842"
"10.6400","2.6377","39.3928","2.6377","1.7585","9.3792"
"10.7200","2.6570","39.7879","2.6570","1.7713","9.4733"
"10.8000","2.6763","40.2039","2.6763","1.7842","9.5724"
"10.8800","2.6975","40.6691","2.6975","1.7983","9.6831"
"10.9600","2.7175","41.1077","2.7175","1.8117","9.7876"
"11.0400","2.7367","41.5295","2.7367","1.8245","9.8880"
"11.1200","2.7570","41.9479","2.7570","1.8380","9.9876"
"11.2000","2.7775","42.3885","2.7775","1.8517","10.0925"
"11.2800","2.7973","42.8056","2.7973","1.8649","10.1918"
"11.3600","2.8176","43.2429","2.8176","1.8784","10.2959"
"11.4400","2.8363","43.6326","2.8363","1.8909","10.3887"
"11.5200","2.8567","44.0717","2.8567","1.9045","10.4933"
"11.6000","2.8772","44.4940","2.8772","1.9181","10.5938"
"11.6800","2.8970","44.9149","2.8970","1.9313","10.6940"
"11.7600","2.9181","45.3802","2.9181","1.9454","10.8048"
"11.8400","2.9376","45.7886","2.9376","1.9584","10.9020"
"11.9200","2.9578","46.2263","2.9578","1.9719","11.0063"
"12.0000","2.9775","46.6411","2.9775","1.9850","11.1050"
"12.0800","2.9966","47.0415","2.9966","1.9977","11.2004"
"12.1600","3.0171","47.4615","3.0171","2.0114","11.3004"
"12.2400","3.0368","47.8760","3.0368","2.0245","11.3990"
"12.3200","3.0563","48.3004","3.0563","2.0375","11.5001"
"12.4000","3.0779","48.7796","3.0779","2.0519","11.6142"
"12.4800","3.0973","49.1929","3.0973","2.0649","11.7126"
"12.5600","3.1180","49.6280","3.1180","2.0787","11.8162"
"12.6400","3.1373","50.0253","3.1373","2.0915","11.9108"
"12.7200","3.1564","50.4221","3.1564","2.1043","12.0053"
"12.8000","3.1767","50.8585","3.1767","2.1178","12.1092"
"12.8800","3.1967","51.2742","3.1967","2.1311","12.2082"
"12.9600","3.2174","51.7307","3.2174","2.1449","12.3168"
"13.0400","3.2384","52.1827","3.2384","2.1589","12.4245"
"13.1200","3.2575","52.5984","3.2575","2.1717","12.5234"
"13.2000","3.2775","53.0126","3.2775","2.1850","12.6221"
"13.2800","3.2972","53.4201","3.2972","2.1981","12.7191"
"13.3600","3.3172","53.8505","3.3172","2.2114","12.8216"
"13.4400","3.3373","54.2749","3.3373","2.2249","12.9226"
"13.5200","3.3558","54.6585","3.3558","2.2372","13.0139"
"13.6000","3.3770","55.1052","3.3770","2.2513","13.1203"
"13.6800","3.3982","55.5631","3.3982","2.2654","13.2293"
"13.7600","3.4173","55.9686","3.4173","2.2782","13.3259"
"13.8400","3.4371","56.3817","3.4371","2.2914","13.4242"
"13.9200","3.4566","56.7872","3.4566","2.3044","13.5208"
"14.0000","3.4768","57.2197","3.4768","2.3179","13.6237"
"14.0800","3.4977","57.6625","3.4977","2.3318","13.7292"
"14.1600","3.5165","58.0565","3.5165","2.3443","13.8230"
"14.2400","3.5380","58.5284","3.5380","2.3587","13.9353"
"14.3200","3.5577","58.9325","3.5577","2.3718","14.0316"
"14.4000","3.5774","59.3429","3.5774","2.3849","14.1293"
"14.4800","3.5975","59.7729","3.5975","2.3983","14.2316"
"14.5600","3.6170","60.1745","3.6170","2.4114","14.3273"
"14.6400","3.6368","60.5937","3.6368","2.4246","14.4271"
"14.7200","3.6567","61.0070","3.6567","2.4378","14.5255"
"14.8000","3.6761","61.4191","3.6761","2.4507","14.6236"
"14.8800","3.6973","61.8835","3.6973","2.4649","14.7342"
"14.9600","3.7174","62.2947","3.7174","2.4782","14.8321"
"15.0400","3.7376","62.7198","3.7376","2.4917","14.9333"
"15.1200","3.7576","63.1369","3.7576","2.5051","15.0326"
"15.2000","3.7762","63.5123","3.7762","2.5174","15.1220"
"15.2800","3.7970","63.9621","3.7970","2.5314","15.2291"
"15.3600","3.8171","64.3682","3.8171","2.5447","15.3258"
"15.4400","3.8370","64.7989","3.8370","2.5580","15.4283"
"15.5200","3.8577","65.2446","3.8577","2.5718","15.5344"
"15.6000","3.8777","65.6470","3.8777","2.5851","15.6302"
"15.6800","3.8979","66.0670","3.8979","2.5986","15.7302"
"15.7600","3.9178","66.4782","3.9178","2.6119","15.8281"
"15.8400","3.9365","66.8636","3.9365","2.6243","15.9199"
"15.9200","3.9570","67.2990","3.9570","2.6380","16.0236"
"16.0000","3.9765","67.6931","3.9765","2.6510","16.1174"
"16.0800","3.9974","68.1362","3.9974","2.6649","16.2229"
"16.1600","4.0179","68.5584","4.0179","2.6786","16.3234"
"16.2400","4.0374","68.9634","4.0374","2.6916","16.4199"
"16.3200","4.0571","69.3781","4.0571","2.7048","16.5186"
"16.4000","4.0772","69.7824","4.0772","2.7181","16.6149"
"16.4800","4.0964","70.1891","4.0964","2.7309","16.7117"
"16.5600","4.1171","70.6170","4.1171","2.7448","16.8136"
"16.6400","4.1363","70.9961","4.1363","2.7575","16.9038"
"16.7200","4.1576","71.4516","4.1576","2.7717","17.0123"
"16.8000","4.1784","71.8817","4.1784","2.7856","17.1147"
"16.8800","4.1979","72.2938","4.1979","2.7986","17.2128"
"16.9600","4.2174","72.6911","4.2174","2.8116","17.3074"
"17.0400","4.2372","73.0961","4.2372","2.8248","17.4038"
"17.1200","4.2567","73.4958","4.2567","2.8378","17.4990"
"17.2000","4.2770","73.9125","4.2770","2.8513","17.5982"
"17.2800","4.2960","74.2954","4.2960","2.8640","17.6894"
"17.3600","4.3167","74.7326","4.3167","2.8778","17.7935"
"17.4400","4.3379","75.1631","4.3379","2.8920","17.8960"
"17.5200","4.3576","75.5677","4.3576","2.9050","17.9923"
"17.6000","4.3776","75.9867","4.3776","2.9184","18.0921"
"17.6800","4.3965","76.3614","4.3965","2.9310","18.1813"
"17.7600","4.4172","76.7901","4.4172","2.9448","18.2834"
"17.8400","4.4374","77.2096","4.4374","2.9582","18.3832"
"17.9200","4.4565","77.5933","4.4565","2.9710","18.4746"
"18.0000","4.4769","78.0259","4.4769","2.9846","18.5776"
"18.0800","4.4981","78.4658","4.4981","2.9987","18.6823"
"18.1600","4.5179","78.8702","4.5179","3.0120","18.7786"
"18.2400","4.5378","79.2621","4.5378","3.0252","18.8719"
"18.3200","4.5559","79.6192","4.5559","3.0373","18.9570"
"18.4000","4.5773","80.0751","4.5773","3.0515","19.0655"
"18.4800","4.5970","80.4926","4.5970","3.0647","19.1649"
"18.5600","4.6170","80.8981","4.6170","3.0780","19.2615"
"18.6400","4.6370","81.3149","4.6370","3.0913","19.3607"
"18.7200","4.6572","81.7125","4.6572","3.1048","19.4554"
"18.8000","4.6771","82.1151","4.6771","3.1181","19.5512"
"18.8800","4.6980","82.5499","4.6980","3.1320","19.6548"
"18.9600","4.7166","82.9211","4.7166","3.1444","19.7431"
"19.0400","4.7368","83.3380","4.7368","3.1579","19.8424"
"19.1200","4.7563","83.7261","4.7563","3.1709","19.9348"
"19.2000","4.7773","84.1858","4.7773","3.1848","20.0442"
"19.2800","4.7988","84.6279","4.7988","3.1992","20.1495"
"19.3600","4.8179","85.0083","4.8179","3.2120","20.2401"
"19.4400","4.8376","85.3942","4.8376","3.2250","20.3320"
"19.5200","4.8573","85.7980","4.8573","3.2382","20.4281"
"19.6000","4.8767","86.1928","4.8767","3.2511","20.5221"
"19.6800","4.8973","86.6351","4.8973","3.2649","20.6274"
"19.7600","4.9166","86.9978","4.9166","3.2777","20.7138"
"19.8400","4.9369","87.4335","4.9369","3.2913","20.8175"
"19.9200","4.9580","87.8575","4.9580","3.3053","20.9185"
"20.0000","4.9771","88.2465","4.9771","3.3181","21.0111"
"20.0800","4.9978","88.6673","4.9978","3.3319","21.1113"
"20.1600","5.0167","89.0419","5.0167","3.3445","21.2005"
"20.2400","5.0365","89.4312","5.0365","3.3576","21.2931"
"20.3200","5.0561","89.8329","5.0561","3.3707","21.3888"
"20.4000","5.0767","90.2435","5.0767","3.3845","21.4865"
"20.4800","5.0977","90.6783","5.0977","3.3985","21.5901"
"20.5600","5.1188","91.1093","5.1188","3.4125","21.6927"
"20.6400","5.1373","91.4721","5.1373","3.4248","21.7791"
"20.7200","5.1570","91.8741","5.1570","3.4380","21.8748"
"20.8000","5.1766","92.2562","5.1766","3.4510","21.9658"
"20.8800","5.1979","92.7107","5.1979","3.4653","22.0740"
"20.9600","5.2174","93.0865","5.2174","3.4783","22.1635"
"21.0400","5.2361","93.4586","5.2361","3.4907","22.2520"
"21.1200","5.2568","93.8811","5.2568","3.5045","22.3526"
"21.2000","5.2777","94.3057","5.2777","3.5184","22.4537"
"21.2800","5.2973","94.6952","5.2973","3.5316","22.5465"
"21.3600","5.3174","95.1055","5.3174","3.5450","22.6442"
"21.4400","5.3365","95.4728","5.3365","3.5577","22.7316"
"21.5200","5.3569","95.8805","5.3569","3.5712","22.8287"
"21.6000","5.3769","96.2814","5.3769","3.5846","22.9241"
"21.6800","5.3967","96.6909","5.3967","3.5978","23.0216"
"21.7600","5.4184","97.1503","5.4184","3.6123","23.1310"
"21.8400","5.4378","97.5138","5.4378","3.6252","23.2176"
"21.9200","5.4577","97.9091","5.4577","3.6385","23.3117"
"22.0000","5.4776","98.3085","5.4776","3.6517","23.4068"
"22.0800","5.4970","98.6982","5.4970","3.6647","23.4996"
"22.1600","5.5174","99.1066","5.5174","3.6783","23.5968"
"22.2400","5.5366","99.4930","5.5366","3.6911","23.6888"
"22.3200","5.5560","99.8836","5.5560","3.7040","23.7818"
"22.4000","5.5779","100.3340","5.5779","3.7186","23.8890"
"22.4800","5.5970","100.6955","5.5970","3.7313","23.9751"
"22.5600","5.6176","101.1112","5.6176","3.7450","24.0741"
"22.6400","5.6374","101.5121","5.6374","3.7583","24.1695"
"22.7200","5.6565","101.8904","5.6565","3.7710","24.2596"
"22.8000","5.6765","102.2908","5.6765","3.7843","24.3550"
"22.8800","5.6967","102.6906","5.6967","3.7978","24.4501"
"22.9600","5.7178","103.1190","5.7178","3.8119","24.5522"
"23.0400","5.7388","103.5500","5.7388","3.8259","24.6548"
"23.1200","5.7569","103.8923","5.7569","3.8380","24.7363"
"23.2000","5.7772","104.2912","5.7772","3.8515","24.8312"
"23.2800","5.7974","104.6928","5.7974","3.8649","24.9269"
"23.3600","5.8172","105.0925","5.8172","3.8781","25.0220"
"23.4400","5.8372","105.4804","5.8372","3.8914","25.1144"
"23.5200","5.8558","105.8431","5.8558","3.9039","25.2007"
"23.6000","5.8772","106.2775","5.8772","3.9181","25.3042"
"23.6800","5.8983","106.7116","5.8983","3.9322","25.4075"
"23.7600","5.9177","107.0878","5.9177","3.9451","25.4971"
"23.8400","5.9373","107.4799","5.9373","3.9582","25.5904"
"23.9200","5.9566","107.8482","5.9566","3.9711","25.6781"
"24.0000","5.9763","108.2417","5.9763","3.9842","25.7718"
"24.0800","5.9974","108.6575","5.9974","3.9983","25.8708"
"24.1600","6.0167","109.0458","6.0167","4.0111","25.9633"
"24.2400","6.0380","109.4754","6.0380","4.0253","26.0656"
"24.3200","6.0579","109.8751","6.0579","4.0386","26.1607"
"24.4000","6.0781","110.2727","6.0781","4.0521","26.2554"
"24.4800","6.0974","110.6581","6.0974","4.0649","26.3472"
"24.5600","6.1169","111.0380","6.1169","4.0779","26.4376"
"24.6400","6.1369","111.4194","6.1369","4.0913","26.5284"
"24.7200","6.1570","111.8133","6.1570","4.1047","26.6222"
"24.8000","6.1758","112.1869","6.1758","4.1172","26.7112"
"24.8800","6.1975","112.6354","6.1975","4.1316","26.8179"
"24.9600","6.2174","113.0294","6.2174","4.1450","26.9118"
"25.0400","6.2378","113.4233","6.2378","4.1586","27.0055"
"25.1200","6.2575","113.8005","6.2575","4.1717","27.0954"
"25.2000","6.2761","114.1587","6.2761","4.1840","27.1806"
"25.2800","6.2967","114.5643","6.2967","4.1978","27.2772"
"25.3600","6.3169","114.9737","6.3169","4.2113","27.3747"
"25.4400","6.3371","115.3629","6.3371","4.2248","27.4674"
"25.5200","6.3578","115.7919","6.3578","4.2385","27.5695"
"25.6000","6.3776","116.1637","6.3776","4.2517","27.6580"
"25.6800","6.3980","116.5574","6.3980","4.2653","27.7518"
"25.7600","6.4181","116.9528","6.4181","4.2788","27.8459"
"25.8400","6.4363","117.3005","6.4363","4.2909","27.9287"
"25.9200","6.4571","117.7108","6.4571","4.3047","28.0264"
"26.0000","6.4762","118.0729","6.4762","4.3175","28.1126"
"26.0800","6.4971","118.4978","6.4971","4.3314","28.2138"
"26.1600","6.5178","118.9073","6.5178","4.3452","28.3113"
"26.2400","6.5373","119.2807","6.5373","4.3582","28.4002"
"26.3200","6.5574","119.6682","6.5574","4.3716","28.4924"
"26.4000","6.5775","120.0571","6.5775","4.3850","28.5850"
"26.4800","6.5966","120.4293","6.5966","4.3977","28.6736"
"26.5600","6.6172","120.8305","6.6172","4.4114","28.7692"
"26.6400","6.6362","121.1921","6.6362","4.4242","28.8553"
"26.7200","6.6578","121.6277","6.6578","4.4386","28.9590"
"26.8000","6.6782","122.0194","6.6782","4.4521","29.0522"
"26.8800","6.6980","122.4146","6.6980","4.4654","29.1463"
"26.9600","6.7176","122.7862","6.7176","4.4784","29.2348"
"27.0400","6.7371","123.1548","6.7371","4.4914","29.3226"
"27.1200","6.7567","123.5409","6.7567","4.5045","29.4145"
"27.2000","6.7773","123.9398","6.7773","4.5182","29.5095"
"27.2800","6.7962","124.2978","6.7962","4.5308","29.5947"
"27.3600","6.8170","124.7133","6.8170","4.5447","29.6936"
"27.4400","6.8378","125.1233","6.8378","4.5586","29.7913"
"27.5200","6.8575","125.5089","6.8575","4.5717","29.8831"
"27.6000","6.8775","125.8920","6.8775","4.5850","29.9743"
"27.6800","6.8962","126.2412","6.8962","4.5975","30.0574"
"27.7600","6.9172","126.6592","6.9172","4.6115","30.1570"
"27.8400","6.9375","127.0458","6.9375","4.6250","30.2490"
"27.9200","6.9565","127.4085","6.9565","4.6377","30.3354"
"28.0000","6.9773","127.8307","6.9773","4.6515","30.4359"
"28.0800","6.9982","128.2263","6.9982","4.6655","30.5301"
"28.1600","7.0179","128.6193","7.0179","4.6786","30.6236"
"28.2400","7.0375","128.9839","7.0375","4.6917","30.7104"
"28.3200","7.0561","129.3330","7.0561","4.7041","30.7936"
"28.4000","7.0773","129.7457","7.0773","4.7182","30.8918"
"28.4800","7.0971","130.1306","7.0971","4.7314","30.9835"
"28.5600","7.1168","130.5031","7.1168","4.7446","31.0722"
"28.6400","7.1365","130.8969","7.1365","4.7577","31.1659"
"28.7200","7.1572","131.2828","7.1572","4.7715","31.2578"
"28.8000","7.1774","131.6702","7.1774","4.7849","31.3501"
"28.8800","7.1977","132.0604","7.1977","4.7985","31.4429"
"28.9600","7.2162","132.4073","7.2162","4.8108","31.5255"
"29.0400","7.2370","132.8153","7.2370","4.8247","31.6227"
"29.1200","7.2566","133.1819","7.2566","4.8378","31.7100"
"29.2000","7.2771","133.5878","7.2771","4.8514","31.8066"
"29.2800","7.2984","134.0008","7.2984","4.8656","31.9050"
"29.3600","7.3181","134.3764","7.3181","4.8788","31.9944"
"29.4400","7.3380","134.7433","7.3380","4.8920","32.0817"
"29.5200","7.3572","135.1049","7.3572","4.9048","32.1678"
"29.6000","7.3767","135.4779","7.3767","4.9178","32.2566"
"29.6800","7.3971","135.8627","7.3971","4.9314","32.3483"
"29.7600","7.4166","136.2197","7.4166","4.9444","32.4333"
"29.8400","7.4366","136.6004","7.4366","4.9577","32.5239"
"29.9200","7.4579","137.0185","7.4579","4.9720","32.6235"
"30.0000","7.4773","137.3943","7.4773","4.9849","32.7129"
"30.0800","7.4977","137.7731","7.4977","4.9985","32.8031"
"30.1600","7.5166","138.1253","7.5166","5.0111","32.8870"
"30.2400","7.5363","138.4843","7.5363","5.0242","32.9725"
"30.3200","7.5569","138.8901","7.5569","5.0379","33.0691"
"30.4000","7.5764","139.2441","7.5764","5.0510","33.1534"
"30.4800","7.5977","139.6604","7.5977","5.0651","33.2525"
"30.5600","7.6186","140.0740","7.6186","5.0791","33.3510"
"30.6400","7.6376","140.4269","7.6376","5.0917","33.4350"
"30.7200","7.6573","140.8013","7.6573","5.1049","33.5241"
"30.8000","7.6766","141.1542","7.6766","5.1178","33.6081"
"30.8800","7.6976","141.5575","7.6976","5.1317","33.7042"
"30.9600","7.7176","141.9303","7.7176","5.1451","33.7929"
"31.0400","7.7360","142.2623","7.7360","5.1574","33.8720"
"31.1200","7.7567","142.6665","7.7567","5.1711","33.9682"
"31.2000","7.7777","143.0772","7.7777","5.1851","34.0660"
"31.2800","7.7979","143.4500","7.7979","5.1986","34.1548"
"31.3600","7.8178","143.8210","7.8178","5.2119","34.2431"
"31.4400","7.8362","144.1482","7.8362","5.2242","34.3210"
"31.5200","7.8570","144.5477","7.8570","5.2380","34.4161"
"31.6000","7.8773","144.9347","7.8773","5.2516","34.5083"
"31.6800","7.8969","145.3027","7.8969","5.2646","34.5959"
"31.7600","7.9184","145.7192","7.9184","5.2789","34.6950"
"31.8400","7.9379","146.0841","7.9379","5.2920","34.7819"
"31.9200","7.9579","146.4524","7.9579","5.3053","34.8696"
"32.0000","7.9773","146.8106","7.9773","5.3182","34.9549"
"32.0800","7.9969","147.1783","7.9969","5.3313","35.0424"
"32.1600","8.0169","147.5420","8.0169","5.3446","35.1290"
"32.2400","8.0368","147.9068","8.0368","5.3579","35.2159"
"32.3200","8.0562","148.2711","8.0562","5.3708","35.3026"
"32.4000","8.0776","148.6889","8.0776","5.3851","35.4021"
"32.4800","8.0974","149.0542","8.0974","5.3983","35.4891"
"32.5600","8.1177","149.4139","8.1177","5.4118","35.5747"
"32.6400","8.1368","149.7671","8.1368","5.4245","35.6588"
"32.7200","8.1566","150.1378","8.1566","5.4377","35.7471"
"32.8000","8.1765","150.5158","8.1765","5.4510","35.8371"
"32.8800","8.1968","150.8894","8.1968","5.4645","35.9260"
"32.9600","8.2174","151.2722","8.2174","5.4783","36.0172"
"33.0400","8.2389","151.6823","8.2389","5.4926","36.1148"
"33.1200","8.2570","151.9990","8.2570","5.5047","36.1902"
"33.2000","8.2773","152.3785","8.2773","5.5182","36.2806"
"33.2800","8.2972","152.7434","8.2972","5.5315","36.3675"
"33.3600","8.3173","153.1254","8.3173","5.5449","36.4584"
"33.4400","8.3371","153.4921","8.3371","5.5581","36.5457"
"33.5200","8.3556","153.8167","8.3556","5.5704","36.6230"
"33.6000","8.3770","154.2280","8.3770","5.5847","36.7209"
"33.6800","8.3983","154.6323","8.3983","5.5989","36.8172"
"33.7600","8.4178","154.9817","8.4178","5.6118","36.9004"
"33.8400","8.4372","155.3476","8.4372","5.6248","36.9875"
"33.9200","8.4565","155.6859","8.4565","5.6377","37.0681"
"34.0000","8.4764","156.0542","8.4764","5.6509","37.1558"
"34.0800","8.4978","156.4642","8.4978","5.6652","37.2534"
"34.1600","8.5170","156.8099","8.5170","5.6780","37.3357"
"34.2400","8.5381","157.2002","8.5381","5.6921","37.4286"
"34.3200","8.5579","157.5616","8.5579","5.7052","37.5147"
"34.4000","8.5776","157.9240","8.5776","5.7184","37.6009"
"34.4800","8.5972","158.2759","8.5972","5.7314","37.6847"
"34.5600","8.6168","158.6180","8.6168","5.7445","37.7662"
"34.6400","8.6370","158.9857","8.6370","5.7580","37.8537"
"34.7200","8.6570","159.3399","8.6570","5.7713","37.9381"
"34.8000","8.6758","159.6865","8.6758","5.7839","38.0206"
"34.8800","8.6976","160.1093","8.6976","5.7984","38.1213"
"34.9600","8.7176","160.4657","8.7176","5.8118","38.2061"
"35.0400","8.7380","160.8436","8.7380","5.8253","38.2961"
"35.1200","8.7572","161.1734","8.7572","5.8382","38.3746"
"35.2000","8.7764","161.5136","8.7764","5.8509","38.4556"
"35.2800","8.7968","161.8820","8.7968","5.8645","38.5433"
"35.3600","8.8164","162.2353","8.8164","5.8776","38.6275"
"35.4400","8.8368","162.6073","8.8368","5.8912","38.7160"
"35.5200","8.8579","163.0056","8.8579","5.9053","38.8108"
"35.6000","8.8778","163.3475","8.8778","5.9186","38.8923"
"35.6800","8.8980","163.7085","8.8980","5.9320","38.9782"
"35.7600","8.9181","164.0709","8.9181","5.9454","39.0645"
"35.8400","8.9363","164.3907","8.9363","5.9575","39.1406"
"35.9200","8.9569","164.7613","8.9569","5.9712","39.2289"
"36.0000","8.9761","165.1041","8.9761","5.9840","39.3105"
"36.0800","8.9971","165.4934","8.9971","5.9981","39.4032"
"36.1600","9.0181","165.8720","9.0181","6.0120","39.4933"
"36.2400","9.0374","166.2076","9.0374","6.0249","39.5732"
"36.3200","9.0573","166.5679","9.0573","6.0382","39.6590"
"36.4000","9.0771","166.9125","9.0771","6.0514","39.7411"
"36.4800","9.0959","167.2506","9.0959","6.0640","39.8216"
"36.5600","9.1172","167.6499","9.1172","6.0781","39.9166"
"36.6400","9.1364","167.9773","9.1364","6.0909","39.9946"
"36.7200","9.1578","168.3642","9.1578","6.1052","40.0867"
"36.8000","9.1780","168.7263","9.1780","6.1187","40.1729"
"36.8800","9.1979","169.0822","9.1979","6.1319","40.2577"
"36.9600","9.2175","169.4229","9.2175","6.1450","40.3388"
"37.0400","9.2372","169.7802","9.2372","6.1582","40.4239"
"37.1200","9.2570","170.1262","9.2570","6.1713","40.5062"
"37.2000","9.2774","170.4975","9.2774","6.1850","40.5946"
"37.2800","9.2960","170.8152","9.2960","6.1973","40.6703"
"37.3600","9.3172","171.2057","9.3172","6.2115","40.7633"
"37.4400","9.3380","171.5750","9.3380","6.2253","40.8512"
"37.5200","9.3573","171.9115","9.3573","6.2382","40.9313"
"37.6000","9.3770","172.2623","9.3770","6.2513","41.0148"
"37.6800","9.3966","172.6028","9.3966","6.2644","41.0959"
"37.7600","9.4170","172.9570","9.4170","6.2780","41.1802"
"37.8400","9.4367","173.3021","9.4367","6.2911","41.2624"
"37.9200","9.4566","173.6675","9.4566","6.3044","41.3494"
"38.0000","9.4776","174.0586","9.4776","6.3184","41.4425"
"38.0800","9.4984","174.4158","9.4984","6.3323","41.5276"
"38.1600","9.5177","174.7434","9.5177","6.3451","41.6056"
"38.2400","9.5379","175.1073","9.5379","6.3586","41.6922"
"38.3200","9.5562","175.4091","9.5562","6.3708","41.7641"
"38.4000","9.5773","175.7948","9.5773","6.3849","41.8559"
"38.4800","9.5970","176.1346","9.5970","6.3980","41.9368"
"38.5600","9.6168","176.4850","9.6168","6.4112","42.0203"
"38.6400","9.6369","176.8506","9.6369","6.4246","42.1073"
"38.7200","9.6573","177.2047","9.6573","6.4382","42.1916"
"38.8000","9.6774","177.5575","9.6774","6.4516","42.2756"
"38.8800","9.6979","177.9147","9.6979","6.4653","42.3606"
"38.9600","9.7165","178.2238","9.7165","6.4777","42.4342"
"39.0400","9.7371","178.5856","9.7371","6.4914","42.5204"
"39.1200","9.7564","178.9204","9.7564","6.5043","42.6001"
"39.2000","9.7773","179.3039","9.7773","6.5182","42.6914"
"39.2800","9.7982","179.6697","9.7982","6.5322","42.7785"
"39.3600","9.8179","180.0126","9.8179","6.5453","42.8601"
"39.4400","9.8378","180.3518","9.8378","6.5585","42.9409"
"39.5200","9.8575","180.6854","9.8575","6.5717","43.0203"
"39.6000","9.8767","181.0160","9.8767","6.5845","43.0990"
"39.6800","9.8971","181.3778","9.8971","6.5980","43.1852"
"39.7600","9.9166","181.7028","9.9166","6.6111","43.2626"
"39.8400","9.9364","182.0514","9.9364","6.6243","43.3456"
"39.9200","9.9582","182.4364","9.9582","6.6388","43.4372"
"40.0000","9.9770","182.7655","9.9770","6.6514","43.5156"
"40.0800","9.9977","183.1196","9.9977","6.6651","43.5999"
"40.1600","10.0168","183.4506","10.0168","6.6778","43.6787"
"40.2400","10.0364","183.7780","10.0364","6.6909","43.7567"
"40.3200","10.0563","184.1265","10.0563","6.7042","43.8396"
"40.4000","10.0768","184.4816","10.0768","6.7179","43.9242"
"40.4800","10.0977","184.8467","10.0977","6.7318","44.0111"
"40.5600","10.1189","185.2234","10.1189","6.7459","44.1008"
"40.6400","10.1374","185.5213","10.1374","6.7583","44.1717"
"40.7200","10.1572","185.8548","10.1572","6.7714","44.2511"
"40.8000","10.1766","186.1890","10.1766","6.7844","44.3307"
"40.8800","10.1977","186.5578","10.1977","6.7985","44.4185"
"40.9600","10.2174","186.8840","10.2174","6.8116","44.4962"
"41.0400","10.2363","187.2006","10.2363","6.8242","44.5716"
"41.1200","10.2566","187.5480","10.2566","6.8377","44.6543"
"41.2000","10.2775","187.9256","10.2775","6.8517","44.7442"
"41.2800","10.2977","188.2579","10.2977","6.8651","44.8233"
"41.3600","10.3178","188.5955","10.3178","6.8785","44.9037"
"41.4400","10.3364","188.8887","10.3364","6.8909","44.9735"
"41.5200","10.3568","189.2355","10.3568","6.9045","45.0561"
"41.6000","10.3772","189.5866","10.3772","6.9181","45.1397"
"41.6800","10.3968","189.9259","10.3968","6.9312","45.2205"
"41.7600","10.4181","190.2959","10.4181","6.9454","45.3085"
"41.8400","10.4376","190.6091","10.4376","6.9584","45.3831"
"41.9200","10.4578","190.9430","10.4578","6.9718","45.4626"
"42.0000","10.4775","191.2731","10.4775","6.9850","45.5412"
"42.0800","10.4971","191.6083","10.4971","6.9981","45.6210"
"42.1600","10.5169","191.9209","10.5169","7.0113","45.6955"
"42.2400","10.5364","192.2482","10.5364","7.0243","45.7734"
"42.3200","10.5563","192.5740","10.5563","7.0376","45.8509"
"42.4000","10.5781","192.9634","10.5781","7.0521","45.9437"
"42.4800","10.5973","193.2610","10.5973","7.0649","46.0145"
"42.5600","10.6175","193.5930","10.6175","7.0784","46.0936"
"42.6400","10.6368","193.8945","10.6368","7.0912","46.1654"
"42.7200","10.6566","194.2199","10.6566","7.1044","46.2428"
"42.8000","10.6766","194.5507","10.6766","7.1177","46.3216"
"42.8800","10.6971","194.8869","10.6971","7.1314","46.4016"
"42.9600","10.7177","195.2311","10.7177","7.1451","46.4836"
"43.0400","10.7387","195.5780","10.7387","7.1592","46.5662"
"43.1200","10.7572","195.8602","10.7572","7.1715","46.6334"
"43.2000","10.7772","196.1823","10.7772","7.1848","46.7101"
"43.2800","10.7975","196.5144","10.7975","7.1983","46.7891"
"43.3600","10.8172","196.8342","10.8172","7.2115","46.8653"
"43.4400","10.8370","197.1478","10.8370","7.2246","46.9400"
"43.5200","10.8558","197.4465","10.8558","7.2372","47.0111"
"43.6000","10.8770","197.7947","10.8770","7.2513","47.0940"
"43.6800","10.8981","198.1433","10.8981","7.2654","47.1770"
"43.7600","10.9177","198.4484","10.9177","7.2784","47.2496"
"43.8400","10.9371","198.7709","10.9371","7.2914","47.3264"
"43.9200","10.9568","199.0770","10.9568","7.3045","47.3993"
"44.0000","10.9767","199.3955","10.9767","7.3178","47.4751"
"44.0800","10.9975","199.7384","10.9975","7.3317","47.5568"
"44.1600","11.0164","200.0184","11.0164","7.3443","47.6234"
"44.2400","11.0379","200.3835","11.0379","7.3586","47.7103"
"44.3200","11.0576","200.6858","11.0576","7.3717","47.7823"
"44.4000","11.0780","201.0085","11.0780","7.3853","47.8592"
"44.4800","11.0971","201.3123","11.0971","7.3981","47.9315"
"44.5600","11.1173","201.6198","11.1173","7.4116","48.0047"
"44.6400","11.1370","201.9337","11.1370","7.4246","48.0795"
"44.7200","11.1571","202.2489","11.1571","7.4381","48.1545"
"44.8000","11.1758","202.5518","11.1758","7.4505","48.2266"
"44.8800","11.1975","202.9221","11.1975","7.4650","48.3148"
"44.9600","11.2177","203.2180","11.2177","7.4785","48.3852"
"45.0400","11.2380","203.5381","11.2380","7.4920","48.4615"
"45.1200","11.2571","203.8214","11.2571","7.5047","48.5289"
"45.2000","11.2763","204.1047","11.2763","7.5175","48.5964"
"45.2800","11.2970","204.4362","11.2970","7.5313","48.6753"
"45.3600","11.3175","204.7654","11.3175","7.5450","48.7537"
"45.4400","11.3371","205.0639","11.3371","7.5581","48.8247"
"45.5200","11.3574","205.3919","11.3574","7.5716","48.9028"
"45.6000","11.3775","205.6994","11.3775","7.5850","48.9760"
"45.6800","11.3982","206.0170","11.3982","7.5988","49.0517"
"45.7600","11.4180","206.3071","11.4180","7.6120","49.1207"
"45.8400","11.4366","206.5894","11.4366","7.6244","49.1879"
"45.9200","11.4567","206.8927","11.4567","7.6378","49.2602"
"46.0000","11.4758","207.1794","11.4758","7.6506","49.3284"
"46.0800","11.4971","207.5116","11.4971","7.6648","49.4075"
"46.1600","11.5180","207.8503","11.5180","7.6787","49.4882"
"46.2400","11.5375","208.1320","11.5375","7.6917","49.5552"
"46.3200","11.5568","208.4209","11.5568","7.7046","49.6240"
"46.4000","11.5773","208.7272","11.5773","7.7182","49.6970"
"46.4800","11.5964","209.0169","11.5964","7.7309","49.7659"
"46.5600","11.6172","209.3352","11.6172","7.7448","49.8417"
"46.6400","11.6361","209.6049","11.6361","7.7574","49.9059"
"46.7200","11.6577","209.9444","11.6577","7.7718","49.9868"
"46.8000","11.6781","210.2604","11.6781","7.7854","50.0620"
"46.8800","11.6981","210.5695","11.6981","7.7987","50.1356"
"46.9600","11.7174","210.8465","11.7174","7.8116","50.2015"
"47.0400","11.7371","211.1363","11.7371","7.8247","50.2705"
"47.1200","11.7567","211.4173","11.7567","7.8378","50.3374"
"47.2000","11.7772","211.7311","11.7772","7.8514","50.4122"
"47.2800","11.7963","212.0004","11.7963","7.8642","50.4763"
"47.3600","11.8174","212.3327","11.8174","7.8783","50.5554"
"47.4400","11.8376","212.6389","11.8376","7.8918","50.6283"
"47.5200","11.8571","212.9213","11.8571","7.9048","50.6955"
"47.6000","11.8774","213.2303","11.8774","7.9182","50.7691"
"47.6800","11.8964","213.4926","11.8964","7.9310","50.8316"
"47.7600","11.9174","213.8218","11.9174","7.9449","50.9100"
"47.8400","11.9373","214.1014","11.9373","7.9582","50.9765"
"47.9200","11.9565","214.3876","11.9565","7.9710","51.0447"
"48.0000","11.9776","214.7072","11.9776","7.9851","51.1208"
"48.0800","11.9983","215.0208","11.9983","7.9989","51.1954"
"48.1600","12.0180","215.3003","12.0180","8.0120","51.2620"
"48.2400","12.0377","215.5799","12.0377","8.0251","51.3286"
"48.3200","12.0563","215.8333","12.0563","8.0375","51.3889"
"48.4000","12.0772","216.1489","12.0772","8.0515","51.4640"
"48.4800","12.0969","216.4290","12.0969","8.0646","51.5307"
"48.5600","12.1170","216.7352","12.1170","8.0780","51.6036"
"48.6400","12.1373","217.0300","12.1373","8.0915","51.6738"
"48.7200","12.1574","217.3073","12.1574","8.1049","51.7398"
"48.8000","12.1773","217.5902","12.1773","8.1182","51.8072"
"48.8800","12.1979","217.8923","12.1979","8.1319","51.8791"
"48.9600","12.2164","218.1393","12.2164","8.1443","51.9379"
"49.0400","12.2369","218.4431","12.2369","8.1579","52.0103"
"49.1200","12.2564","218.7068","12.2564","8.1709","52.0730"
"49.2000","12.2774","219.0314","12.2774","8.1849","52.1503"
"49.2800","12.2985","219.3364","12.2985","8.1990","52.2229"
"49.3600","12.3178","219.5940","12.3178","8.2118","52.2843"
"49.4400","12.3376","219.8684","12.3376","8.2251","52.3496"
"49.5200","12.3575","220.1489","12.3575","8.2383","52.4164"
"49.6000","12.3766","220.4039","12.3766","8.2511","52.4771"
"49.6800","12.3971","220.6996","12.3971","8.2647","52.5475"
"49.7600","12.4164","220.9572","12.4164","8.2776","52.6089"
"49.8400","12.4366","221.2398","12.4366","8.2910","52.6761"
"49.9200","12.4579","221.5597","12.4579","8.3053","52.7523"
"50.0000","12.4771","221.8157","12.4771","8.3181","52.8133"
"50.0800","12.4977","222.1024","12.4977","8.3318","52.8815"
"50.1600","12.5167","222.3596","12.5167","8.3445","52.9428"
"50.2400","12.5371","222.6419","12.5371","8.3581","53.0100"
"50.3200","12.5568","222.9088","12.5568","8.3712","53.0735"
"50.4000","12.5766","223.1900","12.5766","8.3844","53.1405"
"50.4800","12.5978","223.4977","12.5978","8.3985","53.2137"
"50.5600","12.6185","223.7777","12.6185","8.4123","53.2804"
"50.6400","12.6371","224.0164","12.6371","8.4247","53.3372"
"50.7200","12.6577","224.2940","12.6577","8.4385","53.4033"
"50.8000","12.6764","224.5387","12.6764","8.4509","53.4616"
"50.8800","12.6974","224.8288","12.6974","8.4650","53.5307"
"50.9600","12.7174","225.0916","12.7174","8.4782","53.5932"
"51.0400","12.7364","225.3421","12.7364","8.4909","53.6529"
"51.1200","12.7570","225.6319","12.7570","8.5047","53.7219"
"51.2000","12.7779","225.9204","12.7779","8.5186","53.7906"
"51.2800","12.7977","226.1876","12.7977","8.5318","53.8542"
"51.3600","12.8177","226.4454","12.8177","8.5451","53.9156"
"51.4400","12.8365","226.6817","12.8365","8.5577","53.9718"
"51.5200","12.8567","226.9577","12.8567","8.5711","54.0375"
"51.6000","12.8770","227.2148","12.8770","8.5847","54.0988"
"51.6800","12.8968","227.4842","12.8968","8.5979","54.1629"
"51.7600","12.9180","227.7832","12.9180","8.6120","54.2341"
"51.8400","12.9377","228.0261","12.9377","8.6251","54.2919"
"51.9200","12.9581","228.2992","12.9581","8.6387","54.3570"
"52.0000","12.9776","228.5331","12.9776","8.6517","54.4126"
"52.0800","12.9968","228.7403","12.9968","8.6646","54.4620"
"52.1600","13.0168","229.0043","13.0168","8.6779","54.5248"
"52.2400","13.0368","229.2471","13.0368","8.6912","54.5826"
"52.3200","13.0563","229.4935","13.0563","8.7042","54.6413"
"52.4000","13.0779","229.7987","13.0779","8.7186","54.7140"
"52.4800","13.0974","230.0223","13.0974","8.7316","54.7672"
"52.5600","13.1180","230.2952","13.1180","8.7454","54.8322"
"52.6400","13.1372","230.5193","13.1372","8.7581","54.8856"
"52.7200","13.1563","230.7611","13.1563","8.7709","54.9431"
"52.8000","13.1763","231.0219","13.1763","8.7842","55.0052"
"52.8800","13.1969","231.2787","13.1969","8.7979","55.0664"
"52.9600","13.2177","231.5507","13.2177","8.8118","55.1311"
"53.0400","13.2386","231.8096","13.2386","8.8257","55.1928"
"53.1200","13.2572","232.0223","13.2572","8.8381","55.2434"
"53.2000","13.2772","232.2609","13.2772","8.8515","55.3002"
"53.2800","13.2973","232.4884","13.2973","8.8649","55.3544"
"53.3600","13.3173","232.7350","13.3173","8.8782","55.4131"
"53.4400","13.3371","232.9575","13.3371","8.8914","55.4661"
"53.5200","13.3558","233.1514","13.3558","8.9038","55.5122"
"53.6000","13.3773","233.4233","13.3773","8.9182","55.5770"
"53.6800","13.3981","233.6682","13.3981","8.9321","55.6353"
"53.7600","13.4175","233.8896","13.4175","8.9450","55.6880"
"53.8400","13.4371","234.1119","13.4371","8.9580","55.7409"
"53.9200","13.4566","234.3172","13.4566","8.9710","55.7898"
"54.0000","13.4767","234.5542","13.4767","8.9845","55.8462"
"54.0800","13.4979","234.8108","13.4979","8.9986","55.9073"
"54.1600","13.5167","235.0105","13.5167","9.0111","55.9549"
"54.2400","13.5378","235.2366","13.5378","9.0252","56.0087"
"54.3200","13.5577","235.4441","13.5577","9.0385","56.0581"
"54.4000","13.5779","235.5618","13.5779","9.0519","56.0861"
"54.4800","13.5976","235.6927","13.5976","9.0651","56.1173"
"54.5600","13.6171","235.8422","13.6171","9.0781","56.1529"
"54.6400","13.6373","236.0419","13.6373","9.0916","56.2004"
"54.7200","13.6571","236.2432","13.6571","9.1048","56.2484"
"54.8000","13.6759","236.4226","13.6759","9.1173","56.2911"
"54.8800","13.6972","236.6697","13.6972","9.1315","56.3499"
"54.9600","13.7174","236.8687","13.7174","9.1450","56.3973"
"55.0400","13.7377","237.0855","13.7377","9.1585","56.4489"
"55.1200","13.7574","237.2895","13.7574","9.1716","56.4975"
"55.2000","13.7763","237.4759","13.7763","9.1842","56.5419"
"55.2800","13.7973","237.7123","13.7973","9.1982","56.5982"
"55.3600","13.8171","237.9193","13.8171","9.2114","56.6475"
"55.4400","13.8368","238.1267","13.8368","9.2245","56.6968"
"55.5200","13.8578","238.3708","13.8578","9.2385","56.7550"
"55.6000","13.8777","238.5581","13.8777","9.2518","56.7995"
"55.6800","13.8979","238.7666","13.8979","9.2653","56.8492"
"55.7600","13.9178","238.9736","13.9178","9.2785","56.8985"
"55.8400","13.9364","239.1486","13.9364","9.2909","56.9401"
"55.9200","13.9565","239.3652","13.9565","9.3043","56.9917"
"56.0000","13.9762","239.5523","13.9762","9.3174","57.0363"
"56.0800","13.9972","239.7974","13.9972","9.3315","57.0946"
"56.1600","14.0181","240.0240","14.0181","9.3454","57.1486"
"56.2400","14.0375","240.2090","14.0375","9.3583","57.1926"
"56.3200","14.0573","240.3918","14.0573","9.3715","57.2361"
"56.4000","14.0772","240.5994","14.0772","9.3848","57.2856"
"56.4800","14.0965","240.7829","14.0965","9.3977","57.3293"
"56.5600","14.1171","241.0023","14.1171","9.4114","57.3815"
"56.6400","14.1360","241.1688","14.1360","9.4240","57.4211"
"56.7200","14.1575","241.4062","14.1575","9.4383","57.4777"
"56.8000","14.1782","241.6217","14.1782","9.4522","57.5290"
"56.8800","14.1979","241.8255","14.1979","9.4653","57.5775"
"56.9600","14.2177","242.0019","14.2177","9.4784","57.6195"
"57.0400","14.2370","242.1800","14.2370","9.4913","57.6619"
"57.1200","14.2567","242.3722","14.2567","9.5045","57.7077"
"57.2000","14.2769","242.5666","14.2769","9.5179","57.7539"
"57.2800","14.2961","242.7550","14.2961","9.5307","57.7988"
"57.3600","14.3173","242.9823","14.3173","9.5449","57.8529"
"57.4400","14.3379","243.1832","14.3379","9.5586","57.9007"
"57.5200","14.3572","243.3549","14.3572","9.5715","57.9417"
"57.6000","14.3770","243.5461","14.3770","9.5847","57.9872"
"57.6800","14.3965","243.7257","14.3965","9.5977","58.0299"
"57.7600","14.4178","243.9458","14.4178","9.6119","58.0823"
"57.8400","14.4372","244.1073","14.4372","9.6248","58.1208"
"57.9200","14.4562","244.2775","14.4562","9.6375","58.1613"
"58.0000","14.4773","244.5048","14.4773","9.6516","58.2154"
"58.0800","14.4982","244.7126","14.4982","9.6655","58.2649"
"58.1600","14.5180","244.8835","14.5180","9.6787","58.3056"
"58.2400","14.5375","245.0418","14.5375","9.6916","58.3433"
"58.3200","14.5559","245.1858","14.5559","9.7039","58.3776"
"58.4000","14.5769","245.3975","14.5769","9.7180","58.4280"
"58.4800","14.5971","245.5824","14.5971","9.7314","58.4720"
"58.5600","14.6168","245.7554","14.6168","9.7446","58.5132"
"58.6400","14.6374","245.9530","14.6374","9.7583","58.5602"
"58.7200","14.6574","246.1209","14.6574","9.7716","58.6002"
"58.8000","14.6775","246.2904","14.6775","9.7850","58.6406"
"58.8800","14.6978","246.4776","14.6978","9.7985","58.6851"
"58.9600","14.7166","246.6333","14.7166","9.8111","58.7222"
"59.0400","14.7369","246.8154","14.7369","9.8246","58.7656"
"59.1200","14.7564","246.9805","14.7564","9.8376","58.8049"
"59.2000","14.7773","247.1779","14.7773","9.8515","58.8519"
"59.2800","14.7986","247.3698","14.7986","9.8657","58.8976"
"59.3600","14.8178","247.5148","14.8178","9.8785","58.9321"
"59.4400","14.8378","247.6890","14.8378","9.8919","58.9736"
"59.5200","14.8574","247.8389","14.8574","9.9049","59.0093"
"59.6000","14.8765","248.0033","14.8765","9.9176","59.0484"
"59.6800","14.8971","248.1772","14.8971","9.9314","59.0898"
"59.7600","14.9163","248.3204","14.9163","9.9442","59.1239"
"59.8400","14.9367","248.4889","14.9367","9.9578","59.1640"
"59.9200","14.9578","248.6694","14.9578","9.9719","59.2070"
"60.0000","14.9771","248.8125","14.9771","9.9847","59.2411"
"60.0800","14.9976","248.9855","14.9976","9.9984","59.2823"
"60.0900","15.0000","249.0110","15.0000","10.0000","59.2883"