File: data/instron_tests/metamaterials/250421/250421_2224_BULK_m2.is_comp_Exports/250421_2224_BULK_m2_2_1.csv
Results Table 1
,Compresson Axis,H*,V*,Height,Thickness,Width,Area,Fixture separation,Specimen label
,,,,(mm),(mm),(mm),(mm^2),(mm),
"2","Y","","","150.00","28.00","150.00","4200.00","150.00","2224_BULK_m2"

Results Table 2
,Modulus (Segment 0 % - 2.5 %),Compresson Axis
,(kPa),
"2","757.34","Y"

Time,Displacement,Force,Compressive displacement,Compressive strain (Displacement),Compressive stress
(s),(mm),(N),(mm),(%),(kPa)
"0.0000","0.0000","-5.0193","0.0000","0.0000","-1.1951"
"0.0800","0.0012","-4.9714","0.0012","0.0008","-1.1837"
"0.1600","0.0176","-4.4666","0.0176","0.0117","-1.0635"
"0.2400","0.0376","-3.9013","0.0376","0.0250","-0.9289"
"0.3200","0.0579","-3.3212","0.0579","0.0386","-0.7908"
"0.4000","0.0770","-2.8036","0.0770","0.0514","-0.6675"
"0.4800","0.0981","-2.2397","0.0981","0.0654","-0.5333"
"0.5600","0.1181","-1.7198","0.1181","0.0787","-0.4095"
"0.6400","0.1377","-1.2147","0.1377","0.0918","-0.2892"
"0.7200","0.1572","-0.7202","0.1572","0.1048","-0.1715"
"0.8000","0.1769","-0.2350","0.1769","0.1180","-0.0560"
"0.8800","0.1975","0.2820","0.1975","0.1317","0.0672"
"0.9600","0.2177","0.7756","0.2177","0.1451","0.1847"
"1.0400","0.2361","1.2331","0.2361","0.1574","0.2936"
"1.1200","0.2571","1.7502","0.2571","0.1714","0.4167"
"1.2000","0.2776","2.2481","0.2776","0.1851","0.5353"
"1.2800","0.2980","2.7355","0.2980","0.1987","0.6513"
"1.3600","0.3179","3.2101","0.3179","0.2119","0.7643"
"1.4400","0.3364","3.6284","0.3364","0.2243","0.8639"
"1.5200","0.3565","4.1023","0.3565","0.2377","0.9767"
"1.6000","0.3771","4.5728","0.3771","0.2514","1.0888"
"1.6800","0.3969","5.0573","0.3969","0.2646","1.2041"
"1.7600","0.4181","5.5389","0.4181","0.2787","1.3188"
"1.8400","0.4376","5.9742","0.4376","0.2917","1.4224"
"1.9200","0.4579","6.4426","0.4579","0.3052","1.5340"
"2.0000","0.4774","6.8895","0.4774","0.3182","1.6404"
"2.0800","0.4964","7.3060","0.4964","0.3309","1.7395"
"2.1600","0.5173","7.7924","0.5173","0.3448","1.8553"
"2.2400","0.5370","8.2378","0.5370","0.3580","1.9614"
"2.3200","0.5568","8.6844","0.5568","0.3712","2.0677"
"2.4000","0.5779","9.1714","0.5779","0.3853","2.1837"
"2.4800","0.5976","9.6087","0.5976","0.3984","2.2878"
"2.5600","0.6183","10.0741","0.6183","0.4122","2.3986"
"2.6400","0.6372","10.4943","0.6372","0.4248","2.4986"
"2.7200","0.6561","10.9239","0.6561","0.4374","2.6009"
"2.8000","0.6769","11.3968","0.6769","0.4512","2.7135"
"2.8800","0.6972","11.8521","0.6972","0.4648","2.8219"
"2.9600","0.7176","12.3010","0.7176","0.4784","2.9288"
"3.0400","0.7383","12.7717","0.7383","0.4922","3.0409"
"3.1200","0.7570","13.1801","0.7570","0.5047","3.1381"
"3.2000","0.7777","13.6464","0.7777","0.5185","3.2491"
"3.2800","0.7973","14.0814","0.7973","0.5316","3.3527"
"3.3600","0.8173","14.5280","0.8173","0.5449","3.4590"
"3.4400","0.8371","14.9728","0.8371","0.5581","3.5650"
"3.5200","0.8560","15.3838","0.8560","0.5707","3.6628"
"3.6000","0.8772","15.8447","0.8772","0.5848","3.7726"
"3.6800","0.8984","16.3302","0.8984","0.5990","3.8881"
"3.7600","0.9176","16.7438","0.9176","0.6118","3.9866"
"3.8400","0.9375","17.1830","0.9375","0.6250","4.0912"
"3.9200","0.9565","17.5789","0.9565","0.6377","4.1854"
"4.0000","0.9762","18.0116","0.9762","0.6508","4.2885"
"4.0800","0.9975","18.4846","0.9975","0.6650","4.4011"
"4.1600","1.0167","18.8968","1.0167","0.6778","4.4992"
"4.2400","1.0378","19.3664","1.0378","0.6919","4.6110"
"4.3200","1.0582","19.8089","1.0582","0.7055","4.7164"
"4.4000","1.0776","20.2180","1.0776","0.7184","4.8138"
"4.4800","1.0974","20.6441","1.0974","0.7316","4.9153"
"4.5600","1.1163","21.0398","1.1163","0.7442","5.0095"
"4.6400","1.1373","21.4948","1.1373","0.7582","5.1178"
"4.7200","1.1576","21.9380","1.1576","0.7717","5.2233"
"4.8000","1.1764","22.3301","1.1764","0.7843","5.3167"
"4.8800","1.1973","22.7965","1.1973","0.7982","5.4277"
"4.9600","1.2178","23.2438","1.2178","0.8118","5.5342"
"5.0400","1.2381","23.6647","1.2381","0.8254","5.6344"
"5.1200","1.2575","24.0891","1.2575","0.8383","5.7355"
"5.2000","1.2762","24.4917","1.2762","0.8508","5.8314"
"5.2800","1.2972","24.9433","1.2972","0.8648","5.9389"
"5.3600","1.3174","25.3882","1.3174","0.8782","6.0448"
"5.4400","1.3372","25.8182","1.3372","0.8914","6.1472"
"5.5200","1.3581","26.2821","1.3581","0.9054","6.2576"
"5.6000","1.3778","26.7009","1.3778","0.9185","6.3574"
"5.6800","1.3981","27.1396","1.3981","0.9320","6.4618"
"5.7600","1.4180","27.5556","1.4180","0.9453","6.5609"
"5.8400","1.4366","27.9610","1.4366","0.9577","6.6574"
"5.9200","1.4572","28.4063","1.4572","0.9715","6.7634"
"6.0000","1.4765","28.8183","1.4765","0.9843","6.8615"
"6.0800","1.4975","29.2745","1.4975","0.9983","6.9701"
"6.1600","1.5182","29.7361","1.5182","1.0121","7.0800"
"6.2400","1.5374","30.1500","1.5374","1.0250","7.1786"
"6.3200","1.5572","30.5667","1.5572","1.0381","7.2778"
"6.4000","1.5771","30.9998","1.5771","1.0514","7.3809"
"6.4800","1.5962","31.4115","1.5962","1.0641","7.4789"
"6.5600","1.6173","31.8645","1.6173","1.0782","7.5868"
"6.6400","1.6362","32.2606","1.6362","1.0908","7.6811"
"6.7200","1.6576","32.7264","1.6576","1.1051","7.7920"
"6.8000","1.6780","33.1684","1.6780","1.1187","7.8972"
"6.8800","1.6977","33.5819","1.6977","1.1318","7.9957"
"6.9600","1.7175","34.0053","1.7175","1.1450","8.0965"
"7.0400","1.7374","34.4321","1.7374","1.1583","8.1981"
"7.1200","1.7570","34.8484","1.7570","1.1713","8.2972"
"7.2000","1.7774","35.2933","1.7774","1.1849","8.4032"
"7.2800","1.7963","35.6917","1.7963","1.1975","8.4980"
"7.3600","1.8176","36.1509","1.8176","1.2117","8.6074"
"7.4400","1.8377","36.5823","1.8377","1.2251","8.7101"
"7.5200","1.8573","36.9997","1.8573","1.2382","8.8095"
"7.6000","1.8775","37.4389","1.8775","1.2517","8.9140"
"7.6800","1.8968","37.8343","1.8968","1.2646","9.0082"
"7.7600","1.9176","38.2826","1.9176","1.2784","9.1149"
"7.8400","1.9373","38.7002","1.9373","1.2915","9.2143"
"7.9200","1.9562","39.1037","1.9562","1.3041","9.3104"
"8.0000","1.9773","39.5484","1.9773","1.3182","9.4163"
"8.0800","1.9984","39.9614","1.9984","1.3323","9.5146"
"8.1600","2.0182","40.3484","2.0182","1.3455","9.6068"
"8.2400","2.0378","40.7498","2.0378","1.3585","9.7023"
"8.3200","2.0562","41.1182","2.0562","1.3708","9.7900"
"8.4000","2.0776","41.5650","2.0776","1.3851","9.8964"
"8.4800","2.0970","41.9601","2.0970","1.3980","9.9905"
"8.5600","2.1170","42.3803","2.1170","1.4113","10.0906"
"8.6400","2.1375","42.8307","2.1375","1.4250","10.1978"
"8.7200","2.1575","43.2334","2.1575","1.4384","10.2937"
"8.8000","2.1776","43.6455","2.1776","1.4517","10.3918"
"8.8800","2.1979","44.0714","2.1979","1.4653","10.4932"
"8.9600","2.2165","44.4436","2.2165","1.4777","10.5818"
"9.0400","2.2370","44.8686","2.2370","1.4914","10.6830"
"9.1200","2.2565","45.2609","2.2565","1.5044","10.7764"
"9.2000","2.2771","45.7060","2.2771","1.5181","10.8824"
"9.2800","2.2988","46.1571","2.2988","1.5325","10.9898"
"9.3600","2.3182","46.5496","2.3182","1.5454","11.0832"
"9.4400","2.3374","46.9304","2.3374","1.5582","11.1739"
"9.5200","2.3570","47.3362","2.3570","1.5713","11.2705"
"9.6000","2.3768","47.7510","2.3768","1.5846","11.3693"
"9.6800","2.3973","48.1645","2.3973","1.5982","11.4677"
"9.7600","2.4165","48.5485","2.4165","1.6110","11.5592"
"9.8400","2.4370","48.9796","2.4370","1.6247","11.6618"
"9.9200","2.4579","49.4166","2.4579","1.6386","11.7659"
"10.0000","2.4772","49.8152","2.4772","1.6515","11.8608"
"10.0800","2.4980","50.2432","2.4980","1.6653","11.9627"
"10.1600","2.5173","50.6671","2.5173","1.6782","12.0636"
"10.2400","2.5369","51.0646","2.5369","1.6913","12.1582"
"10.3200","2.5571","51.4831","2.5571","1.7047","12.2579"
"10.4000","2.5767","51.8777","2.5767","1.7178","12.3518"
"10.4800","2.5978","52.3221","2.5978","1.7319","12.4576"
"10.5600","2.6189","52.7620","2.6189","1.7459","12.5624"
"10.6400","2.6375","53.1339","2.6375","1.7583","12.6509"
"10.7200","2.6573","53.5465","2.6573","1.7716","12.7492"
"10.8000","2.6767","53.9338","2.6767","1.7844","12.8414"
"10.8800","2.6977","54.3711","2.6977","1.7984","12.9455"
"10.9600","2.7177","54.7701","2.7177","1.8118","13.0405"
"11.0400","2.7362","55.1389","2.7362","1.8241","13.1283"
"11.1200","2.7569","55.5781","2.7569","1.8379","13.2329"
"11.2000","2.7776","56.0000","2.7776","1.8518","13.3333"
"11.2800","2.7976","56.3973","2.7976","1.8650","13.4279"
"11.3600","2.8177","56.8158","2.8177","1.8785","13.5276"
"11.4400","2.8363","57.1932","2.8363","1.8909","13.6174"
"11.5200","2.8569","57.6184","2.8569","1.9046","13.7187"
"11.6000","2.8772","58.0333","2.8772","1.9182","13.8175"
"11.6800","2.8968","58.4299","2.8968","1.9312","13.9119"
"11.7600","2.9183","58.8784","2.9183","1.9455","14.0187"
"11.8400","2.9378","59.2668","2.9378","1.9585","14.1111"
"11.9200","2.9580","59.6717","2.9580","1.9720","14.2076"
"12.0000","2.9773","60.0504","2.9773","1.9848","14.2977"
"12.0800","2.9969","60.4521","2.9969","1.9979","14.3934"
"12.1600","3.0172","60.8774","3.0172","2.0115","14.4946"
"12.2400","3.0370","61.2607","3.0370","2.0247","14.5859"
"12.3200","3.0563","61.6509","3.0563","2.0375","14.6788"
"12.4000","3.0777","62.1101","3.0777","2.0518","14.7881"
"12.4800","3.0971","62.4846","3.0971","2.0647","14.8773"
"12.5600","3.1183","62.9285","3.1183","2.0789","14.9830"
"12.6400","3.1375","63.3014","3.1375","2.0916","15.0718"
"12.7200","3.1566","63.6893","3.1566","2.1044","15.1641"
"12.8000","3.1767","64.0953","3.1767","2.1178","15.2608"
"12.8800","3.1970","64.5018","3.1970","2.1314","15.3576"
"12.9600","3.2175","64.9195","3.2175","2.1450","15.4570"
"13.0400","3.2383","65.3438","3.2383","2.1589","15.5580"
"13.1200","3.2576","65.7479","3.2576","2.1717","15.6543"
"13.2000","3.2777","66.1488","3.2777","2.1851","15.7497"
"13.2800","3.2973","66.5354","3.2973","2.1982","15.8418"
"13.3600","3.3170","66.9317","3.3170","2.2113","15.9361"
"13.4400","3.3373","67.3327","3.3373","2.2248","16.0316"
"13.5200","3.3562","67.6938","3.3562","2.2375","16.1176"
"13.6000","3.3773","68.1304","3.3773","2.2515","16.2215"
"13.6800","3.3981","68.5550","3.3981","2.2654","16.3226"
"13.7600","3.4178","68.9527","3.4178","2.2785","16.4173"
"13.8400","3.4374","69.3490","3.4374","2.2916","16.5117"
"13.9200","3.4566","69.7252","3.4566","2.3044","16.6012"
"14.0000","3.4768","70.1398","3.4768","2.3178","16.7000"
"14.0800","3.4976","70.5634","3.4976","2.3318","16.8008"
"14.1600","3.5165","70.9269","3.5165","2.3443","16.8874"
"14.2400","3.5379","71.3799","3.5379","2.3586","16.9952"
"14.3200","3.5578","71.7758","3.5578","2.3719","17.0895"
"14.4000","3.5780","72.1807","3.5780","2.3853","17.1859"
"14.4800","3.5974","72.5748","3.5974","2.3983","17.2797"
"14.5600","3.6168","72.9491","3.6168","2.4112","17.3688"
"14.6400","3.6371","73.3630","3.6371","2.4247","17.4674"
"14.7200","3.6570","73.7566","3.6570","2.4380","17.5611"
"14.8000","3.6760","74.1233","3.6760","2.4507","17.6484"
"14.8800","3.6972","74.5523","3.6972","2.4648","17.7506"
"14.9600","3.7176","74.9506","3.7176","2.4784","17.8454"
"15.0400","3.7382","75.3648","3.7382","2.4921","17.9440"
"15.1200","3.7575","75.7434","3.7575","2.5050","18.0341"
"15.2000","3.7760","76.1116","3.7760","2.5174","18.1218"
"15.2800","3.7971","76.5271","3.7971","2.5314","18.2207"
"15.3600","3.8171","76.9286","3.8171","2.5447","18.3163"
"15.4400","3.8372","77.3391","3.8372","2.5581","18.4141"
"15.5200","3.8580","77.7636","3.8580","2.5720","18.5151"
"15.6000","3.8777","78.1466","3.8777","2.5852","18.6063"
"15.6800","3.8981","78.5529","3.8981","2.5987","18.7031"
"15.7600","3.9180","78.9446","3.9180","2.6120","18.7963"
"15.8400","3.9366","79.3159","3.9366","2.6244","18.8847"
"15.9200","3.9574","79.7503","3.9574","2.6383","18.9882"
"16.0000","3.9764","80.1167","3.9764","2.6509","19.0754"
"16.0800","3.9974","80.5508","3.9974","2.6650","19.1788"
"16.1600","4.0186","80.9751","4.0186","2.6791","19.2798"
"16.2400","4.0376","81.3391","4.0376","2.6917","19.3665"
"16.3200","4.0571","81.7250","4.0571","2.7047","19.4583"
"16.4000","4.0770","82.1220","4.0770","2.7180","19.5529"
"16.4800","4.0964","82.5203","4.0964","2.7309","19.6477"
"16.5600","4.1176","82.9516","4.1176","2.7451","19.7504"
"16.6400","4.1363","83.3000","4.1363","2.7575","19.8333"
"16.7200","4.1576","83.7414","4.1576","2.7717","19.9384"
"16.8000","4.1781","84.1518","4.1781","2.7854","20.0361"
"16.8800","4.1978","84.5564","4.1978","2.7985","20.1325"
"16.9600","4.2174","84.9400","4.2174","2.8116","20.2238"
"17.0400","4.2372","85.3283","4.2372","2.8248","20.3163"
"17.1200","4.2569","85.7380","4.2569","2.8379","20.4138"
"17.2000","4.2774","86.1443","4.2774","2.8516","20.5105"
"17.2800","4.2960","86.4938","4.2960","2.8640","20.5938"
"17.3600","4.3174","86.9359","4.3174","2.8783","20.6990"
"17.4400","4.3378","87.3501","4.3378","2.8919","20.7976"
"17.5200","4.3571","87.7268","4.3571","2.9048","20.8873"
"17.6000","4.3775","88.1308","4.3775","2.9183","20.9835"
"17.6800","4.3967","88.5048","4.3967","2.9312","21.0726"
"17.7600","4.4175","88.9356","4.4175","2.9450","21.1752"
"17.8400","4.4373","89.3213","4.4373","2.9582","21.2670"
"17.9200","4.4566","89.7060","4.4566","2.9711","21.3586"
"18.0000","4.4774","90.1329","4.4774","2.9849","21.4602"
"18.0800","4.4982","90.5510","4.4982","2.9988","21.5598"
"18.1600","4.5179","90.9445","4.5179","3.0120","21.6535"
"18.2400","4.5379","91.3382","4.5379","3.0252","21.7472"
"18.3200","4.5563","91.6977","4.5563","3.0375","21.8328"
"18.4000","4.5775","92.1333","4.5775","3.0517","21.9365"
"18.4800","4.5970","92.5219","4.5970","3.0647","22.0290"
"18.5600","4.6171","92.9288","4.6171","3.0780","22.1259"
"18.6400","4.6374","93.3419","4.6374","3.0916","22.2243"
"18.7200","4.6576","93.7283","4.6576","3.1051","22.3163"
"18.8000","4.6774","94.1182","4.6774","3.1182","22.4091"
"18.8800","4.6981","94.5427","4.6981","3.1321","22.5102"
"18.9600","4.7164","94.8952","4.7164","3.1443","22.5941"
"19.0400","4.7369","95.3206","4.7369","3.1579","22.6954"
"19.1200","4.7564","95.6949","4.7564","3.1709","22.7845"
"19.2000","4.7771","96.1269","4.7771","3.1848","22.8874"
"19.2800","4.7989","96.5818","4.7989","3.1993","22.9957"
"19.3600","4.8182","96.9355","4.8182","3.2122","23.0799"
"19.4400","4.8376","97.3122","4.8376","3.2251","23.1696"
"19.5200","4.8574","97.7034","4.8574","3.2382","23.2627"
"19.6000","4.8767","98.0973","4.8767","3.2511","23.3565"
"19.6800","4.8975","98.5357","4.8975","3.2650","23.4609"
"19.7600","4.9166","98.9022","4.9166","3.2777","23.5481"
"19.8400","4.9371","99.3114","4.9371","3.2914","23.6456"
"19.9200","4.9580","99.7350","4.9580","3.3053","23.7464"
"20.0000","4.9772","100.1096","4.9772","3.3181","23.8356"
"20.0800","4.9977","100.5189","4.9977","3.3318","23.9331"
"20.1600","5.0168","100.8827","5.0168","3.3445","24.0197"
"20.2400","5.0369","101.2796","5.0369","3.3579","24.1142"
"20.3200","5.0567","101.6831","5.0567","3.3712","24.2103"
"20.4000","5.0761","102.0420","5.0761","3.3841","24.2957"
"20.4800","5.0979","102.5020","5.0979","3.3986","24.4052"
"20.5600","5.1186","102.9178","5.1186","3.4124","24.5042"
"20.6400","5.1377","103.2870","5.1377","3.4251","24.5921"
"20.7200","5.1575","103.6803","5.1575","3.4384","24.6858"
"20.8000","5.1767","104.0484","5.1767","3.4512","24.7734"
"20.8800","5.1977","104.4723","5.1977","3.4651","24.8744"
"20.9600","5.2175","104.8602","5.2175","3.4783","24.9667"
"21.0400","5.2364","105.2245","5.2364","3.4909","25.0534"
"21.1200","5.2570","105.6416","5.2570","3.5047","25.1528"
"21.2000","5.2776","106.0550","5.2776","3.5184","25.2512"
"21.2800","5.2976","106.4440","5.2976","3.5317","25.3438"
"21.3600","5.3178","106.8458","5.3178","3.5452","25.4395"
"21.4400","5.3362","107.1888","5.3362","3.5575","25.5211"
"21.5200","5.3567","107.6071","5.3567","3.5711","25.6207"
"21.6000","5.3774","108.0267","5.3774","3.5849","25.7206"
"21.6800","5.3971","108.4178","5.3971","3.5981","25.8138"
"21.7600","5.4180","108.8325","5.4180","3.6120","25.9125"
"21.8400","5.4376","109.2076","5.4376","3.6250","26.0018"
"21.9200","5.4579","109.6149","5.4579","3.6386","26.0988"
"22.0000","5.4776","110.0026","5.4776","3.6517","26.1911"
"22.0800","5.4972","110.3905","5.4972","3.6648","26.2834"
"22.1600","5.5173","110.7896","5.5173","3.6782","26.3785"
"22.2400","5.5367","111.1572","5.5367","3.6911","26.4660"
"22.3200","5.5562","111.5513","5.5562","3.7042","26.5598"
"22.4000","5.5776","111.9920","5.5776","3.7184","26.6648"
"22.4800","5.5974","112.3758","5.5974","3.7316","26.7561"
"22.5600","5.6183","112.7814","5.6183","3.7455","26.8527"
"22.6400","5.6370","113.1402","5.6370","3.7580","26.9381"
"22.7200","5.6554","113.4918","5.6554","3.7703","27.0219"
"22.8000","5.6765","113.9295","5.6765","3.7843","27.1261"
"22.8800","5.6974","114.3403","5.6974","3.7983","27.2239"
"22.9600","5.7180","114.7322","5.7180","3.8120","27.3172"
"23.0400","5.7385","115.1486","5.7385","3.8256","27.4163"
"23.1200","5.7571","115.5030","5.7571","3.8381","27.5007"
"23.2000","5.7776","115.9195","5.7776","3.8518","27.5999"
"23.2800","5.7975","116.2986","5.7975","3.8650","27.6901"
"23.3600","5.8174","116.6917","5.8174","3.8783","27.7837"
"23.4400","5.8373","117.0883","5.8373","3.8915","27.8782"
"23.5200","5.8564","117.4496","5.8564","3.9043","27.9642"
"23.6000","5.8772","117.8706","5.8772","3.9181","28.0644"
"23.6800","5.8984","118.2935","5.8984","3.9322","28.1651"
"23.7600","5.9179","118.6795","5.9179","3.9453","28.2570"
"23.8400","5.9371","119.0339","5.9371","3.9581","28.3414"
"23.9200","5.9563","119.3948","5.9563","3.9709","28.4273"
"24.0000","5.9765","119.8008","5.9765","3.9843","28.5240"
"24.0800","5.9981","120.2361","5.9981","3.9987","28.6276"
"24.1600","6.0166","120.5840","6.0166","4.0111","28.7105"
"24.2400","6.0378","121.0128","6.0378","4.0252","28.8126"
"24.3200","6.0581","121.4204","6.0581","4.0387","28.9096"
"24.4000","6.0785","121.8152","6.0785","4.0523","29.0036"
"24.4800","6.0976","122.1845","6.0976","4.0650","29.0916"
"24.5600","6.1169","122.5537","6.1169","4.0779","29.1794"
"24.6400","6.1369","122.9293","6.1369","4.0913","29.2689"
"24.7200","6.1574","123.3402","6.1574","4.1049","29.3667"
"24.8000","6.1761","123.6969","6.1761","4.1174","29.4516"
"24.8800","6.1973","124.1376","6.1973","4.1316","29.5566"
"24.9600","6.2170","124.5087","6.2170","4.1447","29.6449"
"25.0400","6.2381","124.9270","6.2381","4.1588","29.7445"
"25.1200","6.2578","125.3065","6.2578","4.1719","29.8349"
"25.2000","6.2760","125.6445","6.2760","4.1840","29.9153"
"25.2800","6.2971","126.0671","6.2971","4.1980","30.0160"
"25.3600","6.3174","126.4590","6.3174","4.2116","30.1093"
"25.4400","6.3372","126.8445","6.3372","4.2248","30.2011"
"25.5200","6.3578","127.2601","6.3578","4.2386","30.3000"
"25.6000","6.3777","127.6344","6.3777","4.2518","30.3891"
"25.6800","6.3981","128.0375","6.3981","4.2654","30.4851"
"25.7600","6.4182","128.4257","6.4182","4.2788","30.5776"
"25.8400","6.4369","128.7756","6.4369","4.2912","30.6608"
"25.9200","6.4571","129.1723","6.4571","4.3047","30.7553"
"26.0000","6.4764","129.5386","6.4764","4.3176","30.8425"
"26.0800","6.4974","129.9557","6.4974","4.3316","30.9418"
"26.1600","6.5183","130.3667","6.5183","4.3455","31.0397"
"26.2400","6.5376","130.7237","6.5376","4.3584","31.1247"
"26.3200","6.5575","131.1089","6.5575","4.3717","31.2164"
"26.4000","6.5771","131.4853","6.5771","4.3847","31.3060"
"26.4800","6.5962","131.8565","6.5962","4.3975","31.3944"
"26.5600","6.6176","132.2851","6.6176","4.4117","31.4965"
"26.6400","6.6368","132.6542","6.6368","4.4245","31.5843"
"26.7200","6.6576","133.0608","6.6576","4.4384","31.6811"
"26.8000","6.6783","133.4642","6.6783","4.4522","31.7772"
"26.8800","6.6980","133.8474","6.6980","4.4653","31.8684"
"26.9600","6.7176","134.2195","6.7176","4.4784","31.9570"
"27.0400","6.7374","134.5994","6.7374","4.4916","32.0475"
"27.1200","6.7569","134.9740","6.7569","4.5046","32.1367"
"27.2000","6.7771","135.3551","6.7771","4.5181","32.2274"
"27.2800","6.7958","135.7082","6.7958","4.5305","32.3115"
"27.3600","6.8170","136.1278","6.8170","4.5447","32.4114"
"27.4400","6.8381","136.5409","6.8381","4.5587","32.5097"
"27.5200","6.8576","136.9153","6.8576","4.5717","32.5989"
"27.6000","6.8775","137.2957","6.8775","4.5850","32.6895"
"27.6800","6.8968","137.6531","6.8968","4.5979","32.7745"
"27.7600","6.9173","138.0591","6.9173","4.6116","32.8712"
"27.8400","6.9374","138.4328","6.9374","4.6249","32.9602"
"27.9200","6.9565","138.7986","6.9565","4.6376","33.0473"
"28.0000","6.9774","139.2301","6.9774","4.6516","33.1500"
"28.0800","6.9984","139.6289","6.9984","4.6656","33.2450"
"28.1600","7.0180","140.0049","7.0180","4.6786","33.3345"
"28.2400","7.0378","140.3772","7.0378","4.6918","33.4231"
"28.3200","7.0562","140.7175","7.0562","4.7042","33.5042"
"28.4000","7.0774","141.1349","7.0774","4.7183","33.6035"
"28.4800","7.0971","141.5099","7.0971","4.7314","33.6928"
"28.5600","7.1167","141.8953","7.1167","4.7445","33.7846"
"28.6400","7.1374","142.3061","7.1374","4.7583","33.8824"
"28.7200","7.1576","142.6908","7.1576","4.7718","33.9740"
"28.8000","7.1775","143.0592","7.1775","4.7850","34.0617"
"28.8800","7.1977","143.4558","7.1977","4.7985","34.1561"
"28.9600","7.2164","143.8042","7.2164","4.8109","34.2391"
"29.0400","7.2369","144.2022","7.2369","4.8246","34.3339"
"29.1200","7.2564","144.5671","7.2564","4.8376","34.4207"
"29.2000","7.2773","144.9830","7.2773","4.8515","34.5198"
"29.2800","7.2987","145.4094","7.2987","4.8658","34.6213"
"29.3600","7.3180","145.7696","7.3180","4.8787","34.7071"
"29.4400","7.3376","146.1407","7.3376","4.8917","34.7954"
"29.5200","7.3574","146.5170","7.3574","4.9049","34.8850"
"29.6000","7.3769","146.8909","7.3769","4.9179","34.9740"
"29.6800","7.3971","147.2785","7.3971","4.9314","35.0663"
"29.7600","7.4159","147.6103","7.4159","4.9439","35.1453"
"29.8400","7.4368","148.0167","7.4368","4.9579","35.2421"
"29.9200","7.4582","148.4330","7.4582","4.9722","35.3412"
"30.0000","7.4773","148.7867","7.4773","4.9848","35.4254"
"30.0800","7.4978","149.1851","7.4978","4.9985","35.5203"
"30.1600","7.5170","149.5410","7.5170","5.0114","35.6050"
"30.2400","7.5371","149.9246","7.5371","5.0247","35.6963"
"30.3200","7.5569","150.2998","7.5569","5.0380","35.7857"
"30.4000","7.5766","150.6655","7.5766","5.0511","35.8727"
"30.4800","7.5976","151.0711","7.5976","5.0651","35.9693"
"30.5600","7.6188","151.4981","7.6188","5.0792","36.0710"
"30.6400","7.6378","151.8374","7.6378","5.0919","36.1518"
"30.7200","7.6572","152.2096","7.6572","5.1048","36.2404"
"30.8000","7.6770","152.5668","7.6770","5.1180","36.3254"
"30.8800","7.6980","152.9817","7.6980","5.1320","36.4242"
"30.9600","7.7174","153.3375","7.7174","5.1449","36.5089"
"31.0400","7.7362","153.6900","7.7362","5.1575","36.5929"
"31.1200","7.7572","154.1053","7.7572","5.1715","36.6917"
"31.2000","7.7780","154.4960","7.7780","5.1853","36.7848"
"31.2800","7.7978","154.8720","7.7978","5.1985","36.8743"
"31.3600","7.8178","155.2378","7.8178","5.2119","36.9614"
"31.4400","7.8365","155.5810","7.8365","5.2243","37.0431"
"31.5200","7.8568","155.9738","7.8568","5.2379","37.1366"
"31.6000","7.8772","156.3525","7.8772","5.2515","37.2268"
"31.6800","7.8972","156.7421","7.8972","5.2648","37.3196"
"31.7600","7.9184","157.1570","7.9184","5.2789","37.4183"
"31.8400","7.9378","157.5041","7.9378","5.2919","37.5010"
"31.9200","7.9576","157.8769","7.9576","5.3050","37.5897"
"32.0000","7.9778","158.2593","7.9778","5.3186","37.6808"
"32.0800","7.9971","158.6241","7.9971","5.3314","37.7676"
"32.1600","8.0175","159.0132","8.0175","5.3450","37.8603"
"32.2400","8.0366","159.3529","8.0366","5.3577","37.9412"
"32.3200","8.0560","159.7223","8.0560","5.3707","38.0291"
"32.4000","8.0779","160.1633","8.0779","5.3853","38.1341"
"32.4800","8.0974","160.5050","8.0974","5.3982","38.2155"
"32.5600","8.1177","160.8874","8.1177","5.4118","38.3065"
"32.6400","8.1373","161.2482","8.1373","5.4249","38.3924"
"32.7200","8.1566","161.6158","8.1566","5.4378","38.4800"
"32.8000","8.1766","161.9836","8.1766","5.4511","38.5675"
"32.8800","8.1968","162.3554","8.1968","5.4645","38.6560"
"32.9600","8.2174","162.7471","8.2174","5.4783","38.7493"
"33.0400","8.2383","163.1509","8.2383","5.4922","38.8455"
"33.1200","8.2571","163.4875","8.2571","5.5047","38.9256"
"33.2000","8.2777","163.8792","8.2777","5.5184","39.0189"
"33.2800","8.2975","164.2574","8.2975","5.5317","39.1089"
"33.3600","8.3175","164.6351","8.3175","5.5450","39.1988"
"33.4400","8.3372","164.9972","8.3372","5.5581","39.2850"
"33.5200","8.3561","165.3404","8.3561","5.5707","39.3668"
"33.6000","8.3773","165.7459","8.3773","5.5849","39.4633"
"33.6800","8.3984","166.1474","8.3984","5.5989","39.5589"
"33.7600","8.4181","166.5238","8.4181","5.6121","39.6485"
"33.8400","8.4373","166.8693","8.4373","5.6249","39.7308"
"33.9200","8.4563","167.2076","8.4563","5.6375","39.8113"
"34.0000","8.4767","167.6047","8.4767","5.6511","39.9059"
"34.0800","8.4978","168.0130","8.4978","5.6652","40.0031"
"34.1600","8.5166","168.3537","8.5166","5.6777","40.0842"
"34.2400","8.5377","168.7507","8.5377","5.6918","40.1787"
"34.3200","8.5579","169.1279","8.5579","5.7052","40.2685"
"34.4000","8.5781","169.5052","8.5781","5.7187","40.3584"
"34.4800","8.5976","169.8521","8.5976","5.7318","40.4410"
"34.5600","8.6170","170.2097","8.6170","5.7447","40.5261"
"34.6400","8.6369","170.5742","8.6369","5.7579","40.6129"
"34.7200","8.6572","170.9537","8.6572","5.7715","40.7033"
"34.8000","8.6758","171.2911","8.6758","5.7839","40.7836"
"34.8800","8.6975","171.7146","8.6975","5.7983","40.8844"
"34.9600","8.7179","172.0765","8.7179","5.8119","40.9706"
"35.0400","8.7376","172.4371","8.7376","5.8251","41.0565"
"35.1200","8.7574","172.7886","8.7574","5.8382","41.1401"
"35.2000","8.7764","173.1323","8.7764","5.8509","41.2220"
"35.2800","8.7970","173.5195","8.7970","5.8647","41.3142"
"35.3600","8.8172","173.8950","8.8172","5.8781","41.4036"
"35.4400","8.8368","174.2587","8.8368","5.8912","41.4902"
"35.5200","8.8577","174.6562","8.8577","5.9051","41.5848"
"35.6000","8.8779","175.0236","8.8779","5.9186","41.6723"
"35.6800","8.8981","175.3827","8.8981","5.9320","41.7578"
"35.7600","8.9179","175.7481","8.9179","5.9453","41.8448"
"35.8400","8.9364","176.0696","8.9364","5.9576","41.9213"
"35.9200","8.9571","176.4620","8.9571","5.9714","42.0148"
"36.0000","8.9766","176.8153","8.9766","5.9844","42.0989"
"36.0800","8.9976","177.2181","8.9976","5.9984","42.1948"
"36.1600","9.0181","177.5996","9.0181","6.0121","42.2856"
"36.2400","9.0374","177.9371","9.0374","6.0249","42.3660"
"36.3200","9.0573","178.3024","9.0573","6.0382","42.4529"
"36.4000","9.0770","178.6591","9.0770","6.0513","42.5379"
"36.4800","9.0963","179.0180","9.0963","6.0642","42.6233"
"36.5600","9.1173","179.4112","9.1173","6.0782","42.7170"
"36.6400","9.1366","179.7469","9.1366","6.0911","42.7969"
"36.7200","9.1577","180.1403","9.1577","6.1052","42.8905"
"36.8000","9.1781","180.5225","9.1781","6.1187","42.9816"
"36.8800","9.1980","180.8931","9.1980","6.1320","43.0698"
"36.9600","9.2177","181.2469","9.2177","6.1451","43.1540"
"37.0400","9.2373","181.5912","9.2373","6.1582","43.2360"
"37.1200","9.2570","181.9576","9.2570","6.1713","43.3232"
"37.2000","9.2774","182.3234","9.2774","6.1849","43.4103"
"37.2800","9.2960","182.6425","9.2960","6.1973","43.4863"
"37.3600","9.3175","183.0536","9.3175","6.2116","43.5842"
"37.4400","9.3380","183.4262","9.3380","6.2254","43.6729"
"37.5200","9.3575","183.7743","9.3575","6.2383","43.7558"
"37.6000","9.3773","184.1352","9.3773","6.2516","43.8417"
"37.6800","9.3960","184.4600","9.3960","6.2640","43.9190"
"37.7600","9.4172","184.8525","9.4172","6.2782","44.0125"
"37.8400","9.4374","185.2133","9.4374","6.2916","44.0984"
"37.9200","9.4566","185.5615","9.4566","6.3044","44.1813"
"38.0000","9.4773","185.9363","9.4773","6.3182","44.2706"
"38.0800","9.4984","186.3207","9.4984","6.3323","44.3621"
"38.1600","9.5181","186.6806","9.5181","6.3454","44.4478"
"38.2400","9.5380","187.0218","9.5380","6.3586","44.5290"
"38.3200","9.5562","187.3460","9.5562","6.3708","44.6062"
"38.4000","9.5775","187.7465","9.5775","6.3850","44.7015"
"38.4800","9.5969","188.0968","9.5969","6.3980","44.7850"
"38.5600","9.6171","188.4685","9.6171","6.4114","44.8734"
"38.6400","9.6375","188.8424","9.6375","6.4250","44.9625"
"38.7200","9.6575","189.1938","9.6575","6.4383","45.0461"
"38.8000","9.6773","189.5367","9.6773","6.4515","45.1278"
"38.8800","9.6980","189.9246","9.6980","6.4654","45.2201"
"38.9600","9.7167","190.2403","9.7167","6.4778","45.2953"
"39.0400","9.7371","190.6121","9.7371","6.4914","45.3838"
"39.1200","9.7563","190.9510","9.7563","6.5042","45.4645"
"39.2000","9.7770","191.3432","9.7770","6.5180","45.5579"
"39.2800","9.7986","191.7479","9.7986","6.5324","45.6543"
"39.3600","9.8183","192.0975","9.8183","6.5455","45.7375"
"39.4400","9.8378","192.4264","9.8378","6.5585","45.8158"
"39.5200","9.8575","192.7796","9.8575","6.5716","45.8999"
"39.6000","9.8771","193.1231","9.8771","6.5847","45.9817"
"39.6800","9.8969","193.4803","9.8969","6.5980","46.0667"
"39.7600","9.9163","193.8186","9.9163","6.6108","46.1473"
"39.8400","9.9371","194.2039","9.9371","6.6247","46.2390"
"39.9200","9.9584","194.5905","9.9584","6.6390","46.3311"
"40.0000","9.9770","194.9139","9.9770","6.6513","46.4081"
"40.0800","9.9979","195.2938","9.9979","6.6653","46.4985"
"40.1600","10.0171","195.6402","10.0171","6.6781","46.5810"
"40.2400","10.0370","195.9902","10.0370","6.6913","46.6643"
"40.3200","10.0567","196.3337","10.0567","6.7044","46.7461"
"40.4000","10.0765","196.6884","10.0765","6.7177","46.8306"
"40.4800","10.0977","197.0803","10.0977","6.7318","46.9239"
"40.5600","10.1188","197.4629","10.1188","6.7459","47.0150"
"40.6400","10.1367","197.7665","10.1367","6.7578","47.0873"
"40.7200","10.1570","198.1288","10.1570","6.7713","47.1735"
"40.8000","10.1769","198.4695","10.1769","6.7846","47.2546"
"40.8800","10.1980","198.8459","10.1980","6.7987","47.3443"
"40.9600","10.2177","199.1841","10.2177","6.8118","47.4248"
"41.0400","10.2364","199.5141","10.2364","6.8242","47.5034"
"41.1200","10.2570","199.8897","10.2570","6.8380","47.5928"
"41.2000","10.2778","200.2698","10.2778","6.8519","47.6833"
"41.2800","10.2977","200.6197","10.2977","6.8651","47.7666"
"41.3600","10.3177","200.9742","10.3177","6.8785","47.8510"
"41.4400","10.3369","201.3192","10.3369","6.8913","47.9331"
"41.5200","10.3569","201.6660","10.3569","6.9046","48.0157"
"41.6000","10.3771","202.0269","10.3771","6.9180","48.1016"
"41.6800","10.3971","202.3921","10.3971","6.9314","48.1886"
"41.7600","10.4184","202.7886","10.4184","6.9456","48.2830"
"41.8400","10.4377","203.1073","10.4377","6.9585","48.3589"
"41.9200","10.4580","203.4635","10.4580","6.9720","48.4437"
"42.0000","10.4778","203.8153","10.4778","6.9852","48.5274"
"42.0800","10.4970","204.1539","10.4970","6.9980","48.6081"
"42.1600","10.5171","204.5107","10.5171","7.0114","48.6930"
"42.2400","10.5366","204.8396","10.5366","7.0244","48.7713"
"42.3200","10.5563","205.1962","10.5563","7.0375","48.8562"
"42.4000","10.5780","205.5944","10.5780","7.0520","48.9510"
"42.4800","10.5975","205.9270","10.5975","7.0650","49.0302"
"42.5600","10.6180","206.2839","10.6180","7.0787","49.1152"
"42.6400","10.6371","206.6129","10.6371","7.0914","49.1935"
"42.7200","10.6565","206.9537","10.6565","7.1043","49.2747"
"42.8000","10.6768","207.3208","10.6768","7.1178","49.3621"
"42.8800","10.6971","207.6704","10.6971","7.1314","49.4453"
"42.9600","10.7173","208.0290","10.7173","7.1448","49.5307"
"43.0400","10.7379","208.3862","10.7379","7.1586","49.6158"
"43.1200","10.7571","208.7185","10.7571","7.1714","49.6949"
"43.2000","10.7779","209.0944","10.7779","7.1852","49.7844"
"43.2800","10.7976","209.4232","10.7976","7.1984","49.8627"
"43.3600","10.8172","209.7746","10.8172","7.2115","49.9463"
"43.4400","10.8372","210.1163","10.8372","7.2248","50.0277"
"43.5200","10.8559","210.4284","10.8559","7.2373","50.1020"
"43.6000","10.8775","210.8208","10.8775","7.2517","50.1954"
"43.6800","10.8985","211.2065","10.8985","7.2657","50.2873"
"43.7600","10.9179","211.5314","10.9179","7.2786","50.3646"
"43.8400","10.9373","211.8785","10.9373","7.2916","50.4473"
"43.9200","10.9565","212.1913","10.9565","7.3043","50.5217"
"44.0000","10.9764","212.5437","10.9764","7.3176","50.6056"
"44.0800","10.9976","212.9096","10.9976","7.3317","50.6928"
"44.1600","11.0167","213.2448","11.0167","7.3445","50.7726"
"44.2400","11.0380","213.6145","11.0380","7.3587","50.8606"
"44.3200","11.0578","213.9622","11.0578","7.3719","50.9434"
"44.4000","11.0783","214.3198","11.0783","7.3855","51.0285"
"44.4800","11.0977","214.6525","11.0977","7.3985","51.1077"
"44.5600","11.1170","214.9734","11.1170","7.4114","51.1841"
"44.6400","11.1367","215.3176","11.1367","7.4245","51.2661"
"44.7200","11.1575","215.6961","11.1575","7.4383","51.3562"
"44.8000","11.1764","216.0088","11.1764","7.4509","51.4307"
"44.8800","11.1976","216.3944","11.1976","7.4651","51.5225"
"44.9600","11.2175","216.7286","11.2175","7.4784","51.6020"
"45.0400","11.2379","217.0897","11.2379","7.4919","51.6880"
"45.1200","11.2574","217.4111","11.2574","7.5049","51.7646"
"45.2000","11.2764","217.7223","11.2764","7.5176","51.8386"
"45.2800","11.2971","218.0905","11.2971","7.5314","51.9263"
"45.3600","11.3174","218.4491","11.3174","7.5449","52.0117"
"45.4400","11.3369","218.7821","11.3369","7.5579","52.0910"
"45.5200","11.3574","219.1429","11.3574","7.5716","52.1769"
"45.6000","11.3776","219.4710","11.3776","7.5850","52.2550"
"45.6800","11.3982","219.8437","11.3982","7.5988","52.3437"
"45.7600","11.4180","220.1791","11.4180","7.6120","52.4236"
"45.8400","11.4362","220.4848","11.4362","7.6241","52.4964"
"45.9200","11.4569","220.8541","11.4569","7.6380","52.5843"
"46.0000","11.4765","221.1794","11.4765","7.6510","52.6618"
"46.0800","11.4975","221.5487","11.4975","7.6650","52.7497"
"46.1600","11.5181","221.9093","11.5181","7.6787","52.8355"
"46.2400","11.5377","222.2387","11.5377","7.6918","52.9140"
"46.3200","11.5573","222.5748","11.5573","7.7049","52.9940"
"46.4000","11.5770","222.9088","11.5770","7.7180","53.0735"
"46.4800","11.5964","223.2324","11.5964","7.7309","53.1506"
"46.5600","11.6176","223.6214","11.6176","7.7451","53.2432"
"46.6400","11.6363","223.9250","11.6363","7.7575","53.3155"
"46.7200","11.6577","224.3052","11.6577","7.7718","53.4060"
"46.8000","11.6783","224.6680","11.6783","7.7855","53.4924"
"46.8800","11.6980","224.9967","11.6980","7.7987","53.5706"
"46.9600","11.7175","225.3205","11.7175","7.8116","53.6477"
"47.0400","11.7372","225.6510","11.7372","7.8248","53.7264"
"47.1200","11.7570","225.9860","11.7570","7.8380","53.8062"
"47.2000","11.7773","226.3485","11.7773","7.8515","53.8925"
"47.2800","11.7963","226.6523","11.7963","7.8642","53.9648"
"47.3600","11.8171","227.0217","11.8171","7.8780","54.0528"
"47.4400","11.8379","227.3906","11.8379","7.8920","54.1406"
"47.5200","11.8576","227.7219","11.8576","7.9051","54.2195"
"47.6000","11.8777","228.0723","11.8777","7.9185","54.3029"
"47.6800","11.8965","228.3712","11.8965","7.9310","54.3741"
"47.7600","11.9174","228.7325","11.9174","7.9450","54.4601"
"47.8400","11.9373","229.0677","11.9373","7.9582","54.5399"
"47.9200","11.9566","229.3837","11.9566","7.9711","54.6152"
"48.0000","11.9773","229.7549","11.9773","7.9849","54.7035"
"48.0800","11.9979","230.1093","11.9979","7.9986","54.7879"
"48.1600","12.0179","230.4442","12.0179","8.0119","54.8677"
"48.2400","12.0381","230.7853","12.0381","8.0254","54.9489"
"48.3200","12.0562","231.0652","12.0562","8.0375","55.0155"
"48.4000","12.0773","231.4420","12.0773","8.0515","55.1052"
"48.4800","12.0971","231.7683","12.0971","8.0647","55.1829"
"48.5600","12.1173","232.1220","12.1173","8.0782","55.2671"
"48.6400","12.1375","232.4708","12.1375","8.0916","55.3502"
"48.7200","12.1577","232.8082","12.1577","8.1052","55.4305"
"48.8000","12.1774","233.1287","12.1774","8.1182","55.5068"
"48.8800","12.1978","233.4812","12.1978","8.1319","55.5908"
"48.9600","12.2165","233.7878","12.2165","8.1444","55.6638"
"49.0400","12.2370","234.1429","12.2370","8.1580","55.7483"
"49.1200","12.2564","234.4534","12.2564","8.1709","55.8222"
"49.2000","12.2773","234.8238","12.2773","8.1849","55.9104"
"49.2800","12.2987","235.1881","12.2987","8.1991","55.9972"
"49.3600","12.3183","235.5101","12.3183","8.2122","56.0738"
"49.4400","12.3380","235.8324","12.3380","8.2253","56.1506"
"49.5200","12.3572","236.1432","12.3572","8.2381","56.2246"
"49.6000","12.3769","236.4818","12.3769","8.2512","56.3052"
"49.6800","12.3972","236.8330","12.3972","8.2648","56.3888"
"49.7600","12.4165","237.1268","12.4165","8.2777","56.4588"
"49.8400","12.4369","237.4781","12.4369","8.2912","56.5424"
"49.9200","12.4579","237.8329","12.4579","8.3052","56.6269"
"50.0000","12.4772","238.1572","12.4772","8.3181","56.7041"
"50.0800","12.4978","238.5035","12.4978","8.3319","56.7865"
"50.1600","12.5169","238.8031","12.5169","8.3446","56.8579"
"50.2400","12.5372","239.1488","12.5372","8.3581","56.9402"
"50.3200","12.5567","239.4850","12.5567","8.3711","57.0202"
"50.4000","12.5765","239.8063","12.5765","8.3843","57.0967"
"50.4800","12.5978","240.1832","12.5978","8.3986","57.1865"
"50.5600","12.6190","240.5429","12.6190","8.4127","57.2721"
"50.6400","12.6374","240.8295","12.6374","8.4250","57.3404"
"50.7200","12.6572","241.1484","12.6572","8.4381","57.4163"
"50.8000","12.6762","241.4568","12.6762","8.4508","57.4897"
"50.8800","12.6977","241.8271","12.6977","8.4652","57.5779"
"50.9600","12.7173","242.1354","12.7173","8.4782","57.6513"
"51.0400","12.7362","242.4480","12.7362","8.4908","57.7257"
"51.1200","12.7573","242.8160","12.7573","8.5048","57.8133"
"51.2000","12.7779","243.1622","12.7779","8.5186","57.8958"
"51.2800","12.7979","243.4892","12.7979","8.5319","57.9736"
"51.3600","12.8176","243.8155","12.8176","8.5451","58.0513"
"51.4400","12.8365","244.1033","12.8365","8.5577","58.1198"
"51.5200","12.8568","244.4511","12.8568","8.5712","58.2026"
"51.6000","12.8770","244.7845","12.8770","8.5847","58.2820"
"51.6800","12.8970","245.1389","12.8970","8.5980","58.3664"
"51.7600","12.9184","245.5201","12.9184","8.6123","58.4572"
"51.8400","12.9379","245.8247","12.9379","8.6253","58.5297"
"51.9200","12.9582","246.1575","12.9582","8.6388","58.6089"
"52.0000","12.9776","246.4710","12.9776","8.6518","58.6836"
"52.0800","12.9973","246.7961","12.9973","8.6649","58.7610"
"52.1600","13.0171","247.1207","13.0171","8.6781","58.8383"
"52.2400","13.0368","247.4383","13.0368","8.6912","58.9139"
"52.3200","13.0562","247.7483","13.0562","8.7042","58.9877"
"52.4000","13.0777","248.1250","13.0777","8.7185","59.0774"
"52.4800","13.0976","248.4568","13.0976","8.7317","59.1564"
"52.5600","13.1182","248.7841","13.1182","8.7455","59.2343"
"52.6400","13.1373","249.0921","13.1373","8.7582","59.3076"
"52.7200","13.1567","249.4074","13.1567","8.7712","59.3827"
"52.8000","13.1765","249.7295","13.1765","8.7843","59.4594"
"52.8800","13.1968","250.0637","13.1968","8.7979","59.5390"
"52.9600","13.2176","250.4007","13.2176","8.8117","59.6192"
"53.0400","13.2385","250.7567","13.2385","8.8257","59.7040"
"53.1200","13.2572","251.0429","13.2572","8.8382","59.7721"
"53.2000","13.2776","251.3829","13.2776","8.8517","59.8531"
"53.2800","13.2975","251.7085","13.2975","8.8650","59.9306"
"53.3600","13.3168","252.0177","13.3168","8.8778","60.0042"
"53.4400","13.3374","252.3648","13.3374","8.8916","60.0868"
"53.5200","13.3562","252.6498","13.3562","8.9041","60.1547"
"53.6000","13.3773","252.9938","13.3773","8.9182","60.2366"
"53.6800","13.3983","253.3526","13.3983","8.9322","60.3220"
"53.7600","13.4176","253.6428","13.4176","8.9451","60.3911"
"53.8400","13.4372","253.9647","13.4372","8.9581","60.4678"
"53.9200","13.4566","254.2661","13.4566","8.9711","60.5396"
"54.0000","13.4771","254.6087","13.4771","8.9847","60.6211"
"54.0800","13.4978","254.9654","13.4978","8.9985","60.7060"
"54.1600","13.5164","255.2530","13.5164","9.0109","60.7745"
"54.2400","13.5380","255.6126","13.5380","9.0253","60.8602"
"54.3200","13.5579","255.9378","13.5579","9.0386","60.9376"
"54.4000","13.5784","256.2570","13.5784","9.0523","61.0136"
"54.4800","13.5977","256.5714","13.5977","9.0652","61.0884"
"54.5600","13.6169","256.8598","13.6169","9.0779","61.1571"
"54.6400","13.6373","257.1890","13.6373","9.0915","61.2355"
"54.7200","13.6573","257.5007","13.6573","9.1049","61.3097"
"54.8000","13.6761","257.8124","13.6761","9.1174","61.3839"
"54.8800","13.6974","258.1723","13.6974","9.1316","61.4696"
"54.9600","13.7175","258.4863","13.7175","9.1450","61.5444"
"55.0400","13.7380","258.8182","13.7380","9.1586","61.6234"
"55.1200","13.7575","259.1198","13.7575","9.1717","61.6952"
"55.2000","13.7764","259.4191","13.7764","9.1843","61.7665"
"55.2800","13.7971","259.7516","13.7971","9.1981","61.8456"
"55.3600","13.8172","260.0702","13.8172","9.2115","61.9215"
"55.4400","13.8370","260.3867","13.8370","9.2247","61.9968"
"55.5200","13.8577","260.7260","13.8577","9.2385","62.0776"
"55.6000","13.8775","261.0210","13.8775","9.2517","62.1479"
"55.6800","13.8977","261.3462","13.8977","9.2651","62.2253"
"55.7600","13.9178","261.6513","13.9178","9.2785","62.2979"
"55.8400","13.9367","261.9438","13.9367","9.2912","62.3676"
"55.9200","13.9569","262.2678","13.9569","9.3046","62.4447"
"56.0000","13.9764","262.5626","13.9764","9.3176","62.5149"
"56.0800","13.9974","262.9186","13.9974","9.3316","62.5997"
"56.1600","14.0183","263.2549","14.0183","9.3455","62.6797"
"56.2400","14.0373","263.5399","14.0373","9.3582","62.7476"
"56.3200","14.0573","263.8489","14.0573","9.3715","62.8212"
"56.4000","14.0772","264.1560","14.0772","9.3848","62.8943"
"56.4800","14.0964","264.4583","14.0964","9.3976","62.9663"
"56.5600","14.1170","264.7877","14.1170","9.4113","63.0447"
"56.6400","14.1363","265.0739","14.1363","9.4242","63.1128"
"56.7200","14.1578","265.4298","14.1578","9.4385","63.1976"
"56.8000","14.1786","265.7655","14.1786","9.4524","63.2775"
"56.8800","14.1979","266.0603","14.1979","9.4653","63.3477"
"56.9600","14.2177","266.3691","14.2177","9.4785","63.4212"
"57.0400","14.2371","266.6575","14.2371","9.4914","63.4899"
"57.1200","14.2569","266.9675","14.2569","9.5046","63.5637"
"57.2000","14.2773","267.2799","14.2773","9.5182","63.6381"
"57.2800","14.2961","267.5679","14.2961","9.5307","63.7066"
"57.3600","14.3174","267.9103","14.3174","9.5449","63.7882"
"57.4400","14.3379","268.2246","14.3379","9.5586","63.8630"
"57.5200","14.3574","268.5322","14.3574","9.5716","63.9362"
"57.6000","14.3774","268.8401","14.3774","9.5850","64.0096"
"57.6800","14.3966","269.1311","14.3966","9.5978","64.0788"
"57.7600","14.4175","269.4531","14.4175","9.6117","64.1555"
"57.8400","14.4373","269.7614","14.4373","9.6248","64.2289"
"57.9200","14.4560","270.0301","14.4560","9.6373","64.2929"
"58.0000","14.4773","270.3853","14.4773","9.6515","64.3774"
"58.0800","14.4983","270.7147","14.4983","9.6655","64.4559"
"58.1600","14.5182","271.0132","14.5182","9.6788","64.5270"
"58.2400","14.5376","271.3022","14.5376","9.6918","64.5958"
"58.3200","14.5563","271.5652","14.5563","9.7042","64.6584"
"58.4000","14.5774","271.9054","14.5774","9.7182","64.7394"
"58.4800","14.5972","272.2031","14.5972","9.7315","64.8103"
"58.5600","14.6168","272.4976","14.6168","9.7445","64.8804"
"58.6400","14.6371","272.8196","14.6371","9.7581","64.9570"
"58.7200","14.6574","273.1267","14.6574","9.7716","65.0302"
"58.8000","14.6775","273.4271","14.6775","9.7850","65.1017"
"58.8800","14.6978","273.7298","14.6978","9.7985","65.1738"
"58.9600","14.7166","274.0103","14.7166","9.8111","65.2406"
"59.0400","14.7370","274.3279","14.7370","9.8247","65.3162"
"59.1200","14.7565","274.6039","14.7565","9.8377","65.3819"
"59.2000","14.7774","274.9383","14.7774","9.8516","65.4615"
"59.2800","14.7987","275.2720","14.7987","9.8658","65.5410"
"59.3600","14.8183","275.5568","14.8183","9.8788","65.6088"
"59.4400","14.8379","275.8317","14.8379","9.8920","65.6742"
"59.5200","14.8574","276.1175","14.8574","9.9050","65.7423"
"59.6000","14.8769","276.4093","14.8769","9.9179","65.8117"
"59.6800","14.8973","276.7274","14.8973","9.9316","65.8875"
"59.7600","14.9165","276.9838","14.9165","9.9443","65.9485"
"59.8400","14.9370","277.3003","14.9370","9.9580","66.0239"
"59.9200","14.9576","277.6082","14.9576","9.9717","66.0972"
"60.0000","14.9771","277.9038","14.9771","9.9848","66.1676"
"60.0800","14.9977","278.2022","14.9977","9.9984","66.2386"
"60.0900","15.0001","278.2391","15.0001","10.0001","66.2474"