File: data/instron_tests/metamaterials/250421/250421_2224_BULK_m2.is_comp_Exports/250421_2224_BULK_m2_1_1.csv
Results Table 1
,Compresson Axis,H*,V*,Height,Thickness,Width,Area,Fixture separation,Specimen label
,,,,(mm),(mm),(mm),(mm^2),(mm),
"1","Y","","","150.00","28.00","150.00","4200.00","150.00","2224_BULK_m2"

Results Table 2
,Modulus (Segment 0 % - 2.5 %),Compresson Axis
,(kPa),
"1","758.22","Y"

Time,Displacement,Force,Compressive displacement,Compressive strain (Displacement),Compressive stress
(s),(mm),(N),(mm),(%),(kPa)
"0.0000","0.0000","-3.7427","0.0000","0.0000","-0.8911"
"0.0800","0.0011","-3.6960","0.0011","0.0007","-0.8800"
"0.1600","0.0172","-3.1980","0.0172","0.0115","-0.7614"
"0.2400","0.0373","-2.6041","0.0373","0.0249","-0.6200"
"0.3200","0.0574","-2.0445","0.0574","0.0383","-0.4868"
"0.4000","0.0766","-1.5153","0.0766","0.0511","-0.3608"
"0.4800","0.0976","-0.9596","0.0976","0.0651","-0.2285"
"0.5600","0.1178","-0.4405","0.1178","0.0785","-0.1049"
"0.6400","0.1372","0.0611","0.1372","0.0914","0.0145"
"0.7200","0.1567","0.5702","0.1567","0.1045","0.1358"
"0.8000","0.1767","1.0611","0.1767","0.1178","0.2526"
"0.8800","0.1973","1.5868","0.1973","0.1315","0.3778"
"0.9600","0.2175","2.0794","0.2175","0.1450","0.4951"
"1.0400","0.2357","2.5364","0.2357","0.1571","0.6039"
"1.1200","0.2567","3.0437","0.2567","0.1711","0.7247"
"1.2000","0.2771","3.5409","0.2771","0.1848","0.8431"
"1.2800","0.2975","4.0220","0.2975","0.1983","0.9576"
"1.3600","0.3174","4.4973","0.3174","0.2116","1.0708"
"1.4400","0.3358","4.9273","0.3358","0.2239","1.1732"
"1.5200","0.3563","5.4142","0.3563","0.2375","1.2891"
"1.6000","0.3769","5.8971","0.3769","0.2512","1.4041"
"1.6800","0.3966","6.3623","0.3966","0.2644","1.5148"
"1.7600","0.4177","6.8522","0.4177","0.2785","1.6315"
"1.8400","0.4374","7.3062","0.4374","0.2916","1.7396"
"1.9200","0.4573","7.7464","0.4573","0.3049","1.8444"
"2.0000","0.4772","8.2117","0.4772","0.3181","1.9552"
"2.0800","0.4958","8.6278","0.4958","0.3305","2.0542"
"2.1600","0.5167","9.1106","0.5167","0.3445","2.1692"
"2.2400","0.5367","9.5635","0.5367","0.3578","2.2770"
"2.3200","0.5562","10.0155","0.5562","0.3708","2.3846"
"2.4000","0.5773","10.5150","0.5773","0.3849","2.5036"
"2.4800","0.5971","10.9509","0.5971","0.3981","2.6074"
"2.5600","0.6179","11.4259","0.6179","0.4119","2.7205"
"2.6400","0.6371","11.8342","0.6371","0.4247","2.8177"
"2.7200","0.6559","12.2669","0.6559","0.4372","2.9207"
"2.8000","0.6763","12.7386","0.6763","0.4509","3.0330"
"2.8800","0.6968","13.1900","0.6968","0.4645","3.1405"
"2.9600","0.7174","13.6641","0.7174","0.4783","3.2534"
"3.0400","0.7382","14.1262","0.7382","0.4921","3.3634"
"3.1200","0.7564","14.5297","0.7564","0.5043","3.4595"
"3.2000","0.7773","15.0057","0.7773","0.5182","3.5728"
"3.2800","0.7972","15.4503","0.7972","0.5315","3.6786"
"3.3600","0.8166","15.8804","0.8166","0.5444","3.7810"
"3.4400","0.8368","16.3289","0.8368","0.5579","3.8878"
"3.5200","0.8557","16.7424","0.8557","0.5705","3.9863"
"3.6000","0.8770","17.2181","0.8770","0.5846","4.0996"
"3.6800","0.8980","17.6843","0.8980","0.5987","4.2106"
"3.7600","0.9174","18.1148","0.9174","0.6116","4.3131"
"3.8400","0.9368","18.5526","0.9368","0.6246","4.4173"
"3.9200","0.9559","18.9542","0.9559","0.6373","4.5129"
"4.0000","0.9759","19.4041","0.9759","0.6506","4.6200"
"4.0800","0.9972","19.8736","0.9972","0.6648","4.7318"
"4.1600","1.0163","20.2882","1.0163","0.6775","4.8305"
"4.2400","1.0376","20.7552","1.0376","0.6917","4.9417"
"4.3200","1.0577","21.1982","1.0577","0.7051","5.0472"
"4.4000","1.0774","21.6220","1.0774","0.7182","5.1481"
"4.4800","1.0970","22.0478","1.0970","0.7313","5.2495"
"4.5600","1.1161","22.4473","1.1161","0.7441","5.3446"
"4.6400","1.1367","22.8949","1.1367","0.7578","5.4512"
"4.7200","1.1570","23.3309","1.1570","0.7714","5.5550"
"4.8000","1.1762","23.7497","1.1762","0.7841","5.6547"
"4.8800","1.1971","24.2083","1.1971","0.7980","5.7639"
"4.9600","1.2175","24.6351","1.2175","0.8117","5.8655"
"5.0400","1.2373","25.0607","1.2373","0.8249","5.9668"
"5.1200","1.2571","25.4787","1.2571","0.8380","6.0664"
"5.2000","1.2758","25.8798","1.2758","0.8505","6.1619"
"5.2800","1.2968","26.3302","1.2968","0.8645","6.2691"
"5.3600","1.3169","26.7713","1.3169","0.8779","6.3741"
"5.4400","1.3368","27.2071","1.3368","0.8912","6.4779"
"5.5200","1.3575","27.6609","1.3575","0.9050","6.5859"
"5.6000","1.3776","28.0787","1.3776","0.9184","6.6854"
"5.6800","1.3980","28.5259","1.3980","0.9320","6.7919"
"5.7600","1.4175","28.9306","1.4175","0.9450","6.8882"
"5.8400","1.4362","29.3317","1.4362","0.9575","6.9837"
"5.9200","1.4568","29.7873","1.4568","0.9712","7.0922"
"6.0000","1.4762","30.2004","1.4762","0.9841","7.1906"
"6.0800","1.4969","30.6466","1.4969","0.9980","7.2968"
"6.1600","1.5179","31.1059","1.5179","1.0119","7.4062"
"6.2400","1.5373","31.5208","1.5373","1.0248","7.5050"
"6.3200","1.5566","31.9277","1.5566","1.0377","7.6018"
"6.4000","1.5766","32.3763","1.5766","1.0511","7.7087"
"6.4800","1.5958","32.7758","1.5958","1.0639","7.8038"
"6.5600","1.6168","33.2342","1.6168","1.0779","7.9129"
"6.6400","1.6358","33.6392","1.6358","1.0906","8.0093"
"6.7200","1.6574","34.1045","1.6574","1.1049","8.1201"
"6.8000","1.6774","34.5387","1.6774","1.1183","8.2235"
"6.8800","1.6975","34.9861","1.6975","1.1317","8.3300"
"6.9600","1.7172","35.3896","1.7172","1.1448","8.4261"
"7.0400","1.7369","35.8148","1.7369","1.1579","8.5273"
"7.1200","1.7564","36.2261","1.7564","1.1709","8.6253"
"7.2000","1.7773","36.6790","1.7773","1.1848","8.7331"
"7.2800","1.7960","37.0597","1.7960","1.1973","8.8237"
"7.3600","1.8170","37.5261","1.8170","1.2113","8.9348"
"7.4400","1.8374","37.9646","1.8374","1.2249","9.0392"
"7.5200","1.8569","38.3916","1.8569","1.2379","9.1409"
"7.6000","1.8773","38.8323","1.8773","1.2515","9.2458"
"7.6800","1.8965","39.2316","1.8965","1.2644","9.3409"
"7.7600","1.9171","39.6721","1.9171","1.2781","9.4457"
"7.8400","1.9367","40.0786","1.9367","1.2912","9.5425"
"7.9200","1.9558","40.4793","1.9558","1.3039","9.6379"
"8.0000","1.9769","40.9110","1.9769","1.3180","9.7407"
"8.0800","1.9983","41.3320","1.9983","1.3322","9.8410"
"8.1600","2.0178","41.7293","2.0178","1.3452","9.9355"
"8.2400","2.0376","42.1454","2.0376","1.3584","10.0346"
"8.3200","2.0561","42.5168","2.0561","1.3707","10.1231"
"8.4000","2.0773","42.9602","2.0773","1.3848","10.2286"
"8.4800","2.0968","43.3558","2.0968","1.3978","10.3228"
"8.5600","2.1163","43.7636","2.1163","1.4109","10.4199"
"8.6400","2.1368","44.1921","2.1368","1.4245","10.5219"
"8.7200","2.1572","44.6017","2.1572","1.4381","10.6195"
"8.8000","2.1771","45.0169","2.1771","1.4514","10.7183"
"8.8800","2.1976","45.4430","2.1976","1.4651","10.8198"
"8.9600","2.2159","45.8148","2.2159","1.4773","10.9083"
"9.0400","2.2367","46.2590","2.2367","1.4911","11.0140"
"9.1200","2.2564","46.6551","2.2564","1.5043","11.1084"
"9.2000","2.2767","47.0847","2.2767","1.5178","11.2107"
"9.2800","2.2982","47.5331","2.2982","1.5322","11.3174"
"9.3600","2.3170","47.9073","2.3170","1.5447","11.4065"
"9.4400","2.3373","48.3358","2.3373","1.5582","11.5085"
"9.5200","2.3572","48.7461","2.3572","1.5715","11.6062"
"9.6000","2.3766","49.1527","2.3766","1.5844","11.7030"
"9.6800","2.3967","49.5821","2.3967","1.5978","11.8053"
"9.7600","2.4160","49.9674","2.4160","1.6107","11.8970"
"9.8400","2.4367","50.4007","2.4367","1.6244","12.0002"
"9.9200","2.4577","50.8419","2.4577","1.6385","12.1052"
"10.0000","2.4768","51.2349","2.4768","1.6512","12.1988"
"10.0800","2.4973","51.6619","2.4973","1.6649","12.3005"
"10.1600","2.5168","52.0601","2.5168","1.6778","12.3953"
"10.2400","2.5365","52.4664","2.5365","1.6910","12.4920"
"10.3200","2.5567","52.8878","2.5567","1.7045","12.5923"
"10.4000","2.5763","53.2779","2.5763","1.7175","12.6852"
"10.4800","2.5974","53.7260","2.5974","1.7316","12.7919"
"10.5600","2.6185","54.1666","2.6185","1.7457","12.8968"
"10.6400","2.6373","54.5427","2.6373","1.7582","12.9864"
"10.7200","2.6570","54.9484","2.6570","1.7713","13.0829"
"10.8000","2.6761","55.3244","2.6761","1.7840","13.1725"
"10.8800","2.6973","55.7760","2.6973","1.7982","13.2800"
"10.9600","2.7175","56.1810","2.7175","1.8117","13.3764"
"11.0400","2.7359","56.5449","2.7359","1.8239","13.4631"
"11.1200","2.7565","56.9817","2.7565","1.8377","13.5671"
"11.2000","2.7776","57.4250","2.7776","1.8517","13.6726"
"11.2800","2.7970","57.8123","2.7970","1.8647","13.7648"
"11.3600","2.8172","58.2294","2.8172","1.8781","13.8641"
"11.4400","2.8359","58.5908","2.8359","1.8906","13.9502"
"11.5200","2.8564","59.0117","2.8564","1.9043","14.0504"
"11.6000","2.8769","59.4237","2.8769","1.9179","14.1485"
"11.6800","2.8967","59.8371","2.8967","1.9311","14.2469"
"11.7600","2.9179","60.2770","2.9179","1.9453","14.3517"
"11.8400","2.9373","60.6544","2.9373","1.9582","14.4415"
"11.9200","2.9575","61.0737","2.9575","1.9716","14.5414"
"12.0000","2.9766","61.4529","2.9766","1.9844","14.6316"
"12.0800","2.9967","61.8665","2.9967","1.9978","14.7301"
"12.1600","3.0172","62.3105","3.0172","2.0115","14.8358"
"12.2400","3.0367","62.6832","3.0367","2.0244","14.9246"
"12.3200","3.0558","63.0666","3.0558","2.0372","15.0159"
"12.4000","3.0772","63.5339","3.0772","2.0515","15.1271"
"12.4800","3.0972","63.9201","3.0972","2.0648","15.2191"
"12.5600","3.1179","64.3387","3.1179","2.0786","15.3187"
"12.6400","3.1369","64.7163","3.1369","2.0913","15.4086"
"12.7200","3.1561","65.1025","3.1561","2.1041","15.5006"
"12.8000","3.1764","65.5293","3.1764","2.1176","15.6022"
"12.8800","3.1966","65.9313","3.1966","2.1310","15.6979"
"12.9600","3.2172","66.3472","3.2172","2.1448","15.7970"
"13.0400","3.2381","66.7809","3.2381","2.1587","15.9002"
"13.1200","3.2569","67.1406","3.2569","2.1712","15.9859"
"13.2000","3.2772","67.5571","3.2772","2.1848","16.0850"
"13.2800","3.2970","67.9532","3.2970","2.1980","16.1793"
"13.3600","3.3167","68.3595","3.3167","2.2112","16.2761"
"13.4400","3.3372","68.7640","3.3372","2.2248","16.3724"
"13.5200","3.3558","69.1375","3.3558","2.2372","16.4613"
"13.6000","3.3768","69.5611","3.3768","2.2512","16.5622"
"13.6800","3.3976","69.9887","3.3976","2.2651","16.6640"
"13.7600","3.4173","70.3719","3.4173","2.2782","16.7552"
"13.8400","3.4370","70.7782","3.4370","2.2914","16.8520"
"13.9200","3.4563","71.1493","3.4563","2.3042","16.9403"
"14.0000","3.4762","71.5572","3.4762","2.3175","17.0374"
"14.0800","3.4974","71.9897","3.4974","2.3316","17.1404"
"14.1600","3.5164","72.3730","3.5164","2.3442","17.2317"
"14.2400","3.5375","72.7927","3.5375","2.3583","17.3316"
"14.3200","3.5574","73.1940","3.5574","2.3716","17.4271"
"14.4000","3.5774","73.6031","3.5774","2.3849","17.5245"
"14.4800","3.5970","73.9916","3.5970","2.3980","17.6170"
"14.5600","3.6165","74.3503","3.6165","2.4110","17.7024"
"14.6400","3.6365","74.7451","3.6365","2.4244","17.7965"
"14.7200","3.6563","75.1362","3.6563","2.4375","17.8896"
"14.8000","3.6758","75.5326","3.6758","2.4505","17.9839"
"14.8800","3.6972","75.9785","3.6972","2.4648","18.0901"
"14.9600","3.7172","76.3558","3.7172","2.4782","18.1800"
"15.0400","3.7375","76.7697","3.7375","2.4917","18.2785"
"15.1200","3.7570","77.1590","3.7570","2.5047","18.3712"
"15.2000","3.7755","77.5227","3.7755","2.5170","18.4578"
"15.2800","3.7968","77.9491","3.7968","2.5312","18.5593"
"15.3600","3.8169","78.3524","3.8169","2.5446","18.6553"
"15.4400","3.8369","78.7463","3.8369","2.5579","18.7491"
"15.5200","3.8574","79.1621","3.8574","2.5716","18.8481"
"15.6000","3.8773","79.5541","3.8773","2.5849","18.9415"
"15.6800","3.8976","79.9785","3.8976","2.5984","19.0425"
"15.7600","3.9177","80.3653","3.9177","2.6118","19.1346"
"15.8400","3.9363","80.7374","3.9363","2.6242","19.2232"
"15.9200","3.9569","81.1619","3.9569","2.6379","19.3243"
"16.0000","3.9762","81.5308","3.9762","2.6508","19.4121"
"16.0800","3.9970","81.9598","3.9970","2.6647","19.5142"
"16.1600","4.0181","82.3843","4.0181","2.6787","19.6153"
"16.2400","4.0372","82.7527","4.0372","2.6915","19.7030"
"16.3200","4.0568","83.1517","4.0568","2.7046","19.7980"
"16.4000","4.0767","83.5403","4.0767","2.7178","19.8905"
"16.4800","4.0962","83.9476","4.0962","2.7308","19.9875"
"16.5600","4.1169","84.3637","4.1169","2.7446","20.0866"
"16.6400","4.1357","84.7121","4.1357","2.7571","20.1696"
"16.7200","4.1573","85.1530","4.1573","2.7716","20.2745"
"16.8000","4.1778","85.5664","4.1778","2.7852","20.3730"
"16.8800","4.1974","85.9579","4.1974","2.7983","20.4662"
"16.9600","4.2171","86.3499","4.2171","2.8114","20.5595"
"17.0400","4.2368","86.7373","4.2368","2.8245","20.6517"
"17.1200","4.2565","87.1386","4.2565","2.8376","20.7473"
"17.2000","4.2770","87.5501","4.2770","2.8514","20.8453"
"17.2800","4.2956","87.8988","4.2956","2.8637","20.9283"
"17.3600","4.3169","88.3383","4.3169","2.8779","21.0329"
"17.4400","4.3374","88.7471","4.3374","2.8916","21.1303"
"17.5200","4.3565","89.1243","4.3565","2.9043","21.2201"
"17.6000","4.3771","89.5298","4.3771","2.9180","21.3166"
"17.6800","4.3966","89.9175","4.3966","2.9311","21.4089"
"17.7600","4.4172","90.3316","4.4172","2.9448","21.5075"
"17.8400","4.4371","90.7288","4.4371","2.9580","21.6021"
"17.9200","4.4562","91.1040","4.4562","2.9708","21.6914"
"18.0000","4.4770","91.5366","4.4770","2.9847","21.7944"
"18.0800","4.4979","91.9497","4.4979","2.9986","21.8928"
"18.1600","4.5175","92.3377","4.5175","3.0117","21.9852"
"18.2400","4.5374","92.7350","4.5374","3.0249","22.0798"
"18.3200","4.5559","93.0923","4.5559","3.0372","22.1648"
"18.4000","4.5770","93.5270","4.5770","3.0513","22.2683"
"18.4800","4.5967","93.9161","4.5967","3.0644","22.3610"
"18.5600","4.6166","94.3170","4.6166","3.0777","22.4564"
"18.6400","4.6370","94.7349","4.6370","3.0913","22.5559"
"18.7200","4.6571","95.1283","4.6571","3.1047","22.6496"
"18.8000","4.6771","95.5180","4.6771","3.1181","22.7424"
"18.8800","4.6977","95.9349","4.6977","3.1318","22.8416"
"18.9600","4.7160","96.2821","4.7160","3.1440","22.9243"
"19.0400","4.7366","96.7092","4.7366","3.1578","23.0260"
"19.1200","4.7560","97.0808","4.7560","3.1707","23.1145"
"19.2000","4.7770","97.5195","4.7770","3.1846","23.2189"
"19.2800","4.7985","97.9684","4.7985","3.1990","23.3258"
"19.3600","4.8177","98.3243","4.8177","3.2118","23.4105"
"19.4400","4.8374","98.7060","4.8374","3.2249","23.5014"
"19.5200","4.8570","99.1059","4.8570","3.2380","23.5966"
"19.6000","4.8764","99.4862","4.8764","3.2509","23.6872"
"19.6800","4.8969","99.9109","4.8969","3.2646","23.7883"
"19.7600","4.9162","100.2738","4.9162","3.2775","23.8747"
"19.8400","4.9366","100.6888","4.9366","3.2911","23.9735"
"19.9200","4.9576","101.1049","4.9576","3.3051","24.0726"
"20.0000","4.9769","101.4831","4.9769","3.3179","24.1626"
"20.0800","4.9973","101.8821","4.9973","3.3315","24.2577"
"20.1600","5.0164","102.2583","5.0164","3.3443","24.3472"
"20.2400","5.0365","102.6583","5.0365","3.3577","24.4425"
"20.3200","5.0563","103.0647","5.0563","3.3709","24.5392"
"20.4000","5.0763","103.4524","5.0763","3.3842","24.6315"
"20.4800","5.0975","103.8865","5.0975","3.3983","24.7349"
"20.5600","5.1176","104.2651","5.1176","3.4117","24.8250"
"20.6400","5.1372","104.6611","5.1372","3.4248","24.9193"
"20.7200","5.1573","105.0648","5.1573","3.4382","25.0154"
"20.8000","5.1765","105.4287","5.1765","3.4510","25.1021"
"20.8800","5.1973","105.8453","5.1973","3.4649","25.2013"
"20.9600","5.2172","106.2361","5.2172","3.4781","25.2943"
"21.0400","5.2359","106.6084","5.2359","3.4906","25.3830"
"21.1200","5.2567","107.0184","5.2567","3.5045","25.4806"
"21.2000","5.2773","107.4309","5.2773","3.5182","25.5788"
"21.2800","5.2971","107.8251","5.2971","3.5314","25.6726"
"21.3600","5.3173","108.2154","5.3173","3.5449","25.7656"
"21.4400","5.3360","108.5690","5.3360","3.5573","25.8498"
"21.5200","5.3563","108.9803","5.3563","3.5709","25.9477"
"21.6000","5.3771","109.4126","5.3771","3.5847","26.0506"
"21.6800","5.3965","109.7941","5.3965","3.5977","26.1414"
"21.7600","5.4178","110.2283","5.4178","3.6119","26.2448"
"21.8400","5.4373","110.6002","5.4373","3.6249","26.3334"
"21.9200","5.4574","110.9921","5.4574","3.6383","26.4267"
"22.0000","5.4771","111.3727","5.4771","3.6514","26.5173"
"22.0800","5.4968","111.7667","5.4968","3.6645","26.6111"
"22.1600","5.5170","112.1571","5.5170","3.6780","26.7041"
"22.2400","5.5365","112.5410","5.5365","3.6910","26.7955"
"22.3200","5.5558","112.9208","5.5558","3.7039","26.8859"
"22.4000","5.5770","113.3521","5.5770","3.7180","26.9886"
"22.4800","5.5971","113.7534","5.5971","3.7314","27.0842"
"22.5600","5.6182","114.1595","5.6182","3.7454","27.1808"
"22.6400","5.6368","114.5206","5.6368","3.7579","27.2668"
"22.7200","5.6557","114.8846","5.6557","3.7704","27.3535"
"22.8000","5.6761","115.3045","5.6761","3.7841","27.4535"
"22.8800","5.6963","115.6865","5.6963","3.7975","27.5444"
"22.9600","5.7173","116.1114","5.7173","3.8115","27.6456"
"23.0400","5.7383","116.5248","5.7383","3.8256","27.7440"
"23.1200","5.7569","116.8748","5.7569","3.8379","27.8273"
"23.2000","5.7774","117.2932","5.7774","3.8516","27.9270"
"23.2800","5.7970","117.6750","5.7970","3.8647","28.0179"
"23.3600","5.8169","118.0546","5.8169","3.8779","28.1083"
"23.4400","5.8368","118.4470","5.8368","3.8912","28.2017"
"23.5200","5.8557","118.8045","5.8557","3.9038","28.2868"
"23.6000","5.8769","119.2379","5.8769","3.9180","28.3900"
"23.6800","5.8982","119.6533","5.8982","3.9321","28.4889"
"23.7600","5.9176","120.0318","5.9176","3.9450","28.5790"
"23.8400","5.9367","120.4009","5.9367","3.9578","28.6669"
"23.9200","5.9560","120.7601","5.9560","3.9707","28.7524"
"24.0000","5.9760","121.1604","5.9760","3.9840","28.8477"
"24.0800","5.9977","121.6032","5.9977","3.9985","28.9531"
"24.1600","6.0161","121.9507","6.0161","4.0107","29.0359"
"24.2400","6.0375","122.3757","6.0375","4.0250","29.1371"
"24.3200","6.0576","122.7723","6.0576","4.0384","29.2315"
"24.4000","6.0778","123.1676","6.0778","4.0519","29.3256"
"24.4800","6.0971","123.5390","6.0971","4.0647","29.4140"
"24.5600","6.1167","123.9119","6.1167","4.0778","29.5028"
"24.6400","6.1366","124.2948","6.1366","4.0911","29.5940"
"24.7200","6.1568","124.6892","6.1568","4.1045","29.6879"
"24.8000","6.1758","125.0550","6.1758","4.1172","29.7750"
"24.8800","6.1972","125.4874","6.1972","4.1314","29.8780"
"24.9600","6.2172","125.8631","6.2172","4.1448","29.9674"
"25.0400","6.2376","126.2621","6.2376","4.1584","30.0624"
"25.1200","6.2567","126.6265","6.2567","4.1711","30.1492"
"25.2000","6.2752","126.9742","6.2752","4.1835","30.2320"
"25.2800","6.2969","127.4127","6.2969","4.1979","30.3363"
"25.3600","6.3168","127.7956","6.3168","4.2112","30.4275"
"25.4400","6.3365","128.1817","6.3365","4.2243","30.5194"
"25.5200","6.3576","128.5981","6.3576","4.2384","30.6186"
"25.6000","6.3774","128.9672","6.3774","4.2516","30.7065"
"25.6800","6.3979","129.3705","6.3979","4.2653","30.8025"
"25.7600","6.4177","129.7475","6.4177","4.2785","30.8923"
"25.8400","6.4361","130.0928","6.4361","4.2908","30.9745"
"25.9200","6.4569","130.5039","6.4569","4.3046","31.0724"
"26.0000","6.4760","130.8547","6.4760","4.3173","31.1559"
"26.0800","6.4971","131.2813","6.4971","4.3314","31.2575"
"26.1600","6.5181","131.6972","6.5181","4.3454","31.3565"
"26.2400","6.5372","132.0419","6.5372","4.3582","31.4386"
"26.3200","6.5572","132.4372","6.5572","4.3715","31.5327"
"26.4000","6.5765","132.7989","6.5765","4.3844","31.6188"
"26.4800","6.5959","133.1695","6.5959","4.3973","31.7070"
"26.5600","6.6172","133.5981","6.6172","4.4115","31.8091"
"26.6400","6.6363","133.9321","6.6363","4.4242","31.8886"
"26.7200","6.6571","134.3585","6.6571","4.4381","31.9901"
"26.8000","6.6781","134.7683","6.6781","4.4521","32.0877"
"26.8800","6.6978","135.1550","6.6978","4.4652","32.1798"
"26.9600","6.7172","135.5159","6.7172","4.4781","32.2657"
"27.0400","6.7368","135.8916","6.7368","4.4912","32.3551"
"27.1200","6.7567","136.2730","6.7567","4.5045","32.4460"
"27.2000","6.7771","136.6554","6.7771","4.5181","32.5370"
"27.2800","6.7954","136.9990","6.7954","4.5303","32.6188"
"27.3600","6.8168","137.4323","6.8168","4.5446","32.7220"
"27.4400","6.8377","137.8372","6.8377","4.5584","32.8184"
"27.5200","6.8569","138.1956","6.8569","4.5713","32.9037"
"27.6000","6.8771","138.5970","6.8771","4.5848","32.9993"
"27.6800","6.8964","138.9501","6.8964","4.5976","33.0833"
"27.7600","6.9167","139.3433","6.9167","4.6111","33.1770"
"27.8400","6.9369","139.7373","6.9369","4.6246","33.2708"
"27.9200","6.9563","140.1007","6.9563","4.6375","33.3573"
"28.0000","6.9773","140.5182","6.9773","4.6515","33.4567"
"28.0800","6.9979","140.9105","6.9979","4.6652","33.5501"
"28.1600","7.0173","141.2780","7.0173","4.6782","33.6376"
"28.2400","7.0374","141.6629","7.0374","4.6916","33.7293"
"28.3200","7.0560","142.0078","7.0560","4.7040","33.8114"
"28.4000","7.0771","142.4161","7.0771","4.7180","33.9086"
"28.4800","7.0967","142.7967","7.0967","4.7311","33.9992"
"28.5600","7.1162","143.1827","7.1162","4.7442","34.0911"
"28.6400","7.1370","143.5829","7.1370","4.7580","34.1864"
"28.7200","7.1571","143.9580","7.1571","4.7714","34.2757"
"28.8000","7.1771","144.3408","7.1771","4.7848","34.3668"
"28.8800","7.1972","144.7161","7.1972","4.7981","34.4562"
"28.9600","7.2158","145.0771","7.2158","4.8105","34.5422"
"29.0400","7.2368","145.4821","7.2368","4.8245","34.6386"
"29.1200","7.2561","145.8396","7.2561","4.8374","34.7237"
"29.2000","7.2769","146.2532","7.2769","4.8512","34.8222"
"29.2800","7.2985","146.6845","7.2985","4.8657","34.9249"
"29.3600","7.3179","147.0474","7.3179","4.8786","35.0113"
"29.4400","7.3375","147.4050","7.3375","4.8917","35.0964"
"29.5200","7.3569","147.7599","7.3569","4.9046","35.1809"
"29.6000","7.3765","148.1404","7.3765","4.9177","35.2715"
"29.6800","7.3966","148.5203","7.3966","4.9311","35.3620"
"29.7600","7.4160","148.8740","7.4160","4.9440","35.4462"
"29.8400","7.4364","149.2700","7.4364","4.9576","35.5405"
"29.9200","7.4577","149.6845","7.4577","4.9718","35.6392"
"30.0000","7.4767","150.0407","7.4767","4.9845","35.7240"
"30.0800","7.4970","150.4184","7.4970","4.9980","35.8139"
"30.1600","7.5165","150.7865","7.5165","5.0110","35.9015"
"30.2400","7.5367","151.1598","7.5367","5.0244","35.9904"
"30.3200","7.5565","151.5373","7.5565","5.0377","36.0803"
"30.4000","7.5762","151.9030","7.5762","5.0508","36.1674"
"30.4800","7.5973","152.3144","7.5973","5.0649","36.2653"
"30.5600","7.6182","152.7183","7.6182","5.0788","36.3615"
"30.6400","7.6370","153.0678","7.6370","5.0914","36.4447"
"30.7200","7.6573","153.4551","7.6573","5.1048","36.5369"
"30.8000","7.6766","153.8144","7.6766","5.1177","36.6225"
"30.8800","7.6974","154.2042","7.6974","5.1316","36.7153"
"30.9600","7.7170","154.5660","7.7170","5.1446","36.8014"
"31.0400","7.7358","154.9168","7.7358","5.1572","36.8850"
"31.1200","7.7569","155.3328","7.7569","5.1713","36.9840"
"31.2000","7.7776","155.7212","7.7776","5.1851","37.0765"
"31.2800","7.7973","156.0823","7.7973","5.1982","37.1624"
"31.3600","7.8174","156.4690","7.8174","5.2116","37.2545"
"31.4400","7.8361","156.7928","7.8361","5.2240","37.3316"
"31.5200","7.8566","157.1907","7.8566","5.2377","37.4264"
"31.6000","7.8769","157.5723","7.8769","5.2513","37.5172"
"31.6800","7.8970","157.9564","7.8970","5.2646","37.6087"
"31.7600","7.9180","158.3566","7.9180","5.2787","37.7039"
"31.8400","7.9375","158.7167","7.9375","5.2917","37.7897"
"31.9200","7.9573","159.0719","7.9573","5.3049","37.8743"
"32.0000","7.9772","159.4443","7.9772","5.3181","37.9629"
"32.0800","7.9965","159.8077","7.9965","5.3310","38.0495"
"32.1600","8.0168","160.1922","8.0168","5.3445","38.1410"
"32.2400","8.0367","160.5626","8.0367","5.3578","38.2292"
"32.3200","8.0557","160.9103","8.0557","5.3705","38.3120"
"32.4000","8.0775","161.3385","8.0775","5.3850","38.4139"
"32.4800","8.0968","161.6801","8.0968","5.3979","38.4953"
"32.5600","8.1172","162.0632","8.1172","5.4115","38.5865"
"32.6400","8.1367","162.4153","8.1367","5.4245","38.6703"
"32.7200","8.1565","162.7807","8.1565","5.4376","38.7573"
"32.8000","8.1761","163.1493","8.1761","5.4508","38.8451"
"32.8800","8.1965","163.5361","8.1965","5.4644","38.9372"
"32.9600","8.2172","163.9305","8.2172","5.4781","39.0311"
"33.0400","8.2378","164.3125","8.2378","5.4919","39.1220"
"33.1200","8.2568","164.6656","8.2568","5.5045","39.2061"
"33.2000","8.2773","165.0478","8.2773","5.5182","39.2971"
"33.2800","8.2970","165.4057","8.2970","5.5313","39.3823"
"33.3600","8.3169","165.7720","8.3169","5.5446","39.4695"
"33.4400","8.3369","166.1460","8.3369","5.5579","39.5586"
"33.5200","8.3556","166.4935","8.3556","5.5704","39.6413"
"33.6000","8.3768","166.8870","8.3768","5.5845","39.7350"
"33.6800","8.3982","167.3026","8.3982","5.5988","39.8340"
"33.7600","8.4177","167.6646","8.4177","5.6118","39.9201"
"33.8400","8.4368","168.0072","8.4368","5.6246","40.0017"
"33.9200","8.4558","168.3472","8.4558","5.6372","40.0827"
"34.0000","8.4763","168.7288","8.4763","5.6508","40.1735"
"34.0800","8.4976","169.1360","8.4976","5.6650","40.2705"
"34.1600","8.5165","169.4792","8.5165","5.6776","40.3522"
"34.2400","8.5375","169.8833","8.5375","5.6916","40.4484"
"34.3200","8.5575","170.2491","8.5575","5.7050","40.5355"
"34.4000","8.5778","170.6192","8.5778","5.7185","40.6236"
"34.4800","8.5972","170.9680","8.5972","5.7315","40.7067"
"34.5600","8.6167","171.3189","8.6167","5.7444","40.7902"
"34.6400","8.6365","171.6749","8.6365","5.7577","40.8750"
"34.7200","8.6567","172.0455","8.6567","5.7711","40.9632"
"34.8000","8.6754","172.3850","8.6754","5.7836","41.0440"
"34.8800","8.6973","172.8202","8.6973","5.7982","41.1477"
"34.9600","8.7174","173.1698","8.7174","5.8116","41.2309"
"35.0400","8.7377","173.5480","8.7377","5.8251","41.3209"
"35.1200","8.7567","173.8685","8.7567","5.8378","41.3973"
"35.2000","8.7756","174.2170","8.7756","5.8504","41.4802"
"35.2800","8.7966","174.6071","8.7966","5.8644","41.5731"
"35.3600","8.8169","174.9792","8.8169","5.8779","41.6617"
"35.4400","8.8366","175.3418","8.8366","5.8910","41.7480"
"35.5200","8.8574","175.7317","8.8574","5.9049","41.8409"
"35.6000","8.8775","176.0859","8.8775","5.9184","41.9252"
"35.6800","8.8977","176.4587","8.8977","5.9318","42.0140"
"35.7600","8.9175","176.8025","8.9175","5.9450","42.0958"
"35.8400","8.9360","177.1349","8.9360","5.9573","42.1750"
"35.9200","8.9565","177.5189","8.9565","5.9710","42.2664"
"36.0000","8.9761","177.8779","8.9761","5.9840","42.3519"
"36.0800","8.9972","178.2714","8.9972","5.9981","42.4456"
"36.1600","9.0178","178.6472","9.0178","6.0119","42.5350"
"36.2400","9.0371","178.9969","9.0371","6.0247","42.6183"
"36.3200","9.0568","179.3368","9.0568","6.0379","42.6992"
"36.4000","9.0765","179.6938","9.0765","6.0510","42.7842"
"36.4800","9.0960","180.0515","9.0960","6.0640","42.8694"
"36.5600","9.1172","180.4523","9.1172","6.0782","42.9648"
"36.6400","9.1359","180.7714","9.1359","6.0906","43.0408"
"36.7200","9.1573","181.1752","9.1573","6.1049","43.1369"
"36.8000","9.1778","181.5499","9.1778","6.1185","43.2262"
"36.8800","9.1976","181.9118","9.1976","6.1317","43.3123"
"36.9600","9.2174","182.2682","9.2174","6.1449","43.3972"
"37.0400","9.2372","182.6125","9.2372","6.1582","43.4792"
"37.1200","9.2566","182.9621","9.2566","6.1710","43.5624"
"37.2000","9.2768","183.3291","9.2768","6.1845","43.6498"
"37.2800","9.2956","183.6579","9.2956","6.1970","43.7281"
"37.3600","9.3171","184.0565","9.3171","6.2114","43.8230"
"37.4400","9.3377","184.4400","9.3377","6.2251","43.9143"
"37.5200","9.3569","184.7748","9.3569","6.2379","43.9940"
"37.6000","9.3764","185.1120","9.3764","6.2510","44.0743"
"37.6800","9.3960","185.4646","9.3960","6.2640","44.1582"
"37.7600","9.4172","185.8443","9.4172","6.2781","44.2487"
"37.8400","9.4368","186.1877","9.4368","6.2912","44.3304"
"37.9200","9.4562","186.5391","9.4562","6.3041","44.4141"
"38.0000","9.4770","186.9246","9.4770","6.3180","44.5059"
"38.0800","9.4980","187.3167","9.4980","6.3320","44.5992"
"38.1600","9.5177","187.6586","9.5177","6.3452","44.6806"
"38.2400","9.5376","188.0076","9.5376","6.3584","44.7637"
"38.3200","9.5557","188.3134","9.5557","6.3705","44.8365"
"38.4000","9.5770","188.7131","9.5770","6.3847","44.9317"
"38.4800","9.5967","189.0468","9.5967","6.3978","45.0111"
"38.5600","9.6165","189.4164","9.6165","6.4110","45.0991"
"38.6400","9.6367","189.7758","9.6367","6.4245","45.1847"
"38.7200","9.6573","190.1472","9.6573","6.4382","45.2732"
"38.8000","9.6770","190.4949","9.6770","6.4513","45.3559"
"38.8800","9.6977","190.8683","9.6977","6.4651","45.4448"
"38.9600","9.7162","191.1858","9.7162","6.4775","45.5204"
"39.0400","9.7367","191.5598","9.7367","6.4911","45.6095"
"39.1200","9.7561","191.8990","9.7561","6.5041","45.6902"
"39.2000","9.7771","192.2831","9.7771","6.5181","45.7817"
"39.2800","9.7982","192.6682","9.7982","6.5322","45.8734"
"39.3600","9.8177","193.0113","9.8177","6.5452","45.9551"
"39.4400","9.8376","193.3412","9.8376","6.5584","46.0336"
"39.5200","9.8572","193.6944","9.8572","6.5714","46.1177"
"39.6000","9.8768","194.0442","9.8768","6.5846","46.2010"
"39.6800","9.8963","194.3941","9.8963","6.5976","46.2843"
"39.7600","9.9157","194.7183","9.9157","6.6105","46.3615"
"39.8400","9.9366","195.1052","9.9366","6.6244","46.4536"
"39.9200","9.9580","195.4858","9.9580","6.6387","46.5442"
"40.0000","9.9765","195.7985","9.9765","6.6510","46.6187"
"40.0800","9.9973","196.1797","9.9973","6.6649","46.7095"
"40.1600","10.0164","196.5136","10.0164","6.6776","46.7890"
"40.2400","10.0362","196.8696","10.0362","6.6908","46.8737"
"40.3200","10.0564","197.2328","10.0564","6.7043","46.9602"
"40.4000","10.0764","197.5768","10.0764","6.7176","47.0421"
"40.4800","10.0974","197.9500","10.0974","6.7316","47.1310"
"40.5600","10.1183","198.3194","10.1183","6.7455","47.2189"
"40.6400","10.1369","198.6392","10.1369","6.7580","47.2951"
"40.7200","10.1569","198.9866","10.1569","6.7713","47.3778"
"40.8000","10.1763","199.3130","10.1763","6.7842","47.4555"
"40.8800","10.1974","199.6931","10.1974","6.7983","47.5460"
"40.9600","10.2172","200.0396","10.2172","6.8114","47.6285"
"41.0400","10.2360","200.3631","10.2360","6.8240","47.7055"
"41.1200","10.2565","200.7302","10.2565","6.8377","47.7929"
"41.2000","10.2770","201.0966","10.2770","6.8513","47.8802"
"41.2800","10.2973","201.4637","10.2973","6.8649","47.9675"
"41.3600","10.3178","201.8453","10.3178","6.8786","48.0584"
"41.4400","10.3363","202.1392","10.3363","6.8908","48.1284"
"41.5200","10.3564","202.4865","10.3564","6.9042","48.2111"
"41.6000","10.3768","202.8469","10.3768","6.9179","48.2969"
"41.6800","10.3967","203.2224","10.3967","6.9311","48.3863"
"41.7600","10.4183","203.6067","10.4183","6.9455","48.4778"
"41.8400","10.4374","203.9234","10.4374","6.9582","48.5532"
"41.9200","10.4576","204.2779","10.4576","6.9717","48.6376"
"42.0000","10.4771","204.6207","10.4771","6.9847","48.7192"
"42.0800","10.4966","204.9608","10.4966","6.9978","48.8002"
"42.1600","10.5168","205.3048","10.5168","7.0112","48.8821"
"42.2400","10.5362","205.6411","10.5362","7.0242","48.9622"
"42.3200","10.5561","205.9923","10.5561","7.0374","49.0458"
"42.4000","10.5776","206.3732","10.5776","7.0517","49.1365"
"42.4800","10.5966","206.6929","10.5966","7.0644","49.2126"
"42.5600","10.6175","207.0645","10.6175","7.0784","49.3011"
"42.6400","10.6369","207.3884","10.6369","7.0913","49.3782"
"42.7200","10.6562","207.7278","10.6562","7.1041","49.4590"
"42.8000","10.6763","208.0792","10.6763","7.1175","49.5427"
"42.8800","10.6967","208.4324","10.6967","7.1311","49.6268"
"42.9600","10.7173","208.7955","10.7173","7.1449","49.7132"
"43.0400","10.7378","209.1469","10.7378","7.1585","49.7969"
"43.1200","10.7567","209.4639","10.7567","7.1711","49.8724"
"43.2000","10.7774","209.8339","10.7774","7.1849","49.9604"
"43.2800","10.7971","210.1712","10.7971","7.1981","50.0408"
"43.3600","10.8167","210.5076","10.8167","7.2111","50.1209"
"43.4400","10.8368","210.8594","10.8368","7.2245","50.2046"
"43.5200","10.8556","211.1691","10.8556","7.2371","50.2784"
"43.6000","10.8769","211.5645","10.8769","7.2513","50.3725"
"43.6800","10.8980","211.9272","10.8980","7.2653","50.4588"
"43.7600","10.9176","212.2575","10.9176","7.2784","50.5375"
"43.8400","10.9371","212.6021","10.9371","7.2914","50.6195"
"43.9200","10.9561","212.9088","10.9561","7.3041","50.6926"
"44.0000","10.9760","213.2513","10.9760","7.3174","50.7741"
"44.0800","10.9972","213.6237","10.9972","7.3315","50.8628"
"44.1600","11.0162","213.9402","11.0162","7.3441","50.9381"
"44.2400","11.0377","214.3305","11.0377","7.3585","51.0311"
"44.3200","11.0574","214.6575","11.0574","7.3716","51.1089"
"44.4000","11.0777","215.0146","11.0777","7.3852","51.1939"
"44.4800","11.0973","215.3389","11.0973","7.3982","51.2712"
"44.5600","11.1167","215.6543","11.1167","7.4111","51.3462"
"44.6400","11.1365","216.0026","11.1365","7.4243","51.4292"
"44.7200","11.1572","216.3718","11.1572","7.4382","51.5171"
"44.8000","11.1759","216.6827","11.1759","7.4506","51.5911"
"44.8800","11.1972","217.0648","11.1972","7.4648","51.6821"
"44.9600","11.2174","217.4078","11.2174","7.4783","51.7638"
"45.0400","11.2374","217.7457","11.2374","7.4916","51.8442"
"45.1200","11.2570","218.0610","11.2570","7.5046","51.9193"
"45.2000","11.2759","218.3737","11.2759","7.5173","51.9938"
"45.2800","11.2964","218.7173","11.2964","7.5309","52.0755"
"45.3600","11.3171","219.0884","11.3171","7.5447","52.1639"
"45.4400","11.3366","219.4116","11.3366","7.5577","52.2409"
"45.5200","11.3573","219.7842","11.3573","7.5715","52.3296"
"45.6000","11.3773","220.1198","11.3773","7.5849","52.4095"
"45.6800","11.3977","220.4657","11.3977","7.5985","52.4918"
"45.7600","11.4176","220.7861","11.4176","7.6117","52.5681"
"45.8400","11.4359","221.0924","11.4359","7.6240","52.6411"
"45.9200","11.4565","221.4556","11.4565","7.6377","52.7275"
"46.0000","11.4759","221.7766","11.4759","7.6506","52.8040"
"46.0800","11.4973","222.1475","11.4973","7.6649","52.8923"
"46.1600","11.5173","222.5007","11.5173","7.6782","52.9764"
"46.2400","11.5373","222.8281","11.5373","7.6915","53.0543"
"46.3200","11.5569","223.1568","11.5569","7.7046","53.1326"
"46.4000","11.5766","223.4842","11.5766","7.7177","53.2105"
"46.4800","11.5960","223.8247","11.5960","7.7307","53.2916"
"46.5600","11.6172","224.1923","11.6172","7.7448","53.3791"
"46.6400","11.6360","224.4848","11.6360","7.7573","53.4488"
"46.7200","11.6574","224.8788","11.6574","7.7716","53.5426"
"46.8000","11.6780","225.2188","11.6780","7.7853","53.6235"
"46.8800","11.6975","225.5474","11.6975","7.7983","53.7018"
"46.9600","11.7172","225.8740","11.7172","7.8114","53.7795"
"47.0400","11.7367","226.1897","11.7367","7.8245","53.8547"
"47.1200","11.7567","226.5306","11.7567","7.8378","53.9358"
"47.2000","11.7771","226.8820","11.7771","7.8514","54.0195"
"47.2800","11.7959","227.1835","11.7959","7.8639","54.0913"
"47.3600","11.8167","227.5376","11.8167","7.8778","54.1756"
"47.4400","11.8377","227.9016","11.8377","7.8918","54.2623"
"47.5200","11.8571","228.2211","11.8571","7.9047","54.3384"
"47.6000","11.8773","228.5802","11.8773","7.9182","54.4239"
"47.6800","11.8962","228.8757","11.8962","7.9308","54.4942"
"47.7600","11.9170","229.2292","11.9170","7.9447","54.5784"
"47.8400","11.9369","229.5608","11.9369","7.9579","54.6573"
"47.9200","11.9561","229.8778","11.9561","7.9708","54.7328"
"48.0000","11.9769","230.2520","11.9769","7.9846","54.8219"
"48.0800","11.9979","230.6001","11.9979","7.9986","54.9048"
"48.1600","12.0174","230.9174","12.0174","8.0116","54.9803"
"48.2400","12.0375","231.2431","12.0375","8.0250","55.0579"
"48.3200","12.0559","231.5313","12.0559","8.0373","55.1265"
"48.4000","12.0771","231.9038","12.0771","8.0514","55.2152"
"48.4800","12.0968","232.2223","12.0968","8.0646","55.2910"
"48.5600","12.1168","232.5513","12.1168","8.0778","55.3694"
"48.6400","12.1370","232.9144","12.1370","8.0913","55.4558"
"48.7200","12.1574","233.2314","12.1574","8.1049","55.5313"
"48.8000","12.1770","233.5528","12.1770","8.1180","55.6078"
"48.8800","12.1973","233.8933","12.1973","8.1316","55.6889"
"48.9600","12.2161","234.1926","12.2161","8.1440","55.7601"
"49.0400","12.2367","234.5454","12.2367","8.1578","55.8441"
"49.1200","12.2562","234.8643","12.2562","8.1708","55.9201"
"49.2000","12.2770","235.2194","12.2770","8.1846","56.0046"
"49.2800","12.2982","235.5848","12.2982","8.1988","56.0916"
"49.3600","12.3177","235.8917","12.3177","8.2118","56.1647"
"49.4400","12.3375","236.2095","12.3375","8.2250","56.2404"
"49.5200","12.3570","236.5231","12.3570","8.2380","56.3150"
"49.6000","12.3764","236.8378","12.3764","8.2509","56.3900"
"49.6800","12.3969","237.2001","12.3969","8.2646","56.4762"
"49.7600","12.4159","237.4773","12.4159","8.2773","56.5422"
"49.8400","12.4363","237.8257","12.4363","8.2909","56.6252"
"49.9200","12.4578","238.1847","12.4578","8.3052","56.7106"
"50.0000","12.4768","238.4991","12.4768","8.3178","56.7855"
"50.0800","12.4974","238.8390","12.4974","8.3316","56.8664"
"50.1600","12.5165","239.1398","12.5165","8.3444","56.9381"
"50.2400","12.5368","239.4618","12.5368","8.3579","57.0147"
"50.3200","12.5562","239.7852","12.5562","8.3708","57.0917"
"50.4000","12.5762","240.1147","12.5762","8.3842","57.1702"
"50.4800","12.5973","240.4783","12.5973","8.3982","57.2567"
"50.5600","12.6186","240.8336","12.6186","8.4124","57.3413"
"50.6400","12.6371","241.1157","12.6371","8.4247","57.4085"
"50.7200","12.6568","241.4315","12.6568","8.4378","57.4837"
"50.8000","12.6761","241.7427","12.6761","8.4508","57.5578"
"50.8800","12.6975","242.1040","12.6975","8.4650","57.6438"
"50.9600","12.7172","242.4192","12.7172","8.4782","57.7188"
"51.0400","12.7362","242.7175","12.7362","8.4908","57.7899"
"51.1200","12.7564","243.0506","12.7564","8.5043","57.8692"
"51.2000","12.7773","243.3965","12.7773","8.5182","57.9515"
"51.2800","12.7973","243.7271","12.7973","8.5315","58.0303"
"51.3600","12.8173","244.0500","12.8173","8.5448","58.1071"
"51.4400","12.8363","244.3453","12.8363","8.5575","58.1775"
"51.5200","12.8566","244.6841","12.8566","8.5711","58.2581"
"51.6000","12.8767","245.0011","12.8767","8.5845","58.3336"
"51.6800","12.8964","245.3394","12.8964","8.5976","58.4141"
"51.7600","12.9179","245.7113","12.9179","8.6120","58.5027"
"51.8400","12.9377","246.0179","12.9377","8.6251","58.5757"
"51.9200","12.9578","246.3429","12.9578","8.6385","58.6531"
"52.0000","12.9772","246.6516","12.9772","8.6515","58.7266"
"52.0800","12.9968","246.9652","12.9968","8.6645","58.8012"
"52.1600","13.0170","247.2949","13.0170","8.6780","58.8797"
"52.2400","13.0365","247.6029","13.0365","8.6910","58.9531"
"52.3200","13.0559","247.9173","13.0559","8.7039","59.0279"
"52.4000","13.0777","248.3059","13.0777","8.7184","59.1204"
"52.4800","13.0972","248.6091","13.0972","8.7315","59.1926"
"52.5600","13.1179","248.9432","13.1179","8.7453","59.2722"
"52.6400","13.1369","249.2327","13.1369","8.7580","59.3411"
"52.7200","13.1558","249.5254","13.1558","8.7705","59.4108"
"52.8000","13.1760","249.8612","13.1760","8.7840","59.4908"
"52.8800","13.1965","250.1844","13.1965","8.7977","59.5677"
"52.9600","13.2172","250.5183","13.2172","8.8114","59.6472"
"53.0400","13.2381","250.8586","13.2381","8.8254","59.7282"
"53.1200","13.2570","251.1522","13.2570","8.8380","59.7981"
"53.2000","13.2771","251.4715","13.2771","8.8514","59.8742"
"53.2800","13.2970","251.7950","13.2970","8.8647","59.9512"
"53.3600","13.3167","252.0970","13.3167","8.8778","60.0231"
"53.4400","13.3369","252.4176","13.3369","8.8913","60.0994"
"53.5200","13.3556","252.7052","13.3556","8.9037","60.1679"
"53.6000","13.3765","253.0439","13.3765","8.9177","60.2485"
"53.6800","13.3980","253.3933","13.3980","8.9320","60.3317"
"53.7600","13.4174","253.7033","13.4174","8.9449","60.4055"
"53.8400","13.4369","254.0134","13.4369","8.9579","60.4794"
"53.9200","13.4562","254.3012","13.4562","8.9708","60.5479"
"54.0000","13.4764","254.6318","13.4764","8.9842","60.6266"
"54.0800","13.4974","254.9746","13.4974","8.9982","60.7082"
"54.1600","13.5161","255.2579","13.5161","9.0108","60.7757"
"54.2400","13.5376","255.6162","13.5376","9.0250","60.8610"
"54.3200","13.5576","255.9335","13.5576","9.0384","60.9366"
"54.4000","13.5780","256.2543","13.5780","9.0520","61.0129"
"54.4800","13.5973","256.5516","13.5973","9.0649","61.0837"
"54.5600","13.6165","256.8381","13.6165","9.0777","61.1519"
"54.6400","13.6368","257.1646","13.6368","9.0912","61.2297"
"54.7200","13.6572","257.4767","13.6572","9.1048","61.3040"
"54.8000","13.6755","257.7529","13.6755","9.1170","61.3697"
"54.8800","13.6970","258.1188","13.6970","9.1313","61.4569"
"54.9600","13.7172","258.4252","13.7172","9.1448","61.5298"
"55.0400","13.7375","258.7413","13.7375","9.1584","61.6051"
"55.1200","13.7571","259.0467","13.7571","9.1714","61.6778"
"55.2000","13.7760","259.3230","13.7760","9.1840","61.7436"
"55.2800","13.7967","259.6595","13.7967","9.1978","61.8237"
"55.3600","13.8170","259.9731","13.8170","9.2113","61.8984"
"55.4400","13.8367","260.2715","13.8367","9.2245","61.9694"
"55.5200","13.8573","260.6085","13.8573","9.2382","62.0496"
"55.6000","13.8772","260.9011","13.8772","9.2514","62.1193"
"55.6800","13.8977","261.2135","13.8977","9.2651","62.1937"
"55.7600","13.9174","261.5140","13.9174","9.2783","62.2652"
"55.8400","13.9361","261.7950","13.9361","9.2907","62.3321"
"55.9200","13.9564","262.1165","13.9564","9.3043","62.4087"
"56.0000","13.9759","262.4103","13.9759","9.3172","62.4786"
"56.0800","13.9971","262.7445","13.9971","9.3314","62.5582"
"56.1600","14.0179","263.0827","14.0179","9.3453","62.6387"
"56.2400","14.0372","263.3691","14.0372","9.3581","62.7069"
"56.3200","14.0565","263.6570","14.0565","9.3710","62.7755"
"56.4000","14.0769","263.9638","14.0769","9.3846","62.8485"
"56.4800","14.0963","264.2646","14.0963","9.3975","62.9201"
"56.5600","14.1168","264.5807","14.1168","9.4112","62.9954"
"56.6400","14.1359","264.8625","14.1359","9.4239","63.0625"
"56.7200","14.1574","265.2051","14.1574","9.4382","63.1441"
"56.8000","14.1780","265.5334","14.1780","9.4520","63.2222"
"56.8800","14.1978","265.8333","14.1978","9.4652","63.2936"
"56.9600","14.2173","266.1253","14.2173","9.4782","63.3632"
"57.0400","14.2367","266.4039","14.2367","9.4911","63.4295"
"57.1200","14.2564","266.7024","14.2564","9.5043","63.5006"
"57.2000","14.2767","267.0130","14.2767","9.5178","63.5745"
"57.2800","14.2959","267.2913","14.2959","9.5306","63.6408"
"57.3600","14.3169","267.6247","14.3169","9.5446","63.7202"
"57.4400","14.3376","267.9341","14.3376","9.5584","63.7938"
"57.5200","14.3571","268.2363","14.3571","9.5714","63.8658"
"57.6000","14.3772","268.5421","14.3772","9.5848","63.9386"
"57.6800","14.3965","268.8147","14.3965","9.5977","64.0035"
"57.7600","14.4171","269.1304","14.4171","9.6114","64.0787"
"57.8400","14.4368","269.4169","14.4368","9.6245","64.1469"
"57.9200","14.4559","269.7052","14.4559","9.6373","64.2155"
"58.0000","14.4771","270.0377","14.4771","9.6514","64.2947"
"58.0800","14.4978","270.3525","14.4978","9.6652","64.3696"
"58.1600","14.5175","270.6378","14.5175","9.6783","64.4376"
"58.2400","14.5372","270.9311","14.5372","9.6915","64.5074"
"58.3200","14.5558","271.1884","14.5558","9.7039","64.5687"
"58.4000","14.5764","271.4970","14.5764","9.7176","64.6421"
"58.4800","14.5968","271.8036","14.5968","9.7312","64.7151"
"58.5600","14.6163","272.0945","14.6163","9.7442","64.7844"
"58.6400","14.6371","272.4080","14.6371","9.7581","64.8590"
"58.7200","14.6571","272.6870","14.6571","9.7714","64.9255"
"58.8000","14.6773","272.9900","14.6773","9.7849","64.9976"
"58.8800","14.6974","273.2845","14.6974","9.7983","65.0677"
"58.9600","14.7162","273.5570","14.7162","9.8108","65.1326"
"59.0400","14.7367","273.8632","14.7367","9.8245","65.2055"
"59.1200","14.7563","274.1423","14.7563","9.8376","65.2720"
"59.2000","14.7769","274.4418","14.7769","9.8513","65.3433"
"59.2800","14.7983","274.7711","14.7983","9.8655","65.4217"
"59.3600","14.8178","275.0465","14.8178","9.8785","65.4873"
"59.4400","14.8377","275.3243","14.8377","9.8918","65.5534"
"59.5200","14.8569","275.5991","14.8569","9.9046","65.6188"
"59.6000","14.8763","275.8734","14.8763","9.9175","65.6841"
"59.6800","14.8967","276.1794","14.8967","9.9312","65.7570"
"59.7600","14.9161","276.4413","14.9161","9.9441","65.8194"
"59.8400","14.9365","276.7429","14.9365","9.9577","65.8912"
"59.9200","14.9573","277.0507","14.9573","9.9715","65.9645"
"60.0000","14.9767","277.3284","14.9767","9.9844","66.0306"
"60.0800","14.9975","277.6248","14.9975","9.9983","66.1012"
"60.0910","15.0002","277.6623","15.0002","10.0001","66.1101"