File: data/instron_tests/509_NS_m1.is_comp_Exports/509_NS_m1_4_1.csv
Sample text inputs : Sample No.,Sample choice input : Leading Direction,Sample choice input : Mode,Specimen choice input : Direction,Specimen properties : Height,Specimen properties : Thickness,Specimen properties : Width,Test : Rate 1
,,,,(mm),(mm),(mm),(mm/min)
"509","Normal-Shear","Unimode","1","150.00","25.00","150.00","15.00"

Time,Displacement,Compressive displacement,Compressive strain (Displacement),Compressive stress,Force
(s),(mm),(mm),(%),(kPa),(N)
"0.0000","0.0000","0.0000","0.0000","-0.7803","-2.8870"
"0.0800","0.0010","0.0010","0.0007","-0.7769","-2.8745"
"0.1600","0.0076","0.0076","0.0051","-0.7581","-2.8051"
"0.2400","0.0275","0.0275","0.0183","-0.7206","-2.6664"
"0.3200","0.0477","0.0477","0.0318","-0.6854","-2.5360"
"0.4000","0.0663","0.0663","0.0442","-0.6477","-2.3967"
"0.4800","0.0869","0.0869","0.0579","-0.6139","-2.2715"
"0.5600","0.1087","0.1087","0.0724","-0.5746","-2.1261"
"0.6400","0.1276","0.1276","0.0851","-0.5374","-1.9884"
"0.7200","0.1473","0.1473","0.0982","-0.5055","-1.8703"
"0.8000","0.1663","0.1663","0.1108","-0.4749","-1.7570"
"0.8800","0.1867","0.1867","0.1244","-0.4399","-1.6278"
"0.9600","0.2071","0.2071","0.1380","-0.4078","-1.5089"
"1.0400","0.2261","0.2261","0.1507","-0.3792","-1.4030"
"1.1200","0.2470","0.2470","0.1647","-0.3425","-1.2673"
"1.2000","0.2676","0.2676","0.1784","-0.3142","-1.1626"
"1.2800","0.2870","0.2870","0.1913","-0.2831","-1.0473"
"1.3600","0.3073","0.3073","0.2049","-0.2502","-0.9256"
"1.4400","0.3265","0.3265","0.2176","-0.2233","-0.8262"
"1.5200","0.3470","0.3470","0.2313","-0.1927","-0.7132"
"1.6000","0.3671","0.3671","0.2447","-0.1648","-0.6098"
"1.6800","0.3860","0.3860","0.2573","-0.1375","-0.5086"
"1.7600","0.4075","0.4075","0.2717","-0.1064","-0.3935"
"1.8400","0.4277","0.4277","0.2852","-0.0786","-0.2909"
"1.9200","0.4477","0.4477","0.2985","-0.0529","-0.1958"
"2.0000","0.4674","0.4674","0.3116","-0.0263","-0.0972"
"2.0800","0.4863","0.4863","0.3242","-0.0049","-0.0182"
"2.1600","0.5069","0.5069","0.3379","0.0177","0.0654"
"2.2400","0.5269","0.5269","0.3513","0.0444","0.1643"
"2.3200","0.5458","0.5458","0.3639","0.0698","0.2584"
"2.4000","0.5667","0.5667","0.3778","0.0956","0.3536"
"2.4800","0.5867","0.5867","0.3911","0.1205","0.4460"
"2.5600","0.6080","0.6080","0.4053","0.1520","0.5622"
"2.6400","0.6276","0.6276","0.4184","0.1801","0.6664"
"2.7200","0.6461","0.6461","0.4307","0.2084","0.7710"
"2.8000","0.6664","0.6664","0.4443","0.2396","0.8867"
"2.8800","0.6867","0.6867","0.4578","0.2679","0.9911"
"2.9600","0.7075","0.7075","0.4716","0.2982","1.1035"
"3.0400","0.7281","0.7281","0.4854","0.3219","1.1912"
"3.1200","0.7470","0.7470","0.4980","0.3480","1.2876"
"3.2000","0.7675","0.7675","0.5117","0.3737","1.3826"
"3.2800","0.7866","0.7866","0.5244","0.3987","1.4750"
"3.3600","0.8065","0.8065","0.5377","0.4273","1.5810"
"3.4400","0.8271","0.8271","0.5514","0.4601","1.7025"
"3.5200","0.8459","0.8459","0.5639","0.4880","1.8058"
"3.6000","0.8668","0.8668","0.5779","0.5168","1.9121"
"3.6800","0.8874","0.8874","0.5916","0.5512","2.0394"
"3.7600","0.9073","0.9073","0.6048","0.5824","2.1550"
"3.8400","0.9274","0.9274","0.6183","0.6142","2.2724"
"3.9200","0.9471","0.9471","0.6314","0.6450","2.3864"
"4.0000","0.9664","0.9664","0.6443","0.6677","2.4706"
"4.0800","0.9873","0.9873","0.6582","0.7074","2.6175"
"4.1600","1.0060","1.0060","0.6707","0.7394","2.7358"
"4.2400","1.0276","1.0276","0.6850","0.7783","2.8797"
"4.3200","1.0481","1.0481","0.6987","0.8141","3.0120"
"4.4000","1.0674","1.0674","0.7116","0.8472","3.1347"
"4.4800","1.0867","1.0867","0.7244","0.8855","3.2765"
"4.5600","1.1069","1.1069","0.7379","0.9188","3.3996"
"4.6400","1.1270","1.1270","0.7514","0.9481","3.5081"
"4.7200","1.1470","1.1470","0.7647","0.9826","3.6356"
"4.8000","1.1654","1.1654","0.7769","1.0199","3.7736"
"4.8800","1.1873","1.1873","0.7915","1.0555","3.9054"
"4.9600","1.2077","1.2077","0.8051","1.0930","4.0442"
"5.0400","1.2271","1.2271","0.8181","1.1277","4.1726"
"5.1200","1.2468","1.2468","0.8312","1.1636","4.3053"
"5.2000","1.2662","1.2662","0.8441","1.1979","4.4321"
"5.2800","1.2868","1.2868","0.8579","1.2363","4.5744"
"5.3600","1.3073","1.3073","0.8715","1.2650","4.6806"
"5.4400","1.3270","1.3270","0.8847","1.3034","4.8227"
"5.5200","1.3478","1.3478","0.8986","1.3414","4.9630"
"5.6000","1.3673","1.3673","0.9115","1.3770","5.0948"
"5.6800","1.3874","1.3874","0.9250","1.4133","5.2294"
"5.7600","1.4076","1.4076","0.9384","1.4491","5.3616"
"5.8400","1.4262","1.4262","0.9508","1.4852","5.4951"
"5.9200","1.4467","1.4467","0.9644","1.5195","5.6222"
"6.0000","1.4660","1.4660","0.9773","1.5575","5.7628"
"6.0800","1.4868","1.4868","0.9912","1.5923","5.8915"
"6.1600","1.5075","1.5075","1.0050","1.6272","6.0208"
"6.2400","1.5274","1.5274","1.0183","1.6628","6.1523"
"6.3200","1.5471","1.5471","1.0314","1.6993","6.2873"
"6.4000","1.5671","1.5671","1.0447","1.7359","6.4230"
"6.4800","1.5856","1.5856","1.0571","1.7745","6.5655"
"6.5600","1.6071","1.6071","1.0714","1.8144","6.7132"
"6.6400","1.6268","1.6268","1.0845","1.8485","6.8395"
"6.7200","1.6477","1.6477","1.0985","1.8867","6.9807"
"6.8000","1.6681","1.6681","1.1121","1.9210","7.1078"
"6.8800","1.6873","1.6873","1.1248","1.9537","7.2286"
"6.9600","1.7072","1.7072","1.1381","1.9916","7.3688"
"7.0400","1.7272","1.7272","1.1514","2.0294","7.5087"
"7.1200","1.7470","1.7470","1.1647","2.0672","7.6487"
"7.2000","1.7666","1.7666","1.1778","2.1056","7.7908"
"7.2800","1.7855","1.7855","1.1903","2.1401","7.9182"
"7.3600","1.8068","1.8068","1.2045","2.1798","8.0654"
"7.4400","1.8280","1.8280","1.2187","2.2217","8.2204"
"7.5200","1.8472","1.8472","1.2315","2.2529","8.3356"
"7.6000","1.8672","1.8672","1.2448","2.2921","8.4808"
"7.6800","1.8861","1.8861","1.2574","2.3267","8.6090"
"7.7600","1.9070","1.9070","1.2714","2.3662","8.7549"
"7.8400","1.9274","1.9274","1.2849","2.4059","8.9017"
"7.9200","1.9467","1.9467","1.2978","2.4439","9.0424"
"8.0000","1.9671","1.9671","1.3114","2.4830","9.1871"
"8.0800","1.9877","1.9877","1.3251","2.5239","9.3384"
"8.1600","2.0075","2.0075","1.3383","2.5630","9.4830"
"8.2400","2.0278","2.0278","1.3519","2.5963","9.6065"
"8.3200","2.0462","2.0462","1.3642","2.6295","9.7291"
"8.4000","2.0672","2.0672","1.3781","2.6705","9.8807"
"8.4800","2.0863","2.0863","1.3909","2.7050","10.0085"
"8.5600","2.1058","2.1058","1.4039","2.7472","10.1646"
"8.6400","2.1267","2.1267","1.4178","2.7871","10.3123"
"8.7200","2.1478","2.1478","1.4319","2.8289","10.4669"
"8.8000","2.1674","2.1674","1.4450","2.8659","10.6039"
"8.8800","2.1872","2.1872","1.4582","2.9049","10.7480"
"8.9600","2.2062","2.2062","1.4708","2.9411","10.8820"
"9.0400","2.2271","2.2271","1.4848","2.9749","11.0070"
"9.1200","2.2468","2.2468","1.4979","3.0150","11.1556"
"9.2000","2.2667","2.2667","1.5111","3.0538","11.2992"
"9.2800","2.2880","2.2880","1.5254","3.0969","11.4586"
"9.3600","2.3074","2.3074","1.5383","3.1340","11.5958"
"9.4400","2.3280","2.3280","1.5520","3.1722","11.7371"
"9.5200","2.3472","2.3472","1.5648","3.2094","11.8748"
"9.6000","2.3662","2.3662","1.5775","3.2464","12.0116"
"9.6800","2.3864","2.3864","1.5909","3.2873","12.1629"
"9.7600","2.4065","2.4065","1.6044","3.3194","12.2818"
"9.8400","2.4268","2.4268","1.6179","3.3591","12.4286"
"9.9200","2.4479","2.4479","1.6319","3.3985","12.5746"
"10.0000","2.4660","2.4660","1.6440","3.4345","12.7078"
"10.0800","2.4872","2.4872","1.6581","3.4767","12.8636"
"10.1600","2.5068","2.5068","1.6712","3.5170","13.0129"
"10.2400","2.5269","2.5269","1.6846","3.5536","13.1483"
"10.3200","2.5468","2.5468","1.6979","3.5955","13.3035"
"10.4000","2.5668","2.5668","1.7112","3.6318","13.4377"
"10.4800","2.5872","2.5872","1.7248","3.6672","13.5686"
"10.5600","2.6084","2.6084","1.7389","3.7087","13.7222"
"10.6400","2.6274","2.6274","1.7516","3.7460","13.8602"
"10.7200","2.6477","2.6477","1.7651","3.7875","14.0137"
"10.8000","2.6662","2.6662","1.7775","3.8201","14.1342"
"10.8800","2.6867","2.6867","1.7911","3.8609","14.2855"
"10.9600","2.7067","2.7067","1.8044","3.8990","14.4263"
"11.0400","2.7259","2.7259","1.8173","3.9364","14.5646"
"11.1200","2.7473","2.7473","1.8316","3.9777","14.7174"
"11.2000","2.7676","2.7676","1.8451","4.0148","14.8546"
"11.2800","2.7870","2.7870","1.8580","4.0510","14.9887"
"11.3600","2.8073","2.8073","1.8715","4.0912","15.1374"
"11.4400","2.8269","2.8269","1.8846","4.1253","15.2637"
"11.5200","2.8471","2.8471","1.8981","4.1648","15.4096"
"11.6000","2.8671","2.8671","1.9114","4.2003","15.5411"
"11.6800","2.8866","2.8866","1.9244","4.2431","15.6995"
"11.7600","2.9078","2.9078","1.9385","4.2845","15.8526"
"11.8400","2.9274","2.9274","1.9516","4.3221","15.9918"
"11.9200","2.9477","2.9477","1.9652","4.3628","16.1422"
"12.0000","2.9673","2.9673","1.9782","4.3981","16.2731"
"12.0800","2.9861","2.9861","1.9907","4.4344","16.4072"
"12.1600","3.0069","3.0069","2.0046","4.4702","16.5397"
"12.2400","3.0269","3.0269","2.0180","4.5088","16.6827"
"12.3200","3.0457","3.0457","2.0305","4.5479","16.8273"
"12.4000","3.0669","3.0669","2.0446","4.5922","16.9913"
"12.4800","3.0869","3.0869","2.0579","4.6271","17.1202"
"12.5600","3.1079","3.1079","2.0719","4.6684","17.2729"
"12.6400","3.1277","3.1277","2.0851","4.7057","17.4111"
"12.7200","3.1464","3.1464","2.0976","4.7434","17.5507"
"12.8000","3.1663","3.1663","2.1109","4.7794","17.6836"
"12.8800","3.1865","3.1865","2.1243","4.8201","17.8344"
"12.9600","3.2070","3.2070","2.1380","4.8597","17.9808"
"13.0400","3.2282","3.2282","2.1521","4.8973","18.1199"
"13.1200","3.2471","3.2471","2.1647","4.9384","18.2721"
"13.2000","3.2674","3.2674","2.1783","4.9695","18.3871"
"13.2800","3.2869","3.2869","2.1913","5.0082","18.5302"
"13.3600","3.3067","3.3067","2.2045","5.0477","18.6763"
"13.4400","3.3269","3.3269","2.2179","5.0875","18.8236"
"13.5200","3.3459","3.3459","2.2306","5.1236","18.9574"
"13.6000","3.3667","3.3667","2.2445","5.1633","19.1041"
"13.6800","3.3876","3.3876","2.2584","5.2011","19.2441"
"13.7600","3.4069","3.4069","2.2713","5.2407","19.3905"
"13.8400","3.4275","3.4275","2.2850","5.2805","19.5379"
"13.9200","3.4468","3.4468","2.2979","5.3170","19.6728"
"14.0000","3.4661","3.4661","2.3107","5.3539","19.8094"
"14.0800","3.4868","3.4868","2.3246","5.3940","19.9578"
"14.1600","3.5065","3.5065","2.3376","5.4340","20.1057"
"14.2400","3.5279","3.5279","2.3519","5.4722","20.2471"
"14.3200","3.5479","3.5479","2.3652","5.5102","20.3878"
"14.4000","3.5675","3.5675","2.3783","5.5492","20.5319"
"14.4800","3.5873","3.5873","2.3916","5.5908","20.6861"
"14.5600","3.6067","3.6067","2.4045","5.6210","20.7975"
"14.6400","3.6267","3.6267","2.4178","5.6604","20.9434"
"14.7200","3.6471","3.6471","2.4314","5.6969","21.0785"
"14.8000","3.6657","3.6657","2.4438","5.7369","21.2266"
"14.8800","3.6868","3.6868","2.4579","5.7771","21.3753"
"14.9600","3.7072","3.7072","2.4715","5.8148","21.5147"
"15.0400","3.7276","3.7276","2.4851","5.8520","21.6525"
"15.1200","3.7472","3.7472","2.4981","5.8905","21.7950"
"15.2000","3.7659","3.7659","2.5106","5.9265","21.9282"
"15.2800","3.7867","3.7867","2.5244","5.9658","22.0735"
"15.3600","3.8073","3.8073","2.5382","6.0064","22.2237"
"15.4400","3.8272","3.8272","2.5514","6.0457","22.3691"
"15.5200","3.8479","3.8479","2.5653","6.0876","22.5242"
"15.6000","3.8675","3.8675","2.5783","6.1229","22.6547"
"15.6800","3.8873","3.8873","2.5915","6.1587","22.7874"
"15.7600","3.9073","3.9073","2.6049","6.1962","22.9259"
"15.8400","3.9263","3.9263","2.6176","6.2356","23.0718"
"15.9200","3.9468","3.9468","2.6312","6.2758","23.2204"
"16.0000","3.9655","3.9655","2.6436","6.3090","23.3433"
"16.0800","3.9864","3.9864","2.6576","6.3502","23.4959"
"16.1600","4.0080","4.0080","2.6720","6.3955","23.6632"
"16.2400","4.0277","4.0277","2.6851","6.4334","23.8035"
"16.3200","4.0471","4.0471","2.6980","6.4651","23.9208"
"16.4000","4.0669","4.0669","2.7113","6.5002","24.0508"
"16.4800","4.0858","4.0858","2.7239","6.5401","24.1985"
"16.5600","4.1071","4.1071","2.7381","6.5824","24.3547"
"16.6400","4.1264","4.1264","2.7510","6.6157","24.4779"
"16.7200","4.1476","4.1476","2.7650","6.6560","24.6273"
"16.8000","4.1681","4.1681","2.7787","6.6953","24.7726"
"16.8800","4.1871","4.1871","2.7914","6.7335","24.9140"
"16.9600","4.2071","4.2071","2.8047","6.7737","25.0627"
"17.0400","4.2268","4.2268","2.8179","6.8078","25.1887"
"17.1200","4.2465","4.2465","2.8310","6.8462","25.3309"
"17.2000","4.2665","4.2665","2.8444","6.8860","25.4783"
"17.2800","4.2857","4.2857","2.8571","6.9207","25.6067"
"17.3600","4.3069","4.3069","2.8713","6.9614","25.7570"
"17.4400","4.3283","4.3283","2.8855","7.0009","25.9034"
"17.5200","4.3470","4.3470","2.8980","7.0382","26.0412"
"17.6000","4.3669","4.3669","2.9112","7.0766","26.1834"
"17.6800","4.3863","4.3863","2.9242","7.1134","26.3197"
"17.7600","4.4071","4.4071","2.9381","7.1509","26.4583"
"17.8400","4.4272","4.4272","2.9515","7.1919","26.6101"
"17.9200","4.4463","4.4463","2.9642","7.2268","26.7392"
"18.0000","4.4670","4.4670","2.9780","7.2659","26.8838"
"18.0800","4.4878","4.4878","2.9919","7.3046","27.0271"
"18.1600","4.5075","4.5075","3.0050","7.3439","27.1725"
"18.2400","4.5278","4.5278","3.0185","7.3830","27.3171"
"18.3200","4.5464","4.5464","3.0309","7.4164","27.4406"
"18.4000","4.5668","4.5668","3.0446","7.4546","27.5822"
"18.4800","4.5862","4.5862","3.0575","7.4917","27.7194"
"18.5600","4.6058","4.6058","3.0705","7.5263","27.8473"
"18.6400","4.6275","4.6275","3.0850","7.5699","28.0088"
"18.7200","4.6476","4.6476","3.0984","7.6031","28.1314"
"18.8000","4.6672","4.6672","3.1115","7.6445","28.2845"
"18.8800","4.6874","4.6874","3.1249","7.6794","28.4137"
"18.9600","4.7059","4.7059","3.1373","7.7145","28.5436"
"19.0400","4.7273","4.7273","3.1515","7.7560","28.6974"
"19.1200","4.7471","4.7471","3.1647","7.7963","28.8464"
"19.2000","4.7669","4.7669","3.1779","7.8331","28.9826"
"19.2800","4.7877","4.7877","3.1918","7.8722","29.1271"
"19.3600","4.8072","4.8072","3.2048","7.9065","29.2542"
"19.4400","4.8277","4.8277","3.2185","7.9462","29.4011"
"19.5200","4.8477","4.8477","3.2318","7.9833","29.5381"
"19.6000","4.8661","4.8661","3.2441","8.0206","29.6764"
"19.6800","4.8862","4.8862","3.2575","8.0577","29.8135"
"19.7600","4.9061","4.9061","3.2708","8.0977","29.9616"
"19.8400","4.9267","4.9267","3.2845","8.1382","30.1115"
"19.9200","4.9479","4.9479","3.2986","8.1788","30.2614"
"20.0000","4.9668","4.9668","3.3112","8.2123","30.3854"
"20.0800","4.9871","4.9871","3.3248","8.2508","30.5279"
"20.1600","5.0067","5.0067","3.3378","8.2899","30.6726"
"20.2400","5.0272","5.0272","3.3515","8.3262","30.8070"
"20.3200","5.0469","5.0469","3.3646","8.3650","30.9503"
"20.4000","5.0661","5.0661","3.3774","8.4014","31.0852"
"20.4800","5.0869","5.0869","3.3913","8.4410","31.2317"
"20.5600","5.1085","5.1085","3.4057","8.4832","31.3879"
"20.6400","5.1274","5.1274","3.4183","8.5189","31.5201"
"20.7200","5.1475","5.1475","3.4317","8.5573","31.6622"
"20.8000","5.1663","5.1663","3.4442","8.5918","31.7896"
"20.8800","5.1863","5.1863","3.4575","8.6262","31.9169"
"20.9600","5.2066","5.2066","3.4711","8.6639","32.0565"
"21.0400","5.2260","5.2260","3.4840","8.7024","32.1990"
"21.1200","5.2471","5.2471","3.4981","8.7413","32.3428"
"21.2000","5.2677","5.2677","3.5118","8.7806","32.4882"
"21.2800","5.2871","5.2871","3.5247","8.8200","32.6339"
"21.3600","5.3075","5.3075","3.5383","8.8593","32.7793"
"21.4400","5.3270","5.3270","3.5514","8.8951","32.9118"
"21.5200","5.3470","5.3470","3.5647","8.9328","33.0514"
"21.6000","5.3674","5.3674","3.5783","8.9688","33.1846"
"21.6800","5.3861","5.3861","3.5907","9.0081","33.3300"
"21.7600","5.4074","5.4074","3.6049","9.0493","33.4825"
"21.8400","5.4278","5.4278","3.6185","9.0880","33.6256"
"21.9200","5.4480","5.4480","3.6320","9.1258","33.7653"
"22.0000","5.4675","5.4675","3.6450","9.1621","33.8999"
"22.0800","5.4862","5.4862","3.6574","9.1989","34.0360"
"22.1600","5.5069","5.5069","3.6713","9.2401","34.1884"
"22.2400","5.5270","5.5270","3.6847","9.2741","34.3141"
"22.3200","5.5458","5.5458","3.6972","9.3103","34.4481"
"22.4000","5.5671","5.5671","3.7114","9.3538","34.6090"
"22.4800","5.5869","5.5869","3.7246","9.3891","34.7397"
"22.5600","5.6079","5.6079","3.7386","9.4291","34.8875"
"22.6400","5.6274","5.6274","3.7516","9.4660","35.0242"
"22.7200","5.6462","5.6462","3.7641","9.5025","35.1592"
"22.8000","5.6663","5.6663","3.7775","9.5411","35.3020"
"22.8800","5.6865","5.6865","3.7910","9.5803","35.4471"
"22.9600","5.7073","5.7073","3.8048","9.6184","35.5882"
"23.0400","5.7289","5.7289","3.8192","9.6601","35.7424"
"23.1200","5.7472","5.7472","3.8314","9.6935","35.8658"
"23.2000","5.7672","5.7672","3.8448","9.7302","36.0017"
"23.2800","5.7869","5.7869","3.8580","9.7662","36.1348"
"23.3600","5.8066","5.8066","3.8710","9.8035","36.2729"
"23.4400","5.8267","5.8267","3.8845","9.8429","36.4186"
"23.5200","5.8452","5.8452","3.8968","9.8775","36.5467"
"23.6000","5.8662","5.8662","3.9108","9.9170","36.6930"
"23.6800","5.8877","5.8877","3.9251","9.9563","36.8382"
"23.7600","5.9075","5.9075","3.9383","9.9951","36.9819"
"23.8400","5.9275","5.9275","3.9517","10.0349","37.1292"
"23.9200","5.9467","5.9467","3.9645","10.0691","37.2558"
"24.0000","5.9665","5.9665","3.9776","10.1066","37.3944"
"24.0800","5.9875","5.9875","3.9917","10.1455","37.5385"
"24.1600","6.0062","6.0062","4.0042","10.1818","37.6727"
"24.2400","6.0276","6.0276","4.0184","10.2226","37.8234"
"24.3200","6.0479","6.0479","4.0319","10.2606","37.9644"
"24.4000","6.0676","6.0676","4.0451","10.2976","38.1013"
"24.4800","6.0869","6.0869","4.0579","10.3356","38.2418"
"24.5600","6.1068","6.1068","4.0712","10.3711","38.3731"
"24.6400","6.1271","6.1271","4.0847","10.4074","38.5074"
"24.7200","6.1472","6.1472","4.0981","10.4452","38.6471"
"24.8000","6.1656","6.1656","4.1104","10.4818","38.7826"
"24.8800","6.1872","6.1872","4.1248","10.5232","38.9357"
"24.9600","6.2076","6.2076","4.1384","10.5659","39.0940"
"25.0400","6.2271","6.2271","4.1514","10.5981","39.2131"
"25.1200","6.2465","6.2465","4.1643","10.6362","39.3538"
"25.2000","6.2661","6.2661","4.1774","10.6736","39.4922"
"25.2800","6.2870","6.2870","4.1914","10.7125","39.6364"
"25.3600","6.3074","6.3074","4.2049","10.7494","39.7729"
"25.4400","6.3268","6.3268","4.2179","10.7885","39.9174"
"25.5200","6.3477","6.3477","4.2318","10.8306","40.0731"
"25.6000","6.3671","6.3671","4.2447","10.8632","40.1938"
"25.6800","6.3872","6.3872","4.2582","10.9005","40.3320"
"25.7600","6.4077","6.4077","4.2718","10.9378","40.4698"
"25.8400","6.4264","6.4264","4.2843","10.9744","40.6053"
"25.9200","6.4465","6.4465","4.2977","11.0110","40.7406"
"26.0000","6.4656","6.4656","4.3104","11.0483","40.8785"
"26.0800","6.4865","6.4865","4.3243","11.0848","41.0136"
"26.1600","6.5074","6.5074","4.3383","11.1265","41.1681"
"26.2400","6.5276","6.5276","4.3517","11.1649","41.3101"
"26.3200","6.5472","6.5472","4.3648","11.2027","41.4499"
"26.4000","6.5674","6.5674","4.3782","11.2381","41.5810"
"26.4800","6.5861","6.5861","4.3907","11.2753","41.7185"
"26.5600","6.6070","6.6070","4.4047","11.3159","41.8688"
"26.6400","6.6266","6.6266","4.4178","11.3509","41.9981"
"26.7200","6.6479","6.6479","4.4320","11.3900","42.1429"
"26.8000","6.6680","6.6680","4.4453","11.4286","42.2858"
"26.8800","6.6873","6.6873","4.4582","11.4654","42.4221"
"26.9600","6.7072","6.7072","4.4715","11.5033","42.5623"
"27.0400","6.7274","6.7274","4.4849","11.5412","42.7025"
"27.1200","6.7468","6.7468","4.4979","11.5789","42.8418"
"27.2000","6.7668","6.7668","4.5112","11.6154","42.9768"
"27.2800","6.7855","6.7855","4.5237","11.6528","43.1153"
"27.3600","6.8069","6.8069","4.5379","11.6906","43.2552"
"27.4400","6.8282","6.8282","4.5521","11.7298","43.4004"
"27.5200","6.8469","6.8469","4.5646","11.7662","43.5351"
"27.6000","6.8668","6.8668","4.5779","11.8044","43.6761"
"27.6800","6.8860","6.8860","4.5907","11.8400","43.8078"
"27.7600","6.9074","6.9074","4.6049","11.8783","43.9498"
"27.8400","6.9273","6.9273","4.6182","11.9169","44.0925"
"27.9200","6.9464","6.9464","4.6309","11.9518","44.2217"
"28.0000","6.9671","6.9671","4.6447","11.9935","44.3760"
"28.0800","6.9878","6.9878","4.6585","12.0305","44.5127"
"28.1600","7.0076","7.0076","4.6717","12.0675","44.6496"
"28.2400","7.0279","7.0279","4.6853","12.1055","44.7905"
"28.3200","7.0462","7.0462","4.6975","12.1350","44.8995"
"28.4000","7.0664","7.0664","4.7109","12.1730","45.0402"
"28.4800","7.0865","7.0865","4.7243","12.2119","45.1842"
"28.5600","7.1061","7.1061","4.7374","12.2504","45.3264"
"28.6400","7.1268","7.1268","4.7512","12.2917","45.4794"
"28.7200","7.1475","7.1475","4.7650","12.3282","45.6145"
"28.8000","7.1677","7.1677","4.7784","12.3653","45.7517"
"28.8800","7.1877","7.1877","4.7918","12.4006","45.8823"
"28.9600","7.2064","7.2064","4.8043","12.4376","46.0192"
"29.0400","7.2272","7.2272","4.8181","12.4753","46.1587"
"29.1200","7.2469","7.2469","4.8312","12.5132","46.2987"
"29.2000","7.2669","7.2669","4.8446","12.5537","46.4489"
"29.2800","7.2877","7.2877","4.8585","12.5928","46.5934"
"29.3600","7.3073","7.3073","4.8715","12.6247","46.7115"
"29.4400","7.3277","7.3277","4.8851","12.6636","46.8554"
"29.5200","7.3476","7.3476","4.8984","12.6997","46.9890"
"29.6000","7.3662","7.3662","4.9108","12.7361","47.1237"
"29.6800","7.3863","7.3863","4.9242","12.7711","47.2532"
"29.7600","7.4063","7.4063","4.9376","12.8116","47.4029"
"29.8400","7.4270","7.4270","4.9513","12.8494","47.5429"
"29.9200","7.4480","7.4480","4.9653","12.8870","47.6820"
"30.0000","7.4667","7.4667","4.9778","12.9246","47.8211"
"30.0800","7.4870","7.4870","4.9913","12.9611","47.9562"
"30.1600","7.5067","7.5067","5.0045","12.9991","48.0968"
"30.2400","7.5269","7.5269","5.0179","13.0387","48.2430"
"30.3200","7.5467","7.5467","5.0311","13.0770","48.3847"
"30.4000","7.5663","7.5663","5.0442","13.1110","48.5108"
"30.4800","7.5871","7.5871","5.0580","13.1488","48.6505"
"30.5600","7.6085","7.6085","5.0723","13.1887","48.7982"
"30.6400","7.6274","7.6274","5.0849","13.2274","48.9416"
"30.7200","7.6474","7.6474","5.0983","13.2665","49.0861"
"30.8000","7.6663","7.6663","5.1109","13.3004","49.2115"
"30.8800","7.6861","7.6861","5.1241","13.3368","49.3462"
"30.9600","7.7065","7.7065","5.1377","13.3736","49.4822"
"31.0400","7.7263","7.7263","5.1509","13.4107","49.6195"
"31.1200","7.7473","7.7473","5.1649","13.4494","49.7630"
"31.2000","7.7676","7.7676","5.1784","13.4874","49.9034"
"31.2800","7.7867","7.7867","5.1912","13.5236","50.0375"
"31.3600","7.8071","7.8071","5.2047","13.5622","50.1800"
"31.4400","7.8265","7.8265","5.2176","13.5970","50.3089"
"31.5200","7.8471","7.8471","5.2314","13.6353","50.4505"
"31.6000","7.8674","7.8674","5.2449","13.6751","50.5978"
"31.6800","7.8861","7.8861","5.2574","13.7104","50.7284"
"31.7600","7.9077","7.9077","5.2718","13.7505","50.8769"
"31.8400","7.9278","7.9278","5.2852","13.7899","51.0226"
"31.9200","7.9480","7.9480","5.2986","13.8249","51.1523"
"32.0000","7.9669","7.9669","5.3112","13.8607","51.2846"
"32.0800","7.9862","7.9862","5.3242","13.8948","51.4106"
"32.1600","8.0069","8.0069","5.3379","13.9340","51.5559"
"32.2400","8.0271","8.0271","5.3514","13.9733","51.7013"
"32.3200","8.0458","8.0458","5.3638","14.0072","51.8267"
"32.4000","8.0668","8.0668","5.3779","14.0500","51.9851"
"32.4800","8.0870","8.0870","5.3913","14.0865","52.1200"
"32.5600","8.1078","8.1078","5.4052","14.1226","52.2536"
"32.6400","8.1274","8.1274","5.4183","14.1573","52.3821"
"32.7200","8.1463","8.1463","5.4309","14.1949","52.5213"
"32.8000","8.1664","8.1664","5.4443","14.2327","52.6609"
"32.8800","8.1867","8.1867","5.4578","14.2709","52.8023"
"32.9600","8.2073","8.2073","5.4715","14.3074","52.9373"
"33.0400","8.2283","8.2283","5.4856","14.3521","53.1029"
"33.1200","8.2476","8.2476","5.4984","14.3881","53.2361"
"33.2000","8.2673","8.2673","5.5115","14.4251","53.3727"
"33.2800","8.2869","8.2869","5.5246","14.4594","53.4998"
"33.3600","8.3065","8.3065","5.5377","14.4961","53.6355"
"33.4400","8.3271","8.3271","5.5514","14.5346","53.7779"
"33.5200","8.3461","8.3461","5.5641","14.5698","53.9084"
"33.6000","8.3666","8.3666","5.5777","14.6060","54.0422"
"33.6800","8.3874","8.3874","5.5916","14.6481","54.1980"
"33.7600","8.4074","8.4074","5.6049","14.6862","54.3390"
"33.8400","8.4273","8.4273","5.6182","14.7236","54.4773"
"33.9200","8.4469","8.4469","5.6312","14.7596","54.6106"
"34.0000","8.4664","8.4664","5.6443","14.7927","54.7331"
"34.0800","8.4870","8.4870","5.6580","14.8322","54.8792"
"34.1600","8.5065","8.5065","5.6710","14.8677","55.0104"
"34.2400","8.5279","8.5279","5.6853","14.9103","55.1680"
"34.3200","8.5480","8.5480","5.6987","14.9449","55.2961"
"34.4000","8.5672","8.5672","5.7114","14.9833","55.4383"
"34.4800","8.5868","8.5868","5.7245","15.0206","55.5761"
"34.5600","8.6070","8.6070","5.7380","15.0592","55.7189"
"34.6400","8.6271","8.6271","5.7514","15.0952","55.8522"
"34.7200","8.6473","8.6473","5.7648","15.1307","55.9838"
"34.8000","8.6657","8.6657","5.7771","15.1675","56.1197"
"34.8800","8.6869","8.6869","5.7913","15.2073","56.2668"
"34.9600","8.7075","8.7075","5.8050","15.2476","56.4163"
"35.0400","8.7277","8.7277","5.8185","15.2840","56.5509"
"35.1200","8.7468","8.7468","5.8312","15.3174","56.6744"
"35.2000","8.7659","8.7659","5.8439","15.3527","56.8049"
"35.2800","8.7868","8.7868","5.8579","15.3928","56.9532"
"35.3600","8.8072","8.8072","5.8715","15.4322","57.0991"
"35.4400","8.8270","8.8270","5.8847","15.4707","57.2416"
"35.5200","8.8477","8.8477","5.8985","15.5109","57.3904"
"35.6000","8.8675","8.8675","5.9117","15.5452","57.5172"
"35.6800","8.8874","8.8874","5.9249","15.5805","57.6478"
"35.7600","8.9077","8.9077","5.9384","15.6189","57.7898"
"35.8400","8.9262","8.9262","5.9508","15.6530","57.9162"
"35.9200","8.9469","8.9469","5.9646","15.6906","58.0553"
"36.0000","8.9661","8.9661","5.9774","15.7291","58.1975"
"36.0800","8.9862","8.9862","5.9908","15.7689","58.3450"
"36.1600","9.0073","9.0073","6.0049","15.8093","58.4945"
"36.2400","9.0276","9.0276","6.0184","15.8440","58.6226"
"36.3200","9.0471","9.0471","6.0314","15.8787","58.7513"
"36.4000","9.0671","9.0671","6.0448","15.9159","58.8890"
"36.4800","9.0860","9.0860","6.0573","15.9517","59.0213"
"36.5600","9.1071","9.1071","6.0714","15.9937","59.1767"
"36.6400","9.1266","9.1266","6.0844","16.0290","59.3072"
"36.7200","9.1474","9.1474","6.0983","16.0683","59.4528"
"36.8000","9.1680","9.1680","6.1120","16.1067","59.5948"
"36.8800","9.1872","9.1872","6.1248","16.1423","59.7266"
"36.9600","9.2071","9.2071","6.1381","16.1805","59.8677"
"37.0400","9.2271","9.2271","6.1514","16.2157","59.9983"
"37.1200","9.2465","9.2465","6.1643","16.2530","60.1361"
"37.2000","9.2664","9.2664","6.1776","16.2902","60.2736"
"37.2800","9.2855","9.2855","6.1903","16.3238","60.3980"
"37.3600","9.3073","9.3073","6.2049","16.3665","60.5562"
"37.4400","9.3281","9.3281","6.2187","16.4032","60.6918"
"37.5200","9.3471","9.3471","6.2314","16.4406","60.8301"
"37.6000","9.3673","9.3673","6.2449","16.4784","60.9700"
"37.6800","9.3860","9.3860","6.2573","16.5136","61.1003"
"37.7600","9.4068","9.4068","6.2712","16.5483","61.2289"
"37.8400","9.4272","9.4272","6.2848","16.5860","61.3682"
"37.9200","9.4464","9.4464","6.2976","16.6228","61.5045"
"38.0000","9.4670","9.4670","6.3113","16.6617","61.6482"
"38.0800","9.4879","9.4879","6.3252","16.7016","61.7959"
"38.1600","9.5077","9.5077","6.3385","16.7386","61.9328"
"38.2400","9.5280","9.5280","6.3520","16.7756","62.0698"
"38.3200","9.5460","9.5460","6.3640","16.8086","62.1918"
"38.4000","9.5664","9.5664","6.3776","16.8450","62.3265"
"38.4800","9.5865","9.5865","6.3910","16.8809","62.4592"
"38.5600","9.6060","9.6060","6.4040","16.9214","62.6092"
"38.6400","9.6275","9.6275","6.4183","16.9644","62.7684"
"38.7200","9.6475","9.6475","6.4317","16.9990","62.8965"
"38.8000","9.6674","9.6674","6.4450","17.0350","63.0296"
"38.8800","9.6873","9.6873","6.4582","17.0710","63.1625"
"38.9600","9.7060","9.7060","6.4707","17.1059","63.2918"
"39.0400","9.7268","9.7268","6.4845","17.1473","63.4451"
"39.1200","9.7469","9.7469","6.4979","17.1852","63.5852"
"39.2000","9.7666","9.7666","6.5111","17.2188","63.7097"
"39.2800","9.7878","9.7878","6.5252","17.2627","63.8721"
"39.3600","9.8075","9.8075","6.5384","17.2983","64.0038"
"39.4400","9.8277","9.8277","6.5518","17.3338","64.1350"
"39.5200","9.8473","9.8473","6.5649","17.3695","64.2670"
"39.6000","9.8664","9.8664","6.5776","17.4076","64.4082"
"39.6800","9.8865","9.8865","6.5910","17.4461","64.5505"
"39.7600","9.9064","9.9064","6.6043","17.4817","64.6821"
"39.8400","9.9269","9.9269","6.6179","17.5210","64.8276"
"39.9200","9.9481","9.9481","6.6321","17.5612","64.9764"
"40.0000","9.9668","9.9668","6.6445","17.5942","65.0984"
"40.0800","9.9872","9.9872","6.6581","17.6304","65.2324"
"40.1600","10.0065","10.0065","6.6710","17.6662","65.3648"
"40.2400","10.0266","10.0266","6.6844","17.7054","65.5098"
"40.3200","10.0467","10.0467","6.6978","17.7432","65.6498"
"40.4000","10.0665","10.0665","6.7110","17.7796","65.7844"
"40.4800","10.0870","10.0870","6.7246","17.8165","65.9212"
"40.5600","10.1085","10.1085","6.7390","17.8559","66.0667"
"40.6400","10.1275","10.1275","6.7517","17.8946","66.2102"
"40.7200","10.1475","10.1475","6.7650","17.9348","66.3587"
"40.8000","10.1664","10.1664","6.7776","17.9656","66.4728"
"40.8800","10.1866","10.1866","6.7911","18.0031","66.6113"
"40.9600","10.2070","10.2070","6.8046","18.0437","66.7617"
"41.0400","10.2261","10.2261","6.8174","18.0780","66.8887"
"41.1200","10.2469","10.2469","6.8312","18.1171","67.0333"
"41.2000","10.2674","10.2674","6.8449","18.1575","67.1829"
"41.2800","10.2870","10.2870","6.8580","18.1962","67.3261"
"41.3600","10.3073","10.3073","6.8716","18.2314","67.4562"
"41.4400","10.3268","10.3268","6.8845","18.2672","67.5887"
"41.5200","10.3470","10.3470","6.8980","18.3063","67.7334"
"41.6000","10.3673","10.3673","6.9116","18.3415","67.8635"
"41.6800","10.3862","10.3862","6.9242","18.3797","68.0048"
"41.7600","10.4073","10.4073","6.9382","18.4204","68.1554"
"41.8400","10.4270","10.4270","6.9514","18.4558","68.2866"
"41.9200","10.4480","10.4480","6.9653","18.4933","68.4254"
"42.0000","10.4675","10.4675","6.9783","18.5304","68.5624"
"42.0800","10.4865","10.4865","6.9910","18.5654","68.6920"
"42.1600","10.5068","10.5068","7.0045","18.6021","68.8277"
"42.2400","10.5270","10.5270","7.0180","18.6410","68.9718"
"42.3200","10.5458","10.5458","7.0305","18.6750","69.0976"
"42.4000","10.5669","10.5669","7.0446","18.7189","69.2599"
"42.4800","10.5868","10.5868","7.0578","18.7515","69.3804"
"42.5600","10.6079","10.6079","7.0719","18.7921","69.5307"
"42.6400","10.6273","10.6273","7.0849","18.8275","69.6616"
"42.7200","10.6464","10.6464","7.0976","18.8649","69.8002"
"42.8000","10.6665","10.6665","7.1110","18.9008","69.9331"
"42.8800","10.6865","10.6865","7.1243","18.9395","70.0760"
"42.9600","10.7070","10.7070","7.1380","18.9778","70.2178"
"43.0400","10.7285","10.7285","7.1523","19.0168","70.3621"
"43.1200","10.7475","10.7475","7.1650","19.0534","70.4976"
"43.2000","10.7673","10.7673","7.1782","19.0877","70.6244"
"43.2800","10.7869","10.7869","7.1913","19.1261","70.7664"
"43.3600","10.8066","10.8066","7.2044","19.1633","70.9041"
"43.4400","10.8272","10.8272","7.2181","19.2037","71.0537"
"43.5200","10.8457","10.8457","7.2304","19.2349","71.1693"
"43.6000","10.8664","10.8664","7.2443","19.2752","71.3182"
"43.6800","10.8877","10.8877","7.2585","19.3155","71.4672"
"43.7600","10.9075","10.9075","7.2717","19.3519","71.6021"
"43.8400","10.9272","10.9272","7.2848","19.3913","71.7479"
"43.9200","10.9468","10.9468","7.2979","19.4265","71.8782"
"44.0000","10.9666","10.9666","7.3110","19.4652","72.0211"
"44.0800","10.9871","10.9871","7.3247","19.4997","72.1490"
"44.1600","11.0059","11.0059","7.3372","19.5349","72.2789"
"44.2400","11.0274","11.0274","7.3516","19.5777","72.4374"
"44.3200","11.0481","11.0481","7.3654","19.6164","72.5808"
"44.4000","11.0677","11.0677","7.3785","19.6507","72.7077"
"44.4800","11.0868","11.0868","7.3912","19.6882","72.8464"
"44.5600","11.1068","11.1068","7.4045","19.7243","72.9798"
"44.6400","11.1270","11.1270","7.4180","19.7604","73.1133"
"44.7200","11.1470","11.1470","7.4313","19.7968","73.2483"
"44.8000","11.1657","11.1657","7.4438","19.8326","73.3805"
"44.8800","11.1870","11.1870","7.4580","19.8760","73.5412"
"44.9600","11.2079","11.2079","7.4719","19.9163","73.6903"
"45.0400","11.2277","11.2277","7.4851","19.9515","73.8207"
"45.1200","11.2467","11.2467","7.4978","19.9835","73.9390"
"45.2000","11.2656","11.2656","7.5104","20.0195","74.0722"
"45.2800","11.2867","11.2867","7.5245","20.0607","74.2245"
"45.3600","11.3075","11.3075","7.5383","20.1000","74.3700"
"45.4400","11.3272","11.3272","7.5514","20.1389","74.5140"
"45.5200","11.3478","11.3478","7.5652","20.1785","74.6605"
"45.6000","11.3673","11.3673","7.5782","20.2154","74.7971"
"45.6800","11.3873","11.3873","7.5915","20.2519","74.9320"
"45.7600","11.4077","11.4077","7.6051","20.2873","75.0628"
"45.8400","11.4265","11.4265","7.6177","20.3244","75.2003"
"45.9200","11.4469","11.4469","7.6313","20.3620","75.3394"
"46.0000","11.4656","11.4656","7.6437","20.3971","75.4693"
"46.0800","11.4865","11.4865","7.6577","20.4358","75.6125"
"46.1600","11.5072","11.5072","7.6715","20.4779","75.7683"
"46.2400","11.5276","11.5276","7.6851","20.5142","75.9025"
"46.3200","11.5473","11.5473","7.6982","20.5538","76.0491"
"46.4000","11.5671","11.5671","7.7114","20.5867","76.1709"
"46.4800","11.5854","11.5854","7.7236","20.6221","76.3016"
"46.5600","11.6066","11.6066","7.7378","20.6651","76.4610"
"46.6400","11.6268","11.6268","7.7512","20.6978","76.5818"
"46.7200","11.6477","11.6477","7.7652","20.7387","76.7333"
"46.8000","11.6679","11.6679","7.7786","20.7740","76.8638"
"46.8800","11.6874","11.6874","7.7916","20.8131","77.0084"
"46.9600","11.7069","11.7069","7.8046","20.8486","77.1398"
"47.0400","11.7271","11.7271","7.8181","20.8866","77.2804"
"47.1200","11.7468","11.7468","7.8312","20.9239","77.4184"
"47.2000","11.7668","11.7668","7.8445","20.9632","77.5639"
"47.2800","11.7857","11.7857","7.8572","20.9969","77.6885"
"47.3600","11.8073","11.8073","7.8715","21.0384","77.8420"
"47.4400","11.8282","11.8282","7.8855","21.0777","77.9874"
"47.5200","11.8471","11.8470","7.8980","21.1109","78.1104"
"47.6000","11.8667","11.8667","7.9112","21.1508","78.2581"
"47.6800","11.8862","11.8862","7.9241","21.1859","78.3879"
"47.7600","11.9074","11.9074","7.9382","21.2226","78.5235"
"47.8400","11.9274","11.9274","7.9516","21.2619","78.6691"
"47.9200","11.9466","11.9466","7.9644","21.2983","78.8037"
"48.0000","11.9668","11.9668","7.9778","21.3366","78.9453"
"48.0800","11.9880","11.9880","7.9920","21.3758","79.0905"
"48.1600","12.0077","12.0077","8.0051","21.4129","79.2278"
"48.2400","12.0278","12.0278","8.0185","21.4512","79.3694"
"48.3200","12.0462","12.0462","8.0308","21.4854","79.4960"
"48.4000","12.0670","12.0670","8.0447","21.5228","79.6344"
"48.4800","12.0862","12.0862","8.0575","21.5596","79.7706"
"48.5600","12.1059","12.1059","8.0706","21.5977","79.9115"
"48.6400","12.1271","12.1271","8.0847","21.6390","80.0643"
"48.7200","12.1475","12.1475","8.0983","21.6787","80.2113"
"48.8000","12.1670","12.1670","8.1114","21.7110","80.3305"
"48.8800","12.1875","12.1875","8.1250","21.7489","80.4708"
"48.9600","12.2058","12.2058","8.1372","21.7826","80.5955"
"49.0400","12.2268","12.2268","8.1512","21.8244","80.7504"
"49.1200","12.2468","12.2468","8.1645","21.8590","80.8784"
"49.2000","12.2668","12.2668","8.1779","21.9002","81.0309"
"49.2800","12.2878","12.2878","8.1918","21.9405","81.1799"
"49.3600","12.3071","12.3071","8.2047","21.9736","81.3024"
"49.4400","12.3279","12.3279","8.2186","22.0117","81.4431"
"49.5200","12.3474","12.3474","8.2316","22.0477","81.5766"
"49.6000","12.3664","12.3664","8.2443","22.0865","81.7200"
"49.6800","12.3866","12.3866","8.2577","22.1256","81.8646"
"49.7600","12.4064","12.4064","8.2709","22.1597","81.9911"
"49.8400","12.4267","12.4267","8.2844","22.1977","82.1315"
"49.9200","12.4479","12.4479","8.2986","22.2390","82.2843"
"50.0000","12.4664","12.4664","8.3109","22.2735","82.4119"
"50.0800","12.4874","12.4874","8.3250","22.3125","82.5561"
"50.1600","12.5069","12.5069","8.3379","22.3506","82.6972"
"50.2400","12.5270","12.5270","8.3513","22.3880","82.8355"
"50.3200","12.5468","12.5468","8.3645","22.4249","82.9720"
"50.4000","12.5665","12.5665","8.3777","22.4604","83.1036"
"50.4800","12.5871","12.5871","8.3914","22.4990","83.2464"
"50.5600","12.6085","12.6085","8.4057","22.5399","83.3976"
"50.6400","12.6274","12.6274","8.4182","22.5772","83.5357"
"50.7200","12.6472","12.6472","8.4315","22.6122","83.6650"
"50.8000","12.6663","12.6663","8.4442","22.6484","83.7992"
"50.8800","12.6869","12.6869","8.4579","22.6863","83.9393"
"50.9600","12.7069","12.7069","8.4712","22.7230","84.0753"
"51.0400","12.7260","12.7260","8.4840","22.7605","84.2140"
"51.1200","12.7470","12.7470","8.4980","22.7996","84.3585"
"51.2000","12.7677","12.7677","8.5118","22.8370","84.4969"
"51.2800","12.7868","12.7868","8.5246","22.8736","84.6324"
"51.3600","12.8070","12.8070","8.5380","22.9148","84.7846"
"51.4400","12.8264","12.8264","8.5509","22.9481","84.9079"
"51.5200","12.8470","12.8470","8.5647","22.9885","85.0575"
"51.6000","12.8675","12.8675","8.5783","23.0232","85.1857"
"51.6800","12.8862","12.8862","8.5908","23.0599","85.3217"
"51.7600","12.9076","12.9076","8.6051","23.1018","85.4767"
"51.8400","12.9275","12.9275","8.6183","23.1366","85.6054"
"51.9200","12.9478","12.9478","8.6318","23.1749","85.7471"
"52.0000","12.9673","12.9673","8.6449","23.2113","85.8820"
"52.0800","12.9864","12.9864","8.6576","23.2463","86.0111"
"52.1600","13.0068","13.0068","8.6712","23.2839","86.1505"
"52.2400","13.0271","13.0271","8.6847","23.3226","86.2937"
"52.3200","13.0460","13.0460","8.6973","23.3593","86.4293"
"52.4000","13.0673","13.0673","8.7116","23.4008","86.5829"
"52.4800","13.0867","13.0867","8.7244","23.4341","86.7063"
"52.5600","13.1080","13.1080","8.7386","23.4743","86.8549"
"52.6400","13.1273","13.1273","8.7515","23.5085","86.9813"
"52.7200","13.1467","13.1467","8.7645","23.5478","87.1268"
"52.8000","13.1666","13.1666","8.7778","23.5864","87.2698"
"52.8800","13.1865","13.1865","8.7910","23.6235","87.4071"
"52.9600","13.2073","13.2073","8.8048","23.6640","87.5567"
"53.0400","13.2285","13.2285","8.8190","23.7030","87.7011"
"53.1200","13.2472","13.2472","8.8314","23.7381","87.8311"
"53.2000","13.2674","13.2674","8.8449","23.7722","87.9571"
"53.2800","13.2870","13.2870","8.8580","23.8105","88.0989"
"53.3600","13.3063","13.3062","8.8708","23.8467","88.2326"
"53.4400","13.3268","13.3268","8.8845","23.8871","88.3822"
"53.5200","13.3460","13.3460","8.8973","23.9197","88.5028"
"53.6000","13.3668","13.3668","8.9112","23.9606","88.6541"
"53.6800","13.3873","13.3873","8.9249","24.0011","88.8041"
"53.7600","13.4073","13.4073","8.9382","24.0386","88.9428"
"53.8400","13.4273","13.4273","8.9515","24.0767","89.0837"
"53.9200","13.4468","13.4468","8.9646","24.1119","89.2140"
"54.0000","13.4663","13.4663","8.9775","24.1477","89.3466"
"54.0800","13.4870","13.4870","8.9913","24.1865","89.4899"
"54.1600","13.5060","13.5060","9.0040","24.2206","89.6162"
"54.2400","13.5278","13.5278","9.0186","24.2646","89.7790"
"54.3200","13.5483","13.5483","9.0322","24.3021","89.9176"
"54.4000","13.5674","13.5674","9.0449","24.3382","90.0513"
"54.4800","13.5867","13.5867","9.0578","24.3754","90.1888"
"54.5600","13.6066","13.6066","9.0711","24.4107","90.3195"
"54.6400","13.6273","13.6273","9.0849","24.4523","90.4734"
"54.7200","13.6474","13.6474","9.0983","24.4881","90.6059"
"54.8000","13.6657","13.6657","9.1105","24.5194","90.7219"
"54.8800","13.6868","13.6868","9.1246","24.5623","90.8805"
"54.9600","13.7075","13.7075","9.1383","24.6023","91.0287"
"55.0400","13.7279","13.7279","9.1520","24.6412","91.1725"
"55.1200","13.7475","13.7475","9.1650","24.6746","91.2961"
"55.2000","13.7658","13.7658","9.1772","24.7076","91.4181"
"55.2800","13.7866","13.7866","9.1911","24.7468","91.5631"
"55.3600","13.8073","13.8073","9.2048","24.7841","91.7010"
"55.4400","13.8273","13.8273","9.2182","24.8230","91.8450"
"55.5200","13.8479","13.8479","9.2319","24.8646","91.9990"
"55.6000","13.8672","13.8672","9.2448","24.8976","92.1211"
"55.6800","13.8875","13.8875","9.2583","24.9356","92.2617"
"55.7600","13.9074","13.9074","9.2716","24.9697","92.3879"
"55.8400","13.9262","13.9262","9.2842","25.0058","92.5213"
"55.9200","13.9470","13.9470","9.2980","25.0471","92.6741"
"56.0000","13.9660","13.9660","9.3106","25.0787","92.7913"
"56.0800","13.9862","13.9862","9.3242","25.1177","92.9355"
"56.1600","14.0074","14.0074","9.3383","25.1577","93.0837"
"56.2400","14.0273","14.0273","9.3515","25.1952","93.2222"
"56.3200","14.0474","14.0474","9.3649","25.2301","93.3513"
"56.4000","14.0672","14.0672","9.3782","25.2684","93.4930"
"56.4800","14.0858","14.0858","9.3905","25.3030","93.6212"
"56.5600","14.1069","14.1069","9.4046","25.3459","93.7797"
"56.6400","14.1265","14.1265","9.4177","25.3828","93.9163"
"56.7200","14.1476","14.1476","9.4317","25.4206","94.0564"
"56.8000","14.1679","14.1679","9.4453","25.4582","94.1952"
"56.8800","14.1871","14.1871","9.4581","25.4984","94.3441"
"56.9600","14.2073","14.2073","9.4715","25.5328","94.4713"
"57.0400","14.2272","14.2272","9.4848","25.5664","94.5957"
"57.1200","14.2468","14.2468","9.4978","25.6046","94.7372"
"57.2000","14.2666","14.2666","9.5111","25.6422","94.8762"
"57.2800","14.2856","14.2856","9.5238","25.6763","95.0021"
"57.3600","14.3072","14.3072","9.5381","25.7204","95.1655"
"57.4400","14.3280","14.3280","9.5520","25.7579","95.3043"
"57.5200","14.3471","14.3471","9.5647","25.7932","95.4349"
"57.6000","14.3669","14.3669","9.5780","25.8287","95.5662"
"57.6800","14.3862","14.3862","9.5908","25.8652","95.7014"
"57.7600","14.4073","14.4073","9.6048","25.9050","95.8484"
"57.8400","14.4276","14.4276","9.6184","25.9418","95.9846"
"57.9200","14.4468","14.4468","9.6312","25.9785","96.1204"
"58.0000","14.4669","14.4669","9.6446","26.0169","96.2625"
"58.0800","14.4878","14.4878","9.6586","26.0556","96.4057"
"58.1600","14.5078","14.5078","9.6719","26.0942","96.5485"
"58.2400","14.5274","14.5274","9.6849","26.1293","96.6785"
"58.3200","14.5462","14.5462","9.6974","26.1635","96.8050"
"58.4000","14.5665","14.5665","9.7110","26.2019","96.9470"
"58.4800","14.5865","14.5865","9.7243","26.2370","97.0770"
"58.5600","14.6061","14.6061","9.7374","26.2752","97.2183"
"58.6400","14.6272","14.6272","9.7515","26.3194","97.3817"
"58.7200","14.6474","14.6474","9.7650","26.3538","97.5091"
"58.8000","14.6672","14.6672","9.7781","26.3881","97.6361"
"58.8800","14.6872","14.6872","9.7915","26.4254","97.7740"
"58.9600","14.7059","14.7059","9.8039","26.4615","97.9074"
"59.0400","14.7272","14.7272","9.8181","26.5003","98.0510"
"59.1200","14.7467","14.7467","9.8311","26.5350","98.1794"
"59.2000","14.7665","14.7665","9.8443","26.5730","98.3202"
"59.2800","14.7876","14.7876","9.8584","26.6149","98.4752"
"59.3600","14.8074","14.8074","9.8716","26.6490","98.6012"
"59.4400","14.8278","14.8278","9.8852","26.6863","98.7394"
"59.5200","14.8473","14.8473","9.8982","26.7200","98.8641"
"59.6000","14.8659","14.8659","9.9106","26.7549","98.9932"
"59.6800","14.8865","14.8865","9.9243","26.7943","99.1389"
"59.7600","14.9063","14.9063","9.9375","26.8300","99.2711"
"59.8400","14.9266","14.9266","9.9511","26.8673","99.4089"
"59.9200","14.9478","14.9478","9.9652","26.9078","99.5588"
"60.0000","14.9666","14.9666","9.9777","26.9433","99.6900"
"60.0800","14.9873","14.9873","9.9915","26.9824","99.8347"
"60.1310","15.0000","15.0000","10.0000","27.0059","99.9218"