File: data/instron_tests/509_NS_m1.is_comp_Exports/509_NS_m1_1_1.csv
Sample text inputs : Sample No.,Sample choice input : Leading Direction,Sample choice input : Mode,Specimen choice input : Direction,Specimen properties : Height,Specimen properties : Thickness,Specimen properties : Width,Test : Rate 1
,,,,(mm),(mm),(mm),(mm/min)
"509","Normal-Shear","Unimode","1","150.00","25.00","150.00","15.00"

Time,Displacement,Compressive displacement,Compressive strain (Displacement),Compressive stress,Force
(s),(mm),(mm),(%),(kPa),(N)
"0.0000","0.0000","0.0000","0.0000","-0.4499","-1.6648"
"0.0800","0.0015","0.0015","0.0010","-0.4420","-1.6355"
"0.1600","0.0188","0.0188","0.0125","-0.3366","-1.2453"
"0.2400","0.0378","0.0378","0.0252","-0.2193","-0.8115"
"0.3200","0.0576","0.0576","0.0384","-0.1087","-0.4021"
"0.4000","0.0783","0.0783","0.0522","0.0054","0.0198"
"0.4800","0.0999","0.0999","0.0666","0.1212","0.4485"
"0.5600","0.1186","0.1186","0.0791","0.2159","0.7990"
"0.6400","0.1384","0.1384","0.0923","0.3218","1.1907"
"0.7200","0.1584","0.1584","0.1056","0.4202","1.5548"
"0.8000","0.1779","0.1779","0.1186","0.5155","1.9073"
"0.8800","0.1988","0.1988","0.1325","0.6202","2.2946"
"0.9600","0.2181","0.2181","0.1454","0.7068","2.6153"
"1.0400","0.2384","0.2384","0.1589","0.8018","2.9667"
"1.1200","0.2593","0.2593","0.1729","0.9044","3.3462"
"1.2000","0.2790","0.2790","0.1860","0.9998","3.6991"
"1.2800","0.2989","0.2989","0.1993","1.0828","4.0064"
"1.3600","0.3182","0.3182","0.2121","1.1767","4.3537"
"1.4400","0.3378","0.3378","0.2252","1.2440","4.6028"
"1.5200","0.3584","0.3584","0.2389","1.3359","4.9428"
"1.6000","0.3776","0.3776","0.2517","1.4188","5.2495"
"1.6800","0.3990","0.3990","0.2660","1.5225","5.6333"
"1.7600","0.4193","0.4193","0.2795","1.6114","5.9622"
"1.8400","0.4383","0.4383","0.2922","1.7031","6.3014"
"1.9200","0.4583","0.4583","0.3056","1.7942","6.6384"
"2.0000","0.4778","0.4778","0.3185","1.8796","6.9546"
"2.0800","0.4986","0.4986","0.3324","1.9781","7.3191"
"2.1600","0.5188","0.5188","0.3458","2.0701","7.6595"
"2.2400","0.5375","0.5375","0.3584","2.1560","7.9773"
"2.3200","0.5587","0.5587","0.3725","2.2586","8.3568"
"2.4000","0.5796","0.5796","0.3864","2.3571","8.7212"
"2.4800","0.5992","0.5992","0.3994","2.4488","9.0606"
"2.5600","0.6187","0.6187","0.4124","2.5430","9.4091"
"2.6400","0.6371","0.6371","0.4248","2.6322","9.7390"
"2.7200","0.6585","0.6585","0.4390","2.7379","10.1301"
"2.8000","0.6776","0.6776","0.4517","2.8286","10.4657"
"2.8800","0.6976","0.6976","0.4650","2.9315","10.8464"
"2.9600","0.7188","0.7188","0.4792","3.0333","11.2233"
"3.0400","0.7387","0.7387","0.4924","3.1342","11.5967"
"3.1200","0.7587","0.7587","0.5058","3.2379","11.9803"
"3.2000","0.7792","0.7792","0.5195","3.3386","12.3528"
"3.2800","0.7978","0.7978","0.5318","3.4431","12.7393"
"3.3600","0.8184","0.8184","0.5456","3.5500","13.1349"
"3.4400","0.8376","0.8376","0.5584","3.6531","13.5166"
"3.5200","0.8585","0.8585","0.5723","3.7734","13.9614"
"3.6000","0.8800","0.8800","0.5867","3.8865","14.3801"
"3.6800","0.8992","0.8992","0.5995","3.9961","14.7856"
"3.7600","0.9189","0.9189","0.6126","4.1127","15.2171"
"3.8400","0.9385","0.9385","0.6256","4.2166","15.6015"
"3.9200","0.9580","0.9580","0.6387","4.3417","16.0643"
"4.0000","0.9784","0.9784","0.6523","4.4698","16.5384"
"4.0800","0.9975","0.9975","0.6650","4.5726","16.9187"
"4.1600","1.0179","1.0179","0.6786","4.7041","17.4053"
"4.2400","1.0392","1.0392","0.6928","4.8292","17.8682"
"4.3200","1.0584","1.0584","0.7056","4.9474","18.3054"
"4.4000","1.0789","1.0789","0.7193","5.0752","18.7783"
"4.4800","1.0982","1.0982","0.7321","5.1873","19.1929"
"4.5600","1.1180","1.1180","0.7453","5.3129","19.6579"
"4.6400","1.1381","1.1381","0.7588","5.4413","20.1327"
"4.7200","1.1582","1.1582","0.7721","5.5685","20.6035"
"4.8000","1.1790","1.1790","0.7860","5.7038","21.1042"
"4.8800","1.1995","1.1995","0.7997","5.8349","21.5890"
"4.9600","1.2185","1.2185","0.8123","5.9599","22.0516"
"5.0400","1.2386","1.2386","0.8257","6.0874","22.5234"
"5.1200","1.2581","1.2581","0.8388","6.2126","22.9868"
"5.2000","1.2787","1.2787","0.8525","6.3504","23.4964"
"5.2800","1.2981","1.2981","0.8654","6.4717","23.9452"
"5.3600","1.3171","1.3171","0.8781","6.5989","24.4161"
"5.4400","1.3379","1.3379","0.8919","6.7397","24.9370"
"5.5200","1.3592","1.3592","0.9061","6.8871","25.4823"
"5.6000","1.3791","1.3791","0.9194","7.0159","25.9588"
"5.6800","1.3991","1.3991","0.9327","7.1557","26.4759"
"5.7600","1.4178","1.4178","0.9452","7.2846","26.9531"
"5.8400","1.4382","1.4382","0.9588","7.4304","27.4926"
"5.9200","1.4584","1.4584","0.9723","7.5673","27.9991"
"6.0000","1.4781","1.4781","0.9854","7.7126","28.5365"
"6.0800","1.4992","1.4992","0.9994","7.8674","29.1092"
"6.1600","1.5189","1.5189","1.0126","8.0092","29.6340"
"6.2400","1.5391","1.5391","1.0261","8.1610","30.1955"
"6.3200","1.5591","1.5591","1.0394","8.3071","30.7364"
"6.4000","1.5780","1.5780","1.0520","8.4460","31.2502"
"6.4800","1.5981","1.5981","1.0654","8.5975","31.8106"
"6.5600","1.6181","1.6181","1.0787","8.7466","32.3623"
"6.6400","1.6377","1.6377","1.0918","8.8978","32.9219"
"6.7200","1.6597","1.6597","1.1064","9.0709","33.5622"
"6.8000","1.6786","1.6786","1.1190","9.2024","34.0490"
"6.8800","1.6985","1.6985","1.1324","9.3546","34.6118"
"6.9600","1.7182","1.7182","1.1455","9.5062","35.1729"
"7.0400","1.7379","1.7379","1.1586","9.6636","35.7554"
"7.1200","1.7581","1.7581","1.1721","9.8183","36.3279"
"7.2000","1.7784","1.7784","1.1856","9.9787","36.9212"
"7.2800","1.7988","1.7988","1.1992","10.1357","37.5022"
"7.3600","1.8199","1.8199","1.2133","10.2937","38.0868"
"7.4400","1.8385","1.8385","1.2257","10.4370","38.6167"
"7.5200","1.8590","1.8590","1.2393","10.5970","39.2089"
"7.6000","1.8783","1.8783","1.2522","10.7474","39.7654"
"7.6800","1.8982","1.8982","1.2655","10.9069","40.3555"
"7.7600","1.9181","1.9181","1.2787","11.0643","40.9379"
"7.8400","1.9369","1.9369","1.2913","11.2070","41.4659"
"7.9200","1.9579","1.9579","1.3053","11.3703","42.0702"
"8.0000","1.9794","1.9794","1.3196","11.5468","42.7233"
"8.0800","1.9989","1.9989","1.3326","11.6998","43.2893"
"8.1600","2.0184","2.0184","1.3456","11.8543","43.8610"
"8.2400","2.0379","2.0379","1.3586","12.0101","44.4375"
"8.3200","2.0580","2.0580","1.3720","12.1679","45.0214"
"8.4000","2.0790","2.0790","1.3860","12.3358","45.6424"
"8.4800","2.0981","2.0981","1.3987","12.4911","46.2171"
"8.5600","2.1196","2.1196","1.4131","12.6655","46.8624"
"8.6400","2.1388","2.1388","1.4259","12.8198","47.4332"
"8.7200","2.1590","2.1590","1.4393","12.9859","48.0477"
"8.8000","2.1786","2.1786","1.4524","13.1448","48.6357"
"8.8800","2.1982","2.1982","1.4654","13.2981","49.2031"
"8.9600","2.2182","2.2182","1.4788","13.4631","49.8136"
"9.0400","2.2383","2.2383","1.4922","13.6253","50.4135"
"9.1200","2.2573","2.2573","1.5049","13.7791","50.9825"
"9.2000","2.2787","2.2787","1.5191","13.9595","51.6501"
"9.2800","2.2990","2.2990","1.5327","14.1246","52.2609"
"9.3600","2.3191","2.3191","1.5461","14.2888","52.8685"
"9.4400","2.3386","2.3386","1.5591","14.4484","53.4591"
"9.5200","2.3575","2.3575","1.5717","14.5977","54.0116"
"9.6000","2.3786","2.3786","1.5857","14.7741","54.6643"
"9.6800","2.3987","2.3987","1.5992","14.9385","55.2723"
"9.7600","2.4184","2.4184","1.6123","15.0979","55.8624"
"9.8400","2.4391","2.4391","1.6260","15.2709","56.5025"
"9.9200","2.4589","2.4589","1.6393","15.4286","57.0857"
"10.0000","2.4792","2.4792","1.6528","15.5964","57.7068"
"10.0800","2.4994","2.4994","1.6663","15.7624","58.3208"
"10.1600","2.5180","2.5180","1.6786","15.9138","58.8810"
"10.2400","2.5377","2.5377","1.6918","16.0769","59.4845"
"10.3200","2.5567","2.5567","1.7044","16.2305","60.0529"
"10.4000","2.5781","2.5781","1.7187","16.4084","60.7111"
"10.4800","2.5995","2.5995","1.7330","16.5865","61.3699"
"10.5600","2.6190","2.6190","1.7460","16.7470","61.9637"
"10.6400","2.6383","2.6383","1.7589","16.9075","62.5579"
"10.7200","2.6583","2.6583","1.7722","17.0696","63.1576"
"10.8000","2.6776","2.6776","1.7850","17.2303","63.7522"
"10.8800","2.6991","2.6991","1.7994","17.4135","64.4301"
"10.9600","2.7178","2.7178","1.8119","17.5626","64.9817"
"11.0400","2.7390","2.7390","1.8260","17.7437","65.6517"
"11.1200","2.7592","2.7592","1.8395","17.9132","66.2789"
"11.2000","2.7794","2.7794","1.8529","18.0837","66.9096"
"11.2800","2.7988","2.7988","1.8659","18.2444","67.5042"
"11.3600","2.8182","2.8182","1.8788","18.4055","68.1005"
"11.4400","2.8378","2.8378","1.8919","18.5703","68.7102"
"11.5200","2.8583","2.8583","1.9055","18.7437","69.3516"
"11.6000","2.8774","2.8774","1.9183","18.9029","69.9407"
"11.6800","2.8987","2.8987","1.9325","19.0858","70.6176"
"11.7600","2.9191","2.9191","1.9461","19.2557","71.2460"
"11.8400","2.9385","2.9385","1.9590","19.4164","71.8405"
"11.9200","2.9585","2.9585","1.9723","19.5822","72.4541"
"12.0000","2.9776","2.9776","1.9851","19.7435","73.0508"
"12.0800","2.9990","2.9990","1.9993","19.9242","73.7197"
"12.1600","3.0186","3.0186","2.0124","20.0878","74.3250"
"12.2400","3.0377","3.0377","2.0252","20.2473","74.9149"
"12.3200","3.0591","3.0591","2.0394","20.4406","75.6301"
"12.4000","3.0798","3.0798","2.0532","20.6109","76.2603"
"12.4800","3.0994","3.0994","2.0663","20.7731","76.8603"
"12.5600","3.1191","3.1191","2.0794","20.9359","77.4628"
"12.6400","3.1373","3.1373","2.0915","21.0846","78.0129"
"12.7200","3.1585","3.1585","2.1056","21.2645","78.6785"
"12.8000","3.1783","3.1783","2.1189","21.4291","79.2875"
"12.8800","3.1976","3.1976","2.1318","21.5899","79.8827"
"12.9600","3.2179","3.2179","2.1453","21.7613","80.5169"
"13.0400","3.2389","3.2389","2.1593","21.9368","81.1660"
"13.1200","3.2588","3.2588","2.1726","22.1022","81.7780"
"13.2000","3.2795","3.2795","2.1863","22.2740","82.4137"
"13.2800","3.2980","3.2980","2.1987","22.4264","82.9779"
"13.3600","3.3182","3.3182","2.2121","22.5953","83.6027"
"13.4400","3.3379","3.3379","2.2252","22.7584","84.2060"
"13.5200","3.3588","3.3588","2.2392","22.9369","84.8665"
"13.6000","3.3795","3.3795","2.2530","23.1091","85.5037"
"13.6800","3.3988","3.3988","2.2659","23.2691","86.0957"
"13.7600","3.4192","3.4192","2.2795","23.4471","86.7543"
"13.8400","3.4386","3.4386","2.2924","23.6068","87.3452"
"13.9200","3.4579","3.4579","2.3053","23.7690","87.9451"
"14.0000","3.4783","3.4783","2.3189","23.9387","88.5732"
"14.0800","3.4974","3.4974","2.3316","24.0924","89.1418"
"14.1600","3.5177","3.5177","2.3452","24.2642","89.7774"
"14.2400","3.5392","3.5392","2.3595","24.4431","90.4396"
"14.3200","3.5582","3.5582","2.3722","24.6008","91.0229"
"14.4000","3.5789","3.5789","2.3859","24.7745","91.6656"
"14.4800","3.5984","3.5984","2.3989","24.9332","92.2527"
"14.5600","3.6182","3.6182","2.4121","25.0954","92.8530"
"14.6400","3.6381","3.6381","2.4254","25.2594","93.4597"
"14.7200","3.6578","3.6578","2.4385","25.4204","94.0556"
"14.8000","3.6790","3.6790","2.4527","25.5991","94.7165"
"14.8800","3.6997","3.6997","2.4665","25.7702","95.3497"
"14.9600","3.7187","3.7187","2.4791","25.9236","95.9172"
"15.0400","3.7385","3.7385","2.4923","26.0840","96.5107"
"15.1200","3.7578","3.7578","2.5052","26.2392","97.0852"
"15.2000","3.7787","3.7787","2.5191","26.4159","97.7388"
"15.2800","3.7985","3.7985","2.5323","26.5756","98.3296"
"15.3600","3.8171","3.8171","2.5447","26.7261","98.8867"
"15.4400","3.8381","3.8381","2.5588","26.9017","99.5362"
"15.5200","3.8589","3.8589","2.5726","27.0696","100.1574"
"15.6000","3.8791","3.8791","2.5861","27.2358","100.7726"
"15.6800","3.8986","3.8986","2.5990","27.3921","101.3508"
"15.7600","3.9177","3.9177","2.6118","27.5422","101.9062"
"15.8400","3.9382","3.9382","2.6254","27.7131","102.5385"
"15.9200","3.9587","3.9587","2.6391","27.8808","103.1589"
"16.0000","3.9783","3.9783","2.6522","28.0440","103.7629"
"16.0800","3.9993","3.9993","2.6662","28.2167","104.4017"
"16.1600","4.0188","4.0188","2.6792","28.3688","104.9645"
"16.2400","4.0393","4.0393","2.6928","28.5375","105.5889"
"16.3200","4.0587","4.0587","2.7058","28.6918","106.1595"
"16.4000","4.0780","4.0780","2.7186","28.8507","106.7474"
"16.4800","4.0982","4.0982","2.7322","29.0175","107.3649"
"16.5600","4.1180","4.1180","2.7453","29.1746","107.9460"
"16.6400","4.1376","4.1376","2.7584","29.3348","108.5389"
"16.7200","4.1593","4.1593","2.7729","29.5144","109.2031"
"16.8000","4.1785","4.1785","2.7857","29.6641","109.7570"
"16.8800","4.1991","4.1991","2.7994","29.8299","110.3707"
"16.9600","4.2184","4.2184","2.8123","29.9802","110.9269"
"17.0400","4.2379","4.2379","2.8253","30.1381","111.5111"
"17.1200","4.2582","4.2582","2.8388","30.3020","112.1173"
"17.2000","4.2784","4.2784","2.8523","30.4638","112.7162"
"17.2800","4.2989","4.2989","2.8660","30.6340","113.3459"
"17.3600","4.3199","4.3199","2.8799","30.8017","113.9662"
"17.4400","4.3382","4.3382","2.8922","30.9434","114.4908"
"17.5200","4.3587","4.3587","2.9058","31.1099","115.1066"
"17.6000","4.3783","4.3783","2.9189","31.2636","115.6754"
"17.6800","4.3982","4.3982","2.9321","31.4241","116.2692"
"17.7600","4.4180","4.4180","2.9454","31.5819","116.8531"
"17.8400","4.4372","4.4372","2.9581","31.7322","117.4092"
"17.9200","4.4583","4.4583","2.9722","31.9019","118.0369"
"18.0000","4.4793","4.4793","2.9862","32.0744","118.6752"
"18.0800","4.4989","4.4989","2.9993","32.2303","119.2522"
"18.1600","4.5186","4.5186","3.0124","32.3867","119.8307"
"18.2400","4.5380","4.5380","3.0253","32.5337","120.3746"
"18.3200","4.5582","4.5582","3.0388","32.6963","120.9763"
"18.4000","4.5790","4.5790","3.0526","32.8619","121.5890"
"18.4800","4.5977","4.5977","3.0651","33.0062","122.1229"
"18.5600","4.6189","4.6189","3.0793","33.1760","122.7511"
"18.6400","4.6392","4.6392","3.0928","33.3380","123.3505"
"18.7200","4.6587","4.6587","3.1058","33.4912","123.9174"
"18.8000","4.6784","4.6784","3.1189","33.6481","124.4979"
"18.8800","4.6982","4.6982","3.1321","33.8000","125.0599"
"18.9600","4.7181","4.7181","3.1454","33.9591","125.6486"
"19.0400","4.7383","4.7383","3.1589","34.1189","126.2400"
"19.1200","4.7573","4.7573","3.1715","34.2642","126.7776"
"19.2000","4.7783","4.7783","3.1855","34.4327","127.4009"
"19.2800","4.7990","4.7990","3.1993","34.5929","127.9936"
"19.3600","4.8190","4.8190","3.2127","34.7487","128.5701"
"19.4400","4.8386","4.8386","3.2257","34.8990","129.1262"
"19.5200","4.8575","4.8575","3.2383","35.0448","129.6659"
"19.6000","4.8785","4.8785","3.2523","35.2102","130.2779"
"19.6800","4.8984","4.8984","3.2656","35.3647","130.8494"
"19.7600","4.9183","4.9183","3.2789","35.5211","131.4281"
"19.8400","4.9390","4.9390","3.2927","35.6854","132.0360"
"19.9200","4.9588","4.9588","3.3059","35.8308","132.5739"
"20.0000","4.9793","4.9793","3.3195","35.9921","133.1709"
"20.0800","4.9994","4.9994","3.3329","36.1470","133.7439"
"20.1600","5.0175","5.0175","3.3450","36.2852","134.2554"
"20.2400","5.0379","5.0379","3.3586","36.4449","134.8461"
"20.3200","5.0574","5.0574","3.3716","36.5926","135.3926"
"20.4000","5.0783","5.0783","3.3855","36.7575","136.0027"
"20.4800","5.0994","5.0994","3.3996","36.9218","136.6107"
"20.5600","5.1187","5.1187","3.4125","37.0673","137.1490"
"20.6400","5.1382","5.1382","3.4255","37.2135","137.6901"
"20.7200","5.1583","5.1583","3.4389","37.3651","138.2510"
"20.8000","5.1779","5.1779","3.4520","37.5153","138.8066"
"20.8800","5.1988","5.1988","3.4659","37.6802","139.4167"
"20.9600","5.2177","5.2177","3.4785","37.8223","139.9423"
"21.0400","5.2389","5.2389","3.4926","37.9872","140.5525"
"21.1200","5.2594","5.2594","3.5063","38.1480","141.1476"
"21.2000","5.2789","5.2789","3.5193","38.2958","141.6944"
"21.2800","5.2986","5.2986","3.5324","38.4475","142.2556"
"21.3600","5.3184","5.3184","3.5456","38.5938","142.7969"
"21.4400","5.3377","5.3377","3.5585","38.7392","143.3350"
"21.5200","5.3582","5.3582","3.5722","38.8980","143.9224"
"21.6000","5.3773","5.3773","3.5849","39.0377","144.4395"
"21.6800","5.3986","5.3986","3.5991","39.2045","145.0565"
"21.7600","5.4192","5.4192","3.6128","39.3639","145.6463"
"21.8400","5.4387","5.4387","3.6258","39.5102","146.1879"
"21.9200","5.4584","5.4584","3.6389","39.6574","146.7322"
"22.0000","5.4778","5.4778","3.6519","39.8065","147.2841"
"22.0800","5.4989","5.4989","3.6660","39.9689","147.8848"
"22.1600","5.5186","5.5186","3.6791","40.1142","148.4227"
"22.2400","5.5378","5.5378","3.6919","40.2567","148.9496"
"22.3200","5.5585","5.5585","3.7057","40.4159","149.5388"
"22.4000","5.5795","5.5795","3.7197","40.5748","150.1267"
"22.4800","5.5995","5.5995","3.7330","40.7225","150.6734"
"22.5600","5.6192","5.6192","3.7461","40.8691","151.2158"
"22.6400","5.6370","5.6370","3.7580","40.9947","151.6804"
"22.7200","5.6584","5.6584","3.7723","41.1596","152.2906"
"22.8000","5.6782","5.6782","3.7855","41.3060","152.8321"
"22.8800","5.6980","5.6980","3.7987","41.4548","153.3826"
"22.9600","5.7182","5.7182","3.8121","41.6078","153.9487"
"23.0400","5.7387","5.7387","3.8258","41.7581","154.5050"
"23.1200","5.7588","5.7588","3.8392","41.9096","155.0656"
"23.2000","5.7793","5.7793","3.8529","42.0632","155.6338"
"23.2800","5.7976","5.7976","3.8651","42.1985","156.1344"
"23.3600","5.8182","5.8182","3.8788","42.3531","156.7065"
"23.4400","5.8379","5.8379","3.8919","42.4953","157.2327"
"23.5200","5.8583","5.8583","3.9055","42.6478","157.7968"
"23.6000","5.8796","5.8796","3.9198","42.8087","158.3921"
"23.6800","5.8992","5.8992","3.9328","42.9513","158.9200"
"23.7600","5.9190","5.9190","3.9460","43.0970","159.4588"
"23.8400","5.9387","5.9387","3.9591","43.2403","159.9889"
"23.9200","5.9580","5.9580","3.9720","43.3836","160.5195"
"24.0000","5.9783","5.9783","3.9855","43.5334","161.0737"
"24.0800","5.9977","5.9977","3.9985","43.6704","161.5806"
"24.1600","6.0181","6.0181","4.0121","43.8211","162.1382"
"24.2400","6.0390","6.0390","4.0260","43.9755","162.7092"
"24.3200","6.0584","6.0584","4.0389","44.1156","163.2276"
"24.4000","6.0791","6.0791","4.0527","44.2653","163.7816"
"24.4800","6.0982","6.0982","4.0654","44.3999","164.2797"
"24.5600","6.1182","6.1182","4.0788","44.5448","164.8156"
"24.6400","6.1380","6.1380","4.0920","44.6916","165.3589"
"24.7200","6.1578","6.1578","4.1052","44.8332","165.8830"
"24.8000","6.1792","6.1792","4.1195","44.9943","166.4790"
"24.8800","6.2002","6.2002","4.1335","45.1491","167.0518"
"24.9600","6.2187","6.2187","4.1458","45.2744","167.5151"
"25.0400","6.2383","6.2383","4.1589","45.4145","168.0335"
"25.1200","6.2578","6.2578","4.1718","45.5526","168.5445"
"25.2000","6.2786","6.2786","4.1858","45.7049","169.1083"
"25.2800","6.2986","6.2986","4.1990","45.8445","169.6247"
"25.3600","6.3170","6.3170","4.2114","45.9748","170.1069"
"25.4400","6.3378","6.3378","4.2252","46.1234","170.6568"
"25.5200","6.3589","6.3589","4.2392","46.2804","171.2375"
"25.6000","6.3790","6.3790","4.2526","46.4221","171.7618"
"25.6800","6.3990","6.3990","4.2660","46.5642","172.2876"
"25.7600","6.4175","6.4175","4.2783","46.6899","172.7528"
"25.8400","6.4382","6.4382","4.2921","46.8373","173.2981"
"25.9200","6.4581","6.4581","4.3054","46.9778","173.8179"
"26.0000","6.4781","6.4781","4.3187","47.1214","174.3492"
"26.0800","6.4994","6.4994","4.3329","47.2762","174.9220"
"26.1600","6.5189","6.5189","4.3459","47.4102","175.4179"
"26.2400","6.5389","6.5389","4.3593","47.5498","175.9344"
"26.3200","6.5589","6.5589","4.3726","47.6926","176.4625"
"26.4000","6.5785","6.5785","4.3857","47.8338","176.9849"
"26.4800","6.5982","6.5982","4.3988","47.9714","177.4941"
"26.5600","6.6181","6.6181","4.4121","48.1085","178.0013"
"26.6400","6.6376","6.6376","4.4251","48.2490","178.5214"
"26.7200","6.6592","6.6592","4.4395","48.4055","179.1005"
"26.8000","6.6784","6.6784","4.4523","48.5370","179.5869"
"26.8800","6.6987","6.6987","4.4658","48.6746","180.0960"
"26.9600","6.7180","6.7180","4.4787","48.8088","180.5927"
"27.0400","6.7379","6.7379","4.4919","48.9530","181.1260"
"27.1200","6.7584","6.7584","4.5056","49.0980","181.6627"
"27.2000","6.7784","6.7784","4.5189","49.2368","182.1762"
"27.2800","6.7991","6.7991","4.5328","49.3812","182.7104"
"27.3600","6.8199","6.8199","4.5466","49.5268","183.2492"
"27.4400","6.8383","6.8383","4.5589","49.6469","183.6937"
"27.5200","6.8587","6.8587","4.5725","49.7921","184.2307"
"27.6000","6.8786","6.8786","4.5857","49.9283","184.7347"
"27.6800","6.8982","6.8982","4.5988","50.0634","185.2347"
"27.7600","6.9182","6.9182","4.6122","50.2018","185.7467"
"27.8400","6.9368","6.9368","4.6245","50.3246","186.2009"
"27.9200","6.9585","6.9585","4.6390","50.4806","186.7781"
"28.0000","6.9796","6.9796","4.6531","50.6274","187.3214"
"28.0800","6.9990","6.9990","4.6660","50.7586","187.8069"
"28.1600","7.0184","7.0184","4.6789","50.8910","188.2969"
"28.2400","7.0379","7.0379","4.6919","51.0171","188.7631"
"28.3200","7.0580","7.0580","4.7053","51.1576","189.2832"
"28.4000","7.0790","7.0790","4.7193","51.3024","189.8188"
"28.4800","7.0972","7.0972","4.7315","51.4198","190.2531"
"28.5600","7.1190","7.1190","4.7460","51.5725","190.8184"
"28.6400","7.1393","7.1393","4.7595","51.7118","191.3337"
"28.7200","7.1593","7.1593","4.7729","51.8466","191.8326"
"28.8000","7.1785","7.1785","4.7856","51.9748","192.3066"
"28.8800","7.1987","7.1987","4.7991","52.1124","192.8160"
"28.9600","7.2185","7.2185","4.8124","52.2459","193.3097"
"29.0400","7.2380","7.2380","4.8253","52.3709","193.7725"
"29.1200","7.2568","7.2568","4.8379","52.4982","194.2432"
"29.2000","7.2787","7.2787","4.8525","52.6535","194.8179"
"29.2800","7.2986","7.2986","4.8657","52.7842","195.3017"
"29.3600","7.3191","7.3191","4.8794","52.9233","195.8161"
"29.4400","7.3387","7.3387","4.8924","53.0499","196.2847"
"29.5200","7.3577","7.3577","4.9051","53.1780","196.7584"
"29.6000","7.3784","7.3784","4.9189","53.3162","197.2699"
"29.6800","7.3984","7.3984","4.9323","53.4493","197.7626"
"29.7600","7.4183","7.4183","4.9455","53.5802","198.2467"
"29.8400","7.4388","7.4388","4.9592","53.7212","198.7684"
"29.9200","7.4593","7.4593","4.9729","53.8553","199.2645"
"30.0000","7.4793","7.4793","4.9862","53.9841","199.7412"
"30.0800","7.4991","7.4991","4.9994","54.1126","200.2167"
"30.1600","7.5172","7.5172","5.0115","54.2271","200.6404"
"30.2400","7.5380","7.5380","5.0253","54.3681","201.1620"
"30.3200","7.5575","7.5575","5.0383","54.4925","201.6222"
"30.4000","7.5788","7.5788","5.0525","54.6408","202.1708"
"30.4800","7.5995","7.5995","5.0663","54.7786","202.6807"
"30.5600","7.6189","7.6189","5.0793","54.9003","203.1310"
"30.6400","7.6389","7.6389","5.0926","55.0326","203.6205"
"30.7200","7.6586","7.6586","5.1057","55.1596","204.0905"
"30.8000","7.6773","7.6773","5.1182","55.2784","204.5299"
"30.8800","7.6988","7.6988","5.1326","55.4243","205.0700"
"30.9600","7.7178","7.7178","5.1452","55.5414","205.5032"
"31.0400","7.7391","7.7391","5.1594","55.6816","206.0219"
"31.1200","7.7590","7.7590","5.1727","55.8097","206.4959"
"31.2000","7.7791","7.7791","5.1861","55.9400","206.9778"
"31.2800","7.7987","7.7987","5.1991","56.0662","207.4448"
"31.3600","7.8183","7.8183","5.2122","56.1907","207.9057"
"31.4400","7.8377","7.8377","5.2251","56.3123","208.3557"
"31.5200","7.8580","7.8580","5.2386","56.4443","208.8440"
"31.6000","7.8775","7.8775","5.2516","56.5667","209.2970"
"31.6800","7.8987","7.8987","5.2658","56.7072","209.8165"
"31.7600","7.9192","7.9192","5.2795","56.8395","210.3060"
"31.8400","7.9384","7.9384","5.2922","56.9575","210.7429"
"31.9200","7.9584","7.9584","5.3056","57.0860","211.2184"
"32.0000","7.9776","7.9776","5.3184","57.2069","211.6657"
"32.0800","7.9986","7.9986","5.3324","57.3445","212.1745"
"32.1600","8.0187","8.0187","5.3458","57.4702","212.6399"
"32.2400","8.0380","8.0380","5.3587","57.5915","213.0885"
"32.3200","8.0588","8.0588","5.3725","57.7282","213.5945"
"32.4000","8.0797","8.0797","5.3865","57.8614","214.0873"
"32.4800","8.0994","8.0994","5.3996","57.9835","214.5391"
"32.5600","8.1191","8.1191","5.4128","58.1035","214.9828"
"32.6400","8.1373","8.1373","5.4249","58.2117","215.3831"
"32.7200","8.1583","8.1583","5.4389","58.3486","215.8900"
"32.8000","8.1780","8.1780","5.4520","58.4699","216.3388"
"32.8800","8.1981","8.1981","5.4654","58.5978","216.8120"
"32.9600","8.2183","8.2183","5.4788","58.7255","217.2845"
"33.0400","8.2386","8.2386","5.4924","58.8474","217.7354"
"33.1200","8.2586","8.2586","5.5057","58.9697","218.1878"
"33.2000","8.2789","8.2789","5.5193","59.0934","218.6458"
"33.2800","8.2981","8.2981","5.5320","59.2101","219.0774"
"33.3600","8.3186","8.3186","5.5457","59.3366","219.5454"
"33.4400","8.3379","8.3379","5.5586","59.4519","219.9722"
"33.5200","8.3582","8.3582","5.5722","59.5773","220.4362"
"33.6000","8.3794","8.3794","5.5863","59.7105","220.9288"
"33.6800","8.3992","8.3992","5.5995","59.8308","221.3738"
"33.7600","8.4191","8.4191","5.6127","59.9491","221.8115"
"33.8400","8.4384","8.4384","5.6256","60.0581","222.2149"
"33.9200","8.4577","8.4577","5.6385","60.1745","222.6456"
"34.0000","8.4782","8.4782","5.6521","60.3025","223.1193"
"34.0800","8.4979","8.4979","5.6652","60.4150","223.5355"
"34.1600","8.5177","8.5177","5.6785","60.5357","223.9822"
"34.2400","8.5390","8.5390","5.6926","60.6660","224.4640"
"34.3200","8.5585","8.5585","5.7057","60.7840","224.9007"
"34.4000","8.5794","8.5794","5.7196","60.9142","225.3827"
"34.4800","8.5983","8.5983","5.7322","61.0186","225.7687"
"34.5600","8.6182","8.6182","5.7455","61.1375","226.2086"
"34.6400","8.6381","8.6381","5.7588","61.2556","226.6456"
"34.7200","8.6582","8.6582","5.7722","61.3734","227.0816"
"34.8000","8.6791","8.6791","5.7861","61.4985","227.5445"
"34.8800","8.6999","8.6999","5.7999","61.6241","228.0090"
"34.9600","8.7189","8.7189","5.8126","61.7312","228.4054"
"35.0400","8.7384","8.7384","5.8256","61.8442","228.8235"
"35.1200","8.7578","8.7578","5.8385","61.9540","229.2300"
"35.2000","8.7786","8.7786","5.8524","62.0802","229.6967"
"35.2800","8.7982","8.7982","5.8655","62.1876","230.0942"
"35.3600","8.8170","8.8170","5.8780","62.2936","230.4863"
"35.4400","8.8382","8.8382","5.8922","62.4205","230.9557"
"35.5200","8.8591","8.8591","5.9061","62.5447","231.4153"
"35.6000","8.8793","8.8793","5.9196","62.6620","231.8493"
"35.6800","8.8993","8.8993","5.9329","62.7746","232.2659"
"35.7600","8.9177","8.9177","5.9451","62.8697","232.6180"
"35.8400","8.9381","8.9381","5.9588","62.9889","233.0590"
"35.9200","8.9584","8.9584","5.9723","63.1044","233.4863"
"36.0000","8.9783","8.9783","5.9855","63.2171","233.9034"
"36.0800","8.9994","8.9994","5.9996","63.3383","234.3518"
"36.1600","9.0184","9.0184","6.0123","63.4388","234.7236"
"36.2400","9.0392","9.0392","6.0261","63.5546","235.1519"
"36.3200","9.0589","9.0589","6.0393","63.6635","235.5551"
"36.4000","9.0782","9.0782","6.0521","63.7692","235.9460"
"36.4800","9.0984","9.0984","6.0656","63.8833","236.3681"
"36.5600","9.1181","9.1181","6.0787","63.9870","236.7519"
"36.6400","9.1373","9.1373","6.0916","64.0913","237.1379"
"36.7200","9.1593","9.1593","6.1062","64.2176","237.6051"
"36.8000","9.1785","9.1785","6.1190","64.3187","237.9791"
"36.8800","9.1991","9.1991","6.1327","64.4291","238.3878"
"36.9600","9.2183","9.2183","6.1456","64.5292","238.7581"
"37.0400","9.2375","9.2375","6.1583","64.6348","239.1487"
"37.1200","9.2579","9.2579","6.1719","64.7440","239.5529"
"37.2000","9.2785","9.2785","6.1857","64.8576","239.9730"
"37.2800","9.2988","9.2988","6.1992","64.9655","240.3724"
"37.3600","9.3199","9.3199","6.2133","65.0824","240.8050"
"37.4400","9.3384","9.3384","6.2256","65.1706","241.1313"
"37.5200","9.3588","9.3588","6.2392","65.2816","241.5419"
"37.6000","9.3785","9.3785","6.2523","65.3803","241.9072"
"37.6800","9.3983","9.3983","6.2655","65.4842","242.2916"
"37.7600","9.4184","9.4184","6.2789","65.5868","242.6712"
"37.8400","9.4370","9.4370","6.2913","65.6761","243.0017"
"37.9200","9.4580","9.4580","6.3054","65.7900","243.4229"
"38.0000","9.4795","9.4795","6.3197","65.9058","243.8513"
"38.0800","9.4992","9.4992","6.3328","66.0049","244.2180"
"38.1600","9.5185","9.5185","6.3457","66.1001","244.5704"
"38.2400","9.5379","9.5379","6.3586","66.1915","244.9086"
"38.3200","9.5579","9.5579","6.3719","66.2956","245.2937"
"38.4000","9.5789","9.5789","6.3860","66.4053","245.6996"
"38.4800","9.5979","9.5979","6.3986","66.4914","246.0182"
"38.5600","9.6190","9.6190","6.4127","66.6018","246.4266"
"38.6400","9.6390","9.6390","6.4260","66.7001","246.7905"
"38.7200","9.6590","9.6590","6.4394","66.7996","247.1585"
"38.8000","9.6785","9.6785","6.4523","66.8928","247.5034"
"38.8800","9.6982","9.6982","6.4654","66.9826","247.8357"
"38.9600","9.7181","9.7181","6.4787","67.0779","248.1884"
"39.0400","9.7381","9.7381","6.4921","67.1729","248.5399"
"39.1200","9.7574","9.7574","6.5049","67.2641","248.8772"
"39.2000","9.7788","9.7788","6.5192","67.3718","249.2755"
"39.2800","9.7985","9.7985","6.5323","67.4633","249.6142"
"39.3600","9.8192","9.8192","6.5462","67.5619","249.9790"
"39.4400","9.8389","9.8389","6.5593","67.6485","250.2993"
"39.5200","9.8575","9.8575","6.5717","67.7314","250.6061"
"39.6000","9.8783","9.8783","6.5855","67.8312","250.9754"
"39.6800","9.8984","9.8984","6.5989","67.9191","251.3008"
"39.7600","9.9182","9.9182","6.6122","68.0099","251.6367"
"39.8400","9.9390","9.9390","6.6260","68.1068","251.9953"
"39.9200","9.9589","9.9589","6.6393","68.1911","252.3072"
"40.0000","9.9793","9.9793","6.6529","68.2821","252.6436"
"40.0800","9.9993","9.9993","6.6662","68.3662","252.9548"
"40.1600","10.0173","10.0173","6.6782","68.4368","253.2163"
"40.2400","10.0379","10.0379","6.6919","68.5304","253.5626"
"40.3200","10.0575","10.0575","6.7050","68.6140","253.8718"
"40.4000","10.0786","10.0786","6.7191","68.7042","254.2057"
"40.4800","10.0994","10.0994","6.7330","68.7963","254.5462"
"40.5600","10.1191","10.1191","6.7461","68.8717","254.8251"
"40.6400","10.1383","10.1383","6.7589","68.9434","255.0907"
"40.7200","10.1584","10.1584","6.7722","69.0235","255.3868"
"40.8000","10.1774","10.1774","6.7849","69.0963","255.6564"
"40.8800","10.1983","10.1983","6.7989","69.1820","255.9735"
"40.9600","10.2177","10.2177","6.8118","69.2533","256.2371"
"41.0400","10.2391","10.2391","6.8261","69.3414","256.5631"
"41.1200","10.2594","10.2594","6.8396","69.4174","256.8445"
"41.2000","10.2792","10.2792","6.8528","69.4895","257.1112"
"41.2800","10.2987","10.2987","6.8658","69.5546","257.3519"
"41.3600","10.3184","10.3184","6.8789","69.6214","257.5990"
"41.4400","10.3382","10.3382","6.8921","69.6911","257.8572"
"41.5200","10.3582","10.3582","6.9055","69.7612","258.1166"
"41.6000","10.3772","10.3772","6.9181","69.8184","258.3280"
"41.6800","10.3987","10.3987","6.9325","69.9008","258.6328"
"41.7600","10.4193","10.4193","6.9462","69.9699","258.8885"
"41.8400","10.4386","10.4386","6.9591","70.0260","259.0962"
"41.9200","10.4584","10.4584","6.9723","70.0851","259.3149"
"42.0000","10.4775","10.4775","6.9850","70.1365","259.5051"
"42.0800","10.4985","10.4985","6.9990","70.2074","259.7675"
"42.1600","10.5186","10.5186","7.0124","70.2651","259.9810"
"42.2400","10.5382","10.5382","7.0254","70.3214","260.1892"
"42.3200","10.5586","10.5586","7.0391","70.3804","260.4075"
"42.4000","10.5795","10.5795","7.0530","70.4401","260.6284"
"42.4800","10.5994","10.5994","7.0663","70.4919","260.8200"
"42.5600","10.6191","10.6191","7.0794","70.5364","260.9847"
"42.6400","10.6373","10.6373","7.0915","70.5702","261.1097"
"42.7200","10.6584","10.6584","7.1056","70.6295","261.3293"
"42.8000","10.6782","10.6782","7.1188","70.6728","261.4892"
"42.8800","10.6981","10.6981","7.1321","70.7183","261.6578"
"42.9600","10.7182","10.7182","7.1455","70.7617","261.8181"
"43.0400","10.7387","10.7387","7.1591","70.8044","261.9762"
"43.1200","10.7588","10.7588","7.1725","70.8443","262.1239"
"43.2000","10.7795","10.7795","7.1863","70.8828","262.2664"
"43.2800","10.7980","10.7980","7.1986","70.9070","262.3558"
"43.3600","10.8183","10.8183","7.2122","70.9422","262.4863"
"43.4400","10.8378","10.8378","7.2252","70.9689","262.5851"
"43.5200","10.8583","10.8583","7.2388","71.0044","262.7161"
"43.6000","10.8795","10.8795","7.2530","71.0404","262.8493"
"43.6800","10.8990","10.8990","7.2660","71.0601","262.9225"
"43.7600","10.9192","10.9192","7.2795","71.0817","263.0023"
"43.8400","10.9383","10.9383","7.2922","71.0956","263.0536"
"43.9200","10.9577","10.9577","7.3052","71.1111","263.1109"
"44.0000","10.9785","10.9785","7.3190","71.1349","263.1992"
"44.0800","10.9977","10.9977","7.3318","71.1385","263.2124"
"44.1600","11.0177","11.0177","7.3451","71.1527","263.2651"
"44.2400","11.0392","11.0392","7.3595","71.1730","263.3400"
"44.3200","11.0583","11.0583","7.3722","71.1779","263.3583"
"44.4000","11.0790","11.0790","7.3860","71.1914","263.4080"
"44.4800","11.0982","11.0982","7.3988","71.1903","263.4041"
"44.5600","11.1184","11.1184","7.4123","71.1968","263.4281"
"44.6400","11.1379","11.1379","7.4253","71.1981","263.4329"
"44.7200","11.1582","11.1582","7.4388","71.2000","263.4400"
"44.8000","11.1788","11.1788","7.4525","71.2071","263.4663"
"44.8800","11.2002","11.2002","7.4668","71.2165","263.5009"
"44.9600","11.2188","11.2188","7.4792","71.1996","263.4384"
"45.0400","11.2384","11.2384","7.4923","71.1924","263.4118"
"45.1200","11.2579","11.2579","7.5053","71.1813","263.3708"
"45.2000","11.2789","11.2789","7.5193","71.1819","263.3730"
"45.2800","11.2986","11.2986","7.5324","71.1659","263.3139"
"45.3600","11.3171","11.3171","7.5447","71.1450","263.2365"
"45.4400","11.3376","11.3376","7.5584","71.1340","263.1957"
"45.5200","11.3591","11.3591","7.5727","71.1303","263.1822"
"45.6000","11.3794","11.3794","7.5862","71.1131","263.1187"
"45.6800","11.3991","11.3991","7.5994","71.0924","263.0418"
"45.7600","11.4179","11.4179","7.6119","71.0576","262.9130"
"45.8400","11.4383","11.4383","7.6255","71.0408","262.8511"
"45.9200","11.4586","11.4586","7.6391","71.0224","262.7829"
"46.0000","11.4782","11.4782","7.6522","71.0035","262.7129"
"46.0800","11.4992","11.4992","7.6661","70.9869","262.6516"
"46.1600","11.5183","11.5183","7.6789","70.9592","262.5490"
"46.2400","11.5392","11.5392","7.6928","70.9402","262.4788"
"46.3200","11.5592","11.5592","7.7061","70.9156","262.3878"
"46.4000","11.5781","11.5781","7.7188","70.8824","262.2647"
"46.4800","11.5981","11.5981","7.7321","70.8557","262.1661"
"46.5600","11.6179","11.6179","7.7453","70.8187","262.0291"
"46.6400","11.6375","11.6375","7.7583","70.7920","261.9305"
"46.7200","11.6594","11.6594","7.7729","70.7786","261.8806"
"46.8000","11.6790","11.6790","7.7860","70.7447","261.7553"
"46.8800","11.6986","11.6986","7.7991","70.7107","261.6298"
"46.9600","11.7180","11.7180","7.8120","70.6729","261.4897"
"47.0400","11.7379","11.7379","7.8252","70.6438","261.3819"
"47.1200","11.7581","11.7581","7.8387","70.6170","261.2830"
"47.2000","11.7784","11.7784","7.8522","70.5833","261.1581"
"47.2800","11.7990","11.7990","7.8660","70.5536","261.0482"
"47.3600","11.8196","11.8196","7.8798","70.5227","260.9339"
"47.4400","11.8382","11.8382","7.8922","70.4803","260.7770"
"47.5200","11.8587","11.8587","7.9058","70.4522","260.6733"
"47.6000","11.8786","11.8786","7.9191","70.4188","260.5494"
"47.6800","11.8986","11.8986","7.9324","70.3859","260.4279"
"47.7600","11.9183","11.9183","7.9455","70.3501","260.2952"
"47.8400","11.9369","11.9369","7.9580","70.3086","260.1417"
"47.9200","11.9585","11.9585","7.9723","70.2856","260.0567"
"48.0000","11.9796","11.9796","7.9864","70.2578","259.9540"
"48.0800","11.9993","11.9993","7.9995","70.2213","259.8190"
"48.1600","12.0184","12.0184","8.0123","70.1848","259.6836"
"48.2400","12.0380","12.0381","8.0254","70.1485","259.5496"
"48.3200","12.0582","12.0582","8.0388","70.1156","259.4278"
"48.4000","12.0790","12.0790","8.0527","70.0858","259.3174"
"48.4800","12.0978","12.0978","8.0652","70.0428","259.1584"
"48.5600","12.1193","12.1193","8.0795","70.0170","259.0630"
"48.6400","12.1389","12.1389","8.0926","69.9787","258.9214"
"48.7200","12.1589","12.1589","8.1060","69.9428","258.7885"
"48.8000","12.1784","12.1784","8.1189","69.9063","258.6534"
"48.8800","12.1979","12.1979","8.1319","69.8665","258.5060"
"48.9600","12.2180","12.2180","8.1453","69.8322","258.3792"
"49.0400","12.2386","12.2386","8.1590","69.7996","258.2585"
"49.1200","12.2572","12.2572","8.1715","69.7582","258.1053"
"49.2000","12.2787","12.2787","8.1858","69.7349","258.0192"
"49.2800","12.2988","12.2988","8.1992","69.6954","257.8731"
"49.3600","12.3192","12.3192","8.2128","69.6627","257.7521"
"49.4400","12.3386","12.3386","8.2257","69.6213","257.5987"
"49.5200","12.3578","12.3578","8.2385","69.5823","257.4545"
"49.6000","12.3786","12.3786","8.2524","69.5535","257.3480"
"49.6800","12.3987","12.3987","8.2658","69.5198","257.2232"
"49.7600","12.4183","12.4183","8.2788","69.4841","257.0912"
"49.8400","12.4392","12.4392","8.2928","69.4574","256.9923"
"49.9200","12.4591","12.4591","8.3061","69.4206","256.8561"
"50.0000","12.4792","12.4792","8.3195","69.3871","256.7322"
"50.0800","12.4994","12.4994","8.3329","69.3563","256.6182"
"50.1600","12.5179","12.5179","8.3452","69.3127","256.4570"
"50.2400","12.5377","12.5377","8.3585","69.2783","256.3296"
"50.3200","12.5568","12.5568","8.3712","69.2399","256.1875"
"50.4000","12.5785","12.5785","8.3857","69.2195","256.1121"
"50.4800","12.5997","12.5997","8.3998","69.1909","256.0063"
"50.5600","12.6188","12.6188","8.4125","69.1541","255.8700"
"50.6400","12.6385","12.6385","8.4256","69.1181","255.7370"
"50.7200","12.6588","12.6588","8.4392","69.0870","255.6218"
"50.8000","12.6777","12.6777","8.4518","69.0532","255.4967"
"50.8800","12.6988","12.6988","8.4658","69.0282","255.4043"
"50.9600","12.7176","12.7176","8.4784","68.9887","255.2582"
"51.0400","12.7390","12.7390","8.4927","68.9680","255.1818"
"51.1200","12.7592","12.7592","8.5061","68.9370","255.0668"
"51.2000","12.7786","12.7786","8.5191","68.9046","254.9471"
"51.2800","12.7986","12.7986","8.5324","68.8753","254.8385"
"51.3600","12.8183","12.8183","8.5455","68.8415","254.7136"
"51.4400","12.8383","12.8383","8.5588","68.8123","254.6054"
"51.5200","12.8582","12.8582","8.5721","68.7797","254.4850"
"51.6000","12.8774","12.8774","8.5849","68.7460","254.3602"
"51.6800","12.8988","12.8988","8.5992","68.7244","254.2803"
"51.7600","12.9191","12.9191","8.6128","68.6904","254.1544"
"51.8400","12.9383","12.9383","8.6255","68.6577","254.0333"
"51.9200","12.9586","12.9586","8.6390","68.6297","253.9301"
"52.0000","12.9780","12.9780","8.6520","68.5932","253.7947"
"52.0800","12.9987","12.9987","8.6658","68.5650","253.6904"
"52.1600","13.0184","13.0184","8.6790","68.5315","253.5667"
"52.2400","13.0380","13.0380","8.6920","68.4991","253.4469"
"52.3200","13.0587","13.0587","8.7058","68.4759","253.3609"
"52.4000","13.0796","13.0796","8.7198","68.4468","253.2531"
"52.4800","13.0992","13.0992","8.7328","68.4158","253.1383"
"52.5600","13.1191","13.1191","8.7461","68.3868","253.0313"
"52.6400","13.1375","13.1375","8.7583","68.3488","252.8905"
"52.7200","13.1584","13.1584","8.7723","68.3261","252.8067"
"52.8000","13.1782","13.1782","8.7854","68.2959","252.6950"
"52.8800","13.1982","13.1982","8.7988","68.2710","252.6028"
"52.9600","13.2185","13.2185","8.8124","68.2431","252.4996"
"53.0400","13.2386","13.2386","8.8258","68.2116","252.3829"
"53.1200","13.2586","13.2586","8.8391","68.1807","252.2688"
"53.2000","13.2790","13.2790","8.8527","68.1534","252.1675"
"53.2800","13.2979","13.2979","8.8653","68.1179","252.0364"
"53.3600","13.3184","13.3184","8.8789","68.0883","251.9266"
"53.4400","13.3379","13.3379","8.8919","68.0510","251.7885"
"53.5200","13.3586","13.3586","8.9058","68.0257","251.6951"
"53.6000","13.3791","13.3791","8.9194","67.9932","251.5750"
"53.6800","13.3986","13.3986","8.9324","67.9623","251.4606"
"53.7600","13.4194","13.4194","8.9463","67.9331","251.3524"
"53.8400","13.4389","13.4389","8.9593","67.8984","251.2242"
"53.9200","13.4581","13.4581","8.9721","67.8646","251.0990"
"54.0000","13.4784","13.4784","8.9856","67.8359","250.9927"
"54.0800","13.4977","13.4977","8.9985","67.7964","250.8465"
"54.1600","13.5179","13.5179","9.0119","67.7686","250.7437"
"54.2400","13.5392","13.5392","9.0261","67.7424","250.6469"
"54.3200","13.5583","13.5583","9.0389","67.7084","250.5210"
"54.4000","13.5791","13.5791","9.0528","67.6769","250.4046"
"54.4800","13.5982","13.5982","9.0655","67.6390","250.2642"
"54.5600","13.6185","13.6185","9.0790","67.6086","250.1519"
"54.6400","13.6379","13.6379","9.0919","67.5754","250.0290"
"54.7200","13.6581","13.6581","9.1054","67.5451","249.9168"
"54.8000","13.6791","13.6791","9.1194","67.5147","249.8042"
"54.8800","13.6997","13.6997","9.1331","67.4804","249.6776"
"54.9600","13.7186","13.7186","9.1457","67.4434","249.5408"
"55.0400","13.7388","13.7388","9.1592","67.4104","249.4185"
"55.1200","13.7576","13.7576","9.1718","67.3675","249.2598"
"55.2000","13.7784","13.7784","9.1856","67.3361","249.1436"
"55.2800","13.7985","13.7985","9.1990","67.3001","249.0105"
"55.3600","13.8176","13.8176","9.2118","67.2611","248.8661"
"55.4400","13.8379","13.8379","9.2253","67.2265","248.7379"
"55.5200","13.8588","13.8588","9.2392","67.1984","248.6340"
"55.6000","13.8794","13.8794","9.2530","67.1637","248.5056"
"55.6800","13.8992","13.8992","9.2661","67.1240","248.3588"
"55.7600","13.9180","13.9180","9.2786","67.0783","248.1897"
"55.8400","13.9384","13.9384","9.2923","67.0383","248.0418"
"55.9200","13.9585","13.9585","9.3057","66.9970","247.8889"
"56.0000","13.9781","13.9781","9.3188","66.9545","247.7318"
"56.0800","13.9996","13.9996","9.3331","66.9154","247.5871"
"56.1600","14.0189","14.0189","9.3459","66.8670","247.4077"
"56.2400","14.0392","14.0392","9.3594","66.8257","247.2550"
"56.3200","14.0589","14.0589","9.3726","66.7791","247.0827"
"56.4000","14.0778","14.0778","9.3852","66.7353","246.9206"
"56.4800","14.0987","14.0987","9.3991","66.7033","246.8021"
"56.5600","14.1182","14.1182","9.4122","66.6511","246.6090"
"56.6400","14.1376","14.1376","9.4251","66.6079","246.4491"
"56.7200","14.1593","14.1593","9.4395","66.5747","246.3264"
"56.8000","14.1789","14.1789","9.4526","66.5253","246.1437"
"56.8800","14.1991","14.1991","9.4660","66.4810","245.9796"
"56.9600","14.2181","14.2181","9.4788","66.4341","245.8063"
"57.0400","14.2374","14.2374","9.4916","66.3932","245.6549"
"57.1200","14.2579","14.2579","9.5053","66.3534","245.5075"
"57.2000","14.2785","14.2785","9.5190","66.3145","245.3635"
"57.2800","14.2991","14.2991","9.5327","66.2730","245.2100"
"57.3600","14.3197","14.3197","9.5465","66.2319","245.0581"
"57.4400","14.3384","14.3384","9.5589","66.1847","244.8833"
"57.5200","14.3588","14.3588","9.5725","66.1444","244.7344"
"57.6000","14.3784","14.3784","9.5856","66.0986","244.5647"
"57.6800","14.3983","14.3983","9.5989","66.0554","244.4050"
"57.7600","14.4183","14.4183","9.6122","66.0121","244.2447"
"57.8400","14.4372","14.4372","9.6248","65.9634","244.0647"
"57.9200","14.4584","14.4584","9.6389","65.9248","243.9216"
"58.0000","14.4792","14.4792","9.6528","65.8854","243.7761"
"58.0800","14.4988","14.4988","9.6659","65.8363","243.5945"
"58.1600","14.5184","14.5184","9.6789","65.7914","243.4283"
"58.2400","14.5379","14.5379","9.6919","65.7377","243.2294"
"58.3200","14.5582","14.5582","9.7055","65.6949","243.0710"
"58.4000","14.5794","14.5794","9.7196","65.6539","242.9194"
"58.4800","14.5979","14.5979","9.7319","65.6017","242.7262"
"58.5600","14.6191","14.6191","9.7461","65.5596","242.5704"
"58.6400","14.6393","14.6393","9.7595","65.5131","242.3986"
"58.7200","14.6589","14.6589","9.7726","65.4652","242.2214"
"58.8000","14.6786","14.6786","9.7858","65.4197","242.0530"
"58.8800","14.6984","14.6984","9.7989","65.3667","241.8568"
"58.9600","14.7183","14.7183","9.8122","65.3120","241.6543"
"59.0400","14.7378","14.7378","9.8252","65.2554","241.4451"
"59.1200","14.7571","14.7571","9.8381","65.2062","241.2628"
"59.2000","14.7789","14.7789","9.8526","65.1664","241.1155"
"59.2800","14.7989","14.7989","9.8659","65.1118","240.9137"
"59.3600","14.8188","14.8188","9.8792","65.0583","240.7157"
"59.4400","14.8386","14.8386","9.8924","65.0066","240.5243"
"59.5200","14.8580","14.8580","9.9053","64.9506","240.3171"
"59.6000","14.8787","14.8787","9.9192","64.9031","240.1415"
"59.6800","14.8985","14.8985","9.9323","64.8458","239.9294"
"59.7600","14.9183","14.9183","9.9455","64.7926","239.7328"
"59.8400","14.9392","14.9392","9.9595","64.7462","239.5609"
"59.9200","14.9590","14.9590","9.9727","64.6890","239.3492"
"60.0000","14.9791","14.9791","9.9861","64.6382","239.1612"
"60.0800","14.9992","14.9992","9.9994","64.5851","238.9649"
"60.0840","15.0001","15.0001","10.0000","64.5823","238.9545"