File: data/instron_tests/509_NS_m1.is_comp_Exports/509_NS_m1_5_1.csv
Sample text inputs : Sample No.,Sample choice input : Leading Direction,Sample choice input : Mode,Specimen choice input : Direction,Specimen properties : Height,Specimen properties : Thickness,Specimen properties : Width,Test : Rate 1
,,,,(mm),(mm),(mm),(mm/min)
"509","Normal-Shear","Unimode","1","150.00","25.00","150.00","15.00"

Time,Displacement,Compressive displacement,Compressive strain (Displacement),Compressive stress,Force
(s),(mm),(mm),(%),(kPa),(N)
"0.0000","-0.0001","-0.0001","-0.0001","-1.1610","-4.2958"
"0.0800","0.0012","0.0012","0.0008","-1.1570","-4.2808"
"0.1600","0.0100","0.0100","0.0067","-1.1366","-4.2056"
"0.2400","0.0308","0.0308","0.0205","-1.0985","-4.0646"
"0.3200","0.0507","0.0507","0.0338","-1.0603","-3.9233"
"0.4000","0.0684","0.0684","0.0456","-1.0274","-3.8014"
"0.4800","0.0885","0.0885","0.0590","-0.9950","-3.6813"
"0.5600","0.1104","0.1104","0.0736","-0.9604","-3.5534"
"0.6400","0.1301","0.1301","0.0867","-0.9298","-3.4403"
"0.7200","0.1498","0.1498","0.0999","-0.9005","-3.3317"
"0.8000","0.1686","0.1686","0.1124","-0.8748","-3.2369"
"0.8800","0.1891","0.1891","0.1261","-0.8470","-3.1341"
"0.9600","0.2099","0.2099","0.1399","-0.8194","-3.0319"
"1.0400","0.2291","0.2291","0.1527","-0.7901","-2.9233"
"1.1200","0.2498","0.2498","0.1665","-0.7660","-2.8342"
"1.2000","0.2704","0.2704","0.1803","-0.7412","-2.7424"
"1.2800","0.2901","0.2901","0.1934","-0.7174","-2.6545"
"1.3600","0.3104","0.3104","0.2070","-0.6930","-2.5642"
"1.4400","0.3293","0.3293","0.2195","-0.6693","-2.4762"
"1.5200","0.3500","0.3500","0.2333","-0.6443","-2.3840"
"1.6000","0.3698","0.3698","0.2465","-0.6202","-2.2948"
"1.6800","0.3889","0.3889","0.2593","-0.5929","-2.1937"
"1.7600","0.4105","0.4105","0.2737","-0.5648","-2.0898"
"1.8400","0.4307","0.4307","0.2871","-0.5409","-2.0012"
"1.9200","0.4506","0.4506","0.3004","-0.5186","-1.9189"
"2.0000","0.4703","0.4703","0.3136","-0.4910","-1.8166"
"2.0800","0.4893","0.4893","0.3262","-0.4638","-1.7160"
"2.1600","0.5099","0.5099","0.3399","-0.4362","-1.6140"
"2.2400","0.5294","0.5294","0.3529","-0.4101","-1.5175"
"2.3200","0.5491","0.5491","0.3661","-0.3855","-1.4265"
"2.4000","0.5700","0.5700","0.3800","-0.3547","-1.3123"
"2.4800","0.5895","0.5895","0.3930","-0.3289","-1.2168"
"2.5600","0.6109","0.6109","0.4073","-0.3016","-1.1161"
"2.6400","0.6301","0.6301","0.4200","-0.2759","-1.0207"
"2.7200","0.6491","0.6491","0.4327","-0.2465","-0.9122"
"2.8000","0.6695","0.6695","0.4463","-0.2199","-0.8135"
"2.8800","0.6895","0.6895","0.4596","-0.1958","-0.7245"
"2.9600","0.7103","0.7103","0.4735","-0.1686","-0.6237"
"3.0400","0.7314","0.7314","0.4876","-0.1440","-0.5328"
"3.1200","0.7497","0.7497","0.4998","-0.1222","-0.4522"
"3.2000","0.7701","0.7701","0.5134","-0.0960","-0.3552"
"3.2800","0.7896","0.7896","0.5264","-0.0738","-0.2729"
"3.3600","0.8096","0.8096","0.5398","-0.0498","-0.1843"
"3.4400","0.8299","0.8299","0.5532","-0.0252","-0.0932"
"3.5200","0.8483","0.8483","0.5656","-0.0022","-0.0082"
"3.6000","0.8697","0.8697","0.5798","0.0228","0.0845"
"3.6800","0.8906","0.8906","0.5937","0.0480","0.1776"
"3.7600","0.9103","0.9103","0.6068","0.0693","0.2563"
"3.8400","0.9304","0.9304","0.6203","0.0947","0.3506"
"3.9200","0.9496","0.9496","0.6330","0.1179","0.4361"
"4.0000","0.9695","0.9695","0.6463","0.1403","0.5191"
"4.0800","0.9902","0.9902","0.6601","0.1693","0.6262"
"4.1600","1.0091","1.0091","0.6727","0.1943","0.7189"
"4.2400","1.0307","1.0307","0.6871","0.2258","0.8354"
"4.3200","1.0505","1.0505","0.7003","0.2542","0.9407"
"4.4000","1.0705","1.0705","0.7136","0.2817","1.0423"
"4.4800","1.0898","1.0898","0.7265","0.3137","1.1607"
"4.5600","1.1094","1.1094","0.7396","0.3432","1.2700"
"4.6400","1.1298","1.1298","0.7532","0.3768","1.3940"
"4.7200","1.1500","1.1500","0.7666","0.4123","1.5254"
"4.8000","1.1684","1.1684","0.7789","0.4463","1.6512"
"4.8800","1.1902","1.1902","0.7935","0.4827","1.7862"
"4.9600","1.2104","1.2104","0.8070","0.5198","1.9231"
"5.0400","1.2303","1.2303","0.8202","0.5515","2.0405"
"5.1200","1.2497","1.2497","0.8331","0.5836","2.1592"
"5.2000","1.2692","1.2692","0.8461","0.6225","2.3032"
"5.2800","1.2898","1.2898","0.8599","0.6564","2.4287"
"5.3600","1.3100","1.3100","0.8733","0.6918","2.5597"
"5.4400","1.3303","1.3303","0.8869","0.7222","2.6723"
"5.5200","1.3511","1.3511","0.9007","0.7611","2.8159"
"5.6000","1.3702","1.3702","0.9135","0.7950","2.9417"
"5.6800","1.3903","1.3903","0.9268","0.8292","3.0681"
"5.7600","1.4102","1.4102","0.9401","0.8674","3.2093"
"5.8400","1.4294","1.4294","0.9529","0.9040","3.3449"
"5.9200","1.4493","1.4493","0.9662","0.9380","3.4706"
"6.0000","1.4683","1.4683","0.9789","0.9712","3.5936"
"6.0800","1.4898","1.4898","0.9932","1.0102","3.7376"
"6.1600","1.5108","1.5108","1.0072","1.0399","3.8475"
"6.2400","1.5302","1.5302","1.0201","1.0779","3.9882"
"6.3200","1.5496","1.5496","1.0331","1.1132","4.1188"
"6.4000","1.5698","1.5698","1.0466","1.1515","4.2606"
"6.4800","1.5888","1.5888","1.0592","1.1876","4.3940"
"6.5600","1.6102","1.6102","1.0735","1.2250","4.5324"
"6.6400","1.6294","1.6294","1.0863","1.2597","4.6609"
"6.7200","1.6506","1.6506","1.1004","1.2979","4.8023"
"6.8000","1.6708","1.6708","1.1138","1.3307","4.9235"
"6.8800","1.6902","1.6902","1.1268","1.3660","5.0543"
"6.9600","1.7099","1.7099","1.1399","1.4016","5.1858"
"7.0400","1.7299","1.7299","1.1533","1.4392","5.3249"
"7.1200","1.7500","1.7500","1.1666","1.4772","5.4657"
"7.2000","1.7696","1.7696","1.1797","1.5116","5.5929"
"7.2800","1.7886","1.7886","1.1924","1.5502","5.7357"
"7.3600","1.8101","1.8101","1.2067","1.5895","5.8811"
"7.4400","1.8308","1.8308","1.2205","1.6235","6.0070"
"7.5200","1.8500","1.8500","1.2334","1.6591","6.1386"
"7.6000","1.8701","1.8701","1.2467","1.6963","6.2762"
"7.6800","1.8890","1.8890","1.2594","1.7300","6.4009"
"7.7600","1.9100","1.9100","1.2734","1.7708","6.5519"
"7.8400","1.9304","1.9304","1.2869","1.8092","6.6939"
"7.9200","1.9497","1.9497","1.2998","1.8466","6.8324"
"8.0000","1.9700","1.9700","1.3133","1.8858","6.9776"
"8.0800","1.9906","1.9906","1.3270","1.9237","7.1176"
"8.1600","2.0104","2.0104","1.3403","1.9528","7.2255"
"8.2400","2.0302","2.0302","1.3535","1.9911","7.3670"
"8.3200","2.0491","2.0491","1.3661","2.0281","7.5041"
"8.4000","2.0701","2.0701","1.3801","2.0683","7.6528"
"8.4800","2.0887","2.0887","1.3925","2.1047","7.7873"
"8.5600","2.1093","2.1093","1.4062","2.1460","7.9402"
"8.6400","2.1305","2.1305","1.4203","2.1863","8.0894"
"8.7200","2.1505","2.1505","1.4337","2.2237","8.2277"
"8.8000","2.1700","2.1700","1.4467","2.2536","8.3383"
"8.8800","2.1901","2.1901","1.4601","2.2905","8.4748"
"8.9600","2.2089","2.2089","1.4726","2.3305","8.6229"
"9.0400","2.2301","2.2301","1.4867","2.3711","8.7732"
"9.1200","2.2494","2.2494","1.4996","2.4074","8.9072"
"9.2000","2.2700","2.2700","1.5133","2.4469","9.0537"
"9.2800","2.2908","2.2908","1.5272","2.4859","9.1978"
"9.3600","2.3104","2.3104","1.5402","2.5230","9.3352"
"9.4400","2.3305","2.3305","1.5537","2.5573","9.4620"
"9.5200","2.3498","2.3498","1.5666","2.5945","9.5996"
"9.6000","2.3693","2.3693","1.5796","2.6329","9.7416"
"9.6800","2.3894","2.3894","1.5929","2.6732","9.8909"
"9.7600","2.4090","2.4090","1.6060","2.7099","10.0265"
"9.8400","2.4300","2.4300","1.6200","2.7486","10.1698"
"9.9200","2.4507","2.4507","1.6338","2.7889","10.3188"
"10.0000","2.4692","2.4692","1.6461","2.8269","10.4596"
"10.0800","2.4901","2.4901","1.6601","2.8636","10.5955"
"10.1600","2.5097","2.5097","1.6731","2.9009","10.7334"
"10.2400","2.5299","2.5299","1.6866","2.9375","10.8688"
"10.3200","2.5496","2.5496","1.6997","2.9750","11.0076"
"10.4000","2.5695","2.5695","1.7130","3.0162","11.1601"
"10.4800","2.5899","2.5899","1.7266","3.0573","11.3119"
"10.5600","2.6110","2.6110","1.7407","3.0982","11.4633"
"10.6400","2.6304","2.6304","1.7536","3.1368","11.6061"
"10.7200","2.6505","2.6505","1.7670","3.1712","11.7335"
"10.8000","2.6693","2.6693","1.7795","3.2052","11.8592"
"10.8800","2.6903","2.6903","1.7935","3.2440","12.0029"
"10.9600","2.7100","2.7100","1.8067","3.2827","12.1461"
"11.0400","2.7292","2.7292","1.8194","3.3203","12.2852"
"11.1200","2.7498","2.7498","1.8332","3.3602","12.4328"
"11.2000","2.7700","2.7700","1.8467","3.4001","12.5802"
"11.2800","2.7901","2.7901","1.8601","3.4382","12.7212"
"11.3600","2.8105","2.8105","1.8737","3.4764","12.8627"
"11.4400","2.8295","2.8295","1.8864","3.5112","12.9916"
"11.5200","2.8498","2.8498","1.8999","3.5499","13.1347"
"11.6000","2.8698","2.8698","1.9132","3.5862","13.2688"
"11.6800","2.8897","2.8897","1.9265","3.6274","13.4212"
"11.7600","2.9109","2.9109","1.9406","3.6698","13.5784"
"11.8400","2.9302","2.9302","1.9535","3.7059","13.7119"
"11.9200","2.9507","2.9507","1.9671","3.7441","13.8531"
"12.0000","2.9703","2.9703","1.9802","3.7839","14.0004"
"12.0800","2.9891","2.9891","1.9927","3.8215","14.1396"
"12.1600","3.0094","3.0094","2.0063","3.8570","14.2708"
"12.2400","3.0295","3.0295","2.0196","3.8949","14.4113"
"12.3200","3.0490","3.0490","2.0327","3.9330","14.5521"
"12.4000","3.0703","3.0703","2.0469","3.9760","14.7111"
"12.4800","3.0897","3.0897","2.0598","4.0123","14.8457"
"12.5600","3.1104","3.1104","2.0736","4.0516","14.9909"
"12.6400","3.1303","3.1303","2.0869","4.0884","15.1272"
"12.7200","3.1493","3.1493","2.0996","4.1267","15.2688"
"12.8000","3.1694","3.1694","2.1129","4.1650","15.4106"
"12.8800","3.1892","3.1892","2.1262","4.2016","15.5460"
"12.9600","3.2099","3.2099","2.1399","4.2428","15.6983"
"13.0400","3.2313","3.2313","2.1542","4.2797","15.8350"
"13.1200","3.2498","3.2498","2.1665","4.3172","15.9737"
"13.2000","3.2701","3.2701","2.1801","4.3551","16.1140"
"13.2800","3.2895","3.2895","2.1930","4.3901","16.2433"
"13.3600","3.3098","3.3098","2.2065","4.4303","16.3921"
"13.4400","3.3300","3.3300","2.2200","4.4714","16.5441"
"13.5200","3.3487","3.3487","2.2325","4.5051","16.6689"
"13.6000","3.3696","3.3696","2.2464","4.5453","16.8178"
"13.6800","3.3904","3.3904","2.2603","4.5867","16.9707"
"13.7600","3.4104","3.4104","2.2736","4.6247","17.1114"
"13.8400","3.4300","3.4300","2.2867","4.6637","17.2557"
"13.9200","3.4494","3.4494","2.2996","4.6994","17.3877"
"14.0000","3.4695","3.4695","2.3130","4.7363","17.5242"
"14.0800","3.4902","3.4902","2.3268","4.7762","17.6720"
"14.1600","3.5094","3.5094","2.3396","4.8099","17.7966"
"14.2400","3.5306","3.5306","2.3538","4.8508","17.9480"
"14.3200","3.5504","3.5504","2.3669","4.8912","18.0973"
"14.4000","3.5706","3.5706","2.3804","4.9287","18.2363"
"14.4800","3.5901","3.5901","2.3934","4.9664","18.3757"
"14.5600","3.6095","3.6095","2.4063","5.0048","18.5178"
"14.6400","3.6297","3.6297","2.4198","5.0418","18.6548"
"14.7200","3.6498","3.6498","2.4332","5.0784","18.7901"
"14.8000","3.6687","3.6687","2.4458","5.1172","18.9337"
"14.8800","3.6899","3.6899","2.4599","5.1610","19.0955"
"14.9600","3.7101","3.7101","2.4734","5.1982","19.2332"
"15.0400","3.7307","3.7307","2.4871","5.2367","19.3757"
"15.1200","3.7502","3.7502","2.5001","5.2740","19.5137"
"15.2000","3.7688","3.7688","2.5125","5.3125","19.6561"
"15.2800","3.7894","3.7894","2.5263","5.3514","19.8002"
"15.3600","3.8101","3.8101","2.5400","5.3913","19.9477"
"15.4400","3.8301","3.8301","2.5534","5.4300","20.0910"
"15.5200","3.8509","3.8509","2.5672","5.4686","20.2338"
"15.6000","3.8698","3.8698","2.5799","5.4989","20.3458"
"15.6800","3.8905","3.8905","2.5936","5.5399","20.4977"
"15.7600","3.9104","3.9104","2.6070","5.5793","20.6432"
"15.8400","3.9294","3.9294","2.6196","5.6176","20.7851"
"15.9200","3.9498","3.9498","2.6332","5.6578","20.9338"
"16.0000","3.9685","3.9685","2.6456","5.6918","21.0597"
"16.0800","3.9894","3.9894","2.6596","5.7307","21.2034"
"16.1600","4.0107","4.0107","2.6738","5.7723","21.3575"
"16.2400","4.0305","4.0305","2.6870","5.8106","21.4991"
"16.3200","4.0499","4.0499","2.7000","5.8474","21.6354"
"16.4000","4.0694","4.0694","2.7129","5.8861","21.7786"
"16.4800","4.0891","4.0891","2.7260","5.9237","21.9177"
"16.5600","4.1101","4.1101","2.7401","5.9655","22.0722"
"16.6400","4.1293","4.1293","2.7529","6.0024","22.2089"
"16.7200","4.1505","4.1505","2.7670","6.0391","22.3446"
"16.8000","4.1708","4.1708","2.7805","6.0827","22.5061"
"16.8800","4.1902","4.1902","2.7934","6.1206","22.6461"
"16.9600","4.2099","4.2099","2.8066","6.1570","22.7810"
"17.0400","4.2295","4.2295","2.8197","6.1920","22.9104"
"17.1200","4.2498","4.2498","2.8332","6.2314","23.0564"
"17.2000","4.2695","4.2695","2.8464","6.2709","23.2023"
"17.2800","4.2883","4.2883","2.8588","6.3049","23.3282"
"17.3600","4.3099","4.3099","2.8733","6.3496","23.4935"
"17.4400","4.3306","4.3306","2.8871","6.3895","23.6411"
"17.5200","4.3500","4.3500","2.9000","6.4210","23.7576"
"17.6000","4.3697","4.3697","2.9131","6.4598","23.9012"
"17.6800","4.3892","4.3892","2.9261","6.4951","24.0320"
"17.7600","4.4102","4.4102","2.9401","6.5373","24.1879"
"17.8400","4.4304","4.4304","2.9536","6.5735","24.3218"
"17.9200","4.4492","4.4492","2.9661","6.6113","24.4619"
"18.0000","4.4697","4.4697","2.9798","6.6526","24.6147"
"18.0800","4.4908","4.4908","2.9938","6.6922","24.7611"
"18.1600","4.5109","4.5109","3.0072","6.7297","24.9000"
"18.2400","4.5307","4.5307","3.0204","6.7660","25.0343"
"18.3200","4.5489","4.5489","3.0326","6.7993","25.1575"
"18.4000","4.5695","4.5695","3.0463","6.8401","25.3083"
"18.4800","4.5890","4.5890","3.0593","6.8766","25.4434"
"18.5600","4.6092","4.6092","3.0728","6.9157","25.5881"
"18.6400","4.6305","4.6305","3.0870","6.9560","25.7372"
"18.7200","4.6504","4.6504","3.1003","6.9945","25.8798"
"18.8000","4.6702","4.6702","3.1134","7.0298","26.0104"
"18.8800","4.6904","4.6904","3.1269","7.0695","26.1571"
"18.9600","4.7089","4.7089","3.1393","7.1056","26.2906"
"19.0400","4.7299","4.7299","3.1533","7.1481","26.4480"
"19.1200","4.7496","4.7496","3.1664","7.1836","26.5792"
"19.2000","4.7701","4.7701","3.1801","7.2223","26.7226"
"19.2800","4.7908","4.7908","3.1939","7.2619","26.8692"
"19.3600","4.8101","4.8101","3.2067","7.2995","27.0083"
"19.4400","4.8303","4.8303","3.2202","7.3371","27.1473"
"19.5200","4.8502","4.8502","3.2334","7.3766","27.2936"
"19.6000","4.8691","4.8691","3.2461","7.4140","27.4316"
"19.6800","4.8894","4.8894","3.2596","7.4517","27.5714"
"19.7600","4.9088","4.9088","3.2725","7.4842","27.6916"
"19.8400","4.9300","4.9300","3.2867","7.5250","27.8426"
"19.9200","4.9507","4.9507","3.3005","7.5654","27.9920"
"20.0000","4.9697","4.9697","3.3131","7.6001","28.1205"
"20.0800","4.9900","4.9900","3.3267","7.6409","28.2713"
"20.1600","5.0095","5.0095","3.3396","7.6799","28.4155"
"20.2400","5.0303","5.0303","3.3535","7.7180","28.5566"
"20.3200","5.0499","5.0499","3.3666","7.7577","28.7034"
"20.4000","5.0690","5.0690","3.3794","7.7930","28.8342"
"20.4800","5.0899","5.0899","3.3933","7.8323","28.9794"
"20.5600","5.1111","5.1111","3.4074","7.8736","29.1322"
"20.6400","5.1303","5.1303","3.4202","7.9098","29.2664"
"20.7200","5.1503","5.1503","3.4335","7.9481","29.4079"
"20.8000","5.1685","5.1685","3.4456","7.9818","29.5327"
"20.8800","5.1897","5.1897","3.4598","8.0234","29.6865"
"20.9600","5.2101","5.2101","3.4734","8.0600","29.8219"
"21.0400","5.2291","5.2291","3.4860","8.0970","29.9591"
"21.1200","5.2498","5.2498","3.4998","8.1383","30.1118"
"21.2000","5.2705","5.2705","3.5137","8.1793","30.2635"
"21.2800","5.2902","5.2902","3.5268","8.2157","30.3980"
"21.3600","5.3107","5.3107","3.5405","8.2561","30.5477"
"21.4400","5.3296","5.3296","3.5531","8.2929","30.6837"
"21.5200","5.3500","5.3500","3.5667","8.3300","30.8211"
"21.6000","5.3699","5.3699","3.5799","8.3670","30.9578"
"21.6800","5.3894","5.3894","3.5929","8.4071","31.1063"
"21.7600","5.4105","5.4105","3.6070","8.4500","31.2651"
"21.8400","5.4305","5.4305","3.6203","8.4849","31.3940"
"21.9200","5.4507","5.4507","3.6338","8.5231","31.5354"
"22.0000","5.4706","5.4706","3.6470","8.5616","31.6778"
"22.0800","5.4890","5.4890","3.6594","8.5955","31.8035"
"22.1600","5.5096","5.5096","3.6731","8.6357","31.9522"
"22.2400","5.5294","5.5294","3.6863","8.6735","32.0919"
"22.3200","5.5493","5.5493","3.6996","8.7146","32.2440"
"22.4000","5.5703","5.5703","3.7136","8.7540","32.3898"
"22.4800","5.5896","5.5896","3.7264","8.7896","32.5216"
"22.5600","5.6109","5.6109","3.7406","8.8327","32.6811"
"22.6400","5.6303","5.6303","3.7536","8.8684","32.8132"
"22.7200","5.6492","5.6492","3.7661","8.9045","32.9466"
"22.8000","5.6690","5.6690","3.7793","8.9426","33.0875"
"22.8800","5.6895","5.6895","3.7930","8.9772","33.2158"
"22.9600","5.7105","5.7105","3.8070","9.0203","33.3752"
"23.0400","5.7317","5.7317","3.8211","9.0605","33.5238"
"23.1200","5.7500","5.7500","3.8333","9.0970","33.6590"
"23.2000","5.7701","5.7701","3.8467","9.1349","33.7990"
"23.2800","5.7894","5.7894","3.8596","9.1706","33.9311"
"23.3600","5.8096","5.8096","3.8731","9.2121","34.0847"
"23.4400","5.8301","5.8301","3.8867","9.2497","34.2238"
"23.5200","5.8489","5.8489","3.8992","9.2841","34.3510"
"23.6000","5.8693","5.8693","3.9129","9.3221","34.4917"
"23.6800","5.8904","5.8904","3.9269","9.3644","34.6485"
"23.7600","5.9103","5.9103","3.9402","9.4035","34.7928"
"23.8400","5.9299","5.9299","3.9532","9.4431","34.9394"
"23.9200","5.9492","5.9492","3.9661","9.4743","35.0551"
"24.0000","5.9697","5.9697","3.9798","9.5141","35.2022"
"24.0800","5.9903","5.9903","3.9936","9.5509","35.3382"
"24.1600","6.0094","6.0094","4.0063","9.5919","35.4900"
"24.2400","6.0307","6.0307","4.0204","9.6320","35.6384"
"24.3200","6.0504","6.0504","4.0336","9.6687","35.7741"
"24.4000","6.0706","6.0706","4.0470","9.7078","35.9189"
"24.4800","6.0898","6.0898","4.0599","9.7444","36.0542"
"24.5600","6.1096","6.1096","4.0730","9.7831","36.1973"
"24.6400","6.1301","6.1301","4.0867","9.8204","36.3353"
"24.7200","6.1499","6.1499","4.0999","9.8603","36.4831"
"24.8000","6.1685","6.1685","4.1123","9.8965","36.6171"
"24.8800","6.1902","6.1902","4.1268","9.9403","36.7791"
"24.9600","6.2102","6.2102","4.1401","9.9764","36.9126"
"25.0400","6.2303","6.2303","4.1535","10.0138","37.0509"
"25.1200","6.2495","6.2495","4.1663","10.0494","37.1827"
"25.2000","6.2689","6.2689","4.1793","10.0878","37.3248"
"25.2800","6.2897","6.2897","4.1931","10.1266","37.4683"
"25.3600","6.3101","6.3101","4.2067","10.1652","37.6114"
"25.4400","6.3302","6.3302","4.2201","10.2076","37.7682"
"25.5200","6.3510","6.3510","4.2340","10.2449","37.9062"
"25.6000","6.3699","6.3699","4.2466","10.2800","38.0358"
"25.6800","6.3901","6.3901","4.2600","10.3164","38.1706"
"25.7600","6.4106","6.4106","4.2737","10.3586","38.3268"
"25.8400","6.4294","6.4294","4.2863","10.3922","38.4511"
"25.9200","6.4495","6.4495","4.2997","10.4333","38.6034"
"26.0000","6.4688","6.4688","4.3125","10.4673","38.7291"
"26.0800","6.4894","6.4894","4.3263","10.5069","38.8755"
"26.1600","6.5101","6.5101","4.3400","10.5474","39.0255"
"26.2400","6.5304","6.5304","4.3536","10.5880","39.1757"
"26.3200","6.5502","6.5502","4.3668","10.6249","39.3122"
"26.4000","6.5699","6.5699","4.3799","10.6614","39.4472"
"26.4800","6.5892","6.5892","4.3928","10.6973","39.5798"
"26.5600","6.6104","6.6104","4.4069","10.7384","39.7320"
"26.6400","6.6295","6.6295","4.4196","10.7739","39.8636"
"26.7200","6.6505","6.6505","4.4337","10.8151","40.0160"
"26.8000","6.6708","6.6708","4.4472","10.8547","40.1624"
"26.8800","6.6902","6.6902","4.4601","10.8905","40.2948"
"26.9600","6.7102","6.7102","4.4734","10.9330","40.4521"
"27.0400","6.7299","6.7299","4.4866","10.9679","40.5811"
"27.1200","6.7498","6.7498","4.4998","11.0063","40.7232"
"27.2000","6.7700","6.7700","4.5133","11.0430","40.8590"
"27.2800","6.7882","6.7882","4.5254","11.0783","40.9897"
"27.3600","6.8099","6.8099","4.5399","11.1199","41.1436"
"27.4400","6.8305","6.8305","4.5537","11.1605","41.2939"
"27.5200","6.8503","6.8503","4.5668","11.1959","41.4248"
"27.6000","6.8696","6.8696","4.5798","11.2345","41.5675"
"27.6800","6.8888","6.8888","4.5925","11.2712","41.7034"
"27.7600","6.9102","6.9102","4.6068","11.3108","41.8499"
"27.8400","6.9302","6.9302","4.6202","11.3476","41.9860"
"27.9200","6.9493","6.9493","4.6329","11.3842","42.1215"
"28.0000","6.9700","6.9700","4.6467","11.4274","42.2814"
"28.0800","6.9905","6.9905","4.6603","11.4635","42.4149"
"28.1600","7.0107","7.0107","4.6738","11.5037","42.5636"
"28.2400","7.0309","7.0309","4.6873","11.5404","42.6994"
"28.3200","7.0489","7.0489","4.6993","11.5742","42.8244"
"28.4000","7.0695","7.0695","4.7130","11.6153","42.9767"
"28.4800","7.0892","7.0892","4.7261","11.6512","43.1095"
"28.5600","7.1094","7.1094","4.7396","11.6915","43.2585"
"28.6400","7.1305","7.1305","4.7537","11.7319","43.4079"
"28.7200","7.1504","7.1504","4.7669","11.7673","43.5392"
"28.8000","7.1706","7.1706","4.7804","11.8049","43.6780"
"28.8800","7.1904","7.1904","4.7936","11.8423","43.8164"
"28.9600","7.2092","7.2092","4.8061","11.8811","43.9601"
"29.0400","7.2295","7.2295","4.8197","11.9189","44.0998"
"29.1200","7.2494","7.2494","4.8329","11.9580","44.2445"
"29.2000","7.2702","7.2702","4.8468","11.9952","44.3821"
"29.2800","7.2911","7.2911","4.8607","12.0355","44.5313"
"29.3600","7.3103","7.3103","4.8735","12.0715","44.6644"
"29.4400","7.3303","7.3303","4.8868","12.1088","44.8026"
"29.5200","7.3501","7.3501","4.9001","12.1468","44.9433"
"29.6000","7.3691","7.3691","4.9128","12.1833","45.0781"
"29.6800","7.3895","7.3895","4.9264","12.2234","45.2264"
"29.7600","7.4089","7.4089","4.9393","12.2606","45.3642"
"29.8400","7.4300","7.4300","4.9534","12.2997","45.5089"
"29.9200","7.4505","7.4505","4.9670","12.3368","45.6463"
"30.0000","7.4697","7.4697","4.9798","12.3757","45.7902"
"30.0800","7.4899","7.4899","4.9933","12.4147","45.9343"
"30.1600","7.5094","7.5094","5.0063","12.4509","46.0682"
"30.2400","7.5301","7.5301","5.0200","12.4884","46.2069"
"30.3200","7.5498","7.5498","5.0332","12.5288","46.3564"
"30.4000","7.5692","7.5692","5.0461","12.5641","46.4873"
"30.4800","7.5902","7.5902","5.0601","12.6060","46.6420"
"30.5600","7.6113","7.6113","5.0742","12.6452","46.7873"
"30.6400","7.6303","7.6303","5.0869","12.6829","46.9267"
"30.7200","7.6504","7.6504","5.1003","12.7210","47.0677"
"30.8000","7.6692","7.6692","5.1128","12.7564","47.1987"
"30.8800","7.6894","7.6894","5.1262","12.7944","47.3394"
"30.9600","7.7097","7.7097","5.1398","12.8303","47.4720"
"31.0400","7.7293","7.7293","5.1528","12.8737","47.6325"
"31.1200","7.7498","7.7498","5.1665","12.9113","47.7719"
"31.2000","7.7702","7.7702","5.1802","12.9507","47.9177"
"31.2800","7.7895","7.7895","5.1930","12.9855","48.0462"
"31.3600","7.8106","7.8106","5.2071","13.0239","48.1884"
"31.4400","7.8297","7.8297","5.2198","13.0627","48.3318"
"31.5200","7.8501","7.8501","5.2334","13.1014","48.4753"
"31.6000","7.8698","7.8698","5.2465","13.1362","48.6038"
"31.6800","7.8891","7.8891","5.2594","13.1739","48.7433"
"31.7600","7.9107","7.9107","5.2738","13.2170","48.9030"
"31.8400","7.9306","7.9306","5.2871","13.2546","49.0419"
"31.9200","7.9507","7.9507","5.3004","13.2910","49.1767"
"32.0000","7.9699","7.9699","5.3132","13.3262","49.3070"
"32.0800","7.9891","7.9891","5.3261","13.3636","49.4453"
"32.1600","8.0098","8.0098","5.3399","13.4068","49.6050"
"32.2400","8.0295","8.0295","5.3530","13.4422","49.7362"
"32.3200","8.0490","8.0490","5.3660","13.4780","49.8687"
"32.4000","8.0701","8.0701","5.3801","13.5188","50.0196"
"32.4800","8.0897","8.0897","5.3931","13.5560","50.1573"
"32.5600","8.1108","8.1108","5.4072","13.5980","50.3127"
"32.6400","8.1301","8.1301","5.4201","13.6331","50.4425"
"32.7200","8.1493","8.1493","5.4328","13.6702","50.5799"
"32.8000","8.1695","8.1695","5.4463","13.7117","50.7331"
"32.8800","8.1895","8.1895","5.4597","13.7483","50.8685"
"32.9600","8.2105","8.2105","5.4737","13.7878","51.0147"
"33.0400","8.2314","8.2314","5.4876","13.8261","51.1567"
"33.1200","8.2499","8.2499","5.4999","13.8625","51.2914"
"33.2000","8.2701","8.2701","5.5134","13.9001","51.4305"
"33.2800","8.2895","8.2895","5.5263","13.9391","51.5748"
"33.3600","8.3097","8.3097","5.5398","13.9766","51.7135"
"33.4400","8.3300","8.3300","5.5533","14.0170","51.8630"
"33.5200","8.3487","8.3487","5.5658","14.0511","51.9889"
"33.6000","8.3696","8.3696","5.5798","14.0915","52.1385"
"33.6800","8.3903","8.3903","5.5935","14.1321","52.2887"
"33.7600","8.4103","8.4103","5.6068","14.1690","52.4254"
"33.8400","8.4304","8.4304","5.6203","14.2103","52.5781"
"33.9200","8.4497","8.4497","5.6331","14.2453","52.7076"
"34.0000","8.4697","8.4697","5.6464","14.2852","52.8553"
"34.0800","8.4899","8.4899","5.6600","14.3184","52.9782"
"34.1600","8.5095","8.5095","5.6730","14.3624","53.1410"
"34.2400","8.5308","8.5308","5.6872","14.4042","53.2956"
"34.3200","8.5505","8.5505","5.7003","14.4386","53.4229"
"34.4000","8.5703","8.5703","5.7136","14.4738","53.5530"
"34.4800","8.5900","8.5900","5.7267","14.5170","53.7129"
"34.5600","8.6096","8.6096","5.7397","14.5500","53.8351"
"34.6400","8.6298","8.6298","5.7532","14.5864","53.9695"
"34.7200","8.6499","8.6499","5.7666","14.6272","54.1208"
"34.8000","8.6687","8.6687","5.7792","14.6650","54.2604"
"34.8800","8.6900","8.6900","5.7933","14.7077","54.4186"
"34.9600","8.7100","8.7100","5.8067","14.7454","54.5579"
"35.0400","8.7307","8.7307","5.8205","14.7844","54.7024"
"35.1200","8.7500","8.7500","5.8333","14.8210","54.8377"
"35.2000","8.7688","8.7688","5.8458","14.8564","54.9687"
"35.2800","8.7895","8.7895","5.8597","14.8955","55.1132"
"35.3600","8.8100","8.8100","5.8734","14.9371","55.2673"
"35.4400","8.8303","8.8303","5.8869","14.9762","55.4121"
"35.5200","8.8511","8.8511","5.9007","15.0147","55.5545"
"35.6000","8.8700","8.8700","5.9134","15.0515","55.6905"
"35.6800","8.8901","8.8901","5.9267","15.0904","55.8345"
"35.7600","8.9104","8.9104","5.9402","15.1289","55.9769"
"35.8400","8.9294","8.9294","5.9529","15.1673","56.1189"
"35.9200","8.9497","8.9497","5.9665","15.2069","56.2656"
"36.0000","8.9685","8.9685","5.9790","15.2410","56.3916"
"36.0800","8.9894","8.9894","5.9930","15.2803","56.5370"
"36.1600","9.0106","9.0106","6.0070","15.3222","56.6922"
"36.2400","9.0304","9.0304","6.0203","15.3607","56.8347"
"36.3200","9.0501","9.0501","6.0334","15.3986","56.9749"
"36.4000","9.0695","9.0695","6.0464","15.4340","57.1056"
"36.4800","9.0887","9.0887","6.0592","15.4738","57.2529"
"36.5600","9.1102","9.1102","6.0735","15.5138","57.4011"
"36.6400","9.1297","9.1297","6.0864","15.5491","57.5318"
"36.7200","9.1507","9.1507","6.1005","15.5913","57.6877"
"36.8000","9.1706","9.1706","6.1137","15.6269","57.8194"
"36.8800","9.1900","9.1900","6.1267","15.6658","57.9636"
"36.9600","9.2098","9.2098","6.1398","15.7062","58.1130"
"37.0400","9.2297","9.2297","6.1531","15.7397","58.2368"
"37.1200","9.2496","9.2496","6.1664","15.7787","58.3813"
"37.2000","9.2696","9.2696","6.1797","15.8166","58.5212"
"37.2800","9.2883","9.2883","6.1922","15.8532","58.6568"
"37.3600","9.3102","9.3102","6.2068","15.8966","58.8174"
"37.4400","9.3305","9.3305","6.2203","15.9349","58.9591"
"37.5200","9.3499","9.3499","6.2333","15.9714","59.0940"
"37.6000","9.3703","9.3703","6.2468","16.0112","59.2414"
"37.6800","9.3890","9.3890","6.2593","16.0455","59.3684"
"37.7600","9.4097","9.4097","6.2732","16.0858","59.5175"
"37.8400","9.4305","9.4305","6.2870","16.1236","59.6575"
"37.9200","9.4496","9.4496","6.2998","16.1643","59.8081"
"38.0000","9.4700","9.4700","6.3133","16.2032","59.9518"
"38.0800","9.4904","9.4904","6.3270","16.2423","60.0965"
"38.1600","9.5107","9.5107","6.3404","16.2814","60.2412"
"38.2400","9.5309","9.5309","6.3540","16.3168","60.3720"
"38.3200","9.5489","9.5489","6.3660","16.3521","60.5028"
"38.4000","9.5693","9.5693","6.3796","16.3921","60.6508"
"38.4800","9.5891","9.5891","6.3927","16.4285","60.7855"
"38.5600","9.6094","9.6094","6.4063","16.4712","60.9436"
"38.6400","9.6304","9.6304","6.4203","16.5131","61.0984"
"38.7200","9.6500","9.6500","6.4333","16.5492","61.2319"
"38.8000","9.6702","9.6702","6.4468","16.5831","61.3574"
"38.8800","9.6904","9.6904","6.4603","16.6235","61.5070"
"38.9600","9.7088","9.7088","6.4726","16.6609","61.6453"
"39.0400","9.7298","9.7298","6.4865","16.6987","61.7850"
"39.1200","9.7495","9.7495","6.4997","16.7354","61.9209"
"39.2000","9.7702","9.7702","6.5134","16.7763","62.0723"
"39.2800","9.7910","9.7910","6.5274","16.8168","62.2223"
"39.3600","9.8103","9.8103","6.5402","16.8550","62.3637"
"39.4400","9.8303","9.8303","6.5536","16.8938","62.5072"
"39.5200","9.8500","9.8500","6.5667","16.9313","62.6456"
"39.6000","9.8694","9.8694","6.5796","16.9708","62.7919"
"39.6800","9.8895","9.8895","6.5930","17.0080","62.9297"
"39.7600","9.9090","9.9090","6.6060","17.0437","63.0618"
"39.8400","9.9299","9.9299","6.6199","17.0823","63.2044"
"39.9200","9.9507","9.9507","6.6338","17.1222","63.3522"
"40.0000","9.9696","9.9696","6.6464","17.1632","63.5038"
"40.0800","9.9900","9.9900","6.6600","17.2018","63.6467"
"40.1600","10.0092","10.0092","6.6728","17.2382","63.7813"
"40.2400","10.0299","10.0299","6.6866","17.2768","63.9240"
"40.3200","10.0497","10.0497","6.6998","17.3159","64.0689"
"40.4000","10.0692","10.0692","6.7128","17.3524","64.2038"
"40.4800","10.0901","10.0901","6.7267","17.3925","64.3523"
"40.5600","10.1112","10.1112","6.7408","17.4349","64.5092"
"40.6400","10.1303","10.1303","6.7536","17.4727","64.6489"
"40.7200","10.1502","10.1502","6.7668","17.5109","64.7904"
"40.8000","10.1691","10.1691","6.7794","17.5461","64.9205"
"40.8800","10.1898","10.1898","6.7932","17.5878","65.0749"
"40.9600","10.2098","10.2098","6.8065","17.6247","65.2115"
"41.0400","10.2290","10.2290","6.8193","17.6617","65.3482"
"41.1200","10.2497","10.2497","6.8331","17.7032","65.5019"
"41.2000","10.2704","10.2704","6.8470","17.7397","65.6370"
"41.2800","10.2902","10.2902","6.8601","17.7794","65.7839"
"41.3600","10.3103","10.3104","6.8736","17.8195","65.9320"
"41.4400","10.3291","10.3291","6.8861","17.8528","66.0553"
"41.5200","10.3501","10.3501","6.9001","17.8954","66.2129"
"41.6000","10.3701","10.3701","6.9134","17.9348","66.3587"
"41.6800","10.3895","10.3895","6.9263","17.9723","66.4974"
"41.7600","10.4105","10.4105","6.9403","18.0155","66.6575"
"41.8400","10.4305","10.4305","6.9537","18.0514","66.7903"
"41.9200","10.4507","10.4507","6.9672","18.0900","66.9328"
"42.0000","10.4702","10.4702","6.9801","18.1246","67.0610"
"42.0800","10.4894","10.4894","6.9929","18.1651","67.2111"
"42.1600","10.5095","10.5095","7.0063","18.2028","67.3503"
"42.2400","10.5294","10.5294","7.0196","18.2407","67.4907"
"42.3200","10.5488","10.5488","7.0325","18.2782","67.6294"
"42.4000","10.5703","10.5703","7.0468","18.3204","67.7855"
"42.4800","10.5896","10.5896","7.0598","18.3579","67.9242"
"42.5600","10.6105","10.6105","7.0737","18.3968","68.0680"
"42.6400","10.6300","10.6300","7.0866","18.4342","68.2066"
"42.7200","10.6496","10.6496","7.0997","18.4731","68.3504"
"42.8000","10.6693","10.6693","7.1128","18.5105","68.4887"
"42.8800","10.6892","10.6892","7.1261","18.5497","68.6338"
"42.9600","10.7103","10.7103","7.1402","18.5901","68.7835"
"43.0400","10.7315","10.7315","7.1543","18.6323","68.9397"
"43.1200","10.7501","10.7501","7.1667","18.6663","69.0652"
"43.2000","10.7699","10.7699","7.1800","18.7050","69.2084"
"43.2800","10.7894","10.7894","7.1929","18.7447","69.3554"
"43.3600","10.8099","10.8099","7.2066","18.7838","69.5000"
"43.4400","10.8303","10.8303","7.2202","18.8240","69.6488"
"43.5200","10.8486","10.8486","7.2324","18.8601","69.7823"
"43.6000","10.8695","10.8695","7.2463","18.8980","69.9224"
"43.6800","10.8903","10.8903","7.2602","18.9400","70.0780"
"43.7600","10.9101","10.9101","7.2734","18.9800","70.2260"
"43.8400","10.9299","10.9299","7.2866","19.0165","70.3612"
"43.9200","10.9497","10.9497","7.2998","19.0536","70.4984"
"44.0000","10.9697","10.9697","7.3132","19.0935","70.6461"
"44.0800","10.9904","10.9904","7.3269","19.1314","70.7860"
"44.1600","11.0093","11.0093","7.3395","19.1689","70.9248"
"44.2400","11.0307","11.0307","7.3538","19.2116","71.0828"
"44.3200","11.0505","11.0505","7.3670","19.2492","71.2222"
"44.4000","11.0706","11.0706","7.3804","19.2876","71.3640"
"44.4800","11.0898","11.0898","7.3932","19.3233","71.4961"
"44.5600","11.1097","11.1097","7.4064","19.3646","71.6490"
"44.6400","11.1297","11.1297","7.4198","19.4018","71.7867"
"44.7200","11.1496","11.1496","7.4331","19.4368","71.9161"
"44.8000","11.1686","11.1686","7.4457","19.4761","72.0617"
"44.8800","11.1902","11.1902","7.4601","19.5199","72.2236"
"44.9600","11.2104","11.2104","7.4736","19.5574","72.3625"
"45.0400","11.2307","11.2307","7.4871","19.5950","72.5016"
"45.1200","11.2495","11.2495","7.4997","19.6339","72.6453"
"45.2000","11.2687","11.2687","7.5125","19.6723","72.7875"
"45.2800","11.2897","11.2897","7.5264","19.7133","72.9392"
"45.3600","11.3101","11.3101","7.5401","19.7535","73.0878"
"45.4400","11.3301","11.3301","7.5534","19.7923","73.2314"
"45.5200","11.3509","11.3509","7.5673","19.8344","73.3874"
"45.6000","11.3700","11.3700","7.5800","19.8683","73.5127"
"45.6800","11.3902","11.3902","7.5935","19.9087","73.6620"
"45.7600","11.4105","11.4105","7.6070","19.9478","73.8068"
"45.8400","11.4294","11.4294","7.6196","19.9846","73.9430"
"45.9200","11.4497","11.4497","7.6331","20.0257","74.0951"
"46.0000","11.4683","11.4683","7.6456","20.0614","74.2271"
"46.0800","11.4896","11.4896","7.6598","20.1015","74.3756"
"46.1600","11.5098","11.5098","7.6732","20.1402","74.5189"
"46.2400","11.5302","11.5302","7.6868","20.1799","74.6657"
"46.3200","11.5505","11.5505","7.7003","20.2209","74.8172"
"46.4000","11.5699","11.5699","7.7133","20.2574","74.9525"
"46.4800","11.5888","11.5888","7.7258","20.2943","75.0888"
"46.5600","11.6104","11.6104","7.7403","20.3354","75.2411"
"46.6400","11.6296","11.6296","7.7531","20.3718","75.3757"
"46.7200","11.6504","11.6504","7.7669","20.4133","75.5291"
"46.8000","11.6706","11.6706","7.7804","20.4524","75.6740"
"46.8800","11.6903","11.6903","7.7935","20.4913","75.8179"
"46.9600","11.7099","11.7099","7.8066","20.5313","75.9659"
"47.0400","11.7301","11.7301","7.8201","20.5696","76.1076"
"47.1200","11.7499","11.7499","7.8332","20.6077","76.2486"
"47.2000","11.7697","11.7697","7.8464","20.6429","76.3788"
"47.2800","11.7882","11.7882","7.8588","20.6820","76.5234"
"47.3600","11.8101","11.8101","7.8734","20.7261","76.6866"
"47.4400","11.8310","11.8310","7.8873","20.7669","76.8374"
"47.5200","11.8503","11.8503","7.9002","20.8040","76.9750"
"47.6000","11.8698","11.8698","7.9132","20.8410","77.1117"
"47.6800","11.8890","11.8890","7.9260","20.8771","77.2454"
"47.7600","11.9102","11.9102","7.9401","20.9183","77.3975"
"47.8400","11.9306","11.9306","7.9537","20.9571","77.5413"
"47.9200","11.9496","11.9496","7.9664","20.9963","77.6862"
"48.0000","11.9699","11.9699","7.9799","21.0371","77.8372"
"48.0800","11.9904","11.9904","7.9936","21.0781","77.9889"
"48.1600","12.0108","12.0108","8.0072","21.1158","78.1285"
"48.2400","12.0307","12.0307","8.0205","21.1522","78.2631"
"48.3200","12.0487","12.0487","8.0325","21.1889","78.3991"
"48.4000","12.0696","12.0696","8.0464","21.2290","78.5474"
"48.4800","12.0884","12.0884","8.0589","21.2634","78.6745"
"48.5600","12.1092","12.1092","8.0728","21.3072","78.8365"
"48.6400","12.1304","12.1304","8.0869","21.3484","78.9889"
"48.7200","12.1504","12.1504","8.1003","21.3856","79.1269"
"48.8000","12.1701","12.1701","8.1134","21.4245","79.2707"
"48.8800","12.1905","12.1905","8.1270","21.4637","79.4157"
"48.9600","12.2091","12.2091","8.1394","21.5006","79.5522"
"49.0400","12.2297","12.2297","8.1532","21.5417","79.7044"
"49.1200","12.2491","12.2491","8.1661","21.5789","79.8420"
"49.2000","12.2701","12.2701","8.1801","21.6203","79.9951"
"49.2800","12.2910","12.2910","8.1940","21.6618","80.1487"
"49.3600","12.3102","12.3102","8.2068","21.6976","80.2811"
"49.4400","12.3304","12.3304","8.2202","21.7349","80.4190"
"49.5200","12.3499","12.3499","8.2333","21.7747","80.5665"
"49.6000","12.3692","12.3692","8.2461","21.8119","80.7039"
"49.6800","12.3896","12.3896","8.2597","21.8558","80.8663"
"49.7600","12.4090","12.4090","8.2726","21.8901","80.9935"
"49.8400","12.4299","12.4299","8.2866","21.9314","81.1463"
"49.9200","12.4508","12.4508","8.3006","21.9717","81.2952"
"50.0000","12.4694","12.4694","8.3130","22.0085","81.4315"
"50.0800","12.4902","12.4901","8.3268","22.0506","81.5873"
"50.1600","12.5096","12.5096","8.3397","22.0860","81.7180"
"50.2400","12.5301","12.5301","8.3534","22.1269","81.8695"
"50.3200","12.5500","12.5500","8.3667","22.1672","82.0188"
"50.4000","12.5692","12.5692","8.3795","22.2043","82.1559"
"50.4800","12.5899","12.5899","8.3933","22.2455","82.3084"
"50.5600","12.6112","12.6112","8.4075","22.2871","82.4623"
"50.6400","12.6305","12.6305","8.4203","22.3237","82.5978"
"50.7200","12.6503","12.6503","8.4336","22.3625","82.7413"
"50.8000","12.6689","12.6689","8.4460","22.3944","82.8592"
"50.8800","12.6899","12.6899","8.4599","22.4389","83.0238"
"50.9600","12.7097","12.7097","8.4731","22.4769","83.1645"
"51.0400","12.7289","12.7289","8.4859","22.5146","83.3040"
"51.1200","12.7497","12.7497","8.4998","22.5568","83.4600"
"51.2000","12.7706","12.7706","8.5137","22.5995","83.6181"
"51.2800","12.7902","12.7902","8.5268","22.6377","83.7596"
"51.3600","12.8100","12.8100","8.5400","22.6738","83.8932"
"51.4400","12.8290","12.8290","8.5527","22.7096","84.0253"
"51.5200","12.8502","12.8502","8.5668","22.7512","84.1796"
"51.6000","12.8702","12.8702","8.5801","22.7910","84.3268"
"51.6800","12.8894","12.8894","8.5930","22.8295","84.4692"
"51.7600","12.9110","12.9110","8.6073","22.8717","84.6254"
"51.8400","12.9303","12.9303","8.6202","22.9091","84.7637"
"51.9200","12.9506","12.9506","8.6337","22.9460","84.9004"
"52.0000","12.9703","12.9703","8.6469","22.9853","85.0457"
"52.0800","12.9894","12.9894","8.6596","23.0242","85.1897"
"52.1600","13.0097","13.0097","8.6731","23.0631","85.3336"
"52.2400","13.0294","13.0294","8.6863","23.1018","85.4767"
"52.3200","13.0490","13.0490","8.6993","23.1388","85.6136"
"52.4000","13.0704","13.0704","8.7136","23.1815","85.7716"
"52.4800","13.0897","13.0897","8.7265","23.2206","85.9161"
"52.5600","13.1106","13.1106","8.7404","23.2610","86.0658"
"52.6400","13.1300","13.1300","8.7533","23.2980","86.2027"
"52.7200","13.1497","13.1497","8.7664","23.3367","86.3459"
"52.8000","13.1694","13.1694","8.7796","23.3764","86.4927"
"52.8800","13.1895","13.1895","8.7930","23.4156","86.6376"
"52.9600","13.2104","13.2104","8.8069","23.4553","86.7846"
"53.0400","13.2315","13.2315","8.8210","23.4972","86.9396"
"53.1200","13.2499","13.2499","8.8333","23.5322","87.0693"
"53.2000","13.2701","13.2701","8.8467","23.5707","87.2117"
"53.2800","13.2893","13.2893","8.8595","23.6097","87.3560"
"53.3600","13.3095","13.3095","8.8730","23.6500","87.5051"
"53.4400","13.3300","13.3300","8.8867","23.6888","87.6486"
"53.5200","13.3487","13.3487","8.8991","23.7249","87.7822"
"53.6000","13.3700","13.3700","8.9133","23.7673","87.9390"
"53.6800","13.3905","13.3905","8.9270","23.8078","88.0889"
"53.7600","13.4101","13.4101","8.9401","23.8460","88.2302"
"53.8400","13.4304","13.4304","8.9536","23.8889","88.3888"
"53.9200","13.4495","13.4495","8.9663","23.9226","88.5138"
"54.0000","13.4696","13.4696","8.9797","23.9618","88.6588"
"54.0800","13.4900","13.4900","8.9934","24.0020","88.8074"
"54.1600","13.5091","13.5091","9.0061","24.0412","88.9525"
"54.2400","13.5308","13.5308","9.0205","24.0853","89.1155"
"54.3200","13.5505","13.5505","9.0337","24.1220","89.2514"
"54.4000","13.5700","13.5700","9.0467","24.1580","89.3846"
"54.4800","13.5897","13.5897","9.0598","24.1994","89.5377"
"54.5600","13.6102","13.6102","9.0734","24.2394","89.6858"
"54.6400","13.6303","13.6303","9.0868","24.2770","89.8248"
"54.7200","13.6501","13.6501","9.1000","24.3134","89.9595"
"54.8000","13.6686","13.6686","9.1124","24.3511","90.0990"
"54.8800","13.6899","13.6899","9.1266","24.3956","90.2637"
"54.9600","13.7103","13.7103","9.1402","24.4356","90.4118"
"55.0400","13.7308","13.7308","9.1538","24.4726","90.5487"
"55.1200","13.7502","13.7502","9.1668","24.5100","90.6871"
"55.2000","13.7687","13.7687","9.1791","24.5461","90.8206"
"55.2800","13.7892","13.7892","9.1928","24.5857","90.9670"
"55.3600","13.8101","13.8101","9.2067","24.6286","91.1259"
"55.4400","13.8304","13.8304","9.2203","24.6692","91.2759"
"55.5200","13.8509","13.8509","9.2340","24.7106","91.4293"
"55.6000","13.8699","13.8699","9.2466","24.7448","91.5557"
"55.6800","13.8903","13.8903","9.2602","24.7859","91.7079"
"55.7600","13.9100","13.9100","9.2734","24.8228","91.8443"
"55.8400","13.9293","13.9293","9.2862","24.8595","91.9802"
"55.9200","13.9497","13.9497","9.2998","24.9007","92.1326"
"56.0000","13.9684","13.9684","9.3123","24.9342","92.2565"
"56.0800","13.9895","13.9895","9.3263","24.9748","92.4068"
"56.1600","14.0108","14.0108","9.3405","25.0174","92.5644"
"56.2400","14.0301","14.0301","9.3534","25.0586","92.7168"
"56.3200","14.0499","14.0499","9.3666","25.0948","92.8508"
"56.4000","14.0698","14.0698","9.3799","25.1318","92.9875"
"56.4800","14.0893","14.0893","9.3928","25.1715","93.1344"
"56.5600","14.1102","14.1102","9.4068","25.2134","93.2896"
"56.6400","14.1292","14.1292","9.4195","25.2506","93.4273"
"56.7200","14.1502","14.1502","9.4334","25.2890","93.5694"
"56.8000","14.1705","14.1705","9.4470","25.3282","93.7143"
"56.8800","14.1903","14.1903","9.4602","25.3682","93.8625"
"56.9600","14.2103","14.2103","9.4735","25.4101","94.0174"
"57.0400","14.2300","14.2300","9.4867","25.4432","94.1397"
"57.1200","14.2497","14.2497","9.4998","25.4834","94.2886"
"57.2000","14.2697","14.2697","9.5131","25.5208","94.4269"
"57.2800","14.2888","14.2888","9.5258","25.5585","94.5664"
"57.3600","14.3103","14.3103","9.5402","25.6003","94.7211"
"57.4400","14.3304","14.3304","9.5536","25.6390","94.8644"
"57.5200","14.3501","14.3501","9.5668","25.6792","95.0132"
"57.6000","14.3700","14.3700","9.5800","25.7192","95.1611"
"57.6800","14.3890","14.3890","9.5927","25.7507","95.2774"
"57.7600","14.4100","14.4100","9.6066","25.7941","95.4380"
"57.8400","14.4305","14.4305","9.6204","25.8351","95.5897"
"57.9200","14.4500","14.4500","9.6333","25.8734","95.7317"
"58.0000","14.4699","14.4699","9.6466","25.9119","95.8742"
"58.0800","14.4904","14.4904","9.6602","25.9514","96.0202"
"58.1600","14.5108","14.5108","9.6739","25.9907","96.1657"
"58.2400","14.5306","14.5306","9.6870","26.0292","96.3079"
"58.3200","14.5488","14.5488","9.6992","26.0599","96.4216"
"58.4000","14.5691","14.5691","9.7127","26.1008","96.5730"
"58.4800","14.5892","14.5892","9.7261","26.1422","96.7262"
"58.5600","14.6094","14.6094","9.7396","26.1803","96.8670"
"58.6400","14.6303","14.6303","9.7535","26.2239","97.0286"
"58.7200","14.6502","14.6502","9.7668","26.2594","97.1598"
"58.8000","14.6701","14.6701","9.7800","26.2950","97.2917"
"58.8800","14.6902","14.6902","9.7935","26.3343","97.4368"
"58.9600","14.7091","14.7091","9.8061","26.3721","97.5769"
"59.0400","14.7298","14.7298","9.8199","26.4120","97.7246"
"59.1200","14.7492","14.7492","9.8328","26.4494","97.8629"
"59.2000","14.7699","14.7699","9.8466","26.4899","98.0126"
"59.2800","14.7909","14.7909","9.8606","26.5300","98.1610"
"59.3600","14.8104","14.8104","9.8736","26.5690","98.3054"
"59.4400","14.8307","14.8307","9.8871","26.6061","98.4426"
"59.5200","14.8494","14.8494","9.8996","26.6406","98.5704"
"59.6000","14.8689","14.8689","9.9126","26.6778","98.7079"
"59.6800","14.8896","14.8896","9.9264","26.7225","98.8734"
"59.7600","14.9090","14.9090","9.9393","26.7544","98.9912"
"59.8400","14.9297","14.9297","9.9532","26.7972","99.1495"
"59.9200","14.9505","14.9505","9.9670","26.8369","99.2967"
"60.0000","14.9695","14.9695","9.9797","26.8729","99.4298"
"60.0800","14.9902","14.9902","9.9935","26.9159","99.5889"
"60.1190","15.0001","15.0001","10.0001","26.9322","99.6493"