File: data/instron_tests/509_NS_m1.is_comp_Exports/509_NS_m1_3_1.csv
Sample text inputs : Sample No.,Sample choice input : Leading Direction,Sample choice input : Mode,Specimen choice input : Direction,Specimen properties : Height,Specimen properties : Thickness,Specimen properties : Width,Test : Rate 1
,,,,(mm),(mm),(mm),(mm/min)
"509","Normal-Shear","Unimode","1","150.00","25.00","150.00","15.00"

Time,Displacement,Compressive displacement,Compressive strain (Displacement),Compressive stress,Force
(s),(mm),(mm),(%),(kPa),(N)
"0.0000","0.0000","0.0000","0.0000","-1.0472","-3.8748"
"0.0800","0.0019","0.0019","0.0012","-1.0331","-3.8223"
"0.1600","0.0201","0.0201","0.0134","-0.9423","-3.4867"
"0.2400","0.0401","0.0401","0.0267","-0.8563","-3.1682"
"0.3200","0.0593","0.0593","0.0395","-0.8131","-3.0085"
"0.4000","0.0799","0.0799","0.0532","-0.7337","-2.7145"
"0.4800","0.1009","0.1009","0.0673","-0.6640","-2.4568"
"0.5600","0.1198","0.1198","0.0799","-0.6111","-2.2610"
"0.6400","0.1398","0.1398","0.0932","-0.5431","-2.0095"
"0.7200","0.1593","0.1593","0.1062","-0.4914","-1.8184"
"0.8000","0.1792","0.1792","0.1194","-0.4289","-1.5870"
"0.8800","0.1997","0.1997","0.1331","-0.3681","-1.3621"
"0.9600","0.2195","0.2195","0.1463","-0.3127","-1.1569"
"1.0400","0.2396","0.2396","0.1597","-0.2486","-0.9198"
"1.1200","0.2607","0.2607","0.1738","-0.1843","-0.6819"
"1.2000","0.2801","0.2801","0.1867","-0.1208","-0.4470"
"1.2800","0.3003","0.3003","0.2002","-0.0625","-0.2314"
"1.3600","0.3194","0.3194","0.2129","-0.0063","-0.0233"
"1.4400","0.3391","0.3391","0.2261","0.0570","0.2108"
"1.5200","0.3592","0.3592","0.2395","0.1025","0.3794"
"1.6000","0.3789","0.3789","0.2526","0.1678","0.6210"
"1.6800","0.4000","0.4000","0.2667","0.2286","0.8457"
"1.7600","0.4200","0.4200","0.2800","0.2936","1.0862"
"1.8400","0.4392","0.4392","0.2928","0.3563","1.3182"
"1.9200","0.4599","0.4599","0.3066","0.4271","1.5803"
"2.0000","0.4788","0.4788","0.3192","0.4915","1.8186"
"2.0800","0.5000","0.5000","0.3333","0.5648","2.0898"
"2.1600","0.5198","0.5198","0.3466","0.6384","2.3622"
"2.2400","0.5387","0.5387","0.3592","0.7049","2.6081"
"2.3200","0.5600","0.5600","0.3733","0.7892","2.9201"
"2.4000","0.5805","0.5805","0.3870","0.8606","3.1843"
"2.4800","0.6003","0.6003","0.4002","0.9334","3.4537"
"2.5600","0.6198","0.6198","0.4132","1.0081","3.7300"
"2.6400","0.6384","0.6384","0.4256","1.0715","3.9646"
"2.7200","0.6595","0.6595","0.4397","1.1582","4.2854"
"2.8000","0.6793","0.6793","0.4529","1.2363","4.5742"
"2.8800","0.6984","0.6984","0.4656","1.3017","4.8163"
"2.9600","0.7196","0.7196","0.4797","1.3986","5.1747"
"3.0400","0.7397","0.7397","0.4931","1.4801","5.4762"
"3.1200","0.7602","0.7602","0.5068","1.5607","5.7745"
"3.2000","0.7802","0.7802","0.5201","1.6489","6.1010"
"3.2800","0.7989","0.7989","0.5326","1.7301","6.4013"
"3.3600","0.8196","0.8196","0.5464","1.8245","6.7505"
"3.4400","0.8389","0.8389","0.5592","1.9143","7.0829"
"3.5200","0.8594","0.8594","0.5730","2.0069","7.4254"
"3.6000","0.8814","0.8814","0.5876","2.1041","7.7853"
"3.6800","0.9003","0.9003","0.6002","2.1944","8.1193"
"3.7600","0.9201","0.9201","0.6134","2.2893","8.4706"
"3.8400","0.9396","0.9396","0.6264","2.3680","8.7615"
"3.9200","0.9592","0.9592","0.6395","2.4697","9.1378"
"4.0000","0.9796","0.9796","0.6531","2.5701","9.5095"
"4.0800","0.9983","0.9983","0.6655","2.6473","9.7950"
"4.1600","1.0191","1.0191","0.6794","2.7609","10.2153"
"4.2400","1.0402","1.0402","0.6935","2.8638","10.5961"
"4.3200","1.0596","1.0596","0.7064","2.9542","10.9305"
"4.4000","1.0801","1.0801","0.7201","3.0658","11.3433"
"4.4800","1.0993","1.0993","0.7329","3.1558","11.6765"
"4.5600","1.1191","1.1191","0.7461","3.2609","12.0655"
"4.6400","1.1394","1.1394","0.7596","3.3736","12.4823"
"4.7200","1.1590","1.1590","0.7727","3.4698","12.8381"
"4.8000","1.1801","1.1801","0.7867","3.5893","13.2806"
"4.8800","1.2006","1.2006","0.8004","3.7039","13.7043"
"4.9600","1.2199","1.2199","0.8133","3.8070","14.0858"
"5.0400","1.2397","1.2397","0.8264","3.9196","14.5027"
"5.1200","1.2588","1.2588","0.8392","4.0259","14.8957"
"5.2000","1.2794","1.2794","0.8529","4.1326","15.2906"
"5.2800","1.2996","1.2996","0.8664","4.2513","15.7299"
"5.3600","1.3188","1.3188","0.8792","4.3653","16.1516"
"5.4400","1.3394","1.3394","0.8929","4.4868","16.6012"
"5.5200","1.3600","1.3600","0.9067","4.6005","17.0220"
"5.6000","1.3802","1.3802","0.9202","4.7259","17.4857"
"5.6800","1.4006","1.4006","0.9337","4.8513","17.9499"
"5.7600","1.4190","1.4190","0.9460","4.9652","18.3714"
"5.8400","1.4393","1.4393","0.9595","5.0903","18.8339"
"5.9200","1.4596","1.4596","0.9731","5.2024","19.2490"
"6.0000","1.4794","1.4794","0.9863","5.3308","19.7240"
"6.0800","1.5005","1.5005","1.0003","5.4684","20.2329"
"6.1600","1.5200","1.5200","1.0134","5.5926","20.6925"
"6.2400","1.5401","1.5401","1.0267","5.7238","21.1781"
"6.3200","1.5601","1.5601","1.0401","5.8512","21.6494"
"6.4000","1.5793","1.5793","1.0529","5.9693","22.0864"
"6.4800","1.5994","1.5994","1.0663","6.1026","22.5798"
"6.5600","1.6190","1.6190","1.0793","6.2312","23.0554"
"6.6400","1.6385","1.6385","1.0923","6.3642","23.5474"
"6.7200","1.6609","1.6609","1.1073","6.5175","24.1149"
"6.8000","1.6800","1.6800","1.1200","6.6420","24.5752"
"6.8800","1.6994","1.6994","1.1329","6.7632","25.0239"
"6.9600","1.7193","1.7193","1.1462","6.9015","25.5355"
"7.0400","1.7393","1.7393","1.1595","7.0434","26.0606"
"7.1200","1.7593","1.7593","1.1729","7.1848","26.5838"
"7.2000","1.7794","1.7794","1.1863","7.3242","27.0995"
"7.2800","1.7999","1.7999","1.2000","7.4717","27.6455"
"7.3600","1.8210","1.8210","1.2140","7.6123","28.1657"
"7.4400","1.8395","1.8395","1.2263","7.7421","28.6458"
"7.5200","1.8599","1.8599","1.2399","7.8886","29.1877"
"7.6000","1.8793","1.8793","1.2529","8.0286","29.7058"
"7.6800","1.8995","1.8995","1.2664","8.1762","30.2518"
"7.7600","1.9188","1.9188","1.2792","8.3139","30.7614"
"7.8400","1.9382","1.9382","1.2922","8.4541","31.2800"
"7.9200","1.9596","1.9596","1.3064","8.6023","31.8287"
"8.0000","1.9806","1.9806","1.3204","8.7633","32.4244"
"8.0800","1.9998","1.9998","1.3332","8.9038","32.9441"
"8.1600","2.0194","2.0194","1.3463","9.0486","33.4797"
"8.2400","2.0388","2.0388","1.3592","9.1896","34.0014"
"8.3200","2.0591","2.0591","1.3727","9.3452","34.5772"
"8.4000","2.0801","2.0801","1.3867","9.5025","35.1591"
"8.4800","2.0992","2.0992","1.3995","9.6452","35.6874"
"8.5600","2.1206","2.1206","1.4138","9.8094","36.2946"
"8.6400","2.1400","2.1400","1.4267","9.9577","36.8435"
"8.7200","2.1603","2.1603","1.4402","10.1139","37.4215"
"8.8000","2.1798","2.1798","1.4532","10.2617","37.9684"
"8.8800","2.1993","2.1993","1.4662","10.4096","38.5156"
"8.9600","2.2194","2.2194","1.4796","10.5624","39.0809"
"9.0400","2.2395","2.2395","1.4930","10.7174","39.6544"
"9.1200","2.2586","2.2586","1.5057","10.8592","40.1791"
"9.2000","2.2801","2.2801","1.5200","11.0300","40.8110"
"9.2800","2.2998","2.2998","1.5332","11.1809","41.3692"
"9.3600","2.3203","2.3203","1.5469","11.3412","41.9625"
"9.4400","2.3398","2.3398","1.5599","11.4902","42.5138"
"9.5200","2.3587","2.3587","1.5725","11.6370","43.0570"
"9.6000","2.3793","2.3793","1.5862","11.8018","43.6668"
"9.6800","2.3999","2.3999","1.5999","11.9575","44.2429"
"9.7600","2.4196","2.4196","1.6131","12.1082","44.8002"
"9.8400","2.4401","2.4401","1.6268","12.2753","45.4186"
"9.9200","2.4598","2.4598","1.6399","12.4258","45.9754"
"10.0000","2.4805","2.4805","1.6537","12.5929","46.5936"
"10.0800","2.5001","2.5001","1.6667","12.7463","47.1614"
"10.1600","2.5191","2.5191","1.6794","12.8958","47.7143"
"10.2400","2.5387","2.5387","1.6925","13.0531","48.2966"
"10.3200","2.5576","2.5576","1.7051","13.2001","48.8402"
"10.4000","2.5800","2.5800","1.7200","13.3829","49.5167"
"10.4800","2.6011","2.6011","1.7341","13.5489","50.1310"
"10.5600","2.6198","2.6198","1.7465","13.6935","50.6660"
"10.6400","2.6394","2.6394","1.7596","13.8517","51.2515"
"10.7200","2.6596","2.6596","1.7730","14.0134","51.8496"
"10.8000","2.6789","2.6789","1.7859","14.1704","52.4306"
"10.8800","2.7001","2.7001","1.8000","14.3414","53.0631"
"10.9600","2.7187","2.7187","1.8125","14.4904","53.6146"
"11.0400","2.7401","2.7401","1.8267","14.6645","54.2585"
"11.1200","2.7605","2.7605","1.8403","14.8298","54.8703"
"11.2000","2.7805","2.7805","1.8537","14.9917","55.4694"
"11.2800","2.7996","2.7996","1.8664","15.1435","56.0311"
"11.3600","2.8193","2.8193","1.8795","15.2997","56.6090"
"11.4400","2.8392","2.8392","1.8928","15.4648","57.2196"
"11.5200","2.8598","2.8598","1.9065","15.6310","57.8349"
"11.6000","2.8788","2.8788","1.9192","15.7863","58.4093"
"11.6800","2.8999","2.8999","1.9332","15.9603","59.0531"
"11.7600","2.9201","2.9201","1.9467","16.1220","59.6514"
"11.8400","2.9394","2.9394","1.9596","16.2776","60.2271"
"11.9200","2.9595","2.9595","1.9730","16.4405","60.8299"
"12.0000","2.9791","2.9791","1.9861","16.6007","61.4224"
"12.0800","2.9999","2.9999","1.9999","16.7682","62.0423"
"12.1600","3.0198","3.0198","2.0132","16.9293","62.6384"
"12.2400","3.0395","3.0395","2.0264","17.0989","63.2658"
"12.3200","3.0599","3.0599","2.0399","17.2670","63.8879"
"12.4000","3.0804","3.0804","2.0536","17.4300","64.4910"
"12.4800","3.1003","3.1003","2.0669","17.5910","65.0866"
"12.5600","3.1199","3.1199","2.0799","17.7445","65.6548"
"12.6400","3.1384","3.1384","2.0923","17.8893","66.1905"
"12.7200","3.1597","3.1597","2.1064","18.0624","66.8310"
"12.8000","3.1792","3.1792","2.1195","18.2211","67.4179"
"12.8800","3.1995","3.1995","2.1330","18.3851","68.0248"
"12.9600","3.2197","3.2197","2.1465","18.5496","68.6336"
"13.0400","3.2396","3.2396","2.1597","18.7068","69.2153"
"13.1200","3.2598","3.2598","2.1732","18.8700","69.8191"
"13.2000","3.2805","3.2805","2.1870","19.0382","70.4414"
"13.2800","3.2992","3.2992","2.1995","19.1895","71.0011"
"13.3600","3.3194","3.3194","2.2129","19.3522","71.6030"
"13.4400","3.3389","3.3389","2.2260","19.5099","72.1867"
"13.5200","3.3603","3.3603","2.2402","19.6837","72.8297"
"13.6000","3.3808","3.3808","2.2539","19.8478","73.4369"
"13.6800","3.3998","3.3998","2.2666","20.0016","74.0058"
"13.7600","3.4200","3.4200","2.2800","20.1696","74.6273"
"13.8400","3.4397","3.4397","2.2931","20.3303","75.2223"
"13.9200","3.4590","3.4590","2.3060","20.4839","75.7904"
"14.0000","3.4796","3.4796","2.3197","20.6500","76.4049"
"14.0800","3.4986","3.4986","2.3324","20.7984","76.9543"
"14.1600","3.5191","3.5191","2.3461","20.9636","77.5652"
"14.2400","3.5405","3.5405","2.3603","21.1391","78.2148"
"14.3200","3.5596","3.5596","2.3731","21.2920","78.7803"
"14.4000","3.5800","3.5800","2.3867","21.4558","79.3864"
"14.4800","3.5995","3.5995","2.3997","21.6123","79.9654"
"14.5600","3.6192","3.6192","2.4128","21.7649","80.5300"
"14.6400","3.6391","3.6391","2.4261","21.9238","81.1182"
"14.7200","3.6587","3.6587","2.4392","22.0805","81.6978"
"14.8000","3.6799","3.6799","2.4533","22.2511","82.3290"
"14.8800","3.7008","3.7008","2.4672","22.4166","82.9415"
"14.9600","3.7200","3.7200","2.4800","22.5693","83.5066"
"15.0400","3.7397","3.7397","2.4932","22.7276","84.0920"
"15.1200","3.7589","3.7589","2.5059","22.8765","84.6429"
"15.2000","3.7798","3.7798","2.5199","23.0435","85.2611"
"15.2800","3.7995","3.7995","2.5330","23.1999","85.8398"
"15.3600","3.8183","3.8183","2.5455","23.3457","86.3791"
"15.4400","3.8390","3.8390","2.5593","23.5122","86.9953"
"15.5200","3.8602","3.8602","2.5735","23.6831","87.6275"
"15.6000","3.8800","3.8800","2.5867","23.8399","88.2077"
"15.6800","3.9001","3.9001","2.6001","23.9983","88.7935"
"15.7600","3.9187","3.9187","2.6125","24.1403","89.3191"
"15.8400","3.9393","3.9393","2.6262","24.3064","89.9337"
"15.9200","3.9596","3.9596","2.6398","24.4689","90.5349"
"16.0000","3.9798","3.9798","2.6532","24.6314","91.1360"
"16.0800","4.0006","4.0006","2.6670","24.7953","91.7426"
"16.1600","4.0197","4.0197","2.6798","24.9446","92.2950"
"16.2400","4.0405","4.0405","2.6937","25.1094","92.9047"
"16.3200","4.0599","4.0599","2.7066","25.2609","93.4653"
"16.4000","4.0791","4.0791","2.7194","25.4101","94.0174"
"16.4800","4.0993","4.0993","2.7328","25.5708","94.6120"
"16.5600","4.1191","4.1191","2.7461","25.7255","95.1845"
"16.6400","4.1390","4.1390","2.7593","25.8837","95.7697"
"16.7200","4.1603","4.1603","2.7736","26.0547","96.4024"
"16.8000","4.1794","4.1794","2.7863","26.2006","96.9422"
"16.8800","4.2005","4.2005","2.8003","26.3679","97.5614"
"16.9600","4.2195","4.2195","2.8130","26.5144","98.1034"
"17.0400","4.2387","4.2387","2.8258","26.6607","98.6446"
"17.1200","4.2593","4.2593","2.8395","26.8240","99.2488"
"17.2000","4.2794","4.2794","2.8529","26.9804","99.8275"
"17.2800","4.3003","4.3003","2.8669","27.1517","100.4612"
"17.3600","4.3212","4.3212","2.8808","27.3162","101.0698"
"17.4400","4.3394","4.3394","2.8930","27.4522","101.5731"
"17.5200","4.3597","4.3597","2.9065","27.6126","102.1665"
"17.6000","4.3794","4.3794","2.9196","27.7626","102.7215"
"17.6800","4.3993","4.3993","2.9329","27.9185","103.2985"
"17.7600","4.4194","4.4194","2.9463","28.0743","103.8750"
"17.8400","4.4376","4.4376","2.9584","28.2105","104.3790"
"17.9200","4.4596","4.4596","2.9731","28.3836","105.0194"
"18.0000","4.4809","4.4809","2.9873","28.5522","105.6431"
"18.0800","4.5002","4.5002","3.0002","28.6965","106.1770"
"18.1600","4.5193","4.5193","3.0129","28.8430","106.7191"
"18.2400","4.5388","4.5388","3.0259","28.9931","107.2746"
"18.3200","4.5594","4.5594","3.0396","29.1543","107.8708"
"18.4000","4.5802","4.5802","3.0534","29.3128","108.4574"
"18.4800","4.5989","4.5989","3.0659","29.4562","108.9878"
"18.5600","4.6202","4.6202","3.0801","29.6212","109.5986"
"18.6400","4.6401","4.6401","3.0934","29.7732","110.1610"
"18.7200","4.6603","4.6603","3.1069","29.9259","110.7260"
"18.8000","4.6797","4.6797","3.1198","30.0741","111.2741"
"18.8800","4.6992","4.6992","3.1328","30.2248","111.8319"
"18.9600","4.7193","4.7193","3.1462","30.3739","112.3835"
"19.0400","4.7394","4.7394","3.1596","30.5321","112.9688"
"19.1200","4.7583","4.7583","3.1722","30.6716","113.4848"
"19.2000","4.7798","4.7798","3.1865","30.8411","114.1121"
"19.2800","4.8000","4.8000","3.2000","30.9904","114.6645"
"19.3600","4.8202","4.8202","3.2134","31.1430","115.2291"
"19.4400","4.8397","4.8397","3.2265","31.2894","115.7706"
"19.5200","4.8587","4.8587","3.2391","31.4317","116.2972"
"19.6000","4.8796","4.8796","3.2531","31.5895","116.8812"
"19.6800","4.8994","4.8994","3.2662","31.7384","117.4321"
"19.7600","4.9194","4.9194","3.2796","31.8892","117.9901"
"19.8400","4.9404","4.9404","3.2936","32.0524","118.5938"
"19.9200","4.9597","4.9597","3.3065","32.1905","119.1050"
"20.0000","4.9804","4.9804","3.3203","32.3463","119.6813"
"20.0800","5.0003","5.0003","3.3335","32.4955","120.2332"
"20.1600","5.0186","5.0186","3.3458","32.6303","120.7320"
"20.2400","5.0391","5.0391","3.3594","32.7850","121.3043"
"20.3200","5.0584","5.0584","3.3723","32.9275","121.8318"
"20.4000","5.0795","5.0795","3.3864","33.0904","122.4344"
"20.4800","5.1006","5.1006","3.4004","33.2499","123.0244"
"20.5600","5.1197","5.1197","3.4131","33.3879","123.5351"
"20.6400","5.1397","5.1397","3.4264","33.5367","124.0857"
"20.7200","5.1595","5.1595","3.4397","33.6816","124.6220"
"20.8000","5.1788","5.1788","3.4525","33.8244","125.1504"
"20.8800","5.2003","5.2003","3.4669","33.9852","125.7454"
"20.9600","5.2189","5.2189","3.4793","34.1184","126.2380"
"21.0400","5.2400","5.2400","3.4933","34.2767","126.8236"
"21.1200","5.2603","5.2603","3.5069","34.4297","127.3899"
"21.2000","5.2801","5.2801","3.5201","34.5770","127.9348"
"21.2800","5.2998","5.2998","3.5332","34.7204","128.4656"
"21.3600","5.3194","5.3194","3.5463","34.8613","128.9868"
"21.4400","5.3389","5.3389","3.5593","35.0040","129.5147"
"21.5200","5.3595","5.3595","3.5730","35.1544","130.0712"
"21.6000","5.3786","5.3786","3.5857","35.2962","130.5960"
"21.6800","5.3999","5.3999","3.5999","35.4536","131.1785"
"21.7600","5.4201","5.4201","3.6134","35.6017","131.7262"
"21.8400","5.4397","5.4397","3.6265","35.7447","132.2555"
"21.9200","5.4595","5.4595","3.6397","35.8899","132.7925"
"22.0000","5.4791","5.4791","3.6527","36.0323","133.3195"
"22.0800","5.5002","5.5002","3.6668","36.1921","133.9107"
"22.1600","5.5198","5.5198","3.6799","36.3284","134.4150"
"22.2400","5.5387","5.5387","3.6925","36.4651","134.9210"
"22.3200","5.5597","5.5597","3.7065","36.6220","135.5013"
"22.4000","5.5804","5.5804","3.7203","36.7701","136.0494"
"22.4800","5.6005","5.6005","3.7337","36.9175","136.5948"
"22.5600","5.6202","5.6202","3.7468","37.0599","137.1217"
"22.6400","5.6382","5.6382","3.7588","37.1838","137.5800"
"22.7200","5.6596","5.6596","3.7731","37.3417","138.1643"
"22.8000","5.6790","5.6790","3.7860","37.4797","138.6748"
"22.8800","5.6991","5.6991","3.7994","37.6273","139.2209"
"22.9600","5.7195","5.7195","3.8130","37.7717","139.7551"
"23.0400","5.7399","5.7399","3.8266","37.9180","140.2964"
"23.1200","5.7599","5.7599","3.8399","38.0626","140.8315"
"23.2000","5.7805","5.7805","3.8536","38.2103","141.3780"
"23.2800","5.7988","5.7988","3.8659","38.3398","141.8573"
"23.3600","5.8196","5.8196","3.8797","38.4927","142.4231"
"23.4400","5.8389","5.8389","3.8926","38.6249","142.9123"
"23.5200","5.8595","5.8595","3.9063","38.7735","143.4619"
"23.6000","5.8808","5.8808","3.9205","38.9296","144.0396"
"23.6800","5.9003","5.9003","3.9335","39.0642","144.5376"
"23.7600","5.9202","5.9202","3.9468","39.2043","145.0559"
"23.8400","5.9398","5.9398","3.9599","39.3421","145.5659"
"23.9200","5.9591","5.9591","3.9727","39.4798","146.0751"
"24.0000","5.9794","5.9794","3.9863","39.6226","146.6036"
"24.0800","5.9987","5.9987","3.9992","39.7554","147.0950"
"24.1600","6.0194","6.0194","4.0129","39.9044","147.6464"
"24.2400","6.0403","6.0403","4.0269","40.0507","148.1878"
"24.3200","6.0596","6.0596","4.0397","40.1885","148.6974"
"24.4000","6.0803","6.0803","4.0535","40.3318","149.2277"
"24.4800","6.0992","6.0992","4.0661","40.4588","149.6977"
"24.5600","6.1193","6.1193","4.0795","40.6001","150.2206"
"24.6400","6.1391","6.1391","4.0927","40.7403","150.7390"
"24.7200","6.1588","6.1588","4.1059","40.8760","151.2413"
"24.8000","6.1805","6.1805","4.1204","41.0354","151.8308"
"24.8800","6.2012","6.2012","4.1341","41.1810","152.3698"
"24.9600","6.2197","6.2197","4.1465","41.3050","152.8283"
"25.0400","6.2397","6.2397","4.1598","41.4426","153.3376"
"25.1200","6.2589","6.2589","4.1726","41.5695","153.8070"
"25.2000","6.2798","6.2798","4.1865","41.7142","154.3425"
"25.2800","6.2998","6.2998","4.1998","41.8507","154.8475"
"25.3600","6.3183","6.3183","4.2122","41.9773","155.3162"
"25.4400","6.3388","6.3388","4.2258","42.1179","155.8364"
"25.5200","6.3599","6.3599","4.2399","42.2666","156.3864"
"25.6000","6.3804","6.3804","4.2536","42.4091","156.9138"
"25.6800","6.4000","6.4000","4.2667","42.5399","157.3978"
"25.7600","6.4187","6.4187","4.2791","42.6638","157.8559"
"25.8400","6.4395","6.4395","4.2930","42.8080","158.3897"
"25.9200","6.4593","6.4593","4.3062","42.9392","158.8751"
"26.0000","6.4790","6.4790","4.3193","43.0749","159.3770"
"26.0800","6.5006","6.5006","4.3338","43.2266","159.9383"
"26.1600","6.5202","6.5202","4.3468","43.3565","160.4189"
"26.2400","6.5405","6.5405","4.3603","43.4927","160.9229"
"26.3200","6.5598","6.5598","4.3732","43.6213","161.3989"
"26.4000","6.5791","6.5791","4.3861","43.7527","161.8851"
"26.4800","6.5997","6.5997","4.3998","43.8956","162.4139"
"26.5600","6.6192","6.6192","4.4128","44.0245","162.8908"
"26.6400","6.6390","6.6390","4.4260","44.1574","163.3825"
"26.7200","6.6605","6.6605","4.4403","44.3084","163.9411"
"26.8000","6.6796","6.6796","4.4531","44.4323","164.3996"
"26.8800","6.6996","6.6996","4.4664","44.5637","164.8856"
"26.9600","6.7192","6.7192","4.4795","44.6948","165.3707"
"27.0400","6.7392","6.7392","4.4928","44.8292","165.8680"
"27.1200","6.7595","6.7595","4.5063","44.9674","166.3795"
"27.2000","6.7793","6.7793","4.5195","45.0969","166.8584"
"27.2800","6.8002","6.8002","4.5334","45.2372","167.3775"
"27.3600","6.8210","6.8210","4.5473","45.3745","167.8858"
"27.4400","6.8393","6.8393","4.5595","45.4907","168.3157"
"27.5200","6.8598","6.8598","4.5732","45.6278","168.8228"
"27.6000","6.8796","6.8796","4.5864","45.7581","169.3049"
"27.6800","6.8994","6.8994","4.5996","45.8881","169.7861"
"27.7600","6.9195","6.9195","4.6130","46.0185","170.2686"
"27.8400","6.9382","6.9382","4.6255","46.1395","170.7160"
"27.9200","6.9595","6.9595","4.6397","46.2792","171.2332"
"28.0000","6.9807","6.9807","4.6538","46.4227","171.7639"
"28.0800","7.0000","7.0000","4.6667","46.5462","172.2210"
"28.1600","7.0194","7.0194","4.6796","46.6705","172.6810"
"28.2400","7.0391","7.0391","4.6928","46.7964","173.1466"
"28.3200","7.0591","7.0591","4.7061","46.9250","173.6226"
"28.4000","7.0800","7.0800","4.7200","47.0600","174.1220"
"28.4800","7.0987","7.0987","4.7325","47.1782","174.5594"
"28.5600","7.1205","7.1205","4.7470","47.3228","175.0945"
"28.6400","7.1401","7.1401","4.7600","47.4457","175.5489"
"28.7200","7.1605","7.1605","4.7737","47.5749","176.0273"
"28.8000","7.1799","7.1799","4.7866","47.7003","176.4909"
"28.8800","7.1996","7.1996","4.7997","47.8240","176.9487"
"28.9600","7.2196","7.2196","4.8131","47.9504","177.4165"
"29.0400","7.2393","7.2393","4.8262","48.0698","177.8581"
"29.1200","7.2581","7.2581","4.8387","48.1904","178.3046"
"29.2000","7.2797","7.2797","4.8531","48.3323","178.8294"
"29.2800","7.2997","7.2997","4.8665","48.4559","179.2868"
"29.3600","7.3202","7.3202","4.8802","48.5837","179.7598"
"29.4400","7.3398","7.3398","4.8932","48.7018","180.1966"
"29.5200","7.3588","7.3588","4.9058","48.8212","180.6384"
"29.6000","7.3797","7.3797","4.9198","48.9524","181.1238"
"29.6800","7.3992","7.3992","4.9328","49.0703","181.5600"
"29.7600","7.4192","7.4192","4.9462","49.1953","182.0226"
"29.8400","7.4403","7.4403","4.9602","49.3328","182.5314"
"29.9200","7.4605","7.4605","4.9737","49.4557","182.9860"
"30.0000","7.4806","7.4806","4.9871","49.5759","183.4310"
"30.0800","7.5003","7.5003","5.0002","49.6959","183.8749"
"30.1600","7.5184","7.5184","5.0123","49.8030","184.2709"
"30.2400","7.5390","7.5390","5.0260","49.9309","184.7443"
"30.3200","7.5583","7.5583","5.0389","50.0456","185.1686"
"30.4000","7.5796","7.5796","5.0530","50.1777","185.6574"
"30.4800","7.6005","7.6005","5.0670","50.3076","186.1381"
"30.5600","7.6203","7.6203","5.0802","50.4271","186.5801"
"30.6400","7.6401","7.6401","5.0934","50.5457","187.0191"
"30.7200","7.6593","7.6593","5.1062","50.6593","187.4395"
"30.8000","7.6792","7.6792","5.1194","50.7779","187.8782"
"30.8800","7.6998","7.6998","5.1332","50.9034","188.3425"
"30.9600","7.7189","7.7189","5.1459","51.0114","188.7422"
"31.0400","7.7401","7.7401","5.1601","51.1425","189.2271"
"31.1200","7.7605","7.7605","5.1737","51.2630","189.6732"
"31.2000","7.7802","7.7802","5.1868","51.3784","190.0999"
"31.2800","7.7996","7.7996","5.1998","51.4920","190.5204"
"31.3600","7.8195","7.8195","5.2130","51.6054","190.9400"
"31.4400","7.8392","7.8392","5.2261","51.7223","191.3726"
"31.5200","7.8594","7.8594","5.2396","51.8404","191.8095"
"31.6000","7.8786","7.8786","5.2524","51.9526","192.2245"
"31.6800","7.8999","7.8999","5.2666","52.0810","192.6997"
"31.7600","7.9201","7.9201","5.2801","52.1976","193.1311"
"31.8400","7.9398","7.9398","5.2932","52.3070","193.5359"
"31.9200","7.9595","7.9595","5.3063","52.4186","193.9488"
"32.0000","7.9788","7.9788","5.3192","52.5264","194.3477"
"32.0800","7.9999","7.9999","5.3333","52.6516","194.8110"
"32.1600","8.0197","8.0197","5.3464","52.7611","195.2160"
"32.2400","8.0393","8.0393","5.3595","52.8721","195.6266"
"32.3200","8.0600","8.0600","5.3733","52.9941","196.0781"
"32.4000","8.0808","8.0808","5.3872","53.1091","196.5038"
"32.4800","8.1003","8.1003","5.4002","53.2128","196.8874"
"32.5600","8.1201","8.1201","5.4134","53.3243","197.3000"
"32.6400","8.1384","8.1384","5.4256","53.4212","197.6584"
"32.7200","8.1594","8.1594","5.4396","53.5415","198.1036"
"32.8000","8.1791","8.1791","5.4527","53.6487","198.5003"
"32.8800","8.1991","8.1991","5.4661","53.7597","198.9110"
"32.9600","8.2196","8.2196","5.4797","53.8765","199.3430"
"33.0400","8.2397","8.2397","5.4932","53.9839","199.7406"
"33.1200","8.2598","8.2598","5.5065","54.0892","200.1302"
"33.2000","8.2800","8.2800","5.5200","54.1966","200.5273"
"33.2800","8.2988","8.2988","5.5325","54.2920","200.8805"
"33.3600","8.3200","8.3200","5.5467","54.4119","201.3239"
"33.4400","8.3391","8.3391","5.5594","54.5052","201.6692"
"33.5200","8.3594","8.3594","5.5729","54.6159","202.0788"
"33.6000","8.3807","8.3807","5.5871","54.7312","202.5054"
"33.6800","8.4004","8.4004","5.6003","54.8348","202.8886"
"33.7600","8.4200","8.4200","5.6133","54.9321","203.2488"
"33.8400","8.4396","8.4396","5.6264","55.0314","203.6163"
"33.9200","8.4590","8.4590","5.6393","55.1311","203.9851"
"34.0000","8.4796","8.4796","5.6531","55.2375","204.3787"
"34.0800","8.4988","8.4988","5.6659","55.3315","204.7266"
"34.1600","8.5190","8.5190","5.6793","55.4347","205.1085"
"34.2400","8.5402","8.5402","5.6935","55.5460","205.5203"
"34.3200","8.5597","8.5597","5.7065","55.6448","205.8858"
"34.4000","8.5804","8.5804","5.7202","55.7510","206.2785"
"34.4800","8.5993","8.5993","5.7329","55.8396","206.6066"
"34.5600","8.6196","8.6196","5.7464","55.9421","206.9858"
"34.6400","8.6394","8.6394","5.7596","56.0372","207.3378"
"34.7200","8.6592","8.6592","5.7728","56.1353","207.7007"
"34.8000","8.6802","8.6802","5.7868","56.2398","208.0873"
"34.8800","8.7010","8.7010","5.8007","56.3430","208.4692"
"34.9600","8.7198","8.7198","5.8132","56.4326","208.8006"
"35.0400","8.7397","8.7397","5.8265","56.5263","209.1474"
"35.1200","8.7589","8.7589","5.8393","56.6130","209.4682"
"35.2000","8.7799","8.7799","5.8533","56.7182","209.8575"
"35.2800","8.7995","8.7995","5.8663","56.8041","210.1752"
"35.3600","8.8185","8.8185","5.8790","56.8913","210.4978"
"35.4400","8.8390","8.8390","5.8926","56.9904","210.8646"
"35.5200","8.8598","8.8598","5.9065","57.0898","211.2324"
"35.6000","8.8803","8.8803","5.9202","57.1820","211.5735"
"35.6800","8.9005","8.9005","5.9337","57.2755","211.9193"
"35.7600","8.9189","8.9189","5.9460","57.3495","212.1930"
"35.8400","8.9392","8.9392","5.9594","57.4428","212.5382"
"35.9200","8.9597","8.9597","5.9731","57.5350","212.8793"
"36.0000","8.9792","8.9792","5.9861","57.6214","213.1992"
"36.0800","9.0006","9.0006","6.0004","57.7203","213.5652"
"36.1600","9.0200","9.0200","6.0133","57.7976","213.8513"
"36.2400","9.0402","9.0402","6.0268","57.8843","214.1718"
"36.3200","9.0601","9.0601","6.0401","57.9690","214.4853"
"36.4000","9.0795","9.0795","6.0530","58.0540","214.7998"
"36.4800","9.0995","9.0995","6.0663","58.1382","215.1115"
"36.5600","9.1190","9.1190","6.0794","58.2151","215.3957"
"36.6400","9.1390","9.1390","6.0927","58.2998","215.7091"
"36.7200","9.1605","9.1605","6.1070","58.3950","216.0614"
"36.8000","9.1797","9.1797","6.1198","58.4669","216.3277"
"36.8800","9.2002","9.2002","6.1334","58.5498","216.6342"
"36.9600","9.2193","9.2193","6.1462","58.6227","216.9038"
"37.0400","9.2389","9.2389","6.1593","58.7011","217.1940"
"37.1200","9.2591","9.2591","6.1727","58.7841","217.5012"
"37.2000","9.2795","9.2795","6.1863","58.8677","217.8106"
"37.2800","9.3002","9.3002","6.2001","58.9512","218.1196"
"37.3600","9.3210","9.3210","6.2140","59.0330","218.4219"
"37.4400","9.3396","9.3396","6.2264","59.1010","218.6739"
"37.5200","9.3596","9.3596","6.2397","59.1740","218.9437"
"37.6000","9.3795","9.3795","6.2530","59.2475","219.2157"
"37.6800","9.3997","9.3997","6.2665","59.3250","219.5027"
"37.7600","9.4194","9.4194","6.2796","59.3981","219.7730"
"37.8400","9.4380","9.4380","6.2920","59.4470","219.9537"
"37.9200","9.4592","9.4592","6.3062","59.5274","220.2515"
"38.0000","9.4807","9.4807","6.3204","59.6118","220.5636"
"38.0800","9.5003","9.5003","6.3335","59.6801","220.8165"
"38.1600","9.5196","9.5196","6.3464","59.7434","221.0504"
"38.2400","9.5389","9.5389","6.3592","59.8052","221.2794"
"38.3200","9.5590","9.5590","6.3727","59.8781","221.5489"
"38.4000","9.5803","9.5803","6.3868","59.9530","221.8259"
"38.4800","9.5991","9.5991","6.3994","60.0125","222.0463"
"38.5600","9.6201","9.6201","6.4134","60.0885","222.3275"
"38.6400","9.6401","9.6401","6.4267","60.1542","222.5705"
"38.7200","9.6603","9.6603","6.4402","60.2225","222.8231"
"38.8000","9.6798","9.6798","6.4532","60.2855","223.0563"
"38.8800","9.6991","9.6991","6.4661","60.3437","223.2717"
"38.9600","9.7193","9.7193","6.4795","60.4086","223.5117"
"39.0400","9.7393","9.7393","6.4929","60.4700","223.7388"
"39.1200","9.7585","9.7585","6.5057","60.5314","223.9662"
"39.2000","9.7801","9.7801","6.5201","60.6070","224.2460"
"39.2800","9.7995","9.7995","6.5330","60.6597","224.4410"
"39.3600","9.8202","9.8202","6.5468","60.7283","224.6947"
"39.4400","9.8400","9.8400","6.5600","60.7841","224.9010"
"39.5200","9.8587","9.8587","6.5725","60.8385","225.1024"
"39.6000","9.8794","9.8794","6.5862","60.9026","225.3395"
"39.6800","9.8996","9.8996","6.5997","60.9622","225.5602"
"39.7600","9.9194","9.9194","6.6129","61.0182","225.7674"
"39.8400","9.9401","9.9401","6.6268","61.0861","226.0187"
"39.9200","9.9601","9.9601","6.6400","61.1387","226.2130"
"40.0000","9.9804","9.9804","6.6536","61.1951","226.4220"
"40.0800","10.0002","10.0002","6.6668","61.2493","226.6223"
"40.1600","10.0185","10.0185","6.6790","61.2943","226.7891"
"40.2400","10.0389","10.0389","6.6926","61.3500","226.9951"
"40.3200","10.0585","10.0585","6.7057","61.4039","227.1944"
"40.4000","10.0801","10.0801","6.7201","61.4664","227.4257"
"40.4800","10.1007","10.1007","6.7338","61.5207","227.6266"
"40.5600","10.1201","10.1201","6.7467","61.5674","227.7994"
"40.6400","10.1399","10.1399","6.7599","61.6158","227.9783"
"40.7200","10.1595","10.1595","6.7730","61.6612","228.1463"
"40.8000","10.1784","10.1784","6.7856","61.7044","228.3063"
"40.8800","10.1996","10.1996","6.7997","61.7636","228.5252"
"40.9600","10.2189","10.2189","6.8126","61.8074","228.6875"
"41.0400","10.2404","10.2404","6.8269","61.8672","228.9087"
"41.1200","10.2605","10.2605","6.8403","61.9154","229.0870"
"41.2000","10.2805","10.2805","6.8536","61.9640","229.2669"
"41.2800","10.2997","10.2997","6.8664","62.0018","229.4066"
"41.3600","10.3193","10.3193","6.8796","62.0465","229.5722"
"41.4400","10.3391","10.3391","6.8928","62.0930","229.7440"
"41.5200","10.3597","10.3597","6.9065","62.1432","229.9300"
"41.6000","10.3783","10.3783","6.9189","62.1809","230.0692"
"41.6800","10.3996","10.3996","6.9331","62.2368","230.2761"
"41.7600","10.4203","10.4203","6.9468","62.2836","230.4494"
"41.8400","10.4399","10.4399","6.9600","62.3215","230.5894"
"41.9200","10.4592","10.4592","6.9728","62.3577","230.7235"
"42.0000","10.4787","10.4787","6.9858","62.3949","230.8610"
"42.0800","10.4998","10.4998","6.9999","62.4442","231.0434"
"42.1600","10.5199","10.5199","7.0133","62.4857","231.1970"
"42.2400","10.5394","10.5394","7.0262","62.5219","231.3312"
"42.3200","10.5598","10.5598","7.0399","62.5670","231.4980"
"42.4000","10.5808","10.5808","7.0539","62.6120","231.6644"
"42.4800","10.6005","10.6005","7.0670","62.6467","231.7928"
"42.5600","10.6203","10.6203","7.0802","62.6831","231.9273"
"42.6400","10.6385","10.6385","7.0923","62.7072","232.0166"
"42.7200","10.6596","10.6595","7.1064","62.7531","232.1863"
"42.8000","10.6791","10.6791","7.1194","62.7863","232.3093"
"42.8800","10.6993","10.6993","7.1329","62.8262","232.4569"
"42.9600","10.7193","10.7193","7.1462","62.8632","232.5938"
"43.0400","10.7398","10.7398","7.1599","62.9005","232.7317"
"43.1200","10.7599","10.7599","7.1732","62.9353","232.8606"
"43.2000","10.7805","10.7805","7.1870","62.9736","233.0024"
"43.2800","10.7992","10.7992","7.1994","62.9999","233.0997"
"43.3600","10.8196","10.8196","7.2131","63.0376","233.2390"
"43.4400","10.8389","10.8389","7.2260","63.0656","233.3429"
"43.5200","10.8597","10.8597","7.2398","63.1026","233.4795"
"43.6000","10.8804","10.8804","7.2536","63.1411","233.6220"
"43.6800","10.9000","10.9000","7.2666","63.1691","233.7258"
"43.7600","10.9198","10.9198","7.2799","63.1960","233.8253"
"43.8400","10.9398","10.9398","7.2932","63.2274","233.9413"
"43.9200","10.9593","10.9593","7.3062","63.2552","234.0441"
"44.0000","10.9796","10.9796","7.3197","63.2901","234.1735"
"44.0800","10.9987","10.9987","7.3325","63.3116","234.2530"
"44.1600","11.0189","11.0189","7.3460","63.3430","234.3690"
"44.2400","11.0403","11.0403","7.3602","63.3800","234.5060"
"44.3200","11.0596","11.0596","7.3731","63.4080","234.6095"
"44.4000","11.0804","11.0804","7.3869","63.4418","234.7346"
"44.4800","11.0993","11.0993","7.3995","63.4608","234.8051"
"44.5600","11.1196","11.1196","7.4130","63.4925","234.9223"
"44.6400","11.1390","11.1390","7.4260","63.5183","235.0179"
"44.7200","11.1593","11.1593","7.4395","63.5497","235.1337"
"44.8000","11.1799","11.1799","7.4533","63.5779","235.2381"
"44.8800","11.2012","11.2012","7.4675","63.6116","235.3627"
"44.9600","11.2199","11.2199","7.4799","63.6316","235.4370"
"45.0400","11.2398","11.2398","7.4932","63.6521","235.5126"
"45.1200","11.2587","11.2587","7.5058","63.6734","235.5916"
"45.2000","11.2801","11.2801","7.5201","63.7070","235.7160"
"45.2800","11.2998","11.2998","7.5332","63.7261","235.7865"
"45.3600","11.3183","11.3183","7.5455","63.7446","235.8550"
"45.4400","11.3387","11.3387","7.5591","63.7736","235.9624"
"45.5200","11.3602","11.3602","7.5735","63.8055","236.0804"
"45.6000","11.3804","11.3804","7.5869","63.8274","236.1612"
"45.6800","11.4002","11.4002","7.6001","63.8480","236.2376"
"45.7600","11.4189","11.4189","7.6126","63.8606","236.2843"
"45.8400","11.4396","11.4396","7.6264","63.8883","236.3867"
"45.9200","11.4593","11.4593","7.6395","63.9072","236.4568"
"46.0000","11.4789","11.4789","7.6526","63.9323","236.5495"
"46.0800","11.5006","11.5006","7.6671","63.9636","236.6653"
"46.1600","11.5202","11.5202","7.6801","63.9797","236.7248"
"46.2400","11.5404","11.5404","7.6936","64.0012","236.8045"
"46.3200","11.5600","11.5600","7.7067","64.0235","236.8868"
"46.4000","11.5796","11.5796","7.7197","64.0439","236.9626"
"46.4800","11.5993","11.5993","7.7329","64.0603","237.0230"
"46.5600","11.6187","11.6187","7.7458","64.0746","237.0759"
"46.6400","11.6387","11.6387","7.7592","64.0986","237.1647"
"46.7200","11.6604","11.6604","7.7736","64.1292","237.2779"
"46.8000","11.6802","11.6802","7.7868","64.1465","237.3421"
"46.8800","11.6998","11.6998","7.7999","64.1614","237.3974"
"46.9600","11.7192","11.7192","7.8128","64.1774","237.4565"
"47.0400","11.7391","11.7391","7.8261","64.1976","237.5311"
"47.1200","11.7590","11.7590","7.8393","64.2157","237.5982"
"47.2000","11.7794","11.7794","7.8530","64.2356","237.6716"
"47.2800","11.8002","11.8002","7.8668","64.2598","237.7614"
"47.3600","11.8211","11.8211","7.8807","64.2804","237.8376"
"47.4400","11.8391","11.8391","7.8927","64.2867","237.8608"
"47.5200","11.8599","11.8599","7.9066","64.3135","237.9599"
"47.6000","11.8799","11.8799","7.9199","64.3286","238.0159"
"47.6800","11.8997","11.8997","7.9332","64.3480","238.0875"
"47.7600","11.9192","11.9192","7.9461","64.3592","238.1290"
"47.8400","11.9381","11.9381","7.9587","64.3699","238.1688"
"47.9200","11.9596","11.9596","7.9731","64.3944","238.2594"
"48.0000","11.9804","11.9804","7.9870","64.4191","238.3506"
"48.0800","12.0003","12.0003","8.0002","64.4321","238.3989"
"48.1600","12.0197","12.0197","8.0131","64.4448","238.4456"
"48.2400","12.0390","12.0390","8.0260","64.4569","238.4906"
"48.3200","12.0592","12.0592","8.0394","64.4752","238.5583"
"48.4000","12.0803","12.0803","8.0535","64.4961","238.6354"
"48.4800","12.0992","12.0992","8.0662","64.5062","238.6730"
"48.5600","12.1202","12.1202","8.0801","64.5280","238.7534"
"48.6400","12.1400","12.1400","8.0933","64.5372","238.7876"
"48.7200","12.1598","12.1598","8.1065","64.5486","238.8299"
"48.8000","12.1790","12.1790","8.1193","64.5639","238.8864"
"48.8800","12.1999","12.1999","8.1332","64.5798","238.9452"
"48.9600","12.2194","12.2194","8.1463","64.5925","238.9921"
"49.0400","12.2396","12.2396","8.1597","64.6056","239.0408"
"49.1200","12.2585","12.2585","8.1724","64.6181","239.0869"
"49.2000","12.2805","12.2805","8.1870","64.6436","239.1813"
"49.2800","12.3000","12.3000","8.2000","64.6495","239.2032"
"49.3600","12.3202","12.3202","8.2135","64.6623","239.2504"
"49.4400","12.3394","12.3394","8.2263","64.6681","239.2720"
"49.5200","12.3589","12.3589","8.2392","64.6782","239.3094"
"49.6000","12.3797","12.3797","8.2531","64.6968","239.3780"
"49.6800","12.3993","12.3993","8.2662","64.7058","239.4115"
"49.7600","12.4192","12.4192","8.2794","64.7174","239.4543"
"49.8400","12.4403","12.4403","8.2935","64.7373","239.5280"
"49.9200","12.4603","12.4603","8.3069","64.7451","239.5568"
"50.0000","12.4806","12.4806","8.3204","64.7588","239.6076"
"50.0800","12.5002","12.5002","8.3335","64.7674","239.6394"
"50.1600","12.5190","12.5190","8.3460","64.7756","239.6697"
"50.2400","12.5390","12.5390","8.3593","64.7855","239.7063"
"50.3200","12.5580","12.5580","8.3720","64.7919","239.7302"
"50.4000","12.5797","12.5797","8.3865","64.8173","239.8241"
"50.4800","12.6005","12.6005","8.4003","64.8296","239.8696"
"50.5600","12.6199","12.6199","8.4133","64.8375","239.8987"
"50.6400","12.6395","12.6395","8.4264","64.8463","239.9312"
"50.7200","12.6599","12.6599","8.4399","64.8569","239.9706"
"50.8000","12.6789","12.6789","8.4526","64.8628","239.9924"
"50.8800","12.6997","12.6997","8.4665","64.8791","240.0525"
"50.9600","12.7188","12.7188","8.4792","64.8805","240.0578"
"51.0400","12.7403","12.7403","8.4935","64.8985","240.1243"
"51.1200","12.7604","12.7604","8.5069","64.9068","240.1550"
"51.2000","12.7799","12.7799","8.5199","64.9143","240.1828"
"51.2800","12.7996","12.7996","8.5330","64.9193","240.2014"
"51.3600","12.8193","12.8193","8.5462","64.9246","240.2209"
"51.4400","12.8395","12.8395","8.5597","64.9336","240.2544"
"51.5200","12.8595","12.8595","8.5730","64.9401","240.2785"
"51.6000","12.8784","12.8784","8.5856","64.9434","240.2906"
"51.6800","12.8998","12.8998","8.5998","64.9590","240.3481"
"51.7600","12.9199","12.9199","8.6132","64.9650","240.3705"
"51.8400","12.9396","12.9396","8.6264","64.9732","240.4007"
"51.9200","12.9601","12.9601","8.6401","64.9828","240.4365"
"52.0000","12.9791","12.9791","8.6527","64.9816","240.4318"
"52.0800","12.9997","12.9997","8.6665","64.9897","240.4618"
"52.1600","13.0197","13.0197","8.6798","64.9933","240.4753"
"52.2400","13.0393","13.0393","8.6929","64.9956","240.4838"
"52.3200","13.0598","13.0598","8.7066","65.0068","240.5251"
"52.4000","13.0806","13.0806","8.7204","65.0119","240.5439"
"52.4800","13.1005","13.1005","8.7337","65.0130","240.5482"
"52.5600","13.1202","13.1202","8.7468","65.0128","240.5474"
"52.6400","13.1387","13.1387","8.7591","65.0081","240.5300"
"52.7200","13.1596","13.1596","8.7730","65.0187","240.5692"
"52.8000","13.1791","13.1791","8.7861","65.0195","240.5722"
"52.8800","13.1997","13.1997","8.7998","65.0252","240.5933"
"52.9600","13.2196","13.2196","8.8131","65.0277","240.6025"
"53.0400","13.2403","13.2403","8.8268","65.0274","240.6015"
"53.1200","13.2597","13.2597","8.8398","65.0242","240.5896"
"53.2000","13.2801","13.2801","8.8534","65.0286","240.6058"
"53.2800","13.2990","13.2990","8.8660","65.0249","240.5920"
"53.3600","13.3197","13.3197","8.8798","65.0286","240.6057"
"53.4400","13.3390","13.3390","8.8927","65.0241","240.5892"
"53.5200","13.3599","13.3599","8.9066","65.0282","240.6042"
"53.6000","13.3805","13.3805","8.9204","65.0260","240.5961"
"53.6800","13.3999","13.3999","8.9333","65.0220","240.5813"
"53.7600","13.4201","13.4201","8.9468","65.0185","240.5685"
"53.8400","13.4396","13.4396","8.9597","65.0109","240.5403"
"53.9200","13.4586","13.4586","8.9724","65.0042","240.5156"
"54.0000","13.4796","13.4796","8.9864","65.0090","240.5333"
"54.0800","13.4988","13.4988","8.9992","64.9930","240.4741"
"54.1600","13.5192","13.5192","9.0128","64.9930","240.4743"
"54.2400","13.5405","13.5405","9.0270","64.9917","240.4692"
"54.3200","13.5597","13.5597","9.0398","64.9810","240.4297"
"54.4000","13.5801","13.5801","9.0534","64.9756","240.4097"
"54.4800","13.5991","13.5991","9.0661","64.9602","240.3528"
"54.5600","13.6198","13.6198","9.0798","64.9565","240.3389"
"54.6400","13.6393","13.6393","9.0928","64.9476","240.3063"
"54.7200","13.6591","13.6591","9.1061","64.9408","240.2811"
"54.8000","13.6801","13.6801","9.1201","64.9407","240.2807"
"54.8800","13.7008","13.7008","9.1339","64.9350","240.2596"
"54.9600","13.7199","13.7199","9.1466","64.9205","240.2057"
"55.0400","13.7400","13.7400","9.1600","64.9144","240.1831"
"55.1200","13.7586","13.7586","9.1724","64.8988","240.1255"
"55.2000","13.7798","13.7798","9.1865","64.8920","240.1004"
"55.2800","13.7997","13.7997","9.1998","64.8798","240.0551"
"55.3600","13.8187","13.8187","9.2125","64.8656","240.0027"
"55.4400","13.8390","13.8390","9.2260","64.8551","239.9640"
"55.5200","13.8599","13.8599","9.2400","64.8485","239.9395"
"55.6000","13.8804","13.8804","9.2536","64.8339","239.8856"
"55.6800","13.9002","13.9002","9.2668","64.8232","239.8457"
"55.7600","13.9188","13.9188","9.2792","64.8038","239.7739"
"55.8400","13.9394","13.9394","9.2930","64.7912","239.7276"
"55.9200","13.9596","13.9596","9.3064","64.7769","239.6745"
"56.0000","13.9796","13.9796","9.3197","64.7725","239.6581"
"56.0800","14.0004","14.0004","9.3336","64.7638","239.6262"
"56.1600","14.0202","14.0202","9.3468","64.7463","239.5613"
"56.2400","14.0402","14.0402","9.3601","64.7331","239.5123"
"56.3200","14.0600","14.0600","9.3733","64.7233","239.4761"
"56.4000","14.0791","14.0791","9.3861","64.7124","239.4358"
"56.4800","14.0996","14.0996","9.3997","64.7029","239.4009"
"56.5600","14.1192","14.1192","9.4128","64.6885","239.3474"
"56.6400","14.1388","14.1388","9.4259","64.6761","239.3015"
"56.7200","14.1605","14.1605","9.4404","64.6700","239.2791"
"56.8000","14.1797","14.1797","9.4531","64.6492","239.2019"
"56.8800","14.2003","14.2003","9.4669","64.6375","239.1587"
"56.9600","14.2193","14.2193","9.4795","64.6137","239.0707"
"57.0400","14.2386","14.2386","9.4924","64.5994","239.0177"
"57.1200","14.2590","14.2590","9.5060","64.5884","238.9772"
"57.2000","14.2795","14.2795","9.5197","64.5704","238.9105"
"57.2800","14.3002","14.3002","9.5334","64.5546","238.8519"
"57.3600","14.3210","14.3210","9.5473","64.5413","238.8029"
"57.4400","14.3397","14.3397","9.5598","64.5197","238.7228"
"57.5200","14.3598","14.3598","9.5732","64.5009","238.6533"
"57.6000","14.3797","14.3797","9.5865","64.4870","238.6017"
"57.6800","14.3997","14.3997","9.5998","64.4706","238.5413"
"57.7600","14.4198","14.4198","9.6132","64.4501","238.4655"
"57.8400","14.4379","14.4379","9.6253","64.4257","238.3751"
"57.9200","14.4593","14.4593","9.6395","64.4152","238.3362"
"58.0000","14.4804","14.4804","9.6536","64.4011","238.2842"
"58.0800","14.5000","14.5000","9.6667","64.3814","238.2113"
"58.1600","14.5196","14.5196","9.6797","64.3605","238.1338"
"58.2400","14.5389","14.5389","9.6926","64.3332","238.0327"
"58.3200","14.5592","14.5592","9.7062","64.3167","237.9718"
"58.4000","14.5803","14.5803","9.7202","64.3009","237.9133"
"58.4800","14.5993","14.5993","9.7329","64.2745","237.8156"
"58.5600","14.6203","14.6203","9.7469","64.2562","237.7479"
"58.6400","14.6400","14.6400","9.7600","64.2314","237.6562"
"58.7200","14.6602","14.6602","9.7735","64.2087","237.5723"
"58.8000","14.6798","14.6798","9.7865","64.1833","237.4783"
"58.8800","14.6997","14.6997","9.7998","64.1565","237.3792"
"58.9600","14.7192","14.7192","9.8128","64.1307","237.2836"
"59.0400","14.7390","14.7390","9.8260","64.1014","237.1753"
"59.1200","14.7587","14.7587","9.8391","64.0812","237.1004"
"59.2000","14.7801","14.7801","9.8534","64.0670","237.0480"
"59.2800","14.7998","14.7998","9.8665","64.0403","236.9492"
"59.3600","14.8201","14.8201","9.8801","64.0158","236.8586"
"59.4400","14.8397","14.8397","9.8932","63.9930","236.7741"
"59.5200","14.8592","14.8592","9.9061","63.9684","236.6833"
"59.6000","14.8798","14.8798","9.9199","63.9436","236.5914"
"59.6800","14.8997","14.8997","9.9331","63.9189","236.5000"
"59.7600","14.9195","14.9195","9.9463","63.8890","236.3892"
"59.8400","14.9402","14.9402","9.9601","63.8685","236.3134"
"59.9200","14.9602","14.9602","9.9734","63.8396","236.2067"
"60.0000","14.9804","14.9804","9.9870","63.8101","236.0974"
"60.0790","15.0002","15.0002","10.0002","63.7794","235.9838"