File: data/instron_tests/539_BULK_m2.is_comp_Exports/539_BULK_m2_4_1.csv
Sample text inputs : Sample No.,Sample choice input : Leading Direction,Sample choice input : Mode,Specimen choice input : Direction,Specimen properties : Height,Specimen properties : Thickness,Specimen properties : Width,Test : Rate 1
,,,,(mm),(mm),(mm),(mm/min)
"509","Bulk","Bimode","1","150.00","25.00","150.00","15.00"

Time,Displacement,Compressive displacement,Compressive strain (Displacement),Compressive stress,Force
(s),(mm),(mm),(%),(kPa),(N)
"0.0000","0.0000","0.0000","0.0000","-0.7959","-2.9450"
"0.0800","0.0014","0.0014","0.0009","-0.7921","-2.9309"
"0.1600","0.0107","0.0107","0.0071","-0.7716","-2.8548"
"0.2400","0.0312","0.0312","0.0208","-0.7318","-2.7077"
"0.3200","0.0513","0.0513","0.0342","-0.6930","-2.5641"
"0.4000","0.0693","0.0693","0.0462","-0.6585","-2.4363"
"0.4800","0.0893","0.0893","0.0595","-0.6233","-2.3062"
"0.5600","0.1109","0.1109","0.0739","-0.5786","-2.1407"
"0.6400","0.1308","0.1308","0.0872","-0.5469","-2.0235"
"0.7200","0.1503","0.1503","0.1002","-0.5116","-1.8929"
"0.8000","0.1695","0.1695","0.1130","-0.4755","-1.7592"
"0.8800","0.1906","0.1906","0.1271","-0.4374","-1.6183"
"0.9600","0.2108","0.2108","0.1405","-0.4048","-1.4978"
"1.0400","0.2296","0.2296","0.1531","-0.3697","-1.3680"
"1.1200","0.2504","0.2504","0.1670","-0.3353","-1.2406"
"1.2000","0.2709","0.2709","0.1806","-0.3018","-1.1165"
"1.2800","0.2910","0.2910","0.1940","-0.2693","-0.9963"
"1.3600","0.3111","0.3111","0.2074","-0.2362","-0.8739"
"1.4400","0.3298","0.3298","0.2199","-0.2062","-0.7631"
"1.5200","0.3506","0.3506","0.2337","-0.1722","-0.6373"
"1.6000","0.3704","0.3704","0.2469","-0.1369","-0.5064"
"1.6800","0.3899","0.3899","0.2599","-0.1048","-0.3877"
"1.7600","0.4112","0.4112","0.2741","-0.0726","-0.2684"
"1.8400","0.4313","0.4313","0.2875","-0.0439","-0.1624"
"1.9200","0.4516","0.4516","0.3010","-0.0128","-0.0472"
"2.0000","0.4709","0.4709","0.3139","0.0188","0.0695"
"2.0800","0.4897","0.4897","0.3264","0.0511","0.1891"
"2.1600","0.5104","0.5104","0.3403","0.0885","0.3273"
"2.2400","0.5301","0.5301","0.3534","0.1208","0.4470"
"2.3200","0.5499","0.5499","0.3666","0.1542","0.5706"
"2.4000","0.5707","0.5707","0.3805","0.1901","0.7033"
"2.4800","0.5901","0.5901","0.3934","0.2226","0.8235"
"2.5600","0.6109","0.6109","0.4073","0.2581","0.9548"
"2.6400","0.6310","0.6310","0.4207","0.2932","1.0849"
"2.7200","0.6502","0.6502","0.4335","0.3262","1.2070"
"2.8000","0.6701","0.6701","0.4467","0.3621","1.3398"
"2.8800","0.6900","0.6900","0.4600","0.3957","1.4641"
"2.9600","0.7110","0.7110","0.4740","0.4326","1.6005"
"3.0400","0.7324","0.7324","0.4883","0.4666","1.7265"
"3.1200","0.7506","0.7506","0.5004","0.4988","1.8454"
"3.2000","0.7707","0.7707","0.5138","0.5358","1.9825"
"3.2800","0.7903","0.7903","0.5268","0.5692","2.1059"
"3.3600","0.8105","0.8105","0.5403","0.6021","2.2278"
"3.4400","0.8310","0.8310","0.5540","0.6391","2.3647"
"3.5200","0.8494","0.8494","0.5663","0.6708","2.4821"
"3.6000","0.8699","0.8699","0.5799","0.7066","2.6143"
"3.6800","0.8911","0.8911","0.5941","0.7413","2.7427"
"3.7600","0.9111","0.9111","0.6074","0.7747","2.8664"
"3.8400","0.9310","0.9310","0.6207","0.8131","3.0086"
"3.9200","0.9502","0.9502","0.6335","0.8446","3.1252"
"4.0000","0.9703","0.9703","0.6469","0.8779","3.2483"
"4.0800","0.9907","0.9907","0.6605","0.9158","3.3883"
"4.1600","1.0100","1.0100","0.6733","0.9503","3.5161"
"4.2400","1.0312","1.0312","0.6875","0.9872","3.6527"
"4.3200","1.0512","1.0512","0.7008","1.0222","3.7821"
"4.4000","1.0712","1.0712","0.7142","1.0499","3.8848"
"4.4800","1.0907","1.0907","0.7271","1.0878","4.0249"
"4.5600","1.1102","1.1102","0.7401","1.1248","4.1618"
"4.6400","1.1306","1.1306","0.7537","1.1595","4.2900"
"4.7200","1.1506","1.1506","0.7670","1.1960","4.4252"
"4.8000","1.1691","1.1691","0.7794","1.2302","4.5516"
"4.8800","1.1904","1.1904","0.7936","1.2704","4.7005"
"4.9600","1.2110","1.2110","0.8073","1.3050","4.8285"
"5.0400","1.2319","1.2319","0.8213","1.3346","4.9379"
"5.1200","1.2502","1.2502","0.8335","1.3673","5.0588"
"5.2000","1.2689","1.2689","0.8460","1.4029","5.1906"
"5.2800","1.2903","1.2903","0.8602","1.4424","5.3370"
"5.3600","1.3108","1.3108","0.8739","1.4793","5.4734"
"5.4400","1.3309","1.3309","0.8873","1.5143","5.6030"
"5.5200","1.3521","1.3521","0.9014","1.5519","5.7422"
"5.6000","1.3708","1.3708","0.9139","1.5789","5.8421"
"5.6800","1.3911","1.3911","0.9274","1.6182","5.9873"
"5.7600","1.4108","1.4108","0.9405","1.6511","6.1092"
"5.8400","1.4301","1.4301","0.9534","1.6835","6.2288"
"5.9200","1.4504","1.4504","0.9669","1.7219","6.3710"
"6.0000","1.4691","1.4691","0.9794","1.7526","6.4846"
"6.0800","1.4904","1.4904","0.9936","1.7961","6.6457"
"6.1600","1.5116","1.5116","1.0077","1.8323","6.7794"
"6.2400","1.5308","1.5308","1.0205","1.8687","6.9143"
"6.3200","1.5501","1.5501","1.0334","1.9049","7.0479"
"6.4000","1.5702","1.5702","1.0468","1.9394","7.1756"
"6.4800","1.5898","1.5898","1.0599","1.9769","7.3146"
"6.5600","1.6109","1.6109","1.0739","2.0084","7.4309"
"6.6400","1.6300","1.6300","1.0867","2.0455","7.5684"
"6.7200","1.6516","1.6516","1.1011","2.0821","7.7038"
"6.8000","1.6715","1.6715","1.1143","2.1195","7.8420"
"6.8800","1.6911","1.6911","1.1274","2.1567","7.9799"
"6.9600","1.7108","1.7108","1.1405","2.1936","8.1164"
"7.0400","1.7304","1.7304","1.1536","2.2230","8.2251"
"7.1200","1.7506","1.7506","1.1670","2.2593","8.3594"
"7.2000","1.7705","1.7705","1.1803","2.2946","8.4900"
"7.2800","1.7891","1.7891","1.1927","2.3259","8.6057"
"7.3600","1.8107","1.8107","1.2071","2.3643","8.7478"
"7.4400","1.8316","1.8316","1.2211","2.4061","8.9024"
"7.5200","1.8507","1.8507","1.2338","2.4409","9.0312"
"7.6000","1.8704","1.8704","1.2469","2.4762","9.1618"
"7.6800","1.8894","1.8894","1.2596","2.5108","9.2899"
"7.7600","1.9111","1.9111","1.2741","2.5494","9.4327"
"7.8400","1.9312","1.9312","1.2874","2.5868","9.5713"
"7.9200","1.9503","1.9503","1.3002","2.6233","9.7060"
"8.0000","1.9709","1.9709","1.3139","2.6550","9.8234"
"8.0800","1.9911","1.9911","1.3274","2.6897","9.9518"
"8.1600","2.0112","2.0112","1.3408","2.7282","10.0942"
"8.2400","2.0315","2.0315","1.3543","2.7657","10.2332"
"8.3200","2.0495","2.0495","1.3663","2.8004","10.3615"
"8.4000","2.0708","2.0708","1.3805","2.8411","10.5121"
"8.4800","2.0899","2.0899","1.3933","2.8740","10.6337"
"8.5600","2.1098","2.1098","1.4065","2.9055","10.7505"
"8.6400","2.1307","2.1307","1.4205","2.9485","10.9095"
"8.7200","2.1511","2.1511","1.4341","2.9836","11.0394"
"8.8000","2.1708","2.1708","1.4472","3.0163","11.1603"
"8.8800","2.1908","2.1908","1.4605","3.0498","11.2843"
"8.9600","2.2097","2.2097","1.4731","3.0850","11.4146"
"9.0400","2.2307","2.2307","1.4872","3.1245","11.5607"
"9.1200","2.2498","2.2498","1.4999","3.1610","11.6957"
"9.2000","2.2705","2.2705","1.5137","3.1994","11.8379"
"9.2800","2.2917","2.2917","1.5278","3.2390","11.9843"
"9.3600","2.3111","2.3111","1.5408","3.2755","12.1193"
"9.4400","2.3311","2.3311","1.5541","3.3111","12.2511"
"9.5200","2.3508","2.3508","1.5672","3.3459","12.3799"
"9.6000","2.3698","2.3698","1.5799","3.3864","12.5297"
"9.6800","2.3904","2.3904","1.5936","3.4221","12.6620"
"9.7600","2.4099","2.4099","1.6066","3.4541","12.7802"
"9.8400","2.4303","2.4303","1.6202","3.4926","12.9225"
"9.9200","2.4514","2.4514","1.6343","3.5313","13.0659"
"10.0000","2.4702","2.4702","1.6468","3.5691","13.2057"
"10.0800","2.4908","2.4908","1.6605","3.6065","13.3442"
"10.1600","2.5098","2.5098","1.6732","3.6397","13.4670"
"10.2400","2.5309","2.5309","1.6873","3.6795","13.6141"
"10.3200","2.5505","2.5505","1.7003","3.7191","13.7606"
"10.4000","2.5703","2.5703","1.7136","3.7555","13.8952"
"10.4800","2.5907","2.5907","1.7272","3.7936","14.0364"
"10.5600","2.6119","2.6119","1.7413","3.8326","14.1807"
"10.6400","2.6310","2.6310","1.7540","3.8643","14.2978"
"10.7200","2.6510","2.6510","1.7673","3.9024","14.4389"
"10.8000","2.6698","2.6698","1.7798","3.9361","14.5636"
"10.8800","2.6905","2.6905","1.7937","3.9745","14.7057"
"10.9600","2.7106","2.7106","1.8071","4.0117","14.8434"
"11.0400","2.7299","2.7299","1.8199","4.0494","14.9828"
"11.1200","2.7507","2.7507","1.8338","4.0899","15.1328"
"11.2000","2.7709","2.7709","1.8473","4.1266","15.2683"
"11.2800","2.7908","2.7908","1.8605","4.1636","15.4052"
"11.3600","2.8114","2.8114","1.8743","4.2040","15.5548"
"11.4400","2.8299","2.8299","1.8866","4.2374","15.6783"
"11.5200","2.8506","2.8506","1.9004","4.2705","15.8010"
"11.6000","2.8705","2.8705","1.9137","4.3070","15.9358"
"11.6800","2.8902","2.8902","1.9268","4.3433","16.0702"
"11.7600","2.9117","2.9117","1.9411","4.3850","16.2244"
"11.8400","2.9313","2.9313","1.9542","4.4179","16.3462"
"11.9200","2.9513","2.9513","1.9675","4.4568","16.4903"
"12.0000","2.9709","2.9709","1.9806","4.4939","16.6274"
"12.0800","2.9896","2.9896","1.9931","4.5306","16.7632"
"12.1600","3.0105","3.0105","2.0070","4.5696","16.9074"
"12.2400","3.0300","3.0300","2.0200","4.6087","17.0520"
"12.3200","3.0498","3.0498","2.0332","4.6426","17.1778"
"12.4000","3.0709","3.0709","2.0472","4.6773","17.3060"
"12.4800","3.0906","3.0906","2.0604","4.7155","17.4475"
"12.5600","3.1113","3.1113","2.0742","4.7542","17.5906"
"12.6400","3.1307","3.1307","2.0872","4.7922","17.7313"
"12.7200","3.1500","3.1500","2.1000","4.8275","17.8619"
"12.8000","3.1700","3.1700","2.1134","4.8659","18.0037"
"12.8800","3.1896","3.1896","2.1264","4.9042","18.1456"
"12.9600","3.2106","3.2106","2.1404","4.9420","18.2855"
"13.0400","3.2322","3.2322","2.1548","4.9829","18.4368"
"13.1200","3.2508","3.2508","2.1672","5.0177","18.5654"
"13.2000","3.2706","3.2706","2.1804","5.0544","18.7012"
"13.2800","3.2899","3.2899","2.1933","5.0906","18.8351"
"13.3600","3.3104","3.3104","2.2069","5.1278","18.9728"
"13.4400","3.3308","3.3308","2.2205","5.1637","19.1057"
"13.5200","3.3497","3.3497","2.2331","5.2007","19.2426"
"13.6000","3.3702","3.3702","2.2468","5.2348","19.3687"
"13.6800","3.3908","3.3908","2.2605","5.2746","19.5159"
"13.7600","3.4109","3.4109","2.2740","5.3148","19.6649"
"13.8400","3.4311","3.4311","2.2874","5.3519","19.8019"
"13.9200","3.4501","3.4501","2.3001","5.3868","19.9313"
"14.0000","3.4703","3.4703","2.3135","5.4225","20.0634"
"14.0800","3.4909","3.4909","2.3272","5.4605","20.2037"
"14.1600","3.5100","3.5100","2.3400","5.4985","20.3443"
"14.2400","3.5315","3.5315","2.3544","5.5387","20.4933"
"14.3200","3.5512","3.5512","2.3675","5.5743","20.6248"
"14.4000","3.5712","3.5712","2.3808","5.6089","20.7531"
"14.4800","3.5908","3.5908","2.3939","5.6464","20.8918"
"14.5600","3.6101","3.6101","2.4067","5.6814","21.0212"
"14.6400","3.6306","3.6306","2.4204","5.7188","21.1595"
"14.7200","3.6504","3.6504","2.4336","5.7513","21.2796"
"14.8000","3.6690","3.6690","2.4460","5.7861","21.4084"
"14.8800","3.6908","3.6908","2.4605","5.8283","21.5647"
"14.9600","3.7110","3.7110","2.4740","5.8666","21.7063"
"15.0400","3.7314","3.7314","2.4876","5.9025","21.8393"
"15.1200","3.7507","3.7507","2.5005","5.9389","21.9739"
"15.2000","3.7693","3.7693","2.5129","5.9751","22.1079"
"15.2800","3.7899","3.7899","2.5266","6.0148","22.2547"
"15.3600","3.8106","3.8106","2.5404","6.0513","22.3898"
"15.4400","3.8306","3.8306","2.5537","6.0894","22.5309"
"15.5200","3.8522","3.8522","2.5682","6.1286","22.6759"
"15.6000","3.8709","3.8709","2.5806","6.1650","22.8106"
"15.6800","3.8907","3.8907","2.5938","6.1994","22.9376"
"15.7600","3.9107","3.9107","2.6071","6.2359","23.0730"
"15.8400","3.9299","3.9299","2.6199","6.2748","23.2168"
"15.9200","3.9504","3.9504","2.6336","6.3160","23.3690"
"16.0000","3.9692","3.9692","2.6461","6.3476","23.4863"
"16.0800","3.9903","3.9903","2.6602","6.3850","23.6245"
"16.1600","4.0114","4.0114","2.6743","6.4276","23.7820"
"16.2400","4.0309","4.0309","2.6873","6.4655","23.9223"
"16.3200","4.0507","4.0507","2.7004","6.5009","24.0535"
"16.4000","4.0702","4.0702","2.7134","6.5380","24.1906"
"16.4800","4.0897","4.0897","2.7264","6.5700","24.3091"
"16.5600","4.1107","4.1107","2.7405","6.6110","24.4606"
"16.6400","4.1299","4.1299","2.7532","6.6470","24.5940"
"16.7200","4.1512","4.1512","2.7675","6.6858","24.7373"
"16.8000","4.1715","4.1715","2.7810","6.7236","24.8774"
"16.8800","4.1909","4.1909","2.7939","6.7619","25.0190"
"16.9600","4.2106","4.2106","2.8071","6.7983","25.1538"
"17.0400","4.2302","4.2302","2.8202","6.8331","25.2823"
"17.1200","4.2504","4.2504","2.8336","6.8729","25.4297"
"17.2000","4.2705","4.2705","2.8470","6.9084","25.5612"
"17.2800","4.2892","4.2892","2.8595","6.9466","25.7025"
"17.3600","4.3105","4.3105","2.8737","6.9851","25.8449"
"17.4400","4.3314","4.3314","2.8876","7.0262","25.9970"
"17.5200","4.3508","4.3508","2.9005","7.0584","26.1159"
"17.6000","4.3705","4.3705","2.9137","7.0932","26.2449"
"17.6800","4.3897","4.3897","2.9265","7.1307","26.3836"
"17.7600","4.4110","4.4110","2.9407","7.1703","26.5299"
"17.8400","4.4309","4.4309","2.9539","7.2049","26.6580"
"17.9200","4.4500","4.4500","2.9667","7.2432","26.7997"
"18.0000","4.4706","4.4706","2.9804","7.2838","26.9501"
"18.0800","4.4913","4.4913","2.9942","7.3199","27.0835"
"18.1600","4.5113","4.5113","3.0075","7.3570","27.2209"
"18.2400","4.5313","4.5313","3.0209","7.3924","27.3518"
"18.3200","4.5499","4.5499","3.0333","7.4284","27.4851"
"18.4000","4.5702","4.5702","3.0468","7.4643","27.6180"
"18.4800","4.5896","4.5896","3.0598","7.5004","27.7513"
"18.5600","4.6101","4.6101","3.0734","7.5402","27.8986"
"18.6400","4.6310","4.6310","3.0873","7.5802","28.0466"
"18.7200","4.6509","4.6509","3.1006","7.6155","28.1775"
"18.8000","4.6707","4.6707","3.1138","7.6531","28.3164"
"18.8800","4.6910","4.6910","3.1273","7.6890","28.4494"
"18.9600","4.7098","4.7098","3.1399","7.7263","28.5873"
"19.0400","4.7305","4.7305","3.1537","7.7687","28.7440"
"19.1200","4.7498","4.7498","3.1665","7.8002","28.8608"
"19.2000","4.7709","4.7709","3.1806","7.8385","29.0026"
"19.2800","4.7916","4.7916","3.1944","7.8785","29.1503"
"19.3600","4.8110","4.8110","3.2074","7.9171","29.2934"
"19.4400","4.8309","4.8309","3.2206","7.9539","29.4296"
"19.5200","4.8507","4.8507","3.2338","7.9891","29.5598"
"19.6000","4.8701","4.8701","3.2467","8.0297","29.7097"
"19.6800","4.8903","4.8903","3.2602","8.0675","29.8497"
"19.7600","4.9096","4.9096","3.2730","8.1000","29.9698"
"19.8400","4.9303","4.9303","3.2869","8.1388","30.1137"
"19.9200","4.9514","4.9514","3.3009","8.1778","30.2578"
"20.0000","4.9708","4.9708","3.3139","8.2185","30.4083"
"20.0800","4.9910","4.9910","3.3274","8.2535","30.5378"
"20.1600","5.0105","5.0105","3.3403","8.2926","30.6826"
"20.2400","5.0307","5.0307","3.3538","8.3271","30.8101"
"20.3200","5.0505","5.0505","3.3670","8.3661","30.9547"
"20.4000","5.0694","5.0694","3.3796","8.4001","31.0804"
"20.4800","5.0907","5.0907","3.3938","8.4372","31.2176"
"20.5600","5.1119","5.1119","3.4079","8.4794","31.3736"
"20.6400","5.1314","5.1314","3.4209","8.5157","31.5079"
"20.7200","5.1511","5.1511","3.4341","8.5553","31.6548"
"20.8000","5.1696","5.1696","3.4464","8.5874","31.7735"
"20.8800","5.1904","5.1904","3.4603","8.6242","31.9096"
"20.9600","5.2103","5.2103","3.4735","8.6589","32.0380"
"21.0400","5.2297","5.2297","3.4864","8.6977","32.1814"
"21.1200","5.2504","5.2504","3.5003","8.7385","32.3326"
"21.2000","5.2710","5.2710","3.5140","8.7774","32.4763"
"21.2800","5.2909","5.2909","3.5273","8.8124","32.6058"
"21.3600","5.3112","5.3112","3.5408","8.8475","32.7358"
"21.4400","5.3299","5.3299","3.5533","8.8857","32.8770"
"21.5200","5.3507","5.3507","3.5671","8.9244","33.0202"
"21.6000","5.3705","5.3705","3.5804","8.9627","33.1620"
"21.6800","5.3905","5.3905","3.5937","9.0025","33.3092"
"21.7600","5.4112","5.4112","3.6075","9.0400","33.4480"
"21.8400","5.4310","5.4310","3.6206","9.0759","33.5809"
"21.9200","5.4515","5.4515","3.6343","9.1127","33.7170"
"22.0000","5.4711","5.4711","3.6474","9.1512","33.8594"
"22.0800","5.4898","5.4898","3.6599","9.1876","33.9941"
"22.1600","5.5106","5.5106","3.6737","9.2256","34.1346"
"22.2400","5.5303","5.5303","3.6869","9.2617","34.2682"
"22.3200","5.5499","5.5499","3.6999","9.2968","34.3981"
"22.4000","5.5708","5.5708","3.7139","9.3377","34.5494"
"22.4800","5.5906","5.5906","3.7271","9.3737","34.6827"
"22.5600","5.6116","5.6116","3.7411","9.4136","34.8302"
"22.6400","5.6309","5.6309","3.7539","9.4491","34.9615"
"22.7200","5.6498","5.6498","3.7665","9.4820","35.0834"
"22.8000","5.6698","5.6698","3.7799","9.5206","35.2261"
"22.8800","5.6901","5.6901","3.7934","9.5569","35.3606"
"22.9600","5.7109","5.7109","3.8073","9.5979","35.5121"
"23.0400","5.7322","5.7322","3.8215","9.6337","35.6445"
"23.1200","5.7507","5.7507","3.8338","9.6743","35.7950"
"23.2000","5.7707","5.7707","3.8471","9.7077","35.9186"
"23.2800","5.7902","5.7902","3.8601","9.7468","36.0633"
"23.3600","5.8104","5.8104","3.8736","9.7857","36.2071"
"23.4400","5.8307","5.8307","3.8872","9.8205","36.3360"
"23.5200","5.8494","5.8494","3.8996","9.8536","36.4584"
"23.6000","5.8703","5.8703","3.9135","9.8921","36.6006"
"23.6800","5.8909","5.8909","3.9273","9.9288","36.7367"
"23.7600","5.9109","5.9109","3.9406","9.9675","36.8797"
"23.8400","5.9312","5.9312","3.9541","10.0062","37.0229"
"23.9200","5.9500","5.9500","3.9666","10.0415","37.1536"
"24.0000","5.9703","5.9703","3.9802","10.0803","37.2970"
"24.0800","5.9911","5.9911","3.9941","10.1167","37.4319"
"24.1600","6.0100","6.0100","4.0067","10.1540","37.5698"
"24.2400","6.0310","6.0310","4.0207","10.1937","37.7167"
"24.3200","6.0512","6.0512","4.0341","10.2301","37.8515"
"24.4000","6.0709","6.0709","4.0472","10.2655","37.9825"
"24.4800","6.0904","6.0904","4.0603","10.3034","38.1227"
"24.5600","6.1103","6.1103","4.0735","10.3417","38.2642"
"24.6400","6.1306","6.1306","4.0871","10.3773","38.3960"
"24.7200","6.1505","6.1505","4.1003","10.4141","38.5321"
"24.8000","6.1693","6.1693","4.1128","10.4493","38.6623"
"24.8800","6.1904","6.1904","4.1269","10.4901","38.8134"
"24.9600","6.2106","6.2106","4.1404","10.5267","38.9490"
"25.0400","6.2320","6.2320","4.1547","10.5673","39.0990"
"25.1200","6.2507","6.2507","4.1671","10.6006","39.2224"
"25.2000","6.2694","6.2694","4.1796","10.6365","39.3550"
"25.2800","6.2902","6.2902","4.1935","10.6757","39.5001"
"25.3600","6.3107","6.3107","4.2071","10.7151","39.6458"
"25.4400","6.3310","6.3310","4.2206","10.7537","39.7888"
"25.5200","6.3516","6.3516","4.2344","10.7914","39.9283"
"25.6000","6.3703","6.3703","4.2469","10.8263","40.0574"
"25.6800","6.3910","6.3910","4.2606","10.8631","40.1936"
"25.7600","6.4111","6.4111","4.2741","10.9000","40.3301"
"25.8400","6.4303","6.4303","4.2869","10.9343","40.4569"
"25.9200","6.4504","6.4504","4.3003","10.9740","40.6039"
"26.0000","6.4692","6.4692","4.3128","11.0084","40.7309"
"26.0800","6.4904","6.4904","4.3269","11.0471","40.8741"
"26.1600","6.5111","6.5111","4.3407","11.0861","41.0187"
"26.2400","6.5309","6.5309","4.3539","11.1239","41.1585"
"26.3200","6.5505","6.5505","4.3670","11.1578","41.2837"
"26.4000","6.5704","6.5704","4.3803","11.1935","41.4160"
"26.4800","6.5900","6.5900","4.3933","11.2307","41.5535"
"26.5600","6.6110","6.6110","4.4073","11.2722","41.7072"
"26.6400","6.6297","6.6297","4.4198","11.3040","41.8249"
"26.7200","6.6511","6.6511","4.4340","11.3405","41.9599"
"26.8000","6.6714","6.6714","4.4476","11.3821","42.1139"
"26.8800","6.6911","6.6911","4.4608","11.4196","42.2526"
"26.9600","6.7107","6.7107","4.4738","11.4592","42.3992"
"27.0400","6.7309","6.7309","4.4873","11.4942","42.5286"
"27.1200","6.7505","6.7505","4.5003","11.5277","42.6525"
"27.2000","6.7703","6.7703","4.5136","11.5651","42.7908"
"27.2800","6.7891","6.7891","4.5260","11.5993","42.9172"
"27.3600","6.8105","6.8105","4.5403","11.6396","43.0664"
"27.4400","6.8313","6.8313","4.5542","11.6797","43.2150"
"27.5200","6.8513","6.8513","4.5675","11.7148","43.3447"
"27.6000","6.8706","6.8706","4.5804","11.7522","43.4831"
"27.6800","6.8896","6.8896","4.5931","11.7881","43.6159"
"27.7600","6.9110","6.9110","4.6073","11.8262","43.7568"
"27.8400","6.9309","6.9309","4.6206","11.8638","43.8960"
"27.9200","6.9505","6.9505","4.6337","11.9015","44.0355"
"28.0000","6.9706","6.9706","4.6470","11.9407","44.1805"
"28.0800","6.9913","6.9913","4.6608","11.9766","44.3134"
"28.1600","7.0113","7.0113","4.6742","12.0104","44.4384"
"28.2400","7.0315","7.0315","4.6876","12.0495","44.5830"
"28.3200","7.0499","7.0499","4.7000","12.0861","44.7184"
"28.4000","7.0701","7.0701","4.7134","12.1218","44.8508"
"28.4800","7.0896","7.0896","4.7264","12.1592","44.9891"
"28.5600","7.1098","7.1098","4.7398","12.1955","45.1234"
"28.6400","7.1312","7.1312","4.7542","12.2362","45.2739"
"28.7200","7.1512","7.1512","4.7674","12.2714","45.4043"
"28.8000","7.1711","7.1711","4.7807","12.3082","45.5405"
"28.8800","7.1910","7.1910","4.7940","12.3467","45.6828"
"28.9600","7.2100","7.2100","4.8067","12.3819","45.8130"
"29.0400","7.2306","7.2306","4.8204","12.4224","45.9628"
"29.1200","7.2498","7.2498","4.8332","12.4571","46.0913"
"29.2000","7.2706","7.2706","4.8471","12.4945","46.2296"
"29.2800","7.2918","7.2918","4.8612","12.5361","46.3835"
"29.3600","7.3112","7.3112","4.8741","12.5718","46.5156"
"29.4400","7.3308","7.3308","4.8872","12.6059","46.6417"
"29.5200","7.3508","7.3508","4.9005","12.6430","46.7790"
"29.6000","7.3699","7.3699","4.9133","12.6781","46.9091"
"29.6800","7.3903","7.3903","4.9269","12.7174","47.0545"
"29.7600","7.4096","7.4096","4.9398","12.7511","47.1792"
"29.8400","7.4308","7.4308","4.9538","12.7911","47.3271"
"29.9200","7.4513","7.4513","4.9675","12.8301","47.4712"
"30.0000","7.4702","7.4702","4.9801","12.8661","47.6045"
"30.0800","7.4909","7.4909","4.9939","12.9059","47.7519"
"30.1600","7.5104","7.5104","5.0070","12.9406","47.8802"
"30.2400","7.5305","7.5305","5.0203","12.9766","48.0136"
"30.3200","7.5505","7.5505","5.0336","13.0138","48.1509"
"30.4000","7.5701","7.5701","5.0467","13.0532","48.2970"
"30.4800","7.5908","7.5908","5.0606","13.0898","48.4323"
"30.5600","7.6120","7.6120","5.0747","13.1310","48.5847"
"30.6400","7.6309","7.6309","5.0873","13.1647","48.7094"
"30.7200","7.6508","7.6508","5.1005","13.2042","48.8555"
"30.8000","7.6696","7.6696","5.1131","13.2356","48.9718"
"30.8800","7.6905","7.6905","5.1270","13.2731","49.1103"
"30.9600","7.7103","7.7103","5.1402","13.3074","49.2374"
"31.0400","7.7297","7.7297","5.1532","13.3486","49.3897"
"31.1200","7.7505","7.7505","5.1670","13.3878","49.5349"
"31.2000","7.7710","7.7710","5.1807","13.4258","49.6754"
"31.2800","7.7908","7.7908","5.1939","13.4615","49.8076"
"31.3600","7.8110","7.8110","5.2074","13.4981","49.9428"
"31.4400","7.8302","7.8302","5.2201","13.5391","50.0945"
"31.5200","7.8507","7.8507","5.2338","13.5750","50.2275"
"31.6000","7.8704","7.8704","5.2469","13.6110","50.3609"
"31.6800","7.8903","7.8903","5.2602","13.6489","50.5009"
"31.7600","7.9116","7.9116","5.2744","13.6904","50.6546"
"31.8400","7.9311","7.9311","5.2874","13.7237","50.7776"
"31.9200","7.9512","7.9512","5.3008","13.7589","50.9080"
"32.0000","7.9707","7.9707","5.3138","13.7954","51.0431"
"32.0800","7.9897","7.9897","5.3265","13.8322","51.1791"
"32.1600","8.0103","8.0103","5.3402","13.8747","51.3364"
"32.2400","8.0304","8.0304","5.3536","13.9091","51.4638"
"32.3200","8.0497","8.0497","5.3665","13.9423","51.5866"
"32.4000","8.0710","8.0710","5.3807","13.9830","51.7372"
"32.4800","8.0901","8.0901","5.3934","14.0190","51.8703"
"32.5600","8.1112","8.1112","5.4075","14.0563","52.0082"
"32.6400","8.1306","8.1306","5.4204","14.0932","52.1448"
"32.7200","8.1501","8.1501","5.4334","14.1314","52.2860"
"32.8000","8.1701","8.1701","5.4468","14.1673","52.4190"
"32.8800","8.1903","8.1903","5.4602","14.2060","52.5621"
"32.9600","8.2110","8.2110","5.4740","14.2441","52.7031"
"33.0400","8.2323","8.2323","5.4882","14.2803","52.8370"
"33.1200","8.2508","8.2508","5.5005","14.3165","52.9709"
"33.2000","8.2704","8.2704","5.5136","14.3509","53.0983"
"33.2800","8.2898","8.2898","5.5265","14.3875","53.2336"
"33.3600","8.3107","8.3107","5.5405","14.4251","53.3730"
"33.4400","8.3312","8.3312","5.5541","14.4637","53.5156"
"33.5200","8.3495","8.3495","5.5663","14.4963","53.6362"
"33.6000","8.3703","8.3703","5.5802","14.5351","53.7799"
"33.6800","8.3910","8.3910","5.5940","14.5743","53.9248"
"33.7600","8.4110","8.4110","5.6073","14.6129","54.0678"
"33.8400","8.4309","8.4309","5.6206","14.6516","54.2110"
"33.9200","8.4495","8.4495","5.6330","14.6831","54.3275"
"34.0000","8.4703","8.4703","5.6469","14.7206","54.4661"
"34.0800","8.4913","8.4913","5.6609","14.7591","54.6087"
"34.1600","8.5107","8.5107","5.6738","14.8004","54.7614"
"34.2400","8.5314","8.5314","5.6876","14.8363","54.8943"
"34.3200","8.5512","8.5512","5.7008","14.8733","55.0314"
"34.4000","8.5709","8.5709","5.7139","14.9084","55.1612"
"34.4800","8.5905","8.5905","5.7270","14.9426","55.2878"
"34.5600","8.6101","8.6101","5.7401","14.9806","55.4282"
"34.6400","8.6309","8.6309","5.7540","15.0197","55.5730"
"34.7200","8.6507","8.6507","5.7671","15.0566","55.7096"
"34.8000","8.6692","8.6692","5.7795","15.0919","55.8399"
"34.8800","8.6908","8.6908","5.7938","15.1310","55.9847"
"34.9600","8.7105","8.7105","5.8070","15.1666","56.1164"
"35.0400","8.7316","8.7316","5.8210","15.2058","56.2615"
"35.1200","8.7507","8.7507","5.8338","15.2389","56.3840"
"35.2000","8.7695","8.7695","5.8463","15.2752","56.5183"
"35.2800","8.7901","8.7901","5.8601","15.3153","56.6665"
"35.3600","8.8106","8.8106","5.8737","15.3532","56.8070"
"35.4400","8.8310","8.8310","5.8874","15.3903","56.9443"
"35.5200","8.8519","8.8519","5.9013","15.4283","57.0847"
"35.6000","8.8711","8.8711","5.9140","15.4623","57.2104"
"35.6800","8.8906","8.8906","5.9271","15.4997","57.3488"
"35.7600","8.9106","8.9106","5.9404","15.5349","57.4790"
"35.8400","8.9303","8.9303","5.9535","15.5742","57.6246"
"35.9200","8.9504","8.9504","5.9669","15.6111","57.7612"
"36.0000","8.9693","8.9693","5.9796","15.6473","57.8950"
"36.0800","8.9902","8.9902","5.9935","15.6844","58.0322"
"36.1600","9.0114","9.0114","6.0076","15.7227","58.1741"
"36.2400","9.0311","9.0311","6.0208","15.7587","58.3073"
"36.3200","9.0506","9.0506","6.0338","15.7953","58.4425"
"36.4000","9.0701","9.0701","6.0468","15.8309","58.5743"
"36.4800","9.0896","9.0896","6.0597","15.8648","58.6997"
"36.5600","9.1109","9.1109","6.0739","15.9063","58.8533"
"36.6400","9.1300","9.1300","6.0867","15.9427","58.9881"
"36.7200","9.1513","9.1513","6.1008","15.9817","59.1322"
"36.8000","9.1714","9.1714","6.1143","16.0183","59.2677"
"36.8800","9.1910","9.1910","6.1274","16.0566","59.4093"
"36.9600","9.2106","9.2106","6.1404","16.0933","59.5453"
"37.0400","9.2303","9.2303","6.1535","16.1256","59.6646"
"37.1200","9.2501","9.2501","6.1667","16.1610","59.7957"
"37.2000","9.2703","9.2703","6.1802","16.1977","59.9314"
"37.2800","9.2893","9.2893","6.1928","16.2353","60.0705"
"37.3600","9.3108","9.3108","6.2072","16.2780","60.2286"
"37.4400","9.3315","9.3315","6.2210","16.3140","60.3618"
"37.5200","9.3508","9.3508","6.2339","16.3506","60.4973"
"37.6000","9.3708","9.3708","6.2472","16.3863","60.6295"
"37.6800","9.3898","9.3898","6.2599","16.4207","60.7564"
"37.7600","9.4107","9.4107","6.2738","16.4566","60.8894"
"37.8400","9.4308","9.4308","6.2872","16.4956","61.0338"
"37.9200","9.4502","9.4502","6.3002","16.5314","61.1661"
"38.0000","9.4705","9.4705","6.3136","16.5738","61.3231"
"38.0800","9.4909","9.4909","6.3272","16.6072","61.4465"
"38.1600","9.5111","9.5111","6.3407","16.6454","61.5881"
"38.2400","9.5314","9.5314","6.3543","16.6815","61.7215"
"38.3200","9.5497","9.5497","6.3665","16.7142","61.8427"
"38.4000","9.5702","9.5702","6.3802","16.7515","61.9805"
"38.4800","9.5897","9.5897","6.3931","16.7874","62.1132"
"38.5600","9.6100","9.6100","6.4067","16.8263","62.2574"
"38.6400","9.6312","9.6312","6.4208","16.8668","62.4070"
"38.7200","9.6509","9.6509","6.4339","16.9025","62.5391"
"38.8000","9.6707","9.6707","6.4471","16.9385","62.6723"
"38.8800","9.6910","9.6910","6.4607","16.9751","62.8078"
"38.9600","9.7097","9.7097","6.4731","17.0101","62.9374"
"39.0400","9.7306","9.7305","6.4870","17.0512","63.0895"
"39.1200","9.7499","9.7499","6.4999","17.0837","63.2098"
"39.2000","9.7713","9.7713","6.5142","17.1253","63.3635"
"39.2800","9.7918","9.7918","6.5279","17.1642","63.5074"
"39.3600","9.8110","9.8110","6.5406","17.1998","63.6392"
"39.4400","9.8310","9.8310","6.5540","17.2378","63.7800"
"39.5200","9.8506","9.8506","6.5671","17.2726","63.9087"
"39.6000","9.8699","9.8699","6.5799","17.3089","64.0428"
"39.6800","9.8905","9.8905","6.5936","17.3488","64.1906"
"39.7600","9.9097","9.9097","6.6065","17.3842","64.3214"
"39.8400","9.9306","9.9306","6.6204","17.4213","64.4590"
"39.9200","9.9514","9.9514","6.6343","17.4562","64.5881"
"40.0000","9.9702","9.9702","6.6468","17.4944","64.7293"
"40.0800","9.9908","9.9908","6.6605","17.5338","64.8751"
"40.1600","10.0099","10.0099","6.6733","17.5707","65.0115"
"40.2400","10.0307","10.0307","6.6871","17.6056","65.1409"
"40.3200","10.0507","10.0507","6.7005","17.6421","65.2757"
"40.4000","10.0698","10.0698","6.7132","17.6795","65.4142"
"40.4800","10.0907","10.0907","6.7272","17.7181","65.5571"
"40.5600","10.1118","10.1118","6.7412","17.7579","65.7041"
"40.6400","10.1312","10.1312","6.7541","17.7923","65.8317"
"40.7200","10.1509","10.1509","6.7673","17.8311","65.9750"
"40.8000","10.1695","10.1695","6.7797","17.8624","66.0909"
"40.8800","10.1907","10.1907","6.7938","17.9015","66.2357"
"40.9600","10.2105","10.2105","6.8070","17.9382","66.3714"
"41.0400","10.2295","10.2295","6.8197","17.9761","66.5117"
"41.1200","10.2505","10.2505","6.8337","18.0150","66.6557"
"41.2000","10.2703","10.2703","6.8469","18.0507","66.7876"
"41.2800","10.2907","10.2907","6.8604","18.0876","66.9242"
"41.3600","10.3116","10.3116","6.8744","18.1261","67.0666"
"41.4400","10.3303","10.3303","6.8869","18.1589","67.1881"
"41.5200","10.3508","10.3508","6.9005","18.1991","67.3367"
"41.6000","10.3705","10.3705","6.9137","18.2354","67.4711"
"41.6800","10.3902","10.3902","6.9268","18.2739","67.6133"
"41.7600","10.4114","10.4114","6.9409","18.3120","67.7543"
"41.8400","10.4309","10.4309","6.9539","18.3486","67.8898"
"41.9200","10.4515","10.4515","6.9677","18.3881","68.0358"
"42.0000","10.4708","10.4708","6.9805","18.4215","68.1596"
"42.0800","10.4901","10.4901","6.9934","18.4573","68.2920"
"42.1600","10.5102","10.5102","7.0068","18.4969","68.4384"
"42.2400","10.5301","10.5301","7.0201","18.5308","68.5640"
"42.3200","10.5500","10.5500","7.0333","18.5678","68.7007"
"42.4000","10.5711","10.5711","7.0474","18.6065","68.8439"
"42.4800","10.5900","10.5900","7.0600","18.6427","68.9779"
"42.5600","10.6112","10.6112","7.0741","18.6824","69.1250"
"42.6400","10.6307","10.6307","7.0872","18.7198","69.2632"
"42.7200","10.6500","10.6500","7.1000","18.7548","69.3926"
"42.8000","10.6702","10.6702","7.1135","18.7925","69.5322"
"42.8800","10.6901","10.6901","7.1267","18.8281","69.6641"
"42.9600","10.7109","10.7109","7.1406","18.8655","69.8024"
"43.0400","10.7323","10.7323","7.1548","18.9026","69.9397"
"43.1200","10.7507","10.7507","7.1672","18.9394","70.0758"
"43.2000","10.7706","10.7706","7.1804","18.9755","70.2093"
"43.2800","10.7901","10.7901","7.1934","19.0124","70.3459"
"43.3600","10.8106","10.8106","7.2070","19.0511","70.4891"
"43.4400","10.8310","10.8310","7.2207","19.0877","70.6245"
"43.5200","10.8492","10.8492","7.2328","19.1210","70.7477"
"43.6000","10.8695","10.8695","7.2463","19.1580","70.8844"
"43.6800","10.8910","10.8910","7.2607","19.1968","71.0280"
"43.7600","10.9114","10.9114","7.2742","19.2368","71.1761"
"43.8400","10.9318","10.9318","7.2879","19.2789","71.3320"
"43.9200","10.9502","10.9502","7.3001","19.3086","71.4418"
"44.0000","10.9701","10.9701","7.3134","19.3455","71.5785"
"44.0800","10.9910","10.9910","7.3274","19.3856","71.7269"
"44.1600","11.0099","11.0099","7.3400","19.4215","71.8596"
"44.2400","11.0314","11.0314","7.3542","19.4631","72.0136"
"44.3200","11.0511","11.0511","7.3674","19.4990","72.1465"
"44.4000","11.0714","11.0714","7.3809","19.5325","72.2701"
"44.4800","11.0907","11.0907","7.3938","19.5693","72.4066"
"44.5600","11.1101","11.1101","7.4067","19.6055","72.5403"
"44.6400","11.1308","11.1308","7.4205","19.6432","72.6798"
"44.7200","11.1501","11.1501","7.4334","19.6793","72.8134"
"44.8000","11.1689","11.1689","7.4459","19.7169","72.9525"
"44.8800","11.1905","11.1905","7.4603","19.7581","73.1051"
"44.9600","11.2108","11.2108","7.4738","19.7958","73.2446"
"45.0400","11.2319","11.2319","7.4880","19.8342","73.3865"
"45.1200","11.2506","11.2506","7.5004","19.8653","73.5016"
"45.2000","11.2691","11.2691","7.5127","19.8997","73.6290"
"45.2800","11.2902","11.2902","7.5268","19.9412","73.7824"
"45.3600","11.3106","11.3106","7.5404","19.9783","73.9196"
"45.4400","11.3307","11.3307","7.5538","20.0156","74.0578"
"45.5200","11.3513","11.3513","7.5675","20.0526","74.1945"
"45.6000","11.3704","11.3704","7.5803","20.0888","74.3285"
"45.6800","11.3913","11.3913","7.5942","20.1268","74.4692"
"45.7600","11.4113","11.4113","7.6075","20.1649","74.6102"
"45.8400","11.4304","11.4304","7.6203","20.2016","74.7457"
"45.9200","11.4504","11.4504","7.6336","20.2392","74.8852"
"46.0000","11.4686","11.4686","7.6457","20.2686","74.9940"
"46.0800","11.4903","11.4903","7.6602","20.3084","75.1411"
"46.1600","11.5119","11.5119","7.6746","20.3492","75.2922"
"46.2400","11.5311","11.5311","7.6874","20.3840","75.4208"
"46.3200","11.5507","11.5507","7.7004","20.4201","75.5543"
"46.4000","11.5705","11.5705","7.7136","20.4590","75.6983"
"46.4800","11.5896","11.5896","7.7264","20.4938","75.8269"
"46.5600","11.6111","11.6111","7.7407","20.5339","75.9756"
"46.6400","11.6300","11.6300","7.7533","20.5668","76.0971"
"46.7200","11.6513","11.6513","7.7675","20.6065","76.2439"
"46.8000","11.6713","11.6713","7.7808","20.6434","76.3805"
"46.8800","11.6911","11.6911","7.7941","20.6830","76.5273"
"46.9600","11.7107","11.7107","7.8072","20.7188","76.6594"
"47.0400","11.7304","11.7304","7.8203","20.7537","76.7886"
"47.1200","11.7504","11.7504","7.8336","20.7915","76.9286"
"47.2000","11.7708","11.7708","7.8472","20.8268","77.0592"
"47.2800","11.7890","11.7890","7.8593","20.8607","77.1846"
"47.3600","11.8108","11.8108","7.8739","20.9010","77.3338"
"47.4400","11.8314","11.8314","7.8876","20.9373","77.4681"
"47.5200","11.8509","11.8509","7.9006","20.9715","77.5947"
"47.6000","11.8705","11.8705","7.9137","21.0092","77.7342"
"47.6800","11.8897","11.8897","7.9265","21.0419","77.8551"
"47.7600","11.9109","11.9109","7.9406","21.0824","78.0048"
"47.8400","11.9308","11.9308","7.9539","21.1197","78.1428"
"47.9200","11.9503","11.9503","7.9669","21.1567","78.2797"
"48.0000","11.9705","11.9705","7.9803","21.1937","78.4168"
"48.0800","11.9912","11.9912","7.9941","21.2321","78.5587"
"48.1600","12.0117","12.0117","8.0078","21.2690","78.6952"
"48.2400","12.0317","12.0317","8.0211","21.3048","78.8278"
"48.3200","12.0495","12.0495","8.0330","21.3381","78.9509"
"48.4000","12.0700","12.0700","8.0467","21.3770","79.0951"
"48.4800","12.0898","12.0898","8.0599","21.4152","79.2362"
"48.5600","12.1099","12.1099","8.0732","21.4513","79.3697"
"48.6400","12.1308","12.1308","8.0872","21.4911","79.5171"
"48.7200","12.1510","12.1510","8.1007","21.5276","79.6520"
"48.8000","12.1709","12.1709","8.1139","21.5634","79.7844"
"48.8800","12.1911","12.1911","8.1274","21.5992","79.9170"
"48.9600","12.2100","12.2100","8.1400","21.6363","80.0543"
"49.0400","12.2308","12.2308","8.1538","21.6760","80.2012"
"49.1200","12.2497","12.2497","8.1664","21.7083","80.3208"
"49.2000","12.2706","12.2706","8.1804","21.7484","80.4693"
"49.2800","12.2918","12.2918","8.1945","21.7877","80.6144"
"49.3600","12.3109","12.3109","8.2072","21.8233","80.7462"
"49.4400","12.3309","12.3309","8.2206","21.8607","80.8844"
"49.5200","12.3507","12.3507","8.2338","21.8959","81.0149"
"49.6000","12.3702","12.3702","8.2468","21.9305","81.1429"
"49.6800","12.3905","12.3905","8.2603","21.9701","81.2894"
"49.7600","12.4095","12.4095","8.2730","22.0050","81.4186"
"49.8400","12.4300","12.4300","8.2867","22.0407","81.5506"
"49.9200","12.4514","12.4514","8.3009","22.0846","81.7131"
"50.0000","12.4703","12.4703","8.3135","22.1206","81.8462"
"50.0800","12.4908","12.4908","8.3272","22.1584","81.9860"
"50.1600","12.5103","12.5103","8.3402","22.1935","82.1159"
"50.2400","12.5309","12.5309","8.3540","22.2318","82.2575"
"50.3200","12.5506","12.5506","8.3670","22.2660","82.3843"
"50.4000","12.5700","12.5700","8.3800","22.3021","82.5178"
"50.4800","12.5907","12.5907","8.3938","22.3423","82.6666"
"50.5600","12.6119","12.6119","8.4080","22.3840","82.8207"
"50.6400","12.6311","12.6311","8.4207","22.4203","82.9550"
"50.7200","12.6509","12.6509","8.4340","22.4558","83.0866"
"50.8000","12.6698","12.6698","8.4465","22.4903","83.2142"
"50.8800","12.6907","12.6907","8.4604","22.5263","83.3473"
"50.9600","12.7101","12.7101","8.4734","22.5616","83.4780"
"51.0400","12.7296","12.7296","8.4864","22.5989","83.6158"
"51.1200","12.7506","12.7506","8.5004","22.6403","83.7691"
"51.2000","12.7710","12.7710","8.5140","22.6770","83.9050"
"51.2800","12.7908","12.7908","8.5272","22.7105","84.0287"
"51.3600","12.8111","12.8111","8.5408","22.7507","84.1776"
"51.4400","12.8300","12.8300","8.5533","22.7849","84.3042"
"51.5200","12.8509","12.8509","8.5672","22.8221","84.4419"
"51.6000","12.8704","12.8704","8.5803","22.8608","84.5849"
"51.6800","12.8901","12.8901","8.5934","22.8978","84.7219"
"51.7600","12.9117","12.9117","8.6078","22.9363","84.8642"
"51.8400","12.9315","12.9315","8.6210","22.9735","85.0018"
"51.9200","12.9513","12.9513","8.6342","23.0073","85.1270"
"52.0000","12.9707","12.9707","8.6472","23.0427","85.2579"
"52.0800","12.9899","12.9899","8.6600","23.0796","85.3945"
"52.1600","13.0106","13.0106","8.6737","23.1202","85.5447"
"52.2400","13.0301","13.0301","8.6867","23.1567","85.6798"
"52.3200","13.0498","13.0498","8.6999","23.1912","85.8074"
"52.4000","13.0708","13.0708","8.7139","23.2307","85.9536"
"52.4800","13.0902","13.0902","8.7268","23.2662","86.0849"
"52.5600","13.1112","13.1112","8.7408","23.3070","86.2359"
"52.6400","13.1307","13.1307","8.7538","23.3396","86.3565"
"52.7200","13.1502","13.1502","8.7668","23.3778","86.4980"
"52.8000","13.1700","13.1700","8.7800","23.4153","86.6365"
"52.8800","13.1901","13.1901","8.7934","23.4500","86.7650"
"52.9600","13.2110","13.2110","8.8073","23.4898","86.9122"
"53.0400","13.2323","13.2323","8.8215","23.5289","87.0569"
"53.1200","13.2504","13.2504","8.8336","23.5631","87.1834"
"53.2000","13.2705","13.2705","8.8470","23.5983","87.3138"
"53.2800","13.2901","13.2901","8.8601","23.6347","87.4484"
"53.3600","13.3107","13.3107","8.8738","23.6714","87.5842"
"53.4400","13.3308","13.3308","8.8872","23.7141","87.7420"
"53.5200","13.3494","13.3494","8.8996","23.7486","87.8699"
"53.6000","13.3701","13.3701","8.9134","23.7841","88.0012"
"53.6800","13.3914","13.3914","8.9276","23.8269","88.1594"
"53.7600","13.4110","13.4110","8.9407","23.8632","88.2938"
"53.8400","13.4309","13.4309","8.9539","23.9019","88.4369"
"53.9200","13.4502","13.4502","8.9668","23.9334","88.5535"
"54.0000","13.4704","13.4704","8.9803","23.9707","88.6915"
"54.0800","13.4910","13.4910","8.9940","24.0063","88.8232"
"54.1600","13.5099","13.5099","9.0066","24.0449","88.9660"
"54.2400","13.5314","13.5314","9.0210","24.0864","89.1195"
"54.3200","13.5512","13.5512","9.0342","24.1228","89.2544"
"54.4000","13.5711","13.5711","9.0474","24.1620","89.3993"
"54.4800","13.5910","13.5910","9.0606","24.1983","89.5337"
"54.5600","13.6102","13.6102","9.0735","24.2329","89.6616"
"54.6400","13.6308","13.6308","9.0872","24.2698","89.7983"
"54.7200","13.6505","13.6505","9.1004","24.3051","89.9288"
"54.8000","13.6692","13.6692","9.1128","24.3400","90.0581"
"54.8800","13.6903","13.6903","9.1269","24.3818","90.2125"
"54.9600","13.7109","13.7109","9.1406","24.4193","90.3515"
"55.0400","13.7316","13.7316","9.1544","24.4578","90.4940"
"55.1200","13.7509","13.7509","9.1672","24.4914","90.6183"
"55.2000","13.7692","13.7692","9.1795","24.5258","90.7456"
"55.2800","13.7900","13.7900","9.1933","24.5675","90.8997"
"55.3600","13.8108","13.8108","9.2072","24.6054","91.0401"
"55.4400","13.8313","13.8313","9.2209","24.6427","91.1780"
"55.5200","13.8519","13.8519","9.2346","24.6814","91.3212"
"55.6000","13.8706","13.8706","9.2471","24.7167","91.4519"
"55.6800","13.8909","13.8909","9.2606","24.7523","91.5837"
"55.7600","13.9108","13.9108","9.2739","24.7921","91.7306"
"55.8400","13.9302","13.9302","9.2868","24.8272","91.8606"
"55.9200","13.9504","13.9504","9.3002","24.8638","91.9959"
"56.0000","13.9693","13.9693","9.3129","24.8988","92.1254"
"56.0800","13.9901","13.9901","9.3267","24.9374","92.2682"
"56.1600","14.0116","14.0116","9.3410","24.9790","92.4225"
"56.2400","14.0308","14.0308","9.3539","25.0113","92.5418"
"56.3200","14.0505","14.0505","9.3670","25.0478","92.6770"
"56.4000","14.0706","14.0706","9.3804","25.0873","92.8229"
"56.4800","14.0903","14.0903","9.3935","25.1220","92.9513"
"56.5600","14.1109","14.1109","9.4072","25.1623","93.1005"
"56.6400","14.1301","14.1301","9.4201","25.1986","93.2349"
"56.7200","14.1511","14.1511","9.4341","25.2352","93.3703"
"56.8000","14.1712","14.1712","9.4475","25.2727","93.5089"
"56.8800","14.1909","14.1909","9.4606","25.3101","93.6475"
"56.9600","14.2107","14.2107","9.4738","25.3488","93.7904"
"57.0400","14.2303","14.2303","9.4869","25.3827","93.9160"
"57.1200","14.2504","14.2504","9.5003","25.4197","94.0529"
"57.2000","14.2705","14.2705","9.5136","25.4581","94.1948"
"57.2800","14.2892","14.2892","9.5261","25.4924","94.3217"
"57.3600","14.3108","14.3108","9.5405","25.5354","94.4808"
"57.4400","14.3311","14.3311","9.5540","25.5733","94.6211"
"57.5200","14.3509","14.3509","9.5673","25.6076","94.7482"
"57.6000","14.3707","14.3707","9.5805","25.6470","94.8940"
"57.6800","14.3896","14.3896","9.5931","25.6784","95.0100"
"57.7600","14.4106","14.4106","9.6071","25.7180","95.1565"
"57.8400","14.4309","14.4309","9.6206","25.7524","95.2840"
"57.9200","14.4504","14.4504","9.6336","25.7933","95.4354"
"58.0000","14.4708","14.4708","9.6472","25.8328","95.5812"
"58.0800","14.4909","14.4909","9.6606","25.8693","95.7163"
"58.1600","14.5115","14.5115","9.6743","25.9061","95.8526"
"58.2400","14.5312","14.5312","9.6875","25.9417","95.9844"
"58.3200","14.5495","14.5495","9.6996","25.9768","96.1143"
"58.4000","14.5703","14.5703","9.7135","26.0140","96.2518"
"58.4800","14.5897","14.5897","9.7265","26.0505","96.3870"
"58.5600","14.6096","14.6096","9.7397","26.0864","96.5197"
"58.6400","14.6310","14.6310","9.7540","26.1268","96.6690"
"58.7200","14.6512","14.6512","9.7675","26.1637","96.8058"
"58.8000","14.6711","14.6711","9.7808","26.2007","96.9426"
"58.8800","14.6909","14.6909","9.7940","26.2359","97.0726"
"58.9600","14.7099","14.7099","9.8066","26.2733","97.2112"
"59.0400","14.7306","14.7306","9.8204","26.3120","97.3546"
"59.1200","14.7499","14.7499","9.8333","26.3467","97.4829"
"59.2000","14.7706","14.7706","9.8470","26.3828","97.6165"
"59.2800","14.7916","14.7916","9.8611","26.4223","97.7626"
"59.3600","14.8109","14.8109","9.8739","26.4584","97.8962"
"59.4400","14.8309","14.8309","9.8873","26.4941","98.0283"
"59.5200","14.8505","14.8505","9.9004","26.5299","98.1605"
"59.6000","14.8699","14.8699","9.9133","26.5664","98.2958"
"59.6800","14.8901","14.8901","9.9267","26.6039","98.4346"
"59.7600","14.9096","14.9096","9.9398","26.6387","98.5633"
"59.8400","14.9302","14.9302","9.9535","26.6765","98.7030"
"59.9200","14.9512","14.9512","9.9674","26.7154","98.8471"
"60.0000","14.9704","14.9704","9.9802","26.7515","98.9805"
"60.0800","14.9909","14.9909","9.9939","26.7930","99.1342"
"60.1150","15.0000","15.0000","10.0000","26.8080","99.1898"