File: data/instron_tests/539_BULK_m2.is_comp_Exports/539_BULK_m2_6_1.csv
Sample text inputs : Sample No.,Sample choice input : Leading Direction,Sample choice input : Mode,Specimen choice input : Direction,Specimen properties : Height,Specimen properties : Thickness,Specimen properties : Width,Test : Rate 1
,,,,(mm),(mm),(mm),(mm/min)
"509","Bulk","Bimode","1","150.00","25.00","150.00","15.00"

Time,Displacement,Compressive displacement,Compressive strain (Displacement),Compressive stress,Force
(s),(mm),(mm),(%),(kPa),(N)
"0.0000","-0.0001","-0.0001","0.0000","-1.3600","-5.0321"
"0.0800","0.0013","0.0013","0.0008","-1.3611","-5.0360"
"0.1600","0.0099","0.0099","0.0066","-1.3420","-4.9655"
"0.2400","0.0302","0.0302","0.0201","-1.3069","-4.8355"
"0.3200","0.0506","0.0506","0.0338","-1.2738","-4.7131"
"0.4000","0.0685","0.0685","0.0457","-1.2456","-4.6089"
"0.4800","0.0885","0.0885","0.0590","-1.2140","-4.4919"
"0.5600","0.1104","0.1104","0.0736","-1.1836","-4.3794"
"0.6400","0.1301","0.1301","0.0868","-1.1531","-4.2666"
"0.7200","0.1497","0.1497","0.0998","-1.1227","-4.1539"
"0.8000","0.1688","0.1688","0.1125","-1.0950","-4.0516"
"0.8800","0.1894","0.1894","0.1263","-1.0709","-3.9624"
"0.9600","0.2097","0.2097","0.1398","-1.0431","-3.8595"
"1.0400","0.2288","0.2288","0.1525","-1.0184","-3.7680"
"1.1200","0.2498","0.2498","0.1666","-0.9892","-3.6601"
"1.2000","0.2703","0.2703","0.1802","-0.9639","-3.5665"
"1.2800","0.2902","0.2902","0.1935","-0.9408","-3.4811"
"1.3600","0.3103","0.3103","0.2069","-0.9162","-3.3899"
"1.4400","0.3289","0.3289","0.2192","-0.8900","-3.2931"
"1.5200","0.3501","0.3501","0.2334","-0.8681","-3.2120"
"1.6000","0.3698","0.3698","0.2465","-0.8419","-3.1149"
"1.6800","0.3892","0.3892","0.2595","-0.8146","-3.0140"
"1.7600","0.4102","0.4102","0.2735","-0.7855","-2.9064"
"1.8400","0.4304","0.4304","0.2870","-0.7578","-2.8040"
"1.9200","0.4508","0.4508","0.3005","-0.7330","-2.7122"
"2.0000","0.4701","0.4701","0.3134","-0.7064","-2.6136"
"2.0800","0.4888","0.4888","0.3259","-0.6796","-2.5144"
"2.1600","0.5095","0.5095","0.3397","-0.6536","-2.4182"
"2.2400","0.5293","0.5293","0.3529","-0.6285","-2.3254"
"2.3200","0.5493","0.5493","0.3662","-0.6002","-2.2206"
"2.4000","0.5698","0.5698","0.3799","-0.5722","-2.1173"
"2.4800","0.5889","0.5889","0.3926","-0.5458","-2.0195"
"2.5600","0.6106","0.6106","0.4071","-0.5160","-1.9093"
"2.6400","0.6305","0.6305","0.4204","-0.4881","-1.8059"
"2.7200","0.6494","0.6494","0.4329","-0.4655","-1.7223"
"2.8000","0.6690","0.6690","0.4460","-0.4334","-1.6035"
"2.8800","0.6892","0.6892","0.4594","-0.4024","-1.4889"
"2.9600","0.7102","0.7102","0.4735","-0.3730","-1.3799"
"3.0400","0.7314","0.7314","0.4876","-0.3459","-1.2800"
"3.1200","0.7499","0.7499","0.4999","-0.3118","-1.1537"
"3.2000","0.7698","0.7698","0.5132","-0.2808","-1.0391"
"3.2800","0.7894","0.7894","0.5262","-0.2490","-0.9212"
"3.3600","0.8097","0.8097","0.5398","-0.2173","-0.8042"
"3.4400","0.8302","0.8302","0.5534","-0.1806","-0.6683"
"3.5200","0.8486","0.8486","0.5658","-0.1513","-0.5599"
"3.6000","0.8694","0.8694","0.5796","-0.1175","-0.4349"
"3.6800","0.8903","0.8903","0.5936","-0.0836","-0.3091"
"3.7600","0.9104","0.9104","0.6069","-0.0485","-0.1796"
"3.8400","0.9302","0.9302","0.6201","-0.0148","-0.0547"
"3.9200","0.9493","0.9493","0.6329","0.0176","0.0651"
"4.0000","0.9695","0.9695","0.6463","0.0498","0.1843"
"4.0800","0.9900","0.9900","0.6600","0.0832","0.3077"
"4.1600","1.0091","1.0091","0.6728","0.1176","0.4350"
"4.2400","1.0305","1.0305","0.6870","0.1544","0.5714"
"4.3200","1.0505","1.0505","0.7003","0.1905","0.7049"
"4.4000","1.0704","1.0704","0.7136","0.2220","0.8213"
"4.4800","1.0897","1.0897","0.7265","0.2595","0.9602"
"4.5600","1.1095","1.1095","0.7397","0.2908","1.0759"
"4.6400","1.1297","1.1297","0.7531","0.3240","1.1990"
"4.7200","1.1497","1.1497","0.7665","0.3583","1.3258"
"4.8000","1.1681","1.1681","0.7787","0.3923","1.4516"
"4.8800","1.1891","1.1891","0.7928","0.4224","1.5627"
"4.9600","1.2098","1.2098","0.8065","0.4578","1.6938"
"5.0400","1.2314","1.2314","0.8209","0.4929","1.8236"
"5.1200","1.2499","1.2499","0.8333","0.5280","1.9536"
"5.2000","1.2686","1.2686","0.8457","0.5604","2.0736"
"5.2800","1.2895","1.2895","0.8597","0.5983","2.2137"
"5.3600","1.3102","1.3102","0.8735","0.6337","2.3445"
"5.4400","1.3305","1.3305","0.8870","0.6693","2.4764"
"5.5200","1.3511","1.3511","0.9008","0.7060","2.6123"
"5.6000","1.3699","1.3699","0.9133","0.7368","2.7263"
"5.6800","1.3902","1.3902","0.9268","0.7728","2.8595"
"5.7600","1.4102","1.4102","0.9402","0.8084","2.9913"
"5.8400","1.4292","1.4292","0.9528","0.8387","3.1030"
"5.9200","1.4496","1.4496","0.9664","0.8777","3.2475"
"6.0000","1.4685","1.4685","0.9790","0.9092","3.3641"
"6.0800","1.4897","1.4897","0.9931","0.9484","3.5091"
"6.1600","1.5106","1.5106","1.0071","0.9843","3.6418"
"6.2400","1.5301","1.5301","1.0201","1.0195","3.7721"
"6.3200","1.5495","1.5495","1.0330","1.0496","3.8834"
"6.4000","1.5696","1.5696","1.0464","1.0865","4.0200"
"6.4800","1.5890","1.5890","1.0593","1.1210","4.1478"
"6.5600","1.6099","1.6099","1.0733","1.1604","4.2937"
"6.6400","1.6291","1.6291","1.0861","1.1949","4.4211"
"6.7200","1.6505","1.6505","1.1004","1.2292","4.5480"
"6.8000","1.6706","1.6706","1.1138","1.2680","4.6915"
"6.8800","1.6904","1.6904","1.1269","1.3001","4.8102"
"6.9600","1.7102","1.7102","1.1401","1.3361","4.9436"
"7.0400","1.7297","1.7297","1.1531","1.3697","5.0679"
"7.1200","1.7497","1.7497","1.1665","1.4056","5.2006"
"7.2000","1.7695","1.7695","1.1796","1.4421","5.3358"
"7.2800","1.7882","1.7882","1.1921","1.4781","5.4690"
"7.3600","1.8099","1.8099","1.2066","1.5177","5.6155"
"7.4400","1.8302","1.8302","1.2202","1.5496","5.7334"
"7.5200","1.8499","1.8499","1.2333","1.5846","5.8632"
"7.6000","1.8698","1.8698","1.2465","1.6224","6.0028"
"7.6800","1.8891","1.8891","1.2594","1.6567","6.1300"
"7.7600","1.9103","1.9103","1.2735","1.6947","6.2702"
"7.8400","1.9303","1.9303","1.2868","1.7334","6.4135"
"7.9200","1.9494","1.9494","1.2996","1.7677","6.5405"
"8.0000","1.9702","1.9702","1.3135","1.8081","6.6900"
"8.0800","1.9906","1.9906","1.3271","1.8377","6.7996"
"8.1600","2.0102","2.0102","1.3401","1.8726","6.9286"
"8.2400","2.0304","2.0304","1.3536","1.9111","7.0711"
"8.3200","2.0488","2.0488","1.3658","1.9428","7.1882"
"8.4000","2.0699","2.0699","1.3799","1.9843","7.3420"
"8.4800","2.0894","2.0894","1.3930","2.0183","7.4677"
"8.5600","2.1089","2.1089","1.4060","2.0523","7.5936"
"8.6400","2.1294","2.1294","1.4196","2.0936","7.7463"
"8.7200","2.1504","2.1504","1.4336","2.1251","7.8628"
"8.8000","2.1702","2.1702","1.4468","2.1603","7.9932"
"8.8800","2.1903","2.1903","1.4602","2.1984","8.1342"
"8.9600","2.2090","2.2090","1.4727","2.2340","8.2657"
"9.0400","2.2300","2.2300","1.4867","2.2749","8.4172"
"9.1200","2.2492","2.2492","1.4994","2.3081","8.5399"
"9.2000","2.2697","2.2697","1.5131","2.3450","8.6764"
"9.2800","2.2908","2.2908","1.5272","2.3828","8.8165"
"9.3600","2.3102","2.3102","1.5401","2.4148","8.9346"
"9.4400","2.3302","2.3302","1.5534","2.4535","9.0781"
"9.5200","2.3501","2.3501","1.5667","2.4906","9.2152"
"9.6000","2.3691","2.3691","1.5794","2.5277","9.3523"
"9.6800","2.3895","2.3895","1.5930","2.5675","9.4998"
"9.7600","2.4091","2.4091","1.6060","2.6026","9.6296"
"9.8400","2.4298","2.4298","1.6199","2.6429","9.7786"
"9.9200","2.4507","2.4507","1.6338","2.6805","9.9179"
"10.0000","2.4693","2.4693","1.6462","2.7204","10.0656"
"10.0800","2.4897","2.4897","1.6598","2.7494","10.1729"
"10.1600","2.5093","2.5093","1.6729","2.7882","10.3164"
"10.2400","2.5304","2.5304","1.6869","2.8272","10.4608"
"10.3200","2.5499","2.5499","1.6999","2.8618","10.5888"
"10.4000","2.5690","2.5690","1.7126","2.8987","10.7251"
"10.4800","2.5901","2.5901","1.7267","2.9390","10.8742"
"10.5600","2.6114","2.6114","1.7409","2.9770","11.0149"
"10.6400","2.6299","2.6299","1.7533","3.0124","11.1458"
"10.7200","2.6502","2.6502","1.7668","3.0522","11.2931"
"10.8000","2.6689","2.6689","1.7793","3.0825","11.4051"
"10.8800","2.6897","2.6897","1.7932","3.1181","11.5369"
"10.9600","2.7096","2.7096","1.8064","3.1594","11.6897"
"11.0400","2.7294","2.7294","1.8196","3.1993","11.8375"
"11.1200","2.7496","2.7496","1.8330","3.2377","11.9795"
"11.2000","2.7704","2.7704","1.8469","3.2772","12.1255"
"11.2800","2.7903","2.7903","1.8602","3.3113","12.2516"
"11.3600","2.8105","2.8105","1.8736","3.3510","12.3986"
"11.4400","2.8291","2.8291","1.8861","3.3825","12.5152"
"11.5200","2.8497","2.8497","1.8998","3.4227","12.6640"
"11.6000","2.8700","2.8700","1.9133","3.4546","12.7820"
"11.6800","2.8896","2.8896","1.9264","3.4944","12.9291"
"11.7600","2.9108","2.9108","1.9405","3.5366","13.0854"
"11.8400","2.9307","2.9307","1.9538","3.5724","13.2178"
"11.9200","2.9503","2.9503","1.9669","3.6066","13.3443"
"12.0000","2.9700","2.9700","1.9800","3.6445","13.4847"
"12.0800","2.9889","2.9889","1.9926","3.6803","13.6170"
"12.1600","3.0094","3.0094","2.0063","3.7181","13.7570"
"12.2400","3.0294","3.0294","2.0196","3.7580","13.9047"
"12.3200","3.0490","3.0490","2.0326","3.7917","14.0293"
"12.4000","3.0701","3.0701","2.0467","3.8288","14.1664"
"12.4800","3.0892","3.0892","2.0595","3.8642","14.2976"
"12.5600","3.1104","3.1104","2.0736","3.9041","14.4453"
"12.6400","3.1302","3.1302","2.0868","3.9448","14.5959"
"12.7200","3.1495","3.1495","2.0997","3.9803","14.7273"
"12.8000","3.1687","3.1687","2.1125","4.0195","14.8721"
"12.8800","3.1893","3.1893","2.1262","4.0548","15.0028"
"12.9600","3.2102","3.2102","2.1401","4.0924","15.1418"
"13.0400","3.2313","3.2313","2.1542","4.1297","15.2799"
"13.1200","3.2499","3.2499","2.1666","4.1664","15.4157"
"13.2000","3.2696","3.2696","2.1798","4.2033","15.5523"
"13.2800","3.2894","3.2894","2.1930","4.2393","15.6854"
"13.3600","3.3096","3.3096","2.2064","4.2799","15.8357"
"13.4400","3.3300","3.3300","2.2200","4.3156","15.9678"
"13.5200","3.3487","3.3487","2.2325","4.3512","16.0996"
"13.6000","3.3695","3.3695","2.2463","4.3905","16.2447"
"13.6800","3.3903","3.3903","2.2602","4.4279","16.3831"
"13.7600","3.4100","3.4100","2.2734","4.4648","16.5197"
"13.8400","3.4300","3.4300","2.2867","4.5012","16.6545"
"13.9200","3.4493","3.4493","2.2995","4.5338","16.7750"
"14.0000","3.4695","3.4695","2.3130","4.5687","16.9041"
"14.0800","3.4900","3.4900","2.3266","4.6087","17.0523"
"14.1600","3.5090","3.5090","2.3394","4.6473","17.1950"
"14.2400","3.5305","3.5305","2.3537","4.6865","17.3401"
"14.3200","3.5503","3.5503","2.3668","4.7241","17.4793"
"14.4000","3.5703","3.5703","2.3802","4.7591","17.6088"
"14.4800","3.5900","3.5900","2.3933","4.7984","17.7539"
"14.5600","3.6098","3.6098","2.4065","4.8344","17.8872"
"14.6400","3.6299","3.6299","2.4200","4.8729","18.0298"
"14.7200","3.6496","3.6496","2.4331","4.9086","18.1617"
"14.8000","3.6683","3.6683","2.4455","4.9463","18.3013"
"14.8800","3.6899","3.6899","2.4599","4.9895","18.4612"
"14.9600","3.7101","3.7101","2.4734","5.0237","18.5879"
"15.0400","3.7309","3.7309","2.4873","5.0583","18.7155"
"15.1200","3.7502","3.7502","2.5001","5.0952","18.8524"
"15.2000","3.7685","3.7685","2.5124","5.1295","18.9793"
"15.2800","3.7893","3.7893","2.5262","5.1700","19.1289"
"15.3600","3.8099","3.8099","2.5400","5.2108","19.2801"
"15.4400","3.8301","3.8301","2.5534","5.2483","19.4188"
"15.5200","3.8509","3.8509","2.5672","5.2891","19.5696"
"15.6000","3.8702","3.8702","2.5802","5.3266","19.7083"
"15.6800","3.8904","3.8904","2.5936","5.3614","19.8371"
"15.7600","3.9100","3.9100","2.6066","5.3973","19.9701"
"15.8400","3.9289","3.9289","2.6193","5.4346","20.1079"
"15.9200","3.9495","3.9495","2.6330","5.4737","20.2529"
"16.0000","3.9685","3.9685","2.6457","5.5104","20.3884"
"16.0800","3.9893","3.9893","2.6595","5.5482","20.5285"
"16.1600","4.0105","4.0105","2.6737","5.5867","20.6707"
"16.2400","4.0301","4.0301","2.6868","5.6268","20.8191"
"16.3200","4.0500","4.0500","2.7000","5.6635","20.9551"
"16.4000","4.0696","4.0696","2.7131","5.6972","21.0797"
"16.4800","4.0887","4.0887","2.7258","5.7336","21.2142"
"16.5600","4.1099","4.1099","2.7399","5.7738","21.3632"
"16.6400","4.1290","4.1290","2.7527","5.8093","21.4944"
"16.7200","4.1503","4.1503","2.7669","5.8458","21.6295"
"16.8000","4.1709","4.1709","2.7806","5.8883","21.7868"
"16.8800","4.1900","4.1900","2.7933","5.9268","21.9290"
"16.9600","4.2099","4.2099","2.8066","5.9666","22.0763"
"17.0400","4.2296","4.2296","2.8198","6.0016","22.2060"
"17.1200","4.2495","4.2495","2.8330","6.0399","22.3476"
"17.2000","4.2695","4.2695","2.8464","6.0758","22.4806"
"17.2800","4.2883","4.2883","2.8589","6.1123","22.6156"
"17.3600","4.3098","4.3098","2.8732","6.1535","22.7681"
"17.4400","4.3309","4.3309","2.8872","6.1942","22.9184"
"17.5200","4.3500","4.3500","2.9000","6.2305","23.0527"
"17.6000","4.3698","4.3698","2.9132","6.2687","23.1943"
"17.6800","4.3888","4.3888","2.9259","6.3024","23.3190"
"17.7600","4.4101","4.4101","2.9401","6.3431","23.4694"
"17.8400","4.4301","4.4301","2.9534","6.3814","23.6113"
"17.9200","4.4491","4.4491","2.9661","6.4190","23.7502"
"18.0000","4.4697","4.4697","2.9798","6.4569","23.8906"
"18.0800","4.4904","4.4904","2.9936","6.4964","24.0367"
"18.1600","4.5107","4.5107","3.0072","6.5313","24.1658"
"18.2400","4.5303","4.5303","3.0202","6.5660","24.2940"
"18.3200","4.5489","4.5489","3.0326","6.6028","24.4304"
"18.4000","4.5696","4.5696","3.0464","6.6419","24.5751"
"18.4800","4.5890","4.5890","3.0594","6.6773","24.7061"
"18.5600","4.6091","4.6091","3.0727","6.7168","24.8523"
"18.6400","4.6302","4.6302","3.0868","6.7571","25.0013"
"18.7200","4.6500","4.6500","3.1000","6.7946","25.1399"
"18.8000","4.6700","4.6700","3.1133","6.8325","25.2801"
"18.8800","4.6903","4.6903","3.1269","6.8696","25.4177"
"18.9600","4.7089","4.7089","3.1393","6.9065","25.5541"
"19.0400","4.7298","4.7298","3.1532","6.9468","25.7033"
"19.1200","4.7492","4.7492","3.1661","6.9827","25.8359"
"19.2000","4.7699","4.7699","3.1799","7.0238","25.9880"
"19.2800","4.7907","4.7907","3.1938","7.0618","26.1288"
"19.3600","4.8104","4.8104","3.2069","7.0994","26.2677"
"19.4400","4.8303","4.8303","3.2202","7.1361","26.4035"
"19.5200","4.8499","4.8499","3.2333","7.1747","26.5465"
"19.6000","4.8692","4.8692","3.2461","7.2095","26.6751"
"19.6800","4.8895","4.8895","3.2597","7.2506","26.8272"
"19.7600","4.9085","4.9085","3.2724","7.2848","26.9539"
"19.8400","4.9295","4.9295","3.2863","7.3264","27.1078"
"19.9200","4.9507","4.9507","3.3005","7.3646","27.2490"
"20.0000","4.9697","4.9697","3.3131","7.4049","27.3980"
"20.0800","4.9901","4.9901","3.3267","7.4441","27.5431"
"20.1600","5.0095","5.0095","3.3397","7.4808","27.6791"
"20.2400","5.0299","5.0299","3.3533","7.5148","27.8049"
"20.3200","5.0500","5.0500","3.3667","7.5537","27.9488"
"20.4000","5.0694","5.0694","3.3796","7.5891","28.0798"
"20.4800","5.0898","5.0898","3.3932","7.6271","28.2204"
"20.5600","5.1108","5.1108","3.4072","7.6659","28.3637"
"20.6400","5.1300","5.1300","3.4200","7.7076","28.5182"
"20.7200","5.1503","5.1503","3.4335","7.7433","28.6503"
"20.8000","5.1689","5.1689","3.4459","7.7777","28.7774"
"20.8800","5.1895","5.1895","3.4597","7.8159","28.9188"
"20.9600","5.2095","5.2095","3.4730","7.8516","29.0508"
"21.0400","5.2287","5.2287","3.4858","7.8905","29.1948"
"21.1200","5.2498","5.2498","3.4998","7.9293","29.3385"
"21.2000","5.2704","5.2704","3.5136","7.9681","29.4819"
"21.2800","5.2901","5.2901","3.5267","8.0081","29.6301"
"21.3600","5.3105","5.3105","3.5403","8.0464","29.7718"
"21.4400","5.3293","5.3293","3.5528","8.0799","29.8955"
"21.5200","5.3499","5.3499","3.5666","8.1197","30.0428"
"21.6000","5.3697","5.3697","3.5798","8.1580","30.1848"
"21.6800","5.3894","5.3894","3.5929","8.1959","30.3249"
"21.7600","5.4108","5.4108","3.6072","8.2371","30.4773"
"21.8400","5.4301","5.4301","3.6201","8.2724","30.6080"
"21.9200","5.4503","5.4503","3.6336","8.3088","30.7426"
"22.0000","5.4702","5.4702","3.6468","8.3459","30.8797"
"22.0800","5.4891","5.4891","3.6594","8.3854","31.0260"
"22.1600","5.5100","5.5100","3.6733","8.4256","31.1748"
"22.2400","5.5296","5.5296","3.6864","8.4611","31.3061"
"22.3200","5.5490","5.5490","3.6994","8.4982","31.4434"
"22.4000","5.5700","5.5700","3.7133","8.5381","31.5910"
"22.4800","5.5897","5.5897","3.7265","8.5743","31.7251"
"22.5600","5.6107","5.6107","3.7404","8.6135","31.8701"
"22.6400","5.6302","5.6302","3.7535","8.6484","31.9992"
"22.7200","5.6494","5.6494","3.7663","8.6874","32.1434"
"22.8000","5.6692","5.6692","3.7795","8.7235","32.2771"
"22.8800","5.6891","5.6891","3.7927","8.7603","32.4130"
"22.9600","5.7103","5.7103","3.8069","8.8002","32.5608"
"23.0400","5.7316","5.7316","3.8210","8.8391","32.7045"
"23.1200","5.7499","5.7499","3.8333","8.8758","32.8405"
"23.2000","5.7699","5.7699","3.8466","8.9142","32.9824"
"23.2800","5.7890","5.7890","3.8593","8.9497","33.1137"
"23.3600","5.8089","5.8089","3.8726","8.9866","33.2503"
"23.4400","5.8301","5.8301","3.8867","9.0263","33.3971"
"23.5200","5.8486","5.8486","3.8991","9.0625","33.5311"
"23.6000","5.8697","5.8697","3.9131","9.1014","33.6750"
"23.6800","5.8902","5.8902","3.9268","9.1419","33.8250"
"23.7600","5.9101","5.9101","3.9401","9.1788","33.9617"
"23.8400","5.9303","5.9303","3.9535","9.2179","34.1062"
"23.9200","5.9493","5.9493","3.9662","9.2500","34.2248"
"24.0000","5.9694","5.9694","3.9796","9.2897","34.3720"
"24.0800","5.9902","5.9902","3.9935","9.3285","34.5153"
"24.1600","6.0093","6.0093","4.0062","9.3676","34.6603"
"24.2400","6.0306","6.0306","4.0204","9.4072","34.8067"
"24.3200","6.0504","6.0504","4.0336","9.4459","34.9497"
"24.4000","6.0703","6.0703","4.0469","9.4811","35.0802"
"24.4800","6.0896","6.0896","4.0598","9.5208","35.2270"
"24.5600","6.1098","6.1098","4.0732","9.5571","35.3612"
"24.6400","6.1300","6.1300","4.0867","9.5949","35.5010"
"24.7200","6.1498","6.1498","4.0999","9.6340","35.6460"
"24.8000","6.1682","6.1682","4.1121","9.6677","35.7705"
"24.8800","6.1897","6.1897","4.1265","9.7114","35.9323"
"24.9600","6.2100","6.2100","4.1400","9.7491","36.0716"
"25.0400","6.2308","6.2308","4.1539","9.7883","36.2168"
"25.1200","6.2501","6.2501","4.1667","9.8225","36.3433"
"25.2000","6.2686","6.2686","4.1790","9.8597","36.4808"
"25.2800","6.2893","6.2893","4.1929","9.8958","36.6143"
"25.3600","6.3100","6.3100","4.2067","9.9356","36.7616"
"25.4400","6.3302","6.3302","4.2201","9.9737","36.9026"
"25.5200","6.3507","6.3507","4.2338","10.0126","37.0467"
"25.6000","6.3698","6.3698","4.2466","10.0471","37.1742"
"25.6800","6.3895","6.3895","4.2597","10.0850","37.3144"
"25.7600","6.4104","6.4104","4.2736","10.1235","37.4570"
"25.8400","6.4297","6.4297","4.2865","10.1643","37.6081"
"25.9200","6.4496","6.4496","4.2998","10.2012","37.7446"
"26.0000","6.4686","6.4686","4.3124","10.2378","37.8797"
"26.0800","6.4895","6.4895","4.3263","10.2744","38.0152"
"26.1600","6.5106","6.5106","4.3404","10.3135","38.1600"
"26.2400","6.5302","6.5302","4.3534","10.3543","38.3107"
"26.3200","6.5499","6.5499","4.3666","10.3906","38.4451"
"26.4000","6.5696","6.5696","4.3797","10.4254","38.5741"
"26.4800","6.5888","6.5888","4.3926","10.4621","38.7098"
"26.5600","6.6101","6.6101","4.4068","10.5042","38.8656"
"26.6400","6.6290","6.6290","4.4193","10.5410","39.0016"
"26.7200","6.6503","6.6503","4.4336","10.5818","39.1528"
"26.8000","6.6705","6.6705","4.4470","10.6182","39.2874"
"26.8800","6.6902","6.6902","4.4601","10.6583","39.4358"
"26.9600","6.7101","6.7101","4.4734","10.6945","39.5697"
"27.0400","6.7298","6.7298","4.4865","10.7315","39.7064"
"27.1200","6.7496","6.7496","4.4998","10.7695","39.8471"
"27.2000","6.7698","6.7698","4.5132","10.8079","39.9891"
"27.2800","6.7886","6.7886","4.5257","10.8428","40.1184"
"27.3600","6.8097","6.8097","4.5398","10.8832","40.2680"
"27.4400","6.8305","6.8305","4.5537","10.9225","40.4134"
"27.5200","6.8502","6.8502","4.5668","10.9593","40.5493"
"27.6000","6.8698","6.8698","4.5799","10.9984","40.6942"
"27.6800","6.8888","6.8888","4.5926","11.0323","40.8196"
"27.7600","6.9098","6.9098","4.6065","11.0717","40.9654"
"27.8400","6.9300","6.9300","4.6200","11.1088","41.1026"
"27.9200","6.9494","6.9494","4.6329","11.1465","41.2420"
"28.0000","6.9700","6.9700","4.6467","11.1862","41.3888"
"28.0800","6.9905","6.9905","4.6603","11.2244","41.5304"
"28.1600","7.0105","7.0105","4.6736","11.2620","41.6695"
"28.2400","7.0302","7.0302","4.6868","11.2973","41.8000"
"28.3200","7.0487","7.0487","4.6992","11.3332","41.9327"
"28.4000","7.0696","7.0696","4.7131","11.3710","42.0726"
"28.4800","7.0885","7.0885","4.7257","11.4056","42.2006"
"28.5600","7.1088","7.1088","4.7392","11.4473","42.3549"
"28.6400","7.1303","7.1303","4.7535","11.4890","42.5093"
"28.7200","7.1508","7.1508","4.7672","11.5267","42.6487"
"28.8000","7.1706","7.1706","4.7804","11.5667","42.7968"
"28.8800","7.1905","7.1905","4.7937","11.6025","42.9293"
"28.9600","7.2093","7.2093","4.8062","11.6397","43.0668"
"29.0400","7.2299","7.2299","4.8199","11.6795","43.2140"
"29.1200","7.2493","7.2493","4.8329","11.7161","43.3494"
"29.2000","7.2697","7.2697","4.8465","11.7520","43.4824"
"29.2800","7.2908","7.2908","4.8605","11.7907","43.6257"
"29.3600","7.3103","7.3103","4.8736","11.8319","43.7780"
"29.4400","7.3303","7.3303","4.8868","11.8691","43.9155"
"29.5200","7.3498","7.3498","4.8999","11.9030","44.0411"
"29.6000","7.3692","7.3692","4.9128","11.9422","44.1862"
"29.6800","7.3896","7.3896","4.9264","11.9827","44.3358"
"29.7600","7.4086","7.4086","4.9391","12.0155","44.4572"
"29.8400","7.4296","7.4296","4.9531","12.0564","44.6087"
"29.9200","7.4505","7.4505","4.9670","12.0960","44.7553"
"30.0000","7.4695","7.4695","4.9796","12.1320","44.8882"
"30.0800","7.4901","7.4901","4.9934","12.1709","45.0322"
"30.1600","7.5096","7.5096","5.0064","12.2104","45.1783"
"30.2400","7.5298","7.5298","5.0199","12.2476","45.3160"
"30.3200","7.5498","7.5498","5.0332","12.2823","45.4444"
"30.4000","7.5691","7.5691","5.0461","12.3221","45.5919"
"30.4800","7.5900","7.5900","5.0600","12.3626","45.7417"
"30.5600","7.6111","7.6111","5.0740","12.4014","45.8852"
"30.6400","7.6301","7.6301","5.0868","12.4374","46.0182"
"30.7200","7.6496","7.6496","5.0997","12.4734","46.1516"
"30.8000","7.6690","7.6690","5.1127","12.5084","46.2812"
"30.8800","7.6900","7.6900","5.1267","12.5475","46.4256"
"30.9600","7.7098","7.7098","5.1399","12.5828","46.5563"
"31.0400","7.7288","7.7288","5.1525","12.6250","46.7124"
"31.1200","7.7495","7.7495","5.1664","12.6633","46.8543"
"31.2000","7.7702","7.7702","5.1802","12.7040","47.0046"
"31.2800","7.7899","7.7899","5.1933","12.7418","47.1448"
"31.3600","7.8102","7.8102","5.2068","12.7744","47.2652"
"31.4400","7.8292","7.8292","5.2194","12.8124","47.4059"
"31.5200","7.8501","7.8501","5.2334","12.8549","47.5631"
"31.6000","7.8698","7.8698","5.2466","12.8912","47.6975"
"31.6800","7.8894","7.8894","5.2596","12.9304","47.8425"
"31.7600","7.9107","7.9107","5.2738","12.9722","47.9973"
"31.8400","7.9303","7.9303","5.2869","13.0061","48.1226"
"31.9200","7.9507","7.9507","5.3004","13.0449","48.2661"
"32.0000","7.9700","7.9700","5.3133","13.0815","48.4014"
"32.0800","7.9888","7.9888","5.3259","13.1176","48.5351"
"32.1600","8.0097","8.0097","5.3398","13.1568","48.6801"
"32.2400","8.0297","8.0297","5.3531","13.1938","48.8170"
"32.3200","8.0490","8.0490","5.3660","13.2311","48.9552"
"32.4000","8.0701","8.0701","5.3801","13.2706","49.1013"
"32.4800","8.0894","8.0894","5.3929","13.3085","49.2414"
"32.5600","8.1104","8.1104","5.4070","13.3472","49.3848"
"32.6400","8.1300","8.1300","5.4200","13.3836","49.5192"
"32.7200","8.1492","8.1492","5.4328","13.4223","49.6624"
"32.8000","8.1693","8.1693","5.4462","13.4609","49.8052"
"32.8800","8.1893","8.1893","5.4596","13.4977","49.9414"
"32.9600","8.2104","8.2104","5.4736","13.5380","50.0906"
"33.0400","8.2315","8.2315","5.4877","13.5758","50.2306"
"33.1200","8.2499","8.2499","5.4999","13.6129","50.3677"
"33.2000","8.2694","8.2694","5.5129","13.6483","50.4988"
"33.2800","8.2894","8.2894","5.5263","13.6869","50.6416"
"33.3600","8.3100","8.3100","5.5400","13.7278","50.7928"
"33.4400","8.3301","8.3301","5.5534","13.7636","50.9254"
"33.5200","8.3485","8.3485","5.5656","13.7973","51.0502"
"33.6000","8.3694","8.3694","5.5796","13.8365","51.1952"
"33.6800","8.3905","8.3905","5.5937","13.8784","51.3503"
"33.7600","8.4102","8.4102","5.6068","13.9144","51.4833"
"33.8400","8.4304","8.4304","5.6202","13.9551","51.6338"
"33.9200","8.4493","8.4493","5.6329","13.9905","51.7649"
"34.0000","8.4691","8.4691","5.6461","14.0264","51.8976"
"34.0800","8.4898","8.4898","5.6599","14.0652","52.0411"
"34.1600","8.5094","8.5094","5.6729","14.1045","52.1866"
"34.2400","8.5307","8.5307","5.6871","14.1465","52.3422"
"34.3200","8.5507","8.5507","5.7005","14.1854","52.4860"
"34.4000","8.5705","8.5705","5.7137","14.2213","52.6189"
"34.4800","8.5899","8.5899","5.7266","14.2565","52.7492"
"34.5600","8.6095","8.6095","5.7397","14.2932","52.8847"
"34.6400","8.6299","8.6299","5.7533","14.3324","53.0301"
"34.7200","8.6498","8.6498","5.7665","14.3701","53.1693"
"34.8000","8.6683","8.6683","5.7789","14.4060","53.3021"
"34.8800","8.6898","8.6898","5.7932","14.4471","53.4541"
"34.9600","8.7098","8.7098","5.8066","14.4881","53.6059"
"35.0400","8.7309","8.7309","5.8206","14.5236","53.7373"
"35.1200","8.7502","8.7502","5.8335","14.5587","53.8672"
"35.2000","8.7689","8.7689","5.8459","14.5964","54.0066"
"35.2800","8.7892","8.7892","5.8595","14.6346","54.1481"
"35.3600","8.8099","8.8099","5.8733","14.6742","54.2945"
"35.4400","8.8299","8.8299","5.8866","14.7111","54.4310"
"35.5200","8.8503","8.8503","5.9002","14.7541","54.5903"
"35.6000","8.8701","8.8701","5.9134","14.7890","54.7194"
"35.6800","8.8903","8.8903","5.9268","14.8258","54.8553"
"35.7600","8.9100","8.9100","5.9400","14.8644","54.9982"
"35.8400","8.9291","8.9291","5.9528","14.9026","55.1396"
"35.9200","8.9499","8.9499","5.9666","14.9413","55.2829"
"36.0000","8.9686","8.9686","5.9791","14.9779","55.4183"
"36.0800","8.9895","8.9895","5.9930","15.0136","55.5502"
"36.1600","9.0104","9.0104","6.0069","15.0531","55.6964"
"36.2400","9.0304","9.0304","6.0202","15.0944","55.8493"
"36.3200","9.0500","9.0500","6.0334","15.1306","55.9834"
"36.4000","9.0697","9.0697","6.0464","15.1719","56.1359"
"36.4800","9.0886","9.0886","6.0590","15.2066","56.2645"
"36.5600","9.1100","9.1100","6.0733","15.2459","56.4097"
"36.6400","9.1290","9.1290","6.0860","15.2780","56.5287"
"36.7200","9.1506","9.1506","6.1004","15.3220","56.6915"
"36.8000","9.1708","9.1708","6.1138","15.3606","56.8341"
"36.8800","9.1900","9.1900","6.1267","15.3972","56.9697"
"36.9600","9.2099","9.2099","6.1400","15.4347","57.1083"
"37.0400","9.2296","9.2296","6.1531","15.4707","57.2416"
"37.1200","9.2494","9.2494","6.1663","15.5109","57.3904"
"37.2000","9.2696","9.2696","6.1797","15.5461","57.5207"
"37.2800","9.2886","9.2886","6.1924","15.5823","57.6544"
"37.3600","9.3101","9.3101","6.2067","15.6269","57.8195"
"37.4400","9.3307","9.3307","6.2204","15.6646","57.9591"
"37.5200","9.3500","9.3500","6.2333","15.7008","58.0930"
"37.6000","9.3696","9.3696","6.2464","15.7364","58.2248"
"37.6800","9.3886","9.3886","6.2591","15.7733","58.3611"
"37.7600","9.4099","9.4099","6.2733","15.8150","58.5156"
"37.8400","9.4303","9.4303","6.2869","15.8553","58.6646"
"37.9200","9.4495","9.4495","6.2996","15.8901","58.7934"
"38.0000","9.4700","9.4700","6.3133","15.9301","58.9414"
"38.0800","9.4901","9.4901","6.3267","15.9661","59.0747"
"38.1600","9.5104","9.5104","6.3403","16.0035","59.2128"
"38.2400","9.5306","9.5306","6.3537","16.0406","59.3501"
"38.3200","9.5488","9.5488","6.3658","16.0787","59.4914"
"38.4000","9.5694","9.5694","6.3796","16.1184","59.6380"
"38.4800","9.5891","9.5891","6.3927","16.1549","59.7730"
"38.5600","9.6092","9.6092","6.4062","16.1961","59.9257"
"38.6400","9.6302","9.6302","6.4201","16.2374","60.0784"
"38.7200","9.6503","9.6503","6.4335","16.2723","60.2074"
"38.8000","9.6701","9.6701","6.4467","16.3086","60.3419"
"38.8800","9.6903","9.6903","6.4602","16.3468","60.4833"
"38.9600","9.7089","9.7089","6.4726","16.3855","60.6264"
"39.0400","9.7299","9.7299","6.4866","16.4249","60.7722"
"39.1200","9.7491","9.7491","6.4994","16.4622","60.9100"
"39.2000","9.7702","9.7702","6.5135","16.5000","61.0499"
"39.2800","9.7910","9.7910","6.5273","16.5436","61.2111"
"39.3600","9.8102","9.8102","6.5401","16.5790","61.3424"
"39.4400","9.8303","9.8303","6.5535","16.6187","61.4890"
"39.5200","9.8500","9.8500","6.5666","16.6544","61.6213"
"39.6000","9.8691","9.8691","6.5794","16.6905","61.7548"
"39.6800","9.8893","9.8893","6.5929","16.7307","61.9035"
"39.7600","9.9088","9.9088","6.6058","16.7654","62.0321"
"39.8400","9.9297","9.9297","6.6198","16.8043","62.1760"
"39.9200","9.9506","9.9506","6.6338","16.8450","62.3265"
"40.0000","9.9695","9.9695","6.6464","16.8838","62.4700"
"40.0800","9.9898","9.9898","6.6598","16.9224","62.6130"
"40.1600","10.0093","10.0093","6.6729","16.9597","62.7507"
"40.2400","10.0299","10.0299","6.6866","16.9975","62.8909"
"40.3200","10.0497","10.0497","6.6998","17.0376","63.0393"
"40.4000","10.0692","10.0692","6.7128","17.0751","63.1778"
"40.4800","10.0901","10.0901","6.7267","17.1130","63.3182"
"40.5600","10.1111","10.1111","6.7408","17.1546","63.4720"
"40.6400","10.1304","10.1304","6.7536","17.1904","63.6044"
"40.7200","10.1501","10.1501","6.7667","17.2287","63.7463"
"40.8000","10.1688","10.1688","6.7792","17.2664","63.8857"
"40.8800","10.1892","10.1892","6.7928","17.3029","64.0207"
"40.9600","10.2095","10.2095","6.8063","17.3417","64.1642"
"41.0400","10.2291","10.2291","6.8194","17.3798","64.3052"
"41.1200","10.2497","10.2497","6.8331","17.4208","64.4570"
"41.2000","10.2704","10.2704","6.8469","17.4600","64.6021"
"41.2800","10.2900","10.2900","6.8600","17.4962","64.7358"
"41.3600","10.3103","10.3103","6.8736","17.5354","64.8810"
"41.4400","10.3293","10.3293","6.8862","17.5713","65.0137"
"41.5200","10.3502","10.3502","6.9001","17.6124","65.1658"
"41.6000","10.3698","10.3698","6.9132","17.6490","65.3014"
"41.6800","10.3895","10.3895","6.9263","17.6891","65.4498"
"41.7600","10.4106","10.4106","6.9404","17.7292","65.5982"
"41.8400","10.4300","10.4300","6.9533","17.7671","65.7383"
"41.9200","10.4505","10.4505","6.9670","17.8019","65.8671"
"42.0000","10.4700","10.4700","6.9800","17.8405","66.0100"
"42.0800","10.4891","10.4891","6.9927","17.8767","66.1437"
"42.1600","10.5095","10.5095","7.0063","17.9184","66.2981"
"42.2400","10.5295","10.5295","7.0197","17.9549","66.4331"
"42.3200","10.5489","10.5489","7.0326","17.9927","66.5729"
"42.4000","10.5701","10.5701","7.0467","18.0317","66.7172"
"42.4800","10.5894","10.5894","7.0596","18.0720","66.8662"
"42.5600","10.6105","10.6105","7.0736","18.1088","67.0025"
"42.6400","10.6300","10.6300","7.0867","18.1457","67.1389"
"42.7200","10.6493","10.6493","7.0995","18.1827","67.2760"
"42.8000","10.6692","10.6692","7.1128","18.2229","67.4246"
"42.8800","10.6896","10.6896","7.1264","18.2594","67.5597"
"42.9600","10.7101","10.7101","7.1401","18.2997","67.7090"
"43.0400","10.7313","10.7313","7.1542","18.3384","67.8522"
"43.1200","10.7499","10.7499","7.1666","18.3797","68.0048"
"43.2000","10.7699","10.7699","7.1800","18.4163","68.1402"
"43.2800","10.7893","10.7893","7.1929","18.4520","68.2724"
"43.3600","10.8097","10.8097","7.2065","18.4900","68.4130"
"43.4400","10.8302","10.8302","7.2202","18.5302","68.5618"
"43.5200","10.8487","10.8487","7.2325","18.5630","68.6830"
"43.6000","10.8693","10.8693","7.2462","18.6002","68.8206"
"43.6800","10.8900","10.8900","7.2600","18.6426","68.9777"
"43.7600","10.9096","10.9096","7.2731","18.6835","69.1291"
"43.8400","10.9307","10.9307","7.2872","18.7235","69.2770"
"43.9200","10.9497","10.9497","7.2998","18.7574","69.4025"
"44.0000","10.9693","10.9693","7.3129","18.7925","69.5324"
"44.0800","10.9900","10.9900","7.3267","18.8293","69.6684"
"44.1600","11.0091","11.0091","7.3394","18.8688","69.8145"
"44.2400","11.0306","11.0306","7.3537","18.9123","69.9756"
"44.3200","11.0504","11.0504","7.3669","18.9468","70.1031"
"44.4000","11.0702","11.0702","7.3801","18.9865","70.2500"
"44.4800","11.0901","11.0901","7.3934","19.0259","70.3958"
"44.5600","11.1095","11.1095","7.4063","19.0654","70.5420"
"44.6400","11.1297","11.1297","7.4198","19.1010","70.6736"
"44.7200","11.1495","11.1495","7.4330","19.1400","70.8180"
"44.8000","11.1683","11.1683","7.4455","19.1750","70.9475"
"44.8800","11.1897","11.1897","7.4598","19.2167","71.1017"
"44.9600","11.2101","11.2101","7.4734","19.2560","71.2470"
"45.0400","11.2310","11.2310","7.4873","19.2962","71.3960"
"45.1200","11.2500","11.2500","7.5000","19.3285","71.5156"
"45.2000","11.2684","11.2684","7.5122","19.3669","71.6575"
"45.2800","11.2894","11.2894","7.5262","19.4084","71.8111"
"45.3600","11.3095","11.3095","7.5397","19.4450","71.9466"
"45.4400","11.3296","11.3296","7.5531","19.4882","72.1065"
"45.5200","11.3509","11.3509","7.5673","19.5285","72.2553"
"45.6000","11.3699","11.3699","7.5799","19.5647","72.3893"
"45.6800","11.3904","11.3904","7.5936","19.6004","72.5215"
"45.7600","11.4104","11.4104","7.6069","19.6355","72.6513"
"45.8400","11.4292","11.4292","7.6195","19.6771","72.8052"
"45.9200","11.4496","11.4496","7.6331","19.7153","72.9465"
"46.0000","11.4680","11.4680","7.6453","19.7482","73.0682"
"46.0800","11.4893","11.4893","7.6596","19.7903","73.2242"
"46.1600","11.5109","11.5109","7.6739","19.8334","73.3835"
"46.2400","11.5304","11.5304","7.6869","19.8705","73.5209"
"46.3200","11.5501","11.5501","7.7000","19.9075","73.6576"
"46.4000","11.5698","11.5698","7.7132","19.9423","73.7865"
"46.4800","11.5890","11.5890","7.7260","19.9808","73.9290"
"46.5600","11.6103","11.6103","7.7402","20.0217","74.0803"
"46.6400","11.6292","11.6292","7.7528","20.0565","74.2091"
"46.7200","11.6505","11.6505","7.7670","20.0959","74.3547"
"46.8000","11.6705","11.6705","7.7803","20.1354","74.5011"
"46.8800","11.6903","11.6903","7.7935","20.1760","74.6512"
"46.9600","11.7101","11.7101","7.8067","20.2128","74.7872"
"47.0400","11.7296","11.7296","7.8198","20.2515","74.9307"
"47.1200","11.7493","11.7493","7.8329","20.2869","75.0617"
"47.2000","11.7699","11.7699","7.8466","20.3251","75.2029"
"47.2800","11.7882","11.7882","7.8588","20.3640","75.3468"
"47.3600","11.8099","11.8099","7.8733","20.4063","75.5032"
"47.4400","11.8307","11.8307","7.8871","20.4467","75.6528"
"47.5200","11.8504","11.8504","7.9003","20.4839","75.7906"
"47.6000","11.8698","11.8698","7.9132","20.5208","75.9269"
"47.6800","11.8887","11.8887","7.9258","20.5556","76.0557"
"47.7600","11.9099","11.9099","7.9400","20.5955","76.2033"
"47.8400","11.9303","11.9303","7.9535","20.6334","76.3435"
"47.9200","11.9495","11.9495","7.9663","20.6727","76.4891"
"48.0000","11.9698","11.9698","7.9799","20.7138","76.6410"
"48.0800","11.9901","11.9901","7.9934","20.7502","76.7758"
"48.1600","12.0104","12.0104","8.0069","20.7894","76.9208"
"48.2400","12.0309","12.0309","8.0206","20.8303","77.0719"
"48.3200","12.0489","12.0489","8.0326","20.8660","77.2041"
"48.4000","12.0696","12.0696","8.0464","20.9044","77.3462"
"48.4800","12.0888","12.0888","8.0592","20.9401","77.4785"
"48.5600","12.1088","12.1088","8.0725","20.9791","77.6226"
"48.6400","12.1301","12.1301","8.0867","21.0213","77.7786"
"48.7200","12.1505","12.1505","8.1003","21.0580","77.9145"
"48.8000","12.1702","12.1702","8.1135","21.0981","78.0629"
"48.8800","12.1904","12.1904","8.1269","21.1337","78.1946"
"48.9600","12.2091","12.2091","8.1394","21.1725","78.3382"
"49.0400","12.2299","12.2299","8.1533","21.2146","78.4939"
"49.1200","12.2489","12.2489","8.1660","21.2515","78.6306"
"49.2000","12.2697","12.2697","8.1798","21.2900","78.7729"
"49.2800","12.2909","12.2909","8.1940","21.3311","78.9249"
"49.3600","12.3103","12.3103","8.2069","21.3667","79.0568"
"49.4400","12.3303","12.3303","8.2202","21.4053","79.1998"
"49.5200","12.3500","12.3500","8.2333","21.4436","79.3415"
"49.6000","12.3692","12.3692","8.2461","21.4786","79.4707"
"49.6800","12.3893","12.3893","8.2595","21.5204","79.6255"
"49.7600","12.4088","12.4088","8.2726","21.5549","79.7531"
"49.8400","12.4295","12.4295","8.2863","21.5944","79.8992"
"49.9200","12.4505","12.4505","8.3003","21.6338","80.0451"
"50.0000","12.4694","12.4694","8.3129","21.6740","80.1937"
"50.0800","12.4900","12.4900","8.3266","21.7127","80.3368"
"50.1600","12.5094","12.5094","8.3396","21.7512","80.4796"
"50.2400","12.5300","12.5300","8.3533","21.7883","80.6169"
"50.3200","12.5499","12.5499","8.3666","21.8284","80.7650"
"50.4000","12.5690","12.5690","8.3794","21.8625","80.8912"
"50.4800","12.5899","12.5899","8.3933","21.9050","81.0485"
"50.5600","12.6112","12.6112","8.4075","21.9487","81.2103"
"50.6400","12.6304","12.6304","8.4203","21.9840","81.3408"
"50.7200","12.6502","12.6502","8.4335","22.0215","81.4795"
"50.8000","12.6690","12.6690","8.4460","22.0578","81.6139"
"50.8800","12.6898","12.6898","8.4598","22.0946","81.7501"
"50.9600","12.7097","12.7097","8.4731","22.1346","81.8982"
"51.0400","12.7289","12.7289","8.4859","22.1718","82.0355"
"51.1200","12.7494","12.7494","8.4996","22.2146","82.1939"
"51.2000","12.7703","12.7703","8.5136","22.2531","82.3364"
"51.2800","12.7902","12.7902","8.5268","22.2921","82.4807"
"51.3600","12.8105","12.8105","8.5403","22.3288","82.6167"
"51.4400","12.8290","12.8290","8.5527","22.3654","82.7518"
"51.5200","12.8497","12.8497","8.5665","22.4039","82.8946"
"51.6000","12.8697","12.8697","8.5798","22.4427","83.0380"
"51.6800","12.8892","12.8892","8.5928","22.4818","83.1827"
"51.7600","12.9111","12.9111","8.6074","22.5267","83.3490"
"51.8400","12.9306","12.9306","8.6204","22.5642","83.4874"
"51.9200","12.9504","12.9504","8.6336","22.5984","83.6141"
"52.0000","12.9698","12.9698","8.6465","22.6372","83.7578"
"52.0800","12.9893","12.9893","8.6595","22.6755","83.8992"
"52.1600","13.0098","13.0098","8.6732","22.7150","84.0456"
"52.2400","13.0294","13.0294","8.6862","22.7501","84.1752"
"52.3200","13.0489","13.0489","8.6992","22.7892","84.3202"
"52.4000","13.0701","13.0701","8.7134","22.8303","84.4721"
"52.4800","13.0894","13.0894","8.7262","22.8658","84.6033"
"52.5600","13.1106","13.1106","8.7404","22.9050","84.7485"
"52.6400","13.1300","13.1300","8.7533","22.9455","84.8984"
"52.7200","13.1495","13.1495","8.7663","22.9823","85.0343"
"52.8000","13.1692","13.1692","8.7794","23.0200","85.1741"
"52.8800","13.1892","13.1892","8.7928","23.0584","85.3162"
"52.9600","13.2101","13.2101","8.8068","23.0994","85.4679"
"53.0400","13.2316","13.2316","8.8210","23.1379","85.6102"
"53.1200","13.2497","13.2497","8.8331","23.1749","85.7471"
"53.2000","13.2699","13.2699","8.8466","23.2125","85.8861"
"53.2800","13.2895","13.2895","8.8596","23.2516","86.0311"
"53.3600","13.3098","13.3098","8.8732","23.2903","86.1742"
"53.4400","13.3298","13.3298","8.8866","23.3282","86.3144"
"53.5200","13.3485","13.3485","8.8990","23.3632","86.4437"
"53.6000","13.3695","13.3695","8.9130","23.4048","86.5978"
"53.6800","13.3906","13.3906","8.9271","23.4461","86.7505"
"53.7600","13.4101","13.4101","8.9400","23.4806","86.8781"
"53.8400","13.4301","13.4301","8.9534","23.5230","87.0350"
"53.9200","13.4495","13.4495","8.9663","23.5580","87.1646"
"54.0000","13.4692","13.4692","8.9795","23.5931","87.2946"
"54.0800","13.4900","13.4900","8.9934","23.6331","87.4425"
"54.1600","13.5093","13.5093","9.0062","23.6736","87.5924"
"54.2400","13.5307","13.5307","9.0205","23.7161","87.7497"
"54.3200","13.5503","13.5503","9.0336","23.7546","87.8922"
"54.4000","13.5703","13.5703","9.0468","23.7898","88.0222"
"54.4800","13.5901","13.5901","9.0601","23.8302","88.1718"
"54.5600","13.6097","13.6097","9.0731","23.8682","88.3123"
"54.6400","13.6299","13.6299","9.0866","23.9033","88.4421"
"54.7200","13.6497","13.6497","9.0998","23.9410","88.5815"
"54.8000","13.6682","13.6682","9.1121","23.9769","88.7143"
"54.8800","13.6895","13.6895","9.1263","24.0211","88.8780"
"54.9600","13.7104","13.7104","9.1403","24.0614","89.0272"
"55.0400","13.7306","13.7306","9.1538","24.0990","89.1664"
"55.1200","13.7501","13.7501","9.1668","24.1345","89.2978"
"55.2000","13.7686","13.7686","9.1790","24.1709","89.4323"
"55.2800","13.7894","13.7894","9.1929","24.2123","89.5854"
"55.3600","13.8100","13.8100","9.2067","24.2514","89.7301"
"55.4400","13.8301","13.8301","9.2201","24.2890","89.8691"
"55.5200","13.8509","13.8509","9.2339","24.3262","90.0071"
"55.6000","13.8701","13.8701","9.2467","24.3630","90.1431"
"55.6800","13.8901","13.8901","9.2601","24.4028","90.2904"
"55.7600","13.9100","13.9100","9.2733","24.4388","90.4236"
"55.8400","13.9292","13.9292","9.2862","24.4788","90.5715"
"55.9200","13.9496","13.9496","9.2997","24.5174","90.7144"
"56.0000","13.9684","13.9684","9.3123","24.5516","90.8410"
"56.0800","13.9894","13.9894","9.3263","24.5935","90.9958"
"56.1600","14.0106","14.0106","9.3404","24.6308","91.1340"
"56.2400","14.0302","14.0302","9.3535","24.6689","91.2750"
"56.3200","14.0496","14.0496","9.3664","24.7066","91.4143"
"56.4000","14.0697","14.0697","9.3798","24.7444","91.5543"
"56.4800","14.0890","14.0890","9.3926","24.7831","91.6975"
"56.5600","14.1101","14.1101","9.4067","24.8254","91.8540"
"56.6400","14.1291","14.1291","9.4194","24.8595","91.9800"
"56.7200","14.1503","14.1503","9.4336","24.8972","92.1198"
"56.8000","14.1706","14.1706","9.4470","24.9354","92.2610"
"56.8800","14.1901","14.1901","9.4601","24.9772","92.4155"
"56.9600","14.2099","14.2099","9.4733","25.0122","92.5453"
"57.0400","14.2296","14.2296","9.4864","25.0500","92.6850"
"57.1200","14.2497","14.2497","9.4998","25.0873","92.8231"
"57.2000","14.2698","14.2698","9.5132","25.1267","92.9688"
"57.2800","14.2883","14.2883","9.5256","25.1609","93.0953"
"57.3600","14.3097","14.3097","9.5398","25.2035","93.2531"
"57.4400","14.3306","14.3306","9.5537","25.2452","93.4074"
"57.5200","14.3503","14.3503","9.5668","25.2796","93.5343"
"57.6000","14.3700","14.3700","9.5800","25.3176","93.6753"
"57.6800","14.3889","14.3889","9.5926","25.3500","93.7949"
"57.7600","14.4097","14.4097","9.6064","25.3910","93.9468"
"57.8400","14.4305","14.4305","9.6203","25.4320","94.0985"
"57.9200","14.4498","14.4498","9.6332","25.4698","94.2384"
"58.0000","14.4700","14.4700","9.6467","25.5077","94.3787"
"58.0800","14.4902","14.4902","9.6601","25.5443","94.5140"
"58.1600","14.5106","14.5106","9.6737","25.5856","94.6668"
"58.2400","14.5307","14.5307","9.6871","25.6207","94.7966"
"58.3200","14.5490","14.5490","9.6993","25.6547","94.9225"
"58.4000","14.5695","14.5695","9.7130","25.6935","95.0659"
"58.4800","14.5889","14.5889","9.7259","25.7306","95.2033"
"58.5600","14.6090","14.6090","9.7393","25.7711","95.3529"
"58.6400","14.6300","14.6300","9.7534","25.8121","95.5048"
"58.7200","14.6499","14.6499","9.7666","25.8462","95.6309"
"58.8000","14.6700","14.6700","9.7800","25.8838","95.7700"
"58.8800","14.6902","14.6902","9.7934","25.9205","95.9057"
"58.9600","14.7091","14.7091","9.8061","25.9569","96.0407"
"59.0400","14.7299","14.7299","9.8199","25.9994","96.1977"
"59.1200","14.7493","14.7493","9.8328","26.0337","96.3245"
"59.2000","14.7699","14.7699","9.8466","26.0707","96.4616"
"59.2800","14.7907","14.7907","9.8605","26.1102","96.6078"
"59.3600","14.8103","14.8103","9.8735","26.1487","96.7501"
"59.4400","14.8304","14.8304","9.8869","26.1877","96.8943"
"59.5200","14.8499","14.8499","9.8999","26.2207","97.0164"
"59.6000","14.8692","14.8692","9.9128","26.2588","97.1577"
"59.6800","14.8889","14.8889","9.9260","26.2938","97.2869"
"59.7600","14.9087","14.9087","9.9391","26.3286","97.4159"
"59.8400","14.9295","14.9295","9.9530","26.3669","97.5576"
"59.9200","14.9506","14.9506","9.9670","26.4086","97.7120"
"60.0000","14.9695","14.9695","9.9797","26.4454","97.8479"
"60.0800","14.9900","14.9900","9.9933","26.4841","97.9912"
"60.1200","15.0000","15.0000","10.0000","26.5012","98.0545"