File: data/instron_tests/539_BULK_m2.is_comp_Exports/539_BULK_m2_3_1.csv
Sample text inputs : Sample No.,Sample choice input : Leading Direction,Sample choice input : Mode,Specimen choice input : Direction,Specimen properties : Height,Specimen properties : Thickness,Specimen properties : Width,Test : Rate 1
,,,,(mm),(mm),(mm),(mm/min)
"509","Bulk","Bimode","1","150.00","25.00","150.00","15.00"

Time,Displacement,Compressive displacement,Compressive strain (Displacement),Compressive stress,Force
(s),(mm),(mm),(%),(kPa),(N)
"0.0000","-0.0001","-0.0001","-0.0001","-0.5139","-1.9013"
"0.0800","0.0012","0.0012","0.0008","-0.5068","-1.8751"
"0.1600","0.0097","0.0097","0.0065","-0.4721","-1.7468"
"0.2400","0.0297","0.0297","0.0198","-0.4069","-1.5057"
"0.3200","0.0502","0.0502","0.0335","-0.3356","-1.2419"
"0.4000","0.0682","0.0682","0.0455","-0.2770","-1.0249"
"0.4800","0.0885","0.0885","0.0590","-0.2183","-0.8078"
"0.5600","0.1101","0.1101","0.0734","-0.1561","-0.5775"
"0.6400","0.1297","0.1297","0.0865","-0.1071","-0.3962"
"0.7200","0.1497","0.1497","0.0998","-0.0557","-0.2060"
"0.8000","0.1687","0.1687","0.1124","-0.0103","-0.0380"
"0.8800","0.1894","0.1894","0.1263","0.0376","0.1391"
"0.9600","0.2095","0.2095","0.1397","0.0821","0.3036"
"1.0400","0.2286","0.2286","0.1524","0.1267","0.4688"
"1.1200","0.2493","0.2493","0.1662","0.1729","0.6397"
"1.2000","0.2698","0.2698","0.1799","0.2130","0.7880"
"1.2800","0.2898","0.2898","0.1932","0.2565","0.9489"
"1.3600","0.3100","0.3100","0.2066","0.3008","1.1129"
"1.4400","0.3287","0.3287","0.2191","0.3333","1.2333"
"1.5200","0.3495","0.3495","0.2330","0.3805","1.4078"
"1.6000","0.3697","0.3697","0.2465","0.4212","1.5583"
"1.6800","0.3888","0.3888","0.2592","0.4616","1.7080"
"1.7600","0.4101","0.4101","0.2734","0.5144","1.9034"
"1.8400","0.4306","0.4306","0.2871","0.5563","2.0584"
"1.9200","0.4507","0.4507","0.3004","0.5983","2.2139"
"2.0000","0.4699","0.4699","0.3133","0.6412","2.3724"
"2.0800","0.4886","0.4886","0.3257","0.6843","2.5320"
"2.1600","0.5097","0.5097","0.3398","0.7361","2.7236"
"2.2400","0.5294","0.5294","0.3529","0.7733","2.8613"
"2.3200","0.5488","0.5488","0.3659","0.8170","3.0230"
"2.4000","0.5696","0.5696","0.3797","0.8646","3.1990"
"2.4800","0.5892","0.5892","0.3928","0.9137","3.3807"
"2.5600","0.6103","0.6103","0.4069","0.9670","3.5780"
"2.6400","0.6297","0.6297","0.4198","1.0114","3.7422"
"2.7200","0.6492","0.6492","0.4328","1.0560","3.9074"
"2.8000","0.6691","0.6691","0.4461","1.1077","4.0986"
"2.8800","0.6890","0.6890","0.4593","1.1581","4.2851"
"2.9600","0.7099","0.7099","0.4733","1.2118","4.4838"
"3.0400","0.7312","0.7312","0.4874","1.2668","4.6873"
"3.1200","0.7496","0.7496","0.4998","1.3108","4.8499"
"3.2000","0.7698","0.7698","0.5132","1.3669","5.0574"
"3.2800","0.7893","0.7893","0.5262","1.4182","5.2473"
"3.3600","0.8093","0.8093","0.5396","1.4742","5.4544"
"3.4400","0.8298","0.8298","0.5532","1.5292","5.6580"
"3.5200","0.8484","0.8484","0.5656","1.5699","5.8085"
"3.6000","0.8690","0.8690","0.5793","1.6250","6.0124"
"3.6800","0.8900","0.8900","0.5933","1.6865","6.2399"
"3.7600","0.9100","0.9100","0.6067","1.7467","6.4629"
"3.8400","0.9300","0.9300","0.6200","1.8005","6.6617"
"3.9200","0.9492","0.9492","0.6328","1.8502","6.8459"
"4.0000","0.9691","0.9691","0.6461","1.9038","7.0439"
"4.0800","0.9897","0.9897","0.6598","1.9622","7.2601"
"4.1600","1.0089","1.0089","0.6726","2.0181","7.4671"
"4.2400","1.0301","1.0301","0.6867","2.0798","7.6954"
"4.3200","1.0504","1.0504","0.7003","2.1322","7.8893"
"4.4000","1.0704","1.0704","0.7136","2.1780","8.0584"
"4.4800","1.0895","1.0895","0.7263","2.2336","8.2644"
"4.5600","1.1092","1.1092","0.7395","2.2911","8.4770"
"4.6400","1.1296","1.1296","0.7531","2.3489","8.6909"
"4.7200","1.1496","1.1496","0.7664","2.4082","8.9102"
"4.8000","1.1680","1.1680","0.7787","2.4613","9.1067"
"4.8800","1.1895","1.1895","0.7930","2.5200","9.3239"
"4.9600","1.2101","1.2101","0.8067","2.5803","9.5472"
"5.0400","1.2309","1.2309","0.8206","2.6386","9.7627"
"5.1200","1.2493","1.2493","0.8329","2.6931","9.9646"
"5.2000","1.2680","1.2680","0.8453","2.7493","10.1723"
"5.2800","1.2892","1.2892","0.8595","2.8152","10.4164"
"5.3600","1.3099","1.3099","0.8733","2.8793","10.6536"
"5.4400","1.3299","1.3299","0.8866","2.9349","10.8592"
"5.5200","1.3509","1.3509","0.9006","3.0001","11.1003"
"5.6000","1.3698","1.3698","0.9132","3.0552","11.3041"
"5.6800","1.3902","1.3902","0.9268","3.1210","11.5477"
"5.7600","1.4097","1.4097","0.9398","3.1803","11.7670"
"5.8400","1.4288","1.4288","0.9525","3.2437","12.0018"
"5.9200","1.4496","1.4496","0.9664","3.3116","12.2528"
"6.0000","1.4682","1.4682","0.9788","3.3579","12.4242"
"6.0800","1.4891","1.4891","0.9927","3.4247","12.6716"
"6.1600","1.5104","1.5104","1.0069","3.4948","12.9307"
"6.2400","1.5299","1.5299","1.0199","3.5573","13.1620"
"6.3200","1.5495","1.5495","1.0330","3.6200","13.3939"
"6.4000","1.5695","1.5695","1.0464","3.6852","13.6351"
"6.4800","1.5887","1.5887","1.0591","3.7462","13.8608"
"6.5600","1.6100","1.6100","1.0733","3.8203","14.1351"
"6.6400","1.6291","1.6291","1.0860","3.8763","14.3425"
"6.7200","1.6504","1.6504","1.1003","3.9352","14.5602"
"6.8000","1.6704","1.6704","1.1136","3.9990","14.7962"
"6.8800","1.6899","1.6899","1.1266","4.0651","15.0408"
"6.9600","1.7097","1.7097","1.1398","4.1310","15.2848"
"7.0400","1.7295","1.7295","1.1530","4.1929","15.5138"
"7.1200","1.7495","1.7495","1.1663","4.2591","15.7586"
"7.2000","1.7694","1.7694","1.1796","4.3240","15.9988"
"7.2800","1.7880","1.7880","1.1920","4.3857","16.2270"
"7.3600","1.8098","1.8098","1.2065","4.4604","16.5035"
"7.4400","1.8306","1.8306","1.2204","4.5313","16.7656"
"7.5200","1.8498","1.8498","1.2332","4.5884","16.9772"
"7.6000","1.8696","1.8696","1.2464","4.6520","17.2125"
"7.6800","1.8884","1.8884","1.2589","4.7139","17.4415"
"7.7600","1.9098","1.9098","1.2732","4.7849","17.7043"
"7.8400","1.9302","1.9302","1.2868","4.8557","17.9661"
"7.9200","1.9494","1.9494","1.2996","4.9198","18.2033"
"8.0000","1.9697","1.9697","1.3131","4.9890","18.4593"
"8.0800","1.9903","1.9903","1.3269","5.0571","18.7111"
"8.1600","2.0101","2.0101","1.3401","5.1236","18.9574"
"8.2400","2.0303","2.0303","1.3535","5.1908","19.2060"
"8.3200","2.0485","2.0485","1.3657","5.2541","19.4403"
"8.4000","2.0698","2.0698","1.3799","5.3226","19.6935"
"8.4800","2.0890","2.0890","1.3926","5.3816","19.9119"
"8.5600","2.1084","2.1084","1.4056","5.4502","20.1657"
"8.6400","2.1298","2.1298","1.4198","5.5230","20.4351"
"8.7200","2.1502","2.1502","1.4334","5.5898","20.6823"
"8.8000","2.1699","2.1699","1.4466","5.6561","20.9275"
"8.8800","2.1901","2.1901","1.4601","5.7241","21.1791"
"8.9600","2.2088","2.2088","1.4725","5.7911","21.4270"
"9.0400","2.2297","2.2297","1.4864","5.8634","21.6948"
"9.1200","2.2490","2.2490","1.4993","5.9276","21.9321"
"9.2000","2.2695","2.2695","1.5130","5.9988","22.1954"
"9.2800","2.2906","2.2906","1.5271","6.0707","22.4616"
"9.3600","2.3099","2.3099","1.5400","6.1334","22.6937"
"9.4400","2.3301","2.3301","1.5534","6.1975","22.9309"
"9.5200","2.3498","2.3498","1.5665","6.2628","23.1725"
"9.6000","2.3690","2.3690","1.5793","6.3301","23.4215"
"9.6800","2.3893","2.3893","1.5929","6.3981","23.6731"
"9.7600","2.4088","2.4088","1.6059","6.4653","23.9216"
"9.8400","2.4292","2.4292","1.6195","6.5367","24.1857"
"9.9200","2.4503","2.4503","1.6336","6.6101","24.4575"
"10.0000","2.4691","2.4691","1.6460","6.6729","24.6896"
"10.0800","2.4895","2.4895","1.6597","6.7411","24.9420"
"10.1600","2.5094","2.5094","1.6729","6.8091","25.1935"
"10.2400","2.5299","2.5299","1.6866","6.8828","25.4665"
"10.3200","2.5494","2.5494","1.6996","6.9493","25.7123"
"10.4000","2.5689","2.5689","1.7126","7.0182","25.9672"
"10.4800","2.5897","2.5897","1.7265","7.0879","26.2251"
"10.5600","2.6110","2.6110","1.7407","7.1626","26.5016"
"10.6400","2.6301","2.6301","1.7534","7.2258","26.7354"
"10.7200","2.6498","2.6498","1.7665","7.2950","26.9915"
"10.8000","2.6688","2.6688","1.7792","7.3587","27.2273"
"10.8800","2.6895","2.6895","1.7930","7.4280","27.4836"
"10.9600","2.7095","2.7095","1.8064","7.4972","27.7396"
"11.0400","2.7291","2.7291","1.8194","7.5665","27.9959"
"11.1200","2.7494","2.7494","1.8329","7.6378","28.2598"
"11.2000","2.7700","2.7700","1.8467","7.7107","28.5295"
"11.2800","2.7899","2.7899","1.8600","7.7760","28.7711"
"11.3600","2.8103","2.8103","1.8736","7.8490","29.0412"
"11.4400","2.8291","2.8291","1.8861","7.9123","29.2756"
"11.5200","2.8496","2.8496","1.8997","7.9802","29.5266"
"11.6000","2.8696","2.8696","1.9131","8.0469","29.7736"
"11.6800","2.8891","2.8891","1.9261","8.1162","30.0300"
"11.7600","2.9106","2.9106","1.9404","8.1895","30.3012"
"11.8400","2.9300","2.9300","1.9533","8.2558","30.5466"
"11.9200","2.9501","2.9501","1.9667","8.3239","30.7984"
"12.0000","2.9701","2.9701","1.9801","8.3950","31.0617"
"12.0800","2.9888","2.9888","1.9925","8.4609","31.3052"
"12.1600","3.0093","3.0093","2.0062","8.5322","31.5690"
"12.2400","3.0292","3.0292","2.0195","8.6000","31.8199"
"12.3200","3.0489","3.0489","2.0326","8.6664","32.0657"
"12.4000","3.0698","3.0698","2.0465","8.7382","32.3313"
"12.4800","3.0890","3.0890","2.0593","8.8020","32.5676"
"12.5600","3.1102","3.1102","2.0735","8.8751","32.8378"
"12.6400","3.1301","3.1301","2.0867","8.9422","33.0862"
"12.7200","3.1491","3.1491","2.0994","9.0077","33.3284"
"12.8000","3.1688","3.1688","2.1126","9.0756","33.5798"
"12.8800","3.1889","3.1889","2.1260","9.1410","33.8217"
"12.9600","3.2095","3.2095","2.1396","9.2110","34.0808"
"13.0400","3.2310","3.2310","2.1540","9.2837","34.3496"
"13.1200","3.2495","3.2495","2.1663","9.3463","34.5814"
"13.2000","3.2695","3.2695","2.1797","9.4131","34.8286"
"13.2800","3.2889","3.2889","2.1926","9.4809","35.0793"
"13.3600","3.3093","3.3093","2.2062","9.5510","35.3387"
"13.4400","3.3297","3.3297","2.2198","9.6238","35.6081"
"13.5200","3.3489","3.3489","2.2326","9.6928","35.8634"
"13.6000","3.3693","3.3693","2.2462","9.7610","36.1157"
"13.6800","3.3900","3.3900","2.2600","9.8326","36.3805"
"13.7600","3.4103","3.4103","2.2735","9.9019","36.6370"
"13.8400","3.4299","3.4299","2.2866","9.9689","36.8849"
"13.9200","3.4492","3.4492","2.2995","10.0313","37.1158"
"14.0000","3.4690","3.4690","2.3127","10.0994","37.3678"
"14.0800","3.4898","3.4898","2.3265","10.1701","37.6293"
"14.1600","3.5091","3.5091","2.3394","10.2386","37.8828"
"14.2400","3.5306","3.5306","2.3537","10.3122","38.1550"
"14.3200","3.5503","3.5503","2.3669","10.3790","38.4024"
"14.4000","3.5702","3.5702","2.3801","10.4465","38.6522"
"14.4800","3.5895","3.5895","2.3930","10.5099","38.8866"
"14.5600","3.6091","3.6091","2.4061","10.5758","39.1303"
"14.6400","3.6294","3.6294","2.4196","10.6448","39.3856"
"14.7200","3.6494","3.6494","2.4330","10.7108","39.6298"
"14.8000","3.6680","3.6680","2.4453","10.7758","39.8704"
"14.8800","3.6896","3.6896","2.4597","10.8510","40.1489"
"14.9600","3.7099","3.7099","2.4733","10.9161","40.3896"
"15.0400","3.7306","3.7306","2.4870","10.9867","40.6506"
"15.1200","3.7498","3.7498","2.4998","11.0494","40.8830"
"15.2000","3.7680","3.7680","2.5120","11.1110","41.1109"
"15.2800","3.7888","3.7888","2.5259","11.1779","41.3584"
"15.3600","3.8100","3.8100","2.5400","11.2498","41.6244"
"15.4400","3.8301","3.8301","2.5534","11.3188","41.8797"
"15.5200","3.8506","3.8506","2.5671","11.3874","42.1334"
"15.6000","3.8700","3.8700","2.5800","11.4533","42.3771"
"15.6800","3.8898","3.8898","2.5932","11.5188","42.6195"
"15.7600","3.9098","3.9098","2.6065","11.5861","42.8687"
"15.8400","3.9288","3.9288","2.6192","11.6527","43.1150"
"15.9200","3.9494","3.9494","2.6329","11.7202","43.3649"
"16.0000","3.9683","3.9683","2.6456","11.7817","43.5921"
"16.0800","3.9893","3.9893","2.6595","11.8523","43.8536"
"16.1600","4.0104","4.0104","2.6736","11.9241","44.1193"
"16.2400","4.0301","4.0301","2.6867","11.9891","44.3595"
"16.3200","4.0498","4.0498","2.6999","12.0544","44.6013"
"16.4000","4.0694","4.0694","2.7129","12.1173","44.8341"
"16.4800","4.0887","4.0887","2.7258","12.1828","45.0764"
"16.5600","4.1097","4.1097","2.7398","12.2539","45.3394"
"16.6400","4.1289","4.1289","2.7526","12.3191","45.5806"
"16.7200","4.1502","4.1502","2.7668","12.3848","45.8238"
"16.8000","4.1706","4.1706","2.7804","12.4532","46.0767"
"16.8800","4.1898","4.1898","2.7932","12.5171","46.3132"
"16.9600","4.2095","4.2095","2.8063","12.5804","46.5475"
"17.0400","4.2293","4.2293","2.8195","12.6446","46.7850"
"17.1200","4.2495","4.2495","2.8330","12.7103","47.0280"
"17.2000","4.2694","4.2694","2.8462","12.7756","47.2698"
"17.2800","4.2880","4.2880","2.8586","12.8360","47.4932"
"17.3600","4.3093","4.3093","2.8729","12.9081","47.7599"
"17.4400","4.3304","4.3304","2.8870","12.9807","48.0286"
"17.5200","4.3498","4.3498","2.8999","13.0413","48.2528"
"17.6000","4.3694","4.3694","2.9129","13.1049","48.4881"
"17.6800","4.3887","4.3887","2.9258","13.1645","48.7088"
"17.7600","4.4098","4.4098","2.9399","13.2340","48.9657"
"17.8400","4.4299","4.4299","2.9532","13.2975","49.2006"
"17.9200","4.4489","4.4489","2.9659","13.3604","49.4334"
"18.0000","4.4693","4.4693","2.9795","13.4266","49.6785"
"18.0800","4.4903","4.4903","2.9936","13.4973","49.9400"
"18.1600","4.5104","4.5104","3.0070","13.5601","50.1722"
"18.2400","4.5305","4.5305","3.0203","13.6249","50.4123"
"18.3200","4.5490","4.5490","3.0327","13.6817","50.6222"
"18.4000","4.5692","4.5692","3.0461","13.7473","50.8650"
"18.4800","4.5888","4.5888","3.0592","13.8112","51.1016"
"18.5600","4.6091","4.6091","3.0727","13.8763","51.3421"
"18.6400","4.6299","4.6299","3.0866","13.9486","51.6098"
"18.7200","4.6499","4.6499","3.1000","14.0101","51.8373"
"18.8000","4.6699","4.6699","3.1133","14.0738","52.0730"
"18.8800","4.6901","4.6901","3.1267","14.1376","52.3091"
"18.9600","4.7088","4.7088","3.1392","14.1980","52.5326"
"19.0400","4.7295","4.7295","3.1530","14.2647","52.7794"
"19.1200","4.7490","4.7490","3.1660","14.3255","53.0044"
"19.2000","4.7696","4.7696","3.1797","14.3923","53.2516"
"19.2800","4.7905","4.7905","3.1937","14.4598","53.5012"
"19.3600","4.8099","4.8099","3.2066","14.5190","53.7204"
"19.4400","4.8299","4.8299","3.2200","14.5834","53.9584"
"19.5200","4.8498","4.8498","3.2332","14.6449","54.1860"
"19.6000","4.8689","4.8689","3.2459","14.7084","54.4209"
"19.6800","4.8891","4.8891","3.2594","14.7708","54.6520"
"19.7600","4.9085","4.9085","3.2723","14.8309","54.8745"
"19.8400","4.9293","4.9293","3.2862","14.8966","55.1176"
"19.9200","4.9503","4.9503","3.3002","14.9635","55.3651"
"20.0000","4.9696","4.9696","3.3131","15.0254","55.5942"
"20.0800","4.9898","4.9898","3.3265","15.0876","55.8241"
"20.1600","5.0096","5.0096","3.3397","15.1513","56.0598"
"20.2400","5.0298","5.0298","3.3532","15.2138","56.2912"
"20.3200","5.0493","5.0493","3.3662","15.2755","56.5194"
"20.4000","5.0687","5.0687","3.3791","15.3330","56.7319"
"20.4800","5.0896","5.0896","3.3930","15.4014","56.9852"
"20.5600","5.1106","5.1106","3.4070","15.4649","57.2202"
"20.6400","5.1300","5.1300","3.4200","15.5262","57.4470"
"20.7200","5.1503","5.1503","3.4335","15.5907","57.6854"
"20.8000","5.1689","5.1689","3.4459","15.6449","57.8863"
"20.8800","5.1893","5.1893","3.4595","15.7076","58.1181"
"20.9600","5.2093","5.2093","3.4729","15.7689","58.3449"
"21.0400","5.2286","5.2286","3.4857","15.8293","58.5684"
"21.1200","5.2495","5.2495","3.4997","15.8965","58.8172"
"21.2000","5.2703","5.2703","3.5135","15.9611","59.0562"
"21.2800","5.2899","5.2899","3.5266","16.0182","59.2675"
"21.3600","5.3102","5.3102","3.5401","16.0813","59.5008"
"21.4400","5.3293","5.3293","3.5529","16.1413","59.7229"
"21.5200","5.3498","5.3498","3.5665","16.2014","59.9452"
"21.6000","5.3695","5.3695","3.5796","16.2625","60.1712"
"21.6800","5.3892","5.3892","3.5928","16.3227","60.3939"
"21.7600","5.4104","5.4104","3.6069","16.3894","60.6406"
"21.8400","5.4301","5.4301","3.6201","16.4465","60.8521"
"21.9200","5.4504","5.4504","3.6336","16.5076","61.0780"
"22.0000","5.4701","5.4701","3.6467","16.5633","61.2843"
"22.0800","5.4888","5.4888","3.6592","16.6208","61.4970"
"22.1600","5.5094","5.5094","3.6729","16.6849","61.7343"
"22.2400","5.5294","5.5294","3.6863","16.7443","61.9539"
"22.3200","5.5488","5.5488","3.6992","16.8005","62.1620"
"22.4000","5.5698","5.5698","3.7132","16.8651","62.4007"
"22.4800","5.5893","5.5893","3.7262","16.9241","62.6192"
"22.5600","5.6103","5.6103","3.7402","16.9864","62.8497"
"22.6400","5.6301","5.6301","3.7534","17.0428","63.0583"
"22.7200","5.6489","5.6489","3.7660","17.0976","63.2612"
"22.8000","5.6685","5.6685","3.7790","17.1568","63.4801"
"22.8800","5.6892","5.6892","3.7928","17.2179","63.7063"
"22.9600","5.7102","5.7102","3.8068","17.2811","63.9401"
"23.0400","5.7316","5.7316","3.8211","17.3446","64.1750"
"23.1200","5.7498","5.7498","3.8332","17.3980","64.3725"
"23.2000","5.7691","5.7691","3.8461","17.4528","64.5754"
"23.2800","5.7891","5.7891","3.8594","17.5127","64.7970"
"23.3600","5.8094","5.8094","3.8729","17.5717","65.0153"
"23.4400","5.8298","5.8298","3.8865","17.6341","65.2463"
"23.5200","5.8484","5.8484","3.8989","17.6833","65.4281"
"23.6000","5.8693","5.8693","3.9129","17.7476","65.6662"
"23.6800","5.8901","5.8901","3.9267","17.8064","65.8839"
"23.7600","5.9098","5.9098","3.9399","17.8660","66.1041"
"23.8400","5.9303","5.9303","3.9535","17.9278","66.3330"
"23.9200","5.9492","5.9492","3.9662","17.9777","66.5173"
"24.0000","5.9692","5.9692","3.9794","18.0387","66.7432"
"24.0800","5.9899","5.9899","3.9933","18.0967","66.9576"
"24.1600","6.0089","6.0089","4.0060","18.1566","67.1795"
"24.2400","6.0302","6.0302","4.0202","18.2161","67.3997"
"24.3200","6.0502","6.0502","4.0335","18.2743","67.6148"
"24.4000","6.0700","6.0700","4.0466","18.3301","67.8214"
"24.4800","6.0895","6.0895","4.0596","18.3884","68.0371"
"24.5600","6.1096","6.1096","4.0730","18.4454","68.2481"
"24.6400","6.1296","6.1296","4.0864","18.5012","68.4544"
"24.7200","6.1496","6.1496","4.0997","18.5597","68.6708"
"24.8000","6.1681","6.1681","4.1120","18.6111","68.8612"
"24.8800","6.1894","6.1894","4.1263","18.6774","69.1064"
"24.9600","6.2097","6.2097","4.1398","18.7333","69.3132"
"25.0400","6.2306","6.2306","4.1537","18.7924","69.5319"
"25.1200","6.2493","6.2493","4.1662","18.8423","69.7167"
"25.2000","6.2682","6.2682","4.1788","18.8954","69.9129"
"25.2800","6.2894","6.2894","4.1929","18.9565","70.1389"
"25.3600","6.3096","6.3096","4.2064","19.0137","70.3508"
"25.4400","6.3292","6.3292","4.2195","19.0663","70.5454"
"25.5200","6.3504","6.3504","4.2336","19.1284","70.7751"
"25.6000","6.3700","6.3700","4.2467","19.1798","70.9653"
"25.6800","6.3900","6.3900","4.2600","19.2348","71.1689"
"25.7600","6.4101","6.4101","4.2734","19.2916","71.3788"
"25.8400","6.4292","6.4292","4.2862","19.3453","71.5776"
"25.9200","6.4496","6.4496","4.2997","19.4028","71.7904"
"26.0000","6.4685","6.4685","4.3123","19.4559","71.9868"
"26.0800","6.4891","6.4891","4.3261","19.5099","72.1865"
"26.1600","6.5101","6.5101","4.3401","19.5737","72.4227"
"26.2400","6.5301","6.5301","4.3534","19.6268","72.6192"
"26.3200","6.5497","6.5497","4.3665","19.6804","72.8176"
"26.4000","6.5694","6.5694","4.3796","19.7325","73.0103"
"26.4800","6.5887","6.5887","4.3925","19.7864","73.2096"
"26.5600","6.6098","6.6098","4.4066","19.8471","73.4342"
"26.6400","6.6288","6.6288","4.4192","19.8970","73.6188"
"26.7200","6.6502","6.6502","4.4335","19.9535","73.8279"
"26.8000","6.6704","6.6704","4.4470","20.0096","74.0354"
"26.8800","6.6899","6.6899","4.4599","20.0639","74.2363"
"26.9600","6.7101","6.7101","4.4734","20.1216","74.4498"
"27.0400","6.7297","6.7297","4.4865","20.1736","74.6422"
"27.1200","6.7493","6.7493","4.4996","20.2249","74.8322"
"27.2000","6.7693","6.7693","4.5129","20.2778","75.0279"
"27.2800","6.7880","6.7880","4.5254","20.3266","75.2083"
"27.3600","6.8094","6.8094","4.5396","20.3885","75.4376"
"27.4400","6.8303","6.8303","4.5535","20.4431","75.6394"
"27.5200","6.8500","6.8500","4.5666","20.4982","75.8433"
"27.6000","6.8696","6.8696","4.5798","20.5506","76.0372"
"27.6800","6.8883","6.8883","4.5922","20.5979","76.2124"
"27.7600","6.9098","6.9098","4.6065","20.6545","76.4215"
"27.8400","6.9299","6.9299","4.6199","20.7058","76.6114"
"27.9200","6.9492","6.9492","4.6328","20.7587","76.8072"
"28.0000","6.9697","6.9697","4.6464","20.8167","77.0217"
"28.0800","6.9905","6.9905","4.6604","20.8701","77.2194"
"28.1600","7.0105","7.0105","4.6737","20.9225","77.4131"
"28.2400","7.0301","7.0301","4.6867","20.9719","77.5961"
"28.3200","7.0489","7.0489","4.6992","21.0205","77.7759"
"28.4000","7.0690","7.0690","4.7126","21.0725","77.9684"
"28.4800","7.0889","7.0889","4.7259","21.1238","78.1581"
"28.5600","7.1088","7.1088","4.7392","21.1787","78.3613"
"28.6400","7.1301","7.1301","4.7534","21.2358","78.5725"
"28.7200","7.1503","7.1503","4.7669","21.2869","78.7614"
"28.8000","7.1702","7.1702","4.7801","21.3362","78.9441"
"28.8800","7.1902","7.1902","4.7934","21.3851","79.1248"
"28.9600","7.2087","7.2087","4.8058","21.4354","79.3110"
"29.0400","7.2298","7.2298","4.8199","21.4906","79.5151"
"29.1200","7.2489","7.2489","4.8326","21.5382","79.6915"
"29.2000","7.2696","7.2696","4.8464","21.5924","79.8920"
"29.2800","7.2907","7.2907","4.8605","21.6483","80.0989"
"29.3600","7.3100","7.3100","4.8733","21.6955","80.2732"
"29.4400","7.3300","7.3300","4.8866","21.7429","80.4489"
"29.5200","7.3496","7.3496","4.8997","21.7918","80.6295"
"29.6000","7.3692","7.3692","4.9128","21.8429","80.8186"
"29.6800","7.3891","7.3891","4.9260","21.8933","81.0053"
"29.7600","7.4087","7.4087","4.9391","21.9401","81.1784"
"29.8400","7.4295","7.4295","4.9530","21.9965","81.3869"
"29.9200","7.4504","7.4504","4.9670","22.0480","81.5775"
"30.0000","7.4691","7.4691","4.9794","22.0965","81.7570"
"30.0800","7.4896","7.4896","4.9931","22.1468","81.9433"
"30.1600","7.5092","7.5092","5.0062","22.1965","82.1272"
"30.2400","7.5296","7.5296","5.0197","22.2451","82.3067"
"30.3200","7.5498","7.5498","5.0332","22.2974","82.5004"
"30.4000","7.5689","7.5689","5.0459","22.3431","82.6695"
"30.4800","7.5895","7.5895","5.0597","22.3927","82.8530"
"30.5600","7.6109","7.6109","5.0740","22.4479","83.0572"
"30.6400","7.6299","7.6299","5.0866","22.4967","83.2380"
"30.7200","7.6497","7.6497","5.0998","22.5431","83.4096"
"30.8000","7.6686","7.6686","5.1124","22.5846","83.5632"
"30.8800","7.6896","7.6896","5.1264","22.6365","83.7550"
"30.9600","7.7094","7.7094","5.1396","22.6797","83.9149"
"31.0400","7.7287","7.7287","5.1525","22.7320","84.1084"
"31.1200","7.7496","7.7496","5.1664","22.7824","84.2949"
"31.2000","7.7700","7.7700","5.1800","22.8308","84.4741"
"31.2800","7.7898","7.7898","5.1932","22.8782","84.6493"
"31.3600","7.8099","7.8099","5.2066","22.9263","84.8274"
"31.4400","7.8290","7.8290","5.2193","22.9699","84.9885"
"31.5200","7.8495","7.8495","5.2330","23.0189","85.1701"
"31.6000","7.8696","7.8696","5.2464","23.0678","85.3510"
"31.6800","7.8891","7.8891","5.2594","23.1145","85.5236"
"31.7600","7.9105","7.9105","5.2737","23.1653","85.7115"
"31.8400","7.9301","7.9301","5.2867","23.2105","85.8789"
"31.9200","7.9502","7.9502","5.3001","23.2563","86.0484"
"32.0000","7.9696","7.9696","5.3131","23.3021","86.2178"
"32.0800","7.9887","7.9887","5.3258","23.3478","86.3869"
"32.1600","8.0095","8.0095","5.3397","23.3957","86.5640"
"32.2400","8.0295","8.0295","5.3530","23.4375","86.7188"
"32.3200","8.0486","8.0486","5.3658","23.4816","86.8818"
"32.4000","8.0699","8.0699","5.3799","23.5315","87.0667"
"32.4800","8.0893","8.0893","5.3929","23.5756","87.2296"
"32.5600","8.1103","8.1103","5.4069","23.6224","87.4028"
"32.6400","8.1299","8.1299","5.4200","23.6668","87.5673"
"32.7200","8.1491","8.1491","5.4327","23.7109","87.7305"
"32.8000","8.1690","8.1690","5.4460","23.7559","87.8969"
"32.8800","8.1890","8.1890","5.4594","23.8005","88.0619"
"32.9600","8.2099","8.2099","5.4733","23.8473","88.2348"
"33.0400","8.2313","8.2313","5.4875","23.8938","88.4072"
"33.1200","8.2497","8.2497","5.4998","23.9350","88.5596"
"33.2000","8.2695","8.2695","5.5130","23.9796","88.7246"
"33.2800","8.2890","8.2890","5.5260","24.0180","88.8667"
"33.3600","8.3093","8.3093","5.5395","24.0628","89.0325"
"33.4400","8.3302","8.3302","5.5534","24.1111","89.2112"
"33.5200","8.3486","8.3486","5.5657","24.1482","89.3485"
"33.6000","8.3694","8.3694","5.5796","24.1941","89.5181"
"33.6800","8.3900","8.3900","5.5933","24.2392","89.6849"
"33.7600","8.4102","8.4102","5.6068","24.2851","89.8550"
"33.8400","8.4300","8.4300","5.6200","24.3251","90.0030"
"33.9200","8.4490","8.4490","5.6327","24.3665","90.1562"
"34.0000","8.4690","8.4690","5.6460","24.4087","90.3123"
"34.0800","8.4900","8.4900","5.6600","24.4544","90.4813"
"34.1600","8.5091","8.5091","5.6728","24.4943","90.6290"
"34.2400","8.5304","8.5304","5.6869","24.5378","90.7898"
"34.3200","8.5503","8.5503","5.7002","24.5809","90.9492"
"34.4000","8.5701","8.5701","5.7134","24.6204","91.0955"
"34.4800","8.5899","8.5899","5.7266","24.6655","91.2622"
"34.5600","8.6093","8.6093","5.7396","24.7019","91.3971"
"34.6400","8.6297","8.6297","5.7531","24.7456","91.5587"
"34.7200","8.6494","8.6494","5.7663","24.7829","91.6968"
"34.8000","8.6682","8.6682","5.7788","24.8210","91.8377"
"34.8800","8.6898","8.6898","5.7932","24.8668","92.0071"
"34.9600","8.7096","8.7096","5.8064","24.9056","92.1508"
"35.0400","8.7303","8.7303","5.8202","24.9461","92.3006"
"35.1200","8.7499","8.7499","5.8332","24.9847","92.4433"
"35.2000","8.7685","8.7685","5.8457","25.0210","92.5775"
"35.2800","8.7891","8.7891","5.8594","25.0636","92.7351"
"35.3600","8.8096","8.8096","5.8731","25.1036","92.8832"
"35.4400","8.8300","8.8300","5.8867","25.1449","93.0360"
"35.5200","8.8508","8.8508","5.9006","25.1846","93.1832"
"35.6000","8.8696","8.8696","5.9131","25.2188","93.3094"
"35.6800","8.8898","8.8898","5.9265","25.2573","93.4521"
"35.7600","8.9096","8.9096","5.9397","25.2930","93.5840"
"35.8400","8.9290","8.9290","5.9527","25.3324","93.7299"
"35.9200","8.9497","8.9497","5.9665","25.3744","93.8854"
"36.0000","8.9681","8.9681","5.9788","25.4066","94.0044"
"36.0800","8.9892","8.9892","5.9928","25.4473","94.1549"
"36.1600","9.0105","9.0105","6.0070","25.4878","94.3048"
"36.2400","9.0301","9.0301","6.0200","25.5221","94.4317"
"36.3200","9.0499","9.0499","6.0333","25.5608","94.5749"
"36.4000","9.0692","9.0692","6.0461","25.5921","94.6908"
"36.4800","9.0884","9.0884","6.0589","25.6277","94.8224"
"36.5600","9.1097","9.1097","6.0731","25.6675","94.9699"
"36.6400","9.1291","9.1291","6.0861","25.7028","95.1004"
"36.7200","9.1502","9.1502","6.1001","25.7386","95.2329"
"36.8000","9.1704","9.1704","6.1136","25.7766","95.3734"
"36.8800","9.1900","9.1900","6.1267","25.8117","95.5033"
"36.9600","9.2096","9.2096","6.1397","25.8446","95.6252"
"37.0400","9.2295","9.2295","6.1530","25.8800","95.7561"
"37.1200","9.2494","9.2494","6.1663","25.9137","95.8807"
"37.2000","9.2694","9.2694","6.1796","25.9474","96.0054"
"37.2800","9.2881","9.2881","6.1921","25.9776","96.1171"
"37.3600","9.3097","9.3097","6.2065","26.0190","96.2704"
"37.4400","9.3306","9.3306","6.2204","26.0545","96.4016"
"37.5200","9.3499","9.3499","6.2332","26.0881","96.5260"
"37.6000","9.3698","9.3698","6.2465","26.1195","96.6421"
"37.6800","9.3885","9.3885","6.2590","26.1487","96.7502"
"37.7600","9.4096","9.4096","6.2731","26.1860","96.8882"
"37.8400","9.4298","9.4298","6.2865","26.2171","97.0035"
"37.9200","9.4492","9.4492","6.2995","26.2504","97.1266"
"38.0000","9.4698","9.4698","6.3132","26.2853","97.2555"
"38.0800","9.4901","9.4901","6.3267","26.3170","97.3728"
"38.1600","9.5098","9.5098","6.3399","26.3472","97.4847"
"38.2400","9.5303","9.5303","6.3536","26.3780","97.5986"
"38.3200","9.5486","9.5486","6.3657","26.4107","97.7194"
"38.4000","9.5692","9.5692","6.3795","26.4409","97.8314"
"38.4800","9.5886","9.5886","6.3924","26.4708","97.9418"
"38.5600","9.6092","9.6092","6.4061","26.5055","98.0703"
"38.6400","9.6300","9.6300","6.4200","26.5417","98.2043"
"38.7200","9.6500","9.6500","6.4333","26.5704","98.3104"
"38.8000","9.6700","9.6700","6.4467","26.6019","98.4269"
"38.8800","9.6902","9.6902","6.4601","26.6312","98.5354"
"38.9600","9.7086","9.7086","6.4724","26.6611","98.6460"
"39.0400","9.7294","9.7294","6.4863","26.6914","98.7580"
"39.1200","9.7491","9.7491","6.4994","26.7225","98.8733"
"39.2000","9.7700","9.7700","6.5133","26.7536","98.9882"
"39.2800","9.7907","9.7907","6.5271","26.7843","99.1021"
"39.3600","9.8100","9.8100","6.5400","26.8141","99.2123"
"39.4400","9.8301","9.8301","6.5534","26.8438","99.3219"
"39.5200","9.8498","9.8498","6.5666","26.8698","99.4183"
"39.6000","9.8690","9.8690","6.5793","26.8983","99.5236"
"39.6800","9.8892","9.8892","6.5928","26.9309","99.6444"
"39.7600","9.9084","9.9084","6.6056","26.9560","99.7371"
"39.8400","9.9296","9.9296","6.6198","26.9857","99.8470"
"39.9200","9.9507","9.9507","6.6338","27.0147","99.9545"
"40.0000","9.9693","9.9693","6.6462","27.0426","100.0578"
"40.0800","9.9897","9.9897","6.6598","27.0680","100.1516"
"40.1600","10.0089","10.0089","6.6726","27.0957","100.2539"
"40.2400","10.0296","10.0296","6.6864","27.1252","100.3631"
"40.3200","10.0497","10.0497","6.6998","27.1512","100.4594"
"40.4000","10.0688","10.0688","6.7126","27.1771","100.5555"
"40.4800","10.0896","10.0896","6.7264","27.2056","100.6606"
"40.5600","10.1108","10.1108","6.7405","27.2330","100.7621"
"40.6400","10.1300","10.1300","6.7534","27.2567","100.8499"
"40.7200","10.1498","10.1498","6.7665","27.2815","100.9416"
"40.8000","10.1681","10.1681","6.7787","27.3015","101.0155"
"40.8800","10.1892","10.1892","6.7928","27.3279","101.1134"
"40.9600","10.2096","10.2096","6.8064","27.3556","101.2157"
"41.0400","10.2286","10.2286","6.8191","27.3805","101.3077"
"41.1200","10.2495","10.2495","6.8330","27.4075","101.4078"
"41.2000","10.2700","10.2700","6.8467","27.4331","101.5026"
"41.2800","10.2899","10.2899","6.8600","27.4566","101.5896"
"41.3600","10.3103","10.3103","6.8735","27.4826","101.6857"
"41.4400","10.3291","10.3291","6.8860","27.4995","101.7483"
"41.5200","10.3496","10.3496","6.8998","27.5272","101.8507"
"41.6000","10.3696","10.3696","6.9131","27.5489","101.9311"
"41.6800","10.3890","10.3890","6.9260","27.5710","102.0128"
"41.7600","10.4105","10.4105","6.9403","27.6003","102.1209"
"41.8400","10.4300","10.4300","6.9533","27.6175","102.1846"
"41.9200","10.4505","10.4505","6.9670","27.6414","102.2730"
"42.0000","10.4698","10.4698","6.9799","27.6594","102.3399"
"42.0800","10.4889","10.4889","6.9926","27.6821","102.4239"
"42.1600","10.5093","10.5093","7.0062","27.7029","102.5006"
"42.2400","10.5293","10.5293","7.0196","27.7250","102.5826"
"42.3200","10.5491","10.5491","7.0327","27.7449","102.6561"
"42.4000","10.5697","10.5697","7.0465","27.7705","102.7509"
"42.4800","10.5892","10.5892","7.0595","27.7891","102.8198"
"42.5600","10.6102","10.6102","7.0735","27.8123","102.9057"
"42.6400","10.6299","10.6299","7.0866","27.8295","102.9691"
"42.7200","10.6492","10.6492","7.0995","27.8474","103.0355"
"42.8000","10.6689","10.6689","7.1126","27.8689","103.1149"
"42.8800","10.6890","10.6890","7.1260","27.8867","103.1806"
"42.9600","10.7098","10.7098","7.1399","27.9065","103.2539"
"43.0400","10.7311","10.7311","7.1541","27.9306","103.3434"
"43.1200","10.7498","10.7498","7.1665","27.9491","103.4118"
"43.2000","10.7697","10.7697","7.1798","27.9677","103.4805"
"43.2800","10.7893","10.7893","7.1928","27.9848","103.5438"
"43.3600","10.8092","10.8092","7.2061","28.0038","103.6142"
"43.4400","10.8295","10.8295","7.2197","28.0222","103.6821"
"43.5200","10.8480","10.8480","7.2320","28.0375","103.7388"
"43.6000","10.8691","10.8691","7.2461","28.0583","103.8158"
"43.6800","10.8901","10.8901","7.2601","28.0767","103.8838"
"43.7600","10.9103","10.9103","7.2735","28.0974","103.9605"
"43.8400","10.9301","10.9301","7.2867","28.1184","104.0381"
"43.9200","10.9492","10.9492","7.2995","28.1289","104.0768"
"44.0000","10.9690","10.9690","7.3126","28.1494","104.1527"
"44.0800","10.9900","10.9900","7.3266","28.1713","104.2337"
"44.1600","11.0087","11.0087","7.3391","28.1842","104.2817"
"44.2400","11.0302","11.0302","7.3535","28.2069","104.3655"
"44.3200","11.0504","11.0504","7.3669","28.2247","104.4314"
"44.4000","11.0704","11.0704","7.3803","28.2377","104.4795"
"44.4800","11.0896","11.0896","7.3931","28.2539","104.5395"
"44.5600","11.1093","11.1093","7.4062","28.2701","104.5993"
"44.6400","11.1297","11.1297","7.4198","28.2886","104.6680"
"44.7200","11.1493","11.1493","7.4328","28.3029","104.7206"
"44.8000","11.1680","11.1680","7.4453","28.3144","104.7631"
"44.8800","11.1897","11.1897","7.4598","28.3392","104.8551"
"44.9600","11.2100","11.2100","7.4733","28.3530","104.9061"
"45.0400","11.2310","11.2310","7.4873","28.3697","104.9679"
"45.1200","11.2496","11.2496","7.4997","28.3811","105.0100"
"45.2000","11.2680","11.2680","7.5120","28.3924","105.0519"
"45.2800","11.2891","11.2891","7.5261","28.4100","105.1169"
"45.3600","11.3098","11.3098","7.5399","28.4262","105.1768"
"45.4400","11.3297","11.3297","7.5531","28.4392","105.2250"
"45.5200","11.3504","11.3504","7.5669","28.4558","105.2865"
"45.6000","11.3697","11.3697","7.5798","28.4668","105.3271"
"45.6800","11.3897","11.3897","7.5931","28.4787","105.3711"
"45.7600","11.4099","11.4099","7.6066","28.4917","105.4193"
"45.8400","11.4292","11.4292","7.6195","28.5056","105.4708"
"45.9200","11.4495","11.4495","7.6330","28.5177","105.5154"
"46.0000","11.4683","11.4683","7.6455","28.5291","105.5578"
"46.0800","11.4891","11.4891","7.6594","28.5426","105.6077"
"46.1600","11.5104","11.5104","7.6736","28.5601","105.6725"
"46.2400","11.5299","11.5299","7.6866","28.5694","105.7069"
"46.3200","11.5497","11.5497","7.6998","28.5819","105.7532"
"46.4000","11.5694","11.5694","7.7129","28.5916","105.7890"
"46.4800","11.5885","11.5885","7.7257","28.6024","105.8288"
"46.5600","11.6099","11.6099","7.7399","28.6152","105.8763"
"46.6400","11.6289","11.6289","7.7526","28.6230","105.9051"
"46.7200","11.6502","11.6502","7.7668","28.6379","105.9601"
"46.8000","11.6700","11.6700","7.7800","28.6473","105.9951"
"46.8800","11.6899","11.6899","7.7933","28.6602","106.0426"
"46.9600","11.7098","11.7098","7.8065","28.6724","106.0879"
"47.0400","11.7296","11.7296","7.8198","28.6826","106.1258"
"47.1200","11.7494","11.7494","7.8330","28.6958","106.1745"
"47.2000","11.7700","11.7700","7.8467","28.7062","106.2129"
"47.2800","11.7882","11.7882","7.8588","28.7162","106.2498"
"47.3600","11.8098","11.8098","7.8732","28.7295","106.2993"
"47.4400","11.8307","11.8307","7.8871","28.7432","106.3498"
"47.5200","11.8499","11.8499","7.8999","28.7547","106.3923"
"47.6000","11.8695","11.8695","7.9130","28.7649","106.4303"
"47.6800","11.8886","11.8886","7.9258","28.7742","106.4645"
"47.7600","11.9100","11.9100","7.9400","28.7861","106.5087"
"47.8400","11.9301","11.9301","7.9534","28.7951","106.5420"
"47.9200","11.9492","11.9492","7.9661","28.8051","106.5790"
"48.0000","11.9695","11.9695","7.9797","28.8162","106.6201"
"48.0800","11.9899","11.9899","7.9933","28.8276","106.6620"
"48.1600","12.0103","12.0103","8.0069","28.8362","106.6940"
"48.2400","12.0303","12.0303","8.0202","28.8433","106.7203"
"48.3200","12.0484","12.0484","8.0322","28.8534","106.7575"
"48.4000","12.0697","12.0697","8.0465","28.8667","106.8068"
"48.4800","12.0884","12.0884","8.0589","28.8711","106.8231"
"48.5600","12.1084","12.1084","8.0722","28.8821","106.8638"
"48.6400","12.1296","12.1296","8.0864","28.8946","106.9100"
"48.7200","12.1502","12.1502","8.1001","28.9034","106.9424"
"48.8000","12.1699","12.1699","8.1133","28.9109","106.9701"
"48.8800","12.1901","12.1901","8.1268","28.9216","107.0098"
"48.9600","12.2091","12.2091","8.1394","28.9285","107.0355"
"49.0400","12.2297","12.2297","8.1531","28.9397","107.0769"
"49.1200","12.2490","12.2490","8.1660","28.9466","107.1023"
"49.2000","12.2695","12.2695","8.1797","28.9560","107.1371"
"49.2800","12.2906","12.2906","8.1937","28.9665","107.1760"
"49.3600","12.3099","12.3099","8.2066","28.9705","107.1910"
"49.4400","12.3300","12.3300","8.2200","28.9792","107.2232"
"49.5200","12.3498","12.3498","8.2332","28.9856","107.2466"
"49.6000","12.3693","12.3693","8.2462","28.9932","107.2748"
"49.6800","12.3895","12.3895","8.2597","29.0006","107.3022"
"49.7600","12.4086","12.4086","8.2724","29.0058","107.3213"
"49.8400","12.4291","12.4291","8.2860","29.0087","107.3322"
"49.9200","12.4503","12.4503","8.3002","29.0182","107.3673"
"50.0000","12.4692","12.4692","8.3128","29.0235","107.3870"
"50.0800","12.4898","12.4898","8.3266","29.0301","107.4113"
"50.1600","12.5092","12.5092","8.3395","29.0362","107.4339"
"50.2400","12.5298","12.5298","8.3532","29.0411","107.4519"
"50.3200","12.5495","12.5495","8.3663","29.0462","107.4708"
"50.4000","12.5689","12.5689","8.3793","29.0496","107.4834"
"50.4800","12.5898","12.5898","8.3932","29.0560","107.5070"
"50.5600","12.6109","12.6109","8.4073","29.0614","107.5270"
"50.6400","12.6302","12.6302","8.4201","29.0660","107.5441"
"50.7200","12.6499","12.6499","8.4333","29.0709","107.5625"
"50.8000","12.6687","12.6687","8.4458","29.0716","107.5651"
"50.8800","12.6895","12.6895","8.4596","29.0775","107.5866"
"50.9600","12.7094","12.7094","8.4729","29.0793","107.5933"
"51.0400","12.7286","12.7286","8.4857","29.0834","107.6085"
"51.1200","12.7497","12.7497","8.4998","29.0908","107.6360"
"51.2000","12.7696","12.7696","8.5131","29.0925","107.6423"
"51.2800","12.7896","12.7896","8.5264","29.0941","107.6483"
"51.3600","12.8103","12.8103","8.5402","29.0995","107.6681"
"51.4400","12.8289","12.8289","8.5526","29.1024","107.6788"
"51.5200","12.8498","12.8498","8.5666","29.1060","107.6923"
"51.6000","12.8697","12.8697","8.5798","29.1063","107.6934"
"51.6800","12.8889","12.8889","8.5926","29.1112","107.7116"
"51.7600","12.9106","12.9106","8.6070","29.1198","107.7434"
"51.8400","12.9302","12.9302","8.6201","29.1196","107.7425"
"51.9200","12.9503","12.9503","8.6335","29.1198","107.7434"
"52.0000","12.9697","12.9697","8.6465","29.1249","107.7620"
"52.0800","12.9889","12.9889","8.6593","29.1270","107.7699"
"52.1600","13.0093","13.0093","8.6729","29.1321","107.7888"
"52.2400","13.0293","13.0293","8.6862","29.1331","107.7925"
"52.3200","13.0488","13.0488","8.6992","29.1353","107.8007"
"52.4000","13.0699","13.0699","8.7133","29.1392","107.8149"
"52.4800","13.0892","13.0892","8.7261","29.1407","107.8205"
"52.5600","13.1104","13.1104","8.7403","29.1398","107.8171"
"52.6400","13.1297","13.1297","8.7531","29.1430","107.8290"
"52.7200","13.1492","13.1492","8.7661","29.1440","107.8329"
"52.8000","13.1690","13.1690","8.7793","29.1471","107.8444"
"52.8800","13.1892","13.1892","8.7928","29.1471","107.8442"
"52.9600","13.2101","13.2101","8.8068","29.1490","107.8513"
"53.0400","13.2313","13.2313","8.8209","29.1488","107.8506"
"53.1200","13.2496","13.2496","8.8330","29.1506","107.8574"
"53.2000","13.2695","13.2695","8.8463","29.1491","107.8515"
"53.2800","13.2892","13.2892","8.8595","29.1489","107.8509"
"53.3600","13.3095","13.3095","8.8730","29.1484","107.8492"
"53.4400","13.3298","13.3298","8.8865","29.1492","107.8522"
"53.5200","13.3484","13.3484","8.8989","29.1475","107.8458"
"53.6000","13.3694","13.3694","8.9129","29.1506","107.8573"
"53.6800","13.3903","13.3903","8.9268","29.1527","107.8652"
"53.7600","13.4095","13.4095","8.9396","29.1511","107.8589"
"53.8400","13.4296","13.4296","8.9531","29.1534","107.8676"
"53.9200","13.4495","13.4495","8.9663","29.1483","107.8486"
"54.0000","13.4691","13.4691","8.9794","29.1457","107.8392"
"54.0800","13.4898","13.4898","8.9932","29.1464","107.8417"
"54.1600","13.5087","13.5087","9.0058","29.1475","107.8456"
"54.2400","13.5305","13.5305","9.0204","29.1507","107.8576"
"54.3200","13.5503","13.5503","9.0335","29.1504","107.8563"
"54.4000","13.5699","13.5699","9.0466","29.1479","107.8472"
"54.4800","13.5896","13.5896","9.0597","29.1487","107.8501"
"54.5600","13.6095","13.6095","9.0730","29.1475","107.8459"
"54.6400","13.6298","13.6298","9.0865","29.1496","107.8536"
"54.7200","13.6496","13.6496","9.0997","29.1451","107.8369"
"54.8000","13.6682","13.6682","9.1122","29.1421","107.8258"
"54.8800","13.6895","13.6895","9.1264","29.1480","107.8476"
"54.9600","13.7100","13.7100","9.1400","29.1467","107.8429"
"55.0400","13.7307","13.7307","9.1538","29.1427","107.8280"
"55.1200","13.7498","13.7498","9.1665","29.1398","107.8172"
"55.2000","13.7683","13.7683","9.1789","29.1360","107.8032"
"55.2800","13.7890","13.7890","9.1927","29.1356","107.8018"
"55.3600","13.8098","13.8098","9.2065","29.1357","107.8022"
"55.4400","13.8301","13.8301","9.2201","29.1325","107.7904"
"55.5200","13.8508","13.8508","9.2338","29.1315","107.7864"
"55.6000","13.8697","13.8697","9.2464","29.1261","107.7666"
"55.6800","13.8899","13.8899","9.2599","29.1220","107.7516"
"55.7600","13.9097","13.9097","9.2732","29.1177","107.7354"
"55.8400","13.9289","13.9289","9.2860","29.1183","107.7377"
"55.9200","13.9494","13.9494","9.2996","29.1116","107.7131"
"56.0000","13.9683","13.9683","9.3122","29.1062","107.6929"
"56.0800","13.9891","13.9891","9.3261","29.1010","107.6737"
"56.1600","14.0101","14.0101","9.3400","29.1002","107.6709"
"56.2400","14.0300","14.0300","9.3533","29.0952","107.6524"
"56.3200","14.0496","14.0496","9.3664","29.0914","107.6382"
"56.4000","14.0691","14.0691","9.3794","29.0868","107.6211"
"56.4800","14.0889","14.0889","9.3926","29.0861","107.6185"
"56.5600","14.1101","14.1101","9.4067","29.0872","107.6226"
"56.6400","14.1293","14.1293","9.4195","29.0764","107.5825"
"56.7200","14.1499","14.1499","9.4333","29.0736","107.5723"
"56.8000","14.1704","14.1704","9.4469","29.0705","107.5610"
"56.8800","14.1899","14.1899","9.4600","29.0671","107.5482"
"56.9600","14.2099","14.2099","9.4733","29.0649","107.5401"
"57.0400","14.2295","14.2295","9.4863","29.0614","107.5271"
"57.1200","14.2493","14.2493","9.4996","29.0568","107.5101"
"57.2000","14.2695","14.2695","9.5130","29.0524","107.4937"
"57.2800","14.2882","14.2882","9.5255","29.0493","107.4825"
"57.3600","14.3097","14.3097","9.5398","29.0497","107.4839"
"57.4400","14.3302","14.3302","9.5535","29.0460","107.4703"
"57.5200","14.3497","14.3497","9.5664","29.0424","107.4571"
"57.6000","14.3699","14.3699","9.5800","29.0396","107.4465"
"57.6800","14.3888","14.3888","9.5925","29.0343","107.4271"
"57.7600","14.4097","14.4097","9.6065","29.0290","107.4073"
"57.8400","14.4300","14.4300","9.6200","29.0276","107.4021"
"57.9200","14.4491","14.4491","9.6327","29.0250","107.3925"
"58.0000","14.4695","14.4695","9.6463","29.0217","107.3804"
"58.0800","14.4901","14.4901","9.6601","29.0165","107.3612"
"58.1600","14.5104","14.5104","9.6736","29.0154","107.3569"
"58.2400","14.5302","14.5302","9.6868","29.0081","107.3299"
"58.3200","14.5485","14.5485","9.6990","29.0000","107.3001"
"58.4000","14.5694","14.5694","9.7130","28.9967","107.2878"
"58.4800","14.5889","14.5889","9.7259","28.9910","107.2668"
"58.5600","14.6090","14.6090","9.7393","28.9890","107.2593"
"58.6400","14.6296","14.6296","9.7531","28.9837","107.2396"
"58.7200","14.6498","14.6498","9.7665","28.9810","107.2295"
"58.8000","14.6700","14.6700","9.7800","28.9754","107.2088"
"58.8800","14.6901","14.6901","9.7934","28.9690","107.1853"
"58.9600","14.7086","14.7086","9.8057","28.9641","107.1671"
"59.0400","14.7295","14.7295","9.8196","28.9584","107.1461"
"59.1200","14.7493","14.7493","9.8329","28.9511","107.1190"
"59.2000","14.7696","14.7696","9.8464","28.9464","107.1016"
"59.2800","14.7908","14.7908","9.8605","28.9402","107.0788"
"59.3600","14.8102","14.8102","9.8735","28.9307","107.0437"
"59.4400","14.8302","14.8302","9.8868","28.9286","107.0360"
"59.5200","14.8496","14.8496","9.8998","28.9184","106.9982"
"59.6000","14.8688","14.8688","9.9125","28.9131","106.9784"
"59.6800","14.8890","14.8890","9.9260","28.9089","106.9628"
"59.7600","14.9087","14.9087","9.9392","28.8952","106.9124"
"59.8400","14.9291","14.9291","9.9527","28.8891","106.8896"
"59.9200","14.9504","14.9504","9.9669","28.8822","106.8642"
"60.0000","14.9695","14.9695","9.9796","28.8747","106.8363"
"60.0800","14.9899","14.9899","9.9932","28.8677","106.8107"
"60.1210","15.0000","15.0000","10.0000","28.8621","106.7896"