File: data/instron_tests/510_BULK_m1.is_comp_Exports/510_BULK_m1_6_1.csv
Sample text inputs : Sample No.,Sample choice input : Leading Direction,Sample choice input : Mode,Specimen choice input : Direction,Specimen properties : Height,Specimen properties : Thickness,Specimen properties : Width,Test : Rate 1
,,,,(mm),(mm),(mm),(mm/min)
"510","Bulk","Unimode","1","150.00","25.00","150.00","15.00"

Time,Displacement,Compressive displacement,Compressive strain (Displacement),Compressive stress,Force
(s),(mm),(mm),(%),(kPa),(N)
"0.0000","-0.0001","-0.0001","-0.0001","-1.0789","-3.9651"
"0.0800","0.0012","0.0012","0.0008","-1.0760","-3.9542"
"0.1600","0.0097","0.0097","0.0064","-1.0511","-3.8627"
"0.2400","0.0305","0.0305","0.0203","-1.0055","-3.6951"
"0.3200","0.0507","0.0507","0.0338","-0.9607","-3.5304"
"0.4000","0.0685","0.0685","0.0457","-0.9224","-3.3899"
"0.4800","0.0885","0.0885","0.0590","-0.8869","-3.2594"
"0.5600","0.1090","0.1090","0.0726","-0.8480","-3.1164"
"0.6400","0.1285","0.1285","0.0857","-0.8117","-2.9829"
"0.7200","0.1493","0.1493","0.0996","-0.7740","-2.8444"
"0.8000","0.1686","0.1686","0.1124","-0.7401","-2.7200"
"0.8800","0.1903","0.1903","0.1269","-0.7004","-2.5738"
"0.9600","0.2106","0.2106","0.1404","-0.6656","-2.4462"
"1.0400","0.2299","0.2299","0.1533","-0.6323","-2.3236"
"1.1200","0.2493","0.2493","0.1662","-0.5969","-2.1937"
"1.2000","0.2692","0.2692","0.1795","-0.5626","-2.0675"
"1.2800","0.2894","0.2894","0.1929","-0.5291","-1.9446"
"1.3600","0.3096","0.3096","0.2064","-0.4949","-1.8187"
"1.4400","0.3280","0.3280","0.2187","-0.4584","-1.6846"
"1.5200","0.3498","0.3498","0.2332","-0.4177","-1.5350"
"1.6000","0.3700","0.3700","0.2467","-0.3840","-1.4111"
"1.6800","0.3897","0.3897","0.2598","-0.3483","-1.2801"
"1.7600","0.4095","0.4095","0.2730","-0.3148","-1.1568"
"1.8400","0.4286","0.4286","0.2857","-0.2815","-1.0345"
"1.9200","0.4495","0.4495","0.2997","-0.2389","-0.8778"
"2.0000","0.4697","0.4697","0.3131","-0.2008","-0.7379"
"2.0800","0.4893","0.4893","0.3262","-0.1599","-0.5877"
"2.1600","0.5102","0.5102","0.3401","-0.1193","-0.4383"
"2.2400","0.5298","0.5298","0.3532","-0.0806","-0.2960"
"2.3200","0.5499","0.5499","0.3666","-0.0426","-0.1565"
"2.4000","0.5705","0.5705","0.3803","-0.0005","-0.0019"
"2.4800","0.5886","0.5886","0.3924","0.0390","0.1434"
"2.5600","0.6093","0.6093","0.4062","0.0808","0.2970"
"2.6400","0.6287","0.6287","0.4191","0.1208","0.4440"
"2.7200","0.6489","0.6489","0.4326","0.1627","0.5978"
"2.8000","0.6695","0.6695","0.4464","0.2057","0.7558"
"2.8800","0.6901","0.6901","0.4601","0.2498","0.9181"
"2.9600","0.7098","0.7098","0.4732","0.2884","1.0597"
"3.0400","0.7293","0.7293","0.4862","0.3284","1.2069"
"3.1200","0.7482","0.7482","0.4988","0.3746","1.3767"
"3.2000","0.7694","0.7694","0.5129","0.4194","1.5411"
"3.2800","0.7894","0.7894","0.5263","0.4629","1.7012"
"3.3600","0.8105","0.8105","0.5404","0.5068","1.8626"
"3.4400","0.8305","0.8305","0.5537","0.5484","2.0152"
"3.5200","0.8495","0.8495","0.5664","0.5925","2.1774"
"3.6000","0.8701","0.8701","0.5800","0.6395","2.3500"
"3.6800","0.8897","0.8897","0.5931","0.6821","2.5065"
"3.7600","0.9090","0.9090","0.6060","0.7250","2.6645"
"3.8400","0.9293","0.9293","0.6195","0.7690","2.8260"
"3.9200","0.9484","0.9484","0.6323","0.8112","2.9812"
"4.0000","0.9694","0.9694","0.6463","0.8561","3.1460"
"4.0800","0.9906","0.9906","0.6604","0.9042","3.3228"
"4.1600","1.0096","1.0096","0.6730","0.9469","3.4800"
"4.2400","1.0296","1.0296","0.6864","0.9892","3.6354"
"4.3200","1.0486","1.0486","0.6991","1.0300","3.7853"
"4.4000","1.0697","1.0697","0.7131","1.0767","3.9570"
"4.4800","1.0899","1.0899","0.7266","1.1220","4.1233"
"4.5600","1.1091","1.1091","0.7394","1.1666","4.2871"
"4.6400","1.1296","1.1296","0.7531","1.2153","4.4663"
"4.7200","1.1504","1.1504","0.7669","1.2582","4.6240"
"4.8000","1.1699","1.1699","0.7799","1.3034","4.7900"
"4.8800","1.1905","1.1905","0.7936","1.3503","4.9622"
"4.9600","1.2091","1.2091","0.8060","1.3880","5.1009"
"5.0400","1.2292","1.2292","0.8194","1.4353","5.2747"
"5.1200","1.2487","1.2487","0.8325","1.4778","5.4311"
"5.2000","1.2687","1.2687","0.8458","1.5273","5.6130"
"5.2800","1.2899","1.2899","0.8599","1.5725","5.7789"
"5.3600","1.3104","1.3104","0.8736","1.6212","5.9578"
"5.4400","1.3297","1.3297","0.8865","1.6646","6.1176"
"5.5200","1.3491","1.3491","0.8994","1.7118","6.2907"
"5.6000","1.3683","1.3683","0.9122","1.7559","6.4528"
"5.6800","1.3898","1.3898","0.9266","1.8085","6.6462"
"5.7600","1.4098","1.4098","0.9399","1.8483","6.7926"
"5.8400","1.4292","1.4292","0.9528","1.8939","6.9600"
"5.9200","1.4501","1.4501","0.9667","1.9442","7.1450"
"6.0000","1.4699","1.4699","0.9799","1.9913","7.3180"
"6.0800","1.4903","1.4903","0.9935","2.0397","7.4959"
"6.1600","1.5099","1.5099","1.0066","2.0839","7.6583"
"6.2400","1.5287","1.5287","1.0191","2.1287","7.8231"
"6.3200","1.5487","1.5487","1.0325","2.1791","8.0083"
"6.4000","1.5689","1.5689","1.0459","2.2261","8.1809"
"6.4800","1.5892","1.5892","1.0595","2.2735","8.3552"
"6.5600","1.6106","1.6106","1.0737","2.3280","8.5554"
"6.6400","1.6292","1.6292","1.0861","2.3729","8.7203"
"6.7200","1.6500","1.6500","1.1000","2.4177","8.8852"
"6.8000","1.6690","1.6690","1.1127","2.4638","9.0543"
"6.8800","1.6894","1.6894","1.1263","2.5165","9.2481"
"6.9600","1.7093","1.7093","1.1395","2.5676","9.4360"
"7.0400","1.7290","1.7290","1.1526","2.6178","9.6204"
"7.1200","1.7496","1.7496","1.1664","2.6659","9.7971"
"7.2000","1.7711","1.7711","1.1808","2.7157","9.9802"
"7.2800","1.7899","1.7899","1.1933","2.7631","10.1545"
"7.3600","1.8101","1.8101","1.2067","2.8121","10.3346"
"7.4400","1.8290","1.8290","1.2193","2.8564","10.4971"
"7.5200","1.8490","1.8490","1.2326","2.9063","10.6805"
"7.6000","1.8696","1.8696","1.2464","2.9583","10.8718"
"7.6800","1.8888","1.8888","1.2592","3.0051","11.0437"
"7.7600","1.9095","1.9095","1.2730","3.0536","11.2218"
"7.8400","1.9299","1.9299","1.2866","3.1061","11.4151"
"7.9200","1.9489","1.9489","1.2993","3.1535","11.5890"
"8.0000","1.9699","1.9699","1.3132","3.2053","11.7794"
"8.0800","1.9896","1.9896","1.3264","3.2531","11.9550"
"8.1600","2.0097","2.0097","1.3398","3.3039","12.1418"
"8.2400","2.0298","2.0298","1.3532","3.3514","12.3164"
"8.3200","2.0487","2.0487","1.3658","3.4024","12.5037"
"8.4000","2.0700","2.0700","1.3800","3.4561","12.7012"
"8.4800","2.0905","2.0905","1.3937","3.5068","12.8875"
"8.5600","2.1103","2.1103","1.4069","3.5585","13.0777"
"8.6400","2.1297","2.1297","1.4198","3.6080","13.2595"
"8.7200","2.1490","2.1490","1.4326","3.6537","13.4272"
"8.8000","2.1693","2.1693","1.4462","3.7022","13.6057"
"8.8800","2.1890","2.1890","1.4593","3.7488","13.7769"
"8.9600","2.2081","2.2081","1.4721","3.8016","13.9708"
"9.0400","2.2297","2.2297","1.4865","3.8591","14.1822"
"9.1200","2.2497","2.2497","1.4998","3.9098","14.3685"
"9.2000","2.2703","2.2703","1.5136","3.9598","14.5522"
"9.2800","2.2899","2.2899","1.5266","4.0086","14.7314"
"9.3600","2.3088","2.3088","1.5392","4.0566","14.9079"
"9.4400","2.3290","2.3290","1.5527","4.1080","15.0968"
"9.5200","2.3490","2.3490","1.5660","4.1590","15.2843"
"9.6000","2.3693","2.3693","1.5795","4.2122","15.4798"
"9.6800","2.3907","2.3907","1.5938","4.2681","15.6852"
"9.7600","2.4097","2.4097","1.6064","4.3171","15.8652"
"9.8400","2.4301","2.4301","1.6201","4.3666","16.0471"
"9.9200","2.4497","2.4497","1.6331","4.4172","16.2332"
"10.0000","2.4690","2.4690","1.6460","4.4701","16.4275"
"10.0800","2.4896","2.4896","1.6597","4.5247","16.6283"
"10.1600","2.5085","2.5085","1.6723","4.5764","16.8184"
"10.2400","2.5291","2.5291","1.6860","4.6275","17.0061"
"10.3200","2.5500","2.5500","1.7000","4.6812","17.2036"
"10.4000","2.5696","2.5696","1.7131","4.7334","17.3953"
"10.4800","2.5895","2.5895","1.7263","4.7848","17.5841"
"10.5600","2.6095","2.6095","1.7397","4.8370","17.7759"
"10.6400","2.6289","2.6289","1.7526","4.8871","17.9600"
"10.7200","2.6495","2.6495","1.7664","4.9431","18.1660"
"10.8000","2.6687","2.6687","1.7791","4.9935","18.3512"
"10.8800","2.6901","2.6901","1.7934","5.0512","18.5633"
"10.9600","2.7107","2.7107","1.8071","5.1070","18.7683"
"11.0400","2.7301","2.7301","1.8201","5.1538","18.9403"
"11.1200","2.7493","2.7493","1.8329","5.2060","19.1320"
"11.2000","2.7694","2.7694","1.8463","5.2604","19.3319"
"11.2800","2.7895","2.7895","1.8597","5.3116","19.5203"
"11.3600","2.8095","2.8095","1.8730","5.3675","19.7256"
"11.4400","2.8279","2.8279","1.8853","5.4167","19.9064"
"11.5200","2.8496","2.8496","1.8997","5.4772","20.1288"
"11.6000","2.8703","2.8703","1.9135","5.5338","20.3366"
"11.6800","2.8902","2.8902","1.9268","5.5870","20.5322"
"11.7600","2.9094","2.9094","1.9396","5.6365","20.7143"
"11.8400","2.9284","2.9284","1.9523","5.6842","20.8893"
"11.9200","2.9495","2.9495","1.9663","5.7420","21.1019"
"12.0000","2.9699","2.9699","1.9799","5.7973","21.3050"
"12.0800","2.9895","2.9895","1.9930","5.8539","21.5131"
"12.1600","3.0099","3.0099","2.0066","5.9116","21.7250"
"12.2400","3.0298","3.0298","2.0199","5.9651","21.9219"
"12.3200","3.0500","3.0500","2.0333","6.0191","22.1204"
"12.4000","3.0701","3.0701","2.0467","6.0716","22.3131"
"12.4800","3.0888","3.0888","2.0592","6.1232","22.5027"
"12.5600","3.1095","3.1095","2.0730","6.1803","22.7126"
"12.6400","3.1287","3.1287","2.0858","6.2302","22.8958"
"12.7200","3.1485","3.1485","2.0990","6.2836","23.0921"
"12.8000","3.1695","3.1695","2.1130","6.3453","23.3192"
"12.8800","3.1903","3.1903","2.1269","6.4029","23.5308"
"12.9600","3.2102","3.2102","2.1401","6.4583","23.7344"
"13.0400","3.2298","3.2298","2.1532","6.5106","23.9266"
"13.1200","3.2484","3.2484","2.1656","6.5629","24.1187"
"13.2000","3.2694","3.2694","2.1796","6.6204","24.3301"
"13.2800","3.2888","3.2888","2.1926","6.6744","24.5284"
"13.3600","3.3099","3.3099","2.2066","6.7323","24.7413"
"13.4400","3.3308","3.3308","2.2205","6.7875","24.9440"
"13.5200","3.3494","3.3494","2.2330","6.8419","25.1441"
"13.6000","3.3696","3.3696","2.2464","6.8958","25.3421"
"13.6800","3.3895","3.3895","2.2597","6.9510","25.5451"
"13.7600","3.4090","3.4090","2.2727","7.0039","25.7394"
"13.8400","3.4292","3.4292","2.2861","7.0609","25.9487"
"13.9200","3.4482","3.4482","2.2988","7.1117","26.1355"
"14.0000","3.4694","3.4694","2.3129","7.1710","26.3535"
"14.0800","3.4905","3.4905","2.3270","7.2287","26.5653"
"14.1600","3.5094","3.5094","2.3396","7.2854","26.7737"
"14.2400","3.5295","3.5295","2.3530","7.3409","26.9778"
"14.3200","3.5487","3.5487","2.3658","7.3932","27.1701"
"14.4000","3.5694","3.5694","2.3796","7.4509","27.3822"
"14.4800","3.5898","3.5898","2.3932","7.5067","27.5871"
"14.5600","3.6089","3.6089","2.4060","7.5614","27.7880"
"14.6400","3.6295","3.6295","2.4197","7.6187","27.9985"
"14.7200","3.6501","3.6501","2.4334","7.6761","28.2097"
"14.8000","3.6701","3.6701","2.4467","7.7308","28.4107"
"14.8800","3.6904","3.6904","2.4603","7.7886","28.6232"
"14.9600","3.7088","3.7088","2.4725","7.8374","28.8025"
"15.0400","3.7293","3.7293","2.4862","7.8939","29.0102"
"15.1200","3.7491","3.7491","2.4994","7.9464","29.2032"
"15.2000","3.7687","3.7687","2.5124","8.0057","29.4210"
"15.2800","3.7897","3.7897","2.5265","8.0635","29.6335"
"15.3600","3.8100","3.8100","2.5400","8.1220","29.8483"
"15.4400","3.8296","3.8296","2.5530","8.1739","30.0391"
"15.5200","3.8494","3.8494","2.5663","8.2305","30.2471"
"15.6000","3.8681","3.8681","2.5788","8.2839","30.4435"
"15.6800","3.8899","3.8899","2.5933","8.3438","30.6636"
"15.7600","3.9098","3.9098","2.6065","8.4002","30.8706"
"15.8400","3.9294","3.9294","2.6196","8.4562","31.0764"
"15.9200","3.9500","3.9500","2.6334","8.5165","31.2980"
"16.0000","3.9698","3.9698","2.6466","8.5708","31.4978"
"16.0800","3.9903","3.9903","2.6602","8.6300","31.7152"
"16.1600","4.0100","4.0100","2.6733","8.6838","31.9131"
"16.2400","4.0286","4.0286","2.6857","8.7389","32.1153"
"16.3200","4.0489","4.0489","2.6993","8.7958","32.3246"
"16.4000","4.0689","4.0689","2.7126","8.8505","32.5254"
"16.4800","4.0895","4.0895","2.7263","8.9094","32.7422"
"16.5600","4.1105","4.1105","2.7403","8.9701","32.9652"
"16.6400","4.1293","4.1293","2.7529","9.0249","33.1666"
"16.7200","4.1501","4.1501","2.7667","9.0825","33.3782"
"16.8000","4.1693","4.1693","2.7795","9.1379","33.5818"
"16.8800","4.1892","4.1892","2.7928","9.1907","33.7760"
"16.9600","4.2092","4.2092","2.8061","9.2497","33.9928"
"17.0400","4.2291","4.2291","2.8194","9.3054","34.1974"
"17.1200","4.2493","4.2493","2.8329","9.3621","34.4056"
"17.2000","4.2707","4.2707","2.8472","9.4237","34.6321"
"17.2800","4.2899","4.2899","2.8600","9.4805","34.8407"
"17.3600","4.3100","4.3100","2.8733","9.5378","35.0512"
"17.4400","4.3288","4.3288","2.8859","9.5895","35.2416"
"17.5200","4.3490","4.3490","2.8994","9.6473","35.4538"
"17.6000","4.3696","4.3696","2.9130","9.7067","35.6721"
"17.6800","4.3886","4.3886","2.9258","9.7632","35.8798"
"17.7600","4.4094","4.4094","2.9396","9.8221","36.0962"
"17.8400","4.4300","4.4300","2.9533","9.8822","36.3172"
"17.9200","4.4496","4.4496","2.9664","9.9371","36.5189"
"18.0000","4.4700","4.4700","2.9800","10.0013","36.7550"
"18.0800","4.4894","4.4894","2.9929","10.0567","36.9582"
"18.1600","4.5097","4.5097","3.0065","10.1128","37.1644"
"18.2400","4.5298","4.5298","3.0199","10.1705","37.3764"
"18.3200","4.5484","4.5484","3.0323","10.2254","37.5783"
"18.4000","4.5703","4.5703","3.0469","10.2906","37.8179"
"18.4800","4.5904","4.5904","3.0603","10.3483","38.0299"
"18.5600","4.6104","4.6104","3.0736","10.4017","38.2263"
"18.6400","4.6298","4.6298","3.0865","10.4602","38.4411"
"18.7200","4.6488","4.6488","3.0992","10.5126","38.6336"
"18.8000","4.6692","4.6692","3.1128","10.5691","38.8416"
"18.8800","4.6892","4.6892","3.1261","10.6292","39.0622"
"18.9600","4.7088","4.7088","3.1392","10.6855","39.2692"
"19.0400","4.7295","4.7295","3.1530","10.7468","39.4946"
"19.1200","4.7494","4.7494","3.1663","10.8033","39.7023"
"19.2000","4.7703","4.7703","3.1802","10.8649","39.9284"
"19.2800","4.7902","4.7902","3.1935","10.9188","40.1267"
"19.3600","4.8090","4.8090","3.2060","10.9750","40.3331"
"19.4400","4.8291","4.8291","3.2194","11.0347","40.5524"
"19.5200","4.8490","4.8490","3.2327","11.0908","40.7587"
"19.6000","4.8696","4.8696","3.2464","11.1520","40.9837"
"19.6800","4.8914","4.8914","3.2609","11.2196","41.2322"
"19.7600","4.9098","4.9098","3.2732","11.2707","41.4197"
"19.8400","4.9299","4.9299","3.2866","11.3296","41.6362"
"19.9200","4.9494","4.9494","3.2996","11.3847","41.8387"
"20.0000","4.9688","4.9688","3.3125","11.4415","42.0476"
"20.0800","4.9895","4.9895","3.3264","11.5047","42.2796"
"20.1600","5.0083","5.0083","3.3389","11.5565","42.4701"
"20.2400","5.0290","5.0290","3.3527","11.6141","42.6819"
"20.3200","5.0499","5.0499","3.3666","11.6791","42.9209"
"20.4000","5.0697","5.0697","3.3798","11.7363","43.1309"
"20.4800","5.0896","5.0896","3.3930","11.7963","43.3513"
"20.5600","5.1094","5.1094","3.4063","11.8529","43.5596"
"20.6400","5.1290","5.1290","3.4193","11.9097","43.7682"
"20.7200","5.1497","5.1497","3.4332","11.9709","43.9932"
"20.8000","5.1686","5.1686","3.4458","12.0251","44.1924"
"20.8800","5.1903","5.1903","3.4602","12.0892","44.4277"
"20.9600","5.2106","5.2106","3.4737","12.1501","44.6515"
"21.0400","5.2300","5.2300","3.4866","12.2052","44.8541"
"21.1200","5.2487","5.2487","3.4991","12.2611","45.0595"
"21.2000","5.2693","5.2693","3.5128","12.3226","45.2857"
"21.2800","5.2897","5.2897","3.5265","12.3832","45.5083"
"21.3600","5.3100","5.3100","3.5400","12.4419","45.7242"
"21.4400","5.3283","5.3283","3.5522","12.4962","45.9236"
"21.5200","5.3498","5.3498","3.5665","12.5604","46.1594"
"21.6000","5.3701","5.3701","3.5801","12.6207","46.3811"
"21.6800","5.3898","5.3898","3.5932","12.6758","46.5835"
"21.7600","5.4092","5.4092","3.6062","12.7370","46.8085"
"21.8400","5.4284","5.4284","3.6189","12.7911","47.0072"
"21.9200","5.4492","5.4492","3.6328","12.8524","47.2327"
"22.0000","5.4698","5.4698","3.6465","12.9152","47.4632"
"22.0800","5.4897","5.4897","3.6598","12.9761","47.6871"
"22.1600","5.5098","5.5098","3.6732","13.0359","47.9070"
"22.2400","5.5297","5.5297","3.6865","13.0948","48.1233"
"22.3200","5.5500","5.5500","3.7000","13.1517","48.3326"
"22.4000","5.5701","5.5701","3.7134","13.2107","48.5493"
"22.4800","5.5889","5.5889","3.7259","13.2691","48.7638"
"22.5600","5.6096","5.6096","3.7397","13.3301","48.9881"
"22.6400","5.6286","5.6286","3.7524","13.3883","49.2020"
"22.7200","5.6487","5.6487","3.7658","13.4489","49.4247"
"22.8000","5.6698","5.6698","3.7799","13.5114","49.6546"
"22.8800","5.6901","5.6901","3.7934","13.5699","49.8693"
"22.9600","5.7096","5.7096","3.8064","13.6287","50.0856"
"23.0400","5.7298","5.7298","3.8199","13.6886","50.3054"
"23.1200","5.7483","5.7483","3.8322","13.7408","50.4973"
"23.2000","5.7695","5.7695","3.8463","13.8052","50.7341"
"23.2800","5.7890","5.7890","3.8593","13.8673","50.9623"
"23.3600","5.8101","5.8101","3.8734","13.9290","51.1889"
"23.4400","5.8306","5.8306","3.8871","13.9916","51.4190"
"23.5200","5.8494","5.8494","3.8996","14.0480","51.6266"
"23.6000","5.8692","5.8692","3.9128","14.1028","51.8279"
"23.6800","5.8899","5.8899","3.9266","14.1704","52.0764"
"23.7600","5.9093","5.9093","3.9396","14.2260","52.2804"
"23.8400","5.9290","5.9290","3.9527","14.2843","52.4947"
"23.9200","5.9482","5.9482","3.9655","14.3423","52.7078"
"24.0000","5.9697","5.9697","3.9798","14.4079","52.9491"
"24.0800","5.9908","5.9908","3.9938","14.4706","53.1793"
"24.1600","6.0097","6.0097","4.0065","14.5299","53.3973"
"24.2400","6.0296","6.0296","4.0198","14.5893","53.6156"
"24.3200","6.0485","6.0485","4.0323","14.6432","53.8137"
"24.4000","6.0695","6.0695","4.0463","14.7051","54.0412"
"24.4800","6.0897","6.0897","4.0598","14.7660","54.2651"
"24.5600","6.1091","6.1091","4.0727","14.8252","54.4826"
"24.6400","6.1298","6.1298","4.0866","14.8893","54.7180"
"24.7200","6.1507","6.1507","4.1005","14.9539","54.9555"
"24.8000","6.1704","6.1704","4.1136","15.0128","55.1720"
"24.8800","6.1903","6.1903","4.1269","15.0731","55.3936"
"24.9600","6.2085","6.2085","4.1390","15.1266","55.5902"
"25.0400","6.2292","6.2292","4.1528","15.1885","55.8176"
"25.1200","6.2492","6.2492","4.1661","15.2481","56.0369"
"25.2000","6.2683","6.2683","4.1789","15.3077","56.2557"
"25.2800","6.2897","6.2897","4.1932","15.3738","56.4986"
"25.3600","6.3102","6.3102","4.2068","15.4353","56.7248"
"25.4400","6.3300","6.3300","4.2200","15.4978","56.9543"
"25.5200","6.3500","6.3500","4.2333","15.5552","57.1652"
"25.6000","6.3688","6.3688","4.2458","15.6136","57.3799"
"25.6800","6.3895","6.3895","4.2597","15.6764","57.6107"
"25.7600","6.4095","6.4095","4.2730","15.7388","57.8402"
"25.8400","6.4292","6.4292","4.2861","15.7968","58.0533"
"25.9200","6.4498","6.4498","4.2999","15.8614","58.2907"
"26.0000","6.4698","6.4698","4.3132","15.9255","58.5261"
"26.0800","6.4906","6.4906","4.3270","15.9850","58.7449"
"26.1600","6.5097","6.5097","4.3398","16.0414","58.9520"
"26.2400","6.5286","6.5286","4.3524","16.1008","59.1705"
"26.3200","6.5489","6.5489","4.3659","16.1633","59.3999"
"26.4000","6.5690","6.5690","4.3793","16.2266","59.6328"
"26.4800","6.5893","6.5893","4.3929","16.2885","59.8602"
"26.5600","6.6108","6.6108","4.4072","16.3556","60.1067"
"26.6400","6.6292","6.6292","4.4195","16.4118","60.3135"
"26.7200","6.6499","6.6499","4.4333","16.4766","60.5513"
"26.8000","6.6695","6.6695","4.4463","16.5347","60.7648"
"26.8800","6.6889","6.6889","4.4593","16.5964","60.9918"
"26.9600","6.7091","6.7091","4.4727","16.6574","61.2160"
"27.0400","6.7292","6.7292","4.4861","16.7213","61.4508"
"27.1200","6.7497","6.7497","4.4998","16.7829","61.6771"
"27.2000","6.7710","6.7710","4.5140","16.8498","61.9229"
"27.2800","6.7901","6.7901","4.5267","16.9086","62.1391"
"27.3600","6.8100","6.8100","4.5400","16.9692","62.3617"
"27.4400","6.8286","6.8286","4.5524","17.0256","62.5691"
"27.5200","6.8489","6.8489","4.5659","17.0876","62.7968"
"27.6000","6.8695","6.8695","4.5796","17.1523","63.0346"
"27.6800","6.8886","6.8886","4.5924","17.2114","63.2520"
"27.7600","6.9095","6.9095","4.6063","17.2751","63.4862"
"27.8400","6.9300","6.9300","4.6200","17.3412","63.7289"
"27.9200","6.9495","6.9495","4.6330","17.4023","63.9535"
"28.0000","6.9700","6.9700","4.6466","17.4668","64.1906"
"28.0800","6.9893","6.9893","4.6595","17.5236","64.3992"
"28.1600","7.0095","7.0095","4.6730","17.5874","64.6338"
"28.2400","7.0297","7.0297","4.6865","17.6481","64.8567"
"28.3200","7.0483","7.0483","4.6988","17.7074","65.0747"
"28.4000","7.0701","7.0701","4.7134","17.7796","65.3400"
"28.4800","7.0901","7.0901","4.7268","17.8387","65.5571"
"28.5600","7.1106","7.1106","4.7404","17.9019","65.7894"
"28.6400","7.1293","7.1293","4.7529","17.9595","66.0013"
"28.7200","7.1484","7.1484","4.7656","18.0175","66.2142"
"28.8000","7.1694","7.1694","4.7796","18.0854","66.4637"
"28.8800","7.1898","7.1898","4.7932","18.1456","66.6851"
"28.9600","7.2084","7.2084","4.8056","18.2035","66.8980"
"29.0400","7.2294","7.2294","4.8196","18.2718","67.1488"
"29.1200","7.2497","7.2497","4.8331","18.3372","67.3890"
"29.2000","7.2700","7.2700","4.8467","18.4000","67.6201"
"29.2800","7.2903","7.2903","4.8602","18.4634","67.8529"
"29.3600","7.3091","7.3091","4.8727","18.5231","68.0724"
"29.4400","7.3293","7.3293","4.8862","18.5911","68.3221"
"29.5200","7.3492","7.3492","4.8995","18.6512","68.5433"
"29.6000","7.3695","7.3695","4.9130","18.7142","68.7746"
"29.6800","7.3909","7.3909","4.9272","18.7824","69.0255"
"29.7600","7.4099","7.4099","4.9399","18.8394","69.2347"
"29.8400","7.4300","7.4300","4.9533","18.9007","69.4600"
"29.9200","7.4499","7.4499","4.9666","18.9666","69.7023"
"30.0000","7.4690","7.4690","4.9794","19.0252","69.9176"
"30.0800","7.4894","7.4894","4.9929","19.0918","70.1622"
"30.1600","7.5080","7.5080","5.0053","19.1481","70.3694"
"30.2400","7.5294","7.5294","5.0196","19.2158","70.6182"
"30.3200","7.5501","7.5501","5.0334","19.2827","70.8638"
"30.4000","7.5698","7.5698","5.0465","19.3501","71.1115"
"30.4800","7.5898","7.5898","5.0599","19.4110","71.3355"
"30.5600","7.6095","7.6095","5.0730","19.4719","71.5593"
"30.6400","7.6288","7.6288","5.0858","19.5350","71.7910"
"30.7200","7.6496","7.6496","5.0997","19.6010","72.0338"
"30.8000","7.6689","7.6689","5.1126","19.6634","72.2630"
"30.8800","7.6906","7.6906","5.1271","19.7314","72.5128"
"30.9600","7.7104","7.7104","5.1403","19.7950","72.7465"
"31.0400","7.7293","7.7293","5.1529","19.8560","72.9706"
"31.1200","7.7494","7.7494","5.1663","19.9178","73.1980"
"31.2000","7.7695","7.7695","5.1797","19.9834","73.4391"
"31.2800","7.7899","7.7899","5.1932","20.0481","73.6768"
"31.3600","7.8099","7.8099","5.2066","20.1126","73.9138"
"31.4400","7.8279","7.8279","5.2186","20.1703","74.1260"
"31.5200","7.8494","7.8494","5.2329","20.2416","74.3880"
"31.6000","7.8703","7.8703","5.2469","20.3082","74.6325"
"31.6800","7.8899","7.8899","5.2600","20.3727","74.8698"
"31.7600","7.9098","7.9098","5.2732","20.4330","75.0911"
"31.8400","7.9285","7.9285","5.2857","20.4940","75.3154"
"31.9200","7.9491","7.9491","5.2994","20.5582","75.5513"
"32.0000","7.9698","7.9698","5.3132","20.6282","75.8087"
"32.0800","7.9893","7.9893","5.3262","20.6921","76.0434"
"32.1600","8.0100","8.0100","5.3400","20.7612","76.2975"
"32.2400","8.0297","8.0297","5.3531","20.8206","76.5158"
"32.3200","8.0502","8.0502","5.3668","20.8874","76.7611"
"32.4000","8.0701","8.0701","5.3801","20.9537","77.0047"
"32.4800","8.0888","8.0888","5.3925","21.0137","77.2252"
"32.5600","8.1096","8.1096","5.4064","21.0827","77.4790"
"32.6400","8.1286","8.1286","5.4191","21.1439","77.7039"
"32.7200","8.1488","8.1488","5.4325","21.2083","77.9403"
"32.8000","8.1698","8.1698","5.4465","21.2835","78.2168"
"32.8800","8.1900","8.1900","5.4600","21.3468","78.4496"
"32.9600","8.2099","8.2099","5.4733","21.4091","78.6785"
"33.0400","8.2299","8.2299","5.4866","21.4738","78.9162"
"33.1200","8.2482","8.2482","5.4988","21.5349","79.1408"
"33.2000","8.2692","8.2692","5.5128","21.6057","79.4009"
"33.2800","8.2890","8.2890","5.5260","21.6701","79.6376"
"33.3600","8.3102","8.3102","5.5401","21.7393","79.8918"
"33.4400","8.3305","8.3305","5.5537","21.8040","80.1298"
"33.5200","8.3494","8.3494","5.5663","21.8659","80.3571"
"33.6000","8.3695","8.3695","5.5796","21.9304","80.5942"
"33.6800","8.3898","8.3898","5.5932","21.9978","80.8420"
"33.7600","8.4090","8.4090","5.6060","22.0626","81.0800"
"33.8400","8.4291","8.4291","5.6194","22.1281","81.3207"
"33.9200","8.4482","8.4482","5.6321","22.1885","81.5428"
"34.0000","8.4695","8.4695","5.6463","22.2596","81.8042"
"34.0800","8.4903","8.4903","5.6602","22.3284","82.0570"
"34.1600","8.5097","8.5097","5.6731","22.3930","82.2942"
"34.2400","8.5298","8.5298","5.6865","22.4573","82.5305"
"34.3200","8.5487","8.5487","5.6991","22.5210","82.7648"
"34.4000","8.5696","8.5696","5.7130","22.5884","83.0125"
"34.4800","8.5898","8.5898","5.7265","22.6567","83.2632"
"34.5600","8.6090","8.6090","5.7394","22.7221","83.5036"
"34.6400","8.6297","8.6297","5.7531","22.7910","83.7568"
"34.7200","8.6505","8.6505","5.7670","22.8614","84.0155"
"34.8000","8.6702","8.6702","5.7801","22.9267","84.2556"
"34.8800","8.6903","8.6903","5.7935","22.9907","84.4910"
"34.9600","8.7084","8.7084","5.8056","23.0489","84.7046"
"35.0400","8.7290","8.7290","5.8193","23.1185","84.9607"
"35.1200","8.7491","8.7491","5.8328","23.1847","85.2039"
"35.2000","8.7685","8.7685","5.8457","23.2531","85.4553"
"35.2800","8.7897","8.7897","5.8598","23.3271","85.7272"
"35.3600","8.8102","8.8102","5.8735","23.3936","85.9714"
"35.4400","8.8300","8.8300","5.8867","23.4568","86.2037"
"35.5200","8.8496","8.8496","5.8998","23.5238","86.4499"
"35.6000","8.8683","8.8683","5.9122","23.5820","86.6640"
"35.6800","8.8896","8.8896","5.9264","23.6569","86.9391"
"35.7600","8.9097","8.9097","5.9398","23.7258","87.1922"
"35.8400","8.9293","8.9293","5.9528","23.7898","87.4275"
"35.9200","8.9500","8.9500","5.9666","23.8625","87.6945"
"36.0000","8.9700","8.9700","5.9800","23.9270","87.9317"
"36.0800","8.9900","8.9900","5.9934","23.9957","88.1843"
"36.1600","9.0099","9.0099","6.0066","24.0584","88.4147"
"36.2400","9.0290","9.0290","6.0194","24.1261","88.6634"
"36.3200","9.0488","9.0488","6.0326","24.1907","88.9007"
"36.4000","9.0686","9.0686","6.0457","24.2599","89.1551"
"36.4800","9.0891","9.0891","6.0594","24.3290","89.4092"
"36.5600","9.1109","9.1109","6.0739","24.4033","89.6823"
"36.6400","9.1294","9.1294","6.0863","24.4636","89.9038"
"36.7200","9.1499","9.1499","6.0999","24.5343","90.1637"
"36.8000","9.1691","9.1691","6.1127","24.5994","90.4028"
"36.8800","9.1891","9.1891","6.1260","24.6665","90.6494"
"36.9600","9.2091","9.2091","6.1394","24.7373","90.9097"
"37.0400","9.2290","9.2290","6.1526","24.8010","91.1436"
"37.1200","9.2497","9.2497","6.1665","24.8734","91.4098"
"37.2000","9.2710","9.2710","6.1807","24.9463","91.6775"
"37.2800","9.2898","9.2898","6.1932","25.0107","91.9145"
"37.3600","9.3099","9.3099","6.2066","25.0791","92.1658"
"37.4400","9.3290","9.3290","6.2193","25.1465","92.4134"
"37.5200","9.3492","9.3492","6.2328","25.2170","92.6725"
"37.6000","9.3695","9.3695","6.2464","25.2850","92.9223"
"37.6800","9.3886","9.3886","6.2590","25.3489","93.1571"
"37.7600","9.4095","9.4095","6.2730","25.4210","93.4223"
"37.8400","9.4298","9.4298","6.2865","25.4903","93.6769"
"37.9200","9.4494","9.4494","6.2996","25.5594","93.9310"
"38.0000","9.4702","9.4702","6.3135","25.6321","94.1981"
"38.0800","9.4895","9.4895","6.3263","25.6960","94.4328"
"38.1600","9.5094","9.5094","6.3396","25.7653","94.6876"
"38.2400","9.5295","9.5295","6.3530","25.8340","94.9400"
"38.3200","9.5482","9.5482","6.3655","25.8978","95.1742"
"38.4000","9.5700","9.5700","6.3800","25.9780","95.4693"
"38.4800","9.5903","9.5903","6.3935","26.0475","95.7245"
"38.5600","9.6106","9.6106","6.4071","26.1162","95.9769"
"38.6400","9.6294","9.6294","6.4196","26.1757","96.1957"
"38.7200","9.6486","9.6486","6.4324","26.2437","96.4456"
"38.8000","9.6691","9.6691","6.4461","26.3149","96.7071"
"38.8800","9.6897","9.6897","6.4598","26.3863","96.9698"
"38.9600","9.7082","9.7082","6.4721","26.4513","97.2085"
"39.0400","9.7295","9.7295","6.4863","26.5275","97.4885"
"39.1200","9.7495","9.7495","6.4997","26.5990","97.7513"
"39.2000","9.7704","9.7704","6.5136","26.6699","98.0118"
"39.2800","9.7901","9.7901","6.5267","26.7366","98.2568"
"39.3600","9.8088","9.8088","6.5392","26.8000","98.4898"
"39.4400","9.8291","9.8291","6.5527","26.8712","98.7516"
"39.5200","9.8494","9.8494","6.5663","26.9438","99.0185"
"39.6000","9.8696","9.8696","6.5797","27.0148","99.2794"
"39.6800","9.8909","9.8909","6.5940","27.0912","99.5603"
"39.7600","9.9100","9.9100","6.6066","27.1572","99.8026"
"39.8400","9.9298","9.9298","6.6199","27.2254","100.0535"
"39.9200","9.9497","9.9497","6.6331","27.2934","100.3032"
"40.0000","9.9690","9.9690","6.6460","27.3638","100.5619"
"40.0800","9.9895","9.9895","6.6597","27.4357","100.8262"
"40.1600","10.0081","10.0081","6.6721","27.4962","101.0485"
"40.2400","10.0291","10.0291","6.6861","27.5688","101.3152"
"40.3200","10.0501","10.0501","6.7001","27.6486","101.6087"
"40.4000","10.0702","10.0702","6.7134","27.7197","101.8699"
"40.4800","10.0897","10.0897","6.7265","27.7901","102.1287"
"40.5600","10.1094","10.1094","6.7396","27.8565","102.3726"
"40.6400","10.1288","10.1288","6.7525","27.9257","102.6270"
"40.7200","10.1494","10.1494","6.7662","27.9993","102.8976"
"40.8000","10.1687","10.1687","6.7791","28.0673","103.1473"
"40.8800","10.1905","10.1905","6.7936","28.1452","103.4334"
"40.9600","10.2104","10.2104","6.8069","28.2141","103.6869"
"41.0400","10.2295","10.2295","6.8197","28.2791","103.9258"
"41.1200","10.2496","10.2496","6.8330","28.3546","104.2031"
"41.2000","10.2694","10.2694","6.8463","28.4251","104.4621"
"41.2800","10.2893","10.2893","6.8596","28.4947","104.7179"
"41.3600","10.3095","10.3095","6.8730","28.5634","104.9706"
"41.4400","10.3282","10.3282","6.8855","28.6300","105.2153"
"41.5200","10.3499","10.3499","6.8999","28.7114","105.5145"
"41.6000","10.3704","10.3704","6.9136","28.7825","105.7756"
"41.6800","10.3896","10.3896","6.9264","28.8498","106.0230"
"41.7600","10.4092","10.4092","6.9395","28.9203","106.2822"
"41.8400","10.4285","10.4285","6.9524","28.9896","106.5370"
"41.9200","10.4494","10.4494","6.9663","29.0619","106.8026"
"42.0000","10.4698","10.4698","6.9799","29.1378","107.0815"
"42.0800","10.4895","10.4895","6.9930","29.2098","107.3459"
"42.1600","10.5097","10.5097","7.0065","29.2836","107.6173"
"42.2400","10.5297","10.5297","7.0198","29.3534","107.8739"
"42.3200","10.5500","10.5500","7.0334","29.4270","108.1443"
"42.4000","10.5703","10.5703","7.0469","29.4988","108.4080"
"42.4800","10.5890","10.5890","7.0593","29.5679","108.6619"
"42.5600","10.6093","10.6093","7.0729","29.6402","108.9279"
"42.6400","10.6286","10.6286","7.0857","29.7102","109.1849"
"42.7200","10.6488","10.6488","7.0992","29.7835","109.4542"
"42.8000","10.6699","10.6699","7.1133","29.8620","109.7428"
"42.8800","10.6904","10.6904","7.1269","29.9356","110.0133"
"42.9600","10.7097","10.7097","7.1398","30.0027","110.2599"
"43.0400","10.7295","10.7295","7.1530","30.0715","110.5129"
"43.1200","10.7484","10.7484","7.1656","30.1424","110.7734"
"43.2000","10.7696","10.7696","7.1797","30.2210","111.0623"
"43.2800","10.7890","10.7890","7.1926","30.2846","111.2959"
"43.3600","10.8094","10.8094","7.2063","30.3633","111.5850"
"43.4400","10.8305","10.8305","7.2203","30.4389","111.8630"
"43.5200","10.8495","10.8495","7.2330","30.5071","112.1135"
"43.6000","10.8698","10.8698","7.2465","30.5798","112.3806"
"43.6800","10.8897","10.8897","7.2598","30.6532","112.6504"
"43.7600","10.9096","10.9096","7.2730","30.7275","112.9234"
"43.8400","10.9295","10.9295","7.2863","30.8013","113.1950"
"43.9200","10.9482","10.9482","7.2988","30.8654","113.4305"
"44.0000","10.9692","10.9692","7.3128","30.9433","113.7166"
"44.0800","10.9907","10.9907","7.3272","31.0257","114.0193"
"44.1600","11.0098","11.0098","7.3399","31.0955","114.2759"
"44.2400","11.0293","11.0293","7.3529","31.1649","114.5308"
"44.3200","11.0490","11.0490","7.3660","31.2366","114.7945"
"44.4000","11.0698","11.0698","7.3798","31.3134","115.0767"
"44.4800","11.0900","11.0900","7.3933","31.3888","115.3537"
"44.5600","11.1092","11.1092","7.4062","31.4566","115.6028"
"44.6400","11.1297","11.1297","7.4198","31.5335","115.8855"
"44.7200","11.1503","11.1503","7.4336","31.6099","116.1665"
"44.8000","11.1697","11.1697","7.4465","31.6811","116.4282"
"44.8800","11.1904","11.1904","7.4602","31.7583","116.7116"
"44.9600","11.2088","11.2088","7.4725","31.8210","116.9420"
"45.0400","11.2291","11.2291","7.4861","31.8962","117.2184"
"45.1200","11.2484","11.2484","7.4989","31.9686","117.4846"
"45.2000","11.2686","11.2686","7.5124","32.0448","117.7645"
"45.2800","11.2900","11.2900","7.5267","32.1265","118.0649"
"45.3600","11.3103","11.3103","7.5402","32.2018","118.3418"
"45.4400","11.3296","11.3296","7.5531","32.2719","118.5992"
"45.5200","11.3496","11.3496","7.5664","32.3450","118.8680"
"45.6000","11.3686","11.3686","7.5791","32.4155","119.1269"
"45.6800","11.3896","11.3896","7.5931","32.4952","119.4199"
"45.7600","11.4095","11.4095","7.6064","32.5707","119.6972"
"45.8400","11.4292","11.4292","7.6195","32.6442","119.9676"
"45.9200","11.4501","11.4501","7.6334","32.7217","120.2521"
"46.0000","11.4699","11.4699","7.6466","32.7958","120.5247"
"46.0800","11.4901","11.4901","7.6601","32.8712","120.8018"
"46.1600","11.5098","11.5098","7.6732","32.9397","121.0536"
"46.2400","11.5292","11.5292","7.6861","33.0133","121.3240"
"46.3200","11.5487","11.5487","7.6992","33.0890","121.6021"
"46.4000","11.5688","11.5688","7.7126","33.1656","121.8837"
"46.4800","11.5890","11.5890","7.7260","33.2414","122.1620"
"46.5600","11.6106","11.6106","7.7404","33.3258","122.4723"
"46.6400","11.6293","11.6293","7.7529","33.3946","122.7250"
"46.7200","11.6498","11.6498","7.7666","33.4698","123.0015"
"46.8000","11.6694","11.6694","7.7796","33.5444","123.2756"
"46.8800","11.6891","11.6891","7.7928","33.6201","123.5539"
"46.9600","11.7094","11.7094","7.8062","33.6957","123.8317"
"47.0400","11.7290","11.7290","7.8193","33.7694","124.1024"
"47.1200","11.7496","11.7496","7.8330","33.8486","124.3935"
"47.2000","11.7712","11.7712","7.8475","33.9304","124.6941"
"47.2800","11.7900","11.7900","7.8600","34.0022","124.9580"
"47.3600","11.8099","11.8099","7.8733","34.0771","125.2333"
"47.4400","11.8291","11.8291","7.8860","34.1474","125.4916"
"47.5200","11.8490","11.8490","7.8994","34.2223","125.7669"
"47.6000","11.8695","11.8695","7.9130","34.2986","126.0475"
"47.6800","11.8886","11.8886","7.9257","34.3724","126.3184"
"47.7600","11.9097","11.9097","7.9398","34.4541","126.6189"
"47.8400","11.9302","11.9302","7.9535","34.5316","126.9035"
"47.9200","11.9493","11.9493","7.9662","34.6059","127.1768"
"48.0000","11.9696","11.9696","7.9797","34.6830","127.4600"
"48.0800","11.9892","11.9892","7.9928","34.7559","127.7279"
"48.1600","12.0096","12.0096","8.0064","34.8337","128.0137"
"48.2400","12.0298","12.0298","8.0199","34.9111","128.2984"
"48.3200","12.0486","12.0486","8.0324","34.9824","128.5604"
"48.4000","12.0700","12.0700","8.0467","35.0672","128.8718"
"48.4800","12.0900","12.0900","8.0600","35.1427","129.1493"
"48.5600","12.1107","12.1107","8.0738","35.2229","129.4440"
"48.6400","12.1299","12.1299","8.0866","35.2971","129.7169"
"48.7200","12.1489","12.1489","8.0993","35.3654","129.9678"
"48.8000","12.1691","12.1691","8.1127","35.4458","130.2633"
"48.8800","12.1893","12.1893","8.1262","35.5209","130.5393"
"48.9600","12.2083","12.2083","8.1389","35.5956","130.8137"
"49.0400","12.2292","12.2292","8.1528","35.6764","131.1107"
"49.1200","12.2493","12.2493","8.1662","35.7551","131.4001"
"49.2000","12.2706","12.2706","8.1804","35.8364","131.6989"
"49.2800","12.2901","12.2901","8.1934","35.9085","131.9636"
"49.3600","12.3089","12.3089","8.2059","35.9827","132.2365"
"49.4400","12.3290","12.3290","8.2194","36.0637","132.5341"
"49.5200","12.3494","12.3494","8.2330","36.1428","132.8247"
"49.6000","12.3698","12.3698","8.2465","36.2227","133.1186"
"49.6800","12.3908","12.3908","8.2605","36.3037","133.4162"
"49.7600","12.4097","12.4097","8.2731","36.3717","133.6660"
"49.8400","12.4300","12.4300","8.2867","36.4534","133.9663"
"49.9200","12.4496","12.4496","8.2997","36.5261","134.2336"
"50.0000","12.4688","12.4688","8.3125","36.6013","134.5098"
"50.0800","12.4896","12.4896","8.3264","36.6858","134.8203"
"50.1600","12.5083","12.5083","8.3389","36.7563","135.0794"
"50.2400","12.5291","12.5291","8.3527","36.8364","135.3737"
"50.3200","12.5501","12.5501","8.3667","36.9220","135.6883"
"50.4000","12.5699","12.5699","8.3800","36.9991","135.9718"
"50.4800","12.5895","12.5895","8.3930","37.0740","136.2468"
"50.5600","12.6095","12.6095","8.4063","37.1525","136.5356"
"50.6400","12.6287","12.6287","8.4191","37.2241","136.7984"
"50.7200","12.6495","12.6495","8.4330","37.3102","137.1149"
"50.8000","12.6687","12.6687","8.4458","37.3858","137.3927"
"50.8800","12.6907","12.6907","8.4604","37.4739","137.7166"
"50.9600","12.7107","12.7107","8.4738","37.5515","138.0019"
"51.0400","12.7301","12.7301","8.4867","37.6282","138.2835"
"51.1200","12.7493","12.7493","8.4995","37.7020","138.5549"
"51.2000","12.7691","12.7691","8.5128","37.7794","138.8393"
"51.2800","12.7896","12.7896","8.5264","37.8610","139.1393"
"51.3600","12.8097","12.8097","8.5398","37.9358","139.4141"
"51.4400","12.8280","12.8280","8.5520","38.0108","139.6898"
"51.5200","12.8496","12.8496","8.5664","38.0970","140.0065"
"51.6000","12.8702","12.8702","8.5801","38.1828","140.3219"
"51.6800","12.8898","12.8898","8.5932","38.2584","140.5995"
"51.7600","12.9097","12.9097","8.6064","38.3363","140.8861"
"51.8400","12.9284","12.9284","8.6189","38.4068","141.1449"
"51.9200","12.9495","12.9495","8.6330","38.4927","141.4607"
"52.0000","12.9699","12.9699","8.6466","38.5715","141.7503"
"52.0800","12.9895","12.9895","8.6596","38.6518","142.0454"
"52.1600","13.0100","13.0100","8.6734","38.7372","142.3593"
"52.2400","13.0299","13.0299","8.6866","38.8117","142.6330"
"52.3200","13.0499","13.0499","8.6999","38.8916","142.9268"
"52.4000","13.0701","13.0701","8.7134","38.9710","143.2184"
"52.4800","13.0888","13.0888","8.7259","39.0450","143.4905"
"52.5600","13.1094","13.1094","8.7396","39.1283","143.7965"
"52.6400","13.1287","13.1287","8.7525","39.2027","144.0699"
"52.7200","13.1488","13.1488","8.7658","39.2841","144.3692"
"52.8000","13.1695","13.1695","8.7797","39.3691","144.6815"
"52.8800","13.1900","13.1900","8.7933","39.4517","144.9849"
"52.9600","13.2099","13.2099","8.8066","39.5281","145.2657"
"53.0400","13.2296","13.2296","8.8198","39.6062","145.5528"
"53.1200","13.2486","13.2486","8.8324","39.6828","145.8343"
"53.2000","13.2699","13.2699","8.8466","39.7772","146.1812"
"53.2800","13.2890","13.2890","8.8593","39.8479","146.4410"
"53.3600","13.3100","13.3100","8.8733","39.9312","146.7471"
"53.4400","13.3308","13.3308","8.8872","40.0156","147.0573"
"53.5200","13.3498","13.3498","8.8998","40.0942","147.3460"
"53.6000","13.3698","13.3698","8.9132","40.1712","147.6290"
"53.6800","13.3896","13.3896","8.9264","40.2525","147.9278"
"53.7600","13.4088","13.4088","8.9392","40.3288","148.2083"
"53.8400","13.4293","13.4293","8.9529","40.4136","148.5201"
"53.9200","13.4484","13.4484","8.9656","40.4897","148.7996"
"54.0000","13.4690","13.4690","8.9794","40.5717","149.1008"
"54.0800","13.4903","13.4903","8.9935","40.6606","149.4277"
"54.1600","13.5094","13.5094","9.0062","40.7374","149.7100"
"54.2400","13.5295","13.5295","9.0197","40.8202","150.0142"
"54.3200","13.5488","13.5488","9.0326","40.8961","150.2930"
"54.4000","13.5699","13.5699","9.0466","40.9823","150.6099"
"54.4800","13.5900","13.5900","9.0600","41.0643","150.9111"
"54.5600","13.6089","13.6089","9.0726","41.1410","151.1931"
"54.6400","13.6296","13.6296","9.0864","41.2266","151.5076"
"54.7200","13.6505","13.6505","9.1003","41.3143","151.8302"
"54.8000","13.6700","13.6700","9.1133","41.3931","152.1196"
"54.8800","13.6899","13.6899","9.1266","41.4739","152.4166"
"54.9600","13.7087","13.7087","9.1392","41.5475","152.6870"
"55.0400","13.7292","13.7292","9.1528","41.6298","152.9894"
"55.1200","13.7490","13.7490","9.1660","41.7117","153.2904"
"55.2000","13.7684","13.7684","9.1789","41.7897","153.5772"
"55.2800","13.7895","13.7895","9.1930","41.8838","153.9229"
"55.3600","13.8104","13.8104","9.2069","41.9673","154.2298"
"55.4400","13.8300","13.8300","9.2200","42.0441","154.5121"
"55.5200","13.8494","13.8494","9.2330","42.1244","154.8072"
"55.6000","13.8686","13.8686","9.2457","42.2020","155.0924"
"55.6800","13.8896","13.8896","9.2598","42.2917","155.4220"
"55.7600","13.9097","13.9097","9.2731","42.3711","155.7139"
"55.8400","13.9290","13.9290","9.2860","42.4525","156.0129"
"55.9200","13.9503","13.9503","9.3002","42.5412","156.3390"
"56.0000","13.9699","13.9699","9.3133","42.6224","156.6375"
"56.0800","13.9905","13.9905","9.3270","42.7072","156.9489"
"56.1600","14.0102","14.0102","9.3401","42.7893","157.2507"
"56.2400","14.0289","14.0289","9.3526","42.8664","157.5339"
"56.3200","14.0485","14.0485","9.3657","42.9474","157.8317"
"56.4000","14.0686","14.0686","9.3791","43.0302","158.1358"
"56.4800","14.0891","14.0891","9.3927","43.1149","158.4474"
"56.5600","14.1105","14.1105","9.4070","43.2069","158.7853"
"56.6400","14.1293","14.1293","9.4195","43.2809","159.0574"
"56.7200","14.1491","14.1491","9.4327","43.3606","159.3502"
"56.8000","14.1692","14.1692","9.4462","43.4468","159.6669"
"56.8800","14.1894","14.1894","9.4596","43.5317","159.9792"
"56.9600","14.2093","14.2093","9.4729","43.6177","160.2950"
"57.0400","14.2288","14.2288","9.4858","43.6942","160.5763"
"57.1200","14.2497","14.2497","9.4998","43.7822","160.8994"
"57.2000","14.2708","14.2708","9.5139","43.8722","161.2304"
"57.2800","14.2900","14.2900","9.5266","43.9520","161.5234"
"57.3600","14.3095","14.3095","9.5397","44.0329","161.8210"
"57.4400","14.3288","14.3288","9.5525","44.1110","162.1078"
"57.5200","14.3489","14.3489","9.5660","44.1963","162.4215"
"57.6000","14.3695","14.3695","9.5797","44.2858","162.7505"
"57.6800","14.3885","14.3885","9.5923","44.3624","163.0318"
"57.7600","14.4095","14.4095","9.6063","44.4531","163.3651"
"57.8400","14.4302","14.4302","9.6201","44.5391","163.6810"
"57.9200","14.4497","14.4497","9.6331","44.6222","163.9867"
"58.0000","14.4698","14.4698","9.6465","44.7075","164.3000"
"58.0800","14.4894","14.4894","9.6596","44.7901","164.6037"
"58.1600","14.5095","14.5095","9.6730","44.8731","164.9088"
"58.2400","14.5293","14.5293","9.6862","44.9534","165.2038"
"58.3200","14.5485","14.5485","9.6990","45.0379","165.5141"
"58.4000","14.5706","14.5706","9.7137","45.1332","165.8646"
"58.4800","14.5906","14.5906","9.7271","45.2167","166.1715"
"58.5600","14.6103","14.6103","9.7402","45.2995","166.4757"
"58.6400","14.6295","14.6295","9.7530","45.3801","166.7719"
"58.7200","14.6485","14.6485","9.7657","45.4583","167.0591"
"58.8000","14.6691","14.6691","9.7794","45.5442","167.3748"
"58.8800","14.6895","14.6895","9.7930","45.6324","167.6989"
"58.9600","14.7084","14.7084","9.8056","45.7099","167.9838"
"59.0400","14.7292","14.7292","9.8195","45.8025","168.3240"
"59.1200","14.7491","14.7491","9.8328","45.8836","168.6223"
"59.2000","14.7700","14.7700","9.8467","45.9747","168.9572"
"59.2800","14.7900","14.7900","9.8600","46.0573","169.2604"
"59.3600","14.8090","14.8090","9.8726","46.1386","169.5593"
"59.4400","14.8292","14.8292","9.8861","46.2267","169.8832"
"59.5200","14.8488","14.8488","9.8992","46.3080","170.1818"
"59.6000","14.8694","14.8694","9.9130","46.3996","170.5185"
"59.6800","14.8908","14.8908","9.9272","46.4910","170.8546"
"59.7600","14.9100","14.9100","9.9400","46.5679","171.1369"
"59.8400","14.9298","14.9298","9.9532","46.6558","171.4600"
"59.9200","14.9496","14.9496","9.9664","46.7353","171.7521"
"60.0000","14.9688","14.9688","9.9792","46.8219","172.0704"
"60.0800","14.9895","14.9895","9.9930","46.9105","172.3960"
"60.1220","15.0000","15.0000","10.0000","46.9525","172.5504"