File: data/instron_tests/510_BULK_m1.is_comp_Exports/510_BULK_m1_7_1.csv
Sample text inputs : Sample No.,Sample choice input : Leading Direction,Sample choice input : Mode,Specimen choice input : Direction,Specimen properties : Height,Specimen properties : Thickness,Specimen properties : Width,Test : Rate 1
,,,,(mm),(mm),(mm),(mm/min)
"510","Bulk","Unimode","1","150.00","25.00","150.00","15.00"

Time,Displacement,Compressive displacement,Compressive strain (Displacement),Compressive stress,Force
(s),(mm),(mm),(%),(kPa),(N)
"0.0000","-0.0001","-0.0001","0.0000","-0.9869","-3.6270"
"0.0800","0.0012","0.0012","0.0008","-0.9784","-3.5955"
"0.1600","0.0096","0.0096","0.0064","-0.9533","-3.5035"
"0.2400","0.0305","0.0305","0.0204","-0.9122","-3.3523"
"0.3200","0.0508","0.0508","0.0339","-0.8636","-3.1737"
"0.4000","0.0692","0.0692","0.0461","-0.8226","-3.0231"
"0.4800","0.0889","0.0889","0.0593","-0.7816","-2.8725"
"0.5600","0.1089","0.1089","0.0726","-0.7402","-2.7204"
"0.6400","0.1286","0.1286","0.0858","-0.7011","-2.5766"
"0.7200","0.1494","0.1494","0.0996","-0.6611","-2.4297"
"0.8000","0.1687","0.1687","0.1124","-0.6257","-2.2995"
"0.8800","0.1904","0.1904","0.1269","-0.5841","-2.1465"
"0.9600","0.2104","0.2104","0.1403","-0.5475","-2.0121"
"1.0400","0.2296","0.2296","0.1531","-0.5059","-1.8593"
"1.1200","0.2493","0.2493","0.1662","-0.4690","-1.7236"
"1.2000","0.2691","0.2691","0.1794","-0.4317","-1.5865"
"1.2800","0.2895","0.2895","0.1930","-0.3945","-1.4497"
"1.3600","0.3096","0.3096","0.2064","-0.3583","-1.3167"
"1.4400","0.3282","0.3282","0.2188","-0.3200","-1.1761"
"1.5200","0.3499","0.3499","0.2333","-0.2752","-1.0113"
"1.6000","0.3700","0.3700","0.2467","-0.2356","-0.8658"
"1.6800","0.3895","0.3895","0.2597","-0.1979","-0.7273"
"1.7600","0.4091","0.4091","0.2728","-0.1598","-0.5873"
"1.8400","0.4286","0.4286","0.2857","-0.1244","-0.4573"
"1.9200","0.4496","0.4496","0.2997","-0.0800","-0.2940"
"2.0000","0.4699","0.4699","0.3133","-0.0382","-0.1403"
"2.0800","0.4892","0.4892","0.3261","-0.0005","-0.0019"
"2.1600","0.5101","0.5101","0.3401","0.0454","0.1669"
"2.2400","0.5299","0.5299","0.3533","0.0863","0.3171"
"2.3200","0.5498","0.5498","0.3665","0.1219","0.4481"
"2.4000","0.5703","0.5703","0.3802","0.1650","0.6065"
"2.4800","0.5887","0.5887","0.3924","0.2076","0.7629"
"2.5600","0.6094","0.6094","0.4063","0.2486","0.9136"
"2.6400","0.6285","0.6285","0.4190","0.2919","1.0727"
"2.7200","0.6489","0.6489","0.4326","0.3344","1.2288"
"2.8000","0.6695","0.6695","0.4464","0.3785","1.3909"
"2.8800","0.6895","0.6895","0.4597","0.4199","1.5432"
"2.9600","0.7098","0.7098","0.4732","0.4635","1.7033"
"3.0400","0.7297","0.7297","0.4865","0.5046","1.8545"
"3.1200","0.7483","0.7483","0.4989","0.5475","2.0122"
"3.2000","0.7694","0.7694","0.5129","0.5959","2.1899"
"3.2800","0.7894","0.7894","0.5263","0.6367","2.3397"
"3.3600","0.8107","0.8107","0.5405","0.6850","2.5173"
"3.4400","0.8308","0.8308","0.5539","0.7283","2.6765"
"3.5200","0.8497","0.8497","0.5665","0.7684","2.8238"
"3.6000","0.8697","0.8697","0.5798","0.8128","2.9872"
"3.6800","0.8896","0.8896","0.5931","0.8582","3.1539"
"3.7600","0.9090","0.9090","0.6060","0.9004","3.3088"
"3.8400","0.9291","0.9291","0.6194","0.9464","3.4779"
"3.9200","0.9481","0.9481","0.6321","0.9899","3.6380"
"4.0000","0.9694","0.9694","0.6463","1.0348","3.8030"
"4.0800","0.9909","0.9909","0.6606","1.0845","3.9855"
"4.1600","1.0094","1.0094","0.6729","1.1274","4.1434"
"4.2400","1.0294","1.0294","0.6863","1.1702","4.3004"
"4.3200","1.0488","1.0488","0.6992","1.2113","4.4514"
"4.4000","1.0694","1.0694","0.7129","1.2582","4.6240"
"4.4800","1.0899","1.0899","0.7266","1.3043","4.7932"
"4.5600","1.1092","1.1092","0.7395","1.3489","4.9573"
"4.6400","1.1295","1.1295","0.7530","1.3939","5.1227"
"4.7200","1.1503","1.1503","0.7669","1.4402","5.2928"
"4.8000","1.1699","1.1699","0.7799","1.4794","5.4370"
"4.8800","1.1904","1.1904","0.7936","1.5307","5.6255"
"4.9600","1.2091","1.2091","0.8061","1.5716","5.7757"
"5.0400","1.2292","1.2292","0.8195","1.6158","5.9380"
"5.1200","1.2488","1.2488","0.8325","1.6595","6.0987"
"5.2000","1.2687","1.2687","0.8458","1.7100","6.2843"
"5.2800","1.2897","1.2897","0.8598","1.7543","6.4470"
"5.3600","1.3103","1.3103","0.8735","1.8023","6.6234"
"5.4400","1.3293","1.3293","0.8862","1.8483","6.7926"
"5.5200","1.3496","1.3496","0.8997","1.8954","6.9657"
"5.6000","1.3685","1.3685","0.9123","1.9407","7.1319"
"5.6800","1.3899","1.3899","0.9266","1.9896","7.3120"
"5.7600","1.4099","1.4099","0.9399","2.0342","7.4757"
"5.8400","1.4291","1.4291","0.9527","2.0806","7.6462"
"5.9200","1.4500","1.4500","0.9667","2.1318","7.8344"
"6.0000","1.4700","1.4700","0.9800","2.1806","8.0136"
"6.0800","1.4904","1.4904","0.9936","2.2272","8.1851"
"6.1600","1.5099","1.5099","1.0066","2.2757","8.3630"
"6.2400","1.5287","1.5287","1.0191","2.3190","8.5222"
"6.3200","1.5487","1.5487","1.0325","2.3668","8.6980"
"6.4000","1.5689","1.5689","1.0459","2.4177","8.8851"
"6.4800","1.5890","1.5890","1.0593","2.4662","9.0634"
"6.5600","1.6105","1.6105","1.0736","2.5165","9.2481"
"6.6400","1.6293","1.6293","1.0862","2.5643","9.4238"
"6.7200","1.6499","1.6499","1.0999","2.6069","9.5803"
"6.8000","1.6690","1.6690","1.1127","2.6544","9.7551"
"6.8800","1.6893","1.6893","1.1262","2.7068","9.9476"
"6.9600","1.7093","1.7093","1.1395","2.7571","10.1323"
"7.0400","1.7290","1.7290","1.1527","2.8042","10.3055"
"7.1200","1.7494","1.7494","1.1663","2.8552","10.4930"
"7.2000","1.7713","1.7713","1.1809","2.9024","10.6663"
"7.2800","1.7899","1.7899","1.1933","2.9507","10.8437"
"7.3600","1.8100","1.8100","1.2067","3.0011","11.0289"
"7.4400","1.8289","1.8289","1.2192","3.0462","11.1949"
"7.5200","1.8490","1.8490","1.2327","3.0979","11.3847"
"7.6000","1.8694","1.8694","1.2463","3.1487","11.5716"
"7.6800","1.8893","1.8893","1.2595","3.1977","11.7514"
"7.7600","1.9096","1.9096","1.2731","3.2475","11.9347"
"7.8400","1.9299","1.9299","1.2866","3.3000","12.1274"
"7.9200","1.9489","1.9489","1.2993","3.3471","12.3006"
"8.0000","1.9698","1.9698","1.3132","3.4005","12.4968"
"8.0800","1.9897","1.9897","1.3265","3.4470","12.6677"
"8.1600","2.0096","2.0096","1.3397","3.4938","12.8398"
"8.2400","2.0296","2.0296","1.3531","3.5426","13.0189"
"8.3200","2.0488","2.0488","1.3659","3.5933","13.2055"
"8.4000","2.0701","2.0701","1.3801","3.6484","13.4080"
"8.4800","2.0903","2.0903","1.3936","3.6997","13.5965"
"8.5600","2.1104","2.1104","1.4069","3.7494","13.7792"
"8.6400","2.1297","2.1297","1.4198","3.7949","13.9462"
"8.7200","2.1488","2.1488","1.4325","3.8418","14.1188"
"8.8000","2.1693","2.1693","1.4462","3.8965","14.3198"
"8.8800","2.1893","2.1893","1.4595","3.9442","14.4949"
"8.9600","2.2082","2.2082","1.4721","3.9949","14.6812"
"9.0400","2.2296","2.2296","1.4864","4.0511","14.8879"
"9.1200","2.2496","2.2496","1.4998","4.0988","15.0629"
"9.2000","2.2702","2.2702","1.5134","4.1501","15.2515"
"9.2800","2.2899","2.2899","1.5266","4.1987","15.4303"
"9.3600","2.3088","2.3088","1.5392","4.2491","15.6156"
"9.4400","2.3288","2.3288","1.5525","4.3018","15.8090"
"9.5200","2.3491","2.3491","1.5660","4.3517","15.9925"
"9.6000","2.3694","2.3694","1.5796","4.4037","16.1836"
"9.6800","2.3909","2.3909","1.5939","4.4589","16.3863"
"9.7600","2.4096","2.4096","1.6064","4.5050","16.5560"
"9.8400","2.4298","2.4298","1.6199","4.5570","16.7471"
"9.9200","2.4498","2.4498","1.6332","4.6102","16.9423"
"10.0000","2.4690","2.4690","1.6460","4.6642","17.1409"
"10.0800","2.4900","2.4900","1.6600","4.7168","17.3343"
"10.1600","2.5083","2.5083","1.6722","4.7651","17.5116"
"10.2400","2.5290","2.5290","1.6860","4.8159","17.6983"
"10.3200","2.5502","2.5502","1.7002","4.8729","17.9078"
"10.4000","2.5698","2.5698","1.7132","4.9281","18.1108"
"10.4800","2.5896","2.5896","1.7264","4.9785","18.2959"
"10.5600","2.6093","2.6093","1.7395","5.0288","18.4807"
"10.6400","2.6284","2.6284","1.7523","5.0815","18.6744"
"10.7200","2.6497","2.6497","1.7665","5.1374","18.8799"
"10.8000","2.6690","2.6690","1.7794","5.1873","19.0632"
"10.8800","2.6902","2.6902","1.7935","5.2425","19.2662"
"10.9600","2.7106","2.7106","1.8071","5.2966","19.4650"
"11.0400","2.7300","2.7300","1.8200","5.3493","19.6587"
"11.1200","2.7492","2.7492","1.8328","5.3969","19.8338"
"11.2000","2.7691","2.7691","1.8461","5.4506","20.0310"
"11.2800","2.7894","2.7894","1.8596","5.5072","20.2388"
"11.3600","2.8096","2.8096","1.8731","5.5593","20.4303"
"11.4400","2.8280","2.8280","1.8853","5.6099","20.6165"
"11.5200","2.8498","2.8498","1.8999","5.6726","20.8467"
"11.6000","2.8704","2.8704","1.9136","5.7257","21.0420"
"11.6800","2.8900","2.8900","1.9267","5.7765","21.2286"
"11.7600","2.9091","2.9091","1.9394","5.8262","21.4113"
"11.8400","2.9285","2.9285","1.9523","5.8774","21.5994"
"11.9200","2.9496","2.9496","1.9664","5.9333","21.8051"
"12.0000","2.9698","2.9698","1.9799","5.9884","22.0074"
"12.0800","2.9895","2.9895","1.9930","6.0464","22.2205"
"12.1600","3.0100","3.0100","2.0067","6.1016","22.4235"
"12.2400","3.0299","3.0299","2.0199","6.1565","22.6251"
"12.3200","3.0499","3.0499","2.0333","6.2087","22.8168"
"12.4000","3.0700","3.0700","2.0467","6.2634","23.0180"
"12.4800","3.0888","3.0888","2.0592","6.3134","23.2018"
"12.5600","3.1094","3.1094","2.0729","6.3699","23.4094"
"12.6400","3.1287","3.1287","2.0858","6.4224","23.6023"
"12.7200","3.1487","3.1487","2.0991","6.4779","23.8061"
"12.8000","3.1698","3.1698","2.1132","6.5379","24.0268"
"12.8800","3.1899","3.1899","2.1266","6.5912","24.2228"
"12.9600","3.2097","3.2097","2.1398","6.6445","24.4184"
"13.0400","3.2295","3.2295","2.1530","6.6984","24.6165"
"13.1200","3.2486","3.2486","2.1658","6.7506","24.8083"
"13.2000","3.2697","3.2697","2.1798","6.8105","25.0287"
"13.2800","3.2890","3.2890","2.1927","6.8624","25.2195"
"13.3600","3.3099","3.3099","2.2066","6.9198","25.4304"
"13.4400","3.3307","3.3307","2.2204","6.9747","25.6319"
"13.5200","3.3495","3.3495","2.2330","7.0277","25.8268"
"13.6000","3.3696","3.3696","2.2464","7.0832","26.0307"
"13.6800","3.3895","3.3895","2.2596","7.1373","26.2295"
"13.7600","3.4091","3.4091","2.2727","7.1947","26.4406"
"13.8400","3.4292","3.4292","2.2862","7.2485","26.6384"
"13.9200","3.4484","3.4484","2.2989","7.3003","26.8286"
"14.0000","3.4693","3.4693","2.3128","7.3569","27.0368"
"14.0800","3.4904","3.4904","2.3270","7.4162","27.2545"
"14.1600","3.5094","3.5094","2.3396","7.4692","27.4493"
"14.2400","3.5294","3.5294","2.3529","7.5263","27.6591"
"14.3200","3.5486","3.5486","2.3657","7.5773","27.8466"
"14.4000","3.5695","3.5695","2.3797","7.6368","28.0653"
"14.4800","3.5898","3.5898","2.3932","7.6912","28.2651"
"14.5600","3.6089","3.6089","2.4059","7.7435","28.4574"
"14.6400","3.6296","3.6296","2.4197","7.7984","28.6593"
"14.7200","3.6501","3.6501","2.4334","7.8545","28.8653"
"14.8000","3.6701","3.6701","2.4467","7.9101","29.0694"
"14.8800","3.6902","3.6902","2.4601","7.9663","29.2761"
"14.9600","3.7089","3.7089","2.4726","8.0175","29.4642"
"15.0400","3.7292","3.7292","2.4861","8.0739","29.6714"
"15.1200","3.7492","3.7492","2.4994","8.1307","29.8805"
"15.2000","3.7686","3.7686","2.5124","8.1862","30.0843"
"15.2800","3.7897","3.7897","2.5265","8.2460","30.3042"
"15.3600","3.8101","3.8101","2.5400","8.3040","30.5174"
"15.4400","3.8296","3.8296","2.5531","8.3551","30.7050"
"15.5200","3.8494","3.8494","2.5663","8.4096","30.9054"
"15.6000","3.8684","3.8684","2.5789","8.4657","31.1113"
"15.6800","3.8900","3.8900","2.5933","8.5261","31.3333"
"15.7600","3.9096","3.9096","2.6064","8.5807","31.5339"
"15.8400","3.9292","3.9292","2.6195","8.6371","31.7414"
"15.9200","3.9500","3.9500","2.6333","8.6977","31.9641"
"16.0000","3.9699","3.9699","2.6466","8.7490","32.1526"
"16.0800","3.9904","3.9904","2.6602","8.8051","32.3589"
"16.1600","4.0100","4.0100","2.6733","8.8585","32.5549"
"16.2400","4.0286","4.0286","2.6858","8.9123","32.7527"
"16.3200","4.0488","4.0488","2.6992","8.9724","32.9734"
"16.4000","4.0689","4.0689","2.7126","9.0249","33.1664"
"16.4800","4.0892","4.0892","2.7262","9.0851","33.3878"
"16.5600","4.1106","4.1106","2.7404","9.1455","33.6097"
"16.6400","4.1294","4.1294","2.7530","9.1991","33.8068"
"16.7200","4.1498","4.1498","2.7666","9.2570","34.0196"
"16.8000","4.1694","4.1694","2.7796","9.3117","34.2206"
"16.8800","4.1891","4.1891","2.7927","9.3678","34.4265"
"16.9600","4.2092","4.2092","2.8061","9.4258","34.6400"
"17.0400","4.2290","4.2290","2.8194","9.4799","34.8388"
"17.1200","4.2494","4.2494","2.8329","9.5365","35.0466"
"17.2000","4.2708","4.2708","2.8472","9.6007","35.2826"
"17.2800","4.2902","4.2902","2.8601","9.6582","35.4939"
"17.3600","4.3100","4.3100","2.8733","9.7158","35.7054"
"17.4400","4.3288","4.3288","2.8858","9.7656","35.8887"
"17.5200","4.3489","4.3489","2.8993","9.8233","36.1008"
"17.6000","4.3694","4.3694","2.9129","9.8831","36.3206"
"17.6800","4.3884","4.3884","2.9256","9.9363","36.5159"
"17.7600","4.4092","4.4092","2.9395","9.9937","36.7268"
"17.8400","4.4300","4.4300","2.9534","10.0530","36.9448"
"17.9200","4.4496","4.4496","2.9664","10.1096","37.1528"
"18.0000","4.4699","4.4699","2.9799","10.1669","37.3633"
"18.0800","4.4896","4.4896","2.9931","10.2258","37.5796"
"18.1600","4.5097","4.5097","3.0064","10.2848","37.7966"
"18.2400","4.5295","4.5295","3.0197","10.3363","37.9859"
"18.3200","4.5482","4.5482","3.0321","10.3914","38.1885"
"18.4000","4.5705","4.5705","3.0470","10.4577","38.4322"
"18.4800","4.5905","4.5905","3.0603","10.5149","38.6422"
"18.5600","4.6104","4.6104","3.0736","10.5706","38.8471"
"18.6400","4.6299","4.6299","3.0866","10.6259","39.0504"
"18.7200","4.6487","4.6487","3.0991","10.6804","39.2503"
"18.8000","4.6694","4.6694","3.1130","10.7406","39.4719"
"18.8800","4.6895","4.6895","3.1263","10.7971","39.6792"
"18.9600","4.7085","4.7085","3.1390","10.8541","39.8889"
"19.0400","4.7294","4.7294","3.1529","10.9159","40.1159"
"19.1200","4.7496","4.7496","3.1664","10.9708","40.3176"
"19.2000","4.7705","4.7705","3.1803","11.0319","40.5423"
"19.2800","4.7901","4.7901","3.1934","11.0876","40.7469"
"19.3600","4.8089","4.8089","3.2059","11.1405","40.9413"
"19.4400","4.8287","4.8287","3.2191","11.1973","41.1502"
"19.5200","4.8490","4.8490","3.2327","11.2578","41.3725"
"19.6000","4.8698","4.8698","3.2465","11.3186","41.5958"
"19.6800","4.8911","4.8911","3.2607","11.3828","41.8316"
"19.7600","4.9099","4.9099","3.2732","11.4338","42.0193"
"19.8400","4.9298","4.9298","3.2865","11.4911","42.2299"
"19.9200","4.9494","4.9494","3.2996","11.5485","42.4407"
"20.0000","4.9689","4.9689","3.3126","11.6054","42.6500"
"20.0800","4.9894","4.9895","3.3263","11.6655","42.8706"
"20.1600","5.0084","5.0084","3.3389","11.7195","43.0692"
"20.2400","5.0289","5.0289","3.3526","11.7778","43.2834"
"20.3200","5.0499","5.0499","3.3666","11.8396","43.5105"
"20.4000","5.0696","5.0696","3.3797","11.8991","43.7292"
"20.4800","5.0897","5.0897","3.3931","11.9592","43.9499"
"20.5600","5.1094","5.1094","3.4063","12.0154","44.1566"
"20.6400","5.1290","5.1290","3.4194","12.0714","44.3623"
"20.7200","5.1497","5.1497","3.4331","12.1318","44.5843"
"20.8000","5.1681","5.1681","3.4454","12.1840","44.7762"
"20.8800","5.1902","5.1902","3.4601","12.2487","45.0138"
"20.9600","5.2107","5.2107","3.4738","12.3088","45.2348"
"21.0400","5.2301","5.2301","3.4868","12.3663","45.4463"
"21.1200","5.2492","5.2492","3.4995","12.4220","45.6508"
"21.2000","5.2693","5.2693","3.5129","12.4825","45.8732"
"21.2800","5.2896","5.2896","3.5264","12.5419","46.0916"
"21.3600","5.3098","5.3098","3.5399","12.5998","46.3042"
"21.4400","5.3283","5.3283","3.5522","12.6533","46.5008"
"21.5200","5.3495","5.3495","3.5664","12.7185","46.7406"
"21.6000","5.3702","5.3702","3.5801","12.7799","46.9662"
"21.6800","5.3896","5.3896","3.5931","12.8389","47.1828"
"21.7600","5.4092","5.4092","3.6061","12.8908","47.3736"
"21.8400","5.4284","5.4284","3.6189","12.9484","47.5852"
"21.9200","5.4496","5.4496","3.6331","13.0102","47.8124"
"22.0000","5.4698","5.4698","3.6465","13.0700","48.0322"
"22.0800","5.4897","5.4897","3.6598","13.1309","48.2560"
"22.1600","5.5101","5.5101","3.6734","13.1920","48.4807"
"22.2400","5.5296","5.5296","3.6864","13.2470","48.6828"
"22.3200","5.5500","5.5500","3.7000","13.3059","48.8991"
"22.4000","5.5701","5.5701","3.7134","13.3670","49.1238"
"22.4800","5.5888","5.5888","3.7259","13.4227","49.3283"
"22.5600","5.6097","5.6097","3.7398","13.4843","49.5547"
"22.6400","5.6285","5.6285","3.7524","13.5393","49.7571"
"22.7200","5.6485","5.6485","3.7656","13.5996","49.9785"
"22.8000","5.6700","5.6700","3.7800","13.6644","50.2167"
"22.8800","5.6900","5.6900","3.7934","13.7210","50.4247"
"22.9600","5.7096","5.7096","3.8064","13.7793","50.6389"
"23.0400","5.7296","5.7296","3.8197","13.8355","50.8453"
"23.1200","5.7479","5.7479","3.8319","13.8913","51.0506"
"23.2000","5.7697","5.7697","3.8465","13.9592","51.3000"
"23.2800","5.7893","5.7893","3.8595","14.0181","51.5164"
"23.3600","5.8104","5.8104","3.8736","14.0782","51.7375"
"23.4400","5.8304","5.8304","3.8869","14.1363","51.9508"
"23.5200","5.8494","5.8494","3.8996","14.1942","52.1637"
"23.6000","5.8699","5.8699","3.9132","14.2550","52.3873"
"23.6800","5.8899","5.8899","3.9266","14.3142","52.6048"
"23.7600","5.9092","5.9092","3.9395","14.3708","52.8125"
"23.8400","5.9290","5.9290","3.9527","14.4294","53.0280"
"23.9200","5.9483","5.9483","3.9655","14.4862","53.2367"
"24.0000","5.9694","5.9694","3.9796","14.5496","53.4699"
"24.0800","5.9906","5.9906","3.9937","14.6130","53.7029"
"24.1600","6.0093","6.0093","4.0062","14.6702","53.9130"
"24.2400","6.0297","6.0297","4.0198","14.7298","54.1321"
"24.3200","6.0485","6.0485","4.0324","14.7864","54.3399"
"24.4000","6.0699","6.0699","4.0466","14.8519","54.5808"
"24.4800","6.0898","6.0898","4.0599","14.9097","54.7933"
"24.5600","6.1090","6.1090","4.0727","14.9669","55.0034"
"24.6400","6.1295","6.1295","4.0863","15.0313","55.2400"
"24.7200","6.1505","6.1505","4.1003","15.0926","55.4652"
"24.8000","6.1700","6.1700","4.1133","15.1525","55.6855"
"24.8800","6.1901","6.1901","4.1267","15.2132","55.9084"
"24.9600","6.2085","6.2085","4.1390","15.2658","56.1017"
"25.0400","6.2292","6.2292","4.1528","15.3268","56.3258"
"25.1200","6.2493","6.2493","4.1662","15.3877","56.5497"
"25.2000","6.2684","6.2684","4.1790","15.4464","56.7654"
"25.2800","6.2894","6.2894","4.1930","15.5120","57.0066"
"25.3600","6.3103","6.3103","4.2069","15.5760","57.2417"
"25.4400","6.3299","6.3299","4.2199","15.6331","57.4517"
"25.5200","6.3500","6.3500","4.2334","15.6937","57.6742"
"25.6000","6.3686","6.3686","4.2457","15.7504","57.8829"
"25.6800","6.3895","6.3895","4.2597","15.8138","58.1156"
"25.7600","6.4096","6.4096","4.2730","15.8764","58.3458"
"25.8400","6.4291","6.4291","4.2861","15.9341","58.5577"
"25.9200","6.4497","6.4497","4.2998","15.9988","58.7957"
"26.0000","6.4698","6.4698","4.3132","16.0554","59.0034"
"26.0800","6.4907","6.4907","4.3271","16.1198","59.2404"
"26.1600","6.5100","6.5100","4.3400","16.1784","59.4555"
"26.2400","6.5284","6.5284","4.3523","16.2346","59.6620"
"26.3200","6.5484","6.5484","4.3656","16.2973","59.8925"
"26.4000","6.5692","6.5692","4.3794","16.3585","60.1176"
"26.4800","6.5891","6.5891","4.3928","16.4200","60.3437"
"26.5600","6.6106","6.6106","4.4071","16.4854","60.5839"
"26.6400","6.6294","6.6294","4.4196","16.5441","60.7997"
"26.7200","6.6498","6.6498","4.4332","16.6037","61.0188"
"26.8000","6.6692","6.6692","4.4462","16.6640","61.2400"
"26.8800","6.6889","6.6889","4.4593","16.7266","61.4703"
"26.9600","6.7093","6.7093","4.4729","16.7914","61.7084"
"27.0400","6.7291","6.7291","4.4861","16.8489","61.9198"
"27.1200","6.7494","6.7494","4.4996","16.9105","62.1459"
"27.2000","6.7711","6.7711","4.5141","16.9765","62.3886"
"27.2800","6.7902","6.7902","4.5268","17.0379","62.6144"
"27.3600","6.8101","6.8101","4.5401","17.0995","62.8408"
"27.4400","6.8286","6.8286","4.5524","17.1531","63.0377"
"27.5200","6.8489","6.8489","4.5659","17.2174","63.2739"
"27.6000","6.8695","6.8695","4.5797","17.2808","63.5069"
"27.6800","6.8887","6.8887","4.5924","17.3405","63.7264"
"27.7600","6.9092","6.9092","4.6061","17.4012","63.9495"
"27.8400","6.9299","6.9299","4.6200","17.4676","64.1933"
"27.9200","6.9495","6.9495","4.6330","17.5298","64.4222"
"28.0000","6.9699","6.9699","4.6466","17.5918","64.6498"
"28.0800","6.9892","6.9892","4.6595","17.6500","64.8639"
"28.1600","7.0095","7.0095","4.6730","17.7119","65.0912"
"28.2400","7.0297","7.0297","4.6865","17.7725","65.3139"
"28.3200","7.0480","7.0480","4.6986","17.8314","65.5304"
"28.4000","7.0703","7.0703","4.7135","17.9037","65.7959"
"28.4800","7.0905","7.0905","4.7270","17.9658","66.0242"
"28.5600","7.1104","7.1104","4.7403","18.0248","66.2412"
"28.6400","7.1296","7.1296","4.7531","18.0854","66.4639"
"28.7200","7.1486","7.1486","4.7658","18.1424","66.6734"
"28.8000","7.1693","7.1693","4.7796","18.2088","66.9172"
"28.8800","7.1897","7.1897","4.7931","18.2694","67.1399"
"28.9600","7.2084","7.2084","4.8056","18.3298","67.3620"
"29.0400","7.2293","7.2293","4.8195","18.3956","67.6038"
"29.1200","7.2495","7.2495","4.8330","18.4601","67.8408"
"29.2000","7.2705","7.2705","4.8470","18.5249","68.0790"
"29.2800","7.2901","7.2901","4.8601","18.5851","68.3001"
"29.3600","7.3087","7.3087","4.8725","18.6450","68.5205"
"29.4400","7.3291","7.3291","4.8861","18.7095","68.7575"
"29.5200","7.3494","7.3494","4.8996","18.7698","68.9789"
"29.6000","7.3698","7.3698","4.9132","18.8357","69.2211"
"29.6800","7.3907","7.3907","4.9271","18.9031","69.4688"
"29.7600","7.4097","7.4097","4.9398","18.9595","69.6760"
"29.8400","7.4299","7.4299","4.9533","19.0254","69.9184"
"29.9200","7.4498","7.4498","4.9665","19.0847","70.1362"
"30.0000","7.4689","7.4689","4.9793","19.1478","70.3683"
"30.0800","7.4894","7.4894","4.9929","19.2112","70.6012"
"30.1600","7.5083","7.5083","5.0055","19.2688","70.8128"
"30.2400","7.5292","7.5292","5.0195","19.3340","71.0524"
"30.3200","7.5500","7.5500","5.0333","19.4020","71.3022"
"30.4000","7.5700","7.5700","5.0466","19.4657","71.5363"
"30.4800","7.5899","7.5899","5.0599","19.5273","71.7629"
"30.5600","7.6094","7.6094","5.0729","19.5889","71.9893"
"30.6400","7.6287","7.6287","5.0858","19.6499","72.2136"
"30.7200","7.6495","7.6495","5.0997","19.7175","72.4617"
"30.8000","7.6688","7.6688","5.1125","19.7779","72.6838"
"30.8800","7.6906","7.6906","5.1271","19.8487","72.9441"
"30.9600","7.7102","7.7102","5.1401","19.9084","73.1635"
"31.0400","7.7297","7.7297","5.1531","19.9701","73.3901"
"31.1200","7.7498","7.7498","5.1665","20.0360","73.6322"
"31.2000","7.7691","7.7691","5.1794","20.0939","73.8450"
"31.2800","7.7895","7.7895","5.1930","20.1599","74.0875"
"31.3600","7.8099","7.8099","5.2066","20.2251","74.3273"
"31.4400","7.8279","7.8279","5.2186","20.2830","74.5400"
"31.5200","7.8494","7.8494","5.2329","20.3554","74.8063"
"31.6000","7.8701","7.8701","5.2468","20.4212","75.0479"
"31.6800","7.8904","7.8904","5.2602","20.4873","75.2907"
"31.7600","7.9098","7.9098","5.2732","20.5488","75.5170"
"31.8400","7.9285","7.9285","5.2857","20.6058","75.7263"
"31.9200","7.9491","7.9491","5.2994","20.6703","75.9633"
"32.0000","7.9697","7.9697","5.3131","20.7397","76.2185"
"32.0800","7.9893","7.9893","5.3262","20.8035","76.4528"
"32.1600","8.0104","8.0104","5.3403","20.8757","76.7181"
"32.2400","8.0298","8.0298","5.3532","20.9369","76.9433"
"32.3200","8.0498","8.0498","5.3665","20.9987","77.1703"
"32.4000","8.0700","8.0700","5.3800","21.0635","77.4085"
"32.4800","8.0887","8.0887","5.3924","21.1245","77.6327"
"32.5600","8.1095","8.1095","5.4063","21.1915","77.8786"
"32.6400","8.1285","8.1285","5.4190","21.2541","78.1089"
"32.7200","8.1486","8.1486","5.4324","21.3180","78.3435"
"32.8000","8.1696","8.1696","5.4464","21.3886","78.6030"
"32.8800","8.1900","8.1900","5.4600","21.4557","78.8497"
"32.9600","8.2099","8.2099","5.4733","21.5169","79.0744"
"33.0400","8.2299","8.2299","5.4866","21.5819","79.3136"
"33.1200","8.2482","8.2482","5.4988","21.6414","79.5322"
"33.2000","8.2695","8.2695","5.5130","21.7150","79.8028"
"33.2800","8.2890","8.2890","5.5260","21.7752","80.0240"
"33.3600","8.3100","8.3100","5.5400","21.8431","80.2732"
"33.4400","8.3301","8.3301","5.5534","21.9082","80.5125"
"33.5200","8.3495","8.3495","5.5663","21.9721","80.7474"
"33.6000","8.3698","8.3698","5.5798","22.0402","80.9978"
"33.6800","8.3898","8.3898","5.5932","22.1059","81.2393"
"33.7600","8.4090","8.4090","5.6060","22.1646","81.4548"
"33.8400","8.4290","8.4290","5.6193","22.2324","81.7039"
"33.9200","8.4483","8.4483","5.6322","22.2946","81.9328"
"34.0000","8.4695","8.4695","5.6464","22.3647","82.1901"
"34.0800","8.4905","8.4905","5.6603","22.4335","82.4429"
"34.1600","8.5097","8.5097","5.6731","22.4999","82.6871"
"34.2400","8.5298","8.5298","5.6866","22.5648","82.9255"
"34.3200","8.5489","8.5489","5.6993","22.6263","83.1516"
"34.4000","8.5694","8.5694","5.7129","22.6946","83.4026"
"34.4800","8.5897","8.5897","5.7265","22.7616","83.6489"
"34.5600","8.6089","8.6089","5.7392","22.8258","83.8846"
"34.6400","8.6296","8.6296","5.7530","22.8923","84.1293"
"34.7200","8.6505","8.6505","5.7670","22.9631","84.3894"
"34.8000","8.6700","8.6700","5.7800","23.0263","84.6217"
"34.8800","8.6902","8.6902","5.7935","23.0901","84.8562"
"34.9600","8.7085","8.7085","5.8057","23.1526","85.0857"
"35.0400","8.7291","8.7291","5.8194","23.2209","85.3368"
"35.1200","8.7489","8.7489","5.8326","23.2849","85.5720"
"35.2000","8.7686","8.7686","5.8458","23.3527","85.8210"
"35.2800","8.7897","8.7897","5.8598","23.4255","86.0885"
"35.3600","8.8103","8.8103","5.8735","23.4926","86.3354"
"35.4400","8.8297","8.8297","5.8864","23.5560","86.5682"
"35.5200","8.8496","8.8496","5.8998","23.6217","86.8097"
"35.6000","8.8684","8.8684","5.9122","23.6830","87.0350"
"35.6800","8.8895","8.8895","5.9263","23.7536","87.2944"
"35.7600","8.9097","8.9097","5.9398","23.8245","87.5552"
"35.8400","8.9294","8.9294","5.9529","23.8896","87.7942"
"35.9200","8.9497","8.9497","5.9664","23.9580","88.0457"
"36.0000","8.9701","8.9701","5.9801","24.0262","88.2964"
"36.0800","8.9904","8.9904","5.9936","24.0924","88.5395"
"36.1600","9.0098","9.0098","6.0065","24.1556","88.7718"
"36.2400","9.0290","9.0290","6.0193","24.2212","89.0129"
"36.3200","9.0489","9.0489","6.0326","24.2893","89.2634"
"36.4000","9.0689","9.0689","6.0459","24.3546","89.5031"
"36.4800","9.0889","9.0889","6.0593","24.4251","89.7622"
"36.5600","9.1109","9.1109","6.0739","24.4986","90.0325"
"36.6400","9.1292","9.1292","6.0861","24.5602","90.2589"
"36.7200","9.1500","9.1500","6.1000","24.6298","90.5144"
"36.8000","9.1689","9.1689","6.1126","24.6956","90.7562"
"36.8800","9.1890","9.1890","6.1260","24.7629","91.0035"
"36.9600","9.2094","9.2094","6.1396","24.8330","91.2611"
"37.0400","9.2291","9.2291","6.1528","24.8984","91.5017"
"37.1200","9.2496","9.2496","6.1664","24.9695","91.7629"
"37.2000","9.2711","9.2711","6.1807","25.0426","92.0316"
"37.2800","9.2898","9.2898","6.1932","25.1058","92.2638"
"37.3600","9.3097","9.3097","6.2065","25.1765","92.5238"
"37.4400","9.3288","9.3288","6.2192","25.2386","92.7518"
"37.5200","9.3490","9.3490","6.2327","25.3048","92.9952"
"37.6000","9.3696","9.3696","6.2464","25.3766","93.2590"
"37.6800","9.3885","9.3885","6.2590","25.4389","93.4878"
"37.7600","9.4095","9.4095","6.2730","25.5124","93.7579"
"37.8400","9.4297","9.4297","6.2865","25.5793","94.0041"
"37.9200","9.4495","9.4495","6.2997","25.6496","94.2623"
"38.0000","9.4700","9.4700","6.3133","25.7204","94.5225"
"38.0800","9.4896","9.4896","6.3264","25.7874","94.7686"
"38.1600","9.5094","9.5094","6.3396","25.8550","95.0171"
"38.2400","9.5298","9.5298","6.3532","25.9224","95.2647"
"38.3200","9.5484","9.5484","6.3656","25.9881","95.5063"
"38.4000","9.5701","9.5701","6.3801","26.0642","95.7861"
"38.4800","9.5901","9.5901","6.3934","26.1336","96.0410"
"38.5600","9.6105","9.6105","6.4070","26.2016","96.2908"
"38.6400","9.6295","9.6295","6.4196","26.2664","96.5288"
"38.7200","9.6487","9.6487","6.4325","26.3327","96.7727"
"38.8000","9.6692","9.6692","6.4461","26.4048","97.0376"
"38.8800","9.6894","9.6894","6.4596","26.4712","97.2817"
"38.9600","9.7083","9.7083","6.4722","26.5386","97.5294"
"39.0400","9.7296","9.7296","6.4864","26.6141","97.8067"
"39.1200","9.7495","9.7495","6.4996","26.6837","98.0628"
"39.2000","9.7702","9.7702","6.5135","26.7550","98.3245"
"39.2800","9.7901","9.7901","6.5268","26.8203","98.5648"
"39.3600","9.8086","9.8086","6.5391","26.8862","98.8068"
"39.4400","9.8290","9.8290","6.5527","26.9588","99.0736"
"39.5200","9.8495","9.8495","6.5663","27.0289","99.3312"
"39.6000","9.8697","9.8697","6.5798","27.1005","99.5943"
"39.6800","9.8906","9.8906","6.5937","27.1736","99.8630"
"39.7600","9.9101","9.9101","6.6067","27.2400","100.1070"
"39.8400","9.9297","9.9297","6.6198","27.3068","100.3525"
"39.9200","9.9496","9.9496","6.6331","27.3746","100.6016"
"40.0000","9.9691","9.9691","6.6461","27.4452","100.8611"
"40.0800","9.9897","9.9897","6.6598","27.5194","101.1337"
"40.1600","10.0082","10.0082","6.6721","27.5785","101.3510"
"40.2400","10.0289","10.0289","6.6859","27.6517","101.6202"
"40.3200","10.0498","10.0498","6.6999","27.7275","101.8987"
"40.4000","10.0702","10.0702","6.7135","27.8030","102.1759"
"40.4800","10.0898","10.0898","6.7266","27.8730","102.4334"
"40.5600","10.1095","10.1095","6.7397","27.9389","102.6755"
"40.6400","10.1289","10.1289","6.7526","28.0057","102.9209"
"40.7200","10.1495","10.1495","6.7663","28.0784","103.1882"
"40.8000","10.1686","10.1686","6.7791","28.1461","103.4371"
"40.8800","10.1903","10.1903","6.7935","28.2240","103.7231"
"40.9600","10.2104","10.2104","6.8069","28.2936","103.9791"
"41.0400","10.2297","10.2297","6.8198","28.3615","104.2285"
"41.1200","10.2490","10.2490","6.8326","28.4319","104.4873"
"41.2000","10.2693","10.2693","6.8462","28.5006","104.7398"
"41.2800","10.2893","10.2893","6.8596","28.5715","105.0002"
"41.3600","10.3097","10.3097","6.8731","28.6431","105.2636"
"41.4400","10.3281","10.3281","6.8854","28.7094","105.5069"
"41.5200","10.3495","10.3495","6.8997","28.7886","105.7979"
"41.6000","10.3705","10.3705","6.9137","28.8620","106.0680"
"41.6800","10.3898","10.3898","6.9265","28.9300","106.3179"
"41.7600","10.4093","10.4093","6.9396","28.9993","106.5724"
"41.8400","10.4287","10.4287","6.9525","29.0664","106.8192"
"41.9200","10.4493","10.4493","6.9662","29.1426","107.0990"
"42.0000","10.4698","10.4698","6.9799","29.2163","107.3697"
"42.0800","10.4896","10.4896","6.9930","29.2885","107.6353"
"42.1600","10.5098","10.5098","7.0065","29.3612","107.9024"
"42.2400","10.5295","10.5295","7.0197","29.4266","108.1428"
"42.3200","10.5499","10.5499","7.0333","29.5049","108.4304"
"42.4000","10.5705","10.5705","7.0470","29.5764","108.6932"
"42.4800","10.5892","10.5892","7.0594","29.6456","108.9475"
"42.5600","10.6094","10.6094","7.0729","29.7169","109.2095"
"42.6400","10.6284","10.6284","7.0856","29.7839","109.4560"
"42.7200","10.6489","10.6489","7.0992","29.8591","109.7321"
"42.8000","10.6701","10.6701","7.1134","29.9384","110.0237"
"42.8800","10.6902","10.6902","7.1268","30.0099","110.2864"
"42.9600","10.7096","10.7096","7.1397","30.0772","110.5336"
"43.0400","10.7297","10.7297","7.1531","30.1471","110.7905"
"43.1200","10.7481","10.7481","7.1654","30.2173","111.0485"
"43.2000","10.7695","10.7695","7.1797","30.2970","111.3414"
"43.2800","10.7891","10.7891","7.1928","30.3649","111.5911"
"43.3600","10.8098","10.8098","7.2065","30.4384","111.8610"
"43.4400","10.8302","10.8302","7.2202","30.5124","112.1331"
"43.5200","10.8497","10.8497","7.2331","30.5805","112.3835"
"43.6000","10.8693","10.8693","7.2462","30.6508","112.6416"
"43.6800","10.8896","10.8896","7.2597","30.7272","112.9224"
"43.7600","10.9096","10.9096","7.2730","30.7975","113.1809"
"43.8400","10.9294","10.9294","7.2863","30.8712","113.4516"
"43.9200","10.9483","10.9483","7.2989","30.9401","113.7048"
"44.0000","10.9694","10.9694","7.3130","31.0165","113.9855"
"44.0800","10.9906","10.9906","7.3271","31.0950","114.2741"
"44.1600","11.0096","11.0096","7.3398","31.1635","114.5259"
"44.2400","11.0297","11.0297","7.3531","31.2346","114.7872"
"44.3200","11.0488","11.0488","7.3659","31.3054","115.0472"
"44.4000","11.0698","11.0698","7.3799","31.3818","115.3283"
"44.4800","11.0898","11.0898","7.3932","31.4550","115.5971"
"44.5600","11.1091","11.1091","7.4061","31.5251","115.8547"
"44.6400","11.1299","11.1299","7.4199","31.6051","116.1488"
"44.7200","11.1506","11.1506","7.4337","31.6808","116.4271"
"44.8000","11.1697","11.1697","7.4465","31.7503","116.6822"
"44.8800","11.1901","11.1901","7.4601","31.8258","116.9600"
"44.9600","11.2088","11.2088","7.4725","31.8934","117.2084"
"45.0400","11.2293","11.2293","7.4862","31.9661","117.4755"
"45.1200","11.2484","11.2484","7.4989","32.0340","117.7249"
"45.2000","11.2684","11.2684","7.5122","32.1112","118.0086"
"45.2800","11.2899","11.2899","7.5266","32.1928","118.3085"
"45.3600","11.3103","11.3103","7.5402","32.2680","118.5849"
"45.4400","11.3297","11.3297","7.5531","32.3391","118.8463"
"45.5200","11.3497","11.3497","7.5665","32.4124","119.1156"
"45.6000","11.3686","11.3686","7.5791","32.4828","119.3743"
"45.6800","11.3893","11.3893","7.5929","32.5611","119.6621"
"45.7600","11.4096","11.4096","7.6064","32.6366","119.9396"
"45.8400","11.4291","11.4291","7.6194","32.7070","120.1981"
"45.9200","11.4500","11.4500","7.6333","32.7883","120.4969"
"46.0000","11.4699","11.4699","7.6466","32.8605","120.7622"
"46.0800","11.4902","11.4902","7.6601","32.9344","121.0338"
"46.1600","11.5096","11.5096","7.6731","33.0063","121.2983"
"46.2400","11.5292","11.5292","7.6861","33.0805","121.5708"
"46.3200","11.5488","11.5488","7.6992","33.1547","121.8437"
"46.4000","11.5686","11.5686","7.7124","33.2281","122.1132"
"46.4800","11.5892","11.5892","7.7261","33.3067","122.4021"
"46.5600","11.6105","11.6105","7.7403","33.3866","122.6957"
"46.6400","11.6294","11.6294","7.7529","33.4568","122.9536"
"46.7200","11.6497","11.6497","7.7664","33.5315","123.2282"
"46.8000","11.6694","11.6694","7.7796","33.6071","123.5062"
"46.8800","11.6894","11.6894","7.7929","33.6850","123.7925"
"46.9600","11.7094","11.7094","7.8063","33.7608","124.0711"
"47.0400","11.7290","11.7290","7.8193","33.8333","124.3372"
"47.1200","11.7495","11.7495","7.8330","33.9084","124.6135"
"47.2000","11.7712","11.7712","7.8475","33.9948","124.9311"
"47.2800","11.7901","11.7901","7.8601","34.0640","125.1851"
"47.3600","11.8099","11.8099","7.8732","34.1372","125.4541"
"47.4400","11.8290","11.8290","7.8860","34.2085","125.7162"
"47.5200","11.8489","11.8489","7.8993","34.2847","125.9964"
"47.6000","11.8694","11.8694","7.9130","34.3623","126.2814"
"47.6800","11.8885","11.8885","7.9257","34.4356","126.5510"
"47.7600","11.9098","11.9098","7.9398","34.5166","126.8484"
"47.8400","11.9302","11.9302","7.9534","34.5961","127.1406"
"47.9200","11.9493","11.9493","7.9662","34.6669","127.4010"
"48.0000","11.9696","11.9696","7.9798","34.7451","127.6884"
"48.0800","11.9891","11.9891","7.9928","34.8162","127.9497"
"48.1600","12.0094","12.0094","8.0063","34.8943","128.2364"
"48.2400","12.0298","12.0298","8.0199","34.9708","128.5175"
"48.3200","12.0486","12.0486","8.0324","35.0443","128.7878"
"48.4000","12.0699","12.0699","8.0466","35.1274","129.0931"
"48.4800","12.0900","12.0900","8.0600","35.2040","129.3746"
"48.5600","12.1107","12.1107","8.0738","35.2837","129.6675"
"48.6400","12.1296","12.1296","8.0864","35.3556","129.9317"
"48.7200","12.1489","12.1489","8.0993","35.4283","130.1990"
"48.8000","12.1692","12.1692","8.1128","35.5068","130.4875"
"48.8800","12.1888","12.1888","8.1259","35.5774","130.7468"
"48.9600","12.2082","12.2082","8.1388","35.6541","131.0287"
"49.0400","12.2298","12.2298","8.1532","35.7395","131.3427"
"49.1200","12.2493","12.2493","8.1662","35.8137","131.6155"
"49.2000","12.2705","12.2705","8.1803","35.8959","131.9173"
"49.2800","12.2900","12.2900","8.1934","35.9713","132.1946"
"49.3600","12.3090","12.3090","8.2060","36.0448","132.4647"
"49.4400","12.3289","12.3289","8.2193","36.1220","132.7483"
"49.5200","12.3493","12.3493","8.2329","36.2027","133.0451"
"49.6000","12.3697","12.3697","8.2465","36.2805","133.3309"
"49.6800","12.3908","12.3908","8.2605","36.3626","133.6325"
"49.7600","12.4098","12.4098","8.2732","36.4338","133.8943"
"49.8400","12.4299","12.4299","8.2866","36.5127","134.1843"
"49.9200","12.4495","12.4495","8.2997","36.5882","134.4616"
"50.0000","12.4688","12.4688","8.3125","36.6641","134.7407"
"50.0800","12.4895","12.4895","8.3263","36.7462","135.0422"
"50.1600","12.5084","12.5084","8.3389","36.8157","135.2976"
"50.2400","12.5289","12.5289","8.3526","36.8924","135.5797"
"50.3200","12.5501","12.5501","8.3667","36.9792","135.8986"
"50.4000","12.5699","12.5699","8.3799","37.0551","136.1774"
"50.4800","12.5896","12.5896","8.3931","37.1327","136.4626"
"50.5600","12.6096","12.6096","8.4064","37.2112","136.7511"
"50.6400","12.6287","12.6287","8.4191","37.2849","137.0222"
"50.7200","12.6495","12.6495","8.4330","37.3686","137.3295"
"50.8000","12.6687","12.6687","8.4458","37.4396","137.5904"
"50.8800","12.6904","12.6904","8.4603","37.5282","137.9162"
"50.9600","12.7105","12.7105","8.4736","37.6089","138.2126"
"51.0400","12.7300","12.7300","8.4867","37.6865","138.4980"
"51.1200","12.7496","12.7496","8.4997","37.7646","138.7849"
"51.2000","12.7692","12.7692","8.5128","37.8391","139.0586"
"51.2800","12.7897","12.7897","8.5265","37.9204","139.3575"
"51.3600","12.8096","12.8096","8.5397","37.9961","139.6355"
"51.4400","12.8277","12.8277","8.5518","38.0668","139.8956"
"51.5200","12.8497","12.8497","8.5665","38.1595","140.2360"
"51.6000","12.8702","12.8702","8.5802","38.2393","140.5293"
"51.6800","12.8900","12.8900","8.5934","38.3152","140.8083"
"51.7600","12.9092","12.9092","8.6061","38.3899","141.0831"
"51.8400","12.9283","12.9283","8.6189","38.4627","141.3504"
"51.9200","12.9491","12.9491","8.6328","38.5461","141.6569"
"52.0000","12.9700","12.9700","8.6466","38.6298","141.9645"
"52.0800","12.9896","12.9896","8.6597","38.7090","142.2557"
"52.1600","13.0102","13.0102","8.6735","38.7963","142.5763"
"52.2400","13.0300","13.0300","8.6867","38.8709","142.8507"
"52.3200","13.0498","13.0498","8.6999","38.9486","143.1361"
"52.4000","13.0700","13.0700","8.7133","39.0277","143.4268"
"52.4800","13.0889","13.0889","8.7259","39.1030","143.7034"
"52.5600","13.1095","13.1095","8.7397","39.1867","144.0110"
"52.6400","13.1287","13.1287","8.7524","39.2601","144.2809"
"52.7200","13.1487","13.1487","8.7658","39.3412","144.5788"
"52.8000","13.1695","13.1695","8.7797","39.4266","144.8929"
"52.8800","13.1900","13.1900","8.7934","39.5076","145.1904"
"52.9600","13.2099","13.2099","8.8066","39.5857","145.4773"
"53.0400","13.2296","13.2296","8.8198","39.6638","145.7643"
"53.1200","13.2485","13.2485","8.8324","39.7410","146.0483"
"53.2000","13.2695","13.2695","8.8463","39.8272","146.3648"
"53.2800","13.2892","13.2892","8.8595","39.9036","146.6459"
"53.3600","13.3102","13.3102","8.8734","39.9890","146.9596"
"53.4400","13.3306","13.3306","8.8871","40.0708","147.2601"
"53.5200","13.3495","13.3495","8.8997","40.1472","147.5411"
"53.6000","13.3697","13.3697","8.9132","40.2303","147.8462"
"53.6800","13.3897","13.3897","8.9264","40.3112","148.1436"
"53.7600","13.4091","13.4091","8.9394","40.3871","148.4226"
"53.8400","13.4291","13.4291","8.9527","40.4692","148.7243"
"53.9200","13.4482","13.4482","8.9655","40.5435","148.9973"
"54.0000","13.4695","13.4695","8.9796","40.6316","149.3210"
"54.0800","13.4906","13.4906","8.9937","40.7159","149.6310"
"54.1600","13.5092","13.5092","9.0062","40.7910","149.9070"
"54.2400","13.5295","13.5295","9.0197","40.8753","150.2166"
"54.3200","13.5488","13.5488","9.0325","40.9504","150.4928"
"54.4000","13.5698","13.5698","9.0466","41.0404","150.8235"
"54.4800","13.5901","13.5901","9.0601","41.1219","151.1229"
"54.5600","13.6086","13.6086","9.0724","41.1949","151.3913"
"54.6400","13.6296","13.6296","9.0864","41.2827","151.7138"
"54.7200","13.6503","13.6503","9.1002","41.3676","152.0261"
"54.8000","13.6702","13.6702","9.1135","41.4483","152.3223"
"54.8800","13.6902","13.6902","9.1268","41.5266","152.6104"
"54.9600","13.7087","13.7087","9.1391","41.6014","152.8851"
"55.0400","13.7291","13.7291","9.1527","41.6856","153.1947"
"55.1200","13.7490","13.7490","9.1660","41.7672","153.4946"
"55.2000","13.7684","13.7684","9.1789","41.8478","153.7907"
"55.2800","13.7897","13.7897","9.1931","41.9386","154.1242"
"55.3600","13.8102","13.8102","9.2068","42.0204","154.4249"
"55.4400","13.8300","13.8300","9.2200","42.1009","154.7208"
"55.5200","13.8497","13.8497","9.2331","42.1812","155.0159"
"55.6000","13.8685","13.8685","9.2457","42.2541","155.2839"
"55.6800","13.8897","13.8897","9.2598","42.3443","155.6153"
"55.7600","13.9096","13.9096","9.2731","42.4252","155.9127"
"55.8400","13.9290","13.9290","9.2860","42.5077","156.2158"
"55.9200","13.9502","13.9502","9.3001","42.5979","156.5475"
"56.0000","13.9700","13.9700","9.3133","42.6779","156.8412"
"56.0800","13.9904","13.9904","9.3269","42.7637","157.1565"
"56.1600","14.0101","14.0101","9.3400","42.8432","157.4488"
"56.2400","14.0288","14.0288","9.3525","42.9190","157.7272"
"56.3200","14.0486","14.0486","9.3657","42.9995","158.0231"
"56.4000","14.0684","14.0684","9.3789","43.0819","158.3261"
"56.4800","14.0890","14.0890","9.3927","43.1691","158.6464"
"56.5600","14.1107","14.1107","9.4071","43.2603","158.9814"
"56.6400","14.1293","14.1293","9.4196","43.3364","159.2612"
"56.7200","14.1495","14.1495","9.4330","43.4185","159.5629"
"56.8000","14.1692","14.1692","9.4462","43.5015","159.8681"
"56.8800","14.1895","14.1895","9.4596","43.5862","160.1791"
"56.9600","14.2090","14.2090","9.4727","43.6682","160.4805"
"57.0400","14.2286","14.2286","9.4857","43.7484","160.7755"
"57.1200","14.2497","14.2497","9.4998","43.8399","161.1116"
"57.2000","14.2708","14.2708","9.5139","43.9299","161.4422"
"57.2800","14.2900","14.2900","9.5266","44.0098","161.7359"
"57.3600","14.3096","14.3096","9.5397","44.0906","162.0329"
"57.4400","14.3288","14.3288","9.5525","44.1688","162.3202"
"57.5200","14.3490","14.3490","9.5660","44.2517","162.6251"
"57.6000","14.3694","14.3694","9.5796","44.3411","162.9536"
"57.6800","14.3882","14.3882","9.5921","44.4159","163.2285"
"57.7600","14.4095","14.4095","9.6063","44.5065","163.5615"
"57.8400","14.4303","14.4303","9.6202","44.5992","163.9022"
"57.9200","14.4496","14.4496","9.6331","44.6776","164.1902"
"58.0000","14.4697","14.4697","9.6465","44.7641","164.5080"
"58.0800","14.4896","14.4896","9.6597","44.8455","164.8073"
"58.1600","14.5096","14.5096","9.6731","44.9274","165.1082"
"58.2400","14.5295","14.5295","9.6864","45.0127","165.4216"
"58.3200","14.5486","14.5486","9.6990","45.0943","165.7214"
"58.4000","14.5701","14.5701","9.7134","45.1859","166.0581"
"58.4800","14.5905","14.5905","9.7270","45.2707","166.3699"
"58.5600","14.6103","14.6103","9.7402","45.3556","166.6819"
"58.6400","14.6295","14.6295","9.7530","45.4353","166.9747"
"58.7200","14.6482","14.6482","9.7655","45.5118","167.2560"
"58.8000","14.6693","14.6693","9.7795","45.6024","167.5887"
"58.8800","14.6896","14.6896","9.7930","45.6899","167.9104"
"58.9600","14.7082","14.7082","9.8055","45.7678","168.1967"
"59.0400","14.7295","14.7295","9.8197","45.8612","168.5399"
"59.1200","14.7494","14.7494","9.8329","45.9448","168.8471"
"59.2000","14.7703","14.7703","9.8469","46.0342","169.1756"
"59.2800","14.7901","14.7901","9.8600","46.1168","169.4792"
"59.3600","14.8089","14.8089","9.8726","46.1984","169.7791"
"59.4400","14.8290","14.8290","9.8860","46.2839","170.0932"
"59.5200","14.8489","14.8489","9.8993","46.3715","170.4152"
"59.6000","14.8695","14.8695","9.9130","46.4594","170.7384"
"59.6800","14.8910","14.8910","9.9274","46.5533","171.0833"
"59.7600","14.9098","14.9098","9.9399","46.6322","171.3733"
"59.8400","14.9297","14.9297","9.9531","46.7137","171.6727"
"59.9200","14.9494","14.9494","9.9663","46.7956","171.9740"
"60.0000","14.9688","14.9688","9.9792","46.8776","172.2752"
"60.0800","14.9896","14.9896","9.9931","46.9717","172.6209"
"60.1220","15.0000","15.0000","10.0000","47.0123","172.7703"