File: data/instron_tests/510_BULK_m1.is_comp_Exports/510_BULK_m1_3_1.csv
Sample text inputs : Sample No.,Sample choice input : Leading Direction,Sample choice input : Mode,Specimen choice input : Direction,Specimen properties : Height,Specimen properties : Thickness,Specimen properties : Width,Test : Rate 1
,,,,(mm),(mm),(mm),(mm/min)
"510","Bulk","Unimode","1","150.00","25.00","150.00","15.00"

Time,Displacement,Compressive displacement,Compressive strain (Displacement),Compressive stress,Force
(s),(mm),(mm),(%),(kPa),(N)
"0.0000","-0.0002","-0.0002","-0.0001","-0.9353","-3.4607"
"0.0800","0.0012","0.0012","0.0008","-0.9305","-3.4430"
"0.1600","0.0103","0.0103","0.0069","-0.8845","-3.2726"
"0.2400","0.0314","0.0314","0.0209","-0.7923","-2.9314"
"0.3200","0.0506","0.0506","0.0337","-0.7156","-2.6478"
"0.4000","0.0684","0.0684","0.0456","-0.6448","-2.3856"
"0.4800","0.0882","0.0882","0.0588","-0.5753","-2.1287"
"0.5600","0.1086","0.1086","0.0724","-0.5065","-1.8740"
"0.6400","0.1298","0.1298","0.0865","-0.4375","-1.6188"
"0.7200","0.1512","0.1512","0.1008","-0.3728","-1.3794"
"0.8000","0.1700","0.1700","0.1133","-0.3183","-1.1777"
"0.8800","0.1904","0.1904","0.1269","-0.2578","-0.9537"
"0.9600","0.2098","0.2098","0.1399","-0.2006","-0.7421"
"1.0400","0.2297","0.2297","0.1531","-0.1404","-0.5196"
"1.1200","0.2499","0.2499","0.1666","-0.0894","-0.3308"
"1.2000","0.2694","0.2694","0.1796","-0.0352","-0.1304"
"1.2800","0.2904","0.2904","0.1936","0.0211","0.0780"
"1.3600","0.3117","0.3117","0.2078","0.0914","0.3383"
"1.4400","0.3307","0.3307","0.2205","0.1383","0.5116"
"1.5200","0.3504","0.3504","0.2336","0.1908","0.7058"
"1.6000","0.3694","0.3694","0.2462","0.2502","0.9257"
"1.6800","0.3900","0.3900","0.2600","0.3133","1.1590"
"1.7600","0.4102","0.4102","0.2735","0.3705","1.3709"
"1.8400","0.4293","0.4293","0.2862","0.4391","1.6248"
"1.9200","0.4501","0.4501","0.3000","0.5049","1.8681"
"2.0000","0.4708","0.4708","0.3139","0.5705","2.1107"
"2.0800","0.4903","0.4903","0.3269","0.6422","2.3762"
"2.1600","0.5107","0.5107","0.3404","0.7156","2.6476"
"2.2400","0.5296","0.5296","0.3531","0.7815","2.8917"
"2.3200","0.5498","0.5498","0.3666","0.8533","3.1572"
"2.4000","0.5700","0.5700","0.3800","0.9322","3.4491"
"2.4800","0.5894","0.5894","0.3929","1.0141","3.7521"
"2.5600","0.6111","0.6111","0.4074","1.0985","4.0643"
"2.6400","0.6312","0.6312","0.4208","1.1832","4.3778"
"2.7200","0.6511","0.6511","0.4341","1.2664","4.6859"
"2.8000","0.6703","0.6703","0.4468","1.3437","4.9718"
"2.8800","0.6895","0.6895","0.4597","1.4227","5.2641"
"2.9600","0.7100","0.7100","0.4733","1.5161","5.6097"
"3.0400","0.7299","0.7299","0.4866","1.6009","5.9235"
"3.1200","0.7490","0.7490","0.4994","1.6817","6.2222"
"3.2000","0.7707","0.7707","0.5138","1.7840","6.6009"
"3.2800","0.7901","0.7901","0.5267","1.8652","6.9014"
"3.3600","0.8109","0.8109","0.5406","1.9589","7.2478"
"3.4400","0.8306","0.8306","0.5537","2.0467","7.5727"
"3.5200","0.8495","0.8495","0.5663","2.1364","7.9048"
"3.6000","0.8697","0.8697","0.5798","2.2286","8.2459"
"3.6800","0.8898","0.8898","0.5932","2.3172","8.5737"
"3.7600","0.9106","0.9106","0.6071","2.4179","8.9461"
"3.8400","0.9322","0.9322","0.6215","2.5204","9.3255"
"3.9200","0.9502","0.9502","0.6335","2.5991","9.6168"
"4.0000","0.9705","0.9705","0.6470","2.6942","9.9687"
"4.0800","0.9903","0.9903","0.6602","2.7894","10.3207"
"4.1600","1.0100","1.0100","0.6733","2.8851","10.6750"
"4.2400","1.0303","1.0303","0.6869","2.9831","11.0375"
"4.3200","1.0488","1.0488","0.6992","3.0697","11.3577"
"4.4000","1.0696","1.0696","0.7131","3.1741","11.7442"
"4.4800","1.0908","1.0908","0.7272","3.2795","12.1343"
"4.5600","1.1107","1.1107","0.7405","3.3738","12.4832"
"4.6400","1.1307","1.1307","0.7538","3.4769","12.8647"
"4.7200","1.1499","1.1499","0.7666","3.5703","13.2101"
"4.8000","1.1694","1.1694","0.7796","3.6678","13.5708"
"4.8800","1.1904","1.1904","0.7936","3.7739","13.9636"
"4.9600","1.2089","1.2089","0.8059","3.8655","14.3023"
"5.0400","1.2310","1.2310","0.8207","3.9817","14.7322"
"5.1200","1.2514","1.2514","0.8343","4.0850","15.1144"
"5.2000","1.2706","1.2706","0.8471","4.1815","15.4717"
"5.2800","1.2898","1.2898","0.8599","4.2802","15.8366"
"5.3600","1.3098","1.3098","0.8732","4.3811","16.2100"
"5.4400","1.3303","1.3303","0.8868","4.4867","16.6008"
"5.5200","1.3504","1.3504","0.9002","4.5898","16.9822"
"5.6000","1.3688","1.3688","0.9125","4.6860","17.3382"
"5.6800","1.3907","1.3907","0.9271","4.8063","17.7833"
"5.7600","1.4102","1.4102","0.9401","4.9066","18.1543"
"5.8400","1.4308","1.4308","0.9539","5.0178","18.5660"
"5.9200","1.4507","1.4507","0.9671","5.1213","18.9488"
"6.0000","1.4692","1.4692","0.9795","5.2186","19.3086"
"6.0800","1.4901","1.4901","0.9934","5.3314","19.7262"
"6.1600","1.5106","1.5106","1.0070","5.4339","20.1055"
"6.2400","1.5300","1.5300","1.0200","5.5431","20.5095"
"6.3200","1.5508","1.5508","1.0339","5.6567","20.9297"
"6.4000","1.5705","1.5705","1.0470","5.7607","21.3147"
"6.4800","1.5908","1.5908","1.0605","5.8739","21.7335"
"6.5600","1.6108","1.6108","1.0739","5.9822","22.1343"
"6.6400","1.6294","1.6294","1.0863","6.0784","22.4900"
"6.7200","1.6501","1.6501","1.1001","6.1958","22.9246"
"6.8000","1.6691","1.6691","1.1128","6.3006","23.3122"
"6.8800","1.6900","1.6900","1.1267","6.4183","23.7476"
"6.9600","1.7106","1.7106","1.1404","6.5355","24.1812"
"7.0400","1.7306","1.7306","1.1537","6.6470","24.5940"
"7.1200","1.7503","1.7503","1.1669","6.7560","24.9970"
"7.2000","1.7702","1.7702","1.1801","6.8629","25.3929"
"7.2800","1.7891","1.7891","1.1927","6.9686","25.7838"
"7.3600","1.8098","1.8098","1.2066","7.0873","26.2231"
"7.4400","1.8298","1.8298","1.2199","7.1979","26.6324"
"7.5200","1.8512","1.8512","1.2341","7.3206","27.0861"
"7.6000","1.8713","1.8713","1.2475","7.4329","27.5017"
"7.6800","1.8903","1.8903","1.2602","7.5405","27.8998"
"7.7600","1.9103","1.9103","1.2735","7.6566","28.3295"
"7.8400","1.9303","1.9303","1.2869","7.7678","28.7408"
"7.9200","1.9499","1.9499","1.2999","7.8754","29.1391"
"8.0000","1.9701","1.9701","1.3134","7.9927","29.5730"
"8.0800","1.9891","1.9891","1.3261","8.1001","29.9704"
"8.1600","2.0102","2.0102","1.3401","8.2231","30.4253"
"8.2400","2.0312","2.0312","1.3541","8.3420","30.8654"
"8.3200","2.0501","2.0501","1.3667","8.4478","31.2567"
"8.4000","2.0705","2.0705","1.3803","8.5676","31.7001"
"8.4800","2.0893","2.0893","1.3928","8.6687","32.0742"
"8.5600","2.1105","2.1105","1.4070","8.7918","32.5296"
"8.6400","2.1307","2.1307","1.4204","8.9051","32.9488"
"8.7200","2.1501","2.1501","1.4334","9.0161","33.3595"
"8.8000","2.1702","2.1702","1.4468","9.1328","33.7913"
"8.8800","2.1909","2.1909","1.4606","9.2503","34.2260"
"8.9600","2.2104","2.2104","1.4736","9.3637","34.6458"
"9.0400","2.2318","2.2318","1.4879","9.4888","35.1085"
"9.1200","2.2496","2.2496","1.4997","9.5875","35.4738"
"9.2000","2.2700","2.2700","1.5133","9.7028","35.9002"
"9.2800","2.2899","2.2899","1.5266","9.8183","36.3277"
"9.3600","2.3095","2.3095","1.5396","9.9313","36.7460"
"9.4400","2.3302","2.3302","1.5535","10.0520","37.1924"
"9.5200","2.3510","2.3510","1.5674","10.1723","37.6376"
"9.6000","2.3704","2.3704","1.5802","10.2786","38.0308"
"9.6800","2.3899","2.3899","1.5933","10.3906","38.4451"
"9.7600","2.4091","2.4091","1.6061","10.5012","38.8543"
"9.8400","2.4305","2.4305","1.6204","10.6262","39.3171"
"9.9200","2.4503","2.4503","1.6335","10.7379","39.7302"
"10.0000","2.4700","2.4700","1.6466","10.8517","40.1512"
"10.0800","2.4908","2.4908","1.6605","10.9707","40.5916"
"10.1600","2.5104","2.5104","1.6736","11.0828","41.0062"
"10.2400","2.5310","2.5310","1.6873","11.2045","41.4568"
"10.3200","2.5505","2.5505","1.7003","11.3152","41.8664"
"10.4000","2.5695","2.5695","1.7130","11.4258","42.2756"
"10.4800","2.5894","2.5894","1.7263","11.5424","42.7067"
"10.5600","2.6095","2.6095","1.7396","11.6547","43.1225"
"10.6400","2.6300","2.6300","1.7533","11.7754","43.5689"
"10.7200","2.6515","2.6515","1.7677","11.9010","44.0336"
"10.8000","2.6698","2.6698","1.7799","12.0049","44.4182"
"10.8800","2.6907","2.6907","1.7938","12.1252","44.8633"
"10.9600","2.7097","2.7097","1.8065","12.2333","45.2630"
"11.0400","2.7299","2.7299","1.8199","12.3527","45.7051"
"11.1200","2.7500","2.7500","1.8333","12.4695","46.1371"
"11.2000","2.7698","2.7698","1.8465","12.5831","46.5574"
"11.2800","2.7902","2.7902","1.8602","12.7002","46.9906"
"11.3600","2.8121","2.8121","1.8747","12.8344","47.4872"
"11.4400","2.8309","2.8309","1.8873","12.9403","47.8791"
"11.5200","2.8508","2.8508","1.9005","13.0542","48.3005"
"11.6000","2.8695","2.8695","1.9130","13.1591","48.6887"
"11.6800","2.8900","2.8900","1.9266","13.2778","49.1279"
"11.7600","2.9105","2.9105","1.9403","13.3980","49.5726"
"11.8400","2.9294","2.9294","1.9529","13.5062","49.9729"
"11.9200","2.9502","2.9502","1.9668","13.6252","50.4132"
"12.0000","2.9707","2.9707","1.9804","13.7444","50.8544"
"12.0800","2.9904","2.9904","1.9936","13.8585","51.2766"
"12.1600","3.0108","3.0108","2.0072","13.9749","51.7073"
"12.2400","3.0299","3.0299","2.0199","14.0790","52.0922"
"12.3200","3.0503","3.0503","2.0335","14.1963","52.5262"
"12.4000","3.0704","3.0704","2.0469","14.3133","52.9592"
"12.4800","3.0891","3.0891","2.0594","14.4192","53.3511"
"12.5600","3.1101","3.1101","2.0734","14.5381","53.7910"
"12.6400","3.1309","3.1309","2.0873","14.6558","54.2264"
"12.7200","3.1512","3.1512","2.1008","14.7694","54.6467"
"12.8000","3.1705","3.1705","2.1137","14.8766","55.0434"
"12.8800","3.1899","3.1899","2.1266","14.9904","55.4646"
"12.9600","3.2099","3.2099","2.1399","15.1018","55.8767"
"13.0400","3.2298","3.2298","2.1532","15.2156","56.2978"
"13.1200","3.2494","3.2494","2.1663","15.3284","56.7151"
"13.2000","3.2705","3.2705","2.1804","15.4488","57.1605"
"13.2800","3.2901","3.2901","2.1934","15.5585","57.5666"
"13.3600","3.3110","3.3110","2.2074","15.6756","57.9999"
"13.4400","3.3306","3.3306","2.2204","15.7856","58.4068"
"13.5200","3.3495","3.3495","2.2330","15.8923","58.8016"
"13.6000","3.3696","3.3696","2.2464","16.0059","59.2219"
"13.6800","3.3898","3.3898","2.2599","16.1179","59.6361"
"13.7600","3.4103","3.4103","2.2735","16.2384","60.0819"
"13.8400","3.4319","3.4319","2.2879","16.3599","60.5317"
"13.9200","3.4504","3.4504","2.3003","16.4616","60.9081"
"14.0000","3.4704","3.4704","2.3136","16.5738","61.3230"
"14.0800","3.4899","3.4899","2.3266","16.6786","61.7108"
"14.1600","3.5097","3.5097","2.3398","16.7925","62.1321"
"14.2400","3.5301","3.5301","2.3534","16.9065","62.5540"
"14.3200","3.5490","3.5490","2.3660","17.0104","62.9385"
"14.4000","3.5699","3.5699","2.3799","17.1270","63.3698"
"14.4800","3.5910","3.5910","2.3940","17.2471","63.8144"
"14.5600","3.6107","3.6107","2.4071","17.3567","64.2198"
"14.6400","3.6305","3.6305","2.4204","17.4670","64.6278"
"14.7200","3.6499","3.6499","2.4333","17.5708","65.0118"
"14.8000","3.6695","3.6695","2.4464","17.6809","65.4194"
"14.8800","3.6903","3.6903","2.4602","17.7957","65.8440"
"14.9600","3.7096","3.7096","2.4731","17.8995","66.2281"
"15.0400","3.7311","3.7311","2.4874","18.0207","66.6766"
"15.1200","3.7511","3.7511","2.5007","18.1303","67.0823"
"15.2000","3.7707","3.7707","2.5138","18.2377","67.4795"
"15.2800","3.7898","3.7898","2.5265","18.3414","67.8631"
"15.3600","3.8095","3.8095","2.5396","18.4457","68.2491"
"15.4400","3.8305","3.8305","2.5537","18.5641","68.6871"
"15.5200","3.8506","3.8506","2.5670","18.6731","69.0904"
"15.6000","3.8689","3.8689","2.5792","18.7719","69.4562"
"15.6800","3.8901","3.8901","2.5934","18.8897","69.8919"
"15.7600","3.9108","3.9108","2.6072","19.0034","70.3126"
"15.8400","3.9311","3.9311","2.6207","19.1144","70.7232"
"15.9200","3.9501","3.9501","2.6334","19.2144","71.0933"
"16.0000","3.9691","3.9691","2.6460","19.3176","71.4753"
"16.0800","3.9902","3.9902","2.6601","19.4326","71.9005"
"16.1600","4.0105","4.0105","2.6737","19.5454","72.3179"
"16.2400","4.0301","4.0301","2.6868","19.6517","72.7113"
"16.3200","4.0505","4.0505","2.7004","19.7648","73.1297"
"16.4000","4.0706","4.0706","2.7137","19.8697","73.5177"
"16.4800","4.0907","4.0907","2.7272","19.9783","73.9197"
"16.5600","4.1107","4.1107","2.7405","20.0839","74.3106"
"16.6400","4.1294","4.1294","2.7529","20.1841","74.6812"
"16.7200","4.1502","4.1502","2.7668","20.2960","75.0953"
"16.8000","4.1690","4.1690","2.7794","20.3986","75.4749"
"16.8800","4.1897","4.1897","2.7931","20.5109","75.8904"
"16.9600","4.2108","4.2108","2.8072","20.6278","76.3229"
"17.0400","4.2307","4.2307","2.8205","20.7334","76.7135"
"17.1200","4.2503","4.2503","2.8336","20.8345","77.0878"
"17.2000","4.2706","4.2706","2.8471","20.9440","77.4927"
"17.2800","4.2896","4.2896","2.8597","21.0449","77.8660"
"17.3600","4.3104","4.3104","2.8736","21.1580","78.2845"
"17.4400","4.3295","4.3295","2.8863","21.2561","78.6475"
"17.5200","4.3505","4.3505","2.9004","21.3676","79.0600"
"17.6000","4.3714","4.3714","2.9143","21.4786","79.4708"
"17.6800","4.3903","4.3903","2.9269","21.5795","79.8440"
"17.7600","4.4102","4.4102","2.9401","21.6836","80.2293"
"17.8400","4.4297","4.4297","2.9531","21.7836","80.5995"
"17.9200","4.4500","4.4500","2.9666","21.8917","80.9995"
"18.0000","4.4702","4.4702","2.9801","21.9981","81.3930"
"18.0800","4.4889","4.4889","2.9926","22.0924","81.7417"
"18.1600","4.5099","4.5099","3.0066","22.2079","82.1693"
"18.2400","4.5312","4.5312","3.0208","22.3157","82.5682"
"18.3200","4.5502","4.5502","3.0335","22.4166","82.9414"
"18.4000","4.5703","4.5703","3.0468","22.5200","83.3239"
"18.4800","4.5892","4.5892","3.0595","22.6161","83.6795"
"18.5600","4.6102","4.6102","3.0734","22.7285","84.0954"
"18.6400","4.6305","4.6305","3.0870","22.8344","84.4874"
"18.7200","4.6498","4.6498","3.0998","22.9302","84.8416"
"18.8000","4.6702","4.6702","3.1135","23.0381","85.2409"
"18.8800","4.6911","4.6911","3.1274","23.1442","85.6337"
"18.9600","4.7109","4.7109","3.1406","23.2458","86.0093"
"19.0400","4.7308","4.7308","3.1539","23.3485","86.3894"
"19.1200","4.7494","4.7494","3.1663","23.4384","86.7222"
"19.2000","4.7701","4.7701","3.1801","23.5463","87.1212"
"19.2800","4.7898","4.7898","3.1932","23.6470","87.4938"
"19.3600","4.8093","4.8093","3.2062","23.7481","87.8679"
"19.4400","4.8306","4.8306","3.2204","23.8584","88.2761"
"19.5200","4.8507","4.8507","3.2338","23.9574","88.6425"
"19.6000","4.8705","4.8705","3.2470","24.0565","89.0090"
"19.6800","4.8906","4.8906","3.2604","24.1582","89.3852"
"19.7600","4.9093","4.9093","3.2729","24.2538","89.7390"
"19.8400","4.9303","4.9303","3.2869","24.3607","90.1345"
"19.9200","4.9498","4.9498","3.2999","24.4588","90.4976"
"20.0000","4.9700","4.9700","3.3134","24.5611","90.8762"
"20.0800","4.9908","4.9908","3.3272","24.6662","91.2650"
"20.1600","5.0106","5.0106","3.3404","24.7679","91.6412"
"20.2400","5.0312","5.0312","3.3541","24.8684","92.0132"
"20.3200","5.0506","5.0506","3.3671","24.9630","92.3629"
"20.4000","5.0687","5.0687","3.3791","25.0496","92.6835"
"20.4800","5.0896","5.0896","3.3931","25.1567","93.0797"
"20.5600","5.1096","5.1096","3.4064","25.2537","93.4386"
"20.6400","5.1303","5.1303","3.4202","25.3629","93.8428"
"20.7200","5.1511","5.1511","3.4341","25.4639","94.2166"
"20.8000","5.1699","5.1699","3.4466","25.5551","94.5538"
"20.8800","5.1905","5.1905","3.4604","25.6589","94.9379"
"20.9600","5.2100","5.2100","3.4733","25.7527","95.2850"
"21.0400","5.2301","5.2301","3.4867","25.8561","95.6676"
"21.1200","5.2502","5.2502","3.5001","25.9548","96.0327"
"21.2000","5.2697","5.2697","3.5131","26.0459","96.3700"
"21.2800","5.2901","5.2901","3.5268","26.1490","96.7515"
"21.3600","5.3117","5.3117","3.5411","26.2570","97.1509"
"21.4400","5.3307","5.3307","3.5538","26.3510","97.4987"
"21.5200","5.3506","5.3506","3.5670","26.4438","97.8419"
"21.6000","5.3694","5.3694","3.5796","26.5324","98.1699"
"21.6800","5.3899","5.3899","3.5933","26.6331","98.5424"
"21.7600","5.4102","5.4102","3.6068","26.7311","98.9051"
"21.8400","5.4293","5.4293","3.6196","26.8243","99.2497"
"21.9200","5.4501","5.4501","3.6334","26.9249","99.6223"
"22.0000","5.4704","5.4704","3.6470","27.0237","99.9877"
"22.0800","5.4905","5.4905","3.6604","27.1208","100.3469"
"22.1600","5.5109","5.5109","3.6739","27.2196","100.7125"
"22.2400","5.5300","5.5300","3.6867","27.3078","101.0388"
"22.3200","5.5503","5.5503","3.7002","27.4039","101.3945"
"22.4000","5.5702","5.5702","3.7134","27.4977","101.7413"
"22.4800","5.5892","5.5892","3.7261","27.5909","102.0865"
"22.5600","5.6112","5.6112","3.7408","27.6974","102.4805"
"22.6400","5.6310","5.6310","3.7540","27.7903","102.8242"
"22.7200","5.6512","5.6512","3.7674","27.8845","103.1726"
"22.8000","5.6710","5.6710","3.7806","27.9792","103.5232"
"22.8800","5.6895","5.6895","3.7930","28.0641","103.8373"
"22.9600","5.7099","5.7099","3.8066","28.1609","104.1953"
"23.0400","5.7303","5.7303","3.8202","28.2535","104.5380"
"23.1200","5.7495","5.7495","3.8330","28.3456","104.8788"
"23.2000","5.7698","5.7698","3.8466","28.4388","105.2236"
"23.2800","5.7899","5.7899","3.8600","28.5303","105.5621"
"23.3600","5.8110","5.8110","3.8740","28.6282","105.9245"
"23.4400","5.8308","5.8308","3.8872","28.7170","106.2530"
"23.5200","5.8496","5.8496","3.8997","28.8034","106.5726"
"23.6000","5.8695","5.8695","3.9130","28.8971","106.9191"
"23.6800","5.8897","5.8897","3.9265","28.9920","107.2704"
"23.7600","5.9103","5.9103","3.9402","29.0860","107.6184"
"23.8400","5.9318","5.9318","3.9546","29.1848","107.9839"
"23.9200","5.9505","5.9505","3.9670","29.2684","108.2930"
"24.0000","5.9706","5.9706","3.9804","29.3561","108.6177"
"24.0800","5.9899","5.9899","3.9933","29.4443","108.9438"
"24.1600","6.0100","6.0100","4.0067","29.5387","109.2932"
"24.2400","6.0303","6.0303","4.0202","29.6283","109.6245"
"24.3200","6.0487","6.0487","4.0325","29.7083","109.9205"
"24.4000","6.0697","6.0697","4.0465","29.8042","110.2756"
"24.4800","6.0908","6.0908","4.0605","29.9001","110.6302"
"24.5600","6.1102","6.1102","4.0734","29.9857","110.9470"
"24.6400","6.1303","6.1303","4.0869","30.0743","111.2749"
"24.7200","6.1504","6.1504","4.1003","30.1629","111.6027"
"24.8000","6.1699","6.1699","4.1133","30.2485","111.9196"
"24.8800","6.1902","6.1902","4.1268","30.3412","112.2624"
"24.9600","6.2092","6.2092","4.1395","30.4228","112.5642"
"25.0400","6.2311","6.2311","4.1541","30.5187","112.9191"
"25.1200","6.2512","6.2512","4.1675","30.6086","113.2518"
"25.2000","6.2707","6.2707","4.1805","30.6928","113.5635"
"25.2800","6.2899","6.2899","4.1932","30.7732","113.8610"
"25.3600","6.3099","6.3099","4.2066","30.8591","114.1785"
"25.4400","6.3299","6.3299","4.2199","30.9458","114.4996"
"25.5200","6.3503","6.3503","4.2335","31.0327","114.8209"
"25.6000","6.3689","6.3689","4.2459","31.1130","115.1181"
"25.6800","6.3902","6.3902","4.2602","31.2091","115.4735"
"25.7600","6.4103","6.4103","4.2735","31.2939","115.7875"
"25.8400","6.4308","6.4308","4.2872","31.3827","116.1161"
"25.9200","6.4512","6.4512","4.3008","31.4719","116.4460"
"26.0000","6.4692","6.4692","4.3128","31.5408","116.7008"
"26.0800","6.4897","6.4897","4.3265","31.6297","117.0299"
"26.1600","6.5105","6.5105","4.3403","31.7171","117.3534"
"26.2400","6.5302","6.5302","4.3535","31.8040","117.6748"
"26.3200","6.5509","6.5509","4.3673","31.8915","117.9984"
"26.4000","6.5707","6.5707","4.3804","31.9715","118.2944"
"26.4800","6.5908","6.5908","4.3938","32.0558","118.6063"
"26.5600","6.6109","6.6109","4.4073","32.1373","118.9081"
"26.6400","6.6297","6.6297","4.4198","32.2140","119.1917"
"26.7200","6.6498","6.6498","4.4332","32.2984","119.5040"
"26.8000","6.6691","6.6691","4.4461","32.3755","119.7895"
"26.8800","6.6899","6.6899","4.4599","32.4618","120.1086"
"26.9600","6.7111","6.7111","4.4741","32.5510","120.4387"
"27.0400","6.7306","6.7306","4.4871","32.6259","120.7160"
"27.1200","6.7504","6.7504","4.5003","32.7050","121.0086"
"27.2000","6.7704","6.7704","4.5136","32.7862","121.3088"
"27.2800","6.7892","6.7892","4.5261","32.8617","121.5882"
"27.3600","6.8105","6.8105","4.5403","32.9482","121.9084"
"27.4400","6.8296","6.8296","4.5530","33.0231","122.1854"
"27.5200","6.8509","6.8509","4.5673","33.1088","122.5027"
"27.6000","6.8710","6.8710","4.5807","33.1870","122.7918"
"27.6800","6.8898","6.8898","4.5932","33.2581","123.0550"
"27.7600","6.9100","6.9100","4.6067","33.3402","123.3588"
"27.8400","6.9304","6.9304","4.6203","33.4179","123.6463"
"27.9200","6.9502","6.9502","4.6335","33.4944","123.9292"
"28.0000","6.9703","6.9703","4.6469","33.5718","124.2158"
"28.0800","6.9890","6.9890","4.6593","33.6404","124.4694"
"28.1600","7.0100","7.0100","4.6733","33.7236","124.7773"
"28.2400","7.0311","7.0311","4.6874","33.8061","125.0825"
"28.3200","7.0503","7.0503","4.7002","33.8766","125.3434"
"28.4000","7.0702","7.0702","4.7135","33.9535","125.6281"
"28.4800","7.0893","7.0893","4.7262","34.0231","125.8854"
"28.5600","7.1105","7.1105","4.7403","34.1041","126.1853"
"28.6400","7.1307","7.1307","4.7538","34.1810","126.4698"
"28.7200","7.1499","7.1499","4.7666","34.2517","126.7312"
"28.8000","7.1705","7.1705","4.7803","34.3292","127.0180"
"28.8800","7.1913","7.1913","4.7942","34.4075","127.3079"
"28.9600","7.2110","7.2110","4.8073","34.4775","127.5666"
"29.0400","7.2304","7.2304","4.8203","34.5449","127.8160"
"29.1200","7.2491","7.2491","4.8327","34.6076","128.0479"
"29.2000","7.2701","7.2701","4.8468","34.6884","128.3471"
"29.2800","7.2900","7.2900","4.8600","34.7576","128.6031"
"29.3600","7.3094","7.3094","4.8729","34.8305","128.8728"
"29.4400","7.3304","7.3304","4.8869","34.9053","129.1497"
"29.5200","7.3510","7.3510","4.9007","34.9793","129.4235"
"29.6000","7.3708","7.3708","4.9139","35.0475","129.6758"
"29.6800","7.3904","7.3904","4.9269","35.1118","129.9137"
"29.7600","7.4094","7.4094","4.9396","35.1782","130.1595"
"29.8400","7.4305","7.4305","4.9537","35.2535","130.4378"
"29.9200","7.4500","7.4500","4.9667","35.3151","130.6658"
"30.0000","7.4699","7.4699","4.9800","35.3839","130.9206"
"30.0800","7.4907","7.4907","4.9938","35.4582","131.1954"
"30.1600","7.5107","7.5107","5.0071","35.5254","131.4438"
"30.2400","7.5311","7.5311","5.0208","35.5907","131.6856"
"30.3200","7.5506","7.5506","5.0337","35.6546","131.9220"
"30.4000","7.5691","7.5691","5.0461","35.7160","132.1492"
"30.4800","7.5895","7.5895","5.0596","35.7823","132.3946"
"30.5600","7.6097","7.6097","5.0731","35.8481","132.6379"
"30.6400","7.6301","7.6301","5.0868","35.9159","132.8889"
"30.7200","7.6514","7.6514","5.1009","35.9867","133.1510"
"30.8000","7.6699","7.6699","5.1132","36.0436","133.3612"
"30.8800","7.6906","7.6906","5.1271","36.1103","133.6082"
"30.9600","7.7101","7.7101","5.1401","36.1708","133.8320"
"31.0400","7.7300","7.7300","5.1533","36.2336","134.0645"
"31.1200","7.7496","7.7496","5.1664","36.2949","134.2910"
"31.2000","7.7698","7.7698","5.1799","36.3540","134.5099"
"31.2800","7.7903","7.7903","5.1936","36.4176","134.7452"
"31.3600","7.8118","7.8118","5.2079","36.4879","135.0052"
"31.4400","7.8306","7.8306","5.2204","36.5404","135.1994"
"31.5200","7.8504","7.8504","5.2336","36.6005","135.4220"
"31.6000","7.8695","7.8695","5.2463","36.6538","135.6190"
"31.6800","7.8900","7.8900","5.2600","36.7168","135.8521"
"31.7600","7.9104","7.9104","5.2736","36.7751","136.0680"
"31.8400","7.9295","7.9295","5.2864","36.8324","136.2797"
"31.9200","7.9501","7.9501","5.3001","36.8915","136.4987"
"32.0000","7.9703","7.9703","5.3135","36.9475","136.7057"
"32.0800","7.9902","7.9902","5.3268","37.0028","136.9104"
"32.1600","8.0109","8.0109","5.3406","37.0631","137.1336"
"32.2400","8.0302","8.0302","5.3535","37.1137","137.3206"
"32.3200","8.0503","8.0503","5.3668","37.1704","137.5304"
"32.4000","8.0702","8.0702","5.3801","37.2216","137.7200"
"32.4800","8.0891","8.0891","5.3927","37.2724","137.9077"
"32.5600","8.1112","8.1112","5.4075","37.3372","138.1477"
"32.6400","8.1311","8.1311","5.4208","37.3865","138.3299"
"32.7200","8.1514","8.1514","5.4342","37.4394","138.5259"
"32.8000","8.1698","8.1698","5.4466","37.4812","138.6804"
"32.8800","8.1893","8.1893","5.4596","37.5293","138.8586"
"32.9600","8.2100","8.2100","5.4733","37.5829","139.0568"
"33.0400","8.2303","8.2303","5.4868","37.6353","139.2506"
"33.1200","8.2492","8.2492","5.4995","37.6830","139.4271"
"33.2000","8.2708","8.2708","5.5138","37.7423","139.6465"
"33.2800","8.2900","8.2900","5.5267","37.7846","139.8028"
"33.3600","8.3106","8.3106","5.5404","37.8348","139.9889"
"33.4400","8.3309","8.3309","5.5539","37.8847","140.1734"
"33.5200","8.3497","8.3497","5.5665","37.9270","140.3297"
"33.6000","8.3698","8.3698","5.5798","37.9740","140.5039"
"33.6800","8.3897","8.3897","5.5932","38.0185","140.6686"
"33.7600","8.4103","8.4103","5.6068","38.0690","140.8552"
"33.8400","8.4316","8.4316","5.6211","38.1206","141.0464"
"33.9200","8.4504","8.4504","5.6336","38.1563","141.1782"
"34.0000","8.4704","8.4704","5.6470","38.1998","141.3391"
"34.0800","8.4905","8.4905","5.6604","38.2446","141.5049"
"34.1600","8.5098","8.5098","5.6732","38.2846","141.6529"
"34.2400","8.5300","8.5300","5.6866","38.3269","141.8094"
"34.3200","8.5488","8.5488","5.6992","38.3604","141.9334"
"34.4000","8.5699","8.5699","5.7133","38.4047","142.0974"
"34.4800","8.5909","8.5909","5.7272","38.4543","142.2811"
"34.5600","8.6109","8.6109","5.7406","38.4956","142.4336"
"34.6400","8.6308","8.6308","5.7538","38.5332","142.5730"
"34.7200","8.6501","8.6501","5.7667","38.5684","142.7032"
"34.8000","8.6695","8.6695","5.7797","38.6047","142.8373"
"34.8800","8.6902","8.6902","5.7935","38.6476","142.9962"
"34.9600","8.7097","8.7097","5.8065","38.6826","143.1256"
"35.0400","8.7315","8.7315","5.8210","38.7267","143.2889"
"35.1200","8.7510","8.7510","5.8340","38.7618","143.4187"
"35.2000","8.7708","8.7708","5.8472","38.7952","143.5422"
"35.2800","8.7899","8.7899","5.8599","38.8285","143.6653"
"35.3600","8.8100","8.8100","5.8733","38.8632","143.7938"
"35.4400","8.8306","8.8306","5.8871","38.9039","143.9446"
"35.5200","8.8507","8.8507","5.9005","38.9352","144.0604"
"35.6000","8.8683","8.8683","5.9122","38.9604","144.1536"
"35.6800","8.8900","8.8900","5.9267","39.0026","144.3097"
"35.7600","8.9108","8.9108","5.9406","39.0379","144.4404"
"35.8400","8.9306","8.9306","5.9538","39.0670","144.5479"
"35.9200","8.9506","8.9506","5.9671","39.1000","144.6702"
"36.0000","8.9693","8.9693","5.9795","39.1241","144.7593"
"36.0800","8.9898","8.9898","5.9932","39.1583","144.8856"
"36.1600","9.0100","9.0100","6.0067","39.1904","145.0043"
"36.2400","9.0303","9.0303","6.0202","39.2229","145.1248"
"36.3200","9.0510","9.0510","6.0340","39.2563","145.2484"
"36.4000","9.0703","9.0703","6.0469","39.2785","145.3304"
"36.4800","9.0906","9.0906","6.0604","39.3080","145.4395"
"36.5600","9.1108","9.1108","6.0739","39.3330","145.5323"
"36.6400","9.1297","9.1297","6.0865","39.3599","145.6318"
"36.7200","9.1501","9.1501","6.1001","39.3922","145.7512"
"36.8000","9.1692","9.1692","6.1128","39.4126","145.8267"
"36.8800","9.1897","9.1897","6.1265","39.4425","145.9371"
"36.9600","9.2109","9.2109","6.1406","39.4754","146.0588"
"37.0400","9.2306","9.2306","6.1537","39.4962","146.1360"
"37.1200","9.2504","9.2504","6.1670","39.5222","146.2322"
"37.2000","9.2703","9.2703","6.1802","39.5448","146.3157"
"37.2800","9.2890","9.2890","6.1927","39.5635","146.3848"
"37.3600","9.3103","9.3103","6.2069","39.5977","146.5114"
"37.4400","9.3298","9.3298","6.2199","39.6178","146.5860"
"37.5200","9.3512","9.3512","6.2341","39.6495","146.7033"
"37.6000","9.3713","9.3713","6.2475","39.6693","146.7766"
"37.6800","9.3904","9.3904","6.2603","39.6876","146.8440"
"37.7600","9.4105","9.4105","6.2737","39.7090","146.9233"
"37.8400","9.4299","9.4299","6.2866","39.7260","146.9862"
"37.9200","9.4496","9.4496","6.2997","39.7445","147.0547"
"38.0000","9.4702","9.4702","6.3135","39.7678","147.1409"
"38.0800","9.4890","9.4890","6.3260","39.7834","147.1987"
"38.1600","9.5099","9.5099","6.3400","39.8071","147.2861"
"38.2400","9.5312","9.5312","6.3541","39.8312","147.3756"
"38.3200","9.5501","9.5501","6.3667","39.8458","147.4295"
"38.4000","9.5706","9.5706","6.3804","39.8676","147.5101"
"38.4800","9.5895","9.5895","6.3930","39.8828","147.5663"
"38.5600","9.6105","9.6105","6.4070","39.9025","147.6393"
"38.6400","9.6304","9.6304","6.4202","39.9220","147.7115"
"38.7200","9.6496","9.6496","6.4331","39.9371","147.7672"
"38.8000","9.6704","9.6704","6.4469","39.9564","147.8387"
"38.8800","9.6912","9.6912","6.4608","39.9806","147.9284"
"38.9600","9.7107","9.7107","6.4738","39.9922","147.9710"
"39.0400","9.7307","9.7307","6.4871","40.0114","148.0421"
"39.1200","9.7492","9.7492","6.4994","40.0188","148.0696"
"39.2000","9.7699","9.7699","6.5133","40.0421","148.1557"
"39.2800","9.7899","9.7899","6.5266","40.0553","148.2046"
"39.3600","9.8096","9.8096","6.5398","40.0717","148.2654"
"39.4400","9.8304","9.8304","6.5536","40.0959","148.3549"
"39.5200","9.8509","9.8509","6.5673","40.1072","148.3967"
"39.6000","9.8706","9.8706","6.5804","40.1217","148.4503"
"39.6800","9.8901","9.8901","6.5934","40.1337","148.4948"
"39.7600","9.9090","9.9090","6.6060","40.1466","148.5425"
"39.8400","9.9306","9.9306","6.6204","40.1685","148.6233"
"39.9200","9.9502","9.9502","6.6335","40.1809","148.6693"
"40.0000","9.9701","9.9701","6.6467","40.1960","148.7253"
"40.0800","9.9911","9.9911","6.6607","40.2154","148.7971"
"40.1600","10.0104","10.0104","6.6736","40.2239","148.8283"
"40.2400","10.0305","10.0305","6.6870","40.2352","148.8703"
"40.3200","10.0508","10.0508","6.7006","40.2501","148.9255"
"40.4000","10.0695","10.0695","6.7130","40.2629","148.9727"
"40.4800","10.0898","10.0898","6.7265","40.2769","149.0246"
"40.5600","10.1095","10.1095","6.7397","40.2901","149.0734"
"40.6400","10.1299","10.1299","6.7533","40.3045","149.1266"
"40.7200","10.1516","10.1516","6.7677","40.3233","149.1963"
"40.8000","10.1705","10.1705","6.7803","40.3332","149.2330"
"40.8800","10.1905","10.1905","6.7937","40.3451","149.2769"
"40.9600","10.2095","10.2095","6.8063","40.3537","149.3086"
"41.0400","10.2300","10.2300","6.8200","40.3695","149.3670"
"41.1200","10.2497","10.2497","6.8331","40.3805","149.4080"
"41.2000","10.2695","10.2695","6.8463","40.3902","149.4436"
"41.2800","10.2904","10.2904","6.8602","40.4078","149.5090"
"41.3600","10.3119","10.3119","6.8746","40.4238","149.5682"
"41.4400","10.3306","10.3306","6.8871","40.4282","149.5843"
"41.5200","10.3505","10.3505","6.9003","40.4410","149.6315"
"41.6000","10.3694","10.3694","6.9129","40.4449","149.6461"
"41.6800","10.3897","10.3897","6.9265","40.4585","149.6965"
"41.7600","10.4103","10.4103","6.9402","40.4669","149.7277"
"41.8400","10.4294","10.4294","6.9529","40.4743","149.7550"
"41.9200","10.4499","10.4499","6.9666","40.4886","149.8079"
"42.0000","10.4705","10.4705","6.9803","40.4990","149.8464"
"42.0800","10.4904","10.4904","6.9936","40.5083","149.8808"
"42.1600","10.5108","10.5108","7.0072","40.5198","149.9234"
"42.2400","10.5301","10.5301","7.0201","40.5235","149.9368"
"42.3200","10.5504","10.5504","7.0336","40.5332","149.9729"
"42.4000","10.5701","10.5701","7.0467","40.5432","150.0097"
"42.4800","10.5889","10.5889","7.0593","40.5484","150.0292"
"42.5600","10.6111","10.6111","7.0741","40.5692","150.1061"
"42.6400","10.6312","10.6312","7.0875","40.5754","150.1292"
"42.7200","10.6515","10.6515","7.1010","40.5846","150.1629"
"42.8000","10.6705","10.6705","7.1137","40.5894","150.1808"
"42.8800","10.6897","10.6897","7.1265","40.5953","150.2025"
"42.9600","10.7097","10.7097","7.1398","40.6033","150.2322"
"43.0400","10.7299","10.7299","7.1532","40.6117","150.2634"
"43.1200","10.7489","10.7489","7.1659","40.6190","150.2905"
"43.2000","10.7705","10.7705","7.1803","40.6319","150.3382"
"43.2800","10.7900","10.7900","7.1933","40.6360","150.3532"
"43.3600","10.8111","10.8111","7.2074","40.6459","150.3897"
"43.4400","10.8304","10.8304","7.2203","40.6466","150.3924"
"43.5200","10.8496","10.8496","7.2330","40.6521","150.4126"
"43.6000","10.8697","10.8697","7.2465","40.6604","150.4433"
"43.6800","10.8900","10.8900","7.2600","40.6673","150.4690"
"43.7600","10.9105","10.9105","7.2737","40.6768","150.5041"
"43.8400","10.9316","10.9316","7.2877","40.6836","150.5293"
"43.9200","10.9504","10.9504","7.3003","40.6833","150.5282"
"44.0000","10.9705","10.9705","7.3136","40.6906","150.5554"
"44.0800","10.9903","10.9903","7.3268","40.6957","150.5740"
"44.1600","11.0100","11.0100","7.3400","40.7026","150.5997"
"44.2400","11.0305","11.0305","7.3537","40.7133","150.6394"
"44.3200","11.0487","11.0487","7.3658","40.7108","150.6301"
"44.4000","11.0697","11.0697","7.3798","40.7210","150.6676"
"44.4800","11.0907","11.0907","7.3938","40.7306","150.7033"
"44.5600","11.1110","11.1110","7.4073","40.7421","150.7457"
"44.6400","11.1308","11.1308","7.4205","40.7486","150.7696"
"44.7200","11.1502","11.1502","7.4334","40.7491","150.7717"
"44.8000","11.1696","11.1696","7.4464","40.7563","150.7984"
"44.8800","11.1901","11.1901","7.4601","40.7630","150.8231"
"44.9600","11.2093","11.2093","7.4729","40.7684","150.8432"
"45.0400","11.2314","11.2314","7.4876","40.7796","150.8846"
"45.1200","11.2513","11.2513","7.5009","40.7850","150.9043"
"45.2000","11.2708","11.2708","7.5139","40.7850","150.9044"
"45.2800","11.2900","11.2900","7.5267","40.7871","150.9123"
"45.3600","11.3100","11.3100","7.5400","40.7914","150.9281"
"45.4400","11.3298","11.3298","7.5532","40.7961","150.9455"
"45.5200","11.3499","11.3499","7.5666","40.7994","150.9579"
"45.6000","11.3691","11.3691","7.5794","40.8074","150.9872"
"45.6800","11.3908","11.3908","7.5938","40.8190","151.0304"
"45.7600","11.4105","11.4105","7.6070","40.8206","151.0362"
"45.8400","11.4303","11.4303","7.6202","40.8226","151.0435"
"45.9200","11.4502","11.4502","7.6335","40.8278","151.0629"
"46.0000","11.4693","11.4693","7.6462","40.8268","151.0593"
"46.0800","11.4899","11.4899","7.6600","40.8365","151.0952"
"46.1600","11.5106","11.5106","7.6737","40.8428","151.1185"
"46.2400","11.5304","11.5304","7.6869","40.8505","151.1468"
"46.3200","11.5507","11.5507","7.7004","40.8583","151.1756"
"46.4000","11.5702","11.5702","7.7134","40.8588","151.1777"
"46.4800","11.5908","11.5908","7.7272","40.8668","151.2073"
"46.5600","11.6114","11.6114","7.7409","40.8726","151.2287"
"46.6400","11.6296","11.6296","7.7531","40.8721","151.2266"
"46.7200","11.6501","11.6501","7.7667","40.8779","151.2482"
"46.8000","11.6691","11.6691","7.7794","40.8778","151.2480"
"46.8800","11.6897","11.6897","7.7931","40.8860","151.2784"
"46.9600","11.7108","11.7108","7.8072","40.8932","151.3047"
"47.0400","11.7308","11.7308","7.8206","40.8906","151.2953"
"47.1200","11.7502","11.7502","7.8335","40.8916","151.2988"
"47.2000","11.7702","11.7702","7.8468","40.8940","151.3077"
"47.2800","11.7893","11.7893","7.8595","40.8909","151.2963"
"47.3600","11.8102","11.8102","7.8734","40.8966","151.3173"
"47.4400","11.8294","11.8294","7.8863","40.8933","151.3051"
"47.5200","11.8510","11.8510","7.9007","40.8928","151.3032"
"47.6000","11.8711","11.8711","7.9140","40.8928","151.3032"
"47.6800","11.8903","11.8903","7.9268","40.8911","151.2972"
"47.7600","11.9104","11.9104","7.9402","40.8956","151.3139"
"47.8400","11.9305","11.9305","7.9536","40.8962","151.3160"
"47.9200","11.9501","11.9501","7.9667","40.8972","151.3198"
"48.0000","11.9703","11.9703","7.9802","40.8983","151.3237"
"48.0800","11.9890","11.9890","7.9927","40.8950","151.3114"
"48.1600","12.0100","12.0100","8.0067","40.8975","151.3207"
"48.2400","12.0311","12.0311","8.0207","40.9030","151.3412"
"48.3200","12.0505","12.0505","8.0337","40.9024","151.3388"
"48.4000","12.0699","12.0699","8.0466","40.8998","151.3292"
"48.4800","12.0897","12.0897","8.0598","40.9002","151.3307"
"48.5600","12.1109","12.1109","8.0739","40.9067","151.3546"
"48.6400","12.1305","12.1305","8.0870","40.9051","151.3490"
"48.7200","12.1500","12.1500","8.1000","40.9073","151.3571"
"48.8000","12.1703","12.1703","8.1135","40.9108","151.3699"
"48.8800","12.1911","12.1911","8.1274","40.9126","151.3766"
"48.9600","12.2106","12.2106","8.1404","40.9100","151.3669"
"49.0400","12.2311","12.2311","8.1541","40.9141","151.3821"
"49.1200","12.2493","12.2493","8.1662","40.9044","151.3464"
"49.2000","12.2697","12.2697","8.1798","40.9058","151.3515"
"49.2800","12.2895","12.2895","8.1930","40.9072","151.3565"
"49.3600","12.3092","12.3092","8.2061","40.9118","151.3738"
"49.4400","12.3305","12.3305","8.2203","40.9186","151.3989"
"49.5200","12.3510","12.3510","8.2340","40.9146","151.3839"
"49.6000","12.3704","12.3704","8.2469","40.9152","151.3863"
"49.6800","12.3903","12.3903","8.2602","40.9142","151.3826"
"49.7600","12.4092","12.4092","8.2728","40.9123","151.3756"
"49.8400","12.4304","12.4304","8.2869","40.9184","151.3981"
"49.9200","12.4502","12.4502","8.3001","40.9152","151.3863"
"50.0000","12.4699","12.4699","8.3133","40.9166","151.3914"
"50.0800","12.4911","12.4911","8.3274","40.9182","151.3973"
"50.1600","12.5106","12.5106","8.3404","40.9141","151.3824"
"50.2400","12.5308","12.5308","8.3539","40.9136","151.3802"
"50.3200","12.5506","12.5506","8.3671","40.9089","151.3628"
"50.4000","12.5699","12.5699","8.3799","40.9054","151.3499"
"50.4800","12.5894","12.5894","8.3929","40.9068","151.3550"
"50.5600","12.6095","12.6095","8.4063","40.9050","151.3484"
"50.6400","12.6300","12.6300","8.4200","40.9073","151.3569"
"50.7200","12.6512","12.6512","8.4342","40.9083","151.3607"
"50.8000","12.6701","12.6701","8.4467","40.9048","151.3478"
"50.8800","12.6907","12.6907","8.4605","40.9040","151.3449"
"50.9600","12.7093","12.7093","8.4729","40.8965","151.3170"
"51.0400","12.7300","12.7300","8.4867","40.8995","151.3281"
"51.1200","12.7504","12.7504","8.5002","40.8977","151.3215"
"51.2000","12.7698","12.7698","8.5132","40.8964","151.3166"
"51.2800","12.7901","12.7901","8.5268","40.8979","151.3221"
"51.3600","12.8120","12.8120","8.5413","40.9023","151.3383"
"51.4400","12.8309","12.8309","8.5539","40.9002","151.3307"
"51.5200","12.8503","12.8503","8.5669","40.8976","151.3210"
"51.6000","12.8693","12.8693","8.5796","40.8900","151.2931"
"51.6800","12.8898","12.8898","8.5932","40.8916","151.2989"
"51.7600","12.9103","12.9103","8.6069","40.8910","151.2965"
"51.8400","12.9293","12.9293","8.6196","40.8884","151.2872"
"51.9200","12.9503","12.9503","8.6336","40.8895","151.2910"
"52.0000","12.9707","12.9707","8.6471","40.8874","151.2834"
"52.0800","12.9902","12.9902","8.6602","40.8796","151.2545"
"52.1600","13.0103","13.0103","8.6735","40.8815","151.2616"
"52.2400","13.0299","13.0299","8.6866","40.8765","151.2429"
"52.3200","13.0504","13.0504","8.7003","40.8758","151.2404"
"52.4000","13.0706","13.0706","8.7137","40.8704","151.2206"
"52.4800","13.0894","13.0894","8.7263","40.8677","151.2106"
"52.5600","13.1107","13.1107","8.7405","40.8707","151.2215"
"52.6400","13.1311","13.1311","8.7540","40.8684","151.2130"
"52.7200","13.1516","13.1516","8.7677","40.8615","151.1877"
"52.8000","13.1704","13.1704","8.7802","40.8540","151.1597"
"52.8800","13.1894","13.1894","8.7930","40.8493","151.1425"
"52.9600","13.2098","13.2098","8.8065","40.8484","151.1389"
"53.0400","13.2300","13.2300","8.8200","40.8438","151.1221"
"53.1200","13.2492","13.2492","8.8328","40.8413","151.1128"
"53.2000","13.2702","13.2702","8.8468","40.8402","151.1089"
"53.2800","13.2899","13.2899","8.8599","40.8342","151.0867"
"53.3600","13.3111","13.3111","8.8741","40.8323","151.0793"
"53.4400","13.3307","13.3307","8.8871","40.8232","151.0460"
"53.5200","13.3495","13.3495","8.8997","40.8195","151.0323"
"53.6000","13.3696","13.3696","8.9130","40.8107","150.9995"
"53.6800","13.3896","13.3896","8.9264","40.8069","150.9854"
"53.7600","13.4103","13.4103","8.9402","40.8044","150.9763"
"53.8400","13.4320","13.4320","8.9547","40.8039","150.9744"
"53.9200","13.4504","13.4504","8.9669","40.7955","150.9433"
"54.0000","13.4704","13.4704","8.9803","40.7903","150.9242"
"54.0800","13.4901","13.4901","8.9934","40.7874","150.9133"
"54.1600","13.5097","13.5097","9.0065","40.7860","150.9081"
"54.2400","13.5304","13.5304","9.0203","40.7846","150.9031"
"54.3200","13.5488","13.5488","9.0325","40.7775","150.8768"
"54.4000","13.5700","13.5700","9.0467","40.7790","150.8824"
"54.4800","13.5909","13.5909","9.0606","40.7812","150.8904"
"54.5600","13.6107","13.6107","9.0738","40.7774","150.8766"
"54.6400","13.6305","13.6305","9.0870","40.7731","150.8606"
"54.7200","13.6499","13.6499","9.1000","40.7641","150.8273"
"54.8000","13.6697","13.6697","9.1132","40.7595","150.8100"
"54.8800","13.6906","13.6906","9.1271","40.7549","150.7933"
"54.9600","13.7097","13.7097","9.1398","40.7490","150.7712"
"55.0400","13.7313","13.7313","9.1542","40.7514","150.7802"
"55.1200","13.7510","13.7510","9.1673","40.7482","150.7683"
"55.2000","13.7706","13.7706","9.1804","40.7452","150.7572"
"55.2800","13.7903","13.7903","9.1935","40.7434","150.7507"
"55.3600","13.8099","13.8099","9.2066","40.7389","150.7341"
"55.4400","13.8306","13.8306","9.2204","40.7406","150.7403"
"55.5200","13.8503","13.8503","9.2336","40.7334","150.7136"
"55.6000","13.8689","13.8689","9.2459","40.7284","150.6951"
"55.6800","13.8903","13.8903","9.2602","40.7301","150.7015"
"55.7600","13.9108","13.9108","9.2739","40.7275","150.6917"
"55.8400","13.9311","13.9311","9.2874","40.7251","150.6830"
"55.9200","13.9501","13.9501","9.3001","40.7165","150.6509"
"56.0000","13.9688","13.9688","9.3125","40.7075","150.6179"
"56.0800","13.9901","13.9901","9.3268","40.7072","150.6165"
"56.1600","14.0105","14.0105","9.3404","40.7031","150.6014"
"56.2400","14.0301","14.0301","9.3534","40.6968","150.5782"
"56.3200","14.0509","14.0509","9.3673","40.6929","150.5636"
"56.4000","14.0702","14.0702","9.3802","40.6822","150.5241"
"56.4800","14.0906","14.0906","9.3937","40.6796","150.5146"
"56.5600","14.1109","14.1109","9.4072","40.6729","150.4897"
"56.6400","14.1298","14.1298","9.4199","40.6649","150.4600"
"56.7200","14.1502","14.1502","9.4335","40.6602","150.4427"
"56.8000","14.1690","14.1690","9.4460","40.6514","150.4100"
"56.8800","14.1896","14.1896","9.4598","40.6456","150.3887"
"56.9600","14.2107","14.2107","9.4738","40.6390","150.3641"
"57.0400","14.2305","14.2305","9.4870","40.6293","150.3284"
"57.1200","14.2503","14.2503","9.5002","40.6175","150.2846"
"57.2000","14.2706","14.2706","9.5137","40.6077","150.2486"
"57.2800","14.2895","14.2895","9.5263","40.5960","150.2054"
"57.3600","14.3104","14.3104","9.5402","40.5890","150.1792"
"57.4400","14.3297","14.3297","9.5531","40.5762","150.1320"
"57.5200","14.3509","14.3509","9.5673","40.5684","150.1032"
"57.6000","14.3713","14.3713","9.5809","40.5587","150.0672"
"57.6800","14.3903","14.3903","9.5935","40.5453","150.0177"
"57.7600","14.4106","14.4106","9.6071","40.5359","149.9828"
"57.8400","14.4303","14.4303","9.6202","40.5261","149.9464"
"57.9200","14.4497","14.4497","9.6331","40.5147","149.9044"
"58.0000","14.4699","14.4699","9.6466","40.5044","149.8664"
"58.0800","14.4892","14.4892","9.6595","40.4943","149.8291"
"58.1600","14.5102","14.5102","9.6735","40.4874","149.8032"
"58.2400","14.5308","14.5308","9.6872","40.4770","149.7650"
"58.3200","14.5504","14.5504","9.7003","40.4692","149.7359"
"58.4000","14.5702","14.5702","9.7135","40.4603","149.7033"
"58.4800","14.5896","14.5896","9.7264","40.4500","149.6651"
"58.5600","14.6106","14.6106","9.7404","40.4459","149.6499"
"58.6400","14.6308","14.6308","9.7539","40.4364","149.6149"
"58.7200","14.6496","14.6496","9.7664","40.4305","149.5928"
"58.8000","14.6703","14.6703","9.7802","40.4293","149.5883"
"58.8800","14.6910","14.6910","9.7940","40.4239","149.5685"
"58.9600","14.7107","14.7107","9.8071","40.4147","149.5344"
"59.0400","14.7308","14.7308","9.8206","40.4079","149.5093"
"59.1200","14.7492","14.7492","9.8328","40.3907","149.4455"
"59.2000","14.7700","14.7700","9.8467","40.3853","149.4255"
"59.2800","14.7898","14.7898","9.8598","40.3742","149.3847"
"59.3600","14.8093","14.8093","9.8728","40.3673","149.3589"
"59.4400","14.8306","14.8306","9.8871","40.3644","149.3483"
"59.5200","14.8508","14.8508","9.9005","40.3572","149.3216"
"59.6000","14.8705","14.8705","9.9136","40.3497","149.2938"
"59.6800","14.8903","14.8903","9.9268","40.3420","149.2653"
"59.7600","14.9092","14.9092","9.9395","40.3354","149.2411"
"59.8400","14.9302","14.9302","9.9535","40.3321","149.2286"
"59.9200","14.9503","14.9503","9.9669","40.3244","149.2002"
"60.0000","14.9700","14.9700","9.9800","40.3165","149.1709"
"60.0800","14.9910","14.9910","9.9940","40.3127","149.1570"
"60.1160","15.0001","15.0001","10.0001","40.3101","149.1475"