File: data/instron_tests/510_BULK_m1.is_comp_Exports/510_BULK_m1_8_1.csv
Sample text inputs : Sample No.,Sample choice input : Leading Direction,Sample choice input : Mode,Specimen choice input : Direction,Specimen properties : Height,Specimen properties : Thickness,Specimen properties : Width,Test : Rate 1
,,,,(mm),(mm),(mm),(mm/min)
"510","Bulk","Unimode","1","150.00","25.00","150.00","15.00"

Time,Displacement,Compressive displacement,Compressive strain (Displacement),Compressive stress,Force
(s),(mm),(mm),(%),(kPa),(N)
"0.0000","0.0000","0.0000","0.0000","-1.0358","-3.8325"
"0.0800","0.0009","0.0009","0.0006","-1.0385","-3.8424"
"0.1600","0.0088","0.0088","0.0059","-0.9999","-3.6995"
"0.2400","0.0295","0.0295","0.0197","-0.8959","-3.3148"
"0.3200","0.0505","0.0505","0.0337","-0.7983","-2.9537"
"0.4000","0.0697","0.0697","0.0465","-0.7163","-2.6502"
"0.4800","0.0899","0.0899","0.0599","-0.6266","-2.3185"
"0.5600","0.1093","0.1093","0.0729","-0.5477","-2.0266"
"0.6400","0.1275","0.1275","0.0850","-0.4726","-1.7488"
"0.7200","0.1480","0.1480","0.0987","-0.3875","-1.4337"
"0.8000","0.1680","0.1680","0.1120","-0.3070","-1.1360"
"0.8800","0.1884","0.1884","0.1256","-0.2285","-0.8453"
"0.9600","0.2094","0.2094","0.1396","-0.1432","-0.5300"
"1.0400","0.2284","0.2284","0.1522","-0.0806","-0.2983"
"1.1200","0.2484","0.2484","0.1656","-0.0001","-0.0005"
"1.2000","0.2686","0.2686","0.1791","0.0817","0.3025"
"1.2800","0.2877","0.2877","0.1918","0.1594","0.5899"
"1.3600","0.3087","0.3087","0.2058","0.2443","0.9038"
"1.4400","0.3279","0.3279","0.2186","0.3205","1.1857"
"1.5200","0.3487","0.3487","0.2324","0.4076","1.5081"
"1.6000","0.3699","0.3699","0.2466","0.4976","1.8410"
"1.6800","0.3893","0.3893","0.2595","0.5766","2.1334"
"1.7600","0.4086","0.4086","0.2724","0.6533","2.4171"
"1.8400","0.4282","0.4282","0.2855","0.7358","2.7225"
"1.9200","0.4484","0.4484","0.2989","0.8198","3.0333"
"2.0000","0.4686","0.4686","0.3124","0.8747","3.2364"
"2.0800","0.4875","0.4875","0.3250","0.9513","3.5196"
"2.1600","0.5084","0.5084","0.3390","1.0373","3.8379"
"2.2400","0.5288","0.5288","0.3525","1.1188","4.1394"
"2.3200","0.5487","0.5487","0.3658","1.2022","4.4480"
"2.4000","0.5690","0.5690","0.3793","1.2872","4.7627"
"2.4800","0.5884","0.5884","0.3923","1.3663","5.0552"
"2.5600","0.6085","0.6085","0.4057","1.4530","5.3763"
"2.6400","0.6284","0.6284","0.4189","1.5371","5.6871"
"2.7200","0.6476","0.6476","0.4318","1.6178","5.9858"
"2.8000","0.6693","0.6693","0.4462","1.7116","6.3328"
"2.8800","0.6896","0.6896","0.4597","1.8002","6.6609"
"2.9600","0.7091","0.7091","0.4728","1.8860","6.9784"
"3.0400","0.7285","0.7285","0.4857","1.9720","7.2966"
"3.1200","0.7478","0.7478","0.4985","2.0547","7.6023"
"3.2000","0.7686","0.7686","0.5124","2.1491","7.9517"
"3.2800","0.7886","0.7886","0.5258","2.2359","8.2727"
"3.3600","0.8072","0.8072","0.5381","2.3245","8.6007"
"3.4400","0.8282","0.8282","0.5521","2.4233","8.9662"
"3.5200","0.8488","0.8488","0.5659","2.5168","9.3122"
"3.6000","0.8692","0.8692","0.5794","2.6161","9.6794"
"3.6800","0.8893","0.8893","0.5929","2.7091","10.0236"
"3.7600","0.9077","0.9077","0.6051","2.7956","10.3436"
"3.8400","0.9281","0.9281","0.6187","2.8971","10.7195"
"3.9200","0.9484","0.9484","0.6323","2.9901","11.0635"
"4.0000","0.9687","0.9687","0.6458","3.0951","11.4519"
"4.0800","0.9899","0.9899","0.6600","3.1999","11.8395"
"4.1600","1.0088","1.0088","0.6725","3.2821","12.1438"
"4.2400","1.0287","1.0287","0.6858","3.3833","12.5181"
"4.3200","1.0489","1.0489","0.6993","3.4862","12.8990"
"4.4000","1.0681","1.0681","0.7121","3.5760","13.2311"
"4.4800","1.0886","1.0886","0.7257","3.6806","13.6184"
"4.5600","1.1073","1.1073","0.7382","3.7761","13.9715"
"4.6400","1.1282","1.1282","0.7521","3.8775","14.3468"
"4.7200","1.1488","1.1488","0.7659","3.9835","14.7390"
"4.8000","1.1685","1.1685","0.7790","4.0863","15.1195"
"4.8800","1.1893","1.1893","0.7929","4.1857","15.4869"
"4.9600","1.2087","1.2087","0.8058","4.2862","15.8589"
"5.0400","1.2280","1.2280","0.8186","4.3889","16.2388"
"5.1200","1.2487","1.2487","0.8325","4.4935","16.6260"
"5.2000","1.2676","1.2676","0.8451","4.5890","16.9793"
"5.2800","1.2894","1.2894","0.8596","4.7100","17.4269"
"5.3600","1.3096","1.3096","0.8731","4.8168","17.8221"
"5.4400","1.3287","1.3287","0.8858","4.9151","18.1858"
"5.5200","1.3482","1.3482","0.8988","5.0219","18.5809"
"5.6000","1.3685","1.3685","0.9123","5.1291","18.9776"
"5.6800","1.3885","1.3885","0.9257","5.2375","19.3787"
"5.7600","1.4087","1.4087","0.9391","5.3430","19.7692"
"5.8400","1.4272","1.4272","0.9515","5.4448","20.1457"
"5.9200","1.4489","1.4489","0.9659","5.5679","20.6013"
"6.0000","1.4694","1.4694","0.9796","5.6817","21.0224"
"6.0800","1.4885","1.4885","0.9923","5.7801","21.3863"
"6.1600","1.5085","1.5085","1.0057","5.8899","21.7926"
"6.2400","1.5278","1.5278","1.0185","5.9945","22.1795"
"6.3200","1.5487","1.5487","1.0325","6.1119","22.6141"
"6.4000","1.5689","1.5689","1.0460","6.2262","23.0368"
"6.4800","1.5884","1.5884","1.0589","6.3324","23.4299"
"6.5600","1.6093","1.6093","1.0729","6.4486","23.8598"
"6.6400","1.6292","1.6292","1.0861","6.5598","24.2714"
"6.7200","1.6489","1.6489","1.0992","6.6719","24.6861"
"6.8000","1.6693","1.6693","1.1129","6.7892","25.1202"
"6.8800","1.6878","1.6878","1.1252","6.8930","25.5042"
"6.9600","1.7086","1.7086","1.1391","7.0109","25.9404"
"7.0400","1.7278","1.7278","1.1519","7.1101","26.3073"
"7.1200","1.7477","1.7477","1.1651","7.2247","26.7313"
"7.2000","1.7681","1.7681","1.1787","7.3429","27.1686"
"7.2800","1.7893","1.7893","1.1928","7.4624","27.6110"
"7.3600","1.8090","1.8090","1.2060","7.5747","28.0263"
"7.4400","1.8288","1.8288","1.2192","7.6878","28.4447"
"7.5200","1.8473","1.8473","1.2315","7.7955","28.8435"
"7.6000","1.8685","1.8685","1.2456","7.9197","29.3028"
"7.6800","1.8884","1.8884","1.2589","8.0264","29.6977"
"7.7600","1.9095","1.9095","1.2730","8.1489","30.1510"
"7.8400","1.9299","1.9299","1.2866","8.2637","30.5755"
"7.9200","1.9487","1.9487","1.2991","8.3717","30.9753"
"8.0000","1.9690","1.9690","1.3127","8.4915","31.4184"
"8.0800","1.9887","1.9887","1.3258","8.6056","31.8409"
"8.1600","2.0081","2.0081","1.3387","8.7181","32.2572"
"8.2400","2.0282","2.0282","1.3521","8.8366","32.6955"
"8.3200","2.0474","2.0474","1.3649","8.9455","33.0982"
"8.4000","2.0684","2.0684","1.3790","9.0620","33.5295"
"8.4800","2.0898","2.0898","1.3932","9.1881","33.9960"
"8.5600","2.1086","2.1086","1.4057","9.2986","34.4049"
"8.6400","2.1288","2.1288","1.4192","9.4166","34.8415"
"8.7200","2.1476","2.1476","1.4317","9.5247","35.2412"
"8.8000","2.1686","2.1686","1.4457","9.6498","35.7042"
"8.8800","2.1887","2.1887","1.4591","9.7674","36.1393"
"8.9600","2.2081","2.2081","1.4720","9.8815","36.5617"
"9.0400","2.2287","2.2287","1.4858","10.0060","37.0222"
"9.1200","2.2497","2.2497","1.4998","10.1245","37.4606"
"9.2000","2.2691","2.2691","1.5127","10.2395","37.8860"
"9.2800","2.2895","2.2895","1.5263","10.3623","38.3406"
"9.3600","2.3086","2.3086","1.5391","10.4708","38.7421"
"9.4400","2.3284","2.3284","1.5523","10.5871","39.1724"
"9.5200","2.3478","2.3478","1.5652","10.7034","39.6025"
"9.6000","2.3675","2.3675","1.5783","10.8220","40.0414"
"9.6800","2.3888","2.3888","1.5925","10.9482","40.5082"
"9.7600","2.4092","2.4092","1.6061","11.0679","40.9511"
"9.8400","2.4285","2.4285","1.6190","11.1763","41.3523"
"9.9200","2.4488","2.4488","1.6326","11.2970","41.7990"
"10.0000","2.4677","2.4677","1.6451","11.4042","42.1954"
"10.0800","2.4889","2.4889","1.6593","11.5327","42.6708"
"10.1600","2.5091","2.5091","1.6727","11.6497","43.1038"
"10.2400","2.5281","2.5281","1.6854","11.7620","43.5195"
"10.3200","2.5490","2.5490","1.6993","11.8864","43.9796"
"10.4000","2.5690","2.5690","1.7126","12.0040","44.4147"
"10.4800","2.5895","2.5895","1.7263","12.1244","44.8604"
"10.5600","2.6089","2.6089","1.7393","12.2373","45.2779"
"10.6400","2.6277","2.6277","1.7518","12.3419","45.6652"
"10.7200","2.6478","2.6478","1.7652","12.4619","46.1089"
"10.8000","2.6681","2.6681","1.7788","12.5803","46.5470"
"10.8800","2.6881","2.6881","1.7920","12.6985","46.9846"
"10.9600","2.7094","2.7094","1.8063","12.8249","47.4520"
"11.0400","2.7285","2.7285","1.8190","12.9359","47.8628"
"11.1200","2.7489","2.7489","1.8326","13.0532","48.2969"
"11.2000","2.7683","2.7683","1.8455","13.1656","48.7127"
"11.2800","2.7884","2.7884","1.8589","13.2878","49.1650"
"11.3600","2.8083","2.8083","1.8722","13.4014","49.5852"
"11.4400","2.8279","2.8279","1.8853","13.5110","49.9905"
"11.5200","2.8489","2.8489","1.8992","13.6428","50.4783"
"11.6000","2.8705","2.8705","1.9137","13.7697","50.9478"
"11.6800","2.8891","2.8891","1.9261","13.8736","51.3323"
"11.7600","2.9090","2.9090","1.9394","13.9896","51.7614"
"11.8400","2.9283","2.9283","1.9522","14.0986","52.1646"
"11.9200","2.9481","2.9481","1.9654","14.2161","52.5996"
"12.0000","2.9687","2.9687","1.9791","14.3363","53.0442"
"12.0800","2.9879","2.9879","1.9919","14.4455","53.4484"
"12.1600","3.0087","3.0087","2.0058","14.5656","53.8926"
"12.2400","3.0292","3.0292","2.0195","14.6837","54.3296"
"12.3200","3.0480","3.0480","2.0320","14.7864","54.7096"
"12.4000","3.0687","3.0687","2.0458","14.9060","55.1522"
"12.4800","3.0889","3.0889","2.0592","15.0191","55.5707"
"12.5600","3.1087","3.1087","2.0725","15.1342","55.9967"
"12.6400","3.1287","3.1287","2.0858","15.2481","56.4179"
"12.7200","3.1481","3.1481","2.0987","15.3616","56.8380"
"12.8000","3.1693","3.1693","2.1129","15.4833","57.2881"
"12.8800","3.1891","3.1891","2.1260","15.5960","57.7053"
"12.9600","3.2094","3.2094","2.1396","15.7128","58.1375"
"13.0400","3.2287","3.2287","2.1525","15.8249","58.5521"
"13.1200","3.2481","3.2481","2.1654","15.9334","58.9534"
"13.2000","3.2683","3.2683","2.1789","16.0454","59.3679"
"13.2800","3.2885","3.2885","2.1923","16.1612","59.7963"
"13.3600","3.3070","3.3070","2.2047","16.2651","60.1810"
"13.4400","3.3284","3.3284","2.2189","16.3897","60.6419"
"13.5200","3.3488","3.3488","2.2325","16.5045","61.0667"
"13.6000","3.3693","3.3693","2.2462","16.6218","61.5005"
"13.6800","3.3892","3.3892","2.2595","16.7349","61.9192"
"13.7600","3.4079","3.4079","2.2719","16.8355","62.2914"
"13.8400","3.4280","3.4280","2.2854","16.9508","62.7180"
"13.9200","3.4480","3.4480","2.2987","17.0630","63.1331"
"14.0000","3.4682","3.4682","2.3122","17.1797","63.5649"
"14.0800","3.4899","3.4899","2.3266","17.3029","64.0207"
"14.1600","3.5089","3.5089","2.3392","17.4064","64.4036"
"14.2400","3.5289","3.5289","2.3526","17.5206","64.8263"
"14.3200","3.5489","3.5489","2.3660","17.6321","65.2387"
"14.4000","3.5681","3.5681","2.3787","17.7398","65.6372"
"14.4800","3.5887","3.5887","2.3924","17.8558","66.0665"
"14.5600","3.6075","3.6075","2.4050","17.9557","66.4360"
"14.6400","3.6282","3.6282","2.4188","18.0742","66.8747"
"14.7200","3.6491","3.6491","2.4327","18.1937","67.3165"
"14.8000","3.6687","3.6687","2.4458","18.3033","67.7224"
"14.8800","3.6889","3.6889","2.4593","18.4148","68.1349"
"14.9600","3.7088","3.7088","2.4725","18.5235","68.5368"
"15.0400","3.7279","3.7279","2.4853","18.6296","68.9296"
"15.1200","3.7486","3.7486","2.4991","18.7447","69.3555"
"15.2000","3.7679","3.7679","2.5119","18.8449","69.7260"
"15.2800","3.7894","3.7894","2.5263","18.9660","70.1740"
"15.3600","3.8096","3.8096","2.5397","19.0760","70.5813"
"15.4400","3.8290","3.8290","2.5526","19.1826","70.9756"
"15.5200","3.8484","3.8484","2.5656","19.2886","71.3678"
"15.6000","3.8683","3.8683","2.5789","19.3984","71.7743"
"15.6800","3.8886","3.8886","2.5924","19.5100","72.1870"
"15.7600","3.9087","3.9087","2.6058","19.6186","72.5890"
"15.8400","3.9271","3.9271","2.6181","19.7171","72.9534"
"15.9200","3.9489","3.9489","2.6326","19.8393","73.4055"
"16.0000","3.9694","3.9694","2.6463","19.9510","73.8185"
"16.0800","3.9887","3.9887","2.6592","20.0527","74.1949"
"16.1600","4.0084","4.0084","2.6723","20.1566","74.5793"
"16.2400","4.0276","4.0276","2.6851","20.2600","74.9620"
"16.3200","4.0486","4.0486","2.6990","20.3750","75.3875"
"16.4000","4.0689","4.0689","2.7126","20.4836","75.7892"
"16.4800","4.0885","4.0885","2.7257","20.5922","76.1911"
"16.5600","4.1091","4.1091","2.7394","20.7051","76.6089"
"16.6400","4.1290","4.1290","2.7526","20.8079","76.9892"
"16.7200","4.1488","4.1488","2.7659","20.9131","77.3784"
"16.8000","4.1692","4.1692","2.7795","21.0209","77.7772"
"16.8800","4.1880","4.1880","2.7920","21.1235","78.1570"
"16.9600","4.2086","4.2086","2.8057","21.2332","78.5628"
"17.0400","4.2278","4.2278","2.8185","21.3321","78.9287"
"17.1200","4.2477","4.2477","2.8318","21.4382","79.3212"
"17.2000","4.2684","4.2684","2.8456","21.5516","79.7411"
"17.2800","4.2892","4.2892","2.8595","21.6592","80.1389"
"17.3600","4.3093","4.3093","2.8729","21.7645","80.5286"
"17.4400","4.3291","4.3291","2.8861","21.8675","80.9096"
"17.5200","4.3475","4.3475","2.8983","21.9606","81.2544"
"17.6000","4.3684","4.3684","2.9122","22.0734","81.6716"
"17.6800","4.3881","4.3881","2.9254","22.1738","82.0429"
"17.7600","4.4088","4.4088","2.9392","22.2855","82.4565"
"17.8400","4.4298","4.4298","2.9532","22.3934","82.8556"
"17.9200","4.4486","4.4486","2.9657","22.4900","83.2131"
"18.0000","4.4687","4.4687","2.9792","22.5948","83.6008"
"18.0800","4.4888","4.4888","2.9925","22.6998","83.9893"
"18.1600","4.5080","4.5080","3.0054","22.7983","84.3539"
"18.2400","4.5282","4.5282","3.0188","22.9020","84.7373"
"18.3200","4.5474","4.5474","3.0316","22.9996","85.0984"
"18.4000","4.5680","4.5680","3.0453","23.1066","85.4943"
"18.4800","4.5897","4.5897","3.0598","23.2198","85.9131"
"18.5600","4.6084","4.6084","3.0722","23.3139","86.2615"
"18.6400","4.6284","4.6284","3.0856","23.4170","86.6428"
"18.7200","4.6475","4.6475","3.0983","23.5115","86.9925"
"18.8000","4.6687","4.6687","3.1124","23.6222","87.4023"
"18.8800","4.6889","4.6889","3.1259","23.7268","87.7893"
"18.9600","4.7082","4.7082","3.1388","23.8189","88.1298"
"19.0400","4.7288","4.7288","3.1526","23.9291","88.5375"
"19.1200","4.7496","4.7496","3.1664","24.0327","88.9211"
"19.2000","4.7689","4.7689","3.1793","24.1302","89.2817"
"19.2800","4.7893","4.7893","3.1929","24.2354","89.6710"
"19.3600","4.8081","4.8081","3.2054","24.3251","90.0027"
"19.4400","4.8280","4.8280","3.2187","24.4232","90.3659"
"19.5200","4.8480","4.8480","3.2320","24.5229","90.7347"
"19.6000","4.8679","4.8679","3.2453","24.6250","91.1124"
"19.6800","4.8890","4.8890","3.2594","24.7314","91.5061"
"19.7600","4.9091","4.9091","3.2728","24.8318","91.8775"
"19.8400","4.9289","4.9289","3.2859","24.9270","92.2298"
"19.9200","4.9490","4.9490","3.2993","25.0281","92.6041"
"20.0000","4.9676","4.9676","3.3118","25.1183","92.9376"
"20.0800","4.9887","4.9887","3.3258","25.2242","93.3295"
"20.1600","5.0089","5.0089","3.3393","25.3243","93.7000"
"20.2400","5.0281","5.0281","3.3521","25.4183","94.0477"
"20.3200","5.0490","5.0490","3.3660","25.5239","94.4385"
"20.4000","5.0688","5.0688","3.3792","25.6189","94.7900"
"20.4800","5.0895","5.0895","3.3930","25.7168","95.1521"
"20.5600","5.1090","5.1090","3.4060","25.8131","95.5086"
"20.6400","5.1278","5.1278","3.4185","25.9035","95.8429"
"20.7200","5.1479","5.1479","3.4319","26.0004","96.2013"
"20.8000","5.1681","5.1681","3.4454","26.1002","96.5709"
"20.8800","5.1882","5.1882","3.4588","26.1972","96.9295"
"20.9600","5.2096","5.2096","3.4731","26.3045","97.3267"
"21.0400","5.2285","5.2285","3.4857","26.3926","97.6527"
"21.1200","5.2487","5.2487","3.4992","26.4894","98.0108"
"21.2000","5.2684","5.2684","3.5123","26.5808","98.3491"
"21.2800","5.2885","5.2885","3.5257","26.6817","98.7222"
"21.3600","5.3085","5.3085","3.5390","26.7764","99.0727"
"21.4400","5.3279","5.3279","3.5520","26.8670","99.4081"
"21.5200","5.3485","5.3485","3.5657","26.9662","99.7749"
"21.6000","5.3699","5.3699","3.5799","27.0710","100.1628"
"21.6800","5.3892","5.3892","3.5928","27.1622","100.5000"
"21.7600","5.4093","5.4093","3.6062","27.2550","100.8433"
"21.8400","5.4280","5.4280","3.6186","27.3380","101.1508"
"21.9200","5.4479","5.4479","3.6319","27.4326","101.5005"
"22.0000","5.4685","5.4685","3.6457","27.5315","101.8666"
"22.0800","5.4876","5.4876","3.6584","27.6173","102.1840"
"22.1600","5.5086","5.5086","3.6724","27.7164","102.5507"
"22.2400","5.5292","5.5292","3.6861","27.8129","102.9076"
"22.3200","5.5488","5.5488","3.6992","27.9036","103.2432"
"22.4000","5.5687","5.5687","3.7125","27.9973","103.5899"
"22.4800","5.5882","5.5882","3.7255","28.0863","103.9194"
"22.5600","5.6088","5.6088","3.7392","28.1827","104.2759"
"22.6400","5.6292","5.6292","3.7528","28.2741","104.6143"
"22.7200","5.6476","5.6476","3.7650","28.3579","104.9242"
"22.8000","5.6689","5.6689","3.7793","28.4582","105.2955"
"22.8800","5.6897","5.6897","3.7931","28.5525","105.6443"
"22.9600","5.7094","5.7094","3.8063","28.6436","105.9812"
"23.0400","5.7289","5.7289","3.8193","28.7310","106.3049"
"23.1200","5.7481","5.7481","3.8321","28.8124","106.6059"
"23.2000","5.7685","5.7685","3.8457","28.9063","106.9532"
"23.2800","5.7886","5.7886","3.8591","28.9976","107.2910"
"23.3600","5.8075","5.8075","3.8716","29.0804","107.5973"
"23.4400","5.8284","5.8284","3.8856","29.1761","107.9514"
"23.5200","5.8485","5.8485","3.8990","29.2619","108.2689"
"23.6000","5.8696","5.8696","3.9130","29.3565","108.6189"
"23.6800","5.8891","5.8891","3.9261","29.4403","108.9293"
"23.7600","5.9079","5.9079","3.9386","29.5235","109.2371"
"23.8400","5.9280","5.9280","3.9520","29.6089","109.5530"
"23.9200","5.9480","5.9480","3.9654","29.6980","109.8826"
"24.0000","5.9687","5.9687","3.9791","29.7918","110.2296"
"24.0800","5.9902","5.9902","3.9935","29.8904","110.5946"
"24.1600","6.0092","6.0092","4.0061","29.9643","110.8679"
"24.2400","6.0291","6.0291","4.0194","30.0519","111.1919"
"24.3200","6.0488","6.0488","4.0325","30.1328","111.4913"
"24.4000","6.0680","6.0680","4.0453","30.2159","111.7989"
"24.4800","6.0886","6.0886","4.0591","30.3057","112.1310"
"24.5600","6.1074","6.1074","4.0716","30.3852","112.4251"
"24.6400","6.1278","6.1278","4.0852","30.4716","112.7450"
"24.7200","6.1484","6.1484","4.0990","30.5574","113.0625"
"24.8000","6.1689","6.1689","4.1126","30.6455","113.3884"
"24.8800","6.1890","6.1890","4.1260","30.7304","113.7024"
"24.9600","6.2088","6.2088","4.1392","30.8096","113.9954"
"25.0400","6.2274","6.2274","4.1516","30.8857","114.2772"
"25.1200","6.2488","6.2488","4.1659","30.9779","114.6184"
"25.2000","6.2678","6.2678","4.1786","31.0553","114.9045"
"25.2800","6.2897","6.2897","4.1931","31.1475","115.2457"
"25.3600","6.3097","6.3097","4.2064","31.2306","115.5532"
"25.4400","6.3290","6.3290","4.2193","31.3087","115.8422"
"25.5200","6.3483","6.3483","4.2322","31.3857","116.1272"
"25.6000","6.3686","6.3686","4.2458","31.4701","116.4395"
"25.6800","6.3888","6.3888","4.2592","31.5509","116.7383"
"25.7600","6.4086","6.4086","4.2724","31.6285","117.0255"
"25.8400","6.4273","6.4273","4.2848","31.7033","117.3021"
"25.9200","6.4488","6.4488","4.2992","31.7940","117.6378"
"26.0000","6.4694","6.4694","4.3130","31.8769","117.9447"
"26.0800","6.4888","6.4888","4.3259","31.9534","118.2274"
"26.1600","6.5082","6.5082","4.3388","32.0278","118.5028"
"26.2400","6.5274","6.5274","4.3516","32.1030","118.7809"
"26.3200","6.5486","6.5486","4.3657","32.1880","119.0955"
"26.4000","6.5691","6.5691","4.3794","32.2689","119.3951"
"26.4800","6.5887","6.5887","4.3925","32.3475","119.6857"
"26.5600","6.6090","6.6090","4.4060","32.4266","119.9784"
"26.6400","6.6288","6.6288","4.4192","32.5007","120.2525"
"26.7200","6.6489","6.6489","4.4326","32.5782","120.5392"
"26.8000","6.6692","6.6692","4.4462","32.6559","120.8268"
"26.8800","6.6878","6.6878","4.4585","32.7248","121.0818"
"26.9600","6.7084","6.7084","4.4723","32.8058","121.3816"
"27.0400","6.7276","6.7276","4.4851","32.8740","121.6339"
"27.1200","6.7476","6.7476","4.4984","32.9516","121.9208"
"27.2000","6.7690","6.7690","4.5127","33.0366","122.2356"
"27.2800","6.7895","6.7895","4.5263","33.1108","122.5099"
"27.3600","6.8090","6.8090","4.5393","33.1811","122.7702"
"27.4400","6.8289","6.8289","4.5526","33.2559","123.0469"
"27.5200","6.8476","6.8476","4.5650","33.3216","123.2900"
"27.6000","6.8682","6.8682","4.5788","33.3983","123.5739"
"27.6800","6.8876","6.8876","4.5918","33.4652","123.8211"
"27.7600","6.9092","6.9092","4.6061","33.5467","124.1227"
"27.8400","6.9299","6.9299","4.6199","33.6216","124.3998"
"27.9200","6.9488","6.9488","4.6326","33.6874","124.6432"
"28.0000","6.9689","6.9689","4.6460","33.7580","124.9047"
"28.0800","6.9892","6.9892","4.6595","33.8327","125.1811"
"28.1600","7.0086","7.0086","4.6724","33.9009","125.4334"
"28.2400","7.0280","7.0280","4.6854","33.9665","125.6759"
"28.3200","7.0472","7.0472","4.6982","34.0297","125.9098"
"28.4000","7.0683","7.0683","4.7122","34.1076","126.1981"
"28.4800","7.0898","7.0898","4.7265","34.1819","126.4730"
"28.5600","7.1085","7.1085","4.7390","34.2440","126.7027"
"28.6400","7.1288","7.1288","4.7525","34.3126","126.9565"
"28.7200","7.1478","7.1478","4.7652","34.3746","127.1860"
"28.8000","7.1689","7.1689","4.7793","34.4491","127.4617"
"28.8800","7.1888","7.1888","4.7925","34.5130","127.6981"
"28.9600","7.2081","7.2081","4.8054","34.5762","127.9320"
"29.0400","7.2286","7.2286","4.8191","34.6440","128.1829"
"29.1200","7.2496","7.2496","4.8330","34.7181","128.4570"
"29.2000","7.2691","7.2691","4.8460","34.7763","128.6722"
"29.2800","7.2892","7.2892","4.8595","34.8406","128.9101"
"29.3600","7.3078","7.3078","4.8719","34.8947","129.1102"
"29.4400","7.3281","7.3281","4.8854","34.9592","129.3489"
"29.5200","7.3486","7.3486","4.8991","35.0229","129.5847"
"29.6000","7.3677","7.3677","4.9118","35.0834","129.8085"
"29.6800","7.3885","7.3885","4.9256","35.1523","130.0637"
"29.7600","7.4093","7.4093","4.9395","35.2184","130.3080"
"29.8400","7.4291","7.4291","4.9527","35.2778","130.5280"
"29.9200","7.4490","7.4490","4.9660","35.3376","130.7490"
"30.0000","7.4679","7.4679","4.9786","35.3916","130.9490"
"30.0800","7.4886","7.4886","4.9924","35.4574","131.1924"
"30.1600","7.5086","7.5086","5.0057","35.5150","131.4055"
"30.2400","7.5280","7.5280","5.0187","35.5751","131.6280"
"30.3200","7.5492","7.5492","5.0328","35.6392","131.8649"
"30.4000","7.5692","7.5692","5.0461","35.6965","132.0771"
"30.4800","7.5897","7.5897","5.0598","35.7557","132.2960"
"30.5600","7.6090","7.6090","5.0727","35.8088","132.4927"
"30.6400","7.6277","7.6277","5.0851","35.8578","132.6740"
"30.7200","7.6476","7.6476","5.0984","35.9167","132.8918"
"30.8000","7.6681","7.6681","5.1121","35.9732","133.1010"
"30.8800","7.6882","7.6882","5.1255","36.0322","133.3193"
"30.9600","7.7095","7.7095","5.1397","36.0946","133.5500"
"31.0400","7.7286","7.7286","5.1524","36.1419","133.7249"
"31.1200","7.7489","7.7489","5.1660","36.2003","133.9411"
"31.2000","7.7685","7.7685","5.1790","36.2470","134.1139"
"31.2800","7.7880","7.7880","5.1920","36.3019","134.3171"
"31.3600","7.8084","7.8084","5.2056","36.3590","134.5284"
"31.4400","7.8280","7.8280","5.2186","36.4051","134.6988"
"31.5200","7.8487","7.8487","5.2325","36.4595","134.9001"
"31.6000","7.8702","7.8702","5.2468","36.5177","135.1154"
"31.6800","7.8892","7.8892","5.2595","36.5660","135.2941"
"31.7600","7.9094","7.9094","5.2730","36.6144","135.4731"
"31.8400","7.9280","7.9280","5.2853","36.6566","135.6293"
"31.9200","7.9477","7.9477","5.2985","36.7041","135.8051"
"32.0000","7.9685","7.9685","5.3123","36.7576","136.0031"
"32.0800","7.9877","7.9877","5.3251","36.8024","136.1688"
"32.1600","8.0086","8.0086","5.3391","36.8524","136.3539"
"32.2400","8.0291","8.0291","5.3527","36.9031","136.5414"
"32.3200","8.0488","8.0488","5.3659","36.9484","136.7091"
"32.4000","8.0687","8.0687","5.3792","36.9972","136.8896"
"32.4800","8.0885","8.0885","5.3923","37.0361","137.0337"
"32.5600","8.1087","8.1087","5.4058","37.0849","137.2139"
"32.6400","8.1286","8.1286","5.4191","37.1240","137.3587"
"32.7200","8.1475","8.1475","5.4316","37.1660","137.5143"
"32.8000","8.1693","8.1693","5.4462","37.2209","137.7174"
"32.8800","8.1895","8.1895","5.4597","37.2608","137.8650"
"32.9600","8.2096","8.2096","5.4730","37.3057","138.0311"
"33.0400","8.2286","8.2286","5.4857","37.3398","138.1572"
"33.1200","8.2479","8.2479","5.4986","37.3774","138.2965"
"33.2000","8.2683","8.2683","5.5122","37.4182","138.4475"
"33.2800","8.2888","8.2888","5.5259","37.4611","138.6060"
"33.3600","8.3073","8.3073","5.5382","37.4947","138.7303"
"33.4400","8.3283","8.3283","5.5522","37.5400","138.8981"
"33.5200","8.3485","8.3485","5.5657","37.5801","139.0462"
"33.6000","8.3695","8.3695","5.5797","37.6228","139.2043"
"33.6800","8.3891","8.3891","5.5927","37.6560","139.3272"
"33.7600","8.4080","8.4080","5.6053","37.6909","139.4562"
"33.8400","8.4283","8.4283","5.6188","37.7280","139.5934"
"33.9200","8.4483","8.4483","5.6322","37.7632","139.7237"
"34.0000","8.4686","8.4686","5.6458","37.8021","139.8677"
"34.0800","8.4898","8.4898","5.6599","37.8450","140.0266"
"34.1600","8.5090","8.5090","5.6727","37.8712","140.1233"
"34.2400","8.5291","8.5291","5.6861","37.9076","140.2580"
"34.3200","8.5487","8.5487","5.6991","37.9407","140.3805"
"34.4000","8.5678","8.5678","5.7119","37.9721","140.4969"
"34.4800","8.5885","8.5885","5.7257","38.0099","140.6367"
"34.5600","8.6074","8.6074","5.7383","38.0331","140.7225"
"34.6400","8.6283","8.6283","5.7522","38.0708","140.8619"
"34.7200","8.6492","8.6492","5.7661","38.1106","141.0092"
"34.8000","8.6691","8.6691","5.7794","38.1418","141.1247"
"34.8800","8.6891","8.6891","5.7927","38.1725","141.2382"
"34.9600","8.7087","8.7087","5.8058","38.2039","141.3544"
"35.0400","8.7277","8.7277","5.8184","38.2298","141.4501"
"35.1200","8.7485","8.7485","5.8323","38.2657","141.5831"
"35.2000","8.7679","8.7679","5.8453","38.2922","141.6813"
"35.2800","8.7897","8.7897","5.8598","38.3270","141.8100"
"35.3600","8.8099","8.8099","5.8733","38.3557","141.9161"
"35.4400","8.8285","8.8285","5.8857","38.3797","142.0049"
"35.5200","8.8484","8.8484","5.8989","38.4085","142.1115"
"35.6000","8.8686","8.8686","5.9124","38.4331","142.2024"
"35.6800","8.8887","8.8887","5.9258","38.4645","142.3187"
"35.7600","8.9091","8.9091","5.9394","38.4904","142.4144"
"35.8400","8.9270","8.9270","5.9514","38.5100","142.4869"
"35.9200","8.9484","8.9484","5.9656","38.5449","142.6162"
"36.0000","8.9695","8.9695","5.9796","38.5773","142.7360"
"36.0800","8.9892","8.9892","5.9928","38.6002","142.8206"
"36.1600","9.0088","9.0088","6.0059","38.6273","142.9210"
"36.2400","9.0277","9.0277","6.0184","38.6436","142.9814"
"36.3200","9.0481","9.0481","6.0321","38.6713","143.0837"
"36.4000","9.0687","9.0687","6.0458","38.6988","143.1855"
"36.4800","9.0886","9.0886","6.0591","38.7219","143.2712"
"36.5600","9.1090","9.1090","6.0727","38.7476","143.3660"
"36.6400","9.1288","9.1288","6.0859","38.7682","143.4422"
"36.7200","9.1490","9.1490","6.0993","38.7925","143.5322"
"36.8000","9.1691","9.1691","6.1127","38.8139","143.6116"
"36.8800","9.1879","9.1879","6.1253","38.8275","143.6616"
"36.9600","9.2089","9.2089","6.1393","38.8557","143.7661"
"37.0400","9.2276","9.2276","6.1517","38.8705","143.8208"
"37.1200","9.2476","9.2476","6.1650","38.8928","143.9034"
"37.2000","9.2688","9.2688","6.1792","38.9216","144.0100"
"37.2800","9.2893","9.2893","6.1929","38.9399","144.0776"
"37.3600","9.3091","9.3091","6.2060","38.9576","144.1432"
"37.4400","9.3292","9.3292","6.2194","38.9760","144.2113"
"37.5200","9.3475","9.3475","6.2317","38.9899","144.2625"
"37.6000","9.3685","9.3685","6.2457","39.0121","144.3449"
"37.6800","9.3881","9.3881","6.2587","39.0265","144.3979"
"37.7600","9.4088","9.4088","6.2725","39.0493","144.4824"
"37.8400","9.4299","9.4299","6.2866","39.0711","144.5629"
"37.9200","9.4486","9.4486","6.2990","39.0819","144.6029"
"38.0000","9.4690","9.4690","6.3126","39.1008","144.6731"
"38.0800","9.4889","9.4889","6.3259","39.1156","144.7278"
"38.1600","9.5081","9.5081","6.3387","39.1338","144.7951"
"38.2400","9.5281","9.5281","6.3520","39.1501","144.8555"
"38.3200","9.5475","9.5475","6.3650","39.1617","144.8983"
"38.4000","9.5684","9.5684","6.3790","39.1821","144.9737"
"38.4800","9.5897","9.5897","6.3931","39.2016","145.0461"
"38.5600","9.6087","9.6087","6.4058","39.2160","145.0994"
"38.6400","9.6290","9.6290","6.4193","39.2324","145.1600"
"38.7200","9.6479","9.6479","6.4319","39.2414","145.1931"
"38.8000","9.6688","9.6688","6.4458","39.2624","145.2708"
"38.8800","9.6888","9.6888","6.4592","39.2735","145.3118"
"38.9600","9.7077","9.7077","6.4718","39.2848","145.3536"
"39.0400","9.7286","9.7286","6.4857","39.3005","145.4117"
"39.1200","9.7498","9.7498","6.4999","39.3213","145.4888"
"39.2000","9.7689","9.7689","6.5126","39.3324","145.5298"
"39.2800","9.7893","9.7893","6.5262","39.3468","145.5831"
"39.3600","9.8078","9.8078","6.5385","39.3534","145.6076"
"39.4400","9.8282","9.8282","6.5521","39.3678","145.6610"
"39.5200","9.8481","9.8481","6.5654","39.3803","145.7070"
"39.6000","9.8675","9.8675","6.5783","39.3947","145.7603"
"39.6800","9.8889","9.8889","6.5926","39.4122","145.8253"
"39.7600","9.9094","9.9094","6.6063","39.4279","145.8831"
"39.8400","9.9288","9.9288","6.6192","39.4347","145.9083"
"39.9200","9.9487","9.9487","6.6324","39.4477","145.9566"
"40.0000","9.9673","9.9673","6.6448","39.4548","145.9828"
"40.0800","9.9886","9.9886","6.6590","39.4734","146.0517"
"40.1600","10.0090","10.0090","6.6727","39.4885","146.1075"
"40.2400","10.0283","10.0283","6.6856","39.4982","146.1434"
"40.3200","10.0488","10.0488","6.6992","39.5108","146.1900"
"40.4000","10.0693","10.0693","6.7128","39.5235","146.2371"
"40.4800","10.0896","10.0896","6.7264","39.5367","146.2856"
"40.5600","10.1092","10.1092","6.7395","39.5433","146.3101"
"40.6400","10.1281","10.1281","6.7521","39.5533","146.3473"
"40.7200","10.1479","10.1479","6.7652","39.5641","146.3871"
"40.8000","10.1680","10.1680","6.7787","39.5758","146.4305"
"40.8800","10.1881","10.1881","6.7920","39.5888","146.4787"
"40.9600","10.2098","10.2098","6.8066","39.6040","146.5346"
"41.0400","10.2285","10.2285","6.8190","39.6072","146.5465"
"41.1200","10.2493","10.2493","6.8329","39.6212","146.5984"
"41.2000","10.2682","10.2682","6.8454","39.6254","146.6141"
"41.2800","10.2878","10.2878","6.8586","39.6352","146.6504"
"41.3600","10.3083","10.3083","6.8722","39.6477","146.6963"
"41.4400","10.3282","10.3282","6.8855","39.6548","146.7228"
"41.5200","10.3488","10.3488","6.8992","39.6672","146.7688"
"41.6000","10.3700","10.3700","6.9134","39.6811","146.8199"
"41.6800","10.3890","10.3890","6.9260","39.6861","146.8387"
"41.7600","10.4091","10.4091","6.9394","39.6978","146.8818"
"41.8400","10.4280","10.4280","6.9520","39.7015","146.8954"
"41.9200","10.4480","10.4480","6.9654","39.7100","146.9268"
"42.0000","10.4687","10.4687","6.9792","39.7202","146.9648"
"42.0800","10.4875","10.4875","6.9917","39.7244","146.9805"
"42.1600","10.5085","10.5085","7.0057","39.7363","147.0243"
"42.2400","10.5290","10.5290","7.0194","39.7467","147.0628"
"42.3200","10.5485","10.5485","7.0323","39.7540","147.0900"
"42.4000","10.5688","10.5688","7.0459","39.7650","147.1305"
"42.4800","10.5886","10.5886","7.0591","39.7712","147.1535"
"42.5600","10.6085","10.6085","7.0724","39.7769","147.1744"
"42.6400","10.6291","10.6291","7.0861","39.7854","147.2059"
"42.7200","10.6474","10.6474","7.0983","39.7883","147.2166"
"42.8000","10.6691","10.6691","7.1128","39.8028","147.2703"
"42.8800","10.6893","10.6893","7.1262","39.8103","147.2982"
"42.9600","10.7097","10.7097","7.1398","39.8184","147.3282"
"43.0400","10.7286","10.7286","7.1524","39.8215","147.3394"
"43.1200","10.7477","10.7477","7.1652","39.8245","147.3505"
"43.2000","10.7687","10.7687","7.1791","39.8357","147.3921"
"43.2800","10.7891","10.7891","7.1927","39.8432","147.4197"
"43.3600","10.8073","10.8073","7.2048","39.8438","147.4219"
"43.4400","10.8288","10.8288","7.2192","39.8559","147.4669"
"43.5200","10.8483","10.8483","7.2322","39.8599","147.4818"
"43.6000","10.8693","10.8693","7.2462","39.8699","147.5185"
"43.6800","10.8892","10.8892","7.2595","39.8696","147.5175"
"43.7600","10.9079","10.9079","7.2719","39.8713","147.5239"
"43.8400","10.9281","10.9281","7.2854","39.8766","147.5435"
"43.9200","10.9482","10.9482","7.2988","39.8803","147.5570"
"44.0000","10.9687","10.9687","7.3124","39.8896","147.5916"
"44.0800","10.9898","10.9898","7.3265","39.8997","147.6288"
"44.1600","11.0092","11.0092","7.3395","39.8986","147.6249"
"44.2400","11.0288","11.0288","7.3525","39.9022","147.6381"
"44.3200","11.0486","11.0486","7.3657","39.9048","147.6477"
"44.4000","11.0678","11.0678","7.3785","39.9105","147.6689"
"44.4800","11.0889","11.0889","7.3926","39.9223","147.7124"
"44.5600","11.1074","11.1074","7.4049","39.9172","147.6935"
"44.6400","11.1279","11.1279","7.4186","39.9227","147.7142"
"44.7200","11.1489","11.1489","7.4326","39.9301","147.7415"
"44.8000","11.1693","11.1693","7.4462","39.9378","147.7699"
"44.8800","11.1889","11.1889","7.4593","39.9370","147.7667"
"44.9600","11.2085","11.2085","7.4723","39.9378","147.7698"
"45.0400","11.2279","11.2279","7.4853","39.9416","147.7839"
"45.1200","11.2487","11.2487","7.4991","39.9506","147.8171"
"45.2000","11.2680","11.2680","7.5120","39.9516","147.8209"
"45.2800","11.2894","11.2894","7.5262","39.9585","147.8466"
"45.3600","11.3093","11.3093","7.5395","39.9614","147.8573"
"45.4400","11.3293","11.3293","7.5529","39.9647","147.8696"
"45.5200","11.3488","11.3488","7.5659","39.9688","147.8846"
"45.6000","11.3686","11.3686","7.5791","39.9690","147.8855"
"45.6800","11.3883","11.3883","7.5922","39.9715","147.8947"
"45.7600","11.4088","11.4088","7.6059","39.9785","147.9205"
"45.8400","11.4273","11.4273","7.6182","39.9776","147.9172"
"45.9200","11.4486","11.4486","7.6324","39.9855","147.9462"
"46.0000","11.4697","11.4697","7.6465","39.9924","147.9718"
"46.0800","11.4887","11.4887","7.6592","39.9910","147.9668"
"46.1600","11.5082","11.5082","7.6721","39.9934","147.9757"
"46.2400","11.5277","11.5277","7.6851","39.9953","147.9827"
"46.3200","11.5489","11.5489","7.6993","39.9982","147.9934"
"46.4000","11.5688","11.5688","7.7125","39.9995","147.9982"
"46.4800","11.5885","11.5885","7.7256","40.0049","148.0180"
"46.5600","11.6088","11.6088","7.7392","40.0079","148.0293"
"46.6400","11.6288","11.6288","7.7525","40.0096","148.0356"
"46.7200","11.6489","11.6489","7.7659","40.0112","148.0415"
"46.8000","11.6693","11.6693","7.7795","40.0149","148.0551"
"46.8800","11.6882","11.6882","7.7922","40.0139","148.0513"
"46.9600","11.7087","11.7087","7.8058","40.0165","148.0612"
"47.0400","11.7275","11.7275","7.8183","40.0119","148.0440"
"47.1200","11.7478","11.7478","7.8319","40.0179","148.0662"
"47.2000","11.7689","11.7689","7.8459","40.0237","148.0876"
"47.2800","11.7894","11.7894","7.8596","40.0246","148.0912"
"47.3600","11.8090","11.8090","7.8727","40.0220","148.0816"
"47.4400","11.8289","11.8289","7.8859","40.0218","148.0808"
"47.5200","11.8473","11.8473","7.8982","40.0223","148.0826"
"47.6000","11.8685","11.8685","7.9123","40.0260","148.0962"
"47.6800","11.8883","11.8883","7.9255","40.0263","148.0972"
"47.7600","11.9087","11.9087","7.9391","40.0255","148.0945"
"47.8400","11.9293","11.9293","7.9528","40.0270","148.0998"
"47.9200","11.9488","11.9488","7.9658","40.0261","148.0967"
"48.0000","11.9690","11.9690","7.9793","40.0255","148.0942"
"48.0800","11.9890","11.9890","7.9927","40.0255","148.0943"
"48.1600","12.0083","12.0083","8.0055","40.0237","148.0878"
"48.2400","12.0284","12.0284","8.0190","40.0262","148.0968"
"48.3200","12.0474","12.0474","8.0316","40.0204","148.0755"
"48.4000","12.0683","12.0683","8.0455","40.0247","148.0912"
"48.4800","12.0899","12.0899","8.0599","40.0265","148.0980"
"48.5600","12.1088","12.1088","8.0725","40.0247","148.0914"
"48.6400","12.1287","12.1287","8.0858","40.0180","148.0664"
"48.7200","12.1478","12.1478","8.0985","40.0153","148.0567"
"48.8000","12.1689","12.1689","8.1126","40.0189","148.0701"
"48.8800","12.1887","12.1887","8.1258","40.0161","148.0595"
"48.9600","12.2084","12.2084","8.1390","40.0140","148.0519"
"49.0400","12.2287","12.2287","8.1525","40.0115","148.0425"
"49.1200","12.2498","12.2498","8.1665","40.0095","148.0352"
"49.2000","12.2688","12.2688","8.1792","40.0060","148.0223"
"49.2800","12.2891","12.2891","8.1928","40.0017","148.0063"
"49.3600","12.3079","12.3079","8.2053","39.9943","147.9788"
"49.4400","12.3284","12.3284","8.2189","39.9930","147.9742"
"49.5200","12.3477","12.3477","8.2318","39.9898","147.9623"
"49.6000","12.3675","12.3675","8.2450","39.9926","147.9727"
"49.6800","12.3891","12.3891","8.2594","39.9974","147.9904"
"49.7600","12.4092","12.4092","8.2728","39.9931","147.9743"
"49.8400","12.4287","12.4287","8.2858","39.9906","147.9651"
"49.9200","12.4488","12.4488","8.2992","39.9893","147.9603"
"50.0000","12.4678","12.4678","8.3118","39.9849","147.9440"
"50.0800","12.4881","12.4881","8.3254","39.9823","147.9344"
"50.1600","12.5087","12.5087","8.3391","39.9849","147.9440"
"50.2400","12.5283","12.5283","8.3522","39.9818","147.9326"
"50.3200","12.5491","12.5491","8.3661","39.9820","147.9335"
"50.4000","12.5688","12.5688","8.3792","39.9757","147.9103"
"50.4800","12.5896","12.5896","8.3931","39.9747","147.9063"
"50.5600","12.6091","12.6091","8.4061","39.9693","147.8863"
"50.6400","12.6281","12.6281","8.4187","39.9642","147.8676"
"50.7200","12.6478","12.6478","8.4319","39.9633","147.8641"
"50.8000","12.6681","12.6681","8.4454","39.9592","147.8489"
"50.8800","12.6882","12.6882","8.4588","39.9568","147.8402"
"50.9600","12.7098","12.7098","8.4732","39.9578","147.8439"
"51.0400","12.7282","12.7282","8.4855","39.9398","147.7773"
"51.1200","12.7487","12.7487","8.4991","39.9359","147.7628"
"51.2000","12.7686","12.7686","8.5124","39.9296","147.7393"
"51.2800","12.7885","12.7885","8.5256","39.9251","147.7229"
"51.3600","12.8083","12.8083","8.5389","39.9204","147.7055"
"51.4400","12.8280","12.8280","8.5520","39.9095","147.6653"
"51.5200","12.8487","12.8487","8.5658","39.9069","147.6554"
"51.6000","12.8704","12.8704","8.5802","39.9065","147.6539"
"51.6800","12.8894","12.8894","8.5929","39.8991","147.6267"
"51.7600","12.9089","12.9089","8.6059","39.8939","147.6073"
"51.8400","12.9281","12.9281","8.6188","39.8867","147.5809"
"51.9200","12.9480","12.9480","8.6320","39.8832","147.5679"
"52.0000","12.9685","12.9685","8.6457","39.8833","147.5682"
"52.0800","12.9876","12.9876","8.6584","39.8750","147.5374"
"52.1600","13.0089","13.0089","8.6726","39.8708","147.5218"
"52.2400","13.0292","13.0292","8.6862","39.8649","147.5003"
"52.3200","13.0484","13.0484","8.6989","39.8551","147.4640"
"52.4000","13.0685","13.0685","8.7124","39.8508","147.4478"
"52.4800","13.0880","13.0880","8.7253","39.8407","147.4104"
"52.5600","13.1086","13.1086","8.7391","39.8402","147.4086"
"52.6400","13.1291","13.1291","8.7528","39.8368","147.3961"
"52.7200","13.1477","13.1477","8.7651","39.8296","147.3694"
"52.8000","13.1693","13.1693","8.7795","39.8316","147.3768"
"52.8800","13.1891","13.1891","8.7927","39.8257","147.3550"
"52.9600","13.2098","13.2098","8.8065","39.8210","147.3378"
"53.0400","13.2289","13.2289","8.8192","39.8157","147.3182"
"53.1200","13.2481","13.2481","8.8321","39.8087","147.2921"
"53.2000","13.2684","13.2684","8.8456","39.8057","147.2811"
"53.2800","13.2887","13.2887","8.8591","39.8019","147.2671"
"53.3600","13.3072","13.3072","8.8715","39.7964","147.2467"
"53.4400","13.3286","13.3286","8.8858","39.7970","147.2487"
"53.5200","13.3486","13.3486","8.8991","39.7932","147.2349"
"53.6000","13.3695","13.3695","8.9130","39.7871","147.2123"
"53.6800","13.3891","13.3891","8.9261","39.7818","147.1928"
"53.7600","13.4080","13.4080","8.9386","39.7744","147.1652"
"53.8400","13.4282","13.4282","8.9521","39.7717","147.1554"
"53.9200","13.4484","13.4484","8.9656","39.7699","147.1485"
"54.0000","13.4688","13.4688","8.9792","39.7656","147.1328"
"54.0800","13.4899","13.4899","8.9933","39.7669","147.1375"
"54.1600","13.5089","13.5089","9.0059","39.7593","147.1095"
"54.2400","13.5290","13.5290","9.0194","39.7533","147.0872"
"54.3200","13.5488","13.5488","9.0326","39.7473","147.0650"
"54.4000","13.5677","13.5677","9.0451","39.7418","147.0446"
"54.4800","13.5885","13.5885","9.0590","39.7372","147.0277"
"54.5600","13.6077","13.6077","9.0718","39.7286","146.9958"
"54.6400","13.6283","13.6283","9.0855","39.7264","146.9876"
"54.7200","13.6489","13.6489","9.0993","39.7239","146.9785"
"54.8000","13.6690","13.6690","9.1126","39.7241","146.9792"
"54.8800","13.6891","13.6891","9.1261","39.7227","146.9739"
"54.9600","13.7088","13.7088","9.1392","39.7160","146.9491"
"55.0400","13.7278","13.7278","9.1519","39.7114","146.9323"
"55.1200","13.7485","13.7485","9.1657","39.7100","146.9269"
"55.2000","13.7676","13.7676","9.1784","39.7019","146.8971"
"55.2800","13.7894","13.7894","9.1930","39.7017","146.8963"
"55.3600","13.8098","13.8098","9.2066","39.7008","146.8931"
"55.4400","13.8290","13.8290","9.2194","39.6943","146.8689"
"55.5200","13.8485","13.8485","9.2323","39.6919","146.8600"
"55.6000","13.8685","13.8685","9.2456","39.6867","146.8409"
"55.6800","13.8885","13.8885","9.2590","39.6835","146.8288"
"55.7600","13.9093","13.9093","9.2729","39.6801","146.8165"
"55.8400","13.9273","13.9273","9.2849","39.6692","146.7759"
"55.9200","13.9484","13.9484","9.2990","39.6702","146.7798"
"56.0000","13.9693","13.9693","9.3129","39.6668","146.7671"
"56.0800","13.9891","13.9891","9.3260","39.6590","146.7384"
"56.1600","14.0086","14.0086","9.3390","39.6558","146.7264"
"56.2400","14.0275","14.0275","9.3516","39.6484","146.6992"
"56.3200","14.0484","14.0484","9.3656","39.6459","146.6897"
"56.4000","14.0691","14.0691","9.3794","39.6444","146.6843"
"56.4800","14.0888","14.0888","9.3925","39.6417","146.6744"
"56.5600","14.1092","14.1092","9.4061","39.6388","146.6635"
"56.6400","14.1289","14.1289","9.4193","39.6294","146.6288"
"56.7200","14.1491","14.1491","9.4328","39.6245","146.6107"
"56.8000","14.1691","14.1691","9.4461","39.6200","146.5939"
"56.8800","14.1879","14.1879","9.4586","39.6141","146.5721"
"56.9600","14.2086","14.2086","9.4724","39.6102","146.5578"
"57.0400","14.2279","14.2279","9.4853","39.6032","146.5319"
"57.1200","14.2476","14.2476","9.4984","39.5991","146.5167"
"57.2000","14.2686","14.2686","9.5124","39.5951","146.5018"
"57.2800","14.2891","14.2891","9.5260","39.5912","146.4875"
"57.3600","14.3091","14.3091","9.5394","39.5822","146.4543"
"57.4400","14.3289","14.3289","9.5526","39.5753","146.4286"
"57.5200","14.3475","14.3475","9.5650","39.5685","146.4033"
"57.6000","14.3688","14.3688","9.5792","39.5683","146.4028"
"57.6800","14.3884","14.3884","9.5922","39.5623","146.3806"
"57.7600","14.4090","14.4090","9.6060","39.5610","146.3756"
"57.8400","14.4296","14.4296","9.6198","39.5537","146.3487"
"57.9200","14.4489","14.4489","9.6326","39.5497","146.3340"
"58.0000","14.4689","14.4689","9.6459","39.5426","146.3075"
"58.0800","14.4888","14.4888","9.6592","39.5377","146.2895"
"58.1600","14.5080","14.5080","9.6720","39.5309","146.2642"
"58.2400","14.5277","14.5277","9.6851","39.5248","146.2417"
"58.3200","14.5475","14.5475","9.6983","39.5173","146.2141"
"58.4000","14.5689","14.5689","9.7126","39.5179","146.2161"
"58.4800","14.5898","14.5898","9.7265","39.5111","146.1912"
"58.5600","14.6082","14.6082","9.7388","39.5057","146.1712"
"58.6400","14.6286","14.6286","9.7524","39.5005","146.1517"
"58.7200","14.6481","14.6481","9.7654","39.4951","146.1320"
"58.8000","14.6689","14.6689","9.7793","39.4895","146.1110"
"58.8800","14.6891","14.6891","9.7927","39.4861","146.0984"
"58.9600","14.7081","14.7081","9.8054","39.4802","146.0767"
"59.0400","14.7287","14.7287","9.8191","39.4788","146.0716"
"59.1200","14.7496","14.7496","9.8331","39.4749","146.0570"
"59.2000","14.7690","14.7690","9.8460","39.4712","146.0435"
"59.2800","14.7892","14.7892","9.8595","39.4673","146.0292"
"59.3600","14.8079","14.8079","9.8719","39.4570","145.9911"
"59.4400","14.8281","14.8281","9.8854","39.4543","145.9810"
"59.5200","14.8481","14.8481","9.8988","39.4483","145.9586"
"59.6000","14.8675","14.8675","9.9116","39.4448","145.9459"
"59.6800","14.8886","14.8886","9.9257","39.4417","145.9344"
"59.7600","14.9094","14.9094","9.9396","39.4315","145.8965"
"59.8400","14.9289","14.9289","9.9526","39.4218","145.8607"
"59.9200","14.9486","14.9486","9.9658","39.4122","145.8250"
"60.0000","14.9676","14.9676","9.9784","39.4017","145.7861"
"60.0800","14.9887","14.9887","9.9925","39.3963","145.7663"
"60.1240","15.0001","15.0001","10.0001","39.3950","145.7613"