File: data/instron_tests/metamaterials/250331/250331_2246_BULK_m1.is_comp_Exports/250331_2246_BULK_m1_3_1.csv
Results Table 1
,Compresson Axis,H*,V*,Height,Thickness,Width,Area,Fixture separation,Specimen label
,,,,(mm),(mm),(mm),(mm^2),(mm),
"3","Y","","","150.00","28.00","150.00","4200.00","150.00","2046_BULK_m1"

Results Table 2
,Modulus (Segment 0 % - 5 %),Compresson Axis
,(kPa),
"3","1520.74","Y"

Time,Displacement,Force,Compressive displacement,Compressive strain (Displacement),Compressive stress
(s),(mm),(N),(mm),(%),(kPa)
"0.0000","0.0000","-9.7138","0.0000","0.0000","-2.3128"
"0.0800","0.0012","-9.6273","0.0012","0.0008","-2.2922"
"0.1600","0.0175","-8.6517","0.0175","0.0117","-2.0599"
"0.2400","0.0379","-7.5354","0.0379","0.0253","-1.7941"
"0.3200","0.0578","-6.4633","0.0578","0.0385","-1.5389"
"0.4000","0.0771","-5.4614","0.0771","0.0514","-1.3003"
"0.4800","0.0985","-4.3504","0.0985","0.0657","-1.0358"
"0.5600","0.1183","-3.3755","0.1183","0.0789","-0.8037"
"0.6400","0.1381","-2.4002","0.1381","0.0920","-0.5715"
"0.7200","0.1576","-1.4443","0.1576","0.1051","-0.3439"
"0.8000","0.1769","-0.4974","0.1769","0.1179","-0.1184"
"0.8800","0.1974","0.4938","0.1974","0.1316","0.1176"
"0.9600","0.2174","1.4559","0.2174","0.1449","0.3466"
"1.0400","0.2365","2.3752","0.2365","0.1577","0.5655"
"1.1200","0.2569","3.3385","0.2569","0.1713","0.7949"
"1.2000","0.2774","4.2986","0.2774","0.1849","1.0235"
"1.2800","0.2982","5.2854","0.2982","0.1988","1.2584"
"1.3600","0.3181","6.2045","0.3181","0.2120","1.4773"
"1.4400","0.3364","7.0625","0.3364","0.2243","1.6816"
"1.5200","0.3568","8.0331","0.3568","0.2378","1.9126"
"1.6000","0.3771","8.9858","0.3771","0.2514","2.1395"
"1.6800","0.3977","9.9506","0.3977","0.2651","2.3692"
"1.7600","0.4186","10.9189","0.4186","0.2791","2.5997"
"1.8400","0.4375","11.7727","0.4375","0.2916","2.8030"
"1.9200","0.4577","12.7120","0.4577","0.3052","3.0267"
"2.0000","0.4775","13.6257","0.4775","0.3184","3.2442"
"2.0800","0.4970","14.5300","0.4970","0.3313","3.4595"
"2.1600","0.5174","15.4858","0.5174","0.3450","3.6871"
"2.2400","0.5363","16.3341","0.5363","0.3576","3.8891"
"2.3200","0.5570","17.3106","0.5570","0.3713","4.1216"
"2.4000","0.5784","18.3044","0.5784","0.3856","4.3582"
"2.4800","0.5978","19.1968","0.5978","0.3985","4.5707"
"2.5600","0.6180","20.1256","0.6180","0.4120","4.7918"
"2.6400","0.6367","20.9680","0.6367","0.4244","4.9924"
"2.7200","0.6566","21.8966","0.6566","0.4377","5.2135"
"2.8000","0.6770","22.8642","0.6770","0.4514","5.4439"
"2.8800","0.6973","23.7928","0.6973","0.4649","5.6649"
"2.9600","0.7179","24.7378","0.7179","0.4786","5.8899"
"3.0400","0.7384","25.6947","0.7384","0.4923","6.1178"
"3.1200","0.7575","26.5600","0.7575","0.5050","6.3238"
"3.2000","0.7777","27.5012","0.7777","0.5185","6.5479"
"3.2800","0.7971","28.3656","0.7971","0.5314","6.7537"
"3.3600","0.8177","29.3204","0.8177","0.5451","6.9810"
"3.4400","0.8373","30.2083","0.8373","0.5582","7.1924"
"3.5200","0.8566","31.0992","0.8566","0.5710","7.4046"
"3.6000","0.8768","32.0175","0.8768","0.5845","7.6232"
"3.6800","0.8980","32.9962","0.8980","0.5987","7.8562"
"3.7600","0.9180","33.9055","0.9180","0.6120","8.0727"
"3.8400","0.9375","34.7893","0.9375","0.6250","8.2832"
"3.9200","0.9562","35.6134","0.9562","0.6375","8.4794"
"4.0000","0.9773","36.6001","0.9773","0.6515","8.7143"
"4.0800","0.9977","37.5256","0.9977","0.6651","8.9347"
"4.1600","1.0171","38.4098","1.0171","0.6780","9.1452"
"4.2400","1.0379","39.3700","1.0379","0.6919","9.3738"
"4.3200","1.0575","40.2564","1.0575","0.7050","9.5849"
"4.4000","1.0782","41.1941","1.0782","0.7188","9.8081"
"4.4800","1.0981","42.1130","1.0981","0.7321","10.0269"
"4.5600","1.1169","42.9480","1.1169","0.7446","10.2257"
"4.6400","1.1371","43.8701","1.1371","0.7580","10.4453"
"4.7200","1.1567","44.7549","1.1567","0.7711","10.6559"
"4.8000","1.1768","45.6898","1.1768","0.7845","10.8785"
"4.8800","1.1984","46.6988","1.1984","0.7989","11.1188"
"4.9600","1.2176","47.5457","1.2176","0.8117","11.3204"
"5.0400","1.2376","48.4566","1.2376","0.8251","11.5373"
"5.1200","1.2571","49.3357","1.2571","0.8381","11.7466"
"5.2000","1.2766","50.2243","1.2766","0.8511","11.9582"
"5.2800","1.2971","51.1748","1.2971","0.8647","12.1845"
"5.3600","1.3172","52.0692","1.3172","0.8782","12.3974"
"5.4400","1.3375","52.9882","1.3375","0.8917","12.6162"
"5.5200","1.3584","53.9432","1.3584","0.9056","12.8436"
"5.6000","1.3779","54.8201","1.3779","0.9186","13.0524"
"5.6800","1.3983","55.7309","1.3983","0.9322","13.2693"
"5.7600","1.4172","56.5669","1.4172","0.9448","13.4683"
"5.8400","1.4372","57.4863","1.4372","0.9581","13.6872"
"5.9200","1.4568","58.3610","1.4568","0.9712","13.8955"
"6.0000","1.4765","59.2363","1.4765","0.9843","14.1039"
"6.0800","1.4978","60.2089","1.4978","0.9985","14.3354"
"6.1600","1.5180","61.1200","1.5180","1.0120","14.5524"
"6.2400","1.5375","61.9960","1.5375","1.0250","14.7610"
"6.3200","1.5575","62.9003","1.5575","1.0383","14.9763"
"6.4000","1.5769","63.7612","1.5769","1.0513","15.1812"
"6.4800","1.5972","64.6864","1.5972","1.0648","15.4015"
"6.5600","1.6181","65.6311","1.6181","1.0787","15.6264"
"6.6400","1.6364","66.4285","1.6364","1.0909","15.8163"
"6.7200","1.6578","67.4159","1.6578","1.1052","16.0514"
"6.8000","1.6781","68.3303","1.6781","1.1187","16.2691"
"6.8800","1.6985","69.2439","1.6985","1.1323","16.4866"
"6.9600","1.7178","70.1070","1.7178","1.1452","16.6921"
"7.0400","1.7368","70.9395","1.7368","1.1579","16.8904"
"7.1200","1.7565","71.8279","1.7565","1.1710","17.1019"
"7.2000","1.7775","72.7791","1.7775","1.1850","17.3284"
"7.2800","1.7964","73.6335","1.7964","1.1976","17.5318"
"7.3600","1.8178","74.6223","1.8178","1.2119","17.7672"
"7.4400","1.8377","75.4940","1.8377","1.2252","17.9748"
"7.5200","1.8579","76.4112","1.8579","1.2386","18.1931"
"7.6000","1.8778","77.2944","1.8778","1.2519","18.4034"
"7.6800","1.8967","78.1357","1.8967","1.2645","18.6037"
"7.7600","1.9171","79.0421","1.9171","1.2780","18.8195"
"7.8400","1.9371","79.9423","1.9371","1.2914","19.0339"
"7.9200","1.9569","80.8346","1.9569","1.3046","19.2463"
"8.0000","1.9784","81.8307","1.9784","1.3190","19.4835"
"8.0800","1.9982","82.6886","1.9982","1.3321","19.6878"
"8.1600","2.0181","83.5821","2.0181","1.3454","19.9005"
"8.2400","2.0376","84.4274","2.0376","1.3584","20.1018"
"8.3200","2.0564","85.2582","2.0564","1.3710","20.2996"
"8.4000","2.0776","86.2268","2.0776","1.3850","20.5302"
"8.4800","2.0967","87.0692","2.0967","1.3978","20.7308"
"8.5600","2.1176","88.0108","2.1176","1.4117","20.9550"
"8.6400","2.1381","88.9332","2.1381","1.4254","21.1746"
"8.7200","2.1576","89.7929","2.1576","1.4384","21.3793"
"8.8000","2.1776","90.6990","2.1776","1.4517","21.5950"
"8.8800","2.1977","91.5903","2.1977","1.4651","21.8072"
"8.9600","2.2168","92.4434","2.2168","1.4779","22.0103"
"9.0400","2.2376","93.3739","2.2376","1.4917","22.2319"
"9.1200","2.2564","94.1758","2.2564","1.5043","22.4228"
"9.2000","2.2778","95.1558","2.2778","1.5185","22.6561"
"9.2800","2.2986","96.0849","2.2986","1.5324","22.8774"
"9.3600","2.3181","96.9389","2.3181","1.5454","23.0807"
"9.4400","2.3373","97.8087","2.3373","1.5582","23.2878"
"9.5200","2.3570","98.6714","2.3570","1.5714","23.4932"
"9.6000","2.3771","99.5662","2.3771","1.5847","23.7062"
"9.6800","2.3976","100.4897","2.3976","1.5984","23.9261"
"9.7600","2.4165","101.3141","2.4165","1.6110","24.1224"
"9.8400","2.4373","102.2513","2.4373","1.6249","24.3455"
"9.9200","2.4578","103.1588","2.4578","1.6385","24.5616"
"10.0000","2.4776","104.0389","2.4776","1.6517","24.7712"
"10.0800","2.4979","104.9303","2.4979","1.6653","24.9834"
"10.1600","2.5169","105.7521","2.5169","1.6779","25.1791"
"10.2400","2.5372","106.6590","2.5372","1.6915","25.3950"
"10.3200","2.5573","107.5567","2.5573","1.7049","25.6087"
"10.4000","2.5768","108.4107","2.5768","1.7178","25.8121"
"10.4800","2.5979","109.3828","2.5979","1.7319","26.0435"
"10.5600","2.6182","110.2765","2.6182","1.7455","26.2563"
"10.6400","2.6379","111.1454","2.6379","1.7586","26.4632"
"10.7200","2.6578","112.0380","2.6578","1.7718","26.6757"
"10.8000","2.6767","112.8942","2.6767","1.7845","26.8796"
"10.8800","2.6977","113.8370","2.6977","1.7985","27.1041"
"10.9600","2.7170","114.6892","2.7170","1.8113","27.3069"
"11.0400","2.7366","115.5552","2.7366","1.8244","27.5131"
"11.1200","2.7571","116.4972","2.7571","1.8381","27.7374"
"11.2000","2.7775","117.3860","2.7775","1.8517","27.9491"
"11.2800","2.7981","118.3033","2.7981","1.8654","28.1675"
"11.3600","2.8181","119.1787","2.8181","1.8788","28.3759"
"11.4400","2.8365","119.9775","2.8365","1.8910","28.5661"
"11.5200","2.8570","120.8998","2.8570","1.9046","28.7857"
"11.6000","2.8767","121.7595","2.8767","1.9178","28.9903"
"11.6800","2.8977","122.7154","2.8977","1.9318","29.2180"
"11.7600","2.9184","123.6188","2.9184","1.9456","29.4330"
"11.8400","2.9376","124.4475","2.9376","1.9584","29.6304"
"11.9200","2.9575","125.3131","2.9575","1.9717","29.8364"
"12.0000","2.9774","126.1999","2.9774","1.9849","30.0476"
"12.0800","2.9974","127.0829","2.9974","1.9983","30.2578"
"12.1600","3.0175","127.9741","3.0175","2.0117","30.4700"
"12.2400","3.0363","128.7721","3.0363","2.0242","30.6600"
"12.3200","3.0571","129.7227","3.0571","2.0381","30.8864"
"12.4000","3.0786","130.6835","3.0786","2.0524","31.1151"
"12.4800","3.0976","131.4944","3.0976","2.0651","31.3082"
"12.5600","3.1177","132.3948","3.1177","2.0785","31.5226"
"12.6400","3.1367","133.2038","3.1367","2.0911","31.7152"
"12.7200","3.1569","134.1078","3.1569","2.1046","31.9304"
"12.8000","3.1770","134.9895","3.1770","2.1180","32.1404"
"12.8800","3.1969","135.8567","3.1969","2.1312","32.3468"
"12.9600","3.2180","136.8107","3.2180","2.1453","32.5740"
"13.0400","3.2388","137.7339","3.2388","2.1592","32.7938"
"13.1200","3.2575","138.5397","3.2575","2.1717","32.9856"
"13.2000","3.2778","139.4437","3.2778","2.1852","33.2009"
"13.2800","3.2971","140.2724","3.2971","2.1981","33.3982"
"13.3600","3.3179","141.2051","3.3179","2.2119","33.6203"
"13.4400","3.3375","142.0507","3.3375","2.2250","33.8216"
"13.5200","3.3562","142.8529","3.3562","2.2375","34.0126"
"13.6000","3.3771","143.7768","3.3771","2.2514","34.2326"
"13.6800","3.3984","144.7336","3.3984","2.2656","34.4604"
"13.7600","3.4180","145.5674","3.4180","2.2786","34.6589"
"13.8400","3.4376","146.4200","3.4376","2.2918","34.8619"
"13.9200","3.4562","147.2009","3.4562","2.3042","35.0478"
"14.0000","3.4772","148.1435","3.4772","2.3181","35.2723"
"14.0800","3.4977","149.0422","3.4977","2.3318","35.4862"
"14.1600","3.5172","149.8839","3.5172","2.3448","35.6866"
"14.2400","3.5378","150.7826","3.5378","2.3585","35.9006"
"14.3200","3.5575","151.6231","3.5575","2.3717","36.1007"
"14.4000","3.5783","152.5367","3.5783","2.3856","36.3183"
"14.4800","3.5979","153.3801","3.5979","2.3986","36.5191"
"14.5600","3.6170","154.1903","3.6170","2.4113","36.7120"
"14.6400","3.6368","155.0437","3.6368","2.4245","36.9152"
"14.7200","3.6567","155.9009","3.6567","2.4378","37.1193"
"14.8000","3.6763","156.7553","3.6763","2.4508","37.3227"
"14.8800","3.6982","157.7417","3.6982","2.4655","37.5575"
"14.9600","3.7177","158.5573","3.7177","2.4785","37.7517"
"15.0400","3.7378","159.4236","3.7378","2.4919","37.9580"
"15.1200","3.7570","160.2249","3.7570","2.5046","38.1488"
"15.2000","3.7767","161.0931","3.7767","2.5178","38.3555"
"15.2800","3.7970","161.9622","3.7970","2.5313","38.5624"
"15.3600","3.8167","162.8046","3.8167","2.5445","38.7630"
"15.4400","3.8376","163.7325","3.8376","2.5584","38.9839"
"15.5200","3.8586","164.6405","3.8586","2.5724","39.2001"
"15.6000","3.8776","165.4344","3.8776","2.5851","39.3891"
"15.6800","3.8978","166.3103","3.8978","2.5985","39.5977"
"15.7600","3.9176","167.1490","3.9176","2.6117","39.7974"
"15.8400","3.9371","167.9839","3.9371","2.6248","39.9962"
"15.9200","3.9572","168.8426","3.9572","2.6382","40.2006"
"16.0000","3.9762","169.6336","3.9762","2.6508","40.3890"
"16.0800","3.9976","170.5824","3.9976","2.6651","40.6148"
"16.1600","4.0183","171.4718","4.0183","2.6789","40.8266"
"16.2400","4.0375","172.2751","4.0375","2.6917","41.0179"
"16.3200","4.0572","173.1104","4.0572","2.7048","41.2168"
"16.4000","4.0771","173.9464","4.0771","2.7180","41.4158"
"16.4800","4.0974","174.8335","4.0974","2.7316","41.6270"
"16.5600","4.1177","175.6973","4.1177","2.7451","41.8327"
"16.6400","4.1363","176.4631","4.1363","2.7575","42.0150"
"16.7200","4.1578","177.4086","4.1578","2.7719","42.2401"
"16.8000","4.1782","178.2878","4.1782","2.7855","42.4495"
"16.8800","4.1986","179.1510","4.1986","2.7990","42.6550"
"16.9600","4.2174","179.9272","4.2174","2.8116","42.8398"
"17.0400","4.2370","180.7446","4.2370","2.8247","43.0344"
"17.1200","4.2569","181.5861","4.2569","2.8379","43.2348"
"17.2000","4.2775","182.4678","4.2775","2.8517","43.4447"
"17.2800","4.2961","183.2321","4.2961","2.8641","43.6267"
"17.3600","4.3175","184.1561","4.3175","2.8783","43.8467"
"17.4400","4.3375","184.9820","4.3375","2.8917","44.0433"
"17.5200","4.3580","185.8605","4.3580","2.9053","44.2525"
"17.6000","4.3773","186.6569","4.3773","2.9182","44.4421"
"17.6800","4.3967","187.4632","4.3967","2.9311","44.6341"
"17.7600","4.4171","188.3238","4.4171","2.9447","44.8390"
"17.8400","4.4371","189.1719","4.4371","2.9581","45.0409"
"17.9200","4.4572","190.0240","4.4572","2.9714","45.2438"
"18.0000","4.4781","190.9250","4.4781","2.9854","45.4583"
"18.0800","4.4981","191.7536","4.4981","2.9987","45.6556"
"18.1600","4.5183","192.6043","4.5183","3.0122","45.8582"
"18.2400","4.5378","193.4022","4.5378","3.0252","46.0482"
"18.3200","4.5566","194.1869","4.5566","3.0377","46.2350"
"18.4000","4.5771","195.0580","4.5771","3.0514","46.4424"
"18.4800","4.5966","195.8707","4.5966","3.0644","46.6359"
"18.5600","4.6177","196.7807","4.6177","3.0784","46.8526"
"18.6400","4.6377","197.6192","4.6377","3.0918","47.0522"
"18.7200","4.6572","198.4196","4.6572","3.1048","47.2428"
"18.8000","4.6775","199.2624","4.6775","3.1183","47.4434"
"18.8800","4.6977","200.0982","4.6977","3.1318","47.6424"
"18.9600","4.7167","200.8860","4.7167","3.1445","47.8300"
"19.0400","4.7373","201.7615","4.7373","3.1582","48.0385"
"19.1200","4.7561","202.5195","4.7561","3.1708","48.2189"
"19.2000","4.7783","203.4896","4.7783","3.1855","48.4499"
"19.2800","4.7989","204.3441","4.7989","3.1993","48.6534"
"19.3600","4.8179","205.1138","4.8179","3.2119","48.8366"
"19.4400","4.8372","205.8920","4.8372","3.2248","49.0219"
"19.5200","4.8573","206.7283","4.8573","3.2382","49.2210"
"19.6000","4.8773","207.5592","4.8773","3.2515","49.4189"
"19.6800","4.8981","208.4483","4.8981","3.2654","49.6305"
"19.7600","4.9166","209.1721","4.9166","3.2777","49.8029"
"19.8400","4.9370","210.0191","4.9370","3.2913","50.0045"
"19.9200","4.9576","210.8698","4.9576","3.3051","50.2071"
"20.0000","4.9775","211.6915","4.9775","3.3184","50.4027"
"20.0800","4.9982","212.5390","4.9982","3.3321","50.6045"
"20.1600","5.0170","213.2686","5.0170","3.3447","50.7782"
"20.2400","5.0372","214.0951","5.0372","3.3581","50.9750"
"20.3200","5.0571","214.9135","5.0571","3.3714","51.1699"
"20.4000","5.0767","215.7064","5.0767","3.3845","51.3587"
"20.4800","5.0980","216.6118","5.0980","3.3987","51.5742"
"20.5600","5.1185","217.4448","5.1185","3.4123","51.7726"
"20.6400","5.1380","218.2331","5.1380","3.4253","51.9603"
"20.7200","5.1577","219.0271","5.1577","3.4385","52.1493"
"20.8000","5.1766","219.7742","5.1766","3.4511","52.3272"
"20.8800","5.1976","220.6569","5.1976","3.4651","52.5374"
"20.9600","5.2172","221.4538","5.2172","3.4782","52.7271"
"21.0400","5.2368","222.2456","5.2368","3.4912","52.9156"
"21.1200","5.2568","223.0584","5.2568","3.5045","53.1092"
"21.2000","5.2777","223.9226","5.2777","3.5185","53.3149"
"21.2800","5.2979","224.7262","5.2979","3.5319","53.5062"
"21.3600","5.3178","225.5307","5.3178","3.5452","53.6978"
"21.4400","5.3363","226.2605","5.3363","3.5575","53.8715"
"21.5200","5.3565","227.0918","5.3565","3.5710","54.0695"
"21.6000","5.3768","227.9220","5.3768","3.5845","54.2671"
"21.6800","5.3981","228.8097","5.3981","3.5987","54.4785"
"21.7600","5.4186","229.6436","5.4186","3.6124","54.6771"
"21.8400","5.4377","230.3731","5.4377","3.6251","54.8507"
"21.9200","5.4577","231.1768","5.4577","3.6385","55.0421"
"22.0000","5.4777","231.9773","5.4777","3.6518","55.2327"
"22.0800","5.4972","232.7698","5.4972","3.6648","55.4214"
"22.1600","5.5177","233.6347","5.5177","3.6785","55.6273"
"22.2400","5.5359","234.3073","5.5359","3.6906","55.7874"
"22.3200","5.5568","235.1715","5.5568","3.7045","55.9932"
"22.4000","5.5785","236.0643","5.5785","3.7190","56.2058"
"22.4800","5.5980","236.8362","5.5980","3.7320","56.3896"
"22.5600","5.6178","237.6050","5.6178","3.7452","56.5726"
"22.6400","5.6367","238.3420","5.6367","3.7578","56.7481"
"22.7200","5.6568","239.1602","5.6568","3.7712","56.9429"
"22.8000","5.6770","239.9719","5.6770","3.7847","57.1362"
"22.8800","5.6970","240.7688","5.6970","3.7980","57.3259"
"22.9600","5.7179","241.6111","5.7179","3.8119","57.5265"
"23.0400","5.7388","242.4625","5.7388","3.8259","57.7292"
"23.1200","5.7577","243.1805","5.7577","3.8384","57.9001"
"23.2000","5.7780","243.9899","5.7780","3.8520","58.0928"
"23.2800","5.7969","244.7053","5.7969","3.8646","58.2632"
"23.3600","5.8175","245.5403","5.8175","3.8783","58.4620"
"23.4400","5.8373","246.3158","5.8373","3.8915","58.6466"
"23.5200","5.8564","247.0655","5.8564","3.9042","58.8251"
"23.6000","5.8770","247.8961","5.8770","3.9180","59.0229"
"23.6800","5.8982","248.7513","5.8982","3.9321","59.2265"
"23.7600","5.9180","249.5238","5.9180","3.9453","59.4104"
"23.8400","5.9376","250.2877","5.9376","3.9584","59.5923"
"23.9200","5.9565","250.9882","5.9565","3.9710","59.7591"
"24.0000","5.9773","251.8331","5.9773","3.9849","59.9603"
"24.0800","5.9978","252.6402","5.9978","3.9986","60.1524"
"24.1600","6.0170","253.3780","6.0170","4.0113","60.3281"
"24.2400","6.0381","254.2287","6.0381","4.0254","60.5307"
"24.3200","6.0577","254.9774","6.0577","4.0385","60.7089"
"24.4000","6.0783","255.7946","6.0783","4.0522","60.9035"
"24.4800","6.0978","256.5544","6.0978","4.0652","61.0844"
"24.5600","6.1168","257.2609","6.1168","4.0779","61.2526"
"24.6400","6.1366","258.0252","6.1366","4.0911","61.4346"
"24.7200","6.1570","258.8159","6.1570","4.1047","61.6228"
"24.8000","6.1771","259.5982","6.1771","4.1181","61.8091"
"24.8800","6.1985","260.4573","6.1985","4.1324","62.0136"
"24.9600","6.2177","261.1556","6.2177","4.1451","62.1799"
"25.0400","6.2381","261.9522","6.2381","4.1588","62.3696"
"25.1200","6.2569","262.6490","6.2569","4.1713","62.5355"
"25.2000","6.2765","263.4111","6.2765","4.1843","62.7169"
"25.2800","6.2971","264.2021","6.2971","4.1980","62.9053"
"25.3600","6.3171","264.9614","6.3171","4.2114","63.0860"
"25.4400","6.3376","265.7493","6.3376","4.2251","63.2736"
"25.5200","6.3587","266.5789","6.3587","4.2391","63.4712"
"25.6000","6.3775","267.2749","6.3775","4.2517","63.6369"
"25.6800","6.3981","268.0845","6.3981","4.2654","63.8297"
"25.7600","6.4175","268.7923","6.4175","4.2783","63.9982"
"25.8400","6.4370","269.5437","6.4370","4.2913","64.1771"
"25.9200","6.4573","270.3203","6.4573","4.3049","64.3620"
"26.0000","6.4762","271.0163","6.4762","4.3175","64.5277"
"26.0800","6.4977","271.8655","6.4977","4.3318","64.7299"
"26.1600","6.5183","272.6530","6.5183","4.3455","64.9174"
"26.2400","6.5377","273.3781","6.5377","4.3585","65.0900"
"26.3200","6.5573","274.1082","6.5573","4.3715","65.2639"
"26.4000","6.5769","274.8453","6.5769","4.3846","65.4394"
"26.4800","6.5973","275.6407","6.5973","4.3982","65.6287"
"26.5600","6.6178","276.4135","6.6178","4.4119","65.8127"
"26.6400","6.6362","277.0735","6.6362","4.4241","65.9699"
"26.7200","6.6576","277.9136","6.6576","4.4384","66.1699"
"26.8000","6.6784","278.7019","6.6784","4.4523","66.3576"
"26.8800","6.6985","279.4564","6.6985","4.4657","66.5372"
"26.9600","6.7175","280.1315","6.7175","4.4783","66.6980"
"27.0400","6.7370","280.8338","6.7370","4.4913","66.8652"
"27.1200","6.7569","281.5871","6.7569","4.5046","67.0445"
"27.2000","6.7774","282.3629","6.7774","4.5183","67.2293"
"27.2800","6.7967","283.0846","6.7967","4.5311","67.4011"
"27.3600","6.8177","283.8974","6.8177","4.5451","67.5946"
"27.4400","6.8374","284.6064","6.8374","4.5583","67.7634"
"27.5200","6.8579","285.3706","6.8579","4.5719","67.9454"
"27.6000","6.8777","286.0992","6.8777","4.5851","68.1188"
"27.6800","6.8966","286.7759","6.8966","4.5977","68.2800"
"27.7600","6.9172","287.5467","6.9172","4.6114","68.4635"
"27.8400","6.9370","288.2787","6.9370","4.6247","68.6378"
"27.9200","6.9569","289.0245","6.9569","4.6379","68.8154"
"28.0000","6.9782","289.8471","6.9782","4.6522","69.0112"
"28.0800","6.9980","290.5499","6.9980","4.6653","69.1786"
"28.1600","7.0180","291.2993","7.0180","4.6787","69.3570"
"28.2400","7.0379","292.0120","7.0379","4.6920","69.5267"
"28.3200","7.0567","292.6976","7.0567","4.7045","69.6899"
"28.4000","7.0774","293.4820","7.0774","4.7183","69.8767"
"28.4800","7.0963","294.1416","7.0963","4.7309","70.0337"
"28.5600","7.1177","294.9642","7.1177","4.7451","70.2296"
"28.6400","7.1379","295.7165","7.1379","4.7586","70.4087"
"28.7200","7.1576","296.4135","7.1576","4.7717","70.5746"
"28.8000","7.1774","297.1299","7.1774","4.7849","70.7452"
"28.8800","7.1979","297.8904","7.1979","4.7986","70.9263"
"28.9600","7.2168","298.5520","7.2168","4.8112","71.0838"
"29.0400","7.2373","299.3061","7.2373","4.8249","71.2634"
"29.1200","7.2562","299.9538","7.2562","4.8375","71.4176"
"29.2000","7.2778","300.7777","7.2778","4.8519","71.6137"
"29.2800","7.2988","301.5739","7.2988","4.8659","71.8033"
"29.3600","7.3178","302.2151","7.3178","4.8785","71.9560"
"29.4400","7.3370","302.8768","7.3370","4.8914","72.1135"
"29.5200","7.3571","303.5945","7.3571","4.9047","72.2844"
"29.6000","7.3774","304.3380","7.3774","4.9183","72.4614"
"29.6800","7.3982","305.0907","7.3982","4.9321","72.6406"
"29.7600","7.4167","305.7006","7.4167","4.9445","72.7859"
"29.8400","7.4370","306.4390","7.4370","4.9580","72.9617"
"29.9200","7.4580","307.2048","7.4580","4.9720","73.1440"
"30.0000","7.4779","307.9206","7.4779","4.9853","73.3144"
"30.0800","7.4981","308.6341","7.4981","4.9987","73.4843"
"30.1600","7.5167","309.2619","7.5167","5.0111","73.6338"
"30.2400","7.5371","309.9957","7.5371","5.0247","73.8085"
"30.3200","7.5568","310.6928","7.5568","5.0379","73.9745"
"30.4000","7.5771","311.4282","7.5771","5.0514","74.1496"
"30.4800","7.5977","312.1750","7.5977","5.0651","74.3274"
"30.5600","7.6185","312.9263","7.6185","5.0790","74.5063"
"30.6400","7.6382","313.6058","7.6382","5.0921","74.6680"
"30.7200","7.6581","314.3090","7.6581","5.1054","74.8355"
"30.8000","7.6767","314.9297","7.6767","5.1178","74.9833"
"30.8800","7.6976","315.6934","7.6976","5.1317","75.1651"
"30.9600","7.7170","316.3561","7.7170","5.1447","75.3229"
"31.0400","7.7367","317.0523","7.7367","5.1578","75.4886"
"31.1200","7.7571","317.7950","7.7571","5.1714","75.6655"
"31.2000","7.7779","318.5283","7.7779","5.1852","75.8401"
"31.2800","7.7981","319.2411","7.7981","5.1988","76.0098"
"31.3600","7.8183","319.9359","7.8183","5.2122","76.1752"
"31.4400","7.8365","320.5271","7.8365","5.2243","76.3160"
"31.5200","7.8568","321.2497","7.8568","5.2379","76.4880"
"31.6000","7.8768","321.9460","7.8768","5.2512","76.6538"
"31.6800","7.8981","322.7239","7.8981","5.2654","76.8390"
"31.7600","7.9185","323.4374","7.9185","5.2790","77.0089"
"31.8400","7.9379","324.0868","7.9379","5.2919","77.1635"
"31.9200","7.9576","324.7563","7.9576","5.3051","77.3229"
"32.0000","7.9776","325.4516","7.9776","5.3184","77.4885"
"32.0800","7.9972","326.1178","7.9972","5.3315","77.6471"
"32.1600","8.0172","326.8160","8.0172","5.3448","77.8133"
"32.2400","8.0365","327.4483","8.0365","5.3577","77.9639"
"32.3200","8.0571","328.1877","8.0571","5.3714","78.1399"
"32.4000","8.0783","328.9378","8.0783","5.3856","78.3185"
"32.4800","8.0975","329.5797","8.0975","5.3983","78.4714"
"32.5600","8.1180","330.2922","8.1180","5.4120","78.6410"
"32.6400","8.1368","330.8874","8.1368","5.4245","78.7827"
"32.7200","8.1568","331.5843","8.1568","5.4378","78.9486"
"32.8000","8.1768","332.2662","8.1768","5.4512","79.1110"
"32.8800","8.1969","332.9499","8.1969","5.4646","79.2738"
"32.9600","8.2177","333.6786","8.2177","5.4785","79.4473"
"33.0400","8.2385","334.3957","8.2385","5.4924","79.6180"
"33.1200","8.2574","335.0139","8.2574","5.5049","79.7652"
"33.2000","8.2775","335.6990","8.2775","5.5184","79.9283"
"33.2800","8.2969","336.3411","8.2969","5.5313","80.0812"
"33.3600","8.3179","337.0843","8.3179","5.5453","80.2582"
"33.4400","8.3373","337.7120","8.3373","5.5582","80.4076"
"33.5200","8.3563","338.3279","8.3563","5.5709","80.5543"
"33.6000","8.3769","339.0463","8.3769","5.5846","80.7253"
"33.6800","8.3984","339.8134","8.3984","5.5990","80.9080"
"33.7600","8.4181","340.4520","8.4181","5.6121","81.0600"
"33.8400","8.4375","341.1026","8.4375","5.6250","81.2149"
"33.9200","8.4561","341.6802","8.4561","5.6374","81.3524"
"34.0000","8.4770","342.4204","8.4770","5.6514","81.5287"
"34.0800","8.4977","343.1217","8.4977","5.6651","81.6956"
"34.1600","8.5173","343.7823","8.5173","5.6782","81.8529"
"34.2400","8.5380","344.4850","8.5380","5.6920","82.0202"
"34.3200","8.5576","345.1092","8.5576","5.7050","82.1689"
"34.4000","8.5782","345.8001","8.5782","5.7188","82.3334"
"34.4800","8.5982","346.4669","8.5982","5.7321","82.4921"
"34.5600","8.6174","347.0808","8.6174","5.7449","82.6383"
"34.6400","8.6369","347.7085","8.6369","5.7579","82.7877"
"34.7200","8.6566","348.3412","8.6566","5.7711","82.9384"
"34.8000","8.6767","349.0340","8.6767","5.7845","83.1033"
"34.8800","8.6983","349.7831","8.6983","5.7988","83.2817"
"34.9600","8.7176","350.3787","8.7176","5.8117","83.4235"
"35.0400","8.7379","351.0384","8.7379","5.8253","83.5806"
"35.1200","8.7569","351.6261","8.7569","5.8379","83.7205"
"35.2000","8.7768","352.2874","8.7768","5.8512","83.8779"
"35.2800","8.7970","352.9540","8.7970","5.8647","84.0367"
"35.3600","8.8167","353.5847","8.8167","5.8778","84.1868"
"35.4400","8.8374","354.2852","8.8374","5.8916","84.3536"
"35.5200","8.8587","355.0087","8.8587","5.9058","84.5259"
"35.6000","8.8777","355.5970","8.8777","5.9185","84.6660"
"35.6800","8.8985","356.2941","8.8985","5.9323","84.8319"
"35.7600","8.9175","356.8625","8.9175","5.9450","84.9672"
"35.8400","8.9366","357.4827","8.9366","5.9577","85.1149"
"35.9200","8.9570","358.1686","8.9570","5.9713","85.2782"
"36.0000","8.9765","358.8034","8.9765","5.9843","85.4294"
"36.0800","8.9974","359.5036","8.9974","5.9982","85.5961"
"36.1600","9.0184","360.2015","9.0184","6.0122","85.7623"
"36.2400","9.0377","360.8075","9.0377","6.0252","85.9066"
"36.3200","9.0573","361.4286","9.0573","6.0382","86.0544"
"36.4000","9.0770","362.0351","9.0770","6.0513","86.1988"
"36.4800","9.0974","362.7145","9.0974","6.0649","86.3606"
"36.5600","9.1175","363.3515","9.1175","6.0784","86.5123"
"36.6400","9.1361","363.9068","9.1361","6.0907","86.6445"
"36.7200","9.1580","364.6546","9.1580","6.1053","86.8225"
"36.8000","9.1783","365.3028","9.1783","6.1188","86.9769"
"36.8800","9.1987","365.9626","9.1987","6.1325","87.1339"
"36.9600","9.2174","366.5173","9.2174","6.1449","87.2660"
"37.0400","9.2371","367.1355","9.2371","6.1581","87.4132"
"37.1200","9.2571","367.7756","9.2571","6.1714","87.5656"
"37.2000","9.2773","368.4152","9.2773","6.1849","87.7179"
"37.2800","9.2964","369.0067","9.2964","6.1976","87.8587"
"37.3600","9.3178","369.7242","9.3178","6.2118","88.0296"
"37.4400","9.3375","370.3337","9.3375","6.2250","88.1747"
"37.5200","9.3581","371.0027","9.3581","6.2387","88.3340"
"37.6000","9.3776","371.5900","9.3776","6.2518","88.4738"
"37.6800","9.3967","372.1745","9.3967","6.2645","88.6130"
"37.7600","9.4171","372.8197","9.4171","6.2781","88.7666"
"37.8400","9.4370","373.4405","9.4370","6.2913","88.9144"
"37.9200","9.4571","374.0835","9.4571","6.3047","89.0675"
"38.0000","9.4781","374.7748","9.4781","6.3187","89.2321"
"38.0800","9.4980","375.3749","9.4980","6.3320","89.3750"
"38.1600","9.5182","376.0010","9.5182","6.3454","89.5240"
"38.2400","9.5378","376.5901","9.5378","6.3585","89.6643"
"38.3200","9.5566","377.1551","9.5566","6.3711","89.7988"
"38.4000","9.5773","377.8191","9.5773","6.3848","89.9569"
"38.4800","9.5963","378.3751","9.5963","6.3975","90.0893"
"38.5600","9.6177","379.0894","9.6177","6.4118","90.2594"
"38.6400","9.6376","379.6953","9.6376","6.4251","90.4036"
"38.7200","9.6577","380.2992","9.6577","6.4384","90.5474"
"38.8000","9.6773","380.8950","9.6773","6.4515","90.6893"
"38.8800","9.6977","381.5351","9.6977","6.4651","90.8417"
"38.9600","9.7167","382.1033","9.7167","6.4778","90.9770"
"39.0400","9.7374","382.7646","9.7374","6.4916","91.1344"
"39.1200","9.7562","383.2967","9.7562","6.5041","91.2611"
"39.2000","9.7778","384.0114","9.7778","6.5185","91.4313"
"39.2800","9.7987","384.6726","9.7987","6.5324","91.5887"
"39.3600","9.8182","385.2531","9.8182","6.5455","91.7269"
"39.4400","9.8372","385.7949","9.8372","6.5581","91.8559"
"39.5200","9.8569","386.3833","9.8569","6.5713","91.9960"
"39.6000","9.8772","387.0367","9.8772","6.5848","92.1516"
"39.6800","9.8976","387.6597","9.8976","6.5984","92.2999"
"39.7600","9.9166","388.2060","9.9166","6.6111","92.4300"
"39.8400","9.9373","388.8509","9.9373","6.6248","92.5835"
"39.9200","9.9578","389.4825","9.9578","6.6385","92.7339"
"40.0000","9.9779","390.1132","9.9779","6.6519","92.8841"
"40.0800","9.9980","390.7170","9.9980","6.6653","93.0279"
"40.1600","10.0170","391.2540","10.0170","6.6780","93.1557"
"40.2400","10.0373","391.8681","10.0373","6.6915","93.3019"
"40.3200","10.0570","392.4459","10.0570","6.7046","93.4395"
"40.4000","10.0771","393.0642","10.0771","6.7181","93.5867"
"40.4800","10.0978","393.7053","10.0978","6.7319","93.7393"
"40.5600","10.1183","394.3251","10.1183","6.7455","93.8869"
"40.6400","10.1378","394.8969","10.1378","6.7586","94.0231"
"40.7200","10.1581","395.5002","10.1581","6.7720","94.1667"
"40.8000","10.1767","396.0205","10.1767","6.7845","94.2906"
"40.8800","10.1976","396.6634","10.1976","6.7984","94.4437"
"40.9600","10.2169","397.2124","10.2169","6.8113","94.5744"
"41.0400","10.2366","397.7975","10.2366","6.8244","94.7137"
"41.1200","10.2571","398.4319","10.2571","6.8381","94.8647"
"41.2000","10.2778","399.0547","10.2778","6.8519","95.0130"
"41.2800","10.2981","399.6650","10.2981","6.8654","95.1583"
"41.3600","10.3182","400.2518","10.3182","6.8788","95.2980"
"41.4400","10.3369","400.7704","10.3369","6.8912","95.4215"
"41.5200","10.3566","401.3565","10.3566","6.9044","95.5611"
"41.6000","10.3767","401.9394","10.3767","6.9178","95.6999"
"41.6800","10.3979","402.6114","10.3979","6.9320","95.8599"
"41.7600","10.4188","403.2396","10.4188","6.9459","96.0094"
"41.8400","10.4376","403.7432","10.4376","6.9584","96.1293"
"41.9200","10.4575","404.3181","10.4575","6.9717","96.2662"
"42.0000","10.4772","404.8997","10.4772","6.9848","96.4047"
"42.0800","10.4974","405.5127","10.4974","6.9983","96.5507"
"42.1600","10.5177","406.1207","10.5177","7.0118","96.6954"
"42.2400","10.5363","406.6054","10.5363","7.0242","96.8108"
"42.3200","10.5571","407.2382","10.5571","7.0381","96.9615"
"42.4000","10.5785","407.8998","10.5785","7.0523","97.1190"
"42.4800","10.5978","408.4377","10.5978","7.0652","97.2471"
"42.5600","10.6181","409.0200","10.6181","7.0787","97.3857"
"42.6400","10.6368","409.5127","10.6368","7.0912","97.5030"
"42.7200","10.6570","410.1159","10.6570","7.1047","97.6467"
"42.8000","10.6768","410.6762","10.6768","7.1179","97.7800"
"42.8800","10.6971","411.2761","10.6971","7.1314","97.9229"
"42.9600","10.7178","411.8835","10.7178","7.1452","98.0675"
"43.0400","10.7385","412.4932","10.7385","7.1590","98.2127"
"43.1200","10.7576","413.0071","10.7576","7.1717","98.3350"
"43.2000","10.7780","413.6071","10.7780","7.1853","98.4779"
"43.2800","10.7970","414.1005","10.7970","7.1980","98.5954"
"43.3600","10.8176","414.7205","10.8176","7.2117","98.7430"
"43.4400","10.8373","415.2611","10.8373","7.2248","98.8717"
"43.5200","10.8564","415.8017","10.8564","7.2376","99.0004"
"43.6000","10.8775","416.4364","10.8775","7.2517","99.1515"
"43.6800","10.8979","417.0068","10.8979","7.2652","99.2873"
"43.7600","10.9177","417.5611","10.9177","7.2784","99.4193"
"43.8400","10.9374","418.1093","10.9374","7.2916","99.5498"
"43.9200","10.9565","418.6049","10.9565","7.3043","99.6678"
"44.0000","10.9769","419.1926","10.9769","7.3179","99.8078"
"44.0800","10.9975","419.7801","10.9975","7.3316","99.9476"
"44.1600","11.0171","420.3333","11.0171","7.3448","100.0794"
"44.2400","11.0378","420.9235","11.0378","7.3586","100.2199"
"44.3200","11.0575","421.4530","11.0575","7.3717","100.3460"
"44.4000","11.0783","422.0518","11.0783","7.3856","100.4885"
"44.4800","11.0981","422.6013","11.0981","7.3988","100.6194"
"44.5600","11.1173","423.1115","11.1173","7.4116","100.7408"
"44.6400","11.1364","423.6194","11.1364","7.4243","100.8618"
"44.7200","11.1565","424.1832","11.1565","7.4377","100.9960"
"44.8000","11.1768","424.7742","11.1768","7.4512","101.1367"
"44.8800","11.1987","425.4341","11.1987","7.4658","101.2938"
"44.9600","11.2179","425.9190","11.2179","7.4786","101.4093"
"45.0400","11.2380","426.4610","11.2380","7.4920","101.5383"
"45.1200","11.2571","426.9455","11.2571","7.5047","101.6537"
"45.2000","11.2769","427.5106","11.2769","7.5179","101.7882"
"45.2800","11.2971","428.0658","11.2971","7.5314","101.9204"
"45.3600","11.3171","428.5932","11.3171","7.5447","102.0460"
"45.4400","11.3375","429.1682","11.3375","7.5583","102.1829"
"45.5200","11.3587","429.7840","11.3587","7.5725","102.3295"
"45.6000","11.3777","430.2657","11.3777","7.5851","102.4442"
"45.6800","11.3982","430.8380","11.3982","7.5988","102.5805"
"45.7600","11.4174","431.3157","11.4174","7.6116","102.6942"
"45.8400","11.4371","431.8652","11.4371","7.6247","102.8250"
"45.9200","11.4571","432.4037","11.4571","7.6381","102.9533"
"46.0000","11.4760","432.8895","11.4760","7.6507","103.0689"
"46.0800","11.4977","433.5067","11.4977","7.6651","103.2159"
"46.1600","11.5180","434.0635","11.5180","7.6787","103.3484"
"46.2400","11.5378","434.5881","11.5378","7.6919","103.4734"
"46.3200","11.5570","435.0831","11.5570","7.7047","103.5912"
"46.4000","11.5768","435.6066","11.5768","7.7179","103.7159"
"46.4800","11.5971","436.1620","11.5971","7.7314","103.8481"
"46.5600","11.6178","436.7344","11.6178","7.7452","103.9844"
"46.6400","11.6362","437.1794","11.6362","7.7574","104.0903"
"46.7200","11.6576","437.8040","11.6576","7.7718","104.2390"
"46.8000","11.6781","438.3626","11.6781","7.7854","104.3720"
"46.8800","11.6989","438.9459","11.6989","7.7993","104.5109"
"46.9600","11.7181","439.4098","11.7181","7.8120","104.6214"
"47.0400","11.7369","439.8649","11.7369","7.8246","104.7297"
"47.1200","11.7569","440.4035","11.7569","7.8379","104.8580"
"47.2000","11.7774","440.9774","11.7774","7.8516","104.9946"
"47.2800","11.7966","441.4665","11.7966","7.8644","105.1111"
"47.3600","11.8179","442.0683","11.8179","7.8786","105.2544"
"47.4400","11.8376","442.5520","11.8376","7.8917","105.3695"
"47.5200","11.8579","443.1098","11.8579","7.9052","105.5023"
"47.6000","11.8776","443.6028","11.8776","7.9184","105.6197"
"47.6800","11.8967","444.0800","11.8967","7.9311","105.7333"
"47.7600","11.9171","444.6201","11.9171","7.9447","105.8619"
"47.8400","11.9366","445.1277","11.9366","7.9577","105.9828"
"47.9200","11.9575","445.7083","11.9575","7.9717","106.1210"
"48.0000","11.9784","446.2834","11.9784","7.9856","106.2580"
"48.0800","11.9986","446.7849","11.9986","7.9990","106.3774"
"48.1600","12.0182","447.2776","12.0182","8.0122","106.4947"
"48.2400","12.0380","447.7741","12.0380","8.0253","106.6129"
"48.3200","12.0566","448.2154","12.0566","8.0377","106.7180"
"48.4000","12.0775","448.7808","12.0775","8.0517","106.8526"
"48.4800","12.0966","449.2362","12.0966","8.0644","106.9610"
"48.5600","12.1177","449.8210","12.1177","8.0784","107.1002"
"48.6400","12.1377","450.3316","12.1377","8.0918","107.2218"
"48.7200","12.1577","450.8439","12.1577","8.1052","107.3438"
"48.8000","12.1776","451.3404","12.1776","8.1184","107.4620"
"48.8800","12.1978","451.8619","12.1978","8.1319","107.5862"
"48.9600","12.2168","452.3132","12.2168","8.1445","107.6936"
"49.0400","12.2370","452.8361","12.2370","8.1580","107.8181"
"49.1200","12.2564","453.3001","12.2564","8.1709","107.9286"
"49.2000","12.2780","453.9037","12.2780","8.1853","108.0723"
"49.2800","12.2986","454.4242","12.2986","8.1991","108.1962"
"49.3600","12.3183","454.9153","12.3183","8.2122","108.3132"
"49.4400","12.3373","455.3451","12.3373","8.2249","108.4155"
"49.5200","12.3571","455.8405","12.3571","8.2381","108.5334"
"49.6000","12.3774","456.3528","12.3774","8.2516","108.6554"
"49.6800","12.3978","456.8708","12.3978","8.2652","108.7788"
"49.7600","12.4161","457.2599","12.4161","8.2774","108.8714"
"49.8400","12.4369","457.8211","12.4369","8.2913","109.0050"
"49.9200","12.4579","458.3640","12.4579","8.3053","109.1343"
"50.0000","12.4779","458.8661","12.4779","8.3186","109.2538"
"50.0800","12.4979","459.3466","12.4979","8.3320","109.3682"
"50.1600","12.5168","459.7563","12.5168","8.3445","109.4658"
"50.2400","12.5373","460.2625","12.5373","8.3582","109.5863"
"50.3200","12.5572","460.7406","12.5572","8.3715","109.7002"
"50.4000","12.5769","461.1973","12.5769","8.3846","109.8089"
"50.4800","12.5975","461.7134","12.5975","8.3983","109.9318"
"50.5600","12.6183","462.2187","12.6183","8.4122","110.0521"
"50.6400","12.6383","462.6840","12.6383","8.4255","110.1629"
"50.7200","12.6579","463.1303","12.6579","8.4386","110.2691"
"50.8000","12.6765","463.5408","12.6765","8.4510","110.3669"
"50.8800","12.6978","464.0860","12.6978","8.4652","110.4967"
"50.9600","12.7168","464.4861","12.7168","8.4779","110.5919"
"51.0400","12.7367","464.9849","12.7367","8.4912","110.7107"
"51.1200","12.7571","465.4779","12.7571","8.5048","110.8281"
"51.2000","12.7777","465.9742","12.7777","8.5185","110.9462"
"51.2800","12.7982","466.4921","12.7982","8.5321","111.0695"
"51.3600","12.8181","466.9337","12.8181","8.5454","111.1747"
"51.4400","12.8366","467.3248","12.8366","8.5577","111.2678"
"51.5200","12.8568","467.8109","12.8568","8.5712","111.3835"
"51.6000","12.8765","468.2523","12.8765","8.5843","111.4886"
"51.6800","12.8979","468.8325","12.8979","8.5986","111.6268"
"51.7600","12.9188","469.3216","12.9188","8.6125","111.7432"
"51.8400","12.9377","469.7255","12.9377","8.6251","111.8394"
"51.9200","12.9579","470.1844","12.9579","8.6386","111.9487"
"52.0000","12.9775","470.6263","12.9775","8.6516","112.0539"
"52.0800","12.9973","471.0833","12.9973","8.6649","112.1627"
"52.1600","13.0173","471.5540","13.0173","8.6782","112.2748"
"52.2400","13.0364","471.9626","13.0364","8.6909","112.3720"
"52.3200","13.0573","472.5038","13.0573","8.7048","112.5009"
"52.4000","13.0785","473.0265","13.0785","8.7190","112.6254"
"52.4800","13.0977","473.4264","13.0977","8.7318","112.7206"
"52.5600","13.1179","473.8860","13.1179","8.7453","112.8300"
"52.6400","13.1368","474.2737","13.1368","8.7579","112.9223"
"52.7200","13.1568","474.7354","13.1568","8.7712","113.0322"
"52.8000","13.1769","475.1925","13.1769","8.7846","113.1411"
"52.8800","13.1970","475.6388","13.1970","8.7980","113.2473"
"52.9600","13.2180","476.1472","13.2180","8.8120","113.3684"
"53.0400","13.2384","476.5935","13.2384","8.8256","113.4747"
"53.1200","13.2574","476.9906","13.2574","8.8383","113.5692"
"53.2000","13.2777","477.4636","13.2777","8.8518","113.6818"
"53.2800","13.2972","477.8787","13.2972","8.8648","113.7806"
"53.3600","13.3179","478.3719","13.3179","8.8786","113.8981"
"53.4400","13.3374","478.7820","13.3374","8.8916","113.9957"
"53.5200","13.3561","479.1578","13.3561","8.9041","114.0852"
"53.6000","13.3774","479.6761","13.3774","8.9183","114.2086"
"53.6800","13.3981","480.1394","13.3981","8.9321","114.3189"
"53.7600","13.4180","480.5744","13.4180","8.9453","114.4225"
"53.8400","13.4377","480.9843","13.4377","8.9584","114.5201"
"53.9200","13.4566","481.3501","13.4566","8.9711","114.6072"
"54.0000","13.4770","481.8256","13.4770","8.9846","114.7204"
"54.0800","13.4975","482.2931","13.4975","8.9983","114.8317"
"54.1600","13.5175","482.7550","13.5175","9.0116","114.9417"
"54.2400","13.5380","483.1997","13.5380","9.0253","115.0475"
"54.3200","13.5575","483.5782","13.5575","9.0383","115.1377"
"54.4000","13.5782","484.0336","13.5782","9.0521","115.2461"
"54.4800","13.5981","484.4576","13.5981","9.0654","115.3471"
"54.5600","13.6174","484.8336","13.6174","9.0782","115.4366"
"54.6400","13.6369","485.2335","13.6369","9.0913","115.5318"
"54.7200","13.6568","485.6320","13.6568","9.1045","115.6267"
"54.8000","13.6769","486.0648","13.6769","9.1179","115.7297"
"54.8800","13.6984","486.5573","13.6984","9.1323","115.8470"
"54.9600","13.7178","486.9061","13.7178","9.1452","115.9300"
"55.0400","13.7380","487.3116","13.7380","9.1587","116.0266"
"55.1200","13.7570","487.6667","13.7570","9.1713","116.1111"
"55.2000","13.7771","488.0955","13.7771","9.1848","116.2132"
"55.2800","13.7970","488.4766","13.7970","9.1980","116.3039"
"55.3600","13.8168","488.8580","13.8168","9.2112","116.3948"
"55.4400","13.8375","489.2973","13.8375","9.2250","116.4994"
"55.5200","13.8586","489.7607","13.8586","9.2391","116.6097"
"55.6000","13.8773","490.0613","13.8773","9.2515","116.6813"
"55.6800","13.8980","490.4870","13.8980","9.2654","116.7826"
"55.7600","13.9177","490.8362","13.9177","9.2785","116.8658"
"55.8400","13.9373","491.2046","13.9373","9.2915","116.9535"
"55.9200","13.9571","491.5778","13.9571","9.3047","117.0423"
"56.0000","13.9761","491.9132","13.9761","9.3174","117.1222"
"56.0800","13.9976","492.3926","13.9976","9.3317","117.2363"
"56.1600","14.0182","492.8174","14.0182","9.3455","117.3375"
"56.2400","14.0376","493.1608","14.0376","9.3584","117.4192"
"56.3200","14.0573","493.5177","14.0573","9.3715","117.5042"
"56.4000","14.0769","493.8628","14.0769","9.3846","117.5864"
"56.4800","14.0972","494.2798","14.0972","9.3981","117.6857"
"56.5600","14.1175","494.6628","14.1175","9.4117","117.7769"
"56.6400","14.1363","494.9771","14.1363","9.4242","117.8517"
"56.7200","14.1577","495.4398","14.1577","9.4385","117.9619"
"56.8000","14.1783","495.8346","14.1783","9.4522","118.0559"
"56.8800","14.1986","496.2219","14.1986","9.4657","118.1481"
"56.9600","14.2178","496.5375","14.2178","9.4785","118.2232"
"57.0400","14.2368","496.8442","14.2368","9.4912","118.2962"
"57.1200","14.2570","497.2217","14.2570","9.5047","118.3861"
"57.2000","14.2773","497.5912","14.2773","9.5182","118.4741"
"57.2800","14.2967","497.9283","14.2967","9.5311","118.5543"
"57.3600","14.3175","498.3325","14.3175","9.5450","118.6506"
"57.4400","14.3374","498.6699","14.3374","9.5583","118.7309"
"57.5200","14.3581","499.0677","14.3581","9.5721","118.8256"
"57.6000","14.3776","499.3747","14.3776","9.5851","118.8987"
"57.6800","14.3969","499.6910","14.3969","9.5979","118.9741"
"57.7600","14.4171","500.0389","14.4171","9.6114","119.0569"
"57.8400","14.4365","500.3368","14.4365","9.6243","119.1278"
"57.9200","14.4570","500.7139","14.4570","9.6380","119.2176"
"58.0000","14.4785","501.1313","14.4785","9.6523","119.3170"
"58.0800","14.4983","501.4474","14.4983","9.6655","119.3922"
"58.1600","14.5181","501.7489","14.5181","9.6787","119.4640"
"58.2400","14.5375","502.0466","14.5375","9.6917","119.5349"
"58.3200","14.5565","502.3279","14.5565","9.7044","119.6019"
"58.4000","14.5772","502.6904","14.5772","9.7181","119.6882"
"58.4800","14.5964","502.9675","14.5964","9.7309","119.7542"
"58.5600","14.6176","503.3654","14.6176","9.7451","119.8489"
"58.6400","14.6380","503.6964","14.6380","9.7587","119.9277"
"58.7200","14.6573","503.9567","14.6573","9.7716","119.9897"
"58.8000","14.6775","504.2782","14.6775","9.7850","120.0662"
"58.8800","14.6976","504.5888","14.6976","9.7984","120.1402"
"58.9600","14.7169","504.8725","14.7169","9.8113","120.2077"
"59.0400","14.7369","505.1772","14.7369","9.8246","120.2803"
"59.1200","14.7563","505.4404","14.7563","9.8375","120.3430"
"59.2000","14.7780","505.8495","14.7780","9.8520","120.4404"
"59.2800","14.7987","506.1699","14.7987","9.8658","120.5167"
"59.3600","14.8182","506.4326","14.8182","9.8788","120.5792"
"59.4400","14.8376","506.6835","14.8376","9.8917","120.6389"
"59.5200","14.8573","506.9441","14.8573","9.9048","120.7010"
"59.6000","14.8773","507.2473","14.8773","9.9182","120.7732"
"59.6800","14.8977","507.5464","14.8977","9.9318","120.8444"
"59.7600","14.9165","507.7610","14.9165","9.9443","120.8955"
"59.8400","14.9371","508.0878","14.9371","9.9581","120.9733"
"59.9200","14.9578","508.3848","14.9578","9.9719","121.0440"
"60.0000","14.9778","508.6649","14.9778","9.9852","121.1107"
"60.0800","14.9984","508.9573","14.9984","9.9989","121.1803"
"60.0870","15.0001","508.9787","15.0001","10.0001","121.1854"