File: data/instron_tests/metamaterials/250331/250331_2246_BULK_m1.is_comp_Exports/250331_2246_BULK_m1_5_1.csv
Results Table 1
,Compresson Axis,H*,V*,Height,Thickness,Width,Area,Fixture separation,Specimen label
,,,,(mm),(mm),(mm),(mm^2),(mm),
"5","X","","","150.00","28.00","150.00","4200.00","150.00","2046_BULK_m1"

Results Table 2
,Modulus (Segment 0 % - 5 %),Compresson Axis
,(kPa),
"5","1975.17","X"

Time,Displacement,Force,Compressive displacement,Compressive strain (Displacement),Compressive stress
(s),(mm),(N),(mm),(%),(kPa)
"0.0000","0.0000","2.1175","0.0000","0.0000","0.5042"
"0.0800","0.0012","2.2222","0.0012","0.0008","0.5291"
"0.1600","0.0175","3.4662","0.0175","0.0117","0.8253"
"0.2400","0.0377","4.9074","0.0377","0.0251","1.1684"
"0.3200","0.0577","6.2879","0.0577","0.0384","1.4971"
"0.4000","0.0771","7.6008","0.0771","0.0514","1.8097"
"0.4800","0.0982","9.0149","0.0982","0.0655","2.1464"
"0.5600","0.1181","10.2925","0.1181","0.0787","2.4506"
"0.6400","0.1377","11.5572","0.1377","0.0918","2.7517"
"0.7200","0.1574","12.8172","0.1574","0.1049","3.0517"
"0.8000","0.1767","14.0362","0.1767","0.1178","3.3419"
"0.8800","0.1970","15.3121","0.1970","0.1314","3.6457"
"0.9600","0.2173","16.5802","0.2173","0.1448","3.9477"
"1.0400","0.2364","17.7588","0.2364","0.1576","4.2283"
"1.1200","0.2574","19.0750","0.2574","0.1716","4.5417"
"1.2000","0.2778","20.3094","0.2778","0.1852","4.8356"
"1.2800","0.2984","21.5603","0.2984","0.1989","5.1334"
"1.3600","0.3180","22.7324","0.3180","0.2120","5.4125"
"1.4400","0.3362","23.8007","0.3362","0.2241","5.6668"
"1.5200","0.3564","25.0254","0.3564","0.2376","5.9584"
"1.6000","0.3771","26.2724","0.3771","0.2514","6.2553"
"1.6800","0.3976","27.5156","0.3976","0.2651","6.5513"
"1.7600","0.4186","28.7576","0.4186","0.2791","6.8471"
"1.8400","0.4375","29.8595","0.4375","0.2917","7.1094"
"1.9200","0.4579","31.0685","0.4579","0.3053","7.3973"
"2.0000","0.4776","32.2334","0.4776","0.3184","7.6746"
"2.0800","0.4968","33.3523","0.4968","0.3312","7.9410"
"2.1600","0.5173","34.5734","0.5173","0.3449","8.2318"
"2.2400","0.5363","35.6697","0.5363","0.3575","8.4928"
"2.3200","0.5570","36.9142","0.5570","0.3713","8.7891"
"2.4000","0.5784","38.1813","0.5784","0.3856","9.0908"
"2.4800","0.5977","39.3039","0.5977","0.3984","9.3581"
"2.5600","0.6176","40.4646","0.6176","0.4117","9.6344"
"2.6400","0.6367","41.5745","0.6367","0.4244","9.8987"
"2.7200","0.6567","42.7505","0.6567","0.4378","10.1787"
"2.8000","0.6770","43.9439","0.6770","0.4513","10.4628"
"2.8800","0.6967","45.0815","0.6967","0.4644","10.7337"
"2.9600","0.7176","46.3241","0.7176","0.4784","11.0295"
"3.0400","0.7384","47.5353","0.7384","0.4923","11.3179"
"3.1200","0.7573","48.6203","0.7573","0.5048","11.5763"
"3.2000","0.7775","49.8159","0.7775","0.5183","11.8609"
"3.2800","0.7971","50.9382","0.7971","0.5314","12.1282"
"3.3600","0.8176","52.1501","0.8176","0.5451","12.4167"
"3.4400","0.8371","53.2688","0.8371","0.5581","12.6830"
"3.5200","0.8562","54.3794","0.8562","0.5708","12.9475"
"3.6000","0.8775","55.6533","0.8775","0.5850","13.2508"
"3.6800","0.8978","56.8161","0.8978","0.5985","13.5276"
"3.7600","0.9172","57.9336","0.9172","0.6115","13.7937"
"3.8400","0.9368","59.0754","0.9368","0.6245","14.0656"
"3.9200","0.9562","60.1850","0.9562","0.6375","14.3298"
"4.0000","0.9774","61.4509","0.9774","0.6516","14.6312"
"4.0800","0.9978","62.6376","0.9978","0.6652","14.9137"
"4.1600","1.0171","63.7535","1.0171","0.6780","15.1794"
"4.2400","1.0378","64.9749","1.0378","0.6919","15.4702"
"4.3200","1.0575","66.0999","1.0575","0.7050","15.7381"
"4.4000","1.0782","67.3179","1.0782","0.7188","16.0281"
"4.4800","1.0980","68.4682","1.0980","0.7320","16.3019"
"4.5600","1.1169","69.5545","1.1169","0.7446","16.5606"
"4.6400","1.1370","70.7368","1.1370","0.7580","16.8421"
"4.7200","1.1566","71.8822","1.1566","0.7711","17.1148"
"4.8000","1.1769","73.0971","1.1769","0.7846","17.4041"
"4.8800","1.1981","74.3540","1.1981","0.7987","17.7033"
"4.9600","1.2174","75.4683","1.2174","0.8116","17.9686"
"5.0400","1.2377","76.6612","1.2377","0.8251","18.2527"
"5.1200","1.2568","77.7584","1.2568","0.8379","18.5139"
"5.2000","1.2764","78.9224","1.2764","0.8509","18.7910"
"5.2800","1.2971","80.1571","1.2971","0.8648","19.0850"
"5.3600","1.3170","81.3140","1.3170","0.8780","19.3605"
"5.4400","1.3372","82.5066","1.3372","0.8914","19.6444"
"5.5200","1.3581","83.7471","1.3581","0.9054","19.9398"
"5.6000","1.3775","84.8741","1.3775","0.9183","20.2081"
"5.6800","1.3979","86.0725","1.3979","0.9320","20.4934"
"5.7600","1.4175","87.2101","1.4175","0.9450","20.7643"
"5.8400","1.4372","88.3756","1.4372","0.9581","21.0418"
"5.9200","1.4570","89.5398","1.4570","0.9714","21.3190"
"6.0000","1.4762","90.6452","1.4762","0.9841","21.5822"
"6.0800","1.4976","91.9400","1.4976","0.9984","21.8905"
"6.1600","1.5181","93.1420","1.5181","1.0120","22.1767"
"6.2400","1.5369","94.2284","1.5369","1.0246","22.4353"
"6.3200","1.5573","95.4608","1.5573","1.0382","22.7288"
"6.4000","1.5771","96.6031","1.5771","1.0514","23.0008"
"6.4800","1.5975","97.8285","1.5975","1.0650","23.2925"
"6.5600","1.6179","99.0317","1.6179","1.0786","23.5790"
"6.6400","1.6364","100.0976","1.6364","1.0909","23.8328"
"6.7200","1.6575","101.3605","1.6575","1.1050","24.1334"
"6.8000","1.6780","102.5939","1.6780","1.1187","24.4271"
"6.8800","1.6984","103.8049","1.6984","1.1322","24.7154"
"6.9600","1.7178","104.9472","1.7178","1.1452","24.9874"
"7.0400","1.7371","106.0536","1.7371","1.1581","25.2509"
"7.1200","1.7568","107.2289","1.7568","1.1712","25.5307"
"7.2000","1.7772","108.4425","1.7772","1.1848","25.8196"
"7.2800","1.7961","109.5481","1.7961","1.1974","26.0829"
"7.3600","1.8177","110.8655","1.8177","1.2118","26.3966"
"7.4400","1.8376","112.0222","1.8376","1.2251","26.6720"
"7.5200","1.8578","113.2301","1.8578","1.2385","26.9596"
"7.6000","1.8774","114.3769","1.8774","1.2516","27.2326"
"7.6800","1.8967","115.5165","1.8967","1.2645","27.5039"
"7.7600","1.9170","116.7138","1.9170","1.2780","27.7890"
"7.8400","1.9369","117.8903","1.9369","1.2912","28.0691"
"7.9200","1.9569","119.0771","1.9569","1.3046","28.3517"
"8.0000","1.9780","120.3586","1.9780","1.3187","28.6568"
"8.0800","1.9980","121.5090","1.9980","1.3320","28.9307"
"8.1600","2.0181","122.7051","2.0181","1.3454","29.2155"
"8.2400","2.0378","123.8665","2.0378","1.3585","29.4920"
"8.3200","2.0566","124.9747","2.0566","1.3711","29.7559"
"8.4000","2.0773","126.2126","2.0773","1.3849","30.0506"
"8.4800","2.0960","127.2816","2.0960","1.3973","30.3051"
"8.5600","2.1170","128.5637","2.1170","1.4113","30.6104"
"8.6400","2.1380","129.8278","2.1380","1.4254","30.9114"
"8.7200","2.1573","130.9302","2.1573","1.4382","31.1739"
"8.8000","2.1776","132.1462","2.1776","1.4517","31.4634"
"8.8800","2.1978","133.3233","2.1978","1.4652","31.7436"
"8.9600","2.2167","134.4481","2.2167","1.4778","32.0115"
"9.0400","2.2375","135.6859","2.2375","1.4917","32.3062"
"9.1200","2.2564","136.7816","2.2564","1.5042","32.5670"
"9.2000","2.2778","138.0883","2.2778","1.5186","32.8782"
"9.2800","2.2985","139.3164","2.2985","1.5323","33.1706"
"9.3600","2.3181","140.4747","2.3181","1.5454","33.4464"
"9.4400","2.3375","141.5850","2.3375","1.5583","33.7107"
"9.5200","2.3569","142.7261","2.3569","1.5713","33.9824"
"9.6000","2.3771","143.9446","2.3771","1.5848","34.2725"
"9.6800","2.3978","145.2130","2.3978","1.5986","34.5745"
"9.7600","2.4164","146.2672","2.4164","1.6109","34.8255"
"9.8400","2.4373","147.5250","2.4373","1.6248","35.1250"
"9.9200","2.4577","148.7305","2.4577","1.6385","35.4120"
"10.0000","2.4774","149.8925","2.4774","1.6516","35.6887"
"10.0800","2.4976","151.0818","2.4976","1.6651","35.9719"
"10.1600","2.5165","152.1641","2.5165","1.6777","36.2296"
"10.2400","2.5371","153.3892","2.5371","1.6914","36.5212"
"10.3200","2.5571","154.5587","2.5571","1.7047","36.7997"
"10.4000","2.5767","155.6998","2.5767","1.7178","37.0714"
"10.4800","2.5978","156.9705","2.5978","1.7318","37.3739"
"10.5600","2.6180","158.1394","2.6180","1.7453","37.6522"
"10.6400","2.6378","159.3008","2.6378","1.7585","37.9288"
"10.7200","2.6577","160.4702","2.6577","1.7718","38.2072"
"10.8000","2.6764","161.5528","2.6764","1.7843","38.4650"
"10.8800","2.6974","162.8143","2.6974","1.7983","38.7653"
"10.9600","2.7169","163.9422","2.7169","1.8113","39.0339"
"11.0400","2.7365","165.0934","2.7365","1.8243","39.3079"
"11.1200","2.7571","166.3305","2.7571","1.8381","39.6025"
"11.2000","2.7776","167.5329","2.7776","1.8517","39.8888"
"11.2800","2.7979","168.7216","2.7979","1.8653","40.1718"
"11.3600","2.8175","169.8580","2.8175","1.8784","40.4424"
"11.4400","2.8363","170.9368","2.8363","1.8909","40.6992"
"11.5200","2.8571","172.1754","2.8571","1.9047","40.9941"
"11.6000","2.8767","173.2980","2.8767","1.9178","41.2614"
"11.6800","2.8973","174.5269","2.8973","1.9316","41.5540"
"11.7600","2.9185","175.7799","2.9185","1.9457","41.8524"
"11.8400","2.9377","176.8634","2.9377","1.9585","42.1103"
"11.9200","2.9575","178.0091","2.9575","1.9717","42.3831"
"12.0000","2.9775","179.1815","2.9775","1.9850","42.6623"
"12.0800","2.9976","180.3957","2.9976","1.9984","42.9514"
"12.1600","3.0172","181.5185","3.0172","2.0115","43.2187"
"12.2400","3.0361","182.5780","3.0361","2.0241","43.4709"
"12.3200","3.0570","183.8438","3.0570","2.0380","43.7723"
"12.4000","3.0784","185.0955","3.0784","2.0523","44.0704"
"12.4800","3.0977","186.1825","3.0977","2.0651","44.3292"
"12.5600","3.1176","187.3211","3.1176","2.0784","44.6003"
"12.6400","3.1365","188.3927","3.1365","2.0910","44.8554"
"12.7200","3.1569","189.5843","3.1569","2.1046","45.1391"
"12.8000","3.1771","190.7672","3.1771","2.1181","45.4208"
"12.8800","3.1969","191.9030","3.1969","2.1313","45.6912"
"12.9600","3.2178","193.1309","3.2178","2.1452","45.9836"
"13.0400","3.2383","194.3252","3.2383","2.1589","46.2679"
"13.1200","3.2576","195.4129","3.2576","2.1717","46.5269"
"13.2000","3.2776","196.5682","3.2776","2.1851","46.8020"
"13.2800","3.2967","197.6356","3.2967","2.1978","47.0561"
"13.3600","3.3176","198.8707","3.3176","2.2118","47.3502"
"13.4400","3.3373","199.9780","3.3373","2.2249","47.6138"
"13.5200","3.3564","201.0741","3.3564","2.2376","47.8748"
"13.6000","3.3770","202.2668","3.3770","2.2514","48.1588"
"13.6800","3.3980","203.4971","3.3980","2.2653","48.4517"
"13.7600","3.4178","204.6168","3.4178","2.2785","48.7183"
"13.8400","3.4375","205.7367","3.4375","2.2917","48.9849"
"13.9200","3.4562","206.7598","3.4562","2.3041","49.2285"
"14.0000","3.4768","207.9689","3.4768","2.3179","49.5164"
"14.0800","3.4975","209.1560","3.4975","2.3317","49.7990"
"14.1600","3.5172","210.2761","3.5172","2.3448","50.0657"
"14.2400","3.5379","211.4476","3.5379","2.3586","50.3447"
"14.3200","3.5574","212.5425","3.5574","2.3716","50.6054"
"14.4000","3.5780","213.7407","3.5780","2.3853","50.8906"
"14.4800","3.5978","214.8567","3.5978","2.3986","51.1563"
"14.5600","3.6168","215.9183","3.6168","2.4112","51.4091"
"14.6400","3.6369","217.0670","3.6369","2.4246","51.6826"
"14.7200","3.6566","218.1628","3.6566","2.4377","51.9435"
"14.8000","3.6767","219.3269","3.6767","2.4511","52.2207"
"14.8800","3.6983","220.5886","3.6983","2.4655","52.5211"
"14.9600","3.7173","221.6203","3.7173","2.4782","52.7667"
"15.0400","3.7375","222.7663","3.7375","2.4917","53.0396"
"15.1200","3.7570","223.8455","3.7570","2.5046","53.2965"
"15.2000","3.7767","224.9741","3.7767","2.5178","53.5653"
"15.2800","3.7969","226.0955","3.7969","2.5312","53.8323"
"15.3600","3.8166","227.1896","3.8166","2.5444","54.0928"
"15.4400","3.8375","228.3989","3.8375","2.5583","54.3807"
"15.5200","3.8583","229.5759","3.8583","2.5722","54.6609"
"15.6000","3.8775","230.6156","3.8775","2.5850","54.9085"
"15.6800","3.8977","231.7666","3.8977","2.5985","55.1825"
"15.7600","3.9175","232.8624","3.9175","2.6117","55.4434"
"15.8400","3.9370","233.9550","3.9370","2.6247","55.7036"
"15.9200","3.9570","235.0819","3.9570","2.6380","55.9719"
"16.0000","3.9760","236.1166","3.9760","2.6507","56.2182"
"16.0800","3.9975","237.3558","3.9975","2.6650","56.5133"
"16.1600","4.0181","238.5132","4.0181","2.6787","56.7889"
"16.2400","4.0374","239.5603","4.0374","2.6916","57.0382"
"16.3200","4.0572","240.6692","4.0572","2.7048","57.3022"
"16.4000","4.0769","241.7551","4.0769","2.7180","57.5607"
"16.4800","4.0972","242.9200","4.0972","2.7314","57.8381"
"16.5600","4.1176","244.0498","4.1176","2.7451","58.1071"
"16.6400","4.1360","245.0459","4.1360","2.7573","58.3443"
"16.7200","4.1574","246.2633","4.1574","2.7716","58.6341"
"16.8000","4.1780","247.4179","4.1780","2.7854","58.9090"
"16.8800","4.1986","248.5661","4.1986","2.7990","59.1824"
"16.9600","4.2174","249.5744","4.2174","2.8116","59.4225"
"17.0400","4.2369","250.6325","4.2369","2.8246","59.6744"
"17.1200","4.2569","251.7336","4.2569","2.8379","59.9366"
"17.2000","4.2774","252.8773","4.2774","2.8516","60.2089"
"17.2800","4.2965","253.9014","4.2965","2.8643","60.4527"
"17.3600","4.3177","255.1185","4.3177","2.8785","60.7425"
"17.4400","4.3374","256.1530","4.3374","2.8916","60.9888"
"17.5200","4.3577","257.2799","4.3577","2.9051","61.2571"
"17.6000","4.3773","258.3325","4.3773","2.9182","61.5077"
"17.6800","4.3967","259.3963","4.3967","2.9312","61.7610"
"17.7600","4.4168","260.4777","4.4168","2.9445","62.0185"
"17.8400","4.4371","261.6003","4.4371","2.9581","62.2858"
"17.9200","4.4570","262.6838","4.4570","2.9713","62.5438"
"18.0000","4.4777","263.8395","4.4777","2.9851","62.8189"
"18.0800","4.4980","264.9348","4.4980","2.9987","63.0797"
"18.1600","4.5183","266.0505","4.5183","3.0122","63.3454"
"18.2400","4.5378","267.0824","4.5378","3.0252","63.5910"
"18.3200","4.5562","268.0610","4.5562","3.0375","63.8241"
"18.4000","4.5770","269.2208","4.5770","3.0513","64.1002"
"18.4800","4.5964","270.2519","4.5964","3.0643","64.3457"
"18.5600","4.6178","271.4482","4.6178","3.0785","64.6305"
"18.6400","4.6378","272.5311","4.6378","3.0918","64.8884"
"18.7200","4.6573","273.5699","4.6573","3.1049","65.1357"
"18.8000","4.6770","274.6372","4.6770","3.1180","65.3898"
"18.8800","4.6975","275.7483","4.6975","3.1317","65.6543"
"18.9600","4.7163","276.7408","4.7163","3.1442","65.8907"
"19.0400","4.7372","277.8886","4.7372","3.1581","66.1640"
"19.1200","4.7560","278.8511","4.7560","3.1707","66.3931"
"19.2000","4.7782","280.1204","4.7782","3.1855","66.6953"
"19.2800","4.7988","281.2236","4.7988","3.1992","66.9580"
"19.3600","4.8181","282.2327","4.8181","3.2121","67.1983"
"19.4400","4.8371","283.2106","4.8371","3.2247","67.4311"
"19.5200","4.8571","284.2812","4.8571","3.2380","67.6860"
"19.6000","4.8772","285.3651","4.8772","3.2515","67.9441"
"19.6800","4.8977","286.5005","4.8977","3.2651","68.2144"
"19.7600","4.9169","287.4923","4.9169","3.2779","68.4505"
"19.8400","4.9370","288.5742","4.9370","3.2913","68.7082"
"19.9200","4.9579","289.6743","4.9579","3.3053","68.9701"
"20.0000","4.9776","290.7132","4.9776","3.3184","69.2174"
"20.0800","4.9978","291.7730","4.9978","3.3319","69.4698"
"20.1600","5.0166","292.7242","5.0166","3.3444","69.6962"
"20.2400","5.0370","293.8117","5.0370","3.3580","69.9552"
"20.3200","5.0567","294.8403","5.0567","3.3711","70.2001"
"20.4000","5.0766","295.8904","5.0766","3.3844","70.4501"
"20.4800","5.0982","297.0713","5.0982","3.3988","70.7313"
"20.5600","5.1184","298.1008","5.1184","3.4123","70.9764"
"20.6400","5.1377","299.1027","5.1377","3.4251","71.2149"
"20.7200","5.1576","300.1523","5.1576","3.4384","71.4648"
"20.8000","5.1764","301.0898","5.1764","3.4509","71.6880"
"20.8800","5.1976","302.2424","5.1976","3.4651","71.9625"
"20.9600","5.2168","303.2206","5.2168","3.4779","72.1954"
"21.0400","5.2368","304.2800","5.2368","3.4912","72.4476"
"21.1200","5.2568","305.3320","5.2568","3.5046","72.6981"
"21.2000","5.2779","306.4362","5.2779","3.5186","72.9610"
"21.2800","5.2979","307.4655","5.2979","3.5319","73.2061"
"21.3600","5.3179","308.4972","5.3179","3.5453","73.4517"
"21.4400","5.3362","309.4050","5.3362","3.5575","73.6679"
"21.5200","5.3568","310.4984","5.3568","3.5712","73.9282"
"21.6000","5.3767","311.5561","5.3767","3.5845","74.1800"
"21.6800","5.3979","312.6819","5.3979","3.5986","74.4481"
"21.7600","5.4178","313.6881","5.4178","3.6119","74.6876"
"21.8400","5.4375","314.6774","5.4375","3.6250","74.9232"
"21.9200","5.4578","315.6979","5.4578","3.6385","75.1662"
"22.0000","5.4776","316.7163","5.4776","3.6518","75.4087"
"22.0800","5.4972","317.7053","5.4972","3.6648","75.6441"
"22.1600","5.5174","318.7529","5.5174","3.6783","75.8936"
"22.2400","5.5365","319.6564","5.5365","3.6910","76.1087"
"22.3200","5.5567","320.7190","5.5567","3.7045","76.3617"
"22.4000","5.5782","321.8514","5.5782","3.7188","76.6313"
"22.4800","5.5974","322.8043","5.5974","3.7316","76.8582"
"22.5600","5.6177","323.8456","5.6177","3.7452","77.1061"
"22.6400","5.6369","324.7901","5.6369","3.7579","77.3310"
"22.7200","5.6568","325.8084","5.6568","3.7712","77.5734"
"22.8000","5.6766","326.8136","5.6766","3.7844","77.8128"
"22.8800","5.6969","327.8422","5.6969","3.7979","78.0577"
"22.9600","5.7176","328.9168","5.7176","3.8118","78.3135"
"23.0400","5.7387","330.0052","5.7387","3.8258","78.5727"
"23.1200","5.7577","330.9339","5.7577","3.8385","78.7938"
"23.2000","5.7776","331.9340","5.7776","3.8517","79.0319"
"23.2800","5.7968","332.8797","5.7968","3.8646","79.2571"
"23.3600","5.8175","333.9530","5.8175","3.8783","79.5126"
"23.4400","5.8373","334.9388","5.8373","3.8916","79.7473"
"23.5200","5.8565","335.8936","5.8565","3.9043","79.9747"
"23.6000","5.8771","336.9323","5.8771","3.9181","80.2220"
"23.6800","5.8979","337.9969","5.8979","3.9319","80.4754"
"23.7600","5.9177","338.9778","5.9177","3.9451","80.7090"
"23.8400","5.9375","339.9666","5.9375","3.9583","80.9444"
"23.9200","5.9565","340.8517","5.9565","3.9710","81.1552"
"24.0000","5.9771","341.9189","5.9771","3.9847","81.4093"
"24.0800","5.9977","342.9489","5.9977","3.9985","81.6545"
"24.1600","6.0169","343.8873","6.0169","4.0113","81.8779"
"24.2400","6.0378","344.9339","6.0378","4.0252","82.1271"
"24.3200","6.0574","345.8760","6.0574","4.0383","82.3514"
"24.4000","6.0778","346.9025","6.0778","4.0519","82.5958"
"24.4800","6.0982","347.9491","6.0982","4.0655","82.8450"
"24.5600","6.1172","348.8318","6.1172","4.0781","83.0552"
"24.6400","6.1369","349.7940","6.1369","4.0913","83.2843"
"24.7200","6.1565","350.7200","6.1565","4.1043","83.5048"
"24.8000","6.1766","351.7342","6.1766","4.1177","83.7462"
"24.8800","6.1982","352.8334","6.1982","4.1321","84.0080"
"24.9600","6.2172","353.7097","6.2172","4.1448","84.2166"
"25.0400","6.2381","354.7445","6.2381","4.1587","84.4630"
"25.1200","6.2571","355.6269","6.2571","4.1714","84.6731"
"25.2000","6.2763","356.5623","6.2763","4.1842","84.8958"
"25.2800","6.2967","357.5616","6.2967","4.1978","85.1337"
"25.3600","6.3168","358.5217","6.3168","4.2112","85.3623"
"25.4400","6.3375","359.5520","6.3375","4.2250","85.6076"
"25.5200","6.3584","360.5813","6.3584","4.2389","85.8527"
"25.6000","6.3779","361.5093","6.3779","4.2519","86.0736"
"25.6800","6.3980","362.4731","6.3980","4.2653","86.3031"
"25.7600","6.4176","363.3987","6.4176","4.2784","86.5235"
"25.8400","6.4372","364.3456","6.4372","4.2915","86.7490"
"25.9200","6.4570","365.2852","6.4570","4.3047","86.9727"
"26.0000","6.4759","366.1748","6.4759","4.3173","87.1845"
"26.0800","6.4975","367.2592","6.4975","4.3317","87.4427"
"26.1600","6.5181","368.2661","6.5181","4.3454","87.6824"
"26.2400","6.5378","369.1844","6.5378","4.3585","87.9011"
"26.3200","6.5573","370.1052","6.5573","4.3715","88.1203"
"26.4000","6.5769","371.0301","6.5769","4.3846","88.3405"
"26.4800","6.5974","372.0644","6.5974","4.3982","88.5868"
"26.5600","6.6177","373.0254","6.6177","4.4118","88.8156"
"26.6400","6.6360","373.8422","6.6360","4.4240","89.0100"
"26.7200","6.6576","374.9221","6.6576","4.4384","89.2672"
"26.8000","6.6780","375.8996","6.6780","4.4520","89.4999"
"26.8800","6.6983","376.8710","6.6983","4.4655","89.7312"
"26.9600","6.7176","377.7434","6.7176","4.4784","89.9389"
"27.0400","6.7369","378.6238","6.7369","4.4912","90.1485"
"27.1200","6.7570","379.5883","6.7570","4.5046","90.3782"
"27.2000","6.7772","380.5464","6.7772","4.5182","90.6063"
"27.2800","6.7964","381.4335","6.7964","4.5309","90.8175"
"27.3600","6.8174","382.4460","6.8174","4.5449","91.0586"
"27.4400","6.8376","383.3855","6.8376","4.5584","91.2823"
"27.5200","6.8580","384.3450","6.8580","4.5720","91.5107"
"27.6000","6.8774","385.2236","6.8774","4.5849","91.7199"
"27.6800","6.8966","386.0971","6.8966","4.5978","91.9279"
"27.7600","6.9170","387.0499","6.9170","4.6113","92.1547"
"27.8400","6.9369","387.9757","6.9369","4.6246","92.3752"
"27.9200","6.9570","388.9177","6.9570","4.6380","92.5995"
"28.0000","6.9781","389.9481","6.9781","4.6521","92.8448"
"28.0800","6.9983","390.8629","6.9983","4.6655","93.0626"
"28.1600","7.0182","391.7666","7.0182","4.6788","93.2778"
"28.2400","7.0377","392.6449","7.0377","4.6918","93.4869"
"28.3200","7.0563","393.4620","7.0563","4.7042","93.6814"
"28.4000","7.0771","394.4582","7.0771","4.7181","93.9186"
"28.4800","7.0966","395.3407","7.0966","4.7311","94.1287"
"28.5600","7.1175","396.3334","7.1175","4.7450","94.3651"
"28.6400","7.1374","397.2364","7.1374","4.7582","94.5801"
"28.7200","7.1575","398.1464","7.1575","4.7716","94.7968"
"28.8000","7.1773","399.0356","7.1773","4.7849","95.0085"
"28.8800","7.1976","399.9583","7.1976","4.7984","95.2282"
"28.9600","7.2169","400.8218","7.2169","4.8113","95.4338"
"29.0400","7.2371","401.7463","7.2371","4.8247","95.6539"
"29.1200","7.2554","402.5081","7.2554","4.8369","95.8353"
"29.2000","7.2774","403.5837","7.2774","4.8516","96.0914"
"29.2800","7.2987","404.5562","7.2987","4.8658","96.3229"
"29.3600","7.3184","405.4443","7.3184","4.8789","96.5344"
"29.4400","7.3373","406.2427","7.3373","4.8915","96.7244"
"29.5200","7.3570","407.0998","7.3570","4.9046","96.9285"
"29.6000","7.3773","408.0204","7.3773","4.9182","97.1477"
"29.6800","7.3977","408.9443","7.3977","4.9318","97.3677"
"29.7600","7.4166","409.7301","7.4166","4.9444","97.5548"
"29.8400","7.4372","410.6773","7.4372","4.9581","97.7803"
"29.9200","7.4576","411.5776","7.4576","4.9717","97.9947"
"30.0000","7.4777","412.4935","7.4777","4.9851","98.2127"
"30.0800","7.4980","413.3791","7.4980","4.9987","98.4236"
"30.1600","7.5169","414.1655","7.5169","5.0112","98.6108"
"30.2400","7.5373","415.0751","7.5373","5.0249","98.8274"
"30.3200","7.5570","415.9379","7.5570","5.0380","99.0328"
"30.4000","7.5768","416.7918","7.5768","5.0512","99.2361"
"30.4800","7.5974","417.7168","7.5974","5.0650","99.4564"
"30.5600","7.6185","418.6537","7.6185","5.0790","99.6795"
"30.6400","7.6383","419.5303","7.6383","5.0922","99.8882"
"30.7200","7.6579","420.3471","7.6579","5.1052","100.0827"
"30.8000","7.6765","421.1190","7.6765","5.1177","100.2664"
"30.8800","7.6977","422.0654","7.6977","5.1318","100.4918"
"30.9600","7.7166","422.8333","7.7166","5.1444","100.6746"
"31.0400","7.7367","423.7157","7.7367","5.1578","100.8847"
"31.1200","7.7569","424.6016","7.7569","5.1713","101.0956"
"31.2000","7.7776","425.4849","7.7776","5.1851","101.3059"
"31.2800","7.7981","426.3702","7.7981","5.1987","101.5167"
"31.3600","7.8179","427.1974","7.8179","5.2119","101.7137"
"31.4400","7.8366","427.9525","7.8366","5.2244","101.8934"
"31.5200","7.8568","428.8235","7.8568","5.2378","102.1008"
"31.6000","7.8765","429.6377","7.8765","5.2510","102.2947"
"31.6800","7.8978","430.6246","7.8978","5.2652","102.5297"
"31.7600","7.9187","431.5175","7.9187","5.2791","102.7423"
"31.8400","7.9376","432.2588","7.9376","5.2917","102.9188"
"31.9200","7.9576","433.0941","7.9576","5.3050","103.1176"
"32.0000","7.9775","433.9310","7.9775","5.3183","103.3169"
"32.0800","7.9973","434.7634","7.9973","5.3315","103.5151"
"32.1600","8.0172","435.5981","8.0172","5.3448","103.7138"
"32.2400","8.0361","436.3393","8.0361","5.3574","103.8903"
"32.3200","8.0567","437.2402","8.0567","5.3712","104.1048"
"32.4000","8.0783","438.1931","8.0783","5.3855","104.3317"
"32.4800","8.0971","438.9357","8.0971","5.3981","104.5085"
"32.5600","8.1178","439.8059","8.1178","5.4119","104.7157"
"32.6400","8.1369","440.5461","8.1369","5.4246","104.8919"
"32.7200","8.1571","441.3864","8.1571","5.4380","105.0920"
"32.8000","8.1767","442.1809","8.1767","5.4511","105.2812"
"32.8800","8.1968","443.0072","8.1968","5.4646","105.4779"
"32.9600","8.2175","443.8821","8.2175","5.4783","105.6862"
"33.0400","8.2383","444.7634","8.2383","5.4922","105.8961"
"33.1200","8.2575","445.5285","8.2575","5.5050","106.0782"
"33.2000","8.2777","446.3482","8.2777","5.5184","106.2734"
"33.2800","8.2969","447.1045","8.2969","5.5313","106.4534"
"33.3600","8.3177","447.9774","8.3177","5.5451","106.6613"
"33.4400","8.3370","448.7324","8.3370","5.5580","106.8411"
"33.5200","8.3564","449.5172","8.3564","5.5709","107.0279"
"33.6000","8.3768","450.3422","8.3768","5.5845","107.2243"
"33.6800","8.3979","451.2386","8.3979","5.5986","107.4378"
"33.7600","8.4185","452.0858","8.4185","5.6124","107.6395"
"33.8400","8.4377","452.8117","8.4377","5.6251","107.8123"
"33.9200","8.4561","453.4860","8.4561","5.6374","107.9729"
"34.0000","8.4766","454.3519","8.4766","5.6511","108.1790"
"34.0800","8.4973","455.1925","8.4973","5.6649","108.3792"
"34.1600","8.5172","455.9988","8.5172","5.6782","108.5711"
"34.2400","8.5378","456.8210","8.5378","5.6919","108.7669"
"34.3200","8.5576","457.5952","8.5576","5.7051","108.9512"
"34.4000","8.5783","458.4288","8.5783","5.7189","109.1497"
"34.4800","8.5976","459.1732","8.5976","5.7318","109.3270"
"34.5600","8.6170","459.9303","8.6170","5.7447","109.5072"
"34.6400","8.6368","460.6957","8.6368","5.7579","109.6895"
"34.7200","8.6565","461.4475","8.6565","5.7710","109.8685"
"34.8000","8.6765","462.2467","8.6765","5.7843","110.0587"
"34.8800","8.6985","463.1551","8.6985","5.7990","110.2750"
"34.9600","8.7175","463.8399","8.7175","5.8116","110.4381"
"35.0400","8.7380","464.6422","8.7380","5.8253","110.6291"
"35.1200","8.7570","465.3318","8.7570","5.8380","110.7933"
"35.2000","8.7769","466.1153","8.7769","5.8512","110.9798"
"35.2800","8.7967","466.8782","8.7967","5.8645","111.1615"
"35.3600","8.8168","467.6474","8.8168","5.8779","111.3446"
"35.4400","8.8373","468.4635","8.8373","5.8915","111.5389"
"35.5200","8.8584","469.3083","8.8584","5.9056","111.7401"
"35.6000","8.8778","470.0315","8.8778","5.9185","111.9123"
"35.6800","8.8979","470.7996","8.8979","5.9320","112.0951"
"35.7600","8.9173","471.4885","8.9173","5.9448","112.2592"
"35.8400","8.9370","472.2711","8.9370","5.9580","112.4455"
"35.9200","8.9568","473.0134","8.9568","5.9712","112.6222"
"36.0000","8.9761","473.7397","8.9761","5.9841","112.7952"
"36.0800","8.9978","474.6317","8.9978","5.9986","113.0075"
"36.1600","9.0178","475.3917","9.0178","6.0119","113.1885"
"36.2400","9.0375","476.1126","9.0375","6.0250","113.3601"
"36.3200","9.0571","476.8373","9.0571","6.0381","113.5327"
"36.4000","9.0768","477.5708","9.0768","6.0512","113.7073"
"36.4800","9.0970","478.3499","9.0970","6.0647","113.8928"
"36.5600","9.1176","479.1378","9.1176","6.0784","114.0804"
"36.6400","9.1363","479.7996","9.1363","6.0909","114.2380"
"36.7200","9.1577","480.6673","9.1577","6.1051","114.4446"
"36.8000","9.1785","481.4912","9.1785","6.1190","114.6408"
"36.8800","9.1987","482.2611","9.1987","6.1325","114.8241"
"36.9600","9.2169","482.8654","9.2169","6.1446","114.9679"
"37.0400","9.2368","483.5915","9.2368","6.1579","115.1408"
"37.1200","9.2571","484.3753","9.2571","6.1714","115.3275"
"37.2000","9.2775","485.1237","9.2775","6.1850","115.5057"
"37.2800","9.2963","485.7966","9.2963","6.1975","115.6659"
"37.3600","9.3175","486.6348","9.3175","6.2117","115.8654"
"37.4400","9.3373","487.3317","9.3373","6.2249","116.0314"
"37.5200","9.3581","488.1407","9.3581","6.2387","116.2240"
"37.6000","9.3775","488.8104","9.3775","6.2516","116.3834"
"37.6800","9.3966","489.5001","9.3966","6.2644","116.5477"
"37.7600","9.4171","490.2641","9.4171","6.2781","116.7296"
"37.8400","9.4369","490.9743","9.4369","6.2913","116.8986"
"37.9200","9.4569","491.7080","9.4569","6.3046","117.0733"
"38.0000","9.4779","492.5221","9.4779","6.3186","117.2672"
"38.0800","9.4982","493.2479","9.4982","6.3321","117.4400"
"38.1600","9.5183","493.9628","9.5183","6.3455","117.6102"
"38.2400","9.5374","494.6082","9.5374","6.3583","117.7639"
"38.3200","9.5564","495.2847","9.5564","6.3709","117.9249"
"38.4000","9.5772","496.0600","9.5772","6.3848","118.1095"
"38.4800","9.5962","496.6893","9.5962","6.3974","118.2594"
"38.5600","9.6176","497.5319","9.6176","6.4117","118.4600"
"38.6400","9.6378","498.2440","9.6378","6.4252","118.6295"
"38.7200","9.6575","498.9231","9.6575","6.4383","118.7912"
"38.8000","9.6772","499.6103","9.6772","6.4515","118.9548"
"38.8800","9.6977","500.3463","9.6977","6.4651","119.1301"
"38.9600","9.7169","500.9995","9.7169","6.4779","119.2856"
"39.0400","9.7369","501.7074","9.7369","6.4913","119.4542"
"39.1200","9.7561","502.3477","9.7561","6.5041","119.6066"
"39.2000","9.7777","503.1672","9.7777","6.5185","119.8017"
"39.2800","9.7985","503.9334","9.7985","6.5323","119.9841"
"39.3600","9.8184","504.6104","9.8184","6.5456","120.1453"
"39.4400","9.8370","505.1758","9.8370","6.5580","120.2799"
"39.5200","9.8570","505.8852","9.8570","6.5713","120.4489"
"39.6000","9.8774","506.6059","9.8774","6.5849","120.6205"
"39.6800","9.8975","507.2924","9.8975","6.5983","120.7839"
"39.7600","9.9164","507.8998","9.9164","6.6109","120.9285"
"39.8400","9.9370","508.6289","9.9370","6.6247","121.1021"
"39.9200","9.9578","509.3613","9.9578","6.6385","121.2765"
"40.0000","9.9776","510.0343","9.9776","6.6517","121.4367"
"40.0800","9.9973","510.6904","9.9973","6.6648","121.5930"
"40.1600","10.0165","511.3046","10.0165","6.6777","121.7392"
"40.2400","10.0375","512.0395","10.0375","6.6917","121.9142"
"40.3200","10.0569","512.6690","10.0569","6.7046","122.0640"
"40.4000","10.0771","513.3558","10.0771","6.7181","122.2276"
"40.4800","10.0979","514.0749","10.0979","6.7319","122.3988"
"40.5600","10.1184","514.7595","10.1184","6.7456","122.5618"
"40.6400","10.1377","515.3829","10.1377","6.7585","122.7102"
"40.7200","10.1577","516.0284","10.1577","6.7718","122.8639"
"40.8000","10.1763","516.5933","10.1763","6.7842","122.9984"
"40.8800","10.1977","517.3559","10.1977","6.7985","123.1800"
"40.9600","10.2168","517.9236","10.2168","6.8112","123.3151"
"41.0400","10.2366","518.5908","10.2366","6.8244","123.4740"
"41.1200","10.2568","519.2618","10.2568","6.8379","123.6338"
"41.2000","10.2777","519.9724","10.2777","6.8518","123.8029"
"41.2800","10.2982","520.6868","10.2982","6.8655","123.9731"
"41.3600","10.3183","521.3275","10.3183","6.8789","124.1256"
"41.4400","10.3367","521.8431","10.3367","6.8911","124.2484"
"41.5200","10.3562","522.4569","10.3562","6.9041","124.3945"
"41.6000","10.3767","523.1440","10.3767","6.9178","124.5581"
"41.6800","10.3980","523.8795","10.3980","6.9320","124.7332"
"41.7600","10.4187","524.5450","10.4187","6.9458","124.8917"
"41.8400","10.4378","525.0982","10.4378","6.9585","125.0234"
"41.9200","10.4577","525.7162","10.4577","6.9718","125.1705"
"42.0000","10.4773","526.3295","10.4773","6.9849","125.3165"
"42.0800","10.4972","526.9471","10.4972","6.9981","125.4636"
"42.1600","10.5171","527.5681","10.5171","7.0114","125.6115"
"42.2400","10.5363","528.1385","10.5363","7.0242","125.7473"
"42.3200","10.5570","528.8108","10.5570","7.0380","125.9073"
"42.4000","10.5778","529.4785","10.5778","7.0519","126.0663"
"42.4800","10.5976","530.0685","10.5976","7.0650","126.2068"
"42.5600","10.6181","530.7071","10.6181","7.0787","126.3588"
"42.6400","10.6368","531.2260","10.6368","7.0912","126.4824"
"42.7200","10.6571","531.8804","10.6571","7.1047","126.6382"
"42.8000","10.6768","532.4955","10.6768","7.1179","126.7847"
"42.8800","10.6969","533.1074","10.6969","7.1313","126.9303"
"42.9600","10.7176","533.7600","10.7176","7.1451","127.0857"
"43.0400","10.7387","534.4217","10.7387","7.1592","127.2433"
"43.1200","10.7576","534.9205","10.7576","7.1717","127.3620"
"43.2000","10.7777","535.5371","10.7777","7.1852","127.5088"
"43.2800","10.7970","536.0588","10.7970","7.1980","127.6331"
"43.3600","10.8175","536.6982","10.8175","7.2116","127.7853"
"43.4400","10.8368","537.2328","10.8368","7.2246","127.9126"
"43.5200","10.8563","537.8022","10.8563","7.2375","128.0482"
"43.6000","10.8774","538.4603","10.8774","7.2516","128.2048"
"43.6800","10.8979","539.0546","10.8979","7.2652","128.3463"
"43.7600","10.9176","539.6105","10.9176","7.2784","128.4787"
"43.8400","10.9373","540.1736","10.9373","7.2915","128.6128"
"43.9200","10.9564","540.6695","10.9564","7.3043","128.7308"
"44.0000","10.9767","541.2715","10.9767","7.3178","128.8742"
"44.0800","10.9974","541.8903","10.9974","7.3316","129.0215"
"44.1600","11.0172","542.4461","11.0172","7.3448","129.1538"
"44.2400","11.0377","543.0423","11.0377","7.3585","129.2958"
"44.3200","11.0574","543.5654","11.0574","7.3716","129.4203"
"44.4000","11.0783","544.1941","11.0783","7.3855","129.5700"
"44.4800","11.0977","544.7059","11.0977","7.3985","129.6919"
"44.5600","11.1173","545.2241","11.1173","7.4115","129.8153"
"44.6400","11.1368","545.7858","11.1368","7.4246","129.9490"
"44.7200","11.1568","546.3198","11.1568","7.4378","130.0762"
"44.8000","11.1765","546.8805","11.1765","7.4510","130.2096"
"44.8800","11.1981","547.5436","11.1981","7.4654","130.3675"
"44.9600","11.2176","548.0363","11.2176","7.4784","130.4848"
"45.0400","11.2380","548.6021","11.2380","7.4920","130.6195"
"45.1200","11.2571","549.0675","11.2571","7.5047","130.7304"
"45.2000","11.2761","549.5697","11.2761","7.5174","130.8499"
"45.2800","11.2971","550.1872","11.2971","7.5314","130.9970"
"45.3600","11.3174","550.7221","11.3174","7.5450","131.1243"
"45.4400","11.3374","551.2532","11.3374","7.5583","131.2508"
"45.5200","11.3585","551.8495","11.3585","7.5723","131.3927"
"45.6000","11.3775","552.3122","11.3775","7.5850","131.5029"
"45.6800","11.3980","552.8622","11.3980","7.5987","131.6338"
"45.7600","11.4173","553.3269","11.4173","7.6115","131.7445"
"45.8400","11.4372","553.8734","11.4372","7.6248","131.8746"
"45.9200","11.4568","554.3511","11.4568","7.6379","131.9883"
"46.0000","11.4760","554.8240","11.4760","7.6507","132.1009"
"46.0800","11.4976","555.4459","11.4976","7.6651","132.2490"
"46.1600","11.5181","555.9907","11.5181","7.6787","132.3787"
"46.2400","11.5377","556.4635","11.5377","7.6918","132.4913"
"46.3200","11.5572","556.9344","11.5572","7.7048","132.6034"
"46.4000","11.5770","557.4046","11.5770","7.7180","132.7154"
"46.4800","11.5968","557.9200","11.5968","7.7312","132.8381"
"46.5600","11.6174","558.4608","11.6174","7.7450","132.9669"
"46.6400","11.6361","558.8659","11.6361","7.7574","133.0633"
"46.7200","11.6576","559.4598","11.6576","7.7717","133.2047"
"46.8000","11.6782","559.9884","11.6782","7.7855","133.3306"
"46.8800","11.6989","560.5296","11.6989","7.7992","133.4594"
"46.9600","11.7176","560.9166","11.7176","7.8118","133.5516"
"47.0400","11.7371","561.3494","11.7371","7.8247","133.6546"
"47.1200","11.7567","561.8062","11.7567","7.8378","133.7634"
"47.2000","11.7774","562.3372","11.7774","7.8516","133.8898"
"47.2800","11.7963","562.7470","11.7963","7.8642","133.9874"
"47.3600","11.8174","563.3186","11.8174","7.8783","134.1235"
"47.4400","11.8371","563.7525","11.8371","7.8914","134.2268"
"47.5200","11.8577","564.2740","11.8577","7.9051","134.3510"
"47.6000","11.8779","564.7383","11.8779","7.9186","134.4615"
"47.6800","11.8969","565.1458","11.8969","7.9313","134.5585"
"47.7600","11.9169","565.5912","11.9169","7.9446","134.6646"
"47.8400","11.9368","566.0538","11.9368","7.9579","134.7747"
"47.9200","11.9573","566.5656","11.9573","7.9716","134.8966"
"48.0000","11.9781","567.0852","11.9781","7.9854","135.0203"
"48.0800","11.9982","567.5288","11.9982","7.9988","135.1259"
"48.1600","12.0181","567.9562","12.0181","8.0121","135.2277"
"48.2400","12.0376","568.3663","12.0376","8.0251","135.3253"
"48.3200","12.0566","568.7505","12.0566","8.0377","135.4168"
"48.4000","12.0774","569.2426","12.0774","8.0516","135.5339"
"48.4800","12.0964","569.6140","12.0964","8.0643","135.6224"
"48.5600","12.1176","570.1417","12.1176","8.0784","135.7480"
"48.6400","12.1378","570.5837","12.1378","8.0919","135.8533"
"48.7200","12.1575","570.9857","12.1575","8.1050","135.9490"
"48.8000","12.1776","571.4321","12.1776","8.1184","136.0553"
"48.8800","12.1976","571.8400","12.1976","8.1317","136.1524"
"48.9600","12.2166","572.2188","12.2166","8.1444","136.2426"
"49.0400","12.2369","572.6517","12.2369","8.1579","136.3456"
"49.1200","12.2561","573.0057","12.2561","8.1707","136.4299"
"49.2000","12.2778","573.5325","12.2778","8.1852","136.5553"
"49.2800","12.2983","573.9730","12.2983","8.1989","136.6602"
"49.3600","12.3186","574.3945","12.3186","8.2124","136.7606"
"49.4400","12.3372","574.6927","12.3372","8.2248","136.8316"
"49.5200","12.3570","575.0724","12.3570","8.2380","136.9220"
"49.6000","12.3770","575.4816","12.3770","8.2513","137.0194"
"49.6800","12.3975","575.9135","12.3975","8.2650","137.1223"
"49.7600","12.4164","576.2204","12.4164","8.2776","137.1953"
"49.8400","12.4370","576.6501","12.4370","8.2913","137.2976"
"49.9200","12.4578","577.0841","12.4578","8.3052","137.4010"
"50.0000","12.4779","577.4678","12.4779","8.3186","137.4923"
"50.0800","12.4976","577.7983","12.4976","8.3317","137.5710"
"50.1600","12.5166","578.0842","12.5166","8.3444","137.6391"
"50.2400","12.5374","578.5122","12.5374","8.3583","137.7410"
"50.3200","12.5572","578.8621","12.5572","8.3715","137.8243"
"50.4000","12.5769","579.2015","12.5769","8.3846","137.9051"
"50.4800","12.5978","579.6346","12.5978","8.3985","138.0082"
"50.5600","12.6185","580.0049","12.6185","8.4123","138.0964"
"50.6400","12.6378","580.3092","12.6378","8.4252","138.1689"
"50.7200","12.6579","580.6647","12.6579","8.4386","138.2535"
"50.8000","12.6764","580.9202","12.6764","8.4509","138.3143"
"50.8800","12.6977","581.3387","12.6977","8.4651","138.4140"
"50.9600","12.7166","581.5833","12.7166","8.4777","138.4722"
"51.0400","12.7365","581.9430","12.7365","8.4910","138.5579"
"51.1200","12.7571","582.3138","12.7571","8.5047","138.6461"
"51.2000","12.7780","582.6890","12.7780","8.5187","138.7355"
"51.2800","12.7980","583.0113","12.7980","8.5320","138.8122"
"51.3600","12.8181","583.3272","12.8181","8.5454","138.8874"
"51.4400","12.8364","583.5223","12.8364","8.5576","138.9339"
"51.5200","12.8565","583.8387","12.8565","8.5710","139.0092"
"51.6000","12.8765","584.1349","12.8765","8.5843","139.0797"
"51.6800","12.8978","584.5262","12.8978","8.5986","139.1729"
"51.7600","12.9185","584.8395","12.9185","8.6123","139.2475"
"51.8400","12.9378","585.0765","12.9378","8.6252","139.3039"
"51.9200","12.9577","585.3353","12.9577","8.6385","139.3656"
"52.0000","12.9776","585.5894","12.9776","8.6517","139.4261"
"52.0800","12.9974","585.8472","12.9974","8.6650","139.4874"
"52.1600","13.0170","586.0684","13.0170","8.6780","139.5401"
"52.2400","13.0363","586.2626","13.0363","8.6909","139.5863"
"52.3200","13.0571","586.5916","13.0571","8.7048","139.6647"
"52.4000","13.0783","586.8123","13.0783","8.7188","139.7172"
"52.4800","13.0979","586.9831","13.0979","8.7320","139.7579"
"52.5600","13.1179","587.1774","13.1179","8.7453","139.8041"
"52.6400","13.1366","587.2944","13.1366","8.7577","139.8320"
"52.7200","13.1568","587.5491","13.1568","8.7712","139.8927"
"52.8000","13.1766","587.7412","13.1766","8.7844","139.9384"
"52.8800","13.1971","587.9760","13.1971","8.7980","139.9943"
"52.9600","13.2178","588.2245","13.2178","8.8119","140.0535"
"53.0400","13.2382","588.4479","13.2382","8.8255","140.1066"
"53.1200","13.2576","588.6249","13.2576","8.8384","140.1488"
"53.2000","13.2776","588.8284","13.2776","8.8517","140.1972"
"53.2800","13.2970","588.9755","13.2970","8.8647","140.2323"
"53.3600","13.3179","589.2379","13.3179","8.8786","140.2947"
"53.4400","13.3371","589.3790","13.3371","8.8914","140.3283"
"53.5200","13.3562","589.5214","13.3562","8.9041","140.3622"
"53.6000","13.3772","589.7702","13.3772","8.9181","140.4215"
"53.6800","13.3978","589.9744","13.3978","8.9319","140.4701"
"53.7600","13.4180","590.1531","13.4180","8.9453","140.5126"
"53.8400","13.4375","590.2864","13.4375","8.9583","140.5444"
"53.9200","13.4564","590.3802","13.4564","8.9709","140.5667"
"54.0000","13.4770","590.5778","13.4770","8.9847","140.6138"
"54.0800","13.4973","590.7436","13.4973","8.9982","140.6532"
"54.1600","13.5174","590.9033","13.5174","9.0116","140.6913"
"54.2400","13.5380","590.9940","13.5380","9.0253","140.7129"
"54.3200","13.5575","591.0387","13.5575","9.0383","140.7235"
"54.4000","13.5784","591.1899","13.5784","9.0523","140.7595"
"54.4800","13.5981","591.2858","13.5981","9.0654","140.7823"
"54.5600","13.6173","591.3488","13.6173","9.0782","140.7973"
"54.6400","13.6371","591.4614","13.6371","9.0914","140.8241"
"54.7200","13.6565","591.5349","13.6565","9.1043","140.8416"
"54.8000","13.6767","591.7000","13.6767","9.1178","140.8809"
"54.8800","13.6981","591.8907","13.6981","9.1320","140.9264"
"54.9600","13.7176","591.9525","13.7176","9.1451","140.9411"
"55.0400","13.7380","592.0737","13.7380","9.1587","140.9699"
"55.1200","13.7571","592.1267","13.7571","9.1714","140.9826"
"55.2000","13.7770","592.2515","13.7770","9.1847","141.0123"
"55.2800","13.7967","592.3419","13.7967","9.1978","141.0338"
"55.3600","13.8165","592.4254","13.8165","9.2110","141.0537"
"55.4400","13.8374","592.5923","13.8374","9.2249","141.0934"
"55.5200","13.8584","592.7369","13.8584","9.2389","141.1278"
"55.6000","13.8778","592.7821","13.8778","9.2519","141.1386"
"55.6800","13.8980","592.8635","13.8980","9.2653","141.1580"
"55.7600","13.9174","592.8860","13.9174","9.2783","141.1633"
"55.8400","13.9372","592.9507","13.9372","9.2914","141.1787"
"55.9200","13.9568","592.9677","13.9568","9.3046","141.1828"
"56.0000","13.9758","592.9496","13.9758","9.3172","141.1785"
"56.0800","13.9974","593.0664","13.9974","9.3316","141.2063"
"56.1600","14.0182","593.0925","14.0182","9.3455","141.2125"
"56.2400","14.0378","593.0897","14.0378","9.3586","141.2118"
"56.3200","14.0572","593.0826","14.0572","9.3715","141.2101"
"56.4000","14.0769","593.0935","14.0769","9.3846","141.2127"
"56.4800","14.0971","593.1570","14.0971","9.3981","141.2279"
"56.5600","14.1174","593.2122","14.1174","9.4116","141.2410"
"56.6400","14.1361","593.1741","14.1361","9.4241","141.2319"
"56.7200","14.1575","593.2911","14.1575","9.4384","141.2598"
"56.8000","14.1781","593.3304","14.1781","9.4521","141.2691"
"56.8800","14.1987","593.3696","14.1987","9.4658","141.2785"
"56.9600","14.2176","593.3031","14.2176","9.4784","141.2626"
"57.0400","14.2370","593.2508","14.2370","9.4914","141.2502"
"57.1200","14.2570","593.2466","14.2570","9.5047","141.2492"
"57.2000","14.2770","593.2278","14.2770","9.5180","141.2447"
"57.2800","14.2964","593.1844","14.2964","9.5310","141.2344"
"57.3600","14.3172","593.1892","14.3172","9.5448","141.2355"
"57.4400","14.3375","593.1441","14.3375","9.5583","141.2248"
"57.5200","14.3579","593.1407","14.3579","9.5720","141.2240"
"57.6000","14.3775","593.0670","14.3775","9.5850","141.2064"
"57.6800","14.3961","592.9503","14.3961","9.5974","141.1786"
"57.7600","14.4171","592.8705","14.4171","9.6114","141.1597"
"57.8400","14.4369","592.8074","14.4369","9.6246","141.1446"
"57.9200","14.4576","592.7811","14.4576","9.6384","141.1383"
"58.0000","14.4780","592.7353","14.4780","9.6520","141.1275"
"58.0800","14.4979","592.6105","14.4979","9.6653","141.0977"
"58.1600","14.5182","592.5336","14.5182","9.6788","141.0794"
"58.2400","14.5376","592.3737","14.5376","9.6917","141.0414"
"58.3200","14.5567","592.2035","14.5567","9.7045","141.0008"
"58.4000","14.5773","592.0931","14.5773","9.7182","140.9746"
"58.4800","14.5961","591.8715","14.5961","9.7307","140.9218"
"58.5600","14.6173","591.8030","14.6173","9.7449","140.9055"
"58.6400","14.6379","591.6911","14.6379","9.7586","140.8788"
"58.7200","14.6576","591.5210","14.6576","9.7717","140.8383"
"58.8000","14.6774","591.3603","14.6774","9.7849","140.8001"
"58.8800","14.6973","591.2048","14.6973","9.7982","140.7631"
"58.9600","14.7169","591.0248","14.7169","9.8113","140.7202"
"59.0400","14.7369","590.7719","14.7369","9.8246","140.6600"
"59.1200","14.7562","590.5687","14.7562","9.8375","140.6116"
"59.2000","14.7779","590.5110","14.7779","9.8519","140.5979"
"59.2800","14.7984","590.3912","14.7984","9.8656","140.5693"
"59.3600","14.8179","590.2400","14.8179","9.8786","140.5333"
"59.4400","14.8374","590.0694","14.8374","9.8916","140.4927"
"59.5200","14.8571","589.9148","14.8571","9.9047","140.4559"
"59.6000","14.8772","589.7812","14.8772","9.9181","140.4241"
"59.6800","14.8974","589.6188","14.8974","9.9316","140.3854"
"59.7600","14.9165","589.4023","14.9165","9.9443","140.3339"
"59.8400","14.9372","589.2737","14.9372","9.9582","140.3033"
"59.9200","14.9577","589.1084","14.9577","9.9718","140.2639"
"60.0000","14.9776","588.9202","14.9776","9.9851","140.2191"
"60.0800","14.9979","588.7200","14.9979","9.9986","140.1714"
"60.0880","15.0000","588.7046","15.0000","10.0000","140.1678"