File: data/instron_tests/metamaterials/250331/250331_2246_BULK_m1.is_comp_Exports/250331_2246_BULK_m1_4_1.csv
Results Table 1
,Compresson Axis,H*,V*,Height,Thickness,Width,Area,Fixture separation,Specimen label
,,,,(mm),(mm),(mm),(mm^2),(mm),
"4","X","","","150.00","28.00","150.00","4200.00","150.00","2046_BULK_m1"

Results Table 2
,Modulus (Segment 0 % - 5 %),Compresson Axis
,(kPa),
"4","1984.74","X"

Time,Displacement,Force,Compressive displacement,Compressive strain (Displacement),Compressive stress
(s),(mm),(N),(mm),(%),(kPa)
"0.0000","0.0000","-23.6439","0.0000","0.0000","-5.6295"
"0.0800","0.0012","-23.5411","0.0012","0.0008","-5.6050"
"0.1600","0.0173","-22.2847","0.0173","0.0115","-5.3059"
"0.2400","0.0374","-20.8152","0.0374","0.0249","-4.9560"
"0.3200","0.0574","-19.4042","0.0574","0.0382","-4.6200"
"0.4000","0.0767","-18.0589","0.0767","0.0511","-4.2997"
"0.4800","0.0980","-16.6100","0.0980","0.0654","-3.9548"
"0.5600","0.1179","-15.2731","0.1179","0.0786","-3.6364"
"0.6400","0.1376","-13.9875","0.1376","0.0917","-3.3304"
"0.7200","0.1573","-12.6838","0.1573","0.1048","-3.0200"
"0.8000","0.1767","-11.4164","0.1767","0.1178","-2.7182"
"0.8800","0.1967","-10.1217","0.1967","0.1311","-2.4099"
"0.9600","0.2167","-8.8520","0.2167","0.1445","-2.1076"
"1.0400","0.2361","-7.6053","0.2361","0.1574","-1.8108"
"1.1200","0.2571","-6.3073","0.2571","0.1714","-1.5017"
"1.2000","0.2774","-5.0382","0.2774","0.1850","-1.1996"
"1.2800","0.2979","-3.7412","0.2979","0.1986","-0.8908"
"1.3600","0.3174","-2.5246","0.3174","0.2116","-0.6011"
"1.4400","0.3360","-1.3736","0.3360","0.2240","-0.3270"
"1.5200","0.3564","-0.0859","0.3564","0.2376","-0.0205"
"1.6000","0.3767","1.1695","0.3767","0.2512","0.2785"
"1.6800","0.3974","2.4654","0.3974","0.2650","0.5870"
"1.7600","0.4184","3.7601","0.4184","0.2790","0.8953"
"1.8400","0.4373","4.8856","0.4373","0.2915","1.1632"
"1.9200","0.4575","6.1185","0.4575","0.3050","1.4568"
"2.0000","0.4771","7.3185","0.4771","0.3181","1.7425"
"2.0800","0.4966","8.5152","0.4966","0.3311","2.0274"
"2.1600","0.5170","9.7619","0.5170","0.3447","2.3243"
"2.2400","0.5361","10.8919","0.5361","0.3574","2.5933"
"2.3200","0.5569","12.1681","0.5569","0.3713","2.8972"
"2.4000","0.5782","13.4685","0.5782","0.3855","3.2068"
"2.4800","0.5976","14.6192","0.5976","0.3984","3.4808"
"2.5600","0.6174","15.8001","0.6174","0.4116","3.7619"
"2.6400","0.6364","16.9202","0.6364","0.4243","4.0286"
"2.7200","0.6563","18.1231","0.6563","0.4375","4.3150"
"2.8000","0.6770","19.3784","0.6770","0.4513","4.6139"
"2.8800","0.6966","20.5246","0.6966","0.4644","4.8868"
"2.9600","0.7175","21.8004","0.7175","0.4784","5.1906"
"3.0400","0.7379","23.0096","0.7379","0.4920","5.4785"
"3.1200","0.7568","24.1254","0.7568","0.5046","5.7441"
"3.2000","0.7774","25.3765","0.7774","0.5183","6.0420"
"3.2800","0.7963","26.4615","0.7963","0.5309","6.3004"
"3.3600","0.8172","27.7343","0.8172","0.5448","6.6034"
"3.4400","0.8370","28.8845","0.8370","0.5580","6.8773"
"3.5200","0.8560","30.0148","0.8560","0.5707","7.1464"
"3.6000","0.8772","31.2921","0.8772","0.5848","7.4505"
"3.6800","0.8977","32.4964","0.8977","0.5984","7.7372"
"3.7600","0.9171","33.6243","0.9171","0.6114","8.0058"
"3.8400","0.9368","34.7809","0.9368","0.6245","8.2812"
"3.9200","0.9559","35.8599","0.9559","0.6373","8.5381"
"4.0000","0.9769","37.1325","0.9769","0.6512","8.8411"
"4.0800","0.9975","38.3398","0.9975","0.6650","9.1285"
"4.1600","1.0168","39.4853","1.0168","0.6779","9.4013"
"4.2400","1.0374","40.7072","1.0374","0.6916","9.6922"
"4.3200","1.0572","41.8606","1.0572","0.7048","9.9668"
"4.4000","1.0777","43.1081","1.0777","0.7185","10.2638"
"4.4800","1.0979","44.3163","1.0979","0.7319","10.5515"
"4.5600","1.1167","45.3985","1.1167","0.7445","10.8092"
"4.6400","1.1368","46.6007","1.1368","0.7579","11.0954"
"4.7200","1.1564","47.7508","1.1564","0.7710","11.3692"
"4.8000","1.1764","48.9589","1.1764","0.7843","11.6569"
"4.8800","1.1980","50.2751","1.1980","0.7986","11.9703"
"4.9600","1.2174","51.3910","1.2174","0.8116","12.2359"
"5.0400","1.2376","52.5924","1.2376","0.8250","12.5220"
"5.1200","1.2569","53.7154","1.2569","0.8379","12.7894"
"5.2000","1.2761","54.8663","1.2761","0.8507","13.0634"
"5.2800","1.2967","56.0993","1.2967","0.8645","13.3570"
"5.3600","1.3166","57.2763","1.3166","0.8777","13.6372"
"5.4400","1.3371","58.4970","1.3371","0.8914","13.9278"
"5.5200","1.3577","59.7206","1.3577","0.9051","14.2192"
"5.6000","1.3772","60.8675","1.3772","0.9181","14.4923"
"5.6800","1.3979","62.1033","1.3979","0.9320","14.7865"
"5.7600","1.4172","63.2167","1.4172","0.9448","15.0516"
"5.8400","1.4368","64.3959","1.4368","0.9578","15.3324"
"5.9200","1.4569","65.5976","1.4569","0.9713","15.6185"
"6.0000","1.4760","66.7281","1.4760","0.9840","15.8877"
"6.0800","1.4972","68.0186","1.4972","0.9981","16.1949"
"6.1600","1.5176","69.2451","1.5176","1.0117","16.4869"
"6.2400","1.5373","70.4179","1.5373","1.0248","16.7662"
"6.3200","1.5571","71.5926","1.5571","1.0381","17.0459"
"6.4000","1.5764","72.7294","1.5764","1.0510","17.3165"
"6.4800","1.5971","74.0071","1.5971","1.0647","17.6207"
"6.5600","1.6176","75.2375","1.6176","1.0784","17.9137"
"6.6400","1.6357","76.2768","1.6357","1.0905","18.1611"
"6.7200","1.6574","77.6209","1.6574","1.1049","18.4812"
"6.8000","1.6779","78.8581","1.6779","1.1186","18.7757"
"6.8800","1.6982","80.0787","1.6982","1.1321","19.0664"
"6.9600","1.7174","81.2113","1.7174","1.1450","19.3360"
"7.0400","1.7368","82.3411","1.7368","1.1579","19.6050"
"7.1200","1.7564","83.5218","1.7564","1.1709","19.8861"
"7.2000","1.7770","84.7581","1.7770","1.1847","20.1805"
"7.2800","1.7959","85.8902","1.7959","1.1973","20.4501"
"7.3600","1.8175","87.2172","1.8175","1.2117","20.7660"
"7.4400","1.8375","88.4001","1.8375","1.2250","21.0476"
"7.5200","1.8577","89.6114","1.8577","1.2384","21.3361"
"7.6000","1.8773","90.7746","1.8773","1.2515","21.6130"
"7.6800","1.8962","91.8896","1.8962","1.2642","21.8785"
"7.7600","1.9169","93.1282","1.9169","1.2779","22.1734"
"7.8400","1.9364","94.2807","1.9364","1.2909","22.4478"
"7.9200","1.9570","95.5235","1.9570","1.3047","22.7437"
"8.0000","1.9778","96.7878","1.9778","1.3185","23.0447"
"8.0800","1.9977","97.9699","1.9977","1.3318","23.3262"
"8.1600","2.0179","99.1892","2.0179","1.3452","23.6165"
"8.2400","2.0376","100.3502","2.0376","1.3584","23.8929"
"8.3200","2.0564","101.4682","2.0564","1.3709","24.1591"
"8.4000","2.0770","102.7274","2.0770","1.3847","24.4589"
"8.4800","2.0961","103.8423","2.0961","1.3974","24.7244"
"8.5600","2.1170","105.1316","2.1170","1.4113","25.0313"
"8.6400","2.1377","106.3948","2.1377","1.4251","25.3321"
"8.7200","2.1572","107.5435","2.1572","1.4381","25.6056"
"8.8000","2.1773","108.7620","2.1773","1.4515","25.8957"
"8.8800","2.1974","109.9506","2.1974","1.4649","26.1787"
"8.9600","2.2165","111.1153","2.2165","1.4777","26.4560"
"9.0400","2.2371","112.3515","2.2371","1.4914","26.7504"
"9.1200","2.2557","113.4273","2.2557","1.5038","27.0065"
"9.2000","2.2775","114.7871","2.2775","1.5183","27.3303"
"9.2800","2.2982","116.0212","2.2982","1.5321","27.6241"
"9.3600","2.3178","117.1861","2.3178","1.5452","27.9015"
"9.4400","2.3371","118.3053","2.3371","1.5580","28.1679"
"9.5200","2.3568","119.4800","2.3568","1.5712","28.4476"
"9.6000","2.3767","120.6840","2.3767","1.5845","28.7343"
"9.6800","2.3974","121.9553","2.3974","1.5983","29.0370"
"9.7600","2.4161","123.0247","2.4161","1.6107","29.2916"
"9.8400","2.4370","124.3037","2.4370","1.6247","29.5961"
"9.9200","2.4576","125.5355","2.4576","1.6384","29.8894"
"10.0000","2.4773","126.7141","2.4773","1.6515","30.1700"
"10.0800","2.4973","127.8940","2.4973","1.6649","30.4510"
"10.1600","2.5163","128.9946","2.5163","1.6775","30.7130"
"10.2400","2.5372","130.3075","2.5372","1.6914","31.0256"
"10.3200","2.5572","131.4904","2.5572","1.7048","31.3072"
"10.4000","2.5764","132.6106","2.5764","1.7176","31.5740"
"10.4800","2.5972","133.8589","2.5972","1.7315","31.8712"
"10.5600","2.6179","135.0897","2.6179","1.7453","32.1642"
"10.6400","2.6377","136.2609","2.6377","1.7585","32.4431"
"10.7200","2.6578","137.4408","2.6578","1.7718","32.7240"
"10.8000","2.6762","138.4954","2.6762","1.7841","32.9751"
"10.8800","2.6971","139.7664","2.6971","1.7981","33.2777"
"10.9600","2.7165","140.8754","2.7165","1.8110","33.5418"
"11.0400","2.7361","142.0336","2.7361","1.8241","33.8175"
"11.1200","2.7568","143.2915","2.7568","1.8379","34.1170"
"11.2000","2.7773","144.4863","2.7773","1.8515","34.4015"
"11.2800","2.7978","145.7030","2.7978","1.8652","34.6912"
"11.3600","2.8176","146.8504","2.8176","1.8784","34.9644"
"11.4400","2.8361","147.9119","2.8361","1.8907","35.2171"
"11.5200","2.8565","149.1274","2.8565","1.9043","35.5065"
"11.6000","2.8764","150.2782","2.8764","1.9176","35.7805"
"11.6800","2.8972","151.5439","2.8972","1.9315","36.0819"
"11.7600","2.9181","152.7848","2.9181","1.9454","36.3773"
"11.8400","2.9374","153.8891","2.9374","1.9583","36.6402"
"11.9200","2.9571","155.0353","2.9571","1.9714","36.9132"
"12.0000","2.9771","156.2182","2.9771","1.9847","37.1948"
"12.0800","2.9973","157.4318","2.9973","1.9982","37.4838"
"12.1600","3.0168","158.5675","3.0168","2.0112","37.7542"
"12.2400","3.0359","159.6402","3.0359","2.0239","38.0096"
"12.3200","3.0565","160.8723","3.0565","2.0377","38.3029"
"12.4000","3.0782","162.1664","3.0782","2.0521","38.6110"
"12.4800","3.0975","163.2666","3.0975","2.0650","38.8730"
"12.5600","3.1176","164.4310","3.1176","2.0784","39.1502"
"12.6400","3.1365","165.5088","3.1365","2.0910","39.4069"
"12.7200","3.1565","166.6851","3.1565","2.1044","39.6869"
"12.8000","3.1768","167.8735","3.1768","2.1179","39.9699"
"12.8800","3.1968","169.0113","3.1968","2.1312","40.2408"
"12.9600","3.2178","170.2550","3.2178","2.1452","40.5369"
"13.0400","3.2383","171.4456","3.2383","2.1588","40.8204"
"13.1200","3.2571","172.5206","3.2571","2.1714","41.0763"
"13.2000","3.2773","173.6889","3.2773","2.1849","41.3545"
"13.2800","3.2967","174.7924","3.2967","2.1978","41.6172"
"13.3600","3.3173","175.9982","3.3173","2.2115","41.9043"
"13.4400","3.3369","177.1214","3.3369","2.2246","42.1718"
"13.5200","3.3562","178.2293","3.3562","2.2375","42.4356"
"13.6000","3.3769","179.4438","3.3769","2.2513","42.7247"
"13.6800","3.3978","180.6506","3.3978","2.2652","43.0120"
"13.7600","3.4175","181.7864","3.4175","2.2784","43.2825"
"13.8400","3.4371","182.9071","3.4371","2.2914","43.5493"
"13.9200","3.4560","183.9499","3.4560","2.3040","43.7976"
"14.0000","3.4768","185.1778","3.4768","2.3179","44.0900"
"14.0800","3.4972","186.3517","3.4972","2.3315","44.3695"
"14.1600","3.5167","187.4697","3.5167","2.3445","44.6356"
"14.2400","3.5375","188.6664","3.5375","2.3583","44.9206"
"14.3200","3.5571","189.7650","3.5571","2.3714","45.1821"
"14.4000","3.5779","190.9656","3.5779","2.3853","45.4680"
"14.4800","3.5977","192.0835","3.5977","2.3984","45.7342"
"14.5600","3.6166","193.1284","3.6166","2.4111","45.9830"
"14.6400","3.6365","194.2599","3.6365","2.4243","46.2524"
"14.7200","3.6564","195.4028","3.6564","2.4376","46.5245"
"14.8000","3.6763","196.5393","3.6763","2.4509","46.7951"
"14.8800","3.6978","197.7959","3.6978","2.4652","47.0943"
"14.9600","3.7173","198.8733","3.7173","2.4782","47.3508"
"15.0400","3.7374","200.0000","3.7374","2.4916","47.6191"
"15.1200","3.7568","201.0837","3.7568","2.5045","47.8771"
"15.2000","3.7762","202.1774","3.7762","2.5175","48.1375"
"15.2800","3.7965","203.3265","3.7965","2.5310","48.4111"
"15.3600","3.8164","204.4445","3.8164","2.5443","48.6773"
"15.4400","3.8372","205.6398","3.8372","2.5581","48.9619"
"15.5200","3.8582","206.8504","3.8582","2.5721","49.2501"
"15.6000","3.8774","207.9065","3.8774","2.5849","49.5016"
"15.6800","3.8974","209.0315","3.8974","2.5983","49.7694"
"15.7600","3.9174","210.1534","3.9174","2.6116","50.0365"
"15.8400","3.9367","211.2226","3.9367","2.6245","50.2911"
"15.9200","3.9567","212.3372","3.9567","2.6378","50.5565"
"16.0000","3.9758","213.3866","3.9758","2.6505","50.8063"
"16.0800","3.9972","214.6317","3.9972","2.6648","51.1028"
"16.1600","4.0180","215.7968","4.0180","2.6787","51.3802"
"16.2400","4.0371","216.8304","4.0371","2.6914","51.6263"
"16.3200","4.0570","217.9530","4.0570","2.7047","51.8936"
"16.4000","4.0768","219.0261","4.0768","2.7179","52.1491"
"16.4800","4.0968","220.1633","4.0968","2.7312","52.4198"
"16.5600","4.1172","221.3013","4.1172","2.7448","52.6908"
"16.6400","4.1357","222.3053","4.1357","2.7572","52.9298"
"16.7200","4.1574","223.5459","4.1574","2.7716","53.2252"
"16.8000","4.1777","224.6774","4.1777","2.7851","53.4946"
"16.8800","4.1982","225.8277","4.1982","2.7988","53.7685"
"16.9600","4.2171","226.8434","4.2171","2.8114","54.0103"
"17.0400","4.2365","227.8971","4.2365","2.8244","54.2612"
"17.1200","4.2567","229.0148","4.2567","2.8378","54.5273"
"17.2000","4.2771","230.1484","4.2771","2.8514","54.7972"
"17.2800","4.2962","231.1820","4.2962","2.8641","55.0433"
"17.3600","4.3172","232.3690","4.3172","2.8781","55.3260"
"17.4400","4.3373","233.4712","4.3373","2.8915","55.5884"
"17.5200","4.3576","234.5869","4.3576","2.9051","55.8540"
"17.6000","4.3770","235.6227","4.3770","2.9180","56.1006"
"17.6800","4.3963","236.6812","4.3963","2.9309","56.3527"
"17.7600","4.4166","237.7838","4.4166","2.9444","56.6152"
"17.8400","4.4368","238.9075","4.4368","2.9579","56.8827"
"17.9200","4.4567","240.0029","4.4567","2.9711","57.1436"
"18.0000","4.4774","241.1712","4.4774","2.9850","57.4217"
"18.0800","4.4980","242.2841","4.4980","2.9987","57.6867"
"18.1600","4.5180","243.3775","4.5180","3.0120","57.9470"
"18.2400","4.5376","244.4166","4.5376","3.0251","58.1944"
"18.3200","4.5560","245.3923","4.5560","3.0374","58.4267"
"18.4000","4.5768","246.5457","4.5768","3.0512","58.7014"
"18.4800","4.5961","247.5795","4.5961","3.0641","58.9475"
"18.5600","4.6173","248.7777","4.6173","3.0782","59.2328"
"18.6400","4.6374","249.8634","4.6374","3.0916","59.4913"
"18.7200","4.6566","250.8744","4.6566","3.1044","59.7320"
"18.8000","4.6769","251.9760","4.6769","3.1179","59.9943"
"18.8800","4.6976","253.1030","4.6976","3.1317","60.2626"
"18.9600","4.7165","254.0898","4.7165","3.1443","60.4976"
"19.0400","4.7372","255.2353","4.7372","3.1582","60.7703"
"19.1200","4.7561","256.2010","4.7561","3.1707","61.0002"
"19.2000","4.7779","257.4404","4.7779","3.1852","61.2953"
"19.2800","4.7982","258.5273","4.7982","3.1988","61.5541"
"19.3600","4.8176","259.5523","4.8176","3.2118","61.7982"
"19.4400","4.8370","260.5608","4.8370","3.2246","62.0383"
"19.5200","4.8568","261.6073","4.8568","3.2379","62.2875"
"19.6000","4.8769","262.6886","4.8769","3.2512","62.5449"
"19.6800","4.8976","263.8399","4.8976","3.2651","62.8190"
"19.7600","4.9166","264.8231","4.9166","3.2777","63.0531"
"19.8400","4.9369","265.9114","4.9369","3.2912","63.3122"
"19.9200","4.9574","267.0060","4.9574","3.3049","63.5729"
"20.0000","4.9775","268.0786","4.9775","3.3183","63.8282"
"20.0800","4.9974","269.1214","4.9974","3.3316","64.0765"
"20.1600","5.0165","270.0937","5.0165","3.3443","64.3080"
"20.2400","5.0368","271.1743","5.0368","3.3579","64.5653"
"20.3200","5.0565","272.2062","5.0565","3.3710","64.8110"
"20.4000","5.0763","273.2384","5.0763","3.3842","65.0568"
"20.4800","5.0979","274.4121","5.0979","3.3986","65.3362"
"20.5600","5.1182","275.4548","5.1182","3.4121","65.5845"
"20.6400","5.1375","276.4590","5.1375","3.4250","65.8236"
"20.7200","5.1573","277.4770","5.1573","3.4382","66.0660"
"20.8000","5.1763","278.4470","5.1763","3.4508","66.2969"
"20.8800","5.1974","279.5868","5.1974","3.4649","66.5683"
"20.9600","5.2168","280.5720","5.2168","3.4778","66.8029"
"21.0400","5.2365","281.6069","5.2365","3.4910","67.0493"
"21.1200","5.2566","282.6588","5.2566","3.5044","67.2997"
"21.2000","5.2774","283.7431","5.2774","3.5183","67.5579"
"21.2800","5.2975","284.7798","5.2975","3.5317","67.8047"
"21.3600","5.3176","285.8074","5.3176","3.5450","68.0494"
"21.4400","5.3360","286.7276","5.3360","3.5573","68.2685"
"21.5200","5.3567","287.8293","5.3567","3.5711","68.5308"
"21.6000","5.3763","288.8512","5.3763","3.5842","68.7741"
"21.6800","5.3974","290.0054","5.3974","3.5983","69.0489"
"21.7600","5.4184","291.0824","5.4184","3.6122","69.3053"
"21.8400","5.4371","292.0017","5.4371","3.6248","69.5242"
"21.9200","5.4569","292.9968","5.4569","3.6379","69.7611"
"22.0000","5.4768","294.0204","5.4768","3.6512","70.0048"
"22.0800","5.4970","295.0768","5.4970","3.6647","70.2564"
"22.1600","5.5173","296.1317","5.5173","3.6782","70.5075"
"22.2400","5.5361","297.0286","5.5361","3.6907","70.7211"
"22.3200","5.5565","298.1052","5.5565","3.7044","70.9774"
"22.4000","5.5779","299.2172","5.5779","3.7186","71.2422"
"22.4800","5.5975","300.2143","5.5975","3.7317","71.4796"
"22.5600","5.6175","301.2049","5.6175","3.7450","71.7154"
"22.6400","5.6366","302.1312","5.6366","3.7577","71.9360"
"22.7200","5.6566","303.1554","5.6566","3.7710","72.1799"
"22.8000","5.6764","304.1622","5.6764","3.7843","72.4196"
"22.8800","5.6966","305.1882","5.6966","3.7978","72.6639"
"22.9600","5.7174","306.2428","5.7174","3.8116","72.9150"
"23.0400","5.7384","307.3338","5.7384","3.8256","73.1747"
"23.1200","5.7574","308.2538","5.7574","3.8382","73.3938"
"23.2000","5.7775","309.2683","5.7775","3.8516","73.6353"
"23.2800","5.7966","310.1830","5.7966","3.8644","73.8531"
"23.3600","5.8174","311.2654","5.8174","3.8783","74.1108"
"23.4400","5.8370","312.2233","5.8370","3.8914","74.3389"
"23.5200","5.8560","313.1463","5.8560","3.9040","74.5586"
"23.6000","5.8766","314.1971","5.8766","3.9177","74.8088"
"23.6800","5.8978","315.2876","5.8978","3.9319","75.0685"
"23.7600","5.9178","316.2771","5.9178","3.9452","75.3041"
"23.8400","5.9372","317.2286","5.9372","3.9581","75.5306"
"23.9200","5.9562","318.1350","5.9562","3.9708","75.7464"
"24.0000","5.9769","319.1918","5.9769","3.9846","75.9981"
"24.0800","5.9973","320.2032","5.9973","3.9982","76.2389"
"24.1600","6.0166","321.1613","6.0166","4.0111","76.4670"
"24.2400","6.0375","322.2126","6.0375","4.0250","76.7173"
"24.3200","6.0572","323.1560","6.0572","4.0381","76.9419"
"24.4000","6.0782","324.2165","6.0782","4.0521","77.1944"
"24.4800","6.0977","325.1858","6.0977","4.0652","77.4252"
"24.5600","6.1163","326.0552","6.1163","4.0776","77.6322"
"24.6400","6.1366","327.0574","6.1366","4.0911","77.8708"
"24.7200","6.1563","327.9948","6.1563","4.1042","78.0940"
"24.8000","6.1767","329.0166","6.1767","4.1178","78.3373"
"24.8800","6.1981","330.0862","6.1981","4.1320","78.5920"
"24.9600","6.2172","330.9633","6.2172","4.1448","78.8008"
"25.0400","6.2378","331.9772","6.2378","4.1585","79.0422"
"25.1200","6.2567","332.8494","6.2567","4.1711","79.2499"
"25.2000","6.2761","333.7889","6.2761","4.1840","79.4735"
"25.2800","6.2967","334.8196","6.2967","4.1978","79.7190"
"25.3600","6.3167","335.7606","6.3167","4.2112","79.9430"
"25.4400","6.3372","336.7440","6.3372","4.2248","80.1772"
"25.5200","6.3579","337.7711","6.3579","4.2386","80.4217"
"25.6000","6.3775","338.6749","6.3775","4.2516","80.6369"
"25.6800","6.3977","339.6441","6.3977","4.2651","80.8676"
"25.7600","6.4172","340.5563","6.4172","4.2781","81.0848"
"25.8400","6.4364","341.4731","6.4364","4.2909","81.3031"
"25.9200","6.4568","342.4585","6.4568","4.3045","81.5377"
"26.0000","6.4758","343.3269","6.4758","4.3172","81.7445"
"26.0800","6.4975","344.4313","6.4975","4.3317","82.0075"
"26.1600","6.5179","345.4078","6.5179","4.3452","82.2399"
"26.2400","6.5375","346.3128","6.5375","4.3583","82.4554"
"26.3200","6.5572","347.2502","6.5572","4.3715","82.6786"
"26.4000","6.5767","348.1459","6.5767","4.3845","82.8919"
"26.4800","6.5970","349.1516","6.5970","4.3980","83.1313"
"26.5600","6.6174","350.1208","6.6174","4.4116","83.3621"
"26.6400","6.6359","350.9445","6.6359","4.4239","83.5582"
"26.7200","6.6573","352.0097","6.6573","4.4382","83.8118"
"26.8000","6.6779","352.9920","6.6779","4.4519","84.0457"
"26.8800","6.6986","353.9809","6.6986","4.4657","84.2812"
"26.9600","6.7172","354.8027","6.7172","4.4782","84.4768"
"27.0400","6.7363","355.6472","6.7363","4.4909","84.6779"
"27.1200","6.7563","356.5870","6.7563","4.5042","84.9017"
"27.2000","6.7770","357.5677","6.7770","4.5180","85.1352"
"27.2800","6.7963","358.4485","6.7963","4.5308","85.3449"
"27.3600","6.8174","359.4659","6.8174","4.5449","85.5871"
"27.4400","6.8371","360.3561","6.8371","4.5581","85.7991"
"27.5200","6.8575","361.3187","6.8575","4.5717","86.0283"
"27.6000","6.8771","362.2072","6.8771","4.5848","86.2398"
"27.6800","6.8965","363.0753","6.8965","4.5976","86.4465"
"27.7600","6.9166","364.0090","6.9166","4.6110","86.6688"
"27.8400","6.9367","364.9447","6.9367","4.6245","86.8916"
"27.9200","6.9568","365.8629","6.9568","4.6378","87.1102"
"28.0000","6.9777","366.8705","6.9777","4.6518","87.3501"
"28.0800","6.9979","367.7795","6.9979","4.6653","87.5665"
"28.1600","7.0179","368.6879","7.0179","4.6786","87.7828"
"28.2400","7.0375","369.5412","7.0375","4.6916","87.9860"
"28.3200","7.0562","370.3740","7.0562","4.7041","88.1843"
"28.4000","7.0770","371.3564","7.0770","4.7180","88.4182"
"28.4800","7.0962","372.1780","7.0962","4.7308","88.6138"
"28.5600","7.1174","373.1883","7.1174","4.7449","88.8544"
"28.6400","7.1372","374.0719","7.1372","4.7581","89.0647"
"28.7200","7.1571","374.9579","7.1571","4.7714","89.2757"
"28.8000","7.1771","375.8636","7.1771","4.7848","89.4913"
"28.8800","7.1973","376.7718","7.1973","4.7982","89.7076"
"28.9600","7.2164","377.6104","7.2164","4.8109","89.9072"
"29.0400","7.2370","378.5530","7.2370","4.8247","90.1317"
"29.1200","7.2558","379.3436","7.2558","4.8372","90.3199"
"29.2000","7.2776","380.4004","7.2776","4.8517","90.5715"
"29.2800","7.2981","381.2991","7.2981","4.8654","90.7855"
"29.3600","7.3173","382.1391","7.3173","4.8782","90.9855"
"29.4400","7.3372","383.0109","7.3372","4.8915","91.1931"
"29.5200","7.3568","383.8514","7.3568","4.9045","91.3932"
"29.6000","7.3769","384.7522","7.3769","4.9179","91.6077"
"29.6800","7.3976","385.6949","7.3976","4.9317","91.8321"
"29.7600","7.4165","386.4763","7.4165","4.9444","92.0182"
"29.8400","7.4369","387.3821","7.4369","4.9580","92.2338"
"29.9200","7.4573","388.2691","7.4573","4.9715","92.4450"
"30.0000","7.4774","389.1608","7.4774","4.9849","92.6573"
"30.0800","7.4976","390.0346","7.4976","4.9984","92.8654"
"30.1600","7.5167","390.8620","7.5167","5.0112","93.0624"
"30.2400","7.5371","391.7463","7.5371","5.0248","93.2729"
"30.3200","7.5568","392.5708","7.5568","5.0379","93.4692"
"30.4000","7.5765","393.4192","7.5765","5.0510","93.6712"
"30.4800","7.5974","394.3514","7.5974","5.0649","93.8932"
"30.5600","7.6181","395.2359","7.6181","5.0787","94.1038"
"30.6400","7.6380","396.0817","7.6380","5.0920","94.3052"
"30.7200","7.6576","396.8833","7.6576","5.1051","94.4960"
"30.8000","7.6761","397.6134","7.6761","5.1174","94.6699"
"30.8800","7.6973","398.5662","7.6973","5.1316","94.8967"
"30.9600","7.7165","399.3359","7.7165","5.1443","95.0800"
"31.0400","7.7365","400.2004","7.7365","5.1577","95.2858"
"31.1200","7.7567","401.0549","7.7567","5.1711","95.4893"
"31.2000","7.7774","401.9498","7.7774","5.1850","95.7023"
"31.2800","7.7978","402.8101","7.7978","5.1986","95.9072"
"31.3600","7.8177","403.6255","7.8177","5.2118","96.1013"
"31.4400","7.8364","404.3692","7.8364","5.2243","96.2784"
"31.5200","7.8567","405.2244","7.8567","5.2378","96.4820"
"31.6000","7.8762","406.0082","7.8762","5.2508","96.6686"
"31.6800","7.8974","406.9662","7.8974","5.2649","96.8967"
"31.7600","7.9183","407.8553","7.9183","5.2789","97.1084"
"31.8400","7.9372","408.5812","7.9372","5.2915","97.2812"
"31.9200","7.9573","409.4002","7.9573","5.3048","97.4762"
"32.0000","7.9771","410.2171","7.9771","5.3181","97.6707"
"32.0800","7.9970","411.0381","7.9970","5.3313","97.8662"
"32.1600","8.0169","411.8604","8.0169","5.3446","98.0620"
"32.2400","8.0361","412.5973","8.0361","5.3574","98.2375"
"32.3200","8.0568","413.4868","8.0568","5.3712","98.4492"
"32.4000","8.0781","414.3926","8.0781","5.3854","98.6649"
"32.4800","8.0972","415.1407","8.0972","5.3982","98.8430"
"32.5600","8.1176","415.9702","8.1176","5.4117","99.0405"
"32.6400","8.1362","416.6709","8.1362","5.4242","99.2074"
"32.7200","8.1564","417.4927","8.1564","5.4376","99.4030"
"32.8000","8.1764","418.3235","8.1764","5.4510","99.6008"
"32.8800","8.1966","419.1245","8.1966","5.4644","99.7915"
"32.9600","8.2173","419.9665","8.2173","5.4782","99.9920"
"33.0400","8.2382","420.8276","8.2382","5.4921","100.1970"
"33.1200","8.2573","421.5520","8.2573","5.5049","100.3695"
"33.2000","8.2772","422.3378","8.2772","5.5181","100.5566"
"33.2800","8.2966","423.0632","8.2966","5.5311","100.7293"
"33.3600","8.3176","423.9466","8.3176","5.5451","100.9397"
"33.4400","8.3368","424.6578","8.3368","5.5579","101.1090"
"33.5200","8.3560","425.4017","8.3560","5.5707","101.2861"
"33.6000","8.3766","426.2163","8.3766","5.5844","101.4801"
"33.6800","8.3980","427.1141","8.3980","5.5987","101.6938"
"33.7600","8.4182","427.8892","8.4182","5.6122","101.8784"
"33.8400","8.4373","428.5987","8.4373","5.6249","102.0473"
"33.9200","8.4558","429.2504","8.4558","5.6372","102.2025"
"34.0000","8.4765","430.1021","8.4765","5.6510","102.4053"
"34.0800","8.4971","430.9200","8.4971","5.6647","102.6000"
"34.1600","8.5167","431.6653","8.5167","5.6778","102.7774"
"34.2400","8.5374","432.5065","8.5374","5.6916","102.9777"
"34.3200","8.5576","433.2725","8.5576","5.7051","103.1601"
"34.4000","8.5779","434.0489","8.5779","5.7186","103.3450"
"34.4800","8.5975","434.7965","8.5975","5.7317","103.5230"
"34.5600","8.6168","435.4904","8.6168","5.7445","103.6882"
"34.6400","8.6366","436.2463","8.6366","5.7577","103.8682"
"34.7200","8.6563","436.9785","8.6563","5.7709","104.0425"
"34.8000","8.6765","437.7913","8.6765","5.7843","104.2360"
"34.8800","8.6979","438.6476","8.6979","5.7986","104.4399"
"34.9600","8.7171","439.3153","8.7171","5.8114","104.5989"
"35.0400","8.7379","440.1272","8.7379","5.8252","104.7922"
"35.1200","8.7566","440.7684","8.7566","5.8377","104.9449"
"35.2000","8.7764","441.5274","8.7764","5.8510","105.1256"
"35.2800","8.7968","442.3040","8.7968","5.8645","105.3105"
"35.3600","8.8164","443.0094","8.8164","5.8776","105.4784"
"35.4400","8.8371","443.8089","8.8371","5.8914","105.6688"
"35.5200","8.8583","444.6453","8.8583","5.9055","105.8679"
"35.6000","8.8776","445.3293","8.8776","5.9184","106.0308"
"35.6800","8.8979","446.0945","8.8979","5.9320","106.2130"
"35.7600","8.9171","446.7474","8.9171","5.9447","106.3684"
"35.8400","8.9366","447.4571","8.9366","5.9577","106.5374"
"35.9200","8.9567","448.1945","8.9567","5.9711","106.7130"
"36.0000","8.9755","448.8601","8.9755","5.9837","106.8715"
"36.0800","8.9974","449.7390","8.9974","5.9982","107.0807"
"36.1600","9.0178","450.4995","9.0178","6.0118","107.2618"
"36.2400","9.0373","451.1890","9.0373","6.0249","107.4260"
"36.3200","9.0569","451.8898","9.0569","6.0379","107.5928"
"36.4000","9.0768","452.5965","9.0768","6.0512","107.7611"
"36.4800","9.0966","453.3244","9.0966","6.0644","107.9344"
"36.5600","9.1173","454.1039","9.1173","6.0782","108.1200"
"36.6400","9.1361","454.7322","9.1361","6.0907","108.2696"
"36.7200","9.1574","455.5572","9.1574","6.1049","108.4660"
"36.8000","9.1781","456.3623","9.1781","6.1187","108.6577"
"36.8800","9.1986","457.1042","9.1986","6.1324","108.8343"
"36.9600","9.2170","457.6927","9.2170","6.1447","108.9744"
"37.0400","9.2367","458.3708","9.2367","6.1578","109.1359"
"37.1200","9.2569","459.0948","9.2569","6.1712","109.3083"
"37.2000","9.2772","459.8333","9.2772","6.1848","109.4841"
"37.2800","9.2958","460.4496","9.2958","6.1972","109.6309"
"37.3600","9.3173","461.2723","9.3173","6.2115","109.8268"
"37.4400","9.3371","461.9477","9.3371","6.2247","109.9875"
"37.5200","9.3577","462.7046","9.3577","6.2384","110.1677"
"37.6000","9.3772","463.3570","9.3772","6.2515","110.3231"
"37.6800","9.3962","463.9902","9.3962","6.2641","110.4739"
"37.7600","9.4168","464.7337","9.4168","6.2779","110.6509"
"37.8400","9.4367","465.4267","9.4367","6.2911","110.8159"
"37.9200","9.4566","466.1292","9.4566","6.3044","110.9832"
"38.0000","9.4774","466.8876","9.4774","6.3183","111.1637"
"38.0800","9.4980","467.5975","9.4980","6.3320","111.3327"
"38.1600","9.5180","468.2797","9.5180","6.3454","111.4952"
"38.2400","9.5374","468.9109","9.5374","6.3582","111.6455"
"38.3200","9.5561","469.5274","9.5561","6.3708","111.7922"
"38.4000","9.5771","470.2719","9.5771","6.3847","111.9695"
"38.4800","9.5959","470.8666","9.5959","6.3973","112.1111"
"38.5600","9.6174","471.6741","9.6174","6.4116","112.3034"
"38.6400","9.6374","472.3342","9.6374","6.4249","112.4605"
"38.7200","9.6571","472.9851","9.6571","6.4381","112.6155"
"38.8000","9.6768","473.6322","9.6768","6.4512","112.7696"
"38.8800","9.6977","474.3684","9.6977","6.4651","112.9449"
"38.9600","9.7165","474.9501","9.7165","6.4777","113.0834"
"39.0400","9.7367","475.6408","9.7367","6.4912","113.2478"
"39.1200","9.7557","476.2287","9.7557","6.5038","113.3878"
"39.2000","9.7775","477.0424","9.7775","6.5183","113.5815"
"39.2800","9.7984","477.7566","9.7984","6.5322","113.7516"
"39.3600","9.8179","478.3868","9.8179","6.5453","113.9016"
"39.4400","9.8365","478.9259","9.8365","6.5577","114.0300"
"39.5200","9.8566","479.6003","9.8566","6.5711","114.1905"
"39.6000","9.8771","480.3043","9.8771","6.5847","114.3582"
"39.6800","9.8974","480.9839","9.8974","6.5983","114.5200"
"39.7600","9.9162","481.5196","9.9162","6.6108","114.6475"
"39.8400","9.9368","482.2372","9.9368","6.6245","114.8184"
"39.9200","9.9576","482.9308","9.9576","6.6384","114.9835"
"40.0000","9.9773","483.5722","9.9773","6.6515","115.1362"
"40.0800","9.9977","484.2392","9.9977","6.6651","115.2950"
"40.1600","10.0166","484.7972","10.0166","6.6777","115.4279"
"40.2400","10.0374","485.4921","10.0374","6.6916","115.5934"
"40.3200","10.0567","486.0725","10.0567","6.7045","115.7316"
"40.4000","10.0766","486.7120","10.0766","6.7177","115.8838"
"40.4800","10.0974","487.3977","10.0974","6.7316","116.0471"
"40.5600","10.1181","488.0624","10.1181","6.7454","116.2053"
"40.6400","10.1374","488.6462","10.1374","6.7583","116.3443"
"40.7200","10.1575","489.2728","10.1575","6.7717","116.4935"
"40.8000","10.1763","489.7928","10.1763","6.7842","116.6173"
"40.8800","10.1972","490.4838","10.1972","6.7982","116.7818"
"40.9600","10.2166","491.0463","10.2166","6.8111","116.9158"
"41.0400","10.2365","491.6768","10.2365","6.8243","117.0659"
"41.1200","10.2566","492.3105","10.2566","6.8377","117.2168"
"41.2000","10.2774","492.9680","10.2774","6.8516","117.3733"
"41.2800","10.2978","493.6182","10.2978","6.8652","117.5281"
"41.3600","10.3182","494.2690","10.3182","6.8788","117.6831"
"41.4400","10.3363","494.7330","10.3363","6.8909","117.7936"
"41.5200","10.3563","495.3524","10.3563","6.9042","117.9411"
"41.6000","10.3763","495.9544","10.3763","6.9176","118.0844"
"41.6800","10.3973","496.6544","10.3973","6.9316","118.2510"
"41.7600","10.4175","497.2562","10.4175","6.9450","118.3943"
"41.8400","10.4375","497.8535","10.4375","6.9583","118.5366"
"41.9200","10.4577","498.4493","10.4577","6.9718","118.6784"
"42.0000","10.4774","499.0159","10.4774","6.9849","118.8133"
"42.0800","10.4969","499.6014","10.4969","6.9979","118.9527"
"42.1600","10.5168","500.1947","10.5168","7.0112","119.0940"
"42.2400","10.5361","500.7125","10.5361","7.0241","119.2173"
"42.3200","10.5566","501.3397","10.5566","7.0377","119.3666"
"42.4000","10.5781","502.0357","10.5781","7.0521","119.5323"
"42.4800","10.5975","502.5719","10.5975","7.0650","119.6600"
"42.5600","10.6176","503.1445","10.6176","7.0784","119.7963"
"42.6400","10.6364","503.6284","10.6364","7.0909","119.9115"
"42.7200","10.6566","504.2391","10.6566","7.1044","120.0569"
"42.8000","10.6765","504.8186","10.6765","7.1177","120.1949"
"42.8800","10.6970","505.4372","10.6970","7.1313","120.3422"
"42.9600","10.7176","506.0484","10.7176","7.1451","120.4877"
"43.0400","10.7383","506.6356","10.7383","7.1589","120.6275"
"43.1200","10.7573","507.1227","10.7573","7.1715","120.7435"
"43.2000","10.7773","507.6898","10.7773","7.1849","120.8785"
"43.2800","10.7967","508.1801","10.7967","7.1978","120.9953"
"43.3600","10.8172","508.7976","10.8172","7.2115","121.1423"
"43.4400","10.8370","509.3170","10.8370","7.2246","121.2659"
"43.5200","10.8559","509.8034","10.8559","7.2373","121.3818"
"43.6000","10.8770","510.4233","10.8770","7.2513","121.5294"
"43.6800","10.8977","511.0124","10.8977","7.2651","121.6696"
"43.7600","10.9174","511.5259","10.9174","7.2782","121.7919"
"43.8400","10.9374","512.0745","10.9374","7.2916","121.9225"
"43.9200","10.9562","512.4973","10.9562","7.3041","122.0232"
"44.0000","10.9764","513.0659","10.9764","7.3176","122.1585"
"44.0800","10.9972","513.6473","10.9972","7.3314","122.2970"
"44.1600","11.0171","514.1788","11.0171","7.3447","122.4235"
"44.2400","11.0373","514.6995","11.0373","7.3582","122.5475"
"44.3200","11.0567","515.1674","11.0567","7.3711","122.6589"
"44.4000","11.0775","515.7527","11.0775","7.3850","122.7983"
"44.4800","11.0978","516.2982","11.0978","7.3986","122.9281"
"44.5600","11.1171","516.7413","11.1171","7.4114","123.0337"
"44.6400","11.1366","517.2604","11.1366","7.4244","123.1572"
"44.7200","11.1567","517.7626","11.1567","7.4378","123.2768"
"44.8000","11.1762","518.2691","11.1762","7.4508","123.3974"
"44.8800","11.1980","518.9034","11.1980","7.4653","123.5484"
"44.9600","11.2175","519.3393","11.2175","7.4783","123.6522"
"45.0400","11.2378","519.8519","11.2378","7.4918","123.7743"
"45.1200","11.2568","520.2771","11.2568","7.5045","123.8755"
"45.2000","11.2765","520.7728","11.2765","7.5177","123.9935"
"45.2800","11.2967","521.2867","11.2967","7.5311","124.1159"
"45.3600","11.3167","521.7558","11.3167","7.5445","124.2276"
"45.4400","11.3371","522.2891","11.3371","7.5581","124.3546"
"45.5200","11.3582","522.8543","11.3582","7.5721","124.4891"
"45.6000","11.3774","523.2719","11.3774","7.5849","124.5885"
"45.6800","11.3977","523.7704","11.3977","7.5985","124.7073"
"45.7600","11.4171","524.1827","11.4171","7.6114","124.8054"
"45.8400","11.4369","524.6785","11.4369","7.6246","124.9234"
"45.9200","11.4566","525.1305","11.4566","7.6377","125.0311"
"46.0000","11.4758","525.5542","11.4758","7.6506","125.1319"
"46.0800","11.4974","526.1255","11.4974","7.6649","125.2680"
"46.1600","11.5180","526.6340","11.5180","7.6786","125.3890"
"46.2400","11.5372","527.0317","11.5372","7.6915","125.4837"
"46.3200","11.5568","527.4697","11.5568","7.7045","125.5880"
"46.4000","11.5767","527.9078","11.5767","7.7178","125.6923"
"46.4800","11.5967","528.3901","11.5967","7.7312","125.8072"
"46.5600","11.6173","528.8824","11.6173","7.7449","125.9244"
"46.6400","11.6359","529.2424","11.6359","7.7572","126.0101"
"46.7200","11.6574","529.7899","11.6574","7.7716","126.1405"
"46.8000","11.6774","530.2429","11.6774","7.7850","126.2483"
"46.8800","11.6981","530.7477","11.6981","7.7988","126.3685"
"46.9600","11.7176","531.1499","11.7176","7.8118","126.4643"
"47.0400","11.7368","531.5109","11.7368","7.8245","126.5502"
"47.1200","11.7567","531.9487","11.7567","7.8378","126.6544"
"47.2000","11.7770","532.3995","11.7770","7.8514","126.7618"
"47.2800","11.7961","532.7832","11.7961","7.8641","126.8531"
"47.3600","11.8173","533.3088","11.8173","7.8782","126.9783"
"47.4400","11.8374","533.7206","11.8374","7.8916","127.0763"
"47.5200","11.8577","534.1669","11.8577","7.9051","127.1826"
"47.6000","11.8772","534.5553","11.8772","7.9181","127.2751"
"47.6800","11.8967","534.9525","11.8967","7.9311","127.3696"
"47.7600","11.9167","535.3583","11.9167","7.9445","127.4663"
"47.8400","11.9367","535.7838","11.9367","7.9578","127.5676"
"47.9200","11.9569","536.2101","11.9569","7.9713","127.6691"
"48.0000","11.9778","536.6967","11.9778","7.9852","127.7849"
"48.0800","11.9979","537.0815","11.9979","7.9986","127.8766"
"48.1600","12.0178","537.4771","12.0178","8.0119","127.9707"
"48.2400","12.0376","537.8674","12.0376","8.0251","128.0637"
"48.3200","12.0563","538.2006","12.0563","8.0376","128.1430"
"48.4000","12.0772","538.6456","12.0772","8.0514","128.2489"
"48.4800","12.0961","538.9629","12.0961","8.0640","128.3245"
"48.5600","12.1174","539.4650","12.1174","8.0782","128.4440"
"48.6400","12.1377","539.8705","12.1377","8.0918","128.5406"
"48.7200","12.1574","540.2358","12.1574","8.1049","128.6276"
"48.8000","12.1771","540.5850","12.1771","8.1181","128.7107"
"48.8800","12.1976","541.0096","12.1976","8.1317","128.8118"
"48.9600","12.2162","541.3007","12.2162","8.1441","128.8811"
"49.0400","12.2365","541.7150","12.2365","8.1577","128.9798"
"49.1200","12.2560","542.0518","12.2560","8.1706","129.0600"
"49.2000","12.2778","542.5509","12.2778","8.1852","129.1788"
"49.2800","12.2982","542.9202","12.2982","8.1988","129.2667"
"49.3600","12.3180","543.2853","12.3180","8.2120","129.3537"
"49.4400","12.3370","543.5609","12.3370","8.2247","129.4193"
"49.5200","12.3568","543.9249","12.3568","8.2378","129.5059"
"49.6000","12.3768","544.2825","12.3768","8.2512","129.5911"
"49.6800","12.3971","544.6636","12.3971","8.2647","129.6818"
"49.7600","12.4158","544.9276","12.4158","8.2772","129.7446"
"49.8400","12.4367","545.3476","12.4367","8.2911","129.8447"
"49.9200","12.4578","545.7455","12.4578","8.3052","129.9394"
"50.0000","12.4777","546.0844","12.4777","8.3185","130.0201"
"50.0800","12.4974","546.3960","12.4974","8.3316","130.0943"
"50.1600","12.5166","546.6590","12.5166","8.3444","130.1569"
"50.2400","12.5370","547.0244","12.5370","8.3580","130.2439"
"50.3200","12.5566","547.3393","12.5566","8.3710","130.3189"
"50.4000","12.5768","547.6895","12.5768","8.3845","130.4023"
"50.4800","12.5975","548.0851","12.5975","8.3983","130.4965"
"50.5600","12.6181","548.4052","12.6181","8.4121","130.5727"
"50.6400","12.6374","548.6780","12.6374","8.4249","130.6376"
"50.7200","12.6575","549.0034","12.6575","8.4383","130.7151"
"50.8000","12.6763","549.2264","12.6763","8.4509","130.7682"
"50.8800","12.6974","549.6057","12.6974","8.4650","130.8585"
"50.9600","12.7166","549.8387","12.7166","8.4777","130.9140"
"51.0400","12.7365","550.1505","12.7365","8.4910","130.9882"
"51.1200","12.7567","550.4544","12.7567","8.5045","131.0606"
"51.2000","12.7776","550.7853","12.7776","8.5184","131.1394"
"51.2800","12.7978","551.0724","12.7978","8.5318","131.2077"
"51.3600","12.8178","551.3450","12.8178","8.5452","131.2726"
"51.4400","12.8361","551.5054","12.8361","8.5574","131.3108"
"51.5200","12.8565","551.8021","12.8565","8.5710","131.3814"
"51.6000","12.8764","552.0538","12.8764","8.5843","131.4414"
"51.6800","12.8973","552.3830","12.8973","8.5982","131.5198"
"51.7600","12.9183","552.6864","12.9183","8.6122","131.5920"
"51.8400","12.9376","552.8698","12.9376","8.6251","131.6357"
"51.9200","12.9577","553.1132","12.9577","8.6385","131.6936"
"52.0000","12.9772","553.3174","12.9772","8.6515","131.7423"
"52.0800","12.9969","553.5450","12.9969","8.6646","131.7964"
"52.1600","13.0170","553.7812","13.0170","8.6780","131.8527"
"52.2400","13.0361","553.9370","13.0361","8.6907","131.8897"
"52.3200","13.0569","554.2296","13.0569","8.7046","131.9594"
"52.4000","13.0779","554.4859","13.0779","8.7186","132.0205"
"52.4800","13.0975","554.6627","13.0975","8.7317","132.0625"
"52.5600","13.1176","554.8382","13.1176","8.7451","132.1043"
"52.6400","13.1364","554.9397","13.1364","8.7576","132.1285"
"52.7200","13.1565","555.1448","13.1565","8.7710","132.1773"
"52.8000","13.1762","555.3256","13.1762","8.7841","132.2204"
"52.8800","13.1968","555.5364","13.1968","8.7979","132.2706"
"52.9600","13.2177","555.7436","13.2177","8.8118","132.3199"
"53.0400","13.2384","555.9420","13.2384","8.8256","132.3671"
"53.1200","13.2568","556.0067","13.2568","8.8379","132.3825"
"53.2000","13.2771","556.2208","13.2771","8.8514","132.4335"
"53.2800","13.2968","556.3321","13.2968","8.8645","132.4600"
"53.3600","13.3175","556.5394","13.3175","8.8784","132.5094"
"53.4400","13.3371","556.6628","13.3371","8.8914","132.5388"
"53.5200","13.3560","556.7614","13.3560","8.9040","132.5622"
"53.6000","13.3769","556.9379","13.3769","8.9179","132.6043"
"53.6800","13.3979","557.1333","13.3979","8.9319","132.6508"
"53.7600","13.4178","557.2293","13.4178","8.9452","132.6737"
"53.8400","13.4375","557.3220","13.4375","8.9583","132.6957"
"53.9200","13.4563","557.3398","13.4563","8.9709","132.7000"
"54.0000","13.4766","557.4755","13.4766","8.9844","132.7323"
"54.0800","13.4972","557.6173","13.4972","8.9981","132.7660"
"54.1600","13.5170","557.7244","13.5170","9.0114","132.7915"
"54.2400","13.5377","557.8546","13.5377","9.0251","132.8225"
"54.3200","13.5572","557.8975","13.5572","9.0381","132.8327"
"54.4000","13.5782","558.0302","13.5782","9.0521","132.8643"
"54.4800","13.5977","558.0700","13.5977","9.0651","132.8738"
"54.5600","13.6171","558.1094","13.6171","9.0781","132.8832"
"54.6400","13.6368","558.1744","13.6368","9.0912","132.8987"
"54.7200","13.6564","558.2087","13.6564","9.1043","132.9068"
"54.8000","13.6763","558.2953","13.6763","9.1175","132.9274"
"54.8800","13.6977","558.4642","13.6977","9.1318","132.9677"
"54.9600","13.7173","558.4972","13.7173","9.1449","132.9755"
"55.0400","13.7376","558.5497","13.7376","9.1584","132.9880"
"55.1200","13.7567","558.5591","13.7567","9.1711","132.9903"
"55.2000","13.7765","558.6485","13.7765","9.1844","133.0115"
"55.2800","13.7965","558.6926","13.7965","9.1977","133.0220"
"55.3600","13.8167","558.7566","13.8167","9.2111","133.0373"
"55.4400","13.8366","558.8100","13.8366","9.2244","133.0500"
"55.5200","13.8582","558.9391","13.8582","9.2388","133.0807"
"55.6000","13.8775","558.9128","13.8775","9.2517","133.0745"
"55.6800","13.8978","558.9518","13.8978","9.2652","133.0838"
"55.7600","13.9175","558.9306","13.9175","9.2783","133.0787"
"55.8400","13.9369","558.9185","13.9369","9.2913","133.0758"
"55.9200","13.9566","558.8859","13.9566","9.3044","133.0681"
"56.0000","13.9758","558.8355","13.9758","9.3172","133.0561"
"56.0800","13.9972","558.8991","13.9972","9.3315","133.0712"
"56.1600","14.0182","558.9495","14.0182","9.3455","133.0832"
"56.2400","14.0376","558.8625","14.0376","9.3584","133.0625"
"56.3200","14.0568","558.7789","14.0568","9.3712","133.0426"
"56.4000","14.0767","558.7235","14.0767","9.3845","133.0294"
"56.4800","14.0969","558.7128","14.0969","9.3979","133.0269"
"56.5600","14.1172","558.6965","14.1172","9.4115","133.0230"
"56.6400","14.1360","558.6068","14.1360","9.4240","133.0016"
"56.7200","14.1573","558.6251","14.1573","9.4382","133.0060"
"56.8000","14.1778","558.5555","14.1778","9.4519","132.9894"
"56.8800","14.1983","558.5377","14.1983","9.4656","132.9852"
"56.9600","14.2173","558.4395","14.2173","9.4782","132.9618"
"57.0400","14.2369","558.3708","14.2369","9.4913","132.9454"
"57.1200","14.2566","558.3074","14.2566","9.5044","132.9303"
"57.2000","14.2768","558.2675","14.2768","9.5179","132.9208"
"57.2800","14.2960","558.1555","14.2960","9.5307","132.8942"
"57.3600","14.3171","558.1047","14.3171","9.5448","132.8821"
"57.4400","14.3371","557.9736","14.3371","9.5581","132.8509"
"57.5200","14.3575","557.8745","14.3575","9.5717","132.8273"
"57.6000","14.3772","557.7062","14.3772","9.5848","132.7872"
"57.6800","14.3965","557.5386","14.3965","9.5977","132.7473"
"57.7600","14.4168","557.3823","14.4168","9.6112","132.7101"
"57.8400","14.4361","557.1929","14.4361","9.6240","132.6650"
"57.9200","14.4566","557.0948","14.4566","9.6378","132.6416"
"58.0000","14.4780","556.9213","14.4780","9.6520","132.6003"
"58.0800","14.4980","556.6926","14.4980","9.6653","132.5459"
"58.1600","14.5178","556.5342","14.5178","9.6785","132.5081"
"58.2400","14.5375","556.3474","14.5375","9.6916","132.4636"
"58.3200","14.5563","556.1686","14.5563","9.7042","132.4211"
"58.4000","14.5767","556.0670","14.5767","9.7178","132.3969"
"58.4800","14.5961","555.8913","14.5961","9.7307","132.3551"
"58.5600","14.6173","555.8397","14.6173","9.7449","132.3428"
"58.6400","14.6377","555.7243","14.6377","9.7585","132.3153"
"58.7200","14.6572","555.5502","14.6572","9.7715","132.2739"
"58.8000","14.6773","555.3940","14.6773","9.7849","132.2367"
"58.8800","14.6972","555.2195","14.6972","9.7981","132.1951"
"58.9600","14.7169","555.0533","14.7169","9.8113","132.1556"
"59.0400","14.7365","554.8597","14.7365","9.8243","132.1095"
"59.1200","14.7558","554.6500","14.7558","9.8372","132.0595"
"59.2000","14.7776","554.5656","14.7776","9.8518","132.0394"
"59.2800","14.7984","554.3965","14.7984","9.8656","131.9992"
"59.3600","14.8178","554.1469","14.8178","9.8785","131.9397"
"59.4400","14.8370","553.7558","14.8370","9.8914","131.8466"
"59.5200","14.8571","553.4665","14.8571","9.9047","131.7777"
"59.6000","14.8771","553.1797","14.8771","9.9181","131.7095"
"59.6800","14.8970","552.9059","14.8970","9.9314","131.6443"
"59.7600","14.9163","552.6187","14.9163","9.9442","131.5759"
"59.8400","14.9368","552.4332","14.9368","9.9579","131.5317"
"59.9200","14.9575","552.2340","14.9575","9.9717","131.4843"
"60.0000","14.9775","552.0272","14.9775","9.9850","131.4350"
"60.0800","14.9975","551.8276","14.9975","9.9983","131.3875"
"60.0900","15.0001","551.8084","15.0001","10.0000","131.3830"