File: data/instron_tests/metamaterials/250331/250331_2246_BULK_m1.is_comp_Exports/250331_2246_BULK_m1_2_1.csv
Results Table 1
,Compresson Axis,H*,V*,Height,Thickness,Width,Area,Fixture separation,Specimen label
,,,,(mm),(mm),(mm),(mm^2),(mm),
"2","Y","","","150.00","28.00","150.00","4200.00","150.00","2046_BULK_m1"

Results Table 2
,Modulus (Segment 0 % - 5 %),Compresson Axis
,(kPa),
"2","1526.17","Y"

Time,Displacement,Force,Compressive displacement,Compressive strain (Displacement),Compressive stress
(s),(mm),(N),(mm),(%),(kPa)
"0.0000","0.0000","0.2285","0.0000","0.0000","0.0544"
"0.0800","0.0012","0.2961","0.0012","0.0008","0.0705"
"0.1600","0.0171","1.2713","0.0171","0.0114","0.3027"
"0.2400","0.0375","2.4414","0.0375","0.0250","0.5813"
"0.3200","0.0575","3.5525","0.0575","0.0384","0.8458"
"0.4000","0.0767","4.5896","0.0767","0.0511","1.0928"
"0.4800","0.0979","5.7372","0.0979","0.0653","1.3660"
"0.5600","0.1179","6.7661","0.1179","0.0786","1.6110"
"0.6400","0.1378","7.7963","0.1378","0.0918","1.8563"
"0.7200","0.1573","8.8081","0.1573","0.1049","2.0972"
"0.8000","0.1762","9.7549","0.1762","0.1174","2.3226"
"0.8800","0.1971","10.8271","0.1971","0.1314","2.5779"
"0.9600","0.2172","11.8259","0.2172","0.1448","2.8157"
"1.0400","0.2360","12.7386","0.2360","0.1573","3.0330"
"1.1200","0.2571","13.8212","0.2571","0.1714","3.2908"
"1.2000","0.2770","14.7061","0.2770","0.1847","3.5015"
"1.2800","0.2980","15.7417","0.2980","0.1987","3.7480"
"1.3600","0.3178","16.7049","0.3178","0.2118","3.9774"
"1.4400","0.3360","17.5774","0.3360","0.2240","4.1851"
"1.5200","0.3563","18.5745","0.3563","0.2376","4.4225"
"1.6000","0.3764","19.5245","0.3764","0.2509","4.6487"
"1.6800","0.3971","20.5383","0.3971","0.2647","4.8901"
"1.7600","0.4184","21.5740","0.4184","0.2790","5.1367"
"1.8400","0.4373","22.4472","0.4373","0.2915","5.3446"
"1.9200","0.4573","23.3940","0.4573","0.3049","5.5700"
"2.0000","0.4770","24.3232","0.4770","0.3180","5.7912"
"2.0800","0.4968","25.2757","0.4968","0.3312","6.0180"
"2.1600","0.5168","26.2245","0.5168","0.3445","6.2439"
"2.2400","0.5361","27.1300","0.5361","0.3574","6.4595"
"2.3200","0.5566","28.1163","0.5566","0.3710","6.6943"
"2.4000","0.5780","29.1451","0.5780","0.3853","6.9393"
"2.4800","0.5973","30.0436","0.5973","0.3982","7.1532"
"2.5600","0.6176","30.9980","0.6176","0.4117","7.3805"
"2.6400","0.6364","31.8684","0.6364","0.4243","7.5877"
"2.7200","0.6559","32.7863","0.6559","0.4373","7.8063"
"2.8000","0.6768","33.7907","0.6768","0.4512","8.0454"
"2.8800","0.6966","34.7223","0.6966","0.4644","8.2672"
"2.9600","0.7177","35.7216","0.7177","0.4785","8.5051"
"3.0400","0.7381","36.6666","0.7381","0.4921","8.7301"
"3.1200","0.7572","37.5580","0.7572","0.5048","8.9424"
"3.2000","0.7772","38.4965","0.7772","0.5181","9.1658"
"3.2800","0.7966","39.3943","0.7966","0.5311","9.3796"
"3.3600","0.8172","40.3668","0.8172","0.5448","9.6111"
"3.4400","0.8372","41.2960","0.8372","0.5582","9.8324"
"3.5200","0.8561","42.1654","0.8561","0.5707","10.0394"
"3.6000","0.8767","43.1348","0.8767","0.5844","10.2702"
"3.6800","0.8976","44.1182","0.8976","0.5984","10.5043"
"3.7600","0.9173","45.0244","0.9173","0.6116","10.7201"
"3.8400","0.9369","45.9293","0.9369","0.6246","10.9355"
"3.9200","0.9555","46.7614","0.9555","0.6370","11.1337"
"4.0000","0.9766","47.7521","0.9766","0.6510","11.3696"
"4.0800","0.9977","48.7371","0.9977","0.6651","11.6041"
"4.1600","1.0170","49.6226","1.0170","0.6780","11.8149"
"4.2400","1.0373","50.5654","1.0373","0.6916","12.0394"
"4.3200","1.0572","51.4693","1.0572","0.7048","12.2546"
"4.4000","1.0776","52.4104","1.0776","0.7184","12.4787"
"4.4800","1.0977","53.3367","1.0977","0.7318","12.6992"
"4.5600","1.1165","54.1855","1.1165","0.7443","12.9013"
"4.6400","1.1366","55.1179","1.1366","0.7577","13.1233"
"4.7200","1.1567","56.0227","1.1567","0.7711","13.3387"
"4.8000","1.1762","56.9359","1.1762","0.7842","13.5562"
"4.8800","1.1979","57.9468","1.1979","0.7986","13.7968"
"4.9600","1.2171","58.8016","1.2171","0.8114","14.0004"
"5.0400","1.2372","59.7251","1.2372","0.8248","14.2203"
"5.1200","1.2568","60.6171","1.2568","0.8379","14.4326"
"5.2000","1.2759","61.4874","1.2759","0.8506","14.6398"
"5.2800","1.2967","62.4534","1.2967","0.8645","14.8699"
"5.3600","1.3168","63.3798","1.3168","0.8779","15.0904"
"5.4400","1.3371","64.3001","1.3371","0.8914","15.3096"
"5.5200","1.3581","65.2901","1.3581","0.9054","15.5453"
"5.6000","1.3776","66.1596","1.3776","0.9184","15.7523"
"5.6800","1.3978","67.0819","1.3978","0.9319","15.9719"
"5.7600","1.4169","67.9367","1.4169","0.9446","16.1754"
"5.8400","1.4365","68.8455","1.4365","0.9577","16.3918"
"5.9200","1.4569","69.7751","1.4569","0.9712","16.6131"
"6.0000","1.4760","70.6353","1.4760","0.9840","16.8179"
"6.0800","1.4974","71.6246","1.4974","0.9982","17.0535"
"6.1600","1.5177","72.5445","1.5177","1.0118","17.2725"
"6.2400","1.5368","73.3939","1.5368","1.0245","17.4747"
"6.3200","1.5570","74.3257","1.5570","1.0380","17.6966"
"6.4000","1.5769","75.2072","1.5769","1.0513","17.9065"
"6.4800","1.5971","76.1298","1.5971","1.0648","18.1261"
"6.5600","1.6174","77.0540","1.6174","1.0783","18.3462"
"6.6400","1.6359","77.8664","1.6359","1.0906","18.5396"
"6.7200","1.6573","78.8691","1.6573","1.1049","18.7784"
"6.8000","1.6779","79.8079","1.6779","1.1186","19.0019"
"6.8800","1.6982","80.7218","1.6982","1.1321","19.2195"
"6.9600","1.7173","81.5797","1.7173","1.1449","19.4237"
"7.0400","1.7363","82.4152","1.7363","1.1575","19.6227"
"7.1200","1.7564","83.3196","1.7564","1.1709","19.8380"
"7.2000","1.7773","84.2813","1.7773","1.1849","20.0670"
"7.2800","1.7959","85.1176","1.7959","1.1973","20.2661"
"7.3600","1.8176","86.1402","1.8176","1.2118","20.5096"
"7.4400","1.8372","86.9980","1.8372","1.2248","20.7138"
"7.5200","1.8575","87.9362","1.8575","1.2384","20.9372"
"7.6000","1.8774","88.8248","1.8774","1.2516","21.1488"
"7.6800","1.8962","89.6597","1.8962","1.2641","21.3476"
"7.7600","1.9167","90.5855","1.9167","1.2778","21.5680"
"7.8400","1.9369","91.5089","1.9369","1.2912","21.7878"
"7.9200","1.9565","92.3960","1.9565","1.3044","21.9990"
"8.0000","1.9778","93.3780","1.9778","1.3185","22.2328"
"8.0800","1.9977","94.2642","1.9977","1.3318","22.4438"
"8.1600","2.0176","95.1606","2.0176","1.3451","22.6573"
"8.2400","2.0376","96.0499","2.0376","1.3584","22.8690"
"8.3200","2.0563","96.8799","2.0563","1.3708","23.0666"
"8.4000","2.0770","97.8093","2.0770","1.3847","23.2879"
"8.4800","2.0964","98.6733","2.0964","1.3976","23.4936"
"8.5600","2.1165","99.5750","2.1165","1.4110","23.7083"
"8.6400","2.1376","100.5285","2.1376","1.4251","23.9354"
"8.7200","2.1574","101.3966","2.1574","1.4383","24.1420"
"8.8000","2.1772","102.2917","2.1772","1.4515","24.3552"
"8.8800","2.1975","103.1916","2.1975","1.4650","24.5694"
"8.9600","2.2166","104.0492","2.2166","1.4777","24.7736"
"9.0400","2.2368","104.9638","2.2368","1.4912","24.9914"
"9.1200","2.2561","105.8053","2.2561","1.5040","25.1917"
"9.2000","2.2776","106.8131","2.2776","1.5184","25.4317"
"9.2800","2.2983","107.7429","2.2983","1.5322","25.6531"
"9.3600","2.3176","108.5979","2.3176","1.5450","25.8567"
"9.4400","2.3368","109.4470","2.3368","1.5579","26.0588"
"9.5200","2.3568","110.3357","2.3568","1.5712","26.2704"
"9.6000","2.3769","111.2485","2.3769","1.5846","26.4877"
"9.6800","2.3974","112.1809","2.3974","1.5983","26.7097"
"9.7600","2.4159","112.9755","2.4159","1.6106","26.8989"
"9.8400","2.4367","113.9264","2.4367","1.6245","27.1253"
"9.9200","2.4576","114.8798","2.4576","1.6384","27.3523"
"10.0000","2.4774","115.7700","2.4774","1.6516","27.5643"
"10.0800","2.4973","116.6505","2.4973","1.6649","27.7739"
"10.1600","2.5166","117.5547","2.5166","1.6777","27.9892"
"10.2400","2.5369","118.4635","2.5369","1.6913","28.2056"
"10.3200","2.5569","119.3554","2.5569","1.7046","28.4179"
"10.4000","2.5762","120.2198","2.5762","1.7175","28.6238"
"10.4800","2.5974","121.2058","2.5974","1.7316","28.8585"
"10.5600","2.6180","122.1072","2.6180","1.7454","29.0732"
"10.6400","2.6375","122.9853","2.6375","1.7583","29.2822"
"10.7200","2.6572","123.8515","2.6572","1.7715","29.4885"
"10.8000","2.6760","124.6767","2.6760","1.7840","29.6849"
"10.8800","2.6972","125.6448","2.6972","1.7981","29.9154"
"10.9600","2.7167","126.5058","2.7167","1.8111","30.1204"
"11.0400","2.7363","127.3752","2.7363","1.8242","30.3274"
"11.1200","2.7568","128.2978","2.7568","1.8379","30.5471"
"11.2000","2.7768","129.1871","2.7768","1.8512","30.7588"
"11.2800","2.7977","130.1216","2.7977","1.8651","30.9813"
"11.3600","2.8178","131.0098","2.8178","1.8785","31.1928"
"11.4400","2.8361","131.7943","2.8361","1.8907","31.3796"
"11.5200","2.8565","132.7177","2.8565","1.9043","31.5994"
"11.6000","2.8765","133.5915","2.8765","1.9177","31.8075"
"11.6800","2.8973","134.5247","2.8973","1.9315","32.0297"
"11.7600","2.9181","135.4456","2.9181","1.9454","32.2489"
"11.8400","2.9371","136.2643","2.9371","1.9581","32.4439"
"11.9200","2.9570","137.1287","2.9570","1.9714","32.6497"
"12.0000","2.9772","138.0274","2.9772","1.9848","32.8637"
"12.0800","2.9968","138.9113","2.9968","1.9979","33.0741"
"12.1600","3.0172","139.8151","3.0172","2.0115","33.2893"
"12.2400","3.0360","140.6193","3.0360","2.0240","33.4808"
"12.3200","3.0566","141.5579","3.0566","2.0377","33.7043"
"12.4000","3.0782","142.5248","3.0782","2.0521","33.9345"
"12.4800","3.0973","143.3608","3.0973","2.0648","34.1335"
"12.5600","3.1176","144.2666","3.1176","2.0784","34.3492"
"12.6400","3.1365","145.0927","3.1365","2.0910","34.5459"
"12.7200","3.1564","145.9778","3.1564","2.1043","34.7566"
"12.8000","3.1764","146.8656","3.1764","2.1176","34.9680"
"12.8800","3.1967","147.7630","3.1967","2.1312","35.1817"
"12.9600","3.2176","148.6967","3.2176","2.1451","35.4040"
"13.0400","3.2384","149.6386","3.2384","2.1589","35.6282"
"13.1200","3.2571","150.4329","3.2571","2.1714","35.8173"
"13.2000","3.2773","151.3373","3.2773","2.1848","36.0327"
"13.2800","3.2967","152.1685","3.2967","2.1978","36.2306"
"13.3600","3.3174","153.1048","3.3174","2.2116","36.4535"
"13.4400","3.3368","153.9292","3.3368","2.2245","36.6498"
"13.5200","3.3558","154.7474","3.3558","2.2372","36.8446"
"13.6000","3.3769","155.6949","3.3769","2.2513","37.0702"
"13.6800","3.3981","156.6336","3.3981","2.2654","37.2937"
"13.7600","3.4175","157.4687","3.4175","2.2784","37.4925"
"13.8400","3.4370","158.3209","3.4370","2.2913","37.6954"
"13.9200","3.4559","159.1080","3.4559","2.3040","37.8829"
"14.0000","3.4767","160.0548","3.4767","2.3178","38.1083"
"14.0800","3.4972","160.9525","3.4972","2.3315","38.3220"
"14.1600","3.5166","161.7986","3.5166","2.3444","38.5235"
"14.2400","3.5376","162.7183","3.5376","2.3584","38.7424"
"14.3200","3.5571","163.5523","3.5571","2.3714","38.9410"
"14.4000","3.5779","164.4599","3.5779","2.3853","39.1571"
"14.4800","3.5974","165.2970","3.5974","2.3983","39.3564"
"14.5600","3.6167","166.1282","3.6167","2.4112","39.5543"
"14.6400","3.6365","166.9821","3.6365","2.4244","39.7577"
"14.7200","3.6563","167.8382","3.6563","2.4375","39.9615"
"14.8000","3.6760","168.7046","3.6760","2.4506","40.1678"
"14.8800","3.6977","169.6966","3.6977","2.4651","40.4040"
"14.9600","3.7175","170.5380","3.7175","2.4783","40.6043"
"15.0400","3.7376","171.4082","3.7376","2.4917","40.8115"
"15.1200","3.7567","172.2024","3.7567","2.5045","41.0006"
"15.2000","3.7761","173.0559","3.7761","2.5174","41.2038"
"15.2800","3.7966","173.9500","3.7966","2.5310","41.4167"
"15.3600","3.8164","174.7841","3.8164","2.5442","41.6153"
"15.4400","3.8371","175.7040","3.8371","2.5581","41.8343"
"15.5200","3.8582","176.6278","3.8582","2.5721","42.0542"
"15.6000","3.8773","177.4294","3.8773","2.5849","42.2451"
"15.6800","3.8975","178.3046","3.8975","2.5983","42.4535"
"15.7600","3.9171","179.1296","3.9171","2.6114","42.6499"
"15.8400","3.9367","179.9856","3.9367","2.6245","42.8537"
"15.9200","3.9569","180.8526","3.9569","2.6379","43.0601"
"16.0000","3.9757","181.6282","3.9757","2.6504","43.2448"
"16.0800","3.9971","182.5885","3.9971","2.6648","43.4734"
"16.1600","4.0180","183.4911","4.0180","2.6787","43.6884"
"16.2400","4.0370","184.2770","4.0370","2.6913","43.8755"
"16.3200","4.0567","185.1238","4.0567","2.7045","44.0771"
"16.4000","4.0766","185.9569","4.0766","2.7177","44.2755"
"16.4800","4.0967","186.8372","4.0967","2.7311","44.4850"
"16.5600","4.1170","187.6929","4.1170","2.7447","44.6888"
"16.6400","4.1356","188.4537","4.1356","2.7570","44.8699"
"16.7200","4.1574","189.4151","4.1574","2.7716","45.0988"
"16.8000","4.1779","190.3037","4.1779","2.7853","45.3104"
"16.8800","4.1983","191.1649","4.1983","2.7989","45.5155"
"16.9600","4.2169","191.9297","4.2169","2.8112","45.6976"
"17.0400","4.2365","192.7468","4.2365","2.8244","45.8921"
"17.1200","4.2567","193.6001","4.2567","2.8378","46.0953"
"17.2000","4.2771","194.4792","4.2771","2.8514","46.3046"
"17.2800","4.2961","195.2682","4.2961","2.8641","46.4924"
"17.3600","4.3172","196.1902","4.3172","2.8781","46.7120"
"17.4400","4.3371","197.0110","4.3371","2.8914","46.9074"
"17.5200","4.3574","197.8695","4.3574","2.9049","47.1118"
"17.6000","4.3771","198.6882","4.3771","2.9181","47.3067"
"17.6800","4.3964","199.4977","4.3964","2.9309","47.4995"
"17.7600","4.4167","200.3558","4.4167","2.9445","47.7038"
"17.8400","4.4368","201.2130","4.4368","2.9579","47.9079"
"17.9200","4.4565","202.0413","4.4565","2.9710","48.1051"
"18.0000","4.4778","202.9602","4.4778","2.9852","48.3239"
"18.0800","4.4978","203.7835","4.4978","2.9985","48.5199"
"18.1600","4.5178","204.6309","4.5178","3.0119","48.7216"
"18.2400","4.5376","205.4435","4.5376","3.0251","48.9151"
"18.3200","4.5562","206.2215","4.5562","3.0375","49.1004"
"18.4000","4.5769","207.0967","4.5769","3.0513","49.3087"
"18.4800","4.5961","207.8962","4.5961","3.0641","49.4991"
"18.5600","4.6172","208.7840","4.6172","3.0782","49.7105"
"18.6400","4.6371","209.6133","4.6371","3.0914","49.9079"
"18.7200","4.6573","210.4505","4.6573","3.1048","50.1073"
"18.8000","4.6771","211.2769","4.6771","3.1181","50.3040"
"18.8800","4.6973","212.1147","4.6973","3.1315","50.5035"
"18.9600","4.7164","212.9153","4.7164","3.1443","50.6941"
"19.0400","4.7370","213.7865","4.7370","3.1580","50.9016"
"19.1200","4.7557","214.5254","4.7557","3.1705","51.0775"
"19.2000","4.7779","215.5024","4.7779","3.1852","51.3101"
"19.2800","4.7982","216.3506","4.7982","3.1988","51.5121"
"19.3600","4.8170","217.1067","4.8170","3.2114","51.6921"
"19.4400","4.8370","217.9339","4.8370","3.2247","51.8890"
"19.5200","4.8572","218.7623","4.8572","3.2381","52.0863"
"19.6000","4.8769","219.5803","4.8769","3.2513","52.2810"
"19.6800","4.8977","220.4719","4.8977","3.2651","52.4933"
"19.7600","4.9162","221.1899","4.9162","3.2775","52.6643"
"19.8400","4.9367","222.0459","4.9367","3.2912","52.8681"
"19.9200","4.9573","222.8977","4.9573","3.3049","53.0709"
"20.0000","4.9775","223.7307","4.9775","3.3183","53.2692"
"20.0800","4.9978","224.5667","4.9978","3.3319","53.4683"
"20.1600","5.0164","225.2943","5.0164","3.3443","53.6415"
"20.2400","5.0366","226.1175","5.0366","3.3577","53.8375"
"20.3200","5.0564","226.9271","5.0564","3.3710","54.0303"
"20.4000","5.0765","227.7439","5.0765","3.3844","54.2247"
"20.4800","5.0970","228.5899","5.0970","3.3980","54.4262"
"20.5600","5.1178","229.4406","5.1178","3.4119","54.6287"
"20.6400","5.1378","230.2643","5.1378","3.4252","54.8248"
"20.7200","5.1576","231.0527","5.1576","3.4384","55.0126"
"20.8000","5.1763","231.7855","5.1763","3.4509","55.1870"
"20.8800","5.1971","232.6582","5.1971","3.4648","55.3948"
"20.9600","5.2168","233.4601","5.2168","3.4778","55.5857"
"21.0400","5.2363","234.2416","5.2363","3.4908","55.7718"
"21.1200","5.2565","235.0709","5.2565","3.5043","55.9693"
"21.2000","5.2774","235.9238","5.2774","3.5183","56.1723"
"21.2800","5.2974","236.7273","5.2974","3.5316","56.3637"
"21.3600","5.3176","237.5413","5.3176","3.5451","56.5574"
"21.4400","5.3360","238.2565","5.3360","3.5573","56.7277"
"21.5200","5.3567","239.1185","5.3567","3.5711","56.9330"
"21.6000","5.3763","239.9030","5.3763","3.5842","57.1198"
"21.6800","5.3974","240.7829","5.3974","3.5982","57.3293"
"21.7600","5.4182","241.6331","5.4182","3.6121","57.5317"
"21.8400","5.4374","242.3699","5.4374","3.6249","57.7071"
"21.9200","5.4573","243.1614","5.4573","3.6382","57.8956"
"22.0000","5.4771","243.9597","5.4771","3.6514","58.0856"
"22.0800","5.4969","244.7527","5.4969","3.6646","58.2744"
"22.1600","5.5175","245.6240","5.5175","3.6783","58.4819"
"22.2400","5.5360","246.3108","5.5360","3.6907","58.6454"
"22.3200","5.5564","247.1476","5.5564","3.7042","58.8447"
"22.4000","5.5777","248.0264","5.5777","3.7185","59.0539"
"22.4800","5.5973","248.8077","5.5973","3.7315","59.2399"
"22.5600","5.6177","249.6167","5.6177","3.7452","59.4326"
"22.6400","5.6365","250.3248","5.6365","3.7577","59.6011"
"22.7200","5.6554","251.0609","5.6554","3.7703","59.7764"
"22.8000","5.6760","251.9016","5.6760","3.7840","59.9766"
"22.8800","5.6969","252.7389","5.6969","3.7980","60.1759"
"22.9600","5.7176","253.5620","5.7176","3.8117","60.3719"
"23.0400","5.7385","254.4112","5.7385","3.8257","60.5741"
"23.1200","5.7571","255.1165","5.7571","3.8381","60.7420"
"23.2000","5.7775","255.9395","5.7775","3.8516","60.9380"
"23.2800","5.7966","256.6656","5.7966","3.8644","61.1108"
"23.3600","5.8175","257.5050","5.8175","3.8783","61.3107"
"23.4400","5.8370","258.2599","5.8370","3.8913","61.4905"
"23.5200","5.8558","258.9871","5.8558","3.9039","61.6636"
"23.6000","5.8767","259.8331","5.8767","3.9178","61.8650"
"23.6800","5.8976","260.6725","5.8976","3.9317","62.0649"
"23.7600","5.9177","261.4701","5.9177","3.9451","62.2548"
"23.8400","5.9375","262.2347","5.9375","3.9583","62.4368"
"23.9200","5.9563","262.9347","5.9563","3.9709","62.6035"
"24.0000","5.9768","263.7555","5.9768","3.9845","62.7989"
"24.0800","5.9972","264.5499","5.9972","3.9982","62.9881"
"24.1600","6.0168","265.3188","6.0168","4.0112","63.1711"
"24.2400","6.0374","266.1265","6.0374","4.0250","63.3634"
"24.3200","6.0572","266.8843","6.0572","4.0381","63.5439"
"24.4000","6.0779","267.7060","6.0779","4.0519","63.7395"
"24.4800","6.0977","268.4926","6.0977","4.0652","63.9268"
"24.5600","6.1171","269.2330","6.1171","4.0781","64.1031"
"24.6400","6.1365","269.9641","6.1365","4.0910","64.2772"
"24.7200","6.1564","270.7224","6.1564","4.1042","64.4577"
"24.8000","6.1764","271.5156","6.1764","4.1176","64.6466"
"24.8800","6.1980","272.3710","6.1980","4.1320","64.8502"
"24.9600","6.2173","273.0865","6.2173","4.1448","65.0206"
"25.0400","6.2373","273.8427","6.2373","4.1582","65.2006"
"25.1200","6.2562","274.5416","6.2562","4.1708","65.3671"
"25.2000","6.2762","275.3276","6.2762","4.1841","65.5542"
"25.2800","6.2966","276.1161","6.2966","4.1977","65.7419"
"25.3600","6.3167","276.8761","6.3167","4.2111","65.9229"
"25.4400","6.3371","277.6677","6.3371","4.2247","66.1114"
"25.5200","6.3580","278.4900","6.3580","4.2387","66.3071"
"25.6000","6.3775","279.2013","6.3775","4.2516","66.4765"
"25.6800","6.3976","279.9775","6.3976","4.2651","66.6613"
"25.7600","6.4172","280.7003","6.4172","4.2782","66.8334"
"25.8400","6.4364","281.4149","6.4364","4.2909","67.0035"
"25.9200","6.4568","282.2018","6.4568","4.3045","67.1909"
"26.0000","6.4754","282.8681","6.4754","4.3169","67.3495"
"26.0800","6.4972","283.7402","6.4972","4.3315","67.5572"
"26.1600","6.5182","284.5568","6.5182","4.3455","67.7516"
"26.2400","6.5376","285.2734","6.5376","4.3584","67.9222"
"26.3200","6.5569","285.9771","6.5569","4.3713","68.0898"
"26.4000","6.5766","286.7017","6.5766","4.3844","68.2623"
"26.4800","6.5970","287.4970","6.5970","4.3980","68.4517"
"26.5600","6.6174","288.2603","6.6174","4.4116","68.6334"
"26.6400","6.6361","288.9297","6.6361","4.4240","68.7928"
"26.7200","6.6574","289.7664","6.6574","4.4383","68.9920"
"26.8000","6.6778","290.5311","6.6778","4.4519","69.1741"
"26.8800","6.6982","291.3014","6.6982","4.4655","69.3575"
"26.9600","6.7171","291.9803","6.7171","4.4781","69.5191"
"27.0400","6.7364","292.6653","6.7364","4.4909","69.6822"
"27.1200","6.7565","293.4172","6.7565","4.5043","69.8612"
"27.2000","6.7771","294.2113","6.7771","4.5181","70.0503"
"27.2800","6.7962","294.9145","6.7962","4.5308","70.2177"
"27.3600","6.8172","295.7090","6.8172","4.5448","70.4069"
"27.4400","6.8370","296.4319","6.8370","4.5580","70.5790"
"27.5200","6.8573","297.1864","6.8573","4.5716","70.7587"
"27.6000","6.8773","297.9094","6.8773","4.5848","70.9308"
"27.6800","6.8963","298.5996","6.8963","4.5975","71.0952"
"27.7600","6.9167","299.3572","6.9167","4.6111","71.2755"
"27.8400","6.9367","300.0869","6.9367","4.6244","71.4492"
"27.9200","6.9568","300.8400","6.9568","4.6379","71.6286"
"28.0000","6.9778","301.6498","6.9778","4.6518","71.8214"
"28.0800","6.9978","302.3535","6.9978","4.6652","71.9889"
"28.1600","7.0176","303.0898","7.0176","4.6784","72.1642"
"28.2400","7.0374","303.8029","7.0374","4.6916","72.3340"
"28.3200","7.0563","304.4997","7.0563","4.7042","72.4999"
"28.4000","7.0772","305.2779","7.0772","4.7181","72.6852"
"28.4800","7.0961","305.9380","7.0961","4.7307","72.8424"
"28.5600","7.1170","306.7193","7.1170","4.7447","73.0284"
"28.6400","7.1374","307.4787","7.1374","4.7582","73.2092"
"28.7200","7.1572","308.1664","7.1572","4.7714","73.3730"
"28.8000","7.1769","308.8820","7.1769","4.7846","73.5433"
"28.8800","7.1974","309.6347","7.1974","4.7982","73.7225"
"28.9600","7.2164","310.3075","7.2164","4.8109","73.8827"
"29.0400","7.2369","311.0553","7.2369","4.8246","74.0608"
"29.1200","7.2557","311.6926","7.2557","4.8372","74.2125"
"29.2000","7.2775","312.5326","7.2775","4.8516","74.4125"
"29.2800","7.2982","313.2937","7.2982","4.8655","74.5937"
"29.3600","7.3177","313.9735","7.3177","4.8785","74.7556"
"29.4400","7.3370","314.6419","7.3370","4.8914","74.9147"
"29.5200","7.3569","315.3440","7.3569","4.9046","75.0819"
"29.6000","7.3770","316.0724","7.3770","4.9180","75.2553"
"29.6800","7.3974","316.8187","7.3974","4.9316","75.4330"
"29.7600","7.4162","317.4417","7.4162","4.9441","75.5813"
"29.8400","7.4365","318.1711","7.4365","4.9577","75.7550"
"29.9200","7.4574","318.9313","7.4574","4.9716","75.9360"
"30.0000","7.4776","319.6527","7.4776","4.9851","76.1078"
"30.0800","7.4976","320.3558","7.4976","4.9984","76.2752"
"30.1600","7.5167","321.0204","7.5167","5.0111","76.4334"
"30.2400","7.5369","321.7424","7.5369","5.0246","76.6053"
"30.3200","7.5565","322.4084","7.5565","5.0376","76.7639"
"30.4000","7.5765","323.1227","7.5765","5.0510","76.9340"
"30.4800","7.5974","323.8834","7.5974","5.0649","77.1151"
"30.5600","7.6183","324.6294","7.6183","5.0789","77.2927"
"30.6400","7.6380","325.2962","7.6380","5.0920","77.4515"
"30.7200","7.6578","325.9894","7.6578","5.1052","77.6165"
"30.8000","7.6763","326.5840","7.6763","5.1175","77.7581"
"30.8800","7.6970","327.3290","7.6970","5.1313","77.9355"
"30.9600","7.7165","327.9962","7.7165","5.1444","78.0943"
"31.0400","7.7363","328.6942","7.7363","5.1575","78.2605"
"31.1200","7.7566","329.4173","7.7566","5.1711","78.4327"
"31.2000","7.7773","330.1493","7.7773","5.1849","78.6070"
"31.2800","7.7978","330.8604","7.7978","5.1985","78.7763"
"31.3600","7.8180","331.5738","7.8180","5.2120","78.9462"
"31.4400","7.8359","332.1246","7.8359","5.2239","79.0773"
"31.5200","7.8564","332.8734","7.8564","5.2376","79.2556"
"31.6000","7.8764","333.5576","7.8764","5.2509","79.4185"
"31.6800","7.8977","334.3358","7.8977","5.2651","79.6038"
"31.7600","7.9181","335.0368","7.9181","5.2788","79.7707"
"31.8400","7.9374","335.6765","7.9374","5.2916","79.9230"
"31.9200","7.9574","336.3522","7.9574","5.3049","80.0838"
"32.0000","7.9774","337.0445","7.9774","5.3182","80.2487"
"32.0800","7.9968","337.7018","7.9968","5.3312","80.4052"
"32.1600","8.0167","338.3759","8.0167","5.3444","80.5657"
"32.2400","8.0360","339.0105","8.0360","5.3573","80.7168"
"32.3200","8.0569","339.7567","8.0569","5.3713","80.8944"
"32.4000","8.0777","340.4736","8.0777","5.3851","81.0651"
"32.4800","8.0969","341.1023","8.0969","5.3980","81.2148"
"32.5600","8.1176","341.8142","8.1176","5.4117","81.3843"
"32.6400","8.1363","342.3957","8.1363","5.4242","81.5228"
"32.7200","8.1565","343.1040","8.1565","5.4377","81.6914"
"32.8000","8.1762","343.7581","8.1762","5.4508","81.8472"
"32.8800","8.1967","344.4576","8.1967","5.4645","82.0137"
"32.9600","8.2176","345.1770","8.2176","5.4784","82.1850"
"33.0400","8.2384","345.8813","8.2384","5.4923","82.3527"
"33.1200","8.2568","346.4537","8.2568","5.5045","82.4890"
"33.2000","8.2770","347.1453","8.2770","5.5180","82.6536"
"33.2800","8.2966","347.7837","8.2966","5.5311","82.8056"
"33.3600","8.3175","348.5014","8.3175","5.5450","82.9765"
"33.4400","8.3370","349.1427","8.3370","5.5580","83.1292"
"33.5200","8.3557","349.7453","8.3557","5.5705","83.2727"
"33.6000","8.3765","350.4561","8.3765","5.5843","83.4419"
"33.6800","8.3981","351.2278","8.3981","5.5987","83.6257"
"33.7600","8.4177","351.8543","8.4177","5.6118","83.7748"
"33.8400","8.4370","352.4740","8.4370","5.6247","83.9224"
"33.9200","8.4557","353.0470","8.4557","5.6372","84.0588"
"34.0000","8.4766","353.7903","8.4766","5.6511","84.2358"
"34.0800","8.4972","354.4692","8.4972","5.6648","84.3974"
"34.1600","8.5165","355.1032","8.5165","5.6777","84.5484"
"34.2400","8.5378","355.8204","8.5378","5.6919","84.7192"
"34.3200","8.5572","356.4335","8.5572","5.7048","84.8651"
"34.4000","8.5779","357.1188","8.5779","5.7186","85.0283"
"34.4800","8.5976","357.7544","8.5976","5.7318","85.1796"
"34.5600","8.6168","358.3486","8.6168","5.7445","85.3211"
"34.6400","8.6361","358.9490","8.6361","5.7574","85.4640"
"34.7200","8.6562","359.5980","8.6562","5.7708","85.6186"
"34.8000","8.6763","360.2711","8.6763","5.7842","85.7788"
"34.8800","8.6978","360.9931","8.6978","5.7985","85.9507"
"34.9600","8.7173","361.6091","8.7173","5.8115","86.0974"
"35.0400","8.7377","362.2493","8.7377","5.8251","86.2498"
"35.1200","8.7567","362.8380","8.7567","5.8378","86.3900"
"35.2000","8.7763","363.4672","8.7763","5.8509","86.5398"
"35.2800","8.7966","364.1311","8.7966","5.8644","86.6979"
"35.3600","8.8165","364.7575","8.8165","5.8776","86.8470"
"35.4400","8.8372","365.4460","8.8372","5.8914","87.0109"
"35.5200","8.8581","366.1391","8.8581","5.9054","87.1760"
"35.6000","8.8774","366.7306","8.8774","5.9183","87.3168"
"35.6800","8.8981","367.4108","8.8981","5.9321","87.4788"
"35.7600","8.9173","367.9921","8.9173","5.9449","87.6172"
"35.8400","8.9365","368.5818","8.9365","5.9577","87.7576"
"35.9200","8.9565","369.2430","8.9565","5.9710","87.9150"
"36.0000","8.9760","369.8672","8.9760","5.9840","88.0636"
"36.0800","8.9970","370.5572","8.9970","5.9980","88.2279"
"36.1600","9.0179","371.2458","9.0179","6.0119","88.3919"
"36.2400","9.0373","371.8420","9.0373","6.0249","88.5338"
"36.3200","9.0569","372.4517","9.0569","6.0379","88.6790"
"36.4000","9.0768","373.0749","9.0768","6.0512","88.8273"
"36.4800","9.0968","373.7128","9.0968","6.0645","88.9792"
"36.5600","9.1173","374.3660","9.1173","6.0782","89.1348"
"36.6400","9.1358","374.9083","9.1358","6.0906","89.2639"
"36.7200","9.1577","375.6429","9.1577","6.1051","89.4388"
"36.8000","9.1777","376.2610","9.1777","6.1184","89.5860"
"36.8800","9.1981","376.9088","9.1981","6.1321","89.7402"
"36.9600","9.2167","377.4487","9.2167","6.1445","89.8687"
"37.0400","9.2366","378.0564","9.2366","6.1578","90.0134"
"37.1200","9.2569","378.7031","9.2569","6.1712","90.1674"
"37.2000","9.2770","379.3259","9.2770","6.1847","90.3157"
"37.2800","9.2959","379.8901","9.2959","6.1973","90.4500"
"37.3600","9.3176","380.6260","9.3176","6.2117","90.6252"
"37.4400","9.3372","381.1999","9.3372","6.2248","90.7619"
"37.5200","9.3576","381.8384","9.3576","6.2384","90.9139"
"37.6000","9.3772","382.4111","9.3772","6.2514","91.0503"
"37.6800","9.3963","382.9813","9.3963","6.2642","91.1860"
"37.7600","9.4168","383.6290","9.4168","6.2778","91.3402"
"37.8400","9.4366","384.2235","9.4366","6.2911","91.4818"
"37.9200","9.4566","384.8451","9.4566","6.3044","91.6298"
"38.0000","9.4777","385.5256","9.4777","6.3184","91.7918"
"38.0800","9.4978","386.1256","9.4978","6.3319","91.9347"
"38.1600","9.5179","386.7381","9.5179","6.3453","92.0805"
"38.2400","9.5375","387.3199","9.5375","6.3584","92.2190"
"38.3200","9.5561","387.8566","9.5561","6.3708","92.3468"
"38.4000","9.5769","388.5121","9.5769","6.3846","92.5029"
"38.4800","9.5961","389.0800","9.5961","6.3974","92.6381"
"38.5600","9.6172","389.7630","9.6172","6.4115","92.8007"
"38.6400","9.6372","390.3585","9.6372","6.4248","92.9425"
"38.7200","9.6571","390.9433","9.6571","6.4380","93.0817"
"38.8000","9.6771","391.5450","9.6771","6.4514","93.2250"
"38.8800","9.6974","392.1550","9.6974","6.4649","93.3702"
"38.9600","9.7164","392.7030","9.7164","6.4776","93.5007"
"39.0400","9.7370","393.3316","9.7370","6.4913","93.6504"
"39.1200","9.7556","393.8364","9.7556","6.5038","93.7706"
"39.2000","9.7775","394.5739","9.7775","6.5183","93.9462"
"39.2800","9.7983","395.1962","9.7983","6.5322","94.0943"
"39.3600","9.8176","395.7501","9.8176","6.5450","94.2262"
"39.4400","9.8368","396.2950","9.8368","6.5579","94.3559"
"39.5200","9.8569","396.8867","9.8569","6.5713","94.4968"
"39.6000","9.8771","397.4947","9.8771","6.5847","94.6416"
"39.6800","9.8972","398.0998","9.8972","6.5981","94.7857"
"39.7600","9.9159","398.5943","9.9159","6.6106","94.9034"
"39.8400","9.9369","399.2598","9.9369","6.6246","95.0619"
"39.9200","9.9575","399.8676","9.9575","6.6383","95.2066"
"40.0000","9.9774","400.4625","9.9774","6.6516","95.3482"
"40.0800","9.9975","401.0480","9.9975","6.6650","95.4876"
"40.1600","10.0164","401.5652","10.0164","6.6776","95.6108"
"40.2400","10.0370","402.1889","10.0370","6.6913","95.7593"
"40.3200","10.0565","402.7238","10.0565","6.7043","95.8866"
"40.4000","10.0764","403.3112","10.0764","6.7176","96.0265"
"40.4800","10.0974","403.9512","10.0974","6.7316","96.1789"
"40.5600","10.1180","404.5390","10.1180","6.7453","96.3188"
"40.6400","10.1374","405.0980","10.1374","6.7583","96.4519"
"40.7200","10.1577","405.6813","10.1577","6.7718","96.5908"
"40.8000","10.1764","406.1754","10.1764","6.7842","96.7084"
"40.8800","10.1972","406.7852","10.1972","6.7981","96.8536"
"40.9600","10.2163","407.3058","10.2163","6.8109","96.9776"
"41.0400","10.2366","407.9040","10.2366","6.8244","97.1200"
"41.1200","10.2568","408.4943","10.2568","6.8379","97.2605"
"41.2000","10.2773","409.0896","10.2773","6.8515","97.4023"
"41.2800","10.2978","409.6887","10.2978","6.8652","97.5449"
"41.3600","10.3177","410.2415","10.3177","6.8785","97.6765"
"41.4400","10.3363","410.7350","10.3363","6.8909","97.7940"
"41.5200","10.3566","411.3313","10.3566","6.9044","97.9360"
"41.6000","10.3763","411.8682","10.3763","6.9175","98.0638"
"41.6800","10.3971","412.5005","10.3971","6.9314","98.2144"
"41.7600","10.4178","413.1019","10.4178","6.9452","98.3576"
"41.8400","10.4373","413.6289","10.4373","6.9582","98.4831"
"41.9200","10.4576","414.2029","10.4576","6.9717","98.6197"
"42.0000","10.4773","414.7422","10.4773","6.9849","98.7481"
"42.0800","10.4971","415.3340","10.4971","6.9981","98.8891"
"42.1600","10.5169","415.8671","10.5169","7.0112","99.0160"
"42.2400","10.5361","416.3673","10.5361","7.0241","99.1351"
"42.3200","10.5569","416.9753","10.5569","7.0379","99.2798"
"42.4000","10.5781","417.5956","10.5781","7.0520","99.4275"
"42.4800","10.5972","418.1056","10.5972","7.0648","99.5490"
"42.5600","10.6177","418.6776","10.6177","7.0785","99.6851"
"42.6400","10.6364","419.1383","10.6364","7.0909","99.7948"
"42.7200","10.6565","419.7011","10.6565","7.1043","99.9288"
"42.8000","10.6761","420.2378","10.6761","7.1174","100.0566"
"42.8800","10.6968","420.8240","10.6968","7.1312","100.1962"
"42.9600","10.7176","421.4178","10.7176","7.1451","100.3376"
"43.0400","10.7379","421.9725","10.7379","7.1586","100.4696"
"43.1200","10.7572","422.4798","10.7572","7.1715","100.5904"
"43.2000","10.7775","423.0421","10.7775","7.1850","100.7243"
"43.2800","10.7967","423.5265","10.7967","7.1978","100.8396"
"43.3600","10.8172","424.1078","10.8172","7.2115","100.9781"
"43.4400","10.8367","424.6217","10.8367","7.2245","101.1004"
"43.5200","10.8558","425.1331","10.8558","7.2372","101.2222"
"43.6000","10.8769","425.7382","10.8769","7.2513","101.3662"
"43.6800","10.8973","426.2946","10.8973","7.2649","101.4987"
"43.7600","10.9173","426.8283","10.9173","7.2782","101.6258"
"43.8400","10.9374","427.3738","10.9374","7.2916","101.7557"
"43.9200","10.9561","427.8280","10.9561","7.3041","101.8638"
"44.0000","10.9768","428.4172","10.9768","7.3178","102.0041"
"44.0800","10.9970","428.9614","10.9970","7.3314","102.1337"
"44.1600","11.0169","429.5097","11.0169","7.3446","102.2642"
"44.2400","11.0375","430.0721","11.0375","7.3583","102.3981"
"44.3200","11.0570","430.5685","11.0570","7.3713","102.5163"
"44.4000","11.0780","431.1612","11.0780","7.3854","102.6574"
"44.4800","11.0976","431.6670","11.0976","7.3984","102.7779"
"44.5600","11.1164","432.1194","11.1164","7.4110","102.8856"
"44.6400","11.1364","432.6852","11.1364","7.4242","103.0203"
"44.7200","11.1568","433.2287","11.1568","7.4379","103.1497"
"44.8000","11.1764","433.7485","11.1764","7.4509","103.2735"
"44.8800","11.1977","434.3513","11.1977","7.4652","103.4170"
"44.9600","11.2174","434.8259","11.2174","7.4782","103.5300"
"45.0400","11.2378","435.3692","11.2378","7.4918","103.6593"
"45.1200","11.2566","435.8238","11.2566","7.5044","103.7676"
"45.2000","11.2764","436.3488","11.2764","7.5176","103.8926"
"45.2800","11.2968","436.8890","11.2968","7.5312","104.0212"
"45.3600","11.3168","437.4021","11.3168","7.5445","104.1434"
"45.4400","11.3369","437.9401","11.3369","7.5579","104.2714"
"45.5200","11.3581","438.5353","11.3581","7.5721","104.4132"
"45.6000","11.3776","439.0116","11.3776","7.5850","104.5266"
"45.6800","11.3977","439.5184","11.3977","7.5985","104.6472"
"45.7600","11.4170","439.9930","11.4170","7.6113","104.7602"
"45.8400","11.4368","440.5283","11.4368","7.6246","104.8877"
"45.9200","11.4566","441.0273","11.4566","7.6377","105.0065"
"46.0000","11.4757","441.4876","11.4757","7.6505","105.1161"
"46.0800","11.4973","442.0926","11.4973","7.6648","105.2601"
"46.1600","11.5177","442.6355","11.5177","7.6785","105.3894"
"46.2400","11.5376","443.1393","11.5376","7.6917","105.5093"
"46.3200","11.5568","443.5997","11.5568","7.7045","105.6190"
"46.4000","11.5762","444.0663","11.5762","7.7175","105.7301"
"46.4800","11.5968","444.6219","11.5968","7.7312","105.8624"
"46.5600","11.6175","445.1647","11.6175","7.7450","105.9916"
"46.6400","11.6356","445.5611","11.6356","7.7571","106.0860"
"46.7200","11.6575","446.1838","11.6575","7.7716","106.2342"
"46.8000","11.6776","446.6920","11.6776","7.7850","106.3552"
"46.8800","11.6985","447.2465","11.6985","7.7990","106.4873"
"46.9600","11.7177","447.6920","11.7177","7.8118","106.5933"
"47.0400","11.7363","448.0950","11.7363","7.8242","106.6893"
"47.1200","11.7563","448.6002","11.7563","7.8375","106.8096"
"47.2000","11.7767","449.1380","11.7767","7.8511","106.9376"
"47.2800","11.7962","449.6141","11.7962","7.8642","107.0510"
"47.3600","11.8175","450.1976","11.8175","7.8783","107.1899"
"47.4400","11.8372","450.6561","11.8372","7.8914","107.2991"
"47.5200","11.8575","451.1934","11.8575","7.9050","107.4270"
"47.6000","11.8773","451.6663","11.8773","7.9182","107.5396"
"47.6800","11.8964","452.1157","11.8964","7.9309","107.6466"
"47.7600","11.9167","452.6127","11.9167","7.9445","107.7649"
"47.8400","11.9367","453.1085","11.9367","7.9578","107.8830"
"47.9200","11.9571","453.6109","11.9571","7.9714","108.0026"
"48.0000","11.9779","454.1647","11.9779","7.9852","108.1345"
"48.0800","11.9982","454.6525","11.9982","7.9988","108.2506"
"48.1600","12.0178","455.1064","12.0178","8.0118","108.3587"
"48.2400","12.0374","455.5577","12.0374","8.0249","108.4661"
"48.3200","12.0562","455.9934","12.0562","8.0375","108.5699"
"48.4000","12.0772","456.5341","12.0772","8.0514","108.6986"
"48.4800","12.0962","456.9515","12.0962","8.0641","108.7980"
"48.5600","12.1171","457.4915","12.1171","8.0781","108.9265"
"48.6400","12.1373","457.9798","12.1373","8.0915","109.0428"
"48.7200","12.1575","458.4685","12.1575","8.1050","109.1592"
"48.8000","12.1772","458.9166","12.1772","8.1181","109.2658"
"48.8800","12.1972","459.3856","12.1972","8.1314","109.3775"
"48.9600","12.2164","459.8212","12.2164","8.1442","109.4812"
"49.0400","12.2367","460.3004","12.2367","8.1578","109.5953"
"49.1200","12.2558","460.7118","12.2558","8.1706","109.6933"
"49.2000","12.2776","461.3013","12.2776","8.1851","109.8336"
"49.2800","12.2983","461.7960","12.2983","8.1989","109.9514"
"49.3600","12.3178","462.2318","12.3178","8.2119","110.0552"
"49.4400","12.3371","462.6534","12.3371","8.2247","110.1556"
"49.5200","12.3566","463.0984","12.3566","8.2377","110.2615"
"49.6000","12.3768","463.5885","12.3768","8.2512","110.3782"
"49.6800","12.3976","464.0982","12.3976","8.2651","110.4996"
"49.7600","12.4159","464.4561","12.4159","8.2773","110.5848"
"49.8400","12.4362","464.9487","12.4362","8.2908","110.7021"
"49.9200","12.4577","465.4955","12.4577","8.3051","110.8323"
"50.0000","12.4777","465.9543","12.4777","8.3185","110.9415"
"50.0800","12.4977","466.3971","12.4977","8.3318","111.0469"
"50.1600","12.5163","466.7605","12.5163","8.3442","111.1334"
"50.2400","12.5370","467.2555","12.5370","8.3580","111.2513"
"50.3200","12.5565","467.6929","12.5565","8.3710","111.3554"
"50.4000","12.5765","468.1543","12.5765","8.3844","111.4653"
"50.4800","12.5975","468.6837","12.5975","8.3983","111.5913"
"50.5600","12.6183","469.1601","12.6183","8.4122","111.7048"
"50.6400","12.6374","469.5570","12.6374","8.4249","111.7993"
"50.7200","12.6574","469.9922","12.6574","8.4382","111.9029"
"50.8000","12.6761","470.3688","12.6761","8.4507","111.9926"
"50.8800","12.6974","470.8806","12.6974","8.4650","112.1144"
"50.9600","12.7164","471.2556","12.7164","8.4776","112.2037"
"51.0400","12.7365","471.7277","12.7365","8.4910","112.3161"
"51.1200","12.7567","472.1850","12.7567","8.5044","112.4250"
"51.2000","12.7772","472.6328","12.7772","8.5182","112.5316"
"51.2800","12.7975","473.0945","12.7975","8.5316","112.6415"
"51.3600","12.8178","473.5413","12.8178","8.5452","112.7479"
"51.4400","12.8363","473.8838","12.8363","8.5575","112.8295"
"51.5200","12.8565","474.3334","12.8565","8.5710","112.9365"
"51.6000","12.8762","474.7418","12.8762","8.5841","113.0338"
"51.6800","12.8973","475.2606","12.8973","8.5982","113.1573"
"51.7600","12.9183","475.7361","12.9183","8.6122","113.2705"
"51.8400","12.9375","476.1178","12.9375","8.6250","113.3614"
"51.9200","12.9576","476.5416","12.9576","8.6384","113.4623"
"52.0000","12.9772","476.9496","12.9772","8.6515","113.5594"
"52.0800","12.9970","477.3813","12.9970","8.6646","113.6622"
"52.1600","13.0170","477.8064","13.0170","8.6780","113.7634"
"52.2400","13.0359","478.1531","13.0359","8.6906","113.8460"
"52.3200","13.0567","478.6715","13.0567","8.7045","113.9694"
"52.4000","13.0779","479.1493","13.0779","8.7186","114.0832"
"52.4800","13.0972","479.5221","13.0972","8.7315","114.1719"
"52.5600","13.1176","479.9595","13.1176","8.7451","114.2761"
"52.6400","13.1366","480.3086","13.1366","8.7577","114.3592"
"52.7200","13.1565","480.7308","13.1565","8.7710","114.4597"
"52.8000","13.1764","481.1435","13.1764","8.7842","114.5580"
"52.8800","13.1966","481.5636","13.1966","8.7977","114.6580"
"52.9600","13.2175","482.0239","13.2175","8.8117","114.7676"
"53.0400","13.2384","482.4710","13.2384","8.8256","114.8740"
"53.1200","13.2576","482.8397","13.2576","8.8384","114.9618"
"53.2000","13.2774","483.2273","13.2774","8.8516","115.0541"
"53.2800","13.2965","483.5727","13.2965","8.8643","115.1363"
"53.3600","13.3172","484.0359","13.3172","8.8782","115.2466"
"53.4400","13.3370","484.4337","13.3370","8.8914","115.3414"
"53.5200","13.3554","484.7500","13.3554","8.9036","115.4167"
"53.6000","13.3767","485.2321","13.3767","8.9178","115.5315"
"53.6800","13.3980","485.6920","13.3980","8.9320","115.6410"
"53.7600","13.4177","486.0544","13.4177","8.9451","115.7272"
"53.8400","13.4373","486.4323","13.4373","8.9582","115.8172"
"53.9200","13.4561","486.7426","13.4561","8.9707","115.8911"
"54.0000","13.4768","487.1906","13.4768","8.9845","115.9978"
"54.0800","13.4971","487.5974","13.4971","8.9981","116.0946"
"54.1600","13.5168","487.9804","13.5168","9.0112","116.1858"
"54.2400","13.5376","488.4103","13.5376","9.0251","116.2882"
"54.3200","13.5571","488.7561","13.5571","9.0381","116.3705"
"54.4000","13.5778","489.1765","13.5778","9.0519","116.4706"
"54.4800","13.5978","489.5665","13.5978","9.0652","116.5634"
"54.5600","13.6168","489.8734","13.6168","9.0779","116.6365"
"54.6400","13.6365","490.2430","13.6365","9.0910","116.7245"
"54.7200","13.6565","490.6119","13.6565","9.1043","116.8124"
"54.8000","13.6763","490.9998","13.6763","9.1176","116.9047"
"54.8800","13.6977","491.4442","13.6977","9.1318","117.0105"
"54.9600","13.7173","491.7630","13.7173","9.1449","117.0864"
"55.0400","13.7376","492.1211","13.7376","9.1584","117.1717"
"55.1200","13.7567","492.4328","13.7567","9.1711","117.2459"
"55.2000","13.7766","492.8016","13.7766","9.1844","117.3337"
"55.2800","13.7963","493.1591","13.7963","9.1976","117.4188"
"55.3600","13.8166","493.5239","13.8166","9.2111","117.5057"
"55.4400","13.8377","493.9389","13.8377","9.2251","117.6045"
"55.5200","13.8582","494.3066","13.8582","9.2388","117.6921"
"55.6000","13.8774","494.6117","13.8774","9.2516","117.7647"
"55.6800","13.8977","494.9828","13.8977","9.2651","117.8530"
"55.7600","13.9171","495.2771","13.9171","9.2781","117.9231"
"55.8400","13.9363","495.5909","13.9363","9.2909","117.9978"
"55.9200","13.9567","495.9557","13.9567","9.3045","118.0847"
"56.0000","13.9757","496.2315","13.9757","9.3172","118.1504"
"56.0800","13.9973","496.6587","13.9973","9.3315","118.2521"
"56.1600","14.0179","497.0318","14.0179","9.3453","118.3409"
"56.2400","14.0373","497.3234","14.0373","9.3582","118.4103"
"56.3200","14.0572","497.6633","14.0572","9.3714","118.4913"
"56.4000","14.0765","497.9400","14.0765","9.3843","118.5571"
"56.4800","14.0967","498.3118","14.0967","9.3978","118.6457"
"56.5600","14.1172","498.6592","14.1172","9.4115","118.7284"
"56.6400","14.1362","498.9395","14.1362","9.4241","118.7951"
"56.7200","14.1572","499.3273","14.1572","9.4381","118.8874"
"56.8000","14.1777","499.6701","14.1777","9.4518","118.9691"
"56.8800","14.1982","500.0251","14.1982","9.4655","119.0536"
"56.9600","14.2174","500.3024","14.2174","9.4782","119.1196"
"57.0400","14.2362","500.5561","14.2362","9.4908","119.1800"
"57.1200","14.2567","500.9083","14.2567","9.5045","119.2639"
"57.2000","14.2768","501.2249","14.2768","9.5179","119.3393"
"57.2800","14.2961","501.5020","14.2961","9.5307","119.4052"
"57.3600","14.3171","501.8642","14.3171","9.5447","119.4915"
"57.4400","14.3373","502.1702","14.3373","9.5582","119.5643"
"57.5200","14.3576","502.4920","14.3576","9.5717","119.6410"
"57.6000","14.3772","502.7590","14.3772","9.5848","119.7045"
"57.6800","14.3966","503.0344","14.3966","9.5977","119.7701"
"57.7600","14.4171","503.3423","14.4171","9.6114","119.8434"
"57.8400","14.4365","503.5963","14.4365","9.6243","119.9039"
"57.9200","14.4567","503.9105","14.4567","9.6378","119.9787"
"58.0000","14.4776","504.2473","14.4776","9.6517","120.0589"
"58.0800","14.4978","504.5133","14.4978","9.6652","120.1222"
"58.1600","14.5170","504.7564","14.5170","9.6780","120.1801"
"58.2400","14.5370","505.0240","14.5370","9.6913","120.2438"
"58.3200","14.5565","505.2784","14.5565","9.7043","120.3044"
"58.4000","14.5769","505.5767","14.5769","9.7179","120.3754"
"58.4800","14.5963","505.8140","14.5963","9.7309","120.4319"
"58.5600","14.6171","506.1342","14.6171","9.7447","120.5081"
"58.6400","14.6374","506.4135","14.6374","9.7583","120.5746"
"58.7200","14.6572","506.6637","14.6572","9.7715","120.6342"
"58.8000","14.6773","506.9258","14.6773","9.7849","120.6966"
"58.8800","14.6973","507.1856","14.6973","9.7982","120.7585"
"58.9600","14.7166","507.4241","14.7166","9.8111","120.8153"
"59.0400","14.7364","507.6664","14.7364","9.8243","120.8729"
"59.1200","14.7559","507.8871","14.7559","9.8372","120.9255"
"59.2000","14.7774","508.2330","14.7774","9.8516","121.0079"
"59.2800","14.7984","508.5352","14.7984","9.8656","121.0798"
"59.3600","14.8177","508.7528","14.8177","9.8785","121.1316"
"59.4400","14.8369","508.9527","14.8369","9.8913","121.1792"
"59.5200","14.8567","509.1827","14.8567","9.9045","121.2340"
"59.6000","14.8770","509.4505","14.8770","9.9180","121.2977"
"59.6800","14.8972","509.7014","14.8972","9.9315","121.3575"
"59.7600","14.9160","509.8682","14.9160","9.9440","121.3972"
"59.8400","14.9366","510.1219","14.9366","9.9577","121.4576"
"59.9200","14.9574","510.4036","14.9574","9.9716","121.5247"
"60.0000","14.9778","510.6384","14.9778","9.9852","121.5806"
"60.0800","14.9977","510.8568","14.9977","9.9985","121.6326"
"60.0900","15.0002","510.8853","15.0002","10.0002","121.6394"