File: data/instron_tests/metamaterials/250331/250331_1049_VERT_m1.is_comp_Exports/250331_1049_VERT_m1_3_1.csv
Results Table 1
,Compresson Axis,H*,V*,Height,Thickness,Width,Area,Fixture separation,Specimen label
,,,,(mm),(mm),(mm),(mm^2),(mm),
"3","Y","","","150.00","28.00","150.00","4200.00","150.00","1049_VERT_m1"

Results Table 2
,Modulus (Segment 0 % - 5 %),Compresson Axis
,(kPa),
"3","920.60","Y"

Time,Displacement,Force,Compressive displacement,Compressive strain (Displacement),Compressive stress
(s),(mm),(N),(mm),(%),(kPa)
"0.0000","0.0000","-12.4480","0.0000","0.0000","-2.9638"
"0.0800","0.0013","-12.4069","0.0013","0.0008","-2.9540"
"0.1600","0.0175","-11.7600","0.0175","0.0117","-2.8000"
"0.2400","0.0384","-10.9806","0.0384","0.0256","-2.6144"
"0.3200","0.0580","-10.2833","0.0580","0.0387","-2.4484"
"0.4000","0.0774","-9.5799","0.0774","0.0516","-2.2809"
"0.4800","0.0984","-8.8466","0.0984","0.0656","-2.1063"
"0.5600","0.1183","-8.1853","0.1183","0.0789","-1.9489"
"0.6400","0.1383","-7.5093","0.1383","0.0922","-1.7879"
"0.7200","0.1578","-6.8619","0.1578","0.1052","-1.6338"
"0.8000","0.1770","-6.2319","0.1770","0.1180","-1.4838"
"0.8800","0.1977","-5.5442","0.1977","0.1318","-1.3201"
"0.9600","0.2168","-4.9430","0.2168","0.1445","-1.1769"
"1.0400","0.2366","-4.2929","0.2366","0.1578","-1.0221"
"1.1200","0.2578","-3.6037","0.2578","0.1719","-0.8580"
"1.2000","0.2777","-2.9771","0.2777","0.1852","-0.7088"
"1.2800","0.2983","-2.3346","0.2983","0.1989","-0.5559"
"1.3600","0.3179","-1.7244","0.3179","0.2119","-0.4106"
"1.4400","0.3366","-1.1402","0.3366","0.2244","-0.2715"
"1.5200","0.3569","-0.4890","0.3569","0.2380","-0.1164"
"1.6000","0.3771","0.1393","0.3771","0.2514","0.0332"
"1.6800","0.3980","0.7951","0.3980","0.2653","0.1893"
"1.7600","0.4188","1.4234","0.4188","0.2792","0.3389"
"1.8400","0.4376","1.9992","0.4376","0.2917","0.4760"
"1.9200","0.4580","2.6124","0.4580","0.3053","0.6220"
"2.0000","0.4777","3.2104","0.4777","0.3185","0.7644"
"2.0800","0.4972","3.8230","0.4972","0.3315","0.9102"
"2.1600","0.5176","4.4509","0.5176","0.3451","1.0597"
"2.2400","0.5368","5.0158","0.5368","0.3578","1.1942"
"2.3200","0.5572","5.6411","0.5572","0.3714","1.3431"
"2.4000","0.5785","6.2864","0.5785","0.3857","1.4968"
"2.4800","0.5981","6.8791","0.5981","0.3987","1.6379"
"2.5600","0.6179","7.4691","0.6179","0.4120","1.7783"
"2.6400","0.6370","8.0295","0.6370","0.4247","1.9118"
"2.7200","0.6567","8.6186","0.6567","0.4378","2.0520"
"2.8000","0.6773","9.2493","0.6773","0.4515","2.2022"
"2.8800","0.6970","9.8238","0.6970","0.4647","2.3390"
"2.9600","0.7181","10.4640","0.7181","0.4787","2.4914"
"3.0400","0.7388","11.0761","0.7388","0.4925","2.6372"
"3.1200","0.7577","11.6478","0.7577","0.5051","2.7733"
"3.2000","0.7777","12.2300","0.7777","0.5184","2.9119"
"3.2800","0.7969","12.7860","0.7969","0.5313","3.0443"
"3.3600","0.8178","13.4123","0.8178","0.5452","3.1934"
"3.4400","0.8380","14.0010","0.8380","0.5587","3.3336"
"3.5200","0.8565","14.5398","0.8565","0.5710","3.4619"
"3.6000","0.8769","15.1383","0.8769","0.5846","3.6044"
"3.6800","0.8980","15.7611","0.8980","0.5987","3.7527"
"3.7600","0.9174","16.3243","0.9174","0.6116","3.8867"
"3.8400","0.9373","16.8822","0.9373","0.6248","4.0196"
"3.9200","0.9565","17.4429","0.9565","0.6376","4.1531"
"4.0000","0.9775","18.0612","0.9775","0.6517","4.3003"
"4.0800","0.9978","18.6439","0.9978","0.6652","4.4390"
"4.1600","1.0174","19.2154","1.0174","0.6783","4.5751"
"4.2400","1.0379","19.8225","1.0379","0.6919","4.7196"
"4.3200","1.0578","20.3803","1.0578","0.7052","4.8525"
"4.4000","1.0787","20.9947","1.0787","0.7192","4.9987"
"4.4800","1.0984","21.5521","1.0984","0.7322","5.1315"
"4.5600","1.1171","22.0802","1.1171","0.7447","5.2572"
"4.6400","1.1371","22.6634","1.1371","0.7581","5.3960"
"4.7200","1.1568","23.2181","1.1568","0.7712","5.5281"
"4.8000","1.1772","23.8180","1.1772","0.7848","5.6710"
"4.8800","1.1986","24.4376","1.1986","0.7990","5.8185"
"4.9600","1.2176","24.9640","1.2176","0.8118","5.9438"
"5.0400","1.2378","25.5367","1.2378","0.8252","6.0802"
"5.1200","1.2573","26.0856","1.2573","0.8382","6.2109"
"5.2000","1.2765","26.6383","1.2765","0.8510","6.3424"
"5.2800","1.2975","27.2473","1.2975","0.8650","6.4875"
"5.3600","1.3170","27.7865","1.3170","0.8780","6.6158"
"5.4400","1.3375","28.3745","1.3375","0.8916","6.7558"
"5.5200","1.3588","28.9925","1.3588","0.9058","6.9030"
"5.6000","1.3780","29.5212","1.3780","0.9187","7.0288"
"5.6800","1.3983","30.0989","1.3983","0.9322","7.1664"
"5.7600","1.4176","30.6353","1.4176","0.9451","7.2941"
"5.8400","1.4375","31.1938","1.4375","0.9583","7.4271"
"5.9200","1.4572","31.7559","1.4572","0.9715","7.5609"
"6.0000","1.4761","32.2753","1.4761","0.9841","7.6846"
"6.0800","1.4973","32.8762","1.4973","0.9982","7.8277"
"6.1600","1.5187","33.4927","1.5187","1.0125","7.9744"
"6.2400","1.5377","34.0169","1.5377","1.0252","8.0993"
"6.3200","1.5574","34.5610","1.5574","1.0382","8.2288"
"6.4000","1.5771","35.1120","1.5771","1.0514","8.3600"
"6.4800","1.5974","35.6873","1.5974","1.0649","8.4970"
"6.5600","1.6180","36.2595","1.6180","1.0787","8.6332"
"6.6400","1.6366","36.7665","1.6366","1.0911","8.7539"
"6.7200","1.6579","37.3724","1.6579","1.1053","8.8982"
"6.8000","1.6783","37.9591","1.6783","1.1189","9.0379"
"6.8800","1.6990","38.5389","1.6990","1.1326","9.1759"
"6.9600","1.7174","39.0305","1.7174","1.1449","9.2930"
"7.0400","1.7366","39.5595","1.7366","1.1578","9.4189"
"7.1200","1.7572","40.1333","1.7572","1.1715","9.5555"
"7.2000","1.7779","40.7116","1.7779","1.1852","9.6932"
"7.2800","1.7969","41.2408","1.7969","1.1979","9.8192"
"7.3600","1.8180","41.8279","1.8180","1.2120","9.9590"
"7.4400","1.8376","42.3577","1.8376","1.2251","10.0852"
"7.5200","1.8578","42.9256","1.8578","1.2385","10.2204"
"7.6000","1.8779","43.4763","1.8779","1.2519","10.3515"
"7.6800","1.8970","43.9909","1.8970","1.2647","10.4740"
"7.7600","1.9173","44.5481","1.9173","1.2782","10.6067"
"7.8400","1.9370","45.0854","1.9370","1.2913","10.7346"
"7.9200","1.9570","45.6380","1.9570","1.3047","10.8662"
"8.0000","1.9784","46.2442","1.9784","1.3189","11.0105"
"8.0800","1.9984","46.7810","1.9984","1.3323","11.1383"
"8.1600","2.0184","47.3205","2.0184","1.3456","11.2668"
"8.2400","2.0380","47.8517","2.0380","1.3586","11.3933"
"8.3200","2.0568","48.3553","2.0568","1.3712","11.5132"
"8.4000","2.0770","48.9116","2.0770","1.3847","11.6456"
"8.4800","2.0969","49.4384","2.0969","1.3979","11.7711"
"8.5600","2.1177","50.0132","2.1177","1.4118","11.9079"
"8.6400","2.1381","50.5644","2.1381","1.4254","12.0391"
"8.7200","2.1578","51.0890","2.1578","1.4385","12.1640"
"8.8000","2.1778","51.6403","2.1778","1.4519","12.2953"
"8.8800","2.1979","52.1816","2.1979","1.4653","12.4242"
"8.9600","2.2170","52.6835","2.2170","1.4780","12.5437"
"9.0400","2.2372","53.2389","2.2372","1.4914","12.6759"
"9.1200","2.2564","53.7454","2.2564","1.5043","12.7965"
"9.2000","2.2785","54.3525","2.2785","1.5190","12.9411"
"9.2800","2.2988","54.8953","2.2988","1.5325","13.0703"
"9.3600","2.3178","55.3962","2.3178","1.5452","13.1896"
"9.4400","2.3375","55.9201","2.3375","1.5583","13.3143"
"9.5200","2.3574","56.4661","2.3574","1.5716","13.4443"
"9.6000","2.3775","57.0102","2.3775","1.5850","13.5739"
"9.6800","2.3979","57.5473","2.3979","1.5986","13.7017"
"9.7600","2.4163","58.0324","2.4163","1.6108","13.8172"
"9.8400","2.4375","58.6227","2.4375","1.6250","13.9578"
"9.9200","2.4582","59.1650","2.4582","1.6388","14.0869"
"10.0000","2.4778","59.6880","2.4778","1.6519","14.2114"
"10.0800","2.4981","60.2330","2.4981","1.6654","14.3412"
"10.1600","2.5172","60.7217","2.5172","1.6781","14.4575"
"10.2400","2.5376","61.2696","2.5376","1.6917","14.5880"
"10.3200","2.5572","61.7830","2.5572","1.7048","14.7102"
"10.4000","2.5765","62.3012","2.5765","1.7177","14.8336"
"10.4800","2.5980","62.8924","2.5980","1.7320","14.9744"
"10.5600","2.6187","63.4359","2.6187","1.7458","15.1038"
"10.6400","2.6383","63.9450","2.6383","1.7589","15.2250"
"10.7200","2.6581","64.4624","2.6581","1.7721","15.3482"
"10.8000","2.6766","64.9424","2.6766","1.7844","15.4625"
"10.8800","2.6975","65.5150","2.6975","1.7983","15.5988"
"10.9600","2.7170","66.0127","2.7170","1.8114","15.7173"
"11.0400","2.7367","66.5479","2.7367","1.8245","15.8447"
"11.1200","2.7576","67.1021","2.7576","1.8384","15.9767"
"11.2000","2.7777","67.6233","2.7777","1.8518","16.1008"
"11.2800","2.7980","68.1646","2.7980","1.8653","16.2297"
"11.3600","2.8181","68.6900","2.8181","1.8787","16.3548"
"11.4400","2.8365","69.1534","2.8365","1.8910","16.4651"
"11.5200","2.8569","69.7113","2.8569","1.9046","16.5979"
"11.6000","2.8770","70.2346","2.8770","1.9180","16.7225"
"11.6800","2.8982","70.8005","2.8982","1.9321","16.8573"
"11.7600","2.9184","71.3271","2.9184","1.9456","16.9826"
"11.8400","2.9376","71.8241","2.9376","1.9584","17.1010"
"11.9200","2.9578","72.3455","2.9578","1.9719","17.2251"
"12.0000","2.9777","72.8705","2.9777","1.9852","17.3501"
"12.0800","2.9974","73.3948","2.9974","1.9983","17.4750"
"12.1600","3.0174","73.9094","3.0174","2.0116","17.5975"
"12.2400","3.0366","74.3951","3.0366","2.0244","17.7131"
"12.3200","3.0573","74.9512","3.0573","2.0382","17.8455"
"12.4000","3.0785","75.5047","3.0785","2.0524","17.9773"
"12.4800","3.0979","76.0091","3.0979","2.0653","18.0974"
"12.5600","3.1182","76.5300","3.1182","2.0788","18.2214"
"12.6400","3.1368","77.0021","3.1368","2.0912","18.3338"
"12.7200","3.1571","77.5381","3.1571","2.1047","18.4615"
"12.8000","3.1773","78.0709","3.1773","2.1182","18.5883"
"12.8800","3.1972","78.5765","3.1972","2.1314","18.7087"
"12.9600","3.2185","79.1584","3.2185","2.1457","18.8472"
"13.0400","3.2388","79.6798","3.2388","2.1592","18.9714"
"13.1200","3.2576","80.1654","3.2576","2.1717","19.0870"
"13.2000","3.2779","80.6921","3.2779","2.1853","19.2124"
"13.2800","3.2971","81.1794","3.2971","2.1980","19.3284"
"13.3600","3.3179","81.7271","3.3179","2.2119","19.4588"
"13.4400","3.3376","82.2304","3.3376","2.2251","19.5787"
"13.5200","3.3561","82.7045","3.3561","2.2374","19.6915"
"13.6000","3.3771","83.2571","3.3771","2.2514","19.8231"
"13.6800","3.3985","83.8254","3.3985","2.2657","19.9584"
"13.7600","3.4180","84.3056","3.4180","2.2787","20.0728"
"13.8400","3.4382","84.8318","3.4382","2.2921","20.1980"
"13.9200","3.4563","85.2695","3.4563","2.3042","20.3023"
"14.0000","3.4773","85.8199","3.4773","2.3182","20.4333"
"14.0800","3.4978","86.3481","3.4978","2.3318","20.5591"
"14.1600","3.5170","86.8451","3.5170","2.3447","20.6774"
"14.2400","3.5378","87.3871","3.5378","2.3586","20.8065"
"14.3200","3.5578","87.8963","3.5578","2.3719","20.9277"
"14.4000","3.5782","88.4163","3.5782","2.3855","21.0515"
"14.4800","3.5980","88.9237","3.5980","2.3987","21.1723"
"14.5600","3.6171","89.4036","3.6171","2.4114","21.2866"
"14.6400","3.6372","89.9232","3.6372","2.4248","21.4103"
"14.7200","3.6567","90.4088","3.6567","2.4378","21.5259"
"14.8000","3.6765","90.9251","3.6765","2.4510","21.6488"
"14.8800","3.6984","91.5115","3.6984","2.4656","21.7884"
"14.9600","3.7178","91.9937","3.7178","2.4785","21.9033"
"15.0400","3.7383","92.5185","3.7383","2.4922","22.0282"
"15.1200","3.7573","92.9930","3.7573","2.5049","22.1412"
"15.2000","3.7766","93.4799","3.7766","2.5177","22.2571"
"15.2800","3.7972","94.0225","3.7972","2.5314","22.3863"
"15.3600","3.8172","94.5245","3.8172","2.5448","22.5058"
"15.4400","3.8377","95.0564","3.8377","2.5584","22.6325"
"15.5200","3.8584","95.5891","3.8584","2.5723","22.7593"
"15.6000","3.8778","96.0821","3.8778","2.5852","22.8767"
"15.6800","3.8983","96.6173","3.8983","2.5988","23.0041"
"15.7600","3.9178","97.1012","3.9178","2.6119","23.1193"
"15.8400","3.9371","97.5995","3.9371","2.6247","23.2380"
"15.9200","3.9573","98.1176","3.9573","2.6382","23.3613"
"16.0000","3.9764","98.5789","3.9764","2.6509","23.4712"
"16.0800","3.9980","99.1352","3.9980","2.6653","23.6036"
"16.1600","4.0186","99.6634","4.0186","2.6791","23.7294"
"16.2400","4.0375","100.1347","4.0375","2.6917","23.8416"
"16.3200","4.0573","100.6336","4.0573","2.7048","23.9604"
"16.4000","4.0770","101.1210","4.0770","2.7180","24.0764"
"16.4800","4.0972","101.6445","4.0972","2.7315","24.2011"
"16.5600","4.1182","102.1718","4.1182","2.7454","24.3266"
"16.6400","4.1367","102.6323","4.1367","2.7578","24.4363"
"16.7200","4.1580","103.1792","4.1580","2.7720","24.5665"
"16.8000","4.1783","103.6973","4.1783","2.7855","24.6898"
"16.8800","4.1982","104.1949","4.1982","2.7988","24.8083"
"16.9600","4.2176","104.6734","4.2176","2.8117","24.9222"
"17.0400","4.2370","105.1511","4.2370","2.8247","25.0360"
"17.1200","4.2572","105.6690","4.2572","2.8381","25.1593"
"17.2000","4.2777","106.1826","4.2777","2.8518","25.2816"
"17.2800","4.2965","106.6505","4.2965","2.8643","25.3930"
"17.3600","4.3177","107.2083","4.3177","2.8785","25.5258"
"17.4400","4.3373","107.6860","4.3373","2.8916","25.6395"
"17.5200","4.3580","108.2134","4.3580","2.9054","25.7651"
"17.6000","4.3780","108.7158","4.3780","2.9186","25.8847"
"17.6800","4.3970","109.1841","4.3970","2.9313","25.9962"
"17.7600","4.4172","109.6893","4.4172","2.9448","26.1165"
"17.8400","4.4372","110.1913","4.4372","2.9581","26.2360"
"17.9200","4.4571","110.6968","4.4571","2.9714","26.3564"
"18.0000","4.4783","111.2582","4.4783","2.9855","26.4900"
"18.0800","4.4983","111.7468","4.4983","2.9989","26.6064"
"18.1600","4.5184","112.2455","4.5184","3.0123","26.7251"
"18.2400","4.5380","112.7159","4.5380","3.0253","26.8371"
"18.3200","4.5567","113.1862","4.5567","3.0378","26.9491"
"18.4000","4.5776","113.7245","4.5776","3.0517","27.0773"
"18.4800","4.5967","114.1851","4.5967","3.0645","27.1869"
"18.5600","4.6175","114.7175","4.6175","3.0783","27.3137"
"18.6400","4.6379","115.2304","4.6379","3.0919","27.4358"
"18.7200","4.6578","115.7287","4.6578","3.1052","27.5544"
"18.8000","4.6777","116.2296","4.6777","3.1185","27.6737"
"18.8800","4.6978","116.7274","4.6978","3.1319","27.7922"
"18.9600","4.7169","117.1906","4.7169","3.1446","27.9025"
"19.0400","4.7374","117.7037","4.7374","3.1583","28.0247"
"19.1200","4.7563","118.1651","4.7563","3.1709","28.1346"
"19.2000","4.7783","118.7380","4.7783","3.1855","28.2709"
"19.2800","4.7985","119.2249","4.7985","3.1990","28.3869"
"19.3600","4.8181","119.7090","4.8181","3.2121","28.5021"
"19.4400","4.8374","120.1671","4.8374","3.2249","28.6112"
"19.5200","4.8573","120.6724","4.8573","3.2382","28.7315"
"19.6000","4.8778","121.1947","4.8778","3.2518","28.8559"
"19.6800","4.8982","121.7085","4.8982","3.2655","28.9782"
"19.7600","4.9165","122.1385","4.9165","3.2777","29.0806"
"19.8400","4.9371","122.6457","4.9371","3.2914","29.2014"
"19.9200","4.9578","123.1682","4.9578","3.3052","29.3258"
"20.0000","4.9779","123.6668","4.9779","3.3186","29.4445"
"20.0800","4.9984","124.1692","4.9984","3.3323","29.5641"
"20.1600","5.0168","124.6034","5.0168","3.3446","29.6675"
"20.2400","5.0370","125.0976","5.0370","3.3580","29.7851"
"20.3200","5.0571","125.5991","5.0571","3.3714","29.9045"
"20.4000","5.0771","126.0927","5.0771","3.3848","30.0221"
"20.4800","5.0983","126.6318","5.0983","3.3988","30.1504"
"20.5600","5.1184","127.1141","5.1184","3.4123","30.2653"
"20.6400","5.1382","127.5920","5.1382","3.4254","30.3790"
"20.7200","5.1581","128.0790","5.1581","3.4388","30.4950"
"20.8000","5.1769","128.5325","5.1769","3.4513","30.6030"
"20.8800","5.1977","129.0584","5.1977","3.4651","30.7282"
"20.9600","5.2171","129.5165","5.2171","3.4781","30.8373"
"21.0400","5.2367","130.0034","5.2367","3.4911","30.9532"
"21.1200","5.2573","130.5150","5.2573","3.5048","31.0750"
"21.2000","5.2778","131.0076","5.2778","3.5185","31.1923"
"21.2800","5.2979","131.4950","5.2979","3.5319","31.3083"
"21.3600","5.3182","131.9887","5.3182","3.5455","31.4259"
"21.4400","5.3363","132.4105","5.3363","3.5576","31.5263"
"21.5200","5.3572","132.9437","5.3572","3.5715","31.6533"
"21.6000","5.3765","133.4043","5.3765","3.5844","31.7629"
"21.6800","5.3977","133.9294","5.3977","3.5984","31.8880"
"21.7600","5.4188","134.4581","5.4188","3.6125","32.0138"
"21.8400","5.4377","134.8915","5.4377","3.6251","32.1170"
"21.9200","5.4578","135.3742","5.4578","3.6386","32.2320"
"22.0000","5.4777","135.8543","5.4777","3.6518","32.3463"
"22.0800","5.4974","136.3413","5.4974","3.6649","32.4622"
"22.1600","5.5176","136.8285","5.5176","3.6784","32.5782"
"22.2400","5.5364","137.2573","5.5364","3.6909","32.6803"
"22.3200","5.5573","137.7847","5.5573","3.7048","32.8059"
"22.4000","5.5784","138.3106","5.5784","3.7189","32.9311"
"22.4800","5.5978","138.7824","5.5978","3.7318","33.0434"
"22.5600","5.6183","139.2853","5.6183","3.7455","33.1632"
"22.6400","5.6370","139.7151","5.6370","3.7580","33.2655"
"22.7200","5.6570","140.1924","5.6570","3.7713","33.3791"
"22.8000","5.6770","140.6781","5.6770","3.7847","33.4948"
"22.8800","5.6972","141.1697","5.6972","3.7981","33.6118"
"22.9600","5.7181","141.6902","5.7181","3.8121","33.7358"
"23.0400","5.7390","142.2072","5.7390","3.8260","33.8589"
"23.1200","5.7577","142.6365","5.7577","3.8384","33.9611"
"23.2000","5.7778","143.1262","5.7778","3.8519","34.0777"
"23.2800","5.7972","143.5766","5.7972","3.8648","34.1849"
"23.3600","5.8182","144.0874","5.8182","3.8788","34.3065"
"23.4400","5.8378","144.5460","5.8378","3.8919","34.4157"
"23.5200","5.8562","144.9806","5.8562","3.9042","34.5192"
"23.6000","5.8770","145.4960","5.8770","3.9180","34.6419"
"23.6800","5.8983","146.0222","5.8983","3.9322","34.7672"
"23.7600","5.9181","146.4873","5.9181","3.9454","34.8779"
"23.8400","5.9378","146.9606","5.9378","3.9585","34.9906"
"23.9200","5.9567","147.3951","5.9567","3.9711","35.0941"
"24.0000","5.9772","147.9007","5.9772","3.9848","35.2145"
"24.0800","5.9979","148.3940","5.9979","3.9986","35.3319"
"24.1600","6.0171","148.8469","6.0171","4.0114","35.4397"
"24.2400","6.0375","149.3362","6.0375","4.0250","35.5562"
"24.3200","6.0577","149.8115","6.0577","4.0385","35.6694"
"24.4000","6.0787","150.3223","6.0787","4.0524","35.7910"
"24.4800","6.0984","150.7955","6.0984","4.0656","35.9037"
"24.5600","6.1176","151.2353","6.1176","4.0784","36.0084"
"24.6400","6.1371","151.6984","6.1371","4.0914","36.1187"
"24.7200","6.1570","152.1680","6.1570","4.1047","36.2305"
"24.8000","6.1765","152.6270","6.1765","4.1177","36.3398"
"24.8800","6.1983","153.1724","6.1983","4.1322","36.4696"
"24.9600","6.2179","153.6148","6.2179","4.1453","36.5750"
"25.0400","6.2383","154.0849","6.2383","4.1588","36.6869"
"25.1200","6.2568","154.5146","6.2568","4.1712","36.7892"
"25.2000","6.2766","154.9809","6.2766","4.1844","36.9002"
"25.2800","6.2973","155.4897","6.2973","4.1982","37.0213"
"25.3600","6.3170","155.9382","6.3170","4.2114","37.1281"
"25.4400","6.3378","156.4391","6.3378","4.2252","37.2474"
"25.5200","6.3586","156.9360","6.3586","4.2391","37.3657"
"25.6000","6.3779","157.3875","6.3779","4.2519","37.4732"
"25.6800","6.3986","157.8896","6.3986","4.2657","37.5928"
"25.7600","6.4178","158.3189","6.4178","4.2785","37.6950"
"25.8400","6.4373","158.7862","6.4373","4.2916","37.8062"
"25.9200","6.4574","159.2551","6.4574","4.3050","37.9179"
"26.0000","6.4761","159.6670","6.4761","4.3174","38.0160"
"26.0800","6.4978","160.1990","6.4978","4.3319","38.1426"
"26.1600","6.5186","160.7029","6.5186","4.3457","38.2626"
"26.2400","6.5378","161.1349","6.5378","4.3585","38.3655"
"26.3200","6.5574","161.5927","6.5574","4.3716","38.4745"
"26.4000","6.5770","162.0406","6.5770","4.3847","38.5811"
"26.4800","6.5974","162.5374","6.5974","4.3983","38.6994"
"26.5600","6.6183","163.0243","6.6183","4.4122","38.8153"
"26.6400","6.6364","163.4213","6.6364","4.4242","38.9098"
"26.7200","6.6577","163.9427","6.6577","4.4385","39.0340"
"26.8000","6.6787","164.4442","6.6787","4.4525","39.1534"
"26.8800","6.6981","164.8868","6.6981","4.4654","39.2588"
"26.9600","6.7174","165.3363","6.7174","4.4783","39.3658"
"27.0400","6.7368","165.7623","6.7368","4.4912","39.4672"
"27.1200","6.7574","166.2540","6.7574","4.5050","39.5843"
"27.2000","6.7776","166.7195","6.7776","4.5184","39.6951"
"27.2800","6.7968","167.1598","6.7968","4.5312","39.7999"
"27.3600","6.8176","167.6575","6.8176","4.5451","39.9184"
"27.4400","6.8375","168.1099","6.8375","4.5583","40.0262"
"27.5200","6.8581","168.5927","6.8581","4.5721","40.1411"
"27.6000","6.8776","169.0370","6.8776","4.5851","40.2469"
"27.6800","6.8970","169.4893","6.8970","4.5980","40.3546"
"27.7600","6.9172","169.9517","6.9172","4.6115","40.4647"
"27.8400","6.9370","170.4086","6.9370","4.6247","40.5735"
"27.9200","6.9572","170.8828","6.9572","4.6381","40.6864"
"28.0000","6.9784","171.3874","6.9784","4.6522","40.8065"
"28.0800","6.9985","171.8495","6.9985","4.6657","40.9166"
"28.1600","7.0184","172.3052","7.0184","4.6789","41.0250"
"28.2400","7.0380","172.7468","7.0380","4.6920","41.1302"
"28.3200","7.0568","173.1745","7.0568","4.7045","41.2320"
"28.4000","7.0774","173.6669","7.0774","4.7183","41.3493"
"28.4800","7.0966","174.1037","7.0966","4.7311","41.4533"
"28.5600","7.1175","174.5941","7.1175","4.7450","41.5700"
"28.6400","7.1380","175.0694","7.1380","4.7587","41.6832"
"28.7200","7.1580","175.5260","7.1580","4.7720","41.7919"
"28.8000","7.1775","175.9685","7.1775","4.7850","41.8973"
"28.8800","7.1977","176.4440","7.1977","4.7985","42.0105"
"28.9600","7.2168","176.8724","7.2168","4.8112","42.1125"
"29.0400","7.2375","177.3545","7.2375","4.8250","42.2273"
"29.1200","7.2562","177.7713","7.2562","4.8375","42.3265"
"29.2000","7.2777","178.2808","7.2777","4.8518","42.4478"
"29.2800","7.2991","178.7906","7.2991","4.8660","42.5692"
"29.3600","7.3182","179.2137","7.3182","4.8788","42.6699"
"29.4400","7.3376","179.6391","7.3376","4.8917","42.7712"
"29.5200","7.3572","180.0766","7.3572","4.9048","42.8754"
"29.6000","7.3775","180.5498","7.3775","4.9184","42.9880"
"29.6800","7.3981","181.0218","7.3981","4.9321","43.1004"
"29.7600","7.4163","181.3993","7.4163","4.9442","43.1903"
"29.8400","7.4372","181.9002","7.4372","4.9581","43.3096"
"29.9200","7.4582","182.3913","7.4582","4.9721","43.4265"
"30.0000","7.4779","182.8395","7.4779","4.9853","43.5332"
"30.0800","7.4981","183.2998","7.4981","4.9988","43.6428"
"30.1600","7.5168","183.6942","7.5168","5.0112","43.7367"
"30.2400","7.5373","184.1626","7.5373","5.0249","43.8482"
"30.3200","7.5574","184.6132","7.5574","5.0383","43.9555"
"30.4000","7.5773","185.0717","7.5773","5.0515","44.0647"
"30.4800","7.5979","185.5512","7.5979","5.0653","44.1789"
"30.5600","7.6186","186.0314","7.6186","5.0790","44.2932"
"30.6400","7.6385","186.4828","7.6385","5.0923","44.4007"
"30.7200","7.6582","186.9219","7.6582","5.1055","44.5052"
"30.8000","7.6770","187.3264","7.6770","5.1180","44.6015"
"30.8800","7.6978","187.7966","7.6978","5.1319","44.7135"
"30.9600","7.7169","188.2156","7.7169","5.1446","44.8132"
"31.0400","7.7366","188.6691","7.7366","5.1577","44.9212"
"31.1200","7.7575","189.1567","7.7575","5.1716","45.0373"
"31.2000","7.7781","189.6249","7.7781","5.1854","45.1488"
"31.2800","7.7983","190.0846","7.7983","5.1988","45.2582"
"31.3600","7.8182","190.5219","7.8182","5.2121","45.3624"
"31.4400","7.8365","190.9146","7.8365","5.2243","45.4559"
"31.5200","7.8570","191.3836","7.8570","5.2380","45.5675"
"31.6000","7.8770","191.8307","7.8770","5.2513","45.6740"
"31.6800","7.8979","192.3292","7.8979","5.2653","45.7927"
"31.7600","7.9190","192.8120","7.9190","5.2793","45.9076"
"31.8400","7.9379","193.2198","7.9379","5.2919","46.0047"
"31.9200","7.9575","193.6385","7.9575","5.3050","46.1044"
"32.0000","7.9776","194.0971","7.9776","5.3184","46.2136"
"32.0800","7.9973","194.5419","7.9973","5.3315","46.3195"
"32.1600","8.0174","194.9942","8.0174","5.3449","46.4272"
"32.2400","8.0367","195.3992","8.0367","5.3578","46.5236"
"32.3200","8.0575","195.8854","8.0575","5.3716","46.6394"
"32.4000","8.0787","196.3744","8.0787","5.3858","46.7558"
"32.4800","8.0979","196.7994","8.0979","5.3986","46.8570"
"32.5600","8.1182","197.2588","8.1182","5.4121","46.9664"
"32.6400","8.1367","197.6410","8.1367","5.4244","47.0574"
"32.7200","8.1568","198.1000","8.1568","5.4378","47.1667"
"32.8000","8.1769","198.5491","8.1769","5.4513","47.2736"
"32.8800","8.1972","198.9997","8.1972","5.4648","47.3809"
"32.9600","8.2180","199.4811","8.2180","5.4787","47.4955"
"33.0400","8.2389","199.9428","8.2389","5.4926","47.6054"
"33.1200","8.2575","200.3390","8.2575","5.5050","47.6998"
"33.2000","8.2777","200.8004","8.2777","5.5185","47.8096"
"33.2800","8.2971","201.2066","8.2971","5.5314","47.9063"
"33.3600","8.3180","201.6928","8.3180","5.5454","48.0221"
"33.4400","8.3375","202.1156","8.3375","5.5583","48.1228"
"33.5200","8.3562","202.5128","8.3562","5.5708","48.2173"
"33.6000","8.3771","202.9989","8.3771","5.5847","48.3331"
"33.6800","8.3985","203.4900","8.3985","5.5990","48.4500"
"33.7600","8.4182","203.9189","8.4182","5.6121","48.5521"
"33.8400","8.4376","204.3302","8.4376","5.6251","48.6501"
"33.9200","8.4564","204.7254","8.4564","5.6376","48.7441"
"34.0000","8.4775","205.2191","8.4775","5.6516","48.8617"
"34.0800","8.4981","205.6836","8.4981","5.6654","48.9723"
"34.1600","8.5174","206.1107","8.5174","5.6782","49.0740"
"34.2400","8.5380","206.5771","8.5380","5.6920","49.1850"
"34.3200","8.5572","206.9791","8.5572","5.7048","49.2807"
"34.4000","8.5784","207.4621","8.5784","5.7189","49.3957"
"34.4800","8.5984","207.8918","8.5984","5.7323","49.4980"
"34.5600","8.6171","208.2927","8.6171","5.7448","49.5935"
"34.6400","8.6368","208.7167","8.6368","5.7578","49.6945"
"34.7200","8.6568","209.1551","8.6568","5.7712","49.7988"
"34.8000","8.6767","209.6054","8.6767","5.7845","49.9060"
"34.8800","8.6986","210.1136","8.6986","5.7991","50.0270"
"34.9600","8.7178","210.5148","8.7178","5.8119","50.1226"
"35.0400","8.7381","210.9628","8.7381","5.8254","50.2292"
"35.1200","8.7573","211.3749","8.7573","5.8382","50.3274"
"35.2000","8.7767","211.7907","8.7767","5.8511","50.4264"
"35.2800","8.7969","212.2479","8.7969","5.8646","50.5352"
"35.3600","8.8170","212.6759","8.8170","5.8780","50.6371"
"35.4400","8.8376","213.1453","8.8376","5.8917","50.7489"
"35.5200","8.8587","213.6156","8.8587","5.9058","50.8609"
"35.6000","8.8778","214.0180","8.8778","5.9186","50.9567"
"35.6800","8.8984","214.4831","8.8984","5.9323","51.0674"
"35.7600","8.9176","214.8806","8.9176","5.9451","51.1620"
"35.8400","8.9374","215.3191","8.9374","5.9583","51.2665"
"35.9200","8.9573","215.7598","8.9573","5.9716","51.3714"
"36.0000","8.9762","216.1593","8.9762","5.9841","51.4665"
"36.0800","8.9978","216.6536","8.9978","5.9985","51.5842"
"36.1600","9.0189","217.1285","9.0189","6.0126","51.6973"
"36.2400","9.0378","217.5124","9.0378","6.0252","51.7887"
"36.3200","9.0572","217.9375","9.0572","6.0381","51.8899"
"36.4000","9.0771","218.3506","9.0771","6.0514","51.9882"
"36.4800","9.0972","218.8097","9.0972","6.0648","52.0975"
"36.5600","9.1179","219.2567","9.1179","6.0786","52.2040"
"36.6400","9.1364","219.6473","9.1364","6.0909","52.2970"
"36.7200","9.1577","220.1243","9.1577","6.1052","52.4105"
"36.8000","9.1783","220.5839","9.1783","6.1189","52.5200"
"36.8800","9.1985","221.0148","9.1985","6.1324","52.6226"
"36.9600","9.2180","221.4379","9.2180","6.1454","52.7233"
"37.0400","9.2373","221.8313","9.2373","6.1582","52.8170"
"37.1200","9.2572","222.2682","9.2572","6.1715","52.9210"
"37.2000","9.2776","222.7154","9.2776","6.1851","53.0275"
"37.2800","9.2966","223.1246","9.2966","6.1977","53.1249"
"37.3600","9.3181","223.6139","9.3181","6.2121","53.2414"
"37.4400","9.3376","224.0181","9.3376","6.2251","53.3376"
"37.5200","9.3579","224.4643","9.3579","6.2386","53.4439"
"37.6000","9.3777","224.8836","9.3777","6.2518","53.5437"
"37.6800","9.3968","225.2889","9.3968","6.2645","53.6402"
"37.7600","9.4171","225.7309","9.4171","6.2781","53.7454"
"37.8400","9.4371","226.1649","9.4371","6.2914","53.8488"
"37.9200","9.4570","226.5960","9.4570","6.3047","53.9514"
"38.0000","9.4784","227.0895","9.4784","6.3190","54.0689"
"38.0800","9.4984","227.5057","9.4984","6.3323","54.1680"
"38.1600","9.5184","227.9442","9.5184","6.3456","54.2724"
"38.2400","9.5380","228.3473","9.5380","6.3587","54.3684"
"38.3200","9.5565","228.7362","9.5565","6.3710","54.4610"
"38.4000","9.5775","229.2085","9.5775","6.3850","54.5734"
"38.4800","9.5967","229.6065","9.5967","6.3978","54.6682"
"38.5600","9.6176","230.0633","9.6176","6.4118","54.7770"
"38.6400","9.6376","230.4969","9.6376","6.4251","54.8802"
"38.7200","9.6578","230.9461","9.6578","6.4386","54.9872"
"38.8000","9.6775","231.3561","9.6775","6.4517","55.0848"
"38.8800","9.6979","231.7906","9.6979","6.4653","55.1882"
"38.9600","9.7169","232.1853","9.7169","6.4779","55.2822"
"39.0400","9.7374","232.6470","9.7374","6.4916","55.3922"
"39.1200","9.7563","233.0235","9.7563","6.5042","55.4818"
"39.2000","9.7780","233.5308","9.7780","6.5187","55.6026"
"39.2800","9.7985","233.9724","9.7985","6.5324","55.7077"
"39.3600","9.8181","234.3876","9.8181","6.5454","55.8066"
"39.4400","9.8376","234.7919","9.8376","6.5584","55.9028"
"39.5200","9.8574","235.2126","9.8574","6.5716","56.0030"
"39.6000","9.8774","235.6402","9.8774","6.5849","56.1048"
"39.6800","9.8979","236.0896","9.8979","6.5986","56.2118"
"39.7600","9.9166","236.4687","9.9166","6.6111","56.3021"
"39.8400","9.9378","236.9403","9.9378","6.6252","56.4144"
"39.9200","9.9582","237.3967","9.9582","6.6388","56.5230"
"40.0000","9.9778","237.8153","9.9778","6.6519","56.6227"
"40.0800","9.9978","238.2405","9.9978","6.6652","56.7239"
"40.1600","10.0168","238.6294","10.0168","6.6779","56.8165"
"40.2400","10.0373","239.0689","10.0373","6.6915","56.9212"
"40.3200","10.0572","239.4953","10.0572","6.7048","57.0227"
"40.4000","10.0770","239.9133","10.0770","6.7180","57.1222"
"40.4800","10.0978","240.3823","10.0978","6.7319","57.2339"
"40.5600","10.1186","240.8232","10.1186","6.7457","57.3388"
"40.6400","10.1380","241.2202","10.1380","6.7587","57.4334"
"40.7200","10.1583","241.6569","10.1583","6.7722","57.5374"
"40.8000","10.1770","242.0320","10.1770","6.7846","57.6267"
"40.8800","10.1978","242.4805","10.1978","6.7986","57.7335"
"40.9600","10.2172","242.8804","10.2172","6.8115","57.8287"
"41.0400","10.2369","243.2907","10.2369","6.8246","57.9264"
"41.1200","10.2571","243.7377","10.2571","6.8380","58.0328"
"41.2000","10.2781","244.1890","10.2781","6.8520","58.1402"
"41.2800","10.2981","244.6079","10.2981","6.8654","58.2400"
"41.3600","10.3182","245.0438","10.3182","6.8788","58.3438"
"41.4400","10.3368","245.4100","10.3368","6.8912","58.4310"
"41.5200","10.3571","245.8588","10.3571","6.9048","58.5378"
"41.6000","10.3765","246.2513","10.3765","6.9176","58.6313"
"41.6800","10.3976","246.7348","10.3976","6.9317","58.7464"
"41.7600","10.4190","247.2035","10.4190","6.9460","58.8580"
"41.8400","10.4379","247.5713","10.4379","6.9586","58.9455"
"41.9200","10.4580","248.0015","10.4580","6.9720","59.0480"
"42.0000","10.4780","248.4496","10.4780","6.9854","59.1547"
"42.0800","10.4975","248.8414","10.4975","6.9983","59.2480"
"42.1600","10.5172","249.2599","10.5172","7.0115","59.3476"
"42.2400","10.5365","249.6441","10.5365","7.0244","59.4391"
"42.3200","10.5572","250.1009","10.5572","7.0381","59.5478"
"42.4000","10.5787","250.5718","10.5787","7.0524","59.6600"
"42.4800","10.5978","250.9712","10.5978","7.0652","59.7550"
"42.5600","10.6182","251.3979","10.6182","7.0788","59.8566"
"42.6400","10.6368","251.7575","10.6368","7.0912","59.9423"
"42.7200","10.6570","252.1983","10.6570","7.1047","60.0472"
"42.8000","10.6773","252.6387","10.6773","7.1182","60.1521"
"42.8800","10.6972","253.0476","10.6972","7.1315","60.2494"
"42.9600","10.7179","253.4950","10.7179","7.1453","60.3560"
"43.0400","10.7387","253.9331","10.7387","7.1591","60.4603"
"43.1200","10.7577","254.3191","10.7577","7.1718","60.5522"
"43.2000","10.7778","254.7504","10.7778","7.1852","60.6549"
"43.2800","10.7971","255.1400","10.7971","7.1981","60.7476"
"43.3600","10.8178","255.6052","10.8178","7.2119","60.8584"
"43.4400","10.8375","255.9948","10.8375","7.2250","60.9511"
"43.5200","10.8566","256.3873","10.8566","7.2377","61.0446"
"43.6000","10.8770","256.8289","10.8770","7.2513","61.1497"
"43.6800","10.8980","257.2827","10.8980","7.2653","61.2578"
"43.7600","10.9180","257.7081","10.9180","7.2787","61.3591"
"43.8400","10.9376","258.1161","10.9376","7.2917","61.4562"
"43.9200","10.9567","258.4884","10.9567","7.3044","61.5449"
"44.0000","10.9776","258.9464","10.9776","7.3184","61.6539"
"44.0800","10.9978","259.3690","10.9978","7.3319","61.7545"
"44.1600","11.0165","259.7385","11.0165","7.3443","61.8425"
"44.2400","11.0377","260.2079","11.0377","7.3585","61.9543"
"44.3200","11.0578","260.6134","11.0578","7.3719","62.0508"
"44.4000","11.0787","261.0610","11.0787","7.3858","62.1574"
"44.4800","11.0983","261.4622","11.0983","7.3988","62.2529"
"44.5600","11.1175","261.8568","11.1175","7.4117","62.3468"
"44.6400","11.1372","262.2841","11.1372","7.4248","62.4486"
"44.7200","11.1569","262.6731","11.1569","7.4379","62.5412"
"44.8000","11.1769","263.1172","11.1769","7.4513","62.6469"
"44.8800","11.1987","263.5796","11.1987","7.4658","62.7570"
"44.9600","11.2180","263.9638","11.2180","7.4787","62.8485"
"45.0400","11.2383","264.3858","11.2383","7.4922","62.9490"
"45.1200","11.2568","264.7406","11.2568","7.5045","63.0335"
"45.2000","11.2767","265.1714","11.2767","7.5178","63.1360"
"45.2800","11.2972","265.6171","11.2972","7.5314","63.2422"
"45.3600","11.3172","266.0229","11.3172","7.5448","63.3388"
"45.4400","11.3376","266.4656","11.3376","7.5584","63.4442"
"45.5200","11.3586","266.9208","11.3586","7.5724","63.5526"
"45.6000","11.3780","267.3138","11.3780","7.5853","63.6462"
"45.6800","11.3985","267.7511","11.3985","7.5990","63.7503"
"45.7600","11.4177","268.1223","11.4177","7.6118","63.8386"
"45.8400","11.4371","268.5338","11.4371","7.6247","63.9366"
"45.9200","11.4570","268.9489","11.4570","7.6380","64.0355"
"46.0000","11.4763","269.3434","11.4763","7.6508","64.1294"
"46.0800","11.4978","269.8258","11.4978","7.6652","64.2442"
"46.1600","11.5184","270.2661","11.5184","7.6789","64.3491"
"46.2400","11.5379","270.6578","11.5379","7.6920","64.4423"
"46.3200","11.5571","271.0451","11.5571","7.7047","64.5346"
"46.4000","11.5766","271.4447","11.5766","7.7178","64.6297"
"46.4800","11.5970","271.8941","11.5970","7.7314","64.7367"
"46.5600","11.6182","272.3520","11.6182","7.7454","64.8457"
"46.6400","11.6367","272.7149","11.6367","7.7578","64.9321"
"46.7200","11.6581","273.1970","11.6581","7.7721","65.0469"
"46.8000","11.6784","273.6296","11.6784","7.7856","65.1499"
"46.8800","11.6989","274.0571","11.6989","7.7993","65.2517"
"46.9600","11.7176","274.4194","11.7176","7.8117","65.3380"
"47.0400","11.7369","274.8041","11.7369","7.8246","65.4295"
"47.1200","11.7571","275.2350","11.7571","7.8381","65.5321"
"47.2000","11.7779","275.6831","11.7779","7.8519","65.6388"
"47.2800","11.7971","276.0855","11.7971","7.8647","65.7347"
"47.3600","11.8178","276.5395","11.8178","7.8786","65.8427"
"47.4400","11.8375","276.9306","11.8375","7.8917","65.9359"
"47.5200","11.8578","277.3696","11.8578","7.9052","66.0404"
"47.6000","11.8777","277.7808","11.8777","7.9185","66.1383"
"47.6800","11.8968","278.1617","11.8968","7.9312","66.2290"
"47.7600","11.9175","278.6109","11.9175","7.9450","66.3359"
"47.8400","11.9372","279.0145","11.9372","7.9581","66.4320"
"47.9200","11.9572","279.4356","11.9572","7.9714","66.5323"
"48.0000","11.9786","279.9256","11.9786","7.9857","66.6489"
"48.0800","11.9983","280.3166","11.9983","7.9989","66.7420"
"48.1600","12.0184","280.7415","12.0184","8.0123","66.8432"
"48.2400","12.0378","281.1278","12.0378","8.0252","66.9352"
"48.3200","12.0565","281.5112","12.0565","8.0377","67.0265"
"48.4000","12.0776","281.9753","12.0776","8.0517","67.1370"
"48.4800","12.0966","282.3481","12.0966","8.0644","67.2257"
"48.5600","12.1178","282.8174","12.1178","8.0785","67.3375"
"48.6400","12.1381","283.2548","12.1381","8.0921","67.4416"
"48.7200","12.1577","283.6500","12.1577","8.1051","67.5357"
"48.8000","12.1775","284.0594","12.1775","8.1184","67.6332"
"48.8800","12.1979","284.4896","12.1979","8.1320","67.7356"
"48.9600","12.2171","284.8734","12.2171","8.1447","67.8270"
"49.0400","12.2373","285.3044","12.2373","8.1582","67.9296"
"49.1200","12.2563","285.6767","12.2563","8.1709","68.0183"
"49.2000","12.2781","286.1779","12.2781","8.1854","68.1376"
"49.2800","12.2989","286.6175","12.2989","8.1992","68.2423"
"49.3600","12.3184","287.0130","12.3184","8.2123","68.3364"
"49.4400","12.3373","287.3799","12.3373","8.2249","68.4238"
"49.5200","12.3571","287.7925","12.3571","8.2381","68.5220"
"49.6000","12.3773","288.2123","12.3773","8.2515","68.6220"
"49.6800","12.3980","288.6703","12.3980","8.2653","68.7310"
"49.7600","12.4166","289.0329","12.4166","8.2778","68.8174"
"49.8400","12.4372","289.4868","12.4372","8.2915","68.9254"
"49.9200","12.4579","289.9192","12.4579","8.3053","69.0284"
"50.0000","12.4780","290.3520","12.4780","8.3187","69.1314"
"50.0800","12.4981","290.7619","12.4981","8.3321","69.2290"
"50.1600","12.5169","291.1229","12.5169","8.3446","69.3150"
"50.2400","12.5374","291.5566","12.5374","8.3583","69.4182"
"50.3200","12.5570","291.9595","12.5570","8.3714","69.5142"
"50.4000","12.5769","292.3856","12.5769","8.3846","69.6156"
"50.4800","12.5980","292.8552","12.5980","8.3986","69.7274"
"50.5600","12.6187","293.2856","12.6187","8.4124","69.8299"
"50.6400","12.6382","293.6799","12.6382","8.4255","69.9238"
"50.7200","12.6584","294.1034","12.6584","8.4389","70.0246"
"50.8000","12.6767","294.4455","12.6767","8.4511","70.1061"
"50.8800","12.6974","294.8874","12.6974","8.4650","70.2113"
"50.9600","12.7167","295.2733","12.7167","8.4778","70.3032"
"51.0400","12.7370","295.7063","12.7370","8.4913","70.4063"
"51.1200","12.7570","296.1382","12.7570","8.5047","70.5091"
"51.2000","12.7781","296.5807","12.7781","8.5188","70.6144"
"51.2800","12.7979","296.9952","12.7979","8.5319","70.7131"
"51.3600","12.8184","297.4282","12.8184","8.5456","70.8162"
"51.4400","12.8369","297.7748","12.8369","8.5579","70.8988"
"51.5200","12.8572","298.2077","12.8572","8.5714","71.0018"
"51.6000","12.8767","298.6061","12.8767","8.5845","71.0967"
"51.6800","12.8976","299.0688","12.8976","8.5984","71.2068"
"51.7600","12.9188","299.5428","12.9188","8.6125","71.3197"
"51.8400","12.9380","299.9204","12.9380","8.6254","71.4096"
"51.9200","12.9581","300.3369","12.9581","8.6387","71.5088"
"52.0000","12.9779","300.7546","12.9779","8.6519","71.6082"
"52.0800","12.9973","301.1484","12.9973","8.6648","71.7020"
"52.1600","13.0171","301.5566","13.0171","8.6781","71.7992"
"52.2400","13.0363","301.9247","13.0363","8.6908","71.8868"
"52.3200","13.0576","302.4259","13.0576","8.7051","72.0062"
"52.4000","13.0786","302.8738","13.0786","8.7191","72.1128"
"52.4800","13.0978","303.2622","13.0978","8.7319","72.2053"
"52.5600","13.1181","303.6757","13.1181","8.7454","72.3037"
"52.6400","13.1368","304.0340","13.1368","8.7579","72.3890"
"52.7200","13.1570","304.4627","13.1570","8.7714","72.4911"
"52.8000","13.1769","304.8743","13.1769","8.7846","72.5891"
"52.8800","13.1971","305.2962","13.1971","8.7981","72.6896"
"52.9600","13.2181","305.7432","13.2181","8.8121","72.7960"
"53.0400","13.2388","306.1815","13.2388","8.8259","72.9004"
"53.1200","13.2577","306.5468","13.2577","8.8385","72.9873"
"53.2000","13.2777","306.9637","13.2777","8.8518","73.0866"
"53.2800","13.2972","307.3569","13.2972","8.8648","73.1802"
"53.3600","13.3180","307.7987","13.3180","8.8786","73.2854"
"53.4400","13.3376","308.1982","13.3376","8.8918","73.3805"
"53.5200","13.3567","308.5780","13.3567","8.9044","73.4710"
"53.6000","13.3772","309.0135","13.3772","8.9181","73.5746"
"53.6800","13.3983","309.4632","13.3983","8.9322","73.6817"
"53.7600","13.4180","309.8589","13.4180","8.9453","73.7759"
"53.8400","13.4378","310.2625","13.4378","8.9585","73.8720"
"53.9200","13.4565","310.6133","13.4565","8.9710","73.9555"
"54.0000","13.4774","311.0773","13.4774","8.9849","74.0660"
"54.0800","13.4978","311.5170","13.4978","8.9986","74.1707"
"54.1600","13.5174","311.9195","13.5174","9.0116","74.2666"
"54.2400","13.5381","312.3610","13.5381","9.0254","74.3717"
"54.3200","13.5578","312.7447","13.5578","9.0386","74.4630"
"54.4000","13.5786","313.1935","13.5786","9.0524","74.5699"
"54.4800","13.5983","313.5886","13.5983","9.0655","74.6639"
"54.5600","13.6173","313.9644","13.6173","9.0782","74.7534"
"54.6400","13.6370","314.3631","13.6370","9.0913","74.8484"
"54.7200","13.6569","314.7674","13.6569","9.1046","74.9446"
"54.8000","13.6770","315.1981","13.6770","9.1180","75.0472"
"54.8800","13.6986","315.6710","13.6986","9.1324","75.1598"
"54.9600","13.7174","316.0228","13.7174","9.1449","75.2435"
"55.0400","13.7380","316.4632","13.7380","9.1587","75.3484"
"55.1200","13.7575","316.8456","13.7575","9.1717","75.4394"
"55.2000","13.7768","317.2372","13.7768","9.1845","75.5327"
"55.2800","13.7968","317.6543","13.7968","9.1979","75.6320"
"55.3600","13.8171","318.0634","13.8171","9.2114","75.7294"
"55.4400","13.8377","318.5150","13.8377","9.2252","75.8369"
"55.5200","13.8588","318.9614","13.8588","9.2392","75.9432"
"55.6000","13.8781","319.3382","13.8781","9.2520","76.0329"
"55.6800","13.8982","319.7500","13.8982","9.2655","76.1309"
"55.7600","13.9174","320.1124","13.9174","9.2783","76.2172"
"55.8400","13.9371","320.5281","13.9371","9.2914","76.3162"
"55.9200","13.9572","320.9290","13.9572","9.3048","76.4117"
"56.0000","13.9761","321.2888","13.9761","9.3174","76.4973"
"56.0800","13.9977","321.7794","13.9977","9.3318","76.6142"
"56.1600","14.0188","322.2395","14.0188","9.3458","76.7237"
"56.2400","14.0378","322.5981","14.0378","9.3585","76.8091"
"56.3200","14.0573","322.9873","14.0573","9.3715","76.9017"
"56.4000","14.0772","323.3813","14.0772","9.3848","76.9955"
"56.4800","14.0974","323.8158","14.0974","9.3983","77.0990"
"56.5600","14.1180","324.2403","14.1180","9.4120","77.2001"
"56.6400","14.1366","324.5898","14.1366","9.4244","77.2833"
"56.7200","14.1577","325.0542","14.1577","9.4384","77.3939"
"56.8000","14.1784","325.4843","14.1784","9.4522","77.4963"
"56.8800","14.1987","325.9084","14.1987","9.4658","77.5972"
"56.9600","14.2180","326.2906","14.2180","9.4786","77.6882"
"57.0400","14.2372","326.6536","14.2372","9.4915","77.7747"
"57.1200","14.2572","327.0713","14.2572","9.5048","77.8741"
"57.2000","14.2776","327.4940","14.2776","9.5184","77.9748"
"57.2800","14.2963","327.8514","14.2963","9.5309","78.0599"
"57.3600","14.3176","328.3215","14.3176","9.5451","78.1718"
"57.4400","14.3373","328.7028","14.3373","9.5582","78.2626"
"57.5200","14.3579","329.1443","14.3579","9.5720","78.3677"
"57.6000","14.3779","329.5375","14.3779","9.5853","78.4613"
"57.6800","14.3971","329.9243","14.3971","9.5981","78.5534"
"57.7600","14.4173","330.3367","14.4173","9.6116","78.6516"
"57.8400","14.4367","330.7108","14.4367","9.6245","78.7407"
"57.9200","14.4570","331.1398","14.4570","9.6380","78.8428"
"58.0000","14.4786","331.6242","14.4786","9.6524","78.9581"
"58.0800","14.4985","332.0052","14.4985","9.6657","79.0489"
"58.1600","14.5183","332.4039","14.5183","9.6788","79.1438"
"58.2400","14.5379","332.7713","14.5379","9.6919","79.2313"
"58.3200","14.5566","333.1429","14.5566","9.7044","79.3197"
"58.4000","14.5773","333.5702","14.5773","9.7182","79.4215"
"58.4800","14.5968","333.9407","14.5968","9.7312","79.5097"
"58.5600","14.6174","334.3770","14.6174","9.7450","79.6136"
"58.6400","14.6377","334.7978","14.6377","9.7585","79.7138"
"58.7200","14.6578","335.1810","14.6578","9.7719","79.8050"
"58.8000","14.6780","335.5815","14.6780","9.7853","79.9004"
"58.8800","14.6978","335.9641","14.6978","9.7985","79.9915"
"58.9600","14.7171","336.3300","14.7171","9.8114","80.0786"
"59.0400","14.7372","336.7393","14.7372","9.8248","80.1760"
"59.1200","14.7562","337.0733","14.7562","9.8374","80.2555"
"59.2000","14.7781","337.5609","14.7781","9.8520","80.3717"
"59.2800","14.7989","337.9791","14.7989","9.8659","80.4712"
"59.3600","14.8184","338.3522","14.8184","9.8789","80.5600"
"59.4400","14.8375","338.7002","14.8375","9.8917","80.6429"
"59.5200","14.8571","339.0703","14.8571","9.9047","80.7310"
"59.6000","14.8775","339.4851","14.8775","9.9184","80.8298"
"59.6800","14.8978","339.8744","14.8978","9.9319","80.9225"
"59.7600","14.9165","340.2069","14.9165","9.9443","81.0016"
"59.8400","14.9371","340.6245","14.9371","9.9581","81.1011"
"59.9200","14.9578","341.0320","14.9578","9.9718","81.1981"
"60.0000","14.9783","341.4496","14.9783","9.9856","81.2975"
"60.0800","14.9982","341.8106","14.9982","9.9988","81.3835"
"60.0880","15.0002","341.8443","15.0002","10.0001","81.3915"