File: data/instron_tests/metamaterials/250331/250331_1049_VERT_m1.is_comp_Exports/250331_1049_VERT_m1_4_1.csv
Results Table 1
,Compresson Axis,H*,V*,Height,Thickness,Width,Area,Fixture separation,Specimen label
,,,,(mm),(mm),(mm),(mm^2),(mm),
"4","X","","","150.00","28.00","150.00","4200.00","150.00","1049_VERT_m1"

Results Table 2
,Modulus (Segment 0 % - 5 %),Compresson Axis
,(kPa),
"4","1776.95","X"

Time,Displacement,Force,Compressive displacement,Compressive strain (Displacement),Compressive stress
(s),(mm),(N),(mm),(%),(kPa)
"0.0000","0.0000","-2.0814","0.0000","0.0000","-0.4956"
"0.0800","0.0014","-2.0177","0.0014","0.0009","-0.4804"
"0.1600","0.0108","-1.3722","0.0108","0.0072","-0.3267"
"0.2400","0.0310","-0.0086","0.0310","0.0207","-0.0020"
"0.3200","0.0507","1.2095","0.0507","0.0338","0.2880"
"0.4000","0.0692","2.3495","0.0692","0.0461","0.5594"
"0.4800","0.0899","3.6212","0.0899","0.0599","0.8622"
"0.5600","0.1113","4.8900","0.1113","0.0742","1.1643"
"0.6400","0.1308","6.0395","0.1308","0.0872","1.4380"
"0.7200","0.1507","7.2020","0.1507","0.1004","1.7148"
"0.8000","0.1704","8.3183","0.1704","0.1136","1.9806"
"0.8800","0.1903","9.4739","0.1903","0.1269","2.2557"
"0.9600","0.2111","10.6619","0.2111","0.1407","2.5385"
"1.0400","0.2298","11.7118","0.2298","0.1532","2.7885"
"1.1200","0.2504","12.8780","0.2504","0.1669","3.0662"
"1.2000","0.2710","14.0449","0.2710","0.1807","3.3440"
"1.2800","0.2909","15.1461","0.2909","0.1939","3.6062"
"1.3600","0.3111","16.2644","0.3111","0.2074","3.8725"
"1.4400","0.3299","17.2890","0.3299","0.2200","4.1164"
"1.5200","0.3504","18.4392","0.3504","0.2336","4.3903"
"1.6000","0.3706","19.5314","0.3706","0.2471","4.6503"
"1.6800","0.3901","20.6119","0.3901","0.2601","4.9076"
"1.7600","0.4115","21.7802","0.4115","0.2744","5.1858"
"1.8400","0.4310","22.8239","0.4310","0.2873","5.4343"
"1.9200","0.4513","23.9115","0.4513","0.3009","5.6932"
"2.0000","0.4708","24.9602","0.4708","0.3139","5.9429"
"2.0800","0.4902","25.9807","0.4902","0.3268","6.1859"
"2.1600","0.5105","27.0690","0.5105","0.3403","6.4450"
"2.2400","0.5306","28.1324","0.5306","0.3538","6.6982"
"2.3200","0.5497","29.1431","0.5497","0.3665","6.9388"
"2.4000","0.5709","30.2808","0.5709","0.3806","7.2097"
"2.4800","0.5910","31.3314","0.5910","0.3940","7.4599"
"2.5600","0.6120","32.4400","0.6120","0.4080","7.7238"
"2.6400","0.6308","33.4010","0.6308","0.4205","7.9526"
"2.7200","0.6497","34.3820","0.6497","0.4332","8.1862"
"2.8000","0.6698","35.4235","0.6698","0.4466","8.4342"
"2.8800","0.6902","36.4865","0.6902","0.4601","8.6873"
"2.9600","0.7108","37.5619","0.7108","0.4739","8.9433"
"3.0400","0.7321","38.6712","0.7321","0.4881","9.2074"
"3.1200","0.7506","39.5823","0.7506","0.5004","9.4244"
"3.2000","0.7708","40.6204","0.7708","0.5139","9.6715"
"3.2800","0.7908","41.6373","0.7908","0.5272","9.9136"
"3.3600","0.8104","42.6290","0.8104","0.5402","10.1498"
"3.4400","0.8302","43.6213","0.8302","0.5535","10.3860"
"3.5200","0.8498","44.6018","0.8498","0.5666","10.6195"
"3.6000","0.8705","45.6328","0.8705","0.5803","10.8650"
"3.6800","0.8913","46.6652","0.8913","0.5942","11.1108"
"3.7600","0.9111","47.6239","0.9111","0.6074","11.3390"
"3.8400","0.9304","48.5285","0.9304","0.6203","11.5544"
"3.9200","0.9499","49.4391","0.9499","0.6333","11.7712"
"4.0000","0.9698","50.3823","0.9698","0.6466","11.9958"
"4.0800","0.9912","51.3985","0.9912","0.6608","12.2377"
"4.1600","1.0101","52.2497","1.0101","0.6734","12.4404"
"4.2400","1.0313","53.2799","1.0313","0.6875","12.6857"
"4.3200","1.0513","54.2249","1.0513","0.7008","12.9107"
"4.4000","1.0715","55.2151","1.0715","0.7143","13.1465"
"4.4800","1.0912","56.1651","1.0912","0.7275","13.3726"
"4.5600","1.1105","57.0804","1.1105","0.7403","13.5906"
"4.6400","1.1304","58.0205","1.1304","0.7536","13.8144"
"4.7200","1.1506","58.9944","1.1506","0.7671","14.0463"
"4.8000","1.1695","59.8466","1.1695","0.7796","14.2492"
"4.8800","1.1913","60.9295","1.1913","0.7942","14.5070"
"4.9600","1.2112","61.8678","1.2112","0.8075","14.7304"
"5.0400","1.2313","62.8532","1.2313","0.8209","14.9650"
"5.1200","1.2508","63.7801","1.2508","0.8339","15.1857"
"5.2000","1.2696","64.6711","1.2696","0.8464","15.3979"
"5.2800","1.2905","65.6940","1.2905","0.8603","15.6414"
"5.3600","1.3108","66.6757","1.3108","0.8739","15.8752"
"5.4400","1.3302","67.5975","1.3302","0.8868","16.0947"
"5.5200","1.3509","68.6310","1.3509","0.9006","16.3407"
"5.6000","1.3713","69.5897","1.3713","0.9142","16.5690"
"5.6800","1.3915","70.5666","1.3915","0.9277","16.8016"
"5.7600","1.4116","71.5183","1.4116","0.9411","17.0282"
"5.8400","1.4297","72.3377","1.4297","0.9531","17.2233"
"5.9200","1.4502","73.3257","1.4502","0.9668","17.4585"
"6.0000","1.4696","74.2385","1.4696","0.9798","17.6758"
"6.0800","1.4906","75.2583","1.4906","0.9937","17.9186"
"6.1600","1.5112","76.2513","1.5112","1.0075","18.1551"
"6.2400","1.5312","77.1944","1.5312","1.0208","18.3796"
"6.3200","1.5506","78.1145","1.5506","1.0337","18.5987"
"6.4000","1.5709","79.1195","1.5709","1.0472","18.8380"
"6.4800","1.5898","80.0316","1.5898","1.0599","19.0551"
"6.5600","1.6110","81.0943","1.6110","1.0740","19.3082"
"6.6400","1.6298","81.9634","1.6298","1.0865","19.5151"
"6.7200","1.6511","83.0465","1.6511","1.1007","19.7730"
"6.8000","1.6718","84.0816","1.6718","1.1145","20.0194"
"6.8800","1.6918","85.0809","1.6918","1.1279","20.2574"
"6.9600","1.7111","85.9982","1.7111","1.1407","20.4758"
"7.0400","1.7301","86.9225","1.7301","1.1534","20.6958"
"7.1200","1.7497","87.8811","1.7497","1.1665","20.9241"
"7.2000","1.7706","88.9619","1.7706","1.1804","21.1814"
"7.2800","1.7900","89.8888","1.7900","1.1933","21.4021"
"7.3600","1.8111","90.9685","1.8111","1.2074","21.6592"
"7.4400","1.8314","91.9745","1.8314","1.2209","21.8987"
"7.5200","1.8505","92.9261","1.8505","1.2337","22.1253"
"7.6000","1.8707","93.9360","1.8707","1.2471","22.3657"
"7.6800","1.8900","94.8749","1.8900","1.2600","22.5893"
"7.7600","1.9110","95.9516","1.9110","1.2740","22.8456"
"7.8400","1.9303","96.9037","1.9303","1.2869","23.0723"
"7.9200","1.9498","97.8681","1.9498","1.2998","23.3019"
"8.0000","1.9710","98.9681","1.9710","1.3140","23.5638"
"8.0800","1.9921","100.0128","1.9921","1.3281","23.8126"
"8.1600","2.0112","100.9528","2.0112","1.3408","24.0364"
"8.2400","2.0312","101.9291","2.0312","1.3541","24.2688"
"8.3200","2.0497","102.8044","2.0497","1.3665","24.4772"
"8.4000","2.0709","103.8916","2.0709","1.3806","24.7361"
"8.4800","2.0902","104.8303","2.0902","1.3935","24.9596"
"8.5600","2.1103","105.9138","2.1103","1.4069","25.2176"
"8.6400","2.1307","106.9323","2.1307","1.4205","25.4601"
"8.7200","2.1511","107.9441","2.1511","1.4341","25.7010"
"8.8000","2.1712","108.9626","2.1712","1.4475","25.9435"
"8.8800","2.1913","109.9701","2.1913","1.4609","26.1834"
"8.9600","2.2100","110.8710","2.2100","1.4733","26.3978"
"9.0400","2.2305","111.9065","2.2305","1.4870","26.6444"
"9.1200","2.2500","112.8825","2.2500","1.5000","26.8768"
"9.2000","2.2706","113.9506","2.2706","1.5138","27.1311"
"9.2800","2.2920","115.0506","2.2920","1.5280","27.3930"
"9.3600","2.3112","115.9774","2.3112","1.5408","27.6137"
"9.4400","2.3311","116.9676","2.3311","1.5541","27.8494"
"9.5200","2.3507","117.9420","2.3507","1.5671","28.0814"
"9.6000","2.3701","118.9068","2.3701","1.5801","28.3111"
"9.6800","2.3904","119.9444","2.3904","1.5936","28.5582"
"9.7600","2.4099","120.8953","2.4099","1.6066","28.7846"
"9.8400","2.4302","121.9316","2.4302","1.6201","29.0313"
"9.9200","2.4514","123.0072","2.4514","1.6343","29.2874"
"10.0000","2.4705","123.9356","2.4705","1.6470","29.5085"
"10.0800","2.4913","124.9873","2.4913","1.6609","29.7589"
"10.1600","2.5106","125.9692","2.5106","1.6737","29.9927"
"10.2400","2.5304","126.9669","2.5304","1.6869","30.2302"
"10.3200","2.5502","127.9488","2.5502","1.7001","30.4640"
"10.4000","2.5695","128.8924","2.5695","1.7130","30.6887"
"10.4800","2.5908","129.9975","2.5908","1.7272","30.9518"
"10.5600","2.6119","131.0743","2.6119","1.7413","31.2082"
"10.6400","2.6314","132.0482","2.6314","1.7542","31.4400"
"10.7200","2.6509","133.0176","2.6509","1.7673","31.6708"
"10.8000","2.6700","133.9492","2.6700","1.7800","31.8927"
"10.8800","2.6905","135.0001","2.6905","1.7937","32.1429"
"10.9600","2.7106","136.0147","2.7106","1.8071","32.3845"
"11.0400","2.7292","136.9114","2.7292","1.8195","32.5980"
"11.1200","2.7504","138.0194","2.7504","1.8336","32.8618"
"11.2000","2.7712","139.0858","2.7712","1.8475","33.1157"
"11.2800","2.7910","140.0742","2.7910","1.8607","33.3510"
"11.3600","2.8110","141.0997","2.8110","1.8740","33.5952"
"11.4400","2.8300","142.0028","2.8300","1.8866","33.8102"
"11.5200","2.8502","143.0538","2.8502","1.9002","34.0604"
"11.6000","2.8707","144.0854","2.8707","1.9138","34.3060"
"11.6800","2.8902","145.0683","2.8902","1.9268","34.5401"
"11.7600","2.9115","146.1811","2.9115","1.9410","34.8050"
"11.8400","2.9307","147.1187","2.9307","1.9538","35.0283"
"11.9200","2.9513","148.1677","2.9513","1.9675","35.2780"
"12.0000","2.9708","149.1462","2.9708","1.9805","35.5110"
"12.0800","2.9905","150.1367","2.9905","1.9937","35.7468"
"12.1600","3.0106","151.1611","3.0106","2.0070","35.9907"
"12.2400","3.0305","152.1458","3.0305","2.0203","36.2252"
"12.3200","3.0497","153.1054","3.0497","2.0331","36.4537"
"12.4000","3.0710","154.2078","3.0710","2.0473","36.7161"
"12.4800","3.0905","155.1705","3.0905","2.0604","36.9454"
"12.5600","3.1121","156.2893","3.1121","2.0747","37.2117"
"12.6400","3.1310","157.1945","3.1310","2.0873","37.4273"
"12.7200","3.1498","158.1324","3.1498","2.0999","37.6506"
"12.8000","3.1696","159.1268","3.1696","2.1131","37.8873"
"12.8800","3.1900","160.1774","3.1900","2.1267","38.1375"
"12.9600","3.2112","161.2866","3.2112","2.1408","38.4016"
"13.0400","3.2324","162.3869","3.2324","2.1549","38.6636"
"13.1200","3.2508","163.2582","3.2508","2.1672","38.8710"
"13.2000","3.2709","164.2731","3.2709","2.1806","39.1126"
"13.2800","3.2909","165.2694","3.2909","2.1939","39.3499"
"13.3600","3.3105","166.2539","3.3105","2.2070","39.5843"
"13.4400","3.3307","167.2729","3.3307","2.2205","39.8269"
"13.5200","3.3494","168.1929","3.3494","2.2329","40.0459"
"13.6000","3.3704","169.2628","3.3704","2.2469","40.3007"
"13.6800","3.3913","170.3469","3.3913","2.2609","40.5588"
"13.7600","3.4113","171.3421","3.4113","2.2742","40.7957"
"13.8400","3.4308","172.3227","3.4308","2.2872","41.0292"
"13.9200","3.4503","173.2701","3.4503","2.3002","41.2548"
"14.0000","3.4698","174.2628","3.4698","2.3132","41.4911"
"14.0800","3.4910","175.3725","3.4910","2.3273","41.7554"
"14.1600","3.5099","176.2887","3.5099","2.3399","41.9735"
"14.2400","3.5312","177.3965","3.5312","2.3542","42.2373"
"14.3200","3.5513","178.4147","3.5513","2.3676","42.4797"
"14.4000","3.5711","179.4006","3.5711","2.3807","42.7144"
"14.4800","3.5905","180.3719","3.5905","2.3937","42.9457"
"14.5600","3.6105","181.3731","3.6105","2.4070","43.1841"
"14.6400","3.6306","182.4040","3.6306","2.4204","43.4295"
"14.7200","3.6504","183.3924","3.6504","2.4336","43.6649"
"14.8000","3.6692","184.3213","3.6692","2.4461","43.8860"
"14.8800","3.6905","185.4348","3.6905","2.4603","44.1511"
"14.9600","3.7112","186.4877","3.7112","2.4742","44.4018"
"15.0400","3.7313","187.5052","3.7313","2.4875","44.6441"
"15.1200","3.7508","188.4782","3.7508","2.5006","44.8758"
"15.2000","3.7693","189.3827","3.7693","2.5128","45.0911"
"15.2800","3.7901","190.4481","3.7901","2.5268","45.3448"
"15.3600","3.8104","191.4846","3.8104","2.5403","45.5916"
"15.4400","3.8305","192.4992","3.8305","2.5536","45.8331"
"15.5200","3.8508","193.5406","3.8508","2.5672","46.0811"
"15.6000","3.8711","194.5578","3.8711","2.5808","46.3233"
"15.6800","3.8917","195.6205","3.8917","2.5945","46.5763"
"15.7600","3.9119","196.6278","3.9119","2.6079","46.8162"
"15.8400","3.9299","197.4985","3.9299","2.6199","47.0234"
"15.9200","3.9503","198.5460","3.9503","2.6335","47.2729"
"16.0000","3.9696","199.4965","3.9696","2.6464","47.4992"
"16.0800","3.9909","200.6113","3.9909","2.6606","47.7646"
"16.1600","4.0111","201.6371","4.0111","2.6741","48.0088"
"16.2400","4.0308","202.6063","4.0308","2.6872","48.2396"
"16.3200","4.0506","203.6003","4.0506","2.7004","48.4763"
"16.4000","4.0709","204.6267","4.0709","2.7139","48.7206"
"16.4800","4.0899","205.5654","4.0899","2.7266","48.9441"
"16.5600","4.1106","206.6322","4.1106","2.7404","49.1981"
"16.6400","4.1298","207.5832","4.1298","2.7532","49.4246"
"16.7200","4.1509","208.6714","4.1509","2.7672","49.6837"
"16.8000","4.1718","209.7419","4.1718","2.7812","49.9385"
"16.8800","4.1914","210.7160","4.1914","2.7942","50.1705"
"16.9600","4.2108","211.6693","4.2108","2.8072","50.3974"
"17.0400","4.2305","212.6591","4.2305","2.8204","50.6331"
"17.1200","4.2500","213.6224","4.2500","2.8333","50.8625"
"17.2000","4.2706","214.6849","4.2706","2.8471","51.1155"
"17.2800","4.2896","215.5987","4.2896","2.8597","51.3330"
"17.3600","4.3107","216.7015","4.3107","2.8738","51.5956"
"17.4400","4.3314","217.7509","4.3314","2.8876","51.8454"
"17.5200","4.3506","218.7017","4.3506","2.9004","52.0718"
"17.6000","4.3708","219.7174","4.3708","2.9138","52.3137"
"17.6800","4.3900","220.6642","4.3900","2.9267","52.5391"
"17.7600","4.4108","221.7369","4.4108","2.9405","52.7945"
"17.8400","4.4305","222.7261","4.4305","2.9537","53.0300"
"17.9200","4.4499","223.6741","4.4499","2.9666","53.2557"
"18.0000","4.4707","224.7484","4.4707","2.9804","53.5115"
"18.0800","4.4920","225.8505","4.4920","2.9947","53.7739"
"18.1600","4.5117","226.8251","4.5117","3.0078","54.0060"
"18.2400","4.5311","227.7773","4.5311","3.0208","54.2327"
"18.3200","4.5497","228.6720","4.5497","3.0332","54.4457"
"18.4000","4.5710","229.7798","4.5710","3.0473","54.7095"
"18.4800","4.5905","230.7420","4.5905","3.0603","54.9386"
"18.5600","4.6103","231.7388","4.6103","3.0735","55.1759"
"18.6400","4.6300","232.7089","4.6300","3.0866","55.4069"
"18.7200","4.6509","233.7769","4.6509","3.1006","55.6612"
"18.8000","4.6712","234.7796","4.6712","3.1142","55.8999"
"18.8800","4.6910","235.7678","4.6910","3.1274","56.1352"
"18.9600","4.7098","236.6703","4.7098","3.1399","56.3501"
"19.0400","4.7304","237.7086","4.7304","3.1536","56.5973"
"19.1200","4.7502","238.6874","4.7502","3.1668","56.8303"
"19.2000","4.7708","239.7531","4.7708","3.1805","57.0841"
"19.2800","4.7920","240.8357","4.7920","3.1947","57.3418"
"19.3600","4.8112","241.7694","4.8112","3.2075","57.5641"
"19.4400","4.8309","242.7330","4.8309","3.2206","57.7936"
"19.5200","4.8508","243.7298","4.8508","3.2339","58.0309"
"19.6000","4.8705","244.6974","4.8705","3.2470","58.2613"
"19.6800","4.8905","245.7197","4.8905","3.2603","58.5047"
"19.7600","4.9102","246.6866","4.9102","3.2734","58.7349"
"19.8400","4.9302","247.6998","4.9302","3.2868","58.9762"
"19.9200","4.9513","248.7746","4.9513","3.3009","59.2320"
"20.0000","4.9708","249.7255","4.9708","3.3138","59.4584"
"20.0800","4.9915","250.7619","4.9915","3.3277","59.7052"
"20.1600","5.0106","251.6651","5.0106","3.3404","59.9203"
"20.2400","5.0299","252.6157","5.0299","3.3533","60.1466"
"20.3200","5.0495","253.5798","5.0495","3.3663","60.3761"
"20.4000","5.0700","254.5979","5.0700","3.3800","60.6186"
"20.4800","5.0910","255.6536","5.0910","3.3940","60.8699"
"20.5600","5.1119","256.7033","5.1119","3.4080","61.1198"
"20.6400","5.1311","257.6227","5.1311","3.4207","61.3387"
"20.7200","5.1510","258.5899","5.1510","3.4340","61.5690"
"20.8000","5.1702","259.5261","5.1702","3.4468","61.7919"
"20.8800","5.1910","260.5904","5.1910","3.4607","62.0453"
"20.9600","5.2108","261.5475","5.2108","3.4738","62.2732"
"21.0400","5.2295","262.4474","5.2295","3.4863","62.4875"
"21.1200","5.2501","263.4756","5.2501","3.5001","62.7323"
"21.2000","5.2712","264.5464","5.2712","3.5141","62.9872"
"21.2800","5.2902","265.4338","5.2902","3.5268","63.1985"
"21.3600","5.3108","266.4716","5.3108","3.5405","63.4456"
"21.4400","5.3301","267.3914","5.3301","3.5534","63.6646"
"21.5200","5.3504","268.4087","5.3504","3.5669","63.9068"
"21.6000","5.3708","269.4251","5.3708","3.5806","64.1488"
"21.6800","5.3902","270.3911","5.3902","3.5935","64.3788"
"21.7600","5.4114","271.4654","5.4114","3.6076","64.6346"
"21.8400","5.4311","272.4152","5.4311","3.6207","64.8608"
"21.9200","5.4514","273.4151","5.4514","3.6343","65.0988"
"22.0000","5.4707","274.3313","5.4707","3.6471","65.3170"
"22.0800","5.4904","275.2972","5.4904","3.6602","65.5469"
"22.1600","5.5106","276.3079","5.5106","3.6737","65.7876"
"22.2400","5.5306","277.2875","5.5306","3.6870","66.0208"
"22.3200","5.5495","278.2188","5.5495","3.6997","66.2426"
"22.4000","5.5709","279.3147","5.5709","3.7139","66.5035"
"22.4800","5.5906","280.2591","5.5906","3.7271","66.7283"
"22.5600","5.6118","281.3332","5.6118","3.7412","66.9841"
"22.6400","5.6309","282.2404","5.6309","3.7540","67.2001"
"22.7200","5.6497","283.1425","5.6497","3.7665","67.4149"
"22.8000","5.6696","284.1201","5.6696","3.7797","67.6476"
"22.8800","5.6903","285.1537","5.6903","3.7935","67.8938"
"22.9600","5.7112","286.2147","5.7112","3.8075","68.1464"
"23.0400","5.7320","287.2567","5.7320","3.8214","68.3944"
"23.1200","5.7507","288.1259","5.7507","3.8338","68.6014"
"23.2000","5.7710","289.1238","5.7710","3.8473","68.8390"
"23.2800","5.7909","290.0922","5.7909","3.8606","69.0696"
"23.3600","5.8107","291.0695","5.8107","3.8738","69.3023"
"23.4400","5.8308","292.0487","5.8308","3.8872","69.5354"
"23.5200","5.8491","292.9129","5.8491","3.8994","69.7412"
"23.6000","5.8704","293.9877","5.8704","3.9136","69.9971"
"23.6800","5.8917","295.0759","5.8917","3.9278","70.2562"
"23.7600","5.9114","296.0282","5.9114","3.9409","70.4829"
"23.8400","5.9306","296.9643","5.9306","3.9537","70.7058"
"23.9200","5.9504","297.9179","5.9504","3.9669","70.9328"
"24.0000","5.9699","298.8608","5.9699","3.9799","71.1573"
"24.0800","5.9910","299.9273","5.9910","3.9940","71.4113"
"24.1600","6.0101","300.8271","6.0101","4.0067","71.6255"
"24.2400","6.0311","301.8777","6.0311","4.0208","71.8757"
"24.3200","6.0505","302.7928","6.0505","4.0336","72.0935"
"24.4000","6.0714","303.8549","6.0714","4.0476","72.3464"
"24.4800","6.0909","304.7911","6.0909","4.0606","72.5693"
"24.5600","6.1110","305.7952","6.1110","4.0740","72.8084"
"24.6400","6.1308","306.7437","6.1308","4.0872","73.0342"
"24.7200","6.1505","307.6933","6.1505","4.1004","73.2603"
"24.8000","6.1694","308.5803","6.1694","4.1129","73.4715"
"24.8800","6.1905","309.6406","6.1905","4.1270","73.7240"
"24.9600","6.2112","310.6535","6.2112","4.1408","73.9651"
"25.0400","6.2314","311.6288","6.2314","4.1543","74.1973"
"25.1200","6.2506","312.5310","6.2506","4.1671","74.4122"
"25.2000","6.2694","313.4114","6.2694","4.1796","74.6218"
"25.2800","6.2904","314.4552","6.2904","4.1936","74.8703"
"25.3600","6.3106","315.4393","6.3106","4.2070","75.1046"
"25.4400","6.3305","316.3937","6.3305","4.2203","75.3318"
"25.5200","6.3509","317.4142","6.3509","4.2339","75.5748"
"25.6000","6.3710","318.3587","6.3710","4.2473","75.7997"
"25.6800","6.3915","319.3740","6.3915","4.2610","76.0414"
"25.7600","6.4117","320.3477","6.4117","4.2745","76.2733"
"25.8400","6.4303","321.2246","6.4303","4.2869","76.4821"
"25.9200","6.4507","322.2314","6.4507","4.3005","76.7218"
"26.0000","6.4694","323.0856","6.4694","4.3129","76.9251"
"26.0800","6.4905","324.1543","6.4905","4.3270","77.1796"
"26.1600","6.5114","325.1962","6.5114","4.3410","77.4277"
"26.2400","6.5313","326.1406","6.5313","4.3542","77.6525"
"26.3200","6.5508","327.0585","6.5508","4.3672","77.8711"
"26.4000","6.5707","328.0060","6.5707","4.3804","78.0967"
"26.4800","6.5900","328.9495","6.5900","4.3934","78.3213"
"26.5600","6.6109","330.0131","6.6109","4.4073","78.5746"
"26.6400","6.6300","330.8884","6.6300","4.4200","78.7830"
"26.7200","6.6507","331.9156","6.6507","4.4338","79.0275"
"26.8000","6.6715","332.9445","6.6715","4.4477","79.2725"
"26.8800","6.6912","333.8869","6.6912","4.4608","79.4969"
"26.9600","6.7109","334.8021","6.7109","4.4739","79.7148"
"27.0400","6.7304","335.7259","6.7304","4.4869","79.9347"
"27.1200","6.7503","336.6865","6.7503","4.5002","80.1635"
"27.2000","6.7703","337.6496","6.7703","4.5135","80.3928"
"27.2800","6.7896","338.5494","6.7896","4.5264","80.6070"
"27.3600","6.8109","339.6052","6.8109","4.5406","80.8584"
"27.4400","6.8314","340.5951","6.8314","4.5542","81.0941"
"27.5200","6.8506","341.5052","6.8506","4.5671","81.3108"
"27.6000","6.8708","342.4676","6.8708","4.5805","81.5399"
"27.6800","6.8901","343.3670","6.8901","4.5934","81.7540"
"27.7600","6.9108","344.3790","6.9108","4.6072","81.9950"
"27.8400","6.9301","345.2805","6.9301","4.6201","82.2096"
"27.9200","6.9499","346.2216","6.9499","4.6333","82.4337"
"28.0000","6.9708","347.2627","6.9708","4.6472","82.6816"
"28.0800","6.9920","348.3027","6.9920","4.6613","82.9292"
"28.1600","7.0117","349.2261","7.0117","4.6745","83.1491"
"28.2400","7.0313","350.1436","7.0313","4.6875","83.3675"
"28.3200","7.0496","350.9785","7.0496","4.6998","83.5663"
"28.4000","7.0709","352.0486","7.0709","4.7139","83.8211"
"28.4800","7.0906","352.9697","7.0906","4.7271","84.0404"
"28.5600","7.1098","353.8766","7.1098","4.7399","84.2563"
"28.6400","7.1302","354.8607","7.1302","4.7535","84.4907"
"28.7200","7.1513","355.8755","7.1513","4.7675","84.7323"
"28.8000","7.1710","356.8033","7.1710","4.7807","84.9532"
"28.8800","7.1912","357.7795","7.1912","4.7942","85.1856"
"28.9600","7.2099","358.6124","7.2099","4.8066","85.3839"
"29.0400","7.2303","359.6201","7.2303","4.8202","85.6238"
"29.1200","7.2495","360.4939","7.2495","4.8330","85.8319"
"29.2000","7.2699","361.5136","7.2699","4.8466","86.0747"
"29.2800","7.2920","362.6147","7.2920","4.8614","86.3368"
"29.3600","7.3113","363.4925","7.3113","4.8742","86.5458"
"29.4400","7.3315","364.4520","7.3315","4.8877","86.7743"
"29.5200","7.3508","365.3462","7.3508","4.9006","86.9872"
"29.6000","7.3703","366.2627","7.3703","4.9135","87.2054"
"29.6800","7.3905","367.2419","7.3905","4.9270","87.4385"
"29.7600","7.4101","368.1420","7.4101","4.9401","87.6529"
"29.8400","7.4300","369.0971","7.4300","4.9534","87.8803"
"29.9200","7.4516","370.1608","7.4516","4.9677","88.1335"
"30.0000","7.4708","371.0340","7.4708","4.9805","88.3414"
"30.0800","7.4913","372.0179","7.4913","4.9942","88.5757"
"30.1600","7.5105","372.9164","7.5105","5.0070","88.7896"
"30.2400","7.5303","373.8654","7.5303","5.0202","89.0156"
"30.3200","7.5497","374.7665","7.5497","5.0331","89.2301"
"30.4000","7.5702","375.7481","7.5702","5.0468","89.4638"
"30.4800","7.5913","376.7855","7.5913","5.0609","89.7108"
"30.5600","7.6122","377.7939","7.6122","5.0748","89.9509"
"30.6400","7.6309","378.6207","7.6309","5.0873","90.1478"
"30.7200","7.6511","379.5824","7.6511","5.1007","90.3768"
"30.8000","7.6702","380.4583","7.6702","5.1135","90.5853"
"30.8800","7.6911","381.4944","7.6911","5.1274","90.8320"
"30.9600","7.7105","382.3683","7.7105","5.1404","91.0401"
"31.0400","7.7291","383.2106","7.7291","5.1527","91.2406"
"31.1200","7.7505","384.2592","7.7505","5.1670","91.4903"
"31.2000","7.7713","385.2735","7.7713","5.1808","91.7318"
"31.2800","7.7914","386.2166","7.7914","5.1943","91.9563"
"31.3600","7.8109","387.1281","7.8109","5.2073","92.1733"
"31.4400","7.8298","387.9816","7.8298","5.2198","92.3766"
"31.5200","7.8502","388.9651","7.8502","5.2335","92.6107"
"31.6000","7.8708","389.9365","7.8708","5.2472","92.8420"
"31.6800","7.8903","390.8584","7.8903","5.2602","93.0615"
"31.7600","7.9116","391.8921","7.9116","5.2744","93.3076"
"31.8400","7.9311","392.7889","7.9311","5.2874","93.5212"
"31.9200","7.9513","393.7219","7.9513","5.3009","93.7433"
"32.0000","7.9711","394.6565","7.9711","5.3141","93.9658"
"32.0800","7.9899","395.5034","7.9899","5.3266","94.1675"
"32.1600","8.0103","396.4849","8.0103","5.3402","94.4012"
"32.2400","8.0305","397.4298","8.0305","5.3536","94.6261"
"32.3200","8.0499","398.3379","8.0499","5.3666","94.8424"
"32.4000","8.0709","399.3739","8.0709","5.3806","95.0890"
"32.4800","8.0909","400.2848","8.0909","5.3939","95.3059"
"32.5600","8.1119","401.3080","8.1119","5.4079","95.5495"
"32.6400","8.1309","402.1487","8.1309","5.4206","95.7497"
"32.7200","8.1500","403.0144","8.1500","5.4333","95.9558"
"32.8000","8.1694","403.9026","8.1694","5.4463","96.1673"
"32.8800","8.1902","404.9005","8.1902","5.4601","96.4049"
"32.9600","8.2107","405.8793","8.2107","5.4738","96.6379"
"33.0400","8.2322","406.9103","8.2322","5.4881","96.8834"
"33.1200","8.2509","407.7290","8.2509","5.5006","97.0783"
"33.2000","8.2709","408.6690","8.2709","5.5139","97.3021"
"33.2800","8.2907","409.5875","8.2907","5.5272","97.5208"
"33.3600","8.3108","410.5481","8.3108","5.5405","97.7495"
"33.4400","8.3307","411.4611","8.3307","5.5538","97.9669"
"33.5200","8.3492","412.2757","8.3492","5.5661","98.1609"
"33.6000","8.3703","413.3034","8.3703","5.5802","98.4056"
"33.6800","8.3914","414.3260","8.3914","5.5943","98.6491"
"33.7600","8.4115","415.2488","8.4115","5.6077","98.8688"
"33.8400","8.4306","416.1053","8.4306","5.6204","99.0727"
"33.9200","8.4498","416.9655","8.4498","5.6332","99.2775"
"34.0000","8.4700","417.9319","8.4700","5.6466","99.5076"
"34.0800","8.4911","418.9395","8.4911","5.6607","99.7475"
"34.1600","8.5101","419.7841","8.5101","5.6734","99.9486"
"34.2400","8.5313","420.8015","8.5313","5.6875","100.1908"
"34.3200","8.5507","421.6657","8.5507","5.7005","100.3966"
"34.4000","8.5712","422.6434","8.5712","5.7141","100.6294"
"34.4800","8.5910","423.5465","8.5910","5.7273","100.8444"
"34.5600","8.6107","424.4232","8.6107","5.7404","101.0531"
"34.6400","8.6304","425.3376","8.6304","5.7536","101.2709"
"34.7200","8.6503","426.2656","8.6503","5.7669","101.4918"
"34.8000","8.6692","427.0997","8.6692","5.7795","101.6904"
"34.8800","8.6909","428.1574","8.6909","5.7939","101.9422"
"34.9600","8.7111","429.0750","8.7111","5.8074","102.1607"
"35.0400","8.7313","430.0252","8.7313","5.8209","102.3870"
"35.1200","8.7509","430.9101","8.7509","5.8339","102.5976"
"35.2000","8.7698","431.7492","8.7698","5.8465","102.7974"
"35.2800","8.7903","432.6996","8.7903","5.8602","103.0237"
"35.3600","8.8104","433.6300","8.8104","5.8736","103.2452"
"35.4400","8.8305","434.5573","8.8305","5.8870","103.4660"
"35.5200","8.8509","435.5276","8.8509","5.9006","103.6970"
"35.6000","8.8714","436.4562","8.8714","5.9142","103.9182"
"35.6800","8.8919","437.4160","8.8919","5.9279","104.1467"
"35.7600","8.9119","438.3197","8.9119","5.9412","104.3618"
"35.8400","8.9300","439.1060","8.9300","5.9534","104.5490"
"35.9200","8.9503","440.0437","8.9503","5.9668","104.7723"
"36.0000","8.9692","440.8784","8.9692","5.9795","104.9711"
"36.0800","8.9902","441.8886","8.9902","5.9934","105.2116"
"36.1600","9.0115","442.9182","9.0115","6.0076","105.4567"
"36.2400","9.0315","443.8162","9.0315","6.0210","105.6705"
"36.3200","9.0506","444.6700","9.0506","6.0338","105.8738"
"36.4000","9.0708","445.5844","9.0708","6.0472","106.0915"
"36.4800","9.0900","446.4552","9.0900","6.0600","106.2989"
"36.5600","9.1101","447.3693","9.1101","6.0734","106.5165"
"36.6400","9.1294","448.2274","9.1294","6.0863","106.7208"
"36.7200","9.1514","449.3108","9.1514","6.1010","106.9788"
"36.8000","9.1718","450.2465","9.1718","6.1145","107.2015"
"36.8800","9.1915","451.1610","9.1915","6.1277","107.4193"
"36.9600","9.2112","452.0311","9.2112","6.1408","107.6265"
"37.0400","9.2309","452.9168","9.2309","6.1540","107.8373"
"37.1200","9.2504","453.7927","9.2504","6.1669","108.0459"
"37.2000","9.2699","454.6793","9.2699","6.1800","108.2570"
"37.2800","9.2895","455.5457","9.2895","6.1930","108.4633"
"37.3600","9.3108","456.5730","9.3108","6.2072","108.7079"
"37.4400","9.3316","457.5279","9.3316","6.2211","108.9352"
"37.5200","9.3507","458.3750","9.3507","6.2338","109.1369"
"37.6000","9.3704","459.2665","9.3704","6.2470","109.3492"
"37.6800","9.3899","460.1335","9.3899","6.2599","109.5556"
"37.7600","9.4109","461.1183","9.4109","6.2739","109.7901"
"37.8400","9.4303","461.9778","9.4303","6.2869","109.9947"
"37.9200","9.4496","462.8297","9.4496","6.2997","110.1975"
"38.0000","9.4706","463.8293","9.4706","6.3137","110.4355"
"38.0800","9.4921","464.8294","9.4921","6.3281","110.6737"
"38.1600","9.5115","465.6810","9.5115","6.3410","110.8764"
"38.2400","9.5312","466.5635","9.5312","6.3542","111.0865"
"38.3200","9.5496","467.3381","9.5496","6.3664","111.2710"
"38.4000","9.5706","468.3314","9.5706","6.3804","111.5075"
"38.4800","9.5904","469.2257","9.5904","6.3936","111.7204"
"38.5600","9.6103","470.1245","9.6103","6.4069","111.9344"
"38.6400","9.6301","471.0095","9.6301","6.4201","112.1451"
"38.7200","9.6509","471.9650","9.6509","6.4339","112.3726"
"38.8000","9.6710","472.8638","9.6710","6.4473","112.5866"
"38.8800","9.6914","473.7977","9.6914","6.4609","112.8090"
"38.9600","9.7101","474.5932","9.7101","6.4734","112.9984"
"39.0400","9.7304","475.5128","9.7304","6.4869","113.2173"
"39.1200","9.7498","476.3607","9.7498","6.4999","113.4192"
"39.2000","9.7709","477.3750","9.7709","6.5139","113.6607"
"39.2800","9.7921","478.3597","9.7921","6.5281","113.8952"
"39.3600","9.8109","479.1548","9.8109","6.5406","114.0845"
"39.4400","9.8312","480.0549","9.8312","6.5541","114.2988"
"39.5200","9.8507","480.9254","9.8507","6.5671","114.5061"
"39.6000","9.8706","481.8126","9.8706","6.5804","114.7173"
"39.6800","9.8894","482.6256","9.8894","6.5929","114.9109"
"39.7600","9.9098","483.5600","9.9098","6.6065","115.1333"
"39.8400","9.9306","484.5255","9.9306","6.6204","115.3632"
"39.9200","9.9517","485.4896","9.9517","6.6344","115.5928"
"40.0000","9.9708","486.3119","9.9708","6.6472","115.7885"
"40.0800","9.9912","487.2410","9.9912","6.6608","116.0098"
"40.1600","10.0105","488.0782","10.0105","6.6737","116.2091"
"40.2400","10.0304","488.9717","10.0304","6.6869","116.4218"
"40.3200","10.0496","489.8040","10.0496","6.6997","116.6200"
"40.4000","10.0699","490.7131","10.0699","6.7133","116.8364"
"40.4800","10.0908","491.6830","10.0908","6.7272","117.0674"
"40.5600","10.1121","492.6711","10.1121","6.7414","117.3027"
"40.6400","10.1312","493.4884","10.1312","6.7541","117.4972"
"40.7200","10.1509","494.3496","10.1509","6.7672","117.7023"
"40.8000","10.1702","495.1680","10.1702","6.7801","117.8971"
"40.8800","10.1909","496.1135","10.1909","6.7939","118.1222"
"40.9600","10.2105","496.9710","10.2105","6.8070","118.3264"
"41.0400","10.2296","497.7887","10.2296","6.8197","118.5211"
"41.1200","10.2502","498.7125","10.2502","6.8334","118.7411"
"41.2000","10.2711","499.6667","10.2711","6.8474","118.9683"
"41.2800","10.2915","500.5858","10.2915","6.8610","119.1871"
"41.3600","10.3114","501.4949","10.3114","6.8742","119.4035"
"41.4400","10.3302","502.2602","10.3302","6.8868","119.5858"
"41.5200","10.3503","503.1690","10.3503","6.9002","119.8021"
"41.6000","10.3707","504.0631","10.3707","6.9138","120.0150"
"41.6800","10.3902","504.9330","10.3902","6.9268","120.2221"
"41.7600","10.4114","505.8893","10.4114","6.9409","120.4498"
"41.8400","10.4309","506.7260","10.4309","6.9539","120.6490"
"41.9200","10.4515","507.6480","10.4515","6.9677","120.8686"
"42.0000","10.4707","508.4665","10.4707","6.9805","121.0634"
"42.0800","10.4902","509.3179","10.4902","6.9935","121.2662"
"42.1600","10.5106","510.2194","10.5106","7.0071","121.4808"
"42.2400","10.5301","511.0539","10.5301","7.0201","121.6795"
"42.3200","10.5498","511.9204","10.5498","7.0332","121.8858"
"42.4000","10.5710","512.8954","10.5710","7.0473","122.1180"
"42.4800","10.5909","513.7477","10.5909","7.0606","122.3209"
"42.5600","10.6118","514.6764","10.6118","7.0745","122.5420"
"42.6400","10.6308","515.4656","10.6308","7.0872","122.7299"
"42.7200","10.6499","516.2856","10.6499","7.1000","122.9251"
"42.8000","10.6698","517.1425","10.6698","7.1132","123.1292"
"42.8800","10.6904","518.0751","10.6904","7.1269","123.3512"
"42.9600","10.7110","518.9903","10.7110","7.1406","123.5691"
"43.0400","10.7316","519.9010","10.7316","7.1544","123.7860"
"43.1200","10.7509","520.7010","10.7509","7.1673","123.9764"
"43.2000","10.7711","521.5778","10.7711","7.1807","124.1852"
"43.2800","10.7909","522.4163","10.7909","7.1939","124.3848"
"43.3600","10.8105","523.2902","10.8105","7.2070","124.5929"
"43.4400","10.8303","524.1208","10.8303","7.2202","124.7907"
"43.5200","10.8495","524.9316","10.8495","7.2330","124.9837"
"43.6000","10.8707","525.8768","10.8707","7.2471","125.2088"
"43.6800","10.8910","526.7580","10.8910","7.2607","125.4186"
"43.7600","10.9112","527.6357","10.9112","7.2742","125.6276"
"43.8400","10.9306","528.4393","10.9306","7.2871","125.8189"
"43.9200","10.9503","529.2646","10.9503","7.3002","126.0154"
"44.0000","10.9702","530.1379","10.9702","7.3135","126.2233"
"44.0800","10.9910","531.0419","10.9910","7.3273","126.4386"
"44.1600","11.0098","531.7960","11.0098","7.3399","126.6181"
"44.2400","11.0311","532.7404","11.0311","7.3541","126.8429"
"44.3200","11.0510","533.5742","11.0510","7.3673","127.0415"
"44.4000","11.0717","534.4897","11.0717","7.3811","127.2595"
"44.4800","11.0907","535.2389","11.0907","7.3938","127.4378"
"44.5600","11.1104","536.0585","11.1104","7.4069","127.6330"
"44.6400","11.1306","536.9289","11.1306","7.4204","127.8402"
"44.7200","11.1502","537.7590","11.1502","7.4335","128.0379"
"44.8000","11.1691","538.5350","11.1691","7.4461","128.2226"
"44.8800","11.1910","539.5319","11.1910","7.4606","128.4600"
"44.9600","11.2114","540.3904","11.2114","7.4743","128.6644"
"45.0400","11.2320","541.2621","11.2320","7.4880","128.8719"
"45.1200","11.2508","541.9764","11.2508","7.5005","129.0420"
"45.2000","11.2694","542.7284","11.2694","7.5130","129.2211"
"45.2800","11.2904","543.6296","11.2904","7.5269","129.4356"
"45.3600","11.3107","544.4796","11.3107","7.5405","129.6380"
"45.4400","11.3305","545.2937","11.3305","7.5536","129.8318"
"45.5200","11.3507","546.1446","11.3507","7.5671","130.0344"
"45.6000","11.3712","546.9949","11.3712","7.5808","130.2369"
"45.6800","11.3917","547.8616","11.3917","7.5945","130.4432"
"45.7600","11.4118","548.6793","11.4118","7.6078","130.6379"
"45.8400","11.4301","549.4169","11.4301","7.6201","130.8135"
"45.9200","11.4502","550.2325","11.4502","7.6335","131.0077"
"46.0000","11.4692","550.9788","11.4692","7.6462","131.1854"
"46.0800","11.4907","551.9272","11.4907","7.6605","131.4112"
"46.1600","11.5110","552.7659","11.5110","7.6740","131.6109"
"46.2400","11.5311","553.5652","11.5311","7.6874","131.8012"
"46.3200","11.5506","554.3284","11.5506","7.7004","131.9830"
"46.4000","11.5707","555.1483","11.5707","7.7138","132.1782"
"46.4800","11.5900","555.9050","11.5900","7.7266","132.3583"
"46.5600","11.6103","556.7574","11.6103","7.7402","132.5613"
"46.6400","11.6295","557.4764","11.6295","7.7530","132.7325"
"46.7200","11.6509","558.4089","11.6509","7.7673","132.9545"
"46.8000","11.6716","559.2560","11.6716","7.7811","133.1562"
"46.8800","11.6919","560.0836","11.6919","7.7946","133.3532"
"46.9600","11.7111","560.7894","11.7111","7.8074","133.5213"
"47.0400","11.7300","561.5026","11.7300","7.8200","133.6911"
"47.1200","11.7504","562.3475","11.7504","7.8336","133.8923"
"47.2000","11.7703","563.1436","11.7703","7.8469","134.0818"
"47.2800","11.7900","563.9115","11.7900","7.8600","134.2646"
"47.3600","11.8110","564.7908","11.8110","7.8740","134.4740"
"47.4400","11.8315","565.5993","11.8315","7.8877","134.6665"
"47.5200","11.8508","566.3331","11.8508","7.9005","134.8412"
"47.6000","11.8707","567.1058","11.8707","7.9138","135.0252"
"47.6800","11.8897","567.8017","11.8897","7.9265","135.1909"
"47.7600","11.9108","568.6815","11.9108","7.9406","135.4004"
"47.8400","11.9307","569.4388","11.9307","7.9538","135.5807"
"47.9200","11.9502","570.1789","11.9502","7.9668","135.7569"
"48.0000","11.9710","571.0124","11.9710","7.9807","135.9553"
"48.0800","11.9917","571.8044","11.9917","7.9944","136.1439"
"48.1600","12.0115","572.5671","12.0115","8.0076","136.3255"
"48.2400","12.0313","573.2926","12.0313","8.0208","136.4982"
"48.3200","12.0495","573.9113","12.0495","8.0330","136.6455"
"48.4000","12.0708","574.7853","12.0708","8.0472","136.8536"
"48.4800","12.0903","575.4865","12.0903","8.0602","137.0206"
"48.5600","12.1103","576.2466","12.1103","8.0735","137.2016"
"48.6400","12.1304","577.0075","12.1304","8.0869","137.3827"
"48.7200","12.1511","577.8030","12.1511","8.1007","137.5722"
"48.8000","12.1711","578.5325","12.1711","8.1141","137.7458"
"48.8800","12.1911","579.2784","12.1911","8.1274","137.9234"
"48.9600","12.2103","579.9356","12.2103","8.1402","138.0799"
"49.0400","12.2303","580.6780","12.2303","8.1536","138.2567"
"49.1200","12.2499","581.3512","12.2499","8.1666","138.4169"
"49.2000","12.2702","582.1357","12.2702","8.1802","138.6037"
"49.2800","12.2922","582.9998","12.2922","8.1948","138.8095"
"49.3600","12.3114","583.6356","12.3114","8.2076","138.9609"
"49.4400","12.3315","584.3320","12.3315","8.2210","139.1267"
"49.5200","12.3506","584.9754","12.3506","8.2338","139.2799"
"49.6000","12.3703","585.6819","12.3703","8.2469","139.4481"
"49.6800","12.3903","586.3852","12.3903","8.2602","139.6155"
"49.7600","12.4100","587.0535","12.4100","8.2733","139.7746"
"49.8400","12.4303","587.7867","12.4303","8.2868","139.9492"
"49.9200","12.4511","588.5316","12.4511","8.3008","140.1266"
"50.0000","12.4703","589.1703","12.4703","8.3135","140.2787"
"50.0800","12.4913","589.9242","12.4913","8.3276","140.4581"
"50.1600","12.5104","590.5281","12.5104","8.3403","140.6019"
"50.2400","12.5308","591.2392","12.5308","8.3538","140.7712"
"50.3200","12.5497","591.8304","12.5497","8.3665","140.9120"
"50.4000","12.5696","592.4835","12.5696","8.3797","141.0675"
"50.4800","12.5906","593.2380","12.5906","8.3937","141.2472"
"50.5600","12.6124","594.0261","12.6124","8.4082","141.4348"
"50.6400","12.6315","594.6238","12.6315","8.4210","141.5771"
"50.7200","12.6509","595.2195","12.6509","8.4340","141.7189"
"50.8000","12.6702","595.7985","12.6702","8.4468","141.8568"
"50.8800","12.6908","596.5012","12.6908","8.4605","142.0241"
"50.9600","12.7103","597.0972","12.7103","8.4735","142.1660"
"51.0400","12.7295","597.6790","12.7295","8.4863","142.3045"
"51.1200","12.7502","598.3481","12.7502","8.5001","142.4638"
"51.2000","12.7708","599.0328","12.7708","8.5139","142.6269"
"51.2800","12.7911","599.6599","12.7911","8.5274","142.7762"
"51.3600","12.8111","600.2972","12.8111","8.5407","142.9279"
"51.4400","12.8308","600.8791","12.8308","8.5538","143.0665"
"51.5200","12.8507","601.4684","12.8507","8.5671","143.2068"
"51.6000","12.8706","602.0589","12.8706","8.5804","143.3474"
"51.6800","12.8901","602.6340","12.8901","8.5934","143.4843"
"51.7600","12.9115","603.3286","12.9115","8.6077","143.6497"
"51.8400","12.9312","603.8763","12.9312","8.6208","143.7801"
"51.9200","12.9516","604.4734","12.9516","8.6344","143.9222"
"52.0000","12.9708","604.9860","12.9708","8.6472","144.0443"
"52.0800","12.9907","605.5633","12.9907","8.6605","144.1817"
"52.1600","13.0103","606.0943","13.0103","8.6736","144.3082"
"52.2400","13.0304","606.6609","13.0304","8.6869","144.4431"
"52.3200","13.0498","607.1871","13.0498","8.6999","144.5684"
"52.4000","13.0711","607.8921","13.0711","8.7140","144.7362"
"52.4800","13.0908","608.3959","13.0908","8.7272","144.8562"
"52.5600","13.1120","609.0092","13.1120","8.7414","145.0022"
"52.6400","13.1309","609.4301","13.1309","8.7539","145.1024"
"52.7200","13.1500","609.8937","13.1500","8.7666","145.2128"
"52.8000","13.1692","610.3470","13.1692","8.7795","145.3207"
"52.8800","13.1899","610.9359","13.1899","8.7933","145.4609"
"52.9600","13.2114","611.5396","13.2114","8.8076","145.6047"
"53.0400","13.2322","612.0948","13.2322","8.8215","145.7369"
"53.1200","13.2515","612.5085","13.2515","8.8343","145.8354"
"53.2000","13.2711","612.9608","13.2711","8.8474","145.9430"
"53.2800","13.2906","613.4010","13.2906","8.8604","146.0479"
"53.3600","13.3105","613.9052","13.3105","8.8737","146.1679"
"53.4400","13.3304","614.3720","13.3304","8.8870","146.2791"
"53.5200","13.3493","614.7505","13.3493","8.8995","146.3692"
"53.6000","13.3709","615.3353","13.3709","8.9139","146.5084"
"53.6800","13.3915","615.8300","13.3915","8.9277","146.6262"
"53.7600","13.4114","616.2547","13.4114","8.9409","146.7273"
"53.8400","13.4306","616.6323","13.4306","8.9537","146.8172"
"53.9200","13.4502","617.0141","13.4502","8.9668","146.9081"
"54.0000","13.4700","617.4493","13.4700","8.9800","147.0117"
"54.0800","13.4910","617.9468","13.4910","8.9940","147.1302"
"54.1600","13.5099","618.2717","13.5099","9.0066","147.2076"
"54.2400","13.5311","618.7712","13.5311","9.0207","147.3265"
"54.3200","13.5514","619.1913","13.5514","9.0343","147.4265"
"54.4000","13.5718","619.6166","13.5718","9.0479","147.5278"
"54.4800","13.5908","619.9187","13.5908","9.0605","147.5997"
"54.5600","13.6106","620.2661","13.6106","9.0737","147.6824"
"54.6400","13.6304","620.6379","13.6304","9.0869","147.7709"
"54.7200","13.6505","621.0164","13.6505","9.1004","147.8610"
"54.8000","13.6695","621.3137","13.6695","9.1130","147.9318"
"54.8800","13.6910","621.7827","13.6910","9.1273","148.0435"
"54.9600","13.7109","622.1041","13.7109","9.1406","148.1200"
"55.0400","13.7313","622.4645","13.7313","9.1542","148.2058"
"55.1200","13.7508","622.7452","13.7508","9.1672","148.2727"
"55.2000","13.7698","622.9919","13.7698","9.1799","148.3314"
"55.2800","13.7903","623.3448","13.7903","9.1935","148.4154"
"55.3600","13.8102","623.6395","13.8102","9.2068","148.4856"
"55.4400","13.8302","623.9543","13.8302","9.2201","148.5606"
"55.5200","13.8512","624.3247","13.8512","9.2341","148.6487"
"55.6000","13.8716","624.6064","13.8716","9.2477","148.7158"
"55.6800","13.8920","624.9067","13.8920","9.2613","148.7873"
"55.7600","13.9114","625.1058","13.9114","9.2743","148.8347"
"55.8400","13.9301","625.2764","13.9301","9.2867","148.8753"
"55.9200","13.9503","625.5461","13.9503","9.3002","148.9395"
"56.0000","13.9695","625.7275","13.9695","9.3130","148.9827"
"56.0800","13.9905","626.0482","13.9905","9.3270","149.0591"
"56.1600","14.0112","626.3641","14.0112","9.3408","149.1343"
"56.2400","14.0312","626.5597","14.0312","9.3541","149.1809"
"56.3200","14.0508","626.7302","14.0508","9.3672","149.2215"
"56.4000","14.0708","626.9189","14.0708","9.3806","149.2664"
"56.4800","14.0902","627.0793","14.0902","9.3935","149.3046"
"56.5600","14.1105","627.2784","14.1105","9.4070","149.3520"
"56.6400","14.1295","627.3859","14.1295","9.4197","149.3776"
"56.7200","14.1509","627.6630","14.1509","9.4339","149.4436"
"56.8000","14.1715","627.8536","14.1715","9.4476","149.4890"
"56.8800","14.1915","628.0170","14.1915","9.4610","149.5279"
"56.9600","14.2111","628.1107","14.2111","9.4741","149.5502"
"57.0400","14.2304","628.1899","14.2304","9.4869","149.5690"
"57.1200","14.2504","628.3386","14.2504","9.5003","149.6044"
"57.2000","14.2702","628.4570","14.2702","9.5135","149.6326"
"57.2800","14.2898","628.5345","14.2898","9.5266","149.6511"
"57.3600","14.3107","628.7057","14.3107","9.5405","149.6918"
"57.4400","14.3314","628.8446","14.3314","9.5543","149.7249"
"57.5200","14.3507","628.8890","14.3507","9.5671","149.7355"
"57.6000","14.3707","628.9748","14.3707","9.5804","149.7559"
"57.6800","14.3896","628.9833","14.3896","9.5931","149.7579"
"57.7600","14.4106","629.1570","14.4106","9.6071","149.7993"
"57.8400","14.4303","629.1939","14.4303","9.6202","149.8081"
"57.9200","14.4498","629.2222","14.4498","9.6332","149.8148"
"58.0000","14.4708","629.3541","14.4708","9.6472","149.8462"
"58.0800","14.4919","629.4694","14.4919","9.6613","149.8737"
"58.1600","14.5117","629.5246","14.5117","9.6745","149.8868"
"58.2400","14.5310","629.5021","14.5310","9.6873","149.8815"
"58.3200","14.5500","629.4564","14.5500","9.7000","149.8706"
"58.4000","14.5705","629.5198","14.5705","9.7137","149.8857"
"58.4800","14.5904","629.5366","14.5904","9.7270","149.8897"
"58.5600","14.6102","629.5488","14.6102","9.7402","149.8926"
"58.6400","14.6301","629.5414","14.6301","9.7534","149.8908"
"58.7200","14.6509","629.5925","14.6509","9.7672","149.9030"
"58.8000","14.6714","629.6138","14.6714","9.7809","149.9080"
"58.8800","14.6914","629.5942","14.6914","9.7942","149.9034"
"58.9600","14.7102","629.4958","14.7102","9.8068","149.8800"
"59.0400","14.7304","629.4836","14.7304","9.8203","149.8771"
"59.1200","14.7498","629.4135","14.7498","9.8332","149.8604"
"59.2000","14.7703","629.4354","14.7703","9.8469","149.8656"
"59.2800","14.7918","629.4992","14.7918","9.8612","149.8808"
"59.3600","14.8115","629.4282","14.8115","9.8743","149.8639"
"59.4400","14.8316","629.3591","14.8316","9.8877","149.8474"
"59.5200","14.8510","629.2643","14.8510","9.9006","149.8248"
"59.6000","14.8701","629.1609","14.8701","9.9134","149.8002"
"59.6800","14.8902","629.1302","14.8902","9.9268","149.7929"
"59.7600","14.9100","629.0405","14.9100","9.9400","149.7716"
"59.8400","14.9303","629.0060","14.9303","9.9535","149.7633"
"59.9200","14.9512","628.9985","14.9512","9.9675","149.7615"
"60.0000","14.9707","628.8880","14.9707","9.9805","149.7352"
"60.0800","14.9917","628.8770","14.9917","9.9945","149.7326"
"60.1140","15.0001","628.8256","15.0001","10.0000","149.7204"