File: data/instron_tests/metamaterials/250331/250331_1049_VERT_m1.is_comp_Exports/250331_1049_VERT_m1_1_1.csv
Results Table 1
,Compresson Axis,H*,V*,Height,Thickness,Width,Area,Fixture separation,Specimen label
,,,,(mm),(mm),(mm),(mm^2),(mm),
"1","Y","","","150.00","28.00","150.00","4200.00","150.00","1049_VERT_m1"

Results Table 2
,Modulus (Segment 0 % - 5 %),Compresson Axis
,(kPa),
"1","918.16","Y"

Time,Displacement,Force,Compressive displacement,Compressive strain (Displacement),Compressive stress
(s),(mm),(N),(mm),(%),(kPa)
"0.0000","0.0000","-3.9842","0.0000","0.0000","-0.9486"
"0.0800","0.0012","-3.9372","0.0012","0.0008","-0.9374"
"0.1600","0.0172","-3.3031","0.0172","0.0115","-0.7864"
"0.2400","0.0383","-2.4938","0.0383","0.0255","-0.5938"
"0.3200","0.0580","-1.7842","0.0580","0.0386","-0.4248"
"0.4000","0.0770","-1.0943","0.0770","0.0513","-0.2605"
"0.4800","0.0980","-0.3434","0.0980","0.0654","-0.0818"
"0.5600","0.1179","0.3460","0.1179","0.0786","0.0824"
"0.6400","0.1379","1.0319","0.1379","0.0919","0.2457"
"0.7200","0.1573","1.6850","0.1573","0.1049","0.4012"
"0.8000","0.1764","2.3300","0.1764","0.1176","0.5548"
"0.8800","0.1970","3.0211","0.1970","0.1313","0.7193"
"0.9600","0.2168","3.6697","0.2168","0.1446","0.8737"
"1.0400","0.2363","4.3222","0.2363","0.1575","1.0291"
"1.1200","0.2572","5.0255","0.2572","0.1715","1.1965"
"1.2000","0.2773","5.6770","0.2773","0.1849","1.3517"
"1.2800","0.2980","6.3509","0.2980","0.1986","1.5121"
"1.3600","0.3174","6.9694","0.3174","0.2116","1.6594"
"1.4400","0.3360","7.5645","0.3360","0.2240","1.8011"
"1.5200","0.3567","8.2317","0.3567","0.2378","1.9599"
"1.6000","0.3768","8.8679","0.3768","0.2512","2.1114"
"1.6800","0.3975","9.5365","0.3975","0.2650","2.2706"
"1.7600","0.4183","10.1908","0.4183","0.2788","2.4264"
"1.8400","0.4370","10.7717","0.4370","0.2914","2.5647"
"1.9200","0.4575","11.4189","0.4575","0.3050","2.7188"
"2.0000","0.4776","12.0488","0.4776","0.3184","2.8688"
"2.0800","0.4966","12.6392","0.4966","0.3311","3.0093"
"2.1600","0.5170","13.2776","0.5170","0.3447","3.1613"
"2.2400","0.5363","13.8546","0.5363","0.3575","3.2987"
"2.3200","0.5570","14.5128","0.5570","0.3713","3.4554"
"2.4000","0.5782","15.1559","0.5782","0.3855","3.6086"
"2.4800","0.5975","15.7505","0.5975","0.3983","3.7501"
"2.5600","0.6174","16.3587","0.6174","0.4116","3.8949"
"2.6400","0.6366","16.9303","0.6366","0.4244","4.0310"
"2.7200","0.6562","17.5258","0.6562","0.4375","4.1728"
"2.8000","0.6769","18.1563","0.6769","0.4513","4.3229"
"2.8800","0.6965","18.7263","0.6965","0.4643","4.4586"
"2.9600","0.7176","19.3609","0.7176","0.4784","4.6097"
"3.0400","0.7385","19.9773","0.7385","0.4923","4.7565"
"3.1200","0.7573","20.5332","0.7573","0.5048","4.8889"
"3.2000","0.7771","21.1196","0.7771","0.5180","5.0285"
"3.2800","0.7967","21.7013","0.7967","0.5311","5.1670"
"3.3600","0.8173","22.3261","0.8173","0.5449","5.3157"
"3.4400","0.8374","22.9134","0.8374","0.5583","5.4556"
"3.5200","0.8558","23.4548","0.8558","0.5705","5.5845"
"3.6000","0.8761","24.0302","0.8761","0.5841","5.7215"
"3.6800","0.8976","24.6947","0.8976","0.5984","5.8797"
"3.7600","0.9178","25.2671","0.9178","0.6119","6.0160"
"3.8400","0.9373","25.8364","0.9373","0.6249","6.1515"
"3.9200","0.9562","26.3817","0.9562","0.6374","6.2814"
"4.0000","0.9770","26.9972","0.9770","0.6514","6.4279"
"4.0800","0.9974","27.5868","0.9974","0.6649","6.5683"
"4.1600","1.0167","28.1634","1.0167","0.6778","6.7056"
"4.2400","1.0376","28.7748","1.0376","0.6918","6.8511"
"4.3200","1.0577","29.3471","1.0577","0.7051","6.9874"
"4.4000","1.0778","29.9287","1.0778","0.7186","7.1259"
"4.4800","1.0979","30.5011","1.0979","0.7319","7.2622"
"4.5600","1.1165","31.0336","1.1165","0.7443","7.3889"
"4.6400","1.1366","31.6049","1.1366","0.7577","7.5250"
"4.7200","1.1562","32.1681","1.1562","0.7708","7.6591"
"4.8000","1.1767","32.7630","1.1767","0.7845","7.8007"
"4.8800","1.1981","33.3880","1.1981","0.7988","7.9495"
"4.9600","1.2173","33.9221","1.2173","0.8116","8.0767"
"5.0400","1.2374","34.4863","1.2374","0.8249","8.2110"
"5.1200","1.2568","35.0311","1.2568","0.8378","8.3407"
"5.2000","1.2760","35.5839","1.2760","0.8507","8.4724"
"5.2800","1.2973","36.1984","1.2973","0.8648","8.6187"
"5.3600","1.3164","36.7184","1.3164","0.8776","8.7425"
"5.4400","1.3369","37.3164","1.3369","0.8913","8.8849"
"5.5200","1.3582","37.9232","1.3582","0.9055","9.0293"
"5.6000","1.3775","38.4648","1.3775","0.9183","9.1583"
"5.6800","1.3975","39.0266","1.3975","0.9317","9.2921"
"5.7600","1.4174","39.5808","1.4174","0.9449","9.4240"
"5.8400","1.4372","40.1494","1.4372","0.9581","9.5594"
"5.9200","1.4570","40.6929","1.4570","0.9713","9.6888"
"6.0000","1.4757","41.1959","1.4757","0.9838","9.8085"
"6.0800","1.4974","41.8359","1.4974","0.9982","9.9609"
"6.1600","1.5182","42.4224","1.5182","1.0122","10.1006"
"6.2400","1.5368","42.9227","1.5368","1.0245","10.2197"
"6.3200","1.5568","43.4956","1.5568","1.0379","10.3561"
"6.4000","1.5769","44.0439","1.5769","1.0513","10.4866"
"6.4800","1.5971","44.6183","1.5971","1.0647","10.6234"
"6.5600","1.6176","45.1861","1.6176","1.0784","10.7586"
"6.6400","1.6362","45.6930","1.6362","1.0908","10.8793"
"6.7200","1.6576","46.2969","1.6576","1.1050","11.0231"
"6.8000","1.6780","46.8639","1.6780","1.1187","11.1581"
"6.8800","1.6982","47.4222","1.6982","1.1321","11.2910"
"6.9600","1.7169","47.9238","1.7169","1.1446","11.4104"
"7.0400","1.7362","48.4347","1.7362","1.1575","11.5321"
"7.1200","1.7568","49.0177","1.7568","1.1712","11.6709"
"7.2000","1.7774","49.5922","1.7774","1.1850","11.8077"
"7.2800","1.7964","50.1163","1.7964","1.1976","11.9324"
"7.3600","1.8175","50.7139","1.8175","1.2117","12.0747"
"7.4400","1.8372","51.2451","1.8372","1.2248","12.2012"
"7.5200","1.8574","51.7988","1.8574","1.2383","12.3330"
"7.6000","1.8774","52.3460","1.8774","1.2516","12.4633"
"7.6800","1.8965","52.8597","1.8965","1.2643","12.5856"
"7.7600","1.9169","53.4287","1.9169","1.2779","12.7211"
"7.8400","1.9368","53.9651","1.9368","1.2912","12.8488"
"7.9200","1.9566","54.5124","1.9566","1.3044","12.9791"
"8.0000","1.9778","55.1129","1.9778","1.3185","13.1221"
"8.0800","1.9982","55.6544","1.9982","1.3321","13.2511"
"8.1600","2.0181","56.1949","2.0181","1.3454","13.3797"
"8.2400","2.0375","56.7072","2.0375","1.3583","13.5017"
"8.3200","2.0562","57.2220","2.0562","1.3708","13.6243"
"8.4000","2.0770","57.7924","2.0770","1.3847","13.7601"
"8.4800","2.0962","58.2959","2.0962","1.3974","13.8800"
"8.5600","2.1166","58.8516","2.1166","1.4110","14.0123"
"8.6400","2.1379","59.4422","2.1379","1.4253","14.1529"
"8.7200","2.1575","59.9690","2.1575","1.4383","14.2783"
"8.8000","2.1776","60.5034","2.1776","1.4517","14.4056"
"8.8800","2.1975","61.0514","2.1975","1.4650","14.5360"
"8.9600","2.2164","61.5579","2.2164","1.4776","14.6567"
"9.0400","2.2368","62.1103","2.2368","1.4912","14.7882"
"9.1200","2.2562","62.6217","2.2562","1.5041","14.9099"
"9.2000","2.2776","63.2140","2.2776","1.5184","15.0510"
"9.2800","2.2986","63.7825","2.2986","1.5324","15.1863"
"9.3600","2.3175","64.2741","2.3175","1.5450","15.3034"
"9.4400","2.3369","64.7979","2.3369","1.5579","15.4281"
"9.5200","2.3570","65.3365","2.3570","1.5713","15.5563"
"9.6000","2.3771","65.8796","2.3771","1.5848","15.6856"
"9.6800","2.3975","66.4204","2.3975","1.5983","15.8144"
"9.7600","2.4158","66.8907","2.4158","1.6106","15.9264"
"9.8400","2.4371","67.4775","2.4371","1.6247","16.0661"
"9.9200","2.4577","68.0147","2.4577","1.6385","16.1940"
"10.0000","2.4773","68.5442","2.4773","1.6516","16.3200"
"10.0800","2.4979","69.1185","2.4979","1.6653","16.4568"
"10.1600","2.5168","69.6060","2.5168","1.6779","16.5729"
"10.2400","2.5369","70.1372","2.5369","1.6913","16.6993"
"10.3200","2.5568","70.6664","2.5568","1.7045","16.8253"
"10.4000","2.5759","71.1670","2.5759","1.7173","16.9445"
"10.4800","2.5974","71.7568","2.5974","1.7316","17.0849"
"10.5600","2.6181","72.3044","2.6181","1.7454","17.2153"
"10.6400","2.6377","72.8130","2.6377","1.7585","17.3364"
"10.7200","2.6576","73.3326","2.6576","1.7718","17.4601"
"10.8000","2.6762","73.8088","2.6762","1.7841","17.5735"
"10.8800","2.6971","74.3622","2.6971","1.7980","17.7053"
"10.9600","2.7171","74.9024","2.7171","1.8114","17.8339"
"11.0400","2.7364","75.4022","2.7364","1.8242","17.9529"
"11.1200","2.7568","75.9572","2.7568","1.8379","18.0851"
"11.2000","2.7774","76.4844","2.7774","1.8516","18.2106"
"11.2800","2.7978","77.0338","2.7978","1.8652","18.3414"
"11.3600","2.8172","77.5222","2.8172","1.8782","18.4577"
"11.4400","2.8360","78.0046","2.8360","1.8907","18.5725"
"11.5200","2.8567","78.5469","2.8567","1.9045","18.7016"
"11.6000","2.8766","79.0752","2.8766","1.9177","18.8274"
"11.6800","2.8975","79.6256","2.8975","1.9317","18.9585"
"11.7600","2.9179","80.1654","2.9179","1.9453","19.0870"
"11.8400","2.9374","80.6618","2.9374","1.9583","19.2052"
"11.9200","2.9575","81.1890","2.9575","1.9717","19.3307"
"12.0000","2.9775","81.7147","2.9775","1.9850","19.4559"
"12.0800","2.9969","82.2200","2.9969","1.9980","19.5762"
"12.1600","3.0169","82.7408","3.0169","2.0112","19.7002"
"12.2400","3.0362","83.2112","3.0362","2.0241","19.8122"
"12.3200","3.0568","83.7729","3.0568","2.0378","19.9459"
"12.4000","3.0779","84.3259","3.0779","2.0519","20.0776"
"12.4800","3.0974","84.8268","3.0974","2.0649","20.1968"
"12.5600","3.1178","85.3564","3.1178","2.0785","20.3230"
"12.6400","3.1365","85.8259","3.1365","2.0910","20.4347"
"12.7200","3.1565","86.3467","3.1565","2.1043","20.5587"
"12.8000","3.1766","86.8729","3.1766","2.1177","20.6840"
"12.8800","3.1968","87.3898","3.1968","2.1312","20.8071"
"12.9600","3.2179","87.9732","3.2179","2.1453","20.9460"
"13.0400","3.2382","88.4943","3.2382","2.1588","21.0701"
"13.1200","3.2573","88.9877","3.2573","2.1715","21.1876"
"13.2000","3.2775","89.5176","3.2775","2.1850","21.3137"
"13.2800","3.2965","89.9978","3.2965","2.1977","21.4280"
"13.3600","3.3174","90.5484","3.3174","2.2116","21.5591"
"13.4400","3.3372","91.0477","3.3372","2.2248","21.6780"
"13.5200","3.3559","91.5257","3.3559","2.2373","21.7918"
"13.6000","3.3770","92.0801","3.3770","2.2513","21.9238"
"13.6800","3.3979","92.6333","3.3979","2.2653","22.0556"
"13.7600","3.4175","93.1269","3.4175","2.2783","22.1731"
"13.8400","3.4376","93.6360","3.4376","2.2917","22.2943"
"13.9200","3.4560","94.0973","3.4560","2.3040","22.4041"
"14.0000","3.4770","94.6469","3.4770","2.3180","22.5350"
"14.0800","3.4973","95.1662","3.4973","2.3316","22.6586"
"14.1600","3.5167","95.6650","3.5167","2.3445","22.7774"
"14.2400","3.5376","96.2142","3.5376","2.3584","22.9081"
"14.3200","3.5570","96.6909","3.5570","2.3713","23.0216"
"14.4000","3.5780","97.2335","3.5780","2.3854","23.1508"
"14.4800","3.5977","97.7341","3.5977","2.3985","23.2700"
"14.5600","3.6168","98.2227","3.6168","2.4112","23.3863"
"14.6400","3.6366","98.7227","3.6366","2.4244","23.5054"
"14.7200","3.6564","99.2300","3.6564","2.4376","23.6262"
"14.8000","3.6761","99.7334","3.6761","2.4507","23.7460"
"14.8800","3.6979","100.3155","3.6979","2.4652","23.8847"
"14.9600","3.7173","100.8024","3.7173","2.4782","24.0006"
"15.0400","3.7376","101.3183","3.7376","2.4917","24.1234"
"15.1200","3.7568","101.7954","3.7568","2.5045","24.2370"
"15.2000","3.7759","102.2849","3.7759","2.5173","24.3536"
"15.2800","3.7965","102.8135","3.7965","2.5310","24.4794"
"15.3600","3.8168","103.3335","3.8168","2.5445","24.6032"
"15.4400","3.8371","103.8507","3.8371","2.5581","24.7264"
"15.5200","3.8581","104.3895","3.8581","2.5721","24.8546"
"15.6000","3.8774","104.8839","3.8774","2.5849","24.9724"
"15.6800","3.8976","105.3988","3.8976","2.5984","25.0950"
"15.7600","3.9174","105.8955","3.9174","2.6116","25.2132"
"15.8400","3.9368","106.3868","3.9368","2.6245","25.3302"
"15.9200","3.9570","106.8944","3.9570","2.6380","25.4510"
"16.0000","3.9761","107.3698","3.9761","2.6507","25.5642"
"16.0800","3.9974","107.9335","3.9974","2.6649","25.6985"
"16.1600","4.0181","108.4592","4.0181","2.6788","25.8236"
"16.2400","4.0372","108.9232","4.0372","2.6915","25.9341"
"16.3200","4.0568","109.4216","4.0568","2.7045","26.0528"
"16.4000","4.0765","109.9039","4.0765","2.7177","26.1676"
"16.4800","4.0969","110.4346","4.0969","2.7312","26.2939"
"16.5600","4.1176","110.9580","4.1176","2.7451","26.4186"
"16.6400","4.1361","111.4060","4.1361","2.7574","26.5252"
"16.7200","4.1575","111.9686","4.1575","2.7717","26.6592"
"16.8000","4.1775","112.4606","4.1775","2.7850","26.7763"
"16.8800","4.1982","112.9947","4.1982","2.7988","26.9035"
"16.9600","4.2172","113.4643","4.2172","2.8115","27.0153"
"17.0400","4.2365","113.9393","4.2365","2.8244","27.1284"
"17.1200","4.2566","114.4490","4.2566","2.8378","27.2498"
"17.2000","4.2772","114.9601","4.2772","2.8515","27.3715"
"17.2800","4.2962","115.4399","4.2962","2.8641","27.4857"
"17.3600","4.3177","115.9929","4.3177","2.8785","27.6174"
"17.4400","4.3369","116.4544","4.3369","2.8913","27.7272"
"17.5200","4.3574","116.9650","4.3574","2.9049","27.8488"
"17.6000","4.3773","117.4693","4.3773","2.9182","27.9689"
"17.6800","4.3966","117.9442","4.3966","2.9311","28.0820"
"17.7600","4.4169","118.4491","4.4169","2.9446","28.2022"
"17.8400","4.4367","118.9455","4.4367","2.9578","28.3204"
"17.9200","4.4564","119.4397","4.4564","2.9709","28.4380"
"18.0000","4.4780","120.0052","4.4780","2.9853","28.5727"
"18.0800","4.4979","120.4853","4.4979","2.9986","28.6870"
"18.1600","4.5179","120.9773","4.5179","3.0119","28.8041"
"18.2400","4.5374","121.4575","4.5374","3.0249","28.9184"
"18.3200","4.5563","121.9236","4.5563","3.0375","29.0294"
"18.4000","4.5771","122.4617","4.5771","3.0514","29.1576"
"18.4800","4.5963","122.9346","4.5963","3.0642","29.2702"
"18.5600","4.6169","123.4486","4.6169","3.0780","29.3925"
"18.6400","4.6377","123.9806","4.6377","3.0918","29.5192"
"18.7200","4.6574","124.4555","4.6574","3.1049","29.6323"
"18.8000","4.6772","124.9398","4.6772","3.1181","29.7476"
"18.8800","4.6975","125.4415","4.6975","3.1317","29.8670"
"18.9600","4.7166","125.9035","4.7166","3.1444","29.9770"
"19.0400","4.7368","126.4098","4.7368","3.1579","30.0976"
"19.1200","4.7557","126.8663","4.7557","3.1704","30.2063"
"19.2000","4.7779","127.4398","4.7779","3.1852","30.3428"
"19.2800","4.7985","127.9575","4.7985","3.1990","30.4661"
"19.3600","4.8175","128.4083","4.8175","3.2117","30.5734"
"19.4400","4.8371","128.8949","4.8371","3.2248","30.6893"
"19.5200","4.8564","129.3523","4.8564","3.2376","30.7982"
"19.6000","4.8772","129.8894","4.8772","3.2515","30.9260"
"19.6800","4.8978","130.3911","4.8978","3.2652","31.0455"
"19.7600","4.9161","130.8107","4.9161","3.2774","31.1454"
"19.8400","4.9368","131.3372","4.9368","3.2912","31.2708"
"19.9200","4.9577","131.8535","4.9577","3.3051","31.3937"
"20.0000","4.9779","132.3553","4.9779","3.3186","31.5132"
"20.0800","4.9975","132.8243","4.9975","3.3316","31.6248"
"20.1600","5.0163","133.2695","5.0163","3.3442","31.7308"
"20.2400","5.0365","133.7562","5.0365","3.3577","31.8467"
"20.3200","5.0568","134.2588","5.0568","3.3712","31.9664"
"20.4000","5.0767","134.7483","5.0767","3.3845","32.0829"
"20.4800","5.0977","135.2737","5.0977","3.3984","32.2080"
"20.5600","5.1181","135.7660","5.1181","3.4120","32.3252"
"20.6400","5.1377","136.2382","5.1377","3.4251","32.4377"
"20.7200","5.1576","136.7220","5.1576","3.4384","32.5529"
"20.8000","5.1761","137.1620","5.1761","3.4507","32.6576"
"20.8800","5.1976","137.7026","5.1976","3.4651","32.7863"
"20.9600","5.2167","138.1468","5.2167","3.4778","32.8921"
"21.0400","5.2363","138.6286","5.2363","3.4909","33.0068"
"21.1200","5.2569","139.1386","5.2569","3.5046","33.1282"
"21.2000","5.2772","139.6160","5.2772","3.5182","33.2419"
"21.2800","5.2976","140.1260","5.2976","3.5317","33.3633"
"21.3600","5.3177","140.6090","5.3177","3.5451","33.4783"
"21.4400","5.3360","141.0276","5.3360","3.5573","33.5780"
"21.5200","5.3567","141.5546","5.3567","3.5712","33.7035"
"21.6000","5.3765","142.0207","5.3765","3.5843","33.8145"
"21.6800","5.3976","142.5550","5.3976","3.5984","33.9417"
"21.7600","5.4181","143.0440","5.4181","3.6121","34.0581"
"21.8400","5.4369","143.4747","5.4369","3.6246","34.1607"
"21.9200","5.4572","143.9543","5.4572","3.6381","34.2748"
"22.0000","5.4773","144.4334","5.4773","3.6515","34.3889"
"22.0800","5.4969","144.9121","5.4969","3.6646","34.5029"
"22.1600","5.5173","145.4124","5.5173","3.6782","34.6220"
"22.2400","5.5360","145.8333","5.5360","3.6907","34.7222"
"22.3200","5.5568","146.3552","5.5568","3.7045","34.8465"
"22.4000","5.5779","146.8654","5.5779","3.7186","34.9680"
"22.4800","5.5972","147.3272","5.5972","3.7315","35.0779"
"22.5600","5.6180","147.8530","5.6180","3.7454","35.2031"
"22.6400","5.6365","148.2618","5.6365","3.7577","35.3004"
"22.7200","5.6563","148.7453","5.6563","3.7709","35.4156"
"22.8000","5.6765","149.2277","5.6765","3.7843","35.5304"
"22.8800","5.6967","149.7108","5.6967","3.7978","35.6454"
"22.9600","5.7175","150.2287","5.7175","3.8117","35.7687"
"23.0400","5.7382","150.7311","5.7382","3.8255","35.8884"
"23.1200","5.7571","151.1749","5.7571","3.8381","35.9940"
"23.2000","5.7776","151.6640","5.7776","3.8517","36.1105"
"23.2800","5.7966","152.0955","5.7966","3.8644","36.2132"
"23.3600","5.8176","152.6154","5.8176","3.8784","36.3370"
"23.4400","5.8373","153.0694","5.8373","3.8915","36.4451"
"23.5200","5.8557","153.4979","5.8557","3.9038","36.5471"
"23.6000","5.8767","154.0227","5.8767","3.9178","36.6721"
"23.6800","5.8982","154.5499","5.8982","3.9321","36.7976"
"23.7600","5.9179","155.0111","5.9179","3.9453","36.9074"
"23.8400","5.9375","155.4814","5.9375","3.9583","37.0194"
"23.9200","5.9561","155.8944","5.9561","3.9707","37.1177"
"24.0000","5.9767","156.3924","5.9767","3.9845","37.2363"
"24.0800","5.9976","156.8932","5.9976","3.9984","37.3555"
"24.1600","6.0166","157.3409","6.0166","4.0111","37.4621"
"24.2400","6.0379","157.8578","6.0379","4.0253","37.5852"
"24.3200","6.0574","158.3117","6.0574","4.0382","37.6933"
"24.4000","6.0780","158.8082","6.0780","4.0520","37.8115"
"24.4800","6.0973","159.2656","6.0973","4.0649","37.9204"
"24.5600","6.1165","159.7078","6.1165","4.0777","38.0257"
"24.6400","6.1368","160.1927","6.1368","4.0912","38.1411"
"24.7200","6.1567","160.6583","6.1567","4.1045","38.2520"
"24.8000","6.1761","161.1182","6.1761","4.1174","38.3615"
"24.8800","6.1978","161.6546","6.1978","4.1318","38.4892"
"24.9600","6.2174","162.0953","6.2174","4.1449","38.5941"
"25.0400","6.2375","162.5617","6.2375","4.1583","38.7052"
"25.1200","6.2567","162.9942","6.2567","4.1711","38.8082"
"25.2000","6.2761","163.4611","6.2761","4.1840","38.9193"
"25.2800","6.2969","163.9681","6.2969","4.1979","39.0400"
"25.3600","6.3167","164.4260","6.3167","4.2112","39.1491"
"25.4400","6.3375","164.9167","6.3375","4.2250","39.2659"
"25.5200","6.3582","165.4152","6.3582","4.2388","39.3846"
"25.6000","6.3775","165.8637","6.3775","4.2517","39.4914"
"25.6800","6.3979","166.3441","6.3979","4.2652","39.6057"
"25.7600","6.4175","166.7891","6.4175","4.2783","39.7117"
"25.8400","6.4369","167.2495","6.4369","4.2913","39.8213"
"25.9200","6.4572","167.7282","6.4572","4.3048","39.9353"
"26.0000","6.4758","168.1460","6.4758","4.3172","40.0348"
"26.0800","6.4974","168.6699","6.4974","4.3316","40.1595"
"26.1600","6.5184","169.1725","6.5184","4.3456","40.2792"
"26.2400","6.5374","169.5997","6.5374","4.3583","40.3809"
"26.3200","6.5568","170.0487","6.5568","4.3712","40.4878"
"26.4000","6.5767","170.4945","6.5767","4.3844","40.5939"
"26.4800","6.5970","170.9821","6.5970","4.3980","40.7100"
"26.5600","6.6176","171.4570","6.6176","4.4117","40.8231"
"26.6400","6.6362","171.8798","6.6362","4.4241","40.9238"
"26.7200","6.6572","172.3797","6.6572","4.4381","41.0428"
"26.8000","6.6777","172.8487","6.6777","4.4518","41.1545"
"26.8800","6.6980","173.3250","6.6980","4.4653","41.2679"
"26.9600","6.7173","173.7573","6.7173","4.4782","41.3708"
"27.0400","6.7365","174.1894","6.7365","4.4910","41.4737"
"27.1200","6.7568","174.6677","6.7568","4.5045","41.5876"
"27.2000","6.7772","175.1418","6.7772","4.5181","41.7004"
"27.2800","6.7962","175.5821","6.7962","4.5308","41.8053"
"27.3600","6.8174","176.0925","6.8174","4.5449","41.9268"
"27.4400","6.8373","176.5515","6.8373","4.5582","42.0361"
"27.5200","6.8577","177.0224","6.8577","4.5718","42.1482"
"27.6000","6.8774","177.4658","6.8774","4.5849","42.2538"
"27.6800","6.8965","177.9045","6.8965","4.5977","42.3582"
"27.7600","6.9168","178.3708","6.9168","4.6112","42.4692"
"27.8400","6.9365","178.8192","6.9365","4.6243","42.5760"
"27.9200","6.9566","179.2853","6.9566","4.6377","42.6870"
"28.0000","6.9779","179.8075","6.9779","4.6519","42.8113"
"28.0800","6.9980","180.2658","6.9980","4.6653","42.9204"
"28.1600","7.0179","180.7233","7.0179","4.6786","43.0294"
"28.2400","7.0376","181.1776","7.0376","4.6918","43.1375"
"28.3200","7.0566","181.5995","7.0566","4.7044","43.2380"
"28.4000","7.0768","182.0644","7.0768","4.7178","43.3487"
"28.4800","7.0961","182.4980","7.0961","4.7307","43.4519"
"28.5600","7.1173","182.9956","7.1173","4.7448","43.5704"
"28.6400","7.1374","183.4617","7.1374","4.7583","43.6814"
"28.7200","7.1573","183.9033","7.1573","4.7715","43.7865"
"28.8000","7.1772","184.3571","7.1772","4.7848","43.8946"
"28.8800","7.1974","184.8125","7.1974","4.7982","44.0030"
"28.9600","7.2163","185.2442","7.2163","4.8109","44.1058"
"29.0400","7.2369","185.7244","7.2369","4.8246","44.2201"
"29.1200","7.2559","186.1328","7.2559","4.8373","44.3173"
"29.2000","7.2773","186.6332","7.2773","4.8516","44.4365"
"29.2800","7.2982","187.1129","7.2982","4.8655","44.5507"
"29.3600","7.3179","187.5545","7.3179","4.8786","44.6558"
"29.4400","7.3372","187.9733","7.3372","4.8915","44.7556"
"29.5200","7.3567","188.4095","7.3567","4.9045","44.8594"
"29.6000","7.3770","188.8743","7.3770","4.9180","44.9701"
"29.6800","7.3976","189.3457","7.3976","4.9317","45.0823"
"29.7600","7.4160","189.7317","7.4160","4.9440","45.1742"
"29.8400","7.4369","190.2252","7.4369","4.9580","45.2917"
"29.9200","7.4579","190.7119","7.4579","4.9719","45.4076"
"30.0000","7.4774","191.1497","7.4774","4.9849","45.5118"
"30.0800","7.4979","191.6304","7.4979","4.9986","45.6263"
"30.1600","7.5165","192.0169","7.5165","5.0110","45.7183"
"30.2400","7.5368","192.4888","7.5368","5.0246","45.8307"
"30.3200","7.5566","192.9214","7.5566","5.0377","45.9337"
"30.4000","7.5765","193.3907","7.5765","5.0510","46.0454"
"30.4800","7.5979","193.8972","7.5979","5.0652","46.1660"
"30.5600","7.6184","194.3548","7.6184","5.0789","46.2750"
"30.6400","7.6378","194.7747","7.6378","5.0919","46.3749"
"30.7200","7.6575","195.2023","7.6575","5.1050","46.4767"
"30.8000","7.6765","195.6212","7.6765","5.1176","46.5765"
"30.8800","7.6975","196.1018","7.6975","5.1316","46.6909"
"30.9600","7.7168","196.5172","7.7168","5.1445","46.7898"
"31.0400","7.7363","196.9589","7.7363","5.1575","46.8950"
"31.1200","7.7566","197.4267","7.7566","5.1711","47.0063"
"31.2000","7.7776","197.9011","7.7776","5.1850","47.1193"
"31.2800","7.7979","198.3634","7.7979","5.1986","47.2294"
"31.3600","7.8177","198.8018","7.8177","5.2118","47.3338"
"31.4400","7.8360","199.1877","7.8360","5.2240","47.4257"
"31.5200","7.8567","199.6638","7.8567","5.2378","47.5390"
"31.6000","7.8768","200.1034","7.8768","5.2512","47.6437"
"31.6800","7.8974","200.5840","7.8974","5.2650","47.7581"
"31.7600","7.9182","201.0490","7.9182","5.2788","47.8688"
"31.8400","7.9371","201.4462","7.9371","5.2914","47.9634"
"31.9200","7.9574","201.8928","7.9574","5.3049","48.0697"
"32.0000","7.9775","202.3345","7.9775","5.3183","48.1749"
"32.0800","7.9968","202.7661","7.9968","5.3312","48.2776"
"32.1600","8.0169","203.2249","8.0169","5.3446","48.3869"
"32.2400","8.0362","203.6248","8.0362","5.3574","48.4821"
"32.3200","8.0569","204.1042","8.0569","5.3713","48.5962"
"32.4000","8.0782","204.5933","8.0782","5.3855","48.7127"
"32.4800","8.0973","205.0120","8.0973","5.3982","48.8124"
"32.5600","8.1176","205.4597","8.1176","5.4117","48.9190"
"32.6400","8.1363","205.8528","8.1363","5.4242","49.0126"
"32.7200","8.1564","206.3136","8.1564","5.4376","49.1223"
"32.8000","8.1766","206.7681","8.1766","5.4511","49.2305"
"32.8800","8.1969","207.2056","8.1969","5.4646","49.3347"
"32.9600","8.2175","207.6695","8.2175","5.4783","49.4451"
"33.0400","8.2382","208.1320","8.2382","5.4921","49.5552"
"33.1200","8.2569","208.5326","8.2569","5.5046","49.6506"
"33.2000","8.2776","208.9995","8.2776","5.5184","49.7618"
"33.2800","8.2967","209.3959","8.2967","5.5311","49.8562"
"33.3600","8.3176","209.8726","8.3176","5.5451","49.9697"
"33.4400","8.3373","210.2951","8.3373","5.5582","50.0703"
"33.5200","8.3558","210.6840","8.3558","5.5705","50.1629"
"33.6000","8.3766","211.1551","8.3766","5.5844","50.2750"
"33.6800","8.3980","211.6400","8.3980","5.5987","50.3905"
"33.7600","8.4176","212.0654","8.4176","5.6118","50.4918"
"33.8400","8.4372","212.4859","8.4372","5.6248","50.5919"
"33.9200","8.4561","212.8743","8.4561","5.6374","50.6844"
"34.0000","8.4768","213.3437","8.4768","5.6512","50.7961"
"34.0800","8.4973","213.7915","8.4973","5.6649","50.9027"
"34.1600","8.5166","214.2099","8.5166","5.6777","51.0023"
"34.2400","8.5374","214.6831","8.5374","5.6916","51.1150"
"34.3200","8.5575","215.0972","8.5575","5.7050","51.2136"
"34.4000","8.5778","215.5436","8.5778","5.7186","51.3199"
"34.4800","8.5977","215.9648","8.5977","5.7318","51.4202"
"34.5600","8.6169","216.3687","8.6169","5.7446","51.5164"
"34.6400","8.6366","216.8021","8.6366","5.7577","51.6195"
"34.7200","8.6564","217.2233","8.6564","5.7710","51.7198"
"34.8000","8.6762","217.6606","8.6762","5.7841","51.8240"
"34.8800","8.6981","218.1740","8.6981","5.7987","51.9462"
"34.9600","8.7174","218.5636","8.7174","5.8116","52.0390"
"35.0400","8.7379","219.0090","8.7379","5.8253","52.1450"
"35.1200","8.7570","219.4050","8.7570","5.8380","52.2393"
"35.2000","8.7761","219.8167","8.7761","5.8507","52.3373"
"35.2800","8.7964","220.2702","8.7964","5.8643","52.4453"
"35.3600","8.8168","220.7089","8.8168","5.8779","52.5497"
"35.4400","8.8372","221.1481","8.8372","5.8915","52.6543"
"35.5200","8.8580","221.6067","8.8580","5.9053","52.7635"
"35.6000","8.8775","222.0123","8.8775","5.9183","52.8601"
"35.6800","8.8980","222.4683","8.8980","5.9320","52.9686"
"35.7600","8.9174","222.8671","8.9174","5.9449","53.0636"
"35.8400","8.9369","223.2866","8.9369","5.9580","53.1635"
"35.9200","8.9568","223.7177","8.9568","5.9712","53.2661"
"36.0000","8.9756","224.1025","8.9756","5.9837","53.3577"
"36.0800","8.9972","224.5963","8.9972","5.9982","53.4753"
"36.1600","9.0182","225.0540","9.0182","6.0121","53.5843"
"36.2400","9.0373","225.4536","9.0373","6.0249","53.6794"
"36.3200","9.0568","225.8642","9.0568","6.0378","53.7772"
"36.4000","9.0765","226.2641","9.0765","6.0510","53.8724"
"36.4800","9.0968","226.7185","9.0968","6.0645","53.9806"
"36.5600","9.1177","227.1697","9.1177","6.0785","54.0880"
"36.6400","9.1361","227.5319","9.1361","6.0907","54.1743"
"36.7200","9.1573","228.0028","9.1573","6.1048","54.2864"
"36.8000","9.1778","228.4534","9.1778","6.1185","54.3937"
"36.8800","9.1983","228.8942","9.1983","6.1322","54.4986"
"36.9600","9.2176","229.2901","9.2176","6.1451","54.5929"
"37.0400","9.2370","229.6873","9.2370","6.1580","54.6875"
"37.1200","9.2566","230.1042","9.2566","6.1710","54.7867"
"37.2000","9.2773","230.5566","9.2773","6.1848","54.8944"
"37.2800","9.2963","230.9553","9.2963","6.1975","54.9894"
"37.3600","9.3177","231.4373","9.3177","6.2118","55.1041"
"37.4400","9.3372","231.8327","9.3372","6.2248","55.1983"
"37.5200","9.3574","232.2680","9.3574","6.2382","55.3019"
"37.6000","9.3773","232.6816","9.3773","6.2516","55.4004"
"37.6800","9.3965","233.0849","9.3965","6.2644","55.4964"
"37.7600","9.4169","233.5236","9.4169","6.2779","55.6009"
"37.8400","9.4365","233.9338","9.4365","6.2910","55.6985"
"37.9200","9.4567","234.3857","9.4567","6.3045","55.8061"
"38.0000","9.4780","234.8656","9.4780","6.3187","55.9204"
"38.0800","9.4979","235.2628","9.4979","6.3319","56.0149"
"38.1600","9.5180","235.6949","9.5180","6.3453","56.1178"
"38.2400","9.5375","236.0891","9.5375","6.3583","56.2117"
"38.3200","9.5559","236.4650","9.5559","6.3706","56.3012"
"38.4000","9.5769","236.9311","9.5769","6.3846","56.4122"
"38.4800","9.5961","237.3253","9.5961","6.3974","56.5060"
"38.5600","9.6171","237.7777","9.6171","6.4114","56.6137"
"38.6400","9.6372","238.2151","9.6372","6.4248","56.7179"
"38.7200","9.6574","238.6316","9.6574","6.4383","56.8171"
"38.8000","9.6772","239.0423","9.6772","6.4515","56.9148"
"38.8800","9.6974","239.4656","9.6974","6.4650","57.0156"
"38.9600","9.7165","239.8578","9.7165","6.4777","57.1090"
"39.0400","9.7370","240.3044","9.7370","6.4913","57.2153"
"39.1200","9.7561","240.6850","9.7561","6.5041","57.3060"
"39.2000","9.7781","241.1942","9.7781","6.5187","57.4272"
"39.2800","9.7982","241.6114","9.7982","6.5321","57.5265"
"39.3600","9.8175","242.0060","9.8175","6.5450","57.6205"
"39.4400","9.8368","242.4022","9.8368","6.5579","57.7148"
"39.5200","9.8570","242.8238","9.8570","6.5713","57.8152"
"39.6000","9.8765","243.2302","9.8765","6.5843","57.9120"
"39.6800","9.8977","243.6964","9.8977","6.5985","58.0229"
"39.7600","9.9162","244.0583","9.9162","6.6108","58.1091"
"39.8400","9.9371","244.5094","9.9371","6.6248","58.2165"
"39.9200","9.9578","244.9654","9.9578","6.6385","58.3251"
"40.0000","9.9773","245.3701","9.9773","6.6515","58.4215"
"40.0800","9.9977","245.8114","9.9977","6.6651","58.5265"
"40.1600","10.0165","246.1709","10.0165","6.6776","58.6121"
"40.2400","10.0367","246.5859","10.0367","6.6911","58.7109"
"40.3200","10.0567","247.0145","10.0567","6.7045","58.8130"
"40.4000","10.0767","247.4308","10.0767","6.7178","58.9121"
"40.4800","10.0976","247.8928","10.0976","6.7317","59.0221"
"40.5600","10.1184","248.3258","10.1184","6.7456","59.1252"
"40.6400","10.1375","248.7008","10.1375","6.7584","59.2145"
"40.7200","10.1575","249.1194","10.1575","6.7717","59.3141"
"40.8000","10.1762","249.4838","10.1762","6.7841","59.4009"
"40.8800","10.1975","249.9519","10.1975","6.7983","59.5124"
"40.9600","10.2168","250.3407","10.2168","6.8112","59.6049"
"41.0400","10.2363","250.7416","10.2363","6.8242","59.7004"
"41.1200","10.2565","251.1747","10.2565","6.8376","59.8035"
"41.2000","10.2775","251.6193","10.2775","6.8517","59.9094"
"41.2800","10.2977","252.0508","10.2977","6.8651","60.0121"
"41.3600","10.3177","252.4534","10.3177","6.8784","60.1080"
"41.4400","10.3365","252.8249","10.3365","6.8910","60.1964"
"41.5200","10.3567","253.2501","10.3567","6.9044","60.2976"
"41.6000","10.3767","253.6620","10.3767","6.9178","60.3957"
"41.6800","10.3974","254.1133","10.3974","6.9316","60.5032"
"41.7600","10.4183","254.5461","10.4183","6.9455","60.6062"
"41.8400","10.4368","254.8967","10.4368","6.9579","60.6897"
"41.9200","10.4574","255.3315","10.4574","6.9716","60.7932"
"42.0000","10.4777","255.7476","10.4777","6.9852","60.8923"
"42.0800","10.4970","256.1443","10.4970","6.9980","60.9867"
"42.1600","10.5170","256.5551","10.5170","7.0113","61.0845"
"42.2400","10.5363","256.9356","10.5363","7.0242","61.1752"
"42.3200","10.5567","257.3610","10.5567","7.0378","61.2764"
"42.4000","10.5782","257.8308","10.5782","7.0521","61.3883"
"42.4800","10.5975","258.2169","10.5975","7.0650","61.4802"
"42.5600","10.6179","258.6419","10.6179","7.0786","61.5814"
"42.6400","10.6364","258.9815","10.6364","7.0909","61.6623"
"42.7200","10.6564","259.4105","10.6564","7.1042","61.7644"
"42.8000","10.6769","259.8489","10.6769","7.1180","61.8688"
"42.8800","10.6968","260.2449","10.6968","7.1312","61.9631"
"42.9600","10.7173","260.6850","10.7173","7.1449","62.0678"
"43.0400","10.7384","261.1245","10.7384","7.1589","62.1725"
"43.1200","10.7573","261.4946","10.7573","7.1715","62.2606"
"43.2000","10.7774","261.9140","10.7774","7.1850","62.3605"
"43.2800","10.7966","262.2787","10.7966","7.1977","62.4473"
"43.3600","10.8172","262.7235","10.8172","7.2114","62.5532"
"43.4400","10.8373","263.1316","10.8373","7.2249","62.6504"
"43.5200","10.8561","263.5095","10.8561","7.2374","62.7404"
"43.6000","10.8763","263.9290","10.8763","7.2509","62.8402"
"43.6800","10.8977","264.3898","10.8977","7.2651","62.9499"
"43.7600","10.9180","264.8052","10.9180","7.2787","63.0489"
"43.8400","10.9374","265.1887","10.9374","7.2916","63.1402"
"43.9200","10.9560","265.5287","10.9560","7.3040","63.2211"
"44.0000","10.9769","265.9790","10.9769","7.3179","63.3283"
"44.0800","10.9971","266.3837","10.9971","7.3314","63.4247"
"44.1600","11.0166","266.7766","11.0166","7.3444","63.5182"
"44.2400","11.0374","267.2101","11.0374","7.3582","63.6215"
"44.3200","11.0572","267.5986","11.0572","7.3715","63.7140"
"44.4000","11.0779","268.0314","11.0779","7.3853","63.8170"
"44.4800","11.0978","268.4345","11.0978","7.3986","63.9130"
"44.5600","11.1172","268.8221","11.1172","7.4114","64.0053"
"44.6400","11.1365","269.2030","11.1365","7.4243","64.0959"
"44.7200","11.1560","269.5800","11.1560","7.4374","64.1857"
"44.8000","11.1764","270.0185","11.1764","7.4509","64.2901"
"44.8800","11.1985","270.4943","11.1985","7.4657","64.4034"
"44.9600","11.2176","270.8533","11.2176","7.4784","64.4889"
"45.0400","11.2378","271.2613","11.2378","7.4919","64.5860"
"45.1200","11.2566","271.6057","11.2566","7.5044","64.6680"
"45.2000","11.2763","272.0115","11.2763","7.5175","64.7646"
"45.2800","11.2969","272.4399","11.2969","7.5313","64.8666"
"45.3600","11.3169","272.8387","11.3169","7.5446","64.9616"
"45.4400","11.3370","273.2491","11.3370","7.5580","65.0593"
"45.5200","11.3583","273.7013","11.3583","7.5722","65.1670"
"45.6000","11.3777","274.0789","11.3777","7.5851","65.2569"
"45.6800","11.3980","274.4820","11.3980","7.5987","65.3528"
"45.7600","11.4172","274.8543","11.4172","7.6115","65.4415"
"45.8400","11.4369","275.2570","11.4369","7.6246","65.5374"
"45.9200","11.4567","275.6494","11.4567","7.6378","65.6308"
"46.0000","11.4757","276.0150","11.4757","7.6505","65.7179"
"46.0800","11.4972","276.4821","11.4972","7.6648","65.8291"
"46.1600","11.5180","276.9136","11.5180","7.6787","65.9318"
"46.2400","11.5373","277.2887","11.5373","7.6915","66.0211"
"46.3200","11.5567","277.6641","11.5567","7.7045","66.1105"
"46.4000","11.5766","278.0650","11.5766","7.7177","66.2060"
"46.4800","11.5968","278.4880","11.5968","7.7312","66.3067"
"46.5600","11.6175","278.9169","11.6175","7.7450","66.4088"
"46.6400","11.6360","279.2638","11.6360","7.7574","66.4914"
"46.7200","11.6576","279.7217","11.6576","7.7717","66.6004"
"46.8000","11.6781","280.1492","11.6781","7.7854","66.7022"
"46.8800","11.6984","280.5479","11.6984","7.7989","66.7971"
"46.9600","11.7170","280.9073","11.7170","7.8113","66.8827"
"47.0400","11.7365","281.2815","11.7365","7.8243","66.9718"
"47.1200","11.7564","281.6727","11.7564","7.8376","67.0649"
"47.2000","11.7775","282.1171","11.7775","7.8516","67.1707"
"47.2800","11.7964","282.4900","11.7964","7.8643","67.2595"
"47.3600","11.8173","282.9227","11.8173","7.8782","67.3625"
"47.4400","11.8374","283.3219","11.8374","7.8916","67.4576"
"47.5200","11.8576","283.7449","11.8576","7.9051","67.5583"
"47.6000","11.8775","284.1332","11.8775","7.9183","67.6508"
"47.6800","11.8962","284.4858","11.8962","7.9308","67.7347"
"47.7600","11.9169","284.9007","11.9169","7.9446","67.8335"
"47.8400","11.9369","285.3102","11.9369","7.9579","67.9310"
"47.9200","11.9567","285.7060","11.9567","7.9711","68.0252"
"48.0000","11.9777","286.1586","11.9777","7.9852","68.1330"
"48.0800","11.9980","286.5614","11.9980","7.9987","68.2289"
"48.1600","12.0182","286.9619","12.0182","8.0121","68.3243"
"48.2400","12.0373","287.3229","12.0373","8.0249","68.4102"
"48.3200","12.0563","287.6916","12.0563","8.0375","68.4980"
"48.4000","12.0772","288.1292","12.0772","8.0515","68.6022"
"48.4800","12.0960","288.4717","12.0960","8.0640","68.6837"
"48.5600","12.1174","288.9320","12.1174","8.0783","68.7933"
"48.6400","12.1377","289.3492","12.1377","8.0918","68.8927"
"48.7200","12.1574","289.7259","12.1574","8.1049","68.9824"
"48.8000","12.1770","290.1064","12.1770","8.1180","69.0729"
"48.8800","12.1974","290.5166","12.1974","8.1316","69.1706"
"48.9600","12.2166","290.8824","12.2166","8.1444","69.2577"
"49.0400","12.2369","291.2998","12.2369","8.1580","69.3571"
"49.1200","12.2558","291.6419","12.2558","8.1705","69.4385"
"49.2000","12.2779","292.1337","12.2779","8.1852","69.5556"
"49.2800","12.2985","292.5421","12.2985","8.1990","69.6529"
"49.3600","12.3179","292.9077","12.3179","8.2119","69.7399"
"49.4400","12.3370","293.2642","12.3370","8.2246","69.8248"
"49.5200","12.3568","293.6562","12.3568","8.2379","69.9181"
"49.6000","12.3769","294.0648","12.3769","8.2513","70.0154"
"49.6800","12.3975","294.4814","12.3975","8.2650","70.1146"
"49.7600","12.4159","294.8129","12.4159","8.2773","70.1935"
"49.8400","12.4368","295.2523","12.4368","8.2912","70.2982"
"49.9200","12.4576","295.6762","12.4576","8.3051","70.3991"
"50.0000","12.4774","296.0672","12.4774","8.3182","70.4922"
"50.0800","12.4974","296.4539","12.4974","8.3316","70.5843"
"50.1600","12.5165","296.7972","12.5165","8.3443","70.6660"
"50.2400","12.5371","297.2196","12.5371","8.3581","70.7666"
"50.3200","12.5568","297.6006","12.5568","8.3712","70.8573"
"50.4000","12.5763","297.9872","12.5763","8.3842","70.9493"
"50.4800","12.5975","298.4427","12.5975","8.3983","71.0578"
"50.5600","12.6183","298.8611","12.6183","8.4122","71.1574"
"50.6400","12.6378","299.2296","12.6378","8.4252","71.2451"
"50.7200","12.6579","299.6280","12.6579","8.4386","71.3400"
"50.8000","12.6763","299.9560","12.6763","8.4509","71.4181"
"50.8800","12.6975","300.3926","12.6975","8.4650","71.5220"
"50.9600","12.7164","300.7361","12.7164","8.4776","71.6038"
"51.0400","12.7363","301.1454","12.7363","8.4909","71.7013"
"51.1200","12.7567","301.5653","12.7567","8.5045","71.8013"
"51.2000","12.7776","302.0038","12.7776","8.5184","71.9057"
"51.2800","12.7978","302.4090","12.7978","8.5319","72.0022"
"51.3600","12.8178","302.7979","12.8178","8.5452","72.0947"
"51.4400","12.8361","303.1217","12.8361","8.5574","72.1718"
"51.5200","12.8566","303.5403","12.8566","8.5711","72.2715"
"51.6000","12.8764","303.9281","12.8764","8.5843","72.3638"
"51.6800","12.8975","304.3737","12.8975","8.5983","72.4699"
"51.7600","12.9182","304.7955","12.9182","8.6122","72.5704"
"51.8400","12.9373","305.1512","12.9373","8.6249","72.6550"
"51.9200","12.9576","305.5486","12.9576","8.6384","72.7497"
"52.0000","12.9774","305.9489","12.9774","8.6516","72.8450"
"52.0800","12.9970","306.3203","12.9970","8.6646","72.9334"
"52.1600","13.0169","306.7243","13.0169","8.6780","73.0296"
"52.2400","13.0363","307.0952","13.0363","8.6909","73.1179"
"52.3200","13.0569","307.5164","13.0569","8.7046","73.2182"
"52.4000","13.0776","307.9313","13.0776","8.7184","73.3170"
"52.4800","13.0974","308.3188","13.0974","8.7316","73.4092"
"52.5600","13.1181","308.7339","13.1181","8.7454","73.5081"
"52.6400","13.1366","309.0594","13.1366","8.7578","73.5856"
"52.7200","13.1566","309.4445","13.1566","8.7710","73.6773"
"52.8000","13.1763","309.8372","13.1763","8.7842","73.7708"
"52.8800","13.1962","310.2190","13.1962","8.7974","73.8617"
"52.9600","13.2176","310.6582","13.2176","8.8117","73.9662"
"53.0400","13.2386","311.0898","13.2386","8.8257","74.0690"
"53.1200","13.2574","311.4295","13.2574","8.8382","74.1499"
"53.2000","13.2775","311.8459","13.2775","8.8516","74.2490"
"53.2800","13.2967","312.1923","13.2967","8.8645","74.3315"
"53.3600","13.3173","312.6192","13.3173","8.8782","74.4331"
"53.4400","13.3372","312.9915","13.3372","8.8914","74.5218"
"53.5200","13.3560","313.3363","13.3560","8.9040","74.6039"
"53.6000","13.3768","313.7599","13.3768","8.9179","74.7048"
"53.6800","13.3977","314.1852","13.3977","8.9318","74.8060"
"53.7600","13.4175","314.5635","13.4175","8.9450","74.8961"
"53.8400","13.4372","314.9452","13.4372","8.9581","74.9869"
"53.9200","13.4562","315.2828","13.4562","8.9708","75.0673"
"54.0000","13.4770","315.7050","13.4770","8.9847","75.1679"
"54.0800","13.4973","316.1066","13.4973","8.9982","75.2635"
"54.1600","13.5169","316.4941","13.5169","9.0113","75.3557"
"54.2400","13.5376","316.9130","13.5376","9.0251","75.4555"
"54.3200","13.5576","317.2841","13.5576","9.0384","75.5438"
"54.4000","13.5782","317.6843","13.5782","9.0521","75.6391"
"54.4800","13.5976","318.0558","13.5976","9.0651","75.7276"
"54.5600","13.6169","318.4138","13.6169","9.0780","75.8128"
"54.6400","13.6369","318.8200","13.6369","9.0913","75.9095"
"54.7200","13.6565","319.1839","13.6565","9.1043","75.9962"
"54.8000","13.6764","319.5857","13.6764","9.1176","76.0918"
"54.8800","13.6981","320.0342","13.6981","9.1321","76.1986"
"54.9600","13.7169","320.3643","13.7169","9.1446","76.2772"
"55.0400","13.7376","320.7831","13.7376","9.1584","76.3769"
"55.1200","13.7571","321.1294","13.7571","9.1714","76.4594"
"55.2000","13.7763","321.5019","13.7763","9.1842","76.5481"
"55.2800","13.7965","321.8928","13.7965","9.1977","76.6411"
"55.3600","13.8170","322.2948","13.8170","9.2113","76.7369"
"55.4400","13.8374","322.6956","13.8374","9.2249","76.8323"
"55.5200","13.8582","323.1104","13.8582","9.2388","76.9310"
"55.6000","13.8776","323.4704","13.8776","9.2518","77.0168"
"55.6800","13.8977","323.8531","13.8977","9.2651","77.1079"
"55.7600","13.9172","324.2078","13.9172","9.2781","77.1923"
"55.8400","13.9368","324.5928","13.9368","9.2912","77.2840"
"55.9200","13.9567","324.9664","13.9567","9.3045","77.3730"
"56.0000","13.9755","325.2940","13.9755","9.3170","77.4510"
"56.0800","13.9975","325.7944","13.9975","9.3317","77.5701"
"56.1600","14.0182","326.1938","14.0182","9.3454","77.6652"
"56.2400","14.0372","326.5213","14.0372","9.3581","77.7432"
"56.3200","14.0569","326.9053","14.0569","9.3712","77.8346"
"56.4000","14.0767","327.2667","14.0767","9.3845","77.9206"
"56.4800","14.0970","327.6696","14.0970","9.3980","78.0166"
"56.5600","14.1175","328.0711","14.1175","9.4117","78.1122"
"56.6400","14.1362","328.3957","14.1362","9.4241","78.1895"
"56.7200","14.1570","328.8184","14.1570","9.4380","78.2901"
"56.8000","14.1778","329.2351","14.1778","9.4519","78.3893"
"56.8800","14.1982","329.6305","14.1982","9.4655","78.4834"
"56.9600","14.2173","329.9707","14.2173","9.4782","78.5645"
"57.0400","14.2367","330.3222","14.2367","9.4911","78.6481"
"57.1200","14.2567","330.7118","14.2567","9.5045","78.7409"
"57.2000","14.2771","331.1045","14.2771","9.5181","78.8344"
"57.2800","14.2962","331.4543","14.2962","9.5308","78.9177"
"57.3600","14.3174","331.8932","14.3174","9.5450","79.0222"
"57.4400","14.3372","332.2511","14.3372","9.5581","79.1074"
"57.5200","14.3569","332.6077","14.3569","9.5713","79.1923"
"57.6000","14.3774","333.0083","14.3774","9.5849","79.2877"
"57.6800","14.3968","333.3620","14.3968","9.5979","79.3719"
"57.7600","14.4171","333.7479","14.4171","9.6114","79.4638"
"57.8400","14.4364","334.0973","14.4364","9.6243","79.5470"
"57.9200","14.4566","334.5033","14.4566","9.6377","79.6437"
"58.0000","14.4780","334.9392","14.4780","9.6520","79.7474"
"58.0800","14.4979","335.3004","14.4979","9.6653","79.8334"
"58.1600","14.5176","335.6503","14.5176","9.6784","79.9167"
"58.2400","14.5373","336.0084","14.5373","9.6915","80.0020"
"58.3200","14.5562","336.3438","14.5562","9.7041","80.0819"
"58.4000","14.5769","336.7449","14.5769","9.7179","80.1774"
"58.4800","14.5963","337.0907","14.5963","9.7309","80.2597"
"58.5600","14.6169","337.4923","14.6169","9.7446","80.3553"
"58.6400","14.6374","337.8849","14.6374","9.7582","80.4488"
"58.7200","14.6571","338.2339","14.6571","9.7714","80.5319"
"58.8000","14.6776","338.6207","14.6776","9.7851","80.6240"
"58.8800","14.6975","338.9796","14.6975","9.7983","80.7094"
"58.9600","14.7165","339.3089","14.7165","9.8110","80.7878"
"59.0400","14.7368","339.6953","14.7368","9.8245","80.8798"
"59.1200","14.7557","340.0000","14.7557","9.8371","80.9524"
"59.2000","14.7777","340.4657","14.7777","9.8518","81.0633"
"59.2800","14.7985","340.8379","14.7985","9.8657","81.1519"
"59.3600","14.8177","341.1742","14.8177","9.8785","81.2319"
"59.4400","14.8371","341.5006","14.8371","9.8914","81.3097"
"59.5200","14.8568","341.8479","14.8568","9.9045","81.3924"
"59.6000","14.8769","342.2123","14.8769","9.9180","81.4791"
"59.6800","14.8973","342.5853","14.8973","9.9315","81.5679"
"59.7600","14.9162","342.8863","14.9162","9.9442","81.6396"
"59.8400","14.9369","343.2711","14.9369","9.9579","81.7312"
"59.9200","14.9576","343.6546","14.9576","9.9717","81.8225"
"60.0000","14.9775","344.0028","14.9775","9.9850","81.9054"
"60.0800","14.9975","344.3520","14.9975","9.9984","81.9886"
"60.0900","15.0001","344.3925","15.0001","10.0000","81.9982"