File: data/instron_tests/metamaterials/250331/250331_1049_VERT_m1.is_comp_Exports/250331_1049_VERT_m1_2_1.csv
Results Table 1
,Compresson Axis,H*,V*,Height,Thickness,Width,Area,Fixture separation,Specimen label
,,,,(mm),(mm),(mm),(mm^2),(mm),
"2","Y","","","150.00","28.00","150.00","4200.00","150.00","1049_VERT_m1"

Results Table 2
,Modulus (Segment 0 % - 5 %),Compresson Axis
,(kPa),
"2","925.33","Y"

Time,Displacement,Force,Compressive displacement,Compressive strain (Displacement),Compressive stress
(s),(mm),(N),(mm),(%),(kPa)
"0.0000","0.0000","-12.2382","0.0000","0.0000","-2.9138"
"0.0800","0.0013","-12.1626","0.0013","0.0009","-2.8959"
"0.1600","0.0179","-11.5128","0.0179","0.0119","-2.7411"
"0.2400","0.0387","-10.7343","0.0387","0.0258","-2.5558"
"0.3200","0.0583","-10.0298","0.0583","0.0388","-2.3880"
"0.4000","0.0777","-9.3428","0.0777","0.0518","-2.2245"
"0.4800","0.0985","-8.6111","0.0985","0.0657","-2.0503"
"0.5600","0.1185","-7.9358","0.1185","0.0790","-1.8895"
"0.6400","0.1386","-7.2590","0.1386","0.0924","-1.7283"
"0.7200","0.1582","-6.6058","0.1582","0.1055","-1.5728"
"0.8000","0.1772","-5.9777","0.1772","0.1181","-1.4233"
"0.8800","0.1979","-5.3141","0.1979","0.1319","-1.2653"
"0.9600","0.2176","-4.6664","0.2176","0.1450","-1.1110"
"1.0400","0.2365","-4.0501","0.2365","0.1577","-0.9643"
"1.1200","0.2576","-3.3659","0.2576","0.1717","-0.8014"
"1.2000","0.2781","-2.7205","0.2781","0.1854","-0.6477"
"1.2800","0.2987","-2.0663","0.2987","0.1991","-0.4920"
"1.3600","0.3181","-1.4576","0.3181","0.2121","-0.3471"
"1.4400","0.3370","-0.8693","0.3370","0.2247","-0.2070"
"1.5200","0.3573","-0.2365","0.3573","0.2382","-0.0563"
"1.6000","0.3773","0.3893","0.3773","0.2516","0.0927"
"1.6800","0.3981","1.0449","0.3981","0.2654","0.2488"
"1.7600","0.4190","1.6901","0.4190","0.2793","0.4024"
"1.8400","0.4380","2.2675","0.4380","0.2920","0.5399"
"1.9200","0.4581","2.8950","0.4581","0.3054","0.6893"
"2.0000","0.4782","3.5034","0.4782","0.3188","0.8341"
"2.0800","0.4974","4.0998","0.4974","0.3316","0.9761"
"2.1600","0.5180","4.7228","0.5180","0.3453","1.1245"
"2.2400","0.5370","5.2900","0.5370","0.3580","1.2595"
"2.3200","0.5577","5.9275","0.5577","0.3718","1.4113"
"2.4000","0.5790","6.5760","0.5790","0.3860","1.5657"
"2.4800","0.5981","7.1457","0.5981","0.3988","1.7013"
"2.5600","0.6184","7.7609","0.6184","0.4123","1.8478"
"2.6400","0.6373","8.3130","0.6373","0.4249","1.9793"
"2.7200","0.6570","8.9044","0.6570","0.4380","2.1201"
"2.8000","0.6774","9.5254","0.6774","0.4516","2.2679"
"2.8800","0.6973","10.1101","0.6973","0.4648","2.4072"
"2.9600","0.7182","10.7478","0.7182","0.4788","2.5590"
"3.0400","0.7393","11.3706","0.7393","0.4929","2.7073"
"3.1200","0.7580","11.9209","0.7580","0.5053","2.8383"
"3.2000","0.7779","12.5106","0.7779","0.5186","2.9787"
"3.2800","0.7973","13.0786","0.7973","0.5315","3.1140"
"3.3600","0.8183","13.7019","0.8183","0.5455","3.2624"
"3.4400","0.8380","14.2788","0.8380","0.5587","3.3997"
"3.5200","0.8566","14.8244","0.8566","0.5711","3.5296"
"3.6000","0.8771","15.4372","0.8771","0.5848","3.6755"
"3.6800","0.8984","16.0710","0.8984","0.5990","3.8264"
"3.7600","0.9185","16.6479","0.9185","0.6123","3.9638"
"3.8400","0.9374","17.1917","0.9374","0.6250","4.0933"
"3.9200","0.9562","17.7287","0.9562","0.6375","4.2211"
"4.0000","0.9780","18.3805","0.9780","0.6520","4.3763"
"4.0800","0.9982","18.9649","0.9982","0.6654","4.5155"
"4.1600","1.0176","19.5317","1.0176","0.6784","4.6504"
"4.2400","1.0383","20.1303","1.0383","0.6922","4.7929"
"4.3200","1.0582","20.7121","1.0582","0.7055","4.9314"
"4.4000","1.0788","21.3025","1.0788","0.7192","5.0720"
"4.4800","1.0987","21.8757","1.0987","0.7325","5.2085"
"4.5600","1.1173","22.4100","1.1173","0.7449","5.3357"
"4.6400","1.1373","22.9825","1.1373","0.7582","5.4720"
"4.7200","1.1570","23.5391","1.1570","0.7714","5.6046"
"4.8000","1.1775","24.1400","1.1775","0.7850","5.7476"
"4.8800","1.1988","24.7574","1.1988","0.7992","5.8946"
"4.9600","1.2179","25.2944","1.2179","0.8120","6.0225"
"5.0400","1.2382","25.8791","1.2382","0.8255","6.1617"
"5.1200","1.2576","26.4187","1.2576","0.8384","6.2902"
"5.2000","1.2770","26.9796","1.2770","0.8513","6.4237"
"5.2800","1.2978","27.5825","1.2978","0.8652","6.5673"
"5.3600","1.3172","28.1176","1.3172","0.8782","6.6947"
"5.4400","1.3378","28.7109","1.3378","0.8919","6.8359"
"5.5200","1.3590","29.3223","1.3590","0.9060","6.9815"
"5.6000","1.3784","29.8714","1.3784","0.9189","7.1122"
"5.6800","1.3982","30.4176","1.3982","0.9322","7.2423"
"5.7600","1.4178","30.9731","1.4178","0.9452","7.3745"
"5.8400","1.4380","31.5540","1.4380","0.9587","7.5129"
"5.9200","1.4576","32.0977","1.4576","0.9718","7.6423"
"6.0000","1.4765","32.6224","1.4765","0.9843","7.7672"
"6.0800","1.4981","33.2516","1.4981","0.9988","7.9171"
"6.1600","1.5188","33.8332","1.5188","1.0126","8.0555"
"6.2400","1.5380","34.3677","1.5380","1.0253","8.1828"
"6.3200","1.5575","34.9254","1.5575","1.0383","8.3156"
"6.4000","1.5768","35.4505","1.5768","1.0512","8.4406"
"6.4800","1.5977","36.0482","1.5977","1.0651","8.5829"
"6.5600","1.6183","36.6260","1.6183","1.0788","8.7205"
"6.6400","1.6368","37.1426","1.6368","1.0912","8.8435"
"6.7200","1.6582","37.7504","1.6582","1.1055","8.9882"
"6.8000","1.6785","38.3155","1.6785","1.1190","9.1227"
"6.8800","1.6995","38.9113","1.6995","1.1330","9.2646"
"6.9600","1.7178","39.4037","1.7178","1.1452","9.3818"
"7.0400","1.7370","39.9273","1.7370","1.1580","9.5065"
"7.1200","1.7574","40.5113","1.7574","1.1716","9.6455"
"7.2000","1.7779","41.0736","1.7779","1.1853","9.7794"
"7.2800","1.7971","41.6116","1.7971","1.1981","9.9075"
"7.3600","1.8185","42.2164","1.8185","1.2123","10.0515"
"7.4400","1.8379","42.7298","1.8379","1.2253","10.1738"
"7.5200","1.8582","43.3001","1.8582","1.2388","10.3096"
"7.6000","1.8780","43.8380","1.8780","1.2520","10.4376"
"7.6800","1.8972","44.3703","1.8972","1.2648","10.5644"
"7.7600","1.9176","44.9361","1.9176","1.2784","10.6991"
"7.8400","1.9375","45.4820","1.9375","1.2917","10.8290"
"7.9200","1.9573","46.0348","1.9573","1.3049","10.9607"
"8.0000","1.9787","46.6454","1.9787","1.3191","11.1061"
"8.0800","1.9987","47.1807","1.9987","1.3325","11.2335"
"8.1600","2.0190","47.7360","2.0190","1.3460","11.3657"
"8.2400","2.0385","48.2535","2.0385","1.3590","11.4889"
"8.3200","2.0570","48.7625","2.0570","1.3713","11.6101"
"8.4000","2.0777","49.3317","2.0777","1.3851","11.7456"
"8.4800","2.0969","49.8557","2.0969","1.3980","11.8704"
"8.5600","2.1178","50.4256","2.1178","1.4119","12.0061"
"8.6400","2.1385","50.9991","2.1385","1.4256","12.1427"
"8.7200","2.1575","51.5003","2.1575","1.4384","12.2620"
"8.8000","2.1781","52.0656","2.1781","1.4521","12.3966"
"8.8800","2.1984","52.6140","2.1984","1.4656","12.5271"
"8.9600","2.2172","53.1083","2.2172","1.4781","12.6448"
"9.0400","2.2374","53.6602","2.2374","1.4916","12.7762"
"9.1200","2.2568","54.1728","2.2568","1.5045","12.8983"
"9.2000","2.2786","54.7789","2.2786","1.5191","13.0426"
"9.2800","2.2991","55.3373","2.2991","1.5327","13.1756"
"9.3600","2.3183","55.8569","2.3183","1.5455","13.2993"
"9.4400","2.3380","56.3944","2.3380","1.5586","13.4272"
"9.5200","2.3575","56.9018","2.3575","1.5717","13.5480"
"9.6000","2.3777","57.4564","2.3777","1.5852","13.6801"
"9.6800","2.3979","58.0013","2.3979","1.5986","13.8098"
"9.7600","2.4166","58.4822","2.4166","1.6110","13.9243"
"9.8400","2.4378","59.0706","2.4378","1.6252","14.0644"
"9.9200","2.4582","59.6100","2.4582","1.6388","14.1929"
"10.0000","2.4780","60.1453","2.4780","1.6520","14.3203"
"10.0800","2.4984","60.6996","2.4984","1.6656","14.4523"
"10.1600","2.5175","61.2023","2.5175","1.6783","14.5720"
"10.2400","2.5378","61.7445","2.5378","1.6919","14.7011"
"10.3200","2.5577","62.2680","2.5577","1.7051","14.8257"
"10.4000","2.5769","62.7841","2.5769","1.7179","14.9486"
"10.4800","2.5983","63.3591","2.5983","1.7322","15.0855"
"10.5600","2.6188","63.9048","2.6188","1.7458","15.2154"
"10.6400","2.6387","64.4371","2.6387","1.7592","15.3422"
"10.7200","2.6585","64.9585","2.6585","1.7723","15.4663"
"10.8000","2.6769","65.4436","2.6769","1.7846","15.5818"
"10.8800","2.6979","66.0101","2.6979","1.7986","15.7167"
"10.9600","2.7176","66.5327","2.7176","1.8117","15.8411"
"11.0400","2.7373","67.0621","2.7373","1.8249","15.9672"
"11.1200","2.7576","67.6006","2.7576","1.8384","16.0954"
"11.2000","2.7779","68.1329","2.7779","1.8519","16.2221"
"11.2800","2.7982","68.6694","2.7982","1.8655","16.3499"
"11.3600","2.8185","69.2035","2.8185","1.8790","16.4770"
"11.4400","2.8365","69.6569","2.8365","1.8910","16.5850"
"11.5200","2.8569","70.2080","2.8569","1.9046","16.7162"
"11.6000","2.8773","70.7460","2.8773","1.9182","16.8443"
"11.6800","2.8985","71.3055","2.8985","1.9323","16.9775"
"11.7600","2.9186","71.8351","2.9186","1.9457","17.1036"
"11.8400","2.9379","72.3384","2.9379","1.9586","17.2234"
"11.9200","2.9581","72.8639","2.9581","1.9721","17.3486"
"12.0000","2.9780","73.3932","2.9780","1.9853","17.4746"
"12.0800","2.9977","73.9084","2.9977","1.9985","17.5972"
"12.1600","3.0177","74.4436","3.0177","2.0118","17.7247"
"12.2400","3.0368","74.9229","3.0368","2.0246","17.8388"
"12.3200","3.0578","75.4941","3.0578","2.0385","17.9748"
"12.4000","3.0788","76.0426","3.0788","2.0525","18.1054"
"12.4800","3.0980","76.5556","3.0980","2.0654","18.2275"
"12.5600","3.1184","77.0780","3.1184","2.0790","18.3519"
"12.6400","3.1374","77.5550","3.1374","2.0916","18.4655"
"12.7200","3.1573","78.0813","3.1573","2.1049","18.5908"
"12.8000","3.1774","78.6082","3.1774","2.1183","18.7162"
"12.8800","3.1974","79.1356","3.1974","2.1316","18.8418"
"12.9600","3.2187","79.7238","3.2187","2.1458","18.9819"
"13.0400","3.2390","80.2519","3.2390","2.1593","19.1076"
"13.1200","3.2580","80.7450","3.2580","2.1720","19.2250"
"13.2000","3.2783","81.2677","3.2783","2.1856","19.3495"
"13.2800","3.2975","81.7551","3.2975","2.1983","19.4655"
"13.3600","3.3183","82.3099","3.3183","2.2122","19.5976"
"13.4400","3.3378","82.8013","3.3378","2.2252","19.7146"
"13.5200","3.3564","83.2798","3.3564","2.2376","19.8285"
"13.6000","3.3777","83.8499","3.3777","2.2518","19.9643"
"13.6800","3.3984","84.3887","3.3984","2.2656","20.0925"
"13.7600","3.4183","84.9017","3.4183","2.2789","20.2147"
"13.8400","3.4381","85.4097","3.4381","2.2920","20.3356"
"13.9200","3.4567","85.8698","3.4567","2.3044","20.4452"
"14.0000","3.4779","86.4323","3.4779","2.3186","20.5791"
"14.0800","3.4981","86.9492","3.4981","2.3321","20.7022"
"14.1600","3.5174","87.4453","3.5174","2.3449","20.8203"
"14.2400","3.5381","87.9933","3.5381","2.3587","20.9508"
"14.3200","3.5579","88.5018","3.5579","2.3719","21.0719"
"14.4000","3.5785","89.0279","3.5785","2.3857","21.1971"
"14.4800","3.5983","89.5427","3.5983","2.3988","21.3197"
"14.5600","3.6177","90.0341","3.6177","2.4118","21.4367"
"14.6400","3.6375","90.5543","3.6375","2.4250","21.5606"
"14.7200","3.6570","91.0489","3.6570","2.4380","21.6783"
"14.8000","3.6768","91.5657","3.6768","2.4512","21.8013"
"14.8800","3.6989","92.1621","3.6989","2.4660","21.9434"
"14.9600","3.7181","92.6372","3.7181","2.4787","22.0565"
"15.0400","3.7383","93.1480","3.7383","2.4922","22.1781"
"15.1200","3.7574","93.6320","3.7574","2.5049","22.2933"
"15.2000","3.7768","94.1433","3.7768","2.5179","22.4151"
"15.2800","3.7973","94.6790","3.7973","2.5315","22.5426"
"15.3600","3.8176","95.1992","3.8176","2.5451","22.6665"
"15.4400","3.8380","95.7296","3.8380","2.5586","22.7928"
"15.5200","3.8590","96.2736","3.8590","2.5726","22.9223"
"15.6000","3.8782","96.7597","3.8782","2.5855","23.0380"
"15.6800","3.8985","97.2815","3.8985","2.5990","23.1623"
"15.7600","3.9180","97.7668","3.9180","2.6120","23.2778"
"15.8400","3.9376","98.2746","3.9376","2.6251","23.3987"
"15.9200","3.9577","98.7845","3.9577","2.6385","23.5201"
"16.0000","3.9768","99.2709","3.9768","2.6512","23.6359"
"16.0800","3.9983","99.8323","3.9983","2.6656","23.7696"
"16.1600","4.0186","100.3484","4.0186","2.6791","23.8925"
"16.2400","4.0378","100.8261","4.0378","2.6919","24.0062"
"16.3200","4.0574","101.3153","4.0574","2.7049","24.1227"
"16.4000","4.0772","101.8040","4.0772","2.7181","24.2391"
"16.4800","4.0977","102.3337","4.0977","2.7318","24.3652"
"16.5600","4.1185","102.8717","4.1185","2.7457","24.4933"
"16.6400","4.1368","103.3185","4.1368","2.7578","24.5996"
"16.7200","4.1583","103.8899","4.1583","2.7722","24.7357"
"16.8000","4.1784","104.3966","4.1784","2.7856","24.8563"
"16.8800","4.1986","104.9109","4.1986","2.7991","24.9788"
"16.9600","4.2179","105.3868","4.2179","2.8119","25.0921"
"17.0400","4.2372","105.8733","4.2372","2.8248","25.2079"
"17.1200","4.2574","106.3838","4.2574","2.8383","25.3295"
"17.2000","4.2780","106.9049","4.2780","2.8520","25.4535"
"17.2800","4.2969","107.3815","4.2969","2.8646","25.5670"
"17.3600","4.3180","107.9270","4.3180","2.8786","25.6969"
"17.4400","4.3378","108.4305","4.3378","2.8919","25.8168"
"17.5200","4.3583","108.9430","4.3583","2.9055","25.9388"
"17.6000","4.3781","109.4455","4.3781","2.9187","26.0585"
"17.6800","4.3973","109.9288","4.3973","2.9316","26.1735"
"17.7600","4.4175","110.4363","4.4175","2.9450","26.2944"
"17.8400","4.4373","110.9301","4.4373","2.9582","26.4119"
"17.9200","4.4573","111.4491","4.4573","2.9716","26.5355"
"18.0000","4.4788","112.0088","4.4788","2.9859","26.6688"
"18.0800","4.4987","112.4958","4.4987","2.9992","26.7847"
"18.1600","4.5188","113.0041","4.5188","3.0125","26.9057"
"18.2400","4.5382","113.4807","4.5382","3.0255","27.0192"
"18.3200","4.5569","113.9488","4.5569","3.0379","27.1307"
"18.4000","4.5781","114.4992","4.5781","3.0520","27.2617"
"18.4800","4.5970","114.9639","4.5970","3.0646","27.3723"
"18.5600","4.6177","115.4886","4.6177","3.0784","27.4973"
"18.6400","4.6384","116.0204","4.6384","3.0923","27.6239"
"18.7200","4.6579","116.4919","4.6579","3.1053","27.7362"
"18.8000","4.6778","116.9953","4.6778","3.1186","27.8560"
"18.8800","4.6981","117.5037","4.6981","3.1321","27.9771"
"18.9600","4.7172","117.9725","4.7172","3.1448","28.0887"
"19.0400","4.7378","118.4976","4.7378","3.1585","28.2137"
"19.1200","4.7564","118.9485","4.7564","3.1710","28.3211"
"19.2000","4.7785","119.5252","4.7785","3.1857","28.4584"
"19.2800","4.7988","120.0271","4.7988","3.1992","28.5779"
"19.3600","4.8184","120.5049","4.8184","3.2123","28.6917"
"19.4400","4.8376","120.9801","4.8376","3.2251","28.8048"
"19.5200","4.8576","121.4869","4.8576","3.2384","28.9255"
"19.6000","4.8782","122.0164","4.8782","3.2521","29.0515"
"19.6800","4.8983","122.5120","4.8983","3.2655","29.1695"
"19.7600","4.9169","122.9492","4.9169","3.2779","29.2736"
"19.8400","4.9376","123.4902","4.9376","3.2918","29.4024"
"19.9200","4.9583","123.9913","4.9583","3.3055","29.5217"
"20.0000","4.9784","124.5108","4.9784","3.3190","29.6454"
"20.0800","4.9982","124.9853","4.9982","3.3322","29.7584"
"20.1600","5.0170","125.4287","5.0170","3.3447","29.8640"
"20.2400","5.0371","125.9234","5.0371","3.3581","29.9818"
"20.3200","5.0575","126.4319","5.0575","3.3717","30.1028"
"20.4000","5.0775","126.9380","5.0775","3.3850","30.2233"
"20.4800","5.0983","127.4581","5.0983","3.3989","30.3472"
"20.5600","5.1186","127.9596","5.1186","3.4124","30.4666"
"20.6400","5.1387","128.4492","5.1387","3.4258","30.5831"
"20.7200","5.1584","128.9243","5.1584","3.4389","30.6963"
"20.8000","5.1771","129.3846","5.1771","3.4514","30.8059"
"20.8800","5.1981","129.9042","5.1981","3.4654","30.9296"
"20.9600","5.2173","130.3690","5.2173","3.4782","31.0402"
"21.0400","5.2370","130.8576","5.2370","3.4913","31.1566"
"21.1200","5.2578","131.3801","5.2578","3.5052","31.2810"
"21.2000","5.2781","131.8764","5.2781","3.5187","31.3991"
"21.2800","5.2981","132.3630","5.2981","3.5321","31.5150"
"21.3600","5.3186","132.8577","5.3186","3.5457","31.6328"
"21.4400","5.3366","133.2852","5.3366","3.5577","31.7346"
"21.5200","5.3574","133.8097","5.3574","3.5716","31.8594"
"21.6000","5.3768","134.2794","5.3768","3.5846","31.9713"
"21.6800","5.3980","134.8194","5.3980","3.5987","32.0998"
"21.7600","5.4190","135.3302","5.4190","3.6127","32.2215"
"21.8400","5.4382","135.7917","5.4382","3.6254","32.3314"
"21.9200","5.4582","136.2674","5.4582","3.6388","32.4446"
"22.0000","5.4779","136.7536","5.4779","3.6519","32.5604"
"22.0800","5.4976","137.2326","5.4976","3.6651","32.6744"
"22.1600","5.5180","137.7307","5.5180","3.6787","32.7930"
"22.2400","5.5367","138.1670","5.5367","3.6911","32.8969"
"22.3200","5.5574","138.6777","5.5574","3.7049","33.0185"
"22.4000","5.5786","139.2131","5.5786","3.7191","33.1460"
"22.4800","5.5981","139.6763","5.5981","3.7320","33.2563"
"22.5600","5.6187","140.2005","5.6187","3.7458","33.3811"
"22.6400","5.6370","140.6218","5.6370","3.7580","33.4814"
"22.7200","5.6571","141.1169","5.6571","3.7714","33.5993"
"22.8000","5.6773","141.6121","5.6773","3.7849","33.7172"
"22.8800","5.6975","142.1004","5.6975","3.7983","33.8334"
"22.9600","5.7186","142.6208","5.7186","3.8124","33.9573"
"23.0400","5.7388","143.1019","5.7388","3.8259","34.0719"
"23.1200","5.7575","143.5480","5.7575","3.8384","34.1781"
"23.2000","5.7784","144.0647","5.7784","3.8522","34.3011"
"23.2800","5.7974","144.5013","5.7974","3.8650","34.4051"
"23.3600","5.8184","145.0247","5.8184","3.8790","34.5297"
"23.4400","5.8381","145.4934","5.8381","3.8920","34.6413"
"23.5200","5.8565","145.9187","5.8565","3.9043","34.7426"
"23.6000","5.8773","146.4454","5.8773","3.9182","34.8680"
"23.6800","5.8990","146.9883","5.8990","3.9326","34.9972"
"23.7600","5.9185","147.4465","5.9185","3.9456","35.1063"
"23.8400","5.9382","147.9137","5.9382","3.9588","35.2176"
"23.9200","5.9569","148.3413","5.9569","3.9713","35.3194"
"24.0000","5.9776","148.8502","5.9776","3.9850","35.4405"
"24.0800","5.9982","149.3509","5.9982","3.9988","35.5597"
"24.1600","6.0175","149.8149","6.0175","4.0117","35.6702"
"24.2400","6.0377","150.2988","6.0377","4.0252","35.7854"
"24.3200","6.0580","150.7879","6.0580","4.0387","35.9019"
"24.4000","6.0789","151.2808","6.0789","4.0526","36.0192"
"24.4800","6.0986","151.7618","6.0986","4.0657","36.1338"
"24.5600","6.1177","152.2054","6.1177","4.0785","36.2394"
"24.6400","6.1375","152.6811","6.1375","4.0917","36.3526"
"24.7200","6.1574","153.1369","6.1574","4.1049","36.4612"
"24.8000","6.1769","153.6077","6.1769","4.1179","36.5733"
"24.8800","6.1987","154.1563","6.1987","4.1325","36.7039"
"24.9600","6.2181","154.6016","6.2181","4.1454","36.8099"
"25.0400","6.2383","155.0700","6.2383","4.1589","36.9214"
"25.1200","6.2574","155.5119","6.2574","4.1716","37.0267"
"25.2000","6.2769","155.9744","6.2769","4.1846","37.1368"
"25.2800","6.2975","156.4649","6.2975","4.1983","37.2535"
"25.3600","6.3173","156.9335","6.3173","4.2116","37.3651"
"25.4400","6.3381","157.4246","6.3381","4.2254","37.4821"
"25.5200","6.3588","157.9289","6.3588","4.2392","37.6021"
"25.6000","6.3783","158.3788","6.3783","4.2522","37.7092"
"25.6800","6.3985","158.8733","6.3985","4.2657","37.8270"
"25.7600","6.4182","159.3250","6.4182","4.2788","37.9345"
"25.8400","6.4378","159.7806","6.4378","4.2919","38.0430"
"25.9200","6.4578","160.2453","6.4578","4.3052","38.1536"
"26.0000","6.4765","160.6703","6.4765","4.3176","38.2548"
"26.0800","6.4978","161.1943","6.4978","4.3319","38.3796"
"26.1600","6.5192","161.7094","6.5192","4.3461","38.5022"
"26.2400","6.5383","162.1492","6.5383","4.3588","38.6070"
"26.3200","6.5577","162.6012","6.5577","4.3718","38.7146"
"26.4000","6.5773","163.0550","6.5773","4.3849","38.8226"
"26.4800","6.5979","163.5556","6.5979","4.3986","38.9418"
"26.5600","6.6185","164.0472","6.6185","4.4123","39.0589"
"26.6400","6.6367","164.4491","6.6367","4.4245","39.1545"
"26.7200","6.6580","164.9686","6.6580","4.4387","39.2782"
"26.8000","6.6786","165.4450","6.6786","4.4524","39.3917"
"26.8800","6.6986","165.9244","6.6986","4.4657","39.5058"
"26.9600","6.7178","166.3439","6.7178","4.4785","39.6057"
"27.0400","6.7370","166.7889","6.7370","4.4913","39.7116"
"27.1200","6.7577","167.2894","6.7577","4.5051","39.8308"
"27.2000","6.7780","167.7646","6.7780","4.5187","39.9439"
"27.2800","6.7970","168.2129","6.7970","4.5313","40.0507"
"27.3600","6.8179","168.7167","6.8179","4.5452","40.1706"
"27.4400","6.8379","169.1737","6.8379","4.5586","40.2795"
"27.5200","6.8584","169.6557","6.8584","4.5722","40.3942"
"27.6000","6.8780","170.1031","6.8780","4.5853","40.5007"
"27.6800","6.8974","170.5627","6.8974","4.5983","40.6102"
"27.7600","6.9175","171.0322","6.9175","4.6117","40.7220"
"27.8400","6.9373","171.4830","6.9373","4.6248","40.8293"
"27.9200","6.9574","171.9694","6.9574","4.6382","40.9451"
"28.0000","6.9787","172.4809","6.9787","4.6525","41.0669"
"28.0800","6.9987","172.9398","6.9987","4.6658","41.1761"
"28.1600","7.0187","173.4021","7.0187","4.6791","41.2862"
"28.2400","7.0383","173.8444","7.0383","4.6922","41.3915"
"28.3200","7.0572","174.2817","7.0572","4.7048","41.4956"
"28.4000","7.0776","174.7672","7.0776","4.7184","41.6112"
"28.4800","7.0969","175.1935","7.0969","4.7313","41.7127"
"28.5600","7.1177","175.6912","7.1177","4.7451","41.8312"
"28.6400","7.1384","176.1830","7.1384","4.7589","41.9483"
"28.7200","7.1582","176.6331","7.1582","4.7722","42.0555"
"28.8000","7.1779","177.0788","7.1779","4.7853","42.1616"
"28.8800","7.1981","177.5402","7.1981","4.7987","42.2715"
"28.9600","7.2175","177.9951","7.2175","4.8116","42.3798"
"29.0400","7.2375","178.4592","7.2375","4.8250","42.4903"
"29.1200","7.2565","178.8826","7.2565","4.8377","42.5911"
"29.2000","7.2784","179.4148","7.2784","4.8523","42.7178"
"29.2800","7.2991","179.8905","7.2991","4.8661","42.8311"
"29.3600","7.3178","180.2990","7.3178","4.8786","42.9283"
"29.4400","7.3377","180.7583","7.3377","4.8918","43.0377"
"29.5200","7.3575","181.2014","7.3575","4.9050","43.1432"
"29.6000","7.3780","181.6791","7.3780","4.9187","43.2569"
"29.6800","7.3986","182.1552","7.3986","4.9324","43.3703"
"29.7600","7.4166","182.5394","7.4166","4.9444","43.4618"
"29.8400","7.4375","183.0357","7.4375","4.9583","43.5799"
"29.9200","7.4584","183.5276","7.4584","4.9723","43.6970"
"30.0000","7.4785","183.9943","7.4785","4.9857","43.8082"
"30.0800","7.4987","184.4715","7.4987","4.9991","43.9218"
"30.1600","7.5171","184.8623","7.5171","5.0114","44.0148"
"30.2400","7.5375","185.3369","7.5375","5.0250","44.1278"
"30.3200","7.5576","185.7878","7.5576","5.0384","44.2352"
"30.4000","7.5773","186.2428","7.5773","5.0515","44.3435"
"30.4800","7.5984","186.7421","7.5984","5.0656","44.4624"
"30.5600","7.6189","187.1984","7.6189","5.0793","44.5710"
"30.6400","7.6385","187.6459","7.6385","5.0924","44.6776"
"30.7200","7.6586","188.0920","7.6586","5.1057","44.7838"
"30.8000","7.6772","188.5036","7.6772","5.1181","44.8818"
"30.8800","7.6981","188.9870","7.6981","5.1321","44.9969"
"30.9600","7.7174","189.4182","7.7174","5.1449","45.0996"
"31.0400","7.7369","189.8548","7.7369","5.1580","45.2035"
"31.1200","7.7578","190.3539","7.7578","5.1719","45.3224"
"31.2000","7.7785","190.8184","7.7785","5.1857","45.4329"
"31.2800","7.7985","191.2734","7.7985","5.1990","45.5413"
"31.3600","7.8183","191.7127","7.8183","5.2122","45.6459"
"31.4400","7.8368","192.1159","7.8368","5.2245","45.7419"
"31.5200","7.8573","192.5887","7.8573","5.2382","45.8545"
"31.6000","7.8772","193.0417","7.8772","5.2515","45.9623"
"31.6800","7.8982","193.5334","7.8982","5.2654","46.0794"
"31.7600","7.9191","194.0106","7.9191","5.2794","46.1930"
"31.8400","7.9380","194.4051","7.9380","5.2920","46.2869"
"31.9200","7.9578","194.8606","7.9578","5.3052","46.3954"
"32.0000","7.9783","195.3200","7.9783","5.3188","46.5048"
"32.0800","7.9975","195.7412","7.9975","5.3317","46.6051"
"32.1600","8.0178","196.2116","8.0178","5.3452","46.7171"
"32.2400","8.0370","196.6254","8.0370","5.3580","46.8156"
"32.3200","8.0576","197.1056","8.0576","5.3717","46.9299"
"32.4000","8.0789","197.6130","8.0789","5.3859","47.0507"
"32.4800","8.0980","198.0274","8.0980","5.3986","47.1494"
"32.5600","8.1183","198.4841","8.1183","5.4122","47.2581"
"32.6400","8.1370","198.8751","8.1370","5.4247","47.3512"
"32.7200","8.1572","199.3482","8.1572","5.4381","47.4639"
"32.8000","8.1774","199.8040","8.1774","5.4516","47.5724"
"32.8800","8.1973","200.2387","8.1973","5.4649","47.6759"
"32.9600","8.2185","200.7429","8.2185","5.4790","47.7959"
"33.0400","8.2389","201.1815","8.2389","5.4926","47.9003"
"33.1200","8.2577","201.6003","8.2577","5.5051","48.0001"
"33.2000","8.2781","202.0610","8.2781","5.5187","48.1098"
"33.2800","8.2976","202.4868","8.2976","5.5317","48.2111"
"33.3600","8.3186","202.9767","8.3186","5.5457","48.3278"
"33.4400","8.3380","203.3781","8.3380","5.5587","48.4233"
"33.5200","8.3565","203.7689","8.3565","5.5710","48.5164"
"33.6000","8.3774","204.2487","8.3774","5.5849","48.6307"
"33.6800","8.3984","204.7437","8.3984","5.5990","48.7485"
"33.7600","8.4184","205.1745","8.4184","5.6123","48.8511"
"33.8400","8.4380","205.5970","8.4380","5.6253","48.9517"
"33.9200","8.4568","206.0031","8.4568","5.6379","49.0484"
"34.0000","8.4776","206.4854","8.4776","5.6518","49.1632"
"34.0800","8.4980","206.9482","8.4980","5.6654","49.2734"
"34.1600","8.5172","207.3568","8.5172","5.6782","49.3707"
"34.2400","8.5383","207.8386","8.5383","5.6922","49.4854"
"34.3200","8.5580","208.2572","8.5580","5.7053","49.5851"
"34.4000","8.5786","208.7269","8.5786","5.7191","49.6969"
"34.4800","8.5985","209.1687","8.5985","5.7323","49.8021"
"34.5600","8.6175","209.5614","8.6175","5.7450","49.8956"
"34.6400","8.6373","210.0096","8.6373","5.7582","50.0023"
"34.7200","8.6571","210.4358","8.6571","5.7714","50.1038"
"34.8000","8.6771","210.8831","8.6771","5.7847","50.2103"
"34.8800","8.6989","211.3954","8.6989","5.7993","50.3322"
"34.9600","8.7181","211.8000","8.7181","5.8121","50.4286"
"35.0400","8.7383","212.2349","8.7383","5.8255","50.5321"
"35.1200","8.7574","212.6402","8.7574","5.8382","50.6286"
"35.2000","8.7770","213.0838","8.7770","5.8513","50.7342"
"35.2800","8.7972","213.5393","8.7972","5.8648","50.8427"
"35.3600","8.8174","213.9768","8.8174","5.8783","50.9468"
"35.4400","8.8379","214.4387","8.8379","5.8919","51.0568"
"35.5200","8.8589","214.9106","8.8589","5.9059","51.1692"
"35.6000","8.8780","215.3184","8.8780","5.9187","51.2663"
"35.6800","8.8989","215.7853","8.8989","5.9326","51.3774"
"35.7600","8.9179","216.1819","8.9179","5.9453","51.4719"
"35.8400","8.9378","216.6171","8.9378","5.9586","51.5755"
"35.9200","8.9579","217.0729","8.9579","5.9719","51.6840"
"36.0000","8.9763","217.4516","8.9763","5.9842","51.7742"
"36.0800","8.9979","217.9515","8.9979","5.9986","51.8932"
"36.1600","9.0191","218.4375","9.0191","6.0127","52.0089"
"36.2400","9.0381","218.8223","9.0381","6.0254","52.1006"
"36.3200","9.0576","219.2509","9.0576","6.0384","52.2026"
"36.4000","9.0773","219.6657","9.0773","6.0516","52.3014"
"36.4800","9.0977","220.1215","9.0977","6.0651","52.4099"
"36.5600","9.1183","220.5724","9.1183","6.0788","52.5172"
"36.6400","9.1369","220.9726","9.1369","6.0913","52.6125"
"36.7200","9.1583","221.4547","9.1583","6.1055","52.7273"
"36.8000","9.1785","221.8980","9.1785","6.1190","52.8329"
"36.8800","9.1984","222.3293","9.1984","6.1322","52.9355"
"36.9600","9.2181","222.7507","9.2181","6.1454","53.0359"
"37.0400","9.2377","223.1694","9.2377","6.1585","53.1356"
"37.1200","9.2575","223.5902","9.2575","6.1716","53.2358"
"37.2000","9.2779","224.0378","9.2779","6.1852","53.3423"
"37.2800","9.2970","224.4475","9.2970","6.1980","53.4399"
"37.3600","9.3183","224.9354","9.3183","6.2122","53.5561"
"37.4400","9.3379","225.3488","9.3379","6.2253","53.6545"
"37.5200","9.3581","225.7943","9.3581","6.2387","53.7606"
"37.6000","9.3779","226.2117","9.3779","6.2519","53.8599"
"37.6800","9.3972","226.6336","9.3972","6.2648","53.9604"
"37.7600","9.4176","227.0739","9.4176","6.2784","54.0652"
"37.8400","9.4373","227.5025","9.4373","6.2915","54.1673"
"37.9200","9.4572","227.9353","9.4572","6.3048","54.2703"
"38.0000","9.4787","228.4328","9.4787","6.3191","54.3888"
"38.0800","9.4988","228.8487","9.4988","6.3325","54.4878"
"38.1600","9.5187","229.2731","9.5187","6.3458","54.5888"
"38.2400","9.5381","229.6812","9.5381","6.3587","54.6860"
"38.3200","9.5567","230.0797","9.5567","6.3712","54.7809"
"38.4000","9.5777","230.5464","9.5777","6.3851","54.8920"
"38.4800","9.5970","230.9505","9.5970","6.3980","54.9882"
"38.5600","9.6179","231.4138","9.6179","6.4119","55.0985"
"38.6400","9.6380","231.8556","9.6380","6.4253","55.2037"
"38.7200","9.6580","232.2798","9.6580","6.4387","55.3047"
"38.8000","9.6778","232.7044","9.6778","6.4519","55.4058"
"38.8800","9.6982","233.1473","9.6982","6.4654","55.5113"
"38.9600","9.7175","233.5627","9.7175","6.4783","55.6102"
"39.0400","9.7379","234.0164","9.7379","6.4919","55.7182"
"39.1200","9.7567","234.3915","9.7567","6.5044","55.8075"
"39.2000","9.7788","234.9177","9.7788","6.5192","55.9328"
"39.2800","9.7989","235.3405","9.7989","6.5326","56.0335"
"39.3600","9.8183","235.7510","9.8183","6.5455","56.1312"
"39.4400","9.8375","236.1427","9.8375","6.5584","56.2245"
"39.5200","9.8574","236.5642","9.8574","6.5716","56.3248"
"39.6000","9.8773","236.9931","9.8773","6.5849","56.4269"
"39.6800","9.8986","237.4633","9.8986","6.5990","56.5389"
"39.7600","9.9171","237.8416","9.9171","6.6114","56.6289"
"39.8400","9.9378","238.3001","9.9378","6.6252","56.7381"
"39.9200","9.9584","238.7638","9.9584","6.6389","56.8485"
"40.0000","9.9781","239.1925","9.9781","6.6520","56.9506"
"40.0800","9.9982","239.6262","9.9982","6.6655","57.0538"
"40.1600","10.0172","239.9946","10.0172","6.6781","57.1416"
"40.2400","10.0376","240.4448","10.0376","6.6917","57.2488"
"40.3200","10.0575","240.8590","10.0575","6.7050","57.3474"
"40.4000","10.0772","241.2829","10.0772","6.7182","57.4483"
"40.4800","10.0980","241.7560","10.0980","6.7320","57.5609"
"40.5600","10.1190","242.1957","10.1190","6.7460","57.6656"
"40.6400","10.1383","242.6051","10.1383","6.7589","57.7631"
"40.7200","10.1586","243.0366","10.1586","6.7724","57.8659"
"40.8000","10.1772","243.4035","10.1772","6.7848","57.9532"
"40.8800","10.1981","243.8565","10.1981","6.7987","58.0611"
"40.9600","10.2174","244.2540","10.2174","6.8116","58.1557"
"41.0400","10.2369","244.6667","10.2369","6.8246","58.2540"
"41.1200","10.2573","245.1186","10.2573","6.8382","58.3616"
"41.2000","10.2784","245.5759","10.2784","6.8523","58.4705"
"41.2800","10.2988","246.0432","10.2988","6.8659","58.5817"
"41.3600","10.3183","246.4373","10.3183","6.8789","58.6755"
"41.4400","10.3371","246.8233","10.3371","6.8914","58.7674"
"41.5200","10.3575","247.2593","10.3575","6.9050","58.8713"
"41.6000","10.3772","247.6780","10.3772","6.9182","58.9709"
"41.6800","10.3983","248.1351","10.3983","6.9322","59.0798"
"41.7600","10.4190","248.5819","10.4190","6.9460","59.1862"
"41.8400","10.4380","248.9622","10.4380","6.9587","59.2767"
"41.9200","10.4581","249.3877","10.4581","6.9721","59.3780"
"42.0000","10.4778","249.8030","10.4778","6.9852","59.4769"
"42.0800","10.4977","250.2165","10.4977","6.9985","59.5753"
"42.1600","10.5177","250.6402","10.5177","7.0118","59.6762"
"42.2400","10.5370","251.0369","10.5370","7.0247","59.7707"
"42.3200","10.5573","251.4720","10.5573","7.0382","59.8743"
"42.4000","10.5788","251.9485","10.5788","7.0525","59.9877"
"42.4800","10.5983","252.3519","10.5983","7.0655","60.0838"
"42.5600","10.6184","252.7718","10.6184","7.0789","60.1838"
"42.6400","10.6372","253.1385","10.6372","7.0915","60.2711"
"42.7200","10.6573","253.5753","10.6573","7.1048","60.3751"
"42.8000","10.6774","254.0029","10.6774","7.1183","60.4769"
"42.8800","10.6977","254.4425","10.6977","7.1318","60.5816"
"42.9600","10.7181","254.8653","10.7181","7.1454","60.6822"
"43.0400","10.7390","255.3152","10.7390","7.1594","60.7893"
"43.1200","10.7578","255.6804","10.7578","7.1719","60.8763"
"43.2000","10.7782","256.1187","10.7782","7.1855","60.9806"
"43.2800","10.7972","256.4986","10.7972","7.1981","61.0711"
"43.3600","10.8179","256.9417","10.8179","7.2120","61.1766"
"43.4400","10.8377","257.3549","10.8377","7.2251","61.2750"
"43.5200","10.8569","257.7534","10.8569","7.2379","61.3698"
"43.6000","10.8771","258.1743","10.8771","7.2514","61.4701"
"43.6800","10.8981","258.6427","10.8981","7.2654","61.5816"
"43.7600","10.9186","259.0761","10.9186","7.2791","61.6848"
"43.8400","10.9383","259.4715","10.9383","7.2922","61.7789"
"43.9200","10.9569","259.8305","10.9569","7.3046","61.8644"
"44.0000","10.9776","260.2757","10.9776","7.3184","61.9704"
"44.0800","10.9979","260.7145","10.9979","7.3319","62.0749"
"44.1600","11.0177","261.1415","11.0177","7.3451","62.1765"
"44.2400","11.0381","261.5702","11.0381","7.3588","62.2786"
"44.3200","11.0580","261.9817","11.0580","7.3720","62.3766"
"44.4000","11.0788","262.4138","11.0788","7.3859","62.4795"
"44.4800","11.0985","262.8224","11.0985","7.3990","62.5767"
"44.5600","11.1174","263.2131","11.1174","7.4116","62.6698"
"44.6400","11.1372","263.6148","11.1372","7.4248","62.7654"
"44.7200","11.1573","264.0366","11.1573","7.4382","62.8659"
"44.8000","11.1774","264.4706","11.1774","7.4516","62.9692"
"44.8800","11.1990","264.9547","11.1990","7.4660","63.0845"
"44.9600","11.2182","265.3215","11.2182","7.4788","63.1718"
"45.0400","11.2384","265.7423","11.2384","7.4923","63.2720"
"45.1200","11.2574","266.1244","11.2574","7.5049","63.3630"
"45.2000","11.2770","266.5331","11.2770","7.5180","63.4603"
"45.2800","11.2974","266.9808","11.2974","7.5316","63.5669"
"45.3600","11.3175","267.3879","11.3175","7.5450","63.6638"
"45.4400","11.3380","267.8268","11.3380","7.5586","63.7683"
"45.5200","11.3590","268.2831","11.3590","7.5727","63.8769"
"45.6000","11.3784","268.6755","11.3784","7.5856","63.9704"
"45.6800","11.3986","269.1071","11.3986","7.5991","64.0731"
"45.7600","11.4177","269.4875","11.4177","7.6118","64.1637"
"45.8400","11.4374","269.9104","11.4374","7.6250","64.2644"
"45.9200","11.4575","270.3120","11.4575","7.6383","64.3600"
"46.0000","11.4764","270.7009","11.4764","7.6510","64.4526"
"46.0800","11.4981","271.1853","11.4981","7.6654","64.5679"
"46.1600","11.5186","271.6144","11.5186","7.6791","64.6701"
"46.2400","11.5382","272.0208","11.5382","7.6921","64.7669"
"46.3200","11.5576","272.4165","11.5576","7.7051","64.8611"
"46.4000","11.5771","272.8065","11.5771","7.7181","64.9539"
"46.4800","11.5976","273.2714","11.5976","7.7318","65.0646"
"46.5600","11.6183","273.7131","11.6183","7.7455","65.1698"
"46.6400","11.6368","274.0652","11.6368","7.7579","65.2536"
"46.7200","11.6585","274.5566","11.6585","7.7723","65.3706"
"46.8000","11.6785","274.9852","11.6785","7.7857","65.4727"
"46.8800","11.6991","275.4142","11.6991","7.7994","65.5748"
"46.9600","11.7179","275.7714","11.7179","7.8120","65.6599"
"47.0400","11.7374","276.1718","11.7374","7.8249","65.7552"
"47.1200","11.7572","276.5767","11.7572","7.8381","65.8516"
"47.2000","11.7780","277.0296","11.7780","7.8520","65.9594"
"47.2800","11.7973","277.4307","11.7973","7.8649","66.0549"
"47.3600","11.8183","277.8962","11.8183","7.8788","66.1658"
"47.4400","11.8379","278.2778","11.8379","7.8919","66.2566"
"47.5200","11.8582","278.7137","11.8582","7.9055","66.3604"
"47.6000","11.8781","279.1248","11.8781","7.9187","66.4583"
"47.6800","11.8971","279.5055","11.8971","7.9314","66.5489"
"47.7600","11.9176","279.9395","11.9176","7.9451","66.6523"
"47.8400","11.9373","280.3529","11.9373","7.9582","66.7507"
"47.9200","11.9576","280.7880","11.9576","7.9718","66.8543"
"48.0000","11.9788","281.2738","11.9788","7.9859","66.9700"
"48.0800","11.9988","281.6771","11.9988","7.9992","67.0660"
"48.1600","12.0186","282.0741","12.0186","8.0124","67.1605"
"48.2400","12.0381","282.4684","12.0381","8.0254","67.2544"
"48.3200","12.0570","282.8507","12.0570","8.0380","67.3454"
"48.4000","12.0778","283.2935","12.0778","8.0519","67.4508"
"48.4800","12.0970","283.6801","12.0970","8.0647","67.5429"
"48.5600","12.1178","284.1300","12.1178","8.0786","67.6500"
"48.6400","12.1386","284.5824","12.1386","8.0924","67.7577"
"48.7200","12.1581","284.9802","12.1581","8.1054","67.8524"
"48.8000","12.1778","285.3817","12.1778","8.1186","67.9480"
"48.8800","12.1981","285.8025","12.1981","8.1321","68.0482"
"48.9600","12.2174","286.1965","12.2174","8.1449","68.1420"
"49.0400","12.2377","286.6295","12.2377","8.1585","68.2451"
"49.1200","12.2566","286.9852","12.2566","8.1711","68.3298"
"49.2000","12.2785","287.4840","12.2785","8.1857","68.4486"
"49.2800","12.2992","287.9259","12.2992","8.1994","68.5538"
"49.3600","12.3186","288.3146","12.3186","8.2124","68.6463"
"49.4400","12.3370","288.6606","12.3370","8.2247","68.7287"
"49.5200","12.3574","289.0938","12.3574","8.2382","68.8318"
"49.6000","12.3778","289.5235","12.3778","8.2519","68.9342"
"49.6800","12.3984","289.9636","12.3984","8.2656","69.0389"
"49.7600","12.4170","290.3263","12.4170","8.2780","69.1253"
"49.8400","12.4375","290.7573","12.4375","8.2916","69.2279"
"49.9200","12.4583","291.2059","12.4583","8.3055","69.3347"
"50.0000","12.4783","291.6187","12.4783","8.3189","69.4330"
"50.0800","12.4985","292.0349","12.4985","8.3323","69.5321"
"50.1600","12.5172","292.4030","12.5172","8.3448","69.6198"
"50.2400","12.5376","292.8184","12.5376","8.3584","69.7187"
"50.3200","12.5573","293.2353","12.5573","8.3716","69.8179"
"50.4000","12.5772","293.6484","12.5772","8.3848","69.9163"
"50.4800","12.5982","294.1172","12.5982","8.3988","70.0279"
"50.5600","12.6191","294.5594","12.6191","8.4127","70.1332"
"50.6400","12.6386","294.9513","12.6386","8.4257","70.2265"
"50.7200","12.6587","295.3558","12.6587","8.4391","70.3228"
"50.8000","12.6771","295.7038","12.6771","8.4514","70.4057"
"50.8800","12.6978","296.1461","12.6978","8.4652","70.5110"
"50.9600","12.7170","296.5316","12.7170","8.4780","70.6028"
"51.0400","12.7372","296.9586","12.7372","8.4915","70.7044"
"51.1200","12.7573","297.3806","12.7573","8.5049","70.8049"
"51.2000","12.7780","297.8172","12.7780","8.5187","70.9089"
"51.2800","12.7986","298.2603","12.7986","8.5324","71.0144"
"51.3600","12.8186","298.6626","12.8186","8.5457","71.1101"
"51.4400","12.8370","299.0086","12.8370","8.5580","71.1925"
"51.5200","12.8574","299.4476","12.8574","8.5716","71.2970"
"51.6000","12.8769","299.8268","12.8769","8.5846","71.3873"
"51.6800","12.8982","300.3127","12.8982","8.5988","71.5030"
"51.7600","12.9191","300.7533","12.9191","8.6127","71.6079"
"51.8400","12.9382","301.1296","12.9382","8.6255","71.6975"
"51.9200","12.9580","301.5212","12.9580","8.6387","71.7908"
"52.0000","12.9782","301.9431","12.9782","8.6521","71.8912"
"52.0800","12.9978","302.3522","12.9978","8.6652","71.9886"
"52.1600","13.0177","302.7823","13.0177","8.6785","72.0910"
"52.2400","13.0369","303.1389","13.0369","8.6912","72.1759"
"52.3200","13.0579","303.6044","13.0579","8.7053","72.2868"
"52.4000","13.0785","304.0374","13.0785","8.7190","72.3898"
"52.4800","13.0981","304.4398","13.0981","8.7321","72.4857"
"52.5600","13.1186","304.8650","13.1186","8.7457","72.5869"
"52.6400","13.1371","305.2060","13.1371","8.7581","72.6681"
"52.7200","13.1572","305.6171","13.1572","8.7715","72.7660"
"52.8000","13.1772","306.0338","13.1772","8.7848","72.8652"
"52.8800","13.1972","306.4338","13.1972","8.7981","72.9604"
"52.9600","13.2181","306.8848","13.2181","8.8120","73.0678"
"53.0400","13.2393","307.3460","13.2393","8.8262","73.1776"
"53.1200","13.2583","307.7110","13.2583","8.8389","73.2645"
"53.2000","13.2783","308.1255","13.2783","8.8522","73.3632"
"53.2800","13.2974","308.4833","13.2974","8.8649","73.4484"
"53.3600","13.3183","308.9376","13.3183","8.8788","73.5566"
"53.4400","13.3380","309.3331","13.3380","8.8920","73.6507"
"53.5200","13.3569","309.7039","13.3569","8.9046","73.7390"
"53.6000","13.3775","310.1328","13.3775","8.9183","73.8412"
"53.6800","13.3983","310.5691","13.3983","8.9322","73.9450"
"53.7600","13.4184","310.9800","13.4184","8.9456","74.0428"
"53.8400","13.4381","311.3743","13.4381","8.9587","74.1367"
"53.9200","13.4568","311.7266","13.4568","8.9712","74.2206"
"54.0000","13.4777","312.1765","13.4777","8.9851","74.3278"
"54.0800","13.4981","312.6173","13.4981","8.9987","74.4327"
"54.1600","13.5177","313.0167","13.5177","9.0118","74.5278"
"54.2400","13.5384","313.4543","13.5384","9.0256","74.6320"
"54.3200","13.5581","313.8273","13.5581","9.0387","74.7208"
"54.4000","13.5789","314.2671","13.5789","9.0526","74.8255"
"54.4800","13.5987","314.6623","13.5987","9.0658","74.9196"
"54.5600","13.6175","315.0145","13.6175","9.0783","75.0035"
"54.6400","13.6376","315.4390","13.6376","9.0917","75.1045"
"54.7200","13.6570","315.8045","13.6570","9.1047","75.1916"
"54.8000","13.6769","316.2291","13.6769","9.1179","75.2926"
"54.8800","13.6988","316.7032","13.6988","9.1325","75.4055"
"54.9600","13.7177","317.0567","13.7177","9.1451","75.4897"
"55.0400","13.7385","317.4945","13.7385","9.1590","75.5939"
"55.1200","13.7578","317.8644","13.7578","9.1719","75.6820"
"55.2000","13.7769","318.2421","13.7769","9.1846","75.7719"
"55.2800","13.7971","318.6686","13.7971","9.1981","75.8735"
"55.3600","13.8175","319.0837","13.8175","9.2117","75.9723"
"55.4400","13.8380","319.5153","13.8380","9.2253","76.0751"
"55.5200","13.8590","319.9609","13.8590","9.2394","76.1812"
"55.6000","13.8784","320.3365","13.8784","9.2523","76.2706"
"55.6800","13.8983","320.7309","13.8983","9.2655","76.3645"
"55.7600","13.9178","321.1092","13.9178","9.2786","76.4546"
"55.8400","13.9376","321.5056","13.9376","9.2917","76.5490"
"55.9200","13.9573","321.9057","13.9573","9.3049","76.6442"
"56.0000","13.9766","322.2789","13.9766","9.3177","76.7331"
"56.0800","13.9982","322.7707","13.9982","9.3321","76.8502"
"56.1600","14.0188","323.1915","14.0188","9.3459","76.9503"
"56.2400","14.0382","323.5585","14.0382","9.3588","77.0377"
"56.3200","14.0576","323.9379","14.0576","9.3717","77.1281"
"56.4000","14.0773","324.3131","14.0773","9.3848","77.2174"
"56.4800","14.0978","324.7499","14.0978","9.3985","77.3214"
"56.5600","14.1182","325.1595","14.1182","9.4122","77.4189"
"56.6400","14.1368","325.5156","14.1368","9.4246","77.5037"
"56.7200","14.1580","325.9634","14.1580","9.4387","77.6103"
"56.8000","14.1786","326.3918","14.1786","9.4524","77.7123"
"56.8800","14.1990","326.8037","14.1990","9.4660","77.8104"
"56.9600","14.2180","327.1616","14.2180","9.4786","77.8956"
"57.0400","14.2374","327.5471","14.2374","9.4916","77.9874"
"57.1200","14.2575","327.9478","14.2575","9.5050","78.0828"
"57.2000","14.2778","328.3642","14.2778","9.5185","78.1820"
"57.2800","14.2968","328.7162","14.2968","9.5312","78.2658"
"57.3600","14.3177","329.1595","14.3177","9.5451","78.3713"
"57.4400","14.3376","329.5555","14.3376","9.5584","78.4656"
"57.5200","14.3583","329.9823","14.3583","9.5722","78.5672"
"57.6000","14.3783","330.3884","14.3783","9.5855","78.6639"
"57.6800","14.3974","330.7397","14.3974","9.5983","78.7475"
"57.7600","14.4174","331.1410","14.4174","9.6116","78.8431"
"57.8400","14.4371","331.5234","14.4371","9.6248","78.9341"
"57.9200","14.4576","331.9529","14.4576","9.6384","79.0364"
"58.0000","14.4788","332.4043","14.4788","9.6525","79.1439"
"58.0800","14.4986","332.7889","14.4986","9.6658","79.2355"
"58.1600","14.5185","333.1679","14.5185","9.6790","79.3257"
"58.2400","14.5381","333.5395","14.5381","9.6921","79.4142"
"58.3200","14.5568","333.8831","14.5568","9.7046","79.4960"
"58.4000","14.5775","334.3083","14.5775","9.7183","79.5972"
"58.4800","14.5971","334.6809","14.5971","9.7314","79.6859"
"58.5600","14.6179","335.1036","14.6179","9.7453","79.7866"
"58.6400","14.6382","335.5122","14.6382","9.7588","79.8839"
"58.7200","14.6578","335.8719","14.6578","9.7719","79.9695"
"58.8000","14.6780","336.2726","14.6780","9.7854","80.0649"
"58.8800","14.6980","336.6463","14.6980","9.7987","80.1539"
"58.9600","14.7174","337.0275","14.7174","9.8116","80.2446"
"59.0400","14.7378","337.4359","14.7378","9.8252","80.3419"
"59.1200","14.7564","337.7465","14.7564","9.8376","80.4158"
"59.2000","14.7785","338.2391","14.7785","9.8524","80.5331"
"59.2800","14.7993","338.6379","14.7993","9.8662","80.6281"
"59.3600","14.8185","338.9888","14.8185","9.8790","80.7116"
"59.4400","14.8378","339.3244","14.8378","9.8918","80.7915"
"59.5200","14.8573","339.6791","14.8573","9.9049","80.8760"
"59.6000","14.8777","340.0894","14.8777","9.9185","80.9737"
"59.6800","14.8981","340.4725","14.8981","9.9321","81.0649"
"59.7600","14.9168","340.7990","14.9168","9.9445","81.1426"
"59.8400","14.9374","341.2064","14.9374","9.9583","81.2396"
"59.9200","14.9581","341.6030","14.9581","9.9721","81.3341"
"60.0000","14.9785","342.0016","14.9785","9.9857","81.4290"
"60.0800","14.9980","342.3322","14.9980","9.9986","81.5077"
"60.0890","15.0002","342.3686","15.0002","10.0002","81.5163"