File: data/instron_tests/metamaterials/250331/250331_1049_VERT_m1.is_comp_Exports/250331_1049_VERT_m1_5_1.csv
Results Table 1
,Compresson Axis,H*,V*,Height,Thickness,Width,Area,Fixture separation,Specimen label
,,,,(mm),(mm),(mm),(mm^2),(mm),
"5","X","","","150.00","28.00","150.00","4200.00","150.00","1049_VERT_m1"

Results Table 2
,Modulus (Segment 0 % - 5 %),Compresson Axis
,(kPa),
"5","1823.35","X"

Time,Displacement,Force,Compressive displacement,Compressive strain (Displacement),Compressive stress
(s),(mm),(N),(mm),(%),(kPa)
"0.0000","0.0000","0.0425","0.0000","0.0000","0.0101"
"0.0800","0.0012","0.1084","0.0012","0.0008","0.0258"
"0.1600","0.0172","1.2626","0.0172","0.0115","0.3006"
"0.2400","0.0380","2.6455","0.0380","0.0253","0.6299"
"0.3200","0.0578","3.9221","0.0578","0.0385","0.9338"
"0.4000","0.0770","5.1546","0.0770","0.0514","1.2273"
"0.4800","0.0982","6.4903","0.0982","0.0655","1.5453"
"0.5600","0.1180","7.7048","0.1180","0.0787","1.8345"
"0.6400","0.1380","8.9200","0.1380","0.0920","2.1238"
"0.7200","0.1576","10.0718","0.1576","0.1051","2.3981"
"0.8000","0.1765","11.1979","0.1765","0.1177","2.6662"
"0.8800","0.1972","12.4350","0.1972","0.1315","2.9607"
"0.9600","0.2170","13.5955","0.2170","0.1447","3.2370"
"1.0400","0.2364","14.7385","0.2364","0.1576","3.5092"
"1.1200","0.2574","15.9778","0.2574","0.1716","3.8042"
"1.2000","0.2769","17.0784","0.2769","0.1846","4.0663"
"1.2800","0.2975","18.2644","0.2975","0.1983","4.3487"
"1.3600","0.3179","19.4368","0.3179","0.2119","4.6278"
"1.4400","0.3363","20.4574","0.3363","0.2242","4.8708"
"1.5200","0.3568","21.6506","0.3568","0.2379","5.1549"
"1.6000","0.3768","22.7801","0.3768","0.2512","5.4238"
"1.6800","0.3973","23.9476","0.3973","0.2649","5.7018"
"1.7600","0.4185","25.1142","0.4185","0.2790","5.9796"
"1.8400","0.4375","26.1369","0.4375","0.2916","6.2231"
"1.9200","0.4575","27.2470","0.4575","0.3050","6.4874"
"2.0000","0.4773","28.3552","0.4773","0.3182","6.7512"
"2.0800","0.4969","29.4242","0.4969","0.3313","7.0058"
"2.1600","0.5173","30.5516","0.5173","0.3449","7.2742"
"2.2400","0.5364","31.5733","0.5364","0.3576","7.5175"
"2.3200","0.5570","32.7028","0.5570","0.3713","7.7864"
"2.4000","0.5781","33.8596","0.5781","0.3854","8.0618"
"2.4800","0.5975","34.8952","0.5975","0.3984","8.3084"
"2.5600","0.6178","35.9852","0.6178","0.4118","8.5679"
"2.6400","0.6365","36.9635","0.6365","0.4243","8.8008"
"2.7200","0.6563","38.0370","0.6563","0.4375","9.0564"
"2.8000","0.6767","39.1434","0.6767","0.4511","9.3199"
"2.8800","0.6968","40.2052","0.6968","0.4645","9.5727"
"2.9600","0.7177","41.3354","0.7177","0.4785","9.8418"
"3.0400","0.7384","42.4583","0.7384","0.4923","10.1091"
"3.1200","0.7573","43.4472","0.7573","0.5049","10.3446"
"3.2000","0.7771","44.5133","0.7771","0.5181","10.5984"
"3.2800","0.7966","45.5402","0.7966","0.5311","10.8429"
"3.3600","0.8176","46.6733","0.8176","0.5451","11.1127"
"3.4400","0.8375","47.7338","0.8375","0.5583","11.3652"
"3.5200","0.8564","48.7447","0.8564","0.5709","11.6059"
"3.6000","0.8766","49.8228","0.8766","0.5844","11.8626"
"3.6800","0.8979","50.9870","0.8979","0.5986","12.1398"
"3.7600","0.9174","52.0205","0.9174","0.6116","12.3858"
"3.8400","0.9372","53.0808","0.9372","0.6248","12.6383"
"3.9200","0.9556","54.0173","0.9556","0.6371","12.8613"
"4.0000","0.9768","55.1825","0.9768","0.6512","13.1387"
"4.0800","0.9976","56.2872","0.9976","0.6650","13.4017"
"4.1600","1.0171","57.3335","1.0171","0.6780","13.6508"
"4.2400","1.0375","58.4132","1.0375","0.6917","13.9079"
"4.3200","1.0576","59.4770","1.0576","0.7050","14.1612"
"4.4000","1.0782","60.5830","1.0782","0.7188","14.4245"
"4.4800","1.0979","61.6241","1.0979","0.7320","14.6724"
"4.5600","1.1166","62.5883","1.1166","0.7444","14.9020"
"4.6400","1.1369","63.6737","1.1369","0.7579","15.1604"
"4.7200","1.1565","64.7081","1.1565","0.7710","15.4067"
"4.8000","1.1766","65.7863","1.1766","0.7844","15.6634"
"4.8800","1.1983","66.9559","1.1983","0.7989","15.9419"
"4.9600","1.2173","67.9207","1.2173","0.8115","16.1716"
"5.0400","1.2374","68.9702","1.2374","0.8249","16.4215"
"5.1200","1.2570","70.0167","1.2570","0.8380","16.6706"
"5.2000","1.2764","71.0357","1.2764","0.8509","16.9133"
"5.2800","1.2968","72.1157","1.2968","0.8645","17.1704"
"5.3600","1.3168","73.1641","1.3168","0.8779","17.4200"
"5.4400","1.3371","74.2479","1.3371","0.8914","17.6781"
"5.5200","1.3583","75.3705","1.3583","0.9055","17.9454"
"5.6000","1.3777","76.3650","1.3777","0.9185","18.1821"
"5.6800","1.3980","77.4245","1.3980","0.9320","18.4344"
"5.7600","1.4172","78.4117","1.4172","0.9448","18.6695"
"5.8400","1.4368","79.4410","1.4368","0.9579","18.9145"
"5.9200","1.4568","80.4947","1.4568","0.9712","19.1654"
"6.0000","1.4760","81.4762","1.4760","0.9840","19.3991"
"6.0800","1.4973","82.6239","1.4973","0.9982","19.6724"
"6.1600","1.5182","83.7237","1.5182","1.0121","19.9342"
"6.2400","1.5371","84.6917","1.5371","1.0247","20.1647"
"6.3200","1.5566","85.7126","1.5566","1.0377","20.4078"
"6.4000","1.5769","86.7647","1.5769","1.0513","20.6583"
"6.4800","1.5972","87.8399","1.5972","1.0648","20.9143"
"6.5600","1.6178","88.9153","1.6178","1.0785","21.1703"
"6.6400","1.6362","89.8611","1.6362","1.0908","21.3955"
"6.7200","1.6576","90.9895","1.6576","1.1050","21.6642"
"6.8000","1.6782","92.0852","1.6782","1.1188","21.9250"
"6.8800","1.6988","93.1565","1.6988","1.1325","22.1801"
"6.9600","1.7174","94.1015","1.7174","1.1449","22.4051"
"7.0400","1.7361","95.0432","1.7361","1.1574","22.6293"
"7.1200","1.7565","96.1189","1.7565","1.1710","22.8854"
"7.2000","1.7774","97.2321","1.7774","1.1850","23.1505"
"7.2800","1.7967","98.2540","1.7967","1.1978","23.3938"
"7.3600","1.8177","99.3646","1.8177","1.2118","23.6582"
"7.4400","1.8371","100.3585","1.8371","1.2248","23.8949"
"7.5200","1.8577","101.4518","1.8577","1.2384","24.1552"
"7.6000","1.8776","102.4815","1.8775","1.2517","24.4004"
"7.6800","1.8965","103.4573","1.8965","1.2643","24.6327"
"7.7600","1.9169","104.5175","1.9169","1.2779","24.8851"
"7.8400","1.9368","105.5634","1.9368","1.2912","25.1341"
"7.9200","1.9569","106.6253","1.9569","1.3046","25.3870"
"8.0000","1.9781","107.7572","1.9781","1.3187","25.6565"
"8.0800","1.9981","108.7857","1.9981","1.3321","25.9014"
"8.1600","2.0179","109.8165","2.0179","1.3453","26.1468"
"8.2400","2.0376","110.8267","2.0376","1.3584","26.3873"
"8.3200","2.0561","111.7793","2.0561","1.3708","26.6141"
"8.4000","2.0771","112.9049","2.0771","1.3847","26.8821"
"8.4800","2.0965","113.8946","2.0965","1.3976","27.1178"
"8.5600","2.1172","114.9919","2.1172","1.4115","27.3790"
"8.6400","2.1372","116.0285","2.1372","1.4248","27.6258"
"8.7200","2.1572","117.0563","2.1572","1.4381","27.8705"
"8.8000","2.1776","118.1268","2.1776","1.4518","28.1254"
"8.8800","2.1977","119.1554","2.1977","1.4651","28.3703"
"8.9600","2.2167","120.1334","2.2167","1.4778","28.6032"
"9.0400","2.2369","121.1839","2.2369","1.4913","28.8533"
"9.1200","2.2559","122.1501","2.2559","1.5040","29.0834"
"9.2000","2.2780","123.3521","2.2780","1.5187","29.3696"
"9.2800","2.2989","124.4409","2.2989","1.5326","29.6288"
"9.3600","2.3178","125.3935","2.3178","1.5452","29.8556"
"9.4400","2.3370","126.3754","2.3370","1.5580","30.0894"
"9.5200","2.3570","127.4182","2.3570","1.5713","30.3377"
"9.6000","2.3769","128.4680","2.3769","1.5846","30.5876"
"9.6800","2.3976","129.5583","2.3976","1.5984","30.8472"
"9.7600","2.4160","130.4715","2.4160","1.6107","31.0647"
"9.8400","2.4370","131.5929","2.4370","1.6247","31.3316"
"9.9200","2.4578","132.6755","2.4578","1.6385","31.5894"
"10.0000","2.4775","133.7026","2.4775","1.6517","31.8340"
"10.0800","2.4976","134.7452","2.4976","1.6651","32.0822"
"10.1600","2.5171","135.7912","2.5171","1.6780","32.3312"
"10.2400","2.5370","136.8236","2.5370","1.6913","32.5771"
"10.3200","2.5568","137.8473","2.5568","1.7046","32.8208"
"10.4000","2.5763","138.8601","2.5763","1.7176","33.0619"
"10.4800","2.5976","140.0006","2.5976","1.7317","33.3335"
"10.5600","2.6179","141.0485","2.6179","1.7453","33.5830"
"10.6400","2.6380","142.0844","2.6380","1.7587","33.8296"
"10.7200","2.6576","143.0904","2.6576","1.7717","34.0691"
"10.8000","2.6764","144.0470","2.6764","1.7842","34.2969"
"10.8800","2.6972","145.1533","2.6972","1.7981","34.5603"
"10.9600","2.7170","146.1547","2.7170","1.8113","34.7987"
"11.0400","2.7365","147.1724","2.7365","1.8243","35.0410"
"11.1200","2.7569","148.2592","2.7569","1.8380","35.2998"
"11.2000","2.7775","149.3341","2.7775","1.8517","35.5557"
"11.2800","2.7975","150.3617","2.7975","1.8650","35.8004"
"11.3600","2.8176","151.4001","2.8176","1.8784","36.0476"
"11.4400","2.8363","152.3413","2.8363","1.8909","36.2717"
"11.5200","2.8567","153.4177","2.8567","1.9045","36.5280"
"11.6000","2.8765","154.4261","2.8765","1.9177","36.7681"
"11.6800","2.8973","155.5304","2.8973","1.9316","37.0310"
"11.7600","2.9184","156.6352","2.9184","1.9456","37.2941"
"11.8400","2.9373","157.5759","2.9373","1.9582","37.5181"
"11.9200","2.9572","158.5974","2.9572","1.9715","37.7613"
"12.0000","2.9774","159.6524","2.9774","1.9849","38.0125"
"12.0800","2.9971","160.6774","2.9971","1.9981","38.2565"
"12.1600","3.0172","161.7402","3.0172","2.0115","38.5096"
"12.2400","3.0362","162.6691","3.0362","2.0241","38.7307"
"12.3200","3.0568","163.7797","3.0568","2.0379","38.9952"
"12.4000","3.0784","164.9171","3.0784","2.0523","39.2660"
"12.4800","3.0974","165.8801","3.0974","2.0649","39.4953"
"12.5600","3.1179","166.9430","3.1179","2.0786","39.7483"
"12.6400","3.1367","167.8927","3.1367","2.0912","39.9745"
"12.7200","3.1569","168.9487","3.1569","2.1046","40.2259"
"12.8000","3.1767","169.9768","3.1767","2.1178","40.4707"
"12.8800","3.1966","170.9951","3.1966","2.1311","40.7131"
"12.9600","3.2179","172.1254","3.2179","2.1453","40.9822"
"13.0400","3.2386","173.2291","3.2386","2.1590","41.2450"
"13.1200","3.2574","174.1725","3.2574","2.1716","41.4696"
"13.2000","3.2774","175.2043","3.2774","2.1849","41.7153"
"13.2800","3.2968","176.1821","3.2968","2.1978","41.9481"
"13.3600","3.3178","177.2896","3.3178","2.2118","42.2118"
"13.4400","3.3372","178.2781","3.3372","2.2248","42.4472"
"13.5200","3.3558","179.2171","3.3558","2.2372","42.6707"
"13.6000","3.3769","180.3269","3.3769","2.2513","42.9350"
"13.6800","3.3981","181.4385","3.3981","2.2654","43.1996"
"13.7600","3.4175","182.4110","3.4175","2.2783","43.4312"
"13.8400","3.4374","183.4286","3.4374","2.2916","43.6735"
"13.9200","3.4562","184.3596","3.4562","2.3041","43.8951"
"14.0000","3.4771","185.4595","3.4771","2.3181","44.1570"
"14.0800","3.4973","186.5016","3.4973","2.3315","44.4051"
"14.1600","3.5169","187.5063","3.5169","2.3446","44.6443"
"14.2400","3.5376","188.5754","3.5376","2.3584","44.8989"
"14.3200","3.5572","189.5711","3.5572","2.3715","45.1360"
"14.4000","3.5780","190.6518","3.5780","2.3853","45.3933"
"14.4800","3.5976","191.6418","3.5976","2.3984","45.6290"
"14.5600","3.6170","192.6254","3.6170","2.4113","45.8632"
"14.6400","3.6367","193.6285","3.6367","2.4245","46.1020"
"14.7200","3.6566","194.6535","3.6566","2.4377","46.3461"
"14.8000","3.6764","195.6749","3.6764","2.4509","46.5893"
"14.8800","3.6978","196.8100","3.6978","2.4652","46.8595"
"14.9600","3.7174","197.7919","3.7174","2.4783","47.0933"
"15.0400","3.7380","198.8557","3.7380","2.4920","47.3466"
"15.1200","3.7572","199.8161","3.7572","2.5048","47.5753"
"15.2000","3.7761","200.7741","3.7761","2.5174","47.8034"
"15.2800","3.7966","201.8250","3.7966","2.5311","48.0536"
"15.3600","3.8165","202.8320","3.8165","2.5444","48.2933"
"15.4400","3.8374","203.9192","3.8374","2.5583","48.5522"
"15.5200","3.8583","205.0009","3.8583","2.5722","48.8097"
"15.6000","3.8774","205.9509","3.8774","2.5849","49.0359"
"15.6800","3.8979","206.9979","3.8979","2.5986","49.2852"
"15.7600","3.9172","207.9677","3.9172","2.6115","49.5161"
"15.8400","3.9366","208.9584","3.9366","2.6244","49.7520"
"15.9200","3.9572","210.0237","3.9572","2.6381","50.0056"
"16.0000","3.9762","210.9605","3.9762","2.6508","50.2287"
"16.0800","3.9973","212.0674","3.9973","2.6649","50.4922"
"16.1600","4.0181","213.1401","4.0181","2.6787","50.7476"
"16.2400","4.0372","214.0879","4.0372","2.6915","50.9733"
"16.3200","4.0567","215.0615","4.0567","2.7045","51.2051"
"16.4000","4.0766","216.0657","4.0766","2.7177","51.4442"
"16.4800","4.0971","217.1248","4.0971","2.7314","51.6964"
"16.5600","4.1178","218.1862","4.1178","2.7452","51.9491"
"16.6400","4.1360","219.0733","4.1360","2.7574","52.1603"
"16.7200","4.1576","220.2103","4.1576","2.7717","52.4310"
"16.8000","4.1780","221.2503","4.1780","2.7854","52.6786"
"16.8800","4.1982","222.2800","4.1982","2.7988","52.9238"
"16.9600","4.2173","223.2158","4.2173","2.8115","53.1466"
"17.0400","4.2367","224.1897","4.2367","2.8245","53.3785"
"17.1200","4.2569","225.2321","4.2569","2.8380","53.6267"
"17.2000","4.2775","226.2812","4.2775","2.8516","53.8765"
"17.2800","4.2962","227.2076","4.2962","2.8641","54.0970"
"17.3600","4.3173","228.3109","4.3173","2.8782","54.3597"
"17.4400","4.3371","229.2840","4.3371","2.8914","54.5914"
"17.5200","4.3574","230.3266","4.3574","2.9049","54.8397"
"17.6000","4.3774","231.3333","4.3774","2.9183","55.0793"
"17.6800","4.3966","232.2928","4.3966","2.9311","55.3078"
"17.7600","4.4169","233.3186","4.4169","2.9446","55.5520"
"17.8400","4.4369","234.3285","4.4369","2.9579","55.7925"
"17.9200","4.4566","235.3267","4.4566","2.9711","56.0302"
"18.0000","4.4778","236.4336","4.4778","2.9852","56.2937"
"18.0800","4.4981","237.4493","4.4981","2.9987","56.5355"
"18.1600","4.5181","238.4554","4.5181","3.0120","56.7751"
"18.2400","4.5376","239.4232","4.5376","3.0251","57.0055"
"18.3200","4.5564","240.3457","4.5564","3.0376","57.2252"
"18.4000","4.5771","241.4142","4.5771","3.0514","57.4796"
"18.4800","4.5966","242.3848","4.5966","3.0644","57.7107"
"18.5600","4.6172","243.4299","4.6172","3.0781","57.9595"
"18.6400","4.6369","244.4171","4.6369","3.0912","58.1945"
"18.7200","4.6574","245.4542","4.6574","3.1049","58.4415"
"18.8000","4.6775","246.4694","4.6775","3.1183","58.6832"
"18.8800","4.6976","247.4704","4.6976","3.1317","58.9215"
"18.9600","4.7165","248.4013","4.7165","3.1443","59.1432"
"19.0400","4.7368","249.4246","4.7368","3.1579","59.3868"
"19.1200","4.7561","250.3824","4.7561","3.1707","59.6149"
"19.2000","4.7778","251.5177","4.7778","3.1852","59.8852"
"19.2800","4.7981","252.5407","4.7981","3.1988","60.1287"
"19.3600","4.8180","253.5255","4.8180","3.2120","60.3632"
"19.4400","4.8372","254.4691","4.8372","3.2248","60.5879"
"19.5200","4.8573","255.4828","4.8573","3.2382","60.8292"
"19.6000","4.8772","256.4847","4.8772","3.2514","61.0678"
"19.6800","4.8981","257.5848","4.8981","3.2654","61.3297"
"19.7600","4.9163","258.4503","4.9163","3.2776","61.5358"
"19.8400","4.9367","259.4804","4.9367","3.2911","61.7811"
"19.9200","4.9576","260.5344","4.9576","3.3051","62.0320"
"20.0000","4.9779","261.5787","4.9779","3.3186","62.2806"
"20.0800","4.9979","262.5604","4.9979","3.3319","62.5144"
"20.1600","5.0165","263.4465","5.0165","3.3443","62.7254"
"20.2400","5.0366","264.4454","5.0366","3.3578","62.9632"
"20.3200","5.0568","265.4583","5.0568","3.3712","63.2044"
"20.4000","5.0768","266.4503","5.0768","3.3845","63.4406"
"20.4800","5.0977","267.5134","5.0977","3.3985","63.6937"
"20.5600","5.1181","268.5268","5.1181","3.4121","63.9350"
"20.6400","5.1378","269.5040","5.1378","3.4252","64.1676"
"20.7200","5.1577","270.4806","5.1577","3.4384","64.4001"
"20.8000","5.1765","271.3959","5.1765","3.4510","64.6181"
"20.8800","5.1976","272.4741","5.1976","3.4650","64.8748"
"20.9600","5.2169","273.4178","5.2169","3.4779","65.0995"
"21.0400","5.2365","274.3895","5.2365","3.4910","65.3308"
"21.1200","5.2567","275.4047","5.2567","3.5044","65.5726"
"21.2000","5.2775","276.4276","5.2775","3.5183","65.8161"
"21.2800","5.2974","277.4158","5.2974","3.5316","66.0514"
"21.3600","5.3178","278.4290","5.3178","3.5452","66.2926"
"21.4400","5.3361","279.3073","5.3361","3.5574","66.5017"
"21.5200","5.3566","280.3475","5.3566","3.5710","66.7494"
"21.6000","5.3759","281.2960","5.3759","3.5840","66.9752"
"21.6800","5.3975","282.4211","5.3975","3.5983","67.2431"
"21.7600","5.4187","283.5106","5.4187","3.6125","67.5025"
"21.8400","5.4376","284.4124","5.4376","3.6251","67.7172"
"21.9200","5.4574","285.3759","5.4574","3.6383","67.9467"
"22.0000","5.4773","286.3654","5.4773","3.6515","68.1822"
"22.0800","5.4971","287.3581","5.4971","3.6647","68.4186"
"22.1600","5.5172","288.3712","5.5172","3.6782","68.6598"
"22.2400","5.5362","289.2704","5.5362","3.6908","68.8739"
"22.3200","5.5568","290.3131","5.5568","3.7045","69.1222"
"22.4000","5.5780","291.3818","5.5780","3.7187","69.3766"
"22.4800","5.5973","292.3401","5.5973","3.7315","69.6048"
"22.5600","5.6180","293.3696","5.6180","3.7453","69.8499"
"22.6400","5.6368","294.2734","5.6368","3.7579","70.0651"
"22.7200","5.6565","295.2581","5.6565","3.7710","70.2995"
"22.8000","5.6766","296.2580","5.6766","3.7844","70.5376"
"22.8800","5.6968","297.2633","5.6968","3.7979","70.7770"
"22.9600","5.7177","298.3329","5.7177","3.8118","71.0317"
"23.0400","5.7386","299.3727","5.7386","3.8257","71.2792"
"23.1200","5.7572","300.2623","5.7572","3.8381","71.4910"
"23.2000","5.7774","301.2724","5.7774","3.8516","71.7315"
"23.2800","5.7966","302.1892","5.7966","3.8644","71.9498"
"23.3600","5.8178","303.2752","5.8178","3.8785","72.2084"
"23.4400","5.8374","304.2231","5.8374","3.8916","72.4341"
"23.5200","5.8559","305.1183","5.8559","3.9039","72.6472"
"23.6000","5.8766","306.1593","5.8766","3.9177","72.8951"
"23.6800","5.8981","307.2589","5.8981","3.9321","73.1569"
"23.7600","5.9178","308.2134","5.9178","3.9452","73.3841"
"23.8400","5.9376","309.1910","5.9376","3.9584","73.6169"
"23.9200","5.9563","310.0697","5.9563","3.9709","73.8261"
"24.0000","5.9768","311.1002","5.9768","3.9845","74.0715"
"24.0800","5.9975","312.1395","5.9975","3.9983","74.3189"
"24.1600","6.0173","313.1434","6.0173","4.0115","74.5580"
"24.2400","6.0380","314.1692","6.0380","4.0253","74.8022"
"24.3200","6.0573","315.0947","6.0573","4.0382","75.0226"
"24.4000","6.0777","316.1075","6.0777","4.0518","75.2637"
"24.4800","6.0970","317.0497","6.0970","4.0647","75.4880"
"24.5600","6.1172","318.0516","6.1172","4.0781","75.7266"
"24.6400","6.1369","319.0073","6.1369","4.0913","75.9541"
"24.7200","6.1567","319.9736","6.1567","4.1045","76.1842"
"24.8000","6.1763","320.9466","6.1763","4.1175","76.4159"
"24.8800","6.1978","322.0475","6.1978","4.1319","76.6780"
"24.9600","6.2177","322.9979","6.2177","4.1451","76.9043"
"25.0400","6.2378","323.9793","6.2378","4.1585","77.1379"
"25.1200","6.2568","324.8923","6.2568","4.1712","77.3553"
"25.2000","6.2763","325.8542","6.2763","4.1842","77.5843"
"25.2800","6.2966","326.8604","6.2966","4.1977","77.8239"
"25.3600","6.3168","327.8362","6.3168","4.2112","78.0562"
"25.4400","6.3373","328.8714","6.3373","4.2248","78.3027"
"25.5200","6.3583","329.9258","6.3583","4.2388","78.5538"
"25.6000","6.3776","330.8528","6.3776","4.2517","78.7745"
"25.6800","6.3981","331.9162","6.3981","4.2654","79.0277"
"25.7600","6.4177","332.8372","6.4177","4.2784","79.2469"
"25.8400","6.4369","333.7641","6.4369","4.2912","79.4676"
"25.9200","6.4569","334.7480","6.4569","4.3046","79.7019"
"26.0000","6.4758","335.6471","6.4758","4.3172","79.9160"
"26.0800","6.4977","336.7608","6.4977","4.3318","80.1812"
"26.1600","6.5184","337.7961","6.5184","4.3456","80.4276"
"26.2400","6.5375","338.6978","6.5375","4.3583","80.6423"
"26.3200","6.5569","339.6402","6.5569","4.3713","80.8667"
"26.4000","6.5768","340.5897","6.5768","4.3845","81.0928"
"26.4800","6.5969","341.5877","6.5969","4.3979","81.3304"
"26.5600","6.6177","342.6241","6.6177","4.4118","81.5772"
"26.6400","6.6364","343.5023","6.6364","4.4242","81.7863"
"26.7200","6.6576","344.5605","6.6576","4.4384","82.0382"
"26.8000","6.6779","345.5612","6.6779","4.4519","82.2765"
"26.8800","6.6979","346.5264","6.6979","4.4653","82.5063"
"26.9600","6.7168","347.4253","6.7168","4.4779","82.7203"
"27.0400","6.7367","348.3744","6.7367","4.4911","82.9463"
"27.1200","6.7570","349.3772","6.7570","4.5046","83.1850"
"27.2000","6.7772","350.3584","6.7772","4.5181","83.4187"
"27.2800","6.7964","351.2990","6.7964","4.5309","83.6426"
"27.3600","6.8173","352.3427","6.8173","4.5449","83.8911"
"27.4400","6.8373","353.3066","6.8373","4.5582","84.1206"
"27.5200","6.8579","354.3425","6.8579","4.5720","84.3673"
"27.6000","6.8775","355.2628","6.8775","4.5850","84.5864"
"27.6800","6.8965","356.1725","6.8965","4.5977","84.8030"
"27.7600","6.9169","357.1596","6.9169","4.6112","85.0380"
"27.8400","6.9367","358.1319","6.9367","4.6244","85.2695"
"27.9200","6.9568","359.1230","6.9568","4.6378","85.5055"
"28.0000","6.9781","360.2045","6.9781","4.6520","85.7630"
"28.0800","6.9981","361.1584","6.9981","4.6654","85.9901"
"28.1600","7.0179","362.1171","7.0179","4.6786","86.2184"
"28.2400","7.0378","363.0716","7.0378","4.6918","86.4456"
"28.3200","7.0566","363.9753","7.0566","4.7044","86.6608"
"28.4000","7.0773","364.9991","7.0773","4.7182","86.9046"
"28.4800","7.0962","365.8848","7.0962","4.7308","87.1154"
"28.5600","7.1172","366.9488","7.1172","4.7448","87.3687"
"28.6400","7.1376","367.9620","7.1376","4.7584","87.6100"
"28.7200","7.1576","368.9140","7.1576","4.7717","87.8367"
"28.8000","7.1773","369.8640","7.1773","4.7848","88.0629"
"28.8800","7.1974","370.8361","7.1974","4.7983","88.2943"
"28.9600","7.2165","371.7527","7.2165","4.8110","88.5126"
"29.0400","7.2368","372.7476","7.2368","4.8246","88.7494"
"29.1200","7.2559","373.6366","7.2559","4.8372","88.9611"
"29.2000","7.2776","374.7515","7.2776","4.8518","89.2266"
"29.2800","7.2984","375.7665","7.2984","4.8656","89.4682"
"29.3600","7.3181","376.7510","7.3181","4.8788","89.7026"
"29.4400","7.3373","377.6378","7.3373","4.8915","89.9138"
"29.5200","7.3567","378.5615","7.3567","4.9045","90.1337"
"29.6000","7.3763","379.4957","7.3763","4.9176","90.3561"
"29.6800","7.3975","380.5545","7.3975","4.9317","90.6082"
"29.7600","7.4164","381.4346","7.4164","4.9443","90.8178"
"29.8400","7.4368","382.4232","7.4368","4.9579","91.0531"
"29.9200","7.4580","383.4797","7.4580","4.9720","91.3047"
"30.0000","7.4780","384.4452","7.4780","4.9853","91.5346"
"30.0800","7.4979","385.3968","7.4979","4.9986","91.7611"
"30.1600","7.5166","386.2603","7.5166","5.0111","91.9667"
"30.2400","7.5368","387.2371","7.5368","5.0246","92.1993"
"30.3200","7.5567","388.1980","7.5567","5.0378","92.4281"
"30.4000","7.5768","389.1658","7.5768","5.0512","92.6585"
"30.4800","7.5977","390.2076","7.5977","5.0651","92.9066"
"30.5600","7.6185","391.2076","7.6185","5.0790","93.1447"
"30.6400","7.6382","392.1824","7.6382","5.0922","93.3768"
"30.7200","7.6582","393.1209","7.6582","5.1055","93.6002"
"30.8000","7.6766","393.9662","7.6766","5.1178","93.8015"
"30.8800","7.6973","394.9768","7.6973","5.1316","94.0421"
"30.9600","7.7165","395.8714","7.7165","5.1443","94.2551"
"31.0400","7.7365","396.8517","7.7365","5.1577","94.4885"
"31.1200","7.7568","397.8482","7.7568","5.1712","94.7258"
"31.2000","7.7776","398.8414","7.7776","5.1851","94.9622"
"31.2800","7.7979","399.8205","7.7979","5.1986","95.1953"
"31.3600","7.8178","400.7621","7.8178","5.2119","95.4195"
"31.4400","7.8360","401.5826","7.8360","5.2240","95.6149"
"31.5200","7.8565","402.5972","7.8565","5.2377","95.8565"
"31.6000","7.8766","403.5472","7.8766","5.2511","96.0827"
"31.6800","7.8976","404.5884","7.8976","5.2650","96.3306"
"31.7600","7.9183","405.5948","7.9183","5.2788","96.5702"
"31.8400","7.9374","406.4770","7.9374","5.2916","96.7802"
"31.9200","7.9574","407.4353","7.9574","5.3049","97.0084"
"32.0000","7.9775","408.3907","7.9775","5.3184","97.2359"
"32.0800","7.9971","409.3202","7.9971","5.3314","97.4572"
"32.1600","8.0169","410.2682","8.0169","5.3446","97.6829"
"32.2400","8.0363","411.1609","8.0363","5.3575","97.8954"
"32.3200","8.0568","412.1641","8.0568","5.3712","98.1343"
"32.4000","8.0781","413.2204","8.0781","5.3854","98.3858"
"32.4800","8.0973","414.1031","8.0973","5.3982","98.5960"
"32.5600","8.1177","415.0751","8.1177","5.4118","98.8274"
"32.6400","8.1365","415.9294","8.1365","5.4243","99.0308"
"32.7200","8.1567","416.9095","8.1567","5.4378","99.2642"
"32.8000","8.1763","417.8430","8.1763","5.4509","99.4864"
"32.8800","8.1968","418.8244","8.1968","5.4646","99.7201"
"32.9600","8.2178","419.8423","8.2178","5.4785","99.9625"
"33.0400","8.2386","420.8437","8.2386","5.4924","100.2009"
"33.1200","8.2571","421.6884","8.2571","5.5048","100.4020"
"33.2000","8.2773","422.6487","8.2773","5.5182","100.6306"
"33.2800","8.2971","423.5839","8.2971","5.5314","100.8533"
"33.3600","8.3180","424.6012","8.3180","5.5453","101.0955"
"33.4400","8.3371","425.4744","8.3371","5.5581","101.3034"
"33.5200","8.3558","426.3315","8.3558","5.5705","101.5075"
"33.6000","8.3766","427.3325","8.3766","5.5844","101.7458"
"33.6800","8.3980","428.3803","8.3980","5.5986","101.9953"
"33.7600","8.4179","429.3170","8.4179","5.6119","102.2183"
"33.8400","8.4373","430.2163","8.4373","5.6249","102.4325"
"33.9200","8.4560","431.0519","8.4560","5.6373","102.6314"
"34.0000","8.4768","432.0787","8.4768","5.6512","102.8759"
"34.0800","8.4975","433.0613","8.4975","5.6650","103.1098"
"34.1600","8.5173","434.0114","8.5173","5.6782","103.3360"
"34.2400","8.5376","434.9590","8.5376","5.6918","103.5617"
"34.3200","8.5572","435.8608","8.5572","5.7048","103.7764"
"34.4000","8.5783","436.8766","8.5783","5.7189","104.0182"
"34.4800","8.5978","437.7766","8.5978","5.7318","104.2325"
"34.5600","8.6168","438.6345","8.6168","5.7446","104.4368"
"34.6400","8.6365","439.5659","8.6365","5.7577","104.6586"
"34.7200","8.6560","440.4485","8.6560","5.7707","104.8687"
"34.8000","8.6762","441.4359","8.6762","5.7842","105.1038"
"34.8800","8.6981","442.5019","8.6981","5.7987","105.3576"
"34.9600","8.7175","443.3764","8.7175","5.8117","105.5658"
"35.0400","8.7380","444.3294","8.7380","5.8253","105.7927"
"35.1200","8.7570","445.1852","8.7570","5.8380","105.9965"
"35.2000","8.7767","446.1194","8.7767","5.8512","106.2189"
"35.2800","8.7966","447.0522","8.7966","5.8644","106.4410"
"35.3600","8.8165","447.9731","8.8165","5.8776","106.6603"
"35.4400","8.8374","448.9792","8.8374","5.8916","106.8998"
"35.5200","8.8583","449.9760","8.8583","5.9055","107.1371"
"35.6000","8.8777","450.8668","8.8777","5.9185","107.3492"
"35.6800","8.8983","451.8344","8.8983","5.9322","107.5796"
"35.7600","8.9174","452.6845","8.9174","5.9450","107.7820"
"35.8400","8.9369","453.5956","8.9369","5.9580","107.9990"
"35.9200","8.9567","454.5086","8.9567","5.9711","108.2163"
"36.0000","8.9755","455.3597","8.9755","5.9837","108.4190"
"36.0800","8.9976","456.4633","8.9976","5.9984","108.6818"
"36.1600","9.0185","457.4614","9.0185","6.0124","108.9194"
"36.2400","9.0377","458.3091","9.0377","6.0251","109.1212"
"36.3200","9.0570","459.1971","9.0570","6.0380","109.3326"
"36.4000","9.0767","460.0956","9.0767","6.0511","109.5466"
"36.4800","9.0967","461.0154","9.0967","6.0644","109.7656"
"36.5600","9.1173","461.9893","9.1173","6.0782","109.9975"
"36.6400","9.1362","462.8280","9.1362","6.0908","110.1971"
"36.7200","9.1577","463.8716","9.1577","6.1051","110.4456"
"36.8000","9.1779","464.8113","9.1779","6.1186","110.6694"
"36.8800","9.1982","465.7567","9.1982","6.1321","110.8944"
"36.9600","9.2171","466.5997","9.2171","6.1447","111.0952"
"37.0400","9.2370","467.5163","9.2370","6.1580","111.3134"
"37.1200","9.2569","468.4296","9.2569","6.1713","111.5309"
"37.2000","9.2769","469.3508","9.2769","6.1846","111.7502"
"37.2800","9.2962","470.2398","9.2962","6.1975","111.9619"
"37.3600","9.3176","471.2613","9.3176","6.2117","112.2051"
"37.4400","9.3374","472.1579","9.3374","6.2249","112.4185"
"37.5200","9.3577","473.1030","9.3577","6.2385","112.6436"
"37.6000","9.3773","473.9926","9.3773","6.2515","112.8554"
"37.6800","9.3966","474.8668","9.3966","6.2644","113.0635"
"37.7600","9.4169","475.8093","9.4169","6.2780","113.2879"
"37.8400","9.4366","476.6937","9.4366","6.2910","113.4985"
"37.9200","9.4567","477.6354","9.4567","6.3045","113.7227"
"38.0000","9.4780","478.6654","9.4780","6.3187","113.9680"
"38.0800","9.4981","479.5569","9.4981","6.3321","114.1802"
"38.1600","9.5180","480.4610","9.5180","6.3454","114.3955"
"38.2400","9.5378","481.3523","9.5378","6.3586","114.6077"
"38.3200","9.5566","482.1853","9.5566","6.3711","114.8060"
"38.4000","9.5769","483.1250","9.5769","6.3846","115.0298"
"38.4800","9.5962","483.9941","9.5962","6.3975","115.2367"
"38.5600","9.6175","484.9907","9.6175","6.4116","115.4740"
"38.6400","9.6371","485.8777","9.6371","6.4247","115.6852"
"38.7200","9.6575","486.8006","9.6575","6.4383","115.9049"
"38.8000","9.6772","487.6807","9.6772","6.4515","116.1145"
"38.8800","9.6974","488.5928","9.6974","6.4650","116.3316"
"38.9600","9.7167","489.4499","9.7167","6.4778","116.5357"
"39.0400","9.7371","490.3926","9.7371","6.4914","116.7601"
"39.1200","9.7560","491.2045","9.7560","6.5040","116.9534"
"39.2000","9.7777","492.2566","9.7777","6.5185","117.2039"
"39.2800","9.7982","493.1748","9.7982","6.5321","117.4226"
"39.3600","9.8177","494.0518","9.8177","6.5451","117.6314"
"39.4400","9.8371","494.8992","9.8371","6.5581","117.8331"
"39.5200","9.8570","495.7783","9.8570","6.5713","118.0424"
"39.6000","9.8771","496.6983","9.8771","6.5848","118.2615"
"39.6800","9.8973","497.6193","9.8973","6.5982","118.4808"
"39.7600","9.9161","498.4145","9.9161","6.6107","118.6701"
"39.8400","9.9368","499.3801","9.9368","6.6245","118.9000"
"39.9200","9.9575","500.3160","9.9575","6.6383","119.1229"
"40.0000","9.9779","501.2614","9.9779","6.6519","119.3480"
"40.0800","9.9978","502.1497","9.9978","6.6652","119.5595"
"40.1600","10.0168","502.9585","10.0168","6.6779","119.7520"
"40.2400","10.0372","503.8769","10.0372","6.6914","119.9707"
"40.3200","10.0564","504.7113","10.0564","6.7043","120.1693"
"40.4000","10.0768","505.6483","10.0768","6.7179","120.3924"
"40.4800","10.0976","506.6013","10.0976","6.7317","120.6194"
"40.5600","10.1181","507.5158","10.1181","6.7454","120.8371"
"40.6400","10.1378","508.3806","10.1378","6.7585","121.0430"
"40.7200","10.1576","509.2505","10.1576","6.7717","121.2501"
"40.8000","10.1766","510.0666","10.1766","6.7844","121.4444"
"40.8800","10.1974","511.0091","10.1974","6.7983","121.6688"
"40.9600","10.2165","511.8172","10.2165","6.8110","121.8612"
"41.0400","10.2367","512.7327","10.2367","6.8245","122.0792"
"41.1200","10.2569","513.6151","10.2569","6.8379","122.2893"
"41.2000","10.2775","514.5531","10.2775","6.8517","122.5126"
"41.2800","10.2979","515.4561","10.2979","6.8653","122.7276"
"41.3600","10.3182","516.3713","10.3182","6.8788","122.9456"
"41.4400","10.3365","517.1173","10.3365","6.8910","123.1232"
"41.5200","10.3568","518.0255","10.3568","6.9046","123.3394"
"41.6000","10.3767","518.8848","10.3767","6.9178","123.5440"
"41.6800","10.3974","519.8211","10.3974","6.9316","123.7669"
"41.7600","10.4182","520.7567","10.4182","6.9455","123.9897"
"41.8400","10.4375","521.5731","10.4375","6.9584","124.1841"
"41.9200","10.4576","522.4430","10.4576","6.9717","124.3912"
"42.0000","10.4774","523.3027","10.4774","6.9849","124.5959"
"42.0800","10.4970","524.1573","10.4970","6.9980","124.7994"
"42.1600","10.5164","525.0145","10.5164","7.0109","125.0035"
"42.2400","10.5360","525.8583","10.5360","7.0240","125.2044"
"42.3200","10.5573","526.8193","10.5573","7.0382","125.4332"
"42.4000","10.5783","527.7520","10.5783","7.0522","125.6552"
"42.4800","10.5976","528.5565","10.5976","7.0651","125.8468"
"42.5600","10.6180","529.4375","10.6180","7.0787","126.0566"
"42.6400","10.6366","530.1871","10.6366","7.0910","126.2350"
"42.7200","10.6565","531.0588","10.6565","7.1043","126.4426"
"42.8000","10.6766","531.9449","10.6766","7.1177","126.6536"
"42.8800","10.6970","532.8329","10.6970","7.1313","126.8650"
"42.9600","10.7176","533.7243","10.7176","7.1451","127.0772"
"43.0400","10.7381","534.6194","10.7381","7.1588","127.2903"
"43.1200","10.7576","535.4474","10.7576","7.1717","127.4875"
"43.2000","10.7774","536.2822","10.7774","7.1849","127.6862"
"43.2800","10.7967","537.0691","10.7967","7.1978","127.8736"
"43.3600","10.8177","538.0173","10.8177","7.2118","128.0994"
"43.4400","10.8369","538.7961","10.8369","7.2246","128.2848"
"43.5200","10.8563","539.6348","10.8563","7.2375","128.4845"
"43.6000","10.8769","540.5261","10.8769","7.2513","128.6967"
"43.6800","10.8975","541.4141","10.8975","7.2650","128.9081"
"43.7600","10.9180","542.2814","10.9180","7.2786","129.1146"
"43.8400","10.9374","543.0692","10.9374","7.2916","129.3022"
"43.9200","10.9564","543.8301","10.9564","7.3043","129.4834"
"44.0000","10.9770","544.7147","10.9770","7.3180","129.6940"
"44.0800","10.9973","545.5555","10.9973","7.3315","129.8942"
"44.1600","11.0169","546.3903","11.0169","7.3446","130.0929"
"44.2400","11.0375","547.2609","11.0375","7.3583","130.3002"
"44.3200","11.0574","548.0744","11.0574","7.3716","130.4939"
"44.4000","11.0782","548.9542","11.0782","7.3854","130.7034"
"44.4800","11.0977","549.7439","11.0977","7.3985","130.8914"
"44.5600","11.1168","550.4970","11.1168","7.4112","131.0707"
"44.6400","11.1367","551.3208","11.1367","7.4244","131.2669"
"44.7200","11.1564","552.1224","11.1564","7.4376","131.4577"
"44.8000","11.1761","552.9324","11.1761","7.4507","131.6506"
"44.8800","11.1978","553.8964","11.1978","7.4652","131.8801"
"44.9600","11.2177","554.6926","11.2177","7.4784","132.0697"
"45.0400","11.2383","555.5569","11.2383","7.4922","132.2754"
"45.1200","11.2568","556.2299","11.2568","7.5045","132.4357"
"45.2000","11.2767","557.0555","11.2767","7.5178","132.6323"
"45.2800","11.2962","557.8240","11.2962","7.5308","132.8152"
"45.3600","11.3169","558.6840","11.3169","7.5446","133.0200"
"45.4400","11.3374","559.5242","11.3374","7.5583","133.2201"
"45.5200","11.3581","560.3754","11.3581","7.5720","133.4227"
"45.6000","11.3777","561.1411","11.3777","7.5851","133.6050"
"45.6800","11.3984","561.9955","11.3984","7.5989","133.8084"
"45.7600","11.4173","562.6956","11.4173","7.6115","133.9751"
"45.8400","11.4369","563.5021","11.4369","7.6246","134.1672"
"45.9200","11.4566","564.2815","11.4566","7.6377","134.3527"
"46.0000","11.4759","565.0268","11.4759","7.6506","134.5302"
"46.0800","11.4973","565.9212","11.4973","7.6649","134.7431"
"46.1600","11.5178","566.7380","11.5178","7.6785","134.9376"
"46.2400","11.5379","567.5208","11.5379","7.6919","135.1240"
"46.3200","11.5570","568.2297","11.5570","7.7046","135.2928"
"46.4000","11.5765","568.9734","11.5765","7.7177","135.4699"
"46.4800","11.5970","569.7975","11.5970","7.7313","135.6661"
"46.5600","11.6174","570.6061","11.6174","7.7450","135.8586"
"46.6400","11.6359","571.2737","11.6359","7.7573","136.0175"
"46.7200","11.6576","572.1769","11.6576","7.7718","136.2326"
"46.8000","11.6777","572.9497","11.6777","7.7851","136.4166"
"46.8800","11.6990","573.8197","11.6990","7.7993","136.6237"
"46.9600","11.7175","574.4643","11.7175","7.8117","136.7772"
"47.0400","11.7365","575.1395","11.7365","7.8243","136.9380"
"47.1200","11.7562","575.9025","11.7562","7.8375","137.1197"
"47.2000","11.7773","576.7471","11.7773","7.8515","137.3207"
"47.2800","11.7968","577.4888","11.7968","7.8645","137.4973"
"47.3600","11.8176","578.3056","11.8176","7.8784","137.6918"
"47.4400","11.8375","579.0408","11.8375","7.8916","137.8669"
"47.5200","11.8577","579.8126","11.8577","7.9051","138.0506"
"47.6000","11.8773","580.5216","11.8773","7.9182","138.2194"
"47.6800","11.8966","581.2339","11.8966","7.9311","138.3890"
"47.7600","11.9170","582.0003","11.9170","7.9447","138.5715"
"47.8400","11.9370","582.7346","11.9370","7.9580","138.7463"
"47.9200","11.9570","583.4901","11.9570","7.9713","138.9262"
"48.0000","11.9778","584.2965","11.9778","7.9852","139.1182"
"48.0800","11.9980","585.0315","11.9980","7.9987","139.2932"
"48.1600","12.0182","585.7768","12.0182","8.0122","139.4707"
"48.2400","12.0378","586.4673","12.0378","8.0252","139.6351"
"48.3200","12.0565","587.1118","12.0565","8.0377","139.7885"
"48.4000","12.0772","587.9001","12.0772","8.0514","139.9762"
"48.4800","12.0960","588.5145","12.0960","8.0640","140.1225"
"48.5600","12.1174","589.3602","12.1174","8.0782","140.3239"
"48.6400","12.1375","590.0936","12.1375","8.0917","140.4985"
"48.7200","12.1577","590.8304","12.1577","8.1052","140.6739"
"48.8000","12.1772","591.5009","12.1772","8.1181","140.8335"
"48.8800","12.1974","592.2180","12.1974","8.1316","141.0043"
"48.9600","12.2166","592.8788","12.2166","8.1444","141.1616"
"49.0400","12.2370","593.6177","12.2370","8.1580","141.3376"
"49.1200","12.2557","594.1966","12.2557","8.1705","141.4754"
"49.2000","12.2777","595.0861","12.2777","8.1852","141.6872"
"49.2800","12.2986","595.8290","12.2986","8.1991","141.8640"
"49.3600","12.3183","596.4962","12.3183","8.2122","142.0229"
"49.4400","12.3370","597.0730","12.3370","8.2246","142.1602"
"49.5200","12.3568","597.7524","12.3568","8.2379","142.3220"
"49.6000","12.3765","598.4281","12.3765","8.2510","142.4829"
"49.6800","12.3972","599.1808","12.3972","8.2648","142.6621"
"49.7600","12.4165","599.7911","12.4165","8.2777","142.8074"
"49.8400","12.4374","600.5381","12.4374","8.2916","142.9853"
"49.9200","12.4576","601.2078","12.4576","8.3051","143.1447"
"50.0000","12.4778","601.9138","12.4778","8.3185","143.3128"
"50.0800","12.4978","602.5656","12.4978","8.3319","143.4680"
"50.1600","12.5166","603.1321","12.5166","8.3444","143.6029"
"50.2400","12.5372","603.8395","12.5372","8.3582","143.7713"
"50.3200","12.5565","604.4459","12.5565","8.3710","143.9157"
"50.4000","12.5765","605.1079","12.5765","8.3843","144.0733"
"50.4800","12.5974","605.8371","12.5974","8.3983","144.2469"
"50.5600","12.6185","606.5573","12.6185","8.4124","144.4184"
"50.6400","12.6381","607.1608","12.6381","8.4254","144.5621"
"50.7200","12.6582","607.8002","12.6582","8.4388","144.7143"
"50.8000","12.6762","608.2903","12.6762","8.4508","144.8310"
"50.8800","12.6971","608.9929","12.6971","8.4647","144.9983"
"50.9600","12.7164","609.5637","12.7164","8.4776","145.1342"
"51.0400","12.7364","610.2191","12.7364","8.4909","145.2903"
"51.1200","12.7567","610.8666","12.7567","8.5045","145.4444"
"51.2000","12.7776","611.5422","12.7776","8.5184","145.6053"
"51.2800","12.7977","612.1658","12.7977","8.5318","145.7538"
"51.3600","12.8181","612.8033","12.8181","8.5454","145.9055"
"51.4400","12.8366","613.3007","12.8366","8.5578","146.0240"
"51.5200","12.8567","613.9294","12.8567","8.5711","146.1737"
"51.6000","12.8763","614.4893","12.8763","8.5842","146.3070"
"51.6800","12.8978","615.2185","12.8978","8.5985","146.4806"
"51.7600","12.9184","615.8492","12.9184","8.6123","146.6308"
"51.8400","12.9378","616.3859","12.9378","8.6252","146.7586"
"51.9200","12.9575","616.9326","12.9575","8.6383","146.8887"
"52.0000","12.9774","617.5247","12.9774","8.6516","147.0297"
"52.0800","12.9974","618.1172","12.9974","8.6650","147.1708"
"52.1600","13.0167","618.6439","13.0167","8.6778","147.2962"
"52.2400","13.0363","619.1840","13.0363","8.6909","147.4248"
"52.3200","13.0568","619.8327","13.0568","8.7045","147.5792"
"52.4000","13.0782","620.5015","13.0782","8.7188","147.7385"
"52.4800","13.0976","621.0256","13.0976","8.7317","147.8632"
"52.5600","13.1178","621.5839","13.1178","8.7452","147.9962"
"52.6400","13.1367","622.0471","13.1367","8.7578","148.1065"
"52.7200","13.1568","622.6172","13.1568","8.7712","148.2422"
"52.8000","13.1763","623.1304","13.1763","8.7842","148.3644"
"52.8800","13.1967","623.7002","13.1967","8.7978","148.5000"
"52.9600","13.2177","624.3050","13.2177","8.8118","148.6440"
"53.0400","13.2387","624.8989","13.2387","8.8258","148.7855"
"53.1200","13.2576","625.3475","13.2576","8.8384","148.8923"
"53.2000","13.2772","625.8541","13.2772","8.8515","149.0129"
"53.2800","13.2967","626.3442","13.2967","8.8645","149.1296"
"53.3600","13.3176","626.9426","13.3176","8.8784","149.2721"
"53.4400","13.3370","627.4115","13.3370","8.8913","149.3837"
"53.5200","13.3563","627.8948","13.3563","8.9042","149.4988"
"53.6000","13.3770","628.4555","13.3770","8.9180","149.6323"
"53.6800","13.3980","629.0355","13.3980","8.9320","149.7703"
"53.7600","13.4178","629.4936","13.4178","8.9452","149.8794"
"53.8400","13.4375","629.9755","13.4375","8.9583","149.9942"
"53.9200","13.4563","630.3735","13.4563","8.9709","150.0889"
"54.0000","13.4769","630.9153","13.4769","8.9846","150.2179"
"54.0800","13.4971","631.4045","13.4971","8.9981","150.3344"
"54.1600","13.5171","631.9254","13.5171","9.0114","150.4584"
"54.2400","13.5377","632.4328","13.5377","9.0252","150.5792"
"54.3200","13.5575","632.8763","13.5575","9.0383","150.6848"
"54.4000","13.5781","633.3826","13.5781","9.0521","150.8054"
"54.4800","13.5980","633.8259","13.5980","9.0653","150.9109"
"54.5600","13.6168","634.1912","13.6168","9.0779","150.9979"
"54.6400","13.6365","634.6346","13.6365","9.0910","151.1035"
"54.7200","13.6568","635.1026","13.6568","9.1045","151.2149"
"54.8000","13.6766","635.5542","13.6766","9.1178","151.3224"
"54.8800","13.6981","636.1078","13.6981","9.1321","151.4542"
"54.9600","13.7173","636.4576","13.7173","9.1449","151.5375"
"55.0400","13.7378","636.9006","13.7378","9.1585","151.6430"
"55.1200","13.7571","637.2673","13.7571","9.1714","151.7303"
"55.2000","13.7767","637.6748","13.7767","9.1845","151.8273"
"55.2800","13.7963","638.0710","13.7963","9.1975","151.9217"
"55.3600","13.8164","638.4740","13.8164","9.2109","152.0176"
"55.4400","13.8368","638.9183","13.8368","9.2246","152.1234"
"55.5200","13.8584","639.4343","13.8584","9.2389","152.2463"
"55.6000","13.8783","639.8150","13.8783","9.2522","152.3369"
"55.6800","13.8983","640.1790","13.8983","9.2655","152.4236"
"55.7600","13.9173","640.4796","13.9173","9.2782","152.4951"
"55.8400","13.9368","640.8516","13.9368","9.2912","152.5837"
"55.9200","13.9569","641.2348","13.9569","9.3046","152.6750"
"56.0000","13.9760","641.5449","13.9760","9.3174","152.7488"
"56.0800","13.9971","641.9938","13.9971","9.3314","152.8557"
"56.1600","14.0181","642.4464","14.0181","9.3454","152.9634"
"56.2400","14.0378","642.7616","14.0378","9.3585","153.0385"
"56.3200","14.0572","643.0736","14.0572","9.3714","153.1128"
"56.4000","14.0769","643.3869","14.0769","9.3846","153.1874"
"56.4800","14.0971","643.7576","14.0971","9.3981","153.2756"
"56.5600","14.1175","644.1049","14.1175","9.4117","153.3583"
"56.6400","14.1362","644.3541","14.1362","9.4241","153.4176"
"56.7200","14.1574","644.7689","14.1574","9.4382","153.5164"
"56.8000","14.1776","645.1028","14.1776","9.4518","153.5959"
"56.8800","14.1985","645.4990","14.1985","9.4657","153.6902"
"56.9600","14.2176","645.7369","14.2176","9.4784","153.7469"
"57.0400","14.2366","645.9712","14.2366","9.4911","153.8027"
"57.1200","14.2568","646.2994","14.2568","9.5045","153.8808"
"57.2000","14.2771","646.6135","14.2771","9.5180","153.9556"
"57.2800","14.2964","646.8674","14.2964","9.5310","154.0160"
"57.3600","14.3174","647.2335","14.3174","9.5450","154.1032"
"57.4400","14.3373","647.4785","14.3373","9.5582","154.1615"
"57.5200","14.3578","647.8145","14.3578","9.5718","154.2415"
"57.6000","14.3774","648.0509","14.3774","9.5849","154.2978"
"57.6800","14.3967","648.2928","14.3967","9.5978","154.3554"
"57.7600","14.4168","648.5502","14.4168","9.6112","154.4167"
"57.8400","14.4366","648.8091","14.4366","9.6244","154.4784"
"57.9200","14.4567","649.0803","14.4567","9.6378","154.5429"
"58.0000","14.4780","649.4431","14.4780","9.6520","154.6293"
"58.0800","14.4981","649.6570","14.4981","9.6654","154.6802"
"58.1600","14.5179","649.9096","14.5179","9.6786","154.7404"
"58.2400","14.5375","650.1304","14.5375","9.6917","154.7929"
"58.3200","14.5566","650.3099","14.5566","9.7044","154.8357"
"58.4000","14.5766","650.5523","14.5766","9.7178","154.8934"
"58.4800","14.5959","650.7242","14.5959","9.7306","154.9343"
"58.5600","14.6167","651.0284","14.6167","9.7445","155.0068"
"58.6400","14.6376","651.3011","14.6376","9.7584","155.0717"
"58.7200","14.6578","651.5124","14.6578","9.7719","155.1220"
"58.8000","14.6777","651.7029","14.6777","9.7851","155.1674"
"58.8800","14.6975","651.8779","14.6975","9.7984","155.2090"
"58.9600","14.7171","652.0645","14.7171","9.8114","155.2535"
"59.0400","14.7370","652.2424","14.7370","9.8246","155.2958"
"59.1200","14.7555","652.3140","14.7555","9.8370","155.3129"
"59.2000","14.7777","652.6705","14.7777","9.8518","155.3977"
"59.2800","14.7987","652.8929","14.7987","9.8658","155.4507"
"59.3600","14.8183","653.0403","14.8183","9.8789","155.4858"
"59.4400","14.8372","653.1055","14.8372","9.8915","155.5013"
"59.5200","14.8567","653.2440","14.8567","9.9045","155.5343"
"59.6000","14.8771","653.4391","14.8771","9.9181","155.5807"
"59.6800","14.8975","653.6176","14.8975","9.9317","155.6232"
"59.7600","14.9162","653.6790","14.9162","9.9441","155.6378"
"59.8400","14.9369","653.8796","14.9369","9.9579","155.6856"
"59.9200","14.9574","654.0361","14.9574","9.9716","155.7229"
"60.0000","14.9779","654.2144","14.9779","9.9853","155.7653"
"60.0800","14.9978","654.3289","14.9978","9.9986","155.7926"
"60.0890","15.0001","654.3351","15.0001","10.0001","155.7941"