File: data/instron_tests/metamaterials/250331/250331_1049_VERT_m1.is_comp_Exports/250331_1049_VERT_m1_6_1.csv
Results Table 1
,Compresson Axis,H*,V*,Height,Thickness,Width,Area,Fixture separation,Specimen label
,,,,(mm),(mm),(mm),(mm^2),(mm),
"6","X","","","150.00","28.00","150.00","4200.00","150.00","1049_VERT_m1"

Results Table 2
,Modulus (Segment 0 % - 5 %),Compresson Axis
,(kPa),
"6","1855.41","X"

Time,Displacement,Force,Compressive displacement,Compressive strain (Displacement),Compressive stress
(s),(mm),(N),(mm),(%),(kPa)
"0.0000","0.0000","-26.8682","0.0000","0.0000","-6.3972"
"0.0800","0.0012","-26.7030","0.0012","0.0008","-6.3579"
"0.1600","0.0175","-25.5260","0.0175","0.0116","-6.0776"
"0.2400","0.0379","-24.1819","0.0379","0.0253","-5.7576"
"0.3200","0.0579","-22.9007","0.0579","0.0386","-5.4526"
"0.4000","0.0771","-21.6899","0.0771","0.0514","-5.1643"
"0.4800","0.0981","-20.3920","0.0981","0.0654","-4.8552"
"0.5600","0.1184","-19.1870","0.1184","0.0789","-4.5683"
"0.6400","0.1383","-18.0026","0.1383","0.0922","-4.2863"
"0.7200","0.1576","-16.8677","0.1576","0.1051","-4.0161"
"0.8000","0.1768","-15.7538","0.1768","0.1179","-3.7509"
"0.8800","0.1976","-14.5429","0.1976","0.1317","-3.4626"
"0.9600","0.2173","-13.4053","0.2173","0.1448","-3.1917"
"1.0400","0.2366","-12.2837","0.2366","0.1577","-2.9247"
"1.1200","0.2576","-11.0683","0.2576","0.1717","-2.6353"
"1.2000","0.2774","-9.9541","0.2774","0.1849","-2.3700"
"1.2800","0.2976","-8.8151","0.2976","0.1984","-2.0988"
"1.3600","0.3177","-7.6791","0.3177","0.2118","-1.8284"
"1.4400","0.3366","-6.6232","0.3366","0.2244","-1.5770"
"1.5200","0.3573","-5.4489","0.3573","0.2382","-1.2974"
"1.6000","0.3772","-4.3377","0.3772","0.2514","-1.0328"
"1.6800","0.3976","-3.1778","0.3976","0.2651","-0.7566"
"1.7600","0.4189","-1.9816","0.4189","0.2793","-0.4718"
"1.8400","0.4378","-0.9451","0.4378","0.2919","-0.2250"
"1.9200","0.4578","0.1515","0.4578","0.3052","0.0361"
"2.0000","0.4775","1.2404","0.4775","0.3183","0.2953"
"2.0800","0.4971","2.3432","0.4971","0.3314","0.5579"
"2.1600","0.5175","3.4733","0.5175","0.3450","0.8270"
"2.2400","0.5366","4.5008","0.5366","0.3578","1.0716"
"2.3200","0.5570","5.6355","0.5570","0.3713","1.3418"
"2.4000","0.5783","6.8241","0.5783","0.3856","1.6248"
"2.4800","0.5978","7.8766","0.5978","0.3985","1.8754"
"2.5600","0.6180","8.9889","0.6180","0.4120","2.1402"
"2.6400","0.6369","9.9924","0.6369","0.4246","2.3791"
"2.7200","0.6566","11.0774","0.6566","0.4377","2.6375"
"2.8000","0.6769","12.1891","0.6769","0.4513","2.9022"
"2.8800","0.6972","13.2801","0.6972","0.4648","3.1619"
"2.9600","0.7181","14.4180","0.7181","0.4787","3.4329"
"3.0400","0.7385","15.5146","0.7385","0.4923","3.6939"
"3.1200","0.7576","16.5461","0.7576","0.5051","3.9395"
"3.2000","0.7775","17.6122","0.7775","0.5183","4.1934"
"3.2800","0.7969","18.6339","0.7969","0.5313","4.4366"
"3.3600","0.8177","19.7686","0.8177","0.5451","4.7068"
"3.4400","0.8378","20.8328","0.8378","0.5585","4.9602"
"3.5200","0.8564","21.8055","0.8564","0.5709","5.1918"
"3.6000","0.8769","22.9036","0.8769","0.5846","5.4532"
"3.6800","0.8982","24.0594","0.8982","0.5988","5.7284"
"3.7600","0.9177","25.0677","0.9177","0.6118","5.9685"
"3.8400","0.9375","26.1277","0.9375","0.6250","6.2209"
"3.9200","0.9560","27.0851","0.9560","0.6373","6.4488"
"4.0000","0.9768","28.2191","0.9768","0.6512","6.7188"
"4.0800","0.9979","29.3260","0.9979","0.6653","6.9824"
"4.1600","1.0174","30.3719","1.0174","0.6783","7.2314"
"4.2400","1.0379","31.4522","1.0379","0.6919","7.4886"
"4.3200","1.0579","32.5045","1.0579","0.7052","7.7392"
"4.4000","1.0784","33.5918","1.0784","0.7189","7.9980"
"4.4800","1.0983","34.6376","1.0983","0.7322","8.2470"
"4.5600","1.1172","35.6289","1.1172","0.7448","8.4831"
"4.6400","1.1372","36.6747","1.1372","0.7581","8.7321"
"4.7200","1.1567","37.7016","1.1567","0.7711","8.9766"
"4.8000","1.1766","38.7641","1.1766","0.7844","9.2295"
"4.8800","1.1984","39.9428","1.1984","0.7989","9.5102"
"4.9600","1.2177","40.9247","1.2177","0.8118","9.7440"
"5.0400","1.2378","41.9870","1.2378","0.8252","9.9969"
"5.1200","1.2573","43.0006","1.2573","0.8382","10.2382"
"5.2000","1.2766","44.0052","1.2766","0.8511","10.4774"
"5.2800","1.2972","45.1111","1.2972","0.8648","10.7407"
"5.3600","1.3172","46.1488","1.3172","0.8781","10.9878"
"5.4400","1.3374","47.2185","1.3374","0.8916","11.2425"
"5.5200","1.3585","48.3368","1.3585","0.9056","11.5088"
"5.6000","1.3780","49.3436","1.3780","0.9187","11.7485"
"5.6800","1.3981","50.3952","1.3981","0.9321","11.9989"
"5.7600","1.4174","51.3815","1.4174","0.9450","12.2337"
"5.8400","1.4370","52.4154","1.4370","0.9580","12.4798"
"5.9200","1.4573","53.4848","1.4573","0.9715","12.7345"
"6.0000","1.4764","54.4685","1.4764","0.9843","12.9687"
"6.0800","1.4977","55.6147","1.4977","0.9985","13.2416"
"6.1600","1.5183","56.7010","1.5183","1.0122","13.5002"
"6.2400","1.5372","57.6721","1.5372","1.0248","13.7314"
"6.3200","1.5570","58.7231","1.5570","1.0380","13.9817"
"6.4000","1.5771","59.7689","1.5771","1.0514","14.2307"
"6.4800","1.5975","60.8504","1.5975","1.0650","14.4882"
"6.5600","1.6180","61.9318","1.6180","1.0787","14.7457"
"6.6400","1.6366","62.8839","1.6366","1.0911","14.9723"
"6.7200","1.6577","64.0096","1.6577","1.1051","15.2404"
"6.8000","1.6783","65.1105","1.6783","1.1189","15.5025"
"6.8800","1.6990","66.2108","1.6990","1.1326","15.7645"
"6.9600","1.7178","67.1754","1.7178","1.1452","15.9941"
"7.0400","1.7365","68.1281","1.7365","1.1577","16.2210"
"7.1200","1.7567","69.2020","1.7567","1.1712","16.4767"
"7.2000","1.7777","70.3336","1.7777","1.1851","16.7461"
"7.2800","1.7969","71.3441","1.7969","1.1979","16.9867"
"7.3600","1.8182","72.4874","1.8182","1.2121","17.2589"
"7.4400","1.8374","73.4741","1.8374","1.2249","17.4938"
"7.5200","1.8580","74.5846","1.8580","1.2387","17.7582"
"7.6000","1.8779","75.6247","1.8779","1.2519","18.0059"
"7.6800","1.8968","76.6164","1.8968","1.2645","18.2420"
"7.7600","1.9171","77.6938","1.9171","1.2781","18.4985"
"7.8400","1.9371","78.7597","1.9371","1.2914","18.7523"
"7.9200","1.9570","79.8081","1.9570","1.3047","19.0019"
"8.0000","1.9785","80.9672","1.9785","1.3190","19.2779"
"8.0800","1.9982","81.9687","1.9982","1.3321","19.5164"
"8.1600","2.0184","83.0607","2.0184","1.3456","19.7764"
"8.2400","2.0380","84.0740","2.0380","1.3587","20.0176"
"8.3200","2.0566","85.0540","2.0566","1.3711","20.2509"
"8.4000","2.0773","86.1534","2.0773","1.3848","20.5127"
"8.4800","2.0967","87.1817","2.0967","1.3978","20.7576"
"8.5600","2.1171","88.2550","2.1171","1.4114","21.0131"
"8.6400","2.1372","89.3223","2.1372","1.4248","21.2672"
"8.7200","2.1578","90.4115","2.1578","1.4385","21.5265"
"8.8000","2.1778","91.4628","2.1778","1.4519","21.7769"
"8.8800","2.1980","92.5113","2.1980","1.4653","22.0265"
"8.9600","2.2170","93.5236","2.2170","1.4780","22.2675"
"9.0400","2.2371","94.5750","2.2371","1.4914","22.5178"
"9.1200","2.2562","95.5750","2.2562","1.5041","22.7559"
"9.2000","2.2779","96.7678","2.2779","1.5186","23.0399"
"9.2800","2.2991","97.8982","2.2991","1.5327","23.3091"
"9.3600","2.3180","98.8731","2.3180","1.5454","23.5412"
"9.4400","2.3374","99.8812","2.3374","1.5583","23.7812"
"9.5200","2.3572","100.9296","2.3572","1.5715","24.0308"
"9.6000","2.3772","102.0071","2.3772","1.5848","24.2874"
"9.6800","2.3977","103.0932","2.3977","1.5985","24.5460"
"9.7600","2.4163","104.0645","2.4163","1.6109","24.7773"
"9.8400","2.4373","105.1953","2.4373","1.6249","25.0465"
"9.9200","2.4580","106.2918","2.4580","1.6386","25.3076"
"10.0000","2.4779","107.3602","2.4779","1.6519","25.5620"
"10.0800","2.4978","108.4080","2.4978","1.6652","25.8114"
"10.1600","2.5173","109.4688","2.5173","1.6782","26.0640"
"10.2400","2.5376","110.5474","2.5376","1.6917","26.3208"
"10.3200","2.5574","111.5819","2.5574","1.7049","26.5671"
"10.4000","2.5766","112.5971","2.5766","1.7177","26.8088"
"10.4800","2.5978","113.7467","2.5978","1.7319","27.0826"
"10.5600","2.6185","114.8259","2.6185","1.7456","27.3395"
"10.6400","2.6382","115.8720","2.6382","1.7588","27.5886"
"10.7200","2.6577","116.8925","2.6577","1.7718","27.8315"
"10.8000","2.6764","117.8654","2.6764","1.7843","28.0632"
"10.8800","2.6976","118.9847","2.6976","1.7984","28.3297"
"10.9600","2.7173","120.0204","2.7173","1.8115","28.5763"
"11.0400","2.7368","121.0468","2.7368","1.8245","28.8207"
"11.1200","2.7572","122.1385","2.7572","1.8382","29.0806"
"11.2000","2.7776","123.1920","2.7776","1.8517","29.3314"
"11.2800","2.7977","124.2523","2.7977","1.8651","29.5839"
"11.3600","2.8183","125.3332","2.8183","1.8788","29.8412"
"11.4400","2.8365","126.2585","2.8365","1.8910","30.0616"
"11.5200","2.8568","127.3296","2.8568","1.9045","30.3166"
"11.6000","2.8766","128.3615","2.8766","1.9177","30.5623"
"11.6800","2.8977","129.5112","2.8977","1.9318","30.8360"
"11.7600","2.9186","130.6197","2.9186","1.9458","31.0999"
"11.8400","2.9375","131.5703","2.9375","1.9583","31.3262"
"11.9200","2.9576","132.6369","2.9576","1.9718","31.5802"
"12.0000","2.9777","133.6985","2.9777","1.9851","31.8330"
"12.0800","2.9974","134.7496","2.9974","1.9983","32.0832"
"12.1600","3.0176","135.8388","3.0176","2.0117","32.3426"
"12.2400","3.0365","136.8018","3.0365","2.0243","32.5719"
"12.3200","3.0571","137.9131","3.0571","2.0380","32.8364"
"12.4000","3.0788","139.0800","3.0788","2.0525","33.1143"
"12.4800","3.0977","140.0641","3.0977","2.0652","33.3486"
"12.5600","3.1180","141.1312","3.1180","2.0787","33.6027"
"12.6400","3.1369","142.1060","3.1369","2.0913","33.8348"
"12.7200","3.1572","143.1893","3.1572","2.1048","34.0927"
"12.8000","3.1769","144.2240","3.1769","2.1179","34.3390"
"12.8800","3.1970","145.2877","3.1970","2.1314","34.5923"
"12.9600","3.2181","146.4205","3.2181","2.1454","34.8620"
"13.0400","3.2387","147.5147","3.2387","2.1591","35.1225"
"13.1200","3.2578","148.5260","3.2578","2.1718","35.3633"
"13.2000","3.2776","149.5625","3.2776","2.1850","35.6101"
"13.2800","3.2970","150.5629","3.2970","2.1980","35.8483"
"13.3600","3.3180","151.6914","3.3180","2.2120","36.1170"
"13.4400","3.3376","152.7067","3.3376","2.2251","36.3587"
"13.5200","3.3562","153.6551","3.3562","2.2375","36.5845"
"13.6000","3.3769","154.7548","3.3769","2.2513","36.8464"
"13.6800","3.3983","155.8957","3.3983","2.2655","37.1180"
"13.7600","3.4181","156.9246","3.4181","2.2787","37.3630"
"13.8400","3.4375","157.9276","3.4375","2.2917","37.6018"
"13.9200","3.4563","158.8773","3.4563","2.3042","37.8279"
"14.0000","3.4772","160.0019","3.4772","2.3181","38.0957"
"14.0800","3.4975","161.0551","3.4975","2.3317","38.3465"
"14.1600","3.5172","162.0955","3.5172","2.3448","38.5942"
"14.2400","3.5383","163.2112","3.5383","2.3589","38.8598"
"14.3200","3.5576","164.2165","3.5576","2.3718","39.0992"
"14.4000","3.5781","165.2889","3.5781","2.3854","39.3545"
"14.4800","3.5979","166.3299","3.5979","2.3986","39.6024"
"14.5600","3.6172","167.3203","3.6172","2.4115","39.8382"
"14.6400","3.6371","168.3674","3.6371","2.4247","40.0875"
"14.7200","3.6568","169.3898","3.6568","2.4379","40.3309"
"14.8000","3.6766","170.4416","3.6766","2.4511","40.5813"
"14.8800","3.6981","171.5983","3.6981","2.4654","40.8567"
"14.9600","3.7176","172.5837","3.7176","2.4784","41.0914"
"15.0400","3.7383","173.6808","3.7383","2.4922","41.3526"
"15.1200","3.7572","174.6493","3.7572","2.5048","41.5832"
"15.2000","3.7766","175.6725","3.7766","2.5178","41.8268"
"15.2800","3.7970","176.7371","3.7970","2.5313","42.0803"
"15.3600","3.8168","177.7523","3.8168","2.5445","42.3220"
"15.4400","3.8377","178.8548","3.8377","2.5585","42.5845"
"15.5200","3.8585","179.9436","3.8585","2.5723","42.8437"
"15.6000","3.8778","180.9315","3.8778","2.5852","43.0789"
"15.6800","3.8983","182.0125","3.8983","2.5988","43.3363"
"15.7600","3.9175","182.9760","3.9175","2.6116","43.5657"
"15.8400","3.9369","183.9910","3.9369","2.6246","43.8074"
"15.9200","3.9574","185.0635","3.9574","2.6383","44.0627"
"16.0000","3.9763","186.0265","3.9763","2.6509","44.2920"
"16.0800","3.9976","187.1495","3.9976","2.6650","44.5594"
"16.1600","4.0184","188.2369","4.0184","2.6789","44.8183"
"16.2400","4.0376","189.2120","4.0376","2.6917","45.0505"
"16.3200","4.0572","190.2309","4.0572","2.7048","45.2931"
"16.4000","4.0770","191.2361","4.0770","2.7180","45.5324"
"16.4800","4.0969","192.2941","4.0969","2.7313","45.7843"
"16.5600","4.1177","193.3706","4.1177","2.7452","46.0406"
"16.6400","4.1366","194.3382","4.1366","2.7577","46.2710"
"16.7200","4.1578","195.4493","4.1578","2.7718","46.5355"
"16.8000","4.1783","196.5222","4.1783","2.7856","46.7910"
"16.8800","4.1985","197.5721","4.1985","2.7990","47.0410"
"16.9600","4.2175","198.5401","4.2175","2.8117","47.2714"
"17.0400","4.2370","199.5303","4.2370","2.8247","47.5072"
"17.1200","4.2571","200.5901","4.2571","2.8381","47.7596"
"17.2000","4.2777","201.6563","4.2777","2.8518","48.0134"
"17.2800","4.2964","202.6226","4.2964","2.8643","48.2435"
"17.3600","4.3176","203.7579","4.3176","2.8784","48.5138"
"17.4400","4.3373","204.7504","4.3373","2.8916","48.7501"
"17.5200","4.3580","205.8413","4.3580","2.9053","49.0098"
"17.6000","4.3776","206.8417","4.3776","2.9184","49.2480"
"17.6800","4.3969","207.8175","4.3969","2.9312","49.4804"
"17.7600","4.4171","208.8766","4.4171","2.9448","49.7325"
"17.8400","4.4371","209.9015","4.4371","2.9581","49.9766"
"17.9200","4.4569","210.9391","4.4569","2.9712","50.2236"
"18.0000","4.4781","212.0561","4.4781","2.9854","50.4895"
"18.0800","4.4983","213.0997","4.4983","2.9989","50.7380"
"18.1600","4.5184","214.1243","4.5184","3.0123","50.9820"
"18.2400","4.5379","215.1026","4.5379","3.0252","51.2149"
"18.3200","4.5565","216.0529","4.5565","3.0377","51.4412"
"18.4000","4.5774","217.1499","4.5774","3.0516","51.7024"
"18.4800","4.5967","218.1305","4.5967","3.0645","51.9358"
"18.5600","4.6177","219.2308","4.6177","3.0785","52.1978"
"18.6400","4.6373","220.2436","4.6373","3.0916","52.4390"
"18.7200","4.6576","221.2810","4.6576","3.1051","52.6859"
"18.8000","4.6776","222.3008","4.6776","3.1184","52.9288"
"18.8800","4.6978","223.3420","4.6978","3.1319","53.1767"
"18.9600","4.7168","224.2991","4.7168","3.1445","53.4045"
"19.0400","4.7372","225.3640","4.7372","3.1581","53.6581"
"19.1200","4.7562","226.3118","4.7562","3.1708","53.8838"
"19.2000","4.7784","227.5098","4.7784","3.1856","54.1690"
"19.2800","4.7987","228.5340","4.7987","3.1991","54.4129"
"19.3600","4.8181","229.5258","4.8181","3.2121","54.6490"
"19.4400","4.8372","230.4841","4.8372","3.2248","54.8772"
"19.5200","4.8574","231.5306","4.8574","3.2383","55.1263"
"19.6000","4.8775","232.5722","4.8775","3.2517","55.3743"
"19.6800","4.8980","233.6491","4.8980","3.2654","55.6307"
"19.7600","4.9164","234.5510","4.9164","3.2776","55.8455"
"19.8400","4.9369","235.6235","4.9369","3.2913","56.1008"
"19.9200","4.9580","236.7201","4.9580","3.3053","56.3619"
"20.0000","4.9781","237.7573","4.9781","3.3187","56.6089"
"20.0800","4.9983","238.7809","4.9983","3.3322","56.8526"
"20.1600","5.0168","239.6738","5.0168","3.3445","57.0652"
"20.2400","5.0369","240.7110","5.0369","3.3579","57.3122"
"20.3200","5.0571","241.7504","5.0571","3.3714","57.5596"
"20.4000","5.0771","242.7655","5.0771","3.3847","57.8013"
"20.4800","5.0980","243.8584","5.0980","3.3987","58.0615"
"20.5600","5.1183","244.8723","5.1183","3.4122","58.3029"
"20.6400","5.1380","245.8766","5.1380","3.4253","58.5420"
"20.7200","5.1580","246.8886","5.1580","3.4387","58.7830"
"20.8000","5.1765","247.7933","5.1765","3.4510","58.9984"
"20.8800","5.1977","248.9148","5.1977","3.4651","59.2654"
"20.9600","5.2171","249.8927","5.2171","3.4781","59.4983"
"21.0400","5.2368","250.8913","5.2368","3.4912","59.7360"
"21.1200","5.2569","251.9135","5.2569","3.5046","59.9794"
"21.2000","5.2776","252.9691","5.2776","3.5184","60.2307"
"21.2800","5.2979","253.9898","5.2979","3.5319","60.4738"
"21.3600","5.3179","254.9928","5.3179","3.5453","60.7126"
"21.4400","5.3364","255.8943","5.3364","3.5576","60.9272"
"21.5200","5.3570","256.9713","5.3570","3.5714","61.1836"
"21.6000","5.3766","257.9719","5.3766","3.5844","61.4219"
"21.6800","5.3979","259.0874","5.3979","3.5986","61.6875"
"21.7600","5.4186","260.1521","5.4186","3.6124","61.9410"
"21.8400","5.4378","261.0917","5.4378","3.6252","62.1647"
"21.9200","5.4578","262.1082","5.4578","3.6385","62.4067"
"22.0000","5.4774","263.0934","5.4774","3.6516","62.6413"
"22.0800","5.4966","264.0586","5.4966","3.6644","62.8711"
"22.1600","5.5174","265.1476","5.5174","3.6783","63.1304"
"22.2400","5.5366","266.0869","5.5366","3.6911","63.3540"
"22.3200","5.5571","267.1541","5.5571","3.7047","63.6081"
"22.4000","5.5785","268.2613","5.5785","3.7190","63.8717"
"22.4800","5.5980","269.2455","5.5980","3.7320","64.1061"
"22.5600","5.6184","270.2842","5.6184","3.7456","64.3534"
"22.6400","5.6369","271.1905","5.6369","3.7579","64.5692"
"22.7200","5.6568","272.2124","5.6568","3.7712","64.8125"
"22.8000","5.6767","273.2222","5.6767","3.7845","65.0529"
"22.8800","5.6972","274.2608","5.6972","3.7981","65.3002"
"22.9600","5.7180","275.3366","5.7180","3.8120","65.5563"
"23.0400","5.7388","276.3951","5.7388","3.8259","65.8084"
"23.1200","5.7574","277.3072","5.7574","3.8382","66.0255"
"23.2000","5.7778","278.3668","5.7778","3.8519","66.2778"
"23.2800","5.7971","279.3160","5.7971","3.8647","66.5038"
"23.3600","5.8180","280.4023","5.8180","3.8787","66.7625"
"23.4400","5.8376","281.3673","5.8376","3.8917","66.9922"
"23.5200","5.8561","282.2901","5.8561","3.9041","67.2119"
"23.6000","5.8769","283.3745","5.8769","3.9179","67.4701"
"23.6800","5.8983","284.4882","5.8983","3.9322","67.7353"
"23.7600","5.9181","285.4737","5.9181","3.9454","67.9699"
"23.8400","5.9376","286.4465","5.9376","3.9584","68.2015"
"23.9200","5.9564","287.3617","5.9564","3.9710","68.4195"
"24.0000","5.9771","288.4356","5.9771","3.9847","68.6752"
"24.0800","5.9976","289.4727","5.9976","3.9984","68.9221"
"24.1600","6.0172","290.4641","6.0172","4.0115","69.1581"
"24.2400","6.0382","291.5427","6.0382","4.0254","69.4149"
"24.3200","6.0575","292.4859","6.0575","4.0383","69.6395"
"24.4000","6.0776","293.5076","6.0776","4.0517","69.8828"
"24.4800","6.0981","294.5773","6.0981","4.0654","70.1374"
"24.5600","6.1178","295.5583","6.1178","4.0785","70.3710"
"24.6400","6.1371","296.5154","6.1371","4.0914","70.5989"
"24.7200","6.1571","297.5153","6.1571","4.1047","70.8370"
"24.8000","6.1770","298.5306","6.1770","4.1180","71.0787"
"24.8800","6.1982","299.6343","6.1982","4.1321","71.3415"
"24.9600","6.2179","300.6073","6.2179","4.1452","71.5732"
"25.0400","6.2378","301.5982","6.2378","4.1586","71.8091"
"25.1200","6.2570","302.5416","6.2570","4.1713","72.0337"
"25.2000","6.2766","303.5336","6.2766","4.1844","72.2699"
"25.2800","6.2970","304.5865","6.2970","4.1980","72.5206"
"25.3600","6.3172","305.5808","6.3172","4.2114","72.7573"
"25.4400","6.3375","306.6142","6.3375","4.2250","73.0034"
"25.5200","6.3585","307.7000","6.3585","4.2390","73.2619"
"25.6000","6.3779","308.6540","6.3779","4.2519","73.4891"
"25.6800","6.3981","309.6793","6.3981","4.2654","73.7332"
"25.7600","6.4176","310.6317","6.4176","4.2784","73.9599"
"25.8400","6.4372","311.6233","6.4372","4.2914","74.1960"
"25.9200","6.4573","312.6313","6.4573","4.3049","74.4360"
"26.0000","6.4760","313.5443","6.4760","4.3173","74.6534"
"26.0800","6.4976","314.6667","6.4976","4.3317","74.9206"
"26.1600","6.5184","315.7289","6.5184","4.3456","75.1735"
"26.2400","6.5381","316.7009","6.5381","4.3587","75.4050"
"26.3200","6.5573","317.6556","6.5573","4.3715","75.6323"
"26.4000","6.5769","318.6175","6.5769","4.3846","75.8613"
"26.4800","6.5973","319.6515","6.5973","4.3982","76.1075"
"26.5600","6.6179","320.6973","6.6179","4.4119","76.3565"
"26.6400","6.6366","321.6033","6.6366","4.4244","76.5722"
"26.7200","6.6578","322.6966","6.6578","4.4385","76.8325"
"26.8000","6.6783","323.7295","6.6783","4.4522","77.0785"
"26.8800","6.6984","324.7353","6.6984","4.4656","77.3179"
"26.9600","6.7176","325.6706","6.7176","4.4784","77.5406"
"27.0400","6.7371","326.6213","6.7371","4.4914","77.7670"
"27.1200","6.7569","327.6031","6.7569","4.5046","78.0007"
"27.2000","6.7774","328.6342","6.7774","4.5182","78.2462"
"27.2800","6.7967","329.5920","6.7967","4.5311","78.4743"
"27.3600","6.8177","330.6688","6.8177","4.5451","78.7307"
"27.4400","6.8374","331.6364","6.8374","4.5583","78.9610"
"27.5200","6.8581","332.6875","6.8581","4.5721","79.2113"
"27.6000","6.8777","333.6570","6.8777","4.5852","79.4422"
"27.6800","6.8967","334.5862","6.8967","4.5978","79.6634"
"27.7600","6.9171","335.6247","6.9171","4.6114","79.9107"
"27.8400","6.9370","336.6100","6.9370","4.6247","80.1452"
"27.9200","6.9571","337.6203","6.9571","4.6381","80.3858"
"28.0000","6.9781","338.6899","6.9781","4.6521","80.6405"
"28.0800","6.9981","339.6764","6.9981","4.6654","80.8753"
"28.1600","7.0182","340.6824","7.0182","4.6788","81.1149"
"28.2400","7.0379","341.6621","7.0379","4.6919","81.3481"
"28.3200","7.0569","342.5922","7.0569","4.7046","81.5696"
"28.4000","7.0776","343.6487","7.0776","4.7184","81.8211"
"28.4800","7.0965","344.5608","7.0965","4.7310","82.0383"
"28.5600","7.1175","345.6385","7.1175","4.7450","82.2949"
"28.6400","7.1379","346.6647","7.1379","4.7586","82.5392"
"28.7200","7.1579","347.6416","7.1579","4.7719","82.7718"
"28.8000","7.1774","348.6037","7.1774","4.7849","83.0009"
"28.8800","7.1977","349.6169","7.1977","4.7985","83.2421"
"28.9600","7.2169","350.5594","7.2169","4.8112","83.4665"
"29.0400","7.2372","351.5722","7.2372","4.8248","83.7077"
"29.1200","7.2560","352.4684","7.2560","4.8374","83.9211"
"29.2000","7.2782","353.6322","7.2782","4.8521","84.1981"
"29.2800","7.2988","354.6699","7.2988","4.8659","84.4452"
"29.3600","7.3184","355.6319","7.3184","4.8789","84.6743"
"29.4400","7.3368","356.4873","7.3368","4.8912","84.8779"
"29.5200","7.3570","357.4944","7.3570","4.9047","85.1177"
"29.6000","7.3773","358.5100","7.3773","4.9182","85.3595"
"29.6800","7.3979","359.5288","7.3979","4.9319","85.6021"
"29.7600","7.4167","360.4285","7.4167","4.9445","85.8163"
"29.8400","7.4371","361.4552","7.4371","4.9581","86.0608"
"29.9200","7.4581","362.5121","7.4581","4.9720","86.3124"
"30.0000","7.4780","363.4979","7.4780","4.9854","86.5471"
"30.0800","7.4981","364.4962","7.4981","4.9987","86.7848"
"30.1600","7.5170","365.3867","7.5170","5.0113","86.9968"
"30.2400","7.5373","366.3961","7.5373","5.0248","87.2372"
"30.3200","7.5570","367.3626","7.5570","5.0380","87.4673"
"30.4000","7.5772","368.3809","7.5772","5.0515","87.7097"
"30.4800","7.5980","369.4234","7.5980","5.0654","87.9580"
"30.5600","7.6187","370.4383","7.6187","5.0791","88.1996"
"30.6400","7.6381","371.4125","7.6381","5.0921","88.4316"
"30.7200","7.6581","372.3919","7.6581","5.1054","88.6647"
"30.8000","7.6770","373.2853","7.6770","5.1180","88.8774"
"30.8800","7.6975","374.2997","7.6975","5.1317","89.1190"
"30.9600","7.7167","375.2184","7.7167","5.1444","89.3377"
"31.0400","7.7367","376.2247","7.7367","5.1578","89.5773"
"31.1200","7.7574","377.2641","7.7574","5.1716","89.8248"
"31.2000","7.7778","378.2645","7.7778","5.1852","90.0630"
"31.2800","7.7980","379.2508","7.7980","5.1987","90.2978"
"31.3600","7.8183","380.2493","7.8183","5.2122","90.5355"
"31.4400","7.8364","381.0908","7.8364","5.2243","90.7359"
"31.5200","7.8569","382.1107","7.8569","5.2379","90.9787"
"31.6000","7.8769","383.0892","7.8769","5.2513","91.2117"
"31.6800","7.8981","384.1645","7.8981","5.2654","91.4677"
"31.7600","7.9184","385.1571","7.9184","5.2790","91.7041"
"31.8400","7.9377","386.0816","7.9377","5.2918","91.9242"
"31.9200","7.9577","387.0438","7.9577","5.3052","92.1533"
"32.0000","7.9777","388.0223","7.9777","5.3185","92.3863"
"32.0800","7.9974","388.9725","7.9974","5.3316","92.6125"
"32.1600","8.0173","389.9341","8.0173","5.3448","92.8415"
"32.2400","8.0362","390.8296","8.0362","5.3575","93.0547"
"32.3200","8.0573","391.8993","8.0573","5.3715","93.3094"
"32.4000","8.0782","392.9304","8.0782","5.3855","93.5549"
"32.4800","8.0975","393.8527","8.0975","5.3983","93.7744"
"32.5600","8.1179","394.8430","8.1179","5.4119","94.0102"
"32.6400","8.1369","395.7239","8.1369","5.4246","94.2200"
"32.7200","8.1569","396.7084","8.1569","5.4380","94.4544"
"32.8000","8.1768","397.6906","8.1768","5.4512","94.6882"
"32.8800","8.1970","398.6673","8.1970","5.4647","94.9208"
"32.9600","8.2180","399.7070","8.2180","5.4787","95.1683"
"33.0400","8.2388","400.7160","8.2388","5.4925","95.4086"
"33.1200","8.2573","401.5740","8.2573","5.5049","95.6129"
"33.2000","8.2775","402.5767","8.2775","5.5184","95.8516"
"33.2800","8.2972","403.5080","8.2972","5.5315","96.0733"
"33.3600","8.3181","404.5452","8.3181","5.5454","96.3203"
"33.4400","8.3374","405.4553","8.3374","5.5583","96.5370"
"33.5200","8.3562","406.3480","8.3562","5.5708","96.7495"
"33.6000","8.3769","407.3698","8.3769","5.5846","96.9928"
"33.6800","8.3984","408.4438","8.3984","5.5989","97.2485"
"33.7600","8.4181","409.3649","8.4181","5.6120","97.4678"
"33.8400","8.4375","410.2846","8.4375","5.6250","97.6868"
"33.9200","8.4564","411.1673","8.4564","5.6376","97.8970"
"34.0000","8.4772","412.2056","8.4772","5.6515","98.1442"
"34.0800","8.4976","413.1808","8.4976","5.6651","98.3764"
"34.1600","8.5173","414.1372","8.5173","5.6782","98.6041"
"34.2400","8.5381","415.1397","8.5381","5.6921","98.8428"
"34.3200","8.5574","416.0515","8.5574","5.7049","99.0599"
"34.4000","8.5784","417.0613","8.5784","5.7190","99.3003"
"34.4800","8.5982","418.0061","8.5982","5.7321","99.5253"
"34.5600","8.6171","418.8864","8.6171","5.7447","99.7349"
"34.6400","8.6366","419.7986","8.6366","5.7578","99.9520"
"34.7200","8.6563","420.7239","8.6563","5.7709","100.1724"
"34.8000","8.6767","421.7299","8.6767","5.7845","100.4119"
"34.8800","8.6983","422.7978","8.6983","5.7989","100.6661"
"34.9600","8.7178","423.7064","8.7178","5.8119","100.8825"
"35.0400","8.7381","424.6479","8.7381","5.8254","101.1066"
"35.1200","8.7572","425.5313","8.7572","5.8381","101.3170"
"35.2000","8.7770","426.4814","8.7770","5.8513","101.5432"
"35.2800","8.7970","427.4268","8.7970","5.8646","101.7683"
"35.3600","8.8167","428.3565","8.8167","5.8778","101.9896"
"35.4400","8.8376","429.3777","8.8376","5.8917","102.2328"
"35.5200","8.8586","430.4044","8.8586","5.9057","102.4772"
"35.6000","8.8780","431.3011","8.8780","5.9187","102.6907"
"35.6800","8.8982","432.2703","8.8982","5.9321","102.9215"
"35.7600","8.9177","433.1710","8.9177","5.9451","103.1359"
"35.8400","8.9373","434.1071","8.9373","5.9582","103.3588"
"35.9200","8.9571","435.0410","8.9571","5.9714","103.5812"
"36.0000","8.9759","435.8994","8.9759","5.9839","103.7856"
"36.0800","8.9976","436.9856","8.9976","5.9984","104.0442"
"36.1600","9.0183","437.9893","9.0183","6.0122","104.2832"
"36.2400","9.0380","438.9046","9.0380","6.0254","104.5011"
"36.3200","9.0575","439.8087","9.0575","6.0383","104.7164"
"36.4000","9.0769","440.6958","9.0769","6.0513","104.9276"
"36.4800","9.0971","441.6727","9.0971","6.0647","105.1602"
"36.5600","9.1177","442.6484","9.1177","6.0784","105.3925"
"36.6400","9.1365","443.5018","9.1365","6.0910","105.5957"
"36.7200","9.1579","444.5590","9.1579","6.1053","105.8474"
"36.8000","9.1782","445.5401","9.1782","6.1188","106.0810"
"36.8800","9.1985","446.5012","9.1985","6.1323","106.3098"
"36.9600","9.2173","447.3388","9.2173","6.1449","106.5092"
"37.0400","9.2372","448.2618","9.2372","6.1581","106.7290"
"37.1200","9.2573","449.2013","9.2573","6.1715","106.9527"
"37.2000","9.2772","450.1351","9.2772","6.1848","107.1750"
"37.2800","9.2965","451.0226","9.2965","6.1977","107.3863"
"37.3600","9.3180","452.0799","9.3180","6.2120","107.6381"
"37.4400","9.3377","452.9734","9.3377","6.2252","107.8508"
"37.5200","9.3580","453.9257","9.3580","6.2387","108.0776"
"37.6000","9.3774","454.8022","9.3774","6.2516","108.2862"
"37.6800","9.3969","455.7060","9.3969","6.2646","108.5014"
"37.7600","9.4172","456.6639","9.4172","6.2782","108.7295"
"37.8400","9.4370","457.5706","9.4370","6.2913","108.9454"
"37.9200","9.4571","458.5213","9.4571","6.3047","109.1717"
"38.0000","9.4781","459.5356","9.4781","6.3187","109.4132"
"38.0800","9.4982","460.4453","9.4982","6.3322","109.6298"
"38.1600","9.5182","461.3698","9.5182","6.3455","109.8500"
"38.2400","9.5379","462.2742","9.5379","6.3586","110.0653"
"38.3200","9.5567","463.1288","9.5567","6.3712","110.2688"
"38.4000","9.5772","464.0918","9.5772","6.3848","110.4980"
"38.4800","9.5965","464.9544","9.5965","6.3976","110.7034"
"38.5600","9.6178","465.9807","9.6178","6.4118","110.9478"
"38.6400","9.6376","466.8977","9.6376","6.4251","111.1661"
"38.7200","9.6576","467.8121","9.6576","6.4384","111.3838"
"38.8000","9.6776","468.7275","9.6776","6.4518","111.6018"
"38.8800","9.6977","469.6515","9.6977","6.4651","111.8218"
"38.9600","9.7169","470.5177","9.7169","6.4779","112.0280"
"39.0400","9.7374","471.4708","9.7374","6.4916","112.2549"
"39.1200","9.7563","472.2900","9.7563","6.5042","112.4500"
"39.2000","9.7780","473.3474","9.7780","6.5187","112.7018"
"39.2800","9.7985","474.2988","9.7985","6.5323","112.9283"
"39.3600","9.8181","475.1965","9.8181","6.5454","113.1420"
"39.4400","9.8373","476.0416","9.8373","6.5582","113.3432"
"39.5200","9.8572","476.9592","9.8572","6.5715","113.5617"
"39.6000","9.8773","477.8725","9.8773","6.5849","113.7792"
"39.6800","9.8975","478.8059","9.8975","6.5983","114.0014"
"39.7600","9.9159","479.6026","9.9159","6.6106","114.1911"
"39.8400","9.9373","480.6308","9.9373","6.6248","114.4359"
"39.9200","9.9582","481.5970","9.9582","6.6388","114.6659"
"40.0000","9.9781","482.5099","9.9781","6.6521","114.8833"
"40.0800","9.9981","483.4025","9.9981","6.6654","115.0958"
"40.1600","10.0170","484.2248","10.0170","6.6780","115.2916"
"40.2400","10.0374","485.1635","10.0374","6.6916","115.5151"
"40.3200","10.0569","486.0402","10.0569","6.7046","115.7239"
"40.4000","10.0770","486.9656","10.0770","6.7180","115.9442"
"40.4800","10.0979","487.9254","10.0979","6.7319","116.1727"
"40.5600","10.1184","488.8498","10.1184","6.7456","116.3928"
"40.6400","10.1380","489.7305","10.1380","6.7587","116.6025"
"40.7200","10.1582","490.6388","10.1582","6.7721","116.8188"
"40.8000","10.1769","491.4462","10.1769","6.7846","117.0110"
"40.8800","10.1976","492.3950","10.1976","6.7984","117.2369"
"40.9600","10.2167","493.2253","10.2167","6.8112","117.4346"
"41.0400","10.2371","494.1758","10.2371","6.8248","117.6609"
"41.1200","10.2572","495.0648","10.2572","6.8381","117.8726"
"41.2000","10.2777","495.9889","10.2777","6.8518","118.0926"
"41.2800","10.2983","496.9178","10.2983","6.8655","118.3138"
"41.3600","10.3180","497.7909","10.3180","6.8787","118.5216"
"41.4400","10.3366","498.5843","10.3366","6.8911","118.7105"
"41.5200","10.3569","499.5032","10.3569","6.9046","118.9293"
"41.6000","10.3769","500.3962","10.3769","6.9179","119.1420"
"41.6800","10.3982","501.3849","10.3982","6.9321","119.3773"
"41.7600","10.4185","502.2865","10.4185","6.9456","119.5920"
"41.8400","10.4377","503.1102","10.4377","6.9585","119.7881"
"41.9200","10.4576","503.9812","10.4576","6.9718","119.9955"
"42.0000","10.4778","504.8814","10.4778","6.9852","120.2099"
"42.0800","10.4976","505.7733","10.4976","6.9984","120.4222"
"42.1600","10.5172","506.6476","10.5172","7.0115","120.6304"
"42.2400","10.5363","507.4461","10.5363","7.0242","120.8205"
"42.3200","10.5566","508.3606","10.5566","7.0377","121.0382"
"42.4000","10.5781","509.3521","10.5781","7.0521","121.2743"
"42.4800","10.5980","510.2176","10.5980","7.0653","121.4804"
"42.5600","10.6184","511.1113","10.6184","7.0789","121.6932"
"42.6400","10.6371","511.8769","10.6371","7.0914","121.8755"
"42.7200","10.6571","512.7559","10.6571","7.1047","122.0847"
"42.8000","10.6765","513.5972","10.6765","7.1177","122.2851"
"42.8800","10.6973","514.5124","10.6973","7.1315","122.5030"
"42.9600","10.7180","515.4409","10.7180","7.1453","122.7240"
"43.0400","10.7384","516.3331","10.7384","7.1590","122.9364"
"43.1200","10.7577","517.1417","10.7577","7.1718","123.1290"
"43.2000","10.7778","518.0203","10.7778","7.1852","123.3382"
"43.2800","10.7970","518.8138","10.7970","7.1980","123.5271"
"43.3600","10.8178","519.7563","10.8178","7.2119","123.7515"
"43.4400","10.8372","520.5598","10.8372","7.2248","123.9428"
"43.5200","10.8568","521.4234","10.8568","7.2378","124.1484"
"43.6000","10.8774","522.3208","10.8774","7.2516","124.3621"
"43.6800","10.8977","523.1892","10.8977","7.2651","124.5689"
"43.7600","10.9179","524.0519","10.9179","7.2786","124.7743"
"43.8400","10.9377","524.9136","10.9377","7.2918","124.9794"
"43.9200","10.9566","525.6646","10.9566","7.3044","125.1582"
"44.0000","10.9772","526.5718","10.9772","7.3181","125.3742"
"44.0800","10.9976","527.4399","10.9976","7.3317","125.5809"
"44.1600","11.0173","528.2720","11.0173","7.3448","125.7790"
"44.2400","11.0378","529.1505","11.0378","7.3585","125.9882"
"44.3200","11.0575","529.9642","11.0575","7.3717","126.1820"
"44.4000","11.0785","530.8703","11.0785","7.3857","126.3977"
"44.4800","11.0981","531.6706","11.0981","7.3987","126.5882"
"44.5600","11.1171","532.4330","11.1171","7.4114","126.7698"
"44.6400","11.1371","533.2731","11.1371","7.4247","126.9698"
"44.7200","11.1565","534.0648","11.1565","7.4377","127.1583"
"44.8000","11.1767","534.9515","11.1767","7.4511","127.3694"
"44.8800","11.1986","535.9157","11.1986","7.4658","127.5990"
"44.9600","11.2180","536.6671","11.2180","7.4787","127.7779"
"45.0400","11.2381","537.4875","11.2381","7.4921","127.9732"
"45.1200","11.2568","538.2188","11.2568","7.5046","128.1473"
"45.2000","11.2763","539.0151","11.2763","7.5175","128.3369"
"45.2800","11.2965","539.8563","11.2965","7.5310","128.5372"
"45.3600","11.3172","540.7272","11.3172","7.5448","128.7446"
"45.4400","11.3377","541.5687","11.3377","7.5584","128.9449"
"45.5200","11.3586","542.4564","11.3586","7.5724","129.1563"
"45.6000","11.3781","543.2344","11.3781","7.5854","129.3415"
"45.6800","11.3986","544.0710","11.3986","7.5991","129.5407"
"45.7600","11.4174","544.7839","11.4174","7.6116","129.7105"
"45.8400","11.4372","545.6354","11.4372","7.6248","129.9132"
"45.9200","11.4570","546.4285","11.4570","7.6380","130.1020"
"46.0000","11.4761","547.1805","11.4761","7.6508","130.2811"
"46.0800","11.4977","548.0981","11.4977","7.6651","130.4995"
"46.1600","11.5183","548.9427","11.5183","7.6789","130.7006"
"46.2400","11.5379","549.7136","11.5379","7.6920","130.8842"
"46.3200","11.5573","550.4611","11.5573","7.7049","131.0622"
"46.4000","11.5767","551.1982","11.5767","7.7178","131.2377"
"46.4800","11.5972","552.0530","11.5972","7.7315","131.4412"
"46.5600","11.6177","552.8741","11.6177","7.7452","131.6367"
"46.6400","11.6362","553.5592","11.6362","7.7574","131.7998"
"46.7200","11.6580","554.4889","11.6580","7.7720","132.0212"
"46.8000","11.6781","555.2691","11.6781","7.7854","132.2069"
"46.8800","11.6989","556.1265","11.6989","7.7993","132.4111"
"46.9600","11.7176","556.8094","11.7176","7.8118","132.5737"
"47.0400","11.7369","557.5254","11.7369","7.8246","132.7441"
"47.1200","11.7569","558.3138","11.7569","7.8379","132.9319"
"47.2000","11.7774","559.1390","11.7774","7.8516","133.1283"
"47.2800","11.7967","559.8713","11.7967","7.8644","133.3027"
"47.3600","11.8177","560.7441","11.8177","7.8785","133.5105"
"47.4400","11.8374","561.4644","11.8374","7.8916","133.6820"
"47.5200","11.8579","562.2934","11.8579","7.9053","133.8794"
"47.6000","11.8777","563.0369","11.8777","7.9185","134.0564"
"47.6800","11.8969","563.7577","11.8969","7.9313","134.2280"
"47.7600","11.9172","564.5330","11.9172","7.9448","134.4126"
"47.8400","11.9372","565.2985","11.9372","7.9581","134.5949"
"47.9200","11.9574","566.0804","11.9574","7.9716","134.7811"
"48.0000","11.9783","566.9180","11.9783","7.9855","134.9805"
"48.0800","11.9983","567.6543","11.9983","7.9989","135.1558"
"48.1600","12.0184","568.4156","12.0184","8.0123","135.3370"
"48.2400","12.0378","569.1190","12.0378","8.0252","135.5045"
"48.3200","12.0566","569.7914","12.0566","8.0377","135.6646"
"48.4000","12.0776","570.6284","12.0776","8.0517","135.8639"
"48.4800","12.0965","571.2847","12.0965","8.0644","136.0202"
"48.5600","12.1177","572.1295","12.1177","8.0785","136.2213"
"48.6400","12.1378","572.8773","12.1378","8.0919","136.3993"
"48.7200","12.1581","573.6254","12.1581","8.1054","136.5775"
"48.8000","12.1776","574.3149","12.1776","8.1184","136.7416"
"48.8800","12.1977","575.0612","12.1977","8.1318","136.9193"
"48.9600","12.2170","575.7540","12.2170","8.1446","137.0843"
"49.0400","12.2374","576.5228","12.2374","8.1582","137.2673"
"49.1200","12.2561","577.1477","12.2561","8.1707","137.4161"
"49.2000","12.2780","578.0217","12.2780","8.1854","137.6242"
"49.2800","12.2988","578.7814","12.2988","8.1992","137.8051"
"49.3600","12.3186","579.4883","12.3186","8.2124","137.9734"
"49.4400","12.3374","580.1024","12.3374","8.2249","138.1196"
"49.5200","12.3570","580.7942","12.3570","8.2380","138.2843"
"49.6000","12.3772","581.5352","12.3772","8.2514","138.4608"
"49.6800","12.3978","582.2961","12.3978","8.2652","138.6419"
"49.7600","12.4164","582.9051","12.4164","8.2776","138.7869"
"49.8400","12.4373","583.6833","12.4373","8.2915","138.9722"
"49.9200","12.4580","584.4162","12.4580","8.3053","139.1467"
"50.0000","12.4778","585.1036","12.4778","8.3185","139.3104"
"50.0800","12.4981","585.8150","12.4981","8.3321","139.4798"
"50.1600","12.5167","586.4025","12.5167","8.3445","139.6196"
"50.2400","12.5373","587.1451","12.5373","8.3582","139.7965"
"50.3200","12.5569","587.8051","12.5569","8.3713","139.9536"
"50.4000","12.5770","588.5032","12.5770","8.3847","140.1198"
"50.4800","12.5973","589.2173","12.5973","8.3982","140.2898"
"50.5600","12.6186","589.9798","12.6186","8.4124","140.4714"
"50.6400","12.6382","590.6417","12.6382","8.4255","140.6290"
"50.7200","12.6582","591.3015","12.6582","8.4388","140.7861"
"50.8000","12.6767","591.8597","12.6767","8.4511","140.9190"
"50.8800","12.6977","592.5779","12.6977","8.4651","141.0900"
"50.9600","12.7169","593.1975","12.7169","8.4779","141.2375"
"51.0400","12.7370","593.8973","12.7370","8.4914","141.4041"
"51.1200","12.7570","594.5523","12.7570","8.5046","141.5601"
"51.2000","12.7777","595.2588","12.7777","8.5185","141.7283"
"51.2800","12.7980","595.9282","12.7980","8.5320","141.8877"
"51.3600","12.8185","596.6431","12.8185","8.5457","142.0579"
"51.4400","12.8369","597.1686","12.8369","8.5579","142.1830"
"51.5200","12.8568","597.8149","12.8568","8.5712","142.3369"
"51.6000","12.8767","598.4536","12.8767","8.5845","142.4889"
"51.6800","12.8980","599.2036","12.8980","8.5986","142.6675"
"51.7600","12.9187","599.8744","12.9187","8.6124","142.8272"
"51.8400","12.9382","600.4708","12.9382","8.6254","142.9692"
"51.9200","12.9581","601.0760","12.9581","8.6387","143.1133"
"52.0000","12.9774","601.6612","12.9774","8.6516","143.2527"
"52.0800","12.9974","602.3098","12.9974","8.6650","143.4071"
"52.1600","13.0171","602.9163","13.0171","8.6780","143.5515"
"52.2400","13.0364","603.4724","13.0364","8.6909","143.6839"
"52.3200","13.0571","604.1898","13.0571","8.7047","143.8547"
"52.4000","13.0785","604.9191","13.0785","8.7190","144.0284"
"52.4800","13.0979","605.4778","13.0979","8.7319","144.1614"
"52.5600","13.1181","606.0878","13.1181","8.7454","144.3066"
"52.6400","13.1370","606.6093","13.1370","8.7580","144.4308"
"52.7200","13.1567","607.1949","13.1567","8.7711","144.5702"
"52.8000","13.1763","607.7808","13.1763","8.7842","144.7097"
"52.8800","13.1966","608.3976","13.1966","8.7978","144.8566"
"52.9600","13.2182","609.0912","13.2182","8.8121","145.0217"
"53.0400","13.2388","609.6954","13.2388","8.8258","145.1656"
"53.1200","13.2579","610.2140","13.2579","8.8386","145.2890"
"53.2000","13.2778","610.7768","13.2778","8.8519","145.4230"
"53.2800","13.2970","611.2935","13.2970","8.8647","145.5461"
"53.3600","13.3178","611.9303","13.3178","8.8785","145.6977"
"53.4400","13.3375","612.4858","13.3375","8.8916","145.8300"
"53.5200","13.3565","613.0051","13.3565","8.9043","145.9536"
"53.6000","13.3774","613.6240","13.3774","8.9182","146.1010"
"53.6800","13.3982","614.2391","13.3982","8.9322","146.2474"
"53.7600","13.4181","614.7776","13.4181","8.9454","146.3756"
"53.8400","13.4376","615.2905","13.4376","8.9584","146.4977"
"53.9200","13.4566","615.7698","13.4566","8.9711","146.6119"
"54.0000","13.4771","616.3655","13.4771","8.9847","146.7537"
"54.0800","13.4973","616.9165","13.4973","8.9982","146.8849"
"54.1600","13.5173","617.4992","13.5173","9.0116","147.0236"
"54.2400","13.5384","618.1172","13.5384","9.0256","147.1708"
"54.3200","13.5577","618.5840","13.5577","9.0385","147.2819"
"54.4000","13.5783","619.1512","13.5783","9.0522","147.4169"
"54.4800","13.5982","619.6652","13.5982","9.0655","147.5393"
"54.5600","13.6173","620.1128","13.6172","9.0782","147.6459"
"54.6400","13.6369","620.6082","13.6369","9.0913","147.7639"
"54.7200","13.6570","621.1309","13.6570","9.1047","147.8883"
"54.8000","13.6769","621.6575","13.6769","9.1179","148.0137"
"54.8800","13.6984","622.2674","13.6984","9.1322","148.1589"
"54.9600","13.7176","622.7018","13.7176","9.1451","148.2623"
"55.0400","13.7381","623.2205","13.7381","9.1587","148.3858"
"55.1200","13.7571","623.6419","13.7571","9.1714","148.4862"
"55.2000","13.7772","624.1559","13.7772","9.1848","148.6086"
"55.2800","13.7967","624.6122","13.7967","9.1978","148.7172"
"55.3600","13.8167","625.1036","13.8167","9.2112","148.8342"
"55.4400","13.8376","625.6537","13.8376","9.2251","148.9652"
"55.5200","13.8589","626.2198","13.8589","9.2393","149.0999"
"55.6000","13.8776","626.5881","13.8776","9.2518","149.1877"
"55.6800","13.8982","627.0905","13.8982","9.2655","149.3073"
"55.7600","13.9175","627.4843","13.9175","9.2783","149.4010"
"55.8400","13.9373","627.9522","13.9373","9.2915","149.5124"
"55.9200","13.9572","628.4043","13.9572","9.3048","149.6201"
"56.0000","13.9763","628.7950","13.9763","9.3175","149.7131"
"56.0800","13.9976","629.3410","13.9976","9.3317","149.8431"
"56.1600","14.0184","629.8758","14.0184","9.3456","149.9704"
"56.2400","14.0381","630.2881","14.0381","9.3587","150.0686"
"56.3200","14.0574","630.6793","14.0574","9.3716","150.1617"
"56.4000","14.0769","631.0768","14.0769","9.3846","150.2564"
"56.4800","14.0974","631.5629","14.0974","9.3982","150.3721"
"56.5600","14.1178","632.0157","14.1178","9.4118","150.4799"
"56.6400","14.1364","632.3502","14.1364","9.4243","150.5596"
"56.7200","14.1578","632.8719","14.1578","9.4385","150.6838"
"56.8000","14.1780","633.3016","14.1780","9.4520","150.7861"
"56.8800","14.1988","633.7791","14.1988","9.4658","150.8998"
"56.9600","14.2177","634.1147","14.2177","9.4784","150.9797"
"57.0400","14.2368","634.4550","14.2368","9.4912","151.0607"
"57.1200","14.2572","634.8985","14.2572","9.5048","151.1663"
"57.2000","14.2775","635.3250","14.2775","9.5183","151.2678"
"57.2800","14.2967","635.6741","14.2967","9.5311","151.3510"
"57.3600","14.3175","636.1363","14.3175","9.5450","151.4610"
"57.4400","14.3376","636.5089","14.3376","9.5584","151.5497"
"57.5200","14.3578","636.9127","14.3578","9.5719","151.6459"
"57.6000","14.3776","637.2771","14.3776","9.5850","151.7326"
"57.6800","14.3971","637.6321","14.3971","9.5981","151.8172"
"57.7600","14.4170","637.9836","14.4170","9.6113","151.9009"
"57.8400","14.4368","638.3499","14.4368","9.6245","151.9881"
"57.9200","14.4572","638.7535","14.4572","9.6381","152.0842"
"58.0000","14.4781","639.1918","14.4781","9.6521","152.1885"
"58.0800","14.4984","639.5454","14.4984","9.6656","152.2727"
"58.1600","14.5181","639.8836","14.5181","9.6787","152.3532"
"58.2400","14.5374","640.1906","14.5374","9.6916","152.4263"
"58.3200","14.5567","640.5099","14.5567","9.7044","152.5024"
"58.4000","14.5772","640.8906","14.5772","9.7181","152.5930"
"58.4800","14.5968","641.2009","14.5968","9.7312","152.6669"
"58.5600","14.6174","641.5834","14.6174","9.7449","152.7579"
"58.6400","14.6376","641.9348","14.6376","9.7584","152.8416"
"58.7200","14.6581","642.2749","14.6581","9.7720","152.9226"
"58.8000","14.6779","642.5652","14.6779","9.7852","152.9917"
"58.8800","14.6977","642.8712","14.6977","9.7985","153.0646"
"58.9600","14.7172","643.1589","14.7172","9.8115","153.1331"
"59.0400","14.7371","643.4676","14.7371","9.8247","153.2066"
"59.1200","14.7560","643.6928","14.7560","9.8373","153.2602"
"59.2000","14.7778","644.1343","14.7778","9.8519","153.3653"
"59.2800","14.7989","644.4807","14.7989","9.8659","153.4478"
"59.3600","14.8184","644.7357","14.8184","9.8789","153.5085"
"59.4400","14.8375","644.9561","14.8375","9.8917","153.5610"
"59.5200","14.8571","645.2030","14.8571","9.9047","153.6198"
"59.6000","14.8775","645.5154","14.8775","9.9183","153.6941"
"59.6800","14.8979","645.8117","14.8979","9.9319","153.7647"
"59.7600","14.9164","645.9774","14.9164","9.9442","153.8041"
"59.8400","14.9369","646.2829","14.9369","9.9580","153.8769"
"59.9200","14.9575","646.5743","14.9575","9.9717","153.9463"
"60.0000","14.9781","646.8802","14.9781","9.9854","154.0191"
"60.0800","14.9983","647.1167","14.9983","9.9989","154.0754"
"60.0870","15.0000","647.1324","15.0000","10.0000","154.0792"